
#######################################################################
# +-----------------------------------------------------------------+ #
# |                            BO4 object                           | #
# +-----------------------------------------------------------------+ #
#######################################################################

Author: NLBlackEagle

Description: No description given

SettingsMode: WriteDisable


#######################################################################
# +-----------------------------------------------------------------+ #
# |                          Main settings                          | #
# +-----------------------------------------------------------------+ #
#######################################################################

Frequency: 0

SpawnHeight: highestBlock

UseCenterForHighestBlock: true

##############################
# Height Limits for the BO4. #
##############################

MinHeight: 0

MaxHeight: 255

InheritBO3: 

InheritBO3Rotation: NORTH

OverrideChildSettings: true

OverrideParentHeight: false

CanOverride: true

BranchFrequency: 0

BranchFrequencyGroup: 

MustBeBelowOther: false

MustBeInside: 

CannotBeInside: 

ReplacesBO3: L4-M-CrossC0R0, L4-M-CrossC0R1, L4-M-CrossC0R2, L4-M-CrossC0R3, L4-M-CrossC1R0, L4-M-CrossC1R1, L4-M-CrossC1R2, L4-M-CrossC1R3, L4-M-CrossC2R0, L4-M-CrossC2R1, L4-M-CrossC2R2, L4-M-CrossC2R3, L4-M-CrossC3R0, L4-M-CrossC3R1, L4-M-CrossC3R2, L4-M-CrossC3R3, L4-M-Straigth-START_01-C0R0, L4-M-Straigth-START_01-C0R1, L4-M-Straigth-START_01-C1R0, L4-M-Straigth-START_01-C1R1, L4-M-Straigth-START_01-C2R0, L4-M-Straigth-START_01-C2R1, L4-M-Straigth-START_01-C3R0, L4-M-Straigth-START_01-C3R1, L4-M-Straigth-3CC0R0, L4-M-Straigth-3CC0R1, L4-M-Straigth-3CC0R2, L4-M-Straigth-3CC1R0, L4-M-Straigth-3CC1R1, L4-M-Straigth-3CC1R2, L4-M-Straigth-3CC2R0, L4-M-Straigth-3CC2R1, L4-M-Straigth-3CC2R2, L4-M-Straigth-3CC3R0, L4-M-Straigth-3CC3R1, L4-M-Straigth-3CC3R2, L4-M-Cross, ruinscraper_2x2_01, ruinscraper_2x2_02, ruinscraper_2x2_03, ruinscraper_2x2_04, ruinscraper_2x2_05, ruinscraper_3x3_01, ruinscraper_3x3_02, ruinscraper_3x3_03, L3-M-Straigth-2CC0R0, L3-M-Straigth-2CC0R1, L3-M-Straigth-2CC1R0, L3-M-Straigth-2CC1R1, L3-M-Straigth-2CC2R0, L3-M-Straigth-2CC2R1, L3-M-Straigth-2CC3R0, L3-M-Straigth-2CC3R1, L3-M-Straigth-3CC0R0, L3-M-Straigth-3CC0R1, L3-M-Straigth-3CC0R2, L3-M-Straigth-3CC1R0, L3-M-Straigth-3CC1R1, L3-M-Straigth-3CC1R2, L3-M-Straigth-3CC2R0, L3-M-Straigth-3CC2R1, L3-M-Straigth-3CC2R2, L3-M-Straigth-3CC3R0, L3-M-Straigth-3CC3R1, L3-M-Straigth-3CC3R2L4-M-CrossC0R0, L4-M-CrossC0R1, L4-M-CrossC0R2, L4-M-CrossC0R3, L4-M-CrossC1R0, L4-M-CrossC1R1, L4-M-CrossC1R2, L4-M-CrossC1R3, L4-M-CrossC2R0, L4-M-CrossC2R1, L4-M-CrossC2R2, L4-M-CrossC2R3, L4-M-CrossC3R0, L4-M-CrossC3R1, L4-M-CrossC3R2, L4-M-CrossC3R3, L4-M-Straigth-START_01-C0R0, L4-M-Straigth-START_01-C0R1, L4-M-Straigth-START_01-C1R0, L4-M-Straigth-START_01-C1R1, L4-M-Straigth-START_01-C2R0, L4-M-Straigth-START_01-C2R1, L4-M-Straigth-START_01-C3R0, L4-M-Straigth-START_01-C3R1, L4-M-Straigth-3CC0R0, L4-M-Straigth-3CC0R1, L4-M-Straigth-3CC0R2, L4-M-Straigth-3CC1R0, L4-M-Straigth-3CC1R1, L4-M-Straigth-3CC1R2, L4-M-Straigth-3CC2R0, L4-M-Straigth-3CC2R1, L4-M-Straigth-3CC2R2, L4-M-Straigth-3CC3R0, L4-M-Straigth-3CC3R1, L4-M-Straigth-3CC3R2, L4-M-Cross, ruinscraper_2x2_01, ruinscraper_2x2_02, ruinscraper_2x2_03, ruinscraper_2x2_04, ruinscraper_2x2_05, ruinscraper_3x3_01, ruinscraper_3x3_02, ruinscraper_3x3_03

MustBeInsideWorldBorders: true
CanSpawnOnWater: true

SpawnOnWaterOnly: false

SpawnUnderWater: false

SpawnAtWaterLevel: false

HeightOffset: 0

RemoveAir: false

ReplaceAbove: 

ReplaceBelow: 

ReplaceWithBiomeBlocks: true

ReplaceWithSurfaceBlock: GRASS

ReplaceWithGroundBlock: DIRT

ReplaceWithStoneBlock: STONE

SmoothRadius: 0

SmoothHeightOffset: 0

SmoothStartTop: false

SmoothStartWood: false

SmoothingSurfaceBlock: 

SmoothingGroundBlock: 

BO3Group: 

IsSpawnPoint: false

DoReplaceBlocks: true


#######################################################################
# +-----------------------------------------------------------------+ #
# |                              Blocks                             | #
# +-----------------------------------------------------------------+ #
#######################################################################

RandomBlock(-8,0,-7,CONCRETE:7,60,quark:iron_plate:1,20,STAINED_CLAY:12,15,STAINED_CLAY:15,5,AIR,7,IRON_BARS,12,CONCRETE:7,100)
RandomBlock(-8,0,-6,CONCRETE:7,60,quark:iron_plate:1,20,STAINED_CLAY:12,15,STAINED_CLAY:15,5,AIR,7,IRON_BARS,12,CONCRETE:7,100)
RandomBlock(-8,0,-5,CONCRETE:7,60,quark:iron_plate:1,20,STAINED_CLAY:12,15,STAINED_CLAY:15,5,AIR,7,IRON_BARS,12,CONCRETE:7,100)
RandomBlock(-8,0,-4,CONCRETE:7,60,quark:iron_plate:1,20,STAINED_CLAY:12,15,STAINED_CLAY:15,5,AIR,7,IRON_BARS,12,CONCRETE:7,100)
RandomBlock(-8,0,-3,CONCRETE:7,60,quark:iron_plate:1,20,STAINED_CLAY:12,15,STAINED_CLAY:15,5,AIR,7,IRON_BARS,12,CONCRETE:7,100)
RandomBlock(-8,0,-2,CONCRETE:7,60,quark:iron_plate:1,20,STAINED_CLAY:12,15,STAINED_CLAY:15,5,AIR,7,IRON_BARS,12,CONCRETE:7,100)
RandomBlock(-8,0,-1,CONCRETE:7,60,quark:iron_plate:1,20,STAINED_CLAY:12,15,STAINED_CLAY:15,5,AIR,7,IRON_BARS,12,CONCRETE:7,100)
RandomBlock(-8,0,0,CONCRETE:7,60,quark:iron_plate:1,20,STAINED_CLAY:12,15,STAINED_CLAY:15,5,AIR,7,IRON_BARS,12,CONCRETE:7,100)
RandomBlock(-8,0,1,CONCRETE:7,60,quark:iron_plate:1,20,STAINED_CLAY:12,15,STAINED_CLAY:15,5,AIR,7,IRON_BARS,12,CONCRETE:7,100)
RandomBlock(-8,0,2,CONCRETE:7,60,quark:iron_plate:1,20,STAINED_CLAY:12,15,STAINED_CLAY:15,5,AIR,7,IRON_BARS,12,CONCRETE:7,100)
RandomBlock(-8,0,3,CONCRETE:7,60,quark:iron_plate:1,20,STAINED_CLAY:12,15,STAINED_CLAY:15,5,AIR,7,IRON_BARS,12,CONCRETE:7,100)
RandomBlock(-8,0,4,CONCRETE:7,60,quark:iron_plate:1,20,STAINED_CLAY:12,15,STAINED_CLAY:15,5,AIR,7,IRON_BARS,12,CONCRETE:7,100)
RandomBlock(-8,0,5,CONCRETE:7,60,quark:iron_plate:1,20,STAINED_CLAY:12,15,STAINED_CLAY:15,5,AIR,7,IRON_BARS,12,CONCRETE:7,100)
RandomBlock(-8,0,6,CONCRETE:7,60,quark:iron_plate:1,20,STAINED_CLAY:12,15,STAINED_CLAY:15,5,AIR,7,IRON_BARS,12,CONCRETE:7,100)
RandomBlock(-8,0,7,CONCRETE:7,60,quark:iron_plate:1,20,STAINED_CLAY:12,15,STAINED_CLAY:15,5,AIR,7,IRON_BARS,12,CONCRETE:7,100)
RandomBlock(-8,0,8,CONCRETE:7,60,quark:iron_plate:1,20,STAINED_CLAY:12,15,STAINED_CLAY:15,5,AIR,7,IRON_BARS,12,CONCRETE:7,100)
Block(-8,1,-4,SMOOTH_STAIRS:2)
RandomBlock(-8,1,-3,CONCRETE:7,60,quark:iron_plate:1,20,STAINED_CLAY:12,15,STAINED_CLAY:15,5,AIR,7,IRON_BARS,12,CONCRETE:7,100)
RandomBlock(-8,1,-2,CONCRETE:7,60,quark:iron_plate:1,20,STAINED_CLAY:12,15,STAINED_CLAY:15,5,AIR,7,IRON_BARS,12,CONCRETE:7,100)
RandomBlock(-8,1,-1,CONCRETE:7,60,quark:iron_plate:1,20,STAINED_CLAY:12,15,STAINED_CLAY:15,5,AIR,7,IRON_BARS,12,CONCRETE:7,100)
RandomBlock(-8,1,0,CONCRETE:7,60,quark:iron_plate:1,20,STAINED_CLAY:12,15,STAINED_CLAY:15,5,AIR,7,IRON_BARS,12,CONCRETE:7,100)
RandomBlock(-8,1,1,CONCRETE:7,60,quark:iron_plate:1,20,STAINED_CLAY:12,15,STAINED_CLAY:15,5,AIR,7,IRON_BARS,12,CONCRETE:7,100)
RandomBlock(-8,1,2,CONCRETE:7,60,quark:iron_plate:1,20,STAINED_CLAY:12,15,STAINED_CLAY:15,5,AIR,7,IRON_BARS,12,CONCRETE:7,100)
Block(-8,1,3,STATIONARY_WATER:0)
Block(-8,1,4,STATIONARY_WATER:0)
RandomBlock(-8,1,5,CONCRETE:7,60,quark:iron_plate:1,20,STAINED_CLAY:12,15,STAINED_CLAY:15,5,AIR,7,IRON_BARS,12,CONCRETE:7,100)
RandomBlock(-8,1,6,CONCRETE:7,60,quark:iron_plate:1,20,STAINED_CLAY:12,15,STAINED_CLAY:15,5,AIR,7,IRON_BARS,12,CONCRETE:7,100)
RandomBlock(-8,1,7,CONCRETE:7,60,quark:iron_plate:1,20,STAINED_CLAY:12,15,STAINED_CLAY:15,5,AIR,7,IRON_BARS,12,CONCRETE:7,100)
RandomBlock(-8,1,8,CONCRETE:7,60,quark:iron_plate:1,20,STAINED_CLAY:12,15,STAINED_CLAY:15,5,AIR,7,IRON_BARS,12,CONCRETE:7,100)
RandomBlock(-8,2,-7,AIR,90,IRON_TRAPDOOR:9,100)
RandomBlock(-8,2,-6,AIR,90,IRON_TRAPDOOR:11,100)
Block(-8,2,-3,SMOOTH_STAIRS:2)
RandomBlock(-8,2,-2,CONCRETE:7,60,quark:iron_plate:1,20,STAINED_CLAY:12,15,STAINED_CLAY:15,5,AIR,7,IRON_BARS,12,CONCRETE:7,100)
RandomBlock(-8,2,-1,CONCRETE:7,60,quark:iron_plate:1,20,STAINED_CLAY:12,15,STAINED_CLAY:15,5,AIR,7,IRON_BARS,12,CONCRETE:7,100)
RandomBlock(-8,2,0,CONCRETE:7,60,quark:iron_plate:1,20,STAINED_CLAY:12,15,STAINED_CLAY:15,5,AIR,7,IRON_BARS,12,CONCRETE:7,100)
RandomBlock(-8,2,1,CONCRETE:7,60,quark:iron_plate:1,20,STAINED_CLAY:12,15,STAINED_CLAY:15,5,AIR,7,IRON_BARS,12,CONCRETE:7,100)
Block(-8,2,2,SMOOTH_STAIRS:3)
Block(-8,2,5,SMOOTH_STAIRS:2)
RandomBlock(-8,2,6,CONCRETE:7,60,quark:iron_plate:1,20,STAINED_CLAY:12,15,STAINED_CLAY:15,5,AIR,7,IRON_BARS,12,CONCRETE:7,100)
RandomBlock(-8,2,7,CONCRETE:7,60,quark:iron_plate:1,20,STAINED_CLAY:12,15,STAINED_CLAY:15,5,AIR,7,IRON_BARS,12,CONCRETE:7,100)
RandomBlock(-8,2,8,CONCRETE:7,60,quark:iron_plate:1,20,STAINED_CLAY:12,15,STAINED_CLAY:15,5,AIR,7,IRON_BARS,12,CONCRETE:7,100)
RandomBlock(-8,3,8,CONCRETE:7,60,quark:iron_plate:1,20,STAINED_CLAY:12,15,STAINED_CLAY:15,5,AIR,7,IRON_BARS,12,CONCRETE:7,100)
RandomBlock(-8,4,8,CONCRETE:7,60,quark:iron_plate:1,20,STAINED_CLAY:12,15,STAINED_CLAY:15,5,AIR,7,IRON_BARS,12,CONCRETE:7,100)
Block(-8,5,6,CONCRETE:12)
Block(-8,5,7,CONCRETE:4)
RandomBlock(-8,5,8,CONCRETE:7,60,quark:iron_plate:1,20,STAINED_CLAY:12,15,STAINED_CLAY:15,5,AIR,7,IRON_BARS,12,CONCRETE:7,100)
RandomBlock(-8,6,-7,CONCRETE:7,60,quark:iron_plate:1,20,STAINED_CLAY:12,15,STAINED_CLAY:15,5,AIR,7,IRON_BARS,12,CONCRETE:7,100)
RandomBlock(-8,6,8,CONCRETE:7,60,quark:iron_plate:1,20,STAINED_CLAY:12,15,STAINED_CLAY:15,5,AIR,7,IRON_BARS,12,CONCRETE:7,100)
RandomBlock(-8,7,-7,CONCRETE:7,60,quark:iron_plate:1,20,STAINED_CLAY:12,15,STAINED_CLAY:15,5,AIR,7,IRON_BARS,12,CONCRETE:7,100)
RandomBlock(-8,7,-6,CONCRETE:7,60,quark:iron_plate:1,20,STAINED_CLAY:12,15,STAINED_CLAY:15,5,AIR,7,IRON_BARS,12,CONCRETE:7,100)
RandomBlock(-8,7,-5,CONCRETE:7,60,quark:iron_plate:1,20,STAINED_CLAY:12,15,STAINED_CLAY:15,5,AIR,7,IRON_BARS,12,CONCRETE:7,100)
RandomBlock(-8,7,-4,CONCRETE:7,60,quark:iron_plate:1,20,STAINED_CLAY:12,15,STAINED_CLAY:15,5,AIR,7,IRON_BARS,12,CONCRETE:7,100)
RandomBlock(-8,7,-3,CONCRETE:7,60,quark:iron_plate:1,20,STAINED_CLAY:12,15,STAINED_CLAY:15,5,AIR,7,IRON_BARS,12,CONCRETE:7,100)
RandomBlock(-8,7,-2,CONCRETE:7,60,quark:iron_plate:1,20,STAINED_CLAY:12,15,STAINED_CLAY:15,5,AIR,7,IRON_BARS,12,CONCRETE:7,100)
RandomBlock(-8,7,-1,CONCRETE:7,60,quark:iron_plate:1,20,STAINED_CLAY:12,15,STAINED_CLAY:15,5,AIR,7,IRON_BARS,12,CONCRETE:7,100)
RandomBlock(-8,7,0,CONCRETE:7,60,quark:iron_plate:1,20,STAINED_CLAY:12,15,STAINED_CLAY:15,5,AIR,7,IRON_BARS,12,CONCRETE:7,100)
RandomBlock(-8,7,1,CONCRETE:7,60,quark:iron_plate:1,20,STAINED_CLAY:12,15,STAINED_CLAY:15,5,AIR,7,IRON_BARS,12,CONCRETE:7,100)
RandomBlock(-8,7,2,CONCRETE:7,60,quark:iron_plate:1,20,STAINED_CLAY:12,15,STAINED_CLAY:15,5,AIR,7,IRON_BARS,12,CONCRETE:7,100)
RandomBlock(-8,7,3,CONCRETE:7,60,quark:iron_plate:1,20,STAINED_CLAY:12,15,STAINED_CLAY:15,5,AIR,7,IRON_BARS,12,CONCRETE:7,100)
RandomBlock(-8,7,4,CONCRETE:7,60,quark:iron_plate:1,20,STAINED_CLAY:12,15,STAINED_CLAY:15,5,AIR,7,IRON_BARS,12,CONCRETE:7,100)
RandomBlock(-8,7,5,CONCRETE:7,60,quark:iron_plate:1,20,STAINED_CLAY:12,15,STAINED_CLAY:15,5,AIR,7,IRON_BARS,12,CONCRETE:7,100)
RandomBlock(-8,7,6,CONCRETE:7,60,quark:iron_plate:1,20,STAINED_CLAY:12,15,STAINED_CLAY:15,5,AIR,7,IRON_BARS,12,CONCRETE:7,100)
RandomBlock(-8,7,7,CONCRETE:7,60,quark:iron_plate:1,20,STAINED_CLAY:12,15,STAINED_CLAY:15,5,AIR,7,IRON_BARS,12,CONCRETE:7,100)
RandomBlock(-8,7,8,CONCRETE:7,60,quark:iron_plate:1,20,STAINED_CLAY:12,15,STAINED_CLAY:15,5,AIR,7,IRON_BARS,12,CONCRETE:7,100)
RandomBlock(-8,8,-7,CONCRETE:7,60,quark:iron_plate:1,20,STAINED_CLAY:12,15,STAINED_CLAY:15,5,AIR,7,IRON_BARS,12,CONCRETE:7,100)
RandomBlock(-8,8,-6,CONCRETE:7,60,quark:iron_plate:1,20,STAINED_CLAY:12,15,STAINED_CLAY:15,5,AIR,7,IRON_BARS,12,CONCRETE:7,100)
RandomBlock(-8,8,-5,CONCRETE:7,60,quark:iron_plate:1,20,STAINED_CLAY:12,15,STAINED_CLAY:15,5,AIR,7,IRON_BARS,12,CONCRETE:7,100)
RandomBlock(-8,8,-4,CONCRETE:7,60,quark:iron_plate:1,20,STAINED_CLAY:12,15,STAINED_CLAY:15,5,AIR,7,IRON_BARS,12,CONCRETE:7,100)
Block(-8,8,-3,IRON_FENCE:0)
Block(-8,8,-2,IRON_FENCE:0)
RandomBlock(-8,8,-1,CONCRETE:7,60,quark:iron_plate:1,20,STAINED_CLAY:12,15,STAINED_CLAY:15,5,AIR,7,IRON_BARS,12,CONCRETE:7,100)
Block(-8,8,2,IRON_DOOR_BLOCK:3)
RandomBlock(-8,8,3,AIR,90,IRON_TRAPDOOR:10,100)
RandomBlock(-8,8,4,AIR,90,IRON_TRAPDOOR:10,100)
RandomBlock(-8,8,5,AIR,90,IRON_TRAPDOOR:8,100)
Block(-8,8,6,IRON_DOOR_BLOCK:1)
RandomBlock(-8,9,-7,CONCRETE:7,60,quark:iron_plate:1,20,STAINED_CLAY:12,15,STAINED_CLAY:15,5,AIR,7,IRON_BARS,12,CONCRETE:7,100)
RandomBlock(-8,9,-6,CONCRETE:7,60,quark:iron_plate:1,20,STAINED_CLAY:12,15,STAINED_CLAY:15,5,AIR,7,IRON_BARS,12,CONCRETE:7,100)
RandomBlock(-8,9,-5,CONCRETE:7,60,quark:iron_plate:1,20,STAINED_CLAY:12,15,STAINED_CLAY:15,5,AIR,7,IRON_BARS,12,CONCRETE:7,100)
RandomBlock(-8,9,-4,CONCRETE:7,60,quark:iron_plate:1,20,STAINED_CLAY:12,15,STAINED_CLAY:15,5,AIR,7,IRON_BARS,12,CONCRETE:7,100)
Block(-8,9,-3,IRON_FENCE:0)
Block(-8,9,-2,IRON_FENCE:0)
RandomBlock(-8,9,-1,CONCRETE:7,60,quark:iron_plate:1,20,STAINED_CLAY:12,15,STAINED_CLAY:15,5,AIR,7,IRON_BARS,12,CONCRETE:7,100)
Block(-8,9,2,IRON_DOOR_BLOCK:8)
RandomBlock(-8,9,3,AIR,90,IRON_TRAPDOOR:10,100)
RandomBlock(-8,9,4,AIR,90,IRON_TRAPDOOR:10,100)
RandomBlock(-8,9,5,AIR,90,IRON_TRAPDOOR:10,100)
Block(-8,9,6,IRON_DOOR_BLOCK:8)
RandomBlock(-8,10,-7,CONCRETE:7,60,quark:iron_plate:1,20,STAINED_CLAY:12,15,STAINED_CLAY:15,5,AIR,7,IRON_BARS,12,CONCRETE:7,100)
RandomBlock(-8,10,-6,CONCRETE:7,60,quark:iron_plate:1,20,STAINED_CLAY:12,15,STAINED_CLAY:15,5,AIR,7,IRON_BARS,12,CONCRETE:7,100)
RandomBlock(-8,10,-5,CONCRETE:7,60,quark:iron_plate:1,20,STAINED_CLAY:12,15,STAINED_CLAY:15,5,AIR,7,IRON_BARS,12,CONCRETE:7,100)
RandomBlock(-8,10,-4,CONCRETE:7,60,quark:iron_plate:1,20,STAINED_CLAY:12,15,STAINED_CLAY:15,5,AIR,7,IRON_BARS,12,CONCRETE:7,100)
Block(-8,10,-3,IRON_FENCE:0)
Block(-8,10,-2,IRON_FENCE:0)
RandomBlock(-8,10,-1,CONCRETE:7,60,quark:iron_plate:1,20,STAINED_CLAY:12,15,STAINED_CLAY:15,5,AIR,7,IRON_BARS,12,CONCRETE:7,100)
Block(-8,10,1,CONCRETE:12)
Block(-8,10,5,CONCRETE:12)
Block(-8,10,7,CONCRETE:12)
RandomBlock(-8,11,-7,CONCRETE:7,60,quark:iron_plate:1,20,STAINED_CLAY:12,15,STAINED_CLAY:15,5,AIR,7,IRON_BARS,12,CONCRETE:7,100)
RandomBlock(-8,11,-6,CONCRETE:7,60,quark:iron_plate:1,20,STAINED_CLAY:12,15,STAINED_CLAY:15,5,AIR,7,IRON_BARS,12,CONCRETE:7,100)
RandomBlock(-8,11,-5,CONCRETE:7,60,quark:iron_plate:1,20,STAINED_CLAY:12,15,STAINED_CLAY:15,5,AIR,7,IRON_BARS,12,CONCRETE:7,100)
RandomBlock(-8,11,-4,CONCRETE:7,60,quark:iron_plate:1,20,STAINED_CLAY:12,15,STAINED_CLAY:15,5,AIR,7,IRON_BARS,12,CONCRETE:7,100)
RandomBlock(-8,11,-3,CONCRETE:7,60,quark:iron_plate:1,20,STAINED_CLAY:12,15,STAINED_CLAY:15,5,AIR,7,IRON_BARS,12,CONCRETE:7,100)
RandomBlock(-8,11,-2,CONCRETE:7,60,quark:iron_plate:1,20,STAINED_CLAY:12,15,STAINED_CLAY:15,5,AIR,7,IRON_BARS,12,CONCRETE:7,100)
RandomBlock(-8,11,-1,CONCRETE:7,60,quark:iron_plate:1,20,STAINED_CLAY:12,15,STAINED_CLAY:15,5,AIR,7,IRON_BARS,12,CONCRETE:7,100)
RandomBlock(-8,11,0,CONCRETE:7,60,quark:iron_plate:1,20,STAINED_CLAY:12,15,STAINED_CLAY:15,5,AIR,7,IRON_BARS,12,CONCRETE:7,100)
RandomBlock(-8,11,1,CONCRETE:7,60,quark:iron_plate:1,20,STAINED_CLAY:12,15,STAINED_CLAY:15,5,AIR,7,IRON_BARS,12,CONCRETE:7,100)
RandomBlock(-8,11,2,CONCRETE:7,60,quark:iron_plate:1,20,STAINED_CLAY:12,15,STAINED_CLAY:15,5,AIR,7,IRON_BARS,12,CONCRETE:7,100)
RandomBlock(-8,11,3,CONCRETE:7,60,quark:iron_plate:1,20,STAINED_CLAY:12,15,STAINED_CLAY:15,5,AIR,7,IRON_BARS,12,CONCRETE:7,100)
RandomBlock(-8,11,4,CONCRETE:7,60,quark:iron_plate:1,20,STAINED_CLAY:12,15,STAINED_CLAY:15,5,AIR,7,IRON_BARS,12,CONCRETE:7,100)
RandomBlock(-8,11,5,CONCRETE:7,60,quark:iron_plate:1,20,STAINED_CLAY:12,15,STAINED_CLAY:15,5,AIR,7,IRON_BARS,12,CONCRETE:7,100)
RandomBlock(-8,11,6,CONCRETE:7,60,quark:iron_plate:1,20,STAINED_CLAY:12,15,STAINED_CLAY:15,5,AIR,7,IRON_BARS,12,CONCRETE:7,100)
RandomBlock(-8,11,7,CONCRETE:7,60,quark:iron_plate:1,20,STAINED_CLAY:12,15,STAINED_CLAY:15,5,AIR,7,IRON_BARS,12,CONCRETE:7,100)
RandomBlock(-8,11,8,CONCRETE:7,60,quark:iron_plate:1,20,STAINED_CLAY:12,15,STAINED_CLAY:15,5,AIR,7,IRON_BARS,12,CONCRETE:7,100)
RandomBlock(-8,12,-7,CONCRETE:7,60,quark:iron_plate:1,20,STAINED_CLAY:12,15,STAINED_CLAY:15,5,AIR,7,IRON_BARS,12,CONCRETE:7,100)
#Block(-8,12,-6,DARK_OAK_FENCE:0)
Block(-8,12,-6,AIR)
#Block(-8,12,-5,DARK_OAK_FENCE:0)
Block(-8,12,-5,AIR)
RandomBlock(-8,12,-3,CONCRETE:8,60,minecraft:stone,15,STONE:5,15,STAINED_CLAY:9,10,IRON_BARS,12,AIR,8,STAINED_CLAY:12,30,CONCRETE:8,100)
RandomBlock(-8,12,-2,CONCRETE:8,60,minecraft:stone,15,STONE:5,15,STAINED_CLAY:9,10,IRON_BARS,12,AIR,8,STAINED_CLAY:12,30,CONCRETE:8,100)
RandomBlock(-8,12,-1,CONCRETE:8,60,minecraft:stone,15,STONE:5,15,STAINED_CLAY:9,10,IRON_BARS,12,AIR,8,STAINED_CLAY:12,30,CONCRETE:8,100)
RandomBlock(-8,12,0,STONE:6,85,CAULDRON:3,100)
RandomBlock(-8,12,4,CONCRETE:8,60,minecraft:stone,15,STONE:5,15,STAINED_CLAY:9,10,IRON_BARS,12,AIR,8,STAINED_CLAY:12,30,CONCRETE:8,100)
RandomBlock(-8,12,5,CONCRETE:8,60,minecraft:stone,15,STONE:5,15,STAINED_CLAY:9,10,IRON_BARS,12,AIR,8,STAINED_CLAY:12,30,CONCRETE:8,100)
RandomBlock(-8,12,6,CONCRETE:8,60,minecraft:stone,15,STONE:5,15,STAINED_CLAY:9,10,IRON_BARS,12,AIR,8,STAINED_CLAY:12,30,CONCRETE:8,100)
RandomBlock(-8,12,7,CONCRETE:8,60,minecraft:stone,15,STONE:5,15,STAINED_CLAY:9,10,IRON_BARS,12,AIR,8,STAINED_CLAY:12,30,CONCRETE:8,100)
RandomBlock(-8,12,8,CONCRETE:8,60,minecraft:stone,15,STONE:5,15,STAINED_CLAY:9,10,IRON_BARS,12,AIR,8,STAINED_CLAY:12,30,CONCRETE:8,100)
RandomBlock(-8,13,-7,CONCRETE:7,60,quark:iron_plate:1,20,STAINED_CLAY:12,15,STAINED_CLAY:15,5,AIR,7,IRON_BARS,12,CONCRETE:7,100)
#Block(-8,13,-6,CARPET:7)
Block(-8,13,-6,AIR)
#Block(-8,13,-5,CARPET:7)
Block(-8,13,-5,AIR)
RandomBlock(-8,13,-3,CONCRETE:8,60,minecraft:stone,15,STONE:5,15,STAINED_CLAY:9,10,IRON_BARS,12,AIR,8,STAINED_CLAY:12,30,CONCRETE:8,100)
RandomBlock(-8,13,-2,CONCRETE:8,60,minecraft:stone,15,STONE:5,15,STAINED_CLAY:9,10,IRON_BARS,12,AIR,8,STAINED_CLAY:12,30,CONCRETE:8,100)
RandomBlock(-8,13,-1,CONCRETE:8,60,minecraft:stone,15,STONE:5,15,STAINED_CLAY:9,10,IRON_BARS,12,AIR,8,STAINED_CLAY:12,30,CONCRETE:8,100)
Block(-8,13,0,TRIPWIRE_HOOK:0)
RandomBlock(-8,13,4,CONCRETE:8,60,minecraft:stone,15,STONE:5,15,STAINED_CLAY:9,10,IRON_BARS,12,AIR,8,STAINED_CLAY:12,30,CONCRETE:8,100)
RandomBlock(-8,13,5,CONCRETE:8,60,minecraft:stone,15,STONE:5,15,STAINED_CLAY:9,10,IRON_BARS,12,AIR,8,STAINED_CLAY:12,30,CONCRETE:8,100)
RandomBlock(-8,13,6,CONCRETE:8,60,minecraft:stone,15,STONE:5,15,STAINED_CLAY:9,10,IRON_BARS,12,AIR,8,STAINED_CLAY:12,30,CONCRETE:8,100)
RandomBlock(-8,13,7,CONCRETE:8,60,minecraft:stone,15,STONE:5,15,STAINED_CLAY:9,10,IRON_BARS,12,AIR,8,STAINED_CLAY:12,30,CONCRETE:8,100)
RandomBlock(-8,13,8,CONCRETE:8,60,minecraft:stone,15,STONE:5,15,STAINED_CLAY:9,10,IRON_BARS,12,AIR,8,STAINED_CLAY:12,30,CONCRETE:8,100)
RandomBlock(-8,14,-7,CONCRETE:7,60,quark:iron_plate:1,20,STAINED_CLAY:12,15,STAINED_CLAY:15,5,AIR,7,IRON_BARS,12,CONCRETE:7,100)
RandomBlock(-8,14,-3,CONCRETE:8,60,minecraft:stone,15,STONE:5,15,STAINED_CLAY:9,10,IRON_BARS,12,AIR,8,STAINED_CLAY:12,30,CONCRETE:8,100)
RandomBlock(-8,14,-2,CONCRETE:8,60,minecraft:stone,15,STONE:5,15,STAINED_CLAY:9,10,IRON_BARS,12,AIR,8,STAINED_CLAY:12,30,CONCRETE:8,100)
RandomBlock(-8,14,-1,CONCRETE:8,60,minecraft:stone,15,STONE:5,15,STAINED_CLAY:9,10,IRON_BARS,12,AIR,8,STAINED_CLAY:12,30,CONCRETE:8,100)
RandomBlock(-8,14,4,CONCRETE:8,60,minecraft:stone,15,STONE:5,15,STAINED_CLAY:9,10,IRON_BARS,12,AIR,8,STAINED_CLAY:12,30,CONCRETE:8,100)
RandomBlock(-8,14,5,CONCRETE:8,60,minecraft:stone,15,STONE:5,15,STAINED_CLAY:9,10,IRON_BARS,12,AIR,8,STAINED_CLAY:12,30,CONCRETE:8,100)
RandomBlock(-8,14,6,CONCRETE:8,60,minecraft:stone,15,STONE:5,15,STAINED_CLAY:9,10,IRON_BARS,12,AIR,8,STAINED_CLAY:12,30,CONCRETE:8,100)
RandomBlock(-8,14,7,CONCRETE:8,60,minecraft:stone,15,STONE:5,15,STAINED_CLAY:9,10,IRON_BARS,12,AIR,8,STAINED_CLAY:12,30,CONCRETE:8,100)
RandomBlock(-8,14,8,CONCRETE:8,60,minecraft:stone,15,STONE:5,15,STAINED_CLAY:9,10,IRON_BARS,12,AIR,8,STAINED_CLAY:12,30,CONCRETE:8,100)
RandomBlock(-8,15,-7,CONCRETE:7,60,quark:iron_plate:1,20,STAINED_CLAY:12,15,STAINED_CLAY:15,5,AIR,7,IRON_BARS,12,CONCRETE:7,100)
RandomBlock(-8,15,-3,CONCRETE:8,60,minecraft:stone,15,STONE:5,15,STAINED_CLAY:9,10,IRON_BARS,12,AIR,8,STAINED_CLAY:12,30,CONCRETE:8,100)
RandomBlock(-8,15,-2,CONCRETE:8,60,minecraft:stone,15,STONE:5,15,STAINED_CLAY:9,10,IRON_BARS,12,AIR,8,STAINED_CLAY:12,30,CONCRETE:8,100)
RandomBlock(-8,15,-1,CONCRETE:8,60,minecraft:stone,15,STONE:5,15,STAINED_CLAY:9,10,IRON_BARS,12,AIR,8,STAINED_CLAY:12,30,CONCRETE:8,100)
RandomBlock(-8,15,0,AIR,90,IRON_TRAPDOOR:9,100)
RandomBlock(-8,15,4,CONCRETE:8,60,minecraft:stone,15,STONE:5,15,STAINED_CLAY:9,10,IRON_BARS,12,AIR,8,STAINED_CLAY:12,30,CONCRETE:8,100)
RandomBlock(-8,15,5,CONCRETE:8,60,minecraft:stone,15,STONE:5,15,STAINED_CLAY:9,10,IRON_BARS,12,AIR,8,STAINED_CLAY:12,30,CONCRETE:8,100)
RandomBlock(-8,15,6,CONCRETE:8,60,minecraft:stone,15,STONE:5,15,STAINED_CLAY:9,10,IRON_BARS,12,AIR,8,STAINED_CLAY:12,30,CONCRETE:8,100)
RandomBlock(-8,15,7,CONCRETE:8,60,minecraft:stone,15,STONE:5,15,STAINED_CLAY:9,10,IRON_BARS,12,AIR,8,STAINED_CLAY:12,30,CONCRETE:8,100)
RandomBlock(-8,15,8,CONCRETE:8,60,minecraft:stone,15,STONE:5,15,STAINED_CLAY:9,10,IRON_BARS,12,AIR,8,STAINED_CLAY:12,30,CONCRETE:8,100)
RandomBlock(-8,16,-7,CONCRETE:7,60,quark:iron_plate:1,20,STAINED_CLAY:12,15,STAINED_CLAY:15,5,AIR,7,IRON_BARS,12,CONCRETE:7,100)
RandomBlock(-8,16,-6,CONCRETE:7,60,quark:iron_plate:1,20,STAINED_CLAY:12,15,STAINED_CLAY:15,5,AIR,7,IRON_BARS,12,CONCRETE:7,100)
RandomBlock(-8,16,-5,CONCRETE:7,60,quark:iron_plate:1,20,STAINED_CLAY:12,15,STAINED_CLAY:15,5,AIR,7,IRON_BARS,12,CONCRETE:7,100)
RandomBlock(-8,16,-4,CONCRETE:7,60,quark:iron_plate:1,20,STAINED_CLAY:12,15,STAINED_CLAY:15,5,AIR,7,IRON_BARS,12,CONCRETE:7,100)
RandomBlock(-8,16,-3,CONCRETE:8,60,minecraft:stone,15,STONE:5,15,STAINED_CLAY:9,10,IRON_BARS,12,AIR,8,STAINED_CLAY:12,30,CONCRETE:8,100)
RandomBlock(-8,16,-2,CONCRETE:8,60,minecraft:stone,15,STONE:5,15,STAINED_CLAY:9,10,IRON_BARS,12,AIR,8,STAINED_CLAY:12,30,CONCRETE:8,100)
RandomBlock(-8,16,-1,CONCRETE:8,60,minecraft:stone,15,STONE:5,15,STAINED_CLAY:9,10,IRON_BARS,12,AIR,8,STAINED_CLAY:12,30,CONCRETE:8,100)
RandomBlock(-8,16,0,CONCRETE:7,60,quark:iron_plate:1,20,STAINED_CLAY:12,15,STAINED_CLAY:15,5,AIR,7,IRON_BARS,12,CONCRETE:7,100)
RandomBlock(-8,16,1,CONCRETE:7,60,quark:iron_plate:1,20,STAINED_CLAY:12,15,STAINED_CLAY:15,5,AIR,7,IRON_BARS,12,CONCRETE:7,100)
RandomBlock(-8,16,2,CONCRETE:7,60,quark:iron_plate:1,20,STAINED_CLAY:12,15,STAINED_CLAY:15,5,AIR,7,IRON_BARS,12,CONCRETE:7,100)
RandomBlock(-8,16,3,CONCRETE:7,60,quark:iron_plate:1,20,STAINED_CLAY:12,15,STAINED_CLAY:15,5,AIR,7,IRON_BARS,12,CONCRETE:7,100)
RandomBlock(-8,16,4,CONCRETE:7,60,quark:iron_plate:1,20,STAINED_CLAY:12,15,STAINED_CLAY:15,5,AIR,7,IRON_BARS,12,CONCRETE:7,100)
RandomBlock(-8,16,5,CONCRETE:7,60,quark:iron_plate:1,20,STAINED_CLAY:12,15,STAINED_CLAY:15,5,AIR,7,IRON_BARS,12,CONCRETE:7,100)
RandomBlock(-8,16,6,CONCRETE:7,60,quark:iron_plate:1,20,STAINED_CLAY:12,15,STAINED_CLAY:15,5,AIR,7,IRON_BARS,12,CONCRETE:7,100)
RandomBlock(-8,16,7,CONCRETE:7,60,quark:iron_plate:1,20,STAINED_CLAY:12,15,STAINED_CLAY:15,5,AIR,7,IRON_BARS,12,CONCRETE:7,100)
RandomBlock(-8,16,8,CONCRETE:7,60,quark:iron_plate:1,20,STAINED_CLAY:12,15,STAINED_CLAY:15,5,AIR,7,IRON_BARS,12,CONCRETE:7,100)
RandomBlock(-8,17,-7,CONCRETE:7,60,quark:iron_plate:1,20,STAINED_CLAY:12,15,STAINED_CLAY:15,5,AIR,7,IRON_BARS,12,CONCRETE:7,100)
RandomBlock(-8,17,-6,CONCRETE:7,60,quark:iron_plate:1,20,STAINED_CLAY:12,15,STAINED_CLAY:15,5,AIR,7,IRON_BARS,12,CONCRETE:7,100)
RandomBlock(-8,17,-5,CONCRETE:7,60,quark:iron_plate:1,20,STAINED_CLAY:12,15,STAINED_CLAY:15,5,AIR,7,IRON_BARS,12,CONCRETE:7,100)
RandomBlock(-8,17,-4,CONCRETE:7,60,quark:iron_plate:1,20,STAINED_CLAY:12,15,STAINED_CLAY:15,5,AIR,7,IRON_BARS,12,CONCRETE:7,100)
RandomBlock(-8,17,-3,CONCRETE:7,60,quark:iron_plate:1,20,STAINED_CLAY:12,15,STAINED_CLAY:15,5,AIR,7,IRON_BARS,12,CONCRETE:7,100)
#Block(-8,17,-2,DARK_OAK_STAIRS:0)
Block(-8,17,-2,AIR)
#Block(-8,17,-1,DARK_OAK_STAIRS:0)
Block(-8,17,-1,AIR)
RandomBlock(-8,17,0,CONCRETE:7,60,quark:iron_plate:1,20,STAINED_CLAY:12,15,STAINED_CLAY:15,5,AIR,7,IRON_BARS,12,CONCRETE:7,100)
RandomBlock(-8,17,1,CONCRETE:7,60,quark:iron_plate:1,20,STAINED_CLAY:12,15,STAINED_CLAY:15,5,AIR,7,IRON_BARS,12,CONCRETE:7,100)
RandomBlock(-8,17,2,CONCRETE:8,60,minecraft:stone,15,STONE:5,15,STAINED_CLAY:9,10,IRON_BARS,12,AIR,8,STAINED_CLAY:12,30,CONCRETE:8,100)
RandomBlock(-8,17,3,CONCRETE:7,60,quark:iron_plate:1,20,STAINED_CLAY:12,15,STAINED_CLAY:15,5,AIR,7,IRON_BARS,12,CONCRETE:7,100)
RandomBlock(-8,17,4,CONCRETE:7,60,quark:iron_plate:1,20,STAINED_CLAY:12,15,STAINED_CLAY:15,5,AIR,7,IRON_BARS,12,CONCRETE:7,100)
RandomBlock(-8,17,5,CONCRETE:7,60,quark:iron_plate:1,20,STAINED_CLAY:12,15,STAINED_CLAY:15,5,AIR,7,IRON_BARS,12,CONCRETE:7,100)
RandomBlock(-8,17,6,CONCRETE:7,60,quark:iron_plate:1,20,STAINED_CLAY:12,15,STAINED_CLAY:15,5,AIR,7,IRON_BARS,12,CONCRETE:7,100)
RandomBlock(-8,17,7,CONCRETE:7,60,quark:iron_plate:1,20,STAINED_CLAY:12,15,STAINED_CLAY:15,5,AIR,7,IRON_BARS,12,CONCRETE:7,100)
RandomBlock(-8,17,8,CONCRETE:7,60,quark:iron_plate:1,20,STAINED_CLAY:12,15,STAINED_CLAY:15,5,AIR,7,IRON_BARS,12,CONCRETE:7,100)
RandomBlock(-8,18,-4,CONCRETE:8,60,minecraft:stone,15,STONE:5,15,STAINED_CLAY:9,10,IRON_BARS,12,AIR,8,STAINED_CLAY:12,30,CONCRETE:8,100)
RandomBlock(-8,18,-3,CONCRETE:7,60,quark:iron_plate:1,20,STAINED_CLAY:12,15,STAINED_CLAY:15,5,AIR,7,IRON_BARS,12,CONCRETE:7,100)
RandomBlock(-8,18,0,STAINED_GLASS_PANE:15,40,AIR,100)
#RandomBlock(-8,18,4,AIR,90,WALL_SIGN:2,../AllScraperData/skyscraper_2x2_03/312-signC16R0.nbt,100)
#Block(-8,18,5,DARK_OAK_STAIRS:0)
Block(-8,18,5,AIR)
#RandomBlock(-8,18,6,AIR,90,WALL_SIGN:3,../AllScraperData/skyscraper_2x2_03/313-signC16R0.nbt,100)
#Block(-8,18,7,DARK_OAK_STAIRS:0)
Block(-8,18,7,AIR)
#Block(-8,18,8,DARK_OAK_STAIRS:0)
Block(-8,18,8,AIR)
RandomBlock(-8,19,-4,CONCRETE:8,60,minecraft:stone,15,STONE:5,15,STAINED_CLAY:9,10,IRON_BARS,12,AIR,8,STAINED_CLAY:12,30,CONCRETE:8,100)
RandomBlock(-8,19,-3,CONCRETE:7,60,quark:iron_plate:1,20,STAINED_CLAY:12,15,STAINED_CLAY:15,5,AIR,7,IRON_BARS,12,CONCRETE:7,100)
RandomBlock(-8,19,0,STAINED_GLASS_PANE:15,40,AIR,100)
#RandomBlock(-8,19,5,AIR,90,TRAP_DOOR:6,100)
RandomBlock(-8,20,-4,CONCRETE:8,60,minecraft:stone,15,STONE:5,15,STAINED_CLAY:9,10,IRON_BARS,12,AIR,8,STAINED_CLAY:12,30,CONCRETE:8,100)
RandomBlock(-8,20,-3,CONCRETE:7,60,quark:iron_plate:1,20,STAINED_CLAY:12,15,STAINED_CLAY:15,5,AIR,7,IRON_BARS,12,CONCRETE:7,100)
#Block(-8,23,-2,DARK_OAK_FENCE:0)
#Block(-8,23,4,DARK_OAK_FENCE:0)
#Block(-8,24,-2,CARPET:8)
#Block(-8,24,4,CARPET:8)
#RandomBlock(-8,33,-2,AIR,95,WALL_BANNER:4,../AllScraperData/skyscraper_2x2_03/314-bannerC16R0.nbt,100)
#RandomBlock(-8,33,-1,AIR,95,WALL_BANNER:4,../AllScraperData/skyscraper_2x2_03/315-bannerC16R0.nbt,100)
#Block(-8,38,5,DARK_OAK_STAIRS:3)
#Block(-8,38,6,DARK_OAK_STAIRS:1)
#Block(-8,38,7,DARK_OAK_STAIRS:2)
#RandomBlock(-8,39,5,AIR,90,TRAP_DOOR:5,100)
#RandomBlock(-8,39,7,AIR,90,TRAP_DOOR:4,100)
#Block(-8,67,-2,CARPET:15)
#Block(-8,67,-1,CARPET:15)
RandomBlock(-8,21,-3,CONCRETE:7,60,quark:iron_plate:1,20,STAINED_CLAY:12,15,STAINED_CLAY:15,5,AIR,7,IRON_BARS,12,CONCRETE:7,100)
RandomBlock(-8,21,-2,CONCRETE:7,60,quark:iron_plate:1,20,STAINED_CLAY:12,15,STAINED_CLAY:15,5,AIR,7,IRON_BARS,12,CONCRETE:7,100)
RandomBlock(-8,21,-1,CONCRETE:7,60,quark:iron_plate:1,20,STAINED_CLAY:12,15,STAINED_CLAY:15,5,AIR,7,IRON_BARS,12,CONCRETE:7,100)
RandomBlock(-8,21,0,CONCRETE:7,60,quark:iron_plate:1,20,STAINED_CLAY:12,15,STAINED_CLAY:15,5,AIR,7,IRON_BARS,12,CONCRETE:7,100)
RandomBlock(-8,21,1,CONCRETE:7,60,quark:iron_plate:1,20,STAINED_CLAY:12,15,STAINED_CLAY:15,5,AIR,7,IRON_BARS,12,CONCRETE:7,100)
RandomBlock(-8,21,2,CONCRETE:7,60,quark:iron_plate:1,20,STAINED_CLAY:12,15,STAINED_CLAY:15,5,AIR,7,IRON_BARS,12,CONCRETE:7,100)
RandomBlock(-8,21,3,CONCRETE:7,60,quark:iron_plate:1,20,STAINED_CLAY:12,15,STAINED_CLAY:15,5,AIR,7,IRON_BARS,12,CONCRETE:7,100)
RandomBlock(-8,21,4,CONCRETE:7,60,quark:iron_plate:1,20,STAINED_CLAY:12,15,STAINED_CLAY:15,5,AIR,7,IRON_BARS,12,CONCRETE:7,100)
RandomBlock(-8,21,5,CONCRETE:7,60,quark:iron_plate:1,20,STAINED_CLAY:12,15,STAINED_CLAY:15,5,AIR,7,IRON_BARS,12,CONCRETE:7,100)
RandomBlock(-8,21,6,CONCRETE:7,60,quark:iron_plate:1,20,STAINED_CLAY:12,15,STAINED_CLAY:15,5,AIR,7,IRON_BARS,12,CONCRETE:7,100)
RandomBlock(-8,21,7,CONCRETE:7,60,quark:iron_plate:1,20,STAINED_CLAY:12,15,STAINED_CLAY:15,5,AIR,7,IRON_BARS,12,CONCRETE:7,100)
RandomBlock(-8,21,8,CONCRETE:7,60,quark:iron_plate:1,20,STAINED_CLAY:12,15,STAINED_CLAY:15,5,AIR,7,IRON_BARS,12,CONCRETE:7,100)
RandomBlock(-8,22,-3,CONCRETE:7,60,quark:iron_plate:1,20,STAINED_CLAY:12,15,STAINED_CLAY:15,5,AIR,7,IRON_BARS,12,CONCRETE:7,100)
#Block(-8,78,-1,CARPET:0)
Block(-8,22,-1,AIR)
#Block(-8,78,0,CARPET:0)
Block(-8,22,0,AIR)
#Block(-8,78,1,CARPET:0)
Block(-8,22,1,AIR)
#Block(-8,78,2,CARPET:0)
Block(-8,22,2,AIR)
#Block(-8,78,3,CARPET:0)
Block(-8,22,3,AIR)
#Block(-8,78,4,CARPET:0)
Block(-8,22,4,AIR)
#Block(-8,78,5,CARPET:0)
Block(-8,22,5,AIR)
#Block(-8,78,6,CARPET:0)
Block(-8,22,6,AIR)
#Block(-8,78,7,CARPET:0)
Block(-8,22,7,AIR)
#Block(-8,78,8,CARPET:0)
Block(-8,22,8,AIR)
RandomBlock(-8,23,-3,CONCRETE:7,60,quark:iron_plate:1,20,STAINED_CLAY:12,15,STAINED_CLAY:15,5,AIR,7,IRON_BARS,12,CONCRETE:7,100)
RandomBlock(-8,24,-3,CONCRETE:7,60,quark:iron_plate:1,20,STAINED_CLAY:12,15,STAINED_CLAY:15,5,AIR,7,IRON_BARS,12,CONCRETE:7,100)
RandomBlock(-8,25,-3,CONCRETE:7,60,quark:iron_plate:1,20,STAINED_CLAY:12,15,STAINED_CLAY:15,5,AIR,7,IRON_BARS,12,CONCRETE:7,100)
#RandomBlock(-8,81,0,AIR,90,TRAP_DOOR:6,100)
#RandomBlock(-8,81,4,AIR,90,TRAP_DOOR:6,100)
RandomBlock(-8,26,-3,CONCRETE:7,60,quark:iron_plate:1,20,STAINED_CLAY:12,15,STAINED_CLAY:15,5,AIR,7,IRON_BARS,12,CONCRETE:7,100)
#RandomBlock(-8,82,8,AIR,90,TRAP_DOOR:6,100)
RandomBlock(-8,27,-3,CONCRETE:7,60,quark:iron_plate:1,20,STAINED_CLAY:12,15,STAINED_CLAY:15,5,AIR,7,IRON_BARS,12,CONCRETE:7,100)
RandomBlock(-8,28,-3,CONCRETE:7,60,quark:iron_plate:1,20,STAINED_CLAY:12,15,STAINED_CLAY:15,5,AIR,7,IRON_BARS,12,CONCRETE:7,100)
RandomBlock(-8,29,-3,CONCRETE:7,60,quark:iron_plate:1,20,STAINED_CLAY:12,15,STAINED_CLAY:15,5,AIR,7,IRON_BARS,12,CONCRETE:7,100)
RandomBlock(-8,30,-3,CONCRETE:7,60,quark:iron_plate:1,20,STAINED_CLAY:12,15,STAINED_CLAY:15,5,AIR,7,IRON_BARS,12,CONCRETE:7,100)
RandomBlock(-8,31,-3,CONCRETE:7,60,quark:iron_plate:1,20,STAINED_CLAY:12,15,STAINED_CLAY:15,5,AIR,7,IRON_BARS,12,CONCRETE:7,100)
RandomBlock(-8,32,-3,CONCRETE:7,60,quark:iron_plate:1,20,STAINED_CLAY:12,15,STAINED_CLAY:15,5,AIR,7,IRON_BARS,12,CONCRETE:7,100)
RandomBlock(-8,33,-3,CONCRETE:7,60,quark:iron_plate:1,20,STAINED_CLAY:12,15,STAINED_CLAY:15,5,AIR,7,IRON_BARS,12,CONCRETE:7,100)
#RandomBlock(-8,89,0,AIR,90,TRAP_DOOR:14,100)
#RandomBlock(-8,89,4,AIR,90,TRAP_DOOR:14,100)
#RandomBlock(-8,89,8,AIR,90,TRAP_DOOR:14,100)
RandomBlock(-8,34,-3,CONCRETE:7,60,quark:iron_plate:1,20,STAINED_CLAY:12,15,STAINED_CLAY:15,5,AIR,7,IRON_BARS,12,CONCRETE:7,100)
RandomBlock(-8,35,-3,CONCRETE:7,60,quark:iron_plate:1,20,STAINED_CLAY:12,15,STAINED_CLAY:15,5,AIR,7,IRON_BARS,12,CONCRETE:7,100)
RandomBlock(-8,36,-3,CONCRETE:7,60,quark:iron_plate:1,20,STAINED_CLAY:12,15,STAINED_CLAY:15,5,AIR,7,IRON_BARS,12,CONCRETE:7,100)
RandomBlock(-8,37,-3,CONCRETE:7,60,quark:iron_plate:1,20,STAINED_CLAY:12,15,STAINED_CLAY:15,5,AIR,7,IRON_BARS,12,CONCRETE:7,100)
RandomBlock(-8,38,-3,CONCRETE:7,60,quark:iron_plate:1,20,STAINED_CLAY:12,15,STAINED_CLAY:15,5,AIR,7,IRON_BARS,12,CONCRETE:7,100)
RandomBlock(-8,38,-2,CONCRETE:7,60,quark:iron_plate:1,20,STAINED_CLAY:12,15,STAINED_CLAY:15,5,AIR,7,IRON_BARS,12,CONCRETE:7,100)
RandomBlock(-8,38,-1,CONCRETE:7,60,quark:iron_plate:1,20,STAINED_CLAY:12,15,STAINED_CLAY:15,5,AIR,7,IRON_BARS,12,CONCRETE:7,100)
RandomBlock(-8,38,0,CONCRETE:7,60,quark:iron_plate:1,20,STAINED_CLAY:12,15,STAINED_CLAY:15,5,AIR,7,IRON_BARS,12,CONCRETE:7,100)
RandomBlock(-8,38,1,CONCRETE:7,60,quark:iron_plate:1,20,STAINED_CLAY:12,15,STAINED_CLAY:15,5,AIR,7,IRON_BARS,12,CONCRETE:7,100)
RandomBlock(-8,38,2,CONCRETE:7,60,quark:iron_plate:1,20,STAINED_CLAY:12,15,STAINED_CLAY:15,5,AIR,7,IRON_BARS,12,CONCRETE:7,100)
RandomBlock(-8,38,3,CONCRETE:7,60,quark:iron_plate:1,20,STAINED_CLAY:12,15,STAINED_CLAY:15,5,AIR,7,IRON_BARS,12,CONCRETE:7,100)
RandomBlock(-8,38,4,CONCRETE:7,60,quark:iron_plate:1,20,STAINED_CLAY:12,15,STAINED_CLAY:15,5,AIR,7,IRON_BARS,12,CONCRETE:7,100)
RandomBlock(-8,38,5,CONCRETE:7,60,quark:iron_plate:1,20,STAINED_CLAY:12,15,STAINED_CLAY:15,5,AIR,7,IRON_BARS,12,CONCRETE:7,100)
RandomBlock(-8,38,6,CONCRETE:7,60,quark:iron_plate:1,20,STAINED_CLAY:12,15,STAINED_CLAY:15,5,AIR,7,IRON_BARS,12,CONCRETE:7,100)
RandomBlock(-8,38,7,CONCRETE:7,60,quark:iron_plate:1,20,STAINED_CLAY:12,15,STAINED_CLAY:15,5,AIR,7,IRON_BARS,12,CONCRETE:7,100)
RandomBlock(-8,38,8,CONCRETE:7,60,quark:iron_plate:1,20,STAINED_CLAY:12,15,STAINED_CLAY:15,5,AIR,7,IRON_BARS,12,CONCRETE:7,100)
RandomBlock(-8,39,-3,CONCRETE:7,60,quark:iron_plate:1,20,STAINED_CLAY:12,15,STAINED_CLAY:15,5,AIR,7,IRON_BARS,12,CONCRETE:7,100)
Block(-8,39,-2,QUARTZ_BLOCK:1)
#RandomBlock(-8,95,-1,AIR,90,WALL_SIGN:2,../AllScraperData/skyscraper_2x2_03/327-signC16R0.nbt,100)
#Block(-8,95,0,DARK_OAK_STAIRS:0)
Block(-8,39,0,AIR)
#RandomBlock(-8,95,1,AIR,90,WALL_SIGN:3,../AllScraperData/skyscraper_2x2_03/328-signC16R0.nbt,100)
#Block(-8,95,4,DARK_OAK_STAIRS:2)
Block(-8,39,4,AIR)
#Block(-8,95,5,BOOKSHELF:0)
Block(-8,39,5,AIR)
RandomBlock(-8,39,6,CONCRETE:7,60,quark:iron_plate:1,20,STAINED_CLAY:12,15,STAINED_CLAY:15,5,AIR,7,IRON_BARS,12,CONCRETE:7,100)
RandomBlock(-8,39,7,CONCRETE:7,60,quark:iron_plate:1,20,STAINED_CLAY:12,15,STAINED_CLAY:15,5,AIR,7,IRON_BARS,12,CONCRETE:7,100)
RandomBlock(-8,39,8,CONCRETE:7,60,quark:iron_plate:1,20,STAINED_CLAY:12,15,STAINED_CLAY:15,5,AIR,7,IRON_BARS,12,CONCRETE:7,100)
RandomBlock(-8,40,-3,CONCRETE:7,60,quark:iron_plate:1,20,STAINED_CLAY:12,15,STAINED_CLAY:15,5,AIR,7,IRON_BARS,12,CONCRETE:7,100)
RandomBlock(-8,40,-2,AIR,75,AIR:0,100)
#RandomBlock(-8,96,0,AIR,95,WALL_BANNER:4,../AllScraperData/skyscraper_2x2_03/330-bannerC16R0.nbt,100)
#Block(-8,96,5,BOOKSHELF:0)
Block(-8,40,5,AIR)
#Block(-8,96,6,DARK_OAK_STAIRS:1)
Block(-8,40,6,AIR)
RandomBlock(-8,40,7,CONCRETE:7,60,quark:iron_plate:1,20,STAINED_CLAY:12,15,STAINED_CLAY:15,5,AIR,7,IRON_BARS,12,CONCRETE:7,100)
Block(-8,40,8,STATIONARY_LAVA:0)
RandomBlock(-8,41,-3,CONCRETE:7,60,quark:iron_plate:1,20,STAINED_CLAY:12,15,STAINED_CLAY:15,5,AIR,7,IRON_BARS,12,CONCRETE:7,100)
Block(-8,41,-2,LEAVES:4)
#Block(-8,97,5,BOOKSHELF:0)
Block(-8,41,5,AIR)
RandomBlock(-8,41,7,CONCRETE:7,60,quark:iron_plate:1,20,STAINED_CLAY:12,15,STAINED_CLAY:15,5,AIR,7,IRON_BARS,12,CONCRETE:7,100)
RandomBlock(-8,42,-3,CONCRETE:7,60,quark:iron_plate:1,20,STAINED_CLAY:12,15,STAINED_CLAY:15,5,AIR,7,IRON_BARS,12,CONCRETE:7,100)
Block(-8,42,-2,LEAVES:4)
#RandomBlock(-8,98,3,AIR,90,TRAP_DOOR:4,100)
#RandomBlock(-8,98,4,AIR,90,TRAP_DOOR:0,100)
#Block(-8,98,5,BOOKSHELF:0)
Block(-8,42,5,AIR)
RandomBlock(-8,42,7,CONCRETE:7,60,quark:iron_plate:1,20,STAINED_CLAY:12,15,STAINED_CLAY:15,5,AIR,7,IRON_BARS,12,CONCRETE:7,100)
RandomBlock(-8,42,8,CONCRETE:7,60,quark:iron_plate:1,20,STAINED_CLAY:12,15,STAINED_CLAY:15,5,AIR,7,IRON_BARS,12,CONCRETE:7,100)
RandomBlock(-8,43,-3,CONCRETE:7,60,quark:iron_plate:1,20,STAINED_CLAY:12,15,STAINED_CLAY:15,5,AIR,7,IRON_BARS,12,CONCRETE:7,100)
#Block(-8,99,5,BOOKSHELF:0)
Block(-8,43,5,AIR)
RandomBlock(-8,43,7,CONCRETE:7,60,quark:iron_plate:1,20,STAINED_CLAY:12,15,STAINED_CLAY:15,5,AIR,7,IRON_BARS,12,CONCRETE:7,100)
RandomBlock(-8,43,8,CONCRETE:7,60,quark:iron_plate:1,20,STAINED_CLAY:12,15,STAINED_CLAY:15,5,AIR,7,IRON_BARS,12,CONCRETE:7,100)
RandomBlock(-8,44,-3,CONCRETE:7,60,quark:iron_plate:1,20,STAINED_CLAY:12,15,STAINED_CLAY:15,5,AIR,7,IRON_BARS,12,CONCRETE:7,100)
#Block(-8,100,5,BOOKSHELF:0)
Block(-8,44,5,AIR)
RandomBlock(-8,44,6,CONCRETE:7,60,quark:iron_plate:1,20,STAINED_CLAY:12,15,STAINED_CLAY:15,5,AIR,7,IRON_BARS,12,CONCRETE:7,100)
RandomBlock(-8,44,7,CONCRETE:7,60,quark:iron_plate:1,20,STAINED_CLAY:12,15,STAINED_CLAY:15,5,AIR,7,IRON_BARS,12,CONCRETE:7,100)
Block(-8,44,8,STATIONARY_LAVA:8)
RandomBlock(-8,45,-3,CONCRETE:7,60,quark:iron_plate:1,20,STAINED_CLAY:12,15,STAINED_CLAY:15,5,AIR,7,IRON_BARS,12,CONCRETE:7,100)
RandomBlock(-8,45,5,CONCRETE:7,60,quark:iron_plate:1,20,STAINED_CLAY:12,15,STAINED_CLAY:15,5,AIR,7,IRON_BARS,12,CONCRETE:7,100)
RandomBlock(-8,45,6,CONCRETE:7,60,quark:iron_plate:1,20,STAINED_CLAY:12,15,STAINED_CLAY:15,5,AIR,7,IRON_BARS,12,CONCRETE:7,100)
RandomBlock(-8,45,7,CONCRETE:7,60,quark:iron_plate:1,20,STAINED_CLAY:12,15,STAINED_CLAY:15,5,AIR,7,IRON_BARS,12,CONCRETE:7,100)
Block(-8,45,8,STATIONARY_LAVA:8)
RandomBlock(-8,46,-3,CONCRETE:7,60,quark:iron_plate:1,20,STAINED_CLAY:12,15,STAINED_CLAY:15,5,AIR,7,IRON_BARS,12,CONCRETE:7,100)
RandomBlock(-8,46,-2,STAINED_GLASS:15,40,AIR,100)
RandomBlock(-8,46,-1,STAINED_GLASS:15,40,AIR,100)
RandomBlock(-8,46,0,STAINED_GLASS:15,40,AIR,100)
RandomBlock(-8,46,1,STAINED_GLASS:15,40,AIR,100)
RandomBlock(-8,46,2,STAINED_GLASS:15,40,AIR,100)
RandomBlock(-8,46,3,STAINED_GLASS:15,40,AIR,100)
RandomBlock(-8,46,4,STAINED_GLASS:15,40,AIR,100)
RandomBlock(-8,46,5,STAINED_GLASS:15,40,AIR,100)
RandomBlock(-8,46,6,STAINED_GLASS:15,40,AIR,100)
RandomBlock(-8,46,7,CONCRETE:7,60,quark:iron_plate:1,20,STAINED_CLAY:12,15,STAINED_CLAY:15,5,AIR,7,IRON_BARS,12,CONCRETE:7,100)
Block(-8,46,8,STATIONARY_LAVA:8)
RandomBlock(-8,47,-3,CONCRETE:7,60,quark:iron_plate:1,20,STAINED_CLAY:12,15,STAINED_CLAY:15,5,AIR,7,IRON_BARS,12,CONCRETE:7,100)
RandomBlock(-8,47,-2,STONE:6,85,CAULDRON:0,100)
#Block(-8,103,0,DARK_OAK_STAIRS:7)
Block(-8,47,0,AIR)
Block(-8,47,1,COBBLE_WALL:0)
#RandomBlock(-8,103,3,AIR,90,TRAP_DOOR:4,100)
Block(-8,47,4,CONCRETE:15)
Block(-8,47,5,AIR:0)
#RandomBlock(-8,103,6,AIR,90,TRAP_DOOR:5,100)
RandomBlock(-8,47,7,CONCRETE:7,60,quark:iron_plate:1,20,STAINED_CLAY:12,15,STAINED_CLAY:15,5,AIR,7,IRON_BARS,12,CONCRETE:7,100)
Block(-8,47,8,STATIONARY_LAVA:0)
RandomBlock(-8,48,-3,CONCRETE:7,60,quark:iron_plate:1,20,STAINED_CLAY:12,15,STAINED_CLAY:15,5,AIR,7,IRON_BARS,12,CONCRETE:7,100)
Block(-8,48,-2,TRIPWIRE_HOOK:0)
RandomBlock(-8,48,0,AIR,75,AIR:0,100)
#Block(-8,104,4,CARPET:13)
Block(-8,48,4,AIR)
#Block(-8,104,5,CARPET:13)
Block(-8,48,5,AIR)
RandomBlock(-8,48,7,CONCRETE:7,60,quark:iron_plate:1,20,STAINED_CLAY:12,15,STAINED_CLAY:15,5,AIR,7,IRON_BARS,12,CONCRETE:7,100)
RandomBlock(-8,48,8,CONCRETE:7,60,quark:iron_plate:1,20,STAINED_CLAY:12,15,STAINED_CLAY:15,5,AIR,7,IRON_BARS,12,CONCRETE:7,100)
RandomBlock(-8,49,-3,CONCRETE:7,60,quark:iron_plate:1,20,STAINED_CLAY:12,15,STAINED_CLAY:15,5,AIR,7,IRON_BARS,12,CONCRETE:7,100)
RandomBlock(-8,49,-2,CONCRETE:7,60,quark:iron_plate:1,20,STAINED_CLAY:12,15,STAINED_CLAY:15,5,AIR,7,IRON_BARS,12,CONCRETE:7,100)
RandomBlock(-8,49,-1,CONCRETE:7,60,quark:iron_plate:1,20,STAINED_CLAY:12,15,STAINED_CLAY:15,5,AIR,7,IRON_BARS,12,CONCRETE:7,100)
RandomBlock(-8,49,0,STAINED_GLASS_PANE:15,40,AIR,100)
RandomBlock(-8,49,7,CONCRETE:7,60,quark:iron_plate:1,20,STAINED_CLAY:12,15,STAINED_CLAY:15,5,AIR,7,IRON_BARS,12,CONCRETE:7,100)
Block(-8,49,8,STATIONARY_WATER:0)
RandomBlock(-8,50,-3,CONCRETE:7,60,quark:iron_plate:1,20,STAINED_CLAY:12,15,STAINED_CLAY:15,5,AIR,7,IRON_BARS,12,CONCRETE:7,100)
RandomBlock(-8,50,0,STAINED_GLASS_PANE:15,40,AIR,100)
RandomBlock(-8,50,7,STAINED_GLASS_PANE:15,40,AIR,100)
RandomBlock(-8,51,-3,CONCRETE:7,60,quark:iron_plate:1,20,STAINED_CLAY:12,15,STAINED_CLAY:15,5,AIR,7,IRON_BARS,12,CONCRETE:7,100)
RandomBlock(-8,52,-3,CONCRETE:7,60,quark:iron_plate:1,20,STAINED_CLAY:12,15,STAINED_CLAY:15,5,AIR,7,IRON_BARS,12,CONCRETE:7,100)
RandomBlock(-8,52,-2,CONCRETE:7,60,quark:iron_plate:1,20,STAINED_CLAY:12,15,STAINED_CLAY:15,5,AIR,7,IRON_BARS,12,CONCRETE:7,100)
RandomBlock(-8,52,-1,CONCRETE:7,60,quark:iron_plate:1,20,STAINED_CLAY:12,15,STAINED_CLAY:15,5,AIR,7,IRON_BARS,12,CONCRETE:7,100)
RandomBlock(-8,52,0,CONCRETE:7,60,quark:iron_plate:1,20,STAINED_CLAY:12,15,STAINED_CLAY:15,5,AIR,7,IRON_BARS,12,CONCRETE:7,100)
RandomBlock(-8,52,1,CONCRETE:7,60,quark:iron_plate:1,20,STAINED_CLAY:12,15,STAINED_CLAY:15,5,AIR,7,IRON_BARS,12,CONCRETE:7,100)
RandomBlock(-8,52,2,CONCRETE:7,60,quark:iron_plate:1,20,STAINED_CLAY:12,15,STAINED_CLAY:15,5,AIR,7,IRON_BARS,12,CONCRETE:7,100)
RandomBlock(-8,52,3,CONCRETE:7,60,quark:iron_plate:1,20,STAINED_CLAY:12,15,STAINED_CLAY:15,5,AIR,7,IRON_BARS,12,CONCRETE:7,100)
RandomBlock(-8,52,4,STAINED_GLASS:15,40,AIR,100)
RandomBlock(-8,53,-3,CONCRETE:7,60,quark:iron_plate:1,20,STAINED_CLAY:12,15,STAINED_CLAY:15,5,AIR,7,IRON_BARS,12,CONCRETE:7,100)
RandomBlock(-8,53,-2,CONCRETE:7,60,quark:iron_plate:1,20,STAINED_CLAY:12,15,STAINED_CLAY:15,5,AIR,7,IRON_BARS,12,CONCRETE:7,100)
RandomBlock(-8,53,-1,CONCRETE:7,60,quark:iron_plate:1,20,STAINED_CLAY:12,15,STAINED_CLAY:15,5,AIR,7,IRON_BARS,12,CONCRETE:7,100)
RandomBlock(-8,53,0,CONCRETE:7,60,quark:iron_plate:1,20,STAINED_CLAY:12,15,STAINED_CLAY:15,5,AIR,7,IRON_BARS,12,CONCRETE:7,100)
RandomBlock(-8,53,1,CONCRETE:7,60,quark:iron_plate:1,20,STAINED_CLAY:12,15,STAINED_CLAY:15,5,AIR,7,IRON_BARS,12,CONCRETE:7,100)
RandomBlock(-8,53,2,CONCRETE:7,60,quark:iron_plate:1,20,STAINED_CLAY:12,15,STAINED_CLAY:15,5,AIR,7,IRON_BARS,12,CONCRETE:7,100)
RandomBlock(-8,53,3,CONCRETE:7,60,quark:iron_plate:1,20,STAINED_CLAY:12,15,STAINED_CLAY:15,5,AIR,7,IRON_BARS,12,CONCRETE:7,100)
RandomBlock(-8,53,4,STAINED_GLASS:15,40,AIR,100)
RandomBlock(-8,54,4,STAINED_GLASS:15,40,AIR,100)
RandomBlock(-8,55,4,STAINED_GLASS:15,40,AIR,100)
RandomBlock(-8,56,4,STAINED_GLASS:15,40,AIR,100)
RandomBlock(-8,56,5,CONCRETE:7,60,quark:iron_plate:1,20,STAINED_CLAY:12,15,STAINED_CLAY:15,5,AIR,7,IRON_BARS,12,CONCRETE:7,100)
RandomBlock(-8,56,6,STAINED_GLASS:15,40,AIR,100)
RandomBlock(-8,56,7,CONCRETE:7,60,quark:iron_plate:1,20,STAINED_CLAY:12,15,STAINED_CLAY:15,5,AIR,7,IRON_BARS,12,CONCRETE:7,100)
RandomBlock(-8,56,8,STAINED_GLASS:15,40,AIR,100)
RandomBlock(-8,57,5,CONCRETE:7,60,quark:iron_plate:1,20,STAINED_CLAY:12,15,STAINED_CLAY:15,5,AIR,7,IRON_BARS,12,CONCRETE:7,100)
RandomBlock(-8,57,7,CONCRETE:7,60,quark:iron_plate:1,20,STAINED_CLAY:12,15,STAINED_CLAY:15,5,AIR,7,IRON_BARS,12,CONCRETE:7,100)
RandomBlock(-7,0,-7,CONCRETE:7,60,quark:iron_plate:1,20,STAINED_CLAY:12,15,STAINED_CLAY:15,5,AIR,7,IRON_BARS,12,CONCRETE:7,100)
RandomBlock(-7,0,-6,CONCRETE:7,60,quark:iron_plate:1,20,STAINED_CLAY:12,15,STAINED_CLAY:15,5,AIR,7,IRON_BARS,12,CONCRETE:7,100)
RandomBlock(-7,0,-5,CONCRETE:7,60,quark:iron_plate:1,20,STAINED_CLAY:12,15,STAINED_CLAY:15,5,AIR,7,IRON_BARS,12,CONCRETE:7,100)
RandomBlock(-7,0,-4,CONCRETE:7,60,quark:iron_plate:1,20,STAINED_CLAY:12,15,STAINED_CLAY:15,5,AIR,7,IRON_BARS,12,CONCRETE:7,100)
RandomBlock(-7,0,-3,CONCRETE:7,60,quark:iron_plate:1,20,STAINED_CLAY:12,15,STAINED_CLAY:15,5,AIR,7,IRON_BARS,12,CONCRETE:7,100)
RandomBlock(-7,0,-2,CONCRETE:7,60,quark:iron_plate:1,20,STAINED_CLAY:12,15,STAINED_CLAY:15,5,AIR,7,IRON_BARS,12,CONCRETE:7,100)
RandomBlock(-7,0,-1,CONCRETE:7,60,quark:iron_plate:1,20,STAINED_CLAY:12,15,STAINED_CLAY:15,5,AIR,7,IRON_BARS,12,CONCRETE:7,100)
RandomBlock(-7,0,0,CONCRETE:7,60,quark:iron_plate:1,20,STAINED_CLAY:12,15,STAINED_CLAY:15,5,AIR,7,IRON_BARS,12,CONCRETE:7,100)
RandomBlock(-7,0,1,CONCRETE:7,60,quark:iron_plate:1,20,STAINED_CLAY:12,15,STAINED_CLAY:15,5,AIR,7,IRON_BARS,12,CONCRETE:7,100)
RandomBlock(-7,0,2,CONCRETE:7,60,quark:iron_plate:1,20,STAINED_CLAY:12,15,STAINED_CLAY:15,5,AIR,7,IRON_BARS,12,CONCRETE:7,100)
RandomBlock(-7,0,3,CONCRETE:7,60,quark:iron_plate:1,20,STAINED_CLAY:12,15,STAINED_CLAY:15,5,AIR,7,IRON_BARS,12,CONCRETE:7,100)
RandomBlock(-7,0,4,CONCRETE:7,60,quark:iron_plate:1,20,STAINED_CLAY:12,15,STAINED_CLAY:15,5,AIR,7,IRON_BARS,12,CONCRETE:7,100)
RandomBlock(-7,0,5,CONCRETE:7,60,quark:iron_plate:1,20,STAINED_CLAY:12,15,STAINED_CLAY:15,5,AIR,7,IRON_BARS,12,CONCRETE:7,100)
RandomBlock(-7,0,6,CONCRETE:7,60,quark:iron_plate:1,20,STAINED_CLAY:12,15,STAINED_CLAY:15,5,AIR,7,IRON_BARS,12,CONCRETE:7,100)
RandomBlock(-7,0,7,CONCRETE:7,60,quark:iron_plate:1,20,STAINED_CLAY:12,15,STAINED_CLAY:15,5,AIR,7,IRON_BARS,12,CONCRETE:7,100)
RandomBlock(-7,0,8,CONCRETE:7,60,quark:iron_plate:1,20,STAINED_CLAY:12,15,STAINED_CLAY:15,5,AIR,7,IRON_BARS,12,CONCRETE:7,100)
RandomBlock(-7,1,-7,CONCRETE:7,60,quark:iron_plate:1,20,STAINED_CLAY:12,15,STAINED_CLAY:15,5,AIR,7,IRON_BARS,12,CONCRETE:7,100)
RandomBlock(-7,1,-6,CONCRETE:7,60,quark:iron_plate:1,20,STAINED_CLAY:12,15,STAINED_CLAY:15,5,AIR,7,IRON_BARS,12,CONCRETE:7,100)
RandomBlock(-7,1,-5,CONCRETE:7,60,quark:iron_plate:1,20,STAINED_CLAY:12,15,STAINED_CLAY:15,5,AIR,7,IRON_BARS,12,CONCRETE:7,100)
RandomBlock(-7,1,-4,CONCRETE:7,60,quark:iron_plate:1,20,STAINED_CLAY:12,15,STAINED_CLAY:15,5,AIR,7,IRON_BARS,12,CONCRETE:7,100)
RandomBlock(-7,1,-3,CONCRETE:7,60,quark:iron_plate:1,20,STAINED_CLAY:12,15,STAINED_CLAY:15,5,AIR,7,IRON_BARS,12,CONCRETE:7,100)
RandomBlock(-7,1,-2,CONCRETE:7,60,quark:iron_plate:1,20,STAINED_CLAY:12,15,STAINED_CLAY:15,5,AIR,7,IRON_BARS,12,CONCRETE:7,100)
RandomBlock(-7,1,-1,CONCRETE:7,60,quark:iron_plate:1,20,STAINED_CLAY:12,15,STAINED_CLAY:15,5,AIR,7,IRON_BARS,12,CONCRETE:7,100)
RandomBlock(-7,1,0,CONCRETE:7,60,quark:iron_plate:1,20,STAINED_CLAY:12,15,STAINED_CLAY:15,5,AIR,7,IRON_BARS,12,CONCRETE:7,100)
RandomBlock(-7,1,1,CONCRETE:7,60,quark:iron_plate:1,20,STAINED_CLAY:12,15,STAINED_CLAY:15,5,AIR,7,IRON_BARS,12,CONCRETE:7,100)
RandomBlock(-7,1,2,CONCRETE:7,60,quark:iron_plate:1,20,STAINED_CLAY:12,15,STAINED_CLAY:15,5,AIR,7,IRON_BARS,12,CONCRETE:7,100)
Block(-7,1,3,STATIONARY_WATER:0)
Block(-7,1,4,STATIONARY_WATER:0)
RandomBlock(-7,1,5,CONCRETE:7,60,quark:iron_plate:1,20,STAINED_CLAY:12,15,STAINED_CLAY:15,5,AIR,7,IRON_BARS,12,CONCRETE:7,100)
RandomBlock(-7,1,6,CONCRETE:7,60,quark:iron_plate:1,20,STAINED_CLAY:12,15,STAINED_CLAY:15,5,AIR,7,IRON_BARS,12,CONCRETE:7,100)
RandomBlock(-7,1,7,CONCRETE:7,60,quark:iron_plate:1,20,STAINED_CLAY:12,15,STAINED_CLAY:15,5,AIR,7,IRON_BARS,12,CONCRETE:7,100)
RandomBlock(-7,1,8,CONCRETE:7,60,quark:iron_plate:1,20,STAINED_CLAY:12,15,STAINED_CLAY:15,5,AIR,7,IRON_BARS,12,CONCRETE:7,100)
RandomBlock(-7,2,-7,CONCRETE:7,60,quark:iron_plate:1,20,STAINED_CLAY:12,15,STAINED_CLAY:15,5,AIR,7,IRON_BARS,12,CONCRETE:7,100)
RandomBlock(-7,2,-6,CONCRETE:7,60,quark:iron_plate:1,20,STAINED_CLAY:12,15,STAINED_CLAY:15,5,AIR,7,IRON_BARS,12,CONCRETE:7,100)
RandomBlock(-7,2,-5,CONCRETE:7,60,quark:iron_plate:1,20,STAINED_CLAY:12,15,STAINED_CLAY:15,5,AIR,7,IRON_BARS,12,CONCRETE:7,100)
RandomBlock(-7,2,-4,CONCRETE:7,60,quark:iron_plate:1,20,STAINED_CLAY:12,15,STAINED_CLAY:15,5,AIR,7,IRON_BARS,12,CONCRETE:7,100)
RandomBlock(-7,2,-3,CONCRETE:7,60,quark:iron_plate:1,20,STAINED_CLAY:12,15,STAINED_CLAY:15,5,AIR,7,IRON_BARS,12,CONCRETE:7,100)
RandomBlock(-7,2,-2,CONCRETE:7,60,quark:iron_plate:1,20,STAINED_CLAY:12,15,STAINED_CLAY:15,5,AIR,7,IRON_BARS,12,CONCRETE:7,100)
RandomBlock(-7,2,-1,CONCRETE:7,60,quark:iron_plate:1,20,STAINED_CLAY:12,15,STAINED_CLAY:15,5,AIR,7,IRON_BARS,12,CONCRETE:7,100)
RandomBlock(-7,2,0,CONCRETE:7,60,quark:iron_plate:1,20,STAINED_CLAY:12,15,STAINED_CLAY:15,5,AIR,7,IRON_BARS,12,CONCRETE:7,100)
RandomBlock(-7,2,1,CONCRETE:7,60,quark:iron_plate:1,20,STAINED_CLAY:12,15,STAINED_CLAY:15,5,AIR,7,IRON_BARS,12,CONCRETE:7,100)
Block(-7,2,2,SMOOTH_STAIRS:3)
Block(-7,2,5,SMOOTH_STAIRS:2)
RandomBlock(-7,2,6,CONCRETE:7,60,quark:iron_plate:1,20,STAINED_CLAY:12,15,STAINED_CLAY:15,5,AIR,7,IRON_BARS,12,CONCRETE:7,100)
RandomBlock(-7,2,7,CONCRETE:7,60,quark:iron_plate:1,20,STAINED_CLAY:12,15,STAINED_CLAY:15,5,AIR,7,IRON_BARS,12,CONCRETE:7,100)
RandomBlock(-7,2,8,CONCRETE:7,60,quark:iron_plate:1,20,STAINED_CLAY:12,15,STAINED_CLAY:15,5,AIR,7,IRON_BARS,12,CONCRETE:7,100)
RandomBlock(-7,3,8,CONCRETE:7,60,quark:iron_plate:1,20,STAINED_CLAY:12,15,STAINED_CLAY:15,5,AIR,7,IRON_BARS,12,CONCRETE:7,100)
RandomBlock(-7,4,8,CONCRETE:7,60,quark:iron_plate:1,20,STAINED_CLAY:12,15,STAINED_CLAY:15,5,AIR,7,IRON_BARS,12,CONCRETE:7,100)
Block(-7,5,6,CONCRETE:12)
Block(-7,5,7,CONCRETE:4)
RandomBlock(-7,5,8,CONCRETE:7,60,quark:iron_plate:1,20,STAINED_CLAY:12,15,STAINED_CLAY:15,5,AIR,7,IRON_BARS,12,CONCRETE:7,100)
RandomBlock(-7,6,-7,CONCRETE:7,60,quark:iron_plate:1,20,STAINED_CLAY:12,15,STAINED_CLAY:15,5,AIR,7,IRON_BARS,12,CONCRETE:7,100)
Block(-7,6,6,IRON_FENCE:0)
RandomBlock(-7,6,8,CONCRETE:7,60,quark:iron_plate:1,20,STAINED_CLAY:12,15,STAINED_CLAY:15,5,AIR,7,IRON_BARS,12,CONCRETE:7,100)
RandomBlock(-7,7,-7,CONCRETE:7,60,quark:iron_plate:1,20,STAINED_CLAY:12,15,STAINED_CLAY:15,5,AIR,7,IRON_BARS,12,CONCRETE:7,100)
RandomBlock(-7,7,-6,CONCRETE:7,60,quark:iron_plate:1,20,STAINED_CLAY:12,15,STAINED_CLAY:15,5,AIR,7,IRON_BARS,12,CONCRETE:7,100)
RandomBlock(-7,7,-5,CONCRETE:7,60,quark:iron_plate:1,20,STAINED_CLAY:12,15,STAINED_CLAY:15,5,AIR,7,IRON_BARS,12,CONCRETE:7,100)
RandomBlock(-7,7,-4,CONCRETE:7,60,quark:iron_plate:1,20,STAINED_CLAY:12,15,STAINED_CLAY:15,5,AIR,7,IRON_BARS,12,CONCRETE:7,100)
RandomBlock(-7,7,-3,CONCRETE:7,60,quark:iron_plate:1,20,STAINED_CLAY:12,15,STAINED_CLAY:15,5,AIR,7,IRON_BARS,12,CONCRETE:7,100)
RandomBlock(-7,7,-2,CONCRETE:7,60,quark:iron_plate:1,20,STAINED_CLAY:12,15,STAINED_CLAY:15,5,AIR,7,IRON_BARS,12,CONCRETE:7,100)
RandomBlock(-7,7,-1,CONCRETE:7,60,quark:iron_plate:1,20,STAINED_CLAY:12,15,STAINED_CLAY:15,5,AIR,7,IRON_BARS,12,CONCRETE:7,100)
RandomBlock(-7,7,0,CONCRETE:7,60,quark:iron_plate:1,20,STAINED_CLAY:12,15,STAINED_CLAY:15,5,AIR,7,IRON_BARS,12,CONCRETE:7,100)
RandomBlock(-7,7,1,CONCRETE:7,60,quark:iron_plate:1,20,STAINED_CLAY:12,15,STAINED_CLAY:15,5,AIR,7,IRON_BARS,12,CONCRETE:7,100)
RandomBlock(-7,7,2,CONCRETE:7,60,quark:iron_plate:1,20,STAINED_CLAY:12,15,STAINED_CLAY:15,5,AIR,7,IRON_BARS,12,CONCRETE:7,100)
RandomBlock(-7,7,3,CONCRETE:7,60,quark:iron_plate:1,20,STAINED_CLAY:12,15,STAINED_CLAY:15,5,AIR,7,IRON_BARS,12,CONCRETE:7,100)
RandomBlock(-7,7,4,CONCRETE:7,60,quark:iron_plate:1,20,STAINED_CLAY:12,15,STAINED_CLAY:15,5,AIR,7,IRON_BARS,12,CONCRETE:7,100)
RandomBlock(-7,7,5,CONCRETE:7,60,quark:iron_plate:1,20,STAINED_CLAY:12,15,STAINED_CLAY:15,5,AIR,7,IRON_BARS,12,CONCRETE:7,100)
RandomBlock(-7,7,6,CONCRETE:7,60,quark:iron_plate:1,20,STAINED_CLAY:12,15,STAINED_CLAY:15,5,AIR,7,IRON_BARS,12,CONCRETE:7,100)
RandomBlock(-7,7,7,CONCRETE:7,60,quark:iron_plate:1,20,STAINED_CLAY:12,15,STAINED_CLAY:15,5,AIR,7,IRON_BARS,12,CONCRETE:7,100)
RandomBlock(-7,7,8,CONCRETE:7,60,quark:iron_plate:1,20,STAINED_CLAY:12,15,STAINED_CLAY:15,5,AIR,7,IRON_BARS,12,CONCRETE:7,100)
RandomBlock(-7,8,-7,CONCRETE:7,60,quark:iron_plate:1,20,STAINED_CLAY:12,15,STAINED_CLAY:15,5,AIR,7,IRON_BARS,12,CONCRETE:7,100)
RandomBlock(-7,8,-6,CONCRETE:7,60,quark:iron_plate:1,20,STAINED_CLAY:12,15,STAINED_CLAY:15,5,AIR,7,IRON_BARS,12,CONCRETE:7,100)
RandomBlock(-7,8,-5,CONCRETE:7,60,quark:iron_plate:1,20,STAINED_CLAY:12,15,STAINED_CLAY:15,5,AIR,7,IRON_BARS,12,CONCRETE:7,100)
RandomBlock(-7,8,-4,CONCRETE:7,60,quark:iron_plate:1,20,STAINED_CLAY:12,15,STAINED_CLAY:15,5,AIR,7,IRON_BARS,12,CONCRETE:7,100)
RandomBlock(-7,8,-3,CONCRETE:7,60,quark:iron_plate:1,20,STAINED_CLAY:12,15,STAINED_CLAY:15,5,AIR,7,IRON_BARS,12,CONCRETE:7,100)
RandomBlock(-7,8,-2,CONCRETE:7,60,quark:iron_plate:1,20,STAINED_CLAY:12,15,STAINED_CLAY:15,5,AIR,7,IRON_BARS,12,CONCRETE:7,100)
RandomBlock(-7,8,-1,AIR,90,IRON_TRAPDOOR:11,100)
RandomBlock(-7,8,3,CONCRETE:7,60,quark:iron_plate:1,20,STAINED_CLAY:12,15,STAINED_CLAY:15,5,AIR,7,IRON_BARS,12,CONCRETE:7,100)
RandomBlock(-7,8,4,CONCRETE:7,60,quark:iron_plate:1,20,STAINED_CLAY:12,15,STAINED_CLAY:15,5,AIR,7,IRON_BARS,12,CONCRETE:7,100)
RandomBlock(-7,9,-7,CONCRETE:7,60,quark:iron_plate:1,20,STAINED_CLAY:12,15,STAINED_CLAY:15,5,AIR,7,IRON_BARS,12,CONCRETE:7,100)
RandomBlock(-7,9,-6,CONCRETE:7,60,quark:iron_plate:1,20,STAINED_CLAY:12,15,STAINED_CLAY:15,5,AIR,7,IRON_BARS,12,CONCRETE:7,100)
RandomBlock(-7,9,-5,CONCRETE:7,60,quark:iron_plate:1,20,STAINED_CLAY:12,15,STAINED_CLAY:15,5,AIR,7,IRON_BARS,12,CONCRETE:7,100)
RandomBlock(-7,9,-4,CONCRETE:7,60,quark:iron_plate:1,20,STAINED_CLAY:12,15,STAINED_CLAY:15,5,AIR,7,IRON_BARS,12,CONCRETE:7,100)
RandomBlock(-7,9,-3,CONCRETE:7,60,quark:iron_plate:1,20,STAINED_CLAY:12,15,STAINED_CLAY:15,5,AIR,7,IRON_BARS,12,CONCRETE:7,100)
RandomBlock(-7,9,-2,CONCRETE:7,60,quark:iron_plate:1,20,STAINED_CLAY:12,15,STAINED_CLAY:15,5,AIR,7,IRON_BARS,12,CONCRETE:7,100)
#RandomBlock(-7,9,-1,AIR:0,30,CHEST:5,../../../../../Chests/Loot/manhunt_urban_junk.nbt,10,CHEST:5,../../../../../Chests/Loot/manhunt_infected_cache.nbt,5,CHEST:5,../../../../../Chests/Loot/manhunt_urban_junk.nbt,65,CHEST:3,../../../../../Chests/Loot/manhunt_urban_junk.nbt,20,CHEST:3,../../../../../Chests/Loot/manhunt_residential_common.nbt,5,CHEST:3,../../../../../Chests/Loot/manhunt_residential_useful.nbt,3,CHEST:3,../../../../../Chests/Loot/manhunt_human_strategic_cache.nbt,1,CHEST:3,../../../../../Chests/Loot/manhunt_urban_junk.nbt,100)
RandomBlock(-7,9,3,CONCRETE:7,60,quark:iron_plate:1,20,STAINED_CLAY:12,15,STAINED_CLAY:15,5,AIR,7,IRON_BARS,12,CONCRETE:7,100)
RandomBlock(-7,9,4,CONCRETE:7,60,quark:iron_plate:1,20,STAINED_CLAY:12,15,STAINED_CLAY:15,5,AIR,7,IRON_BARS,12,CONCRETE:7,100)
RandomBlock(-7,10,-7,CONCRETE:7,60,quark:iron_plate:1,20,STAINED_CLAY:12,15,STAINED_CLAY:15,5,AIR,7,IRON_BARS,12,CONCRETE:7,100)
RandomBlock(-7,10,-6,CONCRETE:7,60,quark:iron_plate:1,20,STAINED_CLAY:12,15,STAINED_CLAY:15,5,AIR,7,IRON_BARS,12,CONCRETE:7,100)
RandomBlock(-7,10,-5,CONCRETE:7,60,quark:iron_plate:1,20,STAINED_CLAY:12,15,STAINED_CLAY:15,5,AIR,7,IRON_BARS,12,CONCRETE:7,100)
RandomBlock(-7,10,-4,CONCRETE:7,60,quark:iron_plate:1,20,STAINED_CLAY:12,15,STAINED_CLAY:15,5,AIR,7,IRON_BARS,12,CONCRETE:7,100)
RandomBlock(-7,10,-3,CONCRETE:7,60,quark:iron_plate:1,20,STAINED_CLAY:12,15,STAINED_CLAY:15,5,AIR,7,IRON_BARS,12,CONCRETE:7,100)
RandomBlock(-7,10,-2,CONCRETE:7,60,quark:iron_plate:1,20,STAINED_CLAY:12,15,STAINED_CLAY:15,5,AIR,7,IRON_BARS,12,CONCRETE:7,100)
Block(-7,10,1,CONCRETE:12)
RandomBlock(-7,10,3,CONCRETE:7,60,quark:iron_plate:1,20,STAINED_CLAY:12,15,STAINED_CLAY:15,5,AIR,7,IRON_BARS,12,CONCRETE:7,100)
RandomBlock(-7,10,4,CONCRETE:7,60,quark:iron_plate:1,20,STAINED_CLAY:12,15,STAINED_CLAY:15,5,AIR,7,IRON_BARS,12,CONCRETE:7,100)
Block(-7,10,5,CONCRETE:12)
Block(-7,10,7,CONCRETE:12)
RandomBlock(-7,11,-7,CONCRETE:7,60,quark:iron_plate:1,20,STAINED_CLAY:12,15,STAINED_CLAY:15,5,AIR,7,IRON_BARS,12,CONCRETE:7,100)
RandomBlock(-7,11,-6,CONCRETE:7,60,quark:iron_plate:1,20,STAINED_CLAY:12,15,STAINED_CLAY:15,5,AIR,7,IRON_BARS,12,CONCRETE:7,100)
RandomBlock(-7,11,-5,CONCRETE:7,60,quark:iron_plate:1,20,STAINED_CLAY:12,15,STAINED_CLAY:15,5,AIR,7,IRON_BARS,12,CONCRETE:7,100)
RandomBlock(-7,11,-4,CONCRETE:7,60,quark:iron_plate:1,20,STAINED_CLAY:12,15,STAINED_CLAY:15,5,AIR,7,IRON_BARS,12,CONCRETE:7,100)
RandomBlock(-7,11,-3,CONCRETE:7,60,quark:iron_plate:1,20,STAINED_CLAY:12,15,STAINED_CLAY:15,5,AIR,7,IRON_BARS,12,CONCRETE:7,100)
RandomBlock(-7,11,-2,CONCRETE:7,60,quark:iron_plate:1,20,STAINED_CLAY:12,15,STAINED_CLAY:15,5,AIR,7,IRON_BARS,12,CONCRETE:7,100)
RandomBlock(-7,11,-1,CONCRETE:7,60,quark:iron_plate:1,20,STAINED_CLAY:12,15,STAINED_CLAY:15,5,AIR,7,IRON_BARS,12,CONCRETE:7,100)
RandomBlock(-7,11,0,CONCRETE:7,60,quark:iron_plate:1,20,STAINED_CLAY:12,15,STAINED_CLAY:15,5,AIR,7,IRON_BARS,12,CONCRETE:7,100)
RandomBlock(-7,11,1,CONCRETE:7,60,quark:iron_plate:1,20,STAINED_CLAY:12,15,STAINED_CLAY:15,5,AIR,7,IRON_BARS,12,CONCRETE:7,100)
RandomBlock(-7,11,2,CONCRETE:7,60,quark:iron_plate:1,20,STAINED_CLAY:12,15,STAINED_CLAY:15,5,AIR,7,IRON_BARS,12,CONCRETE:7,100)
RandomBlock(-7,11,3,CONCRETE:7,60,quark:iron_plate:1,20,STAINED_CLAY:12,15,STAINED_CLAY:15,5,AIR,7,IRON_BARS,12,CONCRETE:7,100)
RandomBlock(-7,11,4,CONCRETE:7,60,quark:iron_plate:1,20,STAINED_CLAY:12,15,STAINED_CLAY:15,5,AIR,7,IRON_BARS,12,CONCRETE:7,100)
Block(-7,11,5,CONCRETE:12)
RandomBlock(-7,11,6,CONCRETE:7,60,quark:iron_plate:1,20,STAINED_CLAY:12,15,STAINED_CLAY:15,5,AIR,7,IRON_BARS,12,CONCRETE:7,100)
RandomBlock(-7,11,7,STONE:6,80,STONE:6,90,STONEBRICK:0,100)
RandomBlock(-7,11,8,CONCRETE:7,60,quark:iron_plate:1,20,STAINED_CLAY:12,15,STAINED_CLAY:15,5,AIR,7,IRON_BARS,12,CONCRETE:7,100)
RandomBlock(-7,12,-7,CONCRETE:7,60,quark:iron_plate:1,20,STAINED_CLAY:12,15,STAINED_CLAY:15,5,AIR,7,IRON_BARS,12,CONCRETE:7,100)
#Block(-7,12,-6,DARK_OAK_STAIRS:0)
Block(-7,12,-6,AIR)
#Block(-7,12,-5,DARK_OAK_STAIRS:0)
Block(-7,12,-5,AIR)
#RandomBlock(-7,12,-4,AIR,90,WALL_SIGN:3,../AllScraperData/skyscraper_2x2_03/336-signC16R0.nbt,100)
RandomBlock(-7,12,-3,CONCRETE:7,60,quark:iron_plate:1,20,STAINED_CLAY:12,15,STAINED_CLAY:15,5,AIR,7,IRON_BARS,12,CONCRETE:7,100)
RandomBlock(-7,12,-2,CONCRETE:7,60,quark:iron_plate:1,20,STAINED_CLAY:12,15,STAINED_CLAY:15,5,AIR,7,IRON_BARS,12,CONCRETE:7,100)
RandomBlock(-7,12,-1,CONCRETE:8,60,minecraft:stone,15,STONE:5,15,STAINED_CLAY:9,10,IRON_BARS,12,AIR,8,STAINED_CLAY:12,30,CONCRETE:8,100)
Block(-7,12,0,QUARTZ_STAIRS:7)
#Block(-7,12,4,SPRUCE_DOOR:1)
Block(-7,12,4,AIR)
RandomBlock(-7,12,5,STONE:6,80,STONE:6,90,STONEBRICK:0,100)
RandomBlock(-7,12,6,CONCRETE:8,60,minecraft:stone,15,STONE:5,15,STAINED_CLAY:9,10,IRON_BARS,12,AIR,8,STAINED_CLAY:12,30,CONCRETE:8,100)
#Block(-7,12,8,SPRUCE_DOOR:3)
Block(-7,12,8,AIR)
RandomBlock(-7,13,-7,CONCRETE:7,60,quark:iron_plate:1,20,STAINED_CLAY:12,15,STAINED_CLAY:15,5,AIR,7,IRON_BARS,12,CONCRETE:7,100)
RandomBlock(-7,13,-3,CONCRETE:7,60,quark:iron_plate:1,20,STAINED_CLAY:12,15,STAINED_CLAY:15,5,AIR,7,IRON_BARS,12,CONCRETE:7,100)
RandomBlock(-7,13,-2,CONCRETE:7,60,quark:iron_plate:1,20,STAINED_CLAY:12,15,STAINED_CLAY:15,5,AIR,7,IRON_BARS,12,CONCRETE:7,100)
RandomBlock(-7,13,-1,CONCRETE:8,60,minecraft:stone,15,STONE:5,15,STAINED_CLAY:9,10,IRON_BARS,12,AIR,8,STAINED_CLAY:12,30,CONCRETE:8,100)
#Block(-7,13,4,SPRUCE_DOOR:8)
Block(-7,13,4,AIR)
#RandomBlock(-7,13,5,AIR,90,TRAP_DOOR:4,100)
RandomBlock(-7,13,6,CONCRETE:8,60,minecraft:stone,15,STONE:5,15,STAINED_CLAY:9,10,IRON_BARS,12,AIR,8,STAINED_CLAY:12,30,CONCRETE:8,100)
#Block(-7,13,8,SPRUCE_DOOR:9)
Block(-7,13,8,AIR)
RandomBlock(-7,14,-7,CONCRETE:7,60,quark:iron_plate:1,20,STAINED_CLAY:12,15,STAINED_CLAY:15,5,AIR,7,IRON_BARS,12,CONCRETE:7,100)
RandomBlock(-7,14,-3,CONCRETE:7,60,quark:iron_plate:1,20,STAINED_CLAY:12,15,STAINED_CLAY:15,5,AIR,7,IRON_BARS,12,CONCRETE:7,100)
RandomBlock(-7,14,-2,CONCRETE:7,60,quark:iron_plate:1,20,STAINED_CLAY:12,15,STAINED_CLAY:15,5,AIR,7,IRON_BARS,12,CONCRETE:7,100)
RandomBlock(-7,14,-1,CONCRETE:8,60,minecraft:stone,15,STONE:5,15,STAINED_CLAY:9,10,IRON_BARS,12,AIR,8,STAINED_CLAY:12,30,CONCRETE:8,100)
#RandomBlock(-7,14,0,AIR,95,WALL_BANNER:3,../AllScraperData/skyscraper_2x2_03/338-bannerC16R0.nbt,100)
#RandomBlock(-7,14,3,AIR,90,TRAP_DOOR:12,100)
#Block(-7,14,4,DARK_OAK_FENCE_GATE:0)
Block(-7,14,4,AIR)
RandomBlock(-7,14,6,CONCRETE:8,60,minecraft:stone,15,STONE:5,15,STAINED_CLAY:9,10,IRON_BARS,12,AIR,8,STAINED_CLAY:12,30,CONCRETE:8,100)
#Block(-7,14,8,DARK_OAK_FENCE_GATE:2)
Block(-7,14,8,AIR)
RandomBlock(-7,15,-7,CONCRETE:7,60,quark:iron_plate:1,20,STAINED_CLAY:12,15,STAINED_CLAY:15,5,AIR,7,IRON_BARS,12,CONCRETE:7,100)
RandomBlock(-7,15,-6,CONCRETE:7,60,quark:iron_plate:1,20,STAINED_CLAY:12,15,STAINED_CLAY:15,5,AIR,7,IRON_BARS,12,CONCRETE:7,100)
RandomBlock(-7,15,-5,CONCRETE:7,60,quark:iron_plate:1,20,STAINED_CLAY:12,15,STAINED_CLAY:15,5,AIR,7,IRON_BARS,12,CONCRETE:7,100)
RandomBlock(-7,15,-4,CONCRETE:7,60,quark:iron_plate:1,20,STAINED_CLAY:12,15,STAINED_CLAY:15,5,AIR,7,IRON_BARS,12,CONCRETE:7,100)
RandomBlock(-7,15,-3,CONCRETE:7,60,quark:iron_plate:1,20,STAINED_CLAY:12,15,STAINED_CLAY:15,5,AIR,7,IRON_BARS,12,CONCRETE:7,100)
RandomBlock(-7,15,-2,CONCRETE:7,60,quark:iron_plate:1,20,STAINED_CLAY:12,15,STAINED_CLAY:15,5,AIR,7,IRON_BARS,12,CONCRETE:7,100)
RandomBlock(-7,15,-1,CONCRETE:8,60,minecraft:stone,15,STONE:5,15,STAINED_CLAY:9,10,IRON_BARS,12,AIR,8,STAINED_CLAY:12,30,CONCRETE:8,100)
RandomBlock(-7,15,0,AIR,90,IRON_TRAPDOOR:9,100)
RandomBlock(-7,15,4,CONCRETE:8,60,minecraft:stone,15,STONE:5,15,STAINED_CLAY:9,10,IRON_BARS,12,AIR,8,STAINED_CLAY:12,30,CONCRETE:8,100)
RandomBlock(-7,15,5,CONCRETE:8,60,minecraft:stone,15,STONE:5,15,STAINED_CLAY:9,10,IRON_BARS,12,AIR,8,STAINED_CLAY:12,30,CONCRETE:8,100)
RandomBlock(-7,15,6,CONCRETE:8,60,minecraft:stone,15,STONE:5,15,STAINED_CLAY:9,10,IRON_BARS,12,AIR,8,STAINED_CLAY:12,30,CONCRETE:8,100)
RandomBlock(-7,15,7,CONCRETE:8,60,minecraft:stone,15,STONE:5,15,STAINED_CLAY:9,10,IRON_BARS,12,AIR,8,STAINED_CLAY:12,30,CONCRETE:8,100)
RandomBlock(-7,15,8,CONCRETE:8,60,minecraft:stone,15,STONE:5,15,STAINED_CLAY:9,10,IRON_BARS,12,AIR,8,STAINED_CLAY:12,30,CONCRETE:8,100)
RandomBlock(-7,16,-7,CONCRETE:7,60,quark:iron_plate:1,20,STAINED_CLAY:12,15,STAINED_CLAY:15,5,AIR,7,IRON_BARS,12,CONCRETE:7,100)
RandomBlock(-7,16,-6,CONCRETE:7,60,quark:iron_plate:1,20,STAINED_CLAY:12,15,STAINED_CLAY:15,5,AIR,7,IRON_BARS,12,CONCRETE:7,100)
RandomBlock(-7,16,-5,CONCRETE:7,60,quark:iron_plate:1,20,STAINED_CLAY:12,15,STAINED_CLAY:15,5,AIR,7,IRON_BARS,12,CONCRETE:7,100)
RandomBlock(-7,16,-4,CONCRETE:7,60,quark:iron_plate:1,20,STAINED_CLAY:12,15,STAINED_CLAY:15,5,AIR,7,IRON_BARS,12,CONCRETE:7,100)
RandomBlock(-7,16,-3,CONCRETE:7,60,quark:iron_plate:1,20,STAINED_CLAY:12,15,STAINED_CLAY:15,5,AIR,7,IRON_BARS,12,CONCRETE:7,100)
RandomBlock(-7,16,-2,CONCRETE:7,60,quark:iron_plate:1,20,STAINED_CLAY:12,15,STAINED_CLAY:15,5,AIR,7,IRON_BARS,12,CONCRETE:7,100)
RandomBlock(-7,16,-1,CONCRETE:7,60,quark:iron_plate:1,20,STAINED_CLAY:12,15,STAINED_CLAY:15,5,AIR,7,IRON_BARS,12,CONCRETE:7,100)
RandomBlock(-7,16,0,CONCRETE:7,60,quark:iron_plate:1,20,STAINED_CLAY:12,15,STAINED_CLAY:15,5,AIR,7,IRON_BARS,12,CONCRETE:7,100)
RandomBlock(-7,16,1,CONCRETE:7,60,quark:iron_plate:1,20,STAINED_CLAY:12,15,STAINED_CLAY:15,5,AIR,7,IRON_BARS,12,CONCRETE:7,100)
RandomBlock(-7,16,2,CONCRETE:7,60,quark:iron_plate:1,20,STAINED_CLAY:12,15,STAINED_CLAY:15,5,AIR,7,IRON_BARS,12,CONCRETE:7,100)
RandomBlock(-7,16,3,CONCRETE:7,60,quark:iron_plate:1,20,STAINED_CLAY:12,15,STAINED_CLAY:15,5,AIR,7,IRON_BARS,12,CONCRETE:7,100)
RandomBlock(-7,16,4,CONCRETE:7,60,quark:iron_plate:1,20,STAINED_CLAY:12,15,STAINED_CLAY:15,5,AIR,7,IRON_BARS,12,CONCRETE:7,100)
RandomBlock(-7,16,5,CONCRETE:7,60,quark:iron_plate:1,20,STAINED_CLAY:12,15,STAINED_CLAY:15,5,AIR,7,IRON_BARS,12,CONCRETE:7,100)
RandomBlock(-7,16,6,CONCRETE:7,60,quark:iron_plate:1,20,STAINED_CLAY:12,15,STAINED_CLAY:15,5,AIR,7,IRON_BARS,12,CONCRETE:7,100)
RandomBlock(-7,16,7,CONCRETE:7,60,quark:iron_plate:1,20,STAINED_CLAY:12,15,STAINED_CLAY:15,5,AIR,7,IRON_BARS,12,CONCRETE:7,100)
RandomBlock(-7,16,8,CONCRETE:7,60,quark:iron_plate:1,20,STAINED_CLAY:12,15,STAINED_CLAY:15,5,AIR,7,IRON_BARS,12,CONCRETE:7,100)
RandomBlock(-7,17,-7,CONCRETE:7,60,quark:iron_plate:1,20,STAINED_CLAY:12,15,STAINED_CLAY:15,5,AIR,7,IRON_BARS,12,CONCRETE:7,100)
RandomBlock(-7,17,-6,CONCRETE:7,60,quark:iron_plate:1,20,STAINED_CLAY:12,15,STAINED_CLAY:15,5,AIR,7,IRON_BARS,12,CONCRETE:7,100)
RandomBlock(-7,17,-5,CONCRETE:7,60,quark:iron_plate:1,20,STAINED_CLAY:12,15,STAINED_CLAY:15,5,AIR,7,IRON_BARS,12,CONCRETE:7,100)
RandomBlock(-7,17,-4,CONCRETE:7,60,quark:iron_plate:1,20,STAINED_CLAY:12,15,STAINED_CLAY:15,5,AIR,7,IRON_BARS,12,CONCRETE:7,100)
RandomBlock(-7,17,-3,CONCRETE:7,60,quark:iron_plate:1,20,STAINED_CLAY:12,15,STAINED_CLAY:15,5,AIR,7,IRON_BARS,12,CONCRETE:7,100)
RandomBlock(-7,17,-2,CONCRETE:7,60,quark:iron_plate:1,20,STAINED_CLAY:12,15,STAINED_CLAY:15,5,AIR,7,IRON_BARS,12,CONCRETE:7,100)
RandomBlock(-7,17,-1,CONCRETE:7,60,quark:iron_plate:1,20,STAINED_CLAY:12,15,STAINED_CLAY:15,5,AIR,7,IRON_BARS,12,CONCRETE:7,100)
RandomBlock(-7,17,0,CONCRETE:7,60,quark:iron_plate:1,20,STAINED_CLAY:12,15,STAINED_CLAY:15,5,AIR,7,IRON_BARS,12,CONCRETE:7,100)
RandomBlock(-7,17,1,CONCRETE:7,60,quark:iron_plate:1,20,STAINED_CLAY:12,15,STAINED_CLAY:15,5,AIR,7,IRON_BARS,12,CONCRETE:7,100)
RandomBlock(-7,17,2,CONCRETE:8,60,minecraft:stone,15,STONE:5,15,STAINED_CLAY:9,10,IRON_BARS,12,AIR,8,STAINED_CLAY:12,30,CONCRETE:8,100)
RandomBlock(-7,17,3,CONCRETE:7,60,quark:iron_plate:1,20,STAINED_CLAY:12,15,STAINED_CLAY:15,5,AIR,7,IRON_BARS,12,CONCRETE:7,100)
RandomBlock(-7,17,4,CONCRETE:7,60,quark:iron_plate:1,20,STAINED_CLAY:12,15,STAINED_CLAY:15,5,AIR,7,IRON_BARS,12,CONCRETE:7,100)
RandomBlock(-7,17,5,CONCRETE:7,60,quark:iron_plate:1,20,STAINED_CLAY:12,15,STAINED_CLAY:15,5,AIR,7,IRON_BARS,12,CONCRETE:7,100)
RandomBlock(-7,17,6,CONCRETE:7,60,quark:iron_plate:1,20,STAINED_CLAY:12,15,STAINED_CLAY:15,5,AIR,7,IRON_BARS,12,CONCRETE:7,100)
RandomBlock(-7,17,7,CONCRETE:7,60,quark:iron_plate:1,20,STAINED_CLAY:12,15,STAINED_CLAY:15,5,AIR,7,IRON_BARS,12,CONCRETE:7,100)
RandomBlock(-7,17,8,CONCRETE:7,60,quark:iron_plate:1,20,STAINED_CLAY:12,15,STAINED_CLAY:15,5,AIR,7,IRON_BARS,12,CONCRETE:7,100)
RandomBlock(-7,18,-3,STAINED_GLASS:15,40,AIR,100)
RandomBlock(-7,18,0,STAINED_GLASS_PANE:15,40,AIR,100)
RandomBlock(-7,18,7,CONCRETE:8,60,minecraft:stone,15,STONE:5,15,STAINED_CLAY:9,10,IRON_BARS,12,AIR,8,STAINED_CLAY:12,30,CONCRETE:8,100)
RandomBlock(-7,18,8,CONCRETE:8,60,minecraft:stone,15,STONE:5,15,STAINED_CLAY:9,10,IRON_BARS,12,AIR,8,STAINED_CLAY:12,30,CONCRETE:8,100)
RandomBlock(-7,19,-3,STAINED_GLASS:15,40,AIR,100)
RandomBlock(-7,19,0,STAINED_GLASS_PANE:15,40,AIR,100)
RandomBlock(-7,19,7,CONCRETE:8,60,minecraft:stone,15,STONE:5,15,STAINED_CLAY:9,10,IRON_BARS,12,AIR,8,STAINED_CLAY:12,30,CONCRETE:8,100)
#RandomBlock(-7,19,8,AIR,95,STANDING_BANNER:4,../AllScraperData/skyscraper_2x2_03/340-bannerC16R0.nbt,100)
RandomBlock(-7,20,-3,STAINED_GLASS:15,40,AIR,100)
RandomBlock(-7,20,7,CONCRETE:8,60,minecraft:stone,15,STONE:5,15,STAINED_CLAY:9,10,IRON_BARS,12,AIR,8,STAINED_CLAY:12,30,CONCRETE:8,100)
#Block(-7,21,7,WOOD_STEP:5)
#Block(-7,21,8,WOOD_STEP:5)
#RandomBlock(-7,32,-2,AIR,95,STANDING_BANNER:12,../AllScraperData/skyscraper_2x2_03/352-bannerC16R0.nbt,100)
#RandomBlock(-7,33,0,AIR,95,WALL_BANNER:3,../AllScraperData/skyscraper_2x2_03/353-bannerC16R0.nbt,100)
#Block(-7,36,5,DARK_OAK_STAIRS:4)
#Block(-7,36,6,DARK_OAK_STAIRS:4)
#Block(-7,36,7,DARK_OAK_STAIRS:4)
#Block(-7,37,5,DARK_OAK_STAIRS:3)
#Block(-7,37,6,DARK_OAK_STAIRS:1)
#Block(-7,37,7,DARK_OAK_STAIRS:2)
#RandomBlock(-7,38,5,AIR,90,TRAP_DOOR:5,100)
#RandomBlock(-7,38,7,AIR,90,TRAP_DOOR:4,100)
#Block(-7,67,-2,CARPET:15)
#Block(-7,67,-1,CARPET:15)
#Block(-7,71,8,DARK_OAK_STAIRS:0)
RandomBlock(-7,21,-3,STAINED_GLASS:15,40,AIR,100)
RandomBlock(-7,21,-2,CONCRETE:7,60,quark:iron_plate:1,20,STAINED_CLAY:12,15,STAINED_CLAY:15,5,AIR,7,IRON_BARS,12,CONCRETE:7,100)
RandomBlock(-7,21,-1,CONCRETE:7,60,quark:iron_plate:1,20,STAINED_CLAY:12,15,STAINED_CLAY:15,5,AIR,7,IRON_BARS,12,CONCRETE:7,100)
RandomBlock(-7,21,0,CONCRETE:7,60,quark:iron_plate:1,20,STAINED_CLAY:12,15,STAINED_CLAY:15,5,AIR,7,IRON_BARS,12,CONCRETE:7,100)
RandomBlock(-7,21,1,CONCRETE:7,60,quark:iron_plate:1,20,STAINED_CLAY:12,15,STAINED_CLAY:15,5,AIR,7,IRON_BARS,12,CONCRETE:7,100)
RandomBlock(-7,21,2,CONCRETE:7,60,quark:iron_plate:1,20,STAINED_CLAY:12,15,STAINED_CLAY:15,5,AIR,7,IRON_BARS,12,CONCRETE:7,100)
RandomBlock(-7,21,3,CONCRETE:7,60,quark:iron_plate:1,20,STAINED_CLAY:12,15,STAINED_CLAY:15,5,AIR,7,IRON_BARS,12,CONCRETE:7,100)
RandomBlock(-7,21,4,CONCRETE:7,60,quark:iron_plate:1,20,STAINED_CLAY:12,15,STAINED_CLAY:15,5,AIR,7,IRON_BARS,12,CONCRETE:7,100)
RandomBlock(-7,21,5,CONCRETE:7,60,quark:iron_plate:1,20,STAINED_CLAY:12,15,STAINED_CLAY:15,5,AIR,7,IRON_BARS,12,CONCRETE:7,100)
RandomBlock(-7,21,6,CONCRETE:7,60,quark:iron_plate:1,20,STAINED_CLAY:12,15,STAINED_CLAY:15,5,AIR,7,IRON_BARS,12,CONCRETE:7,100)
RandomBlock(-7,21,7,CONCRETE:7,60,quark:iron_plate:1,20,STAINED_CLAY:12,15,STAINED_CLAY:15,5,AIR,7,IRON_BARS,12,CONCRETE:7,100)
RandomBlock(-7,21,8,CONCRETE:7,60,quark:iron_plate:1,20,STAINED_CLAY:12,15,STAINED_CLAY:15,5,AIR,7,IRON_BARS,12,CONCRETE:7,100)
RandomBlock(-7,22,-3,STAINED_GLASS:15,40,AIR,100)
RandomBlock(-7,23,-3,STAINED_GLASS:15,40,AIR,100)
RandomBlock(-7,24,-3,STAINED_GLASS:15,40,AIR,100)
#Block(-7,80,0,DARK_OAK_STAIRS:4)
Block(-7,24,0,AIR)
#Block(-7,80,4,DARK_OAK_STAIRS:4)
Block(-7,24,4,AIR)
RandomBlock(-7,25,-3,STAINED_GLASS:15,40,AIR,100)
#RandomBlock(-7,81,-1,AIR,90,TRAP_DOOR:4,100)
Block(-7,25,0,LEAVES:4)
#RandomBlock(-7,81,1,AIR,90,TRAP_DOOR:5,100)
#RandomBlock(-7,81,3,AIR,90,TRAP_DOOR:4,100)
Block(-7,25,4,LEAVES:4)
#RandomBlock(-7,81,5,AIR,90,TRAP_DOOR:5,100)
#Block(-7,81,8,DARK_OAK_STAIRS:4)
Block(-7,25,8,AIR)
RandomBlock(-7,26,-3,STAINED_GLASS:15,40,AIR,100)
Block(-7,26,0,LEAVES:4)
Block(-7,26,4,LEAVES:12)
#RandomBlock(-7,82,7,AIR,90,TRAP_DOOR:12,100)
Block(-7,26,8,LEAVES:4)
RandomBlock(-7,27,-3,STAINED_GLASS:15,40,AIR,100)
Block(-7,27,0,LEAVES:4)
Block(-7,27,4,LEAVES:12)
Block(-7,27,8,LEAVES:4)
RandomBlock(-7,28,-3,STAINED_GLASS:15,40,AIR,100)
Block(-7,28,0,LEAVES:4)
Block(-7,28,4,LEAVES:4)
Block(-7,28,8,LEAVES:4)
RandomBlock(-7,29,-3,STAINED_GLASS:15,40,AIR,100)
Block(-7,29,0,LEAVES:4)
Block(-7,29,4,LEAVES:4)
Block(-7,29,8,LEAVES:4)
RandomBlock(-7,30,-3,STAINED_GLASS:15,40,AIR,100)
Block(-7,30,0,LEAVES:4)
Block(-7,30,4,LEAVES:4)
Block(-7,30,8,LEAVES:4)
RandomBlock(-7,31,-3,STAINED_GLASS:15,40,AIR,100)
Block(-7,31,0,LEAVES:4)
Block(-7,31,4,LEAVES:4)
Block(-7,31,8,LEAVES:4)
RandomBlock(-7,32,-3,STAINED_GLASS:15,40,AIR,100)
Block(-7,32,0,LEAVES:4)
Block(-7,32,4,LEAVES:4)
Block(-7,32,8,LEAVES:4)
RandomBlock(-7,33,-3,STAINED_GLASS:15,40,AIR,100)
#RandomBlock(-7,89,-1,AIR,90,TRAP_DOOR:12,100)
Block(-7,33,0,LEAVES:12)
#RandomBlock(-7,89,1,AIR,90,TRAP_DOOR:13,100)
#RandomBlock(-7,89,3,AIR,90,TRAP_DOOR:12,100)
Block(-7,33,4,LEAVES:12)
#RandomBlock(-7,89,5,AIR,90,TRAP_DOOR:13,100)
#RandomBlock(-7,89,7,AIR,90,TRAP_DOOR:12,100)
Block(-7,33,8,LEAVES:4)
RandomBlock(-7,34,-3,STAINED_GLASS:15,40,AIR,100)
#Block(-7,90,0,DARK_OAK_STAIRS:0)
Block(-7,34,0,AIR)
#Block(-7,90,4,DARK_OAK_STAIRS:0)
Block(-7,34,4,AIR)
#Block(-7,90,8,DARK_OAK_STAIRS:0)
Block(-7,34,8,AIR)
RandomBlock(-7,35,-3,STAINED_GLASS:15,40,AIR,100)
RandomBlock(-7,36,-3,STAINED_GLASS:15,40,AIR,100)
RandomBlock(-7,37,-3,STAINED_GLASS:15,40,AIR,100)
RandomBlock(-7,38,-3,STAINED_GLASS:15,40,AIR,100)
RandomBlock(-7,38,-2,STAINED_GLASS:15,40,AIR,100)
RandomBlock(-7,38,-1,STAINED_GLASS:15,40,AIR,100)
RandomBlock(-7,38,0,STAINED_GLASS:15,40,AIR,100)
RandomBlock(-7,38,1,STAINED_GLASS:15,40,AIR,100)
RandomBlock(-7,38,2,STAINED_GLASS:15,40,AIR,100)
RandomBlock(-7,38,3,STAINED_GLASS:15,40,AIR,100)
RandomBlock(-7,38,4,STAINED_GLASS:15,40,AIR,100)
RandomBlock(-7,38,5,STAINED_GLASS:15,40,AIR,100)
RandomBlock(-7,38,6,STAINED_GLASS:15,40,AIR,100)
RandomBlock(-7,38,7,STAINED_GLASS:15,40,AIR,100)
RandomBlock(-7,38,8,STAINED_GLASS:15,40,AIR,100)
RandomBlock(-7,39,-3,STAINED_GLASS:15,40,AIR,100)
#RandomBlock(-7,95,0,AIR,90,TRAP_DOOR:7,100)
Block(-7,39,3,LADDER:4)
#Block(-7,95,4,DARK_OAK_STAIRS:2)
Block(-7,39,4,AIR)
#Block(-7,95,5,BOOKSHELF:0)
Block(-7,39,5,AIR)
#Block(-7,95,6,BOOKSHELF:0)
Block(-7,39,6,AIR)
RandomBlock(-7,39,7,CONCRETE:7,60,quark:iron_plate:1,20,STAINED_CLAY:12,15,STAINED_CLAY:15,5,AIR,7,IRON_BARS,12,CONCRETE:7,100)
RandomBlock(-7,39,8,CONCRETE:7,60,quark:iron_plate:1,20,STAINED_CLAY:12,15,STAINED_CLAY:15,5,AIR,7,IRON_BARS,12,CONCRETE:7,100)
RandomBlock(-7,40,-3,STAINED_GLASS:15,40,AIR,100)
#RandomBlock(-7,96,0,AIR,90,TRAP_DOOR:7,100)
Block(-7,40,3,LADDER:4)
#Block(-7,96,5,BOOKSHELF:0)
Block(-7,40,5,AIR)
RandomBlock(-7,40,7,CONCRETE:7,60,quark:iron_plate:1,20,STAINED_CLAY:12,15,STAINED_CLAY:15,5,AIR,7,IRON_BARS,12,CONCRETE:7,100)
Block(-7,40,8,STATIONARY_LAVA:0)
RandomBlock(-7,41,-3,STAINED_GLASS:15,40,AIR,100)
Block(-7,41,3,LADDER:4)
#Block(-7,97,5,BOOKSHELF:0)
Block(-7,41,5,AIR)
RandomBlock(-7,41,7,CONCRETE:7,60,quark:iron_plate:1,20,STAINED_CLAY:12,15,STAINED_CLAY:15,5,AIR,7,IRON_BARS,12,CONCRETE:7,100)
Block(-7,41,8,STATIONARY_LAVA:8)
RandomBlock(-7,42,-3,STAINED_GLASS:15,40,AIR,100)
Block(-7,42,3,LADDER:4)
#RandomBlock(-7,98,4,AIR,90,TRAP_DOOR:0,100)
#Block(-7,98,5,BOOKSHELF:0)
Block(-7,42,5,AIR)
RandomBlock(-7,42,7,CONCRETE:7,60,quark:iron_plate:1,20,STAINED_CLAY:12,15,STAINED_CLAY:15,5,AIR,7,IRON_BARS,12,CONCRETE:7,100)
Block(-7,42,8,STATIONARY_LAVA:8)
RandomBlock(-7,43,-3,STAINED_GLASS:15,40,AIR,100)
Block(-7,43,3,LADDER:4)
#Block(-7,99,5,BOOKSHELF:0)
Block(-7,43,5,AIR)
RandomBlock(-7,43,7,CONCRETE:7,60,quark:iron_plate:1,20,STAINED_CLAY:12,15,STAINED_CLAY:15,5,AIR,7,IRON_BARS,12,CONCRETE:7,100)
Block(-7,43,8,STATIONARY_LAVA:8)
RandomBlock(-7,44,-3,STAINED_GLASS:15,40,AIR,100)
#Block(-7,100,5,BOOKSHELF:0)
Block(-7,44,5,AIR)
RandomBlock(-7,44,6,CONCRETE:7,60,quark:iron_plate:1,20,STAINED_CLAY:12,15,STAINED_CLAY:15,5,AIR,7,IRON_BARS,12,CONCRETE:7,100)
RandomBlock(-7,44,7,CONCRETE:7,60,quark:iron_plate:1,20,STAINED_CLAY:12,15,STAINED_CLAY:15,5,AIR,7,IRON_BARS,12,CONCRETE:7,100)
Block(-7,44,8,STATIONARY_LAVA:8)
RandomBlock(-7,45,-3,STAINED_GLASS:15,40,AIR,100)
RandomBlock(-7,45,5,CONCRETE:7,60,quark:iron_plate:1,20,STAINED_CLAY:12,15,STAINED_CLAY:15,5,AIR,7,IRON_BARS,12,CONCRETE:7,100)
RandomBlock(-7,45,6,CONCRETE:7,60,quark:iron_plate:1,20,STAINED_CLAY:12,15,STAINED_CLAY:15,5,AIR,7,IRON_BARS,12,CONCRETE:7,100)
RandomBlock(-7,45,7,CONCRETE:7,60,quark:iron_plate:1,20,STAINED_CLAY:12,15,STAINED_CLAY:15,5,AIR,7,IRON_BARS,12,CONCRETE:7,100)
Block(-7,45,8,STATIONARY_LAVA:8)
RandomBlock(-7,46,-3,STAINED_GLASS:15,40,AIR,100)
RandomBlock(-7,46,-2,STAINED_GLASS:15,40,AIR,100)
RandomBlock(-7,46,-1,STAINED_GLASS:15,40,AIR,100)
RandomBlock(-7,46,0,STAINED_GLASS:15,40,AIR,100)
RandomBlock(-7,46,1,STAINED_GLASS:15,40,AIR,100)
RandomBlock(-7,46,2,STAINED_GLASS:15,40,AIR,100)
RandomBlock(-7,46,3,STAINED_GLASS:15,40,AIR,100)
RandomBlock(-7,46,4,STAINED_GLASS:15,40,AIR,100)
RandomBlock(-7,46,5,STAINED_GLASS:15,40,AIR,100)
RandomBlock(-7,46,6,STAINED_GLASS:15,40,AIR,100)
RandomBlock(-7,46,7,CONCRETE:7,60,quark:iron_plate:1,20,STAINED_CLAY:12,15,STAINED_CLAY:15,5,AIR,7,IRON_BARS,12,CONCRETE:7,100)
Block(-7,46,8,STATIONARY_LAVA:8)
RandomBlock(-7,47,-3,STAINED_GLASS:15,40,AIR,100)
RandomBlock(-7,47,-2,AIR,90,IRON_TRAPDOOR:10,100)
#Block(-7,103,0,DARK_OAK_STAIRS:7)
Block(-7,47,0,AIR)
#RandomBlock(-7,103,3,AIR,90,TRAP_DOOR:4,100)
Block(-7,47,4,AIR:0)
Block(-7,47,5,AIR:0)
#RandomBlock(-7,103,6,AIR,90,TRAP_DOOR:5,100)
RandomBlock(-7,47,7,CONCRETE:7,60,quark:iron_plate:1,20,STAINED_CLAY:12,15,STAINED_CLAY:15,5,AIR,7,IRON_BARS,12,CONCRETE:7,100)
Block(-7,47,8,STATIONARY_LAVA:0)
RandomBlock(-7,48,-3,STAINED_GLASS:15,40,AIR,100)
#Block(-7,104,4,CARPET:13)
Block(-7,48,4,AIR)
#Block(-7,104,5,CARPET:13)
Block(-7,48,5,AIR)
RandomBlock(-7,48,7,CONCRETE:7,60,quark:iron_plate:1,20,STAINED_CLAY:12,15,STAINED_CLAY:15,5,AIR,7,IRON_BARS,12,CONCRETE:7,100)
RandomBlock(-7,48,8,CONCRETE:7,60,quark:iron_plate:1,20,STAINED_CLAY:12,15,STAINED_CLAY:15,5,AIR,7,IRON_BARS,12,CONCRETE:7,100)
RandomBlock(-7,49,-3,STAINED_GLASS:15,40,AIR,100)
RandomBlock(-7,49,-2,STAINED_GLASS:15,40,AIR,100)
RandomBlock(-7,49,-1,STAINED_GLASS:15,40,AIR,100)
RandomBlock(-7,49,0,STAINED_GLASS_PANE:15,40,AIR,100)
RandomBlock(-7,49,7,CONCRETE:7,60,quark:iron_plate:1,20,STAINED_CLAY:12,15,STAINED_CLAY:15,5,AIR,7,IRON_BARS,12,CONCRETE:7,100)
Block(-7,49,8,STATIONARY_WATER:0)
RandomBlock(-7,50,-3,STAINED_GLASS:15,40,AIR,100)
RandomBlock(-7,50,0,STAINED_GLASS_PANE:15,40,AIR,100)
RandomBlock(-7,50,7,STAINED_GLASS_PANE:15,40,AIR,100)
RandomBlock(-7,51,-3,STAINED_GLASS:15,40,AIR,100)
RandomBlock(-7,52,-3,STAINED_GLASS:15,40,AIR,100)
RandomBlock(-7,52,-2,STAINED_GLASS:15,40,AIR,100)
RandomBlock(-7,52,-1,STAINED_GLASS:15,40,AIR,100)
RandomBlock(-7,52,0,STAINED_GLASS:15,40,AIR,100)
RandomBlock(-7,52,1,STAINED_GLASS:15,40,AIR,100)
RandomBlock(-7,52,2,STAINED_GLASS:15,40,AIR,100)
RandomBlock(-7,52,3,STAINED_GLASS:15,40,AIR,100)
RandomBlock(-7,52,4,STAINED_GLASS:15,40,AIR,100)
RandomBlock(-7,53,4,STAINED_GLASS:15,40,AIR,100)
RandomBlock(-7,54,4,STAINED_GLASS:15,40,AIR,100)
RandomBlock(-7,55,4,STAINED_GLASS:15,40,AIR,100)
RandomBlock(-7,56,4,STAINED_GLASS:15,40,AIR,100)
RandomBlock(-7,56,5,CONCRETE:7,60,quark:iron_plate:1,20,STAINED_CLAY:12,15,STAINED_CLAY:15,5,AIR,7,IRON_BARS,12,CONCRETE:7,100)
RandomBlock(-7,56,6,STAINED_GLASS:15,40,AIR,100)
RandomBlock(-7,56,7,CONCRETE:7,60,quark:iron_plate:1,20,STAINED_CLAY:12,15,STAINED_CLAY:15,5,AIR,7,IRON_BARS,12,CONCRETE:7,100)
RandomBlock(-7,56,8,STAINED_GLASS:15,40,AIR,100)
RandomBlock(-7,57,5,CONCRETE:7,60,quark:iron_plate:1,20,STAINED_CLAY:12,15,STAINED_CLAY:15,5,AIR,7,IRON_BARS,12,CONCRETE:7,100)
RandomBlock(-7,57,7,CONCRETE:7,60,quark:iron_plate:1,20,STAINED_CLAY:12,15,STAINED_CLAY:15,5,AIR,7,IRON_BARS,12,CONCRETE:7,100)
RandomBlock(-6,0,-7,CONCRETE:7,60,quark:iron_plate:1,20,STAINED_CLAY:12,15,STAINED_CLAY:15,5,AIR,7,IRON_BARS,12,CONCRETE:7,100)
RandomBlock(-6,0,-6,CONCRETE:7,60,quark:iron_plate:1,20,STAINED_CLAY:12,15,STAINED_CLAY:15,5,AIR,7,IRON_BARS,12,CONCRETE:7,100)
RandomBlock(-6,0,-5,CONCRETE:7,60,quark:iron_plate:1,20,STAINED_CLAY:12,15,STAINED_CLAY:15,5,AIR,7,IRON_BARS,12,CONCRETE:7,100)
RandomBlock(-6,0,-4,CONCRETE:7,60,quark:iron_plate:1,20,STAINED_CLAY:12,15,STAINED_CLAY:15,5,AIR,7,IRON_BARS,12,CONCRETE:7,100)
RandomBlock(-6,0,-3,CONCRETE:7,60,quark:iron_plate:1,20,STAINED_CLAY:12,15,STAINED_CLAY:15,5,AIR,7,IRON_BARS,12,CONCRETE:7,100)
RandomBlock(-6,0,-2,CONCRETE:7,60,quark:iron_plate:1,20,STAINED_CLAY:12,15,STAINED_CLAY:15,5,AIR,7,IRON_BARS,12,CONCRETE:7,100)
RandomBlock(-6,0,-1,CONCRETE:7,60,quark:iron_plate:1,20,STAINED_CLAY:12,15,STAINED_CLAY:15,5,AIR,7,IRON_BARS,12,CONCRETE:7,100)
RandomBlock(-6,0,0,CONCRETE:7,60,quark:iron_plate:1,20,STAINED_CLAY:12,15,STAINED_CLAY:15,5,AIR,7,IRON_BARS,12,CONCRETE:7,100)
RandomBlock(-6,0,1,CONCRETE:7,60,quark:iron_plate:1,20,STAINED_CLAY:12,15,STAINED_CLAY:15,5,AIR,7,IRON_BARS,12,CONCRETE:7,100)
RandomBlock(-6,0,2,CONCRETE:7,60,quark:iron_plate:1,20,STAINED_CLAY:12,15,STAINED_CLAY:15,5,AIR,7,IRON_BARS,12,CONCRETE:7,100)
RandomBlock(-6,0,3,CONCRETE:7,60,quark:iron_plate:1,20,STAINED_CLAY:12,15,STAINED_CLAY:15,5,AIR,7,IRON_BARS,12,CONCRETE:7,100)
RandomBlock(-6,0,4,CONCRETE:7,60,quark:iron_plate:1,20,STAINED_CLAY:12,15,STAINED_CLAY:15,5,AIR,7,IRON_BARS,12,CONCRETE:7,100)
RandomBlock(-6,0,5,CONCRETE:7,60,quark:iron_plate:1,20,STAINED_CLAY:12,15,STAINED_CLAY:15,5,AIR,7,IRON_BARS,12,CONCRETE:7,100)
RandomBlock(-6,0,6,CONCRETE:7,60,quark:iron_plate:1,20,STAINED_CLAY:12,15,STAINED_CLAY:15,5,AIR,7,IRON_BARS,12,CONCRETE:7,100)
RandomBlock(-6,0,7,CONCRETE:7,60,quark:iron_plate:1,20,STAINED_CLAY:12,15,STAINED_CLAY:15,5,AIR,7,IRON_BARS,12,CONCRETE:7,100)
RandomBlock(-6,0,8,CONCRETE:7,60,quark:iron_plate:1,20,STAINED_CLAY:12,15,STAINED_CLAY:15,5,AIR,7,IRON_BARS,12,CONCRETE:7,100)
RandomBlock(-6,1,-7,CONCRETE:7,60,quark:iron_plate:1,20,STAINED_CLAY:12,15,STAINED_CLAY:15,5,AIR,7,IRON_BARS,12,CONCRETE:7,100)
RandomBlock(-6,1,-6,CONCRETE:7,60,quark:iron_plate:1,20,STAINED_CLAY:12,15,STAINED_CLAY:15,5,AIR,7,IRON_BARS,12,CONCRETE:7,100)
RandomBlock(-6,1,-5,CONCRETE:7,60,quark:iron_plate:1,20,STAINED_CLAY:12,15,STAINED_CLAY:15,5,AIR,7,IRON_BARS,12,CONCRETE:7,100)
RandomBlock(-6,1,-4,CONCRETE:7,60,quark:iron_plate:1,20,STAINED_CLAY:12,15,STAINED_CLAY:15,5,AIR,7,IRON_BARS,12,CONCRETE:7,100)
RandomBlock(-6,1,-3,CONCRETE:7,60,quark:iron_plate:1,20,STAINED_CLAY:12,15,STAINED_CLAY:15,5,AIR,7,IRON_BARS,12,CONCRETE:7,100)
RandomBlock(-6,1,-2,CONCRETE:7,60,quark:iron_plate:1,20,STAINED_CLAY:12,15,STAINED_CLAY:15,5,AIR,7,IRON_BARS,12,CONCRETE:7,100)
RandomBlock(-6,1,-1,CONCRETE:7,60,quark:iron_plate:1,20,STAINED_CLAY:12,15,STAINED_CLAY:15,5,AIR,7,IRON_BARS,12,CONCRETE:7,100)
RandomBlock(-6,1,0,CONCRETE:7,60,quark:iron_plate:1,20,STAINED_CLAY:12,15,STAINED_CLAY:15,5,AIR,7,IRON_BARS,12,CONCRETE:7,100)
RandomBlock(-6,1,1,CONCRETE:7,60,quark:iron_plate:1,20,STAINED_CLAY:12,15,STAINED_CLAY:15,5,AIR,7,IRON_BARS,12,CONCRETE:7,100)
RandomBlock(-6,1,2,CONCRETE:7,60,quark:iron_plate:1,20,STAINED_CLAY:12,15,STAINED_CLAY:15,5,AIR,7,IRON_BARS,12,CONCRETE:7,100)
Block(-6,1,3,STATIONARY_WATER:0)
Block(-6,1,4,STATIONARY_WATER:0)
RandomBlock(-6,1,5,CONCRETE:7,60,quark:iron_plate:1,20,STAINED_CLAY:12,15,STAINED_CLAY:15,5,AIR,7,IRON_BARS,12,CONCRETE:7,100)
RandomBlock(-6,1,6,CONCRETE:7,60,quark:iron_plate:1,20,STAINED_CLAY:12,15,STAINED_CLAY:15,5,AIR,7,IRON_BARS,12,CONCRETE:7,100)
RandomBlock(-6,1,7,CONCRETE:7,60,quark:iron_plate:1,20,STAINED_CLAY:12,15,STAINED_CLAY:15,5,AIR,7,IRON_BARS,12,CONCRETE:7,100)
RandomBlock(-6,1,8,CONCRETE:7,60,quark:iron_plate:1,20,STAINED_CLAY:12,15,STAINED_CLAY:15,5,AIR,7,IRON_BARS,12,CONCRETE:7,100)
Block(-6,2,-7,SMOOTH_STAIRS:1)
Block(-6,2,-6,SMOOTH_STAIRS:1)
Block(-6,2,-5,SMOOTH_STAIRS:1)
Block(-6,2,-4,SMOOTH_STAIRS:1)
Block(-6,2,-3,SMOOTH_STAIRS:1)
Block(-6,2,-2,SMOOTH_STAIRS:1)
Block(-6,2,-1,SMOOTH_STAIRS:1)
Block(-6,2,0,SMOOTH_STAIRS:1)
Block(-6,2,1,SMOOTH_STAIRS:1)
Block(-6,2,2,SMOOTH_STAIRS:1)
Block(-6,2,5,SMOOTH_STAIRS:1)
Block(-6,2,6,SMOOTH_STAIRS:1)
Block(-6,2,7,SMOOTH_STAIRS:1)
Block(-6,2,8,SMOOTH_STAIRS:1)
Block(-6,5,6,CONCRETE:12)
Block(-6,5,7,CONCRETE:4)
RandomBlock(-6,6,-7,CONCRETE:7,60,quark:iron_plate:1,20,STAINED_CLAY:12,15,STAINED_CLAY:15,5,AIR,7,IRON_BARS,12,CONCRETE:7,100)
RandomBlock(-6,7,-7,CONCRETE:7,60,quark:iron_plate:1,20,STAINED_CLAY:12,15,STAINED_CLAY:15,5,AIR,7,IRON_BARS,12,CONCRETE:7,100)
RandomBlock(-6,7,-6,CONCRETE:7,60,quark:iron_plate:1,20,STAINED_CLAY:12,15,STAINED_CLAY:15,5,AIR,7,IRON_BARS,12,CONCRETE:7,100)
RandomBlock(-6,7,-5,CONCRETE:7,60,quark:iron_plate:1,20,STAINED_CLAY:12,15,STAINED_CLAY:15,5,AIR,7,IRON_BARS,12,CONCRETE:7,100)
RandomBlock(-6,7,-4,CONCRETE:7,60,quark:iron_plate:1,20,STAINED_CLAY:12,15,STAINED_CLAY:15,5,AIR,7,IRON_BARS,12,CONCRETE:7,100)
RandomBlock(-6,7,-3,CONCRETE:7,60,quark:iron_plate:1,20,STAINED_CLAY:12,15,STAINED_CLAY:15,5,AIR,7,IRON_BARS,12,CONCRETE:7,100)
RandomBlock(-6,7,-2,CONCRETE:7,60,quark:iron_plate:1,20,STAINED_CLAY:12,15,STAINED_CLAY:15,5,AIR,7,IRON_BARS,12,CONCRETE:7,100)
RandomBlock(-6,7,-1,CONCRETE:7,60,quark:iron_plate:1,20,STAINED_CLAY:12,15,STAINED_CLAY:15,5,AIR,7,IRON_BARS,12,CONCRETE:7,100)
RandomBlock(-6,7,0,CONCRETE:7,60,quark:iron_plate:1,20,STAINED_CLAY:12,15,STAINED_CLAY:15,5,AIR,7,IRON_BARS,12,CONCRETE:7,100)
RandomBlock(-6,7,1,CONCRETE:7,60,quark:iron_plate:1,20,STAINED_CLAY:12,15,STAINED_CLAY:15,5,AIR,7,IRON_BARS,12,CONCRETE:7,100)
RandomBlock(-6,7,2,CONCRETE:7,60,quark:iron_plate:1,20,STAINED_CLAY:12,15,STAINED_CLAY:15,5,AIR,7,IRON_BARS,12,CONCRETE:7,100)
RandomBlock(-6,7,3,CONCRETE:7,60,quark:iron_plate:1,20,STAINED_CLAY:12,15,STAINED_CLAY:15,5,AIR,7,IRON_BARS,12,CONCRETE:7,100)
RandomBlock(-6,7,4,CONCRETE:7,60,quark:iron_plate:1,20,STAINED_CLAY:12,15,STAINED_CLAY:15,5,AIR,7,IRON_BARS,12,CONCRETE:7,100)
RandomBlock(-6,7,5,CONCRETE:7,60,quark:iron_plate:1,20,STAINED_CLAY:12,15,STAINED_CLAY:15,5,AIR,7,IRON_BARS,12,CONCRETE:7,100)
RandomBlock(-6,7,6,CONCRETE:7,60,quark:iron_plate:1,20,STAINED_CLAY:12,15,STAINED_CLAY:15,5,AIR,7,IRON_BARS,12,CONCRETE:7,100)
RandomBlock(-6,7,7,CONCRETE:7,60,quark:iron_plate:1,20,STAINED_CLAY:12,15,STAINED_CLAY:15,5,AIR,7,IRON_BARS,12,CONCRETE:7,100)
RandomBlock(-6,7,8,CONCRETE:7,60,quark:iron_plate:1,20,STAINED_CLAY:12,15,STAINED_CLAY:15,5,AIR,7,IRON_BARS,12,CONCRETE:7,100)
RandomBlock(-6,8,-7,CONCRETE:7,60,quark:iron_plate:1,20,STAINED_CLAY:12,15,STAINED_CLAY:15,5,AIR,7,IRON_BARS,12,CONCRETE:7,100)
RandomBlock(-6,8,-6,CONCRETE:7,60,quark:iron_plate:1,20,STAINED_CLAY:12,15,STAINED_CLAY:15,5,AIR,7,IRON_BARS,12,CONCRETE:7,100)
RandomBlock(-6,8,-5,CONCRETE:7,60,quark:iron_plate:1,20,STAINED_CLAY:12,15,STAINED_CLAY:15,5,AIR,7,IRON_BARS,12,CONCRETE:7,100)
RandomBlock(-6,8,-4,CONCRETE:7,60,quark:iron_plate:1,20,STAINED_CLAY:12,15,STAINED_CLAY:15,5,AIR,7,IRON_BARS,12,CONCRETE:7,100)
RandomBlock(-6,8,-3,CONCRETE:7,60,quark:iron_plate:1,20,STAINED_CLAY:12,15,STAINED_CLAY:15,5,AIR,7,IRON_BARS,12,CONCRETE:7,100)
RandomBlock(-6,8,-2,CONCRETE:7,60,quark:iron_plate:1,20,STAINED_CLAY:12,15,STAINED_CLAY:15,5,AIR,7,IRON_BARS,12,CONCRETE:7,100)
RandomBlock(-6,8,-1,AIR,90,IRON_TRAPDOOR:9,100)
RandomBlock(-6,8,3,CONCRETE:7,60,quark:iron_plate:1,20,STAINED_CLAY:12,15,STAINED_CLAY:15,5,AIR,7,IRON_BARS,12,CONCRETE:7,100)
RandomBlock(-6,8,4,CONCRETE:7,60,quark:iron_plate:1,20,STAINED_CLAY:12,15,STAINED_CLAY:15,5,AIR,7,IRON_BARS,12,CONCRETE:7,100)
Block(-6,8,7,COBBLE_WALL:0)
RandomBlock(-6,9,-7,CONCRETE:7,60,quark:iron_plate:1,20,STAINED_CLAY:12,15,STAINED_CLAY:15,5,AIR,7,IRON_BARS,12,CONCRETE:7,100)
RandomBlock(-6,9,-6,CONCRETE:7,60,quark:iron_plate:1,20,STAINED_CLAY:12,15,STAINED_CLAY:15,5,AIR,7,IRON_BARS,12,CONCRETE:7,100)
RandomBlock(-6,9,-5,CONCRETE:7,60,quark:iron_plate:1,20,STAINED_CLAY:12,15,STAINED_CLAY:15,5,AIR,7,IRON_BARS,12,CONCRETE:7,100)
RandomBlock(-6,9,-4,CONCRETE:7,60,quark:iron_plate:1,20,STAINED_CLAY:12,15,STAINED_CLAY:15,5,AIR,7,IRON_BARS,12,CONCRETE:7,100)
RandomBlock(-6,9,-3,CONCRETE:7,60,quark:iron_plate:1,20,STAINED_CLAY:12,15,STAINED_CLAY:15,5,AIR,7,IRON_BARS,12,CONCRETE:7,100)
RandomBlock(-6,9,-2,CONCRETE:7,60,quark:iron_plate:1,20,STAINED_CLAY:12,15,STAINED_CLAY:15,5,AIR,7,IRON_BARS,12,CONCRETE:7,100)
#RandomBlock(-6,9,-1,AIR:0,30,CHEST:5,../../../../../Chests/Loot/manhunt_urban_junk.nbt,10,CHEST:5,../../../../../Chests/Loot/manhunt_infected_cache.nbt,5,CHEST:5,../../../../../Chests/Loot/manhunt_urban_junk.nbt,65,CHEST:3,../../../../../Chests/Loot/manhunt_urban_junk.nbt,20,CHEST:3,../../../../../Chests/Loot/manhunt_residential_common.nbt,5,CHEST:3,../../../../../Chests/Loot/manhunt_residential_useful.nbt,3,CHEST:3,../../../../../Chests/Loot/manhunt_human_strategic_cache.nbt,1,CHEST:3,../../../../../Chests/Loot/manhunt_urban_junk.nbt,100)
RandomBlock(-6,9,3,CONCRETE:7,60,quark:iron_plate:1,20,STAINED_CLAY:12,15,STAINED_CLAY:15,5,AIR,7,IRON_BARS,12,CONCRETE:7,100)
RandomBlock(-6,9,4,CONCRETE:7,60,quark:iron_plate:1,20,STAINED_CLAY:12,15,STAINED_CLAY:15,5,AIR,7,IRON_BARS,12,CONCRETE:7,100)
Block(-6,9,7,COBBLE_WALL:0)
RandomBlock(-6,10,-7,CONCRETE:7,60,quark:iron_plate:1,20,STAINED_CLAY:12,15,STAINED_CLAY:15,5,AIR,7,IRON_BARS,12,CONCRETE:7,100)
RandomBlock(-6,10,-6,CONCRETE:7,60,quark:iron_plate:1,20,STAINED_CLAY:12,15,STAINED_CLAY:15,5,AIR,7,IRON_BARS,12,CONCRETE:7,100)
RandomBlock(-6,10,-5,CONCRETE:7,60,quark:iron_plate:1,20,STAINED_CLAY:12,15,STAINED_CLAY:15,5,AIR,7,IRON_BARS,12,CONCRETE:7,100)
RandomBlock(-6,10,-4,CONCRETE:7,60,quark:iron_plate:1,20,STAINED_CLAY:12,15,STAINED_CLAY:15,5,AIR,7,IRON_BARS,12,CONCRETE:7,100)
RandomBlock(-6,10,-3,CONCRETE:7,60,quark:iron_plate:1,20,STAINED_CLAY:12,15,STAINED_CLAY:15,5,AIR,7,IRON_BARS,12,CONCRETE:7,100)
RandomBlock(-6,10,-2,CONCRETE:7,60,quark:iron_plate:1,20,STAINED_CLAY:12,15,STAINED_CLAY:15,5,AIR,7,IRON_BARS,12,CONCRETE:7,100)
Block(-6,10,1,CONCRETE:12)
RandomBlock(-6,10,3,CONCRETE:7,60,quark:iron_plate:1,20,STAINED_CLAY:12,15,STAINED_CLAY:15,5,AIR,7,IRON_BARS,12,CONCRETE:7,100)
RandomBlock(-6,10,4,CONCRETE:7,60,quark:iron_plate:1,20,STAINED_CLAY:12,15,STAINED_CLAY:15,5,AIR,7,IRON_BARS,12,CONCRETE:7,100)
Block(-6,10,5,CONCRETE:12)
Block(-6,10,7,CONCRETE:12)
RandomBlock(-6,11,-7,CONCRETE:7,60,quark:iron_plate:1,20,STAINED_CLAY:12,15,STAINED_CLAY:15,5,AIR,7,IRON_BARS,12,CONCRETE:7,100)
RandomBlock(-6,11,-6,CONCRETE:7,60,quark:iron_plate:1,20,STAINED_CLAY:12,15,STAINED_CLAY:15,5,AIR,7,IRON_BARS,12,CONCRETE:7,100)
RandomBlock(-6,11,-5,CONCRETE:7,60,quark:iron_plate:1,20,STAINED_CLAY:12,15,STAINED_CLAY:15,5,AIR,7,IRON_BARS,12,CONCRETE:7,100)
RandomBlock(-6,11,-4,CONCRETE:7,60,quark:iron_plate:1,20,STAINED_CLAY:12,15,STAINED_CLAY:15,5,AIR,7,IRON_BARS,12,CONCRETE:7,100)
RandomBlock(-6,11,-3,CONCRETE:7,60,quark:iron_plate:1,20,STAINED_CLAY:12,15,STAINED_CLAY:15,5,AIR,7,IRON_BARS,12,CONCRETE:7,100)
RandomBlock(-6,11,-2,CONCRETE:7,60,quark:iron_plate:1,20,STAINED_CLAY:12,15,STAINED_CLAY:15,5,AIR,7,IRON_BARS,12,CONCRETE:7,100)
RandomBlock(-6,11,-1,CONCRETE:7,60,quark:iron_plate:1,20,STAINED_CLAY:12,15,STAINED_CLAY:15,5,AIR,7,IRON_BARS,12,CONCRETE:7,100)
RandomBlock(-6,11,0,CONCRETE:7,60,quark:iron_plate:1,20,STAINED_CLAY:12,15,STAINED_CLAY:15,5,AIR,7,IRON_BARS,12,CONCRETE:7,100)
RandomBlock(-6,11,1,CONCRETE:7,60,quark:iron_plate:1,20,STAINED_CLAY:12,15,STAINED_CLAY:15,5,AIR,7,IRON_BARS,12,CONCRETE:7,100)
RandomBlock(-6,11,2,CONCRETE:7,60,quark:iron_plate:1,20,STAINED_CLAY:12,15,STAINED_CLAY:15,5,AIR,7,IRON_BARS,12,CONCRETE:7,100)
RandomBlock(-6,11,3,CONCRETE:7,60,quark:iron_plate:1,20,STAINED_CLAY:12,15,STAINED_CLAY:15,5,AIR,7,IRON_BARS,12,CONCRETE:7,100)
RandomBlock(-6,11,4,CONCRETE:7,60,quark:iron_plate:1,20,STAINED_CLAY:12,15,STAINED_CLAY:15,5,AIR,7,IRON_BARS,12,CONCRETE:7,100)
RandomBlock(-6,11,5,CONCRETE:7,60,quark:iron_plate:1,20,STAINED_CLAY:12,15,STAINED_CLAY:15,5,AIR,7,IRON_BARS,12,CONCRETE:7,100)
RandomBlock(-6,11,6,CONCRETE:7,60,quark:iron_plate:1,20,STAINED_CLAY:12,15,STAINED_CLAY:15,5,AIR,7,IRON_BARS,12,CONCRETE:7,100)
RandomBlock(-6,11,7,CONCRETE:7,60,quark:iron_plate:1,20,STAINED_CLAY:12,15,STAINED_CLAY:15,5,AIR,7,IRON_BARS,12,CONCRETE:7,100)
RandomBlock(-6,11,8,CONCRETE:7,60,quark:iron_plate:1,20,STAINED_CLAY:12,15,STAINED_CLAY:15,5,AIR,7,IRON_BARS,12,CONCRETE:7,100)
RandomBlock(-6,12,-7,CONCRETE:7,60,quark:iron_plate:1,20,STAINED_CLAY:12,15,STAINED_CLAY:15,5,AIR,7,IRON_BARS,12,CONCRETE:7,100)
RandomBlock(-6,12,-3,AIR,90,IRON_TRAPDOOR:8,100)
RandomBlock(-6,12,-2,CONCRETE:7,60,quark:iron_plate:1,20,STAINED_CLAY:12,15,STAINED_CLAY:15,5,AIR,7,IRON_BARS,12,CONCRETE:7,100)
RandomBlock(-6,12,-1,CONCRETE:8,60,minecraft:stone,15,STONE:5,15,STAINED_CLAY:9,10,IRON_BARS,12,AIR,8,STAINED_CLAY:12,30,CONCRETE:8,100)
RandomBlock(-6,12,0,STONE:6,85,CAULDRON:3,100)
RandomBlock(-6,12,4,CONCRETE:8,60,minecraft:stone,15,STONE:5,15,STAINED_CLAY:9,10,IRON_BARS,12,AIR,8,STAINED_CLAY:12,30,CONCRETE:8,100)
RandomBlock(-6,12,5,CONCRETE:8,60,minecraft:stone,15,STONE:5,15,STAINED_CLAY:9,10,IRON_BARS,12,AIR,8,STAINED_CLAY:12,30,CONCRETE:8,100)
RandomBlock(-6,12,6,CONCRETE:8,60,minecraft:stone,15,STONE:5,15,STAINED_CLAY:9,10,IRON_BARS,12,AIR,8,STAINED_CLAY:12,30,CONCRETE:8,100)
RandomBlock(-6,12,7,CONCRETE:8,60,minecraft:stone,15,STONE:5,15,STAINED_CLAY:9,10,IRON_BARS,12,AIR,8,STAINED_CLAY:12,30,CONCRETE:8,100)
RandomBlock(-6,12,8,CONCRETE:8,60,minecraft:stone,15,STONE:5,15,STAINED_CLAY:9,10,IRON_BARS,12,AIR,8,STAINED_CLAY:12,30,CONCRETE:8,100)
RandomBlock(-6,13,-7,CONCRETE:7,60,quark:iron_plate:1,20,STAINED_CLAY:12,15,STAINED_CLAY:15,5,AIR,7,IRON_BARS,12,CONCRETE:7,100)
RandomBlock(-6,13,-2,CONCRETE:7,60,quark:iron_plate:1,20,STAINED_CLAY:12,15,STAINED_CLAY:15,5,AIR,7,IRON_BARS,12,CONCRETE:7,100)
RandomBlock(-6,13,-1,CONCRETE:8,60,minecraft:stone,15,STONE:5,15,STAINED_CLAY:9,10,IRON_BARS,12,AIR,8,STAINED_CLAY:12,30,CONCRETE:8,100)
Block(-6,13,0,TRIPWIRE_HOOK:0)
RandomBlock(-6,13,4,CONCRETE:8,60,minecraft:stone,15,STONE:5,15,STAINED_CLAY:9,10,IRON_BARS,12,AIR,8,STAINED_CLAY:12,30,CONCRETE:8,100)
RandomBlock(-6,13,5,CONCRETE:8,60,minecraft:stone,15,STONE:5,15,STAINED_CLAY:9,10,IRON_BARS,12,AIR,8,STAINED_CLAY:12,30,CONCRETE:8,100)
RandomBlock(-6,13,6,CONCRETE:8,60,minecraft:stone,15,STONE:5,15,STAINED_CLAY:9,10,IRON_BARS,12,AIR,8,STAINED_CLAY:12,30,CONCRETE:8,100)
RandomBlock(-6,13,7,CONCRETE:8,60,minecraft:stone,15,STONE:5,15,STAINED_CLAY:9,10,IRON_BARS,12,AIR,8,STAINED_CLAY:12,30,CONCRETE:8,100)
RandomBlock(-6,13,8,CONCRETE:8,60,minecraft:stone,15,STONE:5,15,STAINED_CLAY:9,10,IRON_BARS,12,AIR,8,STAINED_CLAY:12,30,CONCRETE:8,100)
RandomBlock(-6,14,-7,CONCRETE:7,60,quark:iron_plate:1,20,STAINED_CLAY:12,15,STAINED_CLAY:15,5,AIR,7,IRON_BARS,12,CONCRETE:7,100)
RandomBlock(-6,14,-2,CONCRETE:7,60,quark:iron_plate:1,20,STAINED_CLAY:12,15,STAINED_CLAY:15,5,AIR,7,IRON_BARS,12,CONCRETE:7,100)
RandomBlock(-6,14,-1,CONCRETE:8,60,minecraft:stone,15,STONE:5,15,STAINED_CLAY:9,10,IRON_BARS,12,AIR,8,STAINED_CLAY:12,30,CONCRETE:8,100)
RandomBlock(-6,14,4,CONCRETE:8,60,minecraft:stone,15,STONE:5,15,STAINED_CLAY:9,10,IRON_BARS,12,AIR,8,STAINED_CLAY:12,30,CONCRETE:8,100)
RandomBlock(-6,14,5,CONCRETE:8,60,minecraft:stone,15,STONE:5,15,STAINED_CLAY:9,10,IRON_BARS,12,AIR,8,STAINED_CLAY:12,30,CONCRETE:8,100)
RandomBlock(-6,14,6,CONCRETE:8,60,minecraft:stone,15,STONE:5,15,STAINED_CLAY:9,10,IRON_BARS,12,AIR,8,STAINED_CLAY:12,30,CONCRETE:8,100)
RandomBlock(-6,14,7,CONCRETE:8,60,minecraft:stone,15,STONE:5,15,STAINED_CLAY:9,10,IRON_BARS,12,AIR,8,STAINED_CLAY:12,30,CONCRETE:8,100)
RandomBlock(-6,14,8,CONCRETE:8,60,minecraft:stone,15,STONE:5,15,STAINED_CLAY:9,10,IRON_BARS,12,AIR,8,STAINED_CLAY:12,30,CONCRETE:8,100)
RandomBlock(-6,15,-7,CONCRETE:7,60,quark:iron_plate:1,20,STAINED_CLAY:12,15,STAINED_CLAY:15,5,AIR,7,IRON_BARS,12,CONCRETE:7,100)
RandomBlock(-6,15,-2,CONCRETE:7,60,quark:iron_plate:1,20,STAINED_CLAY:12,15,STAINED_CLAY:15,5,AIR,7,IRON_BARS,12,CONCRETE:7,100)
RandomBlock(-6,15,-1,CONCRETE:8,60,minecraft:stone,15,STONE:5,15,STAINED_CLAY:9,10,IRON_BARS,12,AIR,8,STAINED_CLAY:12,30,CONCRETE:8,100)
RandomBlock(-6,15,0,AIR,90,IRON_TRAPDOOR:9,100)
RandomBlock(-6,15,4,CONCRETE:8,60,minecraft:stone,15,STONE:5,15,STAINED_CLAY:9,10,IRON_BARS,12,AIR,8,STAINED_CLAY:12,30,CONCRETE:8,100)
RandomBlock(-6,15,5,CONCRETE:8,60,minecraft:stone,15,STONE:5,15,STAINED_CLAY:9,10,IRON_BARS,12,AIR,8,STAINED_CLAY:12,30,CONCRETE:8,100)
RandomBlock(-6,15,6,CONCRETE:8,60,minecraft:stone,15,STONE:5,15,STAINED_CLAY:9,10,IRON_BARS,12,AIR,8,STAINED_CLAY:12,30,CONCRETE:8,100)
RandomBlock(-6,15,7,CONCRETE:8,60,minecraft:stone,15,STONE:5,15,STAINED_CLAY:9,10,IRON_BARS,12,AIR,8,STAINED_CLAY:12,30,CONCRETE:8,100)
RandomBlock(-6,15,8,CONCRETE:8,60,minecraft:stone,15,STONE:5,15,STAINED_CLAY:9,10,IRON_BARS,12,AIR,8,STAINED_CLAY:12,30,CONCRETE:8,100)
RandomBlock(-6,16,-7,CONCRETE:7,60,quark:iron_plate:1,20,STAINED_CLAY:12,15,STAINED_CLAY:15,5,AIR,7,IRON_BARS,12,CONCRETE:7,100)
RandomBlock(-6,16,-6,CONCRETE:7,60,quark:iron_plate:1,20,STAINED_CLAY:12,15,STAINED_CLAY:15,5,AIR,7,IRON_BARS,12,CONCRETE:7,100)
RandomBlock(-6,16,-5,CONCRETE:7,60,quark:iron_plate:1,20,STAINED_CLAY:12,15,STAINED_CLAY:15,5,AIR,7,IRON_BARS,12,CONCRETE:7,100)
RandomBlock(-6,16,-4,CONCRETE:7,60,quark:iron_plate:1,20,STAINED_CLAY:12,15,STAINED_CLAY:15,5,AIR,7,IRON_BARS,12,CONCRETE:7,100)
RandomBlock(-6,16,-3,CONCRETE:7,60,quark:iron_plate:1,20,STAINED_CLAY:12,15,STAINED_CLAY:15,5,AIR,7,IRON_BARS,12,CONCRETE:7,100)
RandomBlock(-6,16,-2,CONCRETE:7,60,quark:iron_plate:1,20,STAINED_CLAY:12,15,STAINED_CLAY:15,5,AIR,7,IRON_BARS,12,CONCRETE:7,100)
RandomBlock(-6,16,-1,CONCRETE:7,60,quark:iron_plate:1,20,STAINED_CLAY:12,15,STAINED_CLAY:15,5,AIR,7,IRON_BARS,12,CONCRETE:7,100)
RandomBlock(-6,16,0,CONCRETE:7,60,quark:iron_plate:1,20,STAINED_CLAY:12,15,STAINED_CLAY:15,5,AIR,7,IRON_BARS,12,CONCRETE:7,100)
RandomBlock(-6,16,1,CONCRETE:7,60,quark:iron_plate:1,20,STAINED_CLAY:12,15,STAINED_CLAY:15,5,AIR,7,IRON_BARS,12,CONCRETE:7,100)
RandomBlock(-6,16,2,CONCRETE:7,60,quark:iron_plate:1,20,STAINED_CLAY:12,15,STAINED_CLAY:15,5,AIR,7,IRON_BARS,12,CONCRETE:7,100)
RandomBlock(-6,16,3,CONCRETE:7,60,quark:iron_plate:1,20,STAINED_CLAY:12,15,STAINED_CLAY:15,5,AIR,7,IRON_BARS,12,CONCRETE:7,100)
RandomBlock(-6,16,4,CONCRETE:7,60,quark:iron_plate:1,20,STAINED_CLAY:12,15,STAINED_CLAY:15,5,AIR,7,IRON_BARS,12,CONCRETE:7,100)
RandomBlock(-6,16,5,CONCRETE:7,60,quark:iron_plate:1,20,STAINED_CLAY:12,15,STAINED_CLAY:15,5,AIR,7,IRON_BARS,12,CONCRETE:7,100)
RandomBlock(-6,16,6,CONCRETE:7,60,quark:iron_plate:1,20,STAINED_CLAY:12,15,STAINED_CLAY:15,5,AIR,7,IRON_BARS,12,CONCRETE:7,100)
RandomBlock(-6,16,7,CONCRETE:7,60,quark:iron_plate:1,20,STAINED_CLAY:12,15,STAINED_CLAY:15,5,AIR,7,IRON_BARS,12,CONCRETE:7,100)
RandomBlock(-6,16,8,CONCRETE:7,60,quark:iron_plate:1,20,STAINED_CLAY:12,15,STAINED_CLAY:15,5,AIR,7,IRON_BARS,12,CONCRETE:7,100)
RandomBlock(-6,17,-7,CONCRETE:7,60,quark:iron_plate:1,20,STAINED_CLAY:12,15,STAINED_CLAY:15,5,AIR,7,IRON_BARS,12,CONCRETE:7,100)
RandomBlock(-6,17,-6,CONCRETE:7,60,quark:iron_plate:1,20,STAINED_CLAY:12,15,STAINED_CLAY:15,5,AIR,7,IRON_BARS,12,CONCRETE:7,100)
RandomBlock(-6,17,-5,CONCRETE:7,60,quark:iron_plate:1,20,STAINED_CLAY:12,15,STAINED_CLAY:15,5,AIR,7,IRON_BARS,12,CONCRETE:7,100)
RandomBlock(-6,17,-4,CONCRETE:7,60,quark:iron_plate:1,20,STAINED_CLAY:12,15,STAINED_CLAY:15,5,AIR,7,IRON_BARS,12,CONCRETE:7,100)
RandomBlock(-6,17,-3,CONCRETE:7,60,quark:iron_plate:1,20,STAINED_CLAY:12,15,STAINED_CLAY:15,5,AIR,7,IRON_BARS,12,CONCRETE:7,100)
RandomBlock(-6,17,-2,CONCRETE:7,60,quark:iron_plate:1,20,STAINED_CLAY:12,15,STAINED_CLAY:15,5,AIR,7,IRON_BARS,12,CONCRETE:7,100)
RandomBlock(-6,17,-1,CONCRETE:7,60,quark:iron_plate:1,20,STAINED_CLAY:12,15,STAINED_CLAY:15,5,AIR,7,IRON_BARS,12,CONCRETE:7,100)
RandomBlock(-6,17,0,CONCRETE:7,60,quark:iron_plate:1,20,STAINED_CLAY:12,15,STAINED_CLAY:15,5,AIR,7,IRON_BARS,12,CONCRETE:7,100)
RandomBlock(-6,17,1,CONCRETE:7,60,quark:iron_plate:1,20,STAINED_CLAY:12,15,STAINED_CLAY:15,5,AIR,7,IRON_BARS,12,CONCRETE:7,100)
RandomBlock(-6,17,2,CONCRETE:8,60,minecraft:stone,15,STONE:5,15,STAINED_CLAY:9,10,IRON_BARS,12,AIR,8,STAINED_CLAY:12,30,CONCRETE:8,100)
RandomBlock(-6,17,3,CONCRETE:7,60,quark:iron_plate:1,20,STAINED_CLAY:12,15,STAINED_CLAY:15,5,AIR,7,IRON_BARS,12,CONCRETE:7,100)
RandomBlock(-6,17,4,CONCRETE:7,60,quark:iron_plate:1,20,STAINED_CLAY:12,15,STAINED_CLAY:15,5,AIR,7,IRON_BARS,12,CONCRETE:7,100)
RandomBlock(-6,17,5,CONCRETE:7,60,quark:iron_plate:1,20,STAINED_CLAY:12,15,STAINED_CLAY:15,5,AIR,7,IRON_BARS,12,CONCRETE:7,100)
RandomBlock(-6,17,6,CONCRETE:7,60,quark:iron_plate:1,20,STAINED_CLAY:12,15,STAINED_CLAY:15,5,AIR,7,IRON_BARS,12,CONCRETE:7,100)
RandomBlock(-6,17,7,CONCRETE:7,60,quark:iron_plate:1,20,STAINED_CLAY:12,15,STAINED_CLAY:15,5,AIR,7,IRON_BARS,12,CONCRETE:7,100)
RandomBlock(-6,17,8,CONCRETE:7,60,quark:iron_plate:1,20,STAINED_CLAY:12,15,STAINED_CLAY:15,5,AIR,7,IRON_BARS,12,CONCRETE:7,100)
RandomBlock(-6,18,-4,CONCRETE:8,60,minecraft:stone,15,STONE:5,15,STAINED_CLAY:9,10,IRON_BARS,12,AIR,8,STAINED_CLAY:12,30,CONCRETE:8,100)
RandomBlock(-6,18,-3,CONCRETE:7,60,quark:iron_plate:1,20,STAINED_CLAY:12,15,STAINED_CLAY:15,5,AIR,7,IRON_BARS,12,CONCRETE:7,100)
RandomBlock(-6,18,-1,STAINED_GLASS_PANE:15,40,AIR,100)
RandomBlock(-6,18,0,STAINED_GLASS_PANE:15,40,AIR,100)
RandomBlock(-6,18,4,CONCRETE:7,60,quark:iron_plate:1,20,STAINED_CLAY:12,15,STAINED_CLAY:15,5,AIR,7,IRON_BARS,12,CONCRETE:7,100)
RandomBlock(-6,18,7,CONCRETE:8,60,minecraft:stone,15,STONE:5,15,STAINED_CLAY:9,10,IRON_BARS,12,AIR,8,STAINED_CLAY:12,30,CONCRETE:8,100)
RandomBlock(-6,18,8,CONCRETE:8,60,minecraft:stone,15,STONE:5,15,STAINED_CLAY:9,10,IRON_BARS,12,AIR,8,STAINED_CLAY:12,30,CONCRETE:8,100)
RandomBlock(-6,19,-4,CONCRETE:8,60,minecraft:stone,15,STONE:5,15,STAINED_CLAY:9,10,IRON_BARS,12,AIR,8,STAINED_CLAY:12,30,CONCRETE:8,100)
RandomBlock(-6,19,-3,CONCRETE:7,60,quark:iron_plate:1,20,STAINED_CLAY:12,15,STAINED_CLAY:15,5,AIR,7,IRON_BARS,12,CONCRETE:7,100)
RandomBlock(-6,19,-1,STAINED_GLASS_PANE:15,40,AIR,100)
RandomBlock(-6,19,0,STAINED_GLASS_PANE:15,40,AIR,100)
RandomBlock(-6,19,4,CONCRETE:7,60,quark:iron_plate:1,20,STAINED_CLAY:12,15,STAINED_CLAY:15,5,AIR,7,IRON_BARS,12,CONCRETE:7,100)
RandomBlock(-6,19,7,CONCRETE:8,60,minecraft:stone,15,STONE:5,15,STAINED_CLAY:9,10,IRON_BARS,12,AIR,8,STAINED_CLAY:12,30,CONCRETE:8,100)
#RandomBlock(-6,19,8,AIR,95,STANDING_BANNER:12,../AllScraperData/skyscraper_2x2_03/363-bannerC16R0.nbt,100)
RandomBlock(-6,20,-4,CONCRETE:8,60,minecraft:stone,15,STONE:5,15,STAINED_CLAY:9,10,IRON_BARS,12,AIR,8,STAINED_CLAY:12,30,CONCRETE:8,100)
RandomBlock(-6,20,-3,CONCRETE:7,60,quark:iron_plate:1,20,STAINED_CLAY:12,15,STAINED_CLAY:15,5,AIR,7,IRON_BARS,12,CONCRETE:7,100)
RandomBlock(-6,20,4,CONCRETE:7,60,quark:iron_plate:1,20,STAINED_CLAY:12,15,STAINED_CLAY:15,5,AIR,7,IRON_BARS,12,CONCRETE:7,100)
RandomBlock(-6,20,7,CONCRETE:8,60,minecraft:stone,15,STONE:5,15,STAINED_CLAY:9,10,IRON_BARS,12,AIR,8,STAINED_CLAY:12,30,CONCRETE:8,100)
#Block(-6,21,7,WOOD_STEP:5)
#Block(-6,21,8,WOOD_STEP:5)
#Block(-6,23,-2,DARK_OAK_FENCE:0)
#Block(-6,23,0,DARK_OAK_FENCE:0)
#Block(-6,23,2,DARK_OAK_FENCE:0)
#Block(-6,24,-2,CARPET:8)
#Block(-6,24,0,CARPET:8)
#Block(-6,24,2,CARPET:8)
#Block(-6,32,-2,DARK_OAK_STAIRS:0)
#RandomBlock(-6,32,-1,AIR,90,WALL_SIGN:3,../AllScraperData/skyscraper_2x2_03/375-signC16R0.nbt,100)
#RandomBlock(-6,32,3,AIR,90,TRAP_DOOR:6,100)
