
#######################################################################
# +-----------------------------------------------------------------+ #
# |                            BO4 object                           | #
# +-----------------------------------------------------------------+ #
#######################################################################

Author: NLBlackEagle

Description: No description given

SettingsMode: WriteWithoutComments


#######################################################################
# +-----------------------------------------------------------------+ #
# |                          Main settings                          | #
# +-----------------------------------------------------------------+ #
#######################################################################

FixedRotation: 

Frequency: 0

SpawnHeight: highestBlock

UseCenterForHighestBlock: true

##############################
# Height Limits for the BO4. #
##############################

MinHeight: 0

MaxHeight: 255

InheritBO3: 

InheritBO3Rotation: NORTH

OverrideChildSettings: true

OverrideParentHeight: false

CanOverride: true

BranchFrequency: 0

BranchFrequencyGroup: 

MustBeBelowOther: false

MustBeInside: 

CannotBeInside: 

ReplacesBO3: 

MustBeInsideWorldBorders: true

CanSpawnOnWater: true

SpawnOnWaterOnly: false

SpawnUnderWater: false

SpawnAtWaterLevel: false

HeightOffset: 0

RemoveAir: false

ReplaceAbove: 

ReplaceBelow: 

ReplaceWithBiomeBlocks: true

ReplaceWithSurfaceBlock: GRASS

ReplaceWithGroundBlock: DIRT

ReplaceWithStoneBlock: STONE

SmoothRadius: 0

SmoothHeightOffset: 0

SmoothStartTop: false

SmoothStartWood: false

SmoothingSurfaceBlock: 

SmoothingGroundBlock: 

BO3Group: 

IsSpawnPoint: false

DoReplaceBlocks: false


#######################################################################
# +-----------------------------------------------------------------+ #
# |                              Blocks                             | #
# +-----------------------------------------------------------------+ #
#######################################################################

Block(-8,0,-5,quark:limestone:0)
Block(-8,0,-4,quark:limestone:0)
Block(-8,0,-3,quark:limestone:0)
Block(-8,0,-2,quark:limestone:0)
Block(-8,0,-1,quark:limestone:0)
Block(-8,1,-5,COBBLESTONE_STAIRS:0)
Block(-8,1,-4,COBBLESTONE_STAIRS:0)
Block(-8,1,-3,COBBLESTONE_STAIRS:0)
Block(-8,1,-2,COBBLESTONE_STAIRS:0)
Block(-8,1,-1,COBBLESTONE_STAIRS:3)
Block(-7,0,-5,quark:limestone:0)
RandomBlock(-7,0,-4,quark:iron_plate:1,70,STAINED_CLAY:15,30,STAINED_CLAY:7,30,quark:iron_plate:1,100)
RandomBlock(-7,0,-3,quark:iron_plate:1,70,STAINED_CLAY:15,30,STAINED_CLAY:7,30,quark:iron_plate:1,100)
RandomBlock(-7,0,-2,quark:iron_plate:1,70,STAINED_CLAY:15,30,STAINED_CLAY:7,30,quark:iron_plate:1,100)
Block(-7,0,-1,quark:limestone:0)
Block(-7,1,-5,COBBLESTONE_STAIRS:2)
RandomBlock(-7,1,-4,quark:iron_plate:1,70,STAINED_CLAY:15,30,STAINED_CLAY:7,30,quark:iron_plate:1,100)
RandomBlock(-7,1,-3,quark:iron_plate:1,70,STAINED_CLAY:15,30,STAINED_CLAY:7,30,quark:iron_plate:1,100)
RandomBlock(-7,1,-2,quark:iron_plate:1,70,STAINED_CLAY:15,30,STAINED_CLAY:7,30,quark:iron_plate:1,100)
Block(-7,1,-1,COBBLESTONE_STAIRS:3)
RandomBlock(-7,2,-4,IRON_FENCE:0,30,IRON_FENCE:0,30,LEAVES:7,30,quark:iron_plate_stairs:6,10,quark:iron_plate_stairs:0,10,quark:iron_plate_stairs:5,10,quark:iron_plate_stairs:3,10,quark:iron_plate_slab:8,10,quark:iron_plate_stairs:7,10,quark:iron_plate_stairs:1,10,quark:iron_plate_slab:0,10,quark:iron_plate_stairs:4,10,quark:iron_plate_stairs:2,10,IRON_FENCE:0,50,IRON_FENCE:0,50,LEAVES:7,100)
RandomBlock(-7,2,-3,quark:iron_plate:1,70,STAINED_CLAY:15,30,STAINED_CLAY:7,30,quark:iron_plate:1,100)
RandomBlock(-7,2,-2,quark:iron_plate:1,70,STAINED_CLAY:15,30,STAINED_CLAY:7,30,quark:iron_plate:1,100)
RandomBlock(-7,3,-4,quark:iron_plate:1,70,STAINED_CLAY:15,30,STAINED_CLAY:7,30,quark:iron_plate:1,100)
RandomBlock(-7,3,-3,quark:iron_plate:1,70,STAINED_CLAY:15,30,STAINED_CLAY:7,30,quark:iron_plate:1,100)
RandomBlock(-7,3,-2,IRON_FENCE:0,30,IRON_FENCE:0,30,LEAVES:7,30,quark:iron_plate_stairs:6,10,quark:iron_plate_stairs:0,10,quark:iron_plate_stairs:5,10,quark:iron_plate_stairs:3,10,quark:iron_plate_slab:8,10,quark:iron_plate_stairs:7,10,quark:iron_plate_stairs:1,10,quark:iron_plate_slab:0,10,quark:iron_plate_stairs:4,10,quark:iron_plate_stairs:2,10,IRON_FENCE:0,50,IRON_FENCE:0,50,LEAVES:7,100)
RandomBlock(-7,4,-4,quark:iron_plate:1,70,STAINED_CLAY:15,30,STAINED_CLAY:7,30,quark:iron_plate:1,100)
RandomBlock(-7,4,-3,quark:iron_plate:1,70,STAINED_CLAY:15,30,STAINED_CLAY:7,30,quark:iron_plate:1,100)
RandomBlock(-7,4,-2,IRON_FENCE:0,30,IRON_FENCE:0,30,LEAVES:7,30,quark:iron_plate_stairs:6,10,quark:iron_plate_stairs:0,10,quark:iron_plate_stairs:5,10,quark:iron_plate_stairs:3,10,quark:iron_plate_slab:8,10,quark:iron_plate_stairs:7,10,quark:iron_plate_stairs:1,10,quark:iron_plate_slab:0,10,quark:iron_plate_stairs:4,10,quark:iron_plate_stairs:2,10,IRON_FENCE:0,50,IRON_FENCE:0,50,LEAVES:7,100)
RandomBlock(-7,5,-4,IRON_FENCE:0,30,IRON_FENCE:0,30,LEAVES:7,30,quark:iron_plate_stairs:6,10,quark:iron_plate_stairs:0,10,quark:iron_plate_stairs:5,10,quark:iron_plate_stairs:3,10,quark:iron_plate_slab:8,10,quark:iron_plate_stairs:7,10,quark:iron_plate_stairs:1,10,quark:iron_plate_slab:0,10,quark:iron_plate_stairs:4,10,quark:iron_plate_stairs:2,10,IRON_FENCE:0,50,IRON_FENCE:0,50,LEAVES:7,100)
RandomBlock(-7,5,-3,quark:iron_plate:1,70,STAINED_CLAY:15,30,STAINED_CLAY:7,30,quark:iron_plate:1,100)
RandomBlock(-7,5,-2,IRON_FENCE:0,30,IRON_FENCE:0,30,LEAVES:7,30,quark:iron_plate_stairs:6,10,quark:iron_plate_stairs:0,10,quark:iron_plate_stairs:5,10,quark:iron_plate_stairs:3,10,quark:iron_plate_slab:8,10,quark:iron_plate_stairs:7,10,quark:iron_plate_stairs:1,10,quark:iron_plate_slab:0,10,quark:iron_plate_stairs:4,10,quark:iron_plate_stairs:2,10,IRON_FENCE:0,50,IRON_FENCE:0,50,LEAVES:7,100)
RandomBlock(-7,6,-4,IRON_FENCE:0,30,IRON_FENCE:0,30,LEAVES:7,30,quark:iron_plate_stairs:6,10,quark:iron_plate_stairs:0,10,quark:iron_plate_stairs:5,10,quark:iron_plate_stairs:3,10,quark:iron_plate_slab:8,10,quark:iron_plate_stairs:7,10,quark:iron_plate_stairs:1,10,quark:iron_plate_slab:0,10,quark:iron_plate_stairs:4,10,quark:iron_plate_stairs:2,10,IRON_FENCE:0,50,IRON_FENCE:0,50,LEAVES:7,100)
RandomBlock(-7,6,-3,quark:iron_plate:1,70,STAINED_CLAY:15,30,STAINED_CLAY:7,30,quark:iron_plate:1,100)
RandomBlock(-7,6,-2,quark:iron_plate:1,70,STAINED_CLAY:15,30,STAINED_CLAY:7,30,quark:iron_plate:1,100)
RandomBlock(-7,7,-4,IRON_FENCE:0,30,IRON_FENCE:0,30,LEAVES:7,30,quark:iron_plate_stairs:6,10,quark:iron_plate_stairs:0,10,quark:iron_plate_stairs:5,10,quark:iron_plate_stairs:3,10,quark:iron_plate_slab:8,10,quark:iron_plate_stairs:7,10,quark:iron_plate_stairs:1,10,quark:iron_plate_slab:0,10,quark:iron_plate_stairs:4,10,quark:iron_plate_stairs:2,10,IRON_FENCE:0,50,IRON_FENCE:0,50,LEAVES:7,100)
RandomBlock(-7,7,-3,quark:iron_plate:1,70,STAINED_CLAY:15,30,STAINED_CLAY:7,30,quark:iron_plate:1,100)
RandomBlock(-7,7,-2,quark:iron_plate:1,70,STAINED_CLAY:15,30,STAINED_CLAY:7,30,quark:iron_plate:1,100)
Block(-7,8,-4,IRON_FENCE:0)
Block(-7,8,-3,IRON_FENCE:0)
Block(-7,8,-2,IRON_FENCE:0)
Block(-6,0,-5,quark:limestone:0)
RandomBlock(-6,0,-4,quark:iron_plate:1,70,STAINED_CLAY:15,30,STAINED_CLAY:7,30,quark:iron_plate:1,100)
Block(-6,0,-3,srparasites:deadblood)
RandomBlock(-6,0,-2,quark:iron_plate:1,70,STAINED_CLAY:15,30,STAINED_CLAY:7,30,quark:iron_plate:1,100)
Block(-6,0,-1,quark:limestone:0)
Block(-6,1,-5,COBBLESTONE_STAIRS:2)
RandomBlock(-6,1,-4,quark:iron_plate:1,70,STAINED_CLAY:15,30,STAINED_CLAY:7,30,quark:iron_plate:1,100)
Block(-6,1,-3,srparasites:deadblood)
RandomBlock(-6,1,-2,quark:iron_plate:1,70,STAINED_CLAY:15,30,STAINED_CLAY:7,30,quark:iron_plate:1,100)
Block(-6,1,-1,COBBLESTONE_STAIRS:3)
RandomBlock(-6,2,-4,quark:iron_plate:1,70,STAINED_CLAY:15,30,STAINED_CLAY:7,30,quark:iron_plate:1,100)
Block(-6,2,-3,srparasites:deadblood)
RandomBlock(-6,2,-2,quark:iron_plate:1,70,STAINED_CLAY:15,30,STAINED_CLAY:7,30,quark:iron_plate:1,100)
RandomBlock(-6,3,-4,quark:iron_plate:1,70,STAINED_CLAY:15,30,STAINED_CLAY:7,30,quark:iron_plate:1,100)
Block(-6,3,-3,srparasites:deadblood)
RandomBlock(-6,3,-2,quark:iron_plate:1,70,STAINED_CLAY:15,30,STAINED_CLAY:7,30,quark:iron_plate:1,100)
RandomBlock(-6,4,-4,quark:iron_plate:1,70,STAINED_CLAY:15,30,STAINED_CLAY:7,30,quark:iron_plate:1,100)
Block(-6,4,-3,srparasites:deadblood)
RandomBlock(-6,4,-2,quark:iron_plate:1,70,STAINED_CLAY:15,30,STAINED_CLAY:7,30,quark:iron_plate:1,100)
RandomBlock(-6,5,-4,quark:iron_plate:1,70,STAINED_CLAY:15,30,STAINED_CLAY:7,30,quark:iron_plate:1,100)
Block(-6,5,-3,srparasites:deadblood)
RandomBlock(-6,5,-2,quark:iron_plate:1,70,STAINED_CLAY:15,30,STAINED_CLAY:7,30,quark:iron_plate:1,100)
RandomBlock(-6,6,-4,quark:iron_plate:1,70,STAINED_CLAY:15,30,STAINED_CLAY:7,30,quark:iron_plate:1,100)
Block(-6,6,-3,srparasites:deadblood)
RandomBlock(-6,6,-2,quark:iron_plate:1,70,STAINED_CLAY:15,30,STAINED_CLAY:7,30,quark:iron_plate:1,100)
RandomBlock(-6,7,-4,IRON_FENCE:0,30,IRON_FENCE:0,30,LEAVES:7,30,quark:iron_plate_stairs:6,10,quark:iron_plate_stairs:0,10,quark:iron_plate_stairs:5,10,quark:iron_plate_stairs:3,10,quark:iron_plate_slab:8,10,quark:iron_plate_stairs:7,10,quark:iron_plate_stairs:1,10,quark:iron_plate_slab:0,10,quark:iron_plate_stairs:4,10,quark:iron_plate_stairs:2,10,IRON_FENCE:0,50,IRON_FENCE:0,50,LEAVES:7,100)
RandomBlock(-6,7,-3,quark:iron_plate:1,70,STAINED_CLAY:15,30,STAINED_CLAY:7,30,quark:iron_plate:1,100)
RandomBlock(-6,7,-2,IRON_FENCE:0,30,IRON_FENCE:0,30,LEAVES:7,30,quark:iron_plate_stairs:6,10,quark:iron_plate_stairs:0,10,quark:iron_plate_stairs:5,10,quark:iron_plate_stairs:3,10,quark:iron_plate_slab:8,10,quark:iron_plate_stairs:7,10,quark:iron_plate_stairs:1,10,quark:iron_plate_slab:0,10,quark:iron_plate_stairs:4,10,quark:iron_plate_stairs:2,10,IRON_FENCE:0,50,IRON_FENCE:0,50,LEAVES:7,100)
Block(-6,8,-4,IRON_FENCE:0)
Block(-6,8,-2,IRON_FENCE:0)
Block(-5,0,-5,quark:limestone:0)
RandomBlock(-5,0,-4,quark:iron_plate:1,70,STAINED_CLAY:15,30,STAINED_CLAY:7,30,quark:iron_plate:1,100)
RandomBlock(-5,0,-3,quark:iron_plate:1,70,STAINED_CLAY:15,30,STAINED_CLAY:7,30,quark:iron_plate:1,100)
RandomBlock(-5,0,-2,quark:iron_plate:1,70,STAINED_CLAY:15,30,STAINED_CLAY:7,30,quark:iron_plate:1,100)
Block(-5,0,-1,quark:limestone:0)
Block(-5,1,-5,COBBLESTONE_STAIRS:2)
RandomBlock(-5,1,-4,quark:iron_plate:1,70,STAINED_CLAY:15,30,STAINED_CLAY:7,30,quark:iron_plate:1,100)
RandomBlock(-5,1,-3,quark:iron_plate:1,70,STAINED_CLAY:15,30,STAINED_CLAY:7,30,quark:iron_plate:1,100)
RandomBlock(-5,1,-2,quark:iron_plate:1,70,STAINED_CLAY:15,30,STAINED_CLAY:7,30,quark:iron_plate:1,100)
Block(-5,1,-1,COBBLESTONE_STAIRS:3)
RandomBlock(-5,2,-4,IRON_FENCE:0,30,IRON_FENCE:0,30,LEAVES:7,30,quark:iron_plate_stairs:6,10,quark:iron_plate_stairs:0,10,quark:iron_plate_stairs:5,10,quark:iron_plate_stairs:3,10,quark:iron_plate_slab:8,10,quark:iron_plate_stairs:7,10,quark:iron_plate_stairs:1,10,quark:iron_plate_slab:0,10,quark:iron_plate_stairs:4,10,quark:iron_plate_stairs:2,10,IRON_FENCE:0,50,IRON_FENCE:0,50,LEAVES:7,100)
RandomBlock(-5,2,-3,quark:iron_plate:1,70,STAINED_CLAY:15,30,STAINED_CLAY:7,30,quark:iron_plate:1,100)
RandomBlock(-5,2,-2,quark:iron_plate:1,70,STAINED_CLAY:15,30,STAINED_CLAY:7,30,quark:iron_plate:1,100)
RandomBlock(-5,3,-4,IRON_FENCE:0,30,IRON_FENCE:0,30,LEAVES:7,30,quark:iron_plate_stairs:6,10,quark:iron_plate_stairs:0,10,quark:iron_plate_stairs:5,10,quark:iron_plate_stairs:3,10,quark:iron_plate_slab:8,10,quark:iron_plate_stairs:7,10,quark:iron_plate_stairs:1,10,quark:iron_plate_slab:0,10,quark:iron_plate_stairs:4,10,quark:iron_plate_stairs:2,10,IRON_FENCE:0,50,IRON_FENCE:0,50,LEAVES:7,100)
RandomBlock(-5,3,-3,quark:iron_plate:1,70,STAINED_CLAY:15,30,STAINED_CLAY:7,30,quark:iron_plate:1,100)
RandomBlock(-5,3,-2,quark:iron_plate:1,70,STAINED_CLAY:15,30,STAINED_CLAY:7,30,quark:iron_plate:1,100)
RandomBlock(-5,4,-4,IRON_FENCE:0,30,IRON_FENCE:0,30,LEAVES:7,30,quark:iron_plate_stairs:6,10,quark:iron_plate_stairs:0,10,quark:iron_plate_stairs:5,10,quark:iron_plate_stairs:3,10,quark:iron_plate_slab:8,10,quark:iron_plate_stairs:7,10,quark:iron_plate_stairs:1,10,quark:iron_plate_slab:0,10,quark:iron_plate_stairs:4,10,quark:iron_plate_stairs:2,10,IRON_FENCE:0,50,IRON_FENCE:0,50,LEAVES:7,100)
RandomBlock(-5,4,-3,quark:iron_plate:1,70,STAINED_CLAY:15,30,STAINED_CLAY:7,30,quark:iron_plate:1,100)
RandomBlock(-5,4,-2,IRON_FENCE:0,30,IRON_FENCE:0,30,LEAVES:7,30,quark:iron_plate_stairs:6,10,quark:iron_plate_stairs:0,10,quark:iron_plate_stairs:5,10,quark:iron_plate_stairs:3,10,quark:iron_plate_slab:8,10,quark:iron_plate_stairs:7,10,quark:iron_plate_stairs:1,10,quark:iron_plate_slab:0,10,quark:iron_plate_stairs:4,10,quark:iron_plate_stairs:2,10,IRON_FENCE:0,50,IRON_FENCE:0,50,LEAVES:7,100)
RandomBlock(-5,5,-4,quark:iron_plate:1,70,STAINED_CLAY:15,30,STAINED_CLAY:7,30,quark:iron_plate:1,100)
RandomBlock(-5,5,-3,quark:iron_plate:1,70,STAINED_CLAY:15,30,STAINED_CLAY:7,30,quark:iron_plate:1,100)
RandomBlock(-5,5,-2,IRON_FENCE:0,30,IRON_FENCE:0,30,LEAVES:7,30,quark:iron_plate_stairs:6,10,quark:iron_plate_stairs:0,10,quark:iron_plate_stairs:5,10,quark:iron_plate_stairs:3,10,quark:iron_plate_slab:8,10,quark:iron_plate_stairs:7,10,quark:iron_plate_stairs:1,10,quark:iron_plate_slab:0,10,quark:iron_plate_stairs:4,10,quark:iron_plate_stairs:2,10,IRON_FENCE:0,50,IRON_FENCE:0,50,LEAVES:7,100)
RandomBlock(-5,6,-4,quark:iron_plate:1,70,STAINED_CLAY:15,30,STAINED_CLAY:7,30,quark:iron_plate:1,100)
Block(-5,6,-3,srparasites:deadblood)
RandomBlock(-5,6,-2,quark:iron_plate:1,70,STAINED_CLAY:15,30,STAINED_CLAY:7,30,quark:iron_plate:1,100)
RandomBlock(-5,7,-4,IRON_FENCE:0,30,IRON_FENCE:0,30,LEAVES:7,30,quark:iron_plate_stairs:6,10,quark:iron_plate_stairs:0,10,quark:iron_plate_stairs:5,10,quark:iron_plate_stairs:3,10,quark:iron_plate_slab:8,10,quark:iron_plate_stairs:7,10,quark:iron_plate_stairs:1,10,quark:iron_plate_slab:0,10,quark:iron_plate_stairs:4,10,quark:iron_plate_stairs:2,10,IRON_FENCE:0,50,IRON_FENCE:0,50,LEAVES:7,100)
RandomBlock(-5,7,-3,quark:iron_plate:1,70,STAINED_CLAY:15,30,STAINED_CLAY:7,30,quark:iron_plate:1,100)
RandomBlock(-5,7,-2,IRON_FENCE:0,30,IRON_FENCE:0,30,LEAVES:7,30,quark:iron_plate_stairs:6,10,quark:iron_plate_stairs:0,10,quark:iron_plate_stairs:5,10,quark:iron_plate_stairs:3,10,quark:iron_plate_slab:8,10,quark:iron_plate_stairs:7,10,quark:iron_plate_stairs:1,10,quark:iron_plate_slab:0,10,quark:iron_plate_stairs:4,10,quark:iron_plate_stairs:2,10,IRON_FENCE:0,50,IRON_FENCE:0,50,LEAVES:7,100)
Block(-5,8,-4,IRON_FENCE:0)
Block(-5,8,-3,IRON_FENCE:0)
Block(-5,8,-2,IRON_FENCE:0)
Block(-4,0,-5,quark:limestone:0)
Block(-4,0,-4,quark:limestone:0)
Block(-4,0,-3,quark:limestone:0)
Block(-4,0,-2,quark:limestone:0)
Block(-4,0,-1,quark:limestone:0)
Block(-4,1,-5,COBBLESTONE_STAIRS:1)
Block(-4,1,-4,COBBLESTONE_STAIRS:1)
Block(-4,1,-3,COBBLESTONE_STAIRS:1)
Block(-4,1,-2,COBBLESTONE_STAIRS:1)
Block(-4,1,-1,COBBLESTONE_STAIRS:3)
Block(-4,5,-4,COBBLESTONE_STAIRS:6)
RandomBlock(-4,5,-3,quark:iron_plate:1,70,STAINED_CLAY:15,30,STAINED_CLAY:7,30,quark:iron_plate:1,100)
Block(-4,5,-2,COBBLESTONE_STAIRS:7)
RandomBlock(-4,6,-4,quark:iron_plate:1,70,STAINED_CLAY:15,30,STAINED_CLAY:7,30,quark:iron_plate:1,100)
Block(-4,6,-3,srparasites:deadblood)
RandomBlock(-4,6,-2,quark:iron_plate:1,70,STAINED_CLAY:15,30,STAINED_CLAY:7,30,quark:iron_plate:1,100)
Block(-4,7,-4,COBBLESTONE_STAIRS:2)
RandomBlock(-4,7,-3,quark:iron_plate:1,70,STAINED_CLAY:15,30,STAINED_CLAY:7,30,quark:iron_plate:1,100)
Block(-4,7,-2,COBBLESTONE_STAIRS:3)
Block(-3,5,-4,COBBLESTONE_STAIRS:6)
RandomBlock(-3,5,-3,quark:iron_plate:1,70,STAINED_CLAY:15,30,STAINED_CLAY:7,30,quark:iron_plate:1,100)
Block(-3,5,-2,COBBLESTONE_STAIRS:7)
RandomBlock(-3,6,-4,quark:iron_plate:1,70,STAINED_CLAY:15,30,STAINED_CLAY:7,30,quark:iron_plate:1,100)
Block(-3,6,-3,srparasites:deadblood)
RandomBlock(-3,6,-2,quark:iron_plate:1,70,STAINED_CLAY:15,30,STAINED_CLAY:7,30,quark:iron_plate:1,100)
Block(-3,7,-4,COBBLESTONE_STAIRS:2)
RandomBlock(-3,7,-3,quark:iron_plate:1,70,STAINED_CLAY:15,30,STAINED_CLAY:7,30,quark:iron_plate:1,100)
Block(-3,7,-2,COBBLESTONE_STAIRS:3)
Block(-2,5,-4,COBBLESTONE_STAIRS:6)
RandomBlock(-2,5,-3,quark:iron_plate:1,70,STAINED_CLAY:15,30,STAINED_CLAY:7,30,quark:iron_plate:1,100)
Block(-2,5,-2,COBBLESTONE_STAIRS:7)
RandomBlock(-2,6,-4,quark:iron_plate:1,70,STAINED_CLAY:15,30,STAINED_CLAY:7,30,quark:iron_plate:1,100)
Block(-2,6,-3,srparasites:deadblood)
RandomBlock(-2,6,-2,quark:iron_plate:1,70,STAINED_CLAY:15,30,STAINED_CLAY:7,30,quark:iron_plate:1,100)
Block(-2,7,-4,COBBLESTONE_STAIRS:2)
RandomBlock(-2,7,-3,IRON_FENCE:0,30,IRON_FENCE:0,30,LEAVES:7,30,quark:iron_plate_stairs:6,10,quark:iron_plate_stairs:0,10,quark:iron_plate_stairs:5,10,quark:iron_plate_stairs:3,10,quark:iron_plate_slab:8,10,quark:iron_plate_stairs:7,10,quark:iron_plate_stairs:1,10,quark:iron_plate_slab:0,10,quark:iron_plate_stairs:4,10,quark:iron_plate_stairs:2,10,IRON_FENCE:0,50,IRON_FENCE:0,50,LEAVES:7,100)
Block(-2,7,-2,COBBLESTONE_STAIRS:3)
Block(-1,5,-4,COBBLESTONE_STAIRS:6)
RandomBlock(-1,5,-3,quark:iron_plate:1,70,STAINED_CLAY:15,30,STAINED_CLAY:7,30,quark:iron_plate:1,100)
Block(-1,5,-2,COBBLESTONE_STAIRS:7)
RandomBlock(-1,6,-4,quark:iron_plate:1,70,STAINED_CLAY:15,30,STAINED_CLAY:7,30,quark:iron_plate:1,100)
Block(-1,6,-3,srparasites:deadblood)
RandomBlock(-1,6,-2,quark:iron_plate:1,70,STAINED_CLAY:15,30,STAINED_CLAY:7,30,quark:iron_plate:1,100)
Block(-1,7,-4,COBBLESTONE_STAIRS:2)
RandomBlock(-1,7,-3,IRON_FENCE:0,30,IRON_FENCE:0,30,LEAVES:7,30,quark:iron_plate_stairs:6,10,quark:iron_plate_stairs:0,10,quark:iron_plate_stairs:5,10,quark:iron_plate_stairs:3,10,quark:iron_plate_slab:8,10,quark:iron_plate_stairs:7,10,quark:iron_plate_stairs:1,10,quark:iron_plate_slab:0,10,quark:iron_plate_stairs:4,10,quark:iron_plate_stairs:2,10,IRON_FENCE:0,50,IRON_FENCE:0,50,LEAVES:7,100)
Block(-1,7,-2,COBBLESTONE_STAIRS:3)
Block(0,5,-4,COBBLESTONE_STAIRS:6)
RandomBlock(0,5,-3,quark:iron_plate:1,70,STAINED_CLAY:15,30,STAINED_CLAY:7,30,quark:iron_plate:1,100)
Block(0,5,-2,COBBLESTONE_STAIRS:7)
RandomBlock(0,6,-4,quark:iron_plate:1,70,STAINED_CLAY:15,30,STAINED_CLAY:7,30,quark:iron_plate:1,100)
Block(0,6,-3,srparasites:deadblood)
RandomBlock(0,6,-2,quark:iron_plate:1,70,STAINED_CLAY:15,30,STAINED_CLAY:7,30,quark:iron_plate:1,100)
Block(0,7,-4,COBBLESTONE_STAIRS:2)
RandomBlock(0,7,-3,IRON_FENCE:0,30,IRON_FENCE:0,30,LEAVES:7,30,quark:iron_plate_stairs:6,10,quark:iron_plate_stairs:0,10,quark:iron_plate_stairs:5,10,quark:iron_plate_stairs:3,10,quark:iron_plate_slab:8,10,quark:iron_plate_stairs:7,10,quark:iron_plate_stairs:1,10,quark:iron_plate_slab:0,10,quark:iron_plate_stairs:4,10,quark:iron_plate_stairs:2,10,IRON_FENCE:0,50,IRON_FENCE:0,50,LEAVES:7,100)
Block(0,7,-2,COBBLESTONE_STAIRS:3)
Block(1,5,-4,COBBLESTONE_STAIRS:6)
RandomBlock(1,5,-3,quark:iron_plate:1,70,STAINED_CLAY:15,30,STAINED_CLAY:7,30,quark:iron_plate:1,100)
Block(1,5,-2,COBBLESTONE_STAIRS:7)
RandomBlock(1,6,-4,quark:iron_plate:1,70,STAINED_CLAY:15,30,STAINED_CLAY:7,30,quark:iron_plate:1,100)
Block(1,6,-3,srparasites:deadblood)
RandomBlock(1,6,-2,quark:iron_plate:1,70,STAINED_CLAY:15,30,STAINED_CLAY:7,30,quark:iron_plate:1,100)
Block(1,7,-4,COBBLESTONE_STAIRS:2)
RandomBlock(1,7,-3,IRON_FENCE:0,30,IRON_FENCE:0,30,LEAVES:7,30,quark:iron_plate_stairs:6,10,quark:iron_plate_stairs:0,10,quark:iron_plate_stairs:5,10,quark:iron_plate_stairs:3,10,quark:iron_plate_slab:8,10,quark:iron_plate_stairs:7,10,quark:iron_plate_stairs:1,10,quark:iron_plate_slab:0,10,quark:iron_plate_stairs:4,10,quark:iron_plate_stairs:2,10,IRON_FENCE:0,50,IRON_FENCE:0,50,LEAVES:7,100)
Block(1,7,-2,COBBLESTONE_STAIRS:3)
Block(2,5,-4,COBBLESTONE_STAIRS:6)
RandomBlock(2,5,-3,quark:iron_plate:1,70,STAINED_CLAY:15,30,STAINED_CLAY:7,30,quark:iron_plate:1,100)
Block(2,5,-2,COBBLESTONE_STAIRS:7)
RandomBlock(2,6,-4,quark:iron_plate:1,70,STAINED_CLAY:15,30,STAINED_CLAY:7,30,quark:iron_plate:1,100)
Block(2,6,-3,srparasites:deadblood)
RandomBlock(2,6,-2,quark:iron_plate:1,70,STAINED_CLAY:15,30,STAINED_CLAY:7,30,quark:iron_plate:1,100)
Block(2,7,-4,COBBLESTONE_STAIRS:2)
RandomBlock(2,7,-3,IRON_FENCE:0,30,IRON_FENCE:0,30,LEAVES:7,30,quark:iron_plate_stairs:6,10,quark:iron_plate_stairs:0,10,quark:iron_plate_stairs:5,10,quark:iron_plate_stairs:3,10,quark:iron_plate_slab:8,10,quark:iron_plate_stairs:7,10,quark:iron_plate_stairs:1,10,quark:iron_plate_slab:0,10,quark:iron_plate_stairs:4,10,quark:iron_plate_stairs:2,10,IRON_FENCE:0,50,IRON_FENCE:0,50,LEAVES:7,100)
Block(2,7,-2,COBBLESTONE_STAIRS:3)
Block(3,5,-4,COBBLESTONE_STAIRS:6)
RandomBlock(3,5,-3,quark:iron_plate:1,70,STAINED_CLAY:15,30,STAINED_CLAY:7,30,quark:iron_plate:1,100)
Block(3,5,-2,COBBLESTONE_STAIRS:7)
RandomBlock(3,6,-4,quark:iron_plate:1,70,STAINED_CLAY:15,30,STAINED_CLAY:7,30,quark:iron_plate:1,100)
Block(3,6,-3,srparasites:deadblood)
RandomBlock(3,6,-2,quark:iron_plate:1,70,STAINED_CLAY:15,30,STAINED_CLAY:7,30,quark:iron_plate:1,100)
Block(3,7,-4,COBBLESTONE_STAIRS:2)
RandomBlock(3,7,-3,quark:iron_plate:1,70,STAINED_CLAY:15,30,STAINED_CLAY:7,30,quark:iron_plate:1,100)
Block(3,7,-2,COBBLESTONE_STAIRS:3)
Block(4,5,-4,COBBLESTONE_STAIRS:6)
RandomBlock(4,5,-3,quark:iron_plate:1,70,STAINED_CLAY:15,30,STAINED_CLAY:7,30,quark:iron_plate:1,100)
Block(4,5,-2,COBBLESTONE_STAIRS:7)
RandomBlock(4,6,-4,quark:iron_plate:1,70,STAINED_CLAY:15,30,STAINED_CLAY:7,30,quark:iron_plate:1,100)
Block(4,6,-3,srparasites:deadblood)
RandomBlock(4,6,-2,quark:iron_plate:1,70,STAINED_CLAY:15,30,STAINED_CLAY:7,30,quark:iron_plate:1,100)
Block(4,7,-4,COBBLESTONE_STAIRS:2)
RandomBlock(4,7,-3,quark:iron_plate:1,70,STAINED_CLAY:15,30,STAINED_CLAY:7,30,quark:iron_plate:1,100)
Block(4,7,-2,COBBLESTONE_STAIRS:3)
RandomBlock(5,0,0,quark:iron_plate:1,70,STAINED_CLAY:15,30,STAINED_CLAY:7,30,quark:iron_plate:1,100)
RandomBlock(5,1,0,quark:iron_plate:1,70,STAINED_CLAY:15,30,STAINED_CLAY:7,30,quark:iron_plate:1,100)
RandomBlock(5,2,0,quark:iron_plate:1,70,STAINED_CLAY:15,30,STAINED_CLAY:7,30,quark:iron_plate:1,100)
RandomBlock(5,3,0,quark:iron_plate:1,70,STAINED_CLAY:15,30,STAINED_CLAY:7,30,quark:iron_plate:1,100)
RandomBlock(5,4,0,quark:iron_plate:1,70,STAINED_CLAY:15,30,STAINED_CLAY:7,30,quark:iron_plate:1,100)
Block(5,5,-4,COBBLESTONE_STAIRS:6)
RandomBlock(5,5,-3,quark:iron_plate:1,70,STAINED_CLAY:15,30,STAINED_CLAY:7,30,quark:iron_plate:1,100)
Block(5,5,-2,COBBLESTONE_STAIRS:7)
RandomBlock(5,5,0,quark:iron_plate:1,70,STAINED_CLAY:15,30,STAINED_CLAY:7,30,quark:iron_plate:1,100)
RandomBlock(5,6,-4,quark:iron_plate:1,70,STAINED_CLAY:15,30,STAINED_CLAY:7,30,quark:iron_plate:1,100)
Block(5,6,-3,srparasites:deadblood)
RandomBlock(5,6,-2,quark:iron_plate:1,70,STAINED_CLAY:15,30,STAINED_CLAY:7,30,quark:iron_plate:1,100)
RandomBlock(5,6,0,quark:iron_plate:1,70,STAINED_CLAY:15,30,STAINED_CLAY:7,30,quark:iron_plate:1,100)
Block(5,7,-4,COBBLESTONE_STAIRS:2)
RandomBlock(5,7,-3,quark:iron_plate:1,70,STAINED_CLAY:15,30,STAINED_CLAY:7,30,quark:iron_plate:1,100)
Block(5,7,-2,COBBLESTONE_STAIRS:3)
RandomBlock(5,7,0,quark:iron_plate:1,70,STAINED_CLAY:15,30,STAINED_CLAY:7,30,quark:iron_plate:1,100)
RandomBlock(5,8,-3,quark:iron_plate:1,70,STAINED_CLAY:15,30,STAINED_CLAY:7,30,quark:iron_plate:1,100)
RandomBlock(5,8,0,quark:iron_plate:1,70,STAINED_CLAY:15,30,STAINED_CLAY:7,30,quark:iron_plate:1,100)
RandomBlock(5,9,-3,quark:iron_plate:1,70,STAINED_CLAY:15,30,STAINED_CLAY:7,30,quark:iron_plate:1,100)
RandomBlock(5,9,0,quark:iron_plate:1,70,STAINED_CLAY:15,30,STAINED_CLAY:7,30,quark:iron_plate:1,100)
Block(6,0,-6,quark:limestone:0)
Block(6,0,-5,quark:limestone:0)
Block(6,0,-4,quark:limestone:0)
Block(6,0,-3,quark:limestone:0)
Block(6,0,-2,quark:limestone:0)
Block(6,0,-1,quark:limestone:0)
Block(6,0,0,quark:limestone:0)
Block(6,0,1,quark:limestone:0)
Block(6,0,2,quark:limestone:0)
RandomBlock(6,1,-6,quark:iron_plate:1,70,STAINED_CLAY:15,30,STAINED_CLAY:7,30,quark:iron_plate:1,100)
Block(6,1,-5,SMOOTH_STAIRS:0)
Block(6,1,-4,SMOOTH_STAIRS:0)
Block(6,1,-3,SMOOTH_STAIRS:0)
Block(6,1,-2,SMOOTH_STAIRS:0)
Block(6,1,-1,SMOOTH_STAIRS:0)
Block(6,1,0,SMOOTH_STAIRS:0)
Block(6,1,1,SMOOTH_STAIRS:0)
RandomBlock(6,1,2,quark:iron_plate:1,70,STAINED_CLAY:15,30,STAINED_CLAY:7,30,quark:iron_plate:1,100)
RandomBlock(6,2,-6,quark:iron_plate:1,70,STAINED_CLAY:15,30,STAINED_CLAY:7,30,quark:iron_plate:1,100)
Block(6,2,-5,SMOOTH_STAIRS:4)
Block(6,2,-4,SMOOTH_STAIRS:4)
Block(6,2,-3,SMOOTH_STAIRS:4)
Block(6,2,-2,SMOOTH_STAIRS:4)
Block(6,2,-1,SMOOTH_STAIRS:4)
Block(6,2,0,SMOOTH_STAIRS:4)
Block(6,2,1,SMOOTH_STAIRS:4)
RandomBlock(6,2,2,quark:iron_plate:1,70,STAINED_CLAY:15,30,STAINED_CLAY:7,30,quark:iron_plate:1,100)
RandomBlock(6,3,-6,quark:iron_plate:1,70,STAINED_CLAY:15,30,STAINED_CLAY:7,30,quark:iron_plate:1,100)
RandomBlock(6,3,-5,quark:iron_plate:1,70,STAINED_CLAY:15,30,STAINED_CLAY:7,30,quark:iron_plate:1,100)
Block(6,3,-4,quark:world_stone_pavement:2)
Block(6,3,-3,quark:world_stone_pavement:2)
Block(6,3,-2,quark:world_stone_pavement:2)
Block(6,3,-1,quark:world_stone_pavement:2)
Block(6,3,0,quark:world_stone_pavement:2)
RandomBlock(6,3,1,quark:iron_plate:1,70,STAINED_CLAY:15,30,STAINED_CLAY:7,30,quark:iron_plate:1,100)
RandomBlock(6,3,2,quark:iron_plate:1,70,STAINED_CLAY:15,30,STAINED_CLAY:7,30,quark:iron_plate:1,100)
RandomBlock(6,4,-6,quark:iron_plate:1,70,STAINED_CLAY:15,30,STAINED_CLAY:7,30,quark:iron_plate:1,100)
Block(6,4,-5,quark:world_stone_pavement:2)
Block(6,4,-4,quark:world_stone_pavement:2)
Block(6,4,-3,quark:world_stone_pavement:2)
Block(6,4,-2,quark:world_stone_pavement:2)
Block(6,4,-1,quark:world_stone_pavement:2)
Block(6,4,0,quark:world_stone_pavement:2)
Block(6,4,1,quark:world_stone_pavement:2)
RandomBlock(6,4,2,quark:iron_plate:1,70,STAINED_CLAY:15,30,STAINED_CLAY:7,30,quark:iron_plate:1,100)
RandomBlock(6,5,-6,quark:iron_plate:1,70,STAINED_CLAY:15,30,STAINED_CLAY:7,30,quark:iron_plate:1,100)
RandomBlock(6,5,-5,quark:iron_plate:1,70,STAINED_CLAY:15,30,STAINED_CLAY:7,30,quark:iron_plate:1,100)
Block(6,5,-4,quark:world_stone_pavement:2)
Block(6,5,-3,quark:world_stone_pavement:2)
Block(6,5,-2,quark:world_stone_pavement:2)
Block(6,5,-1,quark:world_stone_pavement:2)
Block(6,5,0,quark:world_stone_pavement:2)
RandomBlock(6,5,1,quark:iron_plate:1,70,STAINED_CLAY:15,30,STAINED_CLAY:7,30,quark:iron_plate:1,100)
RandomBlock(6,5,2,quark:iron_plate:1,70,STAINED_CLAY:15,30,STAINED_CLAY:7,30,quark:iron_plate:1,100)
RandomBlock(6,6,-6,quark:iron_plate:1,70,STAINED_CLAY:15,30,STAINED_CLAY:7,30,quark:iron_plate:1,100)
Block(6,6,-5,quark:world_stone_pavement:2)
Block(6,6,-4,quark:world_stone_pavement:2)
Block(6,6,-3,srparasites:deadblood)
Block(6,6,-2,quark:world_stone_pavement:2)
Block(6,6,-1,quark:world_stone_pavement:2)
Block(6,6,0,quark:world_stone_pavement:2)
Block(6,6,1,quark:world_stone_pavement:2)
RandomBlock(6,6,2,quark:iron_plate:1,70,STAINED_CLAY:15,30,STAINED_CLAY:7,30,quark:iron_plate:1,100)
RandomBlock(6,7,-6,quark:iron_plate:1,70,STAINED_CLAY:15,30,STAINED_CLAY:7,30,quark:iron_plate:1,100)
RandomBlock(6,7,-5,quark:iron_plate:1,70,STAINED_CLAY:15,30,STAINED_CLAY:7,30,quark:iron_plate:1,100)
Block(6,7,-4,quark:world_stone_pavement:2)
Block(6,7,-3,quark:world_stone_pavement:2)
Block(6,7,-2,quark:world_stone_pavement:2)
Block(6,7,-1,quark:world_stone_pavement:2)
Block(6,7,0,quark:world_stone_pavement:2)
RandomBlock(6,7,1,quark:iron_plate:1,70,STAINED_CLAY:15,30,STAINED_CLAY:7,30,quark:iron_plate:1,100)
RandomBlock(6,7,2,quark:iron_plate:1,70,STAINED_CLAY:15,30,STAINED_CLAY:7,30,quark:iron_plate:1,100)
RandomBlock(6,8,-6,quark:iron_plate:1,70,STAINED_CLAY:15,30,STAINED_CLAY:7,30,quark:iron_plate:1,100)
Block(6,8,-5,quark:world_stone_pavement:2)
Block(6,8,-4,quark:world_stone_pavement:2)
Block(6,8,-3,quark:world_stone_pavement:2)
Block(6,8,-2,quark:world_stone_pavement:2)
Block(6,8,-1,quark:world_stone_pavement:2)
Block(6,8,0,quark:world_stone_pavement:2)
Block(6,8,1,quark:world_stone_pavement:2)
RandomBlock(6,8,2,quark:iron_plate:1,70,STAINED_CLAY:15,30,STAINED_CLAY:7,30,quark:iron_plate:1,100)
RandomBlock(6,9,-3,quark:iron_plate:1,70,STAINED_CLAY:15,30,STAINED_CLAY:7,30,quark:iron_plate:1,100)
Block(6,9,-2,quark:stone_basalt_slab:0)
Block(6,9,-1,quark:stone_basalt_slab:0)
RandomBlock(6,9,0,quark:iron_plate:1,70,STAINED_CLAY:15,30,STAINED_CLAY:7,30,quark:iron_plate:1,100)
Block(6,9,1,quark:stone_basalt_slab:0)
Block(6,9,2,quark:stone_basalt_slab:0)
Block(7,0,-6,quark:limestone:0)
Block(7,0,-5,quark:limestone:0)
Block(7,0,-4,quark:limestone:0)
Block(7,0,-3,quark:limestone:0)
Block(7,0,-2,quark:limestone:0)
Block(7,0,-1,quark:limestone:0)
Block(7,0,0,quark:limestone:0)
Block(7,0,1,quark:limestone:0)
Block(7,0,2,quark:limestone:0)
Block(7,1,-6,SMOOTH_STAIRS:2)
RandomBlock(7,1,-5,quark:iron_plate:1,70,STAINED_CLAY:15,30,STAINED_CLAY:7,30,quark:iron_plate:1,100)
RandomBlock(7,1,-4,quark:iron_plate:1,70,STAINED_CLAY:15,30,STAINED_CLAY:7,30,quark:iron_plate:1,100)
RandomBlock(7,1,-3,quark:iron_plate:1,70,STAINED_CLAY:15,30,STAINED_CLAY:7,30,quark:iron_plate:1,100)
RandomBlock(7,1,-2,quark:iron_plate:1,70,STAINED_CLAY:15,30,STAINED_CLAY:7,30,quark:iron_plate:1,100)
RandomBlock(7,1,-1,quark:iron_plate:1,70,STAINED_CLAY:15,30,STAINED_CLAY:7,30,quark:iron_plate:1,100)
RandomBlock(7,1,0,quark:iron_plate:1,70,STAINED_CLAY:15,30,STAINED_CLAY:7,30,quark:iron_plate:1,100)
RandomBlock(7,1,1,quark:iron_plate:1,70,STAINED_CLAY:15,30,STAINED_CLAY:7,30,quark:iron_plate:1,100)
Block(7,1,2,SMOOTH_STAIRS:3)
Block(7,2,-6,SMOOTH_STAIRS:6)
Block(7,2,-5,srparasites:deadblood)
Block(7,2,-4,srparasites:deadblood:1)
Block(7,2,-3,srparasites:deadblood:1)
Block(7,2,-2,srparasites:deadblood:1)
Block(7,2,-1,srparasites:deadblood:2)
Block(7,2,0,srparasites:deadblood:1)
Block(7,2,1,srparasites:deadblood)
Block(7,2,2,SMOOTH_STAIRS:7)
RandomBlock(7,3,-6,quark:iron_plate:1,70,STAINED_CLAY:15,30,STAINED_CLAY:7,30,quark:iron_plate:1,100)
Block(7,3,-5,quark:framed_glass:0)
RandomBlock(7,3,-4,quark:iron_plate:1,70,STAINED_CLAY:15,30,STAINED_CLAY:7,30,quark:iron_plate:1,100)
Block(7,3,-3,srparasites:deadblood)
RandomBlock(7,3,-2,quark:iron_plate:1,70,STAINED_CLAY:15,30,STAINED_CLAY:7,30,quark:iron_plate:1,100)
Block(7,3,-1,quark:framed_glass:0)
Block(7,3,0,quark:framed_glass:0)
Block(7,3,1,quark:framed_glass:0)
RandomBlock(7,3,2,quark:iron_plate:1,70,STAINED_CLAY:15,30,STAINED_CLAY:7,30,quark:iron_plate:1,100)
Block(7,4,-6,quark:world_stone_pavement:2)
Block(7,4,-5,AIR:0)
Block(7,4,-4,quark:framed_glass:0)
Block(7,4,-3,srparasites:deadblood)
Block(7,4,-2,quark:framed_glass:0)
Block(7,4,-1,AIR:0)
Block(7,4,0,AIR:0)
Block(7,4,1,AIR:0)
Block(7,4,2,quark:world_stone_pavement:2)
RandomBlock(7,5,-6,quark:iron_plate:1,70,STAINED_CLAY:15,30,STAINED_CLAY:7,30,quark:iron_plate:1,100)
Block(7,5,-5,AIR:0)
Block(7,5,-4,quark:framed_glass:0)
Block(7,5,-3,srparasites:deadblood)
Block(7,5,-2,quark:framed_glass:0)
Block(7,5,-1,AIR:0)
Block(7,5,0,AIR:0)
Block(7,5,1,AIR:0)
RandomBlock(7,5,2,quark:iron_plate:1,70,STAINED_CLAY:15,30,STAINED_CLAY:7,30,quark:iron_plate:1,100)
Block(7,6,-6,quark:world_stone_pavement:2)
Block(7,6,-5,AIR:0)
RandomBlock(7,6,-4,quark:iron_plate:1,70,STAINED_CLAY:15,30,STAINED_CLAY:7,30,quark:iron_plate:1,100)
Block(7,6,-3,srparasites:deadblood)
RandomBlock(7,6,-2,quark:iron_plate:1,70,STAINED_CLAY:15,30,STAINED_CLAY:7,30,quark:iron_plate:1,100)
Block(7,6,-1,AIR:0)
Block(7,6,0,AIR:0)
Block(7,6,1,AIR:0)
Block(7,6,2,quark:world_stone_pavement:2)
RandomBlock(7,7,-6,quark:iron_plate:1,70,STAINED_CLAY:15,30,STAINED_CLAY:7,30,quark:iron_plate:1,100)
Block(7,7,-5,AIR:0)
Block(7,7,-4,COBBLESTONE_STAIRS:2)
RandomBlock(7,7,-3,quark:iron_plate:1,70,STAINED_CLAY:15,30,STAINED_CLAY:7,30,quark:iron_plate:1,100)
Block(7,7,-2,COBBLESTONE_STAIRS:3)
Block(7,7,-1,AIR:0)
Block(7,7,0,AIR:0)
Block(7,7,1,AIR:0)
RandomBlock(7,7,2,quark:iron_plate:1,70,STAINED_CLAY:15,30,STAINED_CLAY:7,30,quark:iron_plate:1,100)
Block(7,8,-6,quark:world_stone_pavement:2)
Block(7,8,-5,quark:world_stone_pavement:2)
Block(7,8,-4,quark:world_stone_pavement:2)
Block(7,8,-3,quark:world_stone_pavement:2)
Block(7,8,-2,quark:world_stone_pavement:2)
Block(7,8,-1,quark:world_stone_pavement:2)
Block(7,8,0,quark:world_stone_pavement:2)
Block(7,8,1,quark:world_stone_pavement:2)
Block(7,8,2,quark:world_stone_pavement:2)
Block(7,9,-5,SMOOTH_BRICK:1)
Block(7,9,-4,quark:iron_plate_slab:0)
RandomBlock(7,9,-3,quark:iron_plate:1,70,STAINED_CLAY:15,30,STAINED_CLAY:7,30,quark:iron_plate:1,100)
RandomBlock(7,9,0,quark:iron_plate:1,70,STAINED_CLAY:15,30,STAINED_CLAY:7,30,quark:iron_plate:1,100)
Block(7,9,2,quark:stone_basalt_slab:0)
Block(7,10,-5,quark:basalt_wall:0)

#######################################################################
# +-----------------------------------------------------------------+ #
# |                             Branches                            | #
# +-----------------------------------------------------------------+ #
#######################################################################

Branch(16,0,0,true,brutal_pipesmall_03C1R0,NORTH,100.0,0)

#######################################################################
# +-----------------------------------------------------------------+ #
# |                             Entities                            | #
# +-----------------------------------------------------------------+ #
#######################################################################


#######################################################################
# +-----------------------------------------------------------------+ #
# |                            Particles                            | #
# +-----------------------------------------------------------------+ #
#######################################################################


#######################################################################
# +-----------------------------------------------------------------+ #
# |                             Spawners                            | #
# +-----------------------------------------------------------------+ #
#######################################################################


#######################################################################
# +-----------------------------------------------------------------+ #
# |                             ModData                             | #
# +-----------------------------------------------------------------+ #
#######################################################################

