
#######################################################################
# +-----------------------------------------------------------------+ #
# |                            BO4 object                           | #
# +-----------------------------------------------------------------+ #
#######################################################################

Author: NLBlackEagle

Description: No description given

SettingsMode: WriteWithoutComments


#######################################################################
# +-----------------------------------------------------------------+ #
# |                          Main settings                          | #
# +-----------------------------------------------------------------+ #
#######################################################################

FixedRotation: 

Frequency: 0

SpawnHeight: highestBlock

UseCenterForHighestBlock: true

##############################
# Height Limits for the BO4. #
##############################

MinHeight: 0

MaxHeight: 255

InheritBO3: 

InheritBO3Rotation: NORTH

OverrideChildSettings: true

OverrideParentHeight: false

CanOverride: true

BranchFrequency: 0

BranchFrequencyGroup: 

MustBeBelowOther: false

MustBeInside: 

CannotBeInside: 

ReplacesBO3: 

MustBeInsideWorldBorders: true

CanSpawnOnWater: true

SpawnOnWaterOnly: false

SpawnUnderWater: false

SpawnAtWaterLevel: false

HeightOffset: 0

RemoveAir: false

ReplaceAbove: 

ReplaceBelow: 

ReplaceWithBiomeBlocks: false

ReplaceWithSurfaceBlock: GRASS

ReplaceWithGroundBlock: DIRT

ReplaceWithStoneBlock: STONE

SmoothRadius: 0

SmoothHeightOffset: 0

SmoothStartTop: false

SmoothStartWood: false

SmoothingSurfaceBlock: 

SmoothingGroundBlock: 

BO3Group: 

IsSpawnPoint: false

DoReplaceBlocks: true


#######################################################################
# +-----------------------------------------------------------------+ #
# |                              Blocks                             | #
# +-----------------------------------------------------------------+ #
#######################################################################

Block(-8,0,-7,quark:world_stone_pavement:2)
Block(-8,0,-6,quark:world_stone_pavement:2)
Block(-8,0,-5,CONCRETE:0)
Block(-8,0,-4,quark:world_stone_pavement:2)
Block(-8,0,-3,quark:world_stone_pavement:2)
Block(-8,0,-2,quark:world_stone_pavement:2)
Block(-8,0,-1,quark:world_stone_pavement:2)
Block(-8,0,0,quark:world_stone_pavement:2)
Block(-8,0,1,quark:world_stone_pavement:2)
Block(-8,0,2,CONCRETE:0)
Block(-8,0,3,quark:world_stone_pavement:2)
Block(-8,0,4,quark:world_stone_pavement:2)
Block(-8,0,5,CONCRETE:0)
Block(-8,0,6,CONCRETE:0)
Block(-8,0,7,quark:world_stone_pavement:2)
Block(-8,0,8,CONCRETE:0)
Block(-8,1,-7,CONCRETE:0)
Block(-8,1,-6,quark:world_stone_pavement:2)
Block(-8,1,-5,CONCRETE:0)
Block(-8,1,-4,quark:world_stone_pavement:2)
Block(-8,1,-3,quark:world_stone_pavement:2)
Block(-8,1,-2,quark:world_stone_pavement:2)
Block(-8,1,-1,quark:world_stone_pavement:2)
Block(-8,1,0,quark:world_stone_pavement:2)
Block(-8,1,1,quark:world_stone_pavement:2)
Block(-8,1,2,CONCRETE:0)
Block(-8,1,3,quark:world_stone_pavement:2)
Block(-8,1,4,CONCRETE:0)
Block(-8,1,5,quark:world_stone_pavement:2)
Block(-8,1,6,quark:world_stone_pavement:2)
Block(-8,1,7,CONCRETE:0)
Block(-8,1,8,CONCRETE:0)
Block(-8,2,-7,quark:world_stone_pavement:2)
Block(-8,2,-6,CONCRETE:0)
Block(-8,2,-5,quark:world_stone_pavement:2)
Block(-8,2,-4,quark:world_stone_pavement:2)
Block(-8,2,-3,quark:world_stone_pavement:2)
Block(-8,2,-2,quark:world_stone_pavement:2)
Block(-8,2,-1,quark:world_stone_pavement:2)
Block(-8,2,0,quark:world_stone_pavement:2)
Block(-8,2,1,quark:world_stone_pavement:2)
Block(-8,2,2,CONCRETE:0)
Block(-8,2,3,quark:world_stone_pavement:2)
Block(-8,2,4,quark:world_stone_pavement:2)
Block(-8,2,5,CONCRETE:0)
Block(-8,2,6,CONCRETE:0)
Block(-8,2,7,CONCRETE:0)
Block(-8,2,8,quark:world_stone_pavement:2)
Block(-8,3,-7,CONCRETE:0)
Block(-8,3,-6,quark:world_stone_pavement:2)
Block(-8,3,-5,CONCRETE:0)
Block(-8,3,-4,quark:world_stone_pavement:2)
Block(-8,3,-3,quark:world_stone_pavement:2)
Block(-8,3,-2,quark:world_stone_pavement:2)
Block(-8,3,-1,quark:world_stone_pavement:2)
Block(-8,3,0,quark:world_stone_pavement:2)
Block(-8,3,1,quark:world_stone_pavement:2)
Block(-8,3,2,CONCRETE:0)
Block(-8,3,3,quark:world_stone_pavement:2)
Block(-8,3,4,quark:world_stone_pavement:2)
Block(-8,3,5,CONCRETE:0)
Block(-8,3,6,CONCRETE:0)
Block(-8,3,7,quark:world_stone_pavement:2)
Block(-8,3,8,quark:world_stone_pavement:2)
Block(-8,4,-7,CONCRETE:0)
Block(-8,4,-6,quark:world_stone_pavement:2)
Block(-8,4,-5,CONCRETE:0)
Block(-8,4,-4,quark:world_stone_pavement:2)
Block(-8,4,-3,quark:world_stone_pavement:2)
Block(-8,4,-2,quark:world_stone_pavement:2)
Block(-8,4,-1,quark:world_stone_pavement:2)
Block(-8,4,0,quark:world_stone_pavement:2)
Block(-8,4,1,quark:world_stone_pavement:2)
Block(-8,4,2,quark:world_stone_pavement:2)
Block(-8,4,3,quark:world_stone_pavement:2)
Block(-8,4,4,STONE:0)
Block(-8,4,5,CONCRETE:0)
Block(-8,4,6,quark:world_stone_pavement:2)
Block(-8,4,7,CONCRETE:0)
Block(-8,4,8,quark:world_stone_pavement:2)
Block(-8,5,-7,quark:world_stone_pavement:2)
Block(-8,5,-6,CONCRETE:0)
Block(-8,5,-5,CONCRETE:0)
Block(-8,5,-4,quark:world_stone_pavement:2)
Block(-8,5,-3,quark:world_stone_pavement:2)
Block(-8,5,-2,quark:world_stone_pavement:2)
Block(-8,5,-1,quark:world_stone_pavement:2)
Block(-8,5,0,quark:world_stone_pavement:2)
Block(-8,5,1,quark:world_stone_pavement:2)
Block(-8,5,2,quark:iron_plate_stairs:0)
Block(-8,5,3,quark:iron_plate_stairs:0)
Block(-8,5,4,STONE:0)
Block(-8,5,5,quark:world_stone_pavement:2)
Block(-8,5,6,quark:world_stone_pavement:2)
Block(-8,5,7,CONCRETE:0)
Block(-8,5,8,CONCRETE:0)
Block(-8,6,-7,CONCRETE:0)
Block(-8,6,-6,CONCRETE:0)
Block(-8,6,-5,CONCRETE:0)
Block(-8,6,-4,quark:world_stone_pavement:2)
Block(-8,6,-3,quark:world_stone_pavement:2)
Block(-8,6,-2,quark:world_stone_pavement:2)
Block(-8,6,-1,quark:world_stone_pavement:2)
Block(-8,6,0,quark:world_stone_pavement:2)
Block(-8,6,1,quark:marble_wall:0)
Block(-8,6,4,STONE:0)
Block(-8,6,5,CONCRETE:0)
Block(-8,6,6,CONCRETE:0)
Block(-8,6,7,quark:world_stone_pavement:2)
Block(-8,6,8,quark:world_stone_pavement:2)
Block(-8,7,-7,CONCRETE:0)
Block(-8,7,-6,CONCRETE:0)
Block(-8,7,-5,quark:world_stone_pavement:2)
Block(-8,7,-4,REDSTONE_WIRE:0)
Block(-8,7,-3,CONCRETE:0)
Block(-8,7,-2,CONCRETE:0)
Block(-8,7,-1,quark:world_stone_pavement:2)
Block(-8,7,0,REDSTONE_WIRE:0)
Block(-8,7,1,quark:marble_wall:0)
Block(-8,7,4,STONE:0)
Block(-8,7,5,CONCRETE:0)
Block(-8,7,6,quark:world_stone_pavement:2)
Block(-8,7,7,CONCRETE:0)
Block(-8,7,8,CONCRETE:0)
Block(-8,8,-7,CONCRETE:0)
Block(-8,8,-6,CONCRETE:0)
Block(-8,8,-5,quark:world_stone_pavement:2)
Block(-8,8,-4,CONCRETE:0)
Block(-8,8,-3,CONCRETE:0)
Block(-8,8,-2,quark:world_stone_pavement:2)
Block(-8,8,-1,CONCRETE:0)
Block(-8,8,0,CONCRETE:0)
Block(-8,8,1,CONCRETE:0)
Block(-8,8,2,srparasites:parasiterubbledense:1)
Block(-8,8,3,srparasites:parasiterubbledense:1)
Block(-8,8,4,quark:world_stone_pavement:2)
Block(-8,8,5,quark:polished_stone:0)
Block(-8,8,6,quark:world_stone_pavement:2)
Block(-8,8,7,quark:polished_stone:0)
Block(-8,8,8,quark:polished_stone:0)
Block(-8,9,0,CONCRETE:0)
Block(-8,9,1,CONCRETE:0)
Block(-8,9,2,quark:world_stone_pavement:2)
Block(-8,9,3,CONCRETE:0)
Block(-8,9,4,quark:world_stone_pavement:2)
Block(-8,9,5,quark:world_stone_pavement:2)
Block(-8,9,6,quark:world_stone_pavement:2)
Block(-8,9,7,quark:polished_stone:0)
Block(-8,9,8,quark:polished_stone:0)
Block(-8,10,-7,quark:grate:0)
Block(-8,10,-6,quark:grate:0)
Block(-8,10,-5,quark:grate:0)
Block(-8,10,-4,quark:grate:0)
Block(-8,10,-3,quark:grate:0)
Block(-8,10,-2,quark:grate:0)
Block(-8,10,-1,quark:grate:0)
Block(-8,10,0,CONCRETE:0)
Block(-8,10,1,CONCRETE:0)
Block(-8,10,2,CONCRETE:0)
Block(-8,10,3,quark:world_stone_pavement:2)
Block(-8,10,4,quark:world_stone_pavement:2)
Block(-8,10,5,srparasites:parasiterubbledense:1)
Block(-8,10,6,quark:polished_stone:0)
Block(-8,10,7,quark:polished_stone:0)
Block(-8,10,8,quark:polished_stone:0)
RandomBlock(-8,11,-5,IRON_FENCE:0,30,IRON_FENCE:0,100)
Block(-8,11,0,quark:iron_plate:1)
Block(-8,11,2,quark:iron_plate:1)
Block(-8,11,4,quark:iron_plate:1)
Block(-8,11,6,DOUBLE_STEP:0)
Block(-8,11,7,quark:iron_plate:1)
Block(-8,12,6,DOUBLE_STEP:0)
Block(-8,12,7,quark:iron_plate:1)
Block(-8,13,6,DOUBLE_STEP:0)
Block(-8,13,7,quark:iron_plate:1)
Block(-8,13,8,quark:polished_stone:0)
Block(-8,14,6,DOUBLE_STEP:0)
Block(-8,14,7,quark:iron_plate:1)
Block(-8,14,8,CONCRETE:0)
Block(-8,15,6,DOUBLE_STEP:0)
Block(-8,15,7,quark:iron_plate:1)
Block(-8,16,6,DOUBLE_STEP:0)
Block(-8,16,7,quark:iron_plate:1)
Block(-8,17,5,quark:iron_plate_slab:8)
Block(-8,17,6,DOUBLE_STEP:0)
Block(-8,17,7,quark:iron_plate:1)
Block(-8,18,-3,srparasites:infestedbush:4)
RandomBlock(-8,18,4,IRON_FENCE:0,30,IRON_FENCE:0,100)
Block(-8,18,5,srparasites:parasitethin)
Block(-8,18,6,DOUBLE_STEP:0)
Block(-8,18,7,quark:iron_plate:1)
Block(-8,18,8,quark:polished_stone:0)
Block(-8,19,-3,srparasites:infestedbush:4)
RandomBlock(-8,19,4,IRON_FENCE:0,30,IRON_FENCE:0,100)
Block(-8,19,5,srparasites:parasitethin)
Block(-8,19,6,quark:iron_plate:1)
Block(-8,19,7,SMOOTH_STAIRS:0)
Block(-8,19,8,quark:iron_plate:1)
Block(-8,20,-3,srparasites:infestedbush:4)
Block(-8,20,5,quark:polished_stone:0)
Block(-8,20,6,SMOOTH_STAIRS:3)
RandomBlock(-8,20,8,IRON_FENCE:0,30,IRON_FENCE:0,100)
Block(-8,21,-5,srparasites:infestedbush:4)
Block(-8,21,-4,quark:iron_plate:1)
Block(-8,21,-3,srparasites:infestedbush:4)
Block(-8,21,4,quark:polished_stone:0)
Block(-8,21,5,STEP:0)
Block(-8,22,-5,srparasites:infestedbush:4)
Block(-8,22,-3,srparasites:infestedbush:4)
Block(-8,22,3,quark:iron_plate:1)
Block(-8,22,4,SMOOTH_STAIRS:3)
Block(-8,23,-7,STEP:0)
Block(-8,23,-5,srparasites:infestedbush:4)
Block(-8,23,-3,srparasites:infestedbush:4)
Block(-8,23,2,quark:iron_plate:1)
Block(-8,23,3,SMOOTH_STAIRS:3)
Block(-8,24,-5,srparasites:parasiterubbledense:1)
Block(-8,24,-4,srparasites:parasiterubbledense:1)
Block(-8,24,-3,srparasites:parasiterubbledense:1)
Block(-8,24,-2,srparasites:parasiterubbledense:1)
Block(-8,24,1,quark:iron_plate:1)
Block(-8,24,2,SMOOTH_STAIRS:3)
RandomBlock(-8,25,-7,CONCRETE:0,40,SMOOTH_BRICK:1,30,SMOOTH_BRICK:2,30,MOSSY_COBBLESTONE:0,30,COBBLESTONE:0,20,CONCRETE:0,100)
RandomBlock(-8,25,-6,CONCRETE:0,40,SMOOTH_BRICK:1,30,SMOOTH_BRICK:2,30,MOSSY_COBBLESTONE:0,30,COBBLESTONE:0,20,CONCRETE:0,100)
RandomBlock(-8,25,-5,CONCRETE:0,40,SMOOTH_BRICK:1,30,SMOOTH_BRICK:2,30,MOSSY_COBBLESTONE:0,30,COBBLESTONE:0,20,CONCRETE:0,100)
RandomBlock(-8,25,-4,CONCRETE:0,40,SMOOTH_BRICK:1,30,SMOOTH_BRICK:2,30,MOSSY_COBBLESTONE:0,30,COBBLESTONE:0,20,CONCRETE:0,100)
RandomBlock(-8,25,-3,CONCRETE:0,40,SMOOTH_BRICK:1,30,SMOOTH_BRICK:2,30,MOSSY_COBBLESTONE:0,30,COBBLESTONE:0,20,CONCRETE:0,100)
Block(-8,25,-2,quark:world_stone_pavement:2)
Block(-8,25,-1,quark:world_stone_pavement:2)
Block(-8,25,0,quark:iron_plate:1)
Block(-8,25,1,SMOOTH_STAIRS:3)
Block(-8,26,-6,DISPENSER:1)
Block(-8,26,-5,quark:basalt_wall:0)
Block(-8,26,-4,quark:basalt_wall:0)
Block(-8,26,-3,quark:iron_plate:1)
Block(-8,26,0,quark:stone_diorite_bricks_wall:0)
Block(-8,27,-6,IRON_TRAPDOOR:0)
Block(-7,0,-7,quark:world_stone_pavement:4)
Block(-7,0,-6,quark:world_stone_pavement:2)
Block(-7,0,-5,quark:world_stone_pavement:2)
Block(-7,0,-4,quark:world_stone_pavement:4)
Block(-7,0,-3,quark:world_stone_pavement:2)
Block(-7,0,-2,quark:world_stone_pavement:1)
Block(-7,0,-1,quark:world_stone_pavement:2)
Block(-7,0,0,CONCRETE:0)
Block(-7,0,1,CONCRETE:0)
Block(-7,0,2,quark:world_stone_pavement:2)
Block(-7,0,3,CONCRETE:0)
Block(-7,0,4,quark:world_stone_pavement:2)
Block(-7,0,5,quark:world_stone_pavement:2)
Block(-7,0,6,CONCRETE:0)
Block(-7,0,7,CONCRETE:0)
Block(-7,0,8,CONCRETE:0)
Block(-7,1,-7,quark:world_stone_pavement:1)
Block(-7,1,-6,quark:world_stone_pavement:2)
Block(-7,1,-5,quark:world_stone_pavement:2)
Block(-7,1,-4,quark:world_stone_pavement:2)
Block(-7,1,-3,quark:world_stone_pavement:2)
Block(-7,1,-2,quark:world_stone_pavement:1)
Block(-7,1,-1,quark:world_stone_pavement:2)
Block(-7,1,0,quark:world_stone_pavement:2)
Block(-7,1,1,CONCRETE:0)
Block(-7,1,2,CONCRETE:0)
Block(-7,1,3,CONCRETE:0)
Block(-7,1,4,quark:world_stone_pavement:2)
Block(-7,1,5,CONCRETE:0)
Block(-7,1,6,quark:world_stone_pavement:2)
Block(-7,1,7,CONCRETE:0)
Block(-7,1,8,quark:world_stone_pavement:2)
Block(-7,2,-7,quark:world_stone_pavement:1)
Block(-7,2,-6,quark:world_stone_pavement:2)
Block(-7,2,-5,quark:world_stone_pavement:2)
Block(-7,2,-4,quark:world_stone_pavement:4)
Block(-7,2,-3,quark:world_stone_pavement:2)
Block(-7,2,-2,quark:world_stone_pavement:1)
Block(-7,2,-1,quark:world_stone_pavement:2)
Block(-7,2,0,quark:world_stone_pavement:2)
Block(-7,2,1,CONCRETE:0)
Block(-7,2,2,CONCRETE:0)
Block(-7,2,3,CONCRETE:0)
Block(-7,2,4,CONCRETE:0)
Block(-7,2,5,CONCRETE:0)
Block(-7,2,6,quark:world_stone_pavement:2)
Block(-7,2,7,CONCRETE:0)
Block(-7,2,8,quark:world_stone_pavement:2)
Block(-7,3,-7,quark:world_stone_pavement:4)
Block(-7,3,-6,quark:world_stone_pavement:2)
Block(-7,3,-5,quark:world_stone_pavement:2)
Block(-7,3,-4,quark:world_stone_pavement:4)
Block(-7,3,-3,quark:world_stone_pavement:2)
Block(-7,3,-2,quark:world_stone_pavement:1)
Block(-7,3,-1,quark:world_stone_pavement:2)
Block(-7,3,0,quark:world_stone_pavement:2)
Block(-7,3,1,CONCRETE:0)
Block(-7,3,2,quark:world_stone_pavement:2)
Block(-7,3,3,CONCRETE:0)
Block(-7,3,4,CONCRETE:0)
Block(-7,3,5,quark:world_stone_pavement:2)
Block(-7,3,6,CONCRETE:0)
Block(-7,3,7,CONCRETE:0)
Block(-7,3,8,CONCRETE:0)
Block(-7,4,-7,quark:world_stone_pavement:4)
Block(-7,4,-6,quark:world_stone_pavement:2)
Block(-7,4,-5,srparasites:parasiterubbledense:1)
Block(-7,4,-4,srparasites:parasiterubbledense:1)
Block(-7,4,-3,srparasites:parasiterubbledense:1)
Block(-7,4,-2,quark:world_stone_pavement:1)
Block(-7,4,-1,quark:world_stone_pavement:2)
Block(-7,4,0,CONCRETE:0)
Block(-7,4,1,CONCRETE:0)
Block(-7,4,2,CONCRETE:0)
Block(-7,4,3,CONCRETE:0)
Block(-7,4,4,STONE:0)
Block(-7,4,5,CONCRETE:0)
Block(-7,4,6,quark:world_stone_pavement:2)
Block(-7,4,7,quark:world_stone_pavement:2)
Block(-7,4,8,quark:world_stone_pavement:2)
Block(-7,5,-7,srparasites:parasiterubbledense:1)
Block(-7,5,-6,srparasites:parasiterubbledense:1)
Block(-7,5,-5,srparasites:parasiterubbledense:1)
Block(-7,5,-4,quark:world_stone_pavement:2)
Block(-7,5,-3,quark:world_stone_pavement:2)
Block(-7,5,-2,quark:world_stone_pavement:2)
Block(-7,5,-1,quark:world_stone_pavement:2)
Block(-7,5,0,CONCRETE:0)
Block(-7,5,1,CONCRETE:0)
Block(-7,5,2,quark:world_stone_pavement:2)
Block(-7,5,3,srparasites:parasiterubbledense:1)
Block(-7,5,4,STONE:0)
Block(-7,5,5,CONCRETE:0)
Block(-7,5,6,quark:world_stone_pavement:2)
Block(-7,5,7,CONCRETE:0)
Block(-7,5,8,CONCRETE:0)
Block(-7,6,-7,LEAVES:4)
Block(-7,6,-6,quark:world_stone_pavement:2)
Block(-7,6,-5,quark:world_stone_pavement:2)
Block(-7,6,-4,quark:world_stone_pavement:1)
Block(-7,6,-3,quark:world_stone_pavement:2)
Block(-7,6,-2,quark:world_stone_pavement:4)
Block(-7,6,-1,quark:world_stone_pavement:2)
Block(-7,6,0,quark:world_stone_pavement:2)
Block(-7,6,1,quark:marble_wall:0)
Block(-7,6,2,quark:marble_wall:0)
Block(-7,6,4,STONE:0)
Block(-7,6,5,CONCRETE:0)
Block(-7,6,6,quark:world_stone_pavement:2)
Block(-7,6,7,CONCRETE:0)
Block(-7,6,8,CONCRETE:0)
Block(-7,7,-7,LEAVES:4)
Block(-7,7,-6,LEAVES:12)
Block(-7,7,-5,quark:world_stone_pavement:4)
Block(-7,7,-4,REDSTONE_LAMP_OFF:0)
Block(-7,7,-3,quark:world_stone_pavement:2)
Block(-7,7,-2,quark:world_stone_pavement:2)
Block(-7,7,-1,CONCRETE:0)
Block(-7,7,0,REDSTONE_WIRE:0)
Block(-7,7,1,quark:marble_wall:0)
Block(-7,7,2,quark:marble_wall:0)
Block(-7,7,4,STONE:0)
Block(-7,7,5,CONCRETE:0)
Block(-7,7,6,quark:world_stone_pavement:2)
Block(-7,7,7,CONCRETE:0)
Block(-7,7,8,CONCRETE:0)
Block(-7,8,-7,quark:world_stone_pavement:4)
Block(-7,8,-6,quark:world_stone_pavement:4)
Block(-7,8,-5,LEAVES:4)
Block(-7,8,-4,quark:world_stone_pavement:4)
Block(-7,8,-3,quark:world_stone_pavement:4)
Block(-7,8,-2,quark:world_stone_pavement:2)
Block(-7,8,-1,quark:world_stone_pavement:2)
Block(-7,8,0,CONCRETE:0)
Block(-7,8,1,CONCRETE:0)
Block(-7,8,2,CONCRETE:0)
Block(-7,8,3,srparasites:parasiterubbledense:1)
Block(-7,8,4,CONCRETE:0)
Block(-7,8,5,quark:polished_stone:0)
Block(-7,8,6,quark:polished_stone:0)
Block(-7,8,7,CONCRETE:0)
Block(-7,8,8,quark:world_stone_pavement:2)
Block(-7,9,-7,quark:iron_plate_stairs:7)
Block(-7,9,-6,quark:iron_plate_stairs:6)
Block(-7,9,-5,CONCRETE:0)
Block(-7,9,-4,LEAVES:4)
Block(-7,9,-3,CONCRETE:0)
Block(-7,9,-2,CONCRETE:0)
Block(-7,9,0,CONCRETE:0)
Block(-7,9,1,quark:world_stone_pavement:2)
Block(-7,9,2,CONCRETE:0)
Block(-7,9,3,CONCRETE:0)
Block(-7,9,4,quark:world_stone_pavement:2)
Block(-7,9,5,quark:polished_stone:0)
Block(-7,9,6,quark:world_stone_pavement:2)
Block(-7,9,7,quark:polished_stone:0)
Block(-7,9,8,quark:polished_stone:0)
Block(-7,10,-7,quark:iron_plate_stairs:1)
Block(-7,10,-6,quark:iron_plate_stairs:1)
Block(-7,10,-5,quark:world_stone_pavement:2)
Block(-7,10,-4,CONCRETE:0)
Block(-7,10,-3,quark:world_stone_pavement:2)
Block(-7,10,-2,CONCRETE:0)
Block(-7,10,-1,quark:grate:0)
Block(-7,10,0,quark:world_stone_pavement:2)
Block(-7,10,1,CONCRETE:0)
Block(-7,10,2,quark:world_stone_pavement:2)
Block(-7,10,3,srparasites:parasiterubbledense:1)
Block(-7,10,4,srparasites:parasiterubbledense:1)
Block(-7,10,5,quark:polished_stone:0)
Block(-7,10,6,quark:polished_stone:0)
Block(-7,10,7,quark:polished_stone:0)
Block(-7,10,8,quark:polished_stone:0)
RandomBlock(-7,11,-5,IRON_FENCE:0,30,IRON_FENCE:0,100)
RandomBlock(-7,11,-4,IRON_FENCE:0,30,IRON_FENCE:0,100)
RandomBlock(-7,11,-3,IRON_FENCE:0,30,IRON_FENCE:0,100)
RandomBlock(-7,11,-2,IRON_FENCE:0,30,IRON_FENCE:0,100)
Block(-7,11,0,quark:iron_plate:1)
Block(-7,11,2,quark:iron_plate:1)
Block(-7,11,3,srparasites:infestedbush:3)
Block(-7,11,4,quark:iron_plate:1)
Block(-7,11,6,quark:polished_stone:0)
Block(-7,11,7,quark:polished_stone:0)
Block(-7,11,8,quark:polished_stone:0)
Block(-7,12,4,quark:iron_plate:1)
RandomBlock(-7,12,6,CONCRETE:0,40,SMOOTH_BRICK:1,30,SMOOTH_BRICK:2,30,MOSSY_COBBLESTONE:0,30,COBBLESTONE:0,20,CONCRETE:0,100)
Block(-7,12,7,quark:polished_stone:0)
Block(-7,12,8,quark:polished_stone:0)
Block(-7,13,4,quark:iron_plate:1)
RandomBlock(-7,13,6,CONCRETE:0,40,SMOOTH_BRICK:1,30,SMOOTH_BRICK:2,30,MOSSY_COBBLESTONE:0,30,COBBLESTONE:0,20,CONCRETE:0,100)
Block(-7,13,7,quark:polished_stone:0)
Block(-7,13,8,quark:polished_stone:0)
Block(-7,14,4,quark:iron_plate:1)
RandomBlock(-7,14,6,CONCRETE:0,40,SMOOTH_BRICK:1,30,SMOOTH_BRICK:2,30,MOSSY_COBBLESTONE:0,30,COBBLESTONE:0,20,CONCRETE:0,100)
Block(-7,14,7,quark:polished_stone:0)
Block(-7,14,8,quark:iron_plate:1)
Block(-7,15,4,quark:iron_plate:1)
Block(-7,15,5,quark:grate:0)
RandomBlock(-7,15,6,CONCRETE:0,40,SMOOTH_BRICK:1,30,SMOOTH_BRICK:2,30,MOSSY_COBBLESTONE:0,30,COBBLESTONE:0,20,CONCRETE:0,100)
Block(-7,15,7,quark:polished_stone:0)
Block(-7,16,4,quark:iron_plate:1)
Block(-7,16,5,quark:iron_plate:1)
Block(-7,16,6,quark:iron_plate:1)
Block(-7,16,7,quark:iron_plate:1)
Block(-7,16,8,quark:iron_plate:1)
Block(-7,17,5,quark:iron_plate_slab:8)
RandomBlock(-7,17,6,CONCRETE:0,40,SMOOTH_BRICK:1,30,SMOOTH_BRICK:2,30,MOSSY_COBBLESTONE:0,30,COBBLESTONE:0,20,CONCRETE:0,100)
Block(-7,17,7,quark:world_stone_pavement:2)
RandomBlock(-7,18,4,IRON_FENCE:0,30,IRON_FENCE:0,100)
Block(-7,18,6,quark:world_stone_pavement:2)
Block(-7,18,7,quark:iron_plate:1)
Block(-7,18,8,SMOOTH_STAIRS:5)
RandomBlock(-7,19,4,IRON_FENCE:0,30,IRON_FENCE:0,100)
Block(-7,19,6,quark:iron_plate:1)
Block(-7,19,7,quark:iron_plate:1)
Block(-7,19,8,quark:iron_plate:1)
Block(-7,20,-2,srparasites:infestedbush:4)
Block(-7,20,5,quark:polished_stone:0)
Block(-7,20,6,SMOOTH_STAIRS:3)
Block(-7,20,7,quark:stone_diorite_bricks_wall:0)
Block(-7,20,8,quark:stone_diorite_bricks_wall:0)
Block(-7,21,-5,srparasites:infestedbush:4)
Block(-7,21,-4,quark:iron_plate:1)
Block(-7,21,-2,srparasites:infestedbush:4)
Block(-7,21,4,quark:polished_stone:0)
Block(-7,21,5,STEP:0)
Block(-7,22,-5,srparasites:infestedbush:4)
Block(-7,22,-3,srparasites:infestedbush:4)
Block(-7,22,-2,srparasites:infestedbush:4)
Block(-7,22,3,quark:iron_plate:1)
Block(-7,22,4,SMOOTH_STAIRS:3)
Block(-7,23,-7,STEP:0)
Block(-7,23,-5,srparasites:infestedbush:4)
Block(-7,23,-4,srparasites:infestedbush:4)
Block(-7,23,-3,srparasites:infestedbush:4)
Block(-7,23,-2,srparasites:infestedbush:4)
Block(-7,23,2,quark:iron_plate:1)
Block(-7,23,3,SMOOTH_STAIRS:3)
Block(-7,24,-5,srparasites:parasiterubbledense:1)
Block(-7,24,-4,srparasites:parasiterubbledense:1)
Block(-7,24,-3,srparasites:parasiterubbledense:1)
Block(-7,24,-2,srparasites:parasiterubbledense:1)
Block(-7,24,1,quark:iron_plate:1)
Block(-7,24,2,SMOOTH_STAIRS:3)
RandomBlock(-7,25,-7,CONCRETE:0,40,SMOOTH_BRICK:1,30,SMOOTH_BRICK:2,30,MOSSY_COBBLESTONE:0,30,COBBLESTONE:0,20,CONCRETE:0,100)
RandomBlock(-7,25,-6,CONCRETE:0,40,SMOOTH_BRICK:1,30,SMOOTH_BRICK:2,30,MOSSY_COBBLESTONE:0,30,COBBLESTONE:0,20,CONCRETE:0,100)
RandomBlock(-7,25,-5,CONCRETE:0,40,SMOOTH_BRICK:1,30,SMOOTH_BRICK:2,30,MOSSY_COBBLESTONE:0,30,COBBLESTONE:0,20,CONCRETE:0,100)
RandomBlock(-7,25,-4,CONCRETE:0,40,SMOOTH_BRICK:1,30,SMOOTH_BRICK:2,30,MOSSY_COBBLESTONE:0,30,COBBLESTONE:0,20,CONCRETE:0,100)
RandomBlock(-7,25,-3,CONCRETE:0,40,SMOOTH_BRICK:1,30,SMOOTH_BRICK:2,30,MOSSY_COBBLESTONE:0,30,COBBLESTONE:0,20,CONCRETE:0,100)
RandomBlock(-7,25,-2,CONCRETE:0,40,SMOOTH_BRICK:1,30,SMOOTH_BRICK:2,30,MOSSY_COBBLESTONE:0,30,COBBLESTONE:0,20,CONCRETE:0,100)
Block(-7,25,-1,quark:polished_stone:0)
Block(-7,25,0,quark:iron_plate:1)
Block(-7,25,1,SMOOTH_STAIRS:3)
Block(-7,26,-3,STEP:0)
Block(-7,26,0,quark:stone_diorite_bricks_wall:0)
Block(-6,0,-7,quark:world_stone_pavement:1)
Block(-6,0,-6,quark:world_stone_pavement:4)
Block(-6,0,-5,quark:world_stone_pavement:2)
Block(-6,0,-4,quark:world_stone_pavement:2)
Block(-6,0,-3,quark:world_stone_pavement:4)
Block(-6,0,-2,quark:world_stone_pavement:1)
Block(-6,0,-1,CONCRETE:0)
Block(-6,0,0,CONCRETE:0)
Block(-6,0,1,quark:world_stone_pavement:2)
Block(-6,0,2,quark:world_stone_pavement:2)
Block(-6,0,3,CONCRETE:0)
Block(-6,0,4,CONCRETE:0)
Block(-6,0,5,quark:world_stone_pavement:2)
Block(-6,0,6,CONCRETE:0)
Block(-6,0,7,quark:world_stone_pavement:2)
Block(-6,0,8,quark:world_stone_pavement:2)
Block(-6,1,-7,quark:iron_plate:1)
Block(-6,1,-6,STATIONARY_WATER:0)
Block(-6,1,-5,quark:iron_plate:1)
Block(-6,1,-4,STATIONARY_WATER:0)
Block(-6,1,-3,quark:iron_plate:1)
Block(-6,1,-2,quark:world_stone_pavement:2)
Block(-6,1,-1,CONCRETE:0)
Block(-6,1,0,CONCRETE:0)
Block(-6,1,1,quark:world_stone_pavement:2)
Block(-6,1,2,quark:world_stone_pavement:2)
Block(-6,1,3,CONCRETE:0)
Block(-6,1,4,CONCRETE:0)
Block(-6,1,5,CONCRETE:0)
Block(-6,1,6,CONCRETE:0)
Block(-6,1,7,CONCRETE:0)
Block(-6,1,8,CONCRETE:0)
Block(-6,2,-7,quark:iron_plate:1)
Block(-6,2,-6,STATIONARY_WATER:0)
Block(-6,2,-5,quark:iron_plate:1)
Block(-6,2,-4,STATIONARY_WATER:0)
Block(-6,2,-3,quark:iron_plate:1)
Block(-6,2,-2,quark:world_stone_pavement:1)
Block(-6,2,-1,CONCRETE:0)
Block(-6,2,0,CONCRETE:0)
Block(-6,2,1,CONCRETE:0)
Block(-6,2,2,quark:world_stone_pavement:2)
Block(-6,2,3,CONCRETE:0)
Block(-6,2,4,CONCRETE:0)
Block(-6,2,5,CONCRETE:0)
Block(-6,2,6,CONCRETE:0)
Block(-6,2,7,CONCRETE:0)
Block(-6,2,8,CONCRETE:0)
Block(-6,3,-7,quark:iron_plate:1)
Block(-6,3,-6,STATIONARY_WATER:0)
Block(-6,3,-5,STATIONARY_WATER:0)
Block(-6,3,-4,STATIONARY_WATER:0)
Block(-6,3,-3,quark:iron_plate:1)
Block(-6,3,-2,quark:world_stone_pavement:1)
Block(-6,3,-1,quark:world_stone_pavement:2)
Block(-6,3,0,quark:world_stone_pavement:2)
Block(-6,3,1,quark:world_stone_pavement:2)
Block(-6,3,2,quark:world_stone_pavement:2)
Block(-6,3,3,quark:world_stone_pavement:2)
Block(-6,3,4,quark:world_stone_pavement:2)
Block(-6,3,5,CONCRETE:0)
Block(-6,3,6,CONCRETE:0)
Block(-6,3,7,CONCRETE:0)
Block(-6,3,8,CONCRETE:0)
Block(-6,4,-7,quark:iron_plate:1)
Block(-6,4,-6,STATIONARY_WATER:0)
Block(-6,4,-5,STATIONARY_WATER:1)
Block(-6,4,-4,STATIONARY_WATER:1)
Block(-6,4,-3,STATIONARY_WATER:0)
Block(-6,4,-2,srparasites:parasiterubbledense)
Block(-6,4,-1,CONCRETE:0)
Block(-6,4,0,CONCRETE:0)
Block(-6,4,1,CONCRETE:0)
Block(-6,4,2,quark:world_stone_pavement:2)
Block(-6,4,3,quark:world_stone_pavement:2)
Block(-6,4,5,CONCRETE:0)
Block(-6,4,6,quark:world_stone_pavement:2)
Block(-6,4,7,CONCRETE:0)
Block(-6,4,8,CONCRETE:0)
Block(-6,5,-7,srparasites:parasitethin)
Block(-6,5,-6,srparasites:parasitethin)
Block(-6,5,-5,srparasites:parasitethin)
Block(-6,5,-4,srparasites:parasitethin)
Block(-6,5,-3,srparasites:parasitethin)
Block(-6,5,-2,srparasites:parasiterubbledense)
Block(-6,5,-1,quark:world_stone_pavement:2)
Block(-6,5,0,quark:world_stone_pavement:2)
Block(-6,5,1,quark:world_stone_pavement:2)
Block(-6,5,2,quark:world_stone_pavement:2)
Block(-6,5,3,srparasites:parasiterubbledense:1)
Block(-6,5,4,quark:grate:0)
Block(-6,5,5,CONCRETE:0)
Block(-6,5,6,CONCRETE:0)
Block(-6,5,7,quark:world_stone_pavement:2)
Block(-6,5,8,CONCRETE:0)
Block(-6,6,-7,srparasites:parasitethin)
Block(-6,6,-6,srparasites:parasitethin)
Block(-6,6,-5,srparasites:parasitethin)
Block(-6,6,-4,srparasites:parasitethin)
Block(-6,6,-3,srparasites:parasitethin)
Block(-6,6,-2,srparasites:parasiterubbledense:1)
Block(-6,6,-1,quark:world_stone_pavement:2)
Block(-6,6,0,quark:world_stone_pavement:2)
Block(-6,6,1,quark:world_stone_pavement:1)
Block(-6,6,2,quark:marble_wall:0)
Block(-6,6,5,quark:world_stone_pavement:2)
Block(-6,6,6,CONCRETE:0)
Block(-6,6,7,CONCRETE:0)
Block(-6,6,8,CONCRETE:0)
Block(-6,7,-7,srparasites:parasitethin)
Block(-6,7,-6,srparasites:parasitethin)
Block(-6,7,-5,srparasites:parasitethin)
Block(-6,7,-4,srparasites:parasitethin)
Block(-6,7,-3,srparasites:parasitethin)
Block(-6,7,-2,quark:world_stone_pavement:4)
Block(-6,7,-1,quark:world_stone_pavement:2)
Block(-6,7,0,REDSTONE_WIRE:0)
Block(-6,7,1,REDSTONE_WIRE:0)
Block(-6,7,2,quark:marble_wall:0)
Block(-6,7,5,srparasites:parasiterubbledense:1)
Block(-6,7,6,quark:world_stone_pavement:2)
Block(-6,7,7,CONCRETE:0)
Block(-6,7,8,CONCRETE:0)
Block(-6,8,-7,srparasites:parasitethin)
Block(-6,8,-6,srparasites:parasitethin)
Block(-6,8,-5,srparasites:parasitethin)
Block(-6,8,-4,srparasites:parasitethin)
Block(-6,8,-3,srparasites:parasitethin)
Block(-6,8,-2,quark:world_stone_pavement:4)
Block(-6,8,-1,CONCRETE:0)
Block(-6,8,0,CONCRETE:0)
Block(-6,8,1,CONCRETE:0)
Block(-6,8,2,quark:world_stone_pavement:2)
Block(-6,8,3,CONCRETE:0)
Block(-6,8,4,CONCRETE:0)
Block(-6,8,5,quark:polished_stone:0)
Block(-6,8,6,quark:world_stone_pavement:2)
Block(-6,8,7,quark:world_stone_pavement:2)
Block(-6,8,8,quark:world_stone_pavement:2)
Block(-6,9,-5,srparasites:parasitethin)
Block(-6,9,-4,srparasites:parasitethin)
Block(-6,9,-3,srparasites:parasitethin)
Block(-6,9,-2,CONCRETE:0)
Block(-6,9,0,CONCRETE:0)
Block(-6,9,1,quark:world_stone_pavement:2)
Block(-6,9,2,quark:world_stone_pavement:2)
Block(-6,9,3,quark:world_stone_pavement:2)
Block(-6,9,4,quark:polished_stone:0)
Block(-6,9,5,quark:world_stone_pavement:2)
Block(-6,9,6,quark:polished_stone:0)
Block(-6,9,7,quark:polished_stone:0)
Block(-6,9,8,quark:polished_stone:0)
Block(-6,10,-5,srparasites:parasitethin)
Block(-6,10,-4,srparasites:parasitethin)
Block(-6,10,-3,srparasites:parasitethin)
Block(-6,10,-2,quark:world_stone_pavement:2)
Block(-6,10,-1,quark:grate:0)
Block(-6,10,0,CONCRETE:0)
Block(-6,10,1,srparasites:parasiterubbledense:1)
Block(-6,10,2,quark:world_stone_pavement:2)
Block(-6,10,3,srparasites:parasiterubbledense:1)
Block(-6,10,4,quark:polished_stone:0)
Block(-6,10,5,quark:world_stone_pavement:2)
Block(-6,10,6,quark:polished_stone:0)
Block(-6,10,7,quark:world_stone_pavement:2)
Block(-6,10,8,quark:polished_stone:0)
RandomBlock(-6,11,-2,IRON_FENCE:0,30,IRON_FENCE:0,100)
Block(-6,11,0,quark:iron_plate:1)
Block(-6,11,1,srparasites:infestedbush:3)
Block(-6,11,2,quark:iron_plate:1)
Block(-6,11,6,quark:iron_plate:1)
Block(-6,11,7,quark:iron_plate:1)
Block(-6,11,8,quark:world_stone_pavement:2)
Block(-6,12,1,srparasites:infestedbush:3)
Block(-6,12,6,quark:iron_plate:1)
Block(-6,12,7,quark:iron_plate:1)
Block(-6,12,8,quark:world_stone_pavement:2)
Block(-6,13,1,srparasites:infestedbush:3)
Block(-6,13,6,quark:iron_plate:1)
Block(-6,13,7,quark:polished_stone:0)
Block(-6,13,8,quark:world_stone_pavement:2)
Block(-6,14,1,srparasites:infestedbush:3)
Block(-6,14,6,DOUBLE_STEP:0)
Block(-6,14,7,quark:polished_stone:0)
Block(-6,14,8,quark:polished_stone:0)
Block(-6,15,6,DOUBLE_STEP:0)
Block(-6,15,7,quark:polished_stone:0)
Block(-6,16,6,quark:polished_stone:0)
Block(-6,16,7,quark:polished_stone:0)
Block(-6,17,5,quark:iron_plate_slab:8)
RandomBlock(-6,17,6,CONCRETE:0,40,SMOOTH_BRICK:1,30,SMOOTH_BRICK:2,30,MOSSY_COBBLESTONE:0,30,COBBLESTONE:0,20,CONCRETE:0,100)
Block(-6,17,7,quark:polished_stone:0)
RandomBlock(-6,18,4,IRON_FENCE:0,30,IRON_FENCE:0,100)
Block(-6,18,5,srparasites:parasitethin)
Block(-6,18,6,DOUBLE_STEP:0)
Block(-6,18,7,quark:iron_plate:1)
RandomBlock(-6,19,4,IRON_FENCE:0,30,IRON_FENCE:0,100)
Block(-6,19,5,srparasites:parasitethin)
Block(-6,19,6,quark:iron_plate:1)
Block(-6,19,7,quark:iron_plate:1)
RandomBlock(-6,19,8,CONCRETE:0,40,SMOOTH_BRICK:1,30,SMOOTH_BRICK:2,30,MOSSY_COBBLESTONE:0,30,COBBLESTONE:0,20,CONCRETE:0,100)
Block(-6,20,5,quark:polished_stone:0)
Block(-6,20,6,SMOOTH_STAIRS:3)
Block(-6,21,-4,quark:iron_plate:1)
Block(-6,21,4,quark:polished_stone:0)
Block(-6,21,5,STEP:0)
Block(-6,22,-6,srparasites:infestedbush:4)
Block(-6,22,-4,srparasites:infestedbush:4)
Block(-6,22,3,quark:iron_plate:1)
Block(-6,22,4,SMOOTH_STAIRS:3)
Block(-6,23,-7,STEP:0)
Block(-6,23,-6,srparasites:infestedbush:4)
Block(-6,23,-4,srparasites:infestedbush:4)
Block(-6,23,2,quark:iron_plate:1)
Block(-6,23,3,SMOOTH_STAIRS:3)
Block(-6,24,-6,srparasites:parasiterubbledense:1)
Block(-6,24,-4,srparasites:parasiterubbledense:1)
Block(-6,24,1,quark:iron_plate:1)
Block(-6,24,2,SMOOTH_STAIRS:3)
RandomBlock(-6,25,-7,CONCRETE:0,40,SMOOTH_BRICK:1,30,SMOOTH_BRICK:2,30,MOSSY_COBBLESTONE:0,30,COBBLESTONE:0,20,CONCRETE:0,100)
RandomBlock(-6,25,-6,CONCRETE:0,40,SMOOTH_BRICK:1,30,SMOOTH_BRICK:2,30,MOSSY_COBBLESTONE:0,30,COBBLESTONE:0,20,CONCRETE:0,100)
RandomBlock(-6,25,-5,CONCRETE:0,40,SMOOTH_BRICK:1,30,SMOOTH_BRICK:2,30,MOSSY_COBBLESTONE:0,30,COBBLESTONE:0,20,CONCRETE:0,100)
RandomBlock(-6,25,-4,CONCRETE:0,40,SMOOTH_BRICK:1,30,SMOOTH_BRICK:2,30,MOSSY_COBBLESTONE:0,30,COBBLESTONE:0,20,CONCRETE:0,100)
RandomBlock(-6,25,-3,CONCRETE:0,40,SMOOTH_BRICK:1,30,SMOOTH_BRICK:2,30,MOSSY_COBBLESTONE:0,30,COBBLESTONE:0,20,CONCRETE:0,100)
RandomBlock(-6,25,-2,CONCRETE:0,40,SMOOTH_BRICK:1,30,SMOOTH_BRICK:2,30,MOSSY_COBBLESTONE:0,30,COBBLESTONE:0,20,CONCRETE:0,100)
RandomBlock(-6,25,-1,CONCRETE:0,40,SMOOTH_BRICK:1,30,SMOOTH_BRICK:2,30,MOSSY_COBBLESTONE:0,30,COBBLESTONE:0,20,CONCRETE:0,100)
Block(-6,25,0,quark:iron_plate:1)
Block(-6,25,1,SMOOTH_STAIRS:3)
Block(-6,26,-6,DISPENSER:1)
Block(-6,26,-5,quark:basalt_wall:0)
Block(-6,26,-4,quark:basalt_wall:0)
Block(-6,26,-3,quark:iron_plate:1)
Block(-6,26,0,quark:stone_diorite_bricks_wall:0)
Block(-6,27,-6,IRON_TRAPDOOR:0)
Block(-5,0,-7,quark:world_stone_pavement:2)
Block(-5,0,-6,quark:world_stone_pavement:2)
Block(-5,0,-5,quark:world_stone_pavement:2)
Block(-5,0,-4,quark:world_stone_pavement:2)
Block(-5,0,-3,quark:world_stone_pavement:1)
Block(-5,0,-2,quark:world_stone_pavement:1)
Block(-5,0,-1,quark:world_stone_pavement:2)
Block(-5,0,0,CONCRETE:0)
Block(-5,0,1,CONCRETE:0)
Block(-5,0,2,CONCRETE:0)
Block(-5,0,3,CONCRETE:0)
Block(-5,0,4,quark:world_stone_pavement:2)
Block(-5,0,5,quark:world_stone_pavement:2)
Block(-5,0,6,CONCRETE:0)
Block(-5,0,7,CONCRETE:0)
Block(-5,0,8,quark:world_stone_pavement:2)
RandomBlock(-5,1,-7,SMOOTH_BRICK:0,5,SMOOTH_BRICK:0,10,thermalfoundation:ore:7,50,SMOOTH_BRICK:0,100)
Block(-5,1,-6,quark:iron_plate:1)
Block(-5,1,-5,STATIONARY_WATER:0)
Block(-5,1,-4,quark:iron_plate:1)
Block(-5,1,-3,STATIONARY_WATER:0)
Block(-5,1,-2,quark:world_stone_pavement:4)
Block(-5,1,-1,quark:world_stone_pavement:2)
Block(-5,1,0,CONCRETE:0)
Block(-5,1,1,CONCRETE:0)
Block(-5,1,2,CONCRETE:0)
Block(-5,1,3,CONCRETE:0)
Block(-5,1,4,CONCRETE:0)
Block(-5,1,5,quark:world_stone_pavement:2)
Block(-5,1,6,quark:world_stone_pavement:2)
Block(-5,1,7,quark:world_stone_pavement:2)
Block(-5,1,8,CONCRETE:0)
RandomBlock(-5,2,-7,SMOOTH_BRICK:0,5,SMOOTH_BRICK:0,10,thermalfoundation:ore:7,50,SMOOTH_BRICK:0,100)
Block(-5,2,-6,quark:iron_plate:1)
Block(-5,2,-5,STATIONARY_WATER:0)
Block(-5,2,-4,quark:iron_plate:1)
Block(-5,2,-3,STATIONARY_WATER:0)
Block(-5,2,-2,quark:world_stone_pavement:1)
Block(-5,2,-1,CONCRETE:0)
Block(-5,2,0,CONCRETE:0)
Block(-5,2,1,quark:world_stone_pavement:2)
Block(-5,2,2,CONCRETE:0)
Block(-5,2,3,quark:world_stone_pavement:2)
Block(-5,2,4,CONCRETE:0)
Block(-5,2,5,quark:world_stone_pavement:2)
Block(-5,2,6,quark:world_stone_pavement:2)
Block(-5,2,7,CONCRETE:0)
Block(-5,2,8,CONCRETE:0)
Block(-5,3,-7,STATIONARY_WATER:0)
Block(-5,3,-6,quark:iron_plate:1)
Block(-5,3,-5,STATIONARY_WATER:0)
Block(-5,3,-4,STATIONARY_WATER:0)
Block(-5,3,-3,STATIONARY_WATER:0)
Block(-5,3,-2,quark:world_stone_pavement:2)
Block(-5,3,-1,CONCRETE:0)
Block(-5,3,0,quark:world_stone_pavement:2)
Block(-5,3,1,CONCRETE:0)
Block(-5,3,2,CONCRETE:0)
Block(-5,3,3,quark:world_stone_pavement:2)
Block(-5,3,4,quark:world_stone_pavement:2)
Block(-5,3,5,quark:world_stone_pavement:2)
Block(-5,3,6,quark:world_stone_pavement:2)
Block(-5,3,7,quark:world_stone_pavement:2)
Block(-5,3,8,quark:world_stone_pavement:2)
Block(-5,4,-7,STATIONARY_WATER:0)
Block(-5,4,-6,STATIONARY_WATER:0)
Block(-5,4,-5,STATIONARY_WATER:0)
Block(-5,4,-4,STATIONARY_WATER:0)
Block(-5,4,-3,STATIONARY_WATER:0)
Block(-5,4,-2,srparasites:parasiterubbledense)
Block(-5,4,-1,CONCRETE:0)
Block(-5,4,0,quark:world_stone_pavement:2)
Block(-5,4,1,quark:world_stone_pavement:2)
Block(-5,4,2,quark:world_stone_pavement:2)
Block(-5,4,3,CONCRETE:0)
Block(-5,4,5,quark:world_stone_pavement:2)
Block(-5,4,6,quark:world_stone_pavement:2)
Block(-5,4,7,quark:world_stone_pavement:2)
Block(-5,4,8,CONCRETE:0)
Block(-5,5,-2,srparasites:parasiterubbledense:1)
Block(-5,5,-1,CONCRETE:0)
Block(-5,5,0,CONCRETE:0)
Block(-5,5,1,CONCRETE:0)
Block(-5,5,2,CONCRETE:0)
Block(-5,5,3,srparasites:parasiterubbledense:1)
Block(-5,5,4,quark:grate:0)
Block(-5,5,5,quark:world_stone_pavement:2)
Block(-5,5,6,CONCRETE:0)
Block(-5,5,7,quark:world_stone_pavement:2)
Block(-5,5,8,CONCRETE:0)
Block(-5,6,-2,quark:world_stone_pavement:2)
Block(-5,6,-1,CONCRETE:0)
Block(-5,6,0,quark:world_stone_pavement:2)
Block(-5,6,1,quark:world_stone_pavement:1)
Block(-5,6,2,quark:marble_wall:0)
Block(-5,6,5,srparasites:parasiterubbledense:1)
Block(-5,6,6,quark:world_stone_pavement:2)
Block(-5,6,7,CONCRETE:0)
Block(-5,6,8,quark:world_stone_pavement:2)
Block(-5,7,-2,REDSTONE_LAMP_OFF:0)
Block(-5,7,-1,REDSTONE_WIRE:0)
Block(-5,7,0,quark:redstone_randomizer:11)
Block(-5,7,1,REDSTONE_WIRE:0)
Block(-5,7,2,quark:marble_wall:0)
Block(-5,7,5,CONCRETE:0)
Block(-5,7,6,quark:world_stone_pavement:2)
Block(-5,7,7,quark:world_stone_pavement:2)
Block(-5,7,8,CONCRETE:0)
Block(-5,8,-2,quark:world_stone_pavement:2)
Block(-5,8,-1,CONCRETE:0)
Block(-5,8,0,quark:world_stone_pavement:2)
Block(-5,8,1,CONCRETE:0)
Block(-5,8,2,quark:world_stone_pavement:2)
Block(-5,8,4,srparasites:parasiterubbledense:1)
Block(-5,8,5,quark:polished_stone:0)
Block(-5,8,6,quark:polished_stone:0)
Block(-5,8,7,quark:polished_stone:0)
Block(-5,8,8,quark:polished_stone:0)
Block(-5,9,-2,CONCRETE:0)
Block(-5,9,0,CONCRETE:0)
Block(-5,9,1,CONCRETE:0)
Block(-5,9,2,CONCRETE:0)
Block(-5,9,3,quark:world_stone_pavement:2)
Block(-5,9,4,quark:world_stone_pavement:2)
Block(-5,9,5,quark:polished_stone:0)
Block(-5,9,6,quark:polished_stone:0)
Block(-5,9,7,quark:world_stone_pavement:2)
Block(-5,9,8,quark:world_stone_pavement:2)
Block(-5,10,-2,quark:world_stone_pavement:2)
Block(-5,10,-1,quark:grate:0)
Block(-5,10,0,CONCRETE:0)
Block(-5,10,1,CONCRETE:0)
Block(-5,10,2,CONCRETE:0)
Block(-5,10,3,srparasites:parasiterubbledense:1)
Block(-5,10,4,CONCRETE:14)
Block(-5,10,5,STAINED_CLAY:1)
Block(-5,10,6,STAINED_CLAY:4)
Block(-5,10,7,srparasites:parasiterubbledense:1)
Block(-5,10,8,srparasites:parasiterubbledense:1)
RandomBlock(-5,11,-2,IRON_FENCE:0,30,IRON_FENCE:0,100)
Block(-5,11,0,quark:iron_plate:1)
Block(-5,11,2,quark:iron_plate:1)
Block(-5,11,3,srparasites:parasitethin)
Block(-5,11,6,IRON_DOOR_BLOCK:5)
Block(-5,12,6,IRON_DOOR_BLOCK:9)
Block(-5,13,6,quark:iron_plate:1)
Block(-5,13,7,quark:iron_plate:1)
Block(-5,13,8,quark:world_stone_pavement:2)
RandomBlock(-5,14,6,CONCRETE:0,40,SMOOTH_BRICK:1,30,SMOOTH_BRICK:2,30,MOSSY_COBBLESTONE:0,30,COBBLESTONE:0,20,CONCRETE:0,100)
Block(-5,14,7,quark:iron_plate:1)
Block(-5,14,8,quark:polished_stone:0)
Block(-5,15,4,quark:iron_plate_slab:8)
Block(-5,15,5,quark:iron_plate_slab:8)
RandomBlock(-5,15,6,CONCRETE:0,40,SMOOTH_BRICK:1,30,SMOOTH_BRICK:2,30,MOSSY_COBBLESTONE:0,30,COBBLESTONE:0,20,CONCRETE:0,100)
Block(-5,15,7,quark:iron_plate:1)
RandomBlock(-5,16,4,IRON_FENCE:0,30,IRON_FENCE:0,100)
RandomBlock(-5,16,5,IRON_FENCE:0,30,IRON_FENCE:0,100)
RandomBlock(-5,16,6,CONCRETE:0,40,SMOOTH_BRICK:1,30,SMOOTH_BRICK:2,30,MOSSY_COBBLESTONE:0,30,COBBLESTONE:0,20,CONCRETE:0,100)
Block(-5,16,7,quark:iron_plate:1)
Block(-5,16,8,quark:iron_plate:1)
RandomBlock(-5,17,4,IRON_FENCE:0,30,IRON_FENCE:0,100)
Block(-5,17,5,quark:iron_plate_slab:8)
RandomBlock(-5,17,6,CONCRETE:0,40,SMOOTH_BRICK:1,30,SMOOTH_BRICK:2,30,MOSSY_COBBLESTONE:0,30,COBBLESTONE:0,20,CONCRETE:0,100)
Block(-5,17,7,quark:polished_stone:0)
RandomBlock(-5,18,4,IRON_FENCE:0,30,IRON_FENCE:0,100)
RandomBlock(-5,18,6,CONCRETE:0,40,SMOOTH_BRICK:1,30,SMOOTH_BRICK:2,30,MOSSY_COBBLESTONE:0,30,COBBLESTONE:0,20,CONCRETE:0,100)
Block(-5,18,7,quark:iron_plate:1)
RandomBlock(-5,19,4,IRON_FENCE:0,30,IRON_FENCE:0,100)
Block(-5,19,6,quark:iron_plate:1)
Block(-5,19,7,quark:iron_plate:1)
RandomBlock(-5,19,8,CONCRETE:0,40,SMOOTH_BRICK:1,30,SMOOTH_BRICK:2,30,MOSSY_COBBLESTONE:0,30,COBBLESTONE:0,20,CONCRETE:0,100)
RandomBlock(-5,20,4,IRON_FENCE:0,30,IRON_FENCE:0,100)
Block(-5,20,5,quark:world_stone_pavement:2)
Block(-5,20,6,SMOOTH_STAIRS:3)
Block(-5,21,-4,quark:iron_plate:1)
Block(-5,21,4,quark:polished_stone:0)
Block(-5,21,5,STEP:0)
Block(-5,22,-2,IRON_TRAPDOOR:9)
Block(-5,22,3,quark:iron_plate:1)
Block(-5,22,4,SMOOTH_STAIRS:3)
Block(-5,23,-7,STEP:0)
Block(-5,23,-6,STEP:0)
Block(-5,23,-5,STEP:0)
Block(-5,23,-4,STEP:0)
Block(-5,23,-3,STEP:0)
Block(-5,23,-2,DISPENSER:0)
Block(-5,23,2,quark:iron_plate:1)
Block(-5,23,3,SMOOTH_STAIRS:3)
RandomBlock(-5,24,-2,IRON_FENCE:0,30,IRON_FENCE:0,100)
Block(-5,24,1,quark:iron_plate:1)
Block(-5,24,2,SMOOTH_STAIRS:3)
RandomBlock(-5,25,-7,CONCRETE:0,40,SMOOTH_BRICK:1,30,SMOOTH_BRICK:2,30,MOSSY_COBBLESTONE:0,30,COBBLESTONE:0,20,CONCRETE:0,100)
RandomBlock(-5,25,-6,CONCRETE:0,40,SMOOTH_BRICK:1,30,SMOOTH_BRICK:2,30,MOSSY_COBBLESTONE:0,30,COBBLESTONE:0,20,CONCRETE:0,100)
RandomBlock(-5,25,-5,CONCRETE:0,40,SMOOTH_BRICK:1,30,SMOOTH_BRICK:2,30,MOSSY_COBBLESTONE:0,30,COBBLESTONE:0,20,CONCRETE:0,100)
RandomBlock(-5,25,-4,CONCRETE:0,40,SMOOTH_BRICK:1,30,SMOOTH_BRICK:2,30,MOSSY_COBBLESTONE:0,30,COBBLESTONE:0,20,CONCRETE:0,100)
RandomBlock(-5,25,-3,CONCRETE:0,40,SMOOTH_BRICK:1,30,SMOOTH_BRICK:2,30,MOSSY_COBBLESTONE:0,30,COBBLESTONE:0,20,CONCRETE:0,100)
RandomBlock(-5,25,-2,CONCRETE:0,40,SMOOTH_BRICK:1,30,SMOOTH_BRICK:2,30,MOSSY_COBBLESTONE:0,30,COBBLESTONE:0,20,CONCRETE:0,100)
RandomBlock(-5,25,-1,CONCRETE:0,40,SMOOTH_BRICK:1,30,SMOOTH_BRICK:2,30,MOSSY_COBBLESTONE:0,30,COBBLESTONE:0,20,CONCRETE:0,100)
Block(-5,25,0,quark:iron_plate:1)
Block(-5,25,1,SMOOTH_STAIRS:3)
Block(-5,26,-3,STEP:0)
Block(-5,26,0,quark:stone_diorite_bricks_wall:0)
Block(-4,0,-7,quark:world_stone_pavement:1)
Block(-4,0,-6,quark:world_stone_pavement:4)
Block(-4,0,-5,quark:world_stone_pavement:4)
Block(-4,0,-4,quark:world_stone_pavement:2)
Block(-4,0,-3,quark:world_stone_pavement:4)
Block(-4,0,-2,quark:world_stone_pavement:1)
Block(-4,0,-1,quark:world_stone_pavement:2)
Block(-4,0,0,CONCRETE:0)
Block(-4,0,1,quark:world_stone_pavement:2)
Block(-4,0,2,quark:world_stone_pavement:2)
Block(-4,0,3,quark:world_stone_pavement:2)
Block(-4,0,4,CONCRETE:0)
Block(-4,0,5,CONCRETE:0)
Block(-4,0,6,CONCRETE:0)
Block(-4,0,7,CONCRETE:0)
Block(-4,0,8,quark:world_stone_pavement:2)
Block(-4,1,-7,quark:iron_plate:1)
RandomBlock(-4,1,-6,SMOOTH_BRICK:0,5,SMOOTH_BRICK:0,10,thermalfoundation:ore:7,50,SMOOTH_BRICK:0,100)
Block(-4,1,-5,quark:iron_plate:1)
RandomBlock(-4,1,-4,SMOOTH_BRICK:0,5,SMOOTH_BRICK:0,10,thermalfoundation:ore:7,50,SMOOTH_BRICK:0,100)
Block(-4,1,-3,quark:iron_plate:1)
Block(-4,1,-2,quark:world_stone_pavement:4)
Block(-4,1,-1,quark:world_stone_pavement:2)
Block(-4,1,0,quark:world_stone_pavement:2)
Block(-4,1,1,quark:world_stone_pavement:2)
Block(-4,1,2,quark:world_stone_pavement:2)
Block(-4,1,3,quark:world_stone_pavement:2)
Block(-4,1,4,CONCRETE:0)
Block(-4,1,5,CONCRETE:0)
Block(-4,1,6,CONCRETE:0)
Block(-4,1,7,CONCRETE:0)
Block(-4,1,8,quark:world_stone_pavement:2)
Block(-4,2,-7,quark:iron_plate:1)
RandomBlock(-4,2,-6,SMOOTH_BRICK:0,5,SMOOTH_BRICK:0,10,thermalfoundation:ore:7,50,SMOOTH_BRICK:0,100)
Block(-4,2,-5,quark:iron_plate:1)
RandomBlock(-4,2,-4,SMOOTH_BRICK:0,5,SMOOTH_BRICK:0,10,thermalfoundation:ore:7,50,SMOOTH_BRICK:0,100)
Block(-4,2,-3,quark:iron_plate:1)
Block(-4,2,-2,quark:world_stone_pavement:4)
Block(-4,2,-1,quark:world_stone_pavement:2)
Block(-4,2,0,quark:world_stone_pavement:2)
Block(-4,2,1,CONCRETE:0)
Block(-4,2,2,quark:world_stone_pavement:2)
Block(-4,2,3,quark:world_stone_pavement:2)
Block(-4,2,4,CONCRETE:0)
Block(-4,2,5,CONCRETE:0)
Block(-4,2,6,CONCRETE:0)
Block(-4,2,7,CONCRETE:0)
Block(-4,2,8,CONCRETE:0)
Block(-4,3,-7,STATIONARY_WATER:0)
Block(-4,3,-6,STATIONARY_WATER:0)
Block(-4,3,-5,STATIONARY_WATER:0)
RandomBlock(-4,3,-4,SMOOTH_BRICK:0,5,SMOOTH_BRICK:0,10,thermalfoundation:ore:7,50,SMOOTH_BRICK:0,100)
Block(-4,3,-3,quark:iron_plate:1)
Block(-4,3,-2,quark:world_stone_pavement:4)
Block(-4,3,-1,quark:world_stone_pavement:2)
Block(-4,3,0,CONCRETE:0)
Block(-4,3,1,CONCRETE:0)
Block(-4,3,2,quark:world_stone_pavement:2)
Block(-4,3,3,quark:world_stone_pavement:2)
Block(-4,3,4,quark:world_stone_pavement:2)
Block(-4,3,5,quark:world_stone_pavement:2)
Block(-4,3,6,CONCRETE:0)
Block(-4,3,7,CONCRETE:0)
Block(-4,3,8,quark:world_stone_pavement:2)
Block(-4,4,-7,STATIONARY_WATER:0)
Block(-4,4,-6,STATIONARY_WATER:0)
Block(-4,4,-5,STATIONARY_WATER:0)
RandomBlock(-4,4,-4,SMOOTH_BRICK:0,5,SMOOTH_BRICK:0,10,thermalfoundation:ore:7,50,SMOOTH_BRICK:0,100)
Block(-4,4,-3,STATIONARY_WATER:0)
Block(-4,4,-2,srparasites:parasiterubbledense:1)
Block(-4,4,-1,quark:world_stone_pavement:2)
Block(-4,4,0,CONCRETE:0)
Block(-4,4,1,CONCRETE:0)
Block(-4,4,2,quark:world_stone_pavement:2)
Block(-4,4,3,quark:world_stone_pavement:2)
Block(-4,4,5,quark:world_stone_pavement:2)
Block(-4,4,6,CONCRETE:0)
Block(-4,4,7,CONCRETE:0)
Block(-4,4,8,CONCRETE:0)
Block(-4,5,-3,srparasites:parasitethin)
Block(-4,5,-2,quark:world_stone_pavement:4)
Block(-4,5,-1,quark:world_stone_pavement:2)
Block(-4,5,0,CONCRETE:0)
Block(-4,5,1,CONCRETE:0)
Block(-4,5,2,quark:world_stone_pavement:2)
Block(-4,5,3,quark:world_stone_pavement:2)
Block(-4,5,4,quark:grate:0)
Block(-4,5,5,quark:world_stone_pavement:2)
Block(-4,5,6,quark:world_stone_pavement:2)
Block(-4,5,7,CONCRETE:0)
Block(-4,5,8,CONCRETE:0)
Block(-4,6,-3,srparasites:parasitethin)
Block(-4,6,-2,quark:world_stone_pavement:2)
Block(-4,6,-1,quark:world_stone_pavement:2)
Block(-4,6,0,quark:world_stone_pavement:2)
Block(-4,6,1,quark:marble_wall:0)
Block(-4,6,2,quark:marble_wall:0)
Block(-4,6,5,srparasites:parasiterubbledense:1)
Block(-4,6,6,quark:world_stone_pavement:2)
Block(-4,6,7,quark:world_stone_pavement:2)
Block(-4,6,8,CONCRETE:0)
Block(-4,7,-3,srparasites:parasitethin)
Block(-4,7,-2,quark:world_stone_pavement:1)
Block(-4,7,-1,quark:world_stone_pavement:2)
Block(-4,7,0,REDSTONE_WIRE:0)
Block(-4,7,1,quark:marble_wall:0)
Block(-4,7,2,quark:marble_wall:0)
Block(-4,7,5,srparasites:parasiterubbledense:1)
Block(-4,7,6,quark:world_stone_pavement:2)
Block(-4,7,7,CONCRETE:0)
Block(-4,7,8,CONCRETE:0)
Block(-4,8,-3,srparasites:parasitethin)
Block(-4,8,-2,srparasites:parasiterubbledense:1)
Block(-4,8,-1,CONCRETE:0)
Block(-4,8,0,quark:world_stone_pavement:2)
Block(-4,8,1,CONCRETE:0)
Block(-4,8,2,CONCRETE:0)
Block(-4,8,3,srparasites:parasiterubbledense:1)
Block(-4,8,4,CONCRETE:0)
Block(-4,8,5,quark:polished_stone:0)
Block(-4,8,6,quark:world_stone_pavement:2)
Block(-4,8,7,quark:world_stone_pavement:2)
Block(-4,8,8,quark:polished_stone:0)
Block(-4,9,-3,srparasites:parasitethin)
Block(-4,9,-2,LEAVES:12)
Block(-4,9,0,CONCRETE:0)
Block(-4,9,1,CONCRETE:0)
Block(-4,9,2,CONCRETE:0)
Block(-4,9,3,CONCRETE:0)
Block(-4,9,4,quark:polished_stone:0)
Block(-4,9,5,quark:polished_stone:0)
Block(-4,9,6,quark:polished_stone:0)
Block(-4,9,7,quark:polished_stone:0)
Block(-4,9,8,CONCRETE:0)
Block(-4,10,-3,srparasites:parasitethin)
Block(-4,10,-2,CONCRETE:0)
Block(-4,10,-1,quark:grate:0)
Block(-4,10,0,quark:world_stone_pavement:2)
Block(-4,10,1,quark:world_stone_pavement:2)
Block(-4,10,2,CONCRETE:0)
Block(-4,10,3,quark:world_stone_pavement:2)
Block(-4,10,4,CONCRETE:14)
Block(-4,10,5,STAINED_CLAY:1)
Block(-4,10,6,STAINED_CLAY:4)
Block(-4,10,7,quark:polished_stone:0)
Block(-4,10,8,srparasites:parasiterubbledense:1)
RandomBlock(-4,11,-2,IRON_FENCE:0,30,IRON_FENCE:0,100)
Block(-4,11,0,quark:iron_plate:1)
Block(-4,11,2,quark:iron_plate:1)
Block(-4,11,6,IRON_DOOR_BLOCK:5)
Block(-4,12,6,IRON_DOOR_BLOCK:8)
Block(-4,13,6,quark:iron_plate:1)
Block(-4,13,7,quark:iron_plate:1)
Block(-4,13,8,quark:world_stone_pavement:2)
Block(-4,14,6,DOUBLE_STEP:0)
Block(-4,14,7,quark:polished_stone:0)
Block(-4,14,8,quark:world_stone_pavement:2)
Block(-4,15,4,quark:iron_plate_slab:8)
Block(-4,15,5,quark:grate:0)
Block(-4,15,6,DOUBLE_STEP:0)
Block(-4,15,7,quark:polished_stone:0)
RandomBlock(-4,15,8,IRON_FENCE:0,30,IRON_FENCE:0,100)
RandomBlock(-4,16,4,IRON_FENCE:0,30,IRON_FENCE:0,100)
Block(-4,16,5,quark:iron_ladder:2)
Block(-4,16,6,DOUBLE_STEP:0)
Block(-4,16,7,quark:iron_plate:1)
Block(-4,16,8,quark:iron_plate:1)
RandomBlock(-4,17,4,IRON_FENCE:0,30,IRON_FENCE:0,100)
Block(-4,17,5,quark:iron_ladder:2)
Block(-4,17,6,DOUBLE_STEP:0)
Block(-4,17,7,quark:world_stone_pavement:2)
Block(-4,18,5,quark:iron_ladder:2)
Block(-4,18,6,DOUBLE_STEP:0)
Block(-4,18,7,quark:iron_plate:1)
Block(-4,19,5,srparasites:parasitethin)
Block(-4,19,6,quark:iron_plate:1)
Block(-4,19,7,quark:iron_plate:1)
RandomBlock(-4,19,8,CONCRETE:0,40,SMOOTH_BRICK:1,30,SMOOTH_BRICK:2,30,MOSSY_COBBLESTONE:0,30,COBBLESTONE:0,20,CONCRETE:0,100)
Block(-4,20,5,quark:world_stone_pavement:2)
Block(-4,20,6,SMOOTH_STAIRS:3)
Block(-4,20,8,DOUBLE_STEP:0)
Block(-4,21,-4,quark:iron_plate:1)
Block(-4,21,4,quark:polished_stone:0)
Block(-4,21,5,STEP:0)
Block(-4,21,8,DOUBLE_STEP:0)
Block(-4,22,3,quark:iron_plate:1)
Block(-4,22,4,SMOOTH_STAIRS:3)
Block(-4,22,8,STEP:0)
Block(-4,23,-7,STEP:0)
Block(-4,23,2,quark:iron_plate:1)
Block(-4,23,3,SMOOTH_STAIRS:3)
Block(-4,24,1,quark:iron_plate:1)
Block(-4,24,2,SMOOTH_STAIRS:3)
Block(-4,25,-7,quark:polished_stone:0)
RandomBlock(-4,25,-6,CONCRETE:0,40,SMOOTH_BRICK:1,30,SMOOTH_BRICK:2,30,MOSSY_COBBLESTONE:0,30,COBBLESTONE:0,20,CONCRETE:0,100)
RandomBlock(-4,25,-5,CONCRETE:0,40,SMOOTH_BRICK:1,30,SMOOTH_BRICK:2,30,MOSSY_COBBLESTONE:0,30,COBBLESTONE:0,20,CONCRETE:0,100)
RandomBlock(-4,25,-4,CONCRETE:0,40,SMOOTH_BRICK:1,30,SMOOTH_BRICK:2,30,MOSSY_COBBLESTONE:0,30,COBBLESTONE:0,20,CONCRETE:0,100)
RandomBlock(-4,25,-3,CONCRETE:0,40,SMOOTH_BRICK:1,30,SMOOTH_BRICK:2,30,MOSSY_COBBLESTONE:0,30,COBBLESTONE:0,20,CONCRETE:0,100)
Block(-4,25,-2,quark:world_stone_pavement:2)
Block(-4,25,-1,quark:world_stone_pavement:2)
Block(-4,25,0,quark:iron_plate:1)
Block(-4,25,1,SMOOTH_STAIRS:3)
Block(-4,26,-3,STEP:0)
Block(-4,26,0,quark:stone_diorite_bricks_wall:0)
Block(-3,0,-7,quark:world_stone_pavement:1)
Block(-3,0,-6,quark:world_stone_pavement:1)
Block(-3,0,-5,quark:world_stone_pavement:2)
Block(-3,0,-4,quark:world_stone_pavement:2)
Block(-3,0,-3,quark:world_stone_pavement:4)
Block(-3,0,-2,quark:world_stone_pavement:1)
Block(-3,0,-1,quark:world_stone_pavement:2)
Block(-3,0,0,quark:world_stone_pavement:2)
Block(-3,0,1,quark:world_stone_pavement:2)
Block(-3,0,2,quark:world_stone_pavement:2)
Block(-3,0,3,quark:world_stone_pavement:2)
Block(-3,0,4,CONCRETE:0)
Block(-3,0,5,quark:world_stone_pavement:2)
Block(-3,0,6,CONCRETE:0)
Block(-3,0,7,CONCRETE:0)
Block(-3,0,8,quark:world_stone_pavement:2)
RandomBlock(-3,1,-7,SMOOTH_BRICK:0,5,SMOOTH_BRICK:0,10,thermalfoundation:ore:7,50,SMOOTH_BRICK:0,100)
Block(-3,1,-6,quark:iron_plate:1)
RandomBlock(-3,1,-5,SMOOTH_BRICK:0,5,SMOOTH_BRICK:0,10,thermalfoundation:ore:7,50,SMOOTH_BRICK:0,100)
Block(-3,1,-4,quark:iron_plate:1)
RandomBlock(-3,1,-3,SMOOTH_BRICK:0,5,SMOOTH_BRICK:0,10,thermalfoundation:ore:7,50,SMOOTH_BRICK:0,100)
Block(-3,1,-2,quark:world_stone_pavement:1)
Block(-3,1,-1,CONCRETE:0)
Block(-3,1,0,CONCRETE:0)
Block(-3,1,1,quark:world_stone_pavement:2)
Block(-3,1,2,CONCRETE:0)
Block(-3,1,3,quark:world_stone_pavement:2)
Block(-3,1,4,quark:world_stone_pavement:2)
Block(-3,1,5,quark:world_stone_pavement:2)
Block(-3,1,6,quark:world_stone_pavement:2)
Block(-3,1,7,CONCRETE:0)
Block(-3,1,8,CONCRETE:0)
Block(-3,2,-7,STATIONARY_WATER:0)
Block(-3,2,-6,quark:iron_plate:1)
RandomBlock(-3,2,-5,SMOOTH_BRICK:0,5,SMOOTH_BRICK:0,10,thermalfoundation:ore:7,50,SMOOTH_BRICK:0,100)
Block(-3,2,-4,quark:iron_plate:1)
RandomBlock(-3,2,-3,SMOOTH_BRICK:0,5,SMOOTH_BRICK:0,10,thermalfoundation:ore:7,50,SMOOTH_BRICK:0,100)
Block(-3,2,-2,quark:world_stone_pavement:2)
Block(-3,2,-1,quark:world_stone_pavement:2)
Block(-3,2,0,CONCRETE:0)
Block(-3,2,1,quark:world_stone_pavement:2)
Block(-3,2,2,CONCRETE:0)
Block(-3,2,3,CONCRETE:0)
Block(-3,2,4,quark:world_stone_pavement:2)
Block(-3,2,5,quark:world_stone_pavement:2)
Block(-3,2,6,CONCRETE:0)
Block(-3,2,7,quark:world_stone_pavement:2)
Block(-3,2,8,quark:world_stone_pavement:2)
Block(-3,3,-7,STATIONARY_WATER:0)
Block(-3,3,-6,quark:iron_plate:1)
RandomBlock(-3,3,-5,SMOOTH_BRICK:0,5,SMOOTH_BRICK:0,10,thermalfoundation:ore:7,50,SMOOTH_BRICK:0,100)
Block(-3,3,-4,quark:iron_plate:1)
Block(-3,3,-3,STATIONARY_WATER:0)
Block(-3,3,-2,quark:world_stone_pavement:1)
Block(-3,3,-1,quark:world_stone_pavement:2)
Block(-3,3,0,CONCRETE:0)
Block(-3,3,1,quark:world_stone_pavement:2)
Block(-3,3,2,quark:world_stone_pavement:2)
Block(-3,3,3,CONCRETE:0)
Block(-3,3,4,CONCRETE:0)
Block(-3,3,5,CONCRETE:0)
Block(-3,3,6,quark:world_stone_pavement:2)
Block(-3,3,7,CONCRETE:0)
Block(-3,3,8,CONCRETE:0)
Block(-3,4,-7,STATIONARY_WATER:1)
Block(-3,4,-6,quark:iron_plate:1)
RandomBlock(-3,4,-5,SMOOTH_BRICK:0,5,SMOOTH_BRICK:0,10,thermalfoundation:ore:7,50,SMOOTH_BRICK:0,100)
Block(-3,4,-4,STATIONARY_WATER:0)
Block(-3,4,-3,STATIONARY_WATER:0)
Block(-3,4,-2,srparasites:parasiterubbledense:1)
Block(-3,4,-1,CONCRETE:0)
Block(-3,4,0,CONCRETE:0)
Block(-3,4,1,quark:world_stone_pavement:2)
Block(-3,4,2,CONCRETE:0)
Block(-3,4,3,CONCRETE:0)
Block(-3,4,4,quark:iron_plate:1)
Block(-3,4,5,CONCRETE:0)
Block(-3,4,6,CONCRETE:0)
Block(-3,4,7,CONCRETE:0)
Block(-3,4,8,quark:world_stone_pavement:2)
Block(-3,5,-3,srparasites:parasitethin)
Block(-3,5,-2,quark:world_stone_pavement:2)
Block(-3,5,-1,quark:world_stone_pavement:2)
Block(-3,5,0,CONCRETE:0)
Block(-3,5,1,quark:world_stone_pavement:2)
Block(-3,5,2,CONCRETE:0)
Block(-3,5,3,CONCRETE:0)
Block(-3,5,4,quark:iron_plate:1)
Block(-3,5,5,CONCRETE:0)
Block(-3,5,6,CONCRETE:0)
Block(-3,5,7,quark:world_stone_pavement:2)
Block(-3,5,8,CONCRETE:0)
Block(-3,6,-3,srparasites:parasitethin)
Block(-3,6,-2,quark:world_stone_pavement:2)
Block(-3,6,-1,quark:world_stone_pavement:2)
Block(-3,6,0,quark:world_stone_pavement:2)
Block(-3,6,1,quark:marble_wall:0)
Block(-3,6,2,quark:basalt_wall:0)
Block(-3,6,4,quark:iron_plate:1)
Block(-3,6,5,CONCRETE:0)
Block(-3,6,6,CONCRETE:0)
Block(-3,6,7,quark:world_stone_pavement:2)
Block(-3,6,8,quark:world_stone_pavement:2)
Block(-3,7,-3,srparasites:parasitethin)
Block(-3,7,-2,CONCRETE:0)
Block(-3,7,-1,CONCRETE:0)
Block(-3,7,0,REDSTONE_WIRE:0)
Block(-3,7,1,quark:marble_wall:0)
Block(-3,7,2,quark:basalt_wall:0)
Block(-3,7,4,quark:iron_plate:1)
Block(-3,7,5,CONCRETE:0)
Block(-3,7,6,quark:world_stone_pavement:2)
Block(-3,7,7,quark:world_stone_pavement:2)
Block(-3,7,8,CONCRETE:0)
Block(-3,8,-3,srparasites:parasitethin)
Block(-3,8,-2,LEAVES:12)
Block(-3,8,-1,CONCRETE:0)
Block(-3,8,0,quark:world_stone_pavement:2)
Block(-3,8,1,quark:world_stone_pavement:2)
Block(-3,8,2,CONCRETE:0)
Block(-3,8,3,CONCRETE:0)
Block(-3,8,4,quark:world_stone_pavement:2)
Block(-3,8,5,quark:polished_stone:0)
Block(-3,8,6,quark:world_stone_pavement:2)
Block(-3,8,7,quark:world_stone_pavement:2)
Block(-3,8,8,quark:world_stone_pavement:2)
Block(-3,9,-3,srparasites:parasitethin)
Block(-3,9,-2,CONCRETE:0)
Block(-3,9,0,CONCRETE:0)
Block(-3,9,1,quark:world_stone_pavement:2)
Block(-3,9,2,quark:world_stone_pavement:2)
Block(-3,9,3,quark:world_stone_pavement:2)
Block(-3,9,4,quark:polished_stone:0)
Block(-3,9,5,quark:polished_stone:0)
Block(-3,9,6,quark:polished_stone:0)
Block(-3,9,7,quark:polished_stone:0)
Block(-3,9,8,CONCRETE:0)
Block(-3,10,-3,srparasites:parasitethin)
Block(-3,10,-2,CONCRETE:0)
Block(-3,10,-1,quark:grate:0)
Block(-3,10,0,CONCRETE:0)
Block(-3,10,1,srparasites:parasiterubbledense:1)
Block(-3,10,2,CONCRETE:0)
Block(-3,10,3,CONCRETE:0)
Block(-3,10,4,srparasites:parasiterubbledense:1)
Block(-3,10,5,quark:polished_stone:0)
Block(-3,10,6,quark:world_stone_pavement:2)
Block(-3,10,7,quark:polished_stone:0)
Block(-3,10,8,quark:world_stone_pavement:2)
RandomBlock(-3,11,-2,IRON_FENCE:0,30,IRON_FENCE:0,100)
Block(-3,11,0,quark:iron_plate:1)
Block(-3,11,1,srparasites:infestedbush:3)
Block(-3,11,2,quark:iron_plate:1)
Block(-3,11,5,srparasites:parasitethin)
Block(-3,11,6,quark:iron_plate:1)
Block(-3,11,7,quark:iron_plate:1)
Block(-3,12,5,srparasites:parasitethin)
Block(-3,12,6,quark:iron_plate:1)
Block(-3,12,7,quark:iron_plate:1)
Block(-3,13,5,srparasites:parasitethin)
Block(-3,13,6,quark:iron_plate:1)
Block(-3,13,7,quark:iron_plate:1)
Block(-3,13,8,srparasites:parasiterubbledense:1)
Block(-3,14,6,quark:polished_stone:0)
Block(-3,14,7,quark:polished_stone:0)
Block(-3,14,8,quark:polished_stone:0)
Block(-3,15,4,quark:iron_plate_slab:8)
Block(-3,15,5,quark:grate:0)
Block(-3,15,6,quark:polished_stone:0)
Block(-3,15,7,quark:iron_plate:1)
RandomBlock(-3,16,4,IRON_FENCE:0,30,IRON_FENCE:0,100)
RandomBlock(-3,16,6,CONCRETE:0,40,SMOOTH_BRICK:1,30,SMOOTH_BRICK:2,30,MOSSY_COBBLESTONE:0,30,COBBLESTONE:0,20,CONCRETE:0,100)
Block(-3,16,7,quark:iron_plate:1)
Block(-3,16,8,quark:iron_plate:1)
RandomBlock(-3,17,4,IRON_FENCE:0,30,IRON_FENCE:0,100)
Block(-3,17,6,quark:world_stone_pavement:2)
Block(-3,17,7,quark:polished_stone:0)
Block(-3,18,-2,srparasites:parasiterubbledense:2)
RandomBlock(-3,18,6,CONCRETE:0,40,SMOOTH_BRICK:1,30,SMOOTH_BRICK:2,30,MOSSY_COBBLESTONE:0,30,COBBLESTONE:0,20,CONCRETE:0,100)
Block(-3,18,7,quark:iron_plate:1)
Block(-3,19,-2,srparasites:parasitethin)
Block(-3,19,6,quark:iron_plate:1)
Block(-3,19,7,quark:iron_plate:1)
RandomBlock(-3,19,8,CONCRETE:0,40,SMOOTH_BRICK:1,30,SMOOTH_BRICK:2,30,MOSSY_COBBLESTONE:0,30,COBBLESTONE:0,20,CONCRETE:0,100)
Block(-3,20,-2,srparasites:parasitethin)
Block(-3,20,5,quark:world_stone_pavement:2)
Block(-3,20,6,SMOOTH_STAIRS:3)
RandomBlock(-3,20,8,CONCRETE:0,40,SMOOTH_BRICK:1,30,SMOOTH_BRICK:2,30,MOSSY_COBBLESTONE:0,30,COBBLESTONE:0,20,CONCRETE:0,100)
Block(-3,21,-4,quark:iron_plate:1)
Block(-3,21,-2,srparasites:parasitethin)
Block(-3,21,4,quark:polished_stone:0)
Block(-3,21,5,STEP:0)
RandomBlock(-3,21,8,CONCRETE:0,40,SMOOTH_BRICK:1,30,SMOOTH_BRICK:2,30,MOSSY_COBBLESTONE:0,30,COBBLESTONE:0,20,CONCRETE:0,100)
Block(-3,22,-4,srparasites:infestedbush:4)
Block(-3,22,-2,srparasites:parasitethin)
Block(-3,22,3,quark:iron_plate:1)
Block(-3,22,4,SMOOTH_STAIRS:3)
Block(-3,22,8,STEP:0)
Block(-3,23,-7,STEP:0)
Block(-3,23,-6,srparasites:infestedbush:4)
Block(-3,23,-5,srparasites:infestedbush:4)
Block(-3,23,-4,srparasites:infestedbush:4)
Block(-3,23,-2,srparasites:parasitethin)
Block(-3,23,2,quark:iron_plate:1)
Block(-3,23,3,SMOOTH_STAIRS:3)
Block(-3,24,-6,srparasites:parasiterubbledense:1)
Block(-3,24,-5,srparasites:parasiterubbledense:1)
Block(-3,24,-4,srparasites:parasiterubbledense:1)
Block(-3,24,-2,srparasites:parasitethin)
Block(-3,24,1,quark:iron_plate:1)
Block(-3,24,2,SMOOTH_STAIRS:3)
Block(-3,25,-7,quark:polished_stone:0)
Block(-3,25,-6,quark:polished_stone:0)
Block(-3,25,-5,quark:polished_stone:0)
RandomBlock(-3,25,-4,CONCRETE:0,40,SMOOTH_BRICK:1,30,SMOOTH_BRICK:2,30,MOSSY_COBBLESTONE:0,30,COBBLESTONE:0,20,CONCRETE:0,100)
RandomBlock(-3,25,-3,CONCRETE:0,40,SMOOTH_BRICK:1,30,SMOOTH_BRICK:2,30,MOSSY_COBBLESTONE:0,30,COBBLESTONE:0,20,CONCRETE:0,100)
Block(-3,25,-2,quark:polished_stone:0)
Block(-3,25,-1,quark:world_stone_pavement:2)
Block(-3,25,0,quark:iron_plate:1)
Block(-3,25,1,SMOOTH_STAIRS:3)
Block(-3,26,-3,STEP:0)
Block(-3,26,0,quark:stone_diorite_bricks_wall:0)
Block(-2,0,-7,quark:world_stone_pavement:2)
Block(-2,0,-6,quark:world_stone_pavement:2)
Block(-2,0,-5,quark:world_stone_pavement:2)
Block(-2,0,-4,quark:world_stone_pavement:2)
Block(-2,0,-3,quark:world_stone_pavement:2)
Block(-2,0,-2,quark:world_stone_pavement:1)
Block(-2,0,-1,quark:world_stone_pavement:2)
Block(-2,0,0,CONCRETE:0)
Block(-2,0,1,quark:world_stone_pavement:2)
Block(-2,0,2,CONCRETE:0)
Block(-2,0,3,CONCRETE:0)
Block(-2,0,4,quark:world_stone_pavement:2)
Block(-2,0,5,CONCRETE:0)
Block(-2,0,6,CONCRETE:0)
Block(-2,0,7,CONCRETE:0)
Block(-2,0,8,CONCRETE:0)
Block(-2,1,-7,quark:iron_plate:1)
Block(-2,1,-6,STATIONARY_WATER:0)
Block(-2,1,-5,quark:iron_plate:1)
Block(-2,1,-4,STATIONARY_WATER:0)
Block(-2,1,-3,quark:iron_plate:1)
Block(-2,1,-2,quark:world_stone_pavement:1)
Block(-2,1,-1,quark:world_stone_pavement:2)
Block(-2,1,0,quark:world_stone_pavement:2)
Block(-2,1,1,quark:world_stone_pavement:2)
Block(-2,1,2,CONCRETE:0)
Block(-2,1,3,CONCRETE:0)
Block(-2,1,4,quark:world_stone_pavement:2)
Block(-2,1,5,CONCRETE:0)
Block(-2,1,6,CONCRETE:0)
Block(-2,1,7,CONCRETE:0)
Block(-2,1,8,CONCRETE:0)
Block(-2,2,-7,quark:iron_plate:1)
Block(-2,2,-6,STATIONARY_WATER:0)
Block(-2,2,-5,quark:iron_plate:1)
Block(-2,2,-4,STATIONARY_WATER:0)
Block(-2,2,-3,quark:iron_plate:1)
Block(-2,2,-2,quark:world_stone_pavement:4)
Block(-2,2,-1,quark:world_stone_pavement:2)
Block(-2,2,0,CONCRETE:0)
Block(-2,2,1,quark:world_stone_pavement:2)
Block(-2,2,2,CONCRETE:0)
Block(-2,2,3,CONCRETE:0)
Block(-2,2,4,CONCRETE:0)
Block(-2,2,5,CONCRETE:0)
Block(-2,2,6,quark:world_stone_pavement:2)
Block(-2,2,7,quark:world_stone_pavement:2)
Block(-2,2,8,quark:world_stone_pavement:2)
Block(-2,3,-7,STATIONARY_WATER:0)
Block(-2,3,-6,STATIONARY_WATER:0)
Block(-2,3,-5,quark:iron_plate:1)
Block(-2,3,-4,STATIONARY_WATER:0)
Block(-2,3,-3,quark:iron_plate:1)
Block(-2,3,-2,quark:world_stone_pavement:1)
Block(-2,3,-1,quark:world_stone_pavement:2)
Block(-2,3,0,quark:world_stone_pavement:2)
Block(-2,3,1,quark:world_stone_pavement:2)
Block(-2,3,2,CONCRETE:0)
Block(-2,3,3,CONCRETE:0)
Block(-2,3,4,CONCRETE:0)
Block(-2,3,5,CONCRETE:0)
Block(-2,3,6,CONCRETE:0)
Block(-2,3,7,quark:world_stone_pavement:2)
Block(-2,3,8,CONCRETE:0)
Block(-2,4,-7,STATIONARY_WATER:0)
Block(-2,4,-6,STATIONARY_WATER:0)
Block(-2,4,-5,quark:iron_plate:1)
Block(-2,4,-4,STATIONARY_WATER:0)
Block(-2,4,-3,STATIONARY_WATER:1)
Block(-2,4,-2,srparasites:parasiterubbledense:1)
Block(-2,4,-1,quark:world_stone_pavement:2)
Block(-2,4,0,CONCRETE:0)
Block(-2,4,1,quark:world_stone_pavement:2)
Block(-2,4,2,CONCRETE:0)
Block(-2,4,3,CONCRETE:0)
Block(-2,4,4,quark:basalt_wall:0)
Block(-2,4,5,CONCRETE:0)
Block(-2,4,6,CONCRETE:0)
Block(-2,4,7,CONCRETE:0)
Block(-2,4,8,CONCRETE:0)
Block(-2,5,-5,quark:iron_plate:1)
Block(-2,5,-2,srparasites:parasiterubbledense:1)
Block(-2,5,-1,quark:world_stone_pavement:2)
Block(-2,5,0,quark:world_stone_pavement:2)
Block(-2,5,1,quark:world_stone_pavement:2)
Block(-2,5,2,CONCRETE:0)
Block(-2,5,3,quark:world_stone_pavement:2)
Block(-2,5,4,quark:basalt_wall:0)
Block(-2,5,5,CONCRETE:0)
Block(-2,5,6,CONCRETE:0)
Block(-2,5,7,CONCRETE:0)
Block(-2,5,8,CONCRETE:0)
Block(-2,6,-2,quark:world_stone_pavement:1)
Block(-2,6,-1,quark:world_stone_pavement:2)
Block(-2,6,0,quark:world_stone_pavement:2)
Block(-2,6,1,quark:marble_wall:0)
Block(-2,6,2,STONE:0)
Block(-2,6,4,quark:basalt_wall:0)
Block(-2,6,5,CONCRETE:0)
Block(-2,6,6,CONCRETE:0)
Block(-2,6,7,quark:world_stone_pavement:2)
Block(-2,6,8,CONCRETE:0)
Block(-2,7,-2,quark:world_stone_pavement:1)
Block(-2,7,-1,quark:world_stone_pavement:2)
Block(-2,7,0,REDSTONE_WIRE:0)
Block(-2,7,1,quark:marble_wall:0)
Block(-2,7,2,STONE:0)
Block(-2,7,4,quark:basalt_wall:0)
Block(-2,7,5,quark:world_stone_pavement:2)
Block(-2,7,6,CONCRETE:0)
Block(-2,7,7,CONCRETE:0)
Block(-2,7,8,CONCRETE:0)
Block(-2,8,-2,quark:world_stone_pavement:1)
Block(-2,8,-1,quark:world_stone_pavement:2)
Block(-2,8,0,CONCRETE:0)
Block(-2,8,1,CONCRETE:0)
Block(-2,8,2,quark:world_stone_pavement:2)
Block(-2,8,3,quark:world_stone_pavement:2)
Block(-2,8,4,CONCRETE:0)
Block(-2,8,5,quark:polished_stone:0)
Block(-2,8,6,quark:polished_stone:0)
Block(-2,8,7,quark:polished_stone:0)
Block(-2,8,8,quark:world_stone_pavement:2)
Block(-2,9,-2,CONCRETE:0)
Block(-2,9,0,CONCRETE:0)
Block(-2,9,1,quark:world_stone_pavement:2)
Block(-2,9,2,CONCRETE:0)
Block(-2,9,3,CONCRETE:0)
Block(-2,9,4,quark:polished_stone:0)
Block(-2,9,5,quark:polished_stone:0)
Block(-2,9,6,quark:polished_stone:0)
Block(-2,9,7,quark:polished_stone:0)
Block(-2,9,8,quark:polished_stone:0)
Block(-2,10,-2,CONCRETE:0)
Block(-2,10,-1,quark:grate:0)
Block(-2,10,0,quark:world_stone_pavement:2)
Block(-2,10,1,srparasites:parasiterubbledense:1)
Block(-2,10,2,CONCRETE:0)
Block(-2,10,3,quark:world_stone_pavement:2)
Block(-2,10,4,srparasites:parasiterubbledense:1)
Block(-2,10,5,quark:world_stone_pavement:2)
Block(-2,10,6,quark:polished_stone:0)
Block(-2,10,7,quark:polished_stone:0)
Block(-2,10,8,quark:polished_stone:0)
RandomBlock(-2,11,-2,IRON_FENCE:0,30,IRON_FENCE:0,100)
Block(-2,11,0,quark:iron_plate:1)
Block(-2,11,1,srparasites:parasitebush)
Block(-2,11,2,quark:iron_plate:1)
Block(-2,11,4,srparasites:infestedbush)
Block(-2,11,5,srparasites:parasitethin)
Block(-2,11,6,quark:polished_stone:0)
Block(-2,11,7,quark:polished_stone:0)
Block(-2,12,1,srparasites:parasitebush)
Block(-2,12,5,srparasites:parasitethin)
Block(-2,12,6,DOUBLE_STEP:0)
Block(-2,12,7,quark:polished_stone:0)
Block(-2,13,1,srparasites:parasitebush)
Block(-2,13,5,srparasites:parasitethin)
Block(-2,13,6,DOUBLE_STEP:0)
Block(-2,13,7,quark:iron_plate:1)
Block(-2,13,8,quark:polished_stone:0)
Block(-2,14,1,srparasites:parasitebush)
Block(-2,14,6,DOUBLE_STEP:0)
Block(-2,14,7,quark:polished_stone:0)
Block(-2,14,8,quark:polished_stone:0)
Block(-2,15,1,srparasites:parasitebush)
Block(-2,15,4,quark:iron_plate_slab:8)
Block(-2,15,5,quark:grate:0)
Block(-2,15,6,DOUBLE_STEP:0)
Block(-2,15,7,quark:world_stone_pavement:2)
RandomBlock(-2,15,8,IRON_FENCE:0,30,IRON_FENCE:0,100)
RandomBlock(-2,16,4,IRON_FENCE:0,30,IRON_FENCE:0,100)
Block(-2,16,5,srparasites:parasitethin)
Block(-2,16,6,DOUBLE_STEP:0)
Block(-2,16,7,quark:iron_plate:1)
Block(-2,16,8,quark:iron_plate:1)
RandomBlock(-2,17,4,IRON_FENCE:0,30,IRON_FENCE:0,100)
Block(-2,17,5,srparasites:parasitethin)
Block(-2,17,6,DOUBLE_STEP:0)
Block(-2,17,7,CONCRETE:0)
Block(-2,18,5,srparasites:parasitethin)
Block(-2,18,6,DOUBLE_STEP:0)
Block(-2,18,7,quark:iron_plate:1)
Block(-2,19,-6,srparasites:parasiterubbledense:2)
Block(-2,19,-5,srparasites:infestedbush:4)
Block(-2,19,5,srparasites:parasitethin)
Block(-2,19,6,quark:iron_plate:1)
Block(-2,19,7,quark:iron_plate:1)
RandomBlock(-2,19,8,CONCRETE:0,40,SMOOTH_BRICK:1,30,SMOOTH_BRICK:2,30,MOSSY_COBBLESTONE:0,30,COBBLESTONE:0,20,CONCRETE:0,100)
Block(-2,20,-6,srparasites:parasitethin)
Block(-2,20,-5,srparasites:infestedbush:4)
Block(-2,20,-3,srparasites:parasitebush:1)
Block(-2,20,5,quark:world_stone_pavement:2)
Block(-2,20,6,SMOOTH_STAIRS:3)
RandomBlock(-2,20,8,CONCRETE:0,40,SMOOTH_BRICK:1,30,SMOOTH_BRICK:2,30,MOSSY_COBBLESTONE:0,30,COBBLESTONE:0,20,CONCRETE:0,100)
Block(-2,21,-5,srparasites:infestedbush:4)
Block(-2,21,-4,quark:iron_plate:1)
Block(-2,21,-3,srparasites:parasitebush:1)
Block(-2,21,4,quark:polished_stone:0)
Block(-2,21,5,STEP:0)
RandomBlock(-2,21,8,CONCRETE:0,40,SMOOTH_BRICK:1,30,SMOOTH_BRICK:2,30,MOSSY_COBBLESTONE:0,30,COBBLESTONE:0,20,CONCRETE:0,100)
Block(-2,22,-5,srparasites:infestedbush:4)
Block(-2,22,-3,srparasites:parasitebush:1)
Block(-2,22,3,quark:iron_plate:1)
Block(-2,22,4,SMOOTH_STAIRS:3)
Block(-2,22,8,STEP:0)
Block(-2,23,-7,STEP:0)
Block(-2,23,-5,srparasites:infestedbush:4)
Block(-2,23,-3,srparasites:parasitebush:1)
Block(-2,23,2,quark:iron_plate:1)
Block(-2,23,3,SMOOTH_STAIRS:3)
Block(-2,24,-7,srparasites:parasiterubbledense:1)
Block(-2,24,-5,srparasites:parasiterubbledense:1)
Block(-2,24,-4,srparasites:parasiterubbledense:1)
Block(-2,24,-3,srparasites:parasiterubbledense:1)
Block(-2,24,-2,srparasites:parasitethin)
Block(-2,24,-1,srparasites:parasitethin)
Block(-2,24,0,srparasites:parasitethin)
Block(-2,24,1,quark:iron_plate:1)
Block(-2,24,2,SMOOTH_STAIRS:3)
RandomBlock(-2,25,-7,CONCRETE:0,40,SMOOTH_BRICK:1,30,SMOOTH_BRICK:2,30,MOSSY_COBBLESTONE:0,30,COBBLESTONE:0,20,CONCRETE:0,100)
Block(-2,25,-6,quark:polished_stone:0)
RandomBlock(-2,25,-5,CONCRETE:0,40,SMOOTH_BRICK:1,30,SMOOTH_BRICK:2,30,MOSSY_COBBLESTONE:0,30,COBBLESTONE:0,20,CONCRETE:0,100)
RandomBlock(-2,25,-4,CONCRETE:0,40,SMOOTH_BRICK:1,30,SMOOTH_BRICK:2,30,MOSSY_COBBLESTONE:0,30,COBBLESTONE:0,20,CONCRETE:0,100)
RandomBlock(-2,25,-3,CONCRETE:0,40,SMOOTH_BRICK:1,30,SMOOTH_BRICK:2,30,MOSSY_COBBLESTONE:0,30,COBBLESTONE:0,20,CONCRETE:0,100)
Block(-2,25,-2,quark:polished_stone:0)
Block(-2,25,-1,quark:world_stone_pavement:2)
Block(-2,25,0,quark:iron_plate:1)
Block(-2,25,1,SMOOTH_STAIRS:3)
Block(-2,26,-3,STEP:0)
Block(-2,26,0,quark:stone_diorite_bricks_wall:0)
Block(-1,0,-7,quark:world_stone_pavement:2)
Block(-1,0,-6,quark:world_stone_pavement:4)
Block(-1,0,-5,quark:world_stone_pavement:4)
Block(-1,0,-4,quark:world_stone_pavement:1)
Block(-1,0,-3,quark:world_stone_pavement:2)
Block(-1,0,-2,quark:world_stone_pavement:2)
Block(-1,0,-1,CONCRETE:0)
Block(-1,0,0,CONCRETE:0)
Block(-1,0,1,quark:world_stone_pavement:2)
Block(-1,0,2,quark:world_stone_pavement:2)
Block(-1,0,3,quark:world_stone_pavement:2)
Block(-1,0,4,quark:world_stone_pavement:2)
Block(-1,0,5,CONCRETE:0)
Block(-1,0,6,quark:world_stone_pavement:2)
Block(-1,0,7,CONCRETE:0)
Block(-1,0,8,CONCRETE:0)
RandomBlock(-1,1,-7,SMOOTH_BRICK:0,5,SMOOTH_BRICK:0,10,thermalfoundation:ore:7,50,SMOOTH_BRICK:0,100)
Block(-1,1,-6,quark:iron_plate:1)
Block(-1,1,-5,STATIONARY_WATER:0)
Block(-1,1,-4,quark:iron_plate:1)
Block(-1,1,-3,STATIONARY_WATER:0)
Block(-1,1,-2,quark:world_stone_pavement:2)
Block(-1,1,-1,quark:world_stone_pavement:2)
Block(-1,1,0,CONCRETE:0)
Block(-1,1,1,quark:world_stone_pavement:2)
Block(-1,1,2,quark:world_stone_pavement:2)
Block(-1,1,3,quark:world_stone_pavement:2)
Block(-1,1,4,CONCRETE:0)
Block(-1,1,5,CONCRETE:0)
Block(-1,1,6,CONCRETE:0)
Block(-1,1,7,quark:world_stone_pavement:2)
Block(-1,1,8,quark:world_stone_pavement:2)
RandomBlock(-1,2,-7,SMOOTH_BRICK:0,5,SMOOTH_BRICK:0,10,thermalfoundation:ore:7,50,SMOOTH_BRICK:0,100)
Block(-1,2,-6,quark:iron_plate:1)
Block(-1,2,-5,STATIONARY_WATER:0)
Block(-1,2,-4,quark:iron_plate:1)
Block(-1,2,-3,STATIONARY_WATER:0)
Block(-1,2,-2,quark:world_stone_pavement:2)
Block(-1,2,-1,CONCRETE:0)
Block(-1,2,0,quark:world_stone_pavement:2)
Block(-1,2,1,quark:world_stone_pavement:2)
Block(-1,2,2,quark:world_stone_pavement:2)
Block(-1,2,3,quark:world_stone_pavement:2)
Block(-1,2,4,CONCRETE:0)
Block(-1,2,5,quark:world_stone_pavement:2)
Block(-1,2,6,CONCRETE:0)
Block(-1,2,7,CONCRETE:0)
Block(-1,2,8,quark:world_stone_pavement:2)
Block(-1,3,-7,STATIONARY_WATER:0)
Block(-1,3,-6,STATIONARY_WATER:0)
Block(-1,3,-5,STATIONARY_WATER:0)
Block(-1,3,-4,quark:iron_plate:1)
Block(-1,3,-3,STATIONARY_WATER:0)
Block(-1,3,-2,quark:world_stone_pavement:2)
Block(-1,3,-1,quark:world_stone_pavement:2)
Block(-1,3,0,quark:world_stone_pavement:2)
Block(-1,3,1,quark:world_stone_pavement:2)
Block(-1,3,2,quark:world_stone_pavement:2)
Block(-1,3,3,quark:world_stone_pavement:2)
Block(-1,3,4,CONCRETE:0)
Block(-1,3,5,CONCRETE:0)
Block(-1,3,6,quark:world_stone_pavement:2)
Block(-1,3,7,quark:world_stone_pavement:2)
Block(-1,3,8,quark:world_stone_pavement:2)
Block(-1,4,-7,STATIONARY_WATER:0)
Block(-1,4,-6,STATIONARY_WATER:0)
Block(-1,4,-5,STATIONARY_WATER:0)
Block(-1,4,-4,STATIONARY_WATER:0)
Block(-1,4,-3,STATIONARY_WATER:1)
Block(-1,4,-2,srparasites:parasiterubbledense:1)
Block(-1,4,-1,quark:world_stone_pavement:2)
Block(-1,4,0,quark:world_stone_pavement:2)
Block(-1,4,1,quark:world_stone_pavement:2)
Block(-1,4,2,quark:world_stone_pavement:2)
Block(-1,4,3,quark:world_stone_pavement:2)
RandomBlock(-1,4,4,IRON_FENCE:0,30,IRON_FENCE:0,100)
Block(-1,4,5,quark:world_stone_pavement:2)
Block(-1,4,6,CONCRETE:0)
Block(-1,4,7,CONCRETE:0)
Block(-1,4,8,CONCRETE:0)
Block(-1,5,-3,srparasites:parasitethin)
Block(-1,5,-2,srparasites:parasiterubbledense)
Block(-1,5,-1,CONCRETE:0)
Block(-1,5,0,CONCRETE:0)
Block(-1,5,1,quark:world_stone_pavement:2)
Block(-1,5,2,quark:world_stone_pavement:2)
Block(-1,5,3,srparasites:parasiterubbledense:1)
RandomBlock(-1,5,4,IRON_FENCE:0,30,IRON_FENCE:0,100)
Block(-1,5,5,quark:world_stone_pavement:2)
Block(-1,5,6,CONCRETE:0)
Block(-1,5,7,CONCRETE:0)
Block(-1,5,8,CONCRETE:0)
Block(-1,6,-3,srparasites:parasitethin)
Block(-1,6,-2,quark:world_stone_pavement:2)
Block(-1,6,-1,quark:world_stone_pavement:2)
Block(-1,6,0,quark:world_stone_pavement:2)
Block(-1,6,1,quark:marble_wall:0)
Block(-1,6,2,quark:basalt_wall:0)
RandomBlock(-1,6,4,IRON_FENCE:0,30,IRON_FENCE:0,100)
Block(-1,6,5,CONCRETE:0)
Block(-1,6,6,quark:world_stone_pavement:2)
Block(-1,6,7,CONCRETE:0)
Block(-1,6,8,CONCRETE:0)
Block(-1,7,-3,srparasites:parasitethin)
Block(-1,7,-2,quark:world_stone_pavement:1)
Block(-1,7,-1,quark:world_stone_pavement:2)
Block(-1,7,0,REDSTONE_WIRE:0)
Block(-1,7,1,quark:marble_wall:0)
Block(-1,7,2,quark:basalt_wall:0)
RandomBlock(-1,7,4,IRON_FENCE:0,30,IRON_FENCE:0,100)
Block(-1,7,5,quark:world_stone_pavement:2)
Block(-1,7,6,CONCRETE:0)
Block(-1,7,7,CONCRETE:0)
Block(-1,7,8,CONCRETE:0)
Block(-1,8,-3,srparasites:parasitethin)
Block(-1,8,-2,quark:world_stone_pavement:4)
Block(-1,8,-1,CONCRETE:0)
Block(-1,8,0,CONCRETE:0)
Block(-1,8,1,quark:world_stone_pavement:2)
Block(-1,8,2,CONCRETE:0)
Block(-1,8,3,srparasites:parasiterubbledense:1)
Block(-1,8,4,srparasites:parasiterubbledense:1)
Block(-1,8,5,quark:polished_stone:0)
Block(-1,8,6,quark:world_stone_pavement:2)
Block(-1,8,7,quark:polished_stone:0)
Block(-1,8,8,quark:polished_stone:0)
Block(-1,9,-3,srparasites:parasitethin)
Block(-1,9,-2,CONCRETE:0)
Block(-1,9,0,CONCRETE:0)
Block(-1,9,1,CONCRETE:0)
Block(-1,9,2,quark:world_stone_pavement:2)
Block(-1,9,3,CONCRETE:0)
Block(-1,9,4,quark:world_stone_pavement:2)
Block(-1,9,5,quark:polished_stone:0)
Block(-1,9,6,quark:polished_stone:0)
Block(-1,9,7,quark:polished_stone:0)
Block(-1,9,8,quark:polished_stone:0)
Block(-1,10,-3,srparasites:parasitethin)
Block(-1,10,-2,CONCRETE:0)
Block(-1,10,-1,quark:grate:0)
Block(-1,10,0,CONCRETE:0)
Block(-1,10,1,srparasites:parasiterubbledense:1)
Block(-1,10,2,quark:world_stone_pavement:2)
Block(-1,10,3,CONCRETE:0)
Block(-1,10,4,srparasites:parasiterubbledense:1)
Block(-1,10,5,quark:polished_stone:0)
Block(-1,10,6,quark:polished_stone:0)
Block(-1,10,7,quark:polished_stone:0)
Block(-1,10,8,srparasites:parasiterubbledense:1)
RandomBlock(-1,11,-2,IRON_FENCE:0,30,IRON_FENCE:0,100)
Block(-1,11,0,quark:iron_plate:1)
Block(-1,11,1,srparasites:parasitebush)
Block(-1,11,2,quark:iron_plate:1)
Block(-1,11,5,srparasites:parasitethin)
RandomBlock(-1,11,6,CONCRETE:0,40,SMOOTH_BRICK:1,30,SMOOTH_BRICK:2,30,MOSSY_COBBLESTONE:0,30,COBBLESTONE:0,20,CONCRETE:0,100)
Block(-1,11,7,quark:polished_stone:0)
Block(-1,11,8,srparasites:parasitebush)
Block(-1,12,1,srparasites:parasitebush)
Block(-1,12,5,srparasites:parasitethin)
RandomBlock(-1,12,6,CONCRETE:0,40,SMOOTH_BRICK:1,30,SMOOTH_BRICK:2,30,MOSSY_COBBLESTONE:0,30,COBBLESTONE:0,20,CONCRETE:0,100)
Block(-1,12,7,quark:polished_stone:0)
Block(-1,12,8,srparasites:parasitebush)
Block(-1,13,5,srparasites:parasitethin)
RandomBlock(-1,13,6,CONCRETE:0,40,SMOOTH_BRICK:1,30,SMOOTH_BRICK:2,30,MOSSY_COBBLESTONE:0,30,COBBLESTONE:0,20,CONCRETE:0,100)
Block(-1,13,7,quark:iron_plate:1)
Block(-1,13,8,quark:polished_stone:0)
RandomBlock(-1,14,6,CONCRETE:0,40,SMOOTH_BRICK:1,30,SMOOTH_BRICK:2,30,MOSSY_COBBLESTONE:0,30,COBBLESTONE:0,20,CONCRETE:0,100)
Block(-1,14,7,quark:polished_stone:0)
Block(-1,14,8,quark:world_stone_pavement:2)
Block(-1,15,4,quark:iron_plate_slab:8)
Block(-1,15,5,quark:grate:0)
RandomBlock(-1,15,6,CONCRETE:0,40,SMOOTH_BRICK:1,30,SMOOTH_BRICK:2,30,MOSSY_COBBLESTONE:0,30,COBBLESTONE:0,20,CONCRETE:0,100)
Block(-1,15,7,quark:iron_plate:1)
RandomBlock(-1,16,4,IRON_FENCE:0,30,IRON_FENCE:0,100)
RandomBlock(-1,16,6,CONCRETE:0,40,SMOOTH_BRICK:1,30,SMOOTH_BRICK:2,30,MOSSY_COBBLESTONE:0,30,COBBLESTONE:0,20,CONCRETE:0,100)
Block(-1,16,7,quark:iron_plate:1)
Block(-1,16,8,quark:iron_plate:1)
RandomBlock(-1,17,4,IRON_FENCE:0,30,IRON_FENCE:0,100)
RandomBlock(-1,17,6,CONCRETE:0,40,SMOOTH_BRICK:1,30,SMOOTH_BRICK:2,30,MOSSY_COBBLESTONE:0,30,COBBLESTONE:0,20,CONCRETE:0,100)
Block(-1,17,7,quark:world_stone_pavement:2)
RandomBlock(-1,18,6,CONCRETE:0,40,SMOOTH_BRICK:1,30,SMOOTH_BRICK:2,30,MOSSY_COBBLESTONE:0,30,COBBLESTONE:0,20,CONCRETE:0,100)
Block(-1,18,7,quark:iron_plate:1)
Block(-1,19,6,quark:iron_plate:1)
Block(-1,19,7,quark:iron_plate:1)
RandomBlock(-1,19,8,CONCRETE:0,40,SMOOTH_BRICK:1,30,SMOOTH_BRICK:2,30,MOSSY_COBBLESTONE:0,30,COBBLESTONE:0,20,CONCRETE:0,100)
Block(-1,20,-6,srparasites:parasitethin)
Block(-1,20,5,quark:world_stone_pavement:2)
Block(-1,20,6,SMOOTH_STAIRS:3)
RandomBlock(-1,20,8,CONCRETE:0,40,SMOOTH_BRICK:1,30,SMOOTH_BRICK:2,30,MOSSY_COBBLESTONE:0,30,COBBLESTONE:0,20,CONCRETE:0,100)
Block(-1,21,-6,srparasites:parasitethin)
Block(-1,21,-4,quark:iron_plate:1)
Block(-1,21,4,quark:polished_stone:0)
Block(-1,21,5,STEP:0)
RandomBlock(-1,21,8,CONCRETE:0,40,SMOOTH_BRICK:1,30,SMOOTH_BRICK:2,30,MOSSY_COBBLESTONE:0,30,COBBLESTONE:0,20,CONCRETE:0,100)
Block(-1,22,-6,srparasites:parasitethin)
Block(-1,22,-2,IRON_TRAPDOOR:9)
Block(-1,22,3,quark:iron_plate:1)
Block(-1,22,4,SMOOTH_STAIRS:3)
Block(-1,22,8,STEP:0)
Block(-1,23,-7,STEP:0)
Block(-1,23,-6,STEP:0)
Block(-1,23,-5,STEP:0)
Block(-1,23,-4,STEP:0)
Block(-1,23,-3,STEP:0)
Block(-1,23,-2,DISPENSER:0)
Block(-1,23,2,quark:iron_plate:1)
Block(-1,23,3,SMOOTH_STAIRS:3)
Block(-1,24,-6,srparasites:parasiterubbledense:1)
Block(-1,24,-5,srparasites:parasiterubbledense:1)
RandomBlock(-1,24,-2,IRON_FENCE:0,30,IRON_FENCE:0,100)
Block(-1,24,0,srparasites:parasitethin)
Block(-1,24,1,quark:iron_plate:1)
Block(-1,24,2,SMOOTH_STAIRS:3)
Block(-1,25,-7,quark:polished_stone:0)
RandomBlock(-1,25,-6,CONCRETE:0,40,SMOOTH_BRICK:1,30,SMOOTH_BRICK:2,30,MOSSY_COBBLESTONE:0,30,COBBLESTONE:0,20,CONCRETE:0,100)
RandomBlock(-1,25,-5,CONCRETE:0,40,SMOOTH_BRICK:1,30,SMOOTH_BRICK:2,30,MOSSY_COBBLESTONE:0,30,COBBLESTONE:0,20,CONCRETE:0,100)
RandomBlock(-1,25,-4,CONCRETE:0,40,SMOOTH_BRICK:1,30,SMOOTH_BRICK:2,30,MOSSY_COBBLESTONE:0,30,COBBLESTONE:0,20,CONCRETE:0,100)
RandomBlock(-1,25,-3,CONCRETE:0,40,SMOOTH_BRICK:1,30,SMOOTH_BRICK:2,30,MOSSY_COBBLESTONE:0,30,COBBLESTONE:0,20,CONCRETE:0,100)
RandomBlock(-1,25,-2,CONCRETE:0,40,SMOOTH_BRICK:1,30,SMOOTH_BRICK:2,30,MOSSY_COBBLESTONE:0,30,COBBLESTONE:0,20,CONCRETE:0,100)
Block(-1,25,-1,quark:world_stone_pavement:2)
Block(-1,25,0,quark:iron_plate:1)
Block(-1,25,1,SMOOTH_STAIRS:3)
Block(-1,26,-5,quark:basalt_wall:0)
Block(-1,26,-4,quark:basalt_wall:0)
Block(-1,26,-3,quark:basalt_wall:0)
Block(-1,26,0,quark:stone_diorite_bricks_wall:0)
Block(-1,27,-5,DISPENSER:1)
Block(-1,27,-4,DISPENSER:1)
Block(-1,27,-3,DISPENSER:1)
Block(-1,28,-5,IRON_TRAPDOOR:1)
Block(-1,28,-4,IRON_TRAPDOOR:0)
Block(-1,28,-3,IRON_TRAPDOOR:0)
Block(0,0,-7,quark:world_stone_pavement:2)
Block(0,0,-6,quark:world_stone_pavement:2)
Block(0,0,-5,quark:world_stone_pavement:2)
Block(0,0,-4,quark:world_stone_pavement:4)
Block(0,0,-3,quark:world_stone_pavement:1)
Block(0,0,-2,quark:world_stone_pavement:2)
Block(0,0,-1,quark:world_stone_pavement:2)
Block(0,0,0,CONCRETE:0)
Block(0,0,1,quark:world_stone_pavement:2)
Block(0,0,2,CONCRETE:0)
Block(0,0,3,CONCRETE:0)
Block(0,0,4,CONCRETE:0)
Block(0,0,5,quark:world_stone_pavement:2)
Block(0,0,6,CONCRETE:0)
Block(0,0,7,CONCRETE:0)
Block(0,0,8,CONCRETE:0)
Block(0,1,-7,quark:iron_plate:1)
RandomBlock(0,1,-6,SMOOTH_BRICK:0,5,SMOOTH_BRICK:0,10,thermalfoundation:ore:7,50,SMOOTH_BRICK:0,100)
Block(0,1,-5,quark:iron_plate:1)
Block(0,1,-4,STATIONARY_WATER:0)
Block(0,1,-3,quark:iron_plate:1)
Block(0,1,-2,quark:world_stone_pavement:1)
Block(0,1,-1,quark:world_stone_pavement:2)
Block(0,1,0,CONCRETE:0)
Block(0,1,1,quark:world_stone_pavement:2)
Block(0,1,2,quark:world_stone_pavement:2)
Block(0,1,3,CONCRETE:0)
Block(0,1,4,quark:world_stone_pavement:2)
Block(0,1,5,quark:world_stone_pavement:2)
Block(0,1,6,CONCRETE:0)
Block(0,1,7,CONCRETE:0)
Block(0,1,8,quark:world_stone_pavement:2)
Block(0,2,-7,quark:iron_plate:1)
RandomBlock(0,2,-6,SMOOTH_BRICK:0,5,SMOOTH_BRICK:0,10,thermalfoundation:ore:7,50,SMOOTH_BRICK:0,100)
Block(0,2,-5,quark:iron_plate:1)
Block(0,2,-4,STATIONARY_WATER:0)
Block(0,2,-3,quark:iron_plate:1)
Block(0,2,-2,quark:world_stone_pavement:1)
Block(0,2,-1,quark:world_stone_pavement:2)
Block(0,2,0,CONCRETE:0)
Block(0,2,1,quark:world_stone_pavement:2)
Block(0,2,2,quark:world_stone_pavement:2)
Block(0,2,3,CONCRETE:0)
Block(0,2,4,CONCRETE:0)
Block(0,2,5,quark:world_stone_pavement:2)
Block(0,2,6,CONCRETE:0)
Block(0,2,7,quark:world_stone_pavement:2)
Block(0,2,8,quark:world_stone_pavement:2)
Block(0,3,-7,quark:iron_plate:1)
Block(0,3,-6,STATIONARY_WATER:0)
Block(0,3,-5,STATIONARY_WATER:0)
Block(0,3,-4,STATIONARY_WATER:0)
Block(0,3,-3,quark:iron_plate:1)
Block(0,3,-2,quark:world_stone_pavement:4)
Block(0,3,-1,quark:world_stone_pavement:2)
Block(0,3,0,CONCRETE:0)
Block(0,3,1,quark:world_stone_pavement:2)
Block(0,3,2,quark:world_stone_pavement:2)
Block(0,3,3,CONCRETE:0)
Block(0,3,4,quark:world_stone_pavement:2)
Block(0,3,5,quark:world_stone_pavement:2)
Block(0,3,6,CONCRETE:0)
Block(0,3,7,quark:world_stone_pavement:2)
Block(0,3,8,CONCRETE:0)
Block(0,4,-7,STATIONARY_WATER:0)
Block(0,4,-6,STATIONARY_WATER:1)
Block(0,4,-5,STATIONARY_WATER:0)
Block(0,4,-4,STATIONARY_WATER:0)
Block(0,4,-3,STATIONARY_WATER:1)
Block(0,4,-2,srparasites:parasiterubbledense:1)
Block(0,4,-1,quark:world_stone_pavement:2)
Block(0,4,0,CONCRETE:0)
Block(0,4,1,quark:world_stone_pavement:2)
Block(0,4,2,CONCRETE:0)
Block(0,4,3,quark:world_stone_pavement:2)
Block(0,4,5,quark:world_stone_pavement:2)
Block(0,4,6,CONCRETE:0)
Block(0,4,7,quark:world_stone_pavement:2)
Block(0,4,8,CONCRETE:0)
Block(0,5,-2,srparasites:parasiterubbledense:1)
Block(0,5,-1,quark:world_stone_pavement:2)
Block(0,5,0,quark:world_stone_pavement:2)
Block(0,5,1,quark:world_stone_pavement:2)
Block(0,5,2,CONCRETE:0)
Block(0,5,3,quark:world_stone_pavement:2)
Block(0,5,4,quark:grate:0)
Block(0,5,5,quark:world_stone_pavement:2)
Block(0,5,6,CONCRETE:0)
Block(0,5,7,quark:world_stone_pavement:2)
Block(0,5,8,CONCRETE:0)
Block(0,6,-2,srparasites:parasiterubbledense:1)
Block(0,6,-1,quark:world_stone_pavement:2)
Block(0,6,0,quark:world_stone_pavement:2)
Block(0,6,1,quark:marble_wall:0)
RandomBlock(0,6,2,IRON_FENCE:0,30,IRON_FENCE:0,100)
Block(0,6,5,quark:world_stone_pavement:2)
Block(0,6,6,CONCRETE:0)
Block(0,6,7,CONCRETE:0)
Block(0,6,8,CONCRETE:0)
Block(0,7,-2,quark:world_stone_pavement:2)
Block(0,7,-1,CONCRETE:0)
Block(0,7,0,REDSTONE_WIRE:0)
Block(0,7,1,quark:marble_wall:0)
RandomBlock(0,7,2,IRON_FENCE:0,30,IRON_FENCE:0,100)
Block(0,7,5,quark:world_stone_pavement:2)
Block(0,7,6,CONCRETE:0)
Block(0,7,7,CONCRETE:0)
Block(0,7,8,quark:world_stone_pavement:2)
Block(0,8,-2,quark:world_stone_pavement:1)
Block(0,8,-1,CONCRETE:0)
Block(0,8,0,CONCRETE:0)
Block(0,8,1,CONCRETE:0)
Block(0,8,2,CONCRETE:0)
Block(0,8,3,srparasites:parasiterubbledense:1)
Block(0,8,4,srparasites:parasiterubbledense:1)
Block(0,8,5,quark:polished_stone:0)
Block(0,8,6,quark:world_stone_pavement:2)
Block(0,8,7,quark:polished_stone:0)
Block(0,8,8,quark:world_stone_pavement:2)
Block(0,9,-2,quark:world_stone_pavement:2)
Block(0,9,0,CONCRETE:0)
Block(0,9,1,quark:world_stone_pavement:2)
Block(0,9,2,CONCRETE:0)
Block(0,9,3,quark:world_stone_pavement:2)
Block(0,9,4,quark:world_stone_pavement:2)
Block(0,9,5,quark:polished_stone:0)
Block(0,9,6,quark:polished_stone:0)
Block(0,9,7,quark:polished_stone:0)
Block(0,9,8,quark:world_stone_pavement:2)
Block(0,10,-2,quark:world_stone_pavement:2)
Block(0,10,-1,quark:grate:0)
Block(0,10,0,quark:world_stone_pavement:2)
Block(0,10,1,CONCRETE:0)
Block(0,10,2,quark:world_stone_pavement:2)
Block(0,10,3,srparasites:parasiterubbledense:1)
Block(0,10,4,quark:polished_stone:0)
Block(0,10,5,quark:world_stone_pavement:2)
Block(0,10,6,quark:polished_stone:0)
Block(0,10,7,quark:world_stone_pavement:2)
Block(0,10,8,srparasites:parasiterubbledense:1)
RandomBlock(0,11,-2,IRON_FENCE:0,30,IRON_FENCE:0,100)
Block(0,11,0,quark:iron_plate:1)
Block(0,11,2,quark:iron_plate:1)
Block(0,11,3,srparasites:infestedbush:3)
Block(0,11,6,quark:world_stone_pavement:2)
Block(0,11,7,quark:polished_stone:0)
Block(0,12,3,srparasites:infestedbush:3)
Block(0,12,6,quark:world_stone_pavement:2)
Block(0,12,7,quark:world_stone_pavement:2)
Block(0,13,3,srparasites:infestedbush:3)
Block(0,13,6,quark:polished_stone:0)
Block(0,13,7,quark:polished_stone:0)
Block(0,13,8,quark:polished_stone:0)
Block(0,14,3,srparasites:infestedbush:3)
Block(0,14,6,DOUBLE_STEP:0)
Block(0,14,7,quark:world_stone_pavement:2)
Block(0,14,8,quark:polished_stone:0)
Block(0,15,3,srparasites:infestedbush:3)
Block(0,15,4,quark:iron_plate_slab:8)
Block(0,15,5,quark:grate:0)
Block(0,15,6,DOUBLE_STEP:0)
Block(0,15,7,CONCRETE:0)
RandomBlock(0,15,8,IRON_FENCE:0,30,IRON_FENCE:0,100)
RandomBlock(0,16,4,IRON_FENCE:0,30,IRON_FENCE:0,100)
Block(0,16,5,srparasites:parasitethin)
Block(0,16,6,DOUBLE_STEP:0)
Block(0,16,7,quark:iron_plate:1)
Block(0,16,8,quark:iron_plate:1)
RandomBlock(0,17,4,IRON_FENCE:0,30,IRON_FENCE:0,100)
Block(0,17,5,srparasites:parasitethin)
Block(0,17,6,DOUBLE_STEP:0)
Block(0,17,7,quark:world_stone_pavement:2)
Block(0,18,5,srparasites:parasitethin)
Block(0,18,6,DOUBLE_STEP:0)
Block(0,18,7,quark:iron_plate:1)
Block(0,19,1,srparasites:parasiterubbledense:2)
Block(0,19,5,srparasites:parasitethin)
Block(0,19,6,quark:iron_plate:1)
Block(0,19,7,quark:iron_plate:1)
RandomBlock(0,19,8,CONCRETE:0,40,SMOOTH_BRICK:1,30,SMOOTH_BRICK:2,30,MOSSY_COBBLESTONE:0,30,COBBLESTONE:0,20,CONCRETE:0,100)
Block(0,20,1,srparasites:parasitethin)
Block(0,20,5,quark:polished_stone:0)
Block(0,20,6,SMOOTH_STAIRS:3)
Block(0,20,8,DOUBLE_STEP:0)
Block(0,21,-4,quark:iron_plate:1)
Block(0,21,1,srparasites:parasitethin)
Block(0,21,4,quark:polished_stone:0)
Block(0,21,5,STEP:0)
Block(0,21,8,DOUBLE_STEP:0)
Block(0,22,-6,srparasites:parasitethin)
Block(0,22,1,srparasites:parasitethin)
Block(0,22,2,srparasites:parasitethin)
Block(0,22,3,quark:iron_plate:1)
Block(0,22,4,SMOOTH_STAIRS:3)
Block(0,22,8,STEP:0)
Block(0,23,-7,STEP:0)
Block(0,23,0,srparasites:parasitethin)
Block(0,23,1,srparasites:parasitethin)
Block(0,23,2,quark:iron_plate:1)
Block(0,23,3,SMOOTH_STAIRS:3)
Block(0,24,-4,srparasites:parasitethin)
Block(0,24,-3,srparasites:parasitethin)
Block(0,24,-2,srparasites:parasitethin)
Block(0,24,-1,srparasites:parasitethin)
Block(0,24,0,srparasites:parasitethin)
Block(0,24,1,quark:iron_plate:1)
Block(0,24,2,SMOOTH_STAIRS:3)
Block(0,25,-7,quark:polished_stone:0)
RandomBlock(0,25,-6,CONCRETE:0,40,SMOOTH_BRICK:1,30,SMOOTH_BRICK:2,30,MOSSY_COBBLESTONE:0,30,COBBLESTONE:0,20,CONCRETE:0,100)
RandomBlock(0,25,-5,CONCRETE:0,40,SMOOTH_BRICK:1,30,SMOOTH_BRICK:2,30,MOSSY_COBBLESTONE:0,30,COBBLESTONE:0,20,CONCRETE:0,100)
RandomBlock(0,25,-4,CONCRETE:0,40,SMOOTH_BRICK:1,30,SMOOTH_BRICK:2,30,MOSSY_COBBLESTONE:0,30,COBBLESTONE:0,20,CONCRETE:0,100)
RandomBlock(0,25,-3,CONCRETE:0,40,SMOOTH_BRICK:1,30,SMOOTH_BRICK:2,30,MOSSY_COBBLESTONE:0,30,COBBLESTONE:0,20,CONCRETE:0,100)
RandomBlock(0,25,-2,CONCRETE:0,40,SMOOTH_BRICK:1,30,SMOOTH_BRICK:2,30,MOSSY_COBBLESTONE:0,30,COBBLESTONE:0,20,CONCRETE:0,100)
RandomBlock(0,25,-1,CONCRETE:0,40,SMOOTH_BRICK:1,30,SMOOTH_BRICK:2,30,MOSSY_COBBLESTONE:0,30,COBBLESTONE:0,20,CONCRETE:0,100)
Block(0,25,0,quark:iron_plate:1)
Block(0,25,1,SMOOTH_STAIRS:3)
Block(0,26,-5,quark:basalt_wall:0)
Block(0,26,-4,quark:basalt_wall:0)
Block(0,26,-3,quark:basalt_wall:0)
Block(0,26,0,quark:stone_diorite_bricks_wall:0)
Block(0,27,-5,DISPENSER:1)
Block(0,27,-4,DISPENSER:1)
Block(0,27,-3,DISPENSER:1)
Block(0,28,-5,IRON_TRAPDOOR:1)
Block(0,28,-4,IRON_TRAPDOOR:0)
Block(0,28,-3,IRON_TRAPDOOR:0)
Block(1,0,-7,quark:world_stone_pavement:4)
Block(1,0,-6,quark:world_stone_pavement:1)
Block(1,0,-5,quark:world_stone_pavement:2)
Block(1,0,-4,quark:world_stone_pavement:2)
Block(1,0,-3,quark:world_stone_pavement:2)
Block(1,0,-2,quark:world_stone_pavement:2)
Block(1,0,-1,quark:world_stone_pavement:2)
Block(1,0,0,CONCRETE:0)
Block(1,0,1,quark:world_stone_pavement:2)
Block(1,0,2,quark:world_stone_pavement:2)
Block(1,0,3,CONCRETE:0)
Block(1,0,4,quark:world_stone_pavement:2)
Block(1,0,5,quark:world_stone_pavement:2)
Block(1,0,6,CONCRETE:0)
Block(1,0,7,CONCRETE:0)
Block(1,0,8,CONCRETE:0)
Block(1,1,-7,STATIONARY_WATER:0)
Block(1,1,-6,quark:iron_plate:1)
RandomBlock(1,1,-5,SMOOTH_BRICK:0,5,SMOOTH_BRICK:0,10,thermalfoundation:ore:7,50,SMOOTH_BRICK:0,100)
Block(1,1,-4,quark:iron_plate:1)
Block(1,1,-3,STATIONARY_WATER:0)
Block(1,1,-2,quark:world_stone_pavement:2)
Block(1,1,-1,CONCRETE:0)
Block(1,1,0,quark:world_stone_pavement:2)
Block(1,1,1,quark:world_stone_pavement:2)
Block(1,1,2,quark:world_stone_pavement:2)
Block(1,1,3,CONCRETE:0)
Block(1,1,4,quark:world_stone_pavement:2)
Block(1,1,5,CONCRETE:0)
Block(1,1,6,CONCRETE:0)
Block(1,1,7,CONCRETE:0)
Block(1,1,8,quark:world_stone_pavement:2)
Block(1,2,-7,STATIONARY_WATER:0)
Block(1,2,-6,quark:iron_plate:1)
RandomBlock(1,2,-5,SMOOTH_BRICK:0,5,SMOOTH_BRICK:0,10,thermalfoundation:ore:7,50,SMOOTH_BRICK:0,100)
Block(1,2,-4,quark:iron_plate:1)
Block(1,2,-3,STATIONARY_WATER:0)
Block(1,2,-2,quark:world_stone_pavement:2)
Block(1,2,-1,quark:world_stone_pavement:2)
Block(1,2,0,CONCRETE:0)
Block(1,2,1,quark:world_stone_pavement:2)
Block(1,2,2,quark:world_stone_pavement:2)
Block(1,2,3,CONCRETE:0)
Block(1,2,4,quark:world_stone_pavement:2)
Block(1,2,5,CONCRETE:0)
Block(1,2,6,quark:world_stone_pavement:2)
Block(1,2,7,quark:world_stone_pavement:2)
Block(1,2,8,quark:world_stone_pavement:2)
Block(1,3,-7,STATIONARY_WATER:0)
Block(1,3,-6,quark:iron_plate:1)
Block(1,3,-5,STATIONARY_WATER:0)
Block(1,3,-4,quark:iron_plate:1)
Block(1,3,-3,STATIONARY_WATER:0)
Block(1,3,-2,quark:world_stone_pavement:2)
Block(1,3,-1,CONCRETE:0)
Block(1,3,0,CONCRETE:0)
Block(1,3,1,quark:world_stone_pavement:2)
Block(1,3,2,quark:world_stone_pavement:2)
Block(1,3,3,CONCRETE:0)
Block(1,3,4,quark:world_stone_pavement:2)
Block(1,3,5,CONCRETE:0)
Block(1,3,6,quark:world_stone_pavement:2)
Block(1,3,7,quark:world_stone_pavement:2)
Block(1,3,8,CONCRETE:0)
Block(1,4,-7,STATIONARY_WATER:0)
Block(1,4,-6,quark:iron_plate:1)
Block(1,4,-5,STATIONARY_WATER:0)
Block(1,4,-4,STATIONARY_WATER:0)
Block(1,4,-3,STATIONARY_WATER:0)
Block(1,4,-2,srparasites:parasiterubbledense:1)
Block(1,4,-1,CONCRETE:0)
Block(1,4,0,CONCRETE:0)
Block(1,4,1,quark:world_stone_pavement:2)
Block(1,4,2,quark:world_stone_pavement:2)
Block(1,4,3,CONCRETE:0)
Block(1,4,5,CONCRETE:0)
Block(1,4,6,quark:world_stone_pavement:2)
Block(1,4,7,quark:world_stone_pavement:2)
Block(1,4,8,CONCRETE:0)
Block(1,5,-3,srparasites:parasitethin)
Block(1,5,-2,srparasites:parasiterubbledense:1)
Block(1,5,-1,CONCRETE:0)
Block(1,5,0,quark:world_stone_pavement:2)
Block(1,5,1,quark:world_stone_pavement:2)
Block(1,5,2,quark:world_stone_pavement:2)
Block(1,5,3,CONCRETE:0)
Block(1,5,4,quark:grate:0)
Block(1,5,5,CONCRETE:0)
Block(1,5,6,quark:world_stone_pavement:2)
Block(1,5,7,quark:world_stone_pavement:2)
Block(1,5,8,CONCRETE:0)
Block(1,6,-3,srparasites:parasitethin)
Block(1,6,-2,quark:world_stone_pavement:2)
Block(1,6,-1,quark:world_stone_pavement:2)
Block(1,6,0,quark:world_stone_pavement:2)
Block(1,6,1,quark:marble_wall:0)
Block(1,6,2,quark:marble_wall:0)
Block(1,6,3,quark:basalt_wall:0)
Block(1,6,5,quark:world_stone_pavement:2)
Block(1,6,6,CONCRETE:0)
Block(1,6,7,CONCRETE:0)
Block(1,6,8,CONCRETE:0)
Block(1,7,-3,srparasites:parasitethin)
Block(1,7,-2,LEAVES:4)
Block(1,7,-1,quark:world_stone_pavement:2)
Block(1,7,0,REDSTONE_WIRE:0)
Block(1,7,1,quark:marble_wall:0)
Block(1,7,2,quark:marble_wall:0)
Block(1,7,3,quark:basalt_wall:0)
Block(1,7,5,CONCRETE:0)
Block(1,7,6,CONCRETE:0)
Block(1,7,7,CONCRETE:0)
Block(1,7,8,quark:world_stone_pavement:2)
Block(1,8,-3,srparasites:parasitethin)
Block(1,8,-2,LEAVES:4)
Block(1,8,-1,CONCRETE:0)
Block(1,8,0,quark:world_stone_pavement:2)
Block(1,8,1,quark:world_stone_pavement:2)
Block(1,8,2,quark:world_stone_pavement:2)
Block(1,8,3,quark:world_stone_pavement:2)
Block(1,8,4,CONCRETE:0)
Block(1,8,5,quark:polished_stone:0)
Block(1,8,6,CONCRETE:0)
Block(1,8,7,quark:polished_stone:0)
Block(1,8,8,quark:world_stone_pavement:2)
Block(1,9,-3,srparasites:parasitethin)
Block(1,9,-2,quark:world_stone_pavement:4)
Block(1,9,0,CONCRETE:0)
Block(1,9,1,CONCRETE:0)
Block(1,9,2,CONCRETE:0)
Block(1,9,3,CONCRETE:0)
Block(1,9,4,quark:world_stone_pavement:2)
Block(1,9,5,quark:polished_stone:0)
Block(1,9,6,quark:polished_stone:0)
Block(1,9,7,quark:polished_stone:0)
Block(1,9,8,quark:world_stone_pavement:2)
Block(1,10,-3,srparasites:parasitethin)
Block(1,10,-2,CONCRETE:0)
Block(1,10,-1,quark:grate:0)
Block(1,10,0,quark:world_stone_pavement:2)
Block(1,10,1,CONCRETE:0)
Block(1,10,2,quark:world_stone_pavement:2)
Block(1,10,3,CONCRETE:0)
Block(1,10,4,quark:polished_stone:0)
Block(1,10,5,quark:polished_stone:0)
Block(1,10,6,quark:polished_stone:0)
Block(1,10,7,quark:polished_stone:0)
Block(1,10,8,srparasites:parasiterubbledense:1)
Block(1,11,0,quark:iron_plate:1)
Block(1,11,2,quark:iron_plate:1)
Block(1,11,6,quark:world_stone_pavement:2)
Block(1,11,7,quark:polished_stone:0)
Block(1,11,8,srparasites:infestedbush:3)
Block(1,12,6,quark:polished_stone:0)
Block(1,12,7,quark:polished_stone:0)
Block(1,12,8,srparasites:infestedbush:3)
Block(1,13,6,quark:polished_stone:0)
Block(1,13,7,quark:world_stone_pavement:2)
Block(1,13,8,quark:world_stone_pavement:2)
RandomBlock(1,14,6,CONCRETE:0,40,SMOOTH_BRICK:1,30,SMOOTH_BRICK:2,30,MOSSY_COBBLESTONE:0,30,COBBLESTONE:0,20,CONCRETE:0,100)
Block(1,14,7,quark:world_stone_pavement:2)
Block(1,14,8,quark:polished_stone:0)
Block(1,15,-3,srparasites:parasiterubbledense:2)
Block(1,15,4,quark:iron_plate_slab:8)
Block(1,15,5,quark:grate:0)
Block(1,15,6,quark:world_stone_pavement:2)
Block(1,15,7,quark:iron_plate:1)
Block(1,16,-3,srparasites:parasitethin)
RandomBlock(1,16,4,IRON_FENCE:0,30,IRON_FENCE:0,100)
RandomBlock(1,16,6,CONCRETE:0,40,SMOOTH_BRICK:1,30,SMOOTH_BRICK:2,30,MOSSY_COBBLESTONE:0,30,COBBLESTONE:0,20,CONCRETE:0,100)
Block(1,16,7,quark:iron_plate:1)
Block(1,16,8,quark:iron_plate:1)
Block(1,17,-3,srparasites:parasitethin)
RandomBlock(1,17,4,IRON_FENCE:0,30,IRON_FENCE:0,100)
RandomBlock(1,17,6,CONCRETE:0,40,SMOOTH_BRICK:1,30,SMOOTH_BRICK:2,30,MOSSY_COBBLESTONE:0,30,COBBLESTONE:0,20,CONCRETE:0,100)
Block(1,17,7,CONCRETE:0)
Block(1,18,-3,srparasites:parasitethin)
RandomBlock(1,18,6,CONCRETE:0,40,SMOOTH_BRICK:1,30,SMOOTH_BRICK:2,30,MOSSY_COBBLESTONE:0,30,COBBLESTONE:0,20,CONCRETE:0,100)
Block(1,18,7,quark:iron_plate:1)
Block(1,19,-4,srparasites:parasiterubbledense:2)
Block(1,19,-3,srparasites:parasitethin)
Block(1,19,6,quark:iron_plate:1)
Block(1,19,7,quark:iron_plate:1)
RandomBlock(1,19,8,CONCRETE:0,40,SMOOTH_BRICK:1,30,SMOOTH_BRICK:2,30,MOSSY_COBBLESTONE:0,30,COBBLESTONE:0,20,CONCRETE:0,100)
Block(1,20,-4,srparasites:parasitethin)
Block(1,20,-3,srparasites:parasitethin)
Block(1,20,5,quark:polished_stone:0)
Block(1,20,6,SMOOTH_STAIRS:3)
Block(1,21,-6,srparasites:parasiterubbledense:2)
Block(1,21,-4,quark:iron_plate:1)
Block(1,21,-3,srparasites:parasitethin)
Block(1,21,4,quark:polished_stone:0)
Block(1,21,5,STEP:0)
Block(1,22,-6,srparasites:parasitethin)
Block(1,22,-5,srparasites:parasitethin)
Block(1,22,-4,srparasites:parasitethin)
Block(1,22,-3,srparasites:parasitethin)
Block(1,22,2,srparasites:parasitethin)
Block(1,22,3,quark:iron_plate:1)
Block(1,22,4,SMOOTH_STAIRS:3)
Block(1,23,-7,STEP:0)
Block(1,23,-5,srparasites:parasitethin)
Block(1,23,2,quark:iron_plate:1)
Block(1,23,3,SMOOTH_STAIRS:3)
Block(1,24,-5,srparasites:parasitethin)
Block(1,24,-4,srparasites:parasitethin)
Block(1,24,1,quark:iron_plate:1)
Block(1,24,2,SMOOTH_STAIRS:3)
RandomBlock(1,25,-7,CONCRETE:0,40,SMOOTH_BRICK:1,30,SMOOTH_BRICK:2,30,MOSSY_COBBLESTONE:0,30,COBBLESTONE:0,20,CONCRETE:0,100)
RandomBlock(1,25,-6,CONCRETE:0,40,SMOOTH_BRICK:1,30,SMOOTH_BRICK:2,30,MOSSY_COBBLESTONE:0,30,COBBLESTONE:0,20,CONCRETE:0,100)
RandomBlock(1,25,-5,CONCRETE:0,40,SMOOTH_BRICK:1,30,SMOOTH_BRICK:2,30,MOSSY_COBBLESTONE:0,30,COBBLESTONE:0,20,CONCRETE:0,100)
RandomBlock(1,25,-4,CONCRETE:0,40,SMOOTH_BRICK:1,30,SMOOTH_BRICK:2,30,MOSSY_COBBLESTONE:0,30,COBBLESTONE:0,20,CONCRETE:0,100)
RandomBlock(1,25,-3,CONCRETE:0,40,SMOOTH_BRICK:1,30,SMOOTH_BRICK:2,30,MOSSY_COBBLESTONE:0,30,COBBLESTONE:0,20,CONCRETE:0,100)
Block(1,25,-2,quark:polished_stone:0)
Block(1,25,-1,quark:polished_stone:0)
Block(1,25,0,quark:iron_plate:1)
Block(1,25,1,SMOOTH_STAIRS:3)
Block(1,26,-7,quark:iron_plate:1)
Block(1,26,-6,quark:iron_plate:1)
Block(1,26,-5,quark:iron_plate:1)
Block(1,26,-4,quark:basalt_wall:0)
Block(1,26,-3,quark:basalt_wall:0)
Block(1,26,0,quark:stone_diorite_bricks_wall:0)
Block(1,27,-5,DISPENSER:1)
Block(1,27,-4,DISPENSER:1)
Block(1,27,-3,DISPENSER:1)
Block(1,28,-5,IRON_TRAPDOOR:1)
Block(1,28,-4,IRON_TRAPDOOR:0)
Block(1,28,-3,IRON_TRAPDOOR:0)
Block(2,0,-7,quark:world_stone_pavement:2)
Block(2,0,-6,quark:world_stone_pavement:4)
Block(2,0,-5,quark:world_stone_pavement:4)
Block(2,0,-4,quark:world_stone_pavement:4)
Block(2,0,-3,quark:world_stone_pavement:2)
Block(2,0,-2,quark:world_stone_pavement:2)
Block(2,0,-1,quark:world_stone_pavement:2)
Block(2,0,0,CONCRETE:0)
Block(2,0,1,CONCRETE:0)
Block(2,0,2,quark:world_stone_pavement:2)
Block(2,0,3,quark:world_stone_pavement:2)
Block(2,0,4,quark:world_stone_pavement:2)
Block(2,0,5,quark:world_stone_pavement:2)
Block(2,0,6,CONCRETE:0)
Block(2,0,7,CONCRETE:0)
Block(2,0,8,CONCRETE:0)
Block(2,1,-7,quark:iron_plate:1)
RandomBlock(2,1,-6,SMOOTH_BRICK:0,5,SMOOTH_BRICK:0,10,thermalfoundation:ore:7,50,SMOOTH_BRICK:0,100)
Block(2,1,-5,quark:iron_plate:1)
Block(2,1,-4,STATIONARY_WATER:0)
Block(2,1,-3,quark:iron_plate:1)
Block(2,1,-2,quark:world_stone_pavement:2)
Block(2,1,-1,quark:world_stone_pavement:2)
Block(2,1,0,CONCRETE:0)
Block(2,1,1,CONCRETE:0)
Block(2,1,2,quark:world_stone_pavement:2)
Block(2,1,3,quark:world_stone_pavement:2)
Block(2,1,4,quark:world_stone_pavement:2)
Block(2,1,5,quark:world_stone_pavement:2)
Block(2,1,6,CONCRETE:0)
Block(2,1,7,CONCRETE:0)
Block(2,1,8,CONCRETE:0)
Block(2,2,-7,quark:iron_plate:1)
RandomBlock(2,2,-6,SMOOTH_BRICK:0,5,SMOOTH_BRICK:0,10,thermalfoundation:ore:7,50,SMOOTH_BRICK:0,100)
Block(2,2,-5,quark:iron_plate:1)
Block(2,2,-4,STATIONARY_WATER:0)
Block(2,2,-3,quark:iron_plate:1)
Block(2,2,-2,quark:world_stone_pavement:2)
Block(2,2,-1,quark:world_stone_pavement:2)
Block(2,2,0,CONCRETE:0)
Block(2,2,1,quark:world_stone_pavement:2)
Block(2,2,2,quark:world_stone_pavement:2)
Block(2,2,3,quark:world_stone_pavement:2)
Block(2,2,4,quark:world_stone_pavement:2)
Block(2,2,5,quark:world_stone_pavement:2)
Block(2,2,6,CONCRETE:0)
Block(2,2,7,CONCRETE:0)
Block(2,2,8,CONCRETE:0)
Block(2,3,-7,quark:iron_plate:1)
Block(2,3,-6,STATIONARY_WATER:0)
Block(2,3,-5,quark:iron_plate:1)
Block(2,3,-4,STATIONARY_WATER:0)
Block(2,3,-3,quark:iron_plate:1)
Block(2,3,-2,quark:world_stone_pavement:2)
Block(2,3,-1,quark:world_stone_pavement:2)
Block(2,3,0,quark:world_stone_pavement:2)
Block(2,3,1,CONCRETE:0)
Block(2,3,2,quark:world_stone_pavement:2)
Block(2,3,3,quark:world_stone_pavement:2)
Block(2,3,4,quark:world_stone_pavement:2)
Block(2,3,5,quark:world_stone_pavement:2)
Block(2,3,6,CONCRETE:0)
Block(2,3,7,CONCRETE:0)
Block(2,3,8,CONCRETE:0)
Block(2,4,-7,quark:iron_plate:1)
Block(2,4,-6,STATIONARY_WATER:0)
Block(2,4,-5,quark:iron_plate:1)
Block(2,4,-4,STATIONARY_WATER:0)
Block(2,4,-3,STATIONARY_WATER:0)
Block(2,4,-2,quark:world_stone_pavement:2)
Block(2,4,-1,quark:world_stone_pavement:2)
Block(2,4,0,CONCRETE:0)
Block(2,4,1,quark:world_stone_pavement:2)
Block(2,4,2,quark:world_stone_pavement:2)
Block(2,4,3,quark:world_stone_pavement:2)
Block(2,4,5,quark:world_stone_pavement:2)
Block(2,4,6,quark:world_stone_pavement:2)
Block(2,4,7,CONCRETE:0)
Block(2,4,8,CONCRETE:0)
Block(2,5,-7,quark:iron_plate:1)
Block(2,5,-3,srparasites:parasitethin)
Block(2,5,-2,srparasites:parasiterubbledense:1)
Block(2,5,-1,quark:world_stone_pavement:2)
Block(2,5,0,quark:world_stone_pavement:2)
Block(2,5,1,CONCRETE:0)
Block(2,5,2,quark:world_stone_pavement:2)
Block(2,5,3,srparasites:parasiterubbledense:1)
Block(2,5,4,quark:grate:0)
Block(2,5,5,quark:world_stone_pavement:2)
Block(2,5,6,CONCRETE:0)
Block(2,5,7,CONCRETE:0)
Block(2,5,8,CONCRETE:0)
Block(2,6,-3,srparasites:parasitethin)
Block(2,6,-2,LEAVES:12)
Block(2,6,-1,quark:world_stone_pavement:2)
Block(2,6,0,quark:world_stone_pavement:2)
Block(2,6,1,quark:world_stone_pavement:2)
Block(2,6,2,quark:marble_wall:0)
Block(2,6,5,quark:world_stone_pavement:2)
Block(2,6,6,CONCRETE:0)
Block(2,6,7,CONCRETE:0)
Block(2,6,8,CONCRETE:0)
Block(2,7,-3,srparasites:parasitethin)
Block(2,7,-2,LEAVES:12)
Block(2,7,-1,CONCRETE:0)
Block(2,7,0,REDSTONE_WIRE:0)
Block(2,7,1,REDSTONE_WIRE:0)
