
#######################################################################
# +-----------------------------------------------------------------+ #
# |                            BO4 object                           | #
# +-----------------------------------------------------------------+ #
#######################################################################

Author: NLBlackEagle

Description: No description given

SettingsMode: WriteWithoutComments


#######################################################################
# +-----------------------------------------------------------------+ #
# |                          Main settings                          | #
# +-----------------------------------------------------------------+ #
#######################################################################

FixedRotation: 

Frequency: 0

SpawnHeight: highestBlock

UseCenterForHighestBlock: true

##############################
# Height Limits for the BO4. #
##############################

MinHeight: 0

MaxHeight: 255

InheritBO3: 

InheritBO3Rotation: NORTH

OverrideChildSettings: true

OverrideParentHeight: false

CanOverride: true

BranchFrequency: 0

BranchFrequencyGroup: 

MustBeBelowOther: false

MustBeInside: 

CannotBeInside: 

ReplacesBO3: 

MustBeInsideWorldBorders: true

CanSpawnOnWater: true

SpawnOnWaterOnly: false

SpawnUnderWater: false

SpawnAtWaterLevel: false

HeightOffset: 0

RemoveAir: false

ReplaceAbove: 

ReplaceBelow: 

ReplaceWithBiomeBlocks: false

ReplaceWithSurfaceBlock: GRASS

ReplaceWithGroundBlock: DIRT

ReplaceWithStoneBlock: STONE

SmoothRadius: 0

SmoothHeightOffset: 0

SmoothStartTop: false

SmoothStartWood: false

SmoothingSurfaceBlock: 

SmoothingGroundBlock: 

BO3Group: 

IsSpawnPoint: false

DoReplaceBlocks: true


#######################################################################
# +-----------------------------------------------------------------+ #
# |                              Blocks                             | #
# +-----------------------------------------------------------------+ #
#######################################################################

RandomBlock(-8,15,-5,IRON_FENCE:0,30,IRON_FENCE:0,100)
Block(-8,16,-7,STEP:8)
Block(-8,16,-6,STEP:8)
Block(-8,16,-5,quark:iron_plate:1)
Block(-8,17,-5,quark:framed_glass:0)
Block(-8,18,-5,quark:framed_glass:0)
Block(-8,19,-7,STEP:8)
Block(-8,19,-6,STEP:8)
Block(-8,19,-5,quark:iron_plate:1)
RandomBlock(-8,20,-5,IRON_FENCE:0,30,IRON_FENCE:0,100)
RandomBlock(-7,15,-5,IRON_FENCE:0,30,IRON_FENCE:0,100)
Block(-7,16,-7,STEP:8)
Block(-7,16,-6,STEP:8)
Block(-7,16,-5,quark:iron_plate:1)
Block(-7,17,-5,quark:framed_glass:0)
Block(-7,18,-5,quark:framed_glass:0)
Block(-7,19,-7,STEP:8)
Block(-7,19,-6,STEP:8)
Block(-7,19,-5,quark:iron_plate:1)
RandomBlock(-7,20,-5,IRON_FENCE:0,30,IRON_FENCE:0,100)
RandomBlock(-6,15,-5,IRON_FENCE:0,30,IRON_FENCE:0,100)
Block(-6,16,-7,STEP:8)
Block(-6,16,-6,STEP:8)
Block(-6,16,-5,quark:iron_plate:1)
Block(-6,17,-5,quark:framed_glass:0)
Block(-6,18,-5,quark:framed_glass:0)
Block(-6,19,-7,STEP:8)
Block(-6,19,-6,STEP:8)
Block(-6,19,-5,quark:iron_plate:1)
RandomBlock(-6,20,-5,IRON_FENCE:0,30,IRON_FENCE:0,100)
Block(-5,0,-7,quark:iron_plate:1)
Block(-5,0,-6,quark:iron_plate:1)
Block(-5,1,-7,quark:iron_plate:1)
Block(-5,1,-6,quark:iron_plate:1)
Block(-5,2,-7,quark:iron_plate:1)
Block(-5,2,-6,quark:iron_plate:1)
Block(-5,3,-7,quark:iron_plate:1)
Block(-5,3,-6,quark:iron_plate:1)
Block(-5,4,-7,quark:iron_plate:1)
Block(-5,4,-6,quark:iron_plate:1)
Block(-5,5,-7,quark:iron_plate:1)
Block(-5,5,-6,quark:iron_plate:1)
Block(-5,6,-7,quark:iron_plate:1)
Block(-5,6,-6,quark:iron_plate:1)
Block(-5,7,-7,quark:iron_plate:1)
Block(-5,7,-6,quark:iron_plate:1)
Block(-5,8,-7,quark:iron_plate:1)
Block(-5,8,-6,quark:iron_plate:1)
Block(-5,9,-7,quark:iron_plate:1)
Block(-5,9,-6,quark:iron_plate:1)
Block(-5,10,-7,quark:iron_plate:1)
Block(-5,10,-6,quark:iron_plate:1)
Block(-5,11,-7,quark:iron_plate:1)
Block(-5,11,-6,quark:iron_plate:1)
Block(-5,12,-7,quark:iron_plate:1)
Block(-5,12,-6,quark:iron_plate:1)
Block(-5,13,-7,quark:iron_plate:1)
Block(-5,13,-6,quark:iron_plate:1)
Block(-5,14,-7,quark:iron_plate:1)
Block(-5,14,-6,quark:iron_plate:1)
Block(-5,15,-7,quark:iron_plate:1)
Block(-5,15,-6,quark:iron_plate:1)
RandomBlock(-5,15,-5,IRON_FENCE:0,30,IRON_FENCE:0,100)
RandomBlock(-5,15,-4,IRON_FENCE:0,30,IRON_FENCE:0,100)
Block(-5,16,-7,quark:iron_plate:1)
Block(-5,16,-6,quark:iron_plate:1)
Block(-5,16,-5,quark:iron_plate:1)
RandomBlock(-5,16,-4,IRON_FENCE:0,30,IRON_FENCE:0,100)
Block(-5,17,-5,SMOOTH_STAIRS:3)
RandomBlock(-5,17,-4,IRON_FENCE:0,30,IRON_FENCE:0,100)
Block(-5,18,-5,SMOOTH_STAIRS:7)
RandomBlock(-5,18,-4,IRON_FENCE:0,30,IRON_FENCE:0,100)
Block(-5,19,-7,STEP:8)
Block(-5,19,-6,STEP:8)
Block(-5,19,-5,quark:iron_plate:1)
RandomBlock(-5,19,-4,IRON_FENCE:0,30,IRON_FENCE:0,100)
RandomBlock(-5,20,-5,IRON_FENCE:0,30,IRON_FENCE:0,100)
RandomBlock(-5,20,-4,IRON_FENCE:0,30,IRON_FENCE:0,100)
RandomBlock(-4,15,-5,IRON_FENCE:0,30,IRON_FENCE:0,100)
Block(-4,16,-7,STEP:8)
Block(-4,16,-6,STEP:8)
Block(-4,16,-5,quark:iron_plate:1)
Block(-4,17,-5,quark:framed_glass:0)
Block(-4,18,-5,quark:framed_glass:0)
Block(-4,19,-7,STEP:8)
Block(-4,19,-6,STEP:8)
Block(-4,19,-5,quark:iron_plate:1)
RandomBlock(-4,20,-5,IRON_FENCE:0,30,IRON_FENCE:0,100)
RandomBlock(-3,15,-5,IRON_FENCE:0,30,IRON_FENCE:0,100)
Block(-3,16,-7,STEP:8)
Block(-3,16,-6,STEP:8)
Block(-3,16,-5,quark:iron_plate:1)
Block(-3,17,-5,quark:framed_glass:0)
Block(-3,18,-5,quark:framed_glass:0)
Block(-3,19,-7,STEP:8)
Block(-3,19,-6,STEP:8)
Block(-3,19,-5,quark:iron_plate:1)
RandomBlock(-3,20,-5,IRON_FENCE:0,30,IRON_FENCE:0,100)
Block(-2,0,-7,CONCRETE:0)
Block(-2,0,-6,quark:world_stone_pavement:2)
Block(-2,0,-5,CONCRETE:0)
Block(-2,0,-4,CONCRETE:0)
Block(-2,0,-3,quark:world_stone_pavement:2)
Block(-2,0,-2,CONCRETE:0)
Block(-2,0,-1,quark:world_stone_pavement:2)
Block(-2,0,0,CONCRETE:0)
Block(-2,1,-7,CONCRETE:0)
Block(-2,1,-6,CONCRETE:0)
Block(-2,1,-5,CONCRETE:0)
Block(-2,1,-4,CONCRETE:0)
Block(-2,1,-3,CONCRETE:0)
Block(-2,1,-2,quark:world_stone_pavement:2)
Block(-2,1,-1,CONCRETE:0)
Block(-2,1,0,CONCRETE:0)
Block(-2,2,-7,CONCRETE:0)
Block(-2,2,-6,CONCRETE:0)
Block(-2,2,-5,CONCRETE:0)
Block(-2,2,-4,quark:world_stone_pavement:2)
Block(-2,2,-3,CONCRETE:0)
Block(-2,2,-2,CONCRETE:0)
Block(-2,2,-1,quark:world_stone_pavement:2)
Block(-2,2,0,CONCRETE:0)
Block(-2,3,-7,CONCRETE:0)
Block(-2,3,-6,CONCRETE:0)
Block(-2,3,-5,quark:world_stone_pavement:2)
Block(-2,3,-4,CONCRETE:0)
Block(-2,3,-3,CONCRETE:0)
Block(-2,3,-2,CONCRETE:0)
Block(-2,3,-1,CONCRETE:0)
Block(-2,3,0,CONCRETE:0)
Block(-2,4,-7,CONCRETE:0)
Block(-2,4,-6,quark:world_stone_pavement:2)
Block(-2,4,-5,CONCRETE:0)
Block(-2,4,-4,quark:world_stone_pavement:2)
Block(-2,4,-3,CONCRETE:0)
Block(-2,4,-2,CONCRETE:0)
Block(-2,4,-1,quark:world_stone_pavement:2)
Block(-2,4,0,CONCRETE:0)
Block(-2,5,-7,CONCRETE:0)
Block(-2,5,-6,CONCRETE:0)
Block(-2,5,-5,quark:world_stone_pavement:2)
Block(-2,5,-4,CONCRETE:0)
Block(-2,5,-3,CONCRETE:0)
Block(-2,5,-2,CONCRETE:0)
Block(-2,5,-1,quark:world_stone_pavement:2)
Block(-2,5,0,quark:world_stone_pavement:2)
Block(-2,6,-7,quark:world_stone_pavement:2)
Block(-2,6,-6,CONCRETE:0)
Block(-2,6,-5,CONCRETE:0)
Block(-2,6,-4,quark:world_stone_pavement:2)
Block(-2,6,-3,CONCRETE:0)
Block(-2,6,-2,CONCRETE:0)
Block(-2,6,-1,CONCRETE:0)
Block(-2,6,0,CONCRETE:0)
Block(-2,7,-7,quark:world_stone_pavement:2)
Block(-2,7,-6,CONCRETE:0)
Block(-2,7,-5,CONCRETE:0)
Block(-2,7,-4,CONCRETE:0)
Block(-2,7,-3,CONCRETE:0)
Block(-2,7,-2,CONCRETE:0)
Block(-2,7,-1,quark:world_stone_pavement:2)
Block(-2,7,0,quark:world_stone_pavement:2)
Block(-2,8,-7,quark:world_stone_pavement:2)
Block(-2,8,-6,CONCRETE:0)
Block(-2,8,-5,CONCRETE:0)
Block(-2,8,-4,quark:world_stone_pavement:2)
Block(-2,8,-3,CONCRETE:0)
Block(-2,8,-2,CONCRETE:0)
Block(-2,8,-1,quark:world_stone_pavement:2)
Block(-2,8,0,quark:world_stone_pavement:2)
Block(-2,9,-7,quark:polished_stone:0)
Block(-2,9,-6,quark:world_stone_pavement:2)
Block(-2,9,-5,CONCRETE:0)
Block(-2,9,-4,quark:polished_stone:0)
Block(-2,9,-3,quark:polished_stone:0)
Block(-2,9,-2,quark:polished_stone:0)
Block(-2,9,-1,quark:world_stone_pavement:2)
Block(-2,9,0,quark:world_stone_pavement:2)
Block(-2,10,-7,quark:polished_stone:0)
Block(-2,10,-6,quark:polished_stone:0)
Block(-2,10,-5,quark:polished_stone:0)
Block(-2,10,-4,quark:polished_stone:0)
Block(-2,10,-3,quark:polished_stone:0)
Block(-2,10,-2,quark:world_stone_pavement:2)
Block(-2,10,-1,quark:polished_stone:0)
Block(-2,10,0,quark:polished_stone:0)
Block(-2,11,-7,IRON_DOOR_BLOCK:2)
RandomBlock(-2,11,-6,CONCRETE:0,40,SMOOTH_BRICK:1,30,SMOOTH_BRICK:2,30,MOSSY_COBBLESTONE:0,30,COBBLESTONE:0,20,CONCRETE:0,100)
Block(-2,11,-5,quark:world_stone_pavement:2)
Block(-2,11,-4,quark:world_stone_pavement:2)
RandomBlock(-2,11,-3,CONCRETE:0,40,SMOOTH_BRICK:1,30,SMOOTH_BRICK:2,30,MOSSY_COBBLESTONE:0,30,COBBLESTONE:0,20,CONCRETE:0,100)
Block(-2,11,-2,quark:world_stone_pavement:2)
Block(-2,11,-1,quark:polished_stone:0)
Block(-2,11,0,quark:polished_stone:0)
Block(-2,12,-7,IRON_DOOR_BLOCK:8)
RandomBlock(-2,12,-6,CONCRETE:0,40,SMOOTH_BRICK:1,30,SMOOTH_BRICK:2,30,MOSSY_COBBLESTONE:0,30,COBBLESTONE:0,20,CONCRETE:0,100)
RandomBlock(-2,12,-5,CONCRETE:0,40,SMOOTH_BRICK:1,30,SMOOTH_BRICK:2,30,MOSSY_COBBLESTONE:0,30,COBBLESTONE:0,20,CONCRETE:0,100)
RandomBlock(-2,12,-4,CONCRETE:0,40,SMOOTH_BRICK:1,30,SMOOTH_BRICK:2,30,MOSSY_COBBLESTONE:0,30,COBBLESTONE:0,20,CONCRETE:0,100)
Block(-2,12,-3,quark:world_stone_pavement:2)
Block(-2,12,-2,quark:world_stone_pavement:2)
RandomBlock(-2,12,-1,CONCRETE:0,40,SMOOTH_BRICK:1,30,SMOOTH_BRICK:2,30,MOSSY_COBBLESTONE:0,30,COBBLESTONE:0,20,CONCRETE:0,100)
RandomBlock(-2,12,0,CONCRETE:0,40,SMOOTH_BRICK:1,30,SMOOTH_BRICK:2,30,MOSSY_COBBLESTONE:0,30,COBBLESTONE:0,20,CONCRETE:0,100)
RandomBlock(-2,13,-7,CONCRETE:0,40,SMOOTH_BRICK:1,30,SMOOTH_BRICK:2,30,MOSSY_COBBLESTONE:0,30,COBBLESTONE:0,20,CONCRETE:0,100)
RandomBlock(-2,13,-6,CONCRETE:0,40,SMOOTH_BRICK:1,30,SMOOTH_BRICK:2,30,MOSSY_COBBLESTONE:0,30,COBBLESTONE:0,20,CONCRETE:0,100)
RandomBlock(-2,13,-5,CONCRETE:0,40,SMOOTH_BRICK:1,30,SMOOTH_BRICK:2,30,MOSSY_COBBLESTONE:0,30,COBBLESTONE:0,20,CONCRETE:0,100)
RandomBlock(-2,13,-4,CONCRETE:0,40,SMOOTH_BRICK:1,30,SMOOTH_BRICK:2,30,MOSSY_COBBLESTONE:0,30,COBBLESTONE:0,20,CONCRETE:0,100)
RandomBlock(-2,13,-3,CONCRETE:0,40,SMOOTH_BRICK:1,30,SMOOTH_BRICK:2,30,MOSSY_COBBLESTONE:0,30,COBBLESTONE:0,20,CONCRETE:0,100)
RandomBlock(-2,13,-2,CONCRETE:0,40,SMOOTH_BRICK:1,30,SMOOTH_BRICK:2,30,MOSSY_COBBLESTONE:0,30,COBBLESTONE:0,20,CONCRETE:0,100)
RandomBlock(-2,13,-1,CONCRETE:0,40,SMOOTH_BRICK:1,30,SMOOTH_BRICK:2,30,MOSSY_COBBLESTONE:0,30,COBBLESTONE:0,20,CONCRETE:0,100)
RandomBlock(-2,13,0,CONCRETE:0,40,SMOOTH_BRICK:1,30,SMOOTH_BRICK:2,30,MOSSY_COBBLESTONE:0,30,COBBLESTONE:0,20,CONCRETE:0,100)
Block(-2,14,-7,STEP:0)
Block(-2,14,-6,STEP:0)
Block(-2,14,-5,STEP:0)
Block(-2,14,-4,STEP:0)
Block(-2,14,-3,STEP:0)
Block(-2,14,-2,STEP:0)
Block(-2,14,-1,STEP:0)
Block(-2,14,0,STEP:0)
RandomBlock(-2,15,-5,IRON_FENCE:0,30,IRON_FENCE:0,100)
Block(-2,16,-7,STEP:8)
Block(-2,16,-6,STEP:8)
Block(-2,16,-5,quark:iron_plate:1)
Block(-2,17,-5,quark:framed_glass:0)
Block(-2,18,-5,quark:framed_glass:0)
Block(-2,19,-7,STEP:8)
Block(-2,19,-6,STEP:8)
Block(-2,19,-5,quark:iron_plate:1)
RandomBlock(-2,20,-5,IRON_FENCE:0,30,IRON_FENCE:0,100)
Block(-1,0,-7,CONCRETE:0)
Block(-1,0,-6,CONCRETE:0)
Block(-1,0,-5,CONCRETE:0)
Block(-1,0,-4,CONCRETE:0)
Block(-1,0,-3,quark:world_stone_pavement:2)
Block(-1,0,-2,CONCRETE:0)
Block(-1,0,-1,CONCRETE:0)
Block(-1,0,0,quark:world_stone_pavement:2)
Block(-1,1,-7,CONCRETE:0)
Block(-1,1,-6,quark:world_stone_pavement:2)
Block(-1,1,-5,quark:world_stone_pavement:2)
Block(-1,1,-4,CONCRETE:0)
Block(-1,1,-3,CONCRETE:0)
Block(-1,1,-2,quark:world_stone_pavement:2)
Block(-1,1,-1,CONCRETE:0)
Block(-1,1,0,quark:world_stone_pavement:2)
Block(-1,2,-7,quark:world_stone_pavement:2)
Block(-1,2,-6,quark:world_stone_pavement:2)
Block(-1,2,-5,quark:world_stone_pavement:2)
Block(-1,2,-4,CONCRETE:0)
Block(-1,2,-3,CONCRETE:0)
Block(-1,2,-2,CONCRETE:0)
Block(-1,2,-1,CONCRETE:0)
Block(-1,2,0,CONCRETE:0)
Block(-1,3,-7,CONCRETE:0)
Block(-1,3,-6,CONCRETE:0)
Block(-1,3,-5,quark:world_stone_pavement:2)
Block(-1,3,-4,quark:world_stone_pavement:2)
Block(-1,3,-3,CONCRETE:0)
Block(-1,3,-2,CONCRETE:0)
Block(-1,3,-1,quark:world_stone_pavement:2)
Block(-1,3,0,CONCRETE:0)
Block(-1,4,-7,CONCRETE:0)
Block(-1,4,-6,CONCRETE:0)
Block(-1,4,-5,CONCRETE:0)
Block(-1,4,-4,CONCRETE:0)
Block(-1,4,-3,quark:world_stone_pavement:2)
Block(-1,4,-2,quark:world_stone_pavement:2)
Block(-1,4,-1,CONCRETE:0)
Block(-1,4,0,CONCRETE:0)
Block(-1,5,-7,quark:world_stone_pavement:2)
Block(-1,5,-6,CONCRETE:0)
Block(-1,5,-5,quark:world_stone_pavement:2)
Block(-1,5,-4,quark:world_stone_pavement:2)
Block(-1,5,-3,CONCRETE:0)
Block(-1,5,-2,CONCRETE:0)
Block(-1,5,-1,quark:world_stone_pavement:2)
Block(-1,5,0,CONCRETE:0)
Block(-1,6,-7,CONCRETE:0)
Block(-1,6,-6,quark:world_stone_pavement:2)
Block(-1,6,-5,quark:world_stone_pavement:2)
Block(-1,6,-4,quark:world_stone_pavement:2)
Block(-1,6,-3,CONCRETE:0)
Block(-1,6,-2,CONCRETE:0)
Block(-1,6,-1,CONCRETE:0)
Block(-1,6,0,CONCRETE:0)
Block(-1,7,-7,CONCRETE:0)
Block(-1,7,-6,quark:world_stone_pavement:2)
Block(-1,7,-5,CONCRETE:0)
Block(-1,7,-4,CONCRETE:0)
Block(-1,7,-3,CONCRETE:0)
Block(-1,7,-2,quark:world_stone_pavement:2)
Block(-1,7,-1,CONCRETE:0)
Block(-1,7,0,CONCRETE:0)
Block(-1,8,-7,CONCRETE:0)
Block(-1,8,-6,quark:world_stone_pavement:2)
Block(-1,8,-5,CONCRETE:0)
Block(-1,8,-4,quark:world_stone_pavement:2)
Block(-1,8,-3,CONCRETE:0)
Block(-1,8,-2,quark:world_stone_pavement:2)
Block(-1,8,-1,CONCRETE:0)
Block(-1,8,0,quark:world_stone_pavement:2)
Block(-1,9,-7,quark:polished_stone:0)
Block(-1,9,-6,quark:world_stone_pavement:2)
Block(-1,9,-5,quark:world_stone_pavement:2)
Block(-1,9,-4,quark:polished_stone:0)
Block(-1,9,-3,quark:polished_stone:0)
Block(-1,9,-2,quark:polished_stone:0)
Block(-1,9,-1,quark:polished_stone:0)
Block(-1,9,0,quark:polished_stone:0)
RandomBlock(-1,10,-7,CONCRETE:0,40,SMOOTH_BRICK:1,30,SMOOTH_BRICK:2,30,MOSSY_COBBLESTONE:0,30,COBBLESTONE:0,20,CONCRETE:0,100)
RandomBlock(-1,10,-6,CONCRETE:0,40,SMOOTH_BRICK:1,30,SMOOTH_BRICK:2,30,MOSSY_COBBLESTONE:0,30,COBBLESTONE:0,20,CONCRETE:0,100)
RandomBlock(-1,10,-5,CONCRETE:0,40,SMOOTH_BRICK:1,30,SMOOTH_BRICK:2,30,MOSSY_COBBLESTONE:0,30,COBBLESTONE:0,20,CONCRETE:0,100)
RandomBlock(-1,10,-4,CONCRETE:0,40,SMOOTH_BRICK:1,30,SMOOTH_BRICK:2,30,MOSSY_COBBLESTONE:0,30,COBBLESTONE:0,20,CONCRETE:0,100)
RandomBlock(-1,10,-3,CONCRETE:0,40,SMOOTH_BRICK:1,30,SMOOTH_BRICK:2,30,MOSSY_COBBLESTONE:0,30,COBBLESTONE:0,20,CONCRETE:0,100)
RandomBlock(-1,10,-2,CONCRETE:0,40,SMOOTH_BRICK:1,30,SMOOTH_BRICK:2,30,MOSSY_COBBLESTONE:0,30,COBBLESTONE:0,20,CONCRETE:0,100)
Block(-1,10,-1,quark:iron_plate:1)
Block(-1,10,0,quark:polished_stone:0)
RandomBlock(-1,11,-6,CONCRETE:0,40,SMOOTH_BRICK:1,30,SMOOTH_BRICK:2,30,MOSSY_COBBLESTONE:0,30,COBBLESTONE:0,20,CONCRETE:0,100)
RandomBlock(-1,11,-5,CONCRETE:0,40,SMOOTH_BRICK:1,30,SMOOTH_BRICK:2,30,MOSSY_COBBLESTONE:0,30,COBBLESTONE:0,20,CONCRETE:0,100)
RandomBlock(-1,11,-4,CONCRETE:0,40,SMOOTH_BRICK:1,30,SMOOTH_BRICK:2,30,MOSSY_COBBLESTONE:0,30,COBBLESTONE:0,20,CONCRETE:0,100)
RandomBlock(-1,11,-3,CONCRETE:0,40,SMOOTH_BRICK:1,30,SMOOTH_BRICK:2,30,MOSSY_COBBLESTONE:0,30,COBBLESTONE:0,20,CONCRETE:0,100)
RandomBlock(-1,11,-2,CONCRETE:0,40,SMOOTH_BRICK:1,30,SMOOTH_BRICK:2,30,MOSSY_COBBLESTONE:0,30,COBBLESTONE:0,20,CONCRETE:0,100)
Block(-1,11,-1,quark:iron_plate:1)
Block(-1,11,0,quark:world_stone_pavement:2)
RandomBlock(-1,12,-6,CONCRETE:0,40,SMOOTH_BRICK:1,30,SMOOTH_BRICK:2,30,MOSSY_COBBLESTONE:0,30,COBBLESTONE:0,20,CONCRETE:0,100)
RandomBlock(-1,12,-5,CONCRETE:0,40,SMOOTH_BRICK:1,30,SMOOTH_BRICK:2,30,MOSSY_COBBLESTONE:0,30,COBBLESTONE:0,20,CONCRETE:0,100)
RandomBlock(-1,12,-4,CONCRETE:0,40,SMOOTH_BRICK:1,30,SMOOTH_BRICK:2,30,MOSSY_COBBLESTONE:0,30,COBBLESTONE:0,20,CONCRETE:0,100)
RandomBlock(-1,12,-3,CONCRETE:0,40,SMOOTH_BRICK:1,30,SMOOTH_BRICK:2,30,MOSSY_COBBLESTONE:0,30,COBBLESTONE:0,20,CONCRETE:0,100)
RandomBlock(-1,12,-2,CONCRETE:0,40,SMOOTH_BRICK:1,30,SMOOTH_BRICK:2,30,MOSSY_COBBLESTONE:0,30,COBBLESTONE:0,20,CONCRETE:0,100)
Block(-1,12,-1,quark:iron_plate:1)
RandomBlock(-1,12,0,CONCRETE:0,40,SMOOTH_BRICK:1,30,SMOOTH_BRICK:2,30,MOSSY_COBBLESTONE:0,30,COBBLESTONE:0,20,CONCRETE:0,100)
RandomBlock(-1,13,-7,CONCRETE:0,40,SMOOTH_BRICK:1,30,SMOOTH_BRICK:2,30,MOSSY_COBBLESTONE:0,30,COBBLESTONE:0,20,CONCRETE:0,100)
RandomBlock(-1,13,-6,CONCRETE:0,40,SMOOTH_BRICK:1,30,SMOOTH_BRICK:2,30,MOSSY_COBBLESTONE:0,30,COBBLESTONE:0,20,CONCRETE:0,100)
RandomBlock(-1,13,-5,CONCRETE:0,40,SMOOTH_BRICK:1,30,SMOOTH_BRICK:2,30,MOSSY_COBBLESTONE:0,30,COBBLESTONE:0,20,CONCRETE:0,100)
RandomBlock(-1,13,-4,CONCRETE:0,40,SMOOTH_BRICK:1,30,SMOOTH_BRICK:2,30,MOSSY_COBBLESTONE:0,30,COBBLESTONE:0,20,CONCRETE:0,100)
RandomBlock(-1,13,-3,CONCRETE:0,40,SMOOTH_BRICK:1,30,SMOOTH_BRICK:2,30,MOSSY_COBBLESTONE:0,30,COBBLESTONE:0,20,CONCRETE:0,100)
RandomBlock(-1,13,-2,CONCRETE:0,40,SMOOTH_BRICK:1,30,SMOOTH_BRICK:2,30,MOSSY_COBBLESTONE:0,30,COBBLESTONE:0,20,CONCRETE:0,100)
Block(-1,13,-1,quark:iron_plate:1)
RandomBlock(-1,13,0,CONCRETE:0,40,SMOOTH_BRICK:1,30,SMOOTH_BRICK:2,30,MOSSY_COBBLESTONE:0,30,COBBLESTONE:0,20,CONCRETE:0,100)
RandomBlock(-1,14,-7,CONCRETE:0,40,SMOOTH_BRICK:1,30,SMOOTH_BRICK:2,30,MOSSY_COBBLESTONE:0,30,COBBLESTONE:0,20,CONCRETE:0,100)
RandomBlock(-1,14,-6,CONCRETE:0,40,SMOOTH_BRICK:1,30,SMOOTH_BRICK:2,30,MOSSY_COBBLESTONE:0,30,COBBLESTONE:0,20,CONCRETE:0,100)
RandomBlock(-1,14,-5,CONCRETE:0,40,SMOOTH_BRICK:1,30,SMOOTH_BRICK:2,30,MOSSY_COBBLESTONE:0,30,COBBLESTONE:0,20,CONCRETE:0,100)
RandomBlock(-1,14,-4,CONCRETE:0,40,SMOOTH_BRICK:1,30,SMOOTH_BRICK:2,30,MOSSY_COBBLESTONE:0,30,COBBLESTONE:0,20,CONCRETE:0,100)
RandomBlock(-1,14,-3,CONCRETE:0,40,SMOOTH_BRICK:1,30,SMOOTH_BRICK:2,30,MOSSY_COBBLESTONE:0,30,COBBLESTONE:0,20,CONCRETE:0,100)
RandomBlock(-1,14,-2,CONCRETE:0,40,SMOOTH_BRICK:1,30,SMOOTH_BRICK:2,30,MOSSY_COBBLESTONE:0,30,COBBLESTONE:0,20,CONCRETE:0,100)
Block(-1,14,-1,quark:iron_plate:1)
Block(-1,14,0,STEP:0)
RandomBlock(-1,15,-7,CONCRETE:0,40,SMOOTH_BRICK:1,30,SMOOTH_BRICK:2,30,MOSSY_COBBLESTONE:0,30,COBBLESTONE:0,20,CONCRETE:0,100)
RandomBlock(-1,15,-6,CONCRETE:0,40,SMOOTH_BRICK:1,30,SMOOTH_BRICK:2,30,MOSSY_COBBLESTONE:0,30,COBBLESTONE:0,20,CONCRETE:0,100)
RandomBlock(-1,15,-5,CONCRETE:0,40,SMOOTH_BRICK:1,30,SMOOTH_BRICK:2,30,MOSSY_COBBLESTONE:0,30,COBBLESTONE:0,20,CONCRETE:0,100)
RandomBlock(-1,15,-4,CONCRETE:0,40,SMOOTH_BRICK:1,30,SMOOTH_BRICK:2,30,MOSSY_COBBLESTONE:0,30,COBBLESTONE:0,20,CONCRETE:0,100)
RandomBlock(-1,15,-3,CONCRETE:0,40,SMOOTH_BRICK:1,30,SMOOTH_BRICK:2,30,MOSSY_COBBLESTONE:0,30,COBBLESTONE:0,20,CONCRETE:0,100)
RandomBlock(-1,15,-2,CONCRETE:0,40,SMOOTH_BRICK:1,30,SMOOTH_BRICK:2,30,MOSSY_COBBLESTONE:0,30,COBBLESTONE:0,20,CONCRETE:0,100)
Block(-1,15,-1,quark:iron_plate:1)
Block(-1,16,-7,quark:iron_plate:1)
Block(-1,16,-6,quark:iron_plate:1)
Block(-1,16,-5,quark:iron_plate:1)
Block(-1,16,-4,quark:iron_plate:1)
Block(-1,16,-3,quark:iron_plate:1)
Block(-1,16,-2,quark:iron_plate:1)
Block(-1,16,-1,quark:iron_plate:1)
Block(-1,17,-5,SMOOTH_STAIRS:3)
Block(-1,17,-4,DOUBLE_STEP:0)
Block(-1,17,-3,STEP:0)
Block(-1,17,-2,STEP:0)
Block(-1,17,-1,STEP:0)
Block(-1,18,-5,SMOOTH_STAIRS:7)
RandomBlock(-1,18,-4,IRON_FENCE:0,30,IRON_FENCE:0,100)
Block(-1,19,-7,STEP:8)
Block(-1,19,-6,STEP:8)
Block(-1,19,-5,quark:iron_plate:1)
RandomBlock(-1,19,-4,IRON_FENCE:0,30,IRON_FENCE:0,100)
RandomBlock(-1,20,-5,IRON_FENCE:0,30,IRON_FENCE:0,100)
RandomBlock(-1,20,-4,IRON_FENCE:0,30,IRON_FENCE:0,100)
Block(0,0,-7,CONCRETE:0)
Block(0,0,-6,CONCRETE:0)
Block(0,0,-5,quark:world_stone_pavement:2)
Block(0,0,-4,quark:world_stone_pavement:2)
Block(0,0,-3,quark:world_stone_pavement:2)
Block(0,0,-2,CONCRETE:0)
Block(0,0,-1,CONCRETE:0)
Block(0,0,0,CONCRETE:0)
Block(0,1,-7,CONCRETE:0)
Block(0,1,-6,CONCRETE:0)
Block(0,1,-5,quark:world_stone_pavement:2)
Block(0,1,-4,quark:world_stone_pavement:2)
Block(0,1,-3,quark:world_stone_pavement:2)
Block(0,1,-2,CONCRETE:0)
Block(0,1,-1,quark:world_stone_pavement:2)
Block(0,1,0,CONCRETE:0)
Block(0,2,-7,CONCRETE:0)
Block(0,2,-6,CONCRETE:0)
Block(0,2,-5,CONCRETE:0)
Block(0,2,-4,CONCRETE:0)
Block(0,2,-3,quark:world_stone_pavement:2)
Block(0,2,-2,quark:world_stone_pavement:2)
Block(0,2,-1,CONCRETE:0)
Block(0,2,0,CONCRETE:0)
Block(0,3,-7,quark:world_stone_pavement:2)
Block(0,3,-6,CONCRETE:0)
Block(0,3,-5,quark:world_stone_pavement:2)
Block(0,3,-4,quark:world_stone_pavement:2)
Block(0,3,-3,CONCRETE:0)
Block(0,3,-2,quark:world_stone_pavement:2)
Block(0,3,-1,quark:world_stone_pavement:2)
Block(0,3,0,CONCRETE:0)
Block(0,4,-7,CONCRETE:0)
Block(0,4,-6,CONCRETE:0)
Block(0,4,-5,CONCRETE:0)
Block(0,4,-4,quark:world_stone_pavement:2)
Block(0,4,-3,CONCRETE:0)
Block(0,4,-2,quark:world_stone_pavement:2)
Block(0,4,-1,quark:world_stone_pavement:2)
Block(0,4,0,CONCRETE:0)
Block(0,5,-7,CONCRETE:0)
Block(0,5,-6,CONCRETE:0)
Block(0,5,-5,quark:world_stone_pavement:2)
Block(0,5,-4,quark:world_stone_pavement:2)
Block(0,5,-3,CONCRETE:0)
Block(0,5,-2,CONCRETE:0)
Block(0,5,-1,quark:world_stone_pavement:2)
Block(0,5,0,CONCRETE:0)
Block(0,6,-7,CONCRETE:0)
Block(0,6,-6,CONCRETE:0)
Block(0,6,-5,quark:world_stone_pavement:2)
Block(0,6,-4,CONCRETE:0)
Block(0,6,-3,quark:world_stone_pavement:2)
Block(0,6,-2,CONCRETE:0)
Block(0,6,-1,CONCRETE:0)
Block(0,6,0,quark:world_stone_pavement:2)
Block(0,7,-7,CONCRETE:0)
Block(0,7,-6,CONCRETE:0)
Block(0,7,-5,CONCRETE:0)
Block(0,7,-4,quark:world_stone_pavement:2)
Block(0,7,-3,CONCRETE:0)
Block(0,7,-2,CONCRETE:0)
Block(0,7,-1,CONCRETE:0)
Block(0,7,0,CONCRETE:0)
Block(0,8,-7,quark:polished_stone:0)
Block(0,8,-6,CONCRETE:0)
Block(0,8,-5,CONCRETE:0)
Block(0,8,-4,CONCRETE:0)
Block(0,8,-3,CONCRETE:0)
Block(0,8,-2,CONCRETE:0)
Block(0,8,-1,CONCRETE:0)
Block(0,8,0,quark:world_stone_pavement:2)
Block(0,9,-7,quark:polished_stone:0)
Block(0,9,-6,quark:polished_stone:0)
Block(0,9,-5,quark:polished_stone:0)
Block(0,9,-4,quark:polished_stone:0)
Block(0,9,-3,quark:polished_stone:0)
Block(0,9,-2,quark:polished_stone:0)
Block(0,9,-1,quark:polished_stone:0)
Block(0,9,0,quark:world_stone_pavement:2)
Block(0,10,-7,quark:world_stone_pavement:2)
Block(0,10,-6,quark:polished_stone:0)
Block(0,10,-5,quark:polished_stone:0)
Block(0,10,-4,quark:polished_stone:0)
Block(0,10,-3,quark:polished_stone:0)
Block(0,10,-2,quark:polished_stone:0)
RandomBlock(0,10,-1,CONCRETE:0,40,SMOOTH_BRICK:1,30,SMOOTH_BRICK:2,30,MOSSY_COBBLESTONE:0,30,COBBLESTONE:0,20,CONCRETE:0,100)
Block(0,10,0,quark:world_stone_pavement:2)
Block(0,11,-5,quark:iron_plate_stairs:2)
Block(0,11,-4,STEP:8)
Block(0,11,-3,STEP:8)
RandomBlock(0,11,-2,CONCRETE:0,40,SMOOTH_BRICK:1,30,SMOOTH_BRICK:2,30,MOSSY_COBBLESTONE:0,30,COBBLESTONE:0,20,CONCRETE:0,100)
RandomBlock(0,11,-1,CONCRETE:0,40,SMOOTH_BRICK:1,30,SMOOTH_BRICK:2,30,MOSSY_COBBLESTONE:0,30,COBBLESTONE:0,20,CONCRETE:0,100)
RandomBlock(0,11,0,CONCRETE:0,40,SMOOTH_BRICK:1,30,SMOOTH_BRICK:2,30,MOSSY_COBBLESTONE:0,30,COBBLESTONE:0,20,CONCRETE:0,100)
RandomBlock(0,12,-2,CONCRETE:0,40,SMOOTH_BRICK:1,30,SMOOTH_BRICK:2,30,MOSSY_COBBLESTONE:0,30,COBBLESTONE:0,20,CONCRETE:0,100)
RandomBlock(0,12,-1,CONCRETE:0,40,SMOOTH_BRICK:1,30,SMOOTH_BRICK:2,30,MOSSY_COBBLESTONE:0,30,COBBLESTONE:0,20,CONCRETE:0,100)
RandomBlock(0,12,0,CONCRETE:0,40,SMOOTH_BRICK:1,30,SMOOTH_BRICK:2,30,MOSSY_COBBLESTONE:0,30,COBBLESTONE:0,20,CONCRETE:0,100)
RandomBlock(0,13,-2,CONCRETE:0,40,SMOOTH_BRICK:1,30,SMOOTH_BRICK:2,30,MOSSY_COBBLESTONE:0,30,COBBLESTONE:0,20,CONCRETE:0,100)
RandomBlock(0,13,-1,CONCRETE:0,40,SMOOTH_BRICK:1,30,SMOOTH_BRICK:2,30,MOSSY_COBBLESTONE:0,30,COBBLESTONE:0,20,CONCRETE:0,100)
RandomBlock(0,13,0,CONCRETE:0,40,SMOOTH_BRICK:1,30,SMOOTH_BRICK:2,30,MOSSY_COBBLESTONE:0,30,COBBLESTONE:0,20,CONCRETE:0,100)
RandomBlock(0,14,-5,IRON_FENCE:0,30,IRON_FENCE:0,100)
RandomBlock(0,14,-2,CONCRETE:0,40,SMOOTH_BRICK:1,30,SMOOTH_BRICK:2,30,MOSSY_COBBLESTONE:0,30,COBBLESTONE:0,20,CONCRETE:0,100)
RandomBlock(0,14,-1,CONCRETE:0,40,SMOOTH_BRICK:1,30,SMOOTH_BRICK:2,30,MOSSY_COBBLESTONE:0,30,COBBLESTONE:0,20,CONCRETE:0,100)
Block(0,14,0,STEP:0)
Block(0,15,-7,quark:iron_plate_stairs:4)
Block(0,15,-6,quark:iron_plate_stairs:4)
RandomBlock(0,15,-5,IRON_FENCE:0,30,IRON_FENCE:0,100)
RandomBlock(0,15,-2,CONCRETE:0,40,SMOOTH_BRICK:1,30,SMOOTH_BRICK:2,30,MOSSY_COBBLESTONE:0,30,COBBLESTONE:0,20,CONCRETE:0,100)
RandomBlock(0,15,-1,CONCRETE:0,40,SMOOTH_BRICK:1,30,SMOOTH_BRICK:2,30,MOSSY_COBBLESTONE:0,30,COBBLESTONE:0,20,CONCRETE:0,100)
Block(0,16,-7,quark:iron_plate_stairs:1)
Block(0,16,-6,quark:iron_plate_stairs:1)
Block(0,16,-5,quark:iron_plate:1)
Block(0,16,-2,quark:iron_plate:1)
Block(0,16,-1,quark:iron_plate:1)
Block(0,17,-5,quark:framed_glass:0)
Block(0,17,-4,STEP:0)
Block(0,17,-3,STEP:0)
Block(0,17,-2,STEP:0)
Block(0,17,-1,STEP:0)
Block(0,18,-5,quark:framed_glass:0)
Block(0,19,-7,STEP:8)
Block(0,19,-6,STEP:8)
Block(0,19,-5,quark:iron_plate:1)
RandomBlock(0,20,-5,IRON_FENCE:0,30,IRON_FENCE:0,100)
Block(1,0,-7,CONCRETE:0)
Block(1,0,-6,CONCRETE:0)
Block(1,0,-5,CONCRETE:0)
Block(1,0,-4,CONCRETE:0)
Block(1,0,-3,quark:world_stone_pavement:2)
Block(1,0,-2,quark:world_stone_pavement:2)
Block(1,0,-1,quark:world_stone_pavement:2)
Block(1,0,0,CONCRETE:0)
Block(1,0,1,quark:iron_plate:1)
Block(1,0,3,quark:iron_plate:1)
Block(1,0,5,quark:iron_plate:1)
Block(1,0,7,quark:iron_plate:1)
Block(1,1,-7,CONCRETE:0)
Block(1,1,-6,CONCRETE:0)
Block(1,1,-5,quark:world_stone_pavement:2)
Block(1,1,-4,CONCRETE:0)
Block(1,1,-3,CONCRETE:0)
Block(1,1,-2,quark:world_stone_pavement:2)
Block(1,1,-1,CONCRETE:0)
Block(1,1,0,CONCRETE:0)
Block(1,1,1,quark:iron_plate:1)
Block(1,1,3,quark:iron_plate:1)
Block(1,1,5,quark:iron_plate:1)
Block(1,1,7,quark:iron_plate:1)
Block(1,2,-7,CONCRETE:0)
Block(1,2,-6,CONCRETE:0)
Block(1,2,-5,CONCRETE:0)
Block(1,2,-4,CONCRETE:0)
Block(1,2,-3,CONCRETE:0)
Block(1,2,-2,quark:world_stone_pavement:2)
Block(1,2,-1,quark:world_stone_pavement:2)
Block(1,2,0,CONCRETE:0)
Block(1,2,1,quark:iron_plate:1)
Block(1,2,3,quark:iron_plate:1)
Block(1,2,5,quark:iron_plate:1)
Block(1,2,7,quark:iron_plate:1)
Block(1,3,-7,CONCRETE:0)
Block(1,3,-6,CONCRETE:0)
Block(1,3,-5,CONCRETE:0)
Block(1,3,-4,quark:world_stone_pavement:2)
Block(1,3,-3,quark:world_stone_pavement:2)
Block(1,3,-2,CONCRETE:0)
Block(1,3,-1,quark:world_stone_pavement:2)
Block(1,3,0,quark:world_stone_pavement:2)
Block(1,3,1,quark:iron_plate:1)
Block(1,3,3,quark:iron_plate:1)
Block(1,3,5,quark:iron_plate:1)
Block(1,3,7,quark:iron_plate:1)
Block(1,4,-7,CONCRETE:0)
Block(1,4,-6,quark:world_stone_pavement:2)
Block(1,4,-5,CONCRETE:0)
Block(1,4,-4,CONCRETE:0)
Block(1,4,-3,CONCRETE:0)
Block(1,4,-2,CONCRETE:0)
Block(1,4,-1,quark:world_stone_pavement:2)
Block(1,4,0,CONCRETE:0)
Block(1,4,1,quark:iron_plate:1)
Block(1,4,3,quark:iron_plate:1)
Block(1,4,5,quark:iron_plate:1)
Block(1,4,7,quark:iron_plate:1)
Block(1,5,-7,quark:world_stone_pavement:2)
Block(1,5,-6,quark:world_stone_pavement:2)
Block(1,5,-5,CONCRETE:0)
Block(1,5,-4,quark:world_stone_pavement:2)
Block(1,5,-3,CONCRETE:0)
Block(1,5,-2,quark:world_stone_pavement:2)
Block(1,5,-1,quark:world_stone_pavement:2)
Block(1,5,0,quark:world_stone_pavement:2)
Block(1,5,1,quark:iron_plate:1)
Block(1,5,3,quark:iron_plate:1)
Block(1,5,5,quark:iron_plate:1)
Block(1,5,7,quark:iron_plate:1)
Block(1,6,-7,CONCRETE:0)
Block(1,6,-6,CONCRETE:0)
Block(1,6,-5,CONCRETE:0)
Block(1,6,-4,CONCRETE:0)
Block(1,6,-3,CONCRETE:0)
Block(1,6,-2,quark:world_stone_pavement:2)
Block(1,6,-1,CONCRETE:0)
Block(1,6,0,CONCRETE:0)
Block(1,6,1,quark:iron_plate:1)
Block(1,6,3,quark:iron_plate:1)
Block(1,6,5,quark:iron_plate:1)
Block(1,6,7,quark:iron_plate:1)
Block(1,7,-7,CONCRETE:0)
Block(1,7,-6,CONCRETE:0)
Block(1,7,-5,CONCRETE:0)
Block(1,7,-4,quark:world_stone_pavement:2)
Block(1,7,-3,CONCRETE:0)
Block(1,7,-2,CONCRETE:0)
Block(1,7,-1,quark:world_stone_pavement:2)
Block(1,7,0,CONCRETE:0)
Block(1,7,1,quark:iron_plate:1)
Block(1,7,3,quark:iron_plate:1)
Block(1,7,5,quark:iron_plate:1)
Block(1,7,7,quark:iron_plate:1)
Block(1,8,-7,quark:polished_stone:0)
Block(1,8,-6,quark:polished_stone:0)
Block(1,8,-5,CONCRETE:0)
Block(1,8,-4,CONCRETE:0)
Block(1,8,-3,CONCRETE:0)
Block(1,8,-2,CONCRETE:0)
Block(1,8,-1,quark:world_stone_pavement:2)
Block(1,8,0,CONCRETE:0)
Block(1,8,1,quark:iron_plate:1)
Block(1,8,3,quark:iron_plate:1)
Block(1,8,5,quark:iron_plate:1)
Block(1,8,7,quark:iron_plate:1)
Block(1,9,-7,quark:polished_stone:0)
Block(1,9,-6,quark:world_stone_pavement:2)
Block(1,9,-5,quark:world_stone_pavement:2)
Block(1,9,-4,quark:polished_stone:0)
Block(1,9,-3,quark:polished_stone:0)
Block(1,9,-2,quark:world_stone_pavement:2)
Block(1,9,-1,quark:polished_stone:0)
Block(1,9,0,quark:polished_stone:0)
Block(1,9,1,quark:iron_plate:1)
Block(1,9,3,quark:iron_plate:1)
Block(1,9,5,quark:iron_plate:1)
Block(1,9,7,quark:iron_plate:1)
Block(1,10,-7,quark:world_stone_pavement:2)
Block(1,10,-6,quark:world_stone_pavement:2)
Block(1,10,-5,quark:polished_stone:0)
Block(1,10,-4,quark:polished_stone:0)
Block(1,10,-3,quark:polished_stone:0)
Block(1,10,-2,quark:polished_stone:0)
RandomBlock(1,10,-1,CONCRETE:0,40,SMOOTH_BRICK:1,30,SMOOTH_BRICK:2,30,MOSSY_COBBLESTONE:0,30,COBBLESTONE:0,20,CONCRETE:0,100)
Block(1,10,0,quark:polished_stone:0)
Block(1,10,1,quark:iron_plate:1)
Block(1,10,3,quark:iron_plate:1)
Block(1,10,5,quark:iron_plate:1)
Block(1,10,7,quark:iron_plate:1)
Block(1,11,-5,quark:iron_plate_stairs:2)
Block(1,11,-4,STEP:8)
Block(1,11,-3,STEP:8)
Block(1,11,-2,DOUBLE_STEP:0)
RandomBlock(1,11,-1,CONCRETE:0,40,SMOOTH_BRICK:1,30,SMOOTH_BRICK:2,30,MOSSY_COBBLESTONE:0,30,COBBLESTONE:0,20,CONCRETE:0,100)
Block(1,11,0,quark:polished_stone:0)
Block(1,11,1,CONCRETE:0)
Block(1,11,3,quark:world_stone_pavement:2)
Block(1,11,5,quark:world_stone_pavement:2)
Block(1,11,7,CONCRETE:0)
Block(1,12,-2,DOUBLE_STEP:0)
RandomBlock(1,12,-1,CONCRETE:0,40,SMOOTH_BRICK:1,30,SMOOTH_BRICK:2,30,MOSSY_COBBLESTONE:0,30,COBBLESTONE:0,20,CONCRETE:0,100)
RandomBlock(1,12,0,CONCRETE:0,40,SMOOTH_BRICK:1,30,SMOOTH_BRICK:2,30,MOSSY_COBBLESTONE:0,30,COBBLESTONE:0,20,CONCRETE:0,100)
Block(1,12,1,quark:world_stone_pavement:2)
Block(1,12,3,quark:world_stone_pavement:2)
Block(1,12,5,CONCRETE:0)
Block(1,12,7,quark:world_stone_pavement:2)
Block(1,13,-2,DOUBLE_STEP:0)
RandomBlock(1,13,-1,CONCRETE:0,40,SMOOTH_BRICK:1,30,SMOOTH_BRICK:2,30,MOSSY_COBBLESTONE:0,30,COBBLESTONE:0,20,CONCRETE:0,100)
RandomBlock(1,13,0,CONCRETE:0,40,SMOOTH_BRICK:1,30,SMOOTH_BRICK:2,30,MOSSY_COBBLESTONE:0,30,COBBLESTONE:0,20,CONCRETE:0,100)
Block(1,13,1,quark:iron_plate:1)
Block(1,13,3,quark:iron_plate:1)
Block(1,13,5,quark:iron_plate:1)
Block(1,13,7,quark:iron_plate:1)
Block(1,14,-7,quark:iron_plate_stairs:4)
Block(1,14,-6,quark:iron_plate_stairs:4)
RandomBlock(1,14,-5,IRON_FENCE:0,30,IRON_FENCE:0,100)
Block(1,14,-2,DOUBLE_STEP:0)
RandomBlock(1,14,-1,CONCRETE:0,40,SMOOTH_BRICK:1,30,SMOOTH_BRICK:2,30,MOSSY_COBBLESTONE:0,30,COBBLESTONE:0,20,CONCRETE:0,100)
Block(1,14,0,STEP:0)
Block(1,14,1,quark:iron_plate:1)
Block(1,14,3,quark:iron_plate:1)
Block(1,14,5,quark:iron_plate:1)
Block(1,14,7,quark:iron_plate:1)
Block(1,15,-7,quark:iron_plate_stairs:1)
Block(1,15,-6,quark:iron_plate_stairs:1)
RandomBlock(1,15,-5,IRON_FENCE:0,30,IRON_FENCE:0,100)
Block(1,15,-2,DOUBLE_STEP:0)
RandomBlock(1,15,-1,CONCRETE:0,40,SMOOTH_BRICK:1,30,SMOOTH_BRICK:2,30,MOSSY_COBBLESTONE:0,30,COBBLESTONE:0,20,CONCRETE:0,100)
Block(1,15,1,quark:iron_plate_stairs:0)
Block(1,15,3,quark:iron_plate_stairs:0)
Block(1,15,5,quark:iron_plate_stairs:0)
Block(1,15,7,quark:iron_plate_stairs:0)
Block(1,16,-5,quark:iron_plate:1)
Block(1,16,-2,quark:iron_plate:1)
Block(1,16,-1,quark:iron_plate:1)
Block(1,17,-5,quark:framed_glass:0)
Block(1,17,-4,STEP:0)
Block(1,17,-3,STEP:0)
Block(1,17,-2,STEP:0)
Block(1,17,-1,STEP:0)
Block(1,18,-5,quark:framed_glass:0)
Block(1,19,-7,STEP:8)
Block(1,19,-6,STEP:8)
Block(1,19,-5,quark:iron_plate:1)
RandomBlock(1,20,-5,IRON_FENCE:0,30,IRON_FENCE:0,100)
Block(2,0,-7,CONCRETE:0)
Block(2,0,-6,CONCRETE:0)
Block(2,0,-5,CONCRETE:0)
Block(2,0,-4,CONCRETE:0)
Block(2,0,-3,quark:world_stone_pavement:2)
Block(2,0,-2,CONCRETE:0)
Block(2,0,-1,CONCRETE:0)
Block(2,0,0,CONCRETE:0)
Block(2,1,-7,CONCRETE:0)
Block(2,1,-6,CONCRETE:0)
Block(2,1,-5,CONCRETE:0)
Block(2,1,-4,quark:world_stone_pavement:2)
Block(2,1,-3,CONCRETE:0)
Block(2,1,-2,quark:world_stone_pavement:2)
Block(2,1,-1,CONCRETE:0)
Block(2,1,0,quark:world_stone_pavement:2)
Block(2,2,-7,CONCRETE:0)
Block(2,2,-6,quark:world_stone_pavement:2)
Block(2,2,-5,CONCRETE:0)
Block(2,2,-4,CONCRETE:0)
Block(2,2,-3,CONCRETE:0)
Block(2,2,-2,CONCRETE:0)
Block(2,2,-1,CONCRETE:0)
Block(2,2,0,CONCRETE:0)
Block(2,3,-7,CONCRETE:0)
Block(2,3,-6,CONCRETE:0)
Block(2,3,-5,quark:world_stone_pavement:2)
Block(2,3,-4,quark:world_stone_pavement:2)
Block(2,3,-3,CONCRETE:0)
Block(2,3,-2,CONCRETE:0)
Block(2,3,-1,CONCRETE:0)
Block(2,3,0,CONCRETE:0)
Block(2,4,-7,CONCRETE:0)
Block(2,4,-6,quark:world_stone_pavement:2)
Block(2,4,-5,CONCRETE:0)
Block(2,4,-4,CONCRETE:0)
Block(2,4,-3,quark:world_stone_pavement:2)
Block(2,4,-2,CONCRETE:0)
Block(2,4,-1,CONCRETE:0)
Block(2,4,0,CONCRETE:0)
Block(2,5,-7,CONCRETE:0)
Block(2,5,-6,CONCRETE:0)
Block(2,5,-5,CONCRETE:0)
Block(2,5,-4,quark:world_stone_pavement:2)
Block(2,5,-3,quark:world_stone_pavement:2)
Block(2,5,-2,CONCRETE:0)
Block(2,5,-1,quark:world_stone_pavement:2)
Block(2,5,0,CONCRETE:0)
Block(2,6,-7,quark:world_stone_pavement:2)
Block(2,6,-6,CONCRETE:0)
Block(2,6,-5,CONCRETE:0)
Block(2,6,-4,CONCRETE:0)
Block(2,6,-3,CONCRETE:0)
Block(2,6,-2,quark:world_stone_pavement:2)
Block(2,6,-1,quark:world_stone_pavement:2)
Block(2,6,0,CONCRETE:0)
Block(2,7,-7,CONCRETE:0)
Block(2,7,-6,CONCRETE:0)
Block(2,7,-5,quark:world_stone_pavement:2)
Block(2,7,-4,quark:world_stone_pavement:2)
Block(2,7,-3,CONCRETE:0)
Block(2,7,-2,CONCRETE:0)
Block(2,7,-1,CONCRETE:0)
Block(2,7,0,CONCRETE:0)
Block(2,8,-7,quark:polished_stone:0)
Block(2,8,-6,quark:world_stone_pavement:2)
Block(2,8,-5,CONCRETE:0)
Block(2,8,-4,quark:world_stone_pavement:2)
Block(2,8,-3,CONCRETE:0)
Block(2,8,-2,CONCRETE:0)
Block(2,8,-1,quark:world_stone_pavement:2)
Block(2,8,0,quark:world_stone_pavement:2)
Block(2,9,-7,quark:polished_stone:0)
Block(2,9,-6,quark:world_stone_pavement:2)
Block(2,9,-5,quark:polished_stone:0)
Block(2,9,-4,quark:world_stone_pavement:2)
Block(2,9,-3,quark:polished_stone:0)
Block(2,9,-2,quark:world_stone_pavement:2)
Block(2,9,-1,quark:polished_stone:0)
Block(2,9,0,quark:polished_stone:0)
Block(2,10,-7,quark:world_stone_pavement:2)
Block(2,10,-6,quark:world_stone_pavement:2)
Block(2,10,-5,quark:world_stone_pavement:2)
Block(2,10,-4,quark:polished_stone:0)
Block(2,10,-3,quark:polished_stone:0)
Block(2,10,-2,quark:world_stone_pavement:2)
RandomBlock(2,10,-1,CONCRETE:0,40,SMOOTH_BRICK:1,30,SMOOTH_BRICK:2,30,MOSSY_COBBLESTONE:0,30,COBBLESTONE:0,20,CONCRETE:0,100)
Block(2,10,0,quark:polished_stone:0)
Block(2,11,-5,quark:iron_plate:1)
RandomBlock(2,11,-2,CONCRETE:0,40,SMOOTH_BRICK:1,30,SMOOTH_BRICK:2,30,MOSSY_COBBLESTONE:0,30,COBBLESTONE:0,20,CONCRETE:0,100)
RandomBlock(2,11,-1,CONCRETE:0,40,SMOOTH_BRICK:1,30,SMOOTH_BRICK:2,30,MOSSY_COBBLESTONE:0,30,COBBLESTONE:0,20,CONCRETE:0,100)
Block(2,11,0,quark:world_stone_pavement:2)
Block(2,12,-5,quark:iron_plate:1)
Block(2,12,-4,quark:iron_plate_stairs:0)
Block(2,12,-3,quark:iron_plate_stairs:0)
RandomBlock(2,12,-2,CONCRETE:0,40,SMOOTH_BRICK:1,30,SMOOTH_BRICK:2,30,MOSSY_COBBLESTONE:0,30,COBBLESTONE:0,20,CONCRETE:0,100)
RandomBlock(2,12,-1,CONCRETE:0,40,SMOOTH_BRICK:1,30,SMOOTH_BRICK:2,30,MOSSY_COBBLESTONE:0,30,COBBLESTONE:0,20,CONCRETE:0,100)
RandomBlock(2,12,0,CONCRETE:0,40,SMOOTH_BRICK:1,30,SMOOTH_BRICK:2,30,MOSSY_COBBLESTONE:0,30,COBBLESTONE:0,20,CONCRETE:0,100)
Block(2,13,-7,STEP:8)
Block(2,13,-6,STEP:8)
Block(2,13,-5,quark:iron_plate:1)
RandomBlock(2,13,-2,CONCRETE:0,40,SMOOTH_BRICK:1,30,SMOOTH_BRICK:2,30,MOSSY_COBBLESTONE:0,30,COBBLESTONE:0,20,CONCRETE:0,100)
RandomBlock(2,13,-1,CONCRETE:0,40,SMOOTH_BRICK:1,30,SMOOTH_BRICK:2,30,MOSSY_COBBLESTONE:0,30,COBBLESTONE:0,20,CONCRETE:0,100)
RandomBlock(2,13,0,CONCRETE:0,40,SMOOTH_BRICK:1,30,SMOOTH_BRICK:2,30,MOSSY_COBBLESTONE:0,30,COBBLESTONE:0,20,CONCRETE:0,100)
Block(2,14,-7,quark:iron_plate_stairs:1)
Block(2,14,-6,quark:iron_plate_stairs:1)
Block(2,14,-5,quark:iron_plate:1)
RandomBlock(2,14,-2,CONCRETE:0,40,SMOOTH_BRICK:1,30,SMOOTH_BRICK:2,30,MOSSY_COBBLESTONE:0,30,COBBLESTONE:0,20,CONCRETE:0,100)
RandomBlock(2,14,-1,CONCRETE:0,40,SMOOTH_BRICK:1,30,SMOOTH_BRICK:2,30,MOSSY_COBBLESTONE:0,30,COBBLESTONE:0,20,CONCRETE:0,100)
Block(2,14,0,STEP:0)
Block(2,15,-5,quark:iron_plate:1)
RandomBlock(2,15,-2,CONCRETE:0,40,SMOOTH_BRICK:1,30,SMOOTH_BRICK:2,30,MOSSY_COBBLESTONE:0,30,COBBLESTONE:0,20,CONCRETE:0,100)
RandomBlock(2,15,-1,CONCRETE:0,40,SMOOTH_BRICK:1,30,SMOOTH_BRICK:2,30,MOSSY_COBBLESTONE:0,30,COBBLESTONE:0,20,CONCRETE:0,100)
Block(2,15,1,quark:iron_plate:1)
Block(2,15,3,quark:iron_plate:1)
Block(2,15,5,quark:iron_plate:1)
Block(2,15,7,quark:iron_plate:1)
Block(2,16,-5,quark:iron_plate:1)
Block(2,16,-2,quark:iron_plate:1)
Block(2,16,-1,quark:iron_plate:1)
Block(2,17,-5,quark:framed_glass:0)
Block(2,17,-4,STEP:0)
Block(2,17,-3,STEP:0)
Block(2,17,-2,STEP:0)
Block(2,17,-1,STEP:0)
Block(2,18,-5,quark:framed_glass:0)
Block(2,19,-7,STEP:8)
Block(2,19,-6,STEP:8)
Block(2,19,-5,quark:iron_plate:1)
RandomBlock(2,20,-5,IRON_FENCE:0,30,IRON_FENCE:0,100)
Block(3,0,-7,quark:world_stone_pavement:2)
Block(3,0,-6,CONCRETE:0)
Block(3,0,-5,CONCRETE:0)
Block(3,0,-4,CONCRETE:0)
Block(3,0,-3,quark:world_stone_pavement:2)
Block(3,0,-2,CONCRETE:0)
Block(3,0,-1,CONCRETE:0)
Block(3,0,0,quark:world_stone_pavement:2)
Block(3,1,-7,quark:world_stone_pavement:2)
Block(3,1,-6,CONCRETE:0)
Block(3,1,-5,CONCRETE:0)
Block(3,1,-4,CONCRETE:0)
Block(3,1,-3,CONCRETE:0)
Block(3,1,-2,CONCRETE:0)
Block(3,1,-1,CONCRETE:0)
Block(3,1,0,CONCRETE:0)
Block(3,2,-7,CONCRETE:0)
Block(3,2,-6,CONCRETE:0)
Block(3,2,-5,CONCRETE:0)
Block(3,2,-4,CONCRETE:0)
Block(3,2,-3,quark:world_stone_pavement:2)
Block(3,2,-2,CONCRETE:0)
Block(3,2,-1,CONCRETE:0)
Block(3,2,0,quark:world_stone_pavement:2)
Block(3,3,-7,CONCRETE:0)
Block(3,3,-6,CONCRETE:0)
Block(3,3,-5,CONCRETE:0)
Block(3,3,-4,CONCRETE:0)
Block(3,3,-3,quark:world_stone_pavement:2)
Block(3,3,-2,quark:world_stone_pavement:2)
Block(3,3,-1,CONCRETE:0)
Block(3,3,0,CONCRETE:0)
Block(3,4,-7,CONCRETE:0)
Block(3,4,-6,CONCRETE:0)
Block(3,4,-5,CONCRETE:0)
Block(3,4,-4,CONCRETE:0)
Block(3,4,-3,CONCRETE:0)
Block(3,4,-2,CONCRETE:0)
Block(3,4,-1,CONCRETE:0)
Block(3,4,0,CONCRETE:0)
Block(3,5,-7,quark:world_stone_pavement:2)
Block(3,5,-6,quark:world_stone_pavement:2)
Block(3,5,-5,quark:world_stone_pavement:2)
Block(3,5,-4,CONCRETE:0)
Block(3,5,-3,CONCRETE:0)
Block(3,5,-2,quark:world_stone_pavement:2)
Block(3,5,-1,CONCRETE:0)
Block(3,5,0,CONCRETE:0)
Block(3,6,-7,CONCRETE:0)
Block(3,6,-6,quark:world_stone_pavement:2)
Block(3,6,-5,quark:world_stone_pavement:2)
Block(3,6,-4,quark:world_stone_pavement:2)
Block(3,6,-3,CONCRETE:0)
Block(3,6,-2,CONCRETE:0)
Block(3,6,-1,CONCRETE:0)
Block(3,6,0,CONCRETE:0)
Block(3,7,-7,CONCRETE:0)
Block(3,7,-6,CONCRETE:0)
Block(3,7,-5,CONCRETE:0)
Block(3,7,-4,quark:world_stone_pavement:2)
Block(3,7,-3,quark:world_stone_pavement:2)
Block(3,7,-2,quark:world_stone_pavement:2)
Block(3,7,-1,CONCRETE:0)
Block(3,7,0,CONCRETE:0)
Block(3,8,-7,quark:polished_stone:0)
Block(3,8,-6,quark:world_stone_pavement:2)
Block(3,8,-5,quark:world_stone_pavement:2)
Block(3,8,-4,quark:polished_stone:0)
Block(3,8,-3,quark:polished_stone:0)
Block(3,8,-2,quark:polished_stone:0)
Block(3,8,-1,quark:world_stone_pavement:2)
Block(3,8,0,CONCRETE:0)
Block(3,9,-7,quark:world_stone_pavement:2)
Block(3,9,-6,quark:polished_stone:0)
Block(3,9,-5,quark:world_stone_pavement:2)
Block(3,9,-4,quark:polished_stone:0)
Block(3,9,-3,quark:world_stone_pavement:2)
Block(3,9,-2,quark:world_stone_pavement:2)
Block(3,9,-1,quark:polished_stone:0)
Block(3,9,0,CONCRETE:0)
Block(3,10,-7,STAINED_CLAY:5)
Block(3,10,-6,quark:world_stone_pavement:2)
Block(3,10,-5,quark:polished_stone:0)
Block(3,10,-4,quark:polished_stone:0)
Block(3,10,-3,quark:polished_stone:0)
Block(3,10,-2,quark:polished_stone:0)
RandomBlock(3,10,-1,CONCRETE:0,40,SMOOTH_BRICK:1,30,SMOOTH_BRICK:2,30,MOSSY_COBBLESTONE:0,30,COBBLESTONE:0,20,CONCRETE:0,100)
Block(3,10,0,quark:world_stone_pavement:2)
Block(3,11,-2,DOUBLE_STEP:0)
RandomBlock(3,11,-1,CONCRETE:0,40,SMOOTH_BRICK:1,30,SMOOTH_BRICK:2,30,MOSSY_COBBLESTONE:0,30,COBBLESTONE:0,20,CONCRETE:0,100)
Block(3,11,0,quark:polished_stone:0)
Block(3,12,-4,STEP:8)
Block(3,12,-3,STEP:8)
Block(3,12,-2,DOUBLE_STEP:0)
RandomBlock(3,12,-1,CONCRETE:0,40,SMOOTH_BRICK:1,30,SMOOTH_BRICK:2,30,MOSSY_COBBLESTONE:0,30,COBBLESTONE:0,20,CONCRETE:0,100)
RandomBlock(3,12,0,CONCRETE:0,40,SMOOTH_BRICK:1,30,SMOOTH_BRICK:2,30,MOSSY_COBBLESTONE:0,30,COBBLESTONE:0,20,CONCRETE:0,100)
Block(3,13,-7,STEP:8)
Block(3,13,-6,STEP:8)
Block(3,13,-5,quark:iron_plate_stairs:3)
Block(3,13,-2,DOUBLE_STEP:0)
RandomBlock(3,13,-1,CONCRETE:0,40,SMOOTH_BRICK:1,30,SMOOTH_BRICK:2,30,MOSSY_COBBLESTONE:0,30,COBBLESTONE:0,20,CONCRETE:0,100)
RandomBlock(3,13,0,CONCRETE:0,40,SMOOTH_BRICK:1,30,SMOOTH_BRICK:2,30,MOSSY_COBBLESTONE:0,30,COBBLESTONE:0,20,CONCRETE:0,100)
Block(3,14,-2,DOUBLE_STEP:0)
RandomBlock(3,14,-1,CONCRETE:0,40,SMOOTH_BRICK:1,30,SMOOTH_BRICK:2,30,MOSSY_COBBLESTONE:0,30,COBBLESTONE:0,20,CONCRETE:0,100)
Block(3,14,0,STEP:0)
Block(3,15,-2,DOUBLE_STEP:0)
RandomBlock(3,15,-1,CONCRETE:0,40,SMOOTH_BRICK:1,30,SMOOTH_BRICK:2,30,MOSSY_COBBLESTONE:0,30,COBBLESTONE:0,20,CONCRETE:0,100)
Block(3,15,1,quark:iron_plate:1)
Block(3,15,3,quark:iron_plate:1)
Block(3,15,5,quark:iron_plate:1)
Block(3,15,7,quark:iron_plate:1)
Block(3,16,-5,quark:iron_plate:1)
Block(3,16,-2,quark:iron_plate:1)
Block(3,16,-1,quark:iron_plate:1)
Block(3,17,-5,SMOOTH_STAIRS:3)
Block(3,17,-4,DOUBLE_STEP:0)
Block(3,17,-3,STEP:0)
Block(3,17,-2,STEP:0)
Block(3,17,-1,STEP:0)
Block(3,18,-5,SMOOTH_STAIRS:7)
RandomBlock(3,18,-4,IRON_FENCE:0,30,IRON_FENCE:0,100)
Block(3,19,-7,STEP:8)
Block(3,19,-6,STEP:8)
Block(3,19,-5,quark:iron_plate:1)
RandomBlock(3,19,-4,IRON_FENCE:0,30,IRON_FENCE:0,100)
RandomBlock(3,20,-5,IRON_FENCE:0,30,IRON_FENCE:0,100)
RandomBlock(3,20,-4,IRON_FENCE:0,30,IRON_FENCE:0,100)
Block(4,0,-7,CONCRETE:0)
Block(4,0,-6,quark:world_stone_pavement:2)
Block(4,0,-5,quark:world_stone_pavement:2)
Block(4,0,-4,CONCRETE:0)
Block(4,0,-3,quark:world_stone_pavement:2)
Block(4,0,-2,quark:world_stone_pavement:2)
Block(4,0,-1,CONCRETE:0)
Block(4,0,0,CONCRETE:0)
Block(4,0,2,quark:iron_plate:1)
Block(4,0,3,quark:iron_plate:1)
Block(4,0,5,quark:iron_plate:1)
Block(4,0,6,quark:iron_plate:1)
Block(4,0,8,quark:iron_plate:1)
Block(4,1,-7,quark:world_stone_pavement:2)
Block(4,1,-6,CONCRETE:0)
Block(4,1,-5,CONCRETE:0)
Block(4,1,-4,CONCRETE:0)
Block(4,1,-3,quark:world_stone_pavement:2)
Block(4,1,-2,quark:world_stone_pavement:2)
Block(4,1,-1,CONCRETE:0)
Block(4,1,0,CONCRETE:0)
Block(4,1,2,quark:iron_plate:1)
Block(4,1,3,quark:iron_plate:1)
Block(4,1,5,quark:iron_plate:1)
Block(4,1,6,quark:iron_plate:1)
Block(4,1,8,quark:iron_plate:1)
Block(4,2,-7,CONCRETE:0)
Block(4,2,-6,quark:world_stone_pavement:2)
Block(4,2,-5,CONCRETE:0)
Block(4,2,-4,quark:world_stone_pavement:2)
Block(4,2,-3,CONCRETE:0)
Block(4,2,-2,CONCRETE:0)
Block(4,2,-1,CONCRETE:0)
Block(4,2,0,CONCRETE:0)
Block(4,2,2,quark:iron_plate:1)
Block(4,2,3,quark:iron_plate:1)
Block(4,2,5,quark:iron_plate:1)
Block(4,2,6,quark:iron_plate:1)
Block(4,2,8,quark:iron_plate:1)
Block(4,3,-7,quark:world_stone_pavement:2)
Block(4,3,-6,CONCRETE:0)
Block(4,3,-5,CONCRETE:0)
Block(4,3,-4,CONCRETE:0)
Block(4,3,-3,CONCRETE:0)
Block(4,3,-2,CONCRETE:0)
Block(4,3,-1,CONCRETE:0)
Block(4,3,0,quark:world_stone_pavement:2)
Block(4,3,2,quark:iron_plate:1)
Block(4,3,3,quark:iron_plate:1)
Block(4,3,5,quark:iron_plate:1)
Block(4,3,6,quark:iron_plate:1)
Block(4,3,8,quark:iron_plate:1)
Block(4,4,-7,quark:world_stone_pavement:2)
Block(4,4,-6,quark:world_stone_pavement:2)
Block(4,4,-5,CONCRETE:0)
Block(4,4,-4,quark:world_stone_pavement:2)
Block(4,4,-3,CONCRETE:0)
Block(4,4,-2,quark:world_stone_pavement:2)
Block(4,4,-1,CONCRETE:0)
Block(4,4,0,CONCRETE:0)
Block(4,4,2,quark:iron_plate:1)
Block(4,4,3,quark:iron_plate:1)
Block(4,4,5,quark:iron_plate:1)
Block(4,4,6,quark:iron_plate:1)
Block(4,4,8,quark:iron_plate:1)
Block(4,5,-7,CONCRETE:0)
Block(4,5,-6,CONCRETE:0)
Block(4,5,-5,CONCRETE:0)
Block(4,5,-4,CONCRETE:0)
Block(4,5,-3,quark:world_stone_pavement:2)
Block(4,5,-2,CONCRETE:0)
Block(4,5,-1,CONCRETE:0)
Block(4,5,0,CONCRETE:0)
Block(4,5,2,quark:iron_plate:1)
Block(4,5,3,quark:iron_plate:1)
Block(4,5,5,quark:iron_plate:1)
Block(4,5,6,quark:iron_plate:1)
Block(4,5,8,quark:iron_plate:1)
Block(4,6,-7,CONCRETE:0)
Block(4,6,-6,quark:world_stone_pavement:2)
Block(4,6,-5,CONCRETE:0)
Block(4,6,-4,CONCRETE:0)
Block(4,6,-3,CONCRETE:0)
Block(4,6,-2,quark:world_stone_pavement:2)
Block(4,6,-1,quark:world_stone_pavement:2)
Block(4,6,0,quark:world_stone_pavement:2)
Block(4,6,2,quark:iron_plate:1)
Block(4,6,3,quark:iron_plate:1)
Block(4,6,5,quark:iron_plate:1)
Block(4,6,6,quark:iron_plate:1)
Block(4,6,8,quark:iron_plate:1)
Block(4,7,-7,quark:world_stone_pavement:2)
Block(4,7,-6,quark:world_stone_pavement:2)
Block(4,7,-5,CONCRETE:0)
Block(4,7,-4,CONCRETE:0)
Block(4,7,-3,quark:world_stone_pavement:2)
Block(4,7,-2,CONCRETE:0)
Block(4,7,-1,CONCRETE:0)
Block(4,7,0,CONCRETE:0)
Block(4,7,2,quark:iron_plate:1)
Block(4,7,3,quark:iron_plate:1)
Block(4,7,5,quark:iron_plate:1)
Block(4,7,6,quark:iron_plate:1)
Block(4,7,8,quark:iron_plate:1)
Block(4,8,-7,quark:polished_stone:0)
Block(4,8,-6,quark:polished_stone:0)
Block(4,8,-5,quark:polished_stone:0)
Block(4,8,-4,quark:polished_stone:0)
Block(4,8,-3,quark:polished_stone:0)
Block(4,8,-2,quark:polished_stone:0)
Block(4,8,-1,CONCRETE:0)
Block(4,8,0,CONCRETE:0)
Block(4,8,2,quark:iron_plate:1)
Block(4,8,3,quark:iron_plate:1)
Block(4,8,5,quark:iron_plate:1)
Block(4,8,6,quark:iron_plate:1)
Block(4,8,8,quark:iron_plate:1)
Block(4,9,-7,quark:polished_stone:0)
Block(4,9,-6,quark:world_stone_pavement:2)
Block(4,9,-5,quark:world_stone_pavement:2)
Block(4,9,-4,quark:polished_stone:0)
Block(4,9,-3,quark:polished_stone:0)
Block(4,9,-2,quark:world_stone_pavement:2)
Block(4,9,-1,quark:polished_stone:0)
Block(4,9,0,CONCRETE:0)
Block(4,9,2,quark:iron_plate:1)
Block(4,9,3,quark:iron_plate:1)
Block(4,9,5,quark:iron_plate:1)
Block(4,9,6,quark:iron_plate:1)
Block(4,9,8,quark:iron_plate:1)
Block(4,10,-7,STAINED_CLAY:13)
Block(4,10,-6,quark:world_stone_pavement:2)
Block(4,10,-5,quark:polished_stone:0)
Block(4,10,-4,quark:world_stone_pavement:2)
Block(4,10,-3,quark:world_stone_pavement:2)
Block(4,10,-2,quark:world_stone_pavement:2)
RandomBlock(4,10,-1,CONCRETE:0,40,SMOOTH_BRICK:1,30,SMOOTH_BRICK:2,30,MOSSY_COBBLESTONE:0,30,COBBLESTONE:0,20,CONCRETE:0,100)
Block(4,10,0,quark:world_stone_pavement:2)
Block(4,10,2,quark:iron_plate:1)
Block(4,10,3,quark:iron_plate:1)
Block(4,10,5,quark:iron_plate:1)
Block(4,10,6,quark:iron_plate:1)
Block(4,10,8,quark:iron_plate:1)
Block(4,11,-5,SMOOTH_BRICK:0)
Block(4,11,-4,SMOOTH_BRICK:0)
RandomBlock(4,11,-2,CONCRETE:0,40,SMOOTH_BRICK:1,30,SMOOTH_BRICK:2,30,MOSSY_COBBLESTONE:0,30,COBBLESTONE:0,20,CONCRETE:0,100)
RandomBlock(4,11,-1,CONCRETE:0,40,SMOOTH_BRICK:1,30,SMOOTH_BRICK:2,30,MOSSY_COBBLESTONE:0,30,COBBLESTONE:0,20,CONCRETE:0,100)
Block(4,11,0,quark:world_stone_pavement:2)
Block(4,11,1,quark:basalt_wall:0)
Block(4,11,2,quark:iron_plate:1)
Block(4,11,3,quark:iron_plate:1)
Block(4,11,4,quark:basalt_wall:0)
Block(4,11,5,quark:iron_plate:1)
Block(4,11,6,quark:iron_plate:1)
Block(4,11,7,quark:basalt_wall:0)
Block(4,11,8,quark:iron_plate:1)
Block(4,12,-5,SMOOTH_BRICK:0)
Block(4,12,-4,STEP:8)
Block(4,12,-3,STEP:8)
RandomBlock(4,12,-2,CONCRETE:0,40,SMOOTH_BRICK:1,30,SMOOTH_BRICK:2,30,MOSSY_COBBLESTONE:0,30,COBBLESTONE:0,20,CONCRETE:0,100)
RandomBlock(4,12,-1,CONCRETE:0,40,SMOOTH_BRICK:1,30,SMOOTH_BRICK:2,30,MOSSY_COBBLESTONE:0,30,COBBLESTONE:0,20,CONCRETE:0,100)
RandomBlock(4,12,0,CONCRETE:0,40,SMOOTH_BRICK:1,30,SMOOTH_BRICK:2,30,MOSSY_COBBLESTONE:0,30,COBBLESTONE:0,20,CONCRETE:0,100)
Block(4,12,1,quark:basalt_wall:0)
Block(4,12,4,quark:basalt_wall:0)
Block(4,12,7,quark:basalt_wall:0)
Block(4,13,-7,STEP:8)
Block(4,13,-6,STEP:8)
Block(4,13,-5,quark:iron_plate_stairs:3)
RandomBlock(4,13,-2,CONCRETE:0,40,SMOOTH_BRICK:1,30,SMOOTH_BRICK:2,30,MOSSY_COBBLESTONE:0,30,COBBLESTONE:0,20,CONCRETE:0,100)
RandomBlock(4,13,-1,CONCRETE:0,40,SMOOTH_BRICK:1,30,SMOOTH_BRICK:2,30,MOSSY_COBBLESTONE:0,30,COBBLESTONE:0,20,CONCRETE:0,100)
RandomBlock(4,13,0,CONCRETE:0,40,SMOOTH_BRICK:1,30,SMOOTH_BRICK:2,30,MOSSY_COBBLESTONE:0,30,COBBLESTONE:0,20,CONCRETE:0,100)
Block(4,13,1,quark:basalt_wall:0)
Block(4,13,2,quark:basalt_wall:0)
Block(4,13,3,quark:basalt_wall:0)
Block(4,13,4,quark:basalt_wall:0)
Block(4,13,5,quark:basalt_wall:0)
Block(4,13,6,quark:basalt_wall:0)
Block(4,13,7,quark:basalt_wall:0)
Block(4,13,8,quark:basalt_wall:0)
RandomBlock(4,14,-2,CONCRETE:0,40,SMOOTH_BRICK:1,30,SMOOTH_BRICK:2,30,MOSSY_COBBLESTONE:0,30,COBBLESTONE:0,20,CONCRETE:0,100)
RandomBlock(4,14,-1,CONCRETE:0,40,SMOOTH_BRICK:1,30,SMOOTH_BRICK:2,30,MOSSY_COBBLESTONE:0,30,COBBLESTONE:0,20,CONCRETE:0,100)
Block(4,14,0,STEP:0)
RandomBlock(4,15,-2,CONCRETE:0,40,SMOOTH_BRICK:1,30,SMOOTH_BRICK:2,30,MOSSY_COBBLESTONE:0,30,COBBLESTONE:0,20,CONCRETE:0,100)
RandomBlock(4,15,-1,CONCRETE:0,40,SMOOTH_BRICK:1,30,SMOOTH_BRICK:2,30,MOSSY_COBBLESTONE:0,30,COBBLESTONE:0,20,CONCRETE:0,100)
Block(4,15,1,quark:iron_plate:1)
Block(4,15,3,quark:iron_plate:1)
Block(4,15,5,quark:iron_plate:1)
Block(4,15,7,quark:iron_plate:1)
Block(4,16,-5,quark:iron_plate:1)
Block(4,16,-2,quark:iron_plate:1)
Block(4,16,-1,quark:iron_plate:1)
Block(4,17,-5,quark:framed_glass:0)
Block(4,17,-4,STEP:0)
Block(4,17,-3,STEP:0)
Block(4,17,-2,STEP:0)
Block(4,17,-1,STEP:0)
Block(4,18,-5,quark:framed_glass:0)
Block(4,19,-7,STEP:8)
Block(4,19,-6,STEP:8)
Block(4,19,-5,quark:iron_plate:1)
RandomBlock(4,20,-5,IRON_FENCE:0,30,IRON_FENCE:0,100)
Block(5,0,-7,quark:world_stone_pavement:2)
Block(5,0,-6,CONCRETE:0)
Block(5,0,-5,CONCRETE:0)
Block(5,0,-4,CONCRETE:0)
Block(5,0,-3,quark:world_stone_pavement:2)
Block(5,0,-2,quark:world_stone_pavement:2)
Block(5,0,-1,CONCRETE:0)
Block(5,0,0,CONCRETE:0)
Block(5,0,1,CONCRETE:0)
Block(5,0,2,CONCRETE:0)
Block(5,0,3,CONCRETE:0)
Block(5,0,4,CONCRETE:0)
Block(5,0,5,CONCRETE:0)
Block(5,0,6,quark:world_stone_pavement:2)
Block(5,0,7,quark:world_stone_pavement:2)
Block(5,0,8,CONCRETE:0)
Block(5,1,-7,CONCRETE:0)
Block(5,1,-6,quark:world_stone_pavement:2)
Block(5,1,-5,CONCRETE:0)
Block(5,1,-4,CONCRETE:0)
Block(5,1,-3,quark:world_stone_pavement:2)
Block(5,1,-2,CONCRETE:0)
Block(5,1,-1,CONCRETE:0)
Block(5,1,0,CONCRETE:0)
Block(5,1,1,CONCRETE:0)
Block(5,1,2,quark:world_stone_pavement:2)
Block(5,1,3,quark:world_stone_pavement:2)
Block(5,1,4,CONCRETE:0)
Block(5,1,5,CONCRETE:0)
Block(5,1,6,quark:world_stone_pavement:2)
Block(5,1,7,quark:world_stone_pavement:2)
Block(5,1,8,CONCRETE:0)
Block(5,2,-7,CONCRETE:0)
Block(5,2,-6,CONCRETE:0)
Block(5,2,-5,CONCRETE:0)
Block(5,2,-4,quark:world_stone_pavement:2)
Block(5,2,-3,CONCRETE:0)
Block(5,2,-2,quark:world_stone_pavement:2)
Block(5,2,-1,CONCRETE:0)
Block(5,2,0,CONCRETE:0)
Block(5,2,1,quark:world_stone_pavement:2)
Block(5,2,2,CONCRETE:0)
Block(5,2,3,CONCRETE:0)
Block(5,2,4,CONCRETE:0)
Block(5,2,5,CONCRETE:0)
Block(5,2,6,CONCRETE:0)
Block(5,2,7,CONCRETE:0)
Block(5,2,8,CONCRETE:0)
Block(5,3,-7,CONCRETE:0)
Block(5,3,-6,CONCRETE:0)
Block(5,3,-5,CONCRETE:0)
Block(5,3,-4,quark:world_stone_pavement:2)
Block(5,3,-3,quark:world_stone_pavement:2)
Block(5,3,-2,CONCRETE:0)
Block(5,3,-1,CONCRETE:0)
Block(5,3,0,CONCRETE:0)
Block(5,3,1,CONCRETE:0)
Block(5,3,2,quark:world_stone_pavement:2)
Block(5,3,3,CONCRETE:0)
Block(5,3,4,quark:world_stone_pavement:2)
Block(5,3,5,CONCRETE:0)
Block(5,3,6,quark:world_stone_pavement:2)
Block(5,3,7,CONCRETE:0)
Block(5,3,8,CONCRETE:0)
Block(5,4,-7,quark:world_stone_pavement:2)
Block(5,4,-6,CONCRETE:0)
Block(5,4,-5,quark:world_stone_pavement:2)
Block(5,4,-4,CONCRETE:0)
Block(5,4,-3,quark:world_stone_pavement:2)
Block(5,4,-2,CONCRETE:0)
Block(5,4,-1,CONCRETE:0)
Block(5,4,0,CONCRETE:0)
Block(5,4,1,quark:world_stone_pavement:2)
Block(5,4,2,CONCRETE:0)
Block(5,4,3,CONCRETE:0)
Block(5,4,4,CONCRETE:0)
Block(5,4,5,CONCRETE:0)
Block(5,4,6,CONCRETE:0)
Block(5,4,7,CONCRETE:0)
Block(5,4,8,quark:world_stone_pavement:2)
Block(5,5,-7,CONCRETE:0)
Block(5,5,-6,CONCRETE:0)
Block(5,5,-5,CONCRETE:0)
Block(5,5,-4,quark:world_stone_pavement:2)
Block(5,5,-3,quark:world_stone_pavement:2)
Block(5,5,-2,CONCRETE:0)
Block(5,5,-1,CONCRETE:0)
Block(5,5,0,quark:world_stone_pavement:2)
Block(5,5,1,CONCRETE:0)
Block(5,5,2,CONCRETE:0)
Block(5,5,3,CONCRETE:0)
Block(5,5,4,CONCRETE:0)
Block(5,5,5,CONCRETE:0)
Block(5,5,6,quark:world_stone_pavement:2)
Block(5,5,7,CONCRETE:0)
Block(5,5,8,CONCRETE:0)
Block(5,6,-7,CONCRETE:0)
Block(5,6,-6,CONCRETE:0)
Block(5,6,-5,CONCRETE:0)
Block(5,6,-4,quark:world_stone_pavement:2)
Block(5,6,-3,quark:world_stone_pavement:2)
Block(5,6,-2,quark:world_stone_pavement:2)
Block(5,6,-1,CONCRETE:0)
Block(5,6,0,quark:world_stone_pavement:2)
Block(5,6,1,CONCRETE:0)
Block(5,6,2,quark:world_stone_pavement:2)
Block(5,6,3,CONCRETE:0)
Block(5,6,4,quark:world_stone_pavement:2)
Block(5,6,5,CONCRETE:0)
Block(5,6,6,CONCRETE:0)
Block(5,6,7,quark:world_stone_pavement:2)
Block(5,6,8,CONCRETE:0)
Block(5,7,-7,quark:world_stone_pavement:2)
Block(5,7,-6,CONCRETE:0)
Block(5,7,-5,quark:world_stone_pavement:2)
Block(5,7,-4,CONCRETE:0)
Block(5,7,-3,quark:world_stone_pavement:2)
Block(5,7,-2,CONCRETE:0)
Block(5,7,-1,CONCRETE:0)
Block(5,7,0,CONCRETE:0)
Block(5,7,1,CONCRETE:0)
Block(5,7,2,quark:world_stone_pavement:2)
Block(5,7,3,CONCRETE:0)
Block(5,7,4,quark:world_stone_pavement:2)
Block(5,7,5,quark:world_stone_pavement:2)
Block(5,7,6,CONCRETE:0)
Block(5,7,7,quark:world_stone_pavement:2)
Block(5,7,8,CONCRETE:0)
Block(5,8,-7,quark:polished_stone:0)
Block(5,8,-6,quark:polished_stone:0)
Block(5,8,-5,quark:polished_stone:0)
Block(5,8,-4,quark:polished_stone:0)
Block(5,8,-3,quark:polished_stone:0)
Block(5,8,-2,quark:polished_stone:0)
Block(5,8,-1,quark:world_stone_pavement:2)
Block(5,8,0,quark:world_stone_pavement:2)
Block(5,8,1,quark:polished_stone:0)
Block(5,8,2,quark:world_stone_pavement:2)
Block(5,8,3,quark:polished_stone:0)
Block(5,8,4,quark:world_stone_pavement:2)
Block(5,8,5,quark:world_stone_pavement:2)
Block(5,8,6,quark:world_stone_pavement:2)
Block(5,8,7,quark:polished_stone:0)
Block(5,8,8,quark:polished_stone:0)
Block(5,9,-7,quark:world_stone_pavement:2)
Block(5,9,-6,quark:polished_stone:0)
Block(5,9,-5,quark:polished_stone:0)
Block(5,9,-4,quark:polished_stone:0)
Block(5,9,-3,quark:polished_stone:0)
Block(5,9,-2,quark:polished_stone:0)
Block(5,9,-1,quark:polished_stone:0)
Block(5,9,0,quark:polished_stone:0)
Block(5,9,1,quark:polished_stone:0)
Block(5,9,2,quark:polished_stone:0)
Block(5,9,3,quark:world_stone_pavement:2)
Block(5,9,4,quark:polished_stone:0)
Block(5,9,5,quark:world_stone_pavement:2)
Block(5,9,6,quark:polished_stone:0)
Block(5,9,7,quark:world_stone_pavement:2)
Block(5,9,8,quark:polished_stone:0)
Block(5,10,-7,STAINED_CLAY:4)
Block(5,10,-6,quark:polished_stone:0)
Block(5,10,-5,quark:polished_stone:0)
Block(5,10,-4,quark:polished_stone:0)
Block(5,10,-3,quark:polished_stone:0)
Block(5,10,-2,quark:polished_stone:0)
Block(5,10,-1,quark:polished_stone:0)
Block(5,10,0,quark:polished_stone:0)
Block(5,10,1,quark:polished_stone:0)
Block(5,10,2,quark:world_stone_pavement:2)
Block(5,10,3,quark:world_stone_pavement:2)
Block(5,10,4,quark:polished_stone:0)
Block(5,10,5,quark:polished_stone:0)
Block(5,10,6,quark:polished_stone:0)
Block(5,10,7,quark:polished_stone:0)
Block(5,10,8,quark:polished_stone:0)
Block(5,11,-7,IRON_DOOR_BLOCK:2)
Block(5,11,-6,quark:iron_plate:1)
Block(5,11,-5,DOUBLE_STEP:0)
RandomBlock(5,11,-4,CONCRETE:0,40,SMOOTH_BRICK:1,30,SMOOTH_BRICK:2,30,MOSSY_COBBLESTONE:0,30,COBBLESTONE:0,20,CONCRETE:0,100)
Block(5,11,-3,DOUBLE_STEP:0)
RandomBlock(5,11,-2,CONCRETE:0,40,SMOOTH_BRICK:1,30,SMOOTH_BRICK:2,30,MOSSY_COBBLESTONE:0,30,COBBLESTONE:0,20,CONCRETE:0,100)
Block(5,11,-1,DOUBLE_STEP:0)
RandomBlock(5,11,0,CONCRETE:0,40,SMOOTH_BRICK:1,30,SMOOTH_BRICK:2,30,MOSSY_COBBLESTONE:0,30,COBBLESTONE:0,20,CONCRETE:0,100)
Block(5,11,1,DOUBLE_STEP:0)
RandomBlock(5,11,2,CONCRETE:0,40,SMOOTH_BRICK:1,30,SMOOTH_BRICK:2,30,MOSSY_COBBLESTONE:0,30,COBBLESTONE:0,20,CONCRETE:0,100)
Block(5,11,3,DOUBLE_STEP:0)
RandomBlock(5,11,4,CONCRETE:0,40,SMOOTH_BRICK:1,30,SMOOTH_BRICK:2,30,MOSSY_COBBLESTONE:0,30,COBBLESTONE:0,20,CONCRETE:0,100)
Block(5,11,5,DOUBLE_STEP:0)
RandomBlock(5,11,6,CONCRETE:0,40,SMOOTH_BRICK:1,30,SMOOTH_BRICK:2,30,MOSSY_COBBLESTONE:0,30,COBBLESTONE:0,20,CONCRETE:0,100)
Block(5,11,7,DOUBLE_STEP:0)
RandomBlock(5,11,8,CONCRETE:0,40,SMOOTH_BRICK:1,30,SMOOTH_BRICK:2,30,MOSSY_COBBLESTONE:0,30,COBBLESTONE:0,20,CONCRETE:0,100)
Block(5,12,-7,IRON_DOOR_BLOCK:8)
Block(5,12,-6,quark:iron_plate:1)
Block(5,12,-5,DOUBLE_STEP:0)
RandomBlock(5,12,-4,CONCRETE:0,40,SMOOTH_BRICK:1,30,SMOOTH_BRICK:2,30,MOSSY_COBBLESTONE:0,30,COBBLESTONE:0,20,CONCRETE:0,100)
Block(5,12,-3,DOUBLE_STEP:0)
RandomBlock(5,12,-2,CONCRETE:0,40,SMOOTH_BRICK:1,30,SMOOTH_BRICK:2,30,MOSSY_COBBLESTONE:0,30,COBBLESTONE:0,20,CONCRETE:0,100)
Block(5,12,-1,DOUBLE_STEP:0)
RandomBlock(5,12,0,CONCRETE:0,40,SMOOTH_BRICK:1,30,SMOOTH_BRICK:2,30,MOSSY_COBBLESTONE:0,30,COBBLESTONE:0,20,CONCRETE:0,100)
Block(5,12,1,DOUBLE_STEP:0)
RandomBlock(5,12,2,CONCRETE:0,40,SMOOTH_BRICK:1,30,SMOOTH_BRICK:2,30,MOSSY_COBBLESTONE:0,30,COBBLESTONE:0,20,CONCRETE:0,100)
Block(5,12,3,DOUBLE_STEP:0)
RandomBlock(5,12,4,CONCRETE:0,40,SMOOTH_BRICK:1,30,SMOOTH_BRICK:2,30,MOSSY_COBBLESTONE:0,30,COBBLESTONE:0,20,CONCRETE:0,100)
Block(5,12,5,DOUBLE_STEP:0)
RandomBlock(5,12,6,CONCRETE:0,40,SMOOTH_BRICK:1,30,SMOOTH_BRICK:2,30,MOSSY_COBBLESTONE:0,30,COBBLESTONE:0,20,CONCRETE:0,100)
Block(5,12,7,DOUBLE_STEP:0)
RandomBlock(5,12,8,CONCRETE:0,40,SMOOTH_BRICK:1,30,SMOOTH_BRICK:2,30,MOSSY_COBBLESTONE:0,30,COBBLESTONE:0,20,CONCRETE:0,100)
Block(5,13,-7,quark:iron_plate:1)
Block(5,13,-6,quark:iron_plate:1)
Block(5,13,-5,DOUBLE_STEP:0)
RandomBlock(5,13,-4,CONCRETE:0,40,SMOOTH_BRICK:1,30,SMOOTH_BRICK:2,30,MOSSY_COBBLESTONE:0,30,COBBLESTONE:0,20,CONCRETE:0,100)
Block(5,13,-3,DOUBLE_STEP:0)
RandomBlock(5,13,-2,CONCRETE:0,40,SMOOTH_BRICK:1,30,SMOOTH_BRICK:2,30,MOSSY_COBBLESTONE:0,30,COBBLESTONE:0,20,CONCRETE:0,100)
Block(5,13,-1,DOUBLE_STEP:0)
RandomBlock(5,13,0,CONCRETE:0,40,SMOOTH_BRICK:1,30,SMOOTH_BRICK:2,30,MOSSY_COBBLESTONE:0,30,COBBLESTONE:0,20,CONCRETE:0,100)
Block(5,13,1,DOUBLE_STEP:0)
RandomBlock(5,13,2,CONCRETE:0,40,SMOOTH_BRICK:1,30,SMOOTH_BRICK:2,30,MOSSY_COBBLESTONE:0,30,COBBLESTONE:0,20,CONCRETE:0,100)
Block(5,13,3,DOUBLE_STEP:0)
RandomBlock(5,13,4,CONCRETE:0,40,SMOOTH_BRICK:1,30,SMOOTH_BRICK:2,30,MOSSY_COBBLESTONE:0,30,COBBLESTONE:0,20,CONCRETE:0,100)
Block(5,13,5,DOUBLE_STEP:0)
RandomBlock(5,13,6,CONCRETE:0,40,SMOOTH_BRICK:1,30,SMOOTH_BRICK:2,30,MOSSY_COBBLESTONE:0,30,COBBLESTONE:0,20,CONCRETE:0,100)
Block(5,13,7,DOUBLE_STEP:0)
RandomBlock(5,13,8,CONCRETE:0,40,SMOOTH_BRICK:1,30,SMOOTH_BRICK:2,30,MOSSY_COBBLESTONE:0,30,COBBLESTONE:0,20,CONCRETE:0,100)
Block(5,14,-7,DOUBLE_STEP:0)
RandomBlock(5,14,-6,CONCRETE:0,40,SMOOTH_BRICK:1,30,SMOOTH_BRICK:2,30,MOSSY_COBBLESTONE:0,30,COBBLESTONE:0,20,CONCRETE:0,100)
Block(5,14,-5,DOUBLE_STEP:0)
RandomBlock(5,14,-4,CONCRETE:0,40,SMOOTH_BRICK:1,30,SMOOTH_BRICK:2,30,MOSSY_COBBLESTONE:0,30,COBBLESTONE:0,20,CONCRETE:0,100)
Block(5,14,-3,DOUBLE_STEP:0)
RandomBlock(5,14,-2,CONCRETE:0,40,SMOOTH_BRICK:1,30,SMOOTH_BRICK:2,30,MOSSY_COBBLESTONE:0,30,COBBLESTONE:0,20,CONCRETE:0,100)
Block(5,14,-1,DOUBLE_STEP:0)
RandomBlock(5,14,0,CONCRETE:0,40,SMOOTH_BRICK:1,30,SMOOTH_BRICK:2,30,MOSSY_COBBLESTONE:0,30,COBBLESTONE:0,20,CONCRETE:0,100)
Block(5,14,1,DOUBLE_STEP:0)
RandomBlock(5,14,2,CONCRETE:0,40,SMOOTH_BRICK:1,30,SMOOTH_BRICK:2,30,MOSSY_COBBLESTONE:0,30,COBBLESTONE:0,20,CONCRETE:0,100)
Block(5,14,3,DOUBLE_STEP:0)
RandomBlock(5,14,4,CONCRETE:0,40,SMOOTH_BRICK:1,30,SMOOTH_BRICK:2,30,MOSSY_COBBLESTONE:0,30,COBBLESTONE:0,20,CONCRETE:0,100)
Block(5,14,5,DOUBLE_STEP:0)
RandomBlock(5,14,6,CONCRETE:0,40,SMOOTH_BRICK:1,30,SMOOTH_BRICK:2,30,MOSSY_COBBLESTONE:0,30,COBBLESTONE:0,20,CONCRETE:0,100)
Block(5,14,7,DOUBLE_STEP:0)
RandomBlock(5,14,8,CONCRETE:0,40,SMOOTH_BRICK:1,30,SMOOTH_BRICK:2,30,MOSSY_COBBLESTONE:0,30,COBBLESTONE:0,20,CONCRETE:0,100)
Block(5,15,-7,DOUBLE_STEP:0)
RandomBlock(5,15,-6,CONCRETE:0,40,SMOOTH_BRICK:1,30,SMOOTH_BRICK:2,30,MOSSY_COBBLESTONE:0,30,COBBLESTONE:0,20,CONCRETE:0,100)
Block(5,15,-5,DOUBLE_STEP:0)
RandomBlock(5,15,-4,CONCRETE:0,40,SMOOTH_BRICK:1,30,SMOOTH_BRICK:2,30,MOSSY_COBBLESTONE:0,30,COBBLESTONE:0,20,CONCRETE:0,100)
Block(5,15,-3,DOUBLE_STEP:0)
RandomBlock(5,15,-2,CONCRETE:0,40,SMOOTH_BRICK:1,30,SMOOTH_BRICK:2,30,MOSSY_COBBLESTONE:0,30,COBBLESTONE:0,20,CONCRETE:0,100)
Block(5,15,-1,DOUBLE_STEP:0)
RandomBlock(5,15,0,CONCRETE:0,40,SMOOTH_BRICK:1,30,SMOOTH_BRICK:2,30,MOSSY_COBBLESTONE:0,30,COBBLESTONE:0,20,CONCRETE:0,100)
Block(5,15,1,DOUBLE_STEP:0)
RandomBlock(5,15,2,CONCRETE:0,40,SMOOTH_BRICK:1,30,SMOOTH_BRICK:2,30,MOSSY_COBBLESTONE:0,30,COBBLESTONE:0,20,CONCRETE:0,100)
Block(5,15,3,DOUBLE_STEP:0)
RandomBlock(5,15,4,CONCRETE:0,40,SMOOTH_BRICK:1,30,SMOOTH_BRICK:2,30,MOSSY_COBBLESTONE:0,30,COBBLESTONE:0,20,CONCRETE:0,100)
Block(5,15,5,DOUBLE_STEP:0)
RandomBlock(5,15,6,CONCRETE:0,40,SMOOTH_BRICK:1,30,SMOOTH_BRICK:2,30,MOSSY_COBBLESTONE:0,30,COBBLESTONE:0,20,CONCRETE:0,100)
Block(5,15,7,DOUBLE_STEP:0)
RandomBlock(5,15,8,CONCRETE:0,40,SMOOTH_BRICK:1,30,SMOOTH_BRICK:2,30,MOSSY_COBBLESTONE:0,30,COBBLESTONE:0,20,CONCRETE:0,100)
Block(5,16,-7,quark:iron_plate:1)
Block(5,16,-6,quark:iron_plate:1)
Block(5,16,-5,quark:iron_plate:1)
Block(5,16,-4,quark:iron_plate:1)
Block(5,16,-3,quark:iron_plate:1)
Block(5,16,-2,quark:iron_plate:1)
Block(5,16,-1,quark:iron_plate:1)
Block(5,16,0,quark:iron_plate:1)
Block(5,16,1,quark:iron_plate:1)
Block(5,16,2,quark:iron_plate:1)
Block(5,16,3,quark:iron_plate:1)
Block(5,16,4,quark:iron_plate:1)
Block(5,16,5,quark:iron_plate:1)
Block(5,16,6,quark:iron_plate:1)
Block(5,16,7,quark:iron_plate:1)
Block(5,16,8,quark:iron_plate:1)
Block(5,17,-5,quark:framed_glass:0)
Block(5,17,-4,quark:iron_plate:1)
Block(5,17,-3,STEP:0)
Block(5,17,-2,STEP:0)
Block(5,17,-1,STEP:0)
Block(5,17,1,quark:iron_plate:1)
Block(5,17,6,quark:iron_plate:1)
Block(5,18,-5,quark:framed_glass:0)
Block(5,18,-4,STEP:0)
Block(5,18,1,STEP:0)
Block(5,18,6,STEP:0)
Block(5,19,-7,quark:iron_plate:1)
Block(5,19,-6,quark:iron_plate:1)
Block(5,19,-5,quark:iron_plate:1)
RandomBlock(5,20,-5,IRON_FENCE:0,30,IRON_FENCE:0,100)
Block(6,0,-7,quark:world_stone_pavement:2)
Block(6,0,-6,CONCRETE:0)
Block(6,0,-5,CONCRETE:0)
Block(6,0,-4,CONCRETE:0)
Block(6,0,-3,CONCRETE:0)
Block(6,0,-2,quark:world_stone_pavement:2)
Block(6,0,-1,CONCRETE:0)
Block(6,0,0,CONCRETE:0)
Block(6,0,1,CONCRETE:0)
Block(6,0,2,quark:world_stone_pavement:2)
Block(6,0,3,quark:world_stone_pavement:2)
Block(6,0,4,CONCRETE:0)
Block(6,0,5,CONCRETE:0)
Block(6,0,6,CONCRETE:0)
Block(6,0,7,CONCRETE:0)
Block(6,0,8,CONCRETE:0)
Block(6,1,-7,CONCRETE:0)
Block(6,1,-6,quark:world_stone_pavement:2)
Block(6,1,-5,CONCRETE:0)
Block(6,1,-4,quark:world_stone_pavement:2)
Block(6,1,-3,CONCRETE:0)
Block(6,1,-2,CONCRETE:0)
Block(6,1,-1,quark:world_stone_pavement:2)
Block(6,1,0,CONCRETE:0)
Block(6,1,1,CONCRETE:0)
Block(6,1,2,quark:world_stone_pavement:2)
Block(6,1,3,CONCRETE:0)
Block(6,1,4,CONCRETE:0)
Block(6,1,5,CONCRETE:0)
Block(6,1,6,CONCRETE:0)
Block(6,1,7,quark:world_stone_pavement:2)
Block(6,1,8,quark:world_stone_pavement:2)
Block(6,2,-7,CONCRETE:0)
Block(6,2,-6,CONCRETE:0)
Block(6,2,-5,CONCRETE:0)
Block(6,2,-4,quark:world_stone_pavement:2)
Block(6,2,-3,CONCRETE:0)
Block(6,2,-2,CONCRETE:0)
Block(6,2,-1,CONCRETE:0)
Block(6,2,0,CONCRETE:0)
Block(6,2,1,quark:world_stone_pavement:2)
Block(6,2,2,CONCRETE:0)
Block(6,2,3,quark:world_stone_pavement:2)
Block(6,2,4,CONCRETE:0)
Block(6,2,5,CONCRETE:0)
Block(6,2,6,quark:world_stone_pavement:2)
Block(6,2,7,CONCRETE:0)
Block(6,2,8,CONCRETE:0)
Block(6,3,-7,CONCRETE:0)
Block(6,3,-6,CONCRETE:0)
Block(6,3,-5,CONCRETE:0)
Block(6,3,-4,quark:world_stone_pavement:2)
Block(6,3,-3,CONCRETE:0)
Block(6,3,-2,CONCRETE:0)
Block(6,3,-1,CONCRETE:0)
Block(6,3,0,CONCRETE:0)
Block(6,3,1,quark:world_stone_pavement:2)
Block(6,3,2,quark:world_stone_pavement:2)
Block(6,3,3,CONCRETE:0)
Block(6,3,4,CONCRETE:0)
Block(6,3,5,CONCRETE:0)
Block(6,3,6,CONCRETE:0)
Block(6,3,7,quark:world_stone_pavement:2)
Block(6,3,8,CONCRETE:0)
Block(6,4,-7,quark:world_stone_pavement:2)
Block(6,4,-6,CONCRETE:0)
Block(6,4,-5,quark:world_stone_pavement:2)
Block(6,4,-4,CONCRETE:0)
Block(6,4,-3,CONCRETE:0)
Block(6,4,-2,quark:world_stone_pavement:2)
Block(6,4,-1,CONCRETE:0)
Block(6,4,0,quark:world_stone_pavement:2)
Block(6,4,1,CONCRETE:0)
Block(6,4,2,quark:world_stone_pavement:2)
Block(6,4,3,CONCRETE:0)
Block(6,4,4,CONCRETE:0)
Block(6,4,5,CONCRETE:0)
Block(6,4,6,quark:world_stone_pavement:2)
Block(6,4,7,CONCRETE:0)
Block(6,4,8,CONCRETE:0)
Block(6,5,-7,CONCRETE:0)
Block(6,5,-6,CONCRETE:0)
Block(6,5,-5,CONCRETE:0)
Block(6,5,-4,quark:world_stone_pavement:2)
Block(6,5,-3,quark:world_stone_pavement:2)
Block(6,5,-2,CONCRETE:0)
Block(6,5,-1,CONCRETE:0)
Block(6,5,0,CONCRETE:0)
Block(6,5,1,quark:world_stone_pavement:2)
Block(6,5,2,quark:world_stone_pavement:2)
Block(6,5,3,CONCRETE:0)
Block(6,5,4,CONCRETE:0)
Block(6,5,5,quark:world_stone_pavement:2)
Block(6,5,6,CONCRETE:0)
Block(6,5,7,CONCRETE:0)
Block(6,5,8,CONCRETE:0)
Block(6,6,-7,CONCRETE:0)
Block(6,6,-6,CONCRETE:0)
Block(6,6,-5,CONCRETE:0)
Block(6,6,-4,quark:world_stone_pavement:2)
Block(6,6,-3,CONCRETE:0)
Block(6,6,-2,CONCRETE:0)
Block(6,6,-1,CONCRETE:0)
Block(6,6,0,CONCRETE:0)
Block(6,6,1,quark:world_stone_pavement:2)
Block(6,6,2,quark:world_stone_pavement:2)
Block(6,6,3,quark:world_stone_pavement:2)
Block(6,6,4,CONCRETE:0)
Block(6,6,5,quark:world_stone_pavement:2)
Block(6,6,6,CONCRETE:0)
Block(6,6,7,quark:world_stone_pavement:2)
Block(6,6,8,CONCRETE:0)
Block(6,7,-7,quark:world_stone_pavement:2)
Block(6,7,-6,CONCRETE:0)
Block(6,7,-5,quark:world_stone_pavement:2)
Block(6,7,-4,quark:world_stone_pavement:2)
Block(6,7,-3,quark:world_stone_pavement:2)
Block(6,7,-2,quark:world_stone_pavement:2)
Block(6,7,-1,CONCRETE:0)
Block(6,7,0,quark:world_stone_pavement:2)
Block(6,7,1,CONCRETE:0)
Block(6,7,2,quark:world_stone_pavement:2)
Block(6,7,3,CONCRETE:0)
Block(6,7,4,CONCRETE:0)
Block(6,7,5,CONCRETE:0)
Block(6,7,6,CONCRETE:0)
Block(6,7,7,quark:world_stone_pavement:2)
Block(6,7,8,CONCRETE:0)
Block(6,8,-7,quark:polished_stone:0)
Block(6,8,-6,quark:polished_stone:0)
Block(6,8,-5,quark:polished_stone:0)
Block(6,8,-4,quark:polished_stone:0)
Block(6,8,-3,quark:polished_stone:0)
Block(6,8,-2,quark:polished_stone:0)
Block(6,8,-1,quark:polished_stone:0)
Block(6,8,0,quark:polished_stone:0)
Block(6,8,1,quark:polished_stone:0)
Block(6,8,2,quark:polished_stone:0)
Block(6,8,3,quark:polished_stone:0)
Block(6,8,4,quark:world_stone_pavement:2)
Block(6,8,5,quark:world_stone_pavement:2)
Block(6,8,6,quark:polished_stone:0)
Block(6,8,7,quark:world_stone_pavement:2)
Block(6,8,8,quark:polished_stone:0)
Block(6,9,-7,quark:world_stone_pavement:2)
Block(6,9,-6,quark:polished_stone:0)
Block(6,9,-5,quark:polished_stone:0)
Block(6,9,-4,quark:polished_stone:0)
Block(6,9,-3,quark:polished_stone:0)
Block(6,9,-2,quark:world_stone_pavement:2)
Block(6,9,-1,quark:polished_stone:0)
Block(6,9,0,quark:polished_stone:0)
Block(6,9,1,quark:polished_stone:0)
Block(6,9,2,quark:polished_stone:0)
Block(6,9,3,quark:polished_stone:0)
Block(6,9,4,quark:polished_stone:0)
Block(6,9,5,quark:polished_stone:0)
Block(6,9,6,quark:polished_stone:0)
Block(6,9,7,quark:polished_stone:0)
Block(6,9,8,quark:world_stone_pavement:2)
Block(6,10,-7,quark:world_stone_pavement:2)
Block(6,10,-6,quark:polished_stone:0)
Block(6,10,-5,quark:polished_stone:0)
Block(6,10,-4,quark:polished_stone:0)
Block(6,10,-3,quark:polished_stone:0)
Block(6,10,-2,quark:world_stone_pavement:2)
Block(6,10,-1,quark:polished_stone:0)
Block(6,10,0,quark:polished_stone:0)
Block(6,10,1,quark:polished_stone:0)
Block(6,10,2,quark:polished_stone:0)
Block(6,10,3,quark:polished_stone:0)
Block(6,10,4,quark:polished_stone:0)
Block(6,10,5,quark:polished_stone:0)
Block(6,10,6,quark:polished_stone:0)
Block(6,10,7,quark:world_stone_pavement:2)
Block(6,10,8,quark:world_stone_pavement:2)
Block(6,11,-6,quark:polished_stone:0)
Block(6,11,-5,quark:iron_plate:1)
Block(6,11,2,srparasites:parasitethin)
Block(6,11,4,srparasites:parasitethin)
Block(6,12,-6,quark:polished_stone:0)
Block(6,12,-5,quark:iron_plate:1)
Block(6,12,-1,srparasites:infestedbush:4)
Block(6,12,1,srparasites:parasitethin)
Block(6,12,2,srparasites:parasitethin)
Block(6,12,3,srparasites:parasitethin)
Block(6,12,4,srparasites:parasitethin)
Block(6,12,6,srparasites:parasitethin)
Block(6,13,-7,quark:polished_stone:0)
Block(6,13,-6,quark:polished_stone:0)
Block(6,13,-5,quark:iron_plate:1)
Block(6,13,-1,srparasites:infestedbush:4)
Block(6,13,1,srparasites:parasitethin)
Block(6,13,2,srparasites:parasitethin)
Block(6,13,3,srparasites:parasitethin)
Block(6,13,4,srparasites:parasitethin)
Block(6,13,6,srparasites:parasitethin)
Block(6,13,8,srparasites:parasitethin)
Block(6,14,-7,quark:iron_plate:1)
Block(6,14,-6,quark:iron_plate:1)
Block(6,14,-5,quark:iron_plate:1)
Block(6,14,-1,srparasites:infestedbush:4)
Block(6,14,1,srparasites:parasitethin)
Block(6,14,2,srparasites:parasitethin)
Block(6,14,3,srparasites:parasitethin)
Block(6,14,4,srparasites:parasitethin)
Block(6,14,6,srparasites:parasitethin)
Block(6,14,7,srparasites:parasitethin)
Block(6,14,8,srparasites:parasitethin)
Block(6,15,-2,srparasites:parasiterubbledense:1)
Block(6,15,-1,srparasites:parasiterubbledense:1)
Block(6,15,1,srparasites:parasitethin)
Block(6,15,2,srparasites:parasitethin)
Block(6,15,3,srparasites:parasitethin)
Block(6,15,4,srparasites:parasitethin)
Block(6,15,6,srparasites:parasitethin)
Block(6,15,7,srparasites:parasitethin)
Block(6,15,8,srparasites:parasitethin)
Block(6,16,-7,SMOOTH_STAIRS:5)
Block(6,16,-6,SMOOTH_STAIRS:5)
Block(6,16,-5,SMOOTH_STAIRS:5)
Block(6,16,-4,quark:iron_plate:1)
Block(6,16,-3,srparasites:parasiterubbledense:1)
Block(6,16,-2,srparasites:parasiterubbledense:1)
Block(6,16,-1,SMOOTH_STAIRS:5)
Block(6,16,0,SMOOTH_STAIRS:5)
Block(6,16,1,quark:iron_plate:1)
Block(6,16,2,SMOOTH_STAIRS:5)
Block(6,16,3,SMOOTH_STAIRS:5)
Block(6,16,4,SMOOTH_STAIRS:5)
Block(6,16,5,SMOOTH_STAIRS:5)
Block(6,16,6,quark:iron_plate:1)
Block(6,16,7,SMOOTH_STAIRS:5)
Block(6,16,8,SMOOTH_STAIRS:5)
Block(6,17,-7,quark:iron_plate:1)
Block(6,17,-6,quark:iron_plate:1)
Block(6,17,-5,quark:iron_plate:1)
Block(6,17,-4,quark:iron_plate:1)
Block(6,17,-3,quark:polished_stone:0)
Block(6,17,-2,quark:polished_stone:0)
Block(6,17,-1,quark:polished_stone:0)
Block(6,17,0,quark:polished_stone:0)
Block(6,17,1,quark:iron_plate:1)
Block(6,17,2,quark:polished_stone:0)
Block(6,17,3,quark:polished_stone:0)
Block(6,17,4,quark:polished_stone:0)
Block(6,17,5,quark:polished_stone:0)
Block(6,17,6,quark:iron_plate:1)
Block(6,17,7,quark:polished_stone:0)
Block(6,17,8,quark:polished_stone:0)
Block(6,18,-5,quark:framed_glass:0)
Block(6,18,-4,SMOOTH_STAIRS:0)
Block(6,18,-3,SMOOTH_STAIRS:0)
Block(6,18,-2,SMOOTH_STAIRS:0)
Block(6,18,-1,SMOOTH_STAIRS:0)
Block(6,18,0,SMOOTH_STAIRS:0)
Block(6,18,1,SMOOTH_STAIRS:0)
Block(6,18,2,SMOOTH_STAIRS:0)
Block(6,18,3,SMOOTH_STAIRS:0)
Block(6,18,4,SMOOTH_STAIRS:0)
Block(6,18,5,SMOOTH_STAIRS:0)
Block(6,18,6,SMOOTH_STAIRS:0)
Block(6,18,7,SMOOTH_STAIRS:0)
Block(6,18,8,SMOOTH_STAIRS:0)
Block(6,19,-7,STEP:8)
Block(6,19,-6,STEP:8)
Block(6,19,-5,quark:iron_plate:1)
RandomBlock(6,20,-5,IRON_FENCE:0,30,IRON_FENCE:0,100)
Block(7,0,-7,quark:world_stone_pavement:2)
Block(7,0,-6,CONCRETE:0)
Block(7,0,-5,CONCRETE:0)
Block(7,0,-4,quark:world_stone_pavement:2)
Block(7,0,-3,CONCRETE:0)
Block(7,0,-2,quark:world_stone_pavement:2)
Block(7,0,-1,CONCRETE:0)
Block(7,0,0,CONCRETE:0)
Block(7,0,1,quark:world_stone_pavement:2)
Block(7,0,2,CONCRETE:0)
Block(7,0,3,CONCRETE:0)
Block(7,0,4,quark:world_stone_pavement:2)
Block(7,0,5,CONCRETE:0)
Block(7,0,6,CONCRETE:0)
Block(7,0,7,quark:world_stone_pavement:2)
Block(7,0,8,quark:world_stone_pavement:2)
Block(7,1,-7,CONCRETE:0)
Block(7,1,-6,quark:world_stone_pavement:2)
Block(7,1,-5,CONCRETE:0)
Block(7,1,-4,CONCRETE:0)
Block(7,1,-3,CONCRETE:0)
Block(7,1,-2,CONCRETE:0)
Block(7,1,-1,quark:world_stone_pavement:2)
Block(7,1,0,CONCRETE:0)
Block(7,1,1,quark:world_stone_pavement:2)
Block(7,1,2,CONCRETE:0)
Block(7,1,3,CONCRETE:0)
Block(7,1,4,CONCRETE:0)
Block(7,1,5,CONCRETE:0)
Block(7,1,6,quark:world_stone_pavement:2)
Block(7,1,7,CONCRETE:0)
Block(7,1,8,CONCRETE:0)
Block(7,2,-7,CONCRETE:0)
Block(7,2,-6,CONCRETE:0)
Block(7,2,-5,CONCRETE:0)
Block(7,2,-4,CONCRETE:0)
Block(7,2,-3,CONCRETE:0)
Block(7,2,-2,CONCRETE:0)
Block(7,2,-1,CONCRETE:0)
Block(7,2,0,CONCRETE:0)
Block(7,2,1,quark:world_stone_pavement:2)
Block(7,2,2,quark:world_stone_pavement:2)
Block(7,2,3,quark:world_stone_pavement:2)
Block(7,2,4,CONCRETE:0)
Block(7,2,5,quark:world_stone_pavement:2)
Block(7,2,6,quark:world_stone_pavement:2)
Block(7,2,7,CONCRETE:0)
Block(7,2,8,quark:world_stone_pavement:2)
Block(7,3,-7,CONCRETE:0)
Block(7,3,-6,CONCRETE:0)
Block(7,3,-5,quark:world_stone_pavement:2)
Block(7,3,-4,CONCRETE:0)
Block(7,3,-3,CONCRETE:0)
Block(7,3,-2,CONCRETE:0)
Block(7,3,-1,CONCRETE:0)
Block(7,3,0,quark:world_stone_pavement:2)
Block(7,3,1,quark:world_stone_pavement:2)
Block(7,3,2,quark:world_stone_pavement:2)
Block(7,3,3,CONCRETE:0)
Block(7,3,4,CONCRETE:0)
Block(7,3,5,CONCRETE:0)
Block(7,3,6,CONCRETE:0)
Block(7,3,7,CONCRETE:0)
Block(7,3,8,CONCRETE:0)
Block(7,4,-7,CONCRETE:0)
Block(7,4,-6,quark:world_stone_pavement:2)
Block(7,4,-5,CONCRETE:0)
Block(7,4,-4,quark:world_stone_pavement:2)
Block(7,4,-3,CONCRETE:0)
Block(7,4,-2,CONCRETE:0)
Block(7,4,-1,quark:world_stone_pavement:2)
Block(7,4,0,CONCRETE:0)
Block(7,4,1,quark:world_stone_pavement:2)
Block(7,4,2,CONCRETE:0)
Block(7,4,3,CONCRETE:0)
Block(7,4,4,CONCRETE:0)
Block(7,4,5,quark:world_stone_pavement:2)
Block(7,4,6,CONCRETE:0)
Block(7,4,7,quark:world_stone_pavement:2)
Block(7,4,8,quark:world_stone_pavement:2)
Block(7,5,-7,quark:world_stone_pavement:2)
Block(7,5,-6,CONCRETE:0)
Block(7,5,-5,CONCRETE:0)
Block(7,5,-4,quark:world_stone_pavement:2)
Block(7,5,-3,quark:world_stone_pavement:2)
Block(7,5,-2,quark:world_stone_pavement:2)
Block(7,5,-1,CONCRETE:0)
Block(7,5,0,CONCRETE:0)
Block(7,5,1,quark:world_stone_pavement:2)
Block(7,5,2,CONCRETE:0)
Block(7,5,3,CONCRETE:0)
Block(7,5,4,CONCRETE:0)
Block(7,5,5,quark:world_stone_pavement:2)
Block(7,5,6,CONCRETE:0)
Block(7,5,7,CONCRETE:0)
Block(7,5,8,CONCRETE:0)
Block(7,6,-7,CONCRETE:0)
Block(7,6,-6,CONCRETE:0)
Block(7,6,-5,quark:world_stone_pavement:2)
Block(7,6,-4,CONCRETE:0)
Block(7,6,-3,quark:world_stone_pavement:2)
Block(7,6,-2,CONCRETE:0)
Block(7,6,-1,CONCRETE:0)
Block(7,6,0,quark:world_stone_pavement:2)
Block(7,6,1,CONCRETE:0)
Block(7,6,2,CONCRETE:0)
Block(7,6,3,CONCRETE:0)
Block(7,6,4,CONCRETE:0)
Block(7,6,5,CONCRETE:0)
Block(7,6,6,quark:world_stone_pavement:2)
Block(7,6,7,CONCRETE:0)
Block(7,6,8,quark:world_stone_pavement:2)
Block(7,7,-7,CONCRETE:0)
Block(7,7,-6,quark:world_stone_pavement:2)
Block(7,7,-5,quark:world_stone_pavement:2)
Block(7,7,-4,CONCRETE:0)
Block(7,7,-3,CONCRETE:0)
Block(7,7,-2,CONCRETE:0)
Block(7,7,-1,quark:world_stone_pavement:2)
Block(7,7,0,quark:world_stone_pavement:2)
Block(7,7,1,quark:world_stone_pavement:2)
Block(7,7,2,CONCRETE:0)
Block(7,7,3,quark:world_stone_pavement:2)
Block(7,7,4,CONCRETE:0)
Block(7,7,5,quark:world_stone_pavement:2)
Block(7,7,6,CONCRETE:0)
Block(7,7,7,CONCRETE:0)
Block(7,7,8,CONCRETE:0)
Block(7,8,-7,quark:polished_stone:0)
Block(7,8,-6,quark:world_stone_pavement:2)
Block(7,8,-5,quark:world_stone_pavement:2)
Block(7,8,-4,quark:polished_stone:0)
Block(7,8,-3,quark:polished_stone:0)
Block(7,8,-2,quark:polished_stone:0)
Block(7,8,-1,quark:world_stone_pavement:2)
Block(7,8,0,quark:world_stone_pavement:2)
Block(7,8,1,quark:polished_stone:0)
Block(7,8,2,quark:polished_stone:0)
Block(7,8,3,quark:world_stone_pavement:2)
Block(7,8,4,quark:polished_stone:0)
Block(7,8,5,quark:polished_stone:0)
Block(7,8,6,quark:world_stone_pavement:2)
Block(7,8,7,quark:polished_stone:0)
Block(7,8,8,quark:polished_stone:0)
Block(7,9,-7,CONCRETE:0)
Block(7,9,-6,CONCRETE:0)
Block(7,9,-5,CONCRETE:0)
Block(7,9,-4,quark:iron_plate:1)
Block(7,9,-3,quark:iron_plate:1)
Block(7,9,-2,quark:iron_plate:1)
Block(7,9,-1,quark:iron_plate:1)
Block(7,9,0,quark:iron_plate:1)
Block(7,9,1,quark:iron_plate:1)
Block(7,9,2,quark:iron_plate:1)
Block(7,9,3,quark:iron_plate:1)
Block(7,9,4,quark:iron_plate:1)
Block(7,9,5,quark:iron_plate:1)
Block(7,9,6,quark:iron_plate:1)
Block(7,9,7,quark:iron_plate:1)
Block(7,9,8,quark:iron_plate:1)
Block(7,10,-7,quark:world_stone_pavement:2)
Block(7,10,-6,quark:world_stone_pavement:2)
Block(7,10,-5,STAINED_CLAY:5)
Block(7,10,-4,STAINED_CLAY:13)
Block(7,10,-3,STAINED_CLAY:4)
Block(7,10,-2,quark:grate:0)
Block(7,10,-1,quark:grate:0)
Block(7,10,0,quark:grate:0)
Block(7,10,1,quark:grate:0)
Block(7,10,2,quark:grate:0)
Block(7,10,3,quark:grate:0)
Block(7,10,4,quark:grate:0)
Block(7,10,5,quark:grate:0)
Block(7,10,6,quark:grate:0)
Block(7,10,7,quark:grate:0)
Block(7,10,8,quark:grate:0)
Block(7,11,-5,IRON_DOOR_BLOCK:1)
Block(7,12,-5,IRON_DOOR_BLOCK:9)
Block(7,13,-7,quark:polished_stone:0)
Block(7,13,-6,quark:polished_stone:0)
Block(7,13,-5,quark:polished_stone:0)
Block(7,14,-7,CONCRETE:0)
Block(7,14,-6,quark:world_stone_pavement:2)
Block(7,14,-5,quark:iron_plate:1)
Block(7,14,-3,srparasites:infestedbush:4)
Block(7,15,-3,srparasites:infestedbush:4)
Block(7,16,-3,srparasites:infestedbush:4)
Block(7,17,-7,SMOOTH_STAIRS:5)
Block(7,17,-6,SMOOTH_STAIRS:5)
Block(7,17,-5,SMOOTH_STAIRS:5)
Block(7,17,-4,quark:iron_plate:1)
Block(7,17,-3,srparasites:parasiterubbledense:1)
Block(7,17,-2,srparasites:parasiterubbledense:1)
Block(7,17,-1,SMOOTH_STAIRS:5)
Block(7,17,0,SMOOTH_STAIRS:5)
Block(7,17,1,quark:iron_plate:1)
Block(7,17,2,SMOOTH_STAIRS:5)
Block(7,17,3,SMOOTH_STAIRS:5)
Block(7,17,4,SMOOTH_STAIRS:5)
Block(7,17,5,SMOOTH_STAIRS:5)
Block(7,17,6,quark:iron_plate:1)
Block(7,17,7,SMOOTH_STAIRS:5)
Block(7,17,8,SMOOTH_STAIRS:5)
Block(7,18,-7,quark:polished_stone:0)
Block(7,18,-6,quark:polished_stone:0)
Block(7,18,-5,quark:polished_stone:0)
Block(7,18,-4,quark:iron_plate:1)
Block(7,18,-3,quark:polished_stone:0)
Block(7,18,-2,quark:polished_stone:0)
Block(7,18,-1,quark:polished_stone:0)
Block(7,18,0,quark:polished_stone:0)
Block(7,18,1,quark:iron_plate:1)
Block(7,18,2,quark:polished_stone:0)
Block(7,18,3,quark:polished_stone:0)
Block(7,18,4,quark:polished_stone:0)
Block(7,18,5,quark:polished_stone:0)
Block(7,18,6,quark:iron_plate:1)
Block(7,18,7,quark:polished_stone:0)
Block(7,18,8,quark:polished_stone:0)
Block(7,19,-7,STEP:8)
Block(7,19,-6,STEP:8)
Block(7,19,-5,quark:iron_plate:1)
RandomBlock(7,19,-4,IRON_FENCE:0,30,IRON_FENCE:0,100)
RandomBlock(7,20,-5,IRON_FENCE:0,30,IRON_FENCE:0,100)
RandomBlock(7,20,-4,IRON_FENCE:0,30,IRON_FENCE:0,100)
Block(7,511,-7,DIAMOND_BLOCK:0)

#######################################################################
# +-----------------------------------------------------------------+ #
# |                             Branches                            | #
# +-----------------------------------------------------------------+ #
#######################################################################

Branch(0,0,16,true,NuclearPowerPlant_InfectedC2R3,NORTH,100.0,0)

#######################################################################
# +-----------------------------------------------------------------+ #
# |                             Entities                            | #
# +-----------------------------------------------------------------+ #
#######################################################################


#######################################################################
# +-----------------------------------------------------------------+ #
# |                            Particles                            | #
# +-----------------------------------------------------------------+ #
#######################################################################


#######################################################################
# +-----------------------------------------------------------------+ #
# |                             Spawners                            | #
# +-----------------------------------------------------------------+ #
#######################################################################


#######################################################################
# +-----------------------------------------------------------------+ #
# |                             ModData                             | #
# +-----------------------------------------------------------------+ #
#######################################################################

