
#######################################################################
# +-----------------------------------------------------------------+ #
# |                            BO4 object                           | #
# +-----------------------------------------------------------------+ #
#######################################################################

Author: NLBlackEagle

Description: No description given

SettingsMode: WriteWithoutComments


#######################################################################
# +-----------------------------------------------------------------+ #
# |                          Main settings                          | #
# +-----------------------------------------------------------------+ #
#######################################################################

FixedRotation: 

Frequency: 0

SpawnHeight: highestBlock

UseCenterForHighestBlock: true

##############################
# Height Limits for the BO4. #
##############################

MinHeight: 0

MaxHeight: 255

InheritBO3: 

InheritBO3Rotation: NORTH

OverrideChildSettings: true

OverrideParentHeight: false

CanOverride: true

BranchFrequency: 0

BranchFrequencyGroup: 

MustBeBelowOther: false

MustBeInside: 

CannotBeInside: 

ReplacesBO3: 

MustBeInsideWorldBorders: true

CanSpawnOnWater: true

SpawnOnWaterOnly: false

SpawnUnderWater: false

SpawnAtWaterLevel: false

HeightOffset: 0

RemoveAir: false

ReplaceAbove: 

ReplaceBelow: 

ReplaceWithBiomeBlocks: false

ReplaceWithSurfaceBlock: GRASS

ReplaceWithGroundBlock: DIRT

ReplaceWithStoneBlock: STONE

SmoothRadius: 0

SmoothHeightOffset: 0

SmoothStartTop: false

SmoothStartWood: false

SmoothingSurfaceBlock: 

SmoothingGroundBlock: 

BO3Group: 

IsSpawnPoint: false

DoReplaceBlocks: true


#######################################################################
# +-----------------------------------------------------------------+ #
# |                              Blocks                             | #
# +-----------------------------------------------------------------+ #
#######################################################################

Block(-8,0,-7,CONCRETE:0)
Block(-8,0,-6,CONCRETE:0)
Block(-8,0,-5,quark:world_stone_pavement:2)
Block(-8,0,-4,quark:world_stone_pavement:2)
Block(-8,0,-3,CONCRETE:0)
Block(-8,0,-2,CONCRETE:0)
Block(-8,0,-1,CONCRETE:0)
Block(-8,0,0,CONCRETE:0)
Block(-8,0,1,CONCRETE:0)
Block(-8,0,2,CONCRETE:0)
Block(-8,0,3,CONCRETE:0)
Block(-8,1,-7,CONCRETE:0)
Block(-8,1,-6,CONCRETE:0)
Block(-8,1,-5,quark:world_stone_pavement:2)
Block(-8,1,-4,quark:world_stone_pavement:2)
Block(-8,1,-3,quark:world_stone_pavement:2)
Block(-8,1,-2,CONCRETE:0)
Block(-8,1,-1,quark:world_stone_pavement:2)
Block(-8,1,0,CONCRETE:0)
Block(-8,1,1,CONCRETE:0)
Block(-8,1,2,CONCRETE:0)
Block(-8,1,3,CONCRETE:0)
Block(-8,2,-7,quark:world_stone_pavement:2)
Block(-8,2,-6,CONCRETE:0)
Block(-8,2,-5,CONCRETE:0)
Block(-8,2,-4,CONCRETE:0)
Block(-8,2,-3,CONCRETE:0)
Block(-8,2,-2,CONCRETE:0)
Block(-8,2,-1,quark:world_stone_pavement:2)
Block(-8,2,0,CONCRETE:0)
Block(-8,2,1,quark:world_stone_pavement:2)
Block(-8,2,2,quark:world_stone_pavement:2)
Block(-8,2,3,CONCRETE:0)
Block(-8,3,-7,CONCRETE:0)
Block(-8,3,-6,CONCRETE:0)
Block(-8,3,-5,CONCRETE:0)
Block(-8,3,-4,CONCRETE:0)
Block(-8,3,-3,CONCRETE:0)
Block(-8,3,-2,CONCRETE:0)
Block(-8,3,-1,CONCRETE:0)
Block(-8,3,0,quark:world_stone_pavement:2)
Block(-8,3,1,CONCRETE:0)
Block(-8,3,2,CONCRETE:0)
Block(-8,3,3,quark:world_stone_pavement:2)
Block(-8,4,-7,quark:world_stone_pavement:2)
Block(-8,4,-6,quark:world_stone_pavement:2)
Block(-8,4,-5,quark:world_stone_pavement:2)
Block(-8,4,-4,quark:world_stone_pavement:2)
Block(-8,4,-3,CONCRETE:0)
Block(-8,4,-2,CONCRETE:0)
Block(-8,4,-1,CONCRETE:0)
Block(-8,4,0,CONCRETE:0)
Block(-8,4,1,CONCRETE:0)
Block(-8,4,2,CONCRETE:0)
Block(-8,4,3,CONCRETE:0)
Block(-8,5,-7,CONCRETE:0)
Block(-8,5,-6,quark:world_stone_pavement:2)
Block(-8,5,-5,quark:world_stone_pavement:2)
Block(-8,5,-4,quark:world_stone_pavement:2)
Block(-8,5,-3,quark:world_stone_pavement:2)
Block(-8,5,-2,CONCRETE:0)
Block(-8,5,-1,CONCRETE:0)
Block(-8,5,0,quark:world_stone_pavement:2)
Block(-8,5,1,quark:world_stone_pavement:2)
Block(-8,5,2,CONCRETE:0)
Block(-8,5,3,CONCRETE:0)
Block(-8,6,-7,CONCRETE:0)
Block(-8,6,-6,CONCRETE:0)
Block(-8,6,-5,quark:world_stone_pavement:2)
Block(-8,6,-4,quark:world_stone_pavement:2)
Block(-8,6,-3,CONCRETE:0)
Block(-8,6,-2,CONCRETE:0)
Block(-8,6,-1,CONCRETE:0)
Block(-8,6,0,CONCRETE:0)
Block(-8,6,1,CONCRETE:0)
Block(-8,6,2,quark:world_stone_pavement:2)
Block(-8,6,3,CONCRETE:0)
Block(-8,7,-7,quark:world_stone_pavement:2)
Block(-8,7,-6,quark:world_stone_pavement:2)
Block(-8,7,-5,quark:world_stone_pavement:2)
Block(-8,7,-4,quark:world_stone_pavement:2)
Block(-8,7,-3,CONCRETE:0)
Block(-8,7,-2,CONCRETE:0)
Block(-8,7,-1,CONCRETE:0)
Block(-8,7,0,CONCRETE:0)
Block(-8,7,1,CONCRETE:0)
Block(-8,7,2,CONCRETE:0)
Block(-8,7,3,CONCRETE:0)
Block(-8,8,-7,quark:world_stone_pavement:2)
Block(-8,8,-6,CONCRETE:0)
Block(-8,8,-5,quark:polished_stone:0)
Block(-8,8,-4,quark:polished_stone:0)
Block(-8,8,-3,quark:polished_stone:0)
Block(-8,8,-2,CONCRETE:0)
Block(-8,8,-1,CONCRETE:0)
Block(-8,8,0,CONCRETE:0)
Block(-8,8,1,CONCRETE:0)
Block(-8,8,2,quark:world_stone_pavement:2)
Block(-8,8,3,quark:world_stone_pavement:2)
Block(-8,9,-7,quark:iron_plate:1)
Block(-8,9,-6,CONCRETE:0)
Block(-8,9,-5,quark:world_stone_pavement:2)
Block(-8,9,-4,quark:world_stone_pavement:2)
Block(-8,9,-3,quark:polished_stone:0)
Block(-8,9,-2,CONCRETE:0)
Block(-8,9,-1,quark:world_stone_pavement:2)
Block(-8,9,0,CONCRETE:0)
Block(-8,9,1,quark:polished_stone:0)
Block(-8,9,2,quark:polished_stone:0)
Block(-8,9,3,quark:polished_stone:0)
Block(-8,10,-7,STAINED_CLAY:14)
Block(-8,10,-6,quark:iron_plate:1)
Block(-8,10,-5,quark:polished_stone:0)
Block(-8,10,-4,quark:polished_stone:0)
Block(-8,10,-3,quark:polished_stone:0)
Block(-8,10,-2,CONCRETE:0)
Block(-8,10,-1,CONCRETE:0)
Block(-8,10,0,quark:world_stone_pavement:2)
Block(-8,10,1,quark:world_stone_pavement:2)
Block(-8,10,2,quark:polished_stone:0)
Block(-8,10,3,quark:polished_stone:0)
Block(-8,11,-7,IRON_TRAPDOOR:4)
Block(-8,11,-6,quark:iron_plate:1)
RandomBlock(-8,11,-3,IRON_FENCE:0,30,IRON_FENCE:0,100)
Block(-8,11,0,quark:iron_plate:0)
RandomBlock(-8,11,3,CONCRETE:0,40,SMOOTH_BRICK:1,30,SMOOTH_BRICK:2,30,MOSSY_COBBLESTONE:0,30,COBBLESTONE:0,20,CONCRETE:0,100)
Block(-8,12,-7,STAINED_CLAY:4)
Block(-8,12,-6,CONCRETE:4)
RandomBlock(-8,12,-3,IRON_FENCE:0,30,IRON_FENCE:0,100)
Block(-8,12,0,quark:iron_plate_stairs:1)
RandomBlock(-8,12,3,CONCRETE:0,40,SMOOTH_BRICK:1,30,SMOOTH_BRICK:2,30,MOSSY_COBBLESTONE:0,30,COBBLESTONE:0,20,CONCRETE:0,100)
Block(-8,13,-6,quark:iron_plate_slab:0)
RandomBlock(-8,13,-3,IRON_FENCE:0,30,IRON_FENCE:0,100)
Block(-8,13,-2,quark:iron_plate_slab:0)
RandomBlock(-8,13,-1,IRON_FENCE:0,30,IRON_FENCE:0,100)
RandomBlock(-8,13,0,IRON_FENCE:0,30,IRON_FENCE:0,100)
RandomBlock(-8,13,1,IRON_FENCE:0,30,IRON_FENCE:0,100)
Block(-8,13,2,quark:iron_plate_slab:0)
RandomBlock(-8,13,3,CONCRETE:0,40,SMOOTH_BRICK:1,30,SMOOTH_BRICK:2,30,MOSSY_COBBLESTONE:0,30,COBBLESTONE:0,20,CONCRETE:0,100)
RandomBlock(-8,14,-3,IRON_FENCE:0,30,IRON_FENCE:0,100)
Block(-8,14,2,srparasites:parasitethin)
RandomBlock(-8,14,3,CONCRETE:0,40,SMOOTH_BRICK:1,30,SMOOTH_BRICK:2,30,MOSSY_COBBLESTONE:0,30,COBBLESTONE:0,20,CONCRETE:0,100)
Block(-8,15,2,srparasites:parasitethin)
RandomBlock(-8,15,3,CONCRETE:0,40,SMOOTH_BRICK:1,30,SMOOTH_BRICK:2,30,MOSSY_COBBLESTONE:0,30,COBBLESTONE:0,20,CONCRETE:0,100)
Block(-8,16,-4,srparasites:parasitebush:1)
Block(-8,16,2,SMOOTH_STAIRS:6)
Block(-8,16,3,quark:iron_plate:1)
Block(-8,17,-4,srparasites:parasitebush:1)
Block(-8,17,1,SMOOTH_STAIRS:6)
Block(-8,17,2,quark:polished_stone:0)
Block(-8,18,-6,quark:iron_plate:1)
Block(-8,18,-4,srparasites:parasiterubbledense:1)
Block(-8,18,-3,srparasites:parasiterubbledense:1)
Block(-8,18,-2,srparasites:parasiterubbledense:1)
Block(-8,18,-1,quark:iron_plate:1)
Block(-8,18,0,quark:polished_stone:0)
Block(-8,18,1,quark:polished_stone:0)
Block(-8,18,2,SMOOTH_STAIRS:3)
RandomBlock(-8,19,-7,CONCRETE:0,40,SMOOTH_BRICK:1,30,SMOOTH_BRICK:2,30,MOSSY_COBBLESTONE:0,30,COBBLESTONE:0,20,CONCRETE:0,100)
Block(-8,19,-6,quark:iron_plate:1)
RandomBlock(-8,19,-5,CONCRETE:0,40,SMOOTH_BRICK:1,30,SMOOTH_BRICK:2,30,MOSSY_COBBLESTONE:0,30,COBBLESTONE:0,20,CONCRETE:0,100)
RandomBlock(-8,19,-4,CONCRETE:0,40,SMOOTH_BRICK:1,30,SMOOTH_BRICK:2,30,MOSSY_COBBLESTONE:0,30,COBBLESTONE:0,20,CONCRETE:0,100)
RandomBlock(-8,19,-3,CONCRETE:0,40,SMOOTH_BRICK:1,30,SMOOTH_BRICK:2,30,MOSSY_COBBLESTONE:0,30,COBBLESTONE:0,20,CONCRETE:0,100)
RandomBlock(-8,19,-2,CONCRETE:0,40,SMOOTH_BRICK:1,30,SMOOTH_BRICK:2,30,MOSSY_COBBLESTONE:0,30,COBBLESTONE:0,20,CONCRETE:0,100)
Block(-8,19,-1,quark:iron_plate:1)
Block(-8,19,0,SMOOTH_STAIRS:3)
Block(-8,20,-1,quark:stone_diorite_bricks_wall:0)
Block(-7,0,-7,quark:world_stone_pavement:2)
Block(-7,0,-6,quark:world_stone_pavement:2)
Block(-7,0,-5,CONCRETE:0)
Block(-7,0,-4,CONCRETE:0)
Block(-7,0,-3,quark:world_stone_pavement:2)
Block(-7,0,-2,CONCRETE:0)
Block(-7,0,-1,quark:world_stone_pavement:2)
Block(-7,0,0,quark:world_stone_pavement:2)
Block(-7,0,1,CONCRETE:0)
Block(-7,0,2,CONCRETE:0)
Block(-7,0,3,quark:world_stone_pavement:2)
Block(-7,1,-7,quark:world_stone_pavement:2)
Block(-7,1,-6,quark:world_stone_pavement:2)
Block(-7,1,-5,CONCRETE:0)
Block(-7,1,-4,CONCRETE:0)
Block(-7,1,-3,CONCRETE:0)
Block(-7,1,-2,CONCRETE:0)
Block(-7,1,-1,CONCRETE:0)
Block(-7,1,0,CONCRETE:0)
Block(-7,1,1,CONCRETE:0)
Block(-7,1,2,CONCRETE:0)
Block(-7,1,3,CONCRETE:0)
Block(-7,2,-7,quark:world_stone_pavement:2)
Block(-7,2,-6,CONCRETE:0)
Block(-7,2,-5,quark:world_stone_pavement:2)
Block(-7,2,-4,quark:world_stone_pavement:2)
Block(-7,2,-3,CONCRETE:0)
Block(-7,2,-2,CONCRETE:0)
Block(-7,2,-1,CONCRETE:0)
Block(-7,2,0,CONCRETE:0)
Block(-7,2,1,CONCRETE:0)
Block(-7,2,2,quark:world_stone_pavement:2)
Block(-7,2,3,quark:world_stone_pavement:2)
Block(-7,3,-7,quark:world_stone_pavement:2)
Block(-7,3,-6,CONCRETE:0)
Block(-7,3,-5,CONCRETE:0)
Block(-7,3,-4,CONCRETE:0)
Block(-7,3,-3,CONCRETE:0)
Block(-7,3,-2,CONCRETE:0)
Block(-7,3,-1,quark:world_stone_pavement:2)
Block(-7,3,0,quark:world_stone_pavement:2)
Block(-7,3,1,quark:world_stone_pavement:2)
Block(-7,3,2,CONCRETE:0)
Block(-7,3,3,quark:world_stone_pavement:2)
Block(-7,4,-7,CONCRETE:0)
Block(-7,4,-6,quark:world_stone_pavement:2)
Block(-7,4,-5,CONCRETE:0)
Block(-7,4,-4,CONCRETE:0)
Block(-7,4,-3,quark:world_stone_pavement:2)
Block(-7,4,-2,CONCRETE:0)
Block(-7,4,-1,CONCRETE:0)
Block(-7,4,0,CONCRETE:0)
Block(-7,4,1,CONCRETE:0)
Block(-7,4,2,CONCRETE:0)
Block(-7,4,3,CONCRETE:0)
Block(-7,5,-7,quark:world_stone_pavement:2)
Block(-7,5,-6,quark:world_stone_pavement:2)
Block(-7,5,-5,CONCRETE:0)
Block(-7,5,-4,CONCRETE:0)
Block(-7,5,-3,CONCRETE:0)
Block(-7,5,-2,quark:world_stone_pavement:2)
Block(-7,5,-1,CONCRETE:0)
Block(-7,5,0,quark:world_stone_pavement:2)
Block(-7,5,1,CONCRETE:0)
Block(-7,5,2,CONCRETE:0)
Block(-7,5,3,CONCRETE:0)
Block(-7,6,-7,CONCRETE:0)
Block(-7,6,-6,quark:world_stone_pavement:2)
Block(-7,6,-5,CONCRETE:0)
Block(-7,6,-4,CONCRETE:0)
Block(-7,6,-3,CONCRETE:0)
Block(-7,6,-2,CONCRETE:0)
Block(-7,6,-1,CONCRETE:0)
Block(-7,6,0,quark:world_stone_pavement:2)
Block(-7,6,1,CONCRETE:0)
Block(-7,6,2,CONCRETE:0)
Block(-7,6,3,CONCRETE:0)
Block(-7,7,-7,CONCRETE:0)
Block(-7,7,-6,CONCRETE:0)
Block(-7,7,-5,CONCRETE:0)
Block(-7,7,-4,CONCRETE:0)
Block(-7,7,-3,quark:world_stone_pavement:2)
Block(-7,7,-2,quark:world_stone_pavement:2)
Block(-7,7,-1,CONCRETE:0)
Block(-7,7,0,quark:world_stone_pavement:2)
Block(-7,7,1,quark:world_stone_pavement:2)
Block(-7,7,2,CONCRETE:0)
Block(-7,7,3,quark:world_stone_pavement:2)
Block(-7,8,-7,quark:world_stone_pavement:2)
Block(-7,8,-6,quark:world_stone_pavement:2)
Block(-7,8,-5,quark:polished_stone:0)
Block(-7,8,-4,quark:polished_stone:0)
Block(-7,8,-3,quark:polished_stone:0)
Block(-7,8,-2,quark:world_stone_pavement:2)
Block(-7,8,-1,CONCRETE:0)
Block(-7,8,0,quark:world_stone_pavement:2)
Block(-7,8,1,CONCRETE:0)
Block(-7,8,2,quark:world_stone_pavement:2)
Block(-7,8,3,quark:polished_stone:0)
Block(-7,9,-7,quark:world_stone_pavement:2)
Block(-7,9,-6,CONCRETE:0)
Block(-7,9,-5,quark:polished_stone:0)
Block(-7,9,-4,quark:polished_stone:0)
Block(-7,9,-3,quark:world_stone_pavement:2)
Block(-7,9,-2,quark:world_stone_pavement:2)
Block(-7,9,-1,quark:polished_stone:0)
Block(-7,9,0,quark:polished_stone:0)
Block(-7,9,1,quark:polished_stone:0)
Block(-7,9,2,quark:world_stone_pavement:2)
Block(-7,9,3,quark:polished_stone:0)
Block(-7,10,-7,quark:iron_plate:1)
Block(-7,10,-6,quark:iron_plate:1)
Block(-7,10,-5,quark:world_stone_pavement:2)
Block(-7,10,-4,quark:world_stone_pavement:2)
Block(-7,10,-3,quark:world_stone_pavement:2)
Block(-7,10,-2,quark:world_stone_pavement:2)
Block(-7,10,-1,quark:world_stone_pavement:2)
Block(-7,10,0,quark:polished_stone:0)
Block(-7,10,1,quark:world_stone_pavement:2)
Block(-7,10,2,quark:polished_stone:0)
Block(-7,10,3,quark:polished_stone:0)
Block(-7,11,-7,quark:iron_plate:1)
Block(-7,11,-6,quark:iron_plate:1)
RandomBlock(-7,11,-3,IRON_FENCE:0,30,IRON_FENCE:0,100)
Block(-7,11,3,DOUBLE_STEP:0)
Block(-7,12,-6,quark:stone_limestone_bricks_stairs:1)
RandomBlock(-7,12,-3,IRON_FENCE:0,30,IRON_FENCE:0,100)
RandomBlock(-7,12,-2,IRON_FENCE:0,30,IRON_FENCE:0,100)
Block(-7,12,-1,quark:grate:0)
Block(-7,12,0,quark:grate:0)
Block(-7,12,1,quark:grate:0)
Block(-7,12,2,quark:grate:0)
Block(-7,12,3,DOUBLE_STEP:0)
RandomBlock(-7,13,-3,IRON_FENCE:0,30,IRON_FENCE:0,100)
Block(-7,13,-2,quark:iron_plate_slab:0)
Block(-7,13,-1,quark:iron_plate_slab:0)
Block(-7,13,0,quark:iron_plate_slab:0)
Block(-7,13,1,quark:iron_plate_slab:0)
Block(-7,13,2,quark:iron_plate_slab:0)
Block(-7,13,3,DOUBLE_STEP:0)
Block(-7,14,-6,srparasites:parasitethin)
RandomBlock(-7,14,-3,IRON_FENCE:0,30,IRON_FENCE:0,100)
Block(-7,14,2,srparasites:parasitethin)
Block(-7,14,3,DOUBLE_STEP:0)
Block(-7,15,-6,srparasites:parasitethin)
Block(-7,15,2,srparasites:parasitethin)
Block(-7,15,3,DOUBLE_STEP:0)
Block(-7,16,-6,srparasites:parasitethin)
Block(-7,16,2,SMOOTH_STAIRS:6)
Block(-7,16,3,quark:iron_plate:1)
Block(-7,17,-6,srparasites:parasitethin)
Block(-7,17,1,SMOOTH_STAIRS:6)
Block(-7,17,2,quark:polished_stone:0)
Block(-7,18,-7,SMOOTH_STAIRS:4)
Block(-7,18,-6,quark:iron_plate:1)
Block(-7,18,-5,SMOOTH_STAIRS:4)
Block(-7,18,-4,SMOOTH_STAIRS:4)
Block(-7,18,-3,SMOOTH_STAIRS:4)
Block(-7,18,-2,SMOOTH_STAIRS:4)
Block(-7,18,-1,quark:iron_plate:1)
Block(-7,18,0,quark:polished_stone:0)
Block(-7,18,1,quark:polished_stone:0)
Block(-7,18,2,SMOOTH_STAIRS:3)
Block(-7,19,-7,quark:iron_plate:1)
Block(-7,19,-6,quark:iron_plate:1)
Block(-7,19,-5,quark:iron_plate:1)
Block(-7,19,-4,quark:iron_plate:1)
Block(-7,19,-3,quark:iron_plate:1)
Block(-7,19,-2,quark:iron_plate:1)
Block(-7,19,-1,quark:iron_plate:1)
Block(-7,19,0,SMOOTH_STAIRS:3)
Block(-7,20,-7,quark:stone_diorite_bricks_wall:0)
Block(-7,20,-6,quark:stone_diorite_bricks_wall:0)
Block(-7,20,-5,quark:stone_diorite_bricks_wall:0)
Block(-7,20,-4,quark:stone_diorite_bricks_wall:0)
Block(-7,20,-3,quark:stone_diorite_bricks_wall:0)
Block(-7,20,-2,quark:stone_diorite_bricks_wall:0)
Block(-7,20,-1,quark:stone_diorite_bricks_wall:0)
Block(-6,0,-7,quark:world_stone_pavement:2)
Block(-6,0,-6,CONCRETE:0)
Block(-6,0,-5,CONCRETE:0)
Block(-6,0,-4,CONCRETE:0)
Block(-6,0,-3,quark:world_stone_pavement:2)
Block(-6,0,-2,CONCRETE:0)
Block(-6,0,-1,quark:world_stone_pavement:2)
Block(-6,0,0,CONCRETE:0)
Block(-6,0,1,quark:world_stone_pavement:2)
Block(-6,0,2,CONCRETE:0)
Block(-6,0,3,CONCRETE:0)
Block(-6,1,-7,CONCRETE:0)
Block(-6,1,-6,CONCRETE:0)
Block(-6,1,-5,quark:world_stone_pavement:2)
Block(-6,1,-4,quark:world_stone_pavement:2)
Block(-6,1,-3,CONCRETE:0)
Block(-6,1,-2,quark:world_stone_pavement:2)
Block(-6,1,-1,CONCRETE:0)
Block(-6,1,0,CONCRETE:0)
Block(-6,1,1,CONCRETE:0)
Block(-6,1,2,quark:world_stone_pavement:2)
Block(-6,1,3,CONCRETE:0)
Block(-6,2,-7,quark:world_stone_pavement:2)
Block(-6,2,-6,CONCRETE:0)
Block(-6,2,-5,quark:world_stone_pavement:2)
Block(-6,2,-4,quark:world_stone_pavement:2)
Block(-6,2,-3,quark:world_stone_pavement:2)
Block(-6,2,-2,CONCRETE:0)
Block(-6,2,-1,CONCRETE:0)
Block(-6,2,0,CONCRETE:0)
Block(-6,2,1,quark:world_stone_pavement:2)
Block(-6,2,2,CONCRETE:0)
Block(-6,2,3,CONCRETE:0)
Block(-6,3,-7,CONCRETE:0)
Block(-6,3,-6,quark:world_stone_pavement:2)
Block(-6,3,-5,quark:world_stone_pavement:2)
Block(-6,3,-4,quark:world_stone_pavement:2)
Block(-6,3,-3,CONCRETE:0)
Block(-6,3,-2,CONCRETE:0)
Block(-6,3,-1,CONCRETE:0)
Block(-6,3,0,CONCRETE:0)
Block(-6,3,1,quark:world_stone_pavement:2)
Block(-6,3,2,quark:world_stone_pavement:2)
Block(-6,3,3,quark:world_stone_pavement:2)
Block(-6,4,-7,CONCRETE:0)
Block(-6,4,-6,CONCRETE:0)
Block(-6,4,-5,CONCRETE:0)
Block(-6,4,-4,CONCRETE:0)
Block(-6,4,-3,CONCRETE:0)
Block(-6,4,-2,CONCRETE:0)
Block(-6,4,-1,CONCRETE:0)
Block(-6,4,0,quark:world_stone_pavement:2)
Block(-6,4,1,quark:world_stone_pavement:2)
Block(-6,4,2,CONCRETE:0)
Block(-6,4,3,CONCRETE:0)
Block(-6,5,-7,CONCRETE:0)
Block(-6,5,-6,CONCRETE:0)
Block(-6,5,-5,CONCRETE:0)
Block(-6,5,-4,CONCRETE:0)
Block(-6,5,-3,quark:world_stone_pavement:2)
Block(-6,5,-2,quark:world_stone_pavement:2)
Block(-6,5,-1,quark:world_stone_pavement:2)
Block(-6,5,0,CONCRETE:0)
Block(-6,5,1,CONCRETE:0)
Block(-6,5,2,CONCRETE:0)
Block(-6,5,3,quark:world_stone_pavement:2)
Block(-6,6,-7,quark:world_stone_pavement:2)
Block(-6,6,-6,CONCRETE:0)
Block(-6,6,-5,quark:world_stone_pavement:2)
Block(-6,6,-4,quark:world_stone_pavement:2)
Block(-6,6,-3,CONCRETE:0)
Block(-6,6,-2,CONCRETE:0)
Block(-6,6,-1,quark:world_stone_pavement:2)
Block(-6,6,0,quark:world_stone_pavement:2)
Block(-6,6,1,CONCRETE:0)
Block(-6,6,2,CONCRETE:0)
Block(-6,6,3,CONCRETE:0)
Block(-6,7,-7,CONCRETE:0)
Block(-6,7,-6,CONCRETE:0)
Block(-6,7,-5,CONCRETE:0)
Block(-6,7,-4,CONCRETE:0)
Block(-6,7,-3,CONCRETE:0)
Block(-6,7,-2,CONCRETE:0)
Block(-6,7,-1,CONCRETE:0)
Block(-6,7,0,CONCRETE:0)
Block(-6,7,1,CONCRETE:0)
Block(-6,7,2,CONCRETE:0)
Block(-6,7,3,quark:world_stone_pavement:2)
Block(-6,8,-7,quark:polished_stone:0)
Block(-6,8,-6,quark:polished_stone:0)
Block(-6,8,-5,quark:polished_stone:0)
Block(-6,8,-4,quark:polished_stone:0)
Block(-6,8,-3,quark:polished_stone:0)
Block(-6,8,-2,quark:world_stone_pavement:2)
Block(-6,8,-1,quark:polished_stone:0)
Block(-6,8,0,quark:world_stone_pavement:2)
Block(-6,8,1,quark:world_stone_pavement:2)
Block(-6,8,2,quark:world_stone_pavement:2)
Block(-6,8,3,quark:polished_stone:0)
Block(-6,9,-7,quark:world_stone_pavement:2)
Block(-6,9,-6,quark:polished_stone:0)
Block(-6,9,-5,quark:polished_stone:0)
Block(-6,9,-4,quark:polished_stone:0)
Block(-6,9,-3,quark:world_stone_pavement:2)
Block(-6,9,-2,quark:polished_stone:0)
Block(-6,9,-1,quark:world_stone_pavement:2)
Block(-6,9,0,quark:world_stone_pavement:2)
Block(-6,9,1,quark:world_stone_pavement:2)
Block(-6,9,2,quark:polished_stone:0)
Block(-6,9,3,quark:world_stone_pavement:2)
Block(-6,10,-7,quark:polished_stone:0)
Block(-6,10,-6,quark:polished_stone:0)
Block(-6,10,-5,quark:polished_stone:0)
Block(-6,10,-4,quark:polished_stone:0)
Block(-6,10,-3,quark:world_stone_pavement:2)
Block(-6,10,-2,quark:polished_stone:0)
Block(-6,10,-1,quark:polished_stone:0)
Block(-6,10,0,quark:world_stone_pavement:2)
Block(-6,10,1,quark:polished_stone:0)
Block(-6,10,2,quark:polished_stone:0)
Block(-6,10,3,quark:world_stone_pavement:2)
RandomBlock(-6,11,-3,IRON_FENCE:0,30,IRON_FENCE:0,100)
RandomBlock(-6,11,3,CONCRETE:0,40,SMOOTH_BRICK:1,30,SMOOTH_BRICK:2,30,MOSSY_COBBLESTONE:0,30,COBBLESTONE:0,20,CONCRETE:0,100)
RandomBlock(-6,12,-3,IRON_FENCE:0,30,IRON_FENCE:0,100)
Block(-6,12,-1,quark:grate:0)
Block(-6,12,0,quark:grate:0)
Block(-6,12,1,quark:grate:0)
Block(-6,12,2,quark:grate:0)
RandomBlock(-6,12,3,CONCRETE:0,40,SMOOTH_BRICK:1,30,SMOOTH_BRICK:2,30,MOSSY_COBBLESTONE:0,30,COBBLESTONE:0,20,CONCRETE:0,100)
RandomBlock(-6,13,-3,IRON_FENCE:0,30,IRON_FENCE:0,100)
Block(-6,13,-2,quark:iron_plate_slab:0)
Block(-6,13,2,quark:iron_plate_slab:0)
RandomBlock(-6,13,3,CONCRETE:0,40,SMOOTH_BRICK:1,30,SMOOTH_BRICK:2,30,MOSSY_COBBLESTONE:0,30,COBBLESTONE:0,20,CONCRETE:0,100)
Block(-6,14,-7,srparasites:parasitethin)
Block(-6,14,-5,srparasites:parasitethin)
RandomBlock(-6,14,-3,IRON_FENCE:0,30,IRON_FENCE:0,100)
Block(-6,14,2,srparasites:parasitethin)
RandomBlock(-6,14,3,CONCRETE:0,40,SMOOTH_BRICK:1,30,SMOOTH_BRICK:2,30,MOSSY_COBBLESTONE:0,30,COBBLESTONE:0,20,CONCRETE:0,100)
Block(-6,15,-7,srparasites:parasitethin)
Block(-6,15,-5,srparasites:parasitethin)
Block(-6,15,2,srparasites:parasitethin)
RandomBlock(-6,15,3,CONCRETE:0,40,SMOOTH_BRICK:1,30,SMOOTH_BRICK:2,30,MOSSY_COBBLESTONE:0,30,COBBLESTONE:0,20,CONCRETE:0,100)
Block(-6,16,-7,srparasites:parasitethin)
Block(-6,16,-5,srparasites:parasitethin)
Block(-6,16,2,SMOOTH_STAIRS:6)
Block(-6,16,3,quark:iron_plate:1)
Block(-6,17,-7,srparasites:parasitethin)
Block(-6,17,-6,quark:iron_plate:1)
Block(-6,17,-5,srparasites:parasitethin)
Block(-6,17,-1,quark:iron_plate:1)
Block(-6,17,1,SMOOTH_STAIRS:6)
Block(-6,17,2,quark:polished_stone:0)
Block(-6,18,-7,quark:polished_stone:0)
Block(-6,18,-6,quark:iron_plate:1)
Block(-6,18,-5,quark:polished_stone:0)
Block(-6,18,-4,quark:polished_stone:0)
Block(-6,18,-3,quark:polished_stone:0)
Block(-6,18,-2,quark:polished_stone:0)
Block(-6,18,-1,quark:iron_plate:1)
Block(-6,18,0,quark:polished_stone:0)
Block(-6,18,1,quark:polished_stone:0)
Block(-6,18,2,SMOOTH_STAIRS:3)
Block(-6,19,-7,SMOOTH_STAIRS:1)
Block(-6,19,-6,SMOOTH_STAIRS:1)
Block(-6,19,-5,SMOOTH_STAIRS:1)
Block(-6,19,-4,SMOOTH_STAIRS:1)
Block(-6,19,-3,SMOOTH_STAIRS:1)
Block(-6,19,-2,SMOOTH_STAIRS:1)
Block(-6,19,-1,SMOOTH_STAIRS:1)
Block(-6,19,0,SMOOTH_STAIRS:1)
Block(-5,0,-7,quark:world_stone_pavement:2)
Block(-5,0,-6,CONCRETE:0)
Block(-5,0,-5,CONCRETE:0)
Block(-5,0,-4,CONCRETE:0)
Block(-5,0,-3,quark:world_stone_pavement:2)
Block(-5,0,-2,quark:world_stone_pavement:2)
Block(-5,0,-1,CONCRETE:0)
Block(-5,0,0,quark:world_stone_pavement:2)
Block(-5,0,1,CONCRETE:0)
Block(-5,0,2,CONCRETE:0)
Block(-5,0,3,CONCRETE:0)
Block(-5,1,-7,quark:world_stone_pavement:2)
Block(-5,1,-6,quark:world_stone_pavement:2)
Block(-5,1,-5,CONCRETE:0)
Block(-5,1,-4,CONCRETE:0)
Block(-5,1,-3,CONCRETE:0)
Block(-5,1,-2,quark:world_stone_pavement:2)
Block(-5,1,-1,quark:world_stone_pavement:2)
Block(-5,1,0,CONCRETE:0)
Block(-5,1,1,CONCRETE:0)
Block(-5,1,2,quark:world_stone_pavement:2)
Block(-5,1,3,CONCRETE:0)
Block(-5,2,-7,quark:world_stone_pavement:2)
Block(-5,2,-6,quark:world_stone_pavement:2)
Block(-5,2,-5,CONCRETE:0)
Block(-5,2,-4,CONCRETE:0)
Block(-5,2,-3,CONCRETE:0)
Block(-5,2,-2,CONCRETE:0)
Block(-5,2,-1,CONCRETE:0)
Block(-5,2,0,CONCRETE:0)
Block(-5,2,1,CONCRETE:0)
Block(-5,2,2,CONCRETE:0)
Block(-5,2,3,CONCRETE:0)
Block(-5,3,-7,quark:world_stone_pavement:2)
Block(-5,3,-6,CONCRETE:0)
Block(-5,3,-5,quark:world_stone_pavement:2)
Block(-5,3,-4,quark:world_stone_pavement:2)
Block(-5,3,-3,CONCRETE:0)
Block(-5,3,-2,quark:world_stone_pavement:2)
Block(-5,3,-1,CONCRETE:0)
Block(-5,3,0,quark:world_stone_pavement:2)
Block(-5,3,1,quark:world_stone_pavement:2)
Block(-5,3,2,quark:world_stone_pavement:2)
Block(-5,3,3,CONCRETE:0)
Block(-5,4,-7,quark:world_stone_pavement:2)
Block(-5,4,-6,quark:world_stone_pavement:2)
Block(-5,4,-5,CONCRETE:0)
Block(-5,4,-4,CONCRETE:0)
Block(-5,4,-3,quark:world_stone_pavement:2)
Block(-5,4,-2,CONCRETE:0)
Block(-5,4,-1,CONCRETE:0)
Block(-5,4,0,quark:world_stone_pavement:2)
Block(-5,4,1,CONCRETE:0)
Block(-5,4,2,CONCRETE:0)
Block(-5,4,3,CONCRETE:0)
Block(-5,5,-7,CONCRETE:0)
Block(-5,5,-6,CONCRETE:0)
Block(-5,5,-5,quark:world_stone_pavement:2)
Block(-5,5,-4,quark:world_stone_pavement:2)
Block(-5,5,-3,quark:world_stone_pavement:2)
Block(-5,5,-2,quark:world_stone_pavement:2)
Block(-5,5,-1,CONCRETE:0)
Block(-5,5,0,CONCRETE:0)
Block(-5,5,1,CONCRETE:0)
Block(-5,5,2,CONCRETE:0)
Block(-5,5,3,CONCRETE:0)
Block(-5,6,-7,CONCRETE:0)
Block(-5,6,-6,CONCRETE:0)
Block(-5,6,-5,CONCRETE:0)
Block(-5,6,-4,CONCRETE:0)
Block(-5,6,-3,quark:world_stone_pavement:2)
Block(-5,6,-2,quark:world_stone_pavement:2)
Block(-5,6,-1,quark:world_stone_pavement:2)
Block(-5,6,0,CONCRETE:0)
Block(-5,6,1,CONCRETE:0)
Block(-5,6,2,CONCRETE:0)
Block(-5,6,3,quark:world_stone_pavement:2)
Block(-5,7,-7,quark:world_stone_pavement:2)
Block(-5,7,-6,CONCRETE:0)
Block(-5,7,-5,CONCRETE:0)
Block(-5,7,-4,CONCRETE:0)
Block(-5,7,-3,quark:world_stone_pavement:2)
Block(-5,7,-2,CONCRETE:0)
Block(-5,7,-1,quark:world_stone_pavement:2)
Block(-5,7,0,quark:world_stone_pavement:2)
Block(-5,7,1,quark:world_stone_pavement:2)
Block(-5,7,2,CONCRETE:0)
Block(-5,7,3,CONCRETE:0)
Block(-5,8,-7,quark:polished_stone:0)
Block(-5,8,-6,quark:world_stone_pavement:2)
Block(-5,8,-5,quark:polished_stone:0)
Block(-5,8,-4,quark:polished_stone:0)
Block(-5,8,-3,quark:polished_stone:0)
Block(-5,8,-2,quark:polished_stone:0)
Block(-5,8,-1,quark:polished_stone:0)
Block(-5,8,0,quark:polished_stone:0)
Block(-5,8,1,CONCRETE:0)
Block(-5,8,2,quark:polished_stone:0)
Block(-5,8,3,quark:world_stone_pavement:2)
Block(-5,9,-7,quark:polished_stone:0)
Block(-5,9,-6,quark:world_stone_pavement:2)
Block(-5,9,-5,quark:polished_stone:0)
Block(-5,9,-4,quark:polished_stone:0)
Block(-5,9,-3,quark:world_stone_pavement:2)
Block(-5,9,-2,quark:world_stone_pavement:2)
Block(-5,9,-1,quark:polished_stone:0)
Block(-5,9,0,quark:world_stone_pavement:2)
Block(-5,9,1,quark:world_stone_pavement:2)
Block(-5,9,2,quark:polished_stone:0)
Block(-5,9,3,quark:world_stone_pavement:2)
Block(-5,10,-7,quark:polished_stone:0)
Block(-5,10,-6,quark:polished_stone:0)
Block(-5,10,-5,quark:polished_stone:0)
Block(-5,10,-4,srparasites:parasiterubbledense:1)
Block(-5,10,-3,srparasites:parasiterubbledense:1)
Block(-5,10,-2,srparasites:parasiterubbledense:1)
Block(-5,10,-1,quark:world_stone_pavement:2)
Block(-5,10,0,quark:world_stone_pavement:2)
Block(-5,10,1,quark:world_stone_pavement:2)
Block(-5,10,2,quark:polished_stone:0)
Block(-5,10,3,quark:world_stone_pavement:2)
RandomBlock(-5,11,-3,IRON_FENCE:0,30,IRON_FENCE:0,100)
Block(-5,11,3,DOUBLE_STEP:0)
Block(-5,12,-6,srparasites:parasitethin)
RandomBlock(-5,12,-3,IRON_FENCE:0,30,IRON_FENCE:0,100)
Block(-5,12,-1,quark:grate:0)
Block(-5,12,0,quark:grate:0)
Block(-5,12,1,quark:grate:0)
Block(-5,12,2,quark:grate:0)
Block(-5,12,3,DOUBLE_STEP:0)
Block(-5,13,-6,srparasites:parasitethin)
RandomBlock(-5,13,-3,IRON_FENCE:0,30,IRON_FENCE:0,100)
Block(-5,13,-2,quark:iron_plate_slab:0)
Block(-5,13,2,quark:iron_plate_slab:0)
Block(-5,13,3,DOUBLE_STEP:0)
Block(-5,14,-6,srparasites:parasitethin)
RandomBlock(-5,14,-3,IRON_FENCE:0,30,IRON_FENCE:0,100)
Block(-5,14,3,DOUBLE_STEP:0)
Block(-5,15,-6,srparasites:parasitethin)
Block(-5,15,3,DOUBLE_STEP:0)
Block(-5,16,-6,srparasites:parasitethin)
Block(-5,16,2,SMOOTH_STAIRS:6)
Block(-5,16,3,quark:iron_plate:1)
Block(-5,17,-7,SMOOTH_STAIRS:4)
Block(-5,17,-6,quark:iron_plate:1)
Block(-5,17,-5,SMOOTH_STAIRS:4)
Block(-5,17,-4,SMOOTH_STAIRS:4)
Block(-5,17,-3,SMOOTH_STAIRS:4)
Block(-5,17,-2,SMOOTH_STAIRS:4)
Block(-5,17,-1,quark:iron_plate:1)
Block(-5,17,0,SMOOTH_STAIRS:4)
Block(-5,17,1,SMOOTH_STAIRS:4)
Block(-5,17,2,quark:polished_stone:0)
Block(-5,18,-7,quark:polished_stone:0)
Block(-5,18,-6,quark:iron_plate:1)
Block(-5,18,-5,quark:polished_stone:0)
Block(-5,18,-4,quark:polished_stone:0)
Block(-5,18,-3,quark:polished_stone:0)
Block(-5,18,-2,quark:polished_stone:0)
Block(-5,18,-1,quark:iron_plate:1)
Block(-5,18,0,quark:polished_stone:0)
Block(-5,18,1,quark:polished_stone:0)
Block(-5,18,2,SMOOTH_STAIRS:3)
Block(-4,0,-7,quark:world_stone_pavement:2)
Block(-4,0,-6,quark:world_stone_pavement:2)
Block(-4,0,-5,CONCRETE:0)
Block(-4,0,-4,CONCRETE:0)
Block(-4,0,-3,CONCRETE:0)
Block(-4,0,-2,quark:world_stone_pavement:2)
Block(-4,0,-1,CONCRETE:0)
Block(-4,0,0,CONCRETE:0)
Block(-4,0,1,quark:world_stone_pavement:2)
Block(-4,0,2,quark:world_stone_pavement:2)
Block(-4,0,3,CONCRETE:0)
Block(-4,1,-7,quark:world_stone_pavement:2)
Block(-4,1,-6,CONCRETE:0)
Block(-4,1,-5,quark:world_stone_pavement:2)
Block(-4,1,-4,quark:world_stone_pavement:2)
Block(-4,1,-3,CONCRETE:0)
Block(-4,1,-2,quark:world_stone_pavement:2)
Block(-4,1,-1,quark:world_stone_pavement:2)
Block(-4,1,0,CONCRETE:0)
Block(-4,1,1,CONCRETE:0)
Block(-4,1,2,CONCRETE:0)
Block(-4,1,3,quark:world_stone_pavement:2)
Block(-4,2,-7,quark:world_stone_pavement:2)
Block(-4,2,-6,CONCRETE:0)
Block(-4,2,-5,CONCRETE:0)
Block(-4,2,-4,CONCRETE:0)
Block(-4,2,-3,quark:world_stone_pavement:2)
Block(-4,2,-2,CONCRETE:0)
Block(-4,2,-1,CONCRETE:0)
Block(-4,2,0,quark:world_stone_pavement:2)
Block(-4,2,1,CONCRETE:0)
Block(-4,2,2,CONCRETE:0)
Block(-4,2,3,CONCRETE:0)
Block(-4,3,-7,quark:world_stone_pavement:2)
Block(-4,3,-6,quark:world_stone_pavement:2)
Block(-4,3,-5,CONCRETE:0)
Block(-4,3,-4,CONCRETE:0)
Block(-4,3,-3,CONCRETE:0)
Block(-4,3,-2,quark:world_stone_pavement:2)
Block(-4,3,-1,CONCRETE:0)
Block(-4,3,0,quark:world_stone_pavement:2)
Block(-4,3,1,quark:world_stone_pavement:2)
Block(-4,3,2,CONCRETE:0)
Block(-4,3,3,CONCRETE:0)
Block(-4,4,-7,quark:world_stone_pavement:2)
Block(-4,4,-6,quark:world_stone_pavement:2)
Block(-4,4,-5,CONCRETE:0)
Block(-4,4,-4,CONCRETE:0)
Block(-4,4,-3,quark:world_stone_pavement:2)
Block(-4,4,-2,CONCRETE:0)
Block(-4,4,-1,CONCRETE:0)
Block(-4,4,0,CONCRETE:0)
Block(-4,4,1,quark:world_stone_pavement:2)
Block(-4,4,2,CONCRETE:0)
Block(-4,4,3,quark:world_stone_pavement:2)
Block(-4,5,-7,quark:world_stone_pavement:2)
Block(-4,5,-6,quark:world_stone_pavement:2)
Block(-4,5,-5,CONCRETE:0)
Block(-4,5,-4,CONCRETE:0)
Block(-4,5,-3,CONCRETE:0)
Block(-4,5,-2,CONCRETE:0)
Block(-4,5,-1,CONCRETE:0)
Block(-4,5,0,CONCRETE:0)
Block(-4,5,1,quark:world_stone_pavement:2)
Block(-4,5,2,quark:world_stone_pavement:2)
Block(-4,5,3,quark:world_stone_pavement:2)
Block(-4,6,-7,CONCRETE:0)
Block(-4,6,-6,CONCRETE:0)
Block(-4,6,-5,quark:world_stone_pavement:2)
Block(-4,6,-4,quark:world_stone_pavement:2)
Block(-4,6,-3,quark:world_stone_pavement:2)
Block(-4,6,-2,CONCRETE:0)
Block(-4,6,-1,quark:world_stone_pavement:2)
Block(-4,6,0,CONCRETE:0)
Block(-4,6,1,CONCRETE:0)
Block(-4,6,2,CONCRETE:0)
Block(-4,6,3,CONCRETE:0)
Block(-4,7,-7,quark:world_stone_pavement:2)
Block(-4,7,-6,quark:world_stone_pavement:2)
Block(-4,7,-5,quark:world_stone_pavement:2)
Block(-4,7,-4,quark:world_stone_pavement:2)
Block(-4,7,-3,CONCRETE:0)
Block(-4,7,-2,CONCRETE:0)
Block(-4,7,-1,CONCRETE:0)
Block(-4,7,0,CONCRETE:0)
Block(-4,7,1,CONCRETE:0)
Block(-4,7,2,CONCRETE:0)
Block(-4,7,3,CONCRETE:0)
Block(-4,8,-7,quark:polished_stone:0)
Block(-4,8,-6,quark:world_stone_pavement:2)
Block(-4,8,-5,quark:polished_stone:0)
Block(-4,8,-4,quark:polished_stone:0)
Block(-4,8,-3,CONCRETE:0)
Block(-4,8,-2,quark:world_stone_pavement:2)
Block(-4,8,-1,quark:world_stone_pavement:2)
Block(-4,8,0,quark:polished_stone:0)
Block(-4,8,1,CONCRETE:0)
Block(-4,8,2,quark:polished_stone:0)
Block(-4,8,3,quark:world_stone_pavement:2)
Block(-4,9,-7,quark:polished_stone:0)
Block(-4,9,-6,quark:world_stone_pavement:2)
Block(-4,9,-5,quark:polished_stone:0)
Block(-4,9,-4,quark:polished_stone:0)
Block(-4,9,-3,quark:polished_stone:0)
Block(-4,9,-2,quark:polished_stone:0)
Block(-4,9,-1,quark:polished_stone:0)
Block(-4,9,0,quark:polished_stone:0)
Block(-4,9,1,quark:world_stone_pavement:2)
Block(-4,9,2,quark:polished_stone:0)
Block(-4,9,3,quark:polished_stone:0)
Block(-4,10,-7,quark:world_stone_pavement:2)
Block(-4,10,-6,quark:polished_stone:0)
Block(-4,10,-5,quark:polished_stone:0)
Block(-4,10,-4,quark:polished_stone:0)
Block(-4,10,-3,quark:polished_stone:0)
Block(-4,10,-2,quark:polished_stone:0)
Block(-4,10,-1,quark:world_stone_pavement:2)
Block(-4,10,0,quark:polished_stone:0)
Block(-4,10,1,quark:world_stone_pavement:2)
Block(-4,10,2,quark:polished_stone:0)
Block(-4,10,3,quark:polished_stone:0)
Block(-4,11,-7,srparasites:parasitethin)
Block(-4,11,-5,srparasites:parasitethin)
RandomBlock(-4,11,-3,IRON_FENCE:0,30,IRON_FENCE:0,100)
RandomBlock(-4,11,2,CHEST:2,../../../../Chests/Loot/manhunt_military_common.nbt,20,CHEST:2,../../../../Chests/Loot/manhunt_military_rare.nbt,10,CHEST:2,../../../../Chests/Loot/manhunt_strategic_cache.nbt,5,CHEST:2,../../../../Chests/Loot/manhunt_military_common.nbt,50,CHEST:2,../../../../Chests/Loot/manhunt_military_rare.nbt,100)
RandomBlock(-4,11,3,CONCRETE:0,40,SMOOTH_BRICK:1,30,SMOOTH_BRICK:2,30,MOSSY_COBBLESTONE:0,30,COBBLESTONE:0,20,CONCRETE:0,100)
Block(-4,12,-7,srparasites:parasitethin)
Block(-4,12,-6,srparasites:parasitethin)
Block(-4,12,-5,srparasites:parasitethin)
RandomBlock(-4,12,-3,IRON_FENCE:0,30,IRON_FENCE:0,100)
RandomBlock(-4,12,-2,IRON_FENCE:0,30,IRON_FENCE:0,100)
Block(-4,12,-1,quark:grate:0)
Block(-4,12,0,quark:grate:0)
Block(-4,12,1,quark:grate:0)
Block(-4,12,2,quark:grate:0)
RandomBlock(-4,12,3,CONCRETE:0,40,SMOOTH_BRICK:1,30,SMOOTH_BRICK:2,30,MOSSY_COBBLESTONE:0,30,COBBLESTONE:0,20,CONCRETE:0,100)
Block(-4,13,-7,srparasites:parasitethin)
Block(-4,13,-6,srparasites:parasitethin)
Block(-4,13,-5,srparasites:parasitethin)
RandomBlock(-4,13,-3,IRON_FENCE:0,30,IRON_FENCE:0,100)
Block(-4,13,-2,quark:iron_plate_slab:0)
Block(-4,13,-1,quark:iron_plate_slab:0)
Block(-4,13,0,quark:iron_plate_slab:0)
Block(-4,13,1,quark:iron_plate_slab:0)
Block(-4,13,2,quark:iron_plate_slab:0)
RandomBlock(-4,13,3,CONCRETE:0,40,SMOOTH_BRICK:1,30,SMOOTH_BRICK:2,30,MOSSY_COBBLESTONE:0,30,COBBLESTONE:0,20,CONCRETE:0,100)
Block(-4,14,-7,srparasites:parasitethin)
Block(-4,14,-6,srparasites:parasitethin)
Block(-4,14,-5,srparasites:parasitethin)
RandomBlock(-4,14,-3,IRON_FENCE:0,30,IRON_FENCE:0,100)
RandomBlock(-4,14,3,CONCRETE:0,40,SMOOTH_BRICK:1,30,SMOOTH_BRICK:2,30,MOSSY_COBBLESTONE:0,30,COBBLESTONE:0,20,CONCRETE:0,100)
Block(-4,15,-7,srparasites:parasitethin)
RandomBlock(-4,15,3,CONCRETE:0,40,SMOOTH_BRICK:1,30,SMOOTH_BRICK:2,30,MOSSY_COBBLESTONE:0,30,COBBLESTONE:0,20,CONCRETE:0,100)
Block(-4,16,-7,SMOOTH_STAIRS:4)
Block(-4,16,-6,quark:iron_plate:1)
Block(-4,16,-5,SMOOTH_STAIRS:4)
Block(-4,16,-4,SMOOTH_STAIRS:4)
Block(-4,16,-3,SMOOTH_STAIRS:4)
Block(-4,16,-2,SMOOTH_STAIRS:4)
Block(-4,16,-1,quark:iron_plate:1)
Block(-4,16,0,SMOOTH_STAIRS:0)
Block(-4,16,1,SMOOTH_STAIRS:4)
Block(-4,16,2,SMOOTH_STAIRS:4)
Block(-4,16,3,quark:iron_plate:1)
Block(-4,17,-7,quark:polished_stone:0)
Block(-4,17,-6,quark:iron_plate:1)
Block(-4,17,-5,quark:polished_stone:0)
Block(-4,17,-4,quark:polished_stone:0)
Block(-4,17,-3,quark:polished_stone:0)
Block(-4,17,-2,quark:polished_stone:0)
Block(-4,17,-1,quark:iron_plate:1)
Block(-4,17,0,quark:polished_stone:0)
Block(-4,17,1,quark:polished_stone:0)
Block(-4,17,2,quark:polished_stone:0)
Block(-4,18,-7,SMOOTH_STAIRS:1)
Block(-4,18,-6,SMOOTH_STAIRS:1)
Block(-4,18,-5,SMOOTH_STAIRS:1)
Block(-4,18,-4,SMOOTH_STAIRS:1)
Block(-4,18,-3,SMOOTH_STAIRS:1)
Block(-4,18,-2,SMOOTH_STAIRS:1)
Block(-4,18,-1,SMOOTH_STAIRS:1)
Block(-4,18,0,SMOOTH_STAIRS:1)
Block(-4,18,1,SMOOTH_STAIRS:1)
Block(-4,18,2,SMOOTH_STAIRS:1)
Block(-3,0,-7,quark:world_stone_pavement:2)
Block(-3,0,-6,quark:world_stone_pavement:2)
Block(-3,0,-5,CONCRETE:0)
Block(-3,0,-4,CONCRETE:0)
Block(-3,0,-3,CONCRETE:0)
Block(-3,0,-2,quark:world_stone_pavement:2)
Block(-3,0,-1,CONCRETE:0)
Block(-3,0,0,quark:world_stone_pavement:2)
Block(-3,0,1,CONCRETE:0)
Block(-3,0,2,CONCRETE:0)
Block(-3,0,3,CONCRETE:0)
Block(-3,1,-7,quark:world_stone_pavement:2)
Block(-3,1,-6,CONCRETE:0)
Block(-3,1,-5,quark:world_stone_pavement:2)
Block(-3,1,-4,quark:world_stone_pavement:2)
Block(-3,1,-3,CONCRETE:0)
Block(-3,1,-2,CONCRETE:0)
Block(-3,1,-1,quark:world_stone_pavement:2)
Block(-3,1,0,CONCRETE:0)
Block(-3,1,1,CONCRETE:0)
Block(-3,1,2,CONCRETE:0)
Block(-3,1,3,CONCRETE:0)
Block(-3,2,-7,quark:world_stone_pavement:2)
Block(-3,2,-6,CONCRETE:0)
Block(-3,2,-5,CONCRETE:0)
Block(-3,2,-4,CONCRETE:0)
Block(-3,2,-3,quark:world_stone_pavement:2)
Block(-3,2,-2,CONCRETE:0)
Block(-3,2,-1,CONCRETE:0)
Block(-3,2,0,CONCRETE:0)
Block(-3,2,1,quark:world_stone_pavement:2)
Block(-3,2,2,quark:world_stone_pavement:2)
Block(-3,2,3,CONCRETE:0)
Block(-3,3,-7,quark:world_stone_pavement:2)
Block(-3,3,-6,quark:world_stone_pavement:2)
Block(-3,3,-5,CONCRETE:0)
Block(-3,3,-4,CONCRETE:0)
Block(-3,3,-3,CONCRETE:0)
Block(-3,3,-2,CONCRETE:0)
Block(-3,3,-1,CONCRETE:0)
Block(-3,3,0,quark:world_stone_pavement:2)
Block(-3,3,1,CONCRETE:0)
Block(-3,3,2,CONCRETE:0)
Block(-3,3,3,CONCRETE:0)
Block(-3,4,-7,quark:world_stone_pavement:2)
Block(-3,4,-6,quark:world_stone_pavement:2)
Block(-3,4,-5,CONCRETE:0)
Block(-3,4,-4,CONCRETE:0)
Block(-3,4,-3,quark:world_stone_pavement:2)
Block(-3,4,-2,CONCRETE:0)
Block(-3,4,-1,CONCRETE:0)
Block(-3,4,0,quark:world_stone_pavement:2)
Block(-3,4,1,CONCRETE:0)
Block(-3,4,2,quark:world_stone_pavement:2)
Block(-3,4,3,quark:world_stone_pavement:2)
Block(-3,5,-7,quark:world_stone_pavement:2)
Block(-3,5,-6,quark:world_stone_pavement:2)
Block(-3,5,-5,CONCRETE:0)
Block(-3,5,-4,CONCRETE:0)
Block(-3,5,-3,CONCRETE:0)
Block(-3,5,-2,CONCRETE:0)
Block(-3,5,-1,CONCRETE:0)
Block(-3,5,0,CONCRETE:0)
Block(-3,5,1,CONCRETE:0)
Block(-3,5,2,quark:world_stone_pavement:2)
Block(-3,5,3,quark:world_stone_pavement:2)
Block(-3,6,-7,CONCRETE:0)
Block(-3,6,-6,CONCRETE:0)
Block(-3,6,-5,quark:world_stone_pavement:2)
Block(-3,6,-4,quark:world_stone_pavement:2)
Block(-3,6,-3,quark:world_stone_pavement:2)
Block(-3,6,-2,CONCRETE:0)
Block(-3,6,-1,CONCRETE:0)
Block(-3,6,0,quark:world_stone_pavement:2)
Block(-3,6,1,CONCRETE:0)
Block(-3,6,2,CONCRETE:0)
Block(-3,6,3,quark:world_stone_pavement:2)
Block(-3,7,-7,quark:world_stone_pavement:2)
Block(-3,7,-6,quark:world_stone_pavement:2)
Block(-3,7,-5,quark:world_stone_pavement:2)
Block(-3,7,-4,quark:world_stone_pavement:2)
Block(-3,7,-3,CONCRETE:0)
Block(-3,7,-2,quark:world_stone_pavement:2)
Block(-3,7,-1,quark:world_stone_pavement:2)
Block(-3,7,0,CONCRETE:0)
Block(-3,7,1,quark:world_stone_pavement:2)
Block(-3,7,2,CONCRETE:0)
Block(-3,7,3,CONCRETE:0)
Block(-3,8,-7,quark:polished_stone:0)
Block(-3,8,-6,quark:world_stone_pavement:2)
Block(-3,8,-5,quark:polished_stone:0)
Block(-3,8,-4,quark:polished_stone:0)
Block(-3,8,-3,CONCRETE:0)
Block(-3,8,-2,CONCRETE:0)
Block(-3,8,-1,CONCRETE:0)
Block(-3,8,0,CONCRETE:0)
Block(-3,8,1,CONCRETE:0)
Block(-3,8,2,CONCRETE:0)
Block(-3,8,3,CONCRETE:0)
Block(-3,9,-7,quark:polished_stone:0)
Block(-3,9,-6,quark:world_stone_pavement:2)
Block(-3,9,-5,quark:polished_stone:0)
Block(-3,9,-4,quark:polished_stone:0)
Block(-3,9,-3,quark:polished_stone:0)
Block(-3,9,-2,quark:world_stone_pavement:2)
Block(-3,9,-1,quark:polished_stone:0)
Block(-3,9,0,quark:polished_stone:0)
Block(-3,9,1,quark:world_stone_pavement:2)
Block(-3,9,2,quark:polished_stone:0)
Block(-3,9,3,quark:world_stone_pavement:2)
Block(-3,10,-7,quark:world_stone_pavement:2)
Block(-3,10,-6,quark:polished_stone:0)
Block(-3,10,-5,quark:polished_stone:0)
Block(-3,10,-4,quark:polished_stone:0)
Block(-3,10,-3,quark:polished_stone:0)
Block(-3,10,-2,quark:world_stone_pavement:2)
Block(-3,10,-1,quark:polished_stone:0)
Block(-3,10,0,quark:world_stone_pavement:2)
Block(-3,10,1,quark:world_stone_pavement:2)
Block(-3,10,2,quark:polished_stone:0)
Block(-3,10,3,quark:world_stone_pavement:2)
Block(-3,11,-7,DOUBLE_STEP:0)
RandomBlock(-3,11,-6,CONCRETE:0,40,SMOOTH_BRICK:1,30,SMOOTH_BRICK:2,30,MOSSY_COBBLESTONE:0,30,COBBLESTONE:0,20,CONCRETE:0,100)
Block(-3,11,-5,DOUBLE_STEP:0)
RandomBlock(-3,11,-4,CONCRETE:0,40,SMOOTH_BRICK:1,30,SMOOTH_BRICK:2,30,MOSSY_COBBLESTONE:0,30,COBBLESTONE:0,20,CONCRETE:0,100)
Block(-3,11,-3,DOUBLE_STEP:0)
RandomBlock(-3,11,-2,CONCRETE:0,40,SMOOTH_BRICK:1,30,SMOOTH_BRICK:2,30,MOSSY_COBBLESTONE:0,30,COBBLESTONE:0,20,CONCRETE:0,100)
Block(-3,11,-1,DOUBLE_STEP:0)
RandomBlock(-3,11,0,CONCRETE:0,40,SMOOTH_BRICK:1,30,SMOOTH_BRICK:2,30,MOSSY_COBBLESTONE:0,30,COBBLESTONE:0,20,CONCRETE:0,100)
Block(-3,11,1,DOUBLE_STEP:0)
RandomBlock(-3,11,2,CONCRETE:0,40,SMOOTH_BRICK:1,30,SMOOTH_BRICK:2,30,MOSSY_COBBLESTONE:0,30,COBBLESTONE:0,20,CONCRETE:0,100)
Block(-3,11,3,DOUBLE_STEP:0)
Block(-3,12,-7,DOUBLE_STEP:0)
RandomBlock(-3,12,-6,CONCRETE:0,40,SMOOTH_BRICK:1,30,SMOOTH_BRICK:2,30,MOSSY_COBBLESTONE:0,30,COBBLESTONE:0,20,CONCRETE:0,100)
Block(-3,12,-5,DOUBLE_STEP:0)
RandomBlock(-3,12,-4,CONCRETE:0,40,SMOOTH_BRICK:1,30,SMOOTH_BRICK:2,30,MOSSY_COBBLESTONE:0,30,COBBLESTONE:0,20,CONCRETE:0,100)
Block(-3,12,-3,DOUBLE_STEP:0)
RandomBlock(-3,12,-2,CONCRETE:0,40,SMOOTH_BRICK:1,30,SMOOTH_BRICK:2,30,MOSSY_COBBLESTONE:0,30,COBBLESTONE:0,20,CONCRETE:0,100)
Block(-3,12,-1,DOUBLE_STEP:0)
RandomBlock(-3,12,0,CONCRETE:0,40,SMOOTH_BRICK:1,30,SMOOTH_BRICK:2,30,MOSSY_COBBLESTONE:0,30,COBBLESTONE:0,20,CONCRETE:0,100)
Block(-3,12,1,DOUBLE_STEP:0)
RandomBlock(-3,12,2,CONCRETE:0,40,SMOOTH_BRICK:1,30,SMOOTH_BRICK:2,30,MOSSY_COBBLESTONE:0,30,COBBLESTONE:0,20,CONCRETE:0,100)
Block(-3,12,3,DOUBLE_STEP:0)
Block(-3,13,-7,DOUBLE_STEP:0)
RandomBlock(-3,13,-6,CONCRETE:0,40,SMOOTH_BRICK:1,30,SMOOTH_BRICK:2,30,MOSSY_COBBLESTONE:0,30,COBBLESTONE:0,20,CONCRETE:0,100)
Block(-3,13,-5,DOUBLE_STEP:0)
RandomBlock(-3,13,-4,CONCRETE:0,40,SMOOTH_BRICK:1,30,SMOOTH_BRICK:2,30,MOSSY_COBBLESTONE:0,30,COBBLESTONE:0,20,CONCRETE:0,100)
Block(-3,13,-3,DOUBLE_STEP:0)
RandomBlock(-3,13,-2,CONCRETE:0,40,SMOOTH_BRICK:1,30,SMOOTH_BRICK:2,30,MOSSY_COBBLESTONE:0,30,COBBLESTONE:0,20,CONCRETE:0,100)
Block(-3,13,-1,DOUBLE_STEP:0)
RandomBlock(-3,13,0,CONCRETE:0,40,SMOOTH_BRICK:1,30,SMOOTH_BRICK:2,30,MOSSY_COBBLESTONE:0,30,COBBLESTONE:0,20,CONCRETE:0,100)
Block(-3,13,1,DOUBLE_STEP:0)
RandomBlock(-3,13,2,CONCRETE:0,40,SMOOTH_BRICK:1,30,SMOOTH_BRICK:2,30,MOSSY_COBBLESTONE:0,30,COBBLESTONE:0,20,CONCRETE:0,100)
Block(-3,13,3,DOUBLE_STEP:0)
Block(-3,14,-7,DOUBLE_STEP:0)
RandomBlock(-3,14,-6,CONCRETE:0,40,SMOOTH_BRICK:1,30,SMOOTH_BRICK:2,30,MOSSY_COBBLESTONE:0,30,COBBLESTONE:0,20,CONCRETE:0,100)
Block(-3,14,-5,DOUBLE_STEP:0)
RandomBlock(-3,14,-4,CONCRETE:0,40,SMOOTH_BRICK:1,30,SMOOTH_BRICK:2,30,MOSSY_COBBLESTONE:0,30,COBBLESTONE:0,20,CONCRETE:0,100)
Block(-3,14,-3,DOUBLE_STEP:0)
RandomBlock(-3,14,-2,CONCRETE:0,40,SMOOTH_BRICK:1,30,SMOOTH_BRICK:2,30,MOSSY_COBBLESTONE:0,30,COBBLESTONE:0,20,CONCRETE:0,100)
Block(-3,14,-1,DOUBLE_STEP:0)
RandomBlock(-3,14,0,CONCRETE:0,40,SMOOTH_BRICK:1,30,SMOOTH_BRICK:2,30,MOSSY_COBBLESTONE:0,30,COBBLESTONE:0,20,CONCRETE:0,100)
Block(-3,14,1,DOUBLE_STEP:0)
RandomBlock(-3,14,2,CONCRETE:0,40,SMOOTH_BRICK:1,30,SMOOTH_BRICK:2,30,MOSSY_COBBLESTONE:0,30,COBBLESTONE:0,20,CONCRETE:0,100)
Block(-3,14,3,DOUBLE_STEP:0)
Block(-3,15,-7,DOUBLE_STEP:0)
RandomBlock(-3,15,-6,CONCRETE:0,40,SMOOTH_BRICK:1,30,SMOOTH_BRICK:2,30,MOSSY_COBBLESTONE:0,30,COBBLESTONE:0,20,CONCRETE:0,100)
Block(-3,15,-5,DOUBLE_STEP:0)
RandomBlock(-3,15,-4,CONCRETE:0,40,SMOOTH_BRICK:1,30,SMOOTH_BRICK:2,30,MOSSY_COBBLESTONE:0,30,COBBLESTONE:0,20,CONCRETE:0,100)
Block(-3,15,-3,DOUBLE_STEP:0)
RandomBlock(-3,15,-2,CONCRETE:0,40,SMOOTH_BRICK:1,30,SMOOTH_BRICK:2,30,MOSSY_COBBLESTONE:0,30,COBBLESTONE:0,20,CONCRETE:0,100)
Block(-3,15,-1,DOUBLE_STEP:0)
RandomBlock(-3,15,0,CONCRETE:0,40,SMOOTH_BRICK:1,30,SMOOTH_BRICK:2,30,MOSSY_COBBLESTONE:0,30,COBBLESTONE:0,20,CONCRETE:0,100)
Block(-3,15,1,DOUBLE_STEP:0)
RandomBlock(-3,15,2,CONCRETE:0,40,SMOOTH_BRICK:1,30,SMOOTH_BRICK:2,30,MOSSY_COBBLESTONE:0,30,COBBLESTONE:0,20,CONCRETE:0,100)
Block(-3,15,3,DOUBLE_STEP:0)
Block(-3,16,-7,quark:iron_plate:1)
Block(-3,16,-6,quark:iron_plate:1)
Block(-3,16,-5,quark:iron_plate:1)
Block(-3,16,-4,quark:iron_plate:1)
Block(-3,16,-3,quark:iron_plate:1)
Block(-3,16,-2,quark:iron_plate:1)
Block(-3,16,-1,quark:iron_plate:1)
Block(-3,16,0,quark:iron_plate:1)
Block(-3,16,1,quark:iron_plate:1)
Block(-3,16,2,quark:iron_plate:1)
Block(-3,16,3,quark:iron_plate:1)
Block(-3,17,-6,quark:iron_plate:1)
Block(-3,17,-1,quark:iron_plate:1)
Block(-3,18,-6,STEP:0)
Block(-3,18,-1,STEP:0)
Block(7,511,-7,DIAMOND_BLOCK:0)

#######################################################################
# +-----------------------------------------------------------------+ #
# |                             Branches                            | #
# +-----------------------------------------------------------------+ #
#######################################################################

Branch(0,0,16,true,NuclearPowerPlant_InfectedC4R5,NORTH,100.0,0)

#######################################################################
# +-----------------------------------------------------------------+ #
# |                             Entities                            | #
# +-----------------------------------------------------------------+ #
#######################################################################

Entity(-6,11,-6,srparasites:ada_yelloweye,1)

#######################################################################
# +-----------------------------------------------------------------+ #
# |                            Particles                            | #
# +-----------------------------------------------------------------+ #
#######################################################################


#######################################################################
# +-----------------------------------------------------------------+ #
# |                             Spawners                            | #
# +-----------------------------------------------------------------+ #
#######################################################################


#######################################################################
# +-----------------------------------------------------------------+ #
# |                             ModData                             | #
# +-----------------------------------------------------------------+ #
#######################################################################

