
#######################################################################
# +-----------------------------------------------------------------+ #
# |                            BO4 object                           | #
# +-----------------------------------------------------------------+ #
#######################################################################

Author: NLBlackEagle

Description: No description given

SettingsMode: WriteWithoutComments


#######################################################################
# +-----------------------------------------------------------------+ #
# |                          Main settings                          | #
# +-----------------------------------------------------------------+ #
#######################################################################

FixedRotation: 

Frequency: 0

SpawnHeight: highestBlock

UseCenterForHighestBlock: true

##############################
# Height Limits for the BO4. #
##############################

MinHeight: 0

MaxHeight: 255

InheritBO3: 

InheritBO3Rotation: NORTH

OverrideChildSettings: true

OverrideParentHeight: false

CanOverride: false

BranchFrequency: 0

BranchFrequencyGroup: 

MustBeBelowOther: false

MustBeInside: 

CannotBeInside: 

ReplacesBO3: 

MustBeInsideWorldBorders: true

CanSpawnOnWater: true

SpawnOnWaterOnly: false

SpawnUnderWater: false

SpawnAtWaterLevel: false

HeightOffset: 0

RemoveAir: false

ReplaceAbove: 

ReplaceBelow: 

ReplaceWithBiomeBlocks: true

ReplaceWithSurfaceBlock: GRASS

ReplaceWithGroundBlock: DIRT

ReplaceWithStoneBlock: STONE

SmoothRadius: 0

SmoothHeightOffset: 0

SmoothStartTop: false

SmoothStartWood: false

SmoothingSurfaceBlock: 

SmoothingGroundBlock: 

BO3Group: 

IsSpawnPoint: false

DoReplaceBlocks: true


#######################################################################
# +-----------------------------------------------------------------+ #
# |                              Blocks                             | #
# +-----------------------------------------------------------------+ #
#######################################################################

Block(-7,67,-2,DIRT:0)
Block(-7,67,-1,DIRT:0)
Block(-7,67,0,DIRT:0)
Block(-7,67,1,DIRT:0)
Block(-7,67,2,DIRT:0)
Block(-7,67,3,DIRT:0)
Block(-7,67,4,DIRT:0)
Block(-7,67,5,DIRT:0)
Block(-7,67,6,DIRT:0)
Block(-7,68,0,DIRT:0)
Block(-7,68,1,DIRT:0)
Block(-7,68,2,DIRT:0)
Block(-7,68,3,DIRT:0)
Block(-7,68,4,DIRT:0)
Block(-7,68,5,DIRT:0)
Block(-7,68,6,DIRT:0)
Block(-6,67,-5,DIRT:0)
Block(-6,67,-4,DIRT:0)
Block(-6,67,-3,DIRT:0)
Block(-6,67,-2,DIRT:0)
Block(-6,67,-1,DIRT:0)
Block(-6,67,0,DIRT:0)
Block(-6,67,1,DIRT:0)
Block(-6,67,2,DIRT:0)
Block(-6,67,3,DIRT:0)
Block(-6,67,4,DIRT:0)
Block(-6,67,5,DIRT:0)
Block(-6,67,6,DIRT:0)
Block(-6,67,7,DIRT:0)
Block(-6,67,8,DIRT:0)
Block(-6,68,-2,DIRT:0)
Block(-6,68,-1,DIRT:0)
Block(-6,68,0,DIRT:0)
Block(-6,68,1,DIRT:0)
Block(-6,68,2,DIRT:0)
Block(-6,68,3,DIRT:0)
Block(-6,68,4,DIRT:0)
Block(-6,68,5,DIRT:0)
Block(-6,68,6,DIRT:0)
Block(-6,68,7,DIRT:0)
Block(-6,68,8,DIRT:0)
Block(-6,69,2,DIRT:0)
Block(-6,69,3,DIRT:0)
Block(-6,69,4,DIRT:0)
Block(-6,69,5,DIRT:0)
Block(-6,70,3,DIRT:0)
Block(-6,70,4,DIRT:0)
Block(-6,70,5,DIRT:0)
Block(-5,67,-6,DIRT:0)
Block(-5,67,-5,DIRT:0)
Block(-5,67,-4,DIRT:0)
Block(-5,67,-3,DIRT:0)
Block(-5,67,-2,DIRT:0)
Block(-5,67,-1,DIRT:0)
Block(-5,67,0,DIRT:0)
Block(-5,67,1,DIRT:0)
Block(-5,67,2,DIRT:0)
Block(-5,67,3,DIRT:0)
Block(-5,67,4,DIRT:0)
Block(-5,67,5,DIRT:0)
Block(-5,67,6,DIRT:0)
Block(-5,67,7,DIRT:0)
Block(-5,67,8,DIRT:0)
Block(-5,68,-3,DIRT:0)
Block(-5,68,-2,DIRT:0)
Block(-5,68,-1,DIRT:0)
Block(-5,68,0,DIRT:0)
Block(-5,68,1,DIRT:0)
Block(-5,68,2,DIRT:0)
Block(-5,68,3,DIRT:0)
Block(-5,68,4,DIRT:0)
Block(-5,68,5,DIRT:0)
Block(-5,68,6,DIRT:0)
Block(-5,68,7,DIRT:0)
Block(-5,68,8,DIRT:0)
Block(-5,69,2,DIRT:0)
Block(-5,69,3,DIRT:0)
Block(-5,69,4,DIRT:0)
Block(-5,69,5,DIRT:0)
Block(-5,69,8,DIRT:0)
Block(-5,70,2,DIRT:0)
Block(-5,70,3,DIRT:0)
Block(-5,70,4,DIRT:0)
Block(-5,70,5,DIRT:0)
Block(-4,67,-7,DIRT:0)
Block(-4,67,-6,DIRT:0)
Block(-4,67,-5,DIRT:0)
Block(-4,67,-4,DIRT:0)
Block(-4,67,-3,DIRT:0)
Block(-4,67,-2,DIRT:0)
Block(-4,67,-1,DIRT:0)
Block(-4,67,0,DIRT:0)
Block(-4,67,1,DIRT:0)
Block(-4,67,2,DIRT:0)
Block(-4,67,3,DIRT:0)
Block(-4,67,4,DIRT:0)
Block(-4,67,5,DIRT:0)
Block(-4,67,6,DIRT:0)
Block(-4,67,7,DIRT:0)
Block(-4,67,8,DIRT:0)
Block(-4,68,-6,DIRT:0)
Block(-4,68,-5,DIRT:0)
Block(-4,68,-4,DIRT:0)
Block(-4,68,-3,DIRT:0)
Block(-4,68,-2,DIRT:0)
Block(-4,68,-1,DIRT:0)
Block(-4,68,0,DIRT:0)
Block(-4,68,1,DIRT:0)
Block(-4,68,2,DIRT:0)
Block(-4,68,3,DIRT:0)
Block(-4,68,4,DIRT:0)
Block(-4,68,5,DIRT:0)
Block(-4,68,6,DIRT:0)
Block(-4,68,7,DIRT:0)
Block(-4,68,8,DIRT:0)
Block(-4,69,-1,DIRT:0)
Block(-4,69,0,DIRT:0)
Block(-4,69,1,DIRT:0)
Block(-4,69,2,DIRT:0)
Block(-4,69,3,DIRT:0)
Block(-4,69,4,DIRT:0)
Block(-4,69,5,DIRT:0)
Block(-4,69,6,DIRT:0)
Block(-4,69,7,DIRT:0)
Block(-4,69,8,DIRT:0)
Block(-4,70,1,DIRT:0)
Block(-4,70,2,DIRT:0)
Block(-4,70,3,DIRT:0)
Block(-4,70,4,DIRT:0)
Block(-4,70,5,DIRT:0)
Block(-4,70,6,DIRT:0)
Block(-4,70,7,DIRT:0)
Block(-4,70,8,DIRT:0)
Block(-4,71,5,DIRT:0)
Block(-4,71,6,DIRT:0)
Block(-4,71,7,DIRT:0)
Block(-4,71,8,DIRT:0)
Block(-3,67,-7,DIRT:0)
Block(-3,67,-6,DIRT:0)
Block(-3,67,-5,DIRT:0)
Block(-3,67,-4,DIRT:0)
Block(-3,67,-3,DIRT:0)
Block(-3,67,-2,DIRT:0)
Block(-3,67,-1,DIRT:0)
Block(-3,67,0,DIRT:0)
Block(-3,67,1,DIRT:0)
Block(-3,67,2,DIRT:0)
Block(-3,67,3,DIRT:0)
Block(-3,67,4,DIRT:0)
Block(-3,67,5,DIRT:0)
Block(-3,67,6,DIRT:0)
Block(-3,67,7,DIRT:0)
Block(-3,67,8,DIRT:0)
Block(-3,68,-7,DIRT:0)
Block(-3,68,-6,DIRT:0)
Block(-3,68,-5,DIRT:0)
Block(-3,68,-4,DIRT:0)
Block(-3,68,-3,DIRT:0)
Block(-3,68,-2,DIRT:0)
Block(-3,68,-1,DIRT:0)
Block(-3,68,0,DIRT:0)
Block(-3,68,1,DIRT:0)
Block(-3,68,2,DIRT:0)
Block(-3,68,3,DIRT:0)
Block(-3,68,4,DIRT:0)
Block(-3,68,5,DIRT:0)
Block(-3,68,6,DIRT:0)
Block(-3,68,7,DIRT:0)
Block(-3,68,8,DIRT:0)
Block(-3,69,-3,DIRT:0)
Block(-3,69,-2,DIRT:0)
Block(-3,69,-1,DIRT:0)
Block(-3,69,0,DIRT:0)
Block(-3,69,1,DIRT:0)
Block(-3,69,2,DIRT:0)
Block(-3,69,3,DIRT:0)
Block(-3,69,4,DIRT:0)
Block(-3,69,5,DIRT:0)
Block(-3,69,6,DIRT:0)
Block(-3,69,7,DIRT:0)
Block(-3,69,8,DIRT:0)
Block(-3,70,-1,DIRT:0)
Block(-3,70,0,DIRT:0)
Block(-3,70,1,DIRT:0)
Block(-3,70,2,DIRT:0)
Block(-3,70,3,DIRT:0)
Block(-3,70,4,DIRT:0)
Block(-3,70,5,DIRT:0)
Block(-3,70,6,DIRT:0)
Block(-3,70,7,DIRT:0)
Block(-3,70,8,DIRT:0)
Block(-3,71,4,DIRT:0)
Block(-3,71,5,DIRT:0)
Block(-3,71,6,DIRT:0)
Block(-3,71,7,DIRT:0)
Block(-3,71,8,DIRT:0)
Block(-3,72,5,DIRT:0)
Block(-3,72,6,DIRT:0)
Block(-3,72,7,DIRT:0)
Block(-3,72,8,DIRT:0)
Block(-3,73,6,DIRT:0)
Block(-2,67,-7,DIRT:0)
Block(-2,67,-6,DIRT:0)
Block(-2,67,-5,DIRT:0)
Block(-2,67,-4,DIRT:0)
Block(-2,67,-3,DIRT:0)
Block(-2,67,-2,DIRT:0)
Block(-2,67,-1,DIRT:0)
Block(-2,67,0,DIRT:0)
Block(-2,67,1,DIRT:0)
Block(-2,67,2,DIRT:0)
Block(-2,67,3,DIRT:0)
Block(-2,67,4,DIRT:0)
Block(-2,67,5,DIRT:0)
Block(-2,67,6,DIRT:0)
Block(-2,67,7,DIRT:0)
Block(-2,67,8,DIRT:0)
Block(-2,68,-7,DIRT:0)
Block(-2,68,-6,DIRT:0)
Block(-2,68,-5,DIRT:0)
Block(-2,68,-4,DIRT:0)
Block(-2,68,-3,DIRT:0)
Block(-2,68,-2,DIRT:0)
Block(-2,68,-1,DIRT:0)
Block(-2,68,0,DIRT:0)
Block(-2,68,1,DIRT:0)
Block(-2,68,2,DIRT:0)
Block(-2,68,3,DIRT:0)
Block(-2,68,4,DIRT:0)
Block(-2,68,5,DIRT:0)
Block(-2,68,6,DIRT:0)
Block(-2,68,7,DIRT:0)
Block(-2,68,8,DIRT:0)
Block(-2,69,-6,DIRT:0)
Block(-2,69,-5,DIRT:0)
Block(-2,69,-4,DIRT:0)
Block(-2,69,-3,DIRT:0)
Block(-2,69,-2,DIRT:0)
Block(-2,69,-1,DIRT:0)
Block(-2,69,0,DIRT:0)
Block(-2,69,1,DIRT:0)
Block(-2,69,2,DIRT:0)
Block(-2,69,3,DIRT:0)
Block(-2,69,4,DIRT:0)
Block(-2,69,5,DIRT:0)
Block(-2,69,6,DIRT:0)
Block(-2,69,7,DIRT:0)
Block(-2,69,8,DIRT:0)
Block(-2,70,-1,DIRT:0)
Block(-2,70,0,DIRT:0)
Block(-2,70,1,DIRT:0)
Block(-2,70,2,DIRT:0)
Block(-2,70,3,DIRT:0)
Block(-2,70,4,DIRT:0)
Block(-2,70,5,DIRT:0)
Block(-2,70,6,DIRT:0)
Block(-2,70,7,DIRT:0)
Block(-2,70,8,DIRT:0)
Block(-2,71,1,DIRT:0)
Block(-2,71,2,DIRT:0)
Block(-2,71,3,DIRT:0)
Block(-2,71,4,DIRT:0)
Block(-2,71,5,DIRT:0)
Block(-2,71,6,DIRT:0)
Block(-2,71,7,DIRT:0)
Block(-2,71,8,DIRT:0)
Block(-2,72,3,DIRT:0)
Block(-2,72,4,DIRT:0)
Block(-2,72,5,DIRT:0)
Block(-2,72,6,DIRT:0)
Block(-2,72,7,DIRT:0)
Block(-2,72,8,DIRT:0)
Block(-2,73,4,DIRT:0)
Block(-2,73,5,DIRT:0)
Block(-2,73,6,DIRT:0)
Block(-2,73,7,DIRT:0)
Block(-2,73,8,DIRT:0)
Block(-2,74,6,DIRT:0)
Block(-2,74,7,DIRT:0)
Block(-2,74,8,DIRT:0)
Block(-1,67,-7,DIRT:0)
Block(-1,67,-6,DIRT:0)
Block(-1,67,-5,DIRT:0)
Block(-1,67,-4,DIRT:0)
Block(-1,67,-3,DIRT:0)
Block(-1,67,-2,DIRT:0)
Block(-1,67,-1,DIRT:0)
Block(-1,67,0,DIRT:0)
Block(-1,67,1,DIRT:0)
Block(-1,67,2,DIRT:0)
Block(-1,67,3,DIRT:0)
Block(-1,67,4,DIRT:0)
Block(-1,67,5,DIRT:0)
Block(-1,67,6,DIRT:0)
Block(-1,67,7,DIRT:0)
Block(-1,67,8,DIRT:0)
Block(-1,68,-7,DIRT:0)
Block(-1,68,-6,DIRT:0)
Block(-1,68,-5,DIRT:0)
Block(-1,68,-4,DIRT:0)
Block(-1,68,-3,DIRT:0)
Block(-1,68,-2,DIRT:0)
Block(-1,68,-1,DIRT:0)
Block(-1,68,0,DIRT:0)
Block(-1,68,1,DIRT:0)
Block(-1,68,2,DIRT:0)
Block(-1,68,3,DIRT:0)
Block(-1,68,4,DIRT:0)
Block(-1,68,5,DIRT:0)
Block(-1,68,6,DIRT:0)
Block(-1,68,7,DIRT:0)
Block(-1,68,8,DIRT:0)
Block(-1,69,-7,DIRT:0)
Block(-1,69,-6,DIRT:0)
Block(-1,69,-5,DIRT:0)
Block(-1,69,-4,DIRT:0)
Block(-1,69,-3,DIRT:0)
Block(-1,69,-2,DIRT:0)
Block(-1,69,-1,DIRT:0)
Block(-1,69,0,DIRT:0)
Block(-1,69,1,DIRT:0)
Block(-1,69,2,DIRT:0)
Block(-1,69,3,DIRT:0)
Block(-1,69,4,DIRT:0)
Block(-1,69,5,DIRT:0)
Block(-1,69,6,DIRT:0)
Block(-1,69,7,DIRT:0)
Block(-1,69,8,DIRT:0)
Block(-1,70,-4,DIRT:0)
Block(-1,70,-3,DIRT:0)
Block(-1,70,-2,DIRT:0)
Block(-1,70,-1,DIRT:0)
Block(-1,70,0,DIRT:0)
Block(-1,70,1,DIRT:0)
Block(-1,70,2,DIRT:0)
Block(-1,70,3,DIRT:0)
Block(-1,70,4,DIRT:0)
Block(-1,70,5,DIRT:0)
Block(-1,70,6,DIRT:0)
Block(-1,70,7,DIRT:0)
Block(-1,70,8,DIRT:0)
Block(-1,71,-1,DIRT:0)
Block(-1,71,0,DIRT:0)
Block(-1,71,1,DIRT:0)
Block(-1,71,2,DIRT:0)
Block(-1,71,3,DIRT:0)
Block(-1,71,4,DIRT:0)
Block(-1,71,5,DIRT:0)
Block(-1,71,6,DIRT:0)
Block(-1,71,7,DIRT:0)
Block(-1,71,8,DIRT:0)
Block(-1,72,1,DIRT:0)
Block(-1,72,2,DIRT:0)
Block(-1,72,3,DIRT:0)
Block(-1,72,4,DIRT:0)
Block(-1,72,5,DIRT:0)
Block(-1,72,6,DIRT:0)
Block(-1,72,7,DIRT:0)
Block(-1,72,8,DIRT:0)
Block(-1,73,2,DIRT:0)
Block(-1,73,3,DIRT:0)
Block(-1,73,4,DIRT:0)
Block(-1,73,5,DIRT:0)
Block(-1,73,6,DIRT:0)
Block(-1,73,7,DIRT:0)
Block(-1,73,8,DIRT:0)
Block(-1,74,4,DIRT:0)
Block(-1,74,5,DIRT:0)
Block(-1,74,6,DIRT:0)
Block(-1,74,7,DIRT:0)
Block(-1,74,8,DIRT:0)
Block(0,67,-7,DIRT:0)
Block(0,67,-6,DIRT:0)
Block(0,67,-5,DIRT:0)
Block(0,67,-4,DIRT:0)
Block(0,67,-3,DIRT:0)
Block(0,67,-2,DIRT:0)
Block(0,67,-1,DIRT:0)
Block(0,67,0,DIRT:0)
Block(0,67,1,DIRT:0)
Block(0,67,2,DIRT:0)
Block(0,67,3,DIRT:0)
Block(0,67,4,DIRT:0)
Block(0,67,5,DIRT:0)
Block(0,67,6,DIRT:0)
Block(0,67,7,DIRT:0)
Block(0,67,8,DIRT:0)
Block(0,68,-7,DIRT:0)
Block(0,68,-6,DIRT:0)
Block(0,68,-5,DIRT:0)
Block(0,68,-4,DIRT:0)
Block(0,68,-3,DIRT:0)
Block(0,68,-2,DIRT:0)
Block(0,68,-1,DIRT:0)
Block(0,68,0,DIRT:0)
Block(0,68,1,DIRT:0)
Block(0,68,2,DIRT:0)
Block(0,68,3,DIRT:0)
Block(0,68,4,DIRT:0)
Block(0,68,5,DIRT:0)
Block(0,68,6,DIRT:0)
Block(0,68,7,DIRT:0)
Block(0,68,8,DIRT:0)
Block(0,69,-7,DIRT:0)
Block(0,69,-6,DIRT:0)
Block(0,69,-5,DIRT:0)
Block(0,69,-4,DIRT:0)
Block(0,69,-3,DIRT:0)
Block(0,69,-2,DIRT:0)
Block(0,69,-1,DIRT:0)
Block(0,69,0,DIRT:0)
Block(0,69,1,DIRT:0)
Block(0,69,2,DIRT:0)
Block(0,69,3,DIRT:0)
Block(0,69,4,DIRT:0)
Block(0,69,5,DIRT:0)
Block(0,69,6,DIRT:0)
Block(0,69,7,DIRT:0)
Block(0,69,8,DIRT:0)
Block(0,70,-6,DIRT:0)
Block(0,70,-5,DIRT:0)
Block(0,70,-4,DIRT:0)
Block(0,70,-3,DIRT:0)
Block(0,70,-2,DIRT:0)
Block(0,70,-1,DIRT:0)
Block(0,70,0,DIRT:0)
Block(0,70,1,DIRT:0)
Block(0,70,2,DIRT:0)
Block(0,70,3,DIRT:0)
Block(0,70,4,DIRT:0)
Block(0,70,5,DIRT:0)
Block(0,70,6,DIRT:0)
Block(0,70,7,DIRT:0)
Block(0,70,8,DIRT:0)
Block(0,71,-3,DIRT:0)
Block(0,71,-2,DIRT:0)
Block(0,71,-1,DIRT:0)
Block(0,71,0,DIRT:0)
Block(0,71,1,DIRT:0)
Block(0,71,2,DIRT:0)
Block(0,71,3,DIRT:0)
Block(0,71,4,DIRT:0)
Block(0,71,5,DIRT:0)
Block(0,71,6,DIRT:0)
Block(0,71,7,DIRT:0)
Block(0,71,8,DIRT:0)
Block(0,72,-1,DIRT:0)
Block(0,72,0,DIRT:0)
Block(0,72,1,DIRT:0)
Block(0,72,2,DIRT:0)
Block(0,72,3,DIRT:0)
Block(0,72,4,DIRT:0)
Block(0,72,5,DIRT:0)
Block(0,72,6,DIRT:0)
Block(0,72,7,DIRT:0)
Block(0,72,8,DIRT:0)
Block(0,73,1,DIRT:0)
Block(0,73,2,DIRT:0)
Block(0,73,3,DIRT:0)
Block(0,73,4,DIRT:0)
Block(0,73,5,DIRT:0)
Block(0,73,6,DIRT:0)
Block(0,73,7,DIRT:0)
Block(0,73,8,DIRT:0)
Block(0,74,1,DIRT:0)
Block(0,74,2,DIRT:0)
Block(0,74,3,DIRT:0)
Block(0,74,4,DIRT:0)
Block(0,74,5,DIRT:0)
Block(0,74,6,DIRT:0)
Block(0,74,7,DIRT:0)
Block(0,74,8,DIRT:0)
Block(0,75,4,DIRT:0)
Block(0,75,5,DIRT:0)
Block(0,75,6,DIRT:0)
Block(0,75,7,DIRT:0)
Block(0,75,8,DIRT:0)
Block(1,67,-7,DIRT:0)
Block(1,67,-6,DIRT:0)
Block(1,67,-5,DIRT:0)
Block(1,67,-4,DIRT:0)
Block(1,67,-3,DIRT:0)
Block(1,67,-2,DIRT:0)
Block(1,67,-1,DIRT:0)
Block(1,67,0,DIRT:0)
Block(1,67,1,DIRT:0)
Block(1,67,2,DIRT:0)
Block(1,67,3,DIRT:0)
Block(1,67,4,DIRT:0)
Block(1,67,5,DIRT:0)
Block(1,67,6,DIRT:0)
Block(1,67,7,DIRT:0)
Block(1,67,8,DIRT:0)
Block(1,68,-7,DIRT:0)
Block(1,68,-6,DIRT:0)
Block(1,68,-5,DIRT:0)
Block(1,68,-4,DIRT:0)
Block(1,68,-3,DIRT:0)
Block(1,68,-2,DIRT:0)
Block(1,68,-1,DIRT:0)
Block(1,68,0,DIRT:0)
Block(1,68,1,DIRT:0)
Block(1,68,2,DIRT:0)
Block(1,68,3,DIRT:0)
Block(1,68,4,DIRT:0)
Block(1,68,5,DIRT:0)
Block(1,68,6,DIRT:0)
Block(1,68,7,DIRT:0)
Block(1,68,8,DIRT:0)
Block(1,69,-7,DIRT:0)
Block(1,69,-6,DIRT:0)
Block(1,69,-5,DIRT:0)
Block(1,69,-4,DIRT:0)
Block(1,69,-3,DIRT:0)
Block(1,69,-2,DIRT:0)
Block(1,69,-1,DIRT:0)
Block(1,69,0,DIRT:0)
Block(1,69,1,DIRT:0)
Block(1,69,2,DIRT:0)
Block(1,69,3,DIRT:0)
Block(1,69,4,DIRT:0)
Block(1,69,5,DIRT:0)
Block(1,69,6,DIRT:0)
Block(1,69,7,DIRT:0)
Block(1,69,8,DIRT:0)
Block(1,70,-7,DIRT:0)
Block(1,70,-6,DIRT:0)
Block(1,70,-5,DIRT:0)
Block(1,70,-4,DIRT:0)
Block(1,70,-3,DIRT:0)
Block(1,70,-2,DIRT:0)
Block(1,70,-1,DIRT:0)
Block(1,70,0,DIRT:0)
Block(1,70,1,DIRT:0)
Block(1,70,2,DIRT:0)
Block(1,70,3,DIRT:0)
Block(1,70,4,DIRT:0)
Block(1,70,5,DIRT:0)
Block(1,70,6,DIRT:0)
Block(1,70,7,DIRT:0)
Block(1,70,8,DIRT:0)
Block(1,71,-4,DIRT:0)
Block(1,71,-3,DIRT:0)
Block(1,71,-2,DIRT:0)
Block(1,71,-1,DIRT:0)
Block(1,71,0,DIRT:0)
Block(1,71,1,DIRT:0)
Block(1,71,2,DIRT:0)
Block(1,71,3,DIRT:0)
Block(1,71,4,DIRT:0)
Block(1,71,5,DIRT:0)
Block(1,71,6,DIRT:0)
Block(1,71,7,DIRT:0)
Block(1,71,8,DIRT:0)
Block(1,72,-1,DIRT:0)
Block(1,72,0,DIRT:0)
Block(1,72,1,DIRT:0)
Block(1,72,2,DIRT:0)
Block(1,72,3,DIRT:0)
Block(1,72,4,DIRT:0)
Block(1,72,5,DIRT:0)
Block(1,72,6,DIRT:0)
Block(1,72,7,DIRT:0)
Block(1,72,8,DIRT:0)
Block(1,73,-1,DIRT:0)
Block(1,73,0,DIRT:0)
Block(1,73,1,DIRT:0)
Block(1,73,2,DIRT:0)
Block(1,73,3,DIRT:0)
Block(1,73,4,DIRT:0)
Block(1,73,5,DIRT:0)
Block(1,73,6,DIRT:0)
Block(1,73,7,DIRT:0)
Block(1,73,8,DIRT:0)
Block(1,74,0,DIRT:0)
Block(1,74,1,DIRT:0)
Block(1,74,2,DIRT:0)
Block(1,74,3,DIRT:0)
Block(1,74,4,DIRT:0)
Block(1,74,5,DIRT:0)
Block(1,74,6,DIRT:0)
Block(1,74,7,DIRT:0)
Block(1,74,8,DIRT:0)
Block(1,75,3,DIRT:0)
Block(1,75,4,DIRT:0)
Block(1,75,5,DIRT:0)
Block(1,75,6,DIRT:0)
Block(1,75,7,DIRT:0)
Block(1,75,8,DIRT:0)
Block(1,76,6,DIRT:0)
Block(1,76,7,DIRT:0)
Block(1,76,8,DIRT:0)
Block(1,83,5,AIR:0)
Block(2,67,-7,DIRT:0)
Block(2,67,-6,DIRT:0)
Block(2,67,-5,DIRT:0)
Block(2,67,-4,DIRT:0)
Block(2,67,-3,DIRT:0)
Block(2,67,-2,DIRT:0)
Block(2,67,-1,DIRT:0)
Block(2,67,0,DIRT:0)
Block(2,67,1,DIRT:0)
Block(2,67,2,DIRT:0)
Block(2,67,3,DIRT:0)
Block(2,67,4,DIRT:0)
Block(2,67,5,DIRT:0)
Block(2,67,6,DIRT:0)
Block(2,67,7,DIRT:0)
Block(2,67,8,DIRT:0)
Block(2,68,-7,DIRT:0)
Block(2,68,-6,DIRT:0)
Block(2,68,-5,DIRT:0)
Block(2,68,-4,DIRT:0)
Block(2,68,-3,DIRT:0)
Block(2,68,-2,DIRT:0)
Block(2,68,-1,DIRT:0)
Block(2,68,0,DIRT:0)
Block(2,68,1,DIRT:0)
Block(2,68,2,DIRT:0)
Block(2,68,3,DIRT:0)
Block(2,68,4,DIRT:0)
Block(2,68,5,DIRT:0)
Block(2,68,6,DIRT:0)
Block(2,68,7,DIRT:0)
Block(2,68,8,DIRT:0)
Block(2,69,-7,DIRT:0)
Block(2,69,-6,DIRT:0)
Block(2,69,-5,DIRT:0)
Block(2,69,-4,DIRT:0)
Block(2,69,-3,DIRT:0)
Block(2,69,-2,DIRT:0)
Block(2,69,-1,DIRT:0)
Block(2,69,0,DIRT:0)
Block(2,69,1,DIRT:0)
Block(2,69,2,DIRT:0)
Block(2,69,3,DIRT:0)
Block(2,69,4,DIRT:0)
Block(2,69,5,DIRT:0)
Block(2,69,6,DIRT:0)
Block(2,69,7,DIRT:0)
Block(2,69,8,DIRT:0)
Block(2,70,-7,DIRT:0)
Block(2,70,-6,DIRT:0)
Block(2,70,-5,DIRT:0)
Block(2,70,-4,DIRT:0)
Block(2,70,-3,DIRT:0)
Block(2,70,-2,DIRT:0)
Block(2,70,-1,DIRT:0)
Block(2,70,0,DIRT:0)
Block(2,70,1,DIRT:0)
Block(2,70,2,DIRT:0)
Block(2,70,3,DIRT:0)
Block(2,70,4,DIRT:0)
Block(2,70,5,DIRT:0)
Block(2,70,6,DIRT:0)
Block(2,70,7,DIRT:0)
Block(2,70,8,DIRT:0)
Block(2,71,-6,DIRT:0)
Block(2,71,-5,DIRT:0)
Block(2,71,-4,DIRT:0)
Block(2,71,-3,DIRT:0)
Block(2,71,-2,DIRT:0)
Block(2,71,-1,DIRT:0)
Block(2,71,0,DIRT:0)
Block(2,71,1,DIRT:0)
Block(2,71,2,DIRT:0)
Block(2,71,3,DIRT:0)
Block(2,71,4,DIRT:0)
Block(2,71,5,DIRT:0)
Block(2,71,6,DIRT:0)
Block(2,71,7,DIRT:0)
Block(2,71,8,DIRT:0)
Block(2,72,-2,DIRT:0)
Block(2,72,-1,DIRT:0)
Block(2,72,0,DIRT:0)
Block(2,72,1,DIRT:0)
Block(2,72,2,DIRT:0)
Block(2,72,3,DIRT:0)
Block(2,72,4,DIRT:0)
Block(2,72,5,DIRT:0)
Block(2,72,6,DIRT:0)
Block(2,72,7,DIRT:0)
Block(2,72,8,DIRT:0)
Block(2,73,-2,DIRT:0)
Block(2,73,-1,DIRT:0)
Block(2,73,0,DIRT:0)
Block(2,73,1,DIRT:0)
Block(2,73,2,DIRT:0)
Block(2,73,3,DIRT:0)
Block(2,73,4,DIRT:0)
Block(2,73,5,DIRT:0)
Block(2,73,6,DIRT:0)
Block(2,73,7,DIRT:0)
Block(2,73,8,DIRT:0)
Block(2,74,-1,DIRT:0)
Block(2,74,0,DIRT:0)
Block(2,74,1,DIRT:0)
Block(2,74,2,DIRT:0)
Block(2,74,3,DIRT:0)
Block(2,74,4,DIRT:0)
Block(2,74,5,DIRT:0)
Block(2,74,6,DIRT:0)
Block(2,74,7,DIRT:0)
Block(2,74,8,DIRT:0)
Block(2,75,1,DIRT:0)
Block(2,75,2,DIRT:0)
Block(2,75,3,DIRT:0)
Block(2,75,4,DIRT:0)
Block(2,75,5,DIRT:0)
Block(2,75,6,DIRT:0)
Block(2,75,7,DIRT:0)
Block(2,75,8,DIRT:0)
Block(2,76,4,DIRT:0)
Block(2,76,5,DIRT:0)
Block(2,76,6,srparasites:parasiterubbledense:1)
Block(2,76,7,srparasites:parasiterubbledense:1)
Block(2,76,8,srparasites:parasiterubbledense:1)
Block(2,77,6,DIRT:0)
Block(2,77,7,DIRT:0)
Block(2,77,8,DIRT:0)
Block(2,83,3,AIR:0)
Block(2,83,4,AIR:0)
Block(2,83,5,AIR:0)
Block(2,83,6,AIR:0)
Block(2,83,7,AIR:0)
Block(3,67,-7,DIRT:0)
Block(3,67,-6,DIRT:0)
Block(3,67,-5,DIRT:0)
Block(3,67,-4,DIRT:0)
Block(3,67,-3,DIRT:0)
Block(3,67,-2,DIRT:0)
Block(3,67,-1,DIRT:0)
Block(3,67,0,DIRT:0)
Block(3,67,1,DIRT:0)
Block(3,67,2,DIRT:0)
Block(3,67,3,DIRT:0)
Block(3,67,4,DIRT:0)
Block(3,67,5,DIRT:0)
Block(3,67,6,DIRT:0)
Block(3,67,7,DIRT:0)
Block(3,67,8,DIRT:0)
Block(3,68,-7,DIRT:0)
Block(3,68,-6,DIRT:0)
Block(3,68,-5,DIRT:0)
Block(3,68,-4,DIRT:0)
Block(3,68,-3,DIRT:0)
Block(3,68,-2,DIRT:0)
Block(3,68,-1,DIRT:0)
Block(3,68,0,DIRT:0)
Block(3,68,1,DIRT:0)
Block(3,68,2,DIRT:0)
Block(3,68,3,DIRT:0)
Block(3,68,4,DIRT:0)
Block(3,68,5,DIRT:0)
Block(3,68,6,DIRT:0)
Block(3,68,7,DIRT:0)
Block(3,68,8,DIRT:0)
Block(3,69,-7,DIRT:0)
Block(3,69,-6,DIRT:0)
Block(3,69,-5,DIRT:0)
Block(3,69,-4,DIRT:0)
Block(3,69,-3,DIRT:0)
Block(3,69,-2,DIRT:0)
Block(3,69,-1,DIRT:0)
Block(3,69,0,DIRT:0)
Block(3,69,1,DIRT:0)
Block(3,69,2,DIRT:0)
Block(3,69,3,DIRT:0)
Block(3,69,4,DIRT:0)
Block(3,69,5,DIRT:0)
Block(3,69,6,DIRT:0)
Block(3,69,7,DIRT:0)
Block(3,69,8,DIRT:0)
Block(3,70,-7,DIRT:0)
Block(3,70,-6,DIRT:0)
Block(3,70,-5,DIRT:0)
Block(3,70,-4,DIRT:0)
Block(3,70,-3,DIRT:0)
Block(3,70,-2,DIRT:0)
Block(3,70,-1,DIRT:0)
Block(3,70,0,DIRT:0)
Block(3,70,1,DIRT:0)
Block(3,70,2,DIRT:0)
Block(3,70,3,DIRT:0)
Block(3,70,4,DIRT:0)
Block(3,70,5,DIRT:0)
Block(3,70,6,DIRT:0)
Block(3,70,7,DIRT:0)
Block(3,70,8,DIRT:0)
Block(3,71,-7,DIRT:0)
Block(3,71,-6,DIRT:0)
Block(3,71,-5,DIRT:0)
Block(3,71,-4,DIRT:0)
Block(3,71,-3,DIRT:0)
Block(3,71,-2,DIRT:0)
Block(3,71,-1,DIRT:0)
Block(3,71,0,DIRT:0)
Block(3,71,1,DIRT:0)
Block(3,71,2,DIRT:0)
Block(3,71,3,DIRT:0)
Block(3,71,4,DIRT:0)
Block(3,71,5,DIRT:0)
Block(3,71,6,DIRT:0)
Block(3,71,7,DIRT:0)
Block(3,71,8,DIRT:0)
Block(3,72,-3,DIRT:0)
Block(3,72,-2,DIRT:0)
Block(3,72,-1,DIRT:0)
Block(3,72,0,DIRT:0)
Block(3,72,1,DIRT:0)
Block(3,72,2,DIRT:0)
Block(3,72,3,DIRT:0)
Block(3,72,4,DIRT:0)
Block(3,72,5,DIRT:0)
Block(3,72,6,DIRT:0)
Block(3,72,7,DIRT:0)
Block(3,72,8,DIRT:0)
Block(3,73,-3,DIRT:0)
Block(3,73,-2,DIRT:0)
Block(3,73,-1,DIRT:0)
Block(3,73,0,DIRT:0)
Block(3,73,1,DIRT:0)
Block(3,73,2,DIRT:0)
Block(3,73,3,DIRT:0)
Block(3,73,4,DIRT:0)
Block(3,73,5,DIRT:0)
Block(3,73,6,DIRT:0)
Block(3,73,7,DIRT:0)
Block(3,73,8,DIRT:0)
Block(3,74,-2,DIRT:0)
Block(3,74,-1,DIRT:0)
Block(3,74,0,DIRT:0)
Block(3,74,1,DIRT:0)
Block(3,74,2,DIRT:0)
Block(3,74,3,DIRT:0)
Block(3,74,4,DIRT:0)
Block(3,74,5,DIRT:0)
Block(3,74,6,DIRT:0)
Block(3,74,7,DIRT:0)
Block(3,74,8,DIRT:0)
Block(3,75,0,DIRT:0)
Block(3,75,1,DIRT:0)
Block(3,75,2,DIRT:0)
Block(3,75,3,DIRT:0)
Block(3,75,4,DIRT:0)
Block(3,75,5,DIRT:0)
Block(3,75,6,DIRT:0)
Block(3,75,7,DIRT:0)
Block(3,75,8,DIRT:0)
Block(3,76,3,DIRT:0)
Block(3,76,4,srparasites:parasiterubbledense:1)
Block(3,76,5,srparasites:parasiterubbledense:1)
Block(3,76,6,srparasites:parasiterubbledense:1)
Block(3,76,7,srparasites:parasiterubbledense:1)
Block(3,76,8,srparasites:parasiterubbledense:1)
Block(3,77,4,DIRT:0)
Block(3,77,5,DIRT:0)
Block(3,77,6,srparasites:parasiterubbledense:1)
Block(3,77,7,srparasites:parasiterubbledense:1)
Block(3,77,8,srparasites:parasiterubbledense:1)
Block(3,78,6,DIRT:0)
Block(3,78,7,DIRT:0)
Block(3,78,8,DIRT:0)
Block(3,83,1,AIR:0)
Block(3,83,2,AIR:0)
Block(3,83,3,AIR:0)
Block(3,83,4,AIR:0)
Block(3,83,5,AIR:0)
Block(3,83,6,AIR:0)
Block(3,83,7,AIR:0)
Block(3,83,8,AIR:0)
Block(4,67,-7,DIRT:0)
Block(4,67,-6,DIRT:0)
Block(4,67,-5,DIRT:0)
Block(4,67,-4,DIRT:0)
Block(4,67,-3,DIRT:0)
Block(4,67,-2,DIRT:0)
Block(4,67,-1,DIRT:0)
Block(4,67,0,DIRT:0)
Block(4,67,1,DIRT:0)
Block(4,67,2,DIRT:0)
Block(4,67,3,DIRT:0)
Block(4,67,4,DIRT:0)
Block(4,67,5,DIRT:0)
Block(4,67,6,DIRT:0)
Block(4,67,7,DIRT:0)
Block(4,67,8,DIRT:0)
Block(4,68,-7,DIRT:0)
Block(4,68,-6,DIRT:0)
Block(4,68,-5,DIRT:0)
Block(4,68,-4,DIRT:0)
Block(4,68,-3,DIRT:0)
Block(4,68,-2,DIRT:0)
Block(4,68,-1,DIRT:0)
Block(4,68,0,DIRT:0)
Block(4,68,1,DIRT:0)
Block(4,68,2,DIRT:0)
Block(4,68,3,DIRT:0)
Block(4,68,4,DIRT:0)
Block(4,68,5,DIRT:0)
Block(4,68,6,DIRT:0)
Block(4,68,7,DIRT:0)
Block(4,68,8,DIRT:0)
Block(4,69,-7,DIRT:0)
Block(4,69,-6,DIRT:0)
Block(4,69,-5,DIRT:0)
Block(4,69,-4,DIRT:0)
Block(4,69,-3,DIRT:0)
Block(4,69,-2,DIRT:0)
Block(4,69,-1,DIRT:0)
Block(4,69,0,DIRT:0)
Block(4,69,1,DIRT:0)
Block(4,69,2,DIRT:0)
Block(4,69,3,DIRT:0)
Block(4,69,4,DIRT:0)
Block(4,69,5,DIRT:0)
Block(4,69,6,DIRT:0)
Block(4,69,7,DIRT:0)
Block(4,69,8,DIRT:0)
Block(4,70,-7,DIRT:0)
Block(4,70,-6,DIRT:0)
Block(4,70,-5,DIRT:0)
Block(4,70,-4,DIRT:0)
Block(4,70,-3,DIRT:0)
Block(4,70,-2,DIRT:0)
Block(4,70,-1,DIRT:0)
Block(4,70,0,DIRT:0)
Block(4,70,1,DIRT:0)
Block(4,70,2,DIRT:0)
Block(4,70,3,DIRT:0)
Block(4,70,4,DIRT:0)
Block(4,70,5,DIRT:0)
Block(4,70,6,DIRT:0)
Block(4,70,7,DIRT:0)
Block(4,70,8,DIRT:0)
Block(4,71,-7,DIRT:0)
Block(4,71,-6,DIRT:0)
Block(4,71,-5,DIRT:0)
Block(4,71,-4,DIRT:0)
Block(4,71,-3,DIRT:0)
Block(4,71,-2,DIRT:0)
Block(4,71,-1,DIRT:0)
Block(4,71,0,DIRT:0)
Block(4,71,1,DIRT:0)
Block(4,71,2,DIRT:0)
Block(4,71,3,DIRT:0)
Block(4,71,4,DIRT:0)
Block(4,71,5,DIRT:0)
Block(4,71,6,DIRT:0)
Block(4,71,7,DIRT:0)
Block(4,71,8,DIRT:0)
Block(4,72,-4,DIRT:0)
Block(4,72,-3,DIRT:0)
Block(4,72,-2,DIRT:0)
Block(4,72,-1,DIRT:0)
Block(4,72,0,DIRT:0)
Block(4,72,1,DIRT:0)
Block(4,72,2,DIRT:0)
Block(4,72,3,DIRT:0)
Block(4,72,4,DIRT:0)
Block(4,72,5,DIRT:0)
Block(4,72,6,DIRT:0)
Block(4,72,7,DIRT:0)
Block(4,72,8,DIRT:0)
Block(4,73,-3,DIRT:0)
Block(4,73,-2,DIRT:0)
Block(4,73,-1,DIRT:0)
Block(4,73,0,DIRT:0)
Block(4,73,1,DIRT:0)
Block(4,73,2,DIRT:0)
Block(4,73,3,DIRT:0)
Block(4,73,4,DIRT:0)
Block(4,73,5,DIRT:0)
Block(4,73,6,DIRT:0)
Block(4,73,7,DIRT:0)
Block(4,73,8,DIRT:0)
Block(4,74,-3,DIRT:0)
Block(4,74,-2,DIRT:0)
Block(4,74,-1,DIRT:0)
Block(4,74,0,DIRT:0)
Block(4,74,1,DIRT:0)
Block(4,74,2,DIRT:0)
Block(4,74,3,DIRT:0)
Block(4,74,4,DIRT:0)
Block(4,74,5,DIRT:0)
Block(4,74,6,DIRT:0)
Block(4,74,7,DIRT:0)
Block(4,74,8,DIRT:0)
Block(4,75,0,DIRT:0)
Block(4,75,1,DIRT:0)
Block(4,75,2,DIRT:0)
Block(4,75,3,DIRT:0)
Block(4,75,4,DIRT:0)
Block(4,75,5,DIRT:0)
Block(4,75,6,DIRT:0)
Block(4,75,7,DIRT:0)
Block(4,75,8,DIRT:0)
Block(4,76,2,DIRT:0)
Block(4,76,3,srparasites:parasiterubbledense:1)
Block(4,76,4,srparasites:parasiterubbledense:1)
Block(4,76,5,srparasites:parasiterubbledense:1)
Block(4,76,6,DIRT:0)
Block(4,76,7,DIRT:0)
Block(4,76,8,DIRT:0)
Block(4,77,3,DIRT:0)
Block(4,77,4,srparasites:parasiterubbledense:1)
Block(4,77,5,srparasites:parasiterubbledense:1)
Block(4,77,6,srparasites:parasiterubbledense:1)
Block(4,77,7,srparasites:parasiterubbledense:1)
Block(4,77,8,srparasites:parasiterubbledense:1)
Block(4,78,4,DIRT:0)
Block(4,78,5,DIRT:0)
Block(4,78,6,srparasites:parasiterubbledense:1)
Block(4,78,7,srparasites:parasiterubbledense:1)
Block(4,78,8,srparasites:parasiterubbledense:1)
Block(4,79,4,DIRT:0)
Block(4,79,5,DIRT:0)
Block(4,79,6,DIRT:0)
Block(4,79,7,DIRT:0)
Block(4,79,8,DIRT:0)
Block(4,82,4,AIR:0)
Block(4,82,5,AIR:0)
Block(4,82,6,AIR:0)
Block(4,82,7,AIR:0)
Block(4,82,8,AIR:0)
Block(4,83,0,AIR:0)
Block(4,83,1,AIR:0)
Block(4,83,2,AIR:0)
Block(4,83,3,AIR:0)
Block(4,83,4,AIR:0)
Block(4,83,5,AIR:0)
Block(4,83,6,AIR:0)
Block(4,83,7,AIR:0)
Block(4,83,8,AIR:0)
Block(5,67,-7,DIRT:0)
Block(5,67,-6,DIRT:0)
Block(5,67,-5,DIRT:0)
Block(5,67,-4,DIRT:0)
Block(5,67,-3,DIRT:0)
Block(5,67,-2,DIRT:0)
Block(5,67,-1,DIRT:0)
Block(5,67,0,DIRT:0)
Block(5,67,1,DIRT:0)
Block(5,67,2,DIRT:0)
Block(5,67,3,DIRT:0)
Block(5,67,4,DIRT:0)
Block(5,67,5,DIRT:0)
Block(5,67,6,DIRT:0)
Block(5,67,7,DIRT:0)
Block(5,67,8,DIRT:0)
Block(5,68,-7,DIRT:0)
Block(5,68,-6,DIRT:0)
Block(5,68,-5,DIRT:0)
Block(5,68,-4,DIRT:0)
Block(5,68,-3,DIRT:0)
Block(5,68,-2,DIRT:0)
Block(5,68,-1,DIRT:0)
Block(5,68,0,DIRT:0)
Block(5,68,1,DIRT:0)
Block(5,68,2,DIRT:0)
Block(5,68,3,DIRT:0)
Block(5,68,4,DIRT:0)
Block(5,68,5,DIRT:0)
Block(5,68,6,DIRT:0)
Block(5,68,7,DIRT:0)
Block(5,68,8,DIRT:0)
Block(5,69,-7,DIRT:0)
Block(5,69,-6,DIRT:0)
Block(5,69,-5,DIRT:0)
Block(5,69,-4,DIRT:0)
Block(5,69,-3,DIRT:0)
Block(5,69,-2,DIRT:0)
Block(5,69,-1,DIRT:0)
Block(5,69,0,DIRT:0)
Block(5,69,1,DIRT:0)
Block(5,69,2,DIRT:0)
Block(5,69,3,DIRT:0)
Block(5,69,4,DIRT:0)
Block(5,69,5,DIRT:0)
Block(5,69,6,DIRT:0)
Block(5,69,7,DIRT:0)
Block(5,69,8,DIRT:0)
Block(5,70,-7,DIRT:0)
Block(5,70,-6,DIRT:0)
Block(5,70,-5,DIRT:0)
Block(5,70,-4,DIRT:0)
Block(5,70,-3,DIRT:0)
Block(5,70,-2,DIRT:0)
Block(5,70,-1,DIRT:0)
Block(5,70,0,DIRT:0)
Block(5,70,1,DIRT:0)
Block(5,70,2,DIRT:0)
Block(5,70,3,DIRT:0)
Block(5,70,4,DIRT:0)
Block(5,70,5,DIRT:0)
Block(5,70,6,DIRT:0)
Block(5,70,7,DIRT:0)
Block(5,70,8,DIRT:0)
Block(5,71,-7,DIRT:0)
Block(5,71,-6,DIRT:0)
Block(5,71,-5,DIRT:0)
Block(5,71,-4,DIRT:0)
Block(5,71,-3,DIRT:0)
Block(5,71,-2,DIRT:0)
Block(5,71,-1,DIRT:0)
Block(5,71,0,DIRT:0)
Block(5,71,1,DIRT:0)
Block(5,71,2,DIRT:0)
Block(5,71,3,DIRT:0)
Block(5,71,4,DIRT:0)
Block(5,71,5,DIRT:0)
Block(5,71,6,DIRT:0)
Block(5,71,7,DIRT:0)
Block(5,71,8,DIRT:0)
Block(5,72,-5,DIRT:0)
Block(5,72,-4,DIRT:0)
Block(5,72,-3,DIRT:0)
Block(5,72,-2,DIRT:0)
Block(5,72,-1,DIRT:0)
Block(5,72,0,DIRT:0)
Block(5,72,1,DIRT:0)
Block(5,72,2,DIRT:0)
Block(5,72,3,DIRT:0)
Block(5,72,4,DIRT:0)
Block(5,72,5,DIRT:0)
Block(5,72,6,DIRT:0)
Block(5,72,7,DIRT:0)
Block(5,72,8,DIRT:0)
Block(5,73,-4,DIRT:0)
Block(5,73,-3,DIRT:0)
Block(5,73,-2,DIRT:0)
Block(5,73,-1,DIRT:0)
Block(5,73,0,DIRT:0)
Block(5,73,1,DIRT:0)
Block(5,73,2,DIRT:0)
Block(5,73,3,DIRT:0)
Block(5,73,4,DIRT:0)
Block(5,73,5,DIRT:0)
Block(5,73,6,DIRT:0)
Block(5,73,7,DIRT:0)
Block(5,73,8,DIRT:0)
Block(5,74,-4,DIRT:0)
Block(5,74,-3,DIRT:0)
Block(5,74,-2,DIRT:0)
Block(5,74,-1,DIRT:0)
Block(5,74,0,DIRT:0)
Block(5,74,1,DIRT:0)
Block(5,74,2,DIRT:0)
Block(5,74,3,DIRT:0)
Block(5,74,4,DIRT:0)
Block(5,74,5,DIRT:0)
Block(5,74,6,DIRT:0)
Block(5,74,7,DIRT:0)
Block(5,74,8,DIRT:0)
Block(5,75,-1,DIRT:0)
Block(5,75,0,DIRT:0)
Block(5,75,1,DIRT:0)
Block(5,75,2,DIRT:0)
Block(5,75,3,DIRT:0)
Block(5,75,4,DIRT:0)
Block(5,75,5,DIRT:0)
Block(5,75,6,DIRT:0)
Block(5,75,7,DIRT:0)
Block(5,75,8,DIRT:0)
Block(5,76,1,DIRT:0)
Block(5,76,2,srparasites:parasiterubbledense:1)
Block(5,76,3,srparasites:parasiterubbledense:1)
Block(5,76,4,DIRT:0)
Block(5,76,5,DIRT:0)
Block(5,76,6,DIRT:0)
Block(5,76,7,DIRT:0)
Block(5,76,8,DIRT:0)
Block(5,77,2,DIRT:0)
Block(5,77,3,srparasites:parasiterubbledense:1)
Block(5,77,4,srparasites:parasiterubbledense:1)
Block(5,77,5,srparasites:parasiterubbledense:1)
Block(5,77,6,srparasites:parasiterubbledense:1)
Block(5,77,7,srparasites:parasiterubbledense:1)
Block(5,77,8,srparasites:parasiterubbledense:1)
Block(5,78,3,DIRT:0)
Block(5,78,4,srparasites:parasiterubbledense:1)
Block(5,78,5,srparasites:parasiterubbledense:1)
Block(5,78,6,srparasites:parasiterubbledense:1)
Block(5,78,7,srparasites:parasiterubbledense:1)
Block(5,78,8,srparasites:parasiterubbledense:1)
Block(5,79,3,DIRT:0)
Block(5,79,4,srparasites:parasiterubbledense:1)
Block(5,79,5,srparasites:parasiterubbledense:1)
Block(5,79,6,srparasites:parasiterubbledense:1)
Block(5,79,7,srparasites:parasiterubbledense:1)
Block(5,79,8,srparasites:parasiterubbledense:1)
Block(5,80,4,DIRT:0)
Block(5,80,5,DIRT:0)
Block(5,80,6,DIRT:0)
Block(5,80,7,DIRT:0)
Block(5,80,8,DIRT:0)
Block(5,81,6,SMOOTH_BRICK:0)
Block(5,81,7,SMOOTH_BRICK:0)
Block(5,81,8,SMOOTH_BRICK:0)
Block(5,82,3,AIR:0)
Block(5,82,4,AIR:0)
Block(5,82,5,AIR:0)
Block(5,82,6,AIR:0)
Block(5,82,7,AIR:0)
Block(5,82,8,AIR:0)
Block(5,83,-2,AIR:0)
Block(5,83,-1,AIR:0)
Block(5,83,0,AIR:0)
Block(5,83,1,AIR:0)
Block(5,83,2,AIR:0)
Block(5,83,3,AIR:0)
Block(5,83,4,AIR:0)
Block(5,83,5,AIR:0)
Block(5,83,6,AIR:0)
Block(5,83,7,AIR:0)
Block(5,83,8,AIR:0)
Block(6,67,-7,DIRT:0)
Block(6,67,-6,DIRT:0)
Block(6,67,-5,DIRT:0)
Block(6,67,-4,DIRT:0)
Block(6,67,-3,DIRT:0)
Block(6,67,-2,DIRT:0)
Block(6,67,-1,DIRT:0)
Block(6,67,0,DIRT:0)
Block(6,67,1,DIRT:0)
Block(6,67,2,DIRT:0)
Block(6,67,3,DIRT:0)
Block(6,67,4,DIRT:0)
Block(6,67,5,DIRT:0)
Block(6,67,6,DIRT:0)
Block(6,67,7,DIRT:0)
Block(6,67,8,DIRT:0)
Block(6,68,-7,DIRT:0)
Block(6,68,-6,DIRT:0)
Block(6,68,-5,DIRT:0)
Block(6,68,-4,DIRT:0)
Block(6,68,-3,DIRT:0)
Block(6,68,-2,DIRT:0)
Block(6,68,-1,DIRT:0)
Block(6,68,0,DIRT:0)
Block(6,68,1,DIRT:0)
Block(6,68,2,DIRT:0)
Block(6,68,3,DIRT:0)
Block(6,68,4,DIRT:0)
Block(6,68,5,DIRT:0)
Block(6,68,6,DIRT:0)
Block(6,68,7,DIRT:0)
Block(6,68,8,DIRT:0)
Block(6,69,-7,DIRT:0)
Block(6,69,-6,DIRT:0)
Block(6,69,-5,DIRT:0)
Block(6,69,-4,DIRT:0)
Block(6,69,-3,DIRT:0)
Block(6,69,-2,DIRT:0)
Block(6,69,-1,DIRT:0)
Block(6,69,0,DIRT:0)
Block(6,69,1,DIRT:0)
Block(6,69,2,DIRT:0)
Block(6,69,3,DIRT:0)
Block(6,69,4,DIRT:0)
Block(6,69,5,DIRT:0)
Block(6,69,6,DIRT:0)
Block(6,69,7,DIRT:0)
Block(6,69,8,DIRT:0)
Block(6,70,-7,DIRT:0)
Block(6,70,-6,DIRT:0)
Block(6,70,-5,DIRT:0)
Block(6,70,-4,DIRT:0)
Block(6,70,-3,DIRT:0)
Block(6,70,-2,DIRT:0)
Block(6,70,-1,DIRT:0)
Block(6,70,0,DIRT:0)
Block(6,70,1,DIRT:0)
Block(6,70,2,DIRT:0)
Block(6,70,3,DIRT:0)
Block(6,70,4,DIRT:0)
Block(6,70,5,DIRT:0)
Block(6,70,6,DIRT:0)
Block(6,70,7,DIRT:0)
Block(6,70,8,DIRT:0)
Block(6,71,-7,DIRT:0)
Block(6,71,-6,DIRT:0)
Block(6,71,-5,DIRT:0)
Block(6,71,-4,DIRT:0)
Block(6,71,-3,DIRT:0)
Block(6,71,-2,DIRT:0)
Block(6,71,-1,DIRT:0)
Block(6,71,0,DIRT:0)
Block(6,71,1,DIRT:0)
Block(6,71,2,DIRT:0)
Block(6,71,3,DIRT:0)
Block(6,71,4,DIRT:0)
Block(6,71,5,DIRT:0)
Block(6,71,6,DIRT:0)
Block(6,71,7,DIRT:0)
Block(6,71,8,DIRT:0)
Block(6,72,-6,DIRT:0)
Block(6,72,-5,DIRT:0)
Block(6,72,-4,DIRT:0)
Block(6,72,-3,DIRT:0)
Block(6,72,-2,DIRT:0)
Block(6,72,-1,DIRT:0)
Block(6,72,0,DIRT:0)
Block(6,72,1,DIRT:0)
Block(6,72,2,DIRT:0)
Block(6,72,3,DIRT:0)
Block(6,72,4,DIRT:0)
Block(6,72,5,DIRT:0)
Block(6,72,6,DIRT:0)
Block(6,72,7,DIRT:0)
Block(6,72,8,DIRT:0)
Block(6,73,-5,DIRT:0)
Block(6,73,-4,DIRT:0)
Block(6,73,-3,DIRT:0)
Block(6,73,-2,DIRT:0)
Block(6,73,-1,DIRT:0)
Block(6,73,0,DIRT:0)
Block(6,73,1,DIRT:0)
Block(6,73,2,DIRT:0)
Block(6,73,3,DIRT:0)
Block(6,73,4,DIRT:0)
Block(6,73,5,DIRT:0)
Block(6,73,6,DIRT:0)
Block(6,73,7,DIRT:0)
Block(6,73,8,DIRT:0)
Block(6,74,-5,DIRT:0)
Block(6,74,-4,DIRT:0)
Block(6,74,-3,DIRT:0)
Block(6,74,-2,DIRT:0)
Block(6,74,-1,DIRT:0)
Block(6,74,0,DIRT:0)
Block(6,74,1,DIRT:0)
Block(6,74,2,DIRT:0)
Block(6,74,3,DIRT:0)
Block(6,74,4,DIRT:0)
Block(6,74,5,DIRT:0)
Block(6,74,6,DIRT:0)
Block(6,74,7,DIRT:0)
Block(6,74,8,DIRT:0)
Block(6,75,-2,DIRT:0)
Block(6,75,-1,DIRT:0)
Block(6,75,0,DIRT:0)
Block(6,75,1,DIRT:0)
Block(6,75,2,DIRT:0)
Block(6,75,3,DIRT:0)
Block(6,75,4,DIRT:0)
Block(6,75,5,DIRT:0)
Block(6,75,6,DIRT:0)
Block(6,75,7,DIRT:0)
Block(6,75,8,DIRT:0)
Block(6,76,0,DIRT:0)
Block(6,76,1,srparasites:parasiterubbledense:1)
Block(6,76,2,srparasites:parasiterubbledense:1)
Block(6,76,3,DIRT:0)
Block(6,76,4,DIRT:0)
Block(6,76,5,DIRT:0)
Block(6,76,6,DIRT:0)
Block(6,76,7,DIRT:0)
Block(6,76,8,DIRT:0)
Block(6,77,1,DIRT:0)
Block(6,77,2,srparasites:parasiterubbledense:1)
Block(6,77,3,srparasites:parasiterubbledense:1)
Block(6,77,4,DIRT:0)
Block(6,77,5,DIRT:0)
Block(6,77,6,DIRT:0)
Block(6,77,7,DIRT:0)
Block(6,77,8,DIRT:0)
Block(6,78,2,DIRT:0)
Block(6,78,3,srparasites:parasiterubbledense:1)
Block(6,78,4,srparasites:parasiterubbledense:1)
Block(6,78,5,srparasites:parasiterubbledense:1)
Block(6,78,6,srparasites:parasiterubbledense:1)
Block(6,78,7,srparasites:parasiterubbledense:1)
Block(6,78,8,srparasites:parasiterubbledense:1)
Block(6,79,2,DIRT:0)
Block(6,79,3,srparasites:parasiterubbledense:1)
Block(6,79,4,srparasites:parasiterubbledense:1)
Block(6,79,5,srparasites:parasiterubbledense:1)
Block(6,79,6,srparasites:parasiterubbledense:1)
Block(6,79,7,srparasites:parasiterubbledense:1)
Block(6,79,8,srparasites:parasiterubbledense:1)
Block(6,80,3,DIRT:0)
Block(6,80,4,srparasites:parasiterubbledense:1)
Block(6,80,5,srparasites:parasiterubbledense:1)
Block(6,80,6,srparasites:parasiterubbledense:1)
Block(6,80,7,srparasites:parasiterubbledense:1)
Block(6,80,8,srparasites:parasiterubbledense:1)
Block(6,81,3,SMOOTH_BRICK:0)
Block(6,81,4,SMOOTH_BRICK:0)
Block(6,81,5,SMOOTH_BRICK:0)
Block(6,81,6,SMOOTH_BRICK:0)
Block(6,81,7,AIR:0)
Block(6,81,8,SMOOTH_BRICK:0)
Block(6,82,1,AIR:0)
Block(6,82,2,AIR:0)
Block(6,82,3,AIR:0)
Block(6,82,4,AIR:0)
Block(6,82,5,AIR:0)
Block(6,82,6,AIR:0)
Block(6,82,7,AIR:0)
Block(6,82,8,AIR:0)
Block(6,83,-3,AIR:0)
Block(6,83,-2,AIR:0)
Block(6,83,-1,AIR:0)
Block(6,83,0,AIR:0)
Block(6,83,1,AIR:0)
Block(6,83,2,AIR:0)
Block(6,83,3,AIR:0)
Block(6,83,4,AIR:0)
Block(6,83,5,AIR:0)
Block(6,83,6,AIR:0)
Block(6,83,7,AIR:0)
Block(6,83,8,AIR:0)
Block(7,67,-7,DIRT:0)
Block(7,67,-6,DIRT:0)
Block(7,67,-5,DIRT:0)
Block(7,67,-4,DIRT:0)
Block(7,67,-3,DIRT:0)
Block(7,67,-2,DIRT:0)
Block(7,67,-1,DIRT:0)
Block(7,67,0,DIRT:0)
Block(7,67,1,DIRT:0)
Block(7,67,2,DIRT:0)
Block(7,67,3,DIRT:0)
Block(7,67,4,DIRT:0)
Block(7,67,5,DIRT:0)
Block(7,67,6,DIRT:0)
Block(7,67,7,DIRT:0)
Block(7,67,8,DIRT:0)
Block(7,68,-7,DIRT:0)
Block(7,68,-6,DIRT:0)
Block(7,68,-5,DIRT:0)
Block(7,68,-4,DIRT:0)
Block(7,68,-3,DIRT:0)
Block(7,68,-2,DIRT:0)
Block(7,68,-1,DIRT:0)
Block(7,68,0,DIRT:0)
Block(7,68,1,DIRT:0)
Block(7,68,2,DIRT:0)
Block(7,68,3,DIRT:0)
Block(7,68,4,DIRT:0)
Block(7,68,5,DIRT:0)
Block(7,68,6,DIRT:0)
Block(7,68,7,DIRT:0)
Block(7,68,8,DIRT:0)
Block(7,69,-7,DIRT:0)
Block(7,69,-6,DIRT:0)
Block(7,69,-5,DIRT:0)
Block(7,69,-4,DIRT:0)
Block(7,69,-3,DIRT:0)
Block(7,69,-2,DIRT:0)
Block(7,69,-1,DIRT:0)
Block(7,69,0,DIRT:0)
Block(7,69,1,DIRT:0)
Block(7,69,2,DIRT:0)
Block(7,69,3,DIRT:0)
Block(7,69,4,DIRT:0)
Block(7,69,5,DIRT:0)
Block(7,69,6,DIRT:0)
Block(7,69,7,DIRT:0)
Block(7,69,8,DIRT:0)
Block(7,70,-7,DIRT:0)
Block(7,70,-6,DIRT:0)
Block(7,70,-5,DIRT:0)
Block(7,70,-4,DIRT:0)
Block(7,70,-3,DIRT:0)
Block(7,70,-2,DIRT:0)
Block(7,70,-1,DIRT:0)
Block(7,70,0,DIRT:0)
Block(7,70,1,DIRT:0)
Block(7,70,2,DIRT:0)
Block(7,70,3,DIRT:0)
Block(7,70,4,DIRT:0)
Block(7,70,5,DIRT:0)
Block(7,70,6,DIRT:0)
Block(7,70,7,DIRT:0)
Block(7,70,8,DIRT:0)
Block(7,71,-7,DIRT:0)
Block(7,71,-6,DIRT:0)
Block(7,71,-5,DIRT:0)
Block(7,71,-4,DIRT:0)
Block(7,71,-3,DIRT:0)
Block(7,71,-2,DIRT:0)
Block(7,71,-1,DIRT:0)
Block(7,71,0,DIRT:0)
Block(7,71,1,DIRT:0)
Block(7,71,2,DIRT:0)
Block(7,71,3,DIRT:0)
Block(7,71,4,DIRT:0)
Block(7,71,5,DIRT:0)
Block(7,71,6,DIRT:0)
Block(7,71,7,DIRT:0)
Block(7,71,8,DIRT:0)
Block(7,72,-7,DIRT:0)
Block(7,72,-6,DIRT:0)
Block(7,72,-5,DIRT:0)
Block(7,72,-4,DIRT:0)
Block(7,72,-3,DIRT:0)
Block(7,72,-2,DIRT:0)
Block(7,72,-1,DIRT:0)
Block(7,72,0,DIRT:0)
Block(7,72,1,DIRT:0)
Block(7,72,2,DIRT:0)
Block(7,72,3,DIRT:0)
Block(7,72,4,DIRT:0)
Block(7,72,5,DIRT:0)
Block(7,72,6,DIRT:0)
Block(7,72,7,DIRT:0)
Block(7,72,8,DIRT:0)
Block(7,73,-6,DIRT:0)
Block(7,73,-5,DIRT:0)
Block(7,73,-4,DIRT:0)
Block(7,73,-3,DIRT:0)
Block(7,73,-2,DIRT:0)
Block(7,73,-1,DIRT:0)
Block(7,73,0,DIRT:0)
Block(7,73,1,DIRT:0)
Block(7,73,2,DIRT:0)
Block(7,73,3,DIRT:0)
Block(7,73,4,DIRT:0)
Block(7,73,5,DIRT:0)
Block(7,73,6,DIRT:0)
Block(7,73,7,DIRT:0)
Block(7,73,8,DIRT:0)
Block(7,74,-5,DIRT:0)
Block(7,74,-4,DIRT:0)
Block(7,74,-3,DIRT:0)
Block(7,74,-2,DIRT:0)
Block(7,74,-1,DIRT:0)
Block(7,74,0,DIRT:0)
Block(7,74,1,DIRT:0)
Block(7,74,2,DIRT:0)
Block(7,74,3,DIRT:0)
Block(7,74,4,DIRT:0)
Block(7,74,5,DIRT:0)
Block(7,74,6,DIRT:0)
Block(7,74,7,DIRT:0)
Block(7,74,8,DIRT:0)
Block(7,75,-2,DIRT:0)
Block(7,75,-1,DIRT:0)
Block(7,75,0,DIRT:0)
Block(7,75,1,DIRT:0)
Block(7,75,2,DIRT:0)
Block(7,75,3,DIRT:0)
Block(7,75,4,DIRT:0)
Block(7,75,5,DIRT:0)
Block(7,75,6,DIRT:0)
Block(7,75,7,DIRT:0)
Block(7,75,8,DIRT:0)
Block(7,76,-1,DIRT:0)
Block(7,76,0,srparasites:parasiterubbledense:1)
Block(7,76,1,srparasites:parasiterubbledense:1)
Block(7,76,2,DIRT:0)
Block(7,76,3,DIRT:0)
Block(7,76,4,DIRT:0)
Block(7,76,5,DIRT:0)
Block(7,76,6,DIRT:0)
Block(7,76,7,DIRT:0)
Block(7,76,8,DIRT:0)
Block(7,77,0,DIRT:0)
Block(7,77,1,srparasites:parasiterubbledense:1)
Block(7,77,2,srparasites:parasiterubbledense:1)
Block(7,77,3,DIRT:0)
Block(7,77,4,DIRT:0)
Block(7,77,5,DIRT:0)
Block(7,77,6,DIRT:0)
Block(7,77,7,DIRT:0)
Block(7,77,8,DIRT:0)
Block(7,78,1,DIRT:0)
Block(7,78,2,srparasites:parasiterubbledense:1)
Block(7,78,3,srparasites:parasiterubbledense:1)
Block(7,78,4,DIRT:0)
Block(7,78,5,DIRT:0)
Block(7,78,6,DIRT:0)
Block(7,78,7,DIRT:0)
Block(7,78,8,DIRT:0)
Block(7,79,1,DIRT:0)
Block(7,79,2,srparasites:parasiterubbledense:1)
Block(7,79,3,srparasites:parasiterubbledense:1)
Block(7,79,4,srparasites:parasiterubbledense:1)
Block(7,79,5,srparasites:parasiterubbledense:1)
Block(7,79,6,srparasites:parasiterubbledense:1)
Block(7,79,7,srparasites:parasiterubbledense:1)
Block(7,79,8,srparasites:parasiterubbledense:1)
Block(7,80,2,DIRT:0)
Block(7,80,3,srparasites:parasiterubbledense:1)
Block(7,80,4,srparasites:parasiterubbledense:1)
Block(7,80,5,srparasites:parasiterubbledense:1)
Block(7,80,6,srparasites:parasiterubbledense:1)
Block(7,80,7,srparasites:parasiterubbledense:1)
Block(7,80,8,srparasites:parasiterubbledense:1)
Block(7,81,2,SMOOTH_BRICK:0)
Block(7,81,3,AIR:0)
Block(7,81,4,AIR:0)
Block(7,81,5,SMOOTH_BRICK:0)
Block(7,81,6,AIR:0)
Block(7,81,7,STONE:0)
Block(7,81,8,SMOOTH_BRICK:0)
Block(7,82,0,AIR:0)
Block(7,82,1,AIR:0)
Block(7,82,2,AIR:0)
Block(7,82,3,AIR:0)
Block(7,82,4,AIR:0)
Block(7,82,5,AIR:0)
Block(7,82,6,AIR:0)
Block(7,82,7,AIR:0)
Block(7,82,8,AIR:0)
Block(7,83,-4,AIR:0)
Block(7,83,-3,AIR:0)
Block(7,83,-2,AIR:0)
Block(7,83,-1,AIR:0)
Block(7,83,0,AIR:0)
Block(7,83,1,AIR:0)
Block(7,83,2,AIR:0)
Block(7,83,3,AIR:0)
Block(7,83,4,AIR:0)
Block(7,83,5,AIR:0)
Block(7,83,6,AIR:0)
Block(7,83,7,AIR:0)
Block(7,83,8,AIR:0)

#######################################################################
# +-----------------------------------------------------------------+ #
# |                             Branches                            | #
# +-----------------------------------------------------------------+ #
#######################################################################

Branch(0,0,16,true,Dimensional_CystC0R2,NORTH,100.0,0)

#######################################################################
# +-----------------------------------------------------------------+ #
# |                             Entities                            | #
# +-----------------------------------------------------------------+ #
#######################################################################


#######################################################################
# +-----------------------------------------------------------------+ #
# |                            Particles                            | #
# +-----------------------------------------------------------------+ #
#######################################################################


#######################################################################
# +-----------------------------------------------------------------+ #
# |                             Spawners                            | #
# +-----------------------------------------------------------------+ #
#######################################################################


#######################################################################
# +-----------------------------------------------------------------+ #
# |                             ModData                             | #
# +-----------------------------------------------------------------+ #
#######################################################################

