
#######################################################################
# +-----------------------------------------------------------------+ #
# |                            BO4 object                           | #
# +-----------------------------------------------------------------+ #
#######################################################################

Author: NLBlackEagle

Description: No description given

SettingsMode: WriteWithoutComments


#######################################################################
# +-----------------------------------------------------------------+ #
# |                          Main settings                          | #
# +-----------------------------------------------------------------+ #
#######################################################################

FixedRotation: 

Frequency: 0

SpawnHeight: highestBlock

UseCenterForHighestBlock: true

##############################
# Height Limits for the BO4. #
##############################

MinHeight: 0

MaxHeight: 255

InheritBO3: 

InheritBO3Rotation: NORTH

OverrideChildSettings: true

OverrideParentHeight: false

CanOverride: false

BranchFrequency: 0

BranchFrequencyGroup: 

MustBeBelowOther: false

MustBeInside: 

CannotBeInside: 

ReplacesBO3: 

MustBeInsideWorldBorders: true

CanSpawnOnWater: true

SpawnOnWaterOnly: false

SpawnUnderWater: false

SpawnAtWaterLevel: false

HeightOffset: 0

RemoveAir: false

ReplaceAbove: 

ReplaceBelow: 

ReplaceWithBiomeBlocks: true

ReplaceWithSurfaceBlock: GRASS

ReplaceWithGroundBlock: DIRT

ReplaceWithStoneBlock: STONE

SmoothRadius: 0

SmoothHeightOffset: 0

SmoothStartTop: false

SmoothStartWood: false

SmoothingSurfaceBlock: 

SmoothingGroundBlock: 

BO3Group: 

IsSpawnPoint: false

DoReplaceBlocks: true


#######################################################################
# +-----------------------------------------------------------------+ #
# |                              Blocks                             | #
# +-----------------------------------------------------------------+ #
#######################################################################

Block(-8,1,-7,srparasites:parasiterubbledense:1)
Block(-8,1,-6,srparasites:parasiterubbledense:1)
Block(-8,1,-5,srparasites:parasiterubbledense:1)
Block(-8,1,-4,srparasites:parasiterubbledense:1)
Block(-8,1,-3,srparasites:parasiterubbledense:1)
Block(-8,2,-7,srparasites:parasiterubbledense:1)
Block(-8,2,-6,srparasites:parasiterubbledense:1)
Block(-8,2,-5,srparasites:parasiterubbledense:1)
Block(-8,2,-4,srparasites:parasiterubbledense:1)
Block(-8,2,-3,srparasites:parasiterubbledense:1)
Block(-8,2,-2,srparasites:parasiterubbledense:1)
Block(-8,3,-7,srparasites:parasiterubbledense:1)
Block(-8,3,-6,srparasites:parasiterubbledense:1)
Block(-8,3,-5,srparasites:parasiterubbledense:1)
Block(-8,3,-3,srparasites:parasiterubbledense:1)
Block(-8,4,-7,srparasites:parasiterubbledense:1)
Block(-8,4,-6,srparasites:parasiterubbledense:1)
Block(-8,4,-5,srparasites:parasiterubbledense:1)
Block(-8,5,-7,srparasites:parasiterubbledense:1)
Block(-8,5,-6,srparasites:parasiterubbledense:1)
Block(-8,5,-5,srparasites:parasiterubbledense:1)
Block(-8,6,-7,srparasites:parasiterubbledense:1)
Block(-8,6,-6,srparasites:parasiterubbledense:1)
Block(-8,6,-5,srparasites:parasiterubbledense:1)
Block(-8,7,-7,srparasites:parasiterubbledense:1)
Block(-8,7,-6,srparasites:parasiterubbledense:1)
Block(-8,7,-5,srparasites:parasiterubbledense:1)
Block(-8,8,-7,srparasites:parasiterubbledense)
Block(-8,8,-6,srparasites:parasiterubbledense:1)
Block(-8,8,-5,srparasites:parasiterubbledense:1)
Block(-8,9,-7,srparasites:parasiterubbledense)
Block(-8,9,-6,AIR:0)
Block(-8,9,-5,srparasites:parasiterubbledense:1)
Block(-8,10,-7,srparasites:parasiterubbledense:1)
Block(-8,10,-6,srparasites:parasiterubbledense:1)
Block(-8,10,-5,srparasites:parasiterubbledense:1)
Block(-8,11,-7,srparasites:parasiterubbledense:1)
Block(-8,11,-6,srparasites:parasiterubbledense:1)
Block(-8,11,-5,srparasites:parasiterubbledense:1)
Block(-8,11,-4,srparasites:parasiterubbledense:1)
Block(-8,12,-7,srparasites:parasiterubbledense:1)
Block(-8,12,-6,srparasites:parasiterubbledense:1)
Block(-8,12,-5,srparasites:parasiterubbledense:1)
Block(-8,12,-4,srparasites:parasiterubbledense:1)
Block(-8,13,-7,srparasites:parasiterubbledense:1)
Block(-8,13,-6,srparasites:parasiterubbledense:1)
Block(-8,13,-5,srparasites:parasiterubbledense:1)
Block(-8,13,-4,srparasites:parasiterubbledense:1)
Block(-8,14,-7,srparasites:parasiterubbledense:1)
Block(-8,14,-6,srparasites:parasiterubbledense:1)
Block(-8,14,-5,srparasites:parasiterubbledense:1)
Block(-8,15,-7,srparasites:parasiterubbledense:1)
Block(-8,15,-6,srparasites:parasiterubbledense:1)
Block(-8,15,-5,srparasites:parasiterubbledense:1)
Block(-8,16,-7,srparasites:parasiterubbledense:1)
Block(-8,16,-6,srparasites:parasiterubbledense:1)
Block(-8,16,-5,srparasites:parasiterubbledense:1)
Block(-8,17,-7,srparasites:parasiterubbledense:1)
Block(-8,17,-6,AIR:0)
Block(-8,17,-5,srparasites:parasiterubbledense:1)
Block(-8,18,-7,srparasites:parasiterubbledense:1)
Block(-8,18,-6,srparasites:parasiterubbledense)
Block(-8,18,-5,AIR:0)
Block(-8,19,-7,srparasites:parasiterubbledense:1)
Block(-8,19,-6,srparasites:parasiterubbledense:1)
Block(-8,19,-5,srparasites:parasiterubbledense:1)
Block(-8,20,-7,srparasites:parasiterubbledense:1)
Block(-8,20,-6,srparasites:parasiterubbledense:1)
Block(-8,20,-5,AIR:0)
Block(-8,21,-7,srparasites:parasiterubbledense:1)
Block(-8,21,-6,srparasites:parasiterubbledense:1)
Block(-8,21,-5,srparasites:parasiterubbledense:1)
Block(-8,21,-4,srparasites:parasiterubbledense:1)
Block(-8,22,-7,srparasites:parasiterubbledense:1)
Block(-8,22,-6,srparasites:parasiterubbledense:1)
Block(-8,22,-5,srparasites:parasiterubbledense:1)
Block(-8,22,-4,srparasites:parasiterubbledense:1)
Block(-8,22,-3,srparasites:parasiterubbledense:1)
Block(-8,23,-7,srparasites:parasiterubbledense:1)
Block(-8,23,-6,srparasites:parasiterubbledense:1)
Block(-8,23,-5,srparasites:parasiterubbledense:1)
Block(-8,23,-4,srparasites:parasiterubbledense:1)
Block(-8,24,-7,srparasites:parasiterubbledense:1)
Block(-8,24,-6,srparasites:parasiterubbledense:1)
Block(-8,24,-5,srparasites:parasiterubbledense:1)
Block(-8,25,-7,srparasites:parasiterubbledense:1)
Block(-8,25,-6,srparasites:parasiterubbledense:1)
Block(-8,25,-5,srparasites:parasiterubbledense:1)
Block(-8,26,-7,srparasites:parasiterubbledense:1)
Block(-8,26,-6,srparasites:parasiterubbledense:1)
Block(-8,26,-5,srparasites:parasiterubbledense)
Block(-8,27,-7,srparasites:parasiterubbledense:1)
Block(-8,27,-6,srparasites:parasiterubbledense)
Block(-8,27,-5,AIR:0)
Block(-8,28,-7,srparasites:parasiterubbledense:1)
Block(-8,28,-6,srparasites:parasiterubbledense)
Block(-8,28,-5,srparasites:parasiterubbledense)
Block(-8,29,-7,srparasites:parasiterubbledense:1)
Block(-8,29,-6,srparasites:parasiterubbledense:1)
Block(-8,29,-5,srparasites:parasiterubbledense:1)
Block(-8,30,-7,srparasites:parasiterubbledense:1)
Block(-8,30,-6,srparasites:parasiterubbledense)
Block(-8,30,-5,srparasites:parasiterubbledense:1)
Block(-8,31,-7,srparasites:parasiterubbledense:1)
Block(-8,31,-6,srparasites:parasiterubbledense:1)
Block(-8,31,-5,srparasites:parasiterubbledense:1)
Block(-8,32,-7,srparasites:parasitebush)
Block(-8,32,-6,srparasites:parasiterubbledense:1)
Block(-8,32,-5,srparasites:parasiterubbledense)
Block(-8,33,-7,srparasites:parasitebush)
Block(-8,33,-6,srparasites:parasiterubbledense:1)
Block(-8,33,-5,srparasites:parasiterubbledense:1)
Block(-8,34,-7,srparasites:parasiterubbledense:1)
Block(-8,34,-6,srparasites:parasiterubbledense:1)
Block(-8,34,-5,srparasites:parasiterubbledense:1)
Block(-8,35,-7,srparasites:parasiterubbledense:1)
Block(-8,35,-6,srparasites:parasiterubbledense:1)
Block(-8,35,-5,srparasites:parasiterubbledense:1)
Block(-8,35,-4,srparasites:parasiterubbledense:1)
Block(-8,35,-3,srparasites:parasiterubbledense:1)
Block(-8,36,-7,srparasites:parasiterubbledense:1)
Block(-8,36,-6,srparasites:parasiterubbledense:1)
Block(-8,36,-5,srparasites:parasiterubbledense:1)
Block(-8,36,-4,srparasites:parasiterubbledense:1)
Block(-8,36,-3,srparasites:parasiterubbledense:1)
Block(-8,37,-7,srparasites:parasiterubbledense:1)
Block(-8,37,-6,srparasites:parasiterubbledense:1)
Block(-8,37,-5,srparasites:parasiterubbledense:1)
Block(-8,37,-4,srparasites:parasiterubbledense:1)
Block(-8,37,-3,srparasites:parasiterubbledense:1)
Block(-8,38,-7,srparasites:parasiterubbledense:1)
Block(-8,38,-6,srparasites:parasiterubbledense:1)
Block(-8,38,-5,srparasites:parasiterubbledense:1)
Block(-8,39,-7,srparasites:parasiterubbledense:1)
Block(-8,39,-6,srparasites:parasiterubbledense)
Block(-8,39,-5,srparasites:parasiterubbledense:1)
Block(-8,40,-7,srparasites:parasiterubbledense:1)
Block(-8,40,-6,AIR:0)
Block(-8,40,-5,srparasites:parasiterubbledense:1)
Block(-8,41,-7,srparasites:parasiterubbledense)
Block(-8,41,-6,srparasites:parasiterubbledense)
Block(-8,41,-5,AIR:0)
Block(-8,42,-7,srparasites:parasiterubbledense:1)
Block(-8,42,-6,srparasites:parasiterubbledense:1)
Block(-8,42,-5,srparasites:parasiterubbledense:1)
Block(-8,43,-7,srparasites:parasiterubbledense:1)
Block(-8,43,-6,srparasites:parasiterubbledense:1)
Block(-8,43,-5,srparasites:parasiterubbledense:1)
Block(-8,44,-7,srparasites:parasiterubbledense:1)
Block(-8,44,-6,srparasites:parasiterubbledense:1)
Block(-8,44,-5,srparasites:parasiterubbledense:1)
Block(-8,45,-7,srparasites:parasiterubbledense:1)
Block(-8,45,-6,srparasites:parasiterubbledense:1)
Block(-8,45,-5,srparasites:parasiterubbledense:1)
Block(-8,46,-7,srparasites:parasiterubbledense:1)
Block(-8,46,-6,srparasites:parasiterubbledense:1)
Block(-8,46,-5,srparasites:parasiterubbledense:1)
Block(-8,46,-4,srparasites:parasiterubbledense:1)
Block(-8,47,-7,srparasites:parasiterubbledense:1)
Block(-8,47,-6,srparasites:parasiterubbledense:1)
Block(-8,47,-5,srparasites:parasiterubbledense:1)
Block(-8,47,-4,srparasites:parasiterubbledense:1)
Block(-8,47,-3,srparasites:parasiterubbledense:1)
Block(-8,48,-7,srparasites:parasitebush)
Block(-8,48,-6,srparasites:parasiterubbledense:1)
Block(-8,48,-5,srparasites:parasiterubbledense:1)
Block(-8,48,-4,srparasites:parasiterubbledense:1)
Block(-8,49,-7,srparasites:parasiterubbledense)
Block(-8,49,-6,srparasites:parasiterubbledense:1)
Block(-8,49,-5,srparasites:parasiterubbledense:1)
Block(-8,50,-7,srparasites:parasiterubbledense)
Block(-8,50,-6,srparasites:parasiterubbledense)
Block(-8,50,-5,srparasites:parasiterubbledense)
Block(-8,51,-7,srparasites:parasiterubbledense:1)
Block(-8,51,-6,srparasites:parasiterubbledense)
Block(-8,51,-5,srparasites:parasiterubbledense)
Block(-8,52,-7,srparasites:parasiterubbledense:1)
Block(-8,52,-6,srparasites:parasiterubbledense:1)
Block(-8,52,-5,srparasites:parasiterubbledense:1)
Block(-8,53,-7,srparasites:parasiterubbledense:1)
Block(-8,53,-6,srparasites:parasiterubbledense:1)
Block(-8,54,-7,srparasites:parasiterubbledense:1)
Block(-8,54,-6,srparasites:parasiterubbledense:1)
Block(-8,54,-4,srparasites:parasiterubbledense:1)
Block(-8,55,-7,AIR:0)
Block(-8,55,-6,srparasites:parasiterubbledense:1)
Block(-8,55,-5,srparasites:parasiterubbledense:1)
Block(-8,55,-4,AIR:0)
Block(-8,55,-3,srparasites:parasiterubbledense:1)
Block(-8,56,-7,AIR:0)
Block(-8,56,-6,srparasites:parasiterubbledense:1)
Block(-8,56,-5,AIR:0)
Block(-8,56,-4,AIR:0)
Block(-8,56,-3,srparasites:parasiterubbledense:1)
Block(-8,57,-7,AIR:0)
Block(-8,57,-6,srparasites:parasiterubbledense:1)
Block(-8,57,-5,srparasites:parasiterubbledense:1)
Block(-8,57,-4,AIR:0)
Block(-8,57,-3,srparasites:parasiterubbledense:1)
Block(-8,57,-2,srparasites:parasiterubbledense:1)
Block(-8,58,-7,AIR:0)
Block(-8,58,-6,AIR:0)
Block(-8,58,-5,srparasites:parasiterubbledense:1)
Block(-8,58,-4,AIR:0)
Block(-8,58,-3,AIR:0)
Block(-8,58,-2,srparasites:parasiterubbledense:1)
Block(-8,59,-7,AIR:0)
Block(-8,59,-6,AIR:0)
Block(-8,59,-5,srparasites:parasiterubbledense:1)
Block(-8,59,-4,AIR:0)
Block(-8,59,-3,AIR:0)
Block(-8,59,-2,srparasites:parasiterubbledense:1)
Block(-8,60,-7,AIR:0)
Block(-8,60,-6,AIR:0)
Block(-8,60,-5,srparasites:parasiterubbledense:1)
Block(-8,60,-4,AIR:0)
Block(-8,60,-3,AIR:0)
Block(-8,60,-2,srparasites:parasiterubbledense:1)
Block(-8,61,-7,AIR:0)
Block(-8,61,-6,AIR:0)
Block(-8,61,-5,srparasites:parasiterubbledense:1)
Block(-8,61,-4,srparasites:parasiterubbledense:1)
Block(-8,61,-3,srparasites:parasiterubbledense:1)
Block(-8,61,-2,srparasites:parasiterubbledense:1)
Block(-8,62,-7,AIR:0)
Block(-8,62,-6,srparasites:parasiterubbledense:1)
Block(-8,62,-5,srparasites:parasiterubbledense:1)
Block(-8,62,-4,srparasites:parasiterubbledense:1)
Block(-8,62,-3,srparasites:parasiterubbledense:1)
Block(-8,62,-2,srparasites:parasiterubbledense:1)
Block(-8,62,-1,srparasites:parasiterubbledense:1)
Block(-8,62,0,srparasites:parasiterubbledense:1)
Block(-8,63,-7,AIR:0)
Block(-8,63,-6,srparasites:parasiterubbledense:1)
Block(-8,63,-5,srparasites:parasiterubbledense:1)
Block(-8,63,-4,srparasites:parasiterubbledense:1)
Block(-8,63,-3,srparasites:parasiterubbledense:1)
Block(-8,63,-2,srparasites:parasiterubbledense:1)
Block(-8,63,-1,srparasites:parasiterubbledense:1)
Block(-8,63,0,srparasites:parasiterubbledense:1)
Block(-8,63,1,srparasites:parasiterubbledense:1)
Block(-8,64,-7,AIR:0)
Block(-8,64,-6,srparasites:parasiterubbledense:1)
Block(-8,64,-5,srparasites:parasiterubbledense:1)
Block(-8,64,-4,srparasites:parasiterubbledense:1)
Block(-8,64,-3,srparasites:parasiterubbledense:1)
Block(-8,64,-2,srparasites:parasiterubbledense:1)
Block(-8,64,-1,srparasites:parasiterubbledense:1)
Block(-8,64,0,srparasites:parasiterubbledense:1)
Block(-8,64,1,srparasites:parasiterubbledense:1)
Block(-8,65,-7,srparasites:parasiterubbledense:1)
Block(-8,65,-6,srparasites:parasiterubbledense:1)
Block(-8,65,-5,srparasites:parasiterubbledense:1)
Block(-8,65,-4,srparasites:parasiterubbledense:1)
Block(-8,65,-3,SMOOTH_BRICK:1)
Block(-8,65,-2,srparasites:parasiterubbledense:1)
Block(-8,65,-1,srparasites:parasiterubbledense:1)
Block(-8,65,0,srparasites:parasiterubbledense:1)
Block(-8,65,1,srparasites:parasiterubbledense:1)
Block(-8,66,-7,srparasites:parasiterubbledense:1)
Block(-8,66,-6,srparasites:parasiterubbledense:1)
Block(-8,66,-5,srparasites:parasiterubbledense:1)
Block(-8,66,-4,AIR:0)
Block(-8,66,-3,SMOOTH_BRICK:3)
Block(-8,66,-2,SMOOTH_BRICK:3)
Block(-8,66,-1,srparasites:parasiterubbledense:1)
Block(-8,66,0,srparasites:parasiterubbledense:1)
Block(-8,66,1,srparasites:parasiterubbledense:1)
Block(-8,67,-7,DIRT:0)
Block(-8,67,-6,DIRT:0)
Block(-8,67,-5,srparasites:parasiterubbledense:1)
Block(-8,67,-4,AIR:0)
Block(-8,67,-3,AIR:0)
Block(-8,67,-2,AIR:0)
Block(-8,67,-1,srparasites:parasiterubbledense:1)
Block(-8,67,0,srparasites:parasiterubbledense:1)
Block(-8,67,1,DIRT:0)
Block(-8,67,2,DIRT:0)
Block(-8,67,3,DIRT:0)
Block(-8,67,4,DIRT:0)
Block(-8,67,5,DIRT:0)
Block(-8,67,6,DIRT:0)
Block(-8,67,7,DIRT:0)
Block(-8,67,8,DIRT:0)
Block(-8,68,-7,DIRT:0)
Block(-8,68,-6,srparasites:parasiterubbledense:1)
Block(-8,68,-5,srparasites:parasiterubbledense:1)
Block(-8,68,-4,srparasites:parasiterubbledense:1)
Block(-8,68,-3,srparasites:parasiterubbledense:1)
Block(-8,68,-2,srparasites:parasiterubbledense:1)
Block(-8,68,-1,srparasites:parasiterubbledense:1)
Block(-8,68,0,DIRT:0)
Block(-8,68,1,DIRT:0)
Block(-8,68,2,DIRT:0)
Block(-8,68,3,DIRT:0)
Block(-8,68,4,DIRT:0)
Block(-8,68,5,DIRT:0)
Block(-8,68,6,DIRT:0)
Block(-8,68,7,DIRT:0)
Block(-8,68,8,DIRT:0)
Block(-8,69,-7,DIRT:0)
Block(-8,69,-6,srparasites:parasiterubbledense:1)
Block(-8,69,-5,DIRT:0)
Block(-8,69,-4,srparasites:parasiterubbledense:1)
Block(-8,69,-3,srparasites:parasiterubbledense:1)
Block(-8,69,-2,srparasites:parasiterubbledense:1)
Block(-8,69,-1,srparasites:parasiterubbledense:1)
Block(-8,69,0,DIRT:0)
Block(-8,69,1,DIRT:0)
Block(-8,69,2,DIRT:0)
Block(-8,69,3,DIRT:0)
Block(-8,69,4,DIRT:0)
Block(-8,69,5,DIRT:0)
Block(-8,69,6,DIRT:0)
Block(-8,69,7,DIRT:0)
Block(-8,69,8,DIRT:0)
Block(-8,70,-7,DIRT:0)
Block(-8,70,-6,srparasites:parasiterubbledense:1)
Block(-8,70,-5,DIRT:0)
Block(-8,70,-4,srparasites:parasiterubbledense:1)
Block(-8,70,-3,srparasites:parasiterubbledense:1)
Block(-8,70,-2,srparasites:parasiterubbledense:1)
Block(-8,70,-1,srparasites:parasiterubbledense:1)
Block(-8,70,0,DIRT:0)
Block(-8,70,1,DIRT:0)
Block(-8,70,2,DIRT:0)
Block(-8,70,3,DIRT:0)
Block(-8,70,4,DIRT:0)
Block(-8,70,5,DIRT:0)
Block(-8,70,6,DIRT:0)
Block(-8,70,7,DIRT:0)
Block(-8,70,8,DIRT:0)
Block(-8,71,-7,DIRT:0)
Block(-8,71,-6,srparasites:parasiterubbledense:1)
Block(-8,71,-5,DIRT:0)
Block(-8,71,-4,DIRT:0)
Block(-8,71,-3,srparasites:parasiterubbledense:1)
Block(-8,71,-2,srparasites:parasiterubbledense:1)
Block(-8,71,-1,srparasites:parasiterubbledense:1)
Block(-8,71,0,DIRT:0)
Block(-8,71,1,DIRT:0)
Block(-8,71,2,DIRT:0)
Block(-8,71,3,DIRT:0)
Block(-8,71,4,DIRT:0)
Block(-8,71,5,DIRT:0)
Block(-8,71,6,DIRT:0)
Block(-8,71,7,DIRT:0)
Block(-8,71,8,DIRT:0)
Block(-8,72,-7,DIRT:0)
Block(-8,72,-6,srparasites:parasiterubbledense:1)
Block(-8,72,-5,DIRT:0)
Block(-8,72,-4,DIRT:0)
Block(-8,72,-3,DIRT:0)
Block(-8,72,-2,DIRT:0)
Block(-8,72,-1,DIRT:0)
Block(-8,72,0,DIRT:0)
Block(-8,72,1,DIRT:0)
Block(-8,72,2,DIRT:0)
Block(-8,72,3,DIRT:0)
Block(-8,72,4,DIRT:0)
Block(-8,72,5,DIRT:0)
Block(-8,72,6,DIRT:0)
Block(-8,72,7,DIRT:0)
Block(-8,72,8,DIRT:0)
Block(-8,73,-7,DIRT:0)
Block(-8,73,-6,srparasites:parasiterubbledense:1)
Block(-8,73,-5,DIRT:0)
Block(-8,73,-4,DIRT:0)
Block(-8,73,-3,DIRT:0)
Block(-8,73,-2,DIRT:0)
Block(-8,73,-1,DIRT:0)
Block(-8,73,0,DIRT:0)
Block(-8,73,1,DIRT:0)
Block(-8,73,2,DIRT:0)
Block(-8,73,3,DIRT:0)
Block(-8,73,4,DIRT:0)
Block(-8,73,5,DIRT:0)
Block(-8,73,6,DIRT:0)
Block(-8,73,7,DIRT:0)
Block(-8,73,8,DIRT:0)
Block(-8,74,-7,srparasites:parasiterubble_slabhalf:0)
Block(-8,74,-6,srparasites:parasiterubbledense:1)
Block(-8,74,-5,DIRT:0)
Block(-8,74,-4,DIRT:0)
Block(-8,74,-3,DIRT:0)
Block(-8,74,-2,DIRT:0)
Block(-8,74,-1,DIRT:0)
Block(-8,74,0,DIRT:0)
Block(-8,74,1,DIRT:0)
Block(-8,74,2,DIRT:0)
Block(-8,74,3,DIRT:0)
Block(-8,74,4,DIRT:0)
Block(-8,74,5,DIRT:0)
Block(-8,74,6,DIRT:0)
Block(-8,74,7,DIRT:0)
Block(-8,74,8,DIRT:0)
Block(-8,75,-7,SMOOTH_BRICK:1)
Block(-8,75,-6,srparasites:parasiterubbledense:1)
Block(-8,75,-5,srparasites:parasiterubble_slabhalf:0)
Block(-8,75,-4,srparasites:parasiterubble_slabhalf:0)
Block(-8,75,-3,srparasites:parasiterubble_slabhalf:0)
Block(-8,75,-2,srparasites:parasiterubble_slabhalf:0)
Block(-8,75,-1,srparasites:parasiterubble_slabhalf:0)
Block(-8,75,0,srparasites:parasiterubble_slabhalf:0)
Block(-8,75,1,srparasites:parasiterubble_slabhalf:0)
Block(-8,75,2,srparasites:parasiterubble_slabhalf:0)
Block(-8,75,3,srparasites:parasiterubble_slabhalf:0)
Block(-8,75,4,srparasites:parasiterubble_slabhalf:0)
Block(-8,75,5,srparasites:parasiterubble_slabhalf:0)
Block(-8,75,6,srparasites:parasiterubbledense:1)
Block(-8,75,7,srparasites:parasiterubbledense:1)
Block(-8,75,8,srparasites:parasiterubbledense:1)
Block(-8,76,-7,SMOOTH_BRICK:2)
Block(-8,76,-6,srparasites:parasiterubbledense:1)
Block(-8,76,-5,SMOOTH_BRICK:0)
Block(-8,76,-4,SMOOTH_BRICK:0)
Block(-8,76,-3,SMOOTH_BRICK:0)
Block(-8,76,-2,SMOOTH_BRICK:0)
Block(-8,76,-1,SMOOTH_BRICK:0)
Block(-8,76,0,SMOOTH_BRICK:0)
Block(-8,76,1,SMOOTH_BRICK:0)
Block(-8,76,2,SMOOTH_BRICK:0)
Block(-8,76,3,SMOOTH_BRICK:0)
Block(-8,76,4,SMOOTH_BRICK:0)
Block(-8,76,5,SMOOTH_BRICK:0)
Block(-8,76,6,srparasites:parasiterubbledense:1)
Block(-8,76,7,srparasites:parasiterubbledense:1)
Block(-8,76,8,srparasites:parasiterubbledense:1)
Block(-8,77,-7,AIR:0)
Block(-8,77,-6,srparasites:parasiterubble_slabhalf:0)
Block(-8,77,-5,AIR:0)
Block(-8,77,-4,AIR:0)
Block(-8,77,-3,AIR:0)
Block(-8,77,-2,AIR:0)
Block(-8,77,-1,AIR:0)
Block(-8,77,0,AIR:0)
Block(-8,77,1,AIR:0)
Block(-8,77,2,AIR:0)
Block(-8,77,3,AIR:0)
Block(-8,77,4,AIR:0)
Block(-8,77,5,AIR:0)
Block(-8,77,6,srparasites:parasiterubble_slabhalf:0)
Block(-8,77,7,srparasites:parasiterubble_slabhalf:0)
Block(-8,77,8,srparasites:parasiterubble_slabhalf:0)
Block(-8,78,-7,AIR:0)
Block(-8,78,-6,AIR:0)
Block(-8,78,-5,AIR:0)
Block(-8,78,-4,AIR:0)
Block(-8,78,-3,AIR:0)
Block(-8,78,-2,AIR:0)
Block(-8,78,-1,AIR:0)
Block(-8,78,0,AIR:0)
Block(-8,78,1,AIR:0)
Block(-8,78,2,AIR:0)
Block(-8,78,3,AIR:0)
Block(-8,78,4,AIR:0)
Block(-8,78,5,AIR:0)
Block(-8,78,6,AIR:0)
Block(-8,78,7,AIR:0)
Block(-8,78,8,AIR:0)
Block(-8,79,-7,AIR:0)
Block(-8,79,-6,AIR:0)
Block(-8,79,-5,AIR:0)
Block(-8,79,-4,AIR:0)
Block(-8,79,-3,AIR:0)
Block(-8,79,-2,AIR:0)
Block(-8,79,-1,AIR:0)
Block(-8,79,0,AIR:0)
Block(-8,79,1,AIR:0)
Block(-8,79,2,AIR:0)
Block(-8,79,3,AIR:0)
Block(-8,79,4,AIR:0)
Block(-8,79,5,AIR:0)
Block(-8,79,6,AIR:0)
Block(-8,79,7,AIR:0)
Block(-8,79,8,AIR:0)
Block(-8,80,-7,AIR:0)
Block(-8,80,-6,AIR:0)
Block(-8,80,-5,AIR:0)
Block(-8,80,-4,AIR:0)
Block(-8,80,-3,AIR:0)
Block(-8,80,-2,AIR:0)
Block(-8,80,-1,AIR:0)
Block(-8,80,0,AIR:0)
Block(-8,80,1,AIR:0)
Block(-8,80,2,AIR:0)
Block(-8,80,3,AIR:0)
Block(-8,80,4,AIR:0)
Block(-8,80,5,AIR:0)
Block(-8,80,6,AIR:0)
Block(-8,80,7,AIR:0)
Block(-8,80,8,AIR:0)
Block(-8,81,-7,AIR:0)
Block(-8,81,-6,AIR:0)
Block(-8,81,-5,AIR:0)
Block(-8,81,-4,AIR:0)
Block(-8,81,-3,AIR:0)
Block(-8,81,-2,AIR:0)
Block(-8,81,-1,AIR:0)
Block(-8,81,0,AIR:0)
Block(-8,81,1,AIR:0)
Block(-8,81,2,AIR:0)
Block(-8,81,3,AIR:0)
Block(-8,81,4,AIR:0)
Block(-8,81,5,AIR:0)
Block(-8,81,6,AIR:0)
Block(-8,81,7,AIR:0)
Block(-8,81,8,AIR:0)
Block(-8,82,-7,AIR:0)
Block(-8,82,-6,AIR:0)
Block(-8,82,-5,AIR:0)
Block(-8,82,-4,AIR:0)
Block(-8,82,-3,AIR:0)
Block(-8,82,-2,AIR:0)
Block(-8,82,-1,AIR:0)
Block(-8,82,0,AIR:0)
Block(-8,82,1,AIR:0)
Block(-8,82,2,AIR:0)
Block(-8,82,3,AIR:0)
Block(-8,82,4,AIR:0)
Block(-8,82,5,AIR:0)
Block(-8,82,6,AIR:0)
Block(-8,82,7,AIR:0)
Block(-8,82,8,AIR:0)
Block(-8,83,-7,AIR:0)
Block(-8,83,-6,AIR:0)
Block(-8,83,-5,AIR:0)
Block(-8,83,-4,AIR:0)
Block(-8,83,-3,AIR:0)
Block(-8,83,-2,AIR:0)
Block(-8,83,-1,AIR:0)
Block(-8,83,0,AIR:0)
Block(-8,83,1,AIR:0)
Block(-8,83,2,AIR:0)
Block(-8,83,3,AIR:0)
Block(-8,83,4,AIR:0)
Block(-8,83,5,AIR:0)
Block(-8,83,6,AIR:0)
Block(-8,83,7,AIR:0)
Block(-8,83,8,AIR:0)
Block(-7,1,-7,srparasites:parasiterubbledense:1)
Block(-7,1,-6,srparasites:parasiterubbledense:1)
Block(-7,1,-5,srparasites:parasiterubbledense:1)
Block(-7,1,-4,srparasites:parasiterubbledense:1)
Block(-7,1,-3,srparasites:parasiterubbledense:1)
Block(-7,1,-2,srparasites:parasiterubbledense:1)
Block(-7,2,-7,srparasites:parasiterubbledense:1)
Block(-7,2,-6,srparasites:parasiterubbledense:1)
Block(-7,2,-5,srparasites:parasiterubbledense:1)
Block(-7,2,-4,srparasites:parasiterubbledense:1)
Block(-7,2,-3,srparasites:parasiterubbledense:1)
Block(-7,2,-2,srparasites:parasiterubbledense:1)
Block(-7,3,-7,srparasites:parasiterubbledense:1)
Block(-7,3,-6,srparasites:parasiterubbledense:1)
Block(-7,3,-5,srparasites:parasiterubbledense:1)
Block(-7,3,-4,srparasites:parasiterubbledense:1)
Block(-7,3,-3,srparasites:parasiterubbledense:1)
Block(-7,3,-2,srparasites:parasiterubbledense:1)
Block(-7,4,-7,srparasites:parasiterubbledense:1)
Block(-7,4,-6,srparasites:parasiterubbledense:1)
Block(-7,4,-5,srparasites:parasiterubbledense:1)
Block(-7,4,-4,srparasites:parasiterubbledense:1)
Block(-7,5,-7,srparasites:parasiterubbledense:1)
Block(-7,5,-6,srparasites:parasiterubbledense:1)
Block(-7,5,-5,srparasites:parasiterubbledense:1)
Block(-7,5,-4,srparasites:parasiterubbledense:1)
Block(-7,5,-3,srparasites:parasiterubbledense:1)
Block(-7,6,-7,srparasites:parasiterubbledense:1)
Block(-7,6,-6,srparasites:parasiterubbledense:1)
Block(-7,6,-5,srparasites:parasiterubbledense:1)
Block(-7,6,-4,srparasites:parasiterubbledense:1)
Block(-7,7,-7,srparasites:parasiterubbledense:1)
Block(-7,7,-6,srparasites:parasiterubbledense:1)
Block(-7,7,-5,srparasites:parasiterubbledense)
Block(-7,8,-7,srparasites:parasiterubbledense:1)
Block(-7,8,-6,srparasites:parasiterubbledense:1)
Block(-7,8,-5,srparasites:parasiterubbledense:1)
Block(-7,9,-7,srparasites:parasiterubbledense:1)
Block(-7,9,-6,srparasites:parasiterubbledense:1)
Block(-7,9,-5,srparasites:parasiterubbledense:1)
Block(-7,10,-7,srparasites:parasiterubbledense:1)
Block(-7,10,-6,srparasites:parasiterubbledense:1)
Block(-7,10,-5,srparasites:parasiterubbledense:1)
Block(-7,10,-4,srparasites:parasiterubbledense:1)
Block(-7,11,-7,srparasites:parasiterubbledense:1)
Block(-7,11,-6,srparasites:parasiterubbledense:1)
Block(-7,11,-5,srparasites:parasiterubbledense:1)
Block(-7,11,-4,srparasites:parasiterubbledense:1)
Block(-7,11,-3,srparasites:parasiterubbledense:1)
Block(-7,12,-7,srparasites:parasiterubbledense:1)
Block(-7,12,-6,srparasites:parasiterubbledense:1)
Block(-7,12,-5,srparasites:parasiterubbledense:1)
Block(-7,12,-4,srparasites:parasiterubbledense:1)
Block(-7,13,-7,srparasites:parasiterubbledense:1)
Block(-7,13,-6,srparasites:parasiterubbledense:1)
Block(-7,13,-5,srparasites:parasiterubbledense:1)
Block(-7,14,-7,srparasites:parasiterubbledense:1)
Block(-7,14,-6,srparasites:parasiterubbledense:1)
Block(-7,14,-5,srparasites:parasiterubbledense:1)
Block(-7,15,-7,srparasites:parasiterubbledense:1)
Block(-7,15,-6,srparasites:parasiterubbledense:1)
Block(-7,15,-5,srparasites:parasiterubbledense:1)
Block(-7,16,-7,srparasites:parasiterubbledense:1)
Block(-7,16,-6,srparasites:parasiterubbledense:1)
Block(-7,16,-5,srparasites:parasiterubbledense)
Block(-7,17,-7,srparasites:parasiterubbledense:1)
Block(-7,17,-6,srparasites:parasitebush)
Block(-7,17,-5,srparasites:parasiterubbledense:1)
Block(-7,18,-7,srparasites:parasiterubbledense:1)
Block(-7,18,-6,srparasites:parasiterubbledense:1)
Block(-7,18,-5,srparasites:parasiterubbledense:1)
Block(-7,19,-7,srparasites:parasiterubbledense:1)
Block(-7,19,-6,srparasites:parasiterubbledense:1)
Block(-7,19,-5,AIR:0)
Block(-7,20,-7,srparasites:parasiterubbledense:1)
Block(-7,20,-6,srparasites:parasiterubbledense)
Block(-7,20,-5,srparasites:parasiterubbledense:1)
Block(-7,21,-7,srparasites:parasiterubbledense:1)
Block(-7,21,-6,srparasites:parasiterubbledense:1)
Block(-7,21,-5,srparasites:parasiterubbledense:1)
Block(-7,21,-4,srparasites:parasiterubbledense:1)
Block(-7,21,-3,srparasites:parasiterubbledense:1)
Block(-7,22,-7,srparasites:parasiterubbledense:1)
Block(-7,22,-6,srparasites:parasiterubbledense:1)
Block(-7,22,-5,srparasites:parasiterubbledense:1)
Block(-7,22,-4,srparasites:parasiterubbledense:1)
Block(-7,22,-3,srparasites:parasiterubbledense:1)
Block(-7,23,-7,srparasites:parasiterubbledense:1)
Block(-7,23,-6,srparasites:parasiterubbledense:1)
Block(-7,23,-5,srparasites:parasiterubbledense:1)
Block(-7,23,-4,srparasites:parasiterubbledense:1)
Block(-7,23,-3,srparasites:parasiterubbledense:1)
Block(-7,24,-7,srparasites:parasiterubbledense:1)
Block(-7,24,-6,srparasites:parasiterubbledense:1)
Block(-7,24,-5,srparasites:parasiterubbledense:1)
Block(-7,25,-7,srparasites:parasiterubbledense:1)
Block(-7,25,-6,srparasites:parasiterubbledense:1)
Block(-7,25,-5,srparasites:parasiterubbledense:1)
Block(-7,26,-7,srparasites:parasiterubbledense:1)
Block(-7,26,-6,srparasites:parasiterubbledense:1)
Block(-7,26,-5,srparasites:parasiterubbledense:1)
Block(-7,27,-7,srparasites:parasiterubbledense:1)
Block(-7,27,-6,srparasites:parasitebush)
Block(-7,27,-5,srparasites:parasiterubbledense:1)
Block(-7,28,-7,srparasites:parasiterubbledense:1)
Block(-7,28,-6,srparasites:parasiterubbledense:1)
Block(-7,28,-5,AIR:0)
Block(-7,29,-7,srparasites:parasiterubbledense:1)
Block(-7,29,-6,srparasites:parasiterubbledense:1)
Block(-7,29,-5,srparasites:parasiterubbledense:1)
Block(-7,30,-7,srparasites:parasiterubbledense:1)
Block(-7,30,-6,srparasites:parasitebush)
Block(-7,30,-5,srparasites:parasiterubbledense)
Block(-7,31,-7,srparasites:parasiterubbledense:1)
Block(-7,31,-6,srparasites:parasiterubbledense:1)
Block(-7,31,-5,srparasites:parasiterubbledense:1)
Block(-7,32,-7,srparasites:parasiterubbledense:1)
Block(-7,32,-6,srparasites:parasiterubbledense:1)
Block(-7,32,-5,srparasites:parasiterubbledense:1)
Block(-7,33,-7,srparasites:parasiterubbledense:1)
Block(-7,33,-6,srparasites:parasiterubbledense:1)
Block(-7,33,-5,srparasites:parasiterubbledense:1)
Block(-7,34,-7,srparasites:parasiterubbledense:1)
Block(-7,34,-6,srparasites:parasiterubbledense:1)
Block(-7,34,-5,srparasites:parasiterubbledense:1)
Block(-7,35,-7,srparasites:parasiterubbledense:1)
Block(-7,35,-6,srparasites:parasiterubbledense:1)
Block(-7,35,-5,srparasites:parasiterubbledense:1)
Block(-7,35,-4,srparasites:parasiterubbledense:1)
Block(-7,36,-7,srparasites:parasiterubbledense:1)
Block(-7,36,-6,srparasites:parasiterubbledense:1)
Block(-7,36,-5,srparasites:parasiterubbledense:1)
Block(-7,36,-4,srparasites:parasiterubbledense:1)
Block(-7,36,-3,srparasites:parasiterubbledense:1)
Block(-7,37,-7,srparasites:parasiterubbledense:1)
Block(-7,37,-6,srparasites:parasiterubbledense:1)
Block(-7,37,-5,srparasites:parasiterubbledense:1)
Block(-7,37,-4,srparasites:parasiterubbledense:1)
Block(-7,38,-7,srparasites:parasiterubbledense:1)
Block(-7,38,-6,srparasites:parasiterubbledense:1)
Block(-7,38,-5,srparasites:parasiterubbledense:1)
Block(-7,39,-7,srparasites:parasiterubbledense:1)
Block(-7,39,-6,srparasites:parasiterubbledense:1)
Block(-7,39,-5,srparasites:parasiterubbledense:1)
Block(-7,40,-7,srparasites:parasiterubbledense:1)
Block(-7,40,-6,srparasites:parasiterubbledense:1)
Block(-7,40,-5,srparasites:parasiterubbledense:1)
Block(-7,41,-7,srparasites:parasiterubbledense:1)
Block(-7,41,-6,srparasites:parasiterubbledense)
Block(-7,41,-5,srparasites:parasiterubbledense)
Block(-7,42,-7,srparasites:parasiterubbledense:1)
Block(-7,42,-6,srparasites:parasiterubbledense:1)
Block(-7,42,-5,srparasites:parasiterubbledense)
Block(-7,43,-7,srparasites:parasiterubbledense:1)
Block(-7,43,-6,srparasites:parasiterubbledense:1)
Block(-7,43,-5,srparasites:parasiterubbledense:1)
Block(-7,44,-7,srparasites:parasiterubbledense:1)
Block(-7,44,-6,srparasites:parasiterubbledense:1)
Block(-7,44,-5,srparasites:parasiterubbledense:1)
Block(-7,45,-7,srparasites:parasiterubbledense:1)
Block(-7,45,-6,srparasites:parasiterubbledense:1)
Block(-7,45,-5,srparasites:parasiterubbledense:1)
Block(-7,45,-4,srparasites:parasiterubbledense:1)
Block(-7,46,-7,srparasites:parasiterubbledense:1)
Block(-7,46,-6,srparasites:parasiterubbledense:1)
Block(-7,46,-5,srparasites:parasiterubbledense:1)
Block(-7,46,-4,srparasites:parasiterubbledense:1)
Block(-7,46,-3,srparasites:parasiterubbledense:1)
Block(-7,47,-7,srparasites:parasiterubbledense:1)
Block(-7,47,-6,srparasites:parasiterubbledense:1)
Block(-7,47,-5,srparasites:parasiterubbledense:1)
Block(-7,47,-4,srparasites:parasiterubbledense:1)
Block(-7,47,-3,srparasites:parasiterubbledense:1)
Block(-7,48,-7,srparasites:parasiterubbledense:1)
Block(-7,48,-6,srparasites:parasiterubbledense:1)
Block(-7,48,-5,srparasites:parasiterubbledense:1)
Block(-7,48,-4,srparasites:parasiterubbledense:1)
Block(-7,48,-3,srparasites:parasiterubbledense:1)
Block(-7,49,-7,srparasites:parasiterubbledense:1)
Block(-7,49,-6,srparasites:parasiterubbledense:1)
Block(-7,49,-5,srparasites:parasiterubbledense)
Block(-7,50,-7,srparasites:parasiterubbledense:1)
Block(-7,50,-6,srparasites:parasiterubbledense:1)
Block(-7,50,-5,srparasites:parasiterubbledense)
Block(-7,51,-7,srparasites:parasiterubbledense:1)
Block(-7,51,-6,srparasites:parasiterubbledense:1)
Block(-7,51,-5,srparasites:parasiterubbledense:1)
Block(-7,52,-7,srparasites:parasiterubbledense:1)
Block(-7,52,-6,srparasites:parasiterubbledense:1)
Block(-7,52,-5,srparasites:parasiterubbledense:1)
Block(-7,53,-7,AIR:0)
Block(-7,53,-6,BONE_BLOCK:0)
Block(-7,53,-5,srparasites:parasiterubbledense:1)
Block(-7,54,-7,AIR:0)
Block(-7,54,-6,AIR:0)
Block(-7,54,-5,srparasites:parasiterubbledense:1)
Block(-7,54,-4,srparasites:parasiterubbledense:1)
Block(-7,54,-3,srparasites:parasiterubbledense:1)
Block(-7,55,-7,AIR:0)
Block(-7,55,-6,AIR:0)
Block(-7,55,-5,AIR:0)
Block(-7,55,-4,AIR:0)
Block(-7,55,-3,srparasites:parasiterubbledense:1)
Block(-7,56,-7,AIR:0)
Block(-7,56,-6,AIR:0)
Block(-7,56,-5,AIR:0)
Block(-7,56,-4,AIR:0)
Block(-7,56,-3,srparasites:parasiterubbledense:1)
Block(-7,56,-2,srparasites:parasiterubbledense:1)
Block(-7,57,-7,AIR:0)
Block(-7,57,-6,AIR:0)
Block(-7,57,-5,AIR:0)
Block(-7,57,-4,AIR:0)
Block(-7,57,-3,AIR:0)
Block(-7,57,-2,AIR:0)
Block(-7,57,-1,srparasites:parasiterubbledense:1)
Block(-7,58,-7,AIR:0)
Block(-7,58,-6,AIR:0)
Block(-7,58,-5,AIR:0)
Block(-7,58,-4,AIR:0)
Block(-7,58,-3,AIR:0)
Block(-7,58,-2,AIR:0)
Block(-7,58,-1,srparasites:parasiterubbledense:1)
Block(-7,59,-7,AIR:0)
Block(-7,59,-6,AIR:0)
Block(-7,59,-5,AIR:0)
Block(-7,59,-4,AIR:0)
Block(-7,59,-3,AIR:0)
Block(-7,59,-2,AIR:0)
Block(-7,59,-1,srparasites:parasiterubbledense:1)
Block(-7,60,-7,AIR:0)
Block(-7,60,-6,AIR:0)
Block(-7,60,-5,AIR:0)
Block(-7,60,-4,AIR:0)
Block(-7,60,-3,AIR:0)
Block(-7,60,-2,AIR:0)
Block(-7,60,-1,srparasites:parasiterubbledense:1)
Block(-7,61,-7,AIR:0)
Block(-7,61,-6,AIR:0)
Block(-7,61,-5,AIR:0)
Block(-7,61,-4,srparasites:parasiterubbledense:1)
Block(-7,61,-3,srparasites:parasiterubbledense:1)
Block(-7,61,-2,srparasites:parasiterubbledense:1)
Block(-7,62,-7,AIR:0)
Block(-7,62,-6,AIR:0)
Block(-7,62,-5,srparasites:parasiterubbledense:1)
Block(-7,62,-4,srparasites:parasiterubbledense:1)
Block(-7,62,-3,srparasites:parasiterubbledense:1)
Block(-7,62,-2,srparasites:parasiterubbledense:1)
Block(-7,62,-1,srparasites:parasiterubbledense:1)
Block(-7,62,0,srparasites:parasiterubbledense:1)
Block(-7,63,-7,AIR:0)
Block(-7,63,-6,AIR:0)
Block(-7,63,-5,srparasites:parasiterubbledense:1)
Block(-7,63,-4,srparasites:parasiterubbledense:1)
Block(-7,63,-3,srparasites:parasiterubbledense:1)
Block(-7,63,-2,srparasites:parasiterubbledense:1)
Block(-7,63,-1,srparasites:parasiterubbledense:1)
Block(-7,63,0,srparasites:parasiterubbledense:1)
Block(-7,63,1,srparasites:parasiterubbledense:1)
Block(-7,64,-7,AIR:0)
Block(-7,64,-6,AIR:0)
Block(-7,64,-5,srparasites:parasiterubbledense:1)
Block(-7,64,-4,srparasites:parasiterubbledense:1)
Block(-7,64,-3,srparasites:parasiterubbledense:1)
Block(-7,64,-2,srparasites:parasiterubbledense:1)
Block(-7,64,-1,srparasites:parasiterubbledense:1)
Block(-7,64,0,srparasites:parasiterubbledense:1)
Block(-7,64,1,srparasites:parasiterubbledense:1)
Block(-7,65,-7,srparasites:parasiterubbledense:1)
Block(-7,65,-6,srparasites:parasiterubbledense:1)
Block(-7,65,-5,srparasites:parasiterubbledense:1)
Block(-7,65,-4,srparasites:parasiterubbledense:1)
Block(-7,65,-3,SMOOTH_BRICK:1)
Block(-7,65,-2,SMOOTH_BRICK:1)
Block(-7,65,-1,AIR:0)
Block(-7,65,0,srparasites:parasiterubbledense:1)
Block(-7,65,1,srparasites:parasiterubbledense:1)
Block(-7,66,-7,srparasites:parasiterubbledense:1)
Block(-7,66,-5,srparasites:parasiterubbledense:1)
Block(-7,66,-4,AIR:0)
Block(-7,66,-3,AIR:0)
Block(-7,66,-2,SMOOTH_BRICK:0)
Block(-7,66,-1,AIR:0)
Block(-7,66,0,srparasites:parasiterubbledense:1)
Block(-7,66,1,srparasites:parasiterubbledense:1)
Block(-7,67,-7,DIRT:0)
Block(-7,67,-6,DIRT:0)
Block(-7,67,-5,srparasites:parasiterubbledense:1)
Block(-7,67,-4,srparasites:parasiterubbledense:1)
Block(-7,67,-3,AIR:0)
Block(-7,67,-2,AIR:0)
Block(-7,67,-1,srparasites:parasiterubbledense:1)
Block(-7,67,0,srparasites:parasiterubbledense:1)
Block(-7,67,1,DIRT:0)
Block(-7,67,2,DIRT:0)
Block(-7,67,3,DIRT:0)
Block(-7,67,4,DIRT:0)
Block(-7,67,5,DIRT:0)
Block(-7,67,6,DIRT:0)
Block(-7,67,7,DIRT:0)
Block(-7,67,8,DIRT:0)
Block(-7,68,-7,srparasites:parasiterubbledense:1)
Block(-7,68,-6,srparasites:parasiterubbledense:1)
Block(-7,68,-5,srparasites:parasiterubbledense:1)
Block(-7,68,-4,srparasites:parasiterubbledense:1)
Block(-7,68,-3,srparasites:parasiterubbledense:1)
Block(-7,68,-2,srparasites:parasiterubbledense:1)
Block(-7,68,-1,srparasites:parasiterubbledense:1)
Block(-7,68,0,DIRT:0)
Block(-7,68,1,DIRT:0)
Block(-7,68,2,DIRT:0)
Block(-7,68,3,DIRT:0)
Block(-7,68,4,DIRT:0)
Block(-7,68,5,DIRT:0)
Block(-7,68,6,DIRT:0)
Block(-7,68,7,DIRT:0)
Block(-7,68,8,DIRT:0)
Block(-7,69,-7,srparasites:parasiterubbledense:1)
Block(-7,69,-6,srparasites:parasiterubbledense:1)
Block(-7,69,-5,DIRT:0)
Block(-7,69,-4,srparasites:parasiterubbledense:1)
Block(-7,69,-3,srparasites:parasiterubbledense:1)
Block(-7,69,-2,srparasites:parasiterubbledense:1)
Block(-7,69,-1,DIRT:0)
Block(-7,69,0,DIRT:0)
Block(-7,69,1,DIRT:0)
Block(-7,69,2,DIRT:0)
Block(-7,69,3,DIRT:0)
Block(-7,69,4,DIRT:0)
Block(-7,69,5,DIRT:0)
Block(-7,69,6,DIRT:0)
Block(-7,69,7,DIRT:0)
Block(-7,69,8,DIRT:0)
Block(-7,70,-7,srparasites:parasiterubbledense:1)
Block(-7,70,-6,srparasites:parasiterubbledense:1)
Block(-7,70,-5,DIRT:0)
Block(-7,70,-4,srparasites:parasiterubbledense:1)
Block(-7,70,-3,srparasites:parasiterubbledense:1)
Block(-7,70,-2,DIRT:0)
Block(-7,70,-1,DIRT:0)
Block(-7,70,0,DIRT:0)
Block(-7,70,1,DIRT:0)
Block(-7,70,2,DIRT:0)
Block(-7,70,3,DIRT:0)
Block(-7,70,4,DIRT:0)
Block(-7,70,5,DIRT:0)
Block(-7,70,6,DIRT:0)
Block(-7,70,7,DIRT:0)
Block(-7,70,8,DIRT:0)
Block(-7,71,-7,srparasites:parasiterubbledense:1)
Block(-7,71,-6,srparasites:parasiterubbledense:1)
Block(-7,71,-5,DIRT:0)
Block(-7,71,-4,srparasites:parasiterubbledense:1)
Block(-7,71,-3,srparasites:parasiterubbledense:1)
Block(-7,71,-2,DIRT:0)
Block(-7,71,-1,DIRT:0)
Block(-7,71,0,DIRT:0)
Block(-7,71,1,DIRT:0)
Block(-7,71,2,DIRT:0)
Block(-7,71,3,DIRT:0)
Block(-7,71,4,DIRT:0)
Block(-7,71,5,DIRT:0)
Block(-7,71,6,DIRT:0)
Block(-7,71,7,DIRT:0)
Block(-7,71,8,DIRT:0)
Block(-7,72,-7,srparasites:parasiterubbledense:1)
Block(-7,72,-6,srparasites:parasiterubbledense:1)
Block(-7,72,-5,DIRT:0)
Block(-7,72,-4,srparasites:parasiterubbledense:1)
Block(-7,72,-3,srparasites:parasiterubbledense:1)
Block(-7,72,-2,DIRT:0)
Block(-7,72,-1,DIRT:0)
Block(-7,72,0,DIRT:0)
Block(-7,72,1,DIRT:0)
Block(-7,72,2,DIRT:0)
Block(-7,72,3,DIRT:0)
Block(-7,72,4,DIRT:0)
Block(-7,72,5,DIRT:0)
Block(-7,72,6,DIRT:0)
Block(-7,72,7,DIRT:0)
Block(-7,72,8,DIRT:0)
Block(-7,73,-7,srparasites:parasiterubbledense:1)
Block(-7,73,-6,srparasites:parasiterubbledense:1)
Block(-7,73,-5,DIRT:0)
Block(-7,73,-4,srparasites:parasiterubbledense:1)
Block(-7,73,-3,srparasites:parasiterubbledense:1)
Block(-7,73,-2,DIRT:0)
Block(-7,73,-1,DIRT:0)
Block(-7,73,0,DIRT:0)
Block(-7,73,1,DIRT:0)
Block(-7,73,2,DIRT:0)
Block(-7,73,3,DIRT:0)
Block(-7,73,4,DIRT:0)
Block(-7,73,5,DIRT:0)
Block(-7,73,6,DIRT:0)
Block(-7,73,7,DIRT:0)
Block(-7,73,8,DIRT:0)
Block(-7,74,-7,srparasites:parasiterubbledense:1)
Block(-7,74,-6,srparasites:parasiterubbledense:1)
Block(-7,74,-5,DIRT:0)
Block(-7,74,-4,srparasites:parasiterubbledense:1)
Block(-7,74,-3,srparasites:parasiterubbledense:1)
Block(-7,74,-2,DIRT:0)
Block(-7,74,-1,DIRT:0)
Block(-7,74,0,DIRT:0)
Block(-7,74,1,DIRT:0)
Block(-7,74,2,DIRT:0)
Block(-7,74,3,DIRT:0)
Block(-7,74,4,DIRT:0)
Block(-7,74,5,DIRT:0)
Block(-7,74,6,DIRT:0)
Block(-7,74,7,DIRT:0)
Block(-7,74,8,DIRT:0)
Block(-7,75,-7,srparasites:parasiterubbledense:1)
Block(-7,75,-6,srparasites:parasiterubbledense:1)
Block(-7,75,-5,srparasites:parasiterubble_slabhalf:0)
Block(-7,75,-4,srparasites:parasiterubbledense:1)
Block(-7,75,-3,srparasites:parasiterubbledense:1)
Block(-7,75,-2,srparasites:parasiterubble_slabhalf:0)
Block(-7,75,-1,srparasites:parasiterubble_slabhalf:0)
Block(-7,75,0,srparasites:parasiterubble_slabhalf:0)
Block(-7,75,1,srparasites:parasiterubble_slabhalf:0)
Block(-7,75,2,srparasites:parasiterubble_slabhalf:0)
Block(-7,75,3,srparasites:parasiterubble_slabhalf:0)
Block(-7,75,4,srparasites:parasiterubble_slabhalf:0)
Block(-7,75,5,srparasites:parasiterubbledense:1)
Block(-7,75,6,srparasites:parasiterubbledense:1)
Block(-7,75,7,srparasites:parasiterubbledense:1)
Block(-7,75,8,srparasites:parasiterubbledense:1)
Block(-7,76,-7,srparasites:parasitebush:4)
Block(-7,76,-6,srparasites:parasiterubbledense:1)
Block(-7,76,-5,SMOOTH_BRICK:0)
Block(-7,76,-4,srparasites:parasiterubbledense:1)
Block(-7,76,-3,srparasites:parasiterubbledense:1)
Block(-7,76,-2,SMOOTH_BRICK:0)
Block(-7,76,-1,SMOOTH_BRICK:0)
Block(-7,76,0,SMOOTH_BRICK:0)
Block(-7,76,1,SMOOTH_BRICK:0)
Block(-7,76,2,SMOOTH_BRICK:0)
Block(-7,76,3,SMOOTH_BRICK:0)
Block(-7,76,4,SMOOTH_BRICK:0)
Block(-7,76,5,srparasites:parasiterubbledense:1)
Block(-7,76,6,srparasites:parasiterubbledense:1)
Block(-7,76,7,srparasites:parasiterubbledense:1)
Block(-7,76,8,srparasites:parasiterubbledense:1)
Block(-7,77,-7,AIR:0)
Block(-7,77,-6,BONE_BLOCK:0)
Block(-7,77,-5,AIR:0)
Block(-7,77,-4,srparasites:parasitebush:4)
Block(-7,77,-3,srparasites:parasitebush:4)
Block(-7,77,-2,AIR:0)
Block(-7,77,-1,AIR:0)
Block(-7,77,0,AIR:0)
Block(-7,77,1,AIR:0)
Block(-7,77,2,AIR:0)
Block(-7,77,3,AIR:0)
Block(-7,77,4,AIR:0)
Block(-7,77,5,AIR:0)
Block(-7,77,6,AIR:0)
Block(-7,77,7,srparasites:parasitebush)
Block(-7,77,8,AIR:0)
Block(-7,78,-7,AIR:0)
Block(-7,78,-6,srparasites:parasiterubble_slabhalf:0)
Block(-7,78,-5,AIR:0)
Block(-7,78,-4,AIR:0)
Block(-7,78,-3,AIR:0)
Block(-7,78,-2,AIR:0)
Block(-7,78,-1,AIR:0)
Block(-7,78,0,AIR:0)
Block(-7,78,1,AIR:0)
Block(-7,78,2,AIR:0)
Block(-7,78,3,AIR:0)
Block(-7,78,4,AIR:0)
Block(-7,78,5,AIR:0)
Block(-7,78,6,AIR:0)
Block(-7,78,7,srparasites:parasitebush)
Block(-7,78,8,AIR:0)
Block(-7,79,-7,AIR:0)
Block(-7,79,-6,AIR:0)
Block(-7,79,-5,AIR:0)
Block(-7,79,-4,AIR:0)
Block(-7,79,-3,AIR:0)
Block(-7,79,-2,AIR:0)
Block(-7,79,-1,AIR:0)
Block(-7,79,0,AIR:0)
Block(-7,79,1,AIR:0)
Block(-7,79,2,AIR:0)
Block(-7,79,3,AIR:0)
Block(-7,79,4,AIR:0)
Block(-7,79,5,AIR:0)
Block(-7,79,6,AIR:0)
Block(-7,79,7,AIR:0)
Block(-7,79,8,AIR:0)
Block(-7,80,-7,AIR:0)
Block(-7,80,-6,AIR:0)
Block(-7,80,-5,AIR:0)
Block(-7,80,-4,AIR:0)
Block(-7,80,-3,AIR:0)
Block(-7,80,-2,AIR:0)
Block(-7,80,-1,AIR:0)
Block(-7,80,0,AIR:0)
Block(-7,80,1,AIR:0)
Block(-7,80,2,AIR:0)
Block(-7,80,3,AIR:0)
Block(-7,80,4,AIR:0)
Block(-7,80,5,AIR:0)
Block(-7,80,6,AIR:0)
Block(-7,80,7,AIR:0)
Block(-7,80,8,AIR:0)
Block(-7,81,-7,AIR:0)
Block(-7,81,-6,AIR:0)
Block(-7,81,-5,AIR:0)
Block(-7,81,-4,AIR:0)
Block(-7,81,-3,AIR:0)
Block(-7,81,-2,AIR:0)
Block(-7,81,-1,AIR:0)
Block(-7,81,0,AIR:0)
Block(-7,81,1,AIR:0)
Block(-7,81,2,AIR:0)
Block(-7,81,3,AIR:0)
Block(-7,81,4,AIR:0)
Block(-7,81,5,AIR:0)
Block(-7,81,6,AIR:0)
Block(-7,81,7,AIR:0)
Block(-7,81,8,AIR:0)
Block(-7,82,-7,AIR:0)
Block(-7,82,-6,AIR:0)
Block(-7,82,-5,AIR:0)
Block(-7,82,-4,AIR:0)
Block(-7,82,-3,AIR:0)
Block(-7,82,-2,AIR:0)
Block(-7,82,-1,AIR:0)
Block(-7,82,0,AIR:0)
Block(-7,82,1,AIR:0)
Block(-7,82,2,AIR:0)
Block(-7,82,3,AIR:0)
Block(-7,82,4,AIR:0)
Block(-7,82,5,AIR:0)
Block(-7,82,6,AIR:0)
Block(-7,82,7,AIR:0)
Block(-7,82,8,AIR:0)
Block(-7,83,-7,AIR:0)
Block(-7,83,-6,AIR:0)
Block(-7,83,-5,AIR:0)
Block(-7,83,-4,AIR:0)
Block(-7,83,-3,AIR:0)
Block(-7,83,-2,AIR:0)
Block(-7,83,-1,AIR:0)
Block(-7,83,0,AIR:0)
Block(-7,83,1,AIR:0)
Block(-7,83,2,AIR:0)
Block(-7,83,3,AIR:0)
Block(-7,83,4,AIR:0)
Block(-7,83,5,AIR:0)
Block(-7,83,6,AIR:0)
Block(-7,83,7,AIR:0)
Block(-7,83,8,AIR:0)
Block(-6,1,-7,srparasites:parasiterubbledense:1)
Block(-6,1,-6,srparasites:parasiterubbledense:1)
Block(-6,1,-5,srparasites:parasiterubbledense:1)
Block(-6,1,-4,srparasites:parasiterubbledense:1)
Block(-6,1,-3,srparasites:parasiterubbledense:1)
Block(-6,1,-2,srparasites:parasiterubbledense:1)
Block(-6,2,-7,srparasites:parasiterubbledense:1)
Block(-6,2,-6,srparasites:parasiterubbledense:1)
Block(-6,2,-5,srparasites:parasiterubbledense:1)
Block(-6,2,-4,srparasites:parasiterubbledense:1)
Block(-6,2,-3,srparasites:parasiterubbledense:1)
Block(-6,2,-2,srparasites:parasiterubbledense:1)
Block(-6,3,-7,srparasites:parasiterubbledense:1)
Block(-6,3,-6,srparasites:parasiterubbledense:1)
Block(-6,3,-5,srparasites:parasiterubbledense:1)
Block(-6,3,-4,srparasites:parasiterubbledense:1)
Block(-6,3,-3,srparasites:parasiterubbledense:1)
Block(-6,4,-7,srparasites:parasiterubbledense:1)
Block(-6,4,-6,srparasites:parasiterubbledense:1)
Block(-6,4,-5,srparasites:parasiterubbledense:1)
Block(-6,4,-4,srparasites:parasiterubbledense:1)
Block(-6,4,-3,srparasites:parasiterubbledense:1)
Block(-6,5,-7,srparasites:parasiterubbledense:1)
Block(-6,5,-6,srparasites:parasiterubbledense:1)
Block(-6,5,-5,srparasites:parasiterubbledense:1)
Block(-6,5,-4,srparasites:parasiterubbledense:1)
Block(-6,5,-3,srparasites:parasiterubbledense:1)
Block(-6,6,-7,srparasites:parasiterubbledense:1)
Block(-6,6,-6,srparasites:parasiterubbledense:1)
Block(-6,6,-5,srparasites:parasiterubbledense:1)
Block(-6,6,-4,srparasites:parasiterubbledense:1)
Block(-6,6,-3,srparasites:parasiterubbledense:1)
Block(-6,7,-7,srparasites:parasiterubbledense:1)
Block(-6,7,-6,srparasites:parasiterubbledense:1)
Block(-6,7,-5,srparasites:parasiterubbledense:1)
Block(-6,7,-4,srparasites:parasiterubbledense:1)
Block(-6,8,-7,srparasites:parasiterubbledense:1)
Block(-6,8,-6,srparasites:parasiterubbledense:1)
Block(-6,8,-5,srparasites:parasiterubbledense)
Block(-6,8,-4,srparasites:parasiterubbledense)
Block(-6,9,-7,srparasites:parasiterubbledense:1)
Block(-6,9,-6,srparasites:parasiterubbledense:1)
Block(-6,9,-5,srparasites:parasiterubbledense:1)
Block(-6,9,-4,srparasites:parasiterubbledense:1)
Block(-6,10,-7,srparasites:parasiterubbledense:1)
Block(-6,10,-6,srparasites:parasiterubbledense:1)
Block(-6,10,-5,srparasites:parasiterubbledense:1)
Block(-6,10,-4,srparasites:parasiterubbledense:1)
Block(-6,10,-3,srparasites:parasiterubbledense:1)
Block(-6,11,-7,srparasites:parasiterubbledense:1)
Block(-6,11,-6,srparasites:parasiterubbledense:1)
Block(-6,11,-5,srparasites:parasiterubbledense:1)
Block(-6,11,-4,srparasites:parasiterubbledense:1)
Block(-6,11,-3,srparasites:parasiterubbledense:1)
Block(-6,12,-7,srparasites:parasiterubbledense:1)
Block(-6,12,-6,srparasites:parasiterubbledense:1)
Block(-6,12,-5,srparasites:parasiterubbledense:1)
Block(-6,12,-4,srparasites:parasiterubbledense:1)
Block(-6,12,-3,srparasites:parasiterubbledense:1)
Block(-6,13,-7,srparasites:parasiterubbledense:1)
Block(-6,13,-6,srparasites:parasiterubbledense:1)
Block(-6,13,-5,srparasites:parasiterubbledense:1)
Block(-6,13,-4,srparasites:parasiterubbledense:1)
Block(-6,14,-7,srparasites:parasiterubbledense:1)
Block(-6,14,-6,srparasites:parasiterubbledense:1)
Block(-6,14,-5,srparasites:parasiterubbledense:1)
Block(-6,14,-4,srparasites:parasiterubbledense:1)
Block(-6,15,-7,srparasites:parasiterubbledense:1)
Block(-6,15,-6,srparasites:parasiterubbledense:1)
Block(-6,15,-5,srparasites:parasitebush)
Block(-6,15,-4,srparasites:parasiterubbledense:1)
Block(-6,16,-7,srparasites:parasiterubbledense:1)
Block(-6,16,-6,srparasites:parasiterubbledense:1)
Block(-6,16,-5,srparasites:parasiterubbledense)
Block(-6,16,-4,AIR:0)
Block(-6,17,-7,srparasites:parasiterubbledense:1)
Block(-6,17,-6,srparasites:parasiterubbledense:1)
Block(-6,17,-5,srparasites:parasiterubbledense:1)
Block(-6,17,-4,srparasites:parasiterubbledense:1)
Block(-6,18,-7,srparasites:parasiterubbledense:1)
Block(-6,18,-6,srparasites:parasiterubbledense:1)
Block(-6,18,-5,srparasites:parasiterubbledense:1)
Block(-6,18,-4,srparasites:parasiterubbledense:1)
Block(-6,19,-7,srparasites:parasiterubbledense:1)
Block(-6,19,-6,srparasites:parasiterubbledense:1)
Block(-6,19,-5,srparasites:parasitebush)
Block(-6,19,-4,srparasites:parasiterubbledense:1)
Block(-6,20,-7,srparasites:parasiterubbledense:1)
Block(-6,20,-6,srparasites:parasiterubbledense:1)
Block(-6,20,-5,srparasites:parasiterubbledense)
Block(-6,20,-4,srparasites:parasiterubbledense)
Block(-6,21,-7,srparasites:parasiterubbledense:1)
Block(-6,21,-6,srparasites:parasiterubbledense:1)
Block(-6,21,-5,srparasites:parasiterubbledense:1)
Block(-6,21,-4,srparasites:parasiterubbledense:1)
Block(-6,22,-7,srparasites:parasiterubbledense:1)
Block(-6,22,-6,srparasites:parasiterubbledense:1)
Block(-6,22,-5,srparasites:parasiterubbledense:1)
Block(-6,22,-4,srparasites:parasiterubbledense:1)
Block(-6,22,-3,srparasites:parasiterubbledense:1)
Block(-6,23,-7,srparasites:parasiterubbledense:1)
Block(-6,23,-6,srparasites:parasiterubbledense:1)
Block(-6,23,-5,srparasites:parasiterubbledense:1)
Block(-6,23,-4,srparasites:parasiterubbledense:1)
Block(-6,24,-7,srparasites:parasiterubbledense:1)
Block(-6,24,-6,srparasites:parasiterubbledense:1)
Block(-6,24,-5,srparasites:parasiterubbledense:1)
Block(-6,24,-4,srparasites:parasiterubbledense:1)
Block(-6,25,-7,srparasites:parasiterubbledense:1)
Block(-6,25,-6,srparasites:parasiterubbledense:1)
Block(-6,25,-5,srparasites:parasiterubbledense:1)
Block(-6,25,-4,srparasites:parasiterubbledense:1)
Block(-6,26,-7,srparasites:parasiterubbledense:1)
Block(-6,26,-6,srparasites:parasiterubbledense:1)
Block(-6,26,-5,srparasites:parasiterubbledense)
Block(-6,26,-4,srparasites:parasiterubbledense:1)
Block(-6,27,-7,srparasites:parasiterubbledense:1)
Block(-6,27,-6,srparasites:parasiterubbledense:1)
Block(-6,27,-5,srparasites:parasiterubbledense:1)
Block(-6,27,-4,srparasites:parasiterubbledense:1)
Block(-6,28,-7,srparasites:parasiterubbledense:1)
Block(-6,28,-6,srparasites:parasiterubbledense:1)
Block(-6,28,-5,srparasites:parasiterubbledense:1)
Block(-6,28,-4,AIR:0)
Block(-6,29,-7,srparasites:parasiterubbledense:1)
Block(-6,29,-6,srparasites:parasiterubbledense:1)
Block(-6,29,-5,srparasites:parasitebush)
Block(-6,29,-4,srparasites:parasiterubbledense:1)
Block(-6,30,-7,srparasites:parasiterubbledense:1)
Block(-6,30,-6,srparasites:parasiterubbledense:1)
Block(-6,30,-5,srparasites:parasiterubbledense)
Block(-6,30,-4,srparasites:parasiterubbledense)
Block(-6,31,-7,srparasites:parasiterubbledense:1)
Block(-6,31,-6,srparasites:parasiterubbledense:1)
Block(-6,31,-5,srparasites:parasiterubbledense:1)
Block(-6,31,-4,srparasites:parasiterubbledense:1)
Block(-6,32,-7,srparasites:parasiterubbledense:1)
Block(-6,32,-6,srparasites:parasiterubbledense:1)
Block(-6,32,-5,srparasites:parasitebush)
Block(-6,32,-4,srparasites:parasiterubbledense:1)
Block(-6,33,-7,srparasites:parasiterubbledense:1)
Block(-6,33,-6,srparasites:parasiterubbledense)
Block(-6,33,-5,srparasites:parasiterubbledense:1)
Block(-6,33,-4,srparasites:parasiterubbledense:1)
Block(-6,34,-7,srparasites:parasiterubbledense:1)
Block(-6,34,-6,srparasites:parasiterubbledense:1)
Block(-6,34,-4,srparasites:parasiterubbledense:1)
Block(-6,35,-7,srparasites:parasiterubbledense:1)
Block(-6,35,-6,srparasites:parasiterubbledense:1)
Block(-6,35,-5,srparasites:parasiterubbledense:1)
Block(-6,35,-4,srparasites:parasiterubbledense:1)
Block(-6,36,-7,srparasites:parasiterubbledense:1)
Block(-6,36,-6,srparasites:parasiterubbledense:1)
Block(-6,36,-5,srparasites:parasiterubbledense:1)
Block(-6,36,-4,srparasites:parasiterubbledense:1)
Block(-6,36,-3,srparasites:parasiterubbledense:1)
Block(-6,37,-7,srparasites:parasiterubbledense:1)
Block(-6,37,-6,srparasites:parasiterubbledense:1)
Block(-6,37,-5,srparasites:parasiterubbledense:1)
Block(-6,37,-4,srparasites:parasiterubbledense:1)
Block(-6,37,-3,srparasites:parasiterubbledense:1)
Block(-6,37,-2,srparasites:parasiterubbledense:1)
Block(-6,38,-7,srparasites:parasiterubbledense:1)
Block(-6,38,-6,srparasites:parasiterubbledense:1)
Block(-6,38,-5,srparasites:parasiterubbledense:1)
Block(-6,38,-4,srparasites:parasiterubbledense:1)
Block(-6,38,-3,srparasites:parasiterubbledense:1)
Block(-6,39,-7,srparasites:parasiterubbledense:1)
Block(-6,39,-6,srparasites:parasiterubbledense:1)
Block(-6,39,-5,srparasites:parasiterubbledense:1)
Block(-6,39,-4,srparasites:parasiterubbledense:1)
Block(-6,40,-7,srparasites:parasiterubbledense:1)
Block(-6,40,-6,srparasites:parasiterubbledense:1)
Block(-6,40,-5,srparasites:parasiterubbledense:1)
Block(-6,40,-4,srparasites:parasiterubbledense:1)
Block(-6,41,-7,srparasites:parasiterubbledense:1)
Block(-6,41,-6,srparasites:parasiterubbledense:1)
Block(-6,41,-5,srparasites:parasiterubbledense)
Block(-6,41,-4,srparasites:parasiterubbledense:1)
Block(-6,42,-7,srparasites:parasiterubbledense:1)
Block(-6,42,-6,srparasites:parasiterubbledense:1)
Block(-6,42,-5,srparasites:parasiterubbledense:1)
Block(-6,42,-4,srparasites:parasiterubbledense:1)
Block(-6,43,-7,srparasites:parasiterubbledense:1)
Block(-6,43,-6,srparasites:parasiterubbledense:1)
Block(-6,43,-5,srparasites:parasiterubbledense:1)
Block(-6,43,-4,srparasites:parasiterubbledense:1)
Block(-6,44,-7,srparasites:parasiterubbledense:1)
Block(-6,44,-6,srparasites:parasiterubbledense:1)
Block(-6,44,-5,srparasites:parasiterubbledense:1)
Block(-6,44,-4,srparasites:parasiterubbledense:1)
Block(-6,45,-7,srparasites:parasiterubbledense:1)
Block(-6,45,-6,srparasites:parasiterubbledense:1)
Block(-6,45,-5,srparasites:parasiterubbledense:1)
Block(-6,45,-4,srparasites:parasiterubbledense:1)
Block(-6,45,-3,srparasites:parasiterubbledense:1)
Block(-6,46,-7,srparasites:parasiterubbledense:1)
Block(-6,46,-6,srparasites:parasiterubbledense:1)
Block(-6,46,-5,srparasites:parasiterubbledense:1)
Block(-6,46,-4,srparasites:parasiterubbledense:1)
Block(-6,46,-3,srparasites:parasiterubbledense:1)
Block(-6,47,-7,srparasites:parasiterubbledense:1)
Block(-6,47,-6,srparasites:parasiterubbledense:1)
Block(-6,47,-5,srparasites:parasiterubbledense:1)
Block(-6,47,-4,srparasites:parasiterubbledense:1)
Block(-6,47,-3,srparasites:parasiterubbledense:1)
Block(-6,48,-7,srparasites:parasiterubbledense:1)
Block(-6,48,-6,srparasites:parasiterubbledense:1)
Block(-6,48,-5,srparasites:parasiterubbledense:1)
Block(-6,48,-4,srparasites:parasiterubbledense:1)
Block(-6,49,-7,srparasites:parasiterubbledense:1)
Block(-6,49,-6,srparasites:parasiterubbledense:1)
Block(-6,49,-5,srparasites:parasiterubbledense:1)
Block(-6,49,-4,srparasites:parasiterubbledense:1)
Block(-6,50,-7,srparasites:parasiterubbledense:1)
Block(-6,50,-6,srparasites:parasiterubbledense:1)
Block(-6,50,-5,srparasites:parasiterubbledense:1)
Block(-6,50,-4,srparasites:parasiterubbledense:1)
Block(-6,51,-7,srparasites:parasiterubbledense:1)
Block(-6,51,-6,srparasites:parasiterubbledense:1)
Block(-6,51,-5,srparasites:parasiterubbledense:1)
Block(-6,51,-4,srparasites:parasiterubbledense:1)
Block(-6,52,-7,srparasites:parasiterubbledense:1)
Block(-6,52,-6,srparasites:parasiterubbledense:1)
Block(-6,52,-5,srparasites:parasiterubbledense:1)
Block(-6,52,-4,srparasites:parasiterubbledense:1)
Block(-6,53,-7,AIR:0)
Block(-6,53,-6,AIR:0)
Block(-6,53,-5,srparasites:parasiterubbledense:1)
Block(-6,54,-7,AIR:0)
Block(-6,54,-6,AIR:0)
Block(-6,54,-5,srparasites:parasiterubbledense:1)
Block(-6,54,-4,srparasites:parasiterubbledense:1)
Block(-6,55,-7,AIR:0)
Block(-6,55,-6,AIR:0)
Block(-6,55,-5,AIR:0)
Block(-6,55,-4,BONE_BLOCK:0)
Block(-6,55,-3,srparasites:parasiterubbledense:1)
Block(-6,56,-7,AIR:0)
Block(-6,56,-6,AIR:0)
Block(-6,56,-5,AIR:0)
Block(-6,56,-4,AIR:0)
Block(-6,56,-3,AIR:0)
Block(-6,56,-2,srparasites:parasiterubbledense:1)
Block(-6,57,-7,AIR:0)
Block(-6,57,-6,AIR:0)
Block(-6,57,-5,AIR:0)
Block(-6,57,-4,AIR:0)
Block(-6,57,-3,AIR:0)
Block(-6,57,-2,srparasites:parasiterubbledense:1)
Block(-6,57,-1,srparasites:parasiterubbledense:1)
Block(-6,58,-7,AIR:0)
Block(-6,58,-6,AIR:0)
Block(-6,58,-5,AIR:0)
Block(-6,58,-4,AIR:0)
Block(-6,58,-3,AIR:0)
Block(-6,58,-2,AIR:0)
Block(-6,58,-1,srparasites:parasiterubbledense:1)
Block(-6,59,-7,AIR:0)
Block(-6,59,-6,AIR:0)
Block(-6,59,-5,AIR:0)
Block(-6,59,-4,AIR:0)
Block(-6,59,-3,AIR:0)
Block(-6,59,-2,AIR:0)
Block(-6,59,-1,srparasites:parasiterubbledense:1)
Block(-6,60,-7,AIR:0)
Block(-6,60,-6,AIR:0)
Block(-6,60,-5,AIR:0)
Block(-6,60,-4,AIR:0)
Block(-6,60,-3,AIR:0)
Block(-6,60,-2,AIR:0)
Block(-6,60,-1,srparasites:parasiterubbledense:1)
Block(-6,61,-7,AIR:0)
Block(-6,61,-6,AIR:0)
Block(-6,61,-5,AIR:0)
Block(-6,61,-4,srparasites:parasiterubbledense:1)
Block(-6,61,-3,srparasites:parasiterubbledense:1)
Block(-6,61,-2,srparasites:parasiterubbledense:1)
Block(-6,61,-1,srparasites:parasiterubbledense:1)
Block(-6,62,-7,AIR:0)
Block(-6,62,-6,AIR:0)
Block(-6,62,-5,srparasites:parasiterubbledense:1)
Block(-6,62,-4,srparasites:parasiterubbledense:1)
Block(-6,62,-3,srparasites:parasiterubbledense:1)
Block(-6,62,-2,srparasites:parasiterubbledense:1)
Block(-6,62,-1,srparasites:parasiterubbledense:1)
Block(-6,62,0,srparasites:parasiterubbledense:1)
Block(-6,63,-7,AIR:0)
Block(-6,63,-6,srparasites:parasiterubbledense:1)
Block(-6,63,-5,srparasites:parasiterubbledense:1)
Block(-6,63,-4,srparasites:parasiterubbledense:1)
Block(-6,63,-3,srparasites:parasiterubbledense:1)
Block(-6,63,-2,srparasites:parasiterubbledense:1)
Block(-6,63,-1,srparasites:parasiterubbledense:1)
Block(-6,63,0,srparasites:parasiterubbledense:1)
Block(-6,63,1,srparasites:parasiterubbledense:1)
Block(-6,64,-7,AIR:0)
Block(-6,64,-6,srparasites:parasiterubbledense:1)
Block(-6,64,-5,srparasites:parasiterubbledense:1)
Block(-6,64,-4,srparasites:parasiterubbledense:1)
Block(-6,64,-3,srparasites:parasiterubbledense:1)
Block(-6,64,-2,srparasites:parasiterubbledense:1)
Block(-6,64,-1,srparasites:parasiterubbledense:1)
Block(-6,64,0,srparasites:parasiterubbledense:1)
Block(-6,64,1,srparasites:parasiterubbledense:1)
Block(-6,65,-7,AIR:0)
Block(-6,65,-6,srparasites:parasiterubbledense:1)
Block(-6,65,-5,srparasites:parasiterubbledense:1)
Block(-6,65,-4,AIR:0)
Block(-6,65,-3,SMOOTH_BRICK:2)
Block(-6,65,-2,SMOOTH_BRICK:1)
Block(-6,65,-1,AIR:0)
Block(-6,65,0,srparasites:parasiterubbledense:1)
Block(-6,65,1,srparasites:parasiterubbledense:1)
Block(-6,66,-7,srparasites:parasiterubbledense:1)
Block(-6,66,-6,srparasites:parasiterubbledense:1)
Block(-6,66,-5,srparasites:parasiterubbledense:1)
Block(-6,66,-4,srparasites:parasiterubbledense:1)
Block(-6,66,-3,AIR:0)
Block(-6,66,-2,AIR:0)
Block(-6,66,-1,srparasites:parasiterubbledense:1)
Block(-6,66,0,srparasites:parasiterubbledense:1)
Block(-6,66,1,srparasites:parasiterubbledense:1)
Block(-6,67,-7,DIRT:0)
Block(-6,67,-6,srparasites:parasiterubbledense:1)
Block(-6,67,-5,srparasites:parasiterubbledense:1)
Block(-6,67,-4,srparasites:parasiterubbledense:1)
Block(-6,67,-3,AIR:0)
Block(-6,67,-2,AIR:0)
Block(-6,67,-1,srparasites:parasiterubbledense:1)
Block(-6,67,0,srparasites:parasiterubbledense:1)
Block(-6,67,1,DIRT:0)
Block(-6,67,2,DIRT:0)
Block(-6,67,3,DIRT:0)
Block(-6,67,4,DIRT:0)
Block(-6,67,5,DIRT:0)
Block(-6,67,6,DIRT:0)
Block(-6,67,7,DIRT:0)
Block(-6,67,8,DIRT:0)
Block(-6,68,-7,DIRT:0)
Block(-6,68,-6,DIRT:0)
Block(-6,68,-5,srparasites:parasiterubbledense:1)
Block(-6,68,-4,srparasites:parasiterubbledense:1)
Block(-6,68,-3,srparasites:parasiterubbledense:1)
Block(-6,68,-2,srparasites:parasiterubbledense:1)
Block(-6,68,-1,DIRT:0)
Block(-6,68,0,DIRT:0)
Block(-6,68,1,DIRT:0)
Block(-6,68,2,DIRT:0)
Block(-6,68,3,DIRT:0)
Block(-6,68,4,DIRT:0)
Block(-6,68,5,DIRT:0)
Block(-6,68,6,DIRT:0)
Block(-6,68,7,DIRT:0)
Block(-6,68,8,DIRT:0)
Block(-6,69,-7,DIRT:0)
Block(-6,69,-6,DIRT:0)
Block(-6,69,-5,srparasites:parasiterubbledense:1)
Block(-6,69,-4,DIRT:0)
Block(-6,69,-3,DIRT:0)
Block(-6,69,-2,DIRT:0)
Block(-6,69,-1,DIRT:0)
Block(-6,69,0,DIRT:0)
Block(-6,69,1,DIRT:0)
Block(-6,69,2,DIRT:0)
Block(-6,69,3,DIRT:0)
Block(-6,69,4,DIRT:0)
Block(-6,69,5,DIRT:0)
Block(-6,69,6,DIRT:0)
Block(-6,69,7,DIRT:0)
Block(-6,69,8,DIRT:0)
Block(-6,70,-7,DIRT:0)
Block(-6,70,-6,DIRT:0)
Block(-6,70,-5,srparasites:parasiterubbledense:1)
Block(-6,70,-4,DIRT:0)
Block(-6,70,-3,DIRT:0)
Block(-6,70,-2,DIRT:0)
Block(-6,70,-1,DIRT:0)
Block(-6,70,0,DIRT:0)
Block(-6,70,1,DIRT:0)
Block(-6,70,2,DIRT:0)
Block(-6,70,3,DIRT:0)
Block(-6,70,4,DIRT:0)
Block(-6,70,5,DIRT:0)
Block(-6,70,6,DIRT:0)
Block(-6,70,7,DIRT:0)
Block(-6,70,8,DIRT:0)
Block(-6,71,-7,DIRT:0)
Block(-6,71,-6,DIRT:0)
Block(-6,71,-5,srparasites:parasiterubbledense:1)
Block(-6,71,-4,DIRT:0)
Block(-6,71,-3,DIRT:0)
Block(-6,71,-2,DIRT:0)
Block(-6,71,-1,DIRT:0)
Block(-6,71,0,DIRT:0)
Block(-6,71,1,DIRT:0)
Block(-6,71,2,DIRT:0)
Block(-6,71,3,DIRT:0)
Block(-6,71,4,DIRT:0)
Block(-6,71,5,DIRT:0)
Block(-6,71,6,DIRT:0)
Block(-6,71,7,DIRT:0)
Block(-6,71,8,DIRT:0)
Block(-6,72,-7,DIRT:0)
Block(-6,72,-6,DIRT:0)
Block(-6,72,-5,srparasites:parasiterubbledense:1)
Block(-6,72,-4,DIRT:0)
Block(-6,72,-3,DIRT:0)
Block(-6,72,-2,DIRT:0)
Block(-6,72,-1,DIRT:0)
Block(-6,72,0,DIRT:0)
Block(-6,72,1,DIRT:0)
Block(-6,72,2,DIRT:0)
Block(-6,72,3,DIRT:0)
Block(-6,72,4,DIRT:0)
Block(-6,72,5,DIRT:0)
Block(-6,72,6,DIRT:0)
Block(-6,72,7,DIRT:0)
Block(-6,72,8,DIRT:0)
Block(-6,73,-7,srparasites:parasiterubble_slabhalf:0)
Block(-6,73,-6,DIRT:0)
Block(-6,73,-5,srparasites:parasiterubbledense:1)
Block(-6,73,-4,DIRT:0)
Block(-6,73,-3,DIRT:0)
Block(-6,73,-2,DIRT:0)
Block(-6,73,-1,DIRT:0)
Block(-6,73,0,DIRT:0)
Block(-6,73,1,DIRT:0)
Block(-6,73,2,DIRT:0)
Block(-6,73,3,DIRT:0)
Block(-6,73,4,DIRT:0)
Block(-6,73,5,DIRT:0)
Block(-6,73,6,DIRT:0)
Block(-6,73,7,DIRT:0)
Block(-6,73,8,DIRT:0)
Block(-6,74,-7,SMOOTH_BRICK:2)
Block(-6,74,-6,BONE_BLOCK:0)
Block(-6,74,-5,srparasites:parasiterubbledense:1)
Block(-6,74,-4,DIRT:0)
Block(-6,74,-3,DIRT:0)
Block(-6,74,-2,DIRT:0)
Block(-6,74,-1,DIRT:0)
Block(-6,74,0,DIRT:0)
Block(-6,74,1,DIRT:0)
Block(-6,74,2,DIRT:0)
Block(-6,74,3,DIRT:0)
Block(-6,74,4,DIRT:0)
Block(-6,74,5,DIRT:0)
Block(-6,74,6,DIRT:0)
Block(-6,74,7,DIRT:0)
Block(-6,74,8,DIRT:0)
Block(-6,75,-7,AIR:0)
Block(-6,75,-6,BONE_BLOCK:0)
Block(-6,75,-5,srparasites:parasiterubbledense:1)
Block(-6,75,-4,srparasites:parasiterubble_slabhalf:0)
Block(-6,75,-3,srparasites:parasiterubble_slabhalf:0)
Block(-6,75,-2,srparasites:parasiterubble_slabhalf:0)
Block(-6,75,-1,srparasites:parasiterubble_slabhalf:0)
Block(-6,75,0,srparasites:parasiterubble_slabhalf:0)
Block(-6,75,1,srparasites:parasiterubble_slabhalf:0)
Block(-6,75,2,srparasites:parasiterubble_slabhalf:0)
Block(-6,75,3,srparasites:parasiterubble_slabhalf:0)
Block(-6,75,4,srparasites:parasiterubble_slabhalf:0)
Block(-6,75,5,srparasites:parasiterubbledense:1)
Block(-6,75,6,srparasites:parasiterubbledense:1)
Block(-6,75,7,srparasites:parasiterubbledense:1)
Block(-6,75,8,DIRT:0)
Block(-6,76,-7,AIR:0)
Block(-6,76,-6,BONE_BLOCK:0)
Block(-6,76,-5,srparasites:parasiterubbledense:1)
Block(-6,76,-4,SMOOTH_BRICK:1)
Block(-6,76,-3,SMOOTH_BRICK:0)
Block(-6,76,-2,SMOOTH_BRICK:0)
Block(-6,76,-1,SMOOTH_BRICK:0)
Block(-6,76,0,SMOOTH_BRICK:0)
Block(-6,76,1,SMOOTH_BRICK:0)
Block(-6,76,2,SMOOTH_BRICK:0)
Block(-6,76,3,SMOOTH_BRICK:0)
Block(-6,76,4,SMOOTH_BRICK:0)
Block(-6,76,5,srparasites:parasiterubbledense:1)
Block(-6,76,6,srparasites:parasiterubbledense:1)
Block(-6,76,7,srparasites:parasiterubbledense:1)
Block(-6,76,8,srparasites:parasiterubbledense:1)
Block(-6,77,-7,AIR:0)
Block(-6,77,-6,BONE_BLOCK:0)
Block(-6,77,-5,srparasites:parasiterubble_slabhalf:0)
Block(-6,77,-4,AIR:0)
Block(-6,77,-3,AIR:0)
Block(-6,77,-2,AIR:0)
Block(-6,77,-1,AIR:0)
Block(-6,77,0,AIR:0)
Block(-6,77,1,AIR:0)
Block(-6,77,2,AIR:0)
Block(-6,77,3,AIR:0)
Block(-6,77,4,AIR:0)
Block(-6,77,5,AIR:0)
Block(-6,77,6,srparasites:parasiterubble_slabhalf:0)
Block(-6,77,7,srparasites:parasiterubble_slabhalf:0)
Block(-6,77,8,srparasites:parasiterubbledense:1)
Block(-6,78,-7,AIR:0)
Block(-6,78,-6,srparasites:parasiterubble_slabhalf:0)
Block(-6,78,-5,AIR:0)
Block(-6,78,-4,AIR:0)
Block(-6,78,-3,AIR:0)
Block(-6,78,-2,AIR:0)
Block(-6,78,-1,AIR:0)
Block(-6,78,0,AIR:0)
Block(-6,78,1,AIR:0)
Block(-6,78,2,AIR:0)
Block(-6,78,3,AIR:0)
Block(-6,78,4,AIR:0)
Block(-6,78,5,AIR:0)
Block(-6,78,6,AIR:0)
Block(-6,78,7,AIR:0)
Block(-6,78,8,AIR:0)
Block(-6,79,-7,AIR:0)
Block(-6,79,-6,AIR:0)
Block(-6,79,-5,AIR:0)
Block(-6,79,-4,AIR:0)
Block(-6,79,-3,AIR:0)
Block(-6,79,-2,AIR:0)
Block(-6,79,-1,AIR:0)
Block(-6,79,0,AIR:0)
Block(-6,79,1,AIR:0)
Block(-6,79,2,AIR:0)
Block(-6,79,3,AIR:0)
Block(-6,79,4,AIR:0)
Block(-6,79,5,AIR:0)
Block(-6,79,6,AIR:0)
Block(-6,79,7,AIR:0)
Block(-6,79,8,AIR:0)
Block(-6,80,-7,AIR:0)
Block(-6,80,-6,AIR:0)
Block(-6,80,-5,AIR:0)
Block(-6,80,-4,AIR:0)
Block(-6,80,-3,AIR:0)
Block(-6,80,-2,AIR:0)
Block(-6,80,-1,AIR:0)
Block(-6,80,0,AIR:0)
Block(-6,80,1,AIR:0)
Block(-6,80,2,AIR:0)
Block(-6,80,3,AIR:0)
Block(-6,80,4,AIR:0)
Block(-6,80,5,AIR:0)
Block(-6,80,6,AIR:0)
Block(-6,80,7,AIR:0)
Block(-6,80,8,AIR:0)
Block(-6,81,-7,AIR:0)
Block(-6,81,-6,AIR:0)
Block(-6,81,-5,AIR:0)
Block(-6,81,-4,AIR:0)
Block(-6,81,-3,AIR:0)
Block(-6,81,-2,AIR:0)
Block(-6,81,-1,AIR:0)
Block(-6,81,0,AIR:0)
Block(-6,81,1,AIR:0)
Block(-6,81,2,AIR:0)
Block(-6,81,3,AIR:0)
Block(-6,81,4,AIR:0)
Block(-6,81,5,AIR:0)
Block(-6,81,6,AIR:0)
Block(-6,81,7,AIR:0)
Block(-6,81,8,AIR:0)
Block(-6,82,-7,AIR:0)
Block(-6,82,-6,AIR:0)
Block(-6,82,-5,AIR:0)
Block(-6,82,-4,AIR:0)
Block(-6,82,-3,AIR:0)
Block(-6,82,-2,AIR:0)
Block(-6,82,-1,AIR:0)
Block(-6,82,0,AIR:0)
Block(-6,82,1,AIR:0)
Block(-6,82,2,AIR:0)
Block(-6,82,3,AIR:0)
Block(-6,82,4,AIR:0)
Block(-6,82,5,AIR:0)
Block(-6,82,6,AIR:0)
Block(-6,82,7,AIR:0)
Block(-6,82,8,AIR:0)
Block(-6,83,-7,AIR:0)
Block(-6,83,-6,AIR:0)
Block(-6,83,-5,AIR:0)
Block(-6,83,-4,AIR:0)
Block(-6,83,-3,AIR:0)
Block(-6,83,-2,AIR:0)
Block(-6,83,-1,AIR:0)
Block(-6,83,0,AIR:0)
Block(-6,83,1,AIR:0)
Block(-6,83,2,AIR:0)
Block(-6,83,3,AIR:0)
Block(-6,83,4,AIR:0)
Block(-6,83,5,AIR:0)
Block(-6,83,6,AIR:0)
Block(-6,83,7,AIR:0)
Block(-6,83,8,AIR:0)
Block(-5,1,-7,srparasites:parasiterubbledense:1)
Block(-5,1,-6,srparasites:parasiterubbledense:1)
Block(-5,1,-5,srparasites:parasiterubbledense:1)
Block(-5,1,-4,srparasites:parasiterubbledense:1)
Block(-5,1,-3,srparasites:parasiterubbledense:1)
Block(-5,1,-2,srparasites:parasiterubbledense:1)
Block(-5,2,-7,srparasites:parasiterubbledense:1)
Block(-5,2,-6,srparasites:parasiterubbledense:1)
Block(-5,2,-5,srparasites:parasiterubbledense:1)
Block(-5,2,-4,srparasites:parasiterubbledense:1)
Block(-5,2,-3,srparasites:parasiterubbledense:1)
Block(-5,3,-7,srparasites:parasiterubbledense:1)
Block(-5,3,-6,srparasites:parasiterubbledense:1)
Block(-5,3,-5,srparasites:parasiterubbledense:1)
Block(-5,3,-4,srparasites:parasiterubbledense:1)
Block(-5,4,-7,srparasites:parasiterubbledense:1)
Block(-5,4,-6,srparasites:parasiterubbledense:1)
Block(-5,4,-5,srparasites:parasiterubbledense:1)
Block(-5,4,-4,srparasites:parasiterubbledense:1)
Block(-5,5,-7,srparasites:parasiterubbledense:1)
Block(-5,5,-6,srparasites:parasiterubbledense:1)
Block(-5,5,-5,srparasites:parasiterubbledense:1)
Block(-5,5,-4,srparasites:parasiterubbledense:1)
Block(-5,5,-3,srparasites:parasiterubbledense:1)
Block(-5,6,-7,srparasites:parasiterubbledense:1)
Block(-5,6,-6,srparasites:parasiterubbledense:1)
Block(-5,6,-5,srparasites:parasiterubbledense:1)
Block(-5,6,-4,srparasites:parasiterubbledense:1)
Block(-5,7,-7,srparasites:parasiterubbledense:1)
Block(-5,7,-6,srparasites:parasiterubbledense:1)
Block(-5,7,-5,srparasites:parasiterubbledense:1)
Block(-5,8,-7,srparasites:parasiterubbledense:1)
Block(-5,8,-6,srparasites:parasiterubbledense:1)
Block(-5,8,-5,srparasites:parasiterubbledense:1)
Block(-5,9,-7,srparasites:parasiterubbledense:1)
Block(-5,9,-6,srparasites:parasiterubbledense:1)
Block(-5,9,-5,srparasites:parasiterubbledense:1)
Block(-5,9,-4,srparasites:parasiterubbledense:1)
Block(-5,10,-7,srparasites:parasiterubbledense:1)
Block(-5,10,-6,srparasites:parasiterubbledense:1)
Block(-5,10,-5,srparasites:parasiterubbledense:1)
Block(-5,10,-4,srparasites:parasiterubbledense:1)
Block(-5,11,-7,srparasites:parasiterubbledense:1)
Block(-5,11,-6,srparasites:parasiterubbledense:1)
Block(-5,11,-5,srparasites:parasiterubbledense:1)
Block(-5,11,-4,srparasites:parasiterubbledense:1)
Block(-5,11,-3,srparasites:parasiterubbledense:1)
Block(-5,12,-7,srparasites:parasiterubbledense:1)
Block(-5,12,-6,srparasites:parasiterubbledense:1)
Block(-5,12,-5,srparasites:parasiterubbledense:1)
Block(-5,12,-4,srparasites:parasiterubbledense:1)
Block(-5,13,-7,srparasites:parasiterubbledense:1)
Block(-5,13,-6,srparasites:parasiterubbledense:1)
Block(-5,13,-5,srparasites:parasiterubbledense:1)
Block(-5,14,-7,srparasites:parasiterubbledense:1)
Block(-5,14,-6,srparasites:parasiterubbledense:1)
Block(-5,14,-5,srparasites:parasiterubbledense:1)
Block(-5,15,-7,srparasites:parasiterubbledense:1)
Block(-5,15,-6,srparasites:parasiterubbledense:1)
Block(-5,15,-5,srparasites:parasiterubbledense:1)
Block(-5,16,-7,srparasites:parasiterubbledense:1)
Block(-5,16,-6,srparasites:parasiterubbledense:1)
Block(-5,16,-5,AIR:0)
Block(-5,17,-7,srparasites:parasiterubbledense:1)
Block(-5,17,-6,srparasites:parasiterubbledense:1)
Block(-5,17,-5,srparasites:parasiterubbledense:1)
Block(-5,18,-7,srparasites:parasiterubbledense:1)
Block(-5,18,-6,srparasites:parasiterubbledense:1)
Block(-5,18,-5,srparasites:parasiterubbledense:1)
Block(-5,19,-7,srparasites:parasiterubbledense:1)
Block(-5,19,-6,srparasites:parasiterubbledense:1)
Block(-5,19,-5,srparasites:parasiterubbledense:1)
Block(-5,20,-7,srparasites:parasiterubbledense:1)
Block(-5,20,-6,srparasites:parasiterubbledense:1)
Block(-5,20,-5,srparasites:parasiterubbledense:1)
Block(-5,21,-7,srparasites:parasiterubbledense:1)
Block(-5,21,-6,srparasites:parasiterubbledense:1)
Block(-5,21,-5,srparasites:parasiterubbledense:1)
Block(-5,22,-7,srparasites:parasiterubbledense:1)
Block(-5,22,-6,srparasites:parasiterubbledense:1)
Block(-5,22,-5,srparasites:parasiterubbledense:1)
Block(-5,23,-7,srparasites:parasiterubbledense:1)
Block(-5,23,-6,srparasites:parasiterubbledense:1)
Block(-5,23,-5,srparasites:parasiterubbledense:1)
Block(-5,23,-4,srparasites:parasiterubbledense:1)
Block(-5,24,-7,srparasites:parasiterubbledense:1)
Block(-5,24,-6,srparasites:parasiterubbledense:1)
Block(-5,24,-5,srparasites:parasiterubbledense:1)
Block(-5,24,-4,srparasites:parasiterubbledense:1)
Block(-5,25,-7,srparasites:parasiterubbledense:1)
Block(-5,25,-6,srparasites:parasiterubbledense:1)
Block(-5,25,-5,srparasites:parasiterubbledense:1)
Block(-5,25,-4,srparasites:parasiterubbledense:1)
Block(-5,26,-7,srparasites:parasiterubbledense:1)
Block(-5,26,-6,srparasites:parasiterubbledense:1)
Block(-5,26,-5,srparasites:parasiterubbledense:1)
Block(-5,27,-7,srparasites:parasiterubbledense:1)
Block(-5,27,-6,srparasites:parasiterubbledense:1)
Block(-5,27,-5,AIR:0)
Block(-5,28,-7,srparasites:parasiterubbledense:1)
Block(-5,28,-6,srparasites:parasiterubbledense:1)
Block(-5,28,-5,srparasites:parasiterubbledense:1)
Block(-5,29,-7,srparasites:parasiterubbledense:1)
Block(-5,29,-6,srparasites:parasiterubbledense:1)
Block(-5,29,-5,srparasites:parasiterubbledense:1)
Block(-5,30,-7,srparasites:parasiterubbledense:1)
Block(-5,30,-6,srparasites:parasiterubbledense:1)
Block(-5,30,-5,srparasites:parasiterubbledense)
Block(-5,31,-7,srparasites:parasiterubbledense:1)
Block(-5,31,-6,srparasites:parasiterubbledense:1)
Block(-5,31,-5,srparasites:parasiterubbledense:1)
Block(-5,32,-7,srparasites:parasiterubbledense:1)
Block(-5,32,-6,srparasites:parasiterubbledense)
Block(-5,32,-5,srparasites:parasiterubbledense:1)
Block(-5,33,-7,srparasites:parasiterubbledense:1)
Block(-5,33,-6,srparasites:parasiterubbledense)
Block(-5,33,-5,AIR:0)
Block(-5,34,-7,srparasites:parasiterubbledense:1)
Block(-5,34,-6,srparasites:parasiterubbledense:1)
Block(-5,35,-7,srparasites:parasiterubbledense:1)
Block(-5,35,-6,srparasites:parasiterubbledense:1)
Block(-5,35,-5,srparasites:parasiterubbledense:1)
Block(-5,36,-7,srparasites:parasiterubbledense:1)
Block(-5,36,-6,srparasites:parasiterubbledense:1)
Block(-5,36,-5,srparasites:parasiterubbledense:1)
Block(-5,36,-4,srparasites:parasiterubbledense:1)
Block(-5,36,-3,srparasites:parasiterubbledense:1)
Block(-5,36,-2,srparasites:parasiterubbledense:1)
Block(-5,37,-7,srparasites:parasiterubbledense:1)
Block(-5,37,-6,srparasites:parasiterubbledense:1)
Block(-5,37,-5,srparasites:parasiterubbledense:1)
Block(-5,37,-4,srparasites:parasiterubbledense:1)
Block(-5,37,-3,srparasites:parasiterubbledense:1)
Block(-5,37,-2,srparasites:parasiterubbledense:1)
Block(-5,38,-7,srparasites:parasiterubbledense:1)
Block(-5,38,-6,srparasites:parasiterubbledense:1)
Block(-5,38,-5,srparasites:parasiterubbledense:1)
Block(-5,38,-4,srparasites:parasiterubbledense:1)
Block(-5,38,-3,srparasites:parasiterubbledense:1)
Block(-5,38,-2,srparasites:parasiterubbledense:1)
Block(-5,39,-7,srparasites:parasiterubbledense:1)
Block(-5,39,-6,srparasites:parasiterubbledense:1)
Block(-5,39,-5,srparasites:parasiterubbledense:1)
Block(-5,40,-7,srparasites:parasiterubbledense:1)
Block(-5,40,-6,srparasites:parasiterubbledense:1)
Block(-5,40,-5,srparasites:parasiterubbledense:1)
Block(-5,41,-7,srparasites:parasiterubbledense:1)
Block(-5,41,-6,srparasites:parasiterubbledense:1)
Block(-5,41,-5,srparasites:parasiterubbledense:1)
Block(-5,42,-7,srparasites:parasiterubbledense:1)
Block(-5,42,-6,srparasites:parasiterubbledense:1)
Block(-5,42,-5,srparasites:parasiterubbledense:1)
Block(-5,43,-7,srparasites:parasiterubbledense:1)
Block(-5,43,-6,srparasites:parasiterubbledense:1)
Block(-5,43,-5,srparasites:parasiterubbledense:1)
Block(-5,44,-7,srparasites:parasiterubbledense:1)
Block(-5,44,-6,srparasites:parasiterubbledense:1)
Block(-5,44,-5,srparasites:parasiterubbledense:1)
Block(-5,45,-7,srparasites:parasiterubbledense:1)
Block(-5,45,-6,srparasites:parasiterubbledense:1)
Block(-5,45,-5,srparasites:parasiterubbledense:1)
Block(-5,45,-4,srparasites:parasiterubbledense:1)
Block(-5,46,-7,srparasites:parasiterubbledense:1)
Block(-5,46,-6,srparasites:parasiterubbledense:1)
Block(-5,46,-5,srparasites:parasiterubbledense:1)
Block(-5,46,-4,srparasites:parasiterubbledense:1)
Block(-5,46,-3,srparasites:parasiterubbledense:1)
Block(-5,47,-7,srparasites:parasiterubbledense:1)
Block(-5,47,-6,srparasites:parasiterubbledense:1)
Block(-5,47,-5,srparasites:parasiterubbledense:1)
Block(-5,47,-4,srparasites:parasiterubbledense:1)
Block(-5,48,-7,srparasites:parasiterubbledense:1)
Block(-5,48,-6,srparasites:parasiterubbledense:1)
Block(-5,48,-5,srparasites:parasiterubbledense:1)
Block(-5,49,-7,srparasites:parasiterubbledense:1)
Block(-5,49,-6,srparasites:parasiterubbledense:1)
Block(-5,49,-5,srparasites:parasiterubbledense:1)
Block(-5,50,-7,srparasites:parasiterubbledense:1)
Block(-5,50,-6,srparasites:parasiterubbledense:1)
Block(-5,50,-5,srparasites:parasiterubbledense:1)
Block(-5,51,-7,srparasites:parasiterubbledense:1)
Block(-5,51,-6,srparasites:parasiterubbledense:1)
Block(-5,51,-5,srparasites:parasiterubbledense:1)
Block(-5,52,-7,srparasites:parasiterubbledense:1)
Block(-5,52,-6,srparasites:parasiterubbledense:1)
Block(-5,52,-5,srparasites:parasiterubbledense:1)
Block(-5,53,-7,BONE_BLOCK:0)
Block(-5,53,-6,AIR:0)
Block(-5,53,-5,srparasites:parasiterubbledense:1)
Block(-5,54,-7,AIR:0)
Block(-5,54,-6,AIR:0)
Block(-5,54,-5,srparasites:parasiterubbledense:1)
Block(-5,54,-4,srparasites:parasiterubbledense:1)
Block(-5,55,-7,AIR:0)
Block(-5,55,-6,AIR:0)
Block(-5,55,-5,AIR:0)
Block(-5,55,-4,srparasites:parasiterubbledense:1)
Block(-5,55,-3,srparasites:parasiterubbledense:1)
Block(-5,56,-7,AIR:0)
Block(-5,56,-6,AIR:0)
Block(-5,56,-5,AIR:0)
Block(-5,56,-4,AIR:0)
Block(-5,56,-3,srparasites:parasiterubbledense:1)
Block(-5,57,-7,AIR:0)
Block(-5,57,-6,AIR:0)
Block(-5,57,-5,AIR:0)
Block(-5,57,-4,AIR:0)
Block(-5,57,-3,srparasites:parasiterubbledense:1)
Block(-5,58,-7,AIR:0)
Block(-5,58,-6,AIR:0)
Block(-5,58,-5,AIR:0)
Block(-5,58,-4,AIR:0)
Block(-5,58,-3,srparasites:parasiterubbledense:1)
Block(-5,58,-2,srparasites:parasiterubbledense:1)
Block(-5,59,-7,AIR:0)
Block(-5,59,-6,AIR:0)
Block(-5,59,-5,AIR:0)
Block(-5,59,-4,AIR:0)
Block(-5,59,-3,srparasites:parasiterubbledense:1)
Block(-5,59,-2,srparasites:parasiterubbledense:1)
Block(-5,60,-7,AIR:0)
Block(-5,60,-6,AIR:0)
Block(-5,60,-5,AIR:0)
Block(-5,60,-4,AIR:0)
Block(-5,60,-3,AIR:0)
Block(-5,60,-2,srparasites:parasiterubbledense:1)
Block(-5,61,-7,AIR:0)
Block(-5,61,-6,AIR:0)
Block(-5,61,-5,AIR:0)
Block(-5,61,-4,srparasites:parasiterubbledense:1)
Block(-5,61,-3,srparasites:parasiterubbledense:1)
Block(-5,61,-2,srparasites:parasiterubbledense:1)
Block(-5,62,-7,AIR:0)
Block(-5,62,-6,AIR:0)
Block(-5,62,-5,AIR:0)
Block(-5,62,-4,srparasites:parasiterubbledense:1)
Block(-5,62,-3,srparasites:parasiterubbledense:1)
Block(-5,62,-2,srparasites:parasiterubbledense:1)
Block(-5,63,-7,AIR:0)
Block(-5,63,-6,AIR:0)
Block(-5,63,-5,srparasites:parasiterubbledense:1)
Block(-5,63,-4,srparasites:parasiterubbledense:1)
Block(-5,63,-3,srparasites:parasiterubbledense:1)
Block(-5,63,-2,srparasites:parasiterubbledense:1)
Block(-5,63,-1,srparasites:parasiterubbledense:1)
Block(-5,63,0,srparasites:parasiterubbledense:1)
Block(-5,64,-7,AIR:0)
Block(-5,64,-6,srparasites:parasiterubbledense:1)
Block(-5,64,-5,srparasites:parasiterubbledense:1)
Block(-5,64,-4,AIR:0)
Block(-5,64,-3,SMOOTH_BRICK:1)
Block(-5,64,-2,SMOOTH_BRICK:1)
Block(-5,64,-1,srparasites:parasiterubbledense:1)
Block(-5,64,0,srparasites:parasiterubbledense:1)
Block(-5,65,-7,srparasites:parasiterubbledense:1)
Block(-5,65,-6,srparasites:parasiterubbledense:1)
Block(-5,65,-5,srparasites:parasiterubbledense:1)
Block(-5,65,-4,AIR:0)
Block(-5,65,-3,SMOOTH_BRICK:3)
Block(-5,65,-2,SMOOTH_BRICK:2)
Block(-5,65,-1,srparasites:parasiterubbledense:1)
Block(-5,65,0,srparasites:parasiterubbledense:1)
Block(-5,66,-7,srparasites:parasiterubbledense:1)
Block(-5,66,-6,srparasites:parasiterubbledense:1)
Block(-5,66,-5,srparasites:parasiterubbledense:1)
Block(-5,66,-4,srparasites:parasiterubbledense:1)
Block(-5,66,-3,AIR:0)
Block(-5,66,-2,AIR:0)
Block(-5,66,-1,srparasites:parasiterubbledense:1)
Block(-5,66,0,srparasites:parasiterubbledense:1)
Block(-5,67,-7,DIRT:0)
Block(-5,67,-6,srparasites:parasiterubbledense:1)
Block(-5,67,-5,srparasites:parasiterubbledense:1)
Block(-5,67,-4,srparasites:parasiterubbledense:1)
Block(-5,67,-3,srparasites:parasiterubbledense:1)
Block(-5,67,-2,srparasites:parasiterubbledense:1)
Block(-5,67,-1,srparasites:parasiterubbledense:1)
Block(-5,67,0,srparasites:parasiterubbledense:1)
Block(-5,67,1,DIRT:0)
Block(-5,67,2,DIRT:0)
Block(-5,67,3,DIRT:0)
Block(-5,67,4,DIRT:0)
Block(-5,67,5,DIRT:0)
Block(-5,67,6,DIRT:0)
Block(-5,67,7,DIRT:0)
Block(-5,67,8,DIRT:0)
Block(-5,68,-7,DIRT:0)
Block(-5,68,-6,DIRT:0)
Block(-5,68,-5,srparasites:parasiterubbledense:1)
Block(-5,68,-4,srparasites:parasiterubbledense:1)
Block(-5,68,-3,srparasites:parasiterubbledense:1)
Block(-5,68,-2,srparasites:parasiterubbledense:1)
Block(-5,68,-1,srparasites:parasiterubbledense:1)
Block(-5,68,0,DIRT:0)
Block(-5,68,1,DIRT:0)
Block(-5,68,2,DIRT:0)
Block(-5,68,3,DIRT:0)
Block(-5,68,4,DIRT:0)
Block(-5,68,5,DIRT:0)
Block(-5,68,6,DIRT:0)
Block(-5,68,7,DIRT:0)
Block(-5,68,8,DIRT:0)
Block(-5,69,-7,DIRT:0)
Block(-5,69,-6,DIRT:0)
Block(-5,69,-5,DIRT:0)
Block(-5,69,-4,DIRT:0)
Block(-5,69,-3,DIRT:0)
Block(-5,69,-2,DIRT:0)
Block(-5,69,-1,DIRT:0)
Block(-5,69,0,DIRT:0)
Block(-5,69,1,DIRT:0)
Block(-5,69,2,DIRT:0)
Block(-5,69,3,DIRT:0)
Block(-5,69,4,DIRT:0)
Block(-5,69,5,DIRT:0)
Block(-5,69,6,DIRT:0)
Block(-5,69,7,DIRT:0)
Block(-5,69,8,DIRT:0)
Block(-5,70,-7,DIRT:0)
Block(-5,70,-6,DIRT:0)
Block(-5,70,-5,DIRT:0)
Block(-5,70,-4,DIRT:0)
Block(-5,70,-3,DIRT:0)
Block(-5,70,-2,DIRT:0)
Block(-5,70,-1,DIRT:0)
Block(-5,70,0,DIRT:0)
Block(-5,70,1,DIRT:0)
Block(-5,70,2,DIRT:0)
Block(-5,70,3,DIRT:0)
Block(-5,70,4,DIRT:0)
Block(-5,70,5,DIRT:0)
Block(-5,70,6,DIRT:0)
Block(-5,70,7,DIRT:0)
Block(-5,70,8,DIRT:0)
Block(-5,71,-7,DIRT:0)
Block(-5,71,-6,DIRT:0)
Block(-5,71,-5,DIRT:0)
Block(-5,71,-4,DIRT:0)
Block(-5,71,-3,DIRT:0)
Block(-5,71,-2,DIRT:0)
Block(-5,71,-1,DIRT:0)
Block(-5,71,0,DIRT:0)
Block(-5,71,1,DIRT:0)
Block(-5,71,2,DIRT:0)
Block(-5,71,3,DIRT:0)
Block(-5,71,4,DIRT:0)
Block(-5,71,5,DIRT:0)
Block(-5,71,6,DIRT:0)
Block(-5,71,7,DIRT:0)
Block(-5,71,8,DIRT:0)
Block(-5,72,-7,srparasites:parasiterubble_slabhalf:0)
Block(-5,72,-6,DIRT:0)
Block(-5,72,-5,DIRT:0)
Block(-5,72,-4,DIRT:0)
Block(-5,72,-3,DIRT:0)
Block(-5,72,-2,DIRT:0)
Block(-5,72,-1,DIRT:0)
Block(-5,72,0,DIRT:0)
Block(-5,72,1,DIRT:0)
Block(-5,72,2,DIRT:0)
Block(-5,72,3,DIRT:0)
Block(-5,72,4,DIRT:0)
Block(-5,72,5,DIRT:0)
Block(-5,72,6,DIRT:0)
Block(-5,72,7,DIRT:0)
Block(-5,72,8,DIRT:0)
Block(-5,73,-7,SMOOTH_BRICK:1)
Block(-5,73,-6,srparasites:parasiterubble_slabhalf:0)
Block(-5,73,-5,DIRT:0)
Block(-5,73,-4,DIRT:0)
Block(-5,73,-3,DIRT:0)
Block(-5,73,-2,DIRT:0)
Block(-5,73,-1,DIRT:0)
Block(-5,73,0,DIRT:0)
Block(-5,73,1,DIRT:0)
Block(-5,73,2,DIRT:0)
Block(-5,73,3,DIRT:0)
Block(-5,73,4,DIRT:0)
Block(-5,73,5,DIRT:0)
Block(-5,73,6,DIRT:0)
Block(-5,73,7,DIRT:0)
Block(-5,73,8,DIRT:0)
Block(-5,74,-7,SMOOTH_BRICK:1)
Block(-5,74,-6,SMOOTH_BRICK:1)
Block(-5,74,-5,srparasites:parasiterubble_slabhalf:0)
Block(-5,74,-4,srparasites:parasiterubble_slabhalf:0)
Block(-5,74,-3,DIRT:0)
Block(-5,74,-2,DIRT:0)
Block(-5,74,-1,DIRT:0)
Block(-5,74,0,DIRT:0)
Block(-5,74,1,DIRT:0)
Block(-5,74,2,DIRT:0)
Block(-5,74,3,DIRT:0)
Block(-5,74,4,DIRT:0)
Block(-5,74,5,DIRT:0)
Block(-5,74,6,DIRT:0)
Block(-5,74,7,DIRT:0)
Block(-5,74,8,DIRT:0)
Block(-5,75,-7,AIR:0)
Block(-5,75,-6,SMOOTH_BRICK:2)
Block(-5,75,-5,SMOOTH_BRICK:1)
Block(-5,75,-4,SMOOTH_BRICK:1)
Block(-5,75,-3,srparasites:parasiterubble_slabhalf:0)
Block(-5,75,-2,srparasites:parasiterubble_slabhalf:0)
Block(-5,75,-1,srparasites:parasiterubble_slabhalf:0)
Block(-5,75,0,srparasites:parasiterubble_slabhalf:0)
Block(-5,75,1,srparasites:parasiterubble_slabhalf:0)
Block(-5,75,2,srparasites:parasiterubble_slabhalf:0)
Block(-5,75,3,srparasites:parasiterubble_slabhalf:0)
Block(-5,75,4,srparasites:parasiterubbledense:1)
Block(-5,75,5,srparasites:parasiterubbledense:1)
Block(-5,75,6,srparasites:parasiterubbledense:1)
Block(-5,75,7,DIRT:0)
Block(-5,75,8,DIRT:0)
Block(-5,76,-7,srparasites:parasiterubbledense:1)
Block(-5,76,-6,AIR:0)
Block(-5,76,-5,AIR:0)
Block(-5,76,-4,SMOOTH_BRICK:2)
Block(-5,76,-3,SMOOTH_BRICK:1)
Block(-5,76,-2,SMOOTH_BRICK:0)
Block(-5,76,-1,SMOOTH_BRICK:0)
Block(-5,76,0,SMOOTH_BRICK:0)
Block(-5,76,1,SMOOTH_BRICK:0)
Block(-5,76,2,SMOOTH_BRICK:0)
Block(-5,76,3,SMOOTH_BRICK:0)
Block(-5,76,4,srparasites:parasiterubbledense:1)
Block(-5,76,5,srparasites:parasiterubbledense:1)
Block(-5,76,6,srparasites:parasiterubbledense:1)
Block(-5,76,7,srparasites:parasiterubbledense:1)
Block(-5,76,8,srparasites:parasiterubbledense:1)
Block(-5,77,-7,BONE_BLOCK:0)
Block(-5,77,-6,AIR:0)
Block(-5,77,-5,AIR:0)
Block(-5,77,-4,AIR:0)
Block(-5,77,-3,AIR:0)
Block(-5,77,-2,AIR:0)
Block(-5,77,-1,AIR:0)
Block(-5,77,0,AIR:0)
Block(-5,77,1,AIR:0)
Block(-5,77,2,AIR:0)
Block(-5,77,3,AIR:0)
Block(-5,77,4,AIR:0)
Block(-5,77,5,srparasites:parasitebush)
Block(-5,77,6,AIR:0)
Block(-5,77,7,srparasites:parasiterubbledense:1)
Block(-5,77,8,srparasites:parasiterubbledense:1)
Block(-5,78,-7,srparasites:parasiterubbledense:1)
Block(-5,78,-6,AIR:0)
Block(-5,78,-5,AIR:0)
Block(-5,78,-4,AIR:0)
Block(-5,78,-3,AIR:0)
Block(-5,78,-2,AIR:0)
Block(-5,78,-1,AIR:0)
Block(-5,78,0,AIR:0)
Block(-5,78,1,AIR:0)
Block(-5,78,2,AIR:0)
Block(-5,78,3,AIR:0)
Block(-5,78,4,AIR:0)
Block(-5,78,5,srparasites:parasitebush)
Block(-5,78,6,AIR:0)
Block(-5,78,7,srparasites:infestedbush:3)
Block(-5,78,8,srparasites:parasiterubble_slabhalf:0)
Block(-5,79,-7,srparasites:parasitebush:4)
Block(-5,79,-6,AIR:0)
Block(-5,79,-5,AIR:0)
Block(-5,79,-4,AIR:0)
Block(-5,79,-3,AIR:0)
Block(-5,79,-2,AIR:0)
Block(-5,79,-1,AIR:0)
Block(-5,79,0,AIR:0)
Block(-5,79,1,AIR:0)
Block(-5,79,2,AIR:0)
Block(-5,79,3,AIR:0)
Block(-5,79,4,AIR:0)
Block(-5,79,5,AIR:0)
Block(-5,79,6,AIR:0)
Block(-5,79,7,srparasites:infestedbush:3)
Block(-5,79,8,AIR:0)
Block(-5,80,-7,AIR:0)
Block(-5,80,-6,AIR:0)
Block(-5,80,-5,AIR:0)
Block(-5,80,-4,AIR:0)
Block(-5,80,-3,AIR:0)
Block(-5,80,-2,AIR:0)
Block(-5,80,-1,AIR:0)
Block(-5,80,0,AIR:0)
Block(-5,80,1,AIR:0)
Block(-5,80,2,AIR:0)
Block(-5,80,3,AIR:0)
Block(-5,80,4,AIR:0)
Block(-5,80,5,AIR:0)
Block(-5,80,6,AIR:0)
Block(-5,80,7,AIR:0)
Block(-5,80,8,AIR:0)
Block(-5,81,-7,AIR:0)
Block(-5,81,-6,AIR:0)
Block(-5,81,-5,AIR:0)
Block(-5,81,-4,AIR:0)
Block(-5,81,-3,AIR:0)
Block(-5,81,-2,AIR:0)
Block(-5,81,-1,AIR:0)
Block(-5,81,0,AIR:0)
Block(-5,81,1,AIR:0)
Block(-5,81,2,AIR:0)
Block(-5,81,3,AIR:0)
Block(-5,81,4,AIR:0)
Block(-5,81,5,AIR:0)
Block(-5,81,6,AIR:0)
Block(-5,81,7,AIR:0)
Block(-5,81,8,AIR:0)
Block(-5,82,-7,AIR:0)
Block(-5,82,-6,AIR:0)
Block(-5,82,-5,AIR:0)
Block(-5,82,-4,AIR:0)
Block(-5,82,-3,AIR:0)
Block(-5,82,-2,AIR:0)
Block(-5,82,-1,AIR:0)
Block(-5,82,0,AIR:0)
Block(-5,82,1,AIR:0)
Block(-5,82,2,AIR:0)
Block(-5,82,3,AIR:0)
Block(-5,82,4,AIR:0)
Block(-5,82,5,AIR:0)
Block(-5,82,6,AIR:0)
Block(-5,82,7,AIR:0)
Block(-5,82,8,AIR:0)
Block(-5,83,-7,AIR:0)
Block(-5,83,-6,AIR:0)
Block(-5,83,-5,AIR:0)
Block(-5,83,-4,AIR:0)
Block(-5,83,-3,AIR:0)
Block(-5,83,-2,AIR:0)
Block(-5,83,-1,AIR:0)
Block(-5,83,0,AIR:0)
Block(-5,83,1,AIR:0)
Block(-5,83,2,AIR:0)
Block(-5,83,3,AIR:0)
Block(-5,83,4,AIR:0)
Block(-5,83,5,AIR:0)
Block(-5,83,6,AIR:0)
Block(-5,83,7,AIR:0)
Block(-5,83,8,AIR:0)
Block(-4,1,-7,srparasites:parasiterubbledense:1)
Block(-4,1,-6,srparasites:parasiterubbledense:1)
Block(-4,1,-5,srparasites:parasiterubbledense:1)
Block(-4,1,-4,srparasites:parasiterubbledense:1)
Block(-4,1,-3,srparasites:parasiterubbledense:1)
Block(-4,1,-2,srparasites:parasiterubbledense:1)
Block(-4,2,-7,srparasites:parasiterubbledense:1)
Block(-4,2,-6,srparasites:parasiterubbledense:1)
Block(-4,2,-5,srparasites:parasiterubbledense:1)
Block(-4,2,-4,srparasites:parasiterubbledense:1)
Block(-4,2,-3,srparasites:parasiterubbledense:1)
Block(-4,2,-2,srparasites:parasiterubbledense:1)
Block(-4,3,-7,srparasites:parasiterubbledense:1)
Block(-4,3,-6,srparasites:parasiterubbledense:1)
Block(-4,3,-5,srparasites:parasiterubbledense:1)
Block(-4,3,-4,srparasites:parasiterubbledense:1)
Block(-4,4,-7,srparasites:parasiterubbledense:1)
Block(-4,4,-6,srparasites:parasiterubbledense:1)
Block(-4,4,-5,srparasites:parasiterubbledense:1)
Block(-4,4,-4,srparasites:parasiterubbledense:1)
Block(-4,5,-7,srparasites:parasiterubbledense:1)
Block(-4,5,-6,srparasites:parasiterubbledense:1)
Block(-4,5,-5,srparasites:parasiterubbledense:1)
Block(-4,5,-4,srparasites:parasiterubbledense:1)
Block(-4,6,-7,srparasites:parasiterubbledense:1)
Block(-4,6,-6,srparasites:parasiterubbledense:1)
Block(-4,6,-5,srparasites:parasiterubbledense:1)
Block(-4,7,-7,srparasites:parasiterubbledense:1)
Block(-4,7,-6,srparasites:parasiterubbledense:1)
Block(-4,7,-5,srparasites:parasiterubbledense:1)
Block(-4,8,-7,srparasites:parasiterubbledense:1)
Block(-4,8,-6,srparasites:parasiterubbledense:1)
Block(-4,9,-7,srparasites:parasiterubbledense:1)
Block(-4,9,-6,srparasites:parasiterubbledense:1)
Block(-4,9,-5,srparasites:parasiterubbledense:1)
Block(-4,10,-7,srparasites:parasiterubbledense:1)
Block(-4,10,-6,srparasites:parasiterubbledense:1)
Block(-4,10,-5,srparasites:parasiterubbledense:1)
Block(-4,10,-4,srparasites:parasiterubbledense:1)
Block(-4,11,-7,srparasites:parasiterubbledense:1)
Block(-4,11,-6,srparasites:parasiterubbledense:1)
Block(-4,11,-5,srparasites:parasiterubbledense:1)
Block(-4,12,-7,srparasites:parasiterubbledense:1)
Block(-4,12,-6,srparasites:parasiterubbledense:1)
Block(-4,13,-7,srparasites:parasiterubbledense:1)
Block(-4,13,-6,srparasites:parasiterubbledense:1)
Block(-4,14,-7,srparasites:parasiterubbledense:1)
Block(-4,14,-6,srparasites:parasiterubbledense:1)
Block(-4,15,-7,srparasites:parasiterubbledense:1)
Block(-4,15,-6,srparasites:parasiterubbledense:1)
Block(-4,16,-7,srparasites:parasiterubbledense:1)
Block(-4,16,-6,srparasites:parasiterubbledense:1)
Block(-4,17,-7,srparasites:parasiterubbledense:1)
Block(-4,17,-6,srparasites:parasiterubbledense:1)
Block(-4,18,-7,srparasites:parasiterubbledense:1)
Block(-4,18,-6,srparasites:parasiterubbledense:1)
Block(-4,19,-7,srparasites:parasiterubbledense:1)
Block(-4,19,-6,srparasites:parasiterubbledense:1)
Block(-4,20,-7,srparasites:parasiterubbledense:1)
Block(-4,20,-6,srparasites:parasiterubbledense:1)
Block(-4,21,-7,srparasites:parasiterubbledense:1)
Block(-4,21,-6,srparasites:parasiterubbledense:1)
Block(-4,22,-7,srparasites:parasiterubbledense:1)
Block(-4,22,-6,srparasites:parasiterubbledense:1)
Block(-4,23,-7,srparasites:parasiterubbledense:1)
Block(-4,23,-6,srparasites:parasiterubbledense:1)
Block(-4,23,-5,srparasites:parasiterubbledense:1)
Block(-4,24,-7,srparasites:parasiterubbledense:1)
Block(-4,24,-6,srparasites:parasiterubbledense:1)
Block(-4,24,-5,srparasites:parasiterubbledense:1)
Block(-4,24,-4,srparasites:parasiterubbledense:1)
Block(-4,25,-7,srparasites:parasiterubbledense:1)
Block(-4,25,-6,srparasites:parasiterubbledense:1)
Block(-4,25,-5,srparasites:parasiterubbledense:1)
Block(-4,26,-7,srparasites:parasiterubbledense:1)
Block(-4,26,-6,srparasites:parasiterubbledense:1)
Block(-4,27,-7,srparasites:parasiterubbledense:1)
Block(-4,27,-6,srparasites:parasiterubbledense:1)
Block(-4,28,-7,srparasites:parasiterubbledense:1)
Block(-4,28,-6,srparasites:parasiterubbledense:1)
Block(-4,29,-7,srparasites:parasiterubbledense:1)
Block(-4,29,-6,srparasites:parasiterubbledense:1)
Block(-4,30,-7,srparasites:parasiterubbledense:1)
Block(-4,30,-6,srparasites:parasiterubbledense:1)
Block(-4,31,-7,srparasites:parasiterubbledense:1)
Block(-4,31,-6,srparasites:parasiterubbledense)
Block(-4,32,-7,srparasites:parasiterubbledense:1)
Block(-4,32,-6,srparasites:parasiterubbledense:1)
Block(-4,33,-7,srparasites:parasiterubbledense:1)
Block(-4,33,-6,srparasites:parasiterubbledense)
Block(-4,34,-7,srparasites:parasiterubbledense:1)
Block(-4,34,-6,srparasites:parasiterubbledense:1)
Block(-4,35,-7,srparasites:parasiterubbledense:1)
Block(-4,35,-6,srparasites:parasiterubbledense:1)
Block(-4,36,-7,srparasites:parasiterubbledense:1)
Block(-4,36,-6,srparasites:parasiterubbledense:1)
Block(-4,36,-5,AIR:0)
Block(-4,36,-4,srparasites:parasiterubbledense:1)
Block(-4,36,-3,srparasites:parasiterubbledense:1)
Block(-4,36,-2,srparasites:parasiterubbledense:1)
Block(-4,37,-7,srparasites:parasiterubbledense:1)
Block(-4,37,-6,srparasites:parasiterubbledense:1)
Block(-4,37,-5,srparasites:parasiterubbledense:1)
Block(-4,37,-4,srparasites:parasiterubbledense:1)
Block(-4,37,-3,srparasites:parasiterubbledense:1)
Block(-4,37,-2,srparasites:parasiterubbledense:1)
Block(-4,38,-7,srparasites:parasiterubbledense:1)
Block(-4,38,-6,srparasites:parasiterubbledense:1)
Block(-4,38,-5,AIR:0)
Block(-4,38,-4,srparasites:parasiterubbledense:1)
Block(-4,38,-3,srparasites:parasiterubbledense:1)
Block(-4,38,-2,srparasites:parasiterubbledense:1)
Block(-4,39,-7,srparasites:parasiterubbledense:1)
Block(-4,39,-6,srparasites:parasiterubbledense:1)
Block(-4,40,-7,srparasites:parasiterubbledense:1)
Block(-4,40,-6,srparasites:parasiterubbledense:1)
Block(-4,41,-7,srparasites:parasiterubbledense:1)
Block(-4,41,-6,srparasites:parasiterubbledense:1)
Block(-4,42,-7,srparasites:parasiterubbledense:1)
Block(-4,42,-6,srparasites:parasiterubbledense:1)
Block(-4,43,-7,srparasites:parasiterubbledense:1)
Block(-4,43,-6,srparasites:parasiterubbledense:1)
Block(-4,43,-5,AIR:0)
Block(-4,43,-4,srparasites:parasiterubbledense:1)
Block(-4,44,-7,srparasites:parasiterubbledense:1)
Block(-4,44,-6,srparasites:parasiterubbledense:1)
Block(-4,44,-5,srparasites:parasiterubbledense:1)
Block(-4,44,-4,srparasites:parasiterubbledense:1)
Block(-4,44,-3,srparasites:parasiterubbledense:1)
Block(-4,45,-7,srparasites:parasiterubbledense:1)
Block(-4,45,-6,srparasites:parasiterubbledense:1)
Block(-4,45,-5,srparasites:parasiterubbledense:1)
Block(-4,45,-4,srparasites:parasiterubbledense:1)
Block(-4,46,-7,srparasites:parasiterubbledense:1)
Block(-4,46,-6,srparasites:parasiterubbledense:1)
Block(-4,46,-5,srparasites:parasiterubbledense:1)
Block(-4,47,-7,srparasites:parasiterubbledense:1)
Block(-4,47,-6,srparasites:parasiterubbledense:1)
Block(-4,47,-5,srparasites:parasiterubbledense:1)
Block(-4,48,-7,srparasites:parasiterubbledense:1)
Block(-4,48,-6,srparasites:parasitebush)
Block(-4,49,-7,srparasites:parasiterubbledense:1)
Block(-4,49,-6,srparasites:parasiterubbledense:1)
Block(-4,50,-7,srparasites:parasiterubbledense:1)
Block(-4,50,-6,srparasites:parasiterubbledense:1)
Block(-4,51,-7,srparasites:parasiterubbledense:1)
Block(-4,51,-6,srparasites:parasiterubbledense:1)
Block(-4,52,-7,srparasites:parasiterubbledense:1)
Block(-4,52,-6,srparasites:parasiterubbledense:1)
Block(-4,53,-7,AIR:0)
Block(-4,53,-6,srparasites:parasiterubbledense:1)
Block(-4,53,-5,srparasites:parasiterubbledense:1)
Block(-4,54,-7,AIR:0)
Block(-4,54,-6,BONE_BLOCK:0)
Block(-4,54,-5,srparasites:parasiterubbledense:1)
Block(-4,54,-4,srparasites:parasiterubbledense:1)
Block(-4,55,-7,AIR:0)
Block(-4,55,-6,AIR:0)
Block(-4,55,-5,AIR:0)
Block(-4,55,-4,srparasites:parasiterubbledense:1)
Block(-4,56,-7,AIR:0)
Block(-4,56,-6,AIR:0)
Block(-4,56,-5,AIR:0)
Block(-4,56,-4,srparasites:parasiterubbledense:1)
Block(-4,57,-7,AIR:0)
Block(-4,57,-6,AIR:0)
Block(-4,57,-5,AIR:0)
Block(-4,57,-4,srparasites:parasiterubbledense:1)
Block(-4,57,-3,srparasites:parasiterubbledense:1)
Block(-4,58,-7,AIR:0)
Block(-4,58,-6,AIR:0)
Block(-4,58,-5,AIR:0)
Block(-4,58,-4,AIR:0)
Block(-4,58,-3,srparasites:parasiterubbledense:1)
Block(-4,59,-7,AIR:0)
Block(-4,59,-6,AIR:0)
Block(-4,59,-5,AIR:0)
Block(-4,59,-4,AIR:0)
Block(-4,59,-3,srparasites:parasiterubbledense:1)
Block(-4,60,-7,AIR:0)
Block(-4,60,-6,AIR:0)
Block(-4,60,-5,AIR:0)
Block(-4,60,-4,AIR:0)
Block(-4,60,-3,srparasites:parasiterubbledense:1)
Block(-4,61,-7,AIR:0)
Block(-4,61,-6,AIR:0)
Block(-4,61,-5,AIR:0)
Block(-4,61,-4,srparasites:parasiterubbledense:1)
Block(-4,61,-3,srparasites:parasiterubbledense:1)
Block(-4,61,-2,srparasites:parasiterubbledense:1)
Block(-4,62,-7,AIR:0)
Block(-4,62,-6,AIR:0)
Block(-4,62,-5,srparasites:parasiterubbledense:1)
Block(-4,62,-4,srparasites:parasiterubbledense:1)
Block(-4,62,-3,srparasites:parasiterubbledense:1)
Block(-4,62,-2,srparasites:parasiterubbledense:1)
Block(-4,62,-1,srparasites:parasiterubbledense:1)
Block(-4,62,0,srparasites:parasiterubbledense:1)
Block(-4,63,-7,AIR:0)
Block(-4,63,-6,AIR:0)
Block(-4,63,-5,srparasites:parasiterubbledense:1)
Block(-4,63,-4,srparasites:parasiterubbledense:1)
Block(-4,63,-3,srparasites:parasiterubbledense:1)
Block(-4,63,-2,srparasites:parasiterubbledense:1)
Block(-4,63,-1,srparasites:parasiterubbledense:1)
Block(-4,63,0,srparasites:parasiterubbledense:1)
Block(-4,63,1,srparasites:parasiterubbledense:1)
Block(-4,64,-7,AIR:0)
Block(-4,64,-6,srparasites:parasiterubbledense:1)
Block(-4,64,-5,srparasites:parasiterubbledense:1)
Block(-4,64,-4,AIR:0)
Block(-4,64,-3,SMOOTH_BRICK:1)
Block(-4,64,-2,SMOOTH_BRICK:1)
Block(-4,64,-1,srparasites:parasiterubbledense:1)
Block(-4,64,0,srparasites:parasiterubbledense:1)
Block(-4,64,1,srparasites:parasiterubbledense:1)
Block(-4,65,-7,AIR:0)
Block(-4,65,-6,AIR:0)
Block(-4,65,-5,srparasites:parasiterubbledense:1)
Block(-4,65,-4,AIR:0)
Block(-4,65,-3,AIR:0)
Block(-4,65,-2,AIR:0)
Block(-4,65,-1,AIR:0)
Block(-4,65,0,srparasites:parasiterubbledense:1)
Block(-4,65,1,srparasites:parasiterubbledense:1)
Block(-4,66,-7,srparasites:parasiterubbledense:1)
Block(-4,66,-6,srparasites:parasiterubbledense:1)
Block(-4,66,-5,srparasites:parasiterubbledense:1)
Block(-4,66,-4,srparasites:parasiterubbledense:1)
Block(-4,66,-3,AIR:0)
Block(-4,66,-2,AIR:0)
Block(-4,66,-1,srparasites:parasiterubbledense:1)
Block(-4,66,0,srparasites:parasiterubbledense:1)
Block(-4,66,1,srparasites:parasiterubbledense:1)
Block(-4,67,-7,DIRT:0)
Block(-4,67,-6,srparasites:parasiterubbledense:1)
Block(-4,67,-5,srparasites:parasiterubbledense:1)
Block(-4,67,-4,srparasites:parasiterubbledense:1)
Block(-4,67,-3,srparasites:parasiterubbledense:1)
Block(-4,67,-2,srparasites:parasiterubbledense:1)
Block(-4,67,-1,srparasites:parasiterubbledense:1)
Block(-4,67,0,srparasites:parasiterubbledense:1)
Block(-4,67,1,DIRT:0)
Block(-4,67,2,DIRT:0)
Block(-4,67,3,DIRT:0)
Block(-4,67,4,DIRT:0)
Block(-4,67,5,DIRT:0)
Block(-4,67,6,DIRT:0)
Block(-4,67,7,DIRT:0)
Block(-4,67,8,DIRT:0)
Block(-4,68,-7,DIRT:0)
Block(-4,68,-6,DIRT:0)
Block(-4,68,-5,srparasites:parasiterubbledense:1)
Block(-4,68,-4,srparasites:parasiterubbledense:1)
Block(-4,68,-3,srparasites:parasiterubbledense:1)
Block(-4,68,-2,srparasites:parasiterubbledense:1)
Block(-4,68,-1,srparasites:parasiterubbledense:1)
Block(-4,68,0,DIRT:0)
Block(-4,68,1,DIRT:0)
Block(-4,68,2,DIRT:0)
Block(-4,68,3,DIRT:0)
Block(-4,68,4,DIRT:0)
Block(-4,68,5,DIRT:0)
Block(-4,68,6,DIRT:0)
Block(-4,68,7,DIRT:0)
Block(-4,68,8,DIRT:0)
Block(-4,69,-7,DIRT:0)
Block(-4,69,-6,DIRT:0)
Block(-4,69,-5,DIRT:0)
Block(-4,69,-4,DIRT:0)
Block(-4,69,-3,DIRT:0)
Block(-4,69,-2,DIRT:0)
Block(-4,69,-1,DIRT:0)
Block(-4,69,0,DIRT:0)
Block(-4,69,1,DIRT:0)
Block(-4,69,2,DIRT:0)
Block(-4,69,3,DIRT:0)
Block(-4,69,4,DIRT:0)
Block(-4,69,5,DIRT:0)
Block(-4,69,6,DIRT:0)
Block(-4,69,7,DIRT:0)
Block(-4,69,8,DIRT:0)
Block(-4,70,-7,DIRT:0)
Block(-4,70,-6,DIRT:0)
Block(-4,70,-5,DIRT:0)
Block(-4,70,-4,DIRT:0)
Block(-4,70,-3,DIRT:0)
Block(-4,70,-2,DIRT:0)
Block(-4,70,-1,DIRT:0)
Block(-4,70,0,DIRT:0)
Block(-4,70,1,DIRT:0)
Block(-4,70,2,DIRT:0)
Block(-4,70,3,DIRT:0)
Block(-4,70,4,DIRT:0)
Block(-4,70,5,DIRT:0)
Block(-4,70,6,DIRT:0)
Block(-4,70,7,DIRT:0)
Block(-4,70,8,DIRT:0)
Block(-4,71,-7,srparasites:parasiterubble_slabhalf:0)
Block(-4,71,-6,DIRT:0)
Block(-4,71,-5,DIRT:0)
Block(-4,71,-4,DIRT:0)
Block(-4,71,-3,DIRT:0)
Block(-4,71,-2,DIRT:0)
Block(-4,71,-1,DIRT:0)
Block(-4,71,0,DIRT:0)
Block(-4,71,1,DIRT:0)
Block(-4,71,2,DIRT:0)
Block(-4,71,3,DIRT:0)
Block(-4,71,4,DIRT:0)
Block(-4,71,5,DIRT:0)
Block(-4,71,6,DIRT:0)
Block(-4,71,7,DIRT:0)
Block(-4,71,8,DIRT:0)
Block(-4,72,-7,SMOOTH_BRICK:1)
Block(-4,72,-6,srparasites:parasiterubble_slabhalf:0)
Block(-4,72,-5,DIRT:0)
Block(-4,72,-4,DIRT:0)
Block(-4,72,-3,DIRT:0)
Block(-4,72,-2,DIRT:0)
Block(-4,72,-1,DIRT:0)
Block(-4,72,0,DIRT:0)
Block(-4,72,1,DIRT:0)
Block(-4,72,2,DIRT:0)
Block(-4,72,3,DIRT:0)
Block(-4,72,4,DIRT:0)
Block(-4,72,5,DIRT:0)
Block(-4,72,6,DIRT:0)
Block(-4,72,7,DIRT:0)
Block(-4,72,8,DIRT:0)
Block(-4,73,-7,SMOOTH_BRICK:1)
Block(-4,73,-6,SMOOTH_BRICK:1)
Block(-4,73,-5,srparasites:parasiterubble_slabhalf:0)
Block(-4,73,-4,DIRT:0)
Block(-4,73,-3,DIRT:0)
Block(-4,73,-2,DIRT:0)
Block(-4,73,-1,DIRT:0)
Block(-4,73,0,DIRT:0)
Block(-4,73,1,DIRT:0)
Block(-4,73,2,DIRT:0)
Block(-4,73,3,DIRT:0)
Block(-4,73,4,DIRT:0)
Block(-4,73,5,DIRT:0)
Block(-4,73,6,DIRT:0)
Block(-4,73,7,DIRT:0)
Block(-4,73,8,DIRT:0)
Block(-4,74,-7,AIR:0)
Block(-4,74,-6,SMOOTH_BRICK:1)
Block(-4,74,-5,SMOOTH_BRICK:1)
Block(-4,74,-4,srparasites:parasiterubble_slabhalf:0)
Block(-4,74,-3,srparasites:parasiterubble_slabhalf:0)
Block(-4,74,-2,DIRT:0)
