
#######################################################################
# +-----------------------------------------------------------------+ #
# |                            BO4 object                           | #
# +-----------------------------------------------------------------+ #
#######################################################################

Author: NLBlackEagle

Description: No description given

SettingsMode: WriteWithoutComments


#######################################################################
# +-----------------------------------------------------------------+ #
# |                          Main settings                          | #
# +-----------------------------------------------------------------+ #
#######################################################################

FixedRotation: 

Frequency: 0

SpawnHeight: highestBlock

UseCenterForHighestBlock: true

##############################
# Height Limits for the BO4. #
##############################

MinHeight: 0

MaxHeight: 255

InheritBO3: 

InheritBO3Rotation: NORTH

OverrideChildSettings: true

OverrideParentHeight: false

CanOverride: true

BranchFrequency: 0

BranchFrequencyGroup: 

MustBeBelowOther: false

MustBeInside: 

CannotBeInside: 

ReplacesBO3: 

MustBeInsideWorldBorders: true

CanSpawnOnWater: true

SpawnOnWaterOnly: false

SpawnUnderWater: false

SpawnAtWaterLevel: false

HeightOffset: 0

RemoveAir: true

ReplaceAbove: 

ReplaceBelow: 

ReplaceWithBiomeBlocks: false

ReplaceWithSurfaceBlock: GRASS

ReplaceWithGroundBlock: DIRT

ReplaceWithStoneBlock: STONE

SmoothRadius: 0

SmoothHeightOffset: 0

SmoothStartTop: false

SmoothStartWood: false

SmoothingSurfaceBlock: 

SmoothingGroundBlock: 

BO3Group: 

IsSpawnPoint: false

DoReplaceBlocks: false


#######################################################################
# +-----------------------------------------------------------------+ #
# |                              Blocks                             | #
# +-----------------------------------------------------------------+ #
#######################################################################

Block(-8,11,-1,quark:limestone:1)
Block(-8,11,0,CONCRETE:8)
Block(-8,11,1,quark:limestone:1)
Block(-8,12,-1,CONCRETE:8)
Block(-8,12,0,CONCRETE:8)
Block(-8,12,1,CONCRETE:8)
Block(-8,13,-1,CONCRETE:8)
Block(-8,13,0,CONCRETE:8)
Block(-8,13,1,CONCRETE:8)
Block(-8,14,-1,CONCRETE:8)
Block(-8,14,0,CONCRETE:8)
Block(-8,14,1,CONCRETE:8)
Block(-8,15,-1,quark:limestone:1)
Block(-8,15,0,STAINED_CLAY:7)
Block(-8,15,1,CONCRETE:8)
Block(-8,16,-1,STAINED_CLAY:7)
Block(-8,16,0,quark:limestone:1)
Block(-8,16,1,STAINED_CLAY:7)
Block(-8,17,-1,STAINED_CLAY:7)
Block(-8,17,0,quark:limestone:1)
Block(-8,17,1,STAINED_CLAY:7)
Block(-8,18,-1,STAINED_CLAY:7)
Block(-8,18,0,STAINED_CLAY:7)
Block(-8,18,1,STAINED_CLAY:7)
Block(-8,19,-1,STAINED_CLAY:7)
Block(-8,19,0,STAINED_CLAY:7)
Block(-8,19,1,quark:limestone:1)
Block(-8,20,-1,CONCRETE:8)
Block(-8,20,0,CONCRETE:8)
Block(-8,20,1,CONCRETE:8)
Block(-8,21,-1,CONCRETE:8)
Block(-8,21,0,CONCRETE:8)
Block(-8,21,1,CONCRETE:8)
Block(-8,21,8,quark:iron_plate:1)
Block(-8,22,-1,CONCRETE:8)
Block(-8,22,0,CONCRETE:8)
Block(-8,22,1,CONCRETE:8)
Block(-8,23,-1,CONCRETE:8)
Block(-8,23,0,quark:limestone:1)
Block(-8,23,1,CONCRETE:8)
Block(-8,24,-1,quark:limestone:1)
Block(-8,24,0,CONCRETE:8)
Block(-8,24,1,CONCRETE:8)
Block(-8,25,-7,quark:iron_plate:1)
Block(-8,25,-1,STAINED_CLAY:7)
Block(-8,25,0,STAINED_CLAY:7)
Block(-8,25,1,CONCRETE:8)
Block(-8,26,-1,STAINED_CLAY:7)
Block(-8,26,0,quark:limestone:1)
Block(-8,26,1,quark:limestone:1)
Block(-8,27,-7,quark:iron_plate:1)
Block(-8,27,-1,STAINED_CLAY:7)
Block(-8,27,0,STAINED_CLAY:7)
Block(-8,27,1,CONCRETE:8)
Block(-8,28,-1,STAINED_CLAY:7)
Block(-8,28,0,STAINED_CLAY:7)
Block(-8,28,1,quark:limestone:1)
Block(-8,29,-1,STAINED_CLAY:7)
Block(-8,29,0,STAINED_CLAY:7)
Block(-8,29,1,quark:limestone:1)
Block(-8,30,-1,CONCRETE:8)
Block(-8,30,0,CONCRETE:8)
Block(-8,30,1,CONCRETE:8)
Block(-8,31,-1,CONCRETE:8)
Block(-8,31,0,CONCRETE:8)
Block(-8,31,1,quark:limestone:1)
Block(-8,31,8,quark:iron_plate:1)
Block(-8,32,-1,CONCRETE:8)
Block(-8,32,0,CONCRETE:8)
Block(-8,32,1,CONCRETE:8)
Block(-8,33,-7,quark:iron_plate:1)
Block(-8,33,-1,CONCRETE:8)
Block(-8,33,0,CONCRETE:8)
Block(-8,33,1,CONCRETE:8)
Block(-8,33,8,quark:iron_plate:1)
Block(-8,34,-7,quark:iron_plate:1)
Block(-8,34,-1,CONCRETE:8)
Block(-8,34,0,CONCRETE:8)
Block(-8,34,1,CONCRETE:8)
Block(-8,34,8,quark:iron_plate:1)
Block(-8,35,-7,IRON_FENCE:0)
Block(-8,35,-6,IRON_FENCE:0)
Block(-8,35,-5,IRON_FENCE:0)
Block(-8,35,-4,IRON_FENCE:0)
Block(-8,35,-3,IRON_FENCE:0)
Block(-8,35,-2,IRON_FENCE:0)
Block(-8,35,-1,quark:limestone:1)
Block(-8,35,0,CONCRETE:8)
Block(-8,35,1,STAINED_CLAY:7)
Block(-8,35,2,IRON_FENCE:0)
Block(-8,35,3,IRON_FENCE:0)
Block(-8,35,4,IRON_FENCE:0)
Block(-8,35,5,IRON_FENCE:0)
Block(-8,35,7,IRON_FENCE:0)
Block(-8,35,8,IRON_FENCE:0)
Block(-8,36,-1,quark:limestone:1)
Block(-8,36,0,CONCRETE:8)
Block(-8,36,1,CONCRETE:8)
Block(-8,37,-1,CONCRETE:8)
Block(-8,37,0,quark:limestone:1)
Block(-8,37,1,CONCRETE:8)
Block(-8,38,-1,CONCRETE:8)
Block(-8,38,0,CONCRETE:8)
Block(-8,38,1,STAINED_CLAY:7)
Block(-8,39,-1,CONCRETE:8)
Block(-8,39,0,CONCRETE:8)
Block(-8,39,1,STAINED_CLAY:7)
Block(-8,39,8,quark:iron_plate:1)
Block(-8,40,-1,CONCRETE:8)
Block(-8,40,0,STAINED_CLAY:7)
Block(-8,40,1,STAINED_CLAY:7)
Block(-8,41,-1,STAINED_CLAY:7)
Block(-8,41,0,STAINED_CLAY:7)
Block(-8,41,1,STAINED_CLAY:7)
Block(-8,42,-2,STAINED_CLAY:7)
Block(-8,42,-1,STAINED_CLAY:7)
Block(-8,42,0,STAINED_CLAY:7)
Block(-8,42,1,STAINED_CLAY:7)
Block(-8,42,2,STAINED_CLAY:7)
Block(-8,43,-4,STAINED_CLAY:7)
Block(-8,43,-3,STAINED_CLAY:7)
Block(-8,43,-2,STATIONARY_WATER:0)
Block(-8,43,-1,quark:limestone)
Block(-8,43,0,quark:limestone)
Block(-8,43,1,STATIONARY_WATER:0)
Block(-8,43,2,STATIONARY_WATER:0)
Block(-8,43,3,STAINED_CLAY:7)
Block(-8,43,4,STAINED_CLAY:7)
Block(-8,44,-4,STAINED_CLAY:7)
Block(-8,44,4,STAINED_CLAY:7)
Block(-8,45,-7,quark:iron_plate:1)
Block(-8,45,-5,STAINED_CLAY:7)
Block(-8,45,5,STAINED_CLAY:7)
Block(-8,46,-7,quark:iron_plate:1)
Block(-8,46,-5,STAINED_CLAY:7)
Block(-8,46,5,STAINED_CLAY:7)
Block(-8,47,-7,quark:iron_plate:1)
Block(-8,47,-5,STONE:6)
Block(-8,47,5,STONE:6)
Block(-8,47,8,quark:iron_plate:1)
Block(-8,48,-5,STAINED_CLAY:7)
Block(-8,48,5,STAINED_CLAY:7)
Block(-8,49,-5,STAINED_CLAY:7)
Block(-8,49,5,STAINED_CLAY:7)
Block(-8,50,-4,STAINED_CLAY:7)
Block(-8,50,4,STAINED_CLAY:7)
Block(-8,51,-4,STAINED_CLAY:7)
Block(-8,51,-3,STAINED_CLAY:7)
Block(-8,51,-2,STAINED_CLAY:7)
Block(-8,51,3,STAINED_CLAY:7)
Block(-8,51,4,STAINED_CLAY:7)
Block(-8,52,-2,STAINED_CLAY:7)
Block(-8,52,-1,STAINED_CLAY:7)
Block(-8,52,0,STAINED_CLAY:7)
Block(-8,52,1,STAINED_CLAY:7)
Block(-8,52,2,STAINED_CLAY:7)
Block(-7,24,-6,quark:iron_plate:1)
Block(-7,28,-6,quark:iron_plate:1)
Block(-7,30,-7,DOUBLE_STEP:5)
Block(-7,31,-7,STEP:5)
Block(-7,33,-6,quark:iron_plate:1)
Block(-7,34,-6,quark:iron_plate:1)
Block(-7,35,-7,IRON_FENCE:0)
Block(-7,35,-6,IRON_FENCE:0)
Block(-7,35,-5,IRON_FENCE:0)
Block(-7,35,-4,IRON_FENCE:0)
Block(-7,35,-3,IRON_FENCE:0)
Block(-7,35,-2,IRON_FENCE:0)
Block(-7,35,-1,IRON_FENCE:0)
Block(-7,35,0,IRON_FENCE:0)
Block(-7,35,2,IRON_FENCE:0)
Block(-7,35,3,IRON_FENCE:0)
Block(-7,35,4,IRON_FENCE:0)
Block(-7,35,5,IRON_FENCE:0)
Block(-7,35,6,IRON_FENCE:0)
Block(-7,35,7,IRON_FENCE:0)
Block(-7,35,8,IRON_FENCE:0)
Block(-7,42,-1,STAINED_CLAY:7)
Block(-7,42,0,STAINED_CLAY:7)
Block(-7,42,1,STAINED_CLAY:7)
Block(-7,43,-3,STAINED_CLAY:7)
Block(-7,43,-2,STAINED_CLAY:7)
Block(-7,43,-1,STATIONARY_WATER:0)
Block(-7,43,0,STATIONARY_WATER:0)
Block(-7,43,1,quark:limestone)
Block(-7,43,2,STAINED_CLAY:7)
Block(-7,43,3,STAINED_CLAY:7)
Block(-7,44,-6,quark:iron_plate:1)
Block(-7,44,-4,STAINED_CLAY:7)
Block(-7,44,-3,STAINED_CLAY:7)
Block(-7,44,3,STAINED_CLAY:7)
Block(-7,44,4,STAINED_CLAY:7)
Block(-7,45,-4,STAINED_CLAY:7)
Block(-7,45,4,STAINED_CLAY:7)
Block(-7,46,-5,STAINED_CLAY:7)
Block(-7,46,5,STAINED_CLAY:7)
Block(-7,47,-6,quark:iron_plate:1)
Block(-7,47,-5,STONE:6)
Block(-7,47,5,STONE:6)
Block(-7,48,-5,STAINED_CLAY:7)
Block(-7,48,5,STAINED_CLAY:7)
Block(-7,49,-4,STAINED_CLAY:7)
Block(-7,49,4,STAINED_CLAY:7)
Block(-7,50,-4,STAINED_CLAY:7)
Block(-7,50,-3,STAINED_CLAY:7)
Block(-7,50,3,STAINED_CLAY:7)
Block(-7,50,4,STAINED_CLAY:7)
Block(-7,51,-3,STAINED_CLAY:7)
Block(-7,51,-2,STAINED_CLAY:7)
Block(-7,51,2,STAINED_CLAY:7)
Block(-7,51,3,STAINED_CLAY:7)
Block(-7,52,-1,STAINED_CLAY:7)
Block(-7,52,0,STAINED_CLAY:7)
Block(-7,52,1,STAINED_CLAY:7)
Block(-6,19,8,quark:iron_plate:1)
Block(-6,20,7,quark:iron_plate:1)
Block(-6,23,-6,quark:iron_plate:1)
Block(-6,29,-7,STEP:13)
Block(-6,29,-6,quark:iron_plate:1)
Block(-6,30,-7,DOUBLE_STEP:5)
Block(-6,32,7,quark:iron_plate:1)
Block(-6,33,-6,quark:iron_plate:1)
Block(-6,33,8,quark:iron_plate:1)
Block(-6,34,-6,quark:iron_plate:1)
Block(-6,34,8,quark:iron_plate:1)
Block(-6,35,-7,IRON_FENCE:0)
Block(-6,35,-5,IRON_FENCE:0)
Block(-6,35,-4,IRON_FENCE:0)
Block(-6,35,-3,IRON_FENCE:0)
Block(-6,35,-2,IRON_FENCE:0)
Block(-6,35,-1,IRON_FENCE:0)
Block(-6,35,0,IRON_FENCE:0)
Block(-6,35,1,IRON_FENCE:0)
Block(-6,35,2,IRON_FENCE:0)
Block(-6,35,3,IRON_FENCE:0)
Block(-6,35,4,IRON_FENCE:0)
Block(-6,35,5,IRON_FENCE:0)
Block(-6,35,7,IRON_FENCE:0)
Block(-6,35,8,IRON_FENCE:0)
Block(-6,37,8,quark:iron_plate:1)
Block(-6,38,8,quark:iron_plate:1)
Block(-6,42,-6,quark:iron_plate:1)
Block(-6,43,-6,quark:iron_plate:1)
Block(-6,43,-1,STAINED_CLAY:7)
Block(-6,43,0,STAINED_CLAY:7)
Block(-6,43,1,STAINED_CLAY:7)
Block(-6,44,-2,STAINED_CLAY:7)
Block(-6,44,-1,STAINED_CLAY:7)
Block(-6,44,0,STAINED_CLAY:7)
Block(-6,44,1,STAINED_CLAY:7)
Block(-6,44,2,STAINED_CLAY:7)
Block(-6,45,-3,STAINED_CLAY:7)
Block(-6,45,-2,STAINED_CLAY:7)
Block(-6,45,2,STAINED_CLAY:7)
Block(-6,45,3,STAINED_CLAY:7)
Block(-6,46,-4,STAINED_CLAY:7)
Block(-6,46,-3,STAINED_CLAY:7)
Block(-6,46,3,STAINED_CLAY:7)
Block(-6,46,4,STAINED_CLAY:7)
Block(-6,47,-6,quark:iron_plate:1)
Block(-6,47,-4,STONE:6)
Block(-6,47,-3,STONE:6)
Block(-6,47,3,STONE:6)
Block(-6,47,4,STONE:6)
Block(-6,47,8,quark:iron_plate:1)
Block(-6,48,-4,STAINED_CLAY:7)
Block(-6,48,-3,STAINED_CLAY:7)
Block(-6,48,3,STAINED_CLAY:7)
Block(-6,48,4,STAINED_CLAY:7)
Block(-6,49,-3,STAINED_CLAY:7)
Block(-6,49,-2,STAINED_CLAY:7)
Block(-6,49,2,STAINED_CLAY:7)
Block(-6,49,3,STAINED_CLAY:7)
Block(-6,50,-2,STAINED_CLAY:7)
Block(-6,50,-1,STAINED_CLAY:7)
Block(-6,50,0,STAINED_CLAY:7)
Block(-6,50,1,STAINED_CLAY:7)
Block(-6,50,2,STAINED_CLAY:7)
Block(-6,51,-1,STAINED_CLAY:7)
Block(-6,51,0,STAINED_CLAY:7)
Block(-6,51,1,STAINED_CLAY:7)
Block(-5,21,7,quark:iron_plate:1)
Block(-5,22,-6,quark:iron_plate:1)
Block(-5,22,6,quark:iron_plate:1)
Block(-5,23,5,quark:iron_plate:1)
Block(-5,24,4,quark:iron_plate:1)
Block(-5,28,4,quark:iron_plate:1)
Block(-5,29,-7,DOUBLE_STEP:5)
Block(-5,29,5,quark:iron_plate:1)
Block(-5,30,-7,STEP:5)
Block(-5,30,-6,quark:iron_plate:1)
Block(-5,30,6,quark:iron_plate:1)
Block(-5,31,7,quark:iron_plate:1)
Block(-5,33,-6,quark:iron_plate:1)
Block(-5,33,4,quark:iron_plate:1)
Block(-5,33,5,quark:iron_plate:1)
Block(-5,33,6,quark:iron_plate:1)
Block(-5,33,7,quark:iron_plate:1)
Block(-5,34,-6,quark:iron_plate:1)
Block(-5,34,4,quark:iron_plate:1)
Block(-5,34,5,quark:iron_plate:1)
Block(-5,34,6,quark:iron_plate:1)
Block(-5,34,7,quark:iron_plate:1)
Block(-5,35,-6,IRON_FENCE:0)
Block(-5,35,-5,IRON_FENCE:0)
Block(-5,35,-4,IRON_FENCE:0)
Block(-5,35,-3,IRON_FENCE:0)
Block(-5,35,-2,IRON_FENCE:0)
Block(-5,35,-1,IRON_FENCE:0)
Block(-5,35,0,IRON_FENCE:0)
Block(-5,35,1,IRON_FENCE:0)
Block(-5,35,4,IRON_FENCE:0)
Block(-5,35,6,IRON_FENCE:0)
Block(-5,35,7,IRON_FENCE:0)
Block(-5,35,8,IRON_FENCE:0)
Block(-5,39,7,quark:iron_plate:1)
Block(-5,40,-6,quark:iron_plate:1)
Block(-5,40,6,quark:iron_plate:1)
Block(-5,41,-6,quark:iron_plate:1)
Block(-5,41,6,quark:iron_plate:1)
Block(-5,42,5,quark:iron_plate:1)
Block(-5,43,5,quark:iron_plate:1)
Block(-5,44,4,quark:iron_plate:1)
Block(-5,45,-1,STAINED_CLAY:7)
Block(-5,45,0,STAINED_CLAY:7)
Block(-5,45,1,STAINED_CLAY:7)
Block(-5,46,-2,STAINED_CLAY:7)
Block(-5,46,-1,STAINED_CLAY:7)
Block(-5,46,0,STAINED_CLAY:7)
Block(-5,46,1,STAINED_CLAY:7)
Block(-5,46,2,STAINED_CLAY:7)
Block(-5,47,-6,quark:iron_plate:1)
Block(-5,47,-2,STONE:6)
Block(-5,47,-1,STONE:6)
Block(-5,47,0,STONE:6)
Block(-5,47,1,STONE:6)
Block(-5,47,2,STONE:6)
Block(-5,47,4,quark:iron_plate:1)
Block(-5,47,5,quark:iron_plate:1)
Block(-5,47,6,quark:iron_plate:1)
Block(-5,47,7,quark:iron_plate:1)
Block(-5,48,-2,STAINED_CLAY:7)
Block(-5,48,-1,STAINED_CLAY:7)
Block(-5,48,0,STAINED_CLAY:7)
Block(-5,48,1,STAINED_CLAY:7)
Block(-5,48,2,STAINED_CLAY:7)
Block(-5,49,-1,STAINED_CLAY:7)
Block(-5,49,0,STAINED_CLAY:7)
Block(-5,49,1,STAINED_CLAY:7)
Block(-4,20,-5,quark:iron_plate:1)
Block(-4,21,-6,quark:iron_plate:1)
Block(-4,25,1,quark:iron_plate:1)
Block(-4,25,3,quark:iron_plate:1)
Block(-4,26,2,quark:iron_plate:1)
Block(-4,27,1,quark:iron_plate:1)
Block(-4,27,3,quark:iron_plate:1)
Block(-4,28,-7,STEP:13)
Block(-4,29,-7,DOUBLE_STEP:5)
Block(-4,31,-6,quark:iron_plate:1)
Block(-4,32,-5,quark:iron_plate:1)
Block(-4,33,-6,quark:iron_plate:1)
Block(-4,33,1,quark:iron_plate:1)
Block(-4,33,2,quark:iron_plate:1)
Block(-4,33,3,quark:iron_plate:1)
Block(-4,34,-6,quark:iron_plate:1)
Block(-4,34,1,quark:iron_plate:1)
Block(-4,34,2,quark:iron_plate:1)
Block(-4,34,3,quark:iron_plate:1)
Block(-4,35,-7,IRON_FENCE:0)
Block(-4,35,-6,IRON_FENCE:0)
Block(-4,35,-5,IRON_FENCE:0)
Block(-4,35,-3,IRON_FENCE:0)
Block(-4,35,-2,IRON_FENCE:0)
Block(-4,35,-1,IRON_FENCE:0)
Block(-4,35,1,IRON_FENCE:0)
Block(-4,35,2,IRON_FENCE:0)
Block(-4,35,3,IRON_FENCE:0)
Block(-4,35,6,IRON_FENCE:0)
Block(-4,35,8,quark:iron_plate:1)
Block(-4,39,-6,quark:iron_plate:1)
Block(-4,45,1,quark:iron_plate:1)
Block(-4,45,3,quark:iron_plate:1)
Block(-4,46,1,quark:iron_plate:1)
Block(-4,46,3,quark:iron_plate:1)
Block(-4,47,-6,quark:iron_plate:1)
Block(-4,47,1,quark:iron_plate:1)
Block(-4,47,2,quark:iron_plate:1)
Block(-4,47,3,quark:iron_plate:1)
Block(-3,19,-5,quark:iron_plate:1)
Block(-3,21,-3,quark:iron_plate:1)
Block(-3,22,-2,quark:iron_plate:1)
Block(-3,23,-1,quark:iron_plate:1)
Block(-3,24,0,quark:iron_plate:1)
Block(-3,27,-7,STEP:13)
Block(-3,28,-6,DOUBLE_STEP:5)
Block(-3,28,0,quark:iron_plate:1)
Block(-3,29,-6,STEP:5)
Block(-3,29,-1,quark:iron_plate:1)
Block(-3,30,-2,quark:iron_plate:1)
Block(-3,31,-3,quark:iron_plate:1)
Block(-3,33,-5,quark:iron_plate:1)
Block(-3,33,-3,quark:iron_plate:1)
Block(-3,33,-2,quark:iron_plate:1)
Block(-3,33,-1,quark:iron_plate:1)
Block(-3,33,0,quark:iron_plate:1)
Block(-3,34,-5,quark:iron_plate:1)
Block(-3,34,-3,quark:iron_plate:1)
Block(-3,34,-2,quark:iron_plate:1)
Block(-3,34,-1,quark:iron_plate:1)
Block(-3,34,0,quark:iron_plate:1)
Block(-3,35,-7,quark:iron_plate:1)
Block(-3,35,-6,IRON_FENCE:0)
Block(-3,35,-5,IRON_FENCE:0)
Block(-3,35,-4,IRON_FENCE:0)
Block(-3,35,-3,IRON_FENCE:0)
Block(-3,35,-2,IRON_FENCE:0)
Block(-3,35,-1,IRON_FENCE:0)
Block(-3,35,0,IRON_FENCE:0)
Block(-3,35,2,IRON_FENCE:0)
Block(-3,35,3,IRON_FENCE:0)
Block(-3,35,4,IRON_FENCE:0)
Block(-3,35,5,IRON_FENCE:0)
Block(-3,35,6,IRON_FENCE:0)
Block(-3,35,7,quark:iron_plate:1)
Block(-3,35,8,quark:iron_plate:1)
Block(-3,37,-5,quark:iron_plate:1)
Block(-3,38,-5,quark:iron_plate:1)
Block(-3,39,-3,quark:iron_plate:1)
Block(-3,40,-2,quark:iron_plate:1)
Block(-3,41,-2,quark:iron_plate:1)
Block(-3,42,-1,quark:iron_plate:1)
Block(-3,43,-1,quark:iron_plate:1)
Block(-3,44,0,quark:iron_plate:1)
Block(-3,47,-5,quark:iron_plate:1)
Block(-3,47,-3,quark:iron_plate:1)
Block(-3,47,-2,quark:iron_plate:1)
Block(-3,47,-1,quark:iron_plate:1)
Block(-3,47,0,quark:iron_plate:1)
Block(-2,11,-5,quark:iron_plate:1)
Block(-2,12,-5,quark:iron_plate:1)
Block(-2,13,-5,quark:iron_plate:1)
Block(-2,14,-5,quark:iron_plate:1)
Block(-2,15,-5,quark:iron_plate:1)
Block(-2,16,-5,quark:iron_plate:1)
Block(-2,17,-5,quark:iron_plate:1)
Block(-2,18,-5,quark:iron_plate:1)
Block(-2,19,-5,quark:iron_plate:1)
Block(-2,19,-4,quark:iron_plate:1)
Block(-2,20,-5,quark:iron_plate:1)
Block(-2,20,-3,quark:iron_plate:1)
Block(-2,21,-5,quark:iron_plate:1)
Block(-2,22,-5,quark:iron_plate:1)
Block(-2,23,-5,quark:iron_plate:1)
Block(-2,24,-5,quark:iron_plate:1)
Block(-2,25,-6,quark:iron_plate:1)
Block(-2,25,-5,quark:iron_plate:1)
Block(-2,26,-6,quark:iron_plate:1)
Block(-2,26,-5,quark:iron_plate:1)
Block(-2,27,-6,STEP:13)
Block(-2,27,-5,quark:iron_plate:1)
Block(-2,28,-6,DOUBLE_STEP:5)
Block(-2,28,-5,quark:iron_plate:1)
Block(-2,29,-5,quark:iron_plate:1)
Block(-2,30,-5,quark:iron_plate:1)
Block(-2,31,-5,quark:iron_plate:1)
Block(-2,32,-5,quark:iron_plate:1)
Block(-2,32,-3,quark:iron_plate:1)
Block(-2,33,-6,quark:iron_plate:1)
Block(-2,33,-5,quark:iron_plate:1)
Block(-2,33,-4,quark:iron_plate:1)
Block(-2,34,-6,quark:iron_plate:1)
Block(-2,34,-5,quark:iron_plate:1)
Block(-2,34,-4,quark:iron_plate:1)
Block(-2,35,-7,quark:iron_plate:1)
Block(-2,35,-6,quark:iron_plate:1)
Block(-2,35,-5,IRON_FENCE:0)
Block(-2,35,-4,IRON_FENCE:0)
Block(-2,35,-3,IRON_FENCE:0)
Block(-2,35,-2,IRON_FENCE:0)
Block(-2,35,-1,IRON_FENCE:0)
Block(-2,35,0,IRON_FENCE:0)
Block(-2,35,2,IRON_FENCE:0)
Block(-2,35,3,IRON_FENCE:0)
Block(-2,35,4,IRON_FENCE:0)
Block(-2,35,5,IRON_FENCE:0)
Block(-2,35,6,quark:iron_plate:1)
Block(-2,35,7,quark:iron_plate:1)
Block(-2,36,-5,quark:iron_plate:1)
Block(-2,37,-5,quark:iron_plate:1)
Block(-2,37,-4,quark:iron_plate:1)
Block(-2,38,-5,quark:iron_plate:1)
Block(-2,38,-4,quark:iron_plate:1)
Block(-2,39,-5,quark:iron_plate:1)
Block(-2,40,-5,quark:iron_plate:1)
Block(-2,41,-5,quark:iron_plate:1)
Block(-2,42,-5,quark:iron_plate:1)
Block(-2,43,-5,quark:iron_plate:1)
Block(-2,44,-5,quark:iron_plate:1)
Block(-2,45,-5,quark:iron_plate:1)
Block(-2,46,-5,quark:iron_plate:1)
Block(-2,47,-5,quark:iron_plate:1)
Block(-2,47,-4,quark:iron_plate:1)
Block(-1,25,-7,quark:iron_plate:1)
Block(-1,25,-5,quark:iron_plate:1)
Block(-1,26,-7,quark:iron_plate:1)
Block(-1,26,-6,IRON_FENCE:0)
Block(-1,26,-5,quark:iron_plate:1)
Block(-1,27,-6,DOUBLE_STEP:5)
Block(-1,28,-6,STEP:5)
Block(-1,33,-7,quark:iron_plate:1)
Block(-1,33,-5,quark:iron_plate:1)
Block(-1,34,-7,quark:iron_plate:1)
Block(-1,34,-5,quark:iron_plate:1)
Block(-1,35,-5,quark:iron_plate:1)
Block(-1,35,-4,quark:iron_plate:1)
Block(-1,35,-3,IRON_FENCE:0)
Block(-1,35,-2,IRON_FENCE:0)
Block(-1,35,0,IRON_FENCE:0)
Block(-1,35,1,IRON_FENCE:0)
Block(-1,35,2,IRON_FENCE:0)
Block(-1,35,3,IRON_FENCE:0)
Block(-1,35,4,quark:iron_plate:1)
Block(-1,35,5,quark:iron_plate:1)
Block(0,25,-4,quark:iron_plate:1)
Block(0,26,-7,IRON_FENCE:0)
Block(0,26,-6,IRON_FENCE:0)
Block(0,26,-5,IRON_FENCE:0)
Block(0,26,-4,quark:iron_plate:1)
Block(0,33,-4,quark:iron_plate:1)
Block(0,34,-4,quark:iron_plate:1)
Block(0,35,-3,quark:iron_plate:1)
Block(0,35,-2,quark:iron_plate:1)
Block(0,35,-1,quark:iron_plate:1)
Block(0,35,0,quark:iron_plate:1)
Block(0,35,1,quark:iron_plate:1)
Block(0,35,2,quark:iron_plate:1)
Block(0,35,3,quark:iron_plate:1)
Block(1,25,-4,quark:iron_plate:1)
Block(1,26,-6,IRON_FENCE:0)
Block(1,26,-5,IRON_FENCE:0)
Block(1,26,-4,quark:iron_plate:1)
Block(1,33,-4,quark:iron_plate:1)
Block(1,34,-4,quark:iron_plate:1)
Block(2,25,-4,quark:iron_plate:1)
Block(2,25,6,quark:iron_plate:1)
Block(2,25,7,quark:iron_plate:1)
Block(2,25,8,quark:iron_plate:1)
Block(2,26,-7,IRON_FENCE:0)
Block(2,26,-6,IRON_FENCE:0)
Block(2,26,-5,IRON_FENCE:0)
Block(2,26,-4,quark:iron_plate:1)
Block(2,26,6,quark:iron_plate:1)
Block(2,26,7,quark:iron_plate:1)
Block(2,26,8,quark:iron_plate:1)
Block(2,33,-4,quark:iron_plate:1)
Block(2,34,-4,quark:iron_plate:1)
Block(3,25,-4,quark:iron_plate:1)
Block(3,25,3,quark:iron_plate:1)
Block(3,25,4,quark:iron_plate:1)
Block(3,25,5,quark:iron_plate:1)
Block(3,26,-6,IRON_FENCE:0)
Block(3,26,-5,IRON_FENCE:0)
Block(3,26,-4,quark:iron_plate:1)
Block(3,26,3,quark:iron_plate:1)
Block(3,26,4,quark:iron_plate:1)
Block(3,26,5,quark:iron_plate:1)
Block(3,33,-4,quark:iron_plate:1)
Block(3,34,-4,quark:iron_plate:1)
Block(4,25,-3,quark:iron_plate:1)
Block(4,25,-1,quark:iron_plate:1)
Block(4,25,0,quark:iron_plate:1)
Block(4,25,1,quark:iron_plate:1)
Block(4,25,2,quark:iron_plate:1)
Block(4,26,-7,IRON_FENCE:0)
Block(4,26,-6,IRON_FENCE:0)
Block(4,26,-5,IRON_FENCE:0)
Block(4,26,-4,IRON_FENCE:0)
Block(4,26,-3,quark:iron_plate:1)
Block(4,26,-1,quark:iron_plate:1)
Block(4,26,0,quark:iron_plate:1)
Block(4,26,1,quark:iron_plate:1)
Block(4,26,2,quark:iron_plate:1)
Block(4,33,-3,quark:iron_plate:1)
Block(4,34,-3,quark:iron_plate:1)
Block(5,11,-3,quark:iron_plate:1)
Block(5,12,-3,quark:iron_plate:1)
Block(5,13,-3,quark:iron_plate:1)
Block(5,14,-3,quark:iron_plate:1)
Block(5,15,-3,quark:iron_plate:1)
Block(5,16,-3,quark:iron_plate:1)
Block(5,17,-3,quark:iron_plate:1)
Block(5,18,-3,quark:iron_plate:1)
Block(5,19,-3,quark:iron_plate:1)
Block(5,20,-3,quark:iron_plate:1)
Block(5,21,-3,quark:iron_plate:1)
Block(5,22,-3,quark:iron_plate:1)
Block(5,23,-3,quark:iron_plate:1)
Block(5,24,-3,quark:iron_plate:1)
Block(5,25,-4,quark:iron_plate:1)
Block(5,25,-3,quark:iron_plate:1)
Block(5,25,-2,quark:iron_plate:1)
Block(5,26,-7,IRON_FENCE:0)
Block(5,26,-6,IRON_FENCE:0)
Block(5,26,-5,IRON_FENCE:0)
Block(5,26,-4,quark:iron_plate:1)
Block(5,26,-3,quark:iron_plate:1)
Block(5,26,-2,quark:iron_plate:1)
Block(5,27,-3,quark:iron_plate:1)
Block(5,28,-3,quark:iron_plate:1)
Block(5,29,-3,quark:iron_plate:1)
Block(5,30,-3,quark:iron_plate:1)
Block(5,31,-3,quark:iron_plate:1)
Block(5,32,-3,quark:iron_plate:1)
Block(5,33,-4,quark:iron_plate:1)
Block(5,33,-3,quark:iron_plate:1)
Block(5,34,-4,quark:iron_plate:1)
Block(5,34,-3,quark:iron_plate:1)
Block(6,25,-7,quark:iron_plate:1)
Block(6,25,-6,quark:iron_plate:1)
Block(6,25,-5,quark:iron_plate:1)
Block(6,26,-7,quark:iron_plate:1)
Block(6,26,-6,quark:iron_plate:1)
Block(6,26,-5,quark:iron_plate:1)
Block(6,33,-7,quark:iron_plate:1)
Block(6,33,-6,quark:iron_plate:1)
Block(6,33,-5,quark:iron_plate:1)
Block(6,34,-7,quark:iron_plate:1)
Block(6,34,-6,quark:iron_plate:1)
Block(6,34,-5,quark:iron_plate:1)

#######################################################################
# +-----------------------------------------------------------------+ #
# |                             Branches                            | #
# +-----------------------------------------------------------------+ #
#######################################################################

Branch(0,0,16,true,ReservoirC1R2,NORTH,100.0,0)

#######################################################################
# +-----------------------------------------------------------------+ #
# |                             Entities                            | #
# +-----------------------------------------------------------------+ #
#######################################################################


#######################################################################
# +-----------------------------------------------------------------+ #
# |                            Particles                            | #
# +-----------------------------------------------------------------+ #
#######################################################################


#######################################################################
# +-----------------------------------------------------------------+ #
# |                             Spawners                            | #
# +-----------------------------------------------------------------+ #
#######################################################################


#######################################################################
# +-----------------------------------------------------------------+ #
# |                             ModData                             | #
# +-----------------------------------------------------------------+ #
#######################################################################

