
#######################################################################
# +-----------------------------------------------------------------+ #
# |                            BO4 object                           | #
# +-----------------------------------------------------------------+ #
#######################################################################

Author: SRP Manhunt

Description: Reinforced observation tower with a clear five-by-five gun deck

SettingsMode: WriteWithoutComments


#######################################################################
# +-----------------------------------------------------------------+ #
# |                          Main settings                          | #
# +-----------------------------------------------------------------+ #
#######################################################################

FixedRotation: NORTH

Frequency: 96

SpawnHeight: highestSolidBlock

UseCenterForHighestBlock: true

##############################
# Height Limits for the BO4. #
##############################

MinHeight: 0

MaxHeight: 255

InheritBO3: 

InheritBO3Rotation: NORTH

OverrideChildSettings: true

OverrideParentHeight: false

CanOverride: true

BranchFrequency: 96

BranchFrequencyGroup: 

MustBeBelowOther: false

MustBeInside: 

CannotBeInside: 

ReplacesBO3: 

MustBeInsideWorldBorders: true

CanSpawnOnWater: false

SpawnOnWaterOnly: false

SpawnUnderWater: false

SpawnAtWaterLevel: false

HeightOffset: 0

RemoveAir: false

ReplaceAbove: 

ReplaceBelow: STONE

ReplaceWithBiomeBlocks: false

ReplaceWithSurfaceBlock: GRASS

ReplaceWithGroundBlock: DIRT

ReplaceWithStoneBlock: STONE

SmoothRadius: 0

SmoothHeightOffset: 0

SmoothStartTop: false

SmoothStartWood: false

SmoothingSurfaceBlock: 

SmoothingGroundBlock: 

BO3Group: military_watchtowers:96,military_sites:12

IsSpawnPoint: false

DoReplaceBlocks: true


#######################################################################
# +-----------------------------------------------------------------+ #
# |                              Blocks                             | #
# +-----------------------------------------------------------------+ #
#######################################################################

Block(-5,0,-5,SMOOTH_BRICK:0)
Block(-4,0,-5,SMOOTH_BRICK:0)
Block(-3,0,-5,SMOOTH_BRICK:0)
Block(-2,0,-5,SMOOTH_BRICK:0)
Block(-1,0,-5,SMOOTH_BRICK:0)
Block(0,0,-5,SMOOTH_BRICK:0)
Block(1,0,-5,SMOOTH_BRICK:0)
Block(2,0,-5,SMOOTH_BRICK:0)
Block(3,0,-5,SMOOTH_BRICK:0)
Block(4,0,-5,SMOOTH_BRICK:0)
Block(5,0,-5,SMOOTH_BRICK:0)
Block(-5,0,-4,SMOOTH_BRICK:0)
Block(-4,0,-4,CONCRETE:7)
Block(-3,0,-4,SMOOTH_BRICK:0)
Block(-2,0,-4,CONCRETE:7)
Block(-1,0,-4,CONCRETE:7)
Block(0,0,-4,CONCRETE:7)
Block(1,0,-4,CONCRETE:7)
Block(2,0,-4,CONCRETE:7)
Block(3,0,-4,CONCRETE:7)
Block(4,0,-4,SMOOTH_BRICK:0)
Block(5,0,-4,SMOOTH_BRICK:0)
Block(-5,0,-3,SMOOTH_BRICK:0)
Block(-4,0,-3,SMOOTH_BRICK:0)
Block(-3,0,-3,CONCRETE:7)
Block(-2,0,-3,CONCRETE:7)
Block(-1,0,-3,CONCRETE:7)
Block(0,0,-3,CONCRETE:7)
Block(1,0,-3,CONCRETE:7)
Block(2,0,-3,CONCRETE:7)
Block(3,0,-3,SMOOTH_BRICK:0)
Block(4,0,-3,CONCRETE:7)
Block(5,0,-3,SMOOTH_BRICK:0)
Block(-5,0,-2,SMOOTH_BRICK:0)
Block(-4,0,-2,CONCRETE:7)
Block(-3,0,-2,CONCRETE:7)
Block(-2,0,-2,CONCRETE:7)
Block(-1,0,-2,CONCRETE:7)
Block(0,0,-2,CONCRETE:7)
Block(1,0,-2,CONCRETE:7)
Block(2,0,-2,SMOOTH_BRICK:0)
Block(3,0,-2,CONCRETE:7)
Block(4,0,-2,CONCRETE:7)
Block(5,0,-2,SMOOTH_BRICK:0)
Block(-5,0,-1,SMOOTH_BRICK:0)
Block(-4,0,-1,CONCRETE:7)
Block(-3,0,-1,CONCRETE:7)
Block(-2,0,-1,CONCRETE:7)
Block(-1,0,-1,CONCRETE:7)
Block(0,0,-1,CONCRETE:7)
Block(1,0,-1,SMOOTH_BRICK:0)
Block(2,0,-1,CONCRETE:7)
Block(3,0,-1,CONCRETE:7)
Block(4,0,-1,CONCRETE:7)
Block(5,0,-1,SMOOTH_BRICK:0)
Block(-5,0,0,SMOOTH_BRICK:0)
Block(-4,0,0,CONCRETE:7)
Block(-3,0,0,CONCRETE:7)
Block(-2,0,0,CONCRETE:7)
Block(-1,0,0,CONCRETE:7)
Block(0,0,0,SMOOTH_BRICK:0)
Block(1,0,0,CONCRETE:7)
Block(2,0,0,CONCRETE:7)
Block(3,0,0,CONCRETE:7)
Block(4,0,0,CONCRETE:7)
Block(5,0,0,SMOOTH_BRICK:0)
Block(-5,0,1,SMOOTH_BRICK:0)
Block(-4,0,1,CONCRETE:7)
Block(-3,0,1,CONCRETE:7)
Block(-2,0,1,CONCRETE:7)
Block(-1,0,1,SMOOTH_BRICK:0)
Block(0,0,1,CONCRETE:7)
Block(1,0,1,CONCRETE:7)
Block(2,0,1,CONCRETE:7)
Block(3,0,1,CONCRETE:7)
Block(4,0,1,CONCRETE:7)
Block(5,0,1,SMOOTH_BRICK:0)
Block(-5,0,2,SMOOTH_BRICK:0)
Block(-4,0,2,CONCRETE:7)
Block(-3,0,2,CONCRETE:7)
Block(-2,0,2,SMOOTH_BRICK:0)
Block(-1,0,2,CONCRETE:7)
Block(0,0,2,CONCRETE:7)
Block(1,0,2,CONCRETE:7)
Block(2,0,2,CONCRETE:7)
Block(3,0,2,CONCRETE:7)
Block(4,0,2,CONCRETE:7)
Block(5,0,2,SMOOTH_BRICK:0)
Block(-5,0,3,SMOOTH_BRICK:0)
Block(-4,0,3,CONCRETE:7)
Block(-3,0,3,SMOOTH_BRICK:0)
Block(-2,0,3,CONCRETE:7)
Block(-1,0,3,CONCRETE:7)
Block(0,0,3,CONCRETE:7)
Block(1,0,3,CONCRETE:7)
Block(2,0,3,CONCRETE:7)
Block(3,0,3,CONCRETE:7)
Block(4,0,3,SMOOTH_BRICK:0)
Block(5,0,3,SMOOTH_BRICK:0)
Block(-5,0,4,SMOOTH_BRICK:0)
Block(-4,0,4,SMOOTH_BRICK:0)
Block(-3,0,4,CONCRETE:7)
Block(-2,0,4,CONCRETE:7)
Block(-1,0,4,CONCRETE:7)
Block(0,0,4,CONCRETE:7)
Block(1,0,4,CONCRETE:7)
Block(2,0,4,CONCRETE:7)
Block(3,0,4,SMOOTH_BRICK:0)
Block(4,0,4,CONCRETE:7)
Block(5,0,4,SMOOTH_BRICK:0)
Block(-5,0,5,SMOOTH_BRICK:0)
Block(-4,0,5,SMOOTH_BRICK:0)
Block(-3,0,5,SMOOTH_BRICK:0)
Block(-2,0,5,SMOOTH_BRICK:0)
Block(-1,0,5,SMOOTH_BRICK:0)
Block(0,0,5,SMOOTH_BRICK:0)
Block(1,0,5,SMOOTH_BRICK:0)
Block(2,0,5,SMOOTH_BRICK:0)
Block(3,0,5,SMOOTH_BRICK:0)
Block(4,0,5,SMOOTH_BRICK:0)
Block(5,0,5,SMOOTH_BRICK:0)
Block(-5,1,-5,SMOOTH_BRICK:0)
Block(-4,1,-5,SMOOTH_BRICK:0)
Block(4,1,-5,SMOOTH_BRICK:0)
Block(5,1,-5,SMOOTH_BRICK:0)
Block(-5,1,-4,SMOOTH_BRICK:0)
Block(-4,1,-4,SMOOTH_BRICK:0)
Block(4,1,-4,SMOOTH_BRICK:0)
Block(5,1,-4,SMOOTH_BRICK:0)
Block(4,1,2,LADDER:4)
Block(5,1,2,SMOOTH_BRICK:0)
Block(-5,1,4,SMOOTH_BRICK:0)
Block(-4,1,4,SMOOTH_BRICK:0)
Block(4,1,4,SMOOTH_BRICK:0)
Block(5,1,4,SMOOTH_BRICK:0)
Block(-5,1,5,SMOOTH_BRICK:0)
Block(-4,1,5,SMOOTH_BRICK:0)
Block(4,1,5,SMOOTH_BRICK:0)
Block(5,1,5,SMOOTH_BRICK:0)
Block(-5,2,-5,CONCRETE:7)
Block(-4,2,-5,CONCRETE:7)
Block(4,2,-5,CONCRETE:7)
Block(5,2,-5,CONCRETE:7)
Block(-5,2,-4,CONCRETE:7)
Block(-4,2,-4,CONCRETE:7)
Block(-3,2,-4,SMOOTH_BRICK:2)
Block(3,2,-4,SMOOTH_BRICK:2)
Block(4,2,-4,CONCRETE:7)
Block(5,2,-4,CONCRETE:7)
Block(-4,2,-3,SMOOTH_BRICK:2)
Block(4,2,-3,SMOOTH_BRICK:2)
Block(4,2,2,LADDER:4)
Block(5,2,2,SMOOTH_BRICK:0)
Block(-4,2,3,SMOOTH_BRICK:2)
Block(4,2,3,SMOOTH_BRICK:2)
Block(-5,2,4,CONCRETE:7)
Block(-4,2,4,CONCRETE:7)
Block(-3,2,4,SMOOTH_BRICK:2)
Block(3,2,4,SMOOTH_BRICK:2)
Block(4,2,4,CONCRETE:7)
Block(5,2,4,CONCRETE:7)
Block(-5,2,5,CONCRETE:7)
Block(-4,2,5,CONCRETE:7)
Block(4,2,5,CONCRETE:7)
Block(5,2,5,CONCRETE:7)
Block(-5,3,-5,CONCRETE:7)
Block(-4,3,-5,CONCRETE:7)
Block(4,3,-5,CONCRETE:7)
Block(5,3,-5,CONCRETE:7)
Block(-5,3,-4,CONCRETE:7)
Block(-4,3,-4,CONCRETE:7)
Block(-2,3,-4,SMOOTH_BRICK:2)
Block(2,3,-4,SMOOTH_BRICK:2)
Block(4,3,-4,CONCRETE:7)
Block(5,3,-4,CONCRETE:7)
Block(-4,3,-2,SMOOTH_BRICK:2)
Block(4,3,-2,SMOOTH_BRICK:2)
Block(-4,3,2,SMOOTH_BRICK:2)
Block(4,3,2,LADDER:4)
Block(5,3,2,SMOOTH_BRICK:0)
Block(-5,3,4,CONCRETE:7)
Block(-4,3,4,CONCRETE:7)
Block(-2,3,4,SMOOTH_BRICK:2)
Block(2,3,4,SMOOTH_BRICK:2)
Block(4,3,4,CONCRETE:7)
Block(5,3,4,CONCRETE:7)
Block(-5,3,5,CONCRETE:7)
Block(-4,3,5,CONCRETE:7)
Block(4,3,5,CONCRETE:7)
Block(5,3,5,CONCRETE:7)
Block(-5,4,-5,SMOOTH_BRICK:0)
Block(-4,4,-5,SMOOTH_BRICK:0)
Block(4,4,-5,SMOOTH_BRICK:0)
Block(5,4,-5,SMOOTH_BRICK:0)
Block(-5,4,-4,SMOOTH_BRICK:0)
Block(-4,4,-4,SMOOTH_BRICK:0)
Block(-3,4,-4,SMOOTH_BRICK:0)
Block(-2,4,-4,SMOOTH_BRICK:0)
Block(-1,4,-4,SMOOTH_BRICK:2)
Block(0,4,-4,SMOOTH_BRICK:0)
Block(1,4,-4,SMOOTH_BRICK:2)
Block(2,4,-4,SMOOTH_BRICK:0)
Block(3,4,-4,SMOOTH_BRICK:0)
Block(4,4,-4,SMOOTH_BRICK:0)
Block(5,4,-4,SMOOTH_BRICK:0)
Block(-4,4,-3,SMOOTH_BRICK:0)
Block(4,4,-3,SMOOTH_BRICK:0)
Block(-4,4,-2,SMOOTH_BRICK:0)
Block(4,4,-2,SMOOTH_BRICK:0)
Block(-4,4,-1,SMOOTH_BRICK:2)
Block(4,4,-1,SMOOTH_BRICK:2)
Block(-4,4,0,SMOOTH_BRICK:0)
Block(4,4,0,SMOOTH_BRICK:0)
Block(-4,4,1,SMOOTH_BRICK:2)
Block(4,4,1,SMOOTH_BRICK:2)
Block(-4,4,2,SMOOTH_BRICK:0)
Block(4,4,2,LADDER:4)
Block(5,4,2,SMOOTH_BRICK:0)
Block(-4,4,3,SMOOTH_BRICK:0)
Block(4,4,3,SMOOTH_BRICK:0)
Block(-5,4,4,SMOOTH_BRICK:0)
Block(-4,4,4,SMOOTH_BRICK:0)
Block(-3,4,4,SMOOTH_BRICK:0)
Block(-2,4,4,SMOOTH_BRICK:0)
Block(-1,4,4,SMOOTH_BRICK:2)
Block(0,4,4,SMOOTH_BRICK:0)
Block(1,4,4,SMOOTH_BRICK:2)
Block(2,4,4,SMOOTH_BRICK:0)
Block(3,4,4,SMOOTH_BRICK:0)
Block(4,4,4,SMOOTH_BRICK:0)
Block(5,4,4,SMOOTH_BRICK:0)
Block(-5,4,5,SMOOTH_BRICK:0)
Block(-4,4,5,SMOOTH_BRICK:0)
Block(4,4,5,SMOOTH_BRICK:0)
Block(5,4,5,SMOOTH_BRICK:0)
Block(-5,5,-5,SMOOTH_BRICK:0)
Block(-4,5,-5,SMOOTH_BRICK:0)
Block(4,5,-5,SMOOTH_BRICK:0)
Block(5,5,-5,SMOOTH_BRICK:0)
Block(-5,5,-4,SMOOTH_BRICK:0)
Block(-4,5,-4,SMOOTH_BRICK:0)
Block(0,5,-4,SMOOTH_BRICK:2)
Block(4,5,-4,SMOOTH_BRICK:0)
Block(5,5,-4,SMOOTH_BRICK:0)
Block(-4,5,0,SMOOTH_BRICK:2)
Block(4,5,0,SMOOTH_BRICK:2)
Block(4,5,2,LADDER:4)
Block(5,5,2,SMOOTH_BRICK:0)
Block(-5,5,4,SMOOTH_BRICK:0)
Block(-4,5,4,SMOOTH_BRICK:0)
Block(0,5,4,SMOOTH_BRICK:2)
Block(4,5,4,SMOOTH_BRICK:0)
Block(5,5,4,SMOOTH_BRICK:0)
Block(-5,5,5,SMOOTH_BRICK:0)
Block(-4,5,5,SMOOTH_BRICK:0)
Block(4,5,5,SMOOTH_BRICK:0)
Block(5,5,5,SMOOTH_BRICK:0)
Block(-5,6,-5,CONCRETE:7)
Block(-4,6,-5,CONCRETE:7)
Block(4,6,-5,CONCRETE:7)
Block(5,6,-5,CONCRETE:7)
Block(-5,6,-4,CONCRETE:7)
Block(-4,6,-4,CONCRETE:7)
Block(-1,6,-4,SMOOTH_BRICK:2)
Block(1,6,-4,SMOOTH_BRICK:2)
Block(4,6,-4,CONCRETE:7)
Block(5,6,-4,CONCRETE:7)
Block(-3,6,-3,STEP:5)
Block(-2,6,-3,STEP:5)
Block(-1,6,-3,STEP:5)
Block(0,6,-3,STEP:5)
Block(1,6,-3,STEP:5)
Block(2,6,-3,STEP:5)
Block(3,6,-3,STEP:5)
Block(-3,6,-2,STEP:5)
Block(-2,6,-2,STEP:5)
Block(-1,6,-2,STEP:5)
Block(0,6,-2,STEP:5)
Block(1,6,-2,STEP:5)
Block(2,6,-2,STEP:5)
Block(3,6,-2,STEP:5)
Block(-4,6,-1,SMOOTH_BRICK:2)
Block(-3,6,-1,STEP:5)
Block(-2,6,-1,STEP:5)
Block(-1,6,-1,STEP:5)
Block(0,6,-1,STEP:5)
Block(1,6,-1,STEP:5)
Block(2,6,-1,STEP:5)
Block(3,6,-1,STEP:5)
Block(4,6,-1,SMOOTH_BRICK:2)
Block(-3,6,0,STEP:5)
Block(-2,6,0,STEP:5)
Block(-1,6,0,STEP:5)
Block(0,6,0,STEP:5)
Block(1,6,0,STEP:5)
Block(2,6,0,STEP:5)
Block(3,6,0,STEP:5)
Block(-4,6,1,SMOOTH_BRICK:2)
Block(-3,6,1,STEP:5)
Block(-2,6,1,STEP:5)
Block(-1,6,1,STEP:5)
Block(0,6,1,STEP:5)
Block(1,6,1,STEP:5)
Block(4,6,1,SMOOTH_BRICK:2)
Block(-3,6,2,STEP:5)
Block(-2,6,2,STEP:5)
Block(-1,6,2,STEP:5)
Block(0,6,2,STEP:5)
Block(1,6,2,STEP:5)
Block(4,6,2,LADDER:4)
Block(5,6,2,SMOOTH_BRICK:0)
Block(-3,6,3,STEP:5)
Block(-2,6,3,STEP:5)
Block(-1,6,3,STEP:5)
Block(0,6,3,STEP:5)
Block(1,6,3,STEP:5)
Block(-5,6,4,CONCRETE:7)
Block(-4,6,4,CONCRETE:7)
Block(-1,6,4,SMOOTH_BRICK:2)
Block(1,6,4,SMOOTH_BRICK:2)
Block(4,6,4,CONCRETE:7)
Block(5,6,4,CONCRETE:7)
Block(-5,6,5,CONCRETE:7)
Block(-4,6,5,CONCRETE:7)
Block(4,6,5,CONCRETE:7)
Block(5,6,5,CONCRETE:7)
Block(-5,7,-5,CONCRETE:7)
Block(-4,7,-5,CONCRETE:7)
Block(4,7,-5,CONCRETE:7)
Block(5,7,-5,CONCRETE:7)
Block(-5,7,-4,CONCRETE:7)
Block(-4,7,-4,CONCRETE:7)
Block(-2,7,-4,SMOOTH_BRICK:2)
Block(2,7,-4,SMOOTH_BRICK:2)
Block(4,7,-4,CONCRETE:7)
Block(5,7,-4,CONCRETE:7)
Block(-3,7,-3,IRON_FENCE:0)
Block(-2,7,-3,IRON_FENCE:0)
Block(-1,7,-3,IRON_FENCE:0)
Block(0,7,-3,IRON_FENCE:0)
Block(1,7,-3,IRON_FENCE:0)
Block(2,7,-3,IRON_FENCE:0)
Block(3,7,-3,IRON_FENCE:0)
Block(-4,7,-2,SMOOTH_BRICK:2)
Block(-3,7,-2,IRON_FENCE:0)
Block(3,7,-2,IRON_FENCE:0)
Block(4,7,-2,SMOOTH_BRICK:2)
Block(-3,7,-1,IRON_FENCE:0)
Block(3,7,-1,IRON_FENCE:0)
Block(-3,7,0,IRON_FENCE:0)
Block(3,7,0,IRON_FENCE:0)
Block(-3,7,1,IRON_FENCE:0)
Block(3,7,1,IRON_FENCE:0)
Block(-4,7,2,SMOOTH_BRICK:2)
Block(-3,7,2,IRON_FENCE:0)
Block(3,7,2,IRON_FENCE:0)
Block(4,7,2,LADDER:4)
Block(5,7,2,SMOOTH_BRICK:0)
Block(-3,7,3,IRON_FENCE:0)
Block(-2,7,3,IRON_FENCE:0)
Block(-1,7,3,IRON_FENCE:0)
Block(0,7,3,IRON_FENCE:0)
Block(1,7,3,IRON_FENCE:0)
Block(2,7,3,IRON_FENCE:0)
Block(3,7,3,IRON_FENCE:0)
Block(-5,7,4,CONCRETE:7)
Block(-4,7,4,CONCRETE:7)
Block(-2,7,4,SMOOTH_BRICK:2)
Block(2,7,4,SMOOTH_BRICK:2)
Block(4,7,4,CONCRETE:7)
Block(5,7,4,CONCRETE:7)
Block(-5,7,5,CONCRETE:7)
Block(-4,7,5,CONCRETE:7)
Block(4,7,5,CONCRETE:7)
Block(5,7,5,CONCRETE:7)
Block(-5,8,-5,SMOOTH_BRICK:0)
Block(-4,8,-5,SMOOTH_BRICK:0)
Block(4,8,-5,SMOOTH_BRICK:0)
Block(5,8,-5,SMOOTH_BRICK:0)
Block(-5,8,-4,SMOOTH_BRICK:0)
Block(-4,8,-4,SMOOTH_BRICK:0)
Block(-3,8,-4,SMOOTH_BRICK:2)
Block(-2,8,-4,SMOOTH_BRICK:0)
Block(-1,8,-4,SMOOTH_BRICK:0)
Block(0,8,-4,SMOOTH_BRICK:0)
Block(1,8,-4,SMOOTH_BRICK:0)
Block(2,8,-4,SMOOTH_BRICK:0)
Block(3,8,-4,SMOOTH_BRICK:2)
Block(4,8,-4,SMOOTH_BRICK:0)
Block(5,8,-4,SMOOTH_BRICK:0)
Block(-4,8,-3,SMOOTH_BRICK:2)
Block(4,8,-3,SMOOTH_BRICK:2)
Block(-4,8,-2,SMOOTH_BRICK:0)
Block(4,8,-2,SMOOTH_BRICK:0)
Block(-4,8,-1,SMOOTH_BRICK:0)
Block(4,8,-1,SMOOTH_BRICK:0)
Block(-4,8,0,SMOOTH_BRICK:0)
Block(4,8,0,SMOOTH_BRICK:0)
Block(-4,8,1,SMOOTH_BRICK:0)
Block(4,8,1,SMOOTH_BRICK:0)
Block(-4,8,2,SMOOTH_BRICK:0)
Block(4,8,2,LADDER:4)
Block(5,8,2,SMOOTH_BRICK:0)
Block(-4,8,3,SMOOTH_BRICK:2)
Block(4,8,3,SMOOTH_BRICK:2)
Block(-5,8,4,SMOOTH_BRICK:0)
Block(-4,8,4,SMOOTH_BRICK:0)
Block(-3,8,4,SMOOTH_BRICK:2)
Block(-2,8,4,SMOOTH_BRICK:0)
Block(-1,8,4,SMOOTH_BRICK:0)
Block(0,8,4,SMOOTH_BRICK:0)
Block(1,8,4,SMOOTH_BRICK:0)
Block(2,8,4,SMOOTH_BRICK:0)
Block(3,8,4,SMOOTH_BRICK:2)
Block(4,8,4,SMOOTH_BRICK:0)
Block(5,8,4,SMOOTH_BRICK:0)
Block(-5,8,5,SMOOTH_BRICK:0)
Block(-4,8,5,SMOOTH_BRICK:0)
Block(4,8,5,SMOOTH_BRICK:0)
Block(5,8,5,SMOOTH_BRICK:0)
Block(-5,9,-5,SMOOTH_BRICK:0)
Block(-4,9,-5,SMOOTH_BRICK:0)
Block(4,9,-5,SMOOTH_BRICK:0)
Block(5,9,-5,SMOOTH_BRICK:0)
Block(-5,9,-4,SMOOTH_BRICK:0)
Block(-4,9,-4,SMOOTH_BRICK:0)
Block(-2,9,-4,SMOOTH_BRICK:2)
Block(2,9,-4,SMOOTH_BRICK:2)
Block(4,9,-4,SMOOTH_BRICK:0)
Block(5,9,-4,SMOOTH_BRICK:0)
Block(-4,9,-2,SMOOTH_BRICK:2)
Block(4,9,-2,SMOOTH_BRICK:2)
Block(-4,9,2,SMOOTH_BRICK:2)
Block(4,9,2,LADDER:4)
Block(5,9,2,SMOOTH_BRICK:0)
Block(-5,9,4,SMOOTH_BRICK:0)
Block(-4,9,4,SMOOTH_BRICK:0)
Block(-2,9,4,SMOOTH_BRICK:2)
Block(2,9,4,SMOOTH_BRICK:2)
Block(4,9,4,SMOOTH_BRICK:0)
Block(5,9,4,SMOOTH_BRICK:0)
Block(-5,9,5,SMOOTH_BRICK:0)
Block(-4,9,5,SMOOTH_BRICK:0)
Block(4,9,5,SMOOTH_BRICK:0)
Block(5,9,5,SMOOTH_BRICK:0)
Block(-5,10,-5,CONCRETE:7)
Block(-4,10,-5,CONCRETE:7)
Block(4,10,-5,CONCRETE:7)
Block(5,10,-5,CONCRETE:7)
Block(-5,10,-4,CONCRETE:7)
Block(-4,10,-4,CONCRETE:7)
Block(-1,10,-4,SMOOTH_BRICK:2)
Block(1,10,-4,SMOOTH_BRICK:2)
Block(4,10,-4,CONCRETE:7)
Block(5,10,-4,CONCRETE:7)
Block(-4,10,-1,SMOOTH_BRICK:2)
Block(4,10,-1,SMOOTH_BRICK:2)
Block(-4,10,1,SMOOTH_BRICK:2)
Block(4,10,1,SMOOTH_BRICK:2)
Block(4,10,2,LADDER:4)
Block(5,10,2,SMOOTH_BRICK:0)
Block(-5,10,4,CONCRETE:7)
Block(-4,10,4,CONCRETE:7)
Block(-1,10,4,SMOOTH_BRICK:2)
Block(1,10,4,SMOOTH_BRICK:2)
Block(4,10,4,CONCRETE:7)
Block(5,10,4,CONCRETE:7)
Block(-5,10,5,CONCRETE:7)
Block(-4,10,5,CONCRETE:7)
Block(4,10,5,CONCRETE:7)
Block(5,10,5,CONCRETE:7)
Block(-5,11,-5,CONCRETE:7)
Block(-4,11,-5,CONCRETE:7)
Block(4,11,-5,CONCRETE:7)
Block(5,11,-5,CONCRETE:7)
Block(-5,11,-4,CONCRETE:7)
Block(-4,11,-4,CONCRETE:7)
Block(0,11,-4,SMOOTH_BRICK:2)
Block(4,11,-4,CONCRETE:7)
Block(5,11,-4,CONCRETE:7)
Block(-4,11,0,SMOOTH_BRICK:2)
Block(4,11,0,SMOOTH_BRICK:2)
Block(4,11,2,LADDER:4)
Block(5,11,2,SMOOTH_BRICK:0)
Block(-5,11,4,CONCRETE:7)
Block(-4,11,4,CONCRETE:7)
Block(0,11,4,SMOOTH_BRICK:2)
Block(4,11,4,CONCRETE:7)
Block(5,11,4,CONCRETE:7)
Block(-5,11,5,CONCRETE:7)
Block(-4,11,5,CONCRETE:7)
Block(4,11,5,CONCRETE:7)
Block(5,11,5,CONCRETE:7)
Block(-5,12,-5,SMOOTH_BRICK:0)
Block(-4,12,-5,SMOOTH_BRICK:0)
Block(4,12,-5,SMOOTH_BRICK:0)
Block(5,12,-5,SMOOTH_BRICK:0)
Block(-5,12,-4,SMOOTH_BRICK:0)
Block(-4,12,-4,SMOOTH_BRICK:0)
Block(-3,12,-4,SMOOTH_BRICK:0)
Block(-2,12,-4,SMOOTH_BRICK:0)
Block(-1,12,-4,SMOOTH_BRICK:2)
Block(0,12,-4,SMOOTH_BRICK:0)
Block(1,12,-4,SMOOTH_BRICK:2)
Block(2,12,-4,SMOOTH_BRICK:0)
Block(3,12,-4,SMOOTH_BRICK:0)
Block(4,12,-4,SMOOTH_BRICK:0)
Block(5,12,-4,SMOOTH_BRICK:0)
Block(-4,12,-3,SMOOTH_BRICK:0)
Block(-3,12,-3,STEP:5)
Block(-2,12,-3,STEP:5)
Block(-1,12,-3,STEP:5)
Block(0,12,-3,STEP:5)
Block(1,12,-3,STEP:5)
Block(2,12,-3,STEP:5)
Block(3,12,-3,STEP:5)
Block(4,12,-3,SMOOTH_BRICK:0)
Block(-4,12,-2,SMOOTH_BRICK:0)
Block(-3,12,-2,STEP:5)
Block(-2,12,-2,STEP:5)
Block(-1,12,-2,STEP:5)
Block(0,12,-2,STEP:5)
Block(1,12,-2,STEP:5)
Block(2,12,-2,STEP:5)
Block(3,12,-2,STEP:5)
Block(4,12,-2,SMOOTH_BRICK:0)
Block(-4,12,-1,SMOOTH_BRICK:2)
Block(-3,12,-1,STEP:5)
Block(-2,12,-1,STEP:5)
Block(-1,12,-1,STEP:5)
Block(0,12,-1,STEP:5)
Block(1,12,-1,STEP:5)
Block(2,12,-1,STEP:5)
Block(3,12,-1,STEP:5)
Block(4,12,-1,SMOOTH_BRICK:2)
Block(-4,12,0,SMOOTH_BRICK:0)
Block(-3,12,0,STEP:5)
Block(-2,12,0,STEP:5)
Block(-1,12,0,STEP:5)
Block(0,12,0,STEP:5)
Block(1,12,0,STEP:5)
Block(2,12,0,STEP:5)
Block(3,12,0,STEP:5)
Block(4,12,0,SMOOTH_BRICK:0)
Block(-4,12,1,SMOOTH_BRICK:2)
Block(-3,12,1,STEP:5)
Block(-2,12,1,STEP:5)
Block(-1,12,1,STEP:5)
Block(0,12,1,STEP:5)
Block(1,12,1,STEP:5)
Block(4,12,1,SMOOTH_BRICK:2)
Block(-4,12,2,SMOOTH_BRICK:0)
Block(-3,12,2,STEP:5)
Block(-2,12,2,STEP:5)
Block(-1,12,2,STEP:5)
Block(0,12,2,STEP:5)
Block(1,12,2,STEP:5)
Block(4,12,2,LADDER:4)
Block(5,12,2,SMOOTH_BRICK:0)
Block(-4,12,3,SMOOTH_BRICK:0)
Block(-3,12,3,STEP:5)
Block(-2,12,3,STEP:5)
Block(-1,12,3,STEP:5)
Block(0,12,3,STEP:5)
Block(1,12,3,STEP:5)
Block(4,12,3,SMOOTH_BRICK:0)
Block(-5,12,4,SMOOTH_BRICK:0)
Block(-4,12,4,SMOOTH_BRICK:0)
Block(-3,12,4,SMOOTH_BRICK:0)
Block(-2,12,4,SMOOTH_BRICK:0)
Block(-1,12,4,SMOOTH_BRICK:2)
Block(0,12,4,SMOOTH_BRICK:0)
Block(1,12,4,SMOOTH_BRICK:2)
Block(2,12,4,SMOOTH_BRICK:0)
Block(3,12,4,SMOOTH_BRICK:0)
Block(4,12,4,SMOOTH_BRICK:0)
Block(5,12,4,SMOOTH_BRICK:0)
Block(-5,12,5,SMOOTH_BRICK:0)
Block(-4,12,5,SMOOTH_BRICK:0)
Block(4,12,5,SMOOTH_BRICK:0)
Block(5,12,5,SMOOTH_BRICK:0)
Block(-5,13,-5,SMOOTH_BRICK:0)
Block(-4,13,-5,SMOOTH_BRICK:0)
Block(4,13,-5,SMOOTH_BRICK:0)
Block(5,13,-5,SMOOTH_BRICK:0)
Block(-5,13,-4,SMOOTH_BRICK:0)
Block(-4,13,-4,SMOOTH_BRICK:0)
Block(-2,13,-4,SMOOTH_BRICK:2)
Block(2,13,-4,SMOOTH_BRICK:2)
Block(4,13,-4,SMOOTH_BRICK:0)
Block(5,13,-4,SMOOTH_BRICK:0)
Block(-3,13,-3,IRON_FENCE:0)
Block(-2,13,-3,IRON_FENCE:0)
Block(-1,13,-3,IRON_FENCE:0)
Block(0,13,-3,IRON_FENCE:0)
Block(1,13,-3,IRON_FENCE:0)
Block(2,13,-3,IRON_FENCE:0)
Block(3,13,-3,IRON_FENCE:0)
Block(-4,13,-2,SMOOTH_BRICK:2)
Block(-3,13,-2,IRON_FENCE:0)
Block(3,13,-2,IRON_FENCE:0)
Block(4,13,-2,SMOOTH_BRICK:2)
Block(-3,13,-1,IRON_FENCE:0)
Block(3,13,-1,IRON_FENCE:0)
Block(-3,13,0,IRON_FENCE:0)
Block(3,13,0,IRON_FENCE:0)
Block(-3,13,1,IRON_FENCE:0)
Block(3,13,1,IRON_FENCE:0)
Block(-4,13,2,SMOOTH_BRICK:2)
Block(-3,13,2,IRON_FENCE:0)
Block(3,13,2,IRON_FENCE:0)
Block(4,13,2,LADDER:4)
Block(5,13,2,SMOOTH_BRICK:0)
Block(-3,13,3,IRON_FENCE:0)
Block(-2,13,3,IRON_FENCE:0)
Block(-1,13,3,IRON_FENCE:0)
Block(0,13,3,IRON_FENCE:0)
Block(1,13,3,IRON_FENCE:0)
Block(2,13,3,IRON_FENCE:0)
Block(3,13,3,IRON_FENCE:0)
Block(-5,13,4,SMOOTH_BRICK:0)
Block(-4,13,4,SMOOTH_BRICK:0)
Block(-2,13,4,SMOOTH_BRICK:2)
Block(2,13,4,SMOOTH_BRICK:2)
Block(4,13,4,SMOOTH_BRICK:0)
Block(5,13,4,SMOOTH_BRICK:0)
Block(-5,13,5,SMOOTH_BRICK:0)
Block(-4,13,5,SMOOTH_BRICK:0)
Block(4,13,5,SMOOTH_BRICK:0)
Block(5,13,5,SMOOTH_BRICK:0)
Block(-5,14,-5,CONCRETE:7)
Block(-4,14,-5,CONCRETE:7)
Block(4,14,-5,CONCRETE:7)
Block(5,14,-5,CONCRETE:7)
Block(-5,14,-4,CONCRETE:7)
Block(-4,14,-4,CONCRETE:7)
Block(-3,14,-4,SMOOTH_BRICK:2)
Block(3,14,-4,SMOOTH_BRICK:2)
Block(4,14,-4,CONCRETE:7)
Block(5,14,-4,CONCRETE:7)
Block(-4,14,-3,SMOOTH_BRICK:2)
Block(4,14,-3,SMOOTH_BRICK:2)
Block(4,14,2,LADDER:4)
Block(5,14,2,SMOOTH_BRICK:0)
Block(-4,14,3,SMOOTH_BRICK:2)
Block(4,14,3,SMOOTH_BRICK:2)
Block(-5,14,4,CONCRETE:7)
Block(-4,14,4,CONCRETE:7)
Block(-3,14,4,SMOOTH_BRICK:2)
Block(3,14,4,SMOOTH_BRICK:2)
Block(4,14,4,CONCRETE:7)
Block(5,14,4,CONCRETE:7)
Block(-5,14,5,CONCRETE:7)
Block(-4,14,5,CONCRETE:7)
Block(4,14,5,CONCRETE:7)
Block(5,14,5,CONCRETE:7)
Block(-5,15,-5,CONCRETE:7)
Block(-4,15,-5,CONCRETE:7)
Block(4,15,-5,CONCRETE:7)
Block(5,15,-5,CONCRETE:7)
Block(-5,15,-4,CONCRETE:7)
Block(-4,15,-4,CONCRETE:7)
Block(-2,15,-4,SMOOTH_BRICK:2)
Block(2,15,-4,SMOOTH_BRICK:2)
Block(4,15,-4,CONCRETE:7)
Block(5,15,-4,CONCRETE:7)
Block(-4,15,-2,SMOOTH_BRICK:2)
Block(4,15,-2,SMOOTH_BRICK:2)
Block(-4,15,2,SMOOTH_BRICK:2)
Block(4,15,2,LADDER:4)
Block(5,15,2,SMOOTH_BRICK:0)
Block(-5,15,4,CONCRETE:7)
Block(-4,15,4,CONCRETE:7)
Block(-2,15,4,SMOOTH_BRICK:2)
Block(2,15,4,SMOOTH_BRICK:2)
Block(4,15,4,CONCRETE:7)
Block(5,15,4,CONCRETE:7)
Block(-5,15,5,CONCRETE:7)
Block(-4,15,5,CONCRETE:7)
Block(4,15,5,CONCRETE:7)
Block(5,15,5,CONCRETE:7)
Block(-5,16,-5,SMOOTH_BRICK:0)
Block(-4,16,-5,SMOOTH_BRICK:0)
Block(4,16,-5,SMOOTH_BRICK:0)
Block(5,16,-5,SMOOTH_BRICK:0)
Block(-5,16,-4,SMOOTH_BRICK:0)
Block(-4,16,-4,SMOOTH_BRICK:0)
Block(-3,16,-4,SMOOTH_BRICK:0)
Block(-2,16,-4,SMOOTH_BRICK:0)
Block(-1,16,-4,SMOOTH_BRICK:0)
Block(0,16,-4,SMOOTH_BRICK:0)
Block(1,16,-4,SMOOTH_BRICK:0)
Block(2,16,-4,SMOOTH_BRICK:0)
Block(3,16,-4,SMOOTH_BRICK:0)
Block(4,16,-4,SMOOTH_BRICK:0)
Block(5,16,-4,SMOOTH_BRICK:0)
Block(-4,16,-3,SMOOTH_BRICK:0)
Block(4,16,-3,SMOOTH_BRICK:0)
Block(-4,16,-2,SMOOTH_BRICK:0)
Block(4,16,-2,SMOOTH_BRICK:0)
Block(-4,16,-1,SMOOTH_BRICK:0)
Block(4,16,-1,SMOOTH_BRICK:0)
Block(-4,16,0,SMOOTH_BRICK:0)
Block(4,16,0,SMOOTH_BRICK:0)
Block(-4,16,1,SMOOTH_BRICK:0)
Block(4,16,1,SMOOTH_BRICK:0)
Block(-4,16,2,SMOOTH_BRICK:0)
Block(4,16,2,LADDER:4)
Block(5,16,2,SMOOTH_BRICK:0)
Block(-4,16,3,SMOOTH_BRICK:0)
Block(4,16,3,SMOOTH_BRICK:0)
Block(-5,16,4,SMOOTH_BRICK:0)
Block(-4,16,4,SMOOTH_BRICK:0)
Block(-3,16,4,SMOOTH_BRICK:0)
Block(-2,16,4,SMOOTH_BRICK:0)
Block(-1,16,4,SMOOTH_BRICK:0)
Block(0,16,4,SMOOTH_BRICK:0)
Block(1,16,4,SMOOTH_BRICK:0)
Block(2,16,4,SMOOTH_BRICK:0)
Block(3,16,4,SMOOTH_BRICK:0)
Block(4,16,4,SMOOTH_BRICK:0)
Block(5,16,4,SMOOTH_BRICK:0)
Block(-5,16,5,SMOOTH_BRICK:0)
Block(-4,16,5,SMOOTH_BRICK:0)
Block(4,16,5,SMOOTH_BRICK:0)
Block(5,16,5,SMOOTH_BRICK:0)
Block(-5,17,-5,CONCRETE:7)
Block(-4,17,-5,CONCRETE:7)
Block(-3,17,-5,CONCRETE:7)
Block(-2,17,-5,CONCRETE:7)
Block(-1,17,-5,CONCRETE:7)
Block(0,17,-5,CONCRETE:7)
Block(1,17,-5,CONCRETE:7)
Block(2,17,-5,CONCRETE:7)
Block(3,17,-5,CONCRETE:7)
Block(4,17,-5,CONCRETE:7)
Block(5,17,-5,CONCRETE:7)
Block(-5,17,-4,CONCRETE:7)
Block(-4,17,-4,CONCRETE:7)
Block(-3,17,-4,CONCRETE:7)
Block(-2,17,-4,CONCRETE:7)
Block(-1,17,-4,CONCRETE:7)
Block(0,17,-4,CONCRETE:7)
Block(1,17,-4,CONCRETE:7)
Block(2,17,-4,CONCRETE:7)
Block(3,17,-4,CONCRETE:7)
Block(4,17,-4,CONCRETE:7)
Block(5,17,-4,CONCRETE:7)
Block(-5,17,-3,CONCRETE:7)
Block(-4,17,-3,CONCRETE:7)
Block(-3,17,-3,CONCRETE:7)
Block(-2,17,-3,CONCRETE:7)
Block(-1,17,-3,CONCRETE:7)
Block(0,17,-3,CONCRETE:7)
Block(1,17,-3,CONCRETE:7)
Block(2,17,-3,CONCRETE:7)
Block(3,17,-3,CONCRETE:7)
Block(4,17,-3,CONCRETE:7)
Block(5,17,-3,CONCRETE:7)
Block(-5,17,-2,CONCRETE:7)
Block(-4,17,-2,CONCRETE:7)
Block(-3,17,-2,CONCRETE:7)
Block(-2,17,-2,CONCRETE:7)
Block(-1,17,-2,CONCRETE:7)
Block(0,17,-2,CONCRETE:7)
Block(1,17,-2,CONCRETE:7)
Block(2,17,-2,CONCRETE:7)
Block(3,17,-2,CONCRETE:7)
Block(4,17,-2,CONCRETE:7)
Block(5,17,-2,CONCRETE:7)
Block(-5,17,-1,CONCRETE:7)
Block(-4,17,-1,CONCRETE:7)
Block(-3,17,-1,CONCRETE:7)
Block(-2,17,-1,CONCRETE:7)
Block(-1,17,-1,CONCRETE:7)
Block(0,17,-1,CONCRETE:7)
Block(1,17,-1,CONCRETE:7)
Block(2,17,-1,CONCRETE:7)
Block(3,17,-1,CONCRETE:7)
Block(4,17,-1,CONCRETE:7)
Block(5,17,-1,CONCRETE:7)
Block(-5,17,0,CONCRETE:7)
Block(-4,17,0,CONCRETE:7)
Block(-3,17,0,CONCRETE:7)
Block(-2,17,0,CONCRETE:7)
Block(-1,17,0,CONCRETE:7)
Block(0,17,0,CONCRETE:7)
Block(1,17,0,CONCRETE:7)
Block(2,17,0,CONCRETE:7)
Block(3,17,0,CONCRETE:7)
Block(4,17,0,CONCRETE:7)
Block(5,17,0,CONCRETE:7)
Block(-5,17,1,CONCRETE:7)
Block(-4,17,1,CONCRETE:7)
Block(-3,17,1,CONCRETE:7)
Block(-2,17,1,CONCRETE:7)
Block(-1,17,1,CONCRETE:7)
Block(0,17,1,CONCRETE:7)
Block(1,17,1,CONCRETE:7)
Block(2,17,1,CONCRETE:7)
Block(3,17,1,CONCRETE:7)
Block(4,17,1,CONCRETE:7)
Block(5,17,1,CONCRETE:7)
Block(-5,17,2,CONCRETE:7)
Block(-4,17,2,CONCRETE:7)
Block(-3,17,2,CONCRETE:7)
Block(-2,17,2,CONCRETE:7)
Block(-1,17,2,CONCRETE:7)
Block(0,17,2,CONCRETE:7)
Block(1,17,2,CONCRETE:7)
Block(2,17,2,CONCRETE:7)
Block(3,17,2,CONCRETE:7)
Block(4,17,2,LADDER:4)
Block(5,17,2,CONCRETE:7)
Block(-5,17,3,CONCRETE:7)
Block(-4,17,3,CONCRETE:7)
Block(-3,17,3,CONCRETE:7)
Block(-2,17,3,CONCRETE:7)
Block(-1,17,3,CONCRETE:7)
Block(0,17,3,CONCRETE:7)
Block(1,17,3,CONCRETE:7)
Block(2,17,3,CONCRETE:7)
Block(3,17,3,CONCRETE:7)
Block(4,17,3,CONCRETE:7)
Block(5,17,3,CONCRETE:7)
Block(-5,17,4,CONCRETE:7)
Block(-4,17,4,CONCRETE:7)
Block(-3,17,4,CONCRETE:7)
Block(-2,17,4,CONCRETE:7)
Block(-1,17,4,CONCRETE:7)
Block(0,17,4,CONCRETE:7)
Block(1,17,4,CONCRETE:7)
Block(2,17,4,CONCRETE:7)
Block(3,17,4,CONCRETE:7)
Block(4,17,4,CONCRETE:7)
Block(5,17,4,CONCRETE:7)
Block(-5,17,5,CONCRETE:7)
Block(-4,17,5,CONCRETE:7)
Block(-3,17,5,CONCRETE:7)
Block(-2,17,5,CONCRETE:7)
Block(-1,17,5,CONCRETE:7)
Block(0,17,5,CONCRETE:7)
Block(1,17,5,CONCRETE:7)
Block(2,17,5,CONCRETE:7)
Block(3,17,5,CONCRETE:7)
Block(4,17,5,CONCRETE:7)
Block(5,17,5,CONCRETE:7)
Block(-5,18,-5,IRON_FENCE:0)
Block(-4,18,-5,IRON_FENCE:0)
Block(-3,18,-5,IRON_FENCE:0)
Block(-2,18,-5,IRON_FENCE:0)
Block(-1,18,-5,IRON_FENCE:0)
Block(0,18,-5,IRON_FENCE:0)
Block(1,18,-5,IRON_FENCE:0)
Block(2,18,-5,IRON_FENCE:0)
Block(3,18,-5,IRON_FENCE:0)
Block(4,18,-5,IRON_FENCE:0)
Block(5,18,-5,IRON_FENCE:0)
Block(-5,18,-4,IRON_FENCE:0)
Block(5,18,-4,IRON_FENCE:0)
Block(-5,18,-3,IRON_FENCE:0)
Block(4,18,-3,dregorarl_srpmanhunt:encounter_marker:13)
Block(5,18,-3,IRON_FENCE:0)
Block(-5,18,-2,IRON_FENCE:0)
Block(5,18,-2,IRON_FENCE:0)
Block(-5,18,-1,IRON_FENCE:0)
Block(5,18,-1,IRON_FENCE:0)
Block(-5,18,0,IRON_FENCE:0)
Block(0,18,0,dregorarl_srpmanhunt:encounter_marker_advanced:5)
Block(5,18,0,IRON_FENCE:0)
Block(-5,18,1,IRON_FENCE:0)
Block(5,18,1,IRON_FENCE:0)
Block(-5,18,2,IRON_FENCE:0)
Block(5,18,2,IRON_FENCE:0)
Block(-5,18,3,IRON_FENCE:0)
Block(-4,18,3,dregorarl_srpmanhunt:encounter_marker:13)
Block(5,18,3,IRON_FENCE:0)
Block(-5,18,4,IRON_FENCE:0)
Block(5,18,4,IRON_FENCE:0)
Block(-5,18,5,IRON_FENCE:0)
Block(-4,18,5,IRON_FENCE:0)
Block(-3,18,5,IRON_FENCE:0)
Block(-2,18,5,IRON_FENCE:0)
Block(-1,18,5,IRON_FENCE:0)
Block(0,18,5,IRON_FENCE:0)
Block(1,18,5,IRON_FENCE:0)
Block(2,18,5,IRON_FENCE:0)
Block(5,18,5,IRON_FENCE:0)
Block(-5,19,-5,IRON_FENCE:0)
Block(5,19,-5,IRON_FENCE:0)
Block(-5,19,5,IRON_FENCE:0)
Block(5,19,5,IRON_FENCE:0)
Block(-5,20,-5,IRON_FENCE:0)
Block(5,20,-5,IRON_FENCE:0)
Block(-5,20,5,IRON_FENCE:0)
Block(5,20,5,IRON_FENCE:0)
Block(-5,21,-5,IRON_FENCE:0)
Block(5,21,-5,IRON_FENCE:0)
Block(-5,21,5,IRON_FENCE:0)
Block(5,21,5,IRON_FENCE:0)
Block(-5,22,-5,SEA_LANTERN:0)
Block(5,22,-5,SEA_LANTERN:0)
Block(-5,22,5,SEA_LANTERN:0)
Block(5,22,5,SEA_LANTERN:0)

#######################################################################
# +-----------------------------------------------------------------+ #
# |                             Branches                            | #
# +-----------------------------------------------------------------+ #
#######################################################################


#######################################################################
# +-----------------------------------------------------------------+ #
# |                             Entities                            | #
# +-----------------------------------------------------------------+ #
#######################################################################


#######################################################################
# +-----------------------------------------------------------------+ #
# |                            Particles                            | #
# +-----------------------------------------------------------------+ #
#######################################################################


#######################################################################
# +-----------------------------------------------------------------+ #
# |                             Spawners                            | #
# +-----------------------------------------------------------------+ #
#######################################################################


#######################################################################
# +-----------------------------------------------------------------+ #
# |                             ModData                             | #
# +-----------------------------------------------------------------+ #
#######################################################################

