
#######################################################################
# +-----------------------------------------------------------------+ #
# |                            BO4 object                           | #
# +-----------------------------------------------------------------+ #
#######################################################################

Author: SRP Manhunt

Description: Maintained radar radome with weathered paneling and service base

SettingsMode: WriteWithoutComments


#######################################################################
# +-----------------------------------------------------------------+ #
# |                          Main settings                          | #
# +-----------------------------------------------------------------+ #
#######################################################################

FixedRotation: NORTH

Frequency: 48

SpawnHeight: highestSolidBlock

UseCenterForHighestBlock: true

##############################
# Height Limits for the BO4. #
##############################

MinHeight: 0

MaxHeight: 255

InheritBO3: 

InheritBO3Rotation: NORTH

OverrideChildSettings: true

OverrideParentHeight: false

CanOverride: true

BranchFrequency: 96

BranchFrequencyGroup: 

MustBeBelowOther: false

MustBeInside: 

CannotBeInside: 

ReplacesBO3: 

MustBeInsideWorldBorders: true

CanSpawnOnWater: false

SpawnOnWaterOnly: false

SpawnUnderWater: false

SpawnAtWaterLevel: false

HeightOffset: 0

RemoveAir: false

ReplaceAbove: 

ReplaceBelow: STONE

ReplaceWithBiomeBlocks: false

ReplaceWithSurfaceBlock: GRASS

ReplaceWithGroundBlock: DIRT

ReplaceWithStoneBlock: STONE

SmoothRadius: 0

SmoothHeightOffset: 0

SmoothStartTop: false

SmoothStartWood: false

SmoothingSurfaceBlock: 

SmoothingGroundBlock: 

BO3Group: military_sites:16

IsSpawnPoint: false

DoReplaceBlocks: true


#######################################################################
# +-----------------------------------------------------------------+ #
# |                              Blocks                             | #
# +-----------------------------------------------------------------+ #
#######################################################################

Block(-7,0,0,CONCRETE:7)
Block(-6,0,-3,CONCRETE:7)
Block(-6,0,-2,CONCRETE:7)
Block(-6,0,-1,CONCRETE:7)
Block(-6,0,0,CONCRETE:7)
Block(-6,0,1,CONCRETE:7)
Block(-6,0,2,CONCRETE:7)
Block(-6,0,3,CONCRETE:7)
Block(-5,0,-4,CONCRETE:7)
Block(-5,0,-3,SMOOTH_BRICK:0)
Block(-5,0,-2,CONCRETE:7)
Block(-5,0,-1,CONCRETE:7)
Block(-5,0,0,CONCRETE:7)
Block(-5,0,1,CONCRETE:7)
Block(-5,0,2,CONCRETE:7)
Block(-5,0,3,CONCRETE:7)
Block(-5,0,4,CONCRETE:7)
Block(-4,0,-5,CONCRETE:7)
Block(-4,0,-4,CONCRETE:7)
Block(-4,0,-3,CONCRETE:7)
Block(-4,0,-2,CONCRETE:7)
Block(-4,0,-1,CONCRETE:7)
Block(-4,0,0,CONCRETE:7)
Block(-4,0,1,SMOOTH_BRICK:0)
Block(-4,0,2,CONCRETE:7)
Block(-4,0,3,CONCRETE:7)
Block(-4,0,4,CONCRETE:7)
Block(-4,0,5,CONCRETE:7)
Block(-3,0,-6,CONCRETE:7)
Block(-3,0,-5,CONCRETE:7)
Block(-3,0,-4,CONCRETE:7)
Block(-3,0,-3,CONCRETE:7)
Block(-3,0,-2,CONCRETE:7)
Block(-3,0,-1,CONCRETE:7)
Block(-3,0,0,CONCRETE:7)
Block(-3,0,1,CONCRETE:7)
Block(-3,0,2,CONCRETE:7)
Block(-3,0,3,CONCRETE:7)
Block(-3,0,4,CONCRETE:7)
Block(-3,0,5,SMOOTH_BRICK:0)
Block(-3,0,6,CONCRETE:7)
Block(-2,0,-6,CONCRETE:7)
Block(-2,0,-5,CONCRETE:7)
Block(-2,0,-4,CONCRETE:7)
Block(-2,0,-3,CONCRETE:7)
Block(-2,0,-2,CONCRETE:7)
Block(-2,0,-1,CONCRETE:7)
Block(-2,0,0,CONCRETE:7)
Block(-2,0,1,CONCRETE:7)
Block(-2,0,2,CONCRETE:7)
Block(-2,0,3,CONCRETE:7)
Block(-2,0,4,CONCRETE:7)
Block(-2,0,5,CONCRETE:7)
Block(-2,0,6,CONCRETE:7)
Block(-1,0,-6,CONCRETE:7)
Block(-1,0,-5,CONCRETE:7)
Block(-1,0,-4,SMOOTH_BRICK:0)
Block(-1,0,-3,CONCRETE:7)
Block(-1,0,-2,CONCRETE:7)
Block(-1,0,-1,CONCRETE:7)
Block(-1,0,0,CONCRETE:7)
Block(-1,0,1,CONCRETE:7)
Block(-1,0,2,CONCRETE:7)
Block(-1,0,3,CONCRETE:7)
Block(-1,0,4,CONCRETE:7)
Block(-1,0,5,CONCRETE:7)
Block(-1,0,6,CONCRETE:7)
Block(0,0,-7,CONCRETE:7)
Block(0,0,-6,CONCRETE:7)
Block(0,0,-5,CONCRETE:7)
Block(0,0,-4,CONCRETE:7)
Block(0,0,-3,CONCRETE:7)
Block(0,0,-2,CONCRETE:7)
Block(0,0,-1,CONCRETE:7)
Block(0,0,0,SMOOTH_BRICK:0)
Block(0,0,1,CONCRETE:7)
Block(0,0,2,CONCRETE:7)
Block(0,0,3,CONCRETE:7)
Block(0,0,4,CONCRETE:7)
Block(0,0,5,CONCRETE:7)
Block(0,0,6,CONCRETE:7)
Block(0,0,7,CONCRETE:7)
Block(1,0,-6,CONCRETE:7)
Block(1,0,-5,CONCRETE:7)
Block(1,0,-4,CONCRETE:7)
Block(1,0,-3,CONCRETE:7)
Block(1,0,-2,CONCRETE:7)
Block(1,0,-1,CONCRETE:7)
Block(1,0,0,CONCRETE:7)
Block(1,0,1,CONCRETE:7)
Block(1,0,2,CONCRETE:7)
Block(1,0,3,CONCRETE:7)
Block(1,0,4,SMOOTH_BRICK:0)
Block(1,0,5,CONCRETE:7)
Block(1,0,6,CONCRETE:7)
Block(2,0,-6,CONCRETE:7)
Block(2,0,-5,CONCRETE:7)
Block(2,0,-4,CONCRETE:7)
Block(2,0,-3,CONCRETE:7)
Block(2,0,-2,CONCRETE:7)
Block(2,0,-1,CONCRETE:7)
Block(2,0,0,CONCRETE:7)
Block(2,0,1,CONCRETE:7)
Block(2,0,2,CONCRETE:7)
Block(2,0,3,CONCRETE:7)
Block(2,0,4,CONCRETE:7)
Block(2,0,5,CONCRETE:7)
Block(2,0,6,CONCRETE:7)
Block(3,0,-6,CONCRETE:7)
Block(3,0,-5,SMOOTH_BRICK:0)
Block(3,0,-4,CONCRETE:7)
Block(3,0,-3,CONCRETE:7)
Block(3,0,-2,CONCRETE:7)
Block(3,0,-1,CONCRETE:7)
Block(3,0,0,CONCRETE:7)
Block(3,0,1,CONCRETE:7)
Block(3,0,2,CONCRETE:7)
Block(3,0,3,CONCRETE:7)
Block(3,0,4,CONCRETE:7)
Block(3,0,5,CONCRETE:7)
Block(3,0,6,CONCRETE:7)
Block(4,0,-5,CONCRETE:7)
Block(4,0,-4,CONCRETE:7)
Block(4,0,-3,CONCRETE:7)
Block(4,0,-2,CONCRETE:7)
Block(4,0,-1,SMOOTH_BRICK:0)
Block(4,0,0,CONCRETE:7)
Block(4,0,1,CONCRETE:7)
Block(4,0,2,CONCRETE:7)
Block(4,0,3,CONCRETE:7)
Block(4,0,4,CONCRETE:7)
Block(4,0,5,CONCRETE:7)
Block(5,0,-4,CONCRETE:7)
Block(5,0,-3,CONCRETE:7)
Block(5,0,-2,CONCRETE:7)
Block(5,0,-1,CONCRETE:7)
Block(5,0,0,CONCRETE:7)
Block(5,0,1,CONCRETE:7)
Block(5,0,2,CONCRETE:7)
Block(5,0,3,SMOOTH_BRICK:0)
Block(5,0,4,CONCRETE:7)
Block(6,0,-3,CONCRETE:7)
Block(6,0,-2,CONCRETE:7)
Block(6,0,-1,CONCRETE:7)
Block(6,0,0,CONCRETE:7)
Block(6,0,1,CONCRETE:7)
Block(6,0,2,CONCRETE:7)
Block(6,0,3,CONCRETE:7)
Block(7,0,0,CONCRETE:7)
Block(-6,1,-2,CONCRETE:0)
Block(-6,2,-2,CONCRETE:0)
Block(-6,1,-1,CONCRETE:0)
Block(-6,2,-1,CONCRETE:0)
Block(-6,3,-1,CONCRETE:0)
Block(-6,1,0,CONCRETE:8)
Block(-6,2,0,CONCRETE:0)
Block(-6,3,0,CONCRETE:8)
Block(-6,1,1,CONCRETE:0)
Block(-6,2,1,CONCRETE:0)
Block(-6,3,1,CONCRETE:0)
Block(-6,1,2,CONCRETE:0)
Block(-6,2,2,CONCRETE:0)
Block(-5,1,-4,CONCRETE:0)
Block(-5,2,-4,CONCRETE:8)
Block(-5,1,-3,CONCRETE:0)
Block(-5,2,-3,CONCRETE:0)
Block(-5,3,-3,CONCRETE:0)
Block(-5,2,-2,CONCRETE:0)
Block(-5,3,-2,CONCRETE:0)
Block(-5,4,-2,CONCRETE:0)
Block(-5,3,-1,CONCRETE:0)
Block(-5,4,-1,CONCRETE:0)
Block(-5,5,-1,CONCRETE:0)
Block(-5,4,0,CONCRETE:0)
Block(-5,5,0,CONCRETE:0)
Block(-5,3,1,CONCRETE:8)
Block(-5,4,1,CONCRETE:0)
Block(-5,5,1,CONCRETE:8)
Block(-5,2,2,CONCRETE:0)
Block(-5,3,2,CONCRETE:0)
Block(-5,4,2,CONCRETE:0)
Block(-5,1,3,CONCRETE:0)
Block(-5,2,3,CONCRETE:0)
Block(-5,3,3,CONCRETE:0)
Block(-5,1,4,CONCRETE:8)
Block(-5,2,4,CONCRETE:0)
Block(-4,1,-5,CONCRETE:8)
Block(-4,2,-5,CONCRETE:0)
Block(-4,1,-4,CONCRETE:0)
Block(-4,2,-4,CONCRETE:0)
Block(-4,3,-4,CONCRETE:0)
Block(-4,4,-4,CONCRETE:0)
Block(-4,4,-3,CONCRETE:8)
Block(-4,5,-3,CONCRETE:0)
Block(-4,5,-2,CONCRETE:0)
Block(-4,5,-1,CONCRETE:0)
Block(-4,6,-1,CONCRETE:0)
Block(-4,5,0,CONCRETE:0)
Block(-4,6,0,CONCRETE:0)
Block(-4,5,1,CONCRETE:0)
Block(-4,6,1,CONCRETE:0)
Block(-4,5,2,CONCRETE:8)
Block(-4,4,3,CONCRETE:0)
Block(-4,5,3,CONCRETE:0)
Block(-4,1,4,CONCRETE:0)
Block(-4,2,4,CONCRETE:0)
Block(-4,3,4,CONCRETE:0)
Block(-4,4,4,CONCRETE:0)
Block(-4,1,5,CONCRETE:8)
Block(-4,2,5,CONCRETE:0)
Block(-3,1,-5,CONCRETE:0)
Block(-3,2,-5,CONCRETE:0)
Block(-3,3,-5,CONCRETE:0)
Block(-3,4,-4,CONCRETE:0)
Block(-3,5,-4,CONCRETE:0)
Block(-3,5,-3,CONCRETE:0)
Block(-3,6,-2,CONCRETE:8)
Block(-3,6,-1,CONCRETE:0)
Block(-3,6,0,CONCRETE:0)
Block(-3,6,1,CONCRETE:0)
Block(-3,6,2,CONCRETE:0)
Block(-3,5,3,CONCRETE:0)
Block(-3,4,4,CONCRETE:0)
Block(-3,5,4,CONCRETE:0)
Block(-3,1,5,CONCRETE:0)
Block(-3,2,5,CONCRETE:0)
Block(-3,3,5,CONCRETE:0)
Block(-2,1,-6,CONCRETE:0)
Block(-2,2,-6,CONCRETE:0)
Block(-2,2,-5,CONCRETE:0)
Block(-2,3,-5,CONCRETE:0)
Block(-2,4,-5,CONCRETE:0)
Block(-2,5,-4,CONCRETE:0)
Block(-2,6,-3,CONCRETE:0)
Block(-2,6,-2,CONCRETE:0)
Block(-2,6,-1,CONCRETE:0)
Block(-2,7,-1,CONCRETE:0)
Block(-2,7,0,CONCRETE:0)
Block(-2,6,1,CONCRETE:0)
Block(-2,7,1,CONCRETE:0)
Block(-2,6,2,CONCRETE:8)
Block(-2,6,3,CONCRETE:0)
Block(-2,5,4,CONCRETE:0)
Block(-2,2,5,CONCRETE:8)
Block(-2,3,5,CONCRETE:0)
Block(-2,4,5,CONCRETE:0)
Block(-2,1,6,CONCRETE:0)
Block(-2,2,6,CONCRETE:0)
Block(-1,1,-6,CONCRETE:0)
Block(-1,2,-6,CONCRETE:0)
Block(-1,3,-6,CONCRETE:0)
Block(-1,3,-5,CONCRETE:0)
Block(-1,4,-5,CONCRETE:0)
Block(-1,5,-5,CONCRETE:0)
Block(-1,5,-4,CONCRETE:0)
Block(-1,6,-4,CONCRETE:0)
Block(-1,6,-3,CONCRETE:0)
Block(-1,6,-2,CONCRETE:0)
Block(-1,7,-2,CONCRETE:8)
Block(-1,7,-1,CONCRETE:0)
Block(-1,7,0,CONCRETE:0)
Block(-1,7,1,CONCRETE:0)
Block(-1,6,2,CONCRETE:0)
Block(-1,7,2,CONCRETE:0)
Block(-1,6,3,CONCRETE:8)
Block(-1,5,4,CONCRETE:0)
Block(-1,6,4,CONCRETE:0)
Block(-1,3,5,CONCRETE:0)
Block(-1,4,5,CONCRETE:0)
Block(-1,5,5,CONCRETE:0)
Block(-1,1,6,CONCRETE:0)
Block(-1,2,6,CONCRETE:8)
Block(-1,3,6,CONCRETE:0)
Block(0,1,-6,CONCRETE:0)
Block(0,2,-6,CONCRETE:0)
Block(0,3,-6,CONCRETE:0)
Block(0,4,-5,CONCRETE:0)
Block(0,5,-5,CONCRETE:0)
Block(0,5,-4,CONCRETE:0)
Block(0,6,-4,CONCRETE:0)
Block(0,6,-3,CONCRETE:0)
Block(0,7,-2,CONCRETE:0)
Block(0,7,-1,CONCRETE:8)
Block(0,7,0,CONCRETE:0)
Block(0,7,1,CONCRETE:0)
Block(0,7,2,CONCRETE:0)
Block(0,6,3,CONCRETE:0)
Block(0,5,4,CONCRETE:0)
Block(0,6,4,CONCRETE:0)
Block(0,4,5,CONCRETE:0)
Block(0,5,5,CONCRETE:0)
Block(0,1,6,CONCRETE:0)
Block(0,2,6,CONCRETE:0)
Block(0,3,6,CONCRETE:0)
Block(1,1,-6,CONCRETE:0)
Block(1,2,-6,CONCRETE:0)
Block(1,3,-6,CONCRETE:0)
Block(1,3,-5,CONCRETE:0)
Block(1,4,-5,CONCRETE:0)
Block(1,5,-5,CONCRETE:0)
Block(1,5,-4,CONCRETE:0)
Block(1,6,-4,CONCRETE:0)
Block(1,6,-3,CONCRETE:0)
Block(1,6,-2,CONCRETE:8)
Block(1,7,-2,CONCRETE:0)
Block(1,7,-1,CONCRETE:0)
Block(1,7,0,CONCRETE:0)
Block(1,7,1,CONCRETE:0)
Block(1,6,2,CONCRETE:0)
Block(1,7,2,CONCRETE:0)
Block(1,6,3,CONCRETE:0)
Block(1,5,4,CONCRETE:0)
Block(1,6,4,CONCRETE:0)
Block(1,3,5,CONCRETE:0)
Block(1,4,5,CONCRETE:0)
Block(1,5,5,CONCRETE:0)
Block(1,1,6,CONCRETE:8)
Block(1,2,6,CONCRETE:0)
Block(1,3,6,CONCRETE:8)
Block(2,1,-6,CONCRETE:0)
Block(2,2,-6,CONCRETE:0)
Block(2,2,-5,CONCRETE:0)
Block(2,3,-5,CONCRETE:0)
Block(2,4,-5,CONCRETE:0)
Block(2,5,-4,CONCRETE:0)
Block(2,6,-3,CONCRETE:0)
Block(2,6,-2,CONCRETE:0)
Block(2,6,-1,CONCRETE:8)
Block(2,7,-1,CONCRETE:0)
Block(2,7,0,CONCRETE:0)
Block(2,6,1,CONCRETE:0)
Block(2,7,1,CONCRETE:0)
Block(2,6,2,CONCRETE:0)
Block(2,6,3,CONCRETE:0)
Block(2,5,4,CONCRETE:0)
Block(2,2,5,CONCRETE:0)
Block(2,3,5,CONCRETE:0)
Block(2,4,5,CONCRETE:0)
Block(2,1,6,CONCRETE:0)
Block(2,2,6,CONCRETE:0)
Block(3,1,-5,CONCRETE:0)
Block(3,2,-5,CONCRETE:0)
Block(3,3,-5,CONCRETE:0)
Block(3,4,-4,CONCRETE:0)
Block(3,5,-4,CONCRETE:0)
Block(3,5,-3,CONCRETE:0)
Block(3,6,-2,CONCRETE:0)
Block(3,6,-1,CONCRETE:0)
Block(3,6,0,CONCRETE:0)
Block(3,6,1,CONCRETE:0)
Block(3,6,2,CONCRETE:0)
Block(3,5,3,CONCRETE:0)
Block(3,4,4,CONCRETE:0)
Block(3,5,4,CONCRETE:0)
Block(3,1,5,CONCRETE:0)
Block(3,2,5,CONCRETE:0)
Block(3,3,5,CONCRETE:0)
Block(4,1,-5,CONCRETE:0)
Block(4,2,-5,CONCRETE:0)
Block(4,1,-4,CONCRETE:0)
Block(4,2,-4,CONCRETE:0)
Block(4,3,-4,CONCRETE:0)
Block(4,4,-4,CONCRETE:0)
Block(4,4,-3,CONCRETE:0)
Block(4,5,-3,CONCRETE:0)
Block(4,5,-2,CONCRETE:0)
Block(4,5,-1,CONCRETE:8)
Block(4,6,-1,CONCRETE:0)
Block(4,5,0,CONCRETE:0)
Block(4,6,0,CONCRETE:0)
Block(4,5,1,CONCRETE:0)
Block(4,6,1,CONCRETE:0)
Block(4,5,2,CONCRETE:0)
Block(4,4,3,CONCRETE:0)
Block(4,5,3,CONCRETE:0)
Block(4,1,4,CONCRETE:0)
Block(4,2,4,CONCRETE:0)
Block(4,3,4,CONCRETE:0)
Block(4,4,4,CONCRETE:0)
Block(4,1,5,CONCRETE:0)
Block(4,2,5,CONCRETE:0)
Block(5,1,-4,CONCRETE:0)
Block(5,2,-4,CONCRETE:0)
Block(5,1,-3,CONCRETE:0)
Block(5,2,-3,CONCRETE:0)
Block(5,3,-3,CONCRETE:0)
Block(5,2,-2,CONCRETE:8)
Block(5,3,-2,CONCRETE:0)
Block(5,4,-2,CONCRETE:8)
Block(5,3,-1,CONCRETE:0)
Block(5,4,-1,CONCRETE:0)
Block(5,5,-1,CONCRETE:0)
Block(5,4,0,CONCRETE:0)
Block(5,5,0,CONCRETE:0)
Block(5,3,1,CONCRETE:0)
Block(5,4,1,CONCRETE:0)
Block(5,5,1,CONCRETE:0)
Block(5,2,2,CONCRETE:0)
Block(5,3,2,CONCRETE:0)
Block(5,4,2,CONCRETE:0)
Block(5,1,3,CONCRETE:0)
Block(5,2,3,CONCRETE:0)
Block(5,3,3,CONCRETE:8)
Block(5,1,4,CONCRETE:0)
Block(5,2,4,CONCRETE:0)
Block(6,1,-2,CONCRETE:0)
Block(6,2,-2,CONCRETE:0)
Block(6,1,-1,CONCRETE:0)
Block(6,2,-1,CONCRETE:0)
Block(6,3,-1,CONCRETE:0)
Block(6,1,0,CONCRETE:0)
Block(6,2,0,CONCRETE:0)
Block(6,3,0,CONCRETE:0)
Block(6,1,1,CONCRETE:0)
Block(6,2,1,CONCRETE:0)
Block(6,3,1,CONCRETE:0)
Block(6,1,2,CONCRETE:0)
Block(6,2,2,CONCRETE:8)
Block(0,1,-6,AIR)
Block(0,2,-6,AIR)
Block(0,3,-6,AIR)
Block(7,1,0,dregorarl_srpmanhunt:encounter_marker:10)
Block(-7,1,0,dregorarl_srpmanhunt:encounter_marker:13)
Block(6,1,4,dregorarl_srpmanhunt:encounter_marker)
Block(-5,1,-4,dregorarl_srpmanhunt:encounter_marker:13)

#######################################################################
# +-----------------------------------------------------------------+ #
# |                             Branches                            | #
# +-----------------------------------------------------------------+ #
#######################################################################


#######################################################################
# +-----------------------------------------------------------------+ #
# |                             Entities                            | #
# +-----------------------------------------------------------------+ #
#######################################################################


#######################################################################
# +-----------------------------------------------------------------+ #
# |                            Particles                            | #
# +-----------------------------------------------------------------+ #
#######################################################################


#######################################################################
# +-----------------------------------------------------------------+ #
# |                             Spawners                            | #
# +-----------------------------------------------------------------+ #
#######################################################################


#######################################################################
# +-----------------------------------------------------------------+ #
# |                             ModData                             | #
# +-----------------------------------------------------------------+ #
#######################################################################

