
#######################################################################
# +-----------------------------------------------------------------+ #
# |                            BO4 object                           | #
# +-----------------------------------------------------------------+ #
#######################################################################

Author: NLBlackEagle

Description: No description given

SettingsMode: WriteWithoutComments


#######################################################################
# +-----------------------------------------------------------------+ #
# |                          Main settings                          | #
# +-----------------------------------------------------------------+ #
#######################################################################

FixedRotation: 

Frequency: 0

SpawnHeight: randomY

UseCenterForHighestBlock: true

##############################
# Height Limits for the BO4. #
##############################

MinHeight: 1

MaxHeight: 1

InheritBO3: 

InheritBO3Rotation: NORTH

OverrideChildSettings: true

OverrideParentHeight: true

CanOverride: true

BranchFrequency: 0

BranchFrequencyGroup: 

MustBeBelowOther: false

MustBeInside: 

CannotBeInside: 

ReplacesBO3: 

MustBeInsideWorldBorders: true

CanSpawnOnWater: true

SpawnOnWaterOnly: false

SpawnUnderWater: false

SpawnAtWaterLevel: false

HeightOffset: 0

RemoveAir: false

ReplaceAbove: 

ReplaceBelow: 

ReplaceWithBiomeBlocks: true

ReplaceWithSurfaceBlock: GRASS

ReplaceWithGroundBlock: DIRT

ReplaceWithStoneBlock: STONE

SmoothRadius: 0

SmoothHeightOffset: 0

SmoothStartTop: false

SmoothStartWood: false

SmoothingSurfaceBlock: 

SmoothingGroundBlock: 

BO3Group: 

IsSpawnPoint: false

DoReplaceBlocks: false


#######################################################################
# +-----------------------------------------------------------------+ #
# |                              Blocks                             | #
# +-----------------------------------------------------------------+ #
#######################################################################

RandomBlock(5,0,-6,quark:iron_plate:1,70,STAINED_CLAY:15,30,STAINED_CLAY:7,30,quark:iron_plate:1,100)
RandomBlock(5,0,-5,quark:iron_plate:1,70,STAINED_CLAY:15,30,STAINED_CLAY:7,30,quark:iron_plate:1,100)
RandomBlock(5,0,-4,IRON_FENCE:0,30,IRON_FENCE:0,30,LEAVES:7,30,quark:iron_plate_stairs:6,10,quark:iron_plate_stairs:0,10,quark:iron_plate_stairs:5,10,quark:iron_plate_stairs:3,10,quark:iron_plate_slab:8,10,quark:iron_plate_stairs:7,10,quark:iron_plate_stairs:1,10,quark:iron_plate_slab:0,10,quark:iron_plate_stairs:4,10,quark:iron_plate_stairs:2,10,IRON_FENCE:0,50,IRON_FENCE:0,50,LEAVES:7,100)
RandomBlock(5,0,-3,IRON_FENCE:0,30,IRON_FENCE:0,30,LEAVES:7,30,quark:iron_plate_stairs:6,10,quark:iron_plate_stairs:0,10,quark:iron_plate_stairs:5,10,quark:iron_plate_stairs:3,10,quark:iron_plate_slab:8,10,quark:iron_plate_stairs:7,10,quark:iron_plate_stairs:1,10,quark:iron_plate_slab:0,10,quark:iron_plate_stairs:4,10,quark:iron_plate_stairs:2,10,IRON_FENCE:0,50,IRON_FENCE:0,50,LEAVES:7,100)
RandomBlock(5,1,-6,quark:iron_plate:1,70,STAINED_CLAY:15,30,STAINED_CLAY:7,30,quark:iron_plate:1,100)
RandomBlock(5,1,-5,quark:iron_plate:1,70,STAINED_CLAY:15,30,STAINED_CLAY:7,30,quark:iron_plate:1,100)
RandomBlock(5,1,-4,quark:iron_plate:1,70,STAINED_CLAY:15,30,STAINED_CLAY:7,30,quark:iron_plate:1,100)
RandomBlock(5,1,-3,IRON_FENCE:0,30,IRON_FENCE:0,30,LEAVES:7,30,quark:iron_plate_stairs:6,10,quark:iron_plate_stairs:0,10,quark:iron_plate_stairs:5,10,quark:iron_plate_stairs:3,10,quark:iron_plate_slab:8,10,quark:iron_plate_stairs:7,10,quark:iron_plate_stairs:1,10,quark:iron_plate_slab:0,10,quark:iron_plate_stairs:4,10,quark:iron_plate_stairs:2,10,IRON_FENCE:0,50,IRON_FENCE:0,50,LEAVES:7,100)
RandomBlock(5,2,-6,quark:iron_plate:1,70,STAINED_CLAY:15,30,STAINED_CLAY:7,30,quark:iron_plate:1,100)
RandomBlock(5,2,-5,quark:iron_plate:1,70,STAINED_CLAY:15,30,STAINED_CLAY:7,30,quark:iron_plate:1,100)
RandomBlock(5,2,-4,quark:iron_plate:1,70,STAINED_CLAY:15,30,STAINED_CLAY:7,30,quark:iron_plate:1,100)
RandomBlock(5,2,-3,quark:iron_plate:1,70,STAINED_CLAY:15,30,STAINED_CLAY:7,30,quark:iron_plate:1,100)
RandomBlock(5,3,-6,quark:iron_plate:1,70,STAINED_CLAY:15,30,STAINED_CLAY:7,30,quark:iron_plate:1,100)
RandomBlock(5,3,-5,quark:iron_plate:1,70,STAINED_CLAY:15,30,STAINED_CLAY:7,30,quark:iron_plate:1,100)
RandomBlock(5,3,-4,quark:iron_plate:1,70,STAINED_CLAY:15,30,STAINED_CLAY:7,30,quark:iron_plate:1,100)
RandomBlock(5,3,-3,IRON_FENCE:0,30,IRON_FENCE:0,30,LEAVES:7,30,quark:iron_plate_stairs:6,10,quark:iron_plate_stairs:0,10,quark:iron_plate_stairs:5,10,quark:iron_plate_stairs:3,10,quark:iron_plate_slab:8,10,quark:iron_plate_stairs:7,10,quark:iron_plate_stairs:1,10,quark:iron_plate_slab:0,10,quark:iron_plate_stairs:4,10,quark:iron_plate_stairs:2,10,IRON_FENCE:0,50,IRON_FENCE:0,50,LEAVES:7,100)
RandomBlock(5,4,-6,quark:iron_plate:1,70,STAINED_CLAY:15,30,STAINED_CLAY:7,30,quark:iron_plate:1,100)
RandomBlock(5,4,-5,quark:iron_plate:1,70,STAINED_CLAY:15,30,STAINED_CLAY:7,30,quark:iron_plate:1,100)
RandomBlock(5,4,-4,quark:iron_plate:1,70,STAINED_CLAY:15,30,STAINED_CLAY:7,30,quark:iron_plate:1,100)
RandomBlock(5,4,-3,IRON_FENCE:0,30,IRON_FENCE:0,30,LEAVES:7,30,quark:iron_plate_stairs:6,10,quark:iron_plate_stairs:0,10,quark:iron_plate_stairs:5,10,quark:iron_plate_stairs:3,10,quark:iron_plate_slab:8,10,quark:iron_plate_stairs:7,10,quark:iron_plate_stairs:1,10,quark:iron_plate_slab:0,10,quark:iron_plate_stairs:4,10,quark:iron_plate_stairs:2,10,IRON_FENCE:0,50,IRON_FENCE:0,50,LEAVES:7,100)
RandomBlock(5,5,-6,quark:iron_plate:1,70,STAINED_CLAY:15,30,STAINED_CLAY:7,30,quark:iron_plate:1,100)
RandomBlock(5,5,-5,quark:iron_plate:1,70,STAINED_CLAY:15,30,STAINED_CLAY:7,30,quark:iron_plate:1,100)
RandomBlock(5,5,-4,quark:iron_plate:1,70,STAINED_CLAY:15,30,STAINED_CLAY:7,30,quark:iron_plate:1,100)
RandomBlock(5,5,-3,quark:iron_plate:1,70,STAINED_CLAY:15,30,STAINED_CLAY:7,30,quark:iron_plate:1,100)
RandomBlock(5,6,-6,quark:iron_plate:1,70,STAINED_CLAY:15,30,STAINED_CLAY:7,30,quark:iron_plate:1,100)
RandomBlock(5,6,-5,quark:iron_plate:1,70,STAINED_CLAY:15,30,STAINED_CLAY:7,30,quark:iron_plate:1,100)
RandomBlock(5,6,-4,quark:iron_plate:1,70,STAINED_CLAY:15,30,STAINED_CLAY:7,30,quark:iron_plate:1,100)
RandomBlock(5,6,-3,quark:iron_plate:1,70,STAINED_CLAY:15,30,STAINED_CLAY:7,30,quark:iron_plate:1,100)
RandomBlock(5,7,-6,quark:iron_plate:1,70,STAINED_CLAY:15,30,STAINED_CLAY:7,30,quark:iron_plate:1,100)
RandomBlock(5,7,-5,quark:iron_plate:1,70,STAINED_CLAY:15,30,STAINED_CLAY:7,30,quark:iron_plate:1,100)
RandomBlock(5,7,-4,quark:iron_plate:1,70,STAINED_CLAY:15,30,STAINED_CLAY:7,30,quark:iron_plate:1,100)
RandomBlock(5,7,-3,quark:iron_plate:1,70,STAINED_CLAY:15,30,STAINED_CLAY:7,30,quark:iron_plate:1,100)
RandomBlock(5,8,-6,quark:iron_plate:1,70,STAINED_CLAY:15,30,STAINED_CLAY:7,30,quark:iron_plate:1,100)
RandomBlock(5,8,-5,quark:iron_plate:1,70,STAINED_CLAY:15,30,STAINED_CLAY:7,30,quark:iron_plate:1,100)
RandomBlock(5,8,-4,quark:iron_plate:1,70,STAINED_CLAY:15,30,STAINED_CLAY:7,30,quark:iron_plate:1,100)
RandomBlock(5,8,-3,quark:iron_plate:1,70,STAINED_CLAY:15,30,STAINED_CLAY:7,30,quark:iron_plate:1,100)
RandomBlock(5,9,-6,quark:iron_plate:1,70,STAINED_CLAY:15,30,STAINED_CLAY:7,30,quark:iron_plate:1,100)
RandomBlock(5,9,-5,quark:iron_plate:1,70,STAINED_CLAY:15,30,STAINED_CLAY:7,30,quark:iron_plate:1,100)
RandomBlock(5,9,-4,quark:iron_plate:1,70,STAINED_CLAY:15,30,STAINED_CLAY:7,30,quark:iron_plate:1,100)
RandomBlock(5,9,-3,IRON_FENCE:0,30,IRON_FENCE:0,30,LEAVES:7,30,quark:iron_plate_stairs:6,10,quark:iron_plate_stairs:0,10,quark:iron_plate_stairs:5,10,quark:iron_plate_stairs:3,10,quark:iron_plate_slab:8,10,quark:iron_plate_stairs:7,10,quark:iron_plate_stairs:1,10,quark:iron_plate_slab:0,10,quark:iron_plate_stairs:4,10,quark:iron_plate_stairs:2,10,IRON_FENCE:0,50,IRON_FENCE:0,50,LEAVES:7,100)
RandomBlock(5,10,-6,quark:iron_plate:1,70,STAINED_CLAY:15,30,STAINED_CLAY:7,30,quark:iron_plate:1,100)
RandomBlock(5,10,-5,quark:iron_plate:1,70,STAINED_CLAY:15,30,STAINED_CLAY:7,30,quark:iron_plate:1,100)
RandomBlock(5,10,-4,IRON_FENCE:0,30,IRON_FENCE:0,30,LEAVES:7,30,quark:iron_plate_stairs:6,10,quark:iron_plate_stairs:0,10,quark:iron_plate_stairs:5,10,quark:iron_plate_stairs:3,10,quark:iron_plate_slab:8,10,quark:iron_plate_stairs:7,10,quark:iron_plate_stairs:1,10,quark:iron_plate_slab:0,10,quark:iron_plate_stairs:4,10,quark:iron_plate_stairs:2,10,IRON_FENCE:0,50,IRON_FENCE:0,50,LEAVES:7,100)
RandomBlock(5,10,-3,IRON_FENCE:0,30,IRON_FENCE:0,30,LEAVES:7,30,quark:iron_plate_stairs:6,10,quark:iron_plate_stairs:0,10,quark:iron_plate_stairs:5,10,quark:iron_plate_stairs:3,10,quark:iron_plate_slab:8,10,quark:iron_plate_stairs:7,10,quark:iron_plate_stairs:1,10,quark:iron_plate_slab:0,10,quark:iron_plate_stairs:4,10,quark:iron_plate_stairs:2,10,IRON_FENCE:0,50,IRON_FENCE:0,50,LEAVES:7,100)
RandomBlock(5,11,-6,quark:iron_plate:1,70,STAINED_CLAY:15,30,STAINED_CLAY:7,30,quark:iron_plate:1,100)
RandomBlock(5,11,-5,IRON_FENCE:0,30,IRON_FENCE:0,30,LEAVES:7,30,quark:iron_plate_stairs:6,10,quark:iron_plate_stairs:0,10,quark:iron_plate_stairs:5,10,quark:iron_plate_stairs:3,10,quark:iron_plate_slab:8,10,quark:iron_plate_stairs:7,10,quark:iron_plate_stairs:1,10,quark:iron_plate_slab:0,10,quark:iron_plate_stairs:4,10,quark:iron_plate_stairs:2,10,IRON_FENCE:0,50,IRON_FENCE:0,50,LEAVES:7,100)
RandomBlock(5,11,-4,IRON_FENCE:0,30,IRON_FENCE:0,30,LEAVES:7,30,quark:iron_plate_stairs:6,10,quark:iron_plate_stairs:0,10,quark:iron_plate_stairs:5,10,quark:iron_plate_stairs:3,10,quark:iron_plate_slab:8,10,quark:iron_plate_stairs:7,10,quark:iron_plate_stairs:1,10,quark:iron_plate_slab:0,10,quark:iron_plate_stairs:4,10,quark:iron_plate_stairs:2,10,IRON_FENCE:0,50,IRON_FENCE:0,50,LEAVES:7,100)
RandomBlock(5,11,-3,IRON_FENCE:0,30,IRON_FENCE:0,30,LEAVES:7,30,quark:iron_plate_stairs:6,10,quark:iron_plate_stairs:0,10,quark:iron_plate_stairs:5,10,quark:iron_plate_stairs:3,10,quark:iron_plate_slab:8,10,quark:iron_plate_stairs:7,10,quark:iron_plate_stairs:1,10,quark:iron_plate_slab:0,10,quark:iron_plate_stairs:4,10,quark:iron_plate_stairs:2,10,IRON_FENCE:0,50,IRON_FENCE:0,50,LEAVES:7,100)
RandomBlock(5,12,-6,quark:iron_plate:1,70,STAINED_CLAY:15,30,STAINED_CLAY:7,30,quark:iron_plate:1,100)
RandomBlock(5,12,-5,quark:iron_plate:1,70,STAINED_CLAY:15,30,STAINED_CLAY:7,30,quark:iron_plate:1,100)
RandomBlock(5,12,-4,IRON_FENCE:0,30,IRON_FENCE:0,30,LEAVES:7,30,quark:iron_plate_stairs:6,10,quark:iron_plate_stairs:0,10,quark:iron_plate_stairs:5,10,quark:iron_plate_stairs:3,10,quark:iron_plate_slab:8,10,quark:iron_plate_stairs:7,10,quark:iron_plate_stairs:1,10,quark:iron_plate_slab:0,10,quark:iron_plate_stairs:4,10,quark:iron_plate_stairs:2,10,IRON_FENCE:0,50,IRON_FENCE:0,50,LEAVES:7,100)
RandomBlock(5,12,-3,quark:iron_plate:1,70,STAINED_CLAY:15,30,STAINED_CLAY:7,30,quark:iron_plate:1,100)
RandomBlock(5,13,-6,quark:iron_plate:1,70,STAINED_CLAY:15,30,STAINED_CLAY:7,30,quark:iron_plate:1,100)
RandomBlock(5,13,-5,IRON_FENCE:0,30,IRON_FENCE:0,30,LEAVES:7,30,quark:iron_plate_stairs:6,10,quark:iron_plate_stairs:0,10,quark:iron_plate_stairs:5,10,quark:iron_plate_stairs:3,10,quark:iron_plate_slab:8,10,quark:iron_plate_stairs:7,10,quark:iron_plate_stairs:1,10,quark:iron_plate_slab:0,10,quark:iron_plate_stairs:4,10,quark:iron_plate_stairs:2,10,IRON_FENCE:0,50,IRON_FENCE:0,50,LEAVES:7,100)
RandomBlock(5,13,-4,IRON_FENCE:0,30,IRON_FENCE:0,30,LEAVES:7,30,quark:iron_plate_stairs:6,10,quark:iron_plate_stairs:0,10,quark:iron_plate_stairs:5,10,quark:iron_plate_stairs:3,10,quark:iron_plate_slab:8,10,quark:iron_plate_stairs:7,10,quark:iron_plate_stairs:1,10,quark:iron_plate_slab:0,10,quark:iron_plate_stairs:4,10,quark:iron_plate_stairs:2,10,IRON_FENCE:0,50,IRON_FENCE:0,50,LEAVES:7,100)
RandomBlock(5,13,-3,IRON_FENCE:0,30,IRON_FENCE:0,30,LEAVES:7,30,quark:iron_plate_stairs:6,10,quark:iron_plate_stairs:0,10,quark:iron_plate_stairs:5,10,quark:iron_plate_stairs:3,10,quark:iron_plate_slab:8,10,quark:iron_plate_stairs:7,10,quark:iron_plate_stairs:1,10,quark:iron_plate_slab:0,10,quark:iron_plate_stairs:4,10,quark:iron_plate_stairs:2,10,IRON_FENCE:0,50,IRON_FENCE:0,50,LEAVES:7,100)
RandomBlock(5,14,-6,quark:iron_plate:1,70,STAINED_CLAY:15,30,STAINED_CLAY:7,30,quark:iron_plate:1,100)
RandomBlock(5,14,-5,IRON_FENCE:0,30,IRON_FENCE:0,30,LEAVES:7,30,quark:iron_plate_stairs:6,10,quark:iron_plate_stairs:0,10,quark:iron_plate_stairs:5,10,quark:iron_plate_stairs:3,10,quark:iron_plate_slab:8,10,quark:iron_plate_stairs:7,10,quark:iron_plate_stairs:1,10,quark:iron_plate_slab:0,10,quark:iron_plate_stairs:4,10,quark:iron_plate_stairs:2,10,IRON_FENCE:0,50,IRON_FENCE:0,50,LEAVES:7,100)
RandomBlock(5,14,-4,IRON_FENCE:0,30,IRON_FENCE:0,30,LEAVES:7,30,quark:iron_plate_stairs:6,10,quark:iron_plate_stairs:0,10,quark:iron_plate_stairs:5,10,quark:iron_plate_stairs:3,10,quark:iron_plate_slab:8,10,quark:iron_plate_stairs:7,10,quark:iron_plate_stairs:1,10,quark:iron_plate_slab:0,10,quark:iron_plate_stairs:4,10,quark:iron_plate_stairs:2,10,IRON_FENCE:0,50,IRON_FENCE:0,50,LEAVES:7,100)
RandomBlock(5,14,-3,IRON_FENCE:0,30,IRON_FENCE:0,30,LEAVES:7,30,quark:iron_plate_stairs:6,10,quark:iron_plate_stairs:0,10,quark:iron_plate_stairs:5,10,quark:iron_plate_stairs:3,10,quark:iron_plate_slab:8,10,quark:iron_plate_stairs:7,10,quark:iron_plate_stairs:1,10,quark:iron_plate_slab:0,10,quark:iron_plate_stairs:4,10,quark:iron_plate_stairs:2,10,IRON_FENCE:0,50,IRON_FENCE:0,50,LEAVES:7,100)
RandomBlock(5,15,-6,quark:iron_plate:1,70,STAINED_CLAY:15,30,STAINED_CLAY:7,30,quark:iron_plate:1,100)
RandomBlock(5,15,-5,IRON_FENCE:0,30,IRON_FENCE:0,30,LEAVES:7,30,quark:iron_plate_stairs:6,10,quark:iron_plate_stairs:0,10,quark:iron_plate_stairs:5,10,quark:iron_plate_stairs:3,10,quark:iron_plate_slab:8,10,quark:iron_plate_stairs:7,10,quark:iron_plate_stairs:1,10,quark:iron_plate_slab:0,10,quark:iron_plate_stairs:4,10,quark:iron_plate_stairs:2,10,IRON_FENCE:0,50,IRON_FENCE:0,50,LEAVES:7,100)
RandomBlock(5,15,-4,IRON_FENCE:0,30,IRON_FENCE:0,30,LEAVES:7,30,quark:iron_plate_stairs:6,10,quark:iron_plate_stairs:0,10,quark:iron_plate_stairs:5,10,quark:iron_plate_stairs:3,10,quark:iron_plate_slab:8,10,quark:iron_plate_stairs:7,10,quark:iron_plate_stairs:1,10,quark:iron_plate_slab:0,10,quark:iron_plate_stairs:4,10,quark:iron_plate_stairs:2,10,IRON_FENCE:0,50,IRON_FENCE:0,50,LEAVES:7,100)
RandomBlock(5,15,-3,quark:iron_plate:1,70,STAINED_CLAY:15,30,STAINED_CLAY:7,30,quark:iron_plate:1,100)
RandomBlock(5,16,-6,IRON_FENCE:0,30,IRON_FENCE:0,30,LEAVES:7,30,quark:iron_plate_stairs:6,10,quark:iron_plate_stairs:0,10,quark:iron_plate_stairs:5,10,quark:iron_plate_stairs:3,10,quark:iron_plate_slab:8,10,quark:iron_plate_stairs:7,10,quark:iron_plate_stairs:1,10,quark:iron_plate_slab:0,10,quark:iron_plate_stairs:4,10,quark:iron_plate_stairs:2,10,IRON_FENCE:0,50,IRON_FENCE:0,50,LEAVES:7,100)
RandomBlock(5,16,-5,IRON_FENCE:0,30,IRON_FENCE:0,30,LEAVES:7,30,quark:iron_plate_stairs:6,10,quark:iron_plate_stairs:0,10,quark:iron_plate_stairs:5,10,quark:iron_plate_stairs:3,10,quark:iron_plate_slab:8,10,quark:iron_plate_stairs:7,10,quark:iron_plate_stairs:1,10,quark:iron_plate_slab:0,10,quark:iron_plate_stairs:4,10,quark:iron_plate_stairs:2,10,IRON_FENCE:0,50,IRON_FENCE:0,50,LEAVES:7,100)
RandomBlock(5,16,-4,IRON_FENCE:0,30,IRON_FENCE:0,30,LEAVES:7,30,quark:iron_plate_stairs:6,10,quark:iron_plate_stairs:0,10,quark:iron_plate_stairs:5,10,quark:iron_plate_stairs:3,10,quark:iron_plate_slab:8,10,quark:iron_plate_stairs:7,10,quark:iron_plate_stairs:1,10,quark:iron_plate_slab:0,10,quark:iron_plate_stairs:4,10,quark:iron_plate_stairs:2,10,IRON_FENCE:0,50,IRON_FENCE:0,50,LEAVES:7,100)
RandomBlock(5,16,-3,quark:iron_plate:1,70,STAINED_CLAY:15,30,STAINED_CLAY:7,30,quark:iron_plate:1,100)
RandomBlock(5,17,-6,IRON_FENCE:0,30,IRON_FENCE:0,30,LEAVES:7,30,quark:iron_plate_stairs:6,10,quark:iron_plate_stairs:0,10,quark:iron_plate_stairs:5,10,quark:iron_plate_stairs:3,10,quark:iron_plate_slab:8,10,quark:iron_plate_stairs:7,10,quark:iron_plate_stairs:1,10,quark:iron_plate_slab:0,10,quark:iron_plate_stairs:4,10,quark:iron_plate_stairs:2,10,IRON_FENCE:0,50,IRON_FENCE:0,50,LEAVES:7,100)
RandomBlock(5,17,-5,IRON_FENCE:0,30,IRON_FENCE:0,30,LEAVES:7,30,quark:iron_plate_stairs:6,10,quark:iron_plate_stairs:0,10,quark:iron_plate_stairs:5,10,quark:iron_plate_stairs:3,10,quark:iron_plate_slab:8,10,quark:iron_plate_stairs:7,10,quark:iron_plate_stairs:1,10,quark:iron_plate_slab:0,10,quark:iron_plate_stairs:4,10,quark:iron_plate_stairs:2,10,IRON_FENCE:0,50,IRON_FENCE:0,50,LEAVES:7,100)
RandomBlock(5,17,-4,IRON_FENCE:0,30,IRON_FENCE:0,30,LEAVES:7,30,quark:iron_plate_stairs:6,10,quark:iron_plate_stairs:0,10,quark:iron_plate_stairs:5,10,quark:iron_plate_stairs:3,10,quark:iron_plate_slab:8,10,quark:iron_plate_stairs:7,10,quark:iron_plate_stairs:1,10,quark:iron_plate_slab:0,10,quark:iron_plate_stairs:4,10,quark:iron_plate_stairs:2,10,IRON_FENCE:0,50,IRON_FENCE:0,50,LEAVES:7,100)
RandomBlock(5,17,-3,quark:iron_plate:1,70,STAINED_CLAY:15,30,STAINED_CLAY:7,30,quark:iron_plate:1,100)
RandomBlock(5,18,-6,quark:iron_plate:1,70,STAINED_CLAY:15,30,STAINED_CLAY:7,30,quark:iron_plate:1,100)
RandomBlock(5,18,-5,IRON_FENCE:0,30,IRON_FENCE:0,30,LEAVES:7,30,quark:iron_plate_stairs:6,10,quark:iron_plate_stairs:0,10,quark:iron_plate_stairs:5,10,quark:iron_plate_stairs:3,10,quark:iron_plate_slab:8,10,quark:iron_plate_stairs:7,10,quark:iron_plate_stairs:1,10,quark:iron_plate_slab:0,10,quark:iron_plate_stairs:4,10,quark:iron_plate_stairs:2,10,IRON_FENCE:0,50,IRON_FENCE:0,50,LEAVES:7,100)
RandomBlock(5,18,-4,IRON_FENCE:0,30,IRON_FENCE:0,30,LEAVES:7,30,quark:iron_plate_stairs:6,10,quark:iron_plate_stairs:0,10,quark:iron_plate_stairs:5,10,quark:iron_plate_stairs:3,10,quark:iron_plate_slab:8,10,quark:iron_plate_stairs:7,10,quark:iron_plate_stairs:1,10,quark:iron_plate_slab:0,10,quark:iron_plate_stairs:4,10,quark:iron_plate_stairs:2,10,IRON_FENCE:0,50,IRON_FENCE:0,50,LEAVES:7,100)
RandomBlock(5,18,-3,IRON_FENCE:0,30,IRON_FENCE:0,30,LEAVES:7,30,quark:iron_plate_stairs:6,10,quark:iron_plate_stairs:0,10,quark:iron_plate_stairs:5,10,quark:iron_plate_stairs:3,10,quark:iron_plate_slab:8,10,quark:iron_plate_stairs:7,10,quark:iron_plate_stairs:1,10,quark:iron_plate_slab:0,10,quark:iron_plate_stairs:4,10,quark:iron_plate_stairs:2,10,IRON_FENCE:0,50,IRON_FENCE:0,50,LEAVES:7,100)
RandomBlock(5,19,-6,quark:iron_plate:1,70,STAINED_CLAY:15,30,STAINED_CLAY:7,30,quark:iron_plate:1,100)
RandomBlock(5,19,-5,IRON_FENCE:0,30,IRON_FENCE:0,30,LEAVES:7,30,quark:iron_plate_stairs:6,10,quark:iron_plate_stairs:0,10,quark:iron_plate_stairs:5,10,quark:iron_plate_stairs:3,10,quark:iron_plate_slab:8,10,quark:iron_plate_stairs:7,10,quark:iron_plate_stairs:1,10,quark:iron_plate_slab:0,10,quark:iron_plate_stairs:4,10,quark:iron_plate_stairs:2,10,IRON_FENCE:0,50,IRON_FENCE:0,50,LEAVES:7,100)
RandomBlock(5,19,-4,IRON_FENCE:0,30,IRON_FENCE:0,30,LEAVES:7,30,quark:iron_plate_stairs:6,10,quark:iron_plate_stairs:0,10,quark:iron_plate_stairs:5,10,quark:iron_plate_stairs:3,10,quark:iron_plate_slab:8,10,quark:iron_plate_stairs:7,10,quark:iron_plate_stairs:1,10,quark:iron_plate_slab:0,10,quark:iron_plate_stairs:4,10,quark:iron_plate_stairs:2,10,IRON_FENCE:0,50,IRON_FENCE:0,50,LEAVES:7,100)
RandomBlock(5,19,-3,IRON_FENCE:0,30,IRON_FENCE:0,30,LEAVES:7,30,quark:iron_plate_stairs:6,10,quark:iron_plate_stairs:0,10,quark:iron_plate_stairs:5,10,quark:iron_plate_stairs:3,10,quark:iron_plate_slab:8,10,quark:iron_plate_stairs:7,10,quark:iron_plate_stairs:1,10,quark:iron_plate_slab:0,10,quark:iron_plate_stairs:4,10,quark:iron_plate_stairs:2,10,IRON_FENCE:0,50,IRON_FENCE:0,50,LEAVES:7,100)
RandomBlock(5,20,-6,IRON_FENCE:0,30,IRON_FENCE:0,30,LEAVES:7,30,quark:iron_plate_stairs:6,10,quark:iron_plate_stairs:0,10,quark:iron_plate_stairs:5,10,quark:iron_plate_stairs:3,10,quark:iron_plate_slab:8,10,quark:iron_plate_stairs:7,10,quark:iron_plate_stairs:1,10,quark:iron_plate_slab:0,10,quark:iron_plate_stairs:4,10,quark:iron_plate_stairs:2,10,IRON_FENCE:0,50,IRON_FENCE:0,50,LEAVES:7,100)
RandomBlock(5,20,-5,quark:iron_plate:1,70,STAINED_CLAY:15,30,STAINED_CLAY:7,30,quark:iron_plate:1,100)
RandomBlock(5,20,-4,IRON_FENCE:0,30,IRON_FENCE:0,30,LEAVES:7,30,quark:iron_plate_stairs:6,10,quark:iron_plate_stairs:0,10,quark:iron_plate_stairs:5,10,quark:iron_plate_stairs:3,10,quark:iron_plate_slab:8,10,quark:iron_plate_stairs:7,10,quark:iron_plate_stairs:1,10,quark:iron_plate_slab:0,10,quark:iron_plate_stairs:4,10,quark:iron_plate_stairs:2,10,IRON_FENCE:0,50,IRON_FENCE:0,50,LEAVES:7,100)
RandomBlock(5,20,-3,IRON_FENCE:0,30,IRON_FENCE:0,30,LEAVES:7,30,quark:iron_plate_stairs:6,10,quark:iron_plate_stairs:0,10,quark:iron_plate_stairs:5,10,quark:iron_plate_stairs:3,10,quark:iron_plate_slab:8,10,quark:iron_plate_stairs:7,10,quark:iron_plate_stairs:1,10,quark:iron_plate_slab:0,10,quark:iron_plate_stairs:4,10,quark:iron_plate_stairs:2,10,IRON_FENCE:0,50,IRON_FENCE:0,50,LEAVES:7,100)
RandomBlock(5,21,-6,IRON_FENCE:0,30,IRON_FENCE:0,30,LEAVES:7,30,quark:iron_plate_stairs:6,10,quark:iron_plate_stairs:0,10,quark:iron_plate_stairs:5,10,quark:iron_plate_stairs:3,10,quark:iron_plate_slab:8,10,quark:iron_plate_stairs:7,10,quark:iron_plate_stairs:1,10,quark:iron_plate_slab:0,10,quark:iron_plate_stairs:4,10,quark:iron_plate_stairs:2,10,IRON_FENCE:0,50,IRON_FENCE:0,50,LEAVES:7,100)
RandomBlock(5,21,-5,quark:iron_plate:1,70,STAINED_CLAY:15,30,STAINED_CLAY:7,30,quark:iron_plate:1,100)
RandomBlock(5,21,-4,IRON_FENCE:0,30,IRON_FENCE:0,30,LEAVES:7,30,quark:iron_plate_stairs:6,10,quark:iron_plate_stairs:0,10,quark:iron_plate_stairs:5,10,quark:iron_plate_stairs:3,10,quark:iron_plate_slab:8,10,quark:iron_plate_stairs:7,10,quark:iron_plate_stairs:1,10,quark:iron_plate_slab:0,10,quark:iron_plate_stairs:4,10,quark:iron_plate_stairs:2,10,IRON_FENCE:0,50,IRON_FENCE:0,50,LEAVES:7,100)
RandomBlock(5,21,-3,IRON_FENCE:0,30,IRON_FENCE:0,30,LEAVES:7,30,quark:iron_plate_stairs:6,10,quark:iron_plate_stairs:0,10,quark:iron_plate_stairs:5,10,quark:iron_plate_stairs:3,10,quark:iron_plate_slab:8,10,quark:iron_plate_stairs:7,10,quark:iron_plate_stairs:1,10,quark:iron_plate_slab:0,10,quark:iron_plate_stairs:4,10,quark:iron_plate_stairs:2,10,IRON_FENCE:0,50,IRON_FENCE:0,50,LEAVES:7,100)
RandomBlock(5,22,-6,IRON_FENCE:0,30,IRON_FENCE:0,30,LEAVES:7,30,quark:iron_plate_stairs:6,10,quark:iron_plate_stairs:0,10,quark:iron_plate_stairs:5,10,quark:iron_plate_stairs:3,10,quark:iron_plate_slab:8,10,quark:iron_plate_stairs:7,10,quark:iron_plate_stairs:1,10,quark:iron_plate_slab:0,10,quark:iron_plate_stairs:4,10,quark:iron_plate_stairs:2,10,IRON_FENCE:0,50,IRON_FENCE:0,50,LEAVES:7,100)
RandomBlock(5,22,-5,IRON_FENCE:0,30,IRON_FENCE:0,30,LEAVES:7,30,quark:iron_plate_stairs:6,10,quark:iron_plate_stairs:0,10,quark:iron_plate_stairs:5,10,quark:iron_plate_stairs:3,10,quark:iron_plate_slab:8,10,quark:iron_plate_stairs:7,10,quark:iron_plate_stairs:1,10,quark:iron_plate_slab:0,10,quark:iron_plate_stairs:4,10,quark:iron_plate_stairs:2,10,IRON_FENCE:0,50,IRON_FENCE:0,50,LEAVES:7,100)
RandomBlock(5,22,-4,quark:iron_plate:1,70,STAINED_CLAY:15,30,STAINED_CLAY:7,30,quark:iron_plate:1,100)
RandomBlock(5,22,-3,IRON_FENCE:0,30,IRON_FENCE:0,30,LEAVES:7,30,quark:iron_plate_stairs:6,10,quark:iron_plate_stairs:0,10,quark:iron_plate_stairs:5,10,quark:iron_plate_stairs:3,10,quark:iron_plate_slab:8,10,quark:iron_plate_stairs:7,10,quark:iron_plate_stairs:1,10,quark:iron_plate_slab:0,10,quark:iron_plate_stairs:4,10,quark:iron_plate_stairs:2,10,IRON_FENCE:0,50,IRON_FENCE:0,50,LEAVES:7,100)
RandomBlock(5,23,-6,IRON_FENCE:0,30,IRON_FENCE:0,30,LEAVES:7,30,quark:iron_plate_stairs:6,10,quark:iron_plate_stairs:0,10,quark:iron_plate_stairs:5,10,quark:iron_plate_stairs:3,10,quark:iron_plate_slab:8,10,quark:iron_plate_stairs:7,10,quark:iron_plate_stairs:1,10,quark:iron_plate_slab:0,10,quark:iron_plate_stairs:4,10,quark:iron_plate_stairs:2,10,IRON_FENCE:0,50,IRON_FENCE:0,50,LEAVES:7,100)
RandomBlock(5,23,-5,quark:iron_plate:1,70,STAINED_CLAY:15,30,STAINED_CLAY:7,30,quark:iron_plate:1,100)
RandomBlock(5,23,-4,quark:iron_plate:1,70,STAINED_CLAY:15,30,STAINED_CLAY:7,30,quark:iron_plate:1,100)
RandomBlock(5,23,-3,quark:iron_plate:1,70,STAINED_CLAY:15,30,STAINED_CLAY:7,30,quark:iron_plate:1,100)
RandomBlock(5,24,-6,quark:iron_plate:1,70,STAINED_CLAY:15,30,STAINED_CLAY:7,30,quark:iron_plate:1,100)
RandomBlock(5,24,-5,quark:iron_plate:1,70,STAINED_CLAY:15,30,STAINED_CLAY:7,30,quark:iron_plate:1,100)
RandomBlock(5,24,-4,quark:iron_plate:1,70,STAINED_CLAY:15,30,STAINED_CLAY:7,30,quark:iron_plate:1,100)
RandomBlock(5,24,-3,quark:iron_plate:1,70,STAINED_CLAY:15,30,STAINED_CLAY:7,30,quark:iron_plate:1,100)
RandomBlock(5,25,-6,quark:iron_plate:1,70,STAINED_CLAY:15,30,STAINED_CLAY:7,30,quark:iron_plate:1,100)
RandomBlock(5,25,-5,quark:iron_plate:1,70,STAINED_CLAY:15,30,STAINED_CLAY:7,30,quark:iron_plate:1,100)
RandomBlock(5,25,-4,quark:iron_plate:1,70,STAINED_CLAY:15,30,STAINED_CLAY:7,30,quark:iron_plate:1,100)
RandomBlock(5,25,-3,quark:iron_plate:1,70,STAINED_CLAY:15,30,STAINED_CLAY:7,30,quark:iron_plate:1,100)
RandomBlock(5,26,-6,quark:iron_plate:1,70,STAINED_CLAY:15,30,STAINED_CLAY:7,30,quark:iron_plate:1,100)
RandomBlock(5,26,-5,quark:iron_plate:1,70,STAINED_CLAY:15,30,STAINED_CLAY:7,30,quark:iron_plate:1,100)
RandomBlock(5,26,-4,quark:iron_plate:1,70,STAINED_CLAY:15,30,STAINED_CLAY:7,30,quark:iron_plate:1,100)
RandomBlock(5,26,-3,quark:iron_plate:1,70,STAINED_CLAY:15,30,STAINED_CLAY:7,30,quark:iron_plate:1,100)
RandomBlock(5,27,-6,quark:iron_plate:1,70,STAINED_CLAY:15,30,STAINED_CLAY:7,30,quark:iron_plate:1,100)
RandomBlock(5,27,-5,quark:iron_plate:1,70,STAINED_CLAY:15,30,STAINED_CLAY:7,30,quark:iron_plate:1,100)
RandomBlock(5,27,-4,quark:iron_plate:1,70,STAINED_CLAY:15,30,STAINED_CLAY:7,30,quark:iron_plate:1,100)
RandomBlock(5,27,-3,quark:iron_plate:1,70,STAINED_CLAY:15,30,STAINED_CLAY:7,30,quark:iron_plate:1,100)
RandomBlock(5,28,-6,quark:iron_plate:1,70,STAINED_CLAY:15,30,STAINED_CLAY:7,30,quark:iron_plate:1,100)
RandomBlock(5,28,-5,quark:iron_plate:1,70,STAINED_CLAY:15,30,STAINED_CLAY:7,30,quark:iron_plate:1,100)
RandomBlock(5,28,-4,quark:iron_plate:1,70,STAINED_CLAY:15,30,STAINED_CLAY:7,30,quark:iron_plate:1,100)
RandomBlock(5,28,-3,quark:iron_plate:1,70,STAINED_CLAY:15,30,STAINED_CLAY:7,30,quark:iron_plate:1,100)
RandomBlock(5,29,-6,quark:iron_plate:1,70,STAINED_CLAY:15,30,STAINED_CLAY:7,30,quark:iron_plate:1,100)
RandomBlock(5,29,-5,quark:iron_plate:1,70,STAINED_CLAY:15,30,STAINED_CLAY:7,30,quark:iron_plate:1,100)
RandomBlock(5,29,-4,quark:iron_plate:1,70,STAINED_CLAY:15,30,STAINED_CLAY:7,30,quark:iron_plate:1,100)
RandomBlock(5,29,-3,quark:iron_plate:1,70,STAINED_CLAY:15,30,STAINED_CLAY:7,30,quark:iron_plate:1,100)
RandomBlock(5,30,-6,quark:iron_plate:1,70,STAINED_CLAY:15,30,STAINED_CLAY:7,30,quark:iron_plate:1,100)
RandomBlock(5,30,-5,quark:iron_plate:1,70,STAINED_CLAY:15,30,STAINED_CLAY:7,30,quark:iron_plate:1,100)
RandomBlock(5,30,-4,quark:iron_plate:1,70,STAINED_CLAY:15,30,STAINED_CLAY:7,30,quark:iron_plate:1,100)
RandomBlock(5,30,-3,quark:iron_plate:1,70,STAINED_CLAY:15,30,STAINED_CLAY:7,30,quark:iron_plate:1,100)
RandomBlock(5,31,-6,quark:iron_plate:1,70,STAINED_CLAY:15,30,STAINED_CLAY:7,30,quark:iron_plate:1,100)
RandomBlock(5,31,-5,quark:iron_plate:1,70,STAINED_CLAY:15,30,STAINED_CLAY:7,30,quark:iron_plate:1,100)
RandomBlock(5,31,-4,quark:iron_plate:1,70,STAINED_CLAY:15,30,STAINED_CLAY:7,30,quark:iron_plate:1,100)
RandomBlock(5,31,-3,quark:iron_plate:1,70,STAINED_CLAY:15,30,STAINED_CLAY:7,30,quark:iron_plate:1,100)
RandomBlock(5,32,-6,IRON_FENCE:0,30,IRON_FENCE:0,30,LEAVES:7,30,quark:iron_plate_stairs:6,10,quark:iron_plate_stairs:0,10,quark:iron_plate_stairs:5,10,quark:iron_plate_stairs:3,10,quark:iron_plate_slab:8,10,quark:iron_plate_stairs:7,10,quark:iron_plate_stairs:1,10,quark:iron_plate_slab:0,10,quark:iron_plate_stairs:4,10,quark:iron_plate_stairs:2,10,IRON_FENCE:0,50,IRON_FENCE:0,50,LEAVES:7,100)
RandomBlock(5,32,-5,quark:iron_plate:1,70,STAINED_CLAY:15,30,STAINED_CLAY:7,30,quark:iron_plate:1,100)
RandomBlock(5,32,-4,quark:iron_plate:1,70,STAINED_CLAY:15,30,STAINED_CLAY:7,30,quark:iron_plate:1,100)
RandomBlock(5,32,-3,quark:iron_plate:1,70,STAINED_CLAY:15,30,STAINED_CLAY:7,30,quark:iron_plate:1,100)
RandomBlock(5,33,-6,IRON_FENCE:0,30,IRON_FENCE:0,30,LEAVES:7,30,quark:iron_plate_stairs:6,10,quark:iron_plate_stairs:0,10,quark:iron_plate_stairs:5,10,quark:iron_plate_stairs:3,10,quark:iron_plate_slab:8,10,quark:iron_plate_stairs:7,10,quark:iron_plate_stairs:1,10,quark:iron_plate_slab:0,10,quark:iron_plate_stairs:4,10,quark:iron_plate_stairs:2,10,IRON_FENCE:0,50,IRON_FENCE:0,50,LEAVES:7,100)
RandomBlock(5,33,-5,IRON_FENCE:0,30,IRON_FENCE:0,30,LEAVES:7,30,quark:iron_plate_stairs:6,10,quark:iron_plate_stairs:0,10,quark:iron_plate_stairs:5,10,quark:iron_plate_stairs:3,10,quark:iron_plate_slab:8,10,quark:iron_plate_stairs:7,10,quark:iron_plate_stairs:1,10,quark:iron_plate_slab:0,10,quark:iron_plate_stairs:4,10,quark:iron_plate_stairs:2,10,IRON_FENCE:0,50,IRON_FENCE:0,50,LEAVES:7,100)
RandomBlock(5,33,-4,quark:iron_plate:1,70,STAINED_CLAY:15,30,STAINED_CLAY:7,30,quark:iron_plate:1,100)
RandomBlock(5,33,-3,quark:iron_plate:1,70,STAINED_CLAY:15,30,STAINED_CLAY:7,30,quark:iron_plate:1,100)
RandomBlock(5,34,-6,IRON_FENCE:0,30,IRON_FENCE:0,30,LEAVES:7,30,quark:iron_plate_stairs:6,10,quark:iron_plate_stairs:0,10,quark:iron_plate_stairs:5,10,quark:iron_plate_stairs:3,10,quark:iron_plate_slab:8,10,quark:iron_plate_stairs:7,10,quark:iron_plate_stairs:1,10,quark:iron_plate_slab:0,10,quark:iron_plate_stairs:4,10,quark:iron_plate_stairs:2,10,IRON_FENCE:0,50,IRON_FENCE:0,50,LEAVES:7,100)
RandomBlock(5,34,-5,quark:iron_plate:1,70,STAINED_CLAY:15,30,STAINED_CLAY:7,30,quark:iron_plate:1,100)
RandomBlock(5,34,-4,quark:iron_plate:1,70,STAINED_CLAY:15,30,STAINED_CLAY:7,30,quark:iron_plate:1,100)
RandomBlock(5,34,-3,quark:iron_plate:1,70,STAINED_CLAY:15,30,STAINED_CLAY:7,30,quark:iron_plate:1,100)
RandomBlock(5,35,-6,quark:iron_plate:1,70,STAINED_CLAY:15,30,STAINED_CLAY:7,30,quark:iron_plate:1,100)
RandomBlock(5,35,-5,quark:iron_plate:1,70,STAINED_CLAY:15,30,STAINED_CLAY:7,30,quark:iron_plate:1,100)
RandomBlock(5,35,-4,quark:iron_plate:1,70,STAINED_CLAY:15,30,STAINED_CLAY:7,30,quark:iron_plate:1,100)
RandomBlock(5,35,-3,quark:iron_plate:1,70,STAINED_CLAY:15,30,STAINED_CLAY:7,30,quark:iron_plate:1,100)
RandomBlock(5,36,-6,quark:iron_plate:1,70,STAINED_CLAY:15,30,STAINED_CLAY:7,30,quark:iron_plate:1,100)
RandomBlock(5,36,-5,quark:iron_plate:1,70,STAINED_CLAY:15,30,STAINED_CLAY:7,30,quark:iron_plate:1,100)
RandomBlock(5,36,-4,quark:iron_plate:1,70,STAINED_CLAY:15,30,STAINED_CLAY:7,30,quark:iron_plate:1,100)
RandomBlock(5,36,-3,IRON_FENCE:0,30,IRON_FENCE:0,30,LEAVES:7,30,quark:iron_plate_stairs:6,10,quark:iron_plate_stairs:0,10,quark:iron_plate_stairs:5,10,quark:iron_plate_stairs:3,10,quark:iron_plate_slab:8,10,quark:iron_plate_stairs:7,10,quark:iron_plate_stairs:1,10,quark:iron_plate_slab:0,10,quark:iron_plate_stairs:4,10,quark:iron_plate_stairs:2,10,IRON_FENCE:0,50,IRON_FENCE:0,50,LEAVES:7,100)
RandomBlock(5,37,-6,IRON_FENCE:0,30,IRON_FENCE:0,30,LEAVES:7,30,quark:iron_plate_stairs:6,10,quark:iron_plate_stairs:0,10,quark:iron_plate_stairs:5,10,quark:iron_plate_stairs:3,10,quark:iron_plate_slab:8,10,quark:iron_plate_stairs:7,10,quark:iron_plate_stairs:1,10,quark:iron_plate_slab:0,10,quark:iron_plate_stairs:4,10,quark:iron_plate_stairs:2,10,IRON_FENCE:0,50,IRON_FENCE:0,50,LEAVES:7,100)
RandomBlock(5,37,-5,quark:iron_plate:1,70,STAINED_CLAY:15,30,STAINED_CLAY:7,30,quark:iron_plate:1,100)
RandomBlock(5,37,-4,quark:iron_plate:1,70,STAINED_CLAY:15,30,STAINED_CLAY:7,30,quark:iron_plate:1,100)
RandomBlock(5,37,-3,quark:iron_plate:1,70,STAINED_CLAY:15,30,STAINED_CLAY:7,30,quark:iron_plate:1,100)
RandomBlock(5,38,-6,IRON_FENCE:0,30,IRON_FENCE:0,30,LEAVES:7,30,quark:iron_plate_stairs:6,10,quark:iron_plate_stairs:0,10,quark:iron_plate_stairs:5,10,quark:iron_plate_stairs:3,10,quark:iron_plate_slab:8,10,quark:iron_plate_stairs:7,10,quark:iron_plate_stairs:1,10,quark:iron_plate_slab:0,10,quark:iron_plate_stairs:4,10,quark:iron_plate_stairs:2,10,IRON_FENCE:0,50,IRON_FENCE:0,50,LEAVES:7,100)
RandomBlock(5,38,-5,quark:iron_plate:1,70,STAINED_CLAY:15,30,STAINED_CLAY:7,30,quark:iron_plate:1,100)
RandomBlock(5,38,-4,quark:iron_plate:1,70,STAINED_CLAY:15,30,STAINED_CLAY:7,30,quark:iron_plate:1,100)
RandomBlock(5,38,-3,quark:iron_plate:1,70,STAINED_CLAY:15,30,STAINED_CLAY:7,30,quark:iron_plate:1,100)
RandomBlock(5,39,-6,IRON_FENCE:0,30,IRON_FENCE:0,30,LEAVES:7,30,quark:iron_plate_stairs:6,10,quark:iron_plate_stairs:0,10,quark:iron_plate_stairs:5,10,quark:iron_plate_stairs:3,10,quark:iron_plate_slab:8,10,quark:iron_plate_stairs:7,10,quark:iron_plate_stairs:1,10,quark:iron_plate_slab:0,10,quark:iron_plate_stairs:4,10,quark:iron_plate_stairs:2,10,IRON_FENCE:0,50,IRON_FENCE:0,50,LEAVES:7,100)
RandomBlock(5,39,-5,quark:iron_plate:1,70,STAINED_CLAY:15,30,STAINED_CLAY:7,30,quark:iron_plate:1,100)
RandomBlock(5,39,-4,quark:iron_plate:1,70,STAINED_CLAY:15,30,STAINED_CLAY:7,30,quark:iron_plate:1,100)
RandomBlock(5,39,-3,quark:iron_plate:1,70,STAINED_CLAY:15,30,STAINED_CLAY:7,30,quark:iron_plate:1,100)
RandomBlock(5,40,-6,IRON_FENCE:0,30,IRON_FENCE:0,30,LEAVES:7,30,quark:iron_plate_stairs:6,10,quark:iron_plate_stairs:0,10,quark:iron_plate_stairs:5,10,quark:iron_plate_stairs:3,10,quark:iron_plate_slab:8,10,quark:iron_plate_stairs:7,10,quark:iron_plate_stairs:1,10,quark:iron_plate_slab:0,10,quark:iron_plate_stairs:4,10,quark:iron_plate_stairs:2,10,IRON_FENCE:0,50,IRON_FENCE:0,50,LEAVES:7,100)
RandomBlock(5,40,-5,IRON_FENCE:0,30,IRON_FENCE:0,30,LEAVES:7,30,quark:iron_plate_stairs:6,10,quark:iron_plate_stairs:0,10,quark:iron_plate_stairs:5,10,quark:iron_plate_stairs:3,10,quark:iron_plate_slab:8,10,quark:iron_plate_stairs:7,10,quark:iron_plate_stairs:1,10,quark:iron_plate_slab:0,10,quark:iron_plate_stairs:4,10,quark:iron_plate_stairs:2,10,IRON_FENCE:0,50,IRON_FENCE:0,50,LEAVES:7,100)
RandomBlock(5,40,-4,quark:iron_plate:1,70,STAINED_CLAY:15,30,STAINED_CLAY:7,30,quark:iron_plate:1,100)
RandomBlock(5,40,-3,quark:iron_plate:1,70,STAINED_CLAY:15,30,STAINED_CLAY:7,30,quark:iron_plate:1,100)
RandomBlock(5,41,-6,IRON_FENCE:0,30,IRON_FENCE:0,30,LEAVES:7,30,quark:iron_plate_stairs:6,10,quark:iron_plate_stairs:0,10,quark:iron_plate_stairs:5,10,quark:iron_plate_stairs:3,10,quark:iron_plate_slab:8,10,quark:iron_plate_stairs:7,10,quark:iron_plate_stairs:1,10,quark:iron_plate_slab:0,10,quark:iron_plate_stairs:4,10,quark:iron_plate_stairs:2,10,IRON_FENCE:0,50,IRON_FENCE:0,50,LEAVES:7,100)
RandomBlock(5,41,-5,IRON_FENCE:0,30,IRON_FENCE:0,30,LEAVES:7,30,quark:iron_plate_stairs:6,10,quark:iron_plate_stairs:0,10,quark:iron_plate_stairs:5,10,quark:iron_plate_stairs:3,10,quark:iron_plate_slab:8,10,quark:iron_plate_stairs:7,10,quark:iron_plate_stairs:1,10,quark:iron_plate_slab:0,10,quark:iron_plate_stairs:4,10,quark:iron_plate_stairs:2,10,IRON_FENCE:0,50,IRON_FENCE:0,50,LEAVES:7,100)
RandomBlock(5,41,-4,IRON_FENCE:0,30,IRON_FENCE:0,30,LEAVES:7,30,quark:iron_plate_stairs:6,10,quark:iron_plate_stairs:0,10,quark:iron_plate_stairs:5,10,quark:iron_plate_stairs:3,10,quark:iron_plate_slab:8,10,quark:iron_plate_stairs:7,10,quark:iron_plate_stairs:1,10,quark:iron_plate_slab:0,10,quark:iron_plate_stairs:4,10,quark:iron_plate_stairs:2,10,IRON_FENCE:0,50,IRON_FENCE:0,50,LEAVES:7,100)
RandomBlock(5,41,-3,quark:iron_plate:1,70,STAINED_CLAY:15,30,STAINED_CLAY:7,30,quark:iron_plate:1,100)
RandomBlock(5,42,-6,IRON_FENCE:0,30,IRON_FENCE:0,30,LEAVES:7,30,quark:iron_plate_stairs:6,10,quark:iron_plate_stairs:0,10,quark:iron_plate_stairs:5,10,quark:iron_plate_stairs:3,10,quark:iron_plate_slab:8,10,quark:iron_plate_stairs:7,10,quark:iron_plate_stairs:1,10,quark:iron_plate_slab:0,10,quark:iron_plate_stairs:4,10,quark:iron_plate_stairs:2,10,IRON_FENCE:0,50,IRON_FENCE:0,50,LEAVES:7,100)
RandomBlock(5,42,-5,IRON_FENCE:0,30,IRON_FENCE:0,30,LEAVES:7,30,quark:iron_plate_stairs:6,10,quark:iron_plate_stairs:0,10,quark:iron_plate_stairs:5,10,quark:iron_plate_stairs:3,10,quark:iron_plate_slab:8,10,quark:iron_plate_stairs:7,10,quark:iron_plate_stairs:1,10,quark:iron_plate_slab:0,10,quark:iron_plate_stairs:4,10,quark:iron_plate_stairs:2,10,IRON_FENCE:0,50,IRON_FENCE:0,50,LEAVES:7,100)
RandomBlock(5,42,-4,quark:iron_plate:1,70,STAINED_CLAY:15,30,STAINED_CLAY:7,30,quark:iron_plate:1,100)
RandomBlock(5,42,-3,quark:iron_plate:1,70,STAINED_CLAY:15,30,STAINED_CLAY:7,30,quark:iron_plate:1,100)
RandomBlock(5,43,-6,IRON_FENCE:0,30,IRON_FENCE:0,30,LEAVES:7,30,quark:iron_plate_stairs:6,10,quark:iron_plate_stairs:0,10,quark:iron_plate_stairs:5,10,quark:iron_plate_stairs:3,10,quark:iron_plate_slab:8,10,quark:iron_plate_stairs:7,10,quark:iron_plate_stairs:1,10,quark:iron_plate_slab:0,10,quark:iron_plate_stairs:4,10,quark:iron_plate_stairs:2,10,IRON_FENCE:0,50,IRON_FENCE:0,50,LEAVES:7,100)
RandomBlock(5,43,-5,IRON_FENCE:0,30,IRON_FENCE:0,30,LEAVES:7,30,quark:iron_plate_stairs:6,10,quark:iron_plate_stairs:0,10,quark:iron_plate_stairs:5,10,quark:iron_plate_stairs:3,10,quark:iron_plate_slab:8,10,quark:iron_plate_stairs:7,10,quark:iron_plate_stairs:1,10,quark:iron_plate_slab:0,10,quark:iron_plate_stairs:4,10,quark:iron_plate_stairs:2,10,IRON_FENCE:0,50,IRON_FENCE:0,50,LEAVES:7,100)
RandomBlock(5,43,-4,IRON_FENCE:0,30,IRON_FENCE:0,30,LEAVES:7,30,quark:iron_plate_stairs:6,10,quark:iron_plate_stairs:0,10,quark:iron_plate_stairs:5,10,quark:iron_plate_stairs:3,10,quark:iron_plate_slab:8,10,quark:iron_plate_stairs:7,10,quark:iron_plate_stairs:1,10,quark:iron_plate_slab:0,10,quark:iron_plate_stairs:4,10,quark:iron_plate_stairs:2,10,IRON_FENCE:0,50,IRON_FENCE:0,50,LEAVES:7,100)
RandomBlock(5,43,-3,quark:iron_plate:1,70,STAINED_CLAY:15,30,STAINED_CLAY:7,30,quark:iron_plate:1,100)
RandomBlock(5,44,-6,IRON_FENCE:0,30,IRON_FENCE:0,30,LEAVES:7,30,quark:iron_plate_stairs:6,10,quark:iron_plate_stairs:0,10,quark:iron_plate_stairs:5,10,quark:iron_plate_stairs:3,10,quark:iron_plate_slab:8,10,quark:iron_plate_stairs:7,10,quark:iron_plate_stairs:1,10,quark:iron_plate_slab:0,10,quark:iron_plate_stairs:4,10,quark:iron_plate_stairs:2,10,IRON_FENCE:0,50,IRON_FENCE:0,50,LEAVES:7,100)
RandomBlock(5,44,-5,IRON_FENCE:0,30,IRON_FENCE:0,30,LEAVES:7,30,quark:iron_plate_stairs:6,10,quark:iron_plate_stairs:0,10,quark:iron_plate_stairs:5,10,quark:iron_plate_stairs:3,10,quark:iron_plate_slab:8,10,quark:iron_plate_stairs:7,10,quark:iron_plate_stairs:1,10,quark:iron_plate_slab:0,10,quark:iron_plate_stairs:4,10,quark:iron_plate_stairs:2,10,IRON_FENCE:0,50,IRON_FENCE:0,50,LEAVES:7,100)
RandomBlock(5,44,-4,IRON_FENCE:0,30,IRON_FENCE:0,30,LEAVES:7,30,quark:iron_plate_stairs:6,10,quark:iron_plate_stairs:0,10,quark:iron_plate_stairs:5,10,quark:iron_plate_stairs:3,10,quark:iron_plate_slab:8,10,quark:iron_plate_stairs:7,10,quark:iron_plate_stairs:1,10,quark:iron_plate_slab:0,10,quark:iron_plate_stairs:4,10,quark:iron_plate_stairs:2,10,IRON_FENCE:0,50,IRON_FENCE:0,50,LEAVES:7,100)
RandomBlock(5,44,-3,IRON_FENCE:0,30,IRON_FENCE:0,30,LEAVES:7,30,quark:iron_plate_stairs:6,10,quark:iron_plate_stairs:0,10,quark:iron_plate_stairs:5,10,quark:iron_plate_stairs:3,10,quark:iron_plate_slab:8,10,quark:iron_plate_stairs:7,10,quark:iron_plate_stairs:1,10,quark:iron_plate_slab:0,10,quark:iron_plate_stairs:4,10,quark:iron_plate_stairs:2,10,IRON_FENCE:0,50,IRON_FENCE:0,50,LEAVES:7,100)
RandomBlock(5,45,-6,quark:iron_plate:1,70,STAINED_CLAY:15,30,STAINED_CLAY:7,30,quark:iron_plate:1,100)
RandomBlock(5,45,-5,quark:iron_plate:1,70,STAINED_CLAY:15,30,STAINED_CLAY:7,30,quark:iron_plate:1,100)
RandomBlock(5,45,-4,IRON_FENCE:0,30,IRON_FENCE:0,30,LEAVES:7,30,quark:iron_plate_stairs:6,10,quark:iron_plate_stairs:0,10,quark:iron_plate_stairs:5,10,quark:iron_plate_stairs:3,10,quark:iron_plate_slab:8,10,quark:iron_plate_stairs:7,10,quark:iron_plate_stairs:1,10,quark:iron_plate_slab:0,10,quark:iron_plate_stairs:4,10,quark:iron_plate_stairs:2,10,IRON_FENCE:0,50,IRON_FENCE:0,50,LEAVES:7,100)
RandomBlock(5,45,-3,IRON_FENCE:0,30,IRON_FENCE:0,30,LEAVES:7,30,quark:iron_plate_stairs:6,10,quark:iron_plate_stairs:0,10,quark:iron_plate_stairs:5,10,quark:iron_plate_stairs:3,10,quark:iron_plate_slab:8,10,quark:iron_plate_stairs:7,10,quark:iron_plate_stairs:1,10,quark:iron_plate_slab:0,10,quark:iron_plate_stairs:4,10,quark:iron_plate_stairs:2,10,IRON_FENCE:0,50,IRON_FENCE:0,50,LEAVES:7,100)
RandomBlock(5,46,-6,quark:iron_plate:1,70,STAINED_CLAY:15,30,STAINED_CLAY:7,30,quark:iron_plate:1,100)
RandomBlock(5,46,-5,quark:iron_plate:1,70,STAINED_CLAY:15,30,STAINED_CLAY:7,30,quark:iron_plate:1,100)
RandomBlock(5,46,-4,quark:iron_plate:1,70,STAINED_CLAY:15,30,STAINED_CLAY:7,30,quark:iron_plate:1,100)
RandomBlock(5,46,-3,IRON_FENCE:0,30,IRON_FENCE:0,30,LEAVES:7,30,quark:iron_plate_stairs:6,10,quark:iron_plate_stairs:0,10,quark:iron_plate_stairs:5,10,quark:iron_plate_stairs:3,10,quark:iron_plate_slab:8,10,quark:iron_plate_stairs:7,10,quark:iron_plate_stairs:1,10,quark:iron_plate_slab:0,10,quark:iron_plate_stairs:4,10,quark:iron_plate_stairs:2,10,IRON_FENCE:0,50,IRON_FENCE:0,50,LEAVES:7,100)
RandomBlock(5,47,-6,quark:iron_plate:1,70,STAINED_CLAY:15,30,STAINED_CLAY:7,30,quark:iron_plate:1,100)
RandomBlock(5,47,-5,quark:iron_plate:1,70,STAINED_CLAY:15,30,STAINED_CLAY:7,30,quark:iron_plate:1,100)
RandomBlock(5,47,-4,quark:iron_plate:1,70,STAINED_CLAY:15,30,STAINED_CLAY:7,30,quark:iron_plate:1,100)
RandomBlock(5,47,-3,quark:iron_plate:1,70,STAINED_CLAY:15,30,STAINED_CLAY:7,30,quark:iron_plate:1,100)
RandomBlock(5,48,-6,quark:iron_plate:1,70,STAINED_CLAY:15,30,STAINED_CLAY:7,30,quark:iron_plate:1,100)
RandomBlock(5,48,-5,quark:iron_plate:1,70,STAINED_CLAY:15,30,STAINED_CLAY:7,30,quark:iron_plate:1,100)
RandomBlock(5,48,-4,quark:iron_plate:1,70,STAINED_CLAY:15,30,STAINED_CLAY:7,30,quark:iron_plate:1,100)
RandomBlock(5,48,-3,quark:iron_plate:1,70,STAINED_CLAY:15,30,STAINED_CLAY:7,30,quark:iron_plate:1,100)
RandomBlock(5,49,-6,quark:iron_plate:1,70,STAINED_CLAY:15,30,STAINED_CLAY:7,30,quark:iron_plate:1,100)
RandomBlock(5,49,-5,quark:iron_plate:1,70,STAINED_CLAY:15,30,STAINED_CLAY:7,30,quark:iron_plate:1,100)
RandomBlock(5,49,-4,quark:iron_plate:1,70,STAINED_CLAY:15,30,STAINED_CLAY:7,30,quark:iron_plate:1,100)
RandomBlock(5,49,-3,quark:iron_plate:1,70,STAINED_CLAY:15,30,STAINED_CLAY:7,30,quark:iron_plate:1,100)
RandomBlock(5,50,-6,quark:iron_plate:1,70,STAINED_CLAY:15,30,STAINED_CLAY:7,30,quark:iron_plate:1,100)
RandomBlock(5,50,-5,quark:iron_plate:1,70,STAINED_CLAY:15,30,STAINED_CLAY:7,30,quark:iron_plate:1,100)
RandomBlock(5,50,-4,quark:iron_plate:1,70,STAINED_CLAY:15,30,STAINED_CLAY:7,30,quark:iron_plate:1,100)
RandomBlock(5,50,-3,quark:iron_plate:1,70,STAINED_CLAY:15,30,STAINED_CLAY:7,30,quark:iron_plate:1,100)
RandomBlock(5,51,-6,IRON_FENCE:0,30,IRON_FENCE:0,30,LEAVES:7,30,quark:iron_plate_stairs:6,10,quark:iron_plate_stairs:0,10,quark:iron_plate_stairs:5,10,quark:iron_plate_stairs:3,10,quark:iron_plate_slab:8,10,quark:iron_plate_stairs:7,10,quark:iron_plate_stairs:1,10,quark:iron_plate_slab:0,10,quark:iron_plate_stairs:4,10,quark:iron_plate_stairs:2,10,IRON_FENCE:0,50,IRON_FENCE:0,50,LEAVES:7,100)
RandomBlock(5,51,-5,quark:iron_plate:1,70,STAINED_CLAY:15,30,STAINED_CLAY:7,30,quark:iron_plate:1,100)
RandomBlock(5,51,-4,quark:iron_plate:1,70,STAINED_CLAY:15,30,STAINED_CLAY:7,30,quark:iron_plate:1,100)
RandomBlock(5,51,-3,quark:iron_plate:1,70,STAINED_CLAY:15,30,STAINED_CLAY:7,30,quark:iron_plate:1,100)
RandomBlock(5,52,-6,IRON_FENCE:0,30,IRON_FENCE:0,30,LEAVES:7,30,quark:iron_plate_stairs:6,10,quark:iron_plate_stairs:0,10,quark:iron_plate_stairs:5,10,quark:iron_plate_stairs:3,10,quark:iron_plate_slab:8,10,quark:iron_plate_stairs:7,10,quark:iron_plate_stairs:1,10,quark:iron_plate_slab:0,10,quark:iron_plate_stairs:4,10,quark:iron_plate_stairs:2,10,IRON_FENCE:0,50,IRON_FENCE:0,50,LEAVES:7,100)
RandomBlock(5,52,-5,IRON_FENCE:0,30,IRON_FENCE:0,30,LEAVES:7,30,quark:iron_plate_stairs:6,10,quark:iron_plate_stairs:0,10,quark:iron_plate_stairs:5,10,quark:iron_plate_stairs:3,10,quark:iron_plate_slab:8,10,quark:iron_plate_stairs:7,10,quark:iron_plate_stairs:1,10,quark:iron_plate_slab:0,10,quark:iron_plate_stairs:4,10,quark:iron_plate_stairs:2,10,IRON_FENCE:0,50,IRON_FENCE:0,50,LEAVES:7,100)
RandomBlock(5,52,-4,quark:iron_plate:1,70,STAINED_CLAY:15,30,STAINED_CLAY:7,30,quark:iron_plate:1,100)
RandomBlock(5,52,-3,quark:iron_plate:1,70,STAINED_CLAY:15,30,STAINED_CLAY:7,30,quark:iron_plate:1,100)
RandomBlock(5,53,-6,IRON_FENCE:0,30,IRON_FENCE:0,30,LEAVES:7,30,quark:iron_plate_stairs:6,10,quark:iron_plate_stairs:0,10,quark:iron_plate_stairs:5,10,quark:iron_plate_stairs:3,10,quark:iron_plate_slab:8,10,quark:iron_plate_stairs:7,10,quark:iron_plate_stairs:1,10,quark:iron_plate_slab:0,10,quark:iron_plate_stairs:4,10,quark:iron_plate_stairs:2,10,IRON_FENCE:0,50,IRON_FENCE:0,50,LEAVES:7,100)
RandomBlock(5,53,-5,quark:iron_plate:1,70,STAINED_CLAY:15,30,STAINED_CLAY:7,30,quark:iron_plate:1,100)
RandomBlock(5,53,-4,quark:iron_plate:1,70,STAINED_CLAY:15,30,STAINED_CLAY:7,30,quark:iron_plate:1,100)
RandomBlock(5,53,-3,quark:iron_plate:1,70,STAINED_CLAY:15,30,STAINED_CLAY:7,30,quark:iron_plate:1,100)
RandomBlock(5,54,-6,IRON_FENCE:0,30,IRON_FENCE:0,30,LEAVES:7,30,quark:iron_plate_stairs:6,10,quark:iron_plate_stairs:0,10,quark:iron_plate_stairs:5,10,quark:iron_plate_stairs:3,10,quark:iron_plate_slab:8,10,quark:iron_plate_stairs:7,10,quark:iron_plate_stairs:1,10,quark:iron_plate_slab:0,10,quark:iron_plate_stairs:4,10,quark:iron_plate_stairs:2,10,IRON_FENCE:0,50,IRON_FENCE:0,50,LEAVES:7,100)
RandomBlock(5,54,-5,quark:iron_plate:1,70,STAINED_CLAY:15,30,STAINED_CLAY:7,30,quark:iron_plate:1,100)
RandomBlock(5,54,-4,quark:iron_plate:1,70,STAINED_CLAY:15,30,STAINED_CLAY:7,30,quark:iron_plate:1,100)
RandomBlock(5,54,-3,quark:iron_plate:1,70,STAINED_CLAY:15,30,STAINED_CLAY:7,30,quark:iron_plate:1,100)
RandomBlock(5,55,-6,quark:iron_plate:1,70,STAINED_CLAY:15,30,STAINED_CLAY:7,30,quark:iron_plate:1,100)
RandomBlock(5,55,-5,quark:iron_plate:1,70,STAINED_CLAY:15,30,STAINED_CLAY:7,30,quark:iron_plate:1,100)
RandomBlock(5,55,-4,quark:iron_plate:1,70,STAINED_CLAY:15,30,STAINED_CLAY:7,30,quark:iron_plate:1,100)
RandomBlock(5,55,-3,quark:iron_plate:1,70,STAINED_CLAY:15,30,STAINED_CLAY:7,30,quark:iron_plate:1,100)
RandomBlock(5,56,-6,quark:iron_plate:1,70,STAINED_CLAY:15,30,STAINED_CLAY:7,30,quark:iron_plate:1,100)
RandomBlock(5,56,-5,quark:iron_plate:1,70,STAINED_CLAY:15,30,STAINED_CLAY:7,30,quark:iron_plate:1,100)
RandomBlock(5,56,-4,quark:iron_plate:1,70,STAINED_CLAY:15,30,STAINED_CLAY:7,30,quark:iron_plate:1,100)
RandomBlock(5,56,-3,IRON_FENCE:0,30,IRON_FENCE:0,30,LEAVES:7,30,quark:iron_plate_stairs:6,10,quark:iron_plate_stairs:0,10,quark:iron_plate_stairs:5,10,quark:iron_plate_stairs:3,10,quark:iron_plate_slab:8,10,quark:iron_plate_stairs:7,10,quark:iron_plate_stairs:1,10,quark:iron_plate_slab:0,10,quark:iron_plate_stairs:4,10,quark:iron_plate_stairs:2,10,IRON_FENCE:0,50,IRON_FENCE:0,50,LEAVES:7,100)
RandomBlock(5,57,-6,quark:iron_plate:1,70,STAINED_CLAY:15,30,STAINED_CLAY:7,30,quark:iron_plate:1,100)
RandomBlock(5,57,-5,quark:iron_plate:1,70,STAINED_CLAY:15,30,STAINED_CLAY:7,30,quark:iron_plate:1,100)
RandomBlock(5,57,-4,IRON_FENCE:0,30,IRON_FENCE:0,30,LEAVES:7,30,quark:iron_plate_stairs:6,10,quark:iron_plate_stairs:0,10,quark:iron_plate_stairs:5,10,quark:iron_plate_stairs:3,10,quark:iron_plate_slab:8,10,quark:iron_plate_stairs:7,10,quark:iron_plate_stairs:1,10,quark:iron_plate_slab:0,10,quark:iron_plate_stairs:4,10,quark:iron_plate_stairs:2,10,IRON_FENCE:0,50,IRON_FENCE:0,50,LEAVES:7,100)
RandomBlock(5,57,-3,IRON_FENCE:0,30,IRON_FENCE:0,30,LEAVES:7,30,quark:iron_plate_stairs:6,10,quark:iron_plate_stairs:0,10,quark:iron_plate_stairs:5,10,quark:iron_plate_stairs:3,10,quark:iron_plate_slab:8,10,quark:iron_plate_stairs:7,10,quark:iron_plate_stairs:1,10,quark:iron_plate_slab:0,10,quark:iron_plate_stairs:4,10,quark:iron_plate_stairs:2,10,IRON_FENCE:0,50,IRON_FENCE:0,50,LEAVES:7,100)
RandomBlock(5,58,-6,quark:iron_plate:1,70,STAINED_CLAY:15,30,STAINED_CLAY:7,30,quark:iron_plate:1,100)
RandomBlock(5,58,-5,quark:iron_plate:1,70,STAINED_CLAY:15,30,STAINED_CLAY:7,30,quark:iron_plate:1,100)
RandomBlock(5,58,-4,IRON_FENCE:0,30,IRON_FENCE:0,30,LEAVES:7,30,quark:iron_plate_stairs:6,10,quark:iron_plate_stairs:0,10,quark:iron_plate_stairs:5,10,quark:iron_plate_stairs:3,10,quark:iron_plate_slab:8,10,quark:iron_plate_stairs:7,10,quark:iron_plate_stairs:1,10,quark:iron_plate_slab:0,10,quark:iron_plate_stairs:4,10,quark:iron_plate_stairs:2,10,IRON_FENCE:0,50,IRON_FENCE:0,50,LEAVES:7,100)
RandomBlock(5,58,-3,IRON_FENCE:0,30,IRON_FENCE:0,30,LEAVES:7,30,quark:iron_plate_stairs:6,10,quark:iron_plate_stairs:0,10,quark:iron_plate_stairs:5,10,quark:iron_plate_stairs:3,10,quark:iron_plate_slab:8,10,quark:iron_plate_stairs:7,10,quark:iron_plate_stairs:1,10,quark:iron_plate_slab:0,10,quark:iron_plate_stairs:4,10,quark:iron_plate_stairs:2,10,IRON_FENCE:0,50,IRON_FENCE:0,50,LEAVES:7,100)
RandomBlock(5,59,-6,quark:iron_plate:1,70,STAINED_CLAY:15,30,STAINED_CLAY:7,30,quark:iron_plate:1,100)
RandomBlock(5,59,-5,IRON_FENCE:0,30,IRON_FENCE:0,30,LEAVES:7,30,quark:iron_plate_stairs:6,10,quark:iron_plate_stairs:0,10,quark:iron_plate_stairs:5,10,quark:iron_plate_stairs:3,10,quark:iron_plate_slab:8,10,quark:iron_plate_stairs:7,10,quark:iron_plate_stairs:1,10,quark:iron_plate_slab:0,10,quark:iron_plate_stairs:4,10,quark:iron_plate_stairs:2,10,IRON_FENCE:0,50,IRON_FENCE:0,50,LEAVES:7,100)
RandomBlock(5,59,-4,IRON_FENCE:0,30,IRON_FENCE:0,30,LEAVES:7,30,quark:iron_plate_stairs:6,10,quark:iron_plate_stairs:0,10,quark:iron_plate_stairs:5,10,quark:iron_plate_stairs:3,10,quark:iron_plate_slab:8,10,quark:iron_plate_stairs:7,10,quark:iron_plate_stairs:1,10,quark:iron_plate_slab:0,10,quark:iron_plate_stairs:4,10,quark:iron_plate_stairs:2,10,IRON_FENCE:0,50,IRON_FENCE:0,50,LEAVES:7,100)
RandomBlock(5,59,-3,IRON_FENCE:0,30,IRON_FENCE:0,30,LEAVES:7,30,quark:iron_plate_stairs:6,10,quark:iron_plate_stairs:0,10,quark:iron_plate_stairs:5,10,quark:iron_plate_stairs:3,10,quark:iron_plate_slab:8,10,quark:iron_plate_stairs:7,10,quark:iron_plate_stairs:1,10,quark:iron_plate_slab:0,10,quark:iron_plate_stairs:4,10,quark:iron_plate_stairs:2,10,IRON_FENCE:0,50,IRON_FENCE:0,50,LEAVES:7,100)
RandomBlock(5,60,-6,quark:iron_plate:1,70,STAINED_CLAY:15,30,STAINED_CLAY:7,30,quark:iron_plate:1,100)
RandomBlock(5,60,-5,IRON_FENCE:0,30,IRON_FENCE:0,30,LEAVES:7,30,quark:iron_plate_stairs:6,10,quark:iron_plate_stairs:0,10,quark:iron_plate_stairs:5,10,quark:iron_plate_stairs:3,10,quark:iron_plate_slab:8,10,quark:iron_plate_stairs:7,10,quark:iron_plate_stairs:1,10,quark:iron_plate_slab:0,10,quark:iron_plate_stairs:4,10,quark:iron_plate_stairs:2,10,IRON_FENCE:0,50,IRON_FENCE:0,50,LEAVES:7,100)
RandomBlock(5,60,-4,IRON_FENCE:0,30,IRON_FENCE:0,30,LEAVES:7,30,quark:iron_plate_stairs:6,10,quark:iron_plate_stairs:0,10,quark:iron_plate_stairs:5,10,quark:iron_plate_stairs:3,10,quark:iron_plate_slab:8,10,quark:iron_plate_stairs:7,10,quark:iron_plate_stairs:1,10,quark:iron_plate_slab:0,10,quark:iron_plate_stairs:4,10,quark:iron_plate_stairs:2,10,IRON_FENCE:0,50,IRON_FENCE:0,50,LEAVES:7,100)
RandomBlock(5,60,-3,quark:iron_plate:1,70,STAINED_CLAY:15,30,STAINED_CLAY:7,30,quark:iron_plate:1,100)
RandomBlock(5,61,-6,IRON_FENCE:0,30,IRON_FENCE:0,30,LEAVES:7,30,quark:iron_plate_stairs:6,10,quark:iron_plate_stairs:0,10,quark:iron_plate_stairs:5,10,quark:iron_plate_stairs:3,10,quark:iron_plate_slab:8,10,quark:iron_plate_stairs:7,10,quark:iron_plate_stairs:1,10,quark:iron_plate_slab:0,10,quark:iron_plate_stairs:4,10,quark:iron_plate_stairs:2,10,IRON_FENCE:0,50,IRON_FENCE:0,50,LEAVES:7,100)
RandomBlock(5,61,-5,IRON_FENCE:0,30,IRON_FENCE:0,30,LEAVES:7,30,quark:iron_plate_stairs:6,10,quark:iron_plate_stairs:0,10,quark:iron_plate_stairs:5,10,quark:iron_plate_stairs:3,10,quark:iron_plate_slab:8,10,quark:iron_plate_stairs:7,10,quark:iron_plate_stairs:1,10,quark:iron_plate_slab:0,10,quark:iron_plate_stairs:4,10,quark:iron_plate_stairs:2,10,IRON_FENCE:0,50,IRON_FENCE:0,50,LEAVES:7,100)
RandomBlock(5,61,-4,IRON_FENCE:0,30,IRON_FENCE:0,30,LEAVES:7,30,quark:iron_plate_stairs:6,10,quark:iron_plate_stairs:0,10,quark:iron_plate_stairs:5,10,quark:iron_plate_stairs:3,10,quark:iron_plate_slab:8,10,quark:iron_plate_stairs:7,10,quark:iron_plate_stairs:1,10,quark:iron_plate_slab:0,10,quark:iron_plate_stairs:4,10,quark:iron_plate_stairs:2,10,IRON_FENCE:0,50,IRON_FENCE:0,50,LEAVES:7,100)
RandomBlock(5,61,-3,quark:iron_plate:1,70,STAINED_CLAY:15,30,STAINED_CLAY:7,30,quark:iron_plate:1,100)
RandomBlock(5,62,-6,quark:iron_plate:1,70,STAINED_CLAY:15,30,STAINED_CLAY:7,30,quark:iron_plate:1,100)
RandomBlock(5,62,-5,IRON_FENCE:0,30,IRON_FENCE:0,30,LEAVES:7,30,quark:iron_plate_stairs:6,10,quark:iron_plate_stairs:0,10,quark:iron_plate_stairs:5,10,quark:iron_plate_stairs:3,10,quark:iron_plate_slab:8,10,quark:iron_plate_stairs:7,10,quark:iron_plate_stairs:1,10,quark:iron_plate_slab:0,10,quark:iron_plate_stairs:4,10,quark:iron_plate_stairs:2,10,IRON_FENCE:0,50,IRON_FENCE:0,50,LEAVES:7,100)
RandomBlock(5,62,-4,quark:iron_plate:1,70,STAINED_CLAY:15,30,STAINED_CLAY:7,30,quark:iron_plate:1,100)
RandomBlock(5,62,-3,quark:iron_plate:1,70,STAINED_CLAY:15,30,STAINED_CLAY:7,30,quark:iron_plate:1,100)
RandomBlock(5,63,-6,quark:iron_plate:1,70,STAINED_CLAY:15,30,STAINED_CLAY:7,30,quark:iron_plate:1,100)
RandomBlock(5,63,-5,quark:iron_plate:1,70,STAINED_CLAY:15,30,STAINED_CLAY:7,30,quark:iron_plate:1,100)
RandomBlock(5,63,-4,quark:iron_plate:1,70,STAINED_CLAY:15,30,STAINED_CLAY:7,30,quark:iron_plate:1,100)
RandomBlock(5,63,-3,quark:iron_plate:1,70,STAINED_CLAY:15,30,STAINED_CLAY:7,30,quark:iron_plate:1,100)
RandomBlock(5,64,-6,quark:iron_plate:1,70,STAINED_CLAY:15,30,STAINED_CLAY:7,30,quark:iron_plate:1,100)
RandomBlock(5,64,-5,quark:iron_plate:1,70,STAINED_CLAY:15,30,STAINED_CLAY:7,30,quark:iron_plate:1,100)
RandomBlock(5,64,-4,quark:iron_plate:1,70,STAINED_CLAY:15,30,STAINED_CLAY:7,30,quark:iron_plate:1,100)
RandomBlock(5,64,-3,quark:iron_plate:1,70,STAINED_CLAY:15,30,STAINED_CLAY:7,30,quark:iron_plate:1,100)
RandomBlock(5,65,-6,quark:iron_plate:1,70,STAINED_CLAY:15,30,STAINED_CLAY:7,30,quark:iron_plate:1,100)
RandomBlock(5,65,-5,quark:iron_plate:1,70,STAINED_CLAY:15,30,STAINED_CLAY:7,30,quark:iron_plate:1,100)
RandomBlock(5,65,-4,quark:iron_plate:1,70,STAINED_CLAY:15,30,STAINED_CLAY:7,30,quark:iron_plate:1,100)
RandomBlock(5,65,-3,quark:iron_plate:1,70,STAINED_CLAY:15,30,STAINED_CLAY:7,30,quark:iron_plate:1,100)
RandomBlock(6,0,-6,quark:iron_plate:1,70,STAINED_CLAY:15,30,STAINED_CLAY:7,30,quark:iron_plate:1,100)
Block(6,0,-5,AIR:0)
Block(6,0,-4,AIR:0)
RandomBlock(6,0,-3,IRON_FENCE:0,30,IRON_FENCE:0,30,LEAVES:7,30,quark:iron_plate_stairs:6,10,quark:iron_plate_stairs:0,10,quark:iron_plate_stairs:5,10,quark:iron_plate_stairs:3,10,quark:iron_plate_slab:8,10,quark:iron_plate_stairs:7,10,quark:iron_plate_stairs:1,10,quark:iron_plate_slab:0,10,quark:iron_plate_stairs:4,10,quark:iron_plate_stairs:2,10,IRON_FENCE:0,50,IRON_FENCE:0,50,LEAVES:7,100)
RandomBlock(6,1,-6,quark:iron_plate:1,70,STAINED_CLAY:15,30,STAINED_CLAY:7,30,quark:iron_plate:1,100)
Block(6,1,-5,AIR:0)
Block(6,1,-4,AIR:0)
RandomBlock(6,1,-3,quark:iron_plate:1,70,STAINED_CLAY:15,30,STAINED_CLAY:7,30,quark:iron_plate:1,100)
RandomBlock(6,2,-6,quark:iron_plate:1,70,STAINED_CLAY:15,30,STAINED_CLAY:7,30,quark:iron_plate:1,100)
Block(6,2,-5,AIR:0)
Block(6,2,-4,AIR:0)
RandomBlock(6,2,-3,IRON_FENCE:0,30,IRON_FENCE:0,30,LEAVES:7,30,quark:iron_plate_stairs:6,10,quark:iron_plate_stairs:0,10,quark:iron_plate_stairs:5,10,quark:iron_plate_stairs:3,10,quark:iron_plate_slab:8,10,quark:iron_plate_stairs:7,10,quark:iron_plate_stairs:1,10,quark:iron_plate_slab:0,10,quark:iron_plate_stairs:4,10,quark:iron_plate_stairs:2,10,IRON_FENCE:0,50,IRON_FENCE:0,50,LEAVES:7,100)
RandomBlock(6,3,-6,quark:iron_plate:1,70,STAINED_CLAY:15,30,STAINED_CLAY:7,30,quark:iron_plate:1,100)
Block(6,3,-5,AIR:0)
Block(6,3,-4,AIR:0)
RandomBlock(6,3,-3,IRON_FENCE:0,30,IRON_FENCE:0,30,LEAVES:7,30,quark:iron_plate_stairs:6,10,quark:iron_plate_stairs:0,10,quark:iron_plate_stairs:5,10,quark:iron_plate_stairs:3,10,quark:iron_plate_slab:8,10,quark:iron_plate_stairs:7,10,quark:iron_plate_stairs:1,10,quark:iron_plate_slab:0,10,quark:iron_plate_stairs:4,10,quark:iron_plate_stairs:2,10,IRON_FENCE:0,50,IRON_FENCE:0,50,LEAVES:7,100)
RandomBlock(6,4,-6,quark:iron_plate:1,70,STAINED_CLAY:15,30,STAINED_CLAY:7,30,quark:iron_plate:1,100)
Block(6,4,-5,AIR:0)
Block(6,4,-4,AIR:0)
RandomBlock(6,4,-3,IRON_FENCE:0,30,IRON_FENCE:0,30,LEAVES:7,30,quark:iron_plate_stairs:6,10,quark:iron_plate_stairs:0,10,quark:iron_plate_stairs:5,10,quark:iron_plate_stairs:3,10,quark:iron_plate_slab:8,10,quark:iron_plate_stairs:7,10,quark:iron_plate_stairs:1,10,quark:iron_plate_slab:0,10,quark:iron_plate_stairs:4,10,quark:iron_plate_stairs:2,10,IRON_FENCE:0,50,IRON_FENCE:0,50,LEAVES:7,100)
RandomBlock(6,5,-6,quark:iron_plate:1,70,STAINED_CLAY:15,30,STAINED_CLAY:7,30,quark:iron_plate:1,100)
Block(6,5,-5,AIR:0)
Block(6,5,-4,AIR:0)
RandomBlock(6,5,-3,IRON_FENCE:0,30,IRON_FENCE:0,30,LEAVES:7,30,quark:iron_plate_stairs:6,10,quark:iron_plate_stairs:0,10,quark:iron_plate_stairs:5,10,quark:iron_plate_stairs:3,10,quark:iron_plate_slab:8,10,quark:iron_plate_stairs:7,10,quark:iron_plate_stairs:1,10,quark:iron_plate_slab:0,10,quark:iron_plate_stairs:4,10,quark:iron_plate_stairs:2,10,IRON_FENCE:0,50,IRON_FENCE:0,50,LEAVES:7,100)
RandomBlock(6,6,-6,quark:iron_plate:1,70,STAINED_CLAY:15,30,STAINED_CLAY:7,30,quark:iron_plate:1,100)
Block(6,6,-5,AIR:0)
Block(6,6,-4,AIR:0)
RandomBlock(6,6,-3,IRON_FENCE:0,30,IRON_FENCE:0,30,LEAVES:7,30,quark:iron_plate_stairs:6,10,quark:iron_plate_stairs:0,10,quark:iron_plate_stairs:5,10,quark:iron_plate_stairs:3,10,quark:iron_plate_slab:8,10,quark:iron_plate_stairs:7,10,quark:iron_plate_stairs:1,10,quark:iron_plate_slab:0,10,quark:iron_plate_stairs:4,10,quark:iron_plate_stairs:2,10,IRON_FENCE:0,50,IRON_FENCE:0,50,LEAVES:7,100)
RandomBlock(6,7,-6,quark:iron_plate:1,70,STAINED_CLAY:15,30,STAINED_CLAY:7,30,quark:iron_plate:1,100)
Block(6,7,-5,AIR:0)
Block(6,7,-4,AIR:0)
RandomBlock(6,7,-3,IRON_FENCE:0,30,IRON_FENCE:0,30,LEAVES:7,30,quark:iron_plate_stairs:6,10,quark:iron_plate_stairs:0,10,quark:iron_plate_stairs:5,10,quark:iron_plate_stairs:3,10,quark:iron_plate_slab:8,10,quark:iron_plate_stairs:7,10,quark:iron_plate_stairs:1,10,quark:iron_plate_slab:0,10,quark:iron_plate_stairs:4,10,quark:iron_plate_stairs:2,10,IRON_FENCE:0,50,IRON_FENCE:0,50,LEAVES:7,100)
RandomBlock(6,8,-6,quark:iron_plate:1,70,STAINED_CLAY:15,30,STAINED_CLAY:7,30,quark:iron_plate:1,100)
Block(6,8,-5,AIR:0)
Block(6,8,-4,AIR:0)
RandomBlock(6,8,-3,IRON_FENCE:0,30,IRON_FENCE:0,30,LEAVES:7,30,quark:iron_plate_stairs:6,10,quark:iron_plate_stairs:0,10,quark:iron_plate_stairs:5,10,quark:iron_plate_stairs:3,10,quark:iron_plate_slab:8,10,quark:iron_plate_stairs:7,10,quark:iron_plate_stairs:1,10,quark:iron_plate_slab:0,10,quark:iron_plate_stairs:4,10,quark:iron_plate_stairs:2,10,IRON_FENCE:0,50,IRON_FENCE:0,50,LEAVES:7,100)
RandomBlock(6,9,-6,quark:iron_plate:1,70,STAINED_CLAY:15,30,STAINED_CLAY:7,30,quark:iron_plate:1,100)
Block(6,9,-5,AIR:0)
Block(6,9,-4,AIR:0)
RandomBlock(6,9,-3,quark:iron_plate:1,70,STAINED_CLAY:15,30,STAINED_CLAY:7,30,quark:iron_plate:1,100)
RandomBlock(6,10,-6,quark:iron_plate:1,70,STAINED_CLAY:15,30,STAINED_CLAY:7,30,quark:iron_plate:1,100)
Block(6,10,-5,AIR:0)
Block(6,10,-4,AIR:0)
RandomBlock(6,10,-3,IRON_FENCE:0,30,IRON_FENCE:0,30,LEAVES:7,30,quark:iron_plate_stairs:6,10,quark:iron_plate_stairs:0,10,quark:iron_plate_stairs:5,10,quark:iron_plate_stairs:3,10,quark:iron_plate_slab:8,10,quark:iron_plate_stairs:7,10,quark:iron_plate_stairs:1,10,quark:iron_plate_slab:0,10,quark:iron_plate_stairs:4,10,quark:iron_plate_stairs:2,10,IRON_FENCE:0,50,IRON_FENCE:0,50,LEAVES:7,100)
RandomBlock(6,11,-6,quark:iron_plate:1,70,STAINED_CLAY:15,30,STAINED_CLAY:7,30,quark:iron_plate:1,100)
Block(6,11,-5,AIR:0)
Block(6,11,-4,AIR:0)
RandomBlock(6,11,-3,quark:iron_plate:1,70,STAINED_CLAY:15,30,STAINED_CLAY:7,30,quark:iron_plate:1,100)
RandomBlock(6,12,-6,quark:iron_plate:1,70,STAINED_CLAY:15,30,STAINED_CLAY:7,30,quark:iron_plate:1,100)
Block(6,12,-5,AIR:0)
Block(6,12,-4,AIR:0)
RandomBlock(6,12,-3,quark:iron_plate:1,70,STAINED_CLAY:15,30,STAINED_CLAY:7,30,quark:iron_plate:1,100)
RandomBlock(6,13,-6,quark:iron_plate:1,70,STAINED_CLAY:15,30,STAINED_CLAY:7,30,quark:iron_plate:1,100)
Block(6,13,-5,AIR:0)
Block(6,13,-4,AIR:0)
RandomBlock(6,13,-3,quark:iron_plate:1,70,STAINED_CLAY:15,30,STAINED_CLAY:7,30,quark:iron_plate:1,100)
RandomBlock(6,14,-6,quark:iron_plate:1,70,STAINED_CLAY:15,30,STAINED_CLAY:7,30,quark:iron_plate:1,100)
Block(6,14,-5,AIR:0)
Block(6,14,-4,AIR:0)
RandomBlock(6,14,-3,quark:iron_plate:1,70,STAINED_CLAY:15,30,STAINED_CLAY:7,30,quark:iron_plate:1,100)
RandomBlock(6,15,-6,quark:iron_plate:1,70,STAINED_CLAY:15,30,STAINED_CLAY:7,30,quark:iron_plate:1,100)
Block(6,15,-5,AIR:0)
Block(6,15,-4,AIR:0)
RandomBlock(6,15,-3,quark:iron_plate:1,70,STAINED_CLAY:15,30,STAINED_CLAY:7,30,quark:iron_plate:1,100)
RandomBlock(6,16,-6,quark:iron_plate:1,70,STAINED_CLAY:15,30,STAINED_CLAY:7,30,quark:iron_plate:1,100)
Block(6,16,-5,AIR:0)
Block(6,16,-4,AIR:0)
RandomBlock(6,16,-3,quark:iron_plate:1,70,STAINED_CLAY:15,30,STAINED_CLAY:7,30,quark:iron_plate:1,100)
RandomBlock(6,17,-6,IRON_FENCE:0,30,IRON_FENCE:0,30,LEAVES:7,30,quark:iron_plate_stairs:6,10,quark:iron_plate_stairs:0,10,quark:iron_plate_stairs:5,10,quark:iron_plate_stairs:3,10,quark:iron_plate_slab:8,10,quark:iron_plate_stairs:7,10,quark:iron_plate_stairs:1,10,quark:iron_plate_slab:0,10,quark:iron_plate_stairs:4,10,quark:iron_plate_stairs:2,10,IRON_FENCE:0,50,IRON_FENCE:0,50,LEAVES:7,100)
Block(6,17,-5,AIR:0)
Block(6,17,-4,AIR:0)
RandomBlock(6,17,-3,quark:iron_plate:1,70,STAINED_CLAY:15,30,STAINED_CLAY:7,30,quark:iron_plate:1,100)
RandomBlock(6,18,-6,quark:iron_plate:1,70,STAINED_CLAY:15,30,STAINED_CLAY:7,30,quark:iron_plate:1,100)
Block(6,18,-5,AIR:0)
Block(6,18,-4,AIR:0)
RandomBlock(6,18,-3,quark:iron_plate:1,70,STAINED_CLAY:15,30,STAINED_CLAY:7,30,quark:iron_plate:1,100)
RandomBlock(6,19,-6,IRON_FENCE:0,30,IRON_FENCE:0,30,LEAVES:7,30,quark:iron_plate_stairs:6,10,quark:iron_plate_stairs:0,10,quark:iron_plate_stairs:5,10,quark:iron_plate_stairs:3,10,quark:iron_plate_slab:8,10,quark:iron_plate_stairs:7,10,quark:iron_plate_stairs:1,10,quark:iron_plate_slab:0,10,quark:iron_plate_stairs:4,10,quark:iron_plate_stairs:2,10,IRON_FENCE:0,50,IRON_FENCE:0,50,LEAVES:7,100)
Block(6,19,-5,AIR:0)
Block(6,19,-4,AIR:0)
RandomBlock(6,19,-3,quark:iron_plate:1,70,STAINED_CLAY:15,30,STAINED_CLAY:7,30,quark:iron_plate:1,100)
RandomBlock(6,20,-6,IRON_FENCE:0,30,IRON_FENCE:0,30,LEAVES:7,30,quark:iron_plate_stairs:6,10,quark:iron_plate_stairs:0,10,quark:iron_plate_stairs:5,10,quark:iron_plate_stairs:3,10,quark:iron_plate_slab:8,10,quark:iron_plate_stairs:7,10,quark:iron_plate_stairs:1,10,quark:iron_plate_slab:0,10,quark:iron_plate_stairs:4,10,quark:iron_plate_stairs:2,10,IRON_FENCE:0,50,IRON_FENCE:0,50,LEAVES:7,100)
Block(6,20,-5,AIR:0)
Block(6,20,-4,AIR:0)
RandomBlock(6,20,-3,IRON_FENCE:0,30,IRON_FENCE:0,30,LEAVES:7,30,quark:iron_plate_stairs:6,10,quark:iron_plate_stairs:0,10,quark:iron_plate_stairs:5,10,quark:iron_plate_stairs:3,10,quark:iron_plate_slab:8,10,quark:iron_plate_stairs:7,10,quark:iron_plate_stairs:1,10,quark:iron_plate_slab:0,10,quark:iron_plate_stairs:4,10,quark:iron_plate_stairs:2,10,IRON_FENCE:0,50,IRON_FENCE:0,50,LEAVES:7,100)
RandomBlock(6,21,-6,IRON_FENCE:0,30,IRON_FENCE:0,30,LEAVES:7,30,quark:iron_plate_stairs:6,10,quark:iron_plate_stairs:0,10,quark:iron_plate_stairs:5,10,quark:iron_plate_stairs:3,10,quark:iron_plate_slab:8,10,quark:iron_plate_stairs:7,10,quark:iron_plate_stairs:1,10,quark:iron_plate_slab:0,10,quark:iron_plate_stairs:4,10,quark:iron_plate_stairs:2,10,IRON_FENCE:0,50,IRON_FENCE:0,50,LEAVES:7,100)
Block(6,21,-5,AIR:0)
Block(6,21,-4,AIR:0)
RandomBlock(6,21,-3,IRON_FENCE:0,30,IRON_FENCE:0,30,LEAVES:7,30,quark:iron_plate_stairs:6,10,quark:iron_plate_stairs:0,10,quark:iron_plate_stairs:5,10,quark:iron_plate_stairs:3,10,quark:iron_plate_slab:8,10,quark:iron_plate_stairs:7,10,quark:iron_plate_stairs:1,10,quark:iron_plate_slab:0,10,quark:iron_plate_stairs:4,10,quark:iron_plate_stairs:2,10,IRON_FENCE:0,50,IRON_FENCE:0,50,LEAVES:7,100)
RandomBlock(6,22,-6,IRON_FENCE:0,30,IRON_FENCE:0,30,LEAVES:7,30,quark:iron_plate_stairs:6,10,quark:iron_plate_stairs:0,10,quark:iron_plate_stairs:5,10,quark:iron_plate_stairs:3,10,quark:iron_plate_slab:8,10,quark:iron_plate_stairs:7,10,quark:iron_plate_stairs:1,10,quark:iron_plate_slab:0,10,quark:iron_plate_stairs:4,10,quark:iron_plate_stairs:2,10,IRON_FENCE:0,50,IRON_FENCE:0,50,LEAVES:7,100)
Block(6,22,-5,AIR:0)
Block(6,22,-4,AIR:0)
RandomBlock(6,22,-3,quark:iron_plate:1,70,STAINED_CLAY:15,30,STAINED_CLAY:7,30,quark:iron_plate:1,100)
RandomBlock(6,23,-6,quark:iron_plate:1,70,STAINED_CLAY:15,30,STAINED_CLAY:7,30,quark:iron_plate:1,100)
Block(6,23,-5,AIR:0)
Block(6,23,-4,AIR:0)
RandomBlock(6,23,-3,quark:iron_plate:1,70,STAINED_CLAY:15,30,STAINED_CLAY:7,30,quark:iron_plate:1,100)
RandomBlock(6,24,-6,quark:iron_plate:1,70,STAINED_CLAY:15,30,STAINED_CLAY:7,30,quark:iron_plate:1,100)
Block(6,24,-5,AIR:0)
Block(6,24,-4,AIR:0)
RandomBlock(6,24,-3,quark:iron_plate:1,70,STAINED_CLAY:15,30,STAINED_CLAY:7,30,quark:iron_plate:1,100)
RandomBlock(6,25,-6,quark:iron_plate:1,70,STAINED_CLAY:15,30,STAINED_CLAY:7,30,quark:iron_plate:1,100)
Block(6,25,-5,AIR:0)
Block(6,25,-4,AIR:0)
RandomBlock(6,25,-3,quark:iron_plate:1,70,STAINED_CLAY:15,30,STAINED_CLAY:7,30,quark:iron_plate:1,100)
RandomBlock(6,26,-6,quark:iron_plate:1,70,STAINED_CLAY:15,30,STAINED_CLAY:7,30,quark:iron_plate:1,100)
Block(6,26,-5,AIR:0)
Block(6,26,-4,AIR:0)
RandomBlock(6,26,-3,quark:iron_plate:1,70,STAINED_CLAY:15,30,STAINED_CLAY:7,30,quark:iron_plate:1,100)
RandomBlock(6,27,-6,quark:iron_plate:1,70,STAINED_CLAY:15,30,STAINED_CLAY:7,30,quark:iron_plate:1,100)
Block(6,27,-5,AIR:0)
Block(6,27,-4,AIR:0)
RandomBlock(6,27,-3,quark:iron_plate:1,70,STAINED_CLAY:15,30,STAINED_CLAY:7,30,quark:iron_plate:1,100)
RandomBlock(6,28,-6,quark:iron_plate:1,70,STAINED_CLAY:15,30,STAINED_CLAY:7,30,quark:iron_plate:1,100)
Block(6,28,-5,AIR:0)
Block(6,28,-4,AIR:0)
RandomBlock(6,28,-3,quark:iron_plate:1,70,STAINED_CLAY:15,30,STAINED_CLAY:7,30,quark:iron_plate:1,100)
RandomBlock(6,29,-6,quark:iron_plate:1,70,STAINED_CLAY:15,30,STAINED_CLAY:7,30,quark:iron_plate:1,100)
Block(6,29,-5,AIR:0)
Block(6,29,-4,AIR:0)
RandomBlock(6,29,-3,quark:iron_plate:1,70,STAINED_CLAY:15,30,STAINED_CLAY:7,30,quark:iron_plate:1,100)
RandomBlock(6,30,-6,quark:iron_plate:1,70,STAINED_CLAY:15,30,STAINED_CLAY:7,30,quark:iron_plate:1,100)
Block(6,30,-5,AIR:0)
Block(6,30,-4,AIR:0)
RandomBlock(6,30,-3,quark:iron_plate:1,70,STAINED_CLAY:15,30,STAINED_CLAY:7,30,quark:iron_plate:1,100)
RandomBlock(6,31,-6,quark:iron_plate:1,70,STAINED_CLAY:15,30,STAINED_CLAY:7,30,quark:iron_plate:1,100)
Block(6,31,-5,AIR:0)
Block(6,31,-4,AIR:0)
RandomBlock(6,31,-3,quark:iron_plate:1,70,STAINED_CLAY:15,30,STAINED_CLAY:7,30,quark:iron_plate:1,100)
RandomBlock(6,32,-6,quark:iron_plate:1,70,STAINED_CLAY:15,30,STAINED_CLAY:7,30,quark:iron_plate:1,100)
Block(6,32,-5,AIR:0)
Block(6,32,-4,AIR:0)
RandomBlock(6,32,-3,quark:iron_plate:1,70,STAINED_CLAY:15,30,STAINED_CLAY:7,30,quark:iron_plate:1,100)
RandomBlock(6,33,-6,IRON_FENCE:0,30,IRON_FENCE:0,30,LEAVES:7,30,quark:iron_plate_stairs:6,10,quark:iron_plate_stairs:0,10,quark:iron_plate_stairs:5,10,quark:iron_plate_stairs:3,10,quark:iron_plate_slab:8,10,quark:iron_plate_stairs:7,10,quark:iron_plate_stairs:1,10,quark:iron_plate_slab:0,10,quark:iron_plate_stairs:4,10,quark:iron_plate_stairs:2,10,IRON_FENCE:0,50,IRON_FENCE:0,50,LEAVES:7,100)
Block(6,33,-5,AIR:0)
Block(6,33,-4,AIR:0)
RandomBlock(6,33,-3,quark:iron_plate:1,70,STAINED_CLAY:15,30,STAINED_CLAY:7,30,quark:iron_plate:1,100)
RandomBlock(6,34,-6,IRON_FENCE:0,30,IRON_FENCE:0,30,LEAVES:7,30,quark:iron_plate_stairs:6,10,quark:iron_plate_stairs:0,10,quark:iron_plate_stairs:5,10,quark:iron_plate_stairs:3,10,quark:iron_plate_slab:8,10,quark:iron_plate_stairs:7,10,quark:iron_plate_stairs:1,10,quark:iron_plate_slab:0,10,quark:iron_plate_stairs:4,10,quark:iron_plate_stairs:2,10,IRON_FENCE:0,50,IRON_FENCE:0,50,LEAVES:7,100)
Block(6,34,-5,AIR:0)
Block(6,34,-4,AIR:0)
RandomBlock(6,34,-3,IRON_FENCE:0,30,IRON_FENCE:0,30,LEAVES:7,30,quark:iron_plate_stairs:6,10,quark:iron_plate_stairs:0,10,quark:iron_plate_stairs:5,10,quark:iron_plate_stairs:3,10,quark:iron_plate_slab:8,10,quark:iron_plate_stairs:7,10,quark:iron_plate_stairs:1,10,quark:iron_plate_slab:0,10,quark:iron_plate_stairs:4,10,quark:iron_plate_stairs:2,10,IRON_FENCE:0,50,IRON_FENCE:0,50,LEAVES:7,100)
RandomBlock(6,35,-6,IRON_FENCE:0,30,IRON_FENCE:0,30,LEAVES:7,30,quark:iron_plate_stairs:6,10,quark:iron_plate_stairs:0,10,quark:iron_plate_stairs:5,10,quark:iron_plate_stairs:3,10,quark:iron_plate_slab:8,10,quark:iron_plate_stairs:7,10,quark:iron_plate_stairs:1,10,quark:iron_plate_slab:0,10,quark:iron_plate_stairs:4,10,quark:iron_plate_stairs:2,10,IRON_FENCE:0,50,IRON_FENCE:0,50,LEAVES:7,100)
Block(6,35,-5,AIR:0)
Block(6,35,-4,AIR:0)
RandomBlock(6,35,-3,IRON_FENCE:0,30,IRON_FENCE:0,30,LEAVES:7,30,quark:iron_plate_stairs:6,10,quark:iron_plate_stairs:0,10,quark:iron_plate_stairs:5,10,quark:iron_plate_stairs:3,10,quark:iron_plate_slab:8,10,quark:iron_plate_stairs:7,10,quark:iron_plate_stairs:1,10,quark:iron_plate_slab:0,10,quark:iron_plate_stairs:4,10,quark:iron_plate_stairs:2,10,IRON_FENCE:0,50,IRON_FENCE:0,50,LEAVES:7,100)
RandomBlock(6,36,-6,IRON_FENCE:0,30,IRON_FENCE:0,30,LEAVES:7,30,quark:iron_plate_stairs:6,10,quark:iron_plate_stairs:0,10,quark:iron_plate_stairs:5,10,quark:iron_plate_stairs:3,10,quark:iron_plate_slab:8,10,quark:iron_plate_stairs:7,10,quark:iron_plate_stairs:1,10,quark:iron_plate_slab:0,10,quark:iron_plate_stairs:4,10,quark:iron_plate_stairs:2,10,IRON_FENCE:0,50,IRON_FENCE:0,50,LEAVES:7,100)
Block(6,36,-5,AIR:0)
Block(6,36,-4,AIR:0)
RandomBlock(6,36,-3,IRON_FENCE:0,30,IRON_FENCE:0,30,LEAVES:7,30,quark:iron_plate_stairs:6,10,quark:iron_plate_stairs:0,10,quark:iron_plate_stairs:5,10,quark:iron_plate_stairs:3,10,quark:iron_plate_slab:8,10,quark:iron_plate_stairs:7,10,quark:iron_plate_stairs:1,10,quark:iron_plate_slab:0,10,quark:iron_plate_stairs:4,10,quark:iron_plate_stairs:2,10,IRON_FENCE:0,50,IRON_FENCE:0,50,LEAVES:7,100)
RandomBlock(6,37,-6,IRON_FENCE:0,30,IRON_FENCE:0,30,LEAVES:7,30,quark:iron_plate_stairs:6,10,quark:iron_plate_stairs:0,10,quark:iron_plate_stairs:5,10,quark:iron_plate_stairs:3,10,quark:iron_plate_slab:8,10,quark:iron_plate_stairs:7,10,quark:iron_plate_stairs:1,10,quark:iron_plate_slab:0,10,quark:iron_plate_stairs:4,10,quark:iron_plate_stairs:2,10,IRON_FENCE:0,50,IRON_FENCE:0,50,LEAVES:7,100)
Block(6,37,-5,AIR:0)
Block(6,37,-4,AIR:0)
RandomBlock(6,37,-3,IRON_FENCE:0,30,IRON_FENCE:0,30,LEAVES:7,30,quark:iron_plate_stairs:6,10,quark:iron_plate_stairs:0,10,quark:iron_plate_stairs:5,10,quark:iron_plate_stairs:3,10,quark:iron_plate_slab:8,10,quark:iron_plate_stairs:7,10,quark:iron_plate_stairs:1,10,quark:iron_plate_slab:0,10,quark:iron_plate_stairs:4,10,quark:iron_plate_stairs:2,10,IRON_FENCE:0,50,IRON_FENCE:0,50,LEAVES:7,100)
RandomBlock(6,38,-6,IRON_FENCE:0,30,IRON_FENCE:0,30,LEAVES:7,30,quark:iron_plate_stairs:6,10,quark:iron_plate_stairs:0,10,quark:iron_plate_stairs:5,10,quark:iron_plate_stairs:3,10,quark:iron_plate_slab:8,10,quark:iron_plate_stairs:7,10,quark:iron_plate_stairs:1,10,quark:iron_plate_slab:0,10,quark:iron_plate_stairs:4,10,quark:iron_plate_stairs:2,10,IRON_FENCE:0,50,IRON_FENCE:0,50,LEAVES:7,100)
Block(6,38,-5,AIR:0)
Block(6,38,-4,AIR:0)
RandomBlock(6,38,-3,quark:iron_plate:1,70,STAINED_CLAY:15,30,STAINED_CLAY:7,30,quark:iron_plate:1,100)
RandomBlock(6,39,-6,IRON_FENCE:0,30,IRON_FENCE:0,30,LEAVES:7,30,quark:iron_plate_stairs:6,10,quark:iron_plate_stairs:0,10,quark:iron_plate_stairs:5,10,quark:iron_plate_stairs:3,10,quark:iron_plate_slab:8,10,quark:iron_plate_stairs:7,10,quark:iron_plate_stairs:1,10,quark:iron_plate_slab:0,10,quark:iron_plate_stairs:4,10,quark:iron_plate_stairs:2,10,IRON_FENCE:0,50,IRON_FENCE:0,50,LEAVES:7,100)
Block(6,39,-5,AIR:0)
Block(6,39,-4,AIR:0)
RandomBlock(6,39,-3,quark:iron_plate:1,70,STAINED_CLAY:15,30,STAINED_CLAY:7,30,quark:iron_plate:1,100)
RandomBlock(6,40,-6,IRON_FENCE:0,30,IRON_FENCE:0,30,LEAVES:7,30,quark:iron_plate_stairs:6,10,quark:iron_plate_stairs:0,10,quark:iron_plate_stairs:5,10,quark:iron_plate_stairs:3,10,quark:iron_plate_slab:8,10,quark:iron_plate_stairs:7,10,quark:iron_plate_stairs:1,10,quark:iron_plate_slab:0,10,quark:iron_plate_stairs:4,10,quark:iron_plate_stairs:2,10,IRON_FENCE:0,50,IRON_FENCE:0,50,LEAVES:7,100)
Block(6,40,-5,AIR:0)
Block(6,40,-4,AIR:0)
RandomBlock(6,40,-3,quark:iron_plate:1,70,STAINED_CLAY:15,30,STAINED_CLAY:7,30,quark:iron_plate:1,100)
RandomBlock(6,41,-6,quark:iron_plate:1,70,STAINED_CLAY:15,30,STAINED_CLAY:7,30,quark:iron_plate:1,100)
Block(6,41,-5,AIR:0)
Block(6,41,-4,AIR:0)
RandomBlock(6,41,-3,quark:iron_plate:1,70,STAINED_CLAY:15,30,STAINED_CLAY:7,30,quark:iron_plate:1,100)
RandomBlock(6,42,-6,IRON_FENCE:0,30,IRON_FENCE:0,30,LEAVES:7,30,quark:iron_plate_stairs:6,10,quark:iron_plate_stairs:0,10,quark:iron_plate_stairs:5,10,quark:iron_plate_stairs:3,10,quark:iron_plate_slab:8,10,quark:iron_plate_stairs:7,10,quark:iron_plate_stairs:1,10,quark:iron_plate_slab:0,10,quark:iron_plate_stairs:4,10,quark:iron_plate_stairs:2,10,IRON_FENCE:0,50,IRON_FENCE:0,50,LEAVES:7,100)
Block(6,42,-5,AIR:0)
Block(6,42,-4,AIR:0)
RandomBlock(6,42,-3,quark:iron_plate:1,70,STAINED_CLAY:15,30,STAINED_CLAY:7,30,quark:iron_plate:1,100)
RandomBlock(6,43,-6,IRON_FENCE:0,30,IRON_FENCE:0,30,LEAVES:7,30,quark:iron_plate_stairs:6,10,quark:iron_plate_stairs:0,10,quark:iron_plate_stairs:5,10,quark:iron_plate_stairs:3,10,quark:iron_plate_slab:8,10,quark:iron_plate_stairs:7,10,quark:iron_plate_stairs:1,10,quark:iron_plate_slab:0,10,quark:iron_plate_stairs:4,10,quark:iron_plate_stairs:2,10,IRON_FENCE:0,50,IRON_FENCE:0,50,LEAVES:7,100)
Block(6,43,-5,AIR:0)
Block(6,43,-4,AIR:0)
RandomBlock(6,43,-3,quark:iron_plate:1,70,STAINED_CLAY:15,30,STAINED_CLAY:7,30,quark:iron_plate:1,100)
RandomBlock(6,44,-6,quark:iron_plate:1,70,STAINED_CLAY:15,30,STAINED_CLAY:7,30,quark:iron_plate:1,100)
Block(6,44,-5,AIR:0)
Block(6,44,-4,AIR:0)
RandomBlock(6,44,-3,quark:iron_plate:1,70,STAINED_CLAY:15,30,STAINED_CLAY:7,30,quark:iron_plate:1,100)
RandomBlock(6,45,-6,quark:iron_plate:1,70,STAINED_CLAY:15,30,STAINED_CLAY:7,30,quark:iron_plate:1,100)
Block(6,45,-5,AIR:0)
Block(6,45,-4,AIR:0)
RandomBlock(6,45,-3,IRON_FENCE:0,30,IRON_FENCE:0,30,LEAVES:7,30,quark:iron_plate_stairs:6,10,quark:iron_plate_stairs:0,10,quark:iron_plate_stairs:5,10,quark:iron_plate_stairs:3,10,quark:iron_plate_slab:8,10,quark:iron_plate_stairs:7,10,quark:iron_plate_stairs:1,10,quark:iron_plate_slab:0,10,quark:iron_plate_stairs:4,10,quark:iron_plate_stairs:2,10,IRON_FENCE:0,50,IRON_FENCE:0,50,LEAVES:7,100)
RandomBlock(6,46,-6,quark:iron_plate:1,70,STAINED_CLAY:15,30,STAINED_CLAY:7,30,quark:iron_plate:1,100)
Block(6,46,-5,AIR:0)
Block(6,46,-4,AIR:0)
RandomBlock(6,46,-3,quark:iron_plate:1,70,STAINED_CLAY:15,30,STAINED_CLAY:7,30,quark:iron_plate:1,100)
RandomBlock(6,47,-6,quark:iron_plate:1,70,STAINED_CLAY:15,30,STAINED_CLAY:7,30,quark:iron_plate:1,100)
Block(6,47,-5,AIR:0)
Block(6,47,-4,AIR:0)
RandomBlock(6,47,-3,quark:iron_plate:1,70,STAINED_CLAY:15,30,STAINED_CLAY:7,30,quark:iron_plate:1,100)
RandomBlock(6,48,-6,quark:iron_plate:1,70,STAINED_CLAY:15,30,STAINED_CLAY:7,30,quark:iron_plate:1,100)
Block(6,48,-5,AIR:0)
Block(6,48,-4,AIR:0)
RandomBlock(6,48,-3,quark:iron_plate:1,70,STAINED_CLAY:15,30,STAINED_CLAY:7,30,quark:iron_plate:1,100)
RandomBlock(6,49,-6,quark:iron_plate:1,70,STAINED_CLAY:15,30,STAINED_CLAY:7,30,quark:iron_plate:1,100)
Block(6,49,-5,AIR:0)
Block(6,49,-4,AIR:0)
RandomBlock(6,49,-3,quark:iron_plate:1,70,STAINED_CLAY:15,30,STAINED_CLAY:7,30,quark:iron_plate:1,100)
RandomBlock(6,50,-6,quark:iron_plate:1,70,STAINED_CLAY:15,30,STAINED_CLAY:7,30,quark:iron_plate:1,100)
Block(6,50,-5,AIR:0)
Block(6,50,-4,AIR:0)
RandomBlock(6,50,-3,quark:iron_plate:1,70,STAINED_CLAY:15,30,STAINED_CLAY:7,30,quark:iron_plate:1,100)
RandomBlock(6,51,-6,quark:iron_plate:1,70,STAINED_CLAY:15,30,STAINED_CLAY:7,30,quark:iron_plate:1,100)
Block(6,51,-5,AIR:0)
Block(6,51,-4,AIR:0)
RandomBlock(6,51,-3,quark:iron_plate:1,70,STAINED_CLAY:15,30,STAINED_CLAY:7,30,quark:iron_plate:1,100)
RandomBlock(6,52,-6,IRON_FENCE:0,30,IRON_FENCE:0,30,LEAVES:7,30,quark:iron_plate_stairs:6,10,quark:iron_plate_stairs:0,10,quark:iron_plate_stairs:5,10,quark:iron_plate_stairs:3,10,quark:iron_plate_slab:8,10,quark:iron_plate_stairs:7,10,quark:iron_plate_stairs:1,10,quark:iron_plate_slab:0,10,quark:iron_plate_stairs:4,10,quark:iron_plate_stairs:2,10,IRON_FENCE:0,50,IRON_FENCE:0,50,LEAVES:7,100)
Block(6,52,-5,AIR:0)
Block(6,52,-4,AIR:0)
RandomBlock(6,52,-3,quark:iron_plate:1,70,STAINED_CLAY:15,30,STAINED_CLAY:7,30,quark:iron_plate:1,100)
RandomBlock(6,53,-6,IRON_FENCE:0,30,IRON_FENCE:0,30,LEAVES:7,30,quark:iron_plate_stairs:6,10,quark:iron_plate_stairs:0,10,quark:iron_plate_stairs:5,10,quark:iron_plate_stairs:3,10,quark:iron_plate_slab:8,10,quark:iron_plate_stairs:7,10,quark:iron_plate_stairs:1,10,quark:iron_plate_slab:0,10,quark:iron_plate_stairs:4,10,quark:iron_plate_stairs:2,10,IRON_FENCE:0,50,IRON_FENCE:0,50,LEAVES:7,100)
Block(6,53,-5,AIR:0)
Block(6,53,-4,AIR:0)
RandomBlock(6,53,-3,quark:iron_plate:1,70,STAINED_CLAY:15,30,STAINED_CLAY:7,30,quark:iron_plate:1,100)
RandomBlock(6,54,-6,IRON_FENCE:0,30,IRON_FENCE:0,30,LEAVES:7,30,quark:iron_plate_stairs:6,10,quark:iron_plate_stairs:0,10,quark:iron_plate_stairs:5,10,quark:iron_plate_stairs:3,10,quark:iron_plate_slab:8,10,quark:iron_plate_stairs:7,10,quark:iron_plate_stairs:1,10,quark:iron_plate_slab:0,10,quark:iron_plate_stairs:4,10,quark:iron_plate_stairs:2,10,IRON_FENCE:0,50,IRON_FENCE:0,50,LEAVES:7,100)
Block(6,54,-5,AIR:0)
Block(6,54,-4,AIR:0)
RandomBlock(6,54,-3,quark:iron_plate:1,70,STAINED_CLAY:15,30,STAINED_CLAY:7,30,quark:iron_plate:1,100)
RandomBlock(6,55,-6,IRON_FENCE:0,30,IRON_FENCE:0,30,LEAVES:7,30,quark:iron_plate_stairs:6,10,quark:iron_plate_stairs:0,10,quark:iron_plate_stairs:5,10,quark:iron_plate_stairs:3,10,quark:iron_plate_slab:8,10,quark:iron_plate_stairs:7,10,quark:iron_plate_stairs:1,10,quark:iron_plate_slab:0,10,quark:iron_plate_stairs:4,10,quark:iron_plate_stairs:2,10,IRON_FENCE:0,50,IRON_FENCE:0,50,LEAVES:7,100)
Block(6,55,-5,AIR:0)
Block(6,55,-4,AIR:0)
RandomBlock(6,55,-3,quark:iron_plate:1,70,STAINED_CLAY:15,30,STAINED_CLAY:7,30,quark:iron_plate:1,100)
RandomBlock(6,56,-6,quark:iron_plate:1,70,STAINED_CLAY:15,30,STAINED_CLAY:7,30,quark:iron_plate:1,100)
Block(6,56,-5,AIR:0)
Block(6,56,-4,AIR:0)
RandomBlock(6,56,-3,quark:iron_plate:1,70,STAINED_CLAY:15,30,STAINED_CLAY:7,30,quark:iron_plate:1,100)
RandomBlock(6,57,-6,quark:iron_plate:1,70,STAINED_CLAY:15,30,STAINED_CLAY:7,30,quark:iron_plate:1,100)
Block(6,57,-5,AIR:0)
Block(6,57,-4,AIR:0)
RandomBlock(6,57,-3,IRON_FENCE:0,30,IRON_FENCE:0,30,LEAVES:7,30,quark:iron_plate_stairs:6,10,quark:iron_plate_stairs:0,10,quark:iron_plate_stairs:5,10,quark:iron_plate_stairs:3,10,quark:iron_plate_slab:8,10,quark:iron_plate_stairs:7,10,quark:iron_plate_stairs:1,10,quark:iron_plate_slab:0,10,quark:iron_plate_stairs:4,10,quark:iron_plate_stairs:2,10,IRON_FENCE:0,50,IRON_FENCE:0,50,LEAVES:7,100)
RandomBlock(6,58,-6,quark:iron_plate:1,70,STAINED_CLAY:15,30,STAINED_CLAY:7,30,quark:iron_plate:1,100)
Block(6,58,-5,AIR:0)
Block(6,58,-4,AIR:0)
RandomBlock(6,58,-3,quark:iron_plate:1,70,STAINED_CLAY:15,30,STAINED_CLAY:7,30,quark:iron_plate:1,100)
RandomBlock(6,59,-6,quark:iron_plate:1,70,STAINED_CLAY:15,30,STAINED_CLAY:7,30,quark:iron_plate:1,100)
Block(6,59,-5,AIR:0)
Block(6,59,-4,AIR:0)
RandomBlock(6,59,-3,quark:iron_plate:1,70,STAINED_CLAY:15,30,STAINED_CLAY:7,30,quark:iron_plate:1,100)
RandomBlock(6,60,-6,quark:iron_plate:1,70,STAINED_CLAY:15,30,STAINED_CLAY:7,30,quark:iron_plate:1,100)
Block(6,60,-5,AIR:0)
Block(6,60,-4,AIR:0)
RandomBlock(6,60,-3,quark:iron_plate:1,70,STAINED_CLAY:15,30,STAINED_CLAY:7,30,quark:iron_plate:1,100)
RandomBlock(6,61,-6,quark:iron_plate:1,70,STAINED_CLAY:15,30,STAINED_CLAY:7,30,quark:iron_plate:1,100)
Block(6,61,-5,AIR:0)
Block(6,61,-4,AIR:0)
RandomBlock(6,61,-3,quark:iron_plate:1,70,STAINED_CLAY:15,30,STAINED_CLAY:7,30,quark:iron_plate:1,100)
RandomBlock(6,62,-6,quark:iron_plate:1,70,STAINED_CLAY:15,30,STAINED_CLAY:7,30,quark:iron_plate:1,100)
Block(6,62,-5,AIR:0)
Block(6,62,-4,AIR:0)
RandomBlock(6,62,-3,quark:iron_plate:1,70,STAINED_CLAY:15,30,STAINED_CLAY:7,30,quark:iron_plate:1,100)
RandomBlock(6,63,-6,quark:iron_plate:1,70,STAINED_CLAY:15,30,STAINED_CLAY:7,30,quark:iron_plate:1,100)
Block(6,63,-5,AIR:0)
Block(6,63,-4,AIR:0)
RandomBlock(6,63,-3,quark:iron_plate:1,70,STAINED_CLAY:15,30,STAINED_CLAY:7,30,quark:iron_plate:1,100)
RandomBlock(6,64,-6,quark:iron_plate:1,70,STAINED_CLAY:15,30,STAINED_CLAY:7,30,quark:iron_plate:1,100)
Block(6,64,-5,AIR:0)
Block(6,64,-4,AIR:0)
RandomBlock(6,64,-3,quark:iron_plate:1,70,STAINED_CLAY:15,30,STAINED_CLAY:7,30,quark:iron_plate:1,100)
RandomBlock(6,65,-6,quark:iron_plate:1,70,STAINED_CLAY:15,30,STAINED_CLAY:7,30,quark:iron_plate:1,100)
Block(6,65,-5,AIR:0)
Block(6,65,-4,AIR:0)
RandomBlock(6,65,-3,quark:iron_plate:1,70,STAINED_CLAY:15,30,STAINED_CLAY:7,30,quark:iron_plate:1,100)
RandomBlock(7,0,-6,quark:iron_plate:1,70,STAINED_CLAY:15,30,STAINED_CLAY:7,30,quark:iron_plate:1,100)
Block(7,0,-5,AIR:0)
Block(7,0,-4,AIR:0)
RandomBlock(7,0,-3,quark:iron_plate:1,70,STAINED_CLAY:15,30,STAINED_CLAY:7,30,quark:iron_plate:1,100)
RandomBlock(7,1,-6,quark:iron_plate:1,70,STAINED_CLAY:15,30,STAINED_CLAY:7,30,quark:iron_plate:1,100)
Block(7,1,-5,AIR:0)
Block(7,1,-4,AIR:0)
RandomBlock(7,1,-3,quark:iron_plate:1,70,STAINED_CLAY:15,30,STAINED_CLAY:7,30,quark:iron_plate:1,100)
RandomBlock(7,2,-6,quark:iron_plate:1,70,STAINED_CLAY:15,30,STAINED_CLAY:7,30,quark:iron_plate:1,100)
Block(7,2,-5,AIR:0)
Block(7,2,-4,AIR:0)
RandomBlock(7,2,-3,quark:iron_plate:1,70,STAINED_CLAY:15,30,STAINED_CLAY:7,30,quark:iron_plate:1,100)
RandomBlock(7,3,-6,quark:iron_plate:1,70,STAINED_CLAY:15,30,STAINED_CLAY:7,30,quark:iron_plate:1,100)
Block(7,3,-5,AIR:0)
Block(7,3,-4,AIR:0)
RandomBlock(7,3,-3,IRON_FENCE:0,30,IRON_FENCE:0,30,LEAVES:7,30,quark:iron_plate_stairs:6,10,quark:iron_plate_stairs:0,10,quark:iron_plate_stairs:5,10,quark:iron_plate_stairs:3,10,quark:iron_plate_slab:8,10,quark:iron_plate_stairs:7,10,quark:iron_plate_stairs:1,10,quark:iron_plate_slab:0,10,quark:iron_plate_stairs:4,10,quark:iron_plate_stairs:2,10,IRON_FENCE:0,50,IRON_FENCE:0,50,LEAVES:7,100)
RandomBlock(7,4,-6,quark:iron_plate:1,70,STAINED_CLAY:15,30,STAINED_CLAY:7,30,quark:iron_plate:1,100)
Block(7,4,-5,AIR:0)
Block(7,4,-4,AIR:0)
RandomBlock(7,4,-3,IRON_FENCE:0,30,IRON_FENCE:0,30,LEAVES:7,30,quark:iron_plate_stairs:6,10,quark:iron_plate_stairs:0,10,quark:iron_plate_stairs:5,10,quark:iron_plate_stairs:3,10,quark:iron_plate_slab:8,10,quark:iron_plate_stairs:7,10,quark:iron_plate_stairs:1,10,quark:iron_plate_slab:0,10,quark:iron_plate_stairs:4,10,quark:iron_plate_stairs:2,10,IRON_FENCE:0,50,IRON_FENCE:0,50,LEAVES:7,100)
RandomBlock(7,5,-6,quark:iron_plate:1,70,STAINED_CLAY:15,30,STAINED_CLAY:7,30,quark:iron_plate:1,100)
Block(7,5,-5,AIR:0)
Block(7,5,-4,AIR:0)
RandomBlock(7,5,-3,IRON_FENCE:0,30,IRON_FENCE:0,30,LEAVES:7,30,quark:iron_plate_stairs:6,10,quark:iron_plate_stairs:0,10,quark:iron_plate_stairs:5,10,quark:iron_plate_stairs:3,10,quark:iron_plate_slab:8,10,quark:iron_plate_stairs:7,10,quark:iron_plate_stairs:1,10,quark:iron_plate_slab:0,10,quark:iron_plate_stairs:4,10,quark:iron_plate_stairs:2,10,IRON_FENCE:0,50,IRON_FENCE:0,50,LEAVES:7,100)
RandomBlock(7,6,-6,quark:iron_plate:1,70,STAINED_CLAY:15,30,STAINED_CLAY:7,30,quark:iron_plate:1,100)
Block(7,6,-5,AIR:0)
Block(7,6,-4,AIR:0)
RandomBlock(7,6,-3,IRON_FENCE:0,30,IRON_FENCE:0,30,LEAVES:7,30,quark:iron_plate_stairs:6,10,quark:iron_plate_stairs:0,10,quark:iron_plate_stairs:5,10,quark:iron_plate_stairs:3,10,quark:iron_plate_slab:8,10,quark:iron_plate_stairs:7,10,quark:iron_plate_stairs:1,10,quark:iron_plate_slab:0,10,quark:iron_plate_stairs:4,10,quark:iron_plate_stairs:2,10,IRON_FENCE:0,50,IRON_FENCE:0,50,LEAVES:7,100)
RandomBlock(7,7,-6,quark:iron_plate:1,70,STAINED_CLAY:15,30,STAINED_CLAY:7,30,quark:iron_plate:1,100)
Block(7,7,-5,AIR:0)
Block(7,7,-4,AIR:0)
RandomBlock(7,7,-3,IRON_FENCE:0,30,IRON_FENCE:0,30,LEAVES:7,30,quark:iron_plate_stairs:6,10,quark:iron_plate_stairs:0,10,quark:iron_plate_stairs:5,10,quark:iron_plate_stairs:3,10,quark:iron_plate_slab:8,10,quark:iron_plate_stairs:7,10,quark:iron_plate_stairs:1,10,quark:iron_plate_slab:0,10,quark:iron_plate_stairs:4,10,quark:iron_plate_stairs:2,10,IRON_FENCE:0,50,IRON_FENCE:0,50,LEAVES:7,100)
RandomBlock(7,8,-6,quark:iron_plate:1,70,STAINED_CLAY:15,30,STAINED_CLAY:7,30,quark:iron_plate:1,100)
Block(7,8,-5,AIR:0)
Block(7,8,-4,AIR:0)
RandomBlock(7,8,-3,IRON_FENCE:0,30,IRON_FENCE:0,30,LEAVES:7,30,quark:iron_plate_stairs:6,10,quark:iron_plate_stairs:0,10,quark:iron_plate_stairs:5,10,quark:iron_plate_stairs:3,10,quark:iron_plate_slab:8,10,quark:iron_plate_stairs:7,10,quark:iron_plate_stairs:1,10,quark:iron_plate_slab:0,10,quark:iron_plate_stairs:4,10,quark:iron_plate_stairs:2,10,IRON_FENCE:0,50,IRON_FENCE:0,50,LEAVES:7,100)
RandomBlock(7,9,-6,quark:iron_plate:1,70,STAINED_CLAY:15,30,STAINED_CLAY:7,30,quark:iron_plate:1,100)
Block(7,9,-5,AIR:0)
Block(7,9,-4,AIR:0)
RandomBlock(7,9,-3,IRON_FENCE:0,30,IRON_FENCE:0,30,LEAVES:7,30,quark:iron_plate_stairs:6,10,quark:iron_plate_stairs:0,10,quark:iron_plate_stairs:5,10,quark:iron_plate_stairs:3,10,quark:iron_plate_slab:8,10,quark:iron_plate_stairs:7,10,quark:iron_plate_stairs:1,10,quark:iron_plate_slab:0,10,quark:iron_plate_stairs:4,10,quark:iron_plate_stairs:2,10,IRON_FENCE:0,50,IRON_FENCE:0,50,LEAVES:7,100)
RandomBlock(7,10,-6,quark:iron_plate:1,70,STAINED_CLAY:15,30,STAINED_CLAY:7,30,quark:iron_plate:1,100)
Block(7,10,-5,AIR:0)
Block(7,10,-4,AIR:0)
RandomBlock(7,10,-3,IRON_FENCE:0,30,IRON_FENCE:0,30,LEAVES:7,30,quark:iron_plate_stairs:6,10,quark:iron_plate_stairs:0,10,quark:iron_plate_stairs:5,10,quark:iron_plate_stairs:3,10,quark:iron_plate_slab:8,10,quark:iron_plate_stairs:7,10,quark:iron_plate_stairs:1,10,quark:iron_plate_slab:0,10,quark:iron_plate_stairs:4,10,quark:iron_plate_stairs:2,10,IRON_FENCE:0,50,IRON_FENCE:0,50,LEAVES:7,100)
RandomBlock(7,11,-6,quark:iron_plate:1,70,STAINED_CLAY:15,30,STAINED_CLAY:7,30,quark:iron_plate:1,100)
Block(7,11,-5,AIR:0)
Block(7,11,-4,AIR:0)
RandomBlock(7,11,-3,quark:iron_plate:1,70,STAINED_CLAY:15,30,STAINED_CLAY:7,30,quark:iron_plate:1,100)
RandomBlock(7,12,-6,quark:iron_plate:1,70,STAINED_CLAY:15,30,STAINED_CLAY:7,30,quark:iron_plate:1,100)
Block(7,12,-5,AIR:0)
Block(7,12,-4,AIR:0)
RandomBlock(7,12,-3,quark:iron_plate:1,70,STAINED_CLAY:15,30,STAINED_CLAY:7,30,quark:iron_plate:1,100)
RandomBlock(7,13,-6,IRON_FENCE:0,30,IRON_FENCE:0,30,LEAVES:7,30,quark:iron_plate_stairs:6,10,quark:iron_plate_stairs:0,10,quark:iron_plate_stairs:5,10,quark:iron_plate_stairs:3,10,quark:iron_plate_slab:8,10,quark:iron_plate_stairs:7,10,quark:iron_plate_stairs:1,10,quark:iron_plate_slab:0,10,quark:iron_plate_stairs:4,10,quark:iron_plate_stairs:2,10,IRON_FENCE:0,50,IRON_FENCE:0,50,LEAVES:7,100)
Block(7,13,-5,AIR:0)
Block(7,13,-4,AIR:0)
RandomBlock(7,13,-3,quark:iron_plate:1,70,STAINED_CLAY:15,30,STAINED_CLAY:7,30,quark:iron_plate:1,100)
RandomBlock(7,14,-6,quark:iron_plate:1,70,STAINED_CLAY:15,30,STAINED_CLAY:7,30,quark:iron_plate:1,100)
Block(7,14,-5,AIR:0)
Block(7,14,-4,AIR:0)
RandomBlock(7,14,-3,quark:iron_plate:1,70,STAINED_CLAY:15,30,STAINED_CLAY:7,30,quark:iron_plate:1,100)
RandomBlock(7,15,-6,IRON_FENCE:0,30,IRON_FENCE:0,30,LEAVES:7,30,quark:iron_plate_stairs:6,10,quark:iron_plate_stairs:0,10,quark:iron_plate_stairs:5,10,quark:iron_plate_stairs:3,10,quark:iron_plate_slab:8,10,quark:iron_plate_stairs:7,10,quark:iron_plate_stairs:1,10,quark:iron_plate_slab:0,10,quark:iron_plate_stairs:4,10,quark:iron_plate_stairs:2,10,IRON_FENCE:0,50,IRON_FENCE:0,50,LEAVES:7,100)
Block(7,15,-5,AIR:0)
Block(7,15,-4,AIR:0)
RandomBlock(7,15,-3,quark:iron_plate:1,70,STAINED_CLAY:15,30,STAINED_CLAY:7,30,quark:iron_plate:1,100)
RandomBlock(7,16,-6,IRON_FENCE:0,30,IRON_FENCE:0,30,LEAVES:7,30,quark:iron_plate_stairs:6,10,quark:iron_plate_stairs:0,10,quark:iron_plate_stairs:5,10,quark:iron_plate_stairs:3,10,quark:iron_plate_slab:8,10,quark:iron_plate_stairs:7,10,quark:iron_plate_stairs:1,10,quark:iron_plate_slab:0,10,quark:iron_plate_stairs:4,10,quark:iron_plate_stairs:2,10,IRON_FENCE:0,50,IRON_FENCE:0,50,LEAVES:7,100)
Block(7,16,-5,AIR:0)
Block(7,16,-4,AIR:0)
RandomBlock(7,16,-3,quark:iron_plate:1,70,STAINED_CLAY:15,30,STAINED_CLAY:7,30,quark:iron_plate:1,100)
RandomBlock(7,17,-6,IRON_FENCE:0,30,IRON_FENCE:0,30,LEAVES:7,30,quark:iron_plate_stairs:6,10,quark:iron_plate_stairs:0,10,quark:iron_plate_stairs:5,10,quark:iron_plate_stairs:3,10,quark:iron_plate_slab:8,10,quark:iron_plate_stairs:7,10,quark:iron_plate_stairs:1,10,quark:iron_plate_slab:0,10,quark:iron_plate_stairs:4,10,quark:iron_plate_stairs:2,10,IRON_FENCE:0,50,IRON_FENCE:0,50,LEAVES:7,100)
Block(7,17,-5,AIR:0)
Block(7,17,-4,AIR:0)
RandomBlock(7,17,-3,quark:iron_plate:1,70,STAINED_CLAY:15,30,STAINED_CLAY:7,30,quark:iron_plate:1,100)
RandomBlock(7,18,-6,IRON_FENCE:0,30,IRON_FENCE:0,30,LEAVES:7,30,quark:iron_plate_stairs:6,10,quark:iron_plate_stairs:0,10,quark:iron_plate_stairs:5,10,quark:iron_plate_stairs:3,10,quark:iron_plate_slab:8,10,quark:iron_plate_stairs:7,10,quark:iron_plate_stairs:1,10,quark:iron_plate_slab:0,10,quark:iron_plate_stairs:4,10,quark:iron_plate_stairs:2,10,IRON_FENCE:0,50,IRON_FENCE:0,50,LEAVES:7,100)
Block(7,18,-5,AIR:0)
Block(7,18,-4,AIR:0)
RandomBlock(7,18,-3,quark:iron_plate:1,70,STAINED_CLAY:15,30,STAINED_CLAY:7,30,quark:iron_plate:1,100)
RandomBlock(7,19,-6,IRON_FENCE:0,30,IRON_FENCE:0,30,LEAVES:7,30,quark:iron_plate_stairs:6,10,quark:iron_plate_stairs:0,10,quark:iron_plate_stairs:5,10,quark:iron_plate_stairs:3,10,quark:iron_plate_slab:8,10,quark:iron_plate_stairs:7,10,quark:iron_plate_stairs:1,10,quark:iron_plate_slab:0,10,quark:iron_plate_stairs:4,10,quark:iron_plate_stairs:2,10,IRON_FENCE:0,50,IRON_FENCE:0,50,LEAVES:7,100)
Block(7,19,-5,AIR:0)
Block(7,19,-4,AIR:0)
RandomBlock(7,19,-3,quark:iron_plate:1,70,STAINED_CLAY:15,30,STAINED_CLAY:7,30,quark:iron_plate:1,100)
RandomBlock(7,20,-6,IRON_FENCE:0,30,IRON_FENCE:0,30,LEAVES:7,30,quark:iron_plate_stairs:6,10,quark:iron_plate_stairs:0,10,quark:iron_plate_stairs:5,10,quark:iron_plate_stairs:3,10,quark:iron_plate_slab:8,10,quark:iron_plate_stairs:7,10,quark:iron_plate_stairs:1,10,quark:iron_plate_slab:0,10,quark:iron_plate_stairs:4,10,quark:iron_plate_stairs:2,10,IRON_FENCE:0,50,IRON_FENCE:0,50,LEAVES:7,100)
Block(7,20,-5,AIR:0)
Block(7,20,-4,AIR:0)
RandomBlock(7,20,-3,quark:iron_plate:1,70,STAINED_CLAY:15,30,STAINED_CLAY:7,30,quark:iron_plate:1,100)
RandomBlock(7,21,-6,quark:iron_plate:1,70,STAINED_CLAY:15,30,STAINED_CLAY:7,30,quark:iron_plate:1,100)
Block(7,21,-5,AIR:0)
Block(7,21,-4,AIR:0)
RandomBlock(7,21,-3,quark:iron_plate:1,70,STAINED_CLAY:15,30,STAINED_CLAY:7,30,quark:iron_plate:1,100)
RandomBlock(7,22,-6,quark:iron_plate:1,70,STAINED_CLAY:15,30,STAINED_CLAY:7,30,quark:iron_plate:1,100)
Block(7,22,-5,AIR:0)
Block(7,22,-4,AIR:0)
RandomBlock(7,22,-3,quark:iron_plate:1,70,STAINED_CLAY:15,30,STAINED_CLAY:7,30,quark:iron_plate:1,100)
RandomBlock(7,23,-6,quark:iron_plate:1,70,STAINED_CLAY:15,30,STAINED_CLAY:7,30,quark:iron_plate:1,100)
Block(7,23,-5,AIR:0)
Block(7,23,-4,AIR:0)
RandomBlock(7,23,-3,quark:iron_plate:1,70,STAINED_CLAY:15,30,STAINED_CLAY:7,30,quark:iron_plate:1,100)
RandomBlock(7,24,-6,quark:iron_plate:1,70,STAINED_CLAY:15,30,STAINED_CLAY:7,30,quark:iron_plate:1,100)
Block(7,24,-5,AIR:0)
Block(7,24,-4,AIR:0)
RandomBlock(7,24,-3,quark:iron_plate:1,70,STAINED_CLAY:15,30,STAINED_CLAY:7,30,quark:iron_plate:1,100)
RandomBlock(7,25,-6,quark:iron_plate:1,70,STAINED_CLAY:15,30,STAINED_CLAY:7,30,quark:iron_plate:1,100)
Block(7,25,-5,AIR:0)
Block(7,25,-4,AIR:0)
RandomBlock(7,25,-3,quark:iron_plate:1,70,STAINED_CLAY:15,30,STAINED_CLAY:7,30,quark:iron_plate:1,100)
RandomBlock(7,26,-6,quark:iron_plate:1,70,STAINED_CLAY:15,30,STAINED_CLAY:7,30,quark:iron_plate:1,100)
Block(7,26,-5,AIR:0)
Block(7,26,-4,AIR:0)
RandomBlock(7,26,-3,quark:iron_plate:1,70,STAINED_CLAY:15,30,STAINED_CLAY:7,30,quark:iron_plate:1,100)
RandomBlock(7,27,-6,quark:iron_plate:1,70,STAINED_CLAY:15,30,STAINED_CLAY:7,30,quark:iron_plate:1,100)
Block(7,27,-5,AIR:0)
Block(7,27,-4,AIR:0)
RandomBlock(7,27,-3,quark:iron_plate:1,70,STAINED_CLAY:15,30,STAINED_CLAY:7,30,quark:iron_plate:1,100)
RandomBlock(7,28,-6,IRON_FENCE:0,30,IRON_FENCE:0,30,LEAVES:7,30,quark:iron_plate_stairs:6,10,quark:iron_plate_stairs:0,10,quark:iron_plate_stairs:5,10,quark:iron_plate_stairs:3,10,quark:iron_plate_slab:8,10,quark:iron_plate_stairs:7,10,quark:iron_plate_stairs:1,10,quark:iron_plate_slab:0,10,quark:iron_plate_stairs:4,10,quark:iron_plate_stairs:2,10,IRON_FENCE:0,50,IRON_FENCE:0,50,LEAVES:7,100)
Block(7,28,-5,AIR:0)
Block(7,28,-4,AIR:0)
RandomBlock(7,28,-3,quark:iron_plate:1,70,STAINED_CLAY:15,30,STAINED_CLAY:7,30,quark:iron_plate:1,100)
RandomBlock(7,29,-6,quark:iron_plate:1,70,STAINED_CLAY:15,30,STAINED_CLAY:7,30,quark:iron_plate:1,100)
Block(7,29,-5,AIR:0)
Block(7,29,-4,AIR:0)
RandomBlock(7,29,-3,quark:iron_plate:1,70,STAINED_CLAY:15,30,STAINED_CLAY:7,30,quark:iron_plate:1,100)
RandomBlock(7,30,-6,quark:iron_plate:1,70,STAINED_CLAY:15,30,STAINED_CLAY:7,30,quark:iron_plate:1,100)
Block(7,30,-5,AIR:0)
Block(7,30,-4,AIR:0)
RandomBlock(7,30,-3,quark:iron_plate:1,70,STAINED_CLAY:15,30,STAINED_CLAY:7,30,quark:iron_plate:1,100)
RandomBlock(7,31,-6,quark:iron_plate:1,70,STAINED_CLAY:15,30,STAINED_CLAY:7,30,quark:iron_plate:1,100)
Block(7,31,-5,AIR:0)
Block(7,31,-4,AIR:0)
RandomBlock(7,31,-3,quark:iron_plate:1,70,STAINED_CLAY:15,30,STAINED_CLAY:7,30,quark:iron_plate:1,100)
RandomBlock(7,32,-6,quark:iron_plate:1,70,STAINED_CLAY:15,30,STAINED_CLAY:7,30,quark:iron_plate:1,100)
Block(7,32,-5,AIR:0)
Block(7,32,-4,AIR:0)
RandomBlock(7,32,-3,IRON_FENCE:0,30,IRON_FENCE:0,30,LEAVES:7,30,quark:iron_plate_stairs:6,10,quark:iron_plate_stairs:0,10,quark:iron_plate_stairs:5,10,quark:iron_plate_stairs:3,10,quark:iron_plate_slab:8,10,quark:iron_plate_stairs:7,10,quark:iron_plate_stairs:1,10,quark:iron_plate_slab:0,10,quark:iron_plate_stairs:4,10,quark:iron_plate_stairs:2,10,IRON_FENCE:0,50,IRON_FENCE:0,50,LEAVES:7,100)
RandomBlock(7,33,-6,quark:iron_plate:1,70,STAINED_CLAY:15,30,STAINED_CLAY:7,30,quark:iron_plate:1,100)
Block(7,33,-5,AIR:0)
Block(7,33,-4,AIR:0)
RandomBlock(7,33,-3,IRON_FENCE:0,30,IRON_FENCE:0,30,LEAVES:7,30,quark:iron_plate_stairs:6,10,quark:iron_plate_stairs:0,10,quark:iron_plate_stairs:5,10,quark:iron_plate_stairs:3,10,quark:iron_plate_slab:8,10,quark:iron_plate_stairs:7,10,quark:iron_plate_stairs:1,10,quark:iron_plate_slab:0,10,quark:iron_plate_stairs:4,10,quark:iron_plate_stairs:2,10,IRON_FENCE:0,50,IRON_FENCE:0,50,LEAVES:7,100)
RandomBlock(7,34,-6,IRON_FENCE:0,30,IRON_FENCE:0,30,LEAVES:7,30,quark:iron_plate_stairs:6,10,quark:iron_plate_stairs:0,10,quark:iron_plate_stairs:5,10,quark:iron_plate_stairs:3,10,quark:iron_plate_slab:8,10,quark:iron_plate_stairs:7,10,quark:iron_plate_stairs:1,10,quark:iron_plate_slab:0,10,quark:iron_plate_stairs:4,10,quark:iron_plate_stairs:2,10,IRON_FENCE:0,50,IRON_FENCE:0,50,LEAVES:7,100)
Block(7,34,-5,AIR:0)
Block(7,34,-4,AIR:0)
RandomBlock(7,34,-3,IRON_FENCE:0,30,IRON_FENCE:0,30,LEAVES:7,30,quark:iron_plate_stairs:6,10,quark:iron_plate_stairs:0,10,quark:iron_plate_stairs:5,10,quark:iron_plate_stairs:3,10,quark:iron_plate_slab:8,10,quark:iron_plate_stairs:7,10,quark:iron_plate_stairs:1,10,quark:iron_plate_slab:0,10,quark:iron_plate_stairs:4,10,quark:iron_plate_stairs:2,10,IRON_FENCE:0,50,IRON_FENCE:0,50,LEAVES:7,100)
RandomBlock(7,35,-6,quark:iron_plate:1,70,STAINED_CLAY:15,30,STAINED_CLAY:7,30,quark:iron_plate:1,100)
Block(7,35,-5,AIR:0)
Block(7,35,-4,AIR:0)
RandomBlock(7,35,-3,IRON_FENCE:0,30,IRON_FENCE:0,30,LEAVES:7,30,quark:iron_plate_stairs:6,10,quark:iron_plate_stairs:0,10,quark:iron_plate_stairs:5,10,quark:iron_plate_stairs:3,10,quark:iron_plate_slab:8,10,quark:iron_plate_stairs:7,10,quark:iron_plate_stairs:1,10,quark:iron_plate_slab:0,10,quark:iron_plate_stairs:4,10,quark:iron_plate_stairs:2,10,IRON_FENCE:0,50,IRON_FENCE:0,50,LEAVES:7,100)
RandomBlock(7,36,-6,IRON_FENCE:0,30,IRON_FENCE:0,30,LEAVES:7,30,quark:iron_plate_stairs:6,10,quark:iron_plate_stairs:0,10,quark:iron_plate_stairs:5,10,quark:iron_plate_stairs:3,10,quark:iron_plate_slab:8,10,quark:iron_plate_stairs:7,10,quark:iron_plate_stairs:1,10,quark:iron_plate_slab:0,10,quark:iron_plate_stairs:4,10,quark:iron_plate_stairs:2,10,IRON_FENCE:0,50,IRON_FENCE:0,50,LEAVES:7,100)
Block(7,36,-5,AIR:0)
Block(7,36,-4,AIR:0)
RandomBlock(7,36,-3,IRON_FENCE:0,30,IRON_FENCE:0,30,LEAVES:7,30,quark:iron_plate_stairs:6,10,quark:iron_plate_stairs:0,10,quark:iron_plate_stairs:5,10,quark:iron_plate_stairs:3,10,quark:iron_plate_slab:8,10,quark:iron_plate_stairs:7,10,quark:iron_plate_stairs:1,10,quark:iron_plate_slab:0,10,quark:iron_plate_stairs:4,10,quark:iron_plate_stairs:2,10,IRON_FENCE:0,50,IRON_FENCE:0,50,LEAVES:7,100)
RandomBlock(7,37,-6,IRON_FENCE:0,30,IRON_FENCE:0,30,LEAVES:7,30,quark:iron_plate_stairs:6,10,quark:iron_plate_stairs:0,10,quark:iron_plate_stairs:5,10,quark:iron_plate_stairs:3,10,quark:iron_plate_slab:8,10,quark:iron_plate_stairs:7,10,quark:iron_plate_stairs:1,10,quark:iron_plate_slab:0,10,quark:iron_plate_stairs:4,10,quark:iron_plate_stairs:2,10,IRON_FENCE:0,50,IRON_FENCE:0,50,LEAVES:7,100)
Block(7,37,-5,AIR:0)
Block(7,37,-4,AIR:0)
RandomBlock(7,37,-3,quark:iron_plate:1,70,STAINED_CLAY:15,30,STAINED_CLAY:7,30,quark:iron_plate:1,100)
RandomBlock(7,38,-6,IRON_FENCE:0,30,IRON_FENCE:0,30,LEAVES:7,30,quark:iron_plate_stairs:6,10,quark:iron_plate_stairs:0,10,quark:iron_plate_stairs:5,10,quark:iron_plate_stairs:3,10,quark:iron_plate_slab:8,10,quark:iron_plate_stairs:7,10,quark:iron_plate_stairs:1,10,quark:iron_plate_slab:0,10,quark:iron_plate_stairs:4,10,quark:iron_plate_stairs:2,10,IRON_FENCE:0,50,IRON_FENCE:0,50,LEAVES:7,100)
Block(7,38,-5,AIR:0)
Block(7,38,-4,AIR:0)
RandomBlock(7,38,-3,quark:iron_plate:1,70,STAINED_CLAY:15,30,STAINED_CLAY:7,30,quark:iron_plate:1,100)
RandomBlock(7,39,-6,quark:iron_plate:1,70,STAINED_CLAY:15,30,STAINED_CLAY:7,30,quark:iron_plate:1,100)
Block(7,39,-5,AIR:0)
Block(7,39,-4,AIR:0)
RandomBlock(7,39,-3,quark:iron_plate:1,70,STAINED_CLAY:15,30,STAINED_CLAY:7,30,quark:iron_plate:1,100)
RandomBlock(7,40,-6,quark:iron_plate:1,70,STAINED_CLAY:15,30,STAINED_CLAY:7,30,quark:iron_plate:1,100)
Block(7,40,-5,AIR:0)
Block(7,40,-4,AIR:0)
RandomBlock(7,40,-3,quark:iron_plate:1,70,STAINED_CLAY:15,30,STAINED_CLAY:7,30,quark:iron_plate:1,100)
RandomBlock(7,41,-6,quark:iron_plate:1,70,STAINED_CLAY:15,30,STAINED_CLAY:7,30,quark:iron_plate:1,100)
Block(7,41,-5,AIR:0)
Block(7,41,-4,AIR:0)
RandomBlock(7,41,-3,quark:iron_plate:1,70,STAINED_CLAY:15,30,STAINED_CLAY:7,30,quark:iron_plate:1,100)
RandomBlock(7,42,-6,quark:iron_plate:1,70,STAINED_CLAY:15,30,STAINED_CLAY:7,30,quark:iron_plate:1,100)
Block(7,42,-5,AIR:0)
