
#######################################################################
# +-----------------------------------------------------------------+ #
# |                            BO4 object                           | #
# +-----------------------------------------------------------------+ #
#######################################################################

Author: NLBlackEagle

Description: No description given

SettingsMode: WriteWithoutComments


#######################################################################
# +-----------------------------------------------------------------+ #
# |                          Main settings                          | #
# +-----------------------------------------------------------------+ #
#######################################################################

FixedRotation: 

Frequency: 0

SpawnHeight: highestBlock

UseCenterForHighestBlock: true

##############################
# Height Limits for the BO4. #
##############################

MinHeight: 0

MaxHeight: 255

InheritBO3: 

InheritBO3Rotation: NORTH

OverrideChildSettings: true

OverrideParentHeight: false

CanOverride: true

BranchFrequency: 0

BranchFrequencyGroup: 

MustBeBelowOther: false

MustBeInside: 

CannotBeInside: 

ReplacesBO3: 

MustBeInsideWorldBorders: true

CanSpawnOnWater: true

SpawnOnWaterOnly: false

SpawnUnderWater: false

SpawnAtWaterLevel: false

HeightOffset: 0

RemoveAir: false

ReplaceAbove: 

ReplaceBelow: 

ReplaceWithBiomeBlocks: true

ReplaceWithSurfaceBlock: GRASS

ReplaceWithGroundBlock: DIRT

ReplaceWithStoneBlock: STONE

SmoothRadius: 0

SmoothHeightOffset: 0

SmoothStartTop: false

SmoothStartWood: false

SmoothingSurfaceBlock: 

SmoothingGroundBlock: 

BO3Group: 

IsSpawnPoint: false

DoReplaceBlocks: false


#######################################################################
# +-----------------------------------------------------------------+ #
# |                              Blocks                             | #
# +-----------------------------------------------------------------+ #
#######################################################################

Block(-8,511,-7,AIR:0)
RandomBlock(-7,0,-6,quark:iron_plate:1,70,STAINED_CLAY:15,30,STAINED_CLAY:7,30,quark:iron_plate:1,100)
RandomBlock(-7,0,-5,quark:iron_plate:1,70,STAINED_CLAY:15,30,STAINED_CLAY:7,30,quark:iron_plate:1,100)
RandomBlock(-7,0,-4,quark:iron_plate:1,70,STAINED_CLAY:15,30,STAINED_CLAY:7,30,quark:iron_plate:1,100)
RandomBlock(-7,0,-3,quark:iron_plate:1,70,STAINED_CLAY:15,30,STAINED_CLAY:7,30,quark:iron_plate:1,100)
RandomBlock(-7,1,-6,quark:iron_plate:1,70,STAINED_CLAY:15,30,STAINED_CLAY:7,30,quark:iron_plate:1,100)
RandomBlock(-7,1,-5,quark:iron_plate:1,70,STAINED_CLAY:15,30,STAINED_CLAY:7,30,quark:iron_plate:1,100)
RandomBlock(-7,1,-4,quark:iron_plate:1,70,STAINED_CLAY:15,30,STAINED_CLAY:7,30,quark:iron_plate:1,100)
RandomBlock(-7,1,-3,quark:iron_plate:1,70,STAINED_CLAY:15,30,STAINED_CLAY:7,30,quark:iron_plate:1,100)
RandomBlock(-7,2,-6,quark:iron_plate:1,70,STAINED_CLAY:15,30,STAINED_CLAY:7,30,quark:iron_plate:1,100)
RandomBlock(-7,2,-5,quark:iron_plate:1,70,STAINED_CLAY:15,30,STAINED_CLAY:7,30,quark:iron_plate:1,100)
RandomBlock(-7,2,-4,quark:iron_plate:1,70,STAINED_CLAY:15,30,STAINED_CLAY:7,30,quark:iron_plate:1,100)
RandomBlock(-7,2,-3,quark:iron_plate:1,70,STAINED_CLAY:15,30,STAINED_CLAY:7,30,quark:iron_plate:1,100)
RandomBlock(-7,3,-6,quark:iron_plate:1,70,STAINED_CLAY:15,30,STAINED_CLAY:7,30,quark:iron_plate:1,100)
RandomBlock(-7,3,-5,quark:iron_plate:1,70,STAINED_CLAY:15,30,STAINED_CLAY:7,30,quark:iron_plate:1,100)
RandomBlock(-7,3,-4,quark:iron_plate:1,70,STAINED_CLAY:15,30,STAINED_CLAY:7,30,quark:iron_plate:1,100)
RandomBlock(-7,3,-3,quark:iron_plate:1,70,STAINED_CLAY:15,30,STAINED_CLAY:7,30,quark:iron_plate:1,100)
RandomBlock(-7,4,-6,quark:iron_plate:1,70,STAINED_CLAY:15,30,STAINED_CLAY:7,30,quark:iron_plate:1,100)
RandomBlock(-7,4,-5,quark:iron_plate:1,70,STAINED_CLAY:15,30,STAINED_CLAY:7,30,quark:iron_plate:1,100)
RandomBlock(-7,4,-4,quark:iron_plate:1,70,STAINED_CLAY:15,30,STAINED_CLAY:7,30,quark:iron_plate:1,100)
RandomBlock(-7,4,-3,quark:iron_plate:1,70,STAINED_CLAY:15,30,STAINED_CLAY:7,30,quark:iron_plate:1,100)
RandomBlock(-7,5,-6,IRON_FENCE:0,30,IRON_FENCE:0,30,LEAVES:7,30,quark:iron_plate_stairs:6,10,quark:iron_plate_stairs:0,10,quark:iron_plate_stairs:5,10,quark:iron_plate_stairs:3,10,quark:iron_plate_slab:8,10,quark:iron_plate_stairs:7,10,quark:iron_plate_stairs:1,10,quark:iron_plate_slab:0,10,quark:iron_plate_stairs:4,10,quark:iron_plate_stairs:2,10,IRON_FENCE:0,50,IRON_FENCE:0,50,LEAVES:7,100)
RandomBlock(-7,5,-5,quark:iron_plate:1,70,STAINED_CLAY:15,30,STAINED_CLAY:7,30,quark:iron_plate:1,100)
RandomBlock(-7,5,-4,quark:iron_plate:1,70,STAINED_CLAY:15,30,STAINED_CLAY:7,30,quark:iron_plate:1,100)
RandomBlock(-7,5,-3,quark:iron_plate:1,70,STAINED_CLAY:15,30,STAINED_CLAY:7,30,quark:iron_plate:1,100)
RandomBlock(-7,6,-6,IRON_FENCE:0,30,IRON_FENCE:0,30,LEAVES:7,30,quark:iron_plate_stairs:6,10,quark:iron_plate_stairs:0,10,quark:iron_plate_stairs:5,10,quark:iron_plate_stairs:3,10,quark:iron_plate_slab:8,10,quark:iron_plate_stairs:7,10,quark:iron_plate_stairs:1,10,quark:iron_plate_slab:0,10,quark:iron_plate_stairs:4,10,quark:iron_plate_stairs:2,10,IRON_FENCE:0,50,IRON_FENCE:0,50,LEAVES:7,100)
RandomBlock(-7,6,-5,IRON_FENCE:0,30,IRON_FENCE:0,30,LEAVES:7,30,quark:iron_plate_stairs:6,10,quark:iron_plate_stairs:0,10,quark:iron_plate_stairs:5,10,quark:iron_plate_stairs:3,10,quark:iron_plate_slab:8,10,quark:iron_plate_stairs:7,10,quark:iron_plate_stairs:1,10,quark:iron_plate_slab:0,10,quark:iron_plate_stairs:4,10,quark:iron_plate_stairs:2,10,IRON_FENCE:0,50,IRON_FENCE:0,50,LEAVES:7,100)
RandomBlock(-7,6,-4,quark:iron_plate:1,70,STAINED_CLAY:15,30,STAINED_CLAY:7,30,quark:iron_plate:1,100)
RandomBlock(-7,6,-3,quark:iron_plate:1,70,STAINED_CLAY:15,30,STAINED_CLAY:7,30,quark:iron_plate:1,100)
RandomBlock(-7,7,-6,IRON_FENCE:0,30,IRON_FENCE:0,30,LEAVES:7,30,quark:iron_plate_stairs:6,10,quark:iron_plate_stairs:0,10,quark:iron_plate_stairs:5,10,quark:iron_plate_stairs:3,10,quark:iron_plate_slab:8,10,quark:iron_plate_stairs:7,10,quark:iron_plate_stairs:1,10,quark:iron_plate_slab:0,10,quark:iron_plate_stairs:4,10,quark:iron_plate_stairs:2,10,IRON_FENCE:0,50,IRON_FENCE:0,50,LEAVES:7,100)
RandomBlock(-7,7,-5,quark:iron_plate:1,70,STAINED_CLAY:15,30,STAINED_CLAY:7,30,quark:iron_plate:1,100)
RandomBlock(-7,7,-4,quark:iron_plate:1,70,STAINED_CLAY:15,30,STAINED_CLAY:7,30,quark:iron_plate:1,100)
RandomBlock(-7,7,-3,quark:iron_plate:1,70,STAINED_CLAY:15,30,STAINED_CLAY:7,30,quark:iron_plate:1,100)
RandomBlock(-7,8,-6,IRON_FENCE:0,30,IRON_FENCE:0,30,LEAVES:7,30,quark:iron_plate_stairs:6,10,quark:iron_plate_stairs:0,10,quark:iron_plate_stairs:5,10,quark:iron_plate_stairs:3,10,quark:iron_plate_slab:8,10,quark:iron_plate_stairs:7,10,quark:iron_plate_stairs:1,10,quark:iron_plate_slab:0,10,quark:iron_plate_stairs:4,10,quark:iron_plate_stairs:2,10,IRON_FENCE:0,50,IRON_FENCE:0,50,LEAVES:7,100)
RandomBlock(-7,8,-5,quark:iron_plate:1,70,STAINED_CLAY:15,30,STAINED_CLAY:7,30,quark:iron_plate:1,100)
RandomBlock(-7,8,-4,quark:iron_plate:1,70,STAINED_CLAY:15,30,STAINED_CLAY:7,30,quark:iron_plate:1,100)
RandomBlock(-7,8,-3,quark:iron_plate:1,70,STAINED_CLAY:15,30,STAINED_CLAY:7,30,quark:iron_plate:1,100)
RandomBlock(-7,9,-6,quark:iron_plate:1,70,STAINED_CLAY:15,30,STAINED_CLAY:7,30,quark:iron_plate:1,100)
RandomBlock(-7,9,-5,quark:iron_plate:1,70,STAINED_CLAY:15,30,STAINED_CLAY:7,30,quark:iron_plate:1,100)
RandomBlock(-7,9,-4,quark:iron_plate:1,70,STAINED_CLAY:15,30,STAINED_CLAY:7,30,quark:iron_plate:1,100)
RandomBlock(-7,9,-3,quark:iron_plate:1,70,STAINED_CLAY:15,30,STAINED_CLAY:7,30,quark:iron_plate:1,100)
RandomBlock(-7,10,-6,quark:iron_plate:1,70,STAINED_CLAY:15,30,STAINED_CLAY:7,30,quark:iron_plate:1,100)
RandomBlock(-7,10,-5,quark:iron_plate:1,70,STAINED_CLAY:15,30,STAINED_CLAY:7,30,quark:iron_plate:1,100)
RandomBlock(-7,10,-4,quark:iron_plate:1,70,STAINED_CLAY:15,30,STAINED_CLAY:7,30,quark:iron_plate:1,100)
RandomBlock(-7,10,-3,IRON_FENCE:0,30,IRON_FENCE:0,30,LEAVES:7,30,quark:iron_plate_stairs:6,10,quark:iron_plate_stairs:0,10,quark:iron_plate_stairs:5,10,quark:iron_plate_stairs:3,10,quark:iron_plate_slab:8,10,quark:iron_plate_stairs:7,10,quark:iron_plate_stairs:1,10,quark:iron_plate_slab:0,10,quark:iron_plate_stairs:4,10,quark:iron_plate_stairs:2,10,IRON_FENCE:0,50,IRON_FENCE:0,50,LEAVES:7,100)
RandomBlock(-7,11,-6,quark:iron_plate:1,70,STAINED_CLAY:15,30,STAINED_CLAY:7,30,quark:iron_plate:1,100)
RandomBlock(-7,11,-5,quark:iron_plate:1,70,STAINED_CLAY:15,30,STAINED_CLAY:7,30,quark:iron_plate:1,100)
RandomBlock(-7,11,-4,IRON_FENCE:0,30,IRON_FENCE:0,30,LEAVES:7,30,quark:iron_plate_stairs:6,10,quark:iron_plate_stairs:0,10,quark:iron_plate_stairs:5,10,quark:iron_plate_stairs:3,10,quark:iron_plate_slab:8,10,quark:iron_plate_stairs:7,10,quark:iron_plate_stairs:1,10,quark:iron_plate_slab:0,10,quark:iron_plate_stairs:4,10,quark:iron_plate_stairs:2,10,IRON_FENCE:0,50,IRON_FENCE:0,50,LEAVES:7,100)
RandomBlock(-7,11,-3,IRON_FENCE:0,30,IRON_FENCE:0,30,LEAVES:7,30,quark:iron_plate_stairs:6,10,quark:iron_plate_stairs:0,10,quark:iron_plate_stairs:5,10,quark:iron_plate_stairs:3,10,quark:iron_plate_slab:8,10,quark:iron_plate_stairs:7,10,quark:iron_plate_stairs:1,10,quark:iron_plate_slab:0,10,quark:iron_plate_stairs:4,10,quark:iron_plate_stairs:2,10,IRON_FENCE:0,50,IRON_FENCE:0,50,LEAVES:7,100)
RandomBlock(-7,12,-6,quark:iron_plate:1,70,STAINED_CLAY:15,30,STAINED_CLAY:7,30,quark:iron_plate:1,100)
RandomBlock(-7,12,-5,quark:iron_plate:1,70,STAINED_CLAY:15,30,STAINED_CLAY:7,30,quark:iron_plate:1,100)
RandomBlock(-7,12,-4,IRON_FENCE:0,30,IRON_FENCE:0,30,LEAVES:7,30,quark:iron_plate_stairs:6,10,quark:iron_plate_stairs:0,10,quark:iron_plate_stairs:5,10,quark:iron_plate_stairs:3,10,quark:iron_plate_slab:8,10,quark:iron_plate_stairs:7,10,quark:iron_plate_stairs:1,10,quark:iron_plate_slab:0,10,quark:iron_plate_stairs:4,10,quark:iron_plate_stairs:2,10,IRON_FENCE:0,50,IRON_FENCE:0,50,LEAVES:7,100)
RandomBlock(-7,12,-3,IRON_FENCE:0,30,IRON_FENCE:0,30,LEAVES:7,30,quark:iron_plate_stairs:6,10,quark:iron_plate_stairs:0,10,quark:iron_plate_stairs:5,10,quark:iron_plate_stairs:3,10,quark:iron_plate_slab:8,10,quark:iron_plate_stairs:7,10,quark:iron_plate_stairs:1,10,quark:iron_plate_slab:0,10,quark:iron_plate_stairs:4,10,quark:iron_plate_stairs:2,10,IRON_FENCE:0,50,IRON_FENCE:0,50,LEAVES:7,100)
RandomBlock(-7,13,-6,quark:iron_plate:1,70,STAINED_CLAY:15,30,STAINED_CLAY:7,30,quark:iron_plate:1,100)
RandomBlock(-7,13,-5,IRON_FENCE:0,30,IRON_FENCE:0,30,LEAVES:7,30,quark:iron_plate_stairs:6,10,quark:iron_plate_stairs:0,10,quark:iron_plate_stairs:5,10,quark:iron_plate_stairs:3,10,quark:iron_plate_slab:8,10,quark:iron_plate_stairs:7,10,quark:iron_plate_stairs:1,10,quark:iron_plate_slab:0,10,quark:iron_plate_stairs:4,10,quark:iron_plate_stairs:2,10,IRON_FENCE:0,50,IRON_FENCE:0,50,LEAVES:7,100)
RandomBlock(-7,13,-4,IRON_FENCE:0,30,IRON_FENCE:0,30,LEAVES:7,30,quark:iron_plate_stairs:6,10,quark:iron_plate_stairs:0,10,quark:iron_plate_stairs:5,10,quark:iron_plate_stairs:3,10,quark:iron_plate_slab:8,10,quark:iron_plate_stairs:7,10,quark:iron_plate_stairs:1,10,quark:iron_plate_slab:0,10,quark:iron_plate_stairs:4,10,quark:iron_plate_stairs:2,10,IRON_FENCE:0,50,IRON_FENCE:0,50,LEAVES:7,100)
RandomBlock(-7,13,-3,IRON_FENCE:0,30,IRON_FENCE:0,30,LEAVES:7,30,quark:iron_plate_stairs:6,10,quark:iron_plate_stairs:0,10,quark:iron_plate_stairs:5,10,quark:iron_plate_stairs:3,10,quark:iron_plate_slab:8,10,quark:iron_plate_stairs:7,10,quark:iron_plate_stairs:1,10,quark:iron_plate_slab:0,10,quark:iron_plate_stairs:4,10,quark:iron_plate_stairs:2,10,IRON_FENCE:0,50,IRON_FENCE:0,50,LEAVES:7,100)
RandomBlock(-7,14,-6,quark:iron_plate:1,70,STAINED_CLAY:15,30,STAINED_CLAY:7,30,quark:iron_plate:1,100)
RandomBlock(-7,14,-5,IRON_FENCE:0,30,IRON_FENCE:0,30,LEAVES:7,30,quark:iron_plate_stairs:6,10,quark:iron_plate_stairs:0,10,quark:iron_plate_stairs:5,10,quark:iron_plate_stairs:3,10,quark:iron_plate_slab:8,10,quark:iron_plate_stairs:7,10,quark:iron_plate_stairs:1,10,quark:iron_plate_slab:0,10,quark:iron_plate_stairs:4,10,quark:iron_plate_stairs:2,10,IRON_FENCE:0,50,IRON_FENCE:0,50,LEAVES:7,100)
RandomBlock(-7,14,-4,IRON_FENCE:0,30,IRON_FENCE:0,30,LEAVES:7,30,quark:iron_plate_stairs:6,10,quark:iron_plate_stairs:0,10,quark:iron_plate_stairs:5,10,quark:iron_plate_stairs:3,10,quark:iron_plate_slab:8,10,quark:iron_plate_stairs:7,10,quark:iron_plate_stairs:1,10,quark:iron_plate_slab:0,10,quark:iron_plate_stairs:4,10,quark:iron_plate_stairs:2,10,IRON_FENCE:0,50,IRON_FENCE:0,50,LEAVES:7,100)
RandomBlock(-7,14,-3,quark:iron_plate:1,70,STAINED_CLAY:15,30,STAINED_CLAY:7,30,quark:iron_plate:1,100)
RandomBlock(-7,15,-6,IRON_FENCE:0,30,IRON_FENCE:0,30,LEAVES:7,30,quark:iron_plate_stairs:6,10,quark:iron_plate_stairs:0,10,quark:iron_plate_stairs:5,10,quark:iron_plate_stairs:3,10,quark:iron_plate_slab:8,10,quark:iron_plate_stairs:7,10,quark:iron_plate_stairs:1,10,quark:iron_plate_slab:0,10,quark:iron_plate_stairs:4,10,quark:iron_plate_stairs:2,10,IRON_FENCE:0,50,IRON_FENCE:0,50,LEAVES:7,100)
RandomBlock(-7,15,-5,IRON_FENCE:0,30,IRON_FENCE:0,30,LEAVES:7,30,quark:iron_plate_stairs:6,10,quark:iron_plate_stairs:0,10,quark:iron_plate_stairs:5,10,quark:iron_plate_stairs:3,10,quark:iron_plate_slab:8,10,quark:iron_plate_stairs:7,10,quark:iron_plate_stairs:1,10,quark:iron_plate_slab:0,10,quark:iron_plate_stairs:4,10,quark:iron_plate_stairs:2,10,IRON_FENCE:0,50,IRON_FENCE:0,50,LEAVES:7,100)
RandomBlock(-7,15,-4,IRON_FENCE:0,30,IRON_FENCE:0,30,LEAVES:7,30,quark:iron_plate_stairs:6,10,quark:iron_plate_stairs:0,10,quark:iron_plate_stairs:5,10,quark:iron_plate_stairs:3,10,quark:iron_plate_slab:8,10,quark:iron_plate_stairs:7,10,quark:iron_plate_stairs:1,10,quark:iron_plate_slab:0,10,quark:iron_plate_stairs:4,10,quark:iron_plate_stairs:2,10,IRON_FENCE:0,50,IRON_FENCE:0,50,LEAVES:7,100)
RandomBlock(-7,15,-3,quark:iron_plate:1,70,STAINED_CLAY:15,30,STAINED_CLAY:7,30,quark:iron_plate:1,100)
RandomBlock(-7,16,-6,quark:iron_plate:1,70,STAINED_CLAY:15,30,STAINED_CLAY:7,30,quark:iron_plate:1,100)
RandomBlock(-7,16,-5,IRON_FENCE:0,30,IRON_FENCE:0,30,LEAVES:7,30,quark:iron_plate_stairs:6,10,quark:iron_plate_stairs:0,10,quark:iron_plate_stairs:5,10,quark:iron_plate_stairs:3,10,quark:iron_plate_slab:8,10,quark:iron_plate_stairs:7,10,quark:iron_plate_stairs:1,10,quark:iron_plate_slab:0,10,quark:iron_plate_stairs:4,10,quark:iron_plate_stairs:2,10,IRON_FENCE:0,50,IRON_FENCE:0,50,LEAVES:7,100)
RandomBlock(-7,16,-4,quark:iron_plate:1,70,STAINED_CLAY:15,30,STAINED_CLAY:7,30,quark:iron_plate:1,100)
RandomBlock(-7,16,-3,quark:iron_plate:1,70,STAINED_CLAY:15,30,STAINED_CLAY:7,30,quark:iron_plate:1,100)
RandomBlock(-7,17,-6,quark:iron_plate:1,70,STAINED_CLAY:15,30,STAINED_CLAY:7,30,quark:iron_plate:1,100)
RandomBlock(-7,17,-5,quark:iron_plate:1,70,STAINED_CLAY:15,30,STAINED_CLAY:7,30,quark:iron_plate:1,100)
RandomBlock(-7,17,-4,quark:iron_plate:1,70,STAINED_CLAY:15,30,STAINED_CLAY:7,30,quark:iron_plate:1,100)
RandomBlock(-7,17,-3,quark:iron_plate:1,70,STAINED_CLAY:15,30,STAINED_CLAY:7,30,quark:iron_plate:1,100)
RandomBlock(-7,18,-6,quark:iron_plate:1,70,STAINED_CLAY:15,30,STAINED_CLAY:7,30,quark:iron_plate:1,100)
RandomBlock(-7,18,-5,quark:iron_plate:1,70,STAINED_CLAY:15,30,STAINED_CLAY:7,30,quark:iron_plate:1,100)
RandomBlock(-7,18,-4,quark:iron_plate:1,70,STAINED_CLAY:15,30,STAINED_CLAY:7,30,quark:iron_plate:1,100)
RandomBlock(-7,18,-3,quark:iron_plate:1,70,STAINED_CLAY:15,30,STAINED_CLAY:7,30,quark:iron_plate:1,100)
RandomBlock(-7,19,-6,quark:iron_plate:1,70,STAINED_CLAY:15,30,STAINED_CLAY:7,30,quark:iron_plate:1,100)
RandomBlock(-7,19,-5,quark:iron_plate:1,70,STAINED_CLAY:15,30,STAINED_CLAY:7,30,quark:iron_plate:1,100)
RandomBlock(-7,19,-4,quark:iron_plate:1,70,STAINED_CLAY:15,30,STAINED_CLAY:7,30,quark:iron_plate:1,100)
RandomBlock(-7,19,-3,quark:iron_plate:1,70,STAINED_CLAY:15,30,STAINED_CLAY:7,30,quark:iron_plate:1,100)
RandomBlock(-6,0,-6,quark:iron_plate:1,70,STAINED_CLAY:15,30,STAINED_CLAY:7,30,quark:iron_plate:1,100)
Block(-6,0,-5,AIR:0)
Block(-6,0,-4,AIR:0)
RandomBlock(-6,0,-3,quark:iron_plate:1,70,STAINED_CLAY:15,30,STAINED_CLAY:7,30,quark:iron_plate:1,100)
RandomBlock(-6,1,-6,quark:iron_plate:1,70,STAINED_CLAY:15,30,STAINED_CLAY:7,30,quark:iron_plate:1,100)
Block(-6,1,-5,AIR:0)
Block(-6,1,-4,AIR:0)
RandomBlock(-6,1,-3,quark:iron_plate:1,70,STAINED_CLAY:15,30,STAINED_CLAY:7,30,quark:iron_plate:1,100)
RandomBlock(-6,2,-6,quark:iron_plate:1,70,STAINED_CLAY:15,30,STAINED_CLAY:7,30,quark:iron_plate:1,100)
Block(-6,2,-5,AIR:0)
Block(-6,2,-4,AIR:0)
RandomBlock(-6,2,-3,quark:iron_plate:1,70,STAINED_CLAY:15,30,STAINED_CLAY:7,30,quark:iron_plate:1,100)
RandomBlock(-6,3,-6,quark:iron_plate:1,70,STAINED_CLAY:15,30,STAINED_CLAY:7,30,quark:iron_plate:1,100)
Block(-6,3,-5,AIR:0)
Block(-6,3,-4,AIR:0)
RandomBlock(-6,3,-3,quark:iron_plate:1,70,STAINED_CLAY:15,30,STAINED_CLAY:7,30,quark:iron_plate:1,100)
RandomBlock(-6,4,-6,quark:iron_plate:1,70,STAINED_CLAY:15,30,STAINED_CLAY:7,30,quark:iron_plate:1,100)
Block(-6,4,-5,AIR:0)
Block(-6,4,-4,AIR:0)
RandomBlock(-6,4,-3,quark:iron_plate:1,70,STAINED_CLAY:15,30,STAINED_CLAY:7,30,quark:iron_plate:1,100)
RandomBlock(-6,5,-6,quark:iron_plate:1,70,STAINED_CLAY:15,30,STAINED_CLAY:7,30,quark:iron_plate:1,100)
Block(-6,5,-5,AIR:0)
Block(-6,5,-4,AIR:0)
RandomBlock(-6,5,-3,quark:iron_plate:1,70,STAINED_CLAY:15,30,STAINED_CLAY:7,30,quark:iron_plate:1,100)
RandomBlock(-6,6,-6,IRON_FENCE:0,30,IRON_FENCE:0,30,LEAVES:7,30,quark:iron_plate_stairs:6,10,quark:iron_plate_stairs:0,10,quark:iron_plate_stairs:5,10,quark:iron_plate_stairs:3,10,quark:iron_plate_slab:8,10,quark:iron_plate_stairs:7,10,quark:iron_plate_stairs:1,10,quark:iron_plate_slab:0,10,quark:iron_plate_stairs:4,10,quark:iron_plate_stairs:2,10,IRON_FENCE:0,50,IRON_FENCE:0,50,LEAVES:7,100)
Block(-6,6,-5,AIR:0)
Block(-6,6,-4,AIR:0)
RandomBlock(-6,6,-3,quark:iron_plate:1,70,STAINED_CLAY:15,30,STAINED_CLAY:7,30,quark:iron_plate:1,100)
RandomBlock(-6,7,-6,IRON_FENCE:0,30,IRON_FENCE:0,30,LEAVES:7,30,quark:iron_plate_stairs:6,10,quark:iron_plate_stairs:0,10,quark:iron_plate_stairs:5,10,quark:iron_plate_stairs:3,10,quark:iron_plate_slab:8,10,quark:iron_plate_stairs:7,10,quark:iron_plate_stairs:1,10,quark:iron_plate_slab:0,10,quark:iron_plate_stairs:4,10,quark:iron_plate_stairs:2,10,IRON_FENCE:0,50,IRON_FENCE:0,50,LEAVES:7,100)
Block(-6,7,-5,AIR:0)
Block(-6,7,-4,AIR:0)
RandomBlock(-6,7,-3,quark:iron_plate:1,70,STAINED_CLAY:15,30,STAINED_CLAY:7,30,quark:iron_plate:1,100)
RandomBlock(-6,8,-6,IRON_FENCE:0,30,IRON_FENCE:0,30,LEAVES:7,30,quark:iron_plate_stairs:6,10,quark:iron_plate_stairs:0,10,quark:iron_plate_stairs:5,10,quark:iron_plate_stairs:3,10,quark:iron_plate_slab:8,10,quark:iron_plate_stairs:7,10,quark:iron_plate_stairs:1,10,quark:iron_plate_slab:0,10,quark:iron_plate_stairs:4,10,quark:iron_plate_stairs:2,10,IRON_FENCE:0,50,IRON_FENCE:0,50,LEAVES:7,100)
Block(-6,8,-5,AIR:0)
Block(-6,8,-4,AIR:0)
RandomBlock(-6,8,-3,quark:iron_plate:1,70,STAINED_CLAY:15,30,STAINED_CLAY:7,30,quark:iron_plate:1,100)
RandomBlock(-6,9,-6,IRON_FENCE:0,30,IRON_FENCE:0,30,LEAVES:7,30,quark:iron_plate_stairs:6,10,quark:iron_plate_stairs:0,10,quark:iron_plate_stairs:5,10,quark:iron_plate_stairs:3,10,quark:iron_plate_slab:8,10,quark:iron_plate_stairs:7,10,quark:iron_plate_stairs:1,10,quark:iron_plate_slab:0,10,quark:iron_plate_stairs:4,10,quark:iron_plate_stairs:2,10,IRON_FENCE:0,50,IRON_FENCE:0,50,LEAVES:7,100)
Block(-6,9,-5,AIR:0)
Block(-6,9,-4,AIR:0)
RandomBlock(-6,9,-3,quark:iron_plate:1,70,STAINED_CLAY:15,30,STAINED_CLAY:7,30,quark:iron_plate:1,100)
RandomBlock(-6,10,-6,quark:iron_plate:1,70,STAINED_CLAY:15,30,STAINED_CLAY:7,30,quark:iron_plate:1,100)
Block(-6,10,-5,AIR:0)
Block(-6,10,-4,AIR:0)
RandomBlock(-6,10,-3,quark:iron_plate:1,70,STAINED_CLAY:15,30,STAINED_CLAY:7,30,quark:iron_plate:1,100)
RandomBlock(-6,11,-6,quark:iron_plate:1,70,STAINED_CLAY:15,30,STAINED_CLAY:7,30,quark:iron_plate:1,100)
Block(-6,11,-5,AIR:0)
Block(-6,11,-4,AIR:0)
RandomBlock(-6,11,-3,IRON_FENCE:0,30,IRON_FENCE:0,30,LEAVES:7,30,quark:iron_plate_stairs:6,10,quark:iron_plate_stairs:0,10,quark:iron_plate_stairs:5,10,quark:iron_plate_stairs:3,10,quark:iron_plate_slab:8,10,quark:iron_plate_stairs:7,10,quark:iron_plate_stairs:1,10,quark:iron_plate_slab:0,10,quark:iron_plate_stairs:4,10,quark:iron_plate_stairs:2,10,IRON_FENCE:0,50,IRON_FENCE:0,50,LEAVES:7,100)
RandomBlock(-6,12,-6,quark:iron_plate:1,70,STAINED_CLAY:15,30,STAINED_CLAY:7,30,quark:iron_plate:1,100)
Block(-6,12,-5,AIR:0)
Block(-6,12,-4,AIR:0)
RandomBlock(-6,12,-3,quark:iron_plate:1,70,STAINED_CLAY:15,30,STAINED_CLAY:7,30,quark:iron_plate:1,100)
RandomBlock(-6,13,-6,quark:iron_plate:1,70,STAINED_CLAY:15,30,STAINED_CLAY:7,30,quark:iron_plate:1,100)
Block(-6,13,-5,AIR:0)
Block(-6,13,-4,AIR:0)
RandomBlock(-6,13,-3,quark:iron_plate:1,70,STAINED_CLAY:15,30,STAINED_CLAY:7,30,quark:iron_plate:1,100)
RandomBlock(-6,14,-6,quark:iron_plate:1,70,STAINED_CLAY:15,30,STAINED_CLAY:7,30,quark:iron_plate:1,100)
Block(-6,14,-5,AIR:0)
Block(-6,14,-4,AIR:0)
RandomBlock(-6,14,-3,quark:iron_plate:1,70,STAINED_CLAY:15,30,STAINED_CLAY:7,30,quark:iron_plate:1,100)
RandomBlock(-6,15,-6,quark:iron_plate:1,70,STAINED_CLAY:15,30,STAINED_CLAY:7,30,quark:iron_plate:1,100)
Block(-6,15,-5,AIR:0)
Block(-6,15,-4,AIR:0)
RandomBlock(-6,15,-3,quark:iron_plate:1,70,STAINED_CLAY:15,30,STAINED_CLAY:7,30,quark:iron_plate:1,100)
RandomBlock(-6,16,-6,quark:iron_plate:1,70,STAINED_CLAY:15,30,STAINED_CLAY:7,30,quark:iron_plate:1,100)
Block(-6,16,-5,AIR:0)
Block(-6,16,-4,AIR:0)
RandomBlock(-6,16,-3,quark:iron_plate:1,70,STAINED_CLAY:15,30,STAINED_CLAY:7,30,quark:iron_plate:1,100)
RandomBlock(-6,17,-6,quark:iron_plate:1,70,STAINED_CLAY:15,30,STAINED_CLAY:7,30,quark:iron_plate:1,100)
Block(-6,17,-5,AIR:0)
Block(-6,17,-4,AIR:0)
RandomBlock(-6,17,-3,quark:iron_plate:1,70,STAINED_CLAY:15,30,STAINED_CLAY:7,30,quark:iron_plate:1,100)
RandomBlock(-6,18,-6,quark:iron_plate:1,70,STAINED_CLAY:15,30,STAINED_CLAY:7,30,quark:iron_plate:1,100)
Block(-6,18,-5,AIR:0)
Block(-6,18,-4,AIR:0)
RandomBlock(-6,18,-3,quark:iron_plate:1,70,STAINED_CLAY:15,30,STAINED_CLAY:7,30,quark:iron_plate:1,100)
RandomBlock(-6,19,-6,quark:iron_plate:1,70,STAINED_CLAY:15,30,STAINED_CLAY:7,30,quark:iron_plate:1,100)
Block(-6,19,-5,AIR:0)
Block(-6,19,-4,AIR:0)
RandomBlock(-6,19,-3,quark:iron_plate:1,70,STAINED_CLAY:15,30,STAINED_CLAY:7,30,quark:iron_plate:1,100)
RandomBlock(-5,0,-6,quark:iron_plate:1,70,STAINED_CLAY:15,30,STAINED_CLAY:7,30,quark:iron_plate:1,100)
Block(-5,0,-5,AIR:0)
Block(-5,0,-4,AIR:0)
RandomBlock(-5,0,-3,quark:iron_plate:1,70,STAINED_CLAY:15,30,STAINED_CLAY:7,30,quark:iron_plate:1,100)
RandomBlock(-5,1,-6,quark:iron_plate:1,70,STAINED_CLAY:15,30,STAINED_CLAY:7,30,quark:iron_plate:1,100)
Block(-5,1,-5,AIR:0)
Block(-5,1,-4,AIR:0)
RandomBlock(-5,1,-3,quark:iron_plate:1,70,STAINED_CLAY:15,30,STAINED_CLAY:7,30,quark:iron_plate:1,100)
RandomBlock(-5,2,-6,quark:iron_plate:1,70,STAINED_CLAY:15,30,STAINED_CLAY:7,30,quark:iron_plate:1,100)
Block(-5,2,-5,AIR:0)
Block(-5,2,-4,AIR:0)
RandomBlock(-5,2,-3,quark:iron_plate:1,70,STAINED_CLAY:15,30,STAINED_CLAY:7,30,quark:iron_plate:1,100)
RandomBlock(-5,3,-6,quark:iron_plate:1,70,STAINED_CLAY:15,30,STAINED_CLAY:7,30,quark:iron_plate:1,100)
Block(-5,3,-5,AIR:0)
Block(-5,3,-4,AIR:0)
RandomBlock(-5,3,-3,quark:iron_plate:1,70,STAINED_CLAY:15,30,STAINED_CLAY:7,30,quark:iron_plate:1,100)
RandomBlock(-5,4,-6,quark:iron_plate:1,70,STAINED_CLAY:15,30,STAINED_CLAY:7,30,quark:iron_plate:1,100)
Block(-5,4,-5,AIR:0)
Block(-5,4,-4,AIR:0)
RandomBlock(-5,4,-3,quark:iron_plate:1,70,STAINED_CLAY:15,30,STAINED_CLAY:7,30,quark:iron_plate:1,100)
RandomBlock(-5,5,-6,quark:iron_plate:1,70,STAINED_CLAY:15,30,STAINED_CLAY:7,30,quark:iron_plate:1,100)
Block(-5,5,-5,AIR:0)
Block(-5,5,-4,AIR:0)
RandomBlock(-5,5,-3,quark:iron_plate:1,70,STAINED_CLAY:15,30,STAINED_CLAY:7,30,quark:iron_plate:1,100)
RandomBlock(-5,6,-6,quark:iron_plate:1,70,STAINED_CLAY:15,30,STAINED_CLAY:7,30,quark:iron_plate:1,100)
Block(-5,6,-5,AIR:0)
Block(-5,6,-4,AIR:0)
RandomBlock(-5,6,-3,quark:iron_plate:1,70,STAINED_CLAY:15,30,STAINED_CLAY:7,30,quark:iron_plate:1,100)
RandomBlock(-5,7,-6,quark:iron_plate:1,70,STAINED_CLAY:15,30,STAINED_CLAY:7,30,quark:iron_plate:1,100)
Block(-5,7,-5,AIR:0)
Block(-5,7,-4,AIR:0)
RandomBlock(-5,7,-3,quark:iron_plate:1,70,STAINED_CLAY:15,30,STAINED_CLAY:7,30,quark:iron_plate:1,100)
RandomBlock(-5,8,-6,IRON_FENCE:0,30,IRON_FENCE:0,30,LEAVES:7,30,quark:iron_plate_stairs:6,10,quark:iron_plate_stairs:0,10,quark:iron_plate_stairs:5,10,quark:iron_plate_stairs:3,10,quark:iron_plate_slab:8,10,quark:iron_plate_stairs:7,10,quark:iron_plate_stairs:1,10,quark:iron_plate_slab:0,10,quark:iron_plate_stairs:4,10,quark:iron_plate_stairs:2,10,IRON_FENCE:0,50,IRON_FENCE:0,50,LEAVES:7,100)
Block(-5,8,-5,AIR:0)
Block(-5,8,-4,AIR:0)
RandomBlock(-5,8,-3,quark:iron_plate:1,70,STAINED_CLAY:15,30,STAINED_CLAY:7,30,quark:iron_plate:1,100)
RandomBlock(-5,9,-6,IRON_FENCE:0,30,IRON_FENCE:0,30,LEAVES:7,30,quark:iron_plate_stairs:6,10,quark:iron_plate_stairs:0,10,quark:iron_plate_stairs:5,10,quark:iron_plate_stairs:3,10,quark:iron_plate_slab:8,10,quark:iron_plate_stairs:7,10,quark:iron_plate_stairs:1,10,quark:iron_plate_slab:0,10,quark:iron_plate_stairs:4,10,quark:iron_plate_stairs:2,10,IRON_FENCE:0,50,IRON_FENCE:0,50,LEAVES:7,100)
Block(-5,9,-5,AIR:0)
Block(-5,9,-4,AIR:0)
RandomBlock(-5,9,-3,quark:iron_plate:1,70,STAINED_CLAY:15,30,STAINED_CLAY:7,30,quark:iron_plate:1,100)
RandomBlock(-5,10,-6,quark:iron_plate:1,70,STAINED_CLAY:15,30,STAINED_CLAY:7,30,quark:iron_plate:1,100)
Block(-5,10,-5,AIR:0)
Block(-5,10,-4,AIR:0)
RandomBlock(-5,10,-3,quark:iron_plate:1,70,STAINED_CLAY:15,30,STAINED_CLAY:7,30,quark:iron_plate:1,100)
RandomBlock(-5,11,-6,quark:iron_plate:1,70,STAINED_CLAY:15,30,STAINED_CLAY:7,30,quark:iron_plate:1,100)
Block(-5,11,-5,AIR:0)
Block(-5,11,-4,AIR:0)
RandomBlock(-5,11,-3,quark:iron_plate:1,70,STAINED_CLAY:15,30,STAINED_CLAY:7,30,quark:iron_plate:1,100)
RandomBlock(-5,12,-6,quark:iron_plate:1,70,STAINED_CLAY:15,30,STAINED_CLAY:7,30,quark:iron_plate:1,100)
Block(-5,12,-5,AIR:0)
Block(-5,12,-4,AIR:0)
RandomBlock(-5,12,-3,quark:iron_plate:1,70,STAINED_CLAY:15,30,STAINED_CLAY:7,30,quark:iron_plate:1,100)
RandomBlock(-5,13,-6,quark:iron_plate:1,70,STAINED_CLAY:15,30,STAINED_CLAY:7,30,quark:iron_plate:1,100)
Block(-5,13,-5,AIR:0)
Block(-5,13,-4,AIR:0)
RandomBlock(-5,13,-3,quark:iron_plate:1,70,STAINED_CLAY:15,30,STAINED_CLAY:7,30,quark:iron_plate:1,100)
RandomBlock(-5,14,-6,IRON_FENCE:0,30,IRON_FENCE:0,30,LEAVES:7,30,quark:iron_plate_stairs:6,10,quark:iron_plate_stairs:0,10,quark:iron_plate_stairs:5,10,quark:iron_plate_stairs:3,10,quark:iron_plate_slab:8,10,quark:iron_plate_stairs:7,10,quark:iron_plate_stairs:1,10,quark:iron_plate_slab:0,10,quark:iron_plate_stairs:4,10,quark:iron_plate_stairs:2,10,IRON_FENCE:0,50,IRON_FENCE:0,50,LEAVES:7,100)
Block(-5,14,-5,AIR:0)
Block(-5,14,-4,AIR:0)
RandomBlock(-5,14,-3,quark:iron_plate:1,70,STAINED_CLAY:15,30,STAINED_CLAY:7,30,quark:iron_plate:1,100)
RandomBlock(-5,15,-6,IRON_FENCE:0,30,IRON_FENCE:0,30,LEAVES:7,30,quark:iron_plate_stairs:6,10,quark:iron_plate_stairs:0,10,quark:iron_plate_stairs:5,10,quark:iron_plate_stairs:3,10,quark:iron_plate_slab:8,10,quark:iron_plate_stairs:7,10,quark:iron_plate_stairs:1,10,quark:iron_plate_slab:0,10,quark:iron_plate_stairs:4,10,quark:iron_plate_stairs:2,10,IRON_FENCE:0,50,IRON_FENCE:0,50,LEAVES:7,100)
Block(-5,15,-5,AIR:0)
Block(-5,15,-4,AIR:0)
RandomBlock(-5,15,-3,quark:iron_plate:1,70,STAINED_CLAY:15,30,STAINED_CLAY:7,30,quark:iron_plate:1,100)
RandomBlock(-5,16,-6,IRON_FENCE:0,30,IRON_FENCE:0,30,LEAVES:7,30,quark:iron_plate_stairs:6,10,quark:iron_plate_stairs:0,10,quark:iron_plate_stairs:5,10,quark:iron_plate_stairs:3,10,quark:iron_plate_slab:8,10,quark:iron_plate_stairs:7,10,quark:iron_plate_stairs:1,10,quark:iron_plate_slab:0,10,quark:iron_plate_stairs:4,10,quark:iron_plate_stairs:2,10,IRON_FENCE:0,50,IRON_FENCE:0,50,LEAVES:7,100)
Block(-5,16,-5,AIR:0)
Block(-5,16,-4,AIR:0)
RandomBlock(-5,16,-3,quark:iron_plate:1,70,STAINED_CLAY:15,30,STAINED_CLAY:7,30,quark:iron_plate:1,100)
RandomBlock(-5,17,-6,quark:iron_plate:1,70,STAINED_CLAY:15,30,STAINED_CLAY:7,30,quark:iron_plate:1,100)
Block(-5,17,-5,AIR:0)
Block(-5,17,-4,AIR:0)
RandomBlock(-5,17,-3,quark:iron_plate:1,70,STAINED_CLAY:15,30,STAINED_CLAY:7,30,quark:iron_plate:1,100)
RandomBlock(-5,18,-6,quark:iron_plate:1,70,STAINED_CLAY:15,30,STAINED_CLAY:7,30,quark:iron_plate:1,100)
Block(-5,18,-5,AIR:0)
Block(-5,18,-4,AIR:0)
RandomBlock(-5,18,-3,IRON_FENCE:0,30,IRON_FENCE:0,30,LEAVES:7,30,quark:iron_plate_stairs:6,10,quark:iron_plate_stairs:0,10,quark:iron_plate_stairs:5,10,quark:iron_plate_stairs:3,10,quark:iron_plate_slab:8,10,quark:iron_plate_stairs:7,10,quark:iron_plate_stairs:1,10,quark:iron_plate_slab:0,10,quark:iron_plate_stairs:4,10,quark:iron_plate_stairs:2,10,IRON_FENCE:0,50,IRON_FENCE:0,50,LEAVES:7,100)
RandomBlock(-5,19,-6,quark:iron_plate:1,70,STAINED_CLAY:15,30,STAINED_CLAY:7,30,quark:iron_plate:1,100)
Block(-5,19,-5,AIR:0)
Block(-5,19,-4,AIR:0)
RandomBlock(-5,19,-3,quark:iron_plate:1,70,STAINED_CLAY:15,30,STAINED_CLAY:7,30,quark:iron_plate:1,100)
RandomBlock(-4,0,-6,quark:iron_plate:1,70,STAINED_CLAY:15,30,STAINED_CLAY:7,30,quark:iron_plate:1,100)
RandomBlock(-4,0,-5,quark:iron_plate:1,70,STAINED_CLAY:15,30,STAINED_CLAY:7,30,quark:iron_plate:1,100)
RandomBlock(-4,0,-4,quark:iron_plate:1,70,STAINED_CLAY:15,30,STAINED_CLAY:7,30,quark:iron_plate:1,100)
RandomBlock(-4,0,-3,quark:iron_plate:1,70,STAINED_CLAY:15,30,STAINED_CLAY:7,30,quark:iron_plate:1,100)
RandomBlock(-4,1,-6,quark:iron_plate:1,70,STAINED_CLAY:15,30,STAINED_CLAY:7,30,quark:iron_plate:1,100)
RandomBlock(-4,1,-5,quark:iron_plate:1,70,STAINED_CLAY:15,30,STAINED_CLAY:7,30,quark:iron_plate:1,100)
RandomBlock(-4,1,-4,quark:iron_plate:1,70,STAINED_CLAY:15,30,STAINED_CLAY:7,30,quark:iron_plate:1,100)
RandomBlock(-4,1,-3,quark:iron_plate:1,70,STAINED_CLAY:15,30,STAINED_CLAY:7,30,quark:iron_plate:1,100)
RandomBlock(-4,2,-6,quark:iron_plate:1,70,STAINED_CLAY:15,30,STAINED_CLAY:7,30,quark:iron_plate:1,100)
RandomBlock(-4,2,-5,quark:iron_plate:1,70,STAINED_CLAY:15,30,STAINED_CLAY:7,30,quark:iron_plate:1,100)
RandomBlock(-4,2,-4,quark:iron_plate:1,70,STAINED_CLAY:15,30,STAINED_CLAY:7,30,quark:iron_plate:1,100)
RandomBlock(-4,2,-3,quark:iron_plate:1,70,STAINED_CLAY:15,30,STAINED_CLAY:7,30,quark:iron_plate:1,100)
RandomBlock(-4,3,-6,quark:iron_plate:1,70,STAINED_CLAY:15,30,STAINED_CLAY:7,30,quark:iron_plate:1,100)
RandomBlock(-4,3,-5,quark:iron_plate:1,70,STAINED_CLAY:15,30,STAINED_CLAY:7,30,quark:iron_plate:1,100)
RandomBlock(-4,3,-4,quark:iron_plate:1,70,STAINED_CLAY:15,30,STAINED_CLAY:7,30,quark:iron_plate:1,100)
RandomBlock(-4,3,-3,quark:iron_plate:1,70,STAINED_CLAY:15,30,STAINED_CLAY:7,30,quark:iron_plate:1,100)
RandomBlock(-4,4,-6,quark:iron_plate:1,70,STAINED_CLAY:15,30,STAINED_CLAY:7,30,quark:iron_plate:1,100)
RandomBlock(-4,4,-5,quark:iron_plate:1,70,STAINED_CLAY:15,30,STAINED_CLAY:7,30,quark:iron_plate:1,100)
RandomBlock(-4,4,-4,quark:iron_plate:1,70,STAINED_CLAY:15,30,STAINED_CLAY:7,30,quark:iron_plate:1,100)
RandomBlock(-4,4,-3,quark:iron_plate:1,70,STAINED_CLAY:15,30,STAINED_CLAY:7,30,quark:iron_plate:1,100)
RandomBlock(-4,5,-6,quark:iron_plate:1,70,STAINED_CLAY:15,30,STAINED_CLAY:7,30,quark:iron_plate:1,100)
RandomBlock(-4,5,-5,quark:iron_plate:1,70,STAINED_CLAY:15,30,STAINED_CLAY:7,30,quark:iron_plate:1,100)
RandomBlock(-4,5,-4,quark:iron_plate:1,70,STAINED_CLAY:15,30,STAINED_CLAY:7,30,quark:iron_plate:1,100)
RandomBlock(-4,5,-3,quark:iron_plate:1,70,STAINED_CLAY:15,30,STAINED_CLAY:7,30,quark:iron_plate:1,100)
RandomBlock(-4,6,-6,quark:iron_plate:1,70,STAINED_CLAY:15,30,STAINED_CLAY:7,30,quark:iron_plate:1,100)
RandomBlock(-4,6,-5,quark:iron_plate:1,70,STAINED_CLAY:15,30,STAINED_CLAY:7,30,quark:iron_plate:1,100)
RandomBlock(-4,6,-4,quark:iron_plate:1,70,STAINED_CLAY:15,30,STAINED_CLAY:7,30,quark:iron_plate:1,100)
RandomBlock(-4,6,-3,quark:iron_plate:1,70,STAINED_CLAY:15,30,STAINED_CLAY:7,30,quark:iron_plate:1,100)
RandomBlock(-4,7,-6,quark:iron_plate:1,70,STAINED_CLAY:15,30,STAINED_CLAY:7,30,quark:iron_plate:1,100)
RandomBlock(-4,7,-5,quark:iron_plate:1,70,STAINED_CLAY:15,30,STAINED_CLAY:7,30,quark:iron_plate:1,100)
RandomBlock(-4,7,-4,quark:iron_plate:1,70,STAINED_CLAY:15,30,STAINED_CLAY:7,30,quark:iron_plate:1,100)
RandomBlock(-4,7,-3,quark:iron_plate:1,70,STAINED_CLAY:15,30,STAINED_CLAY:7,30,quark:iron_plate:1,100)
RandomBlock(-4,8,-6,IRON_FENCE:0,30,IRON_FENCE:0,30,LEAVES:7,30,quark:iron_plate_stairs:6,10,quark:iron_plate_stairs:0,10,quark:iron_plate_stairs:5,10,quark:iron_plate_stairs:3,10,quark:iron_plate_slab:8,10,quark:iron_plate_stairs:7,10,quark:iron_plate_stairs:1,10,quark:iron_plate_slab:0,10,quark:iron_plate_stairs:4,10,quark:iron_plate_stairs:2,10,IRON_FENCE:0,50,IRON_FENCE:0,50,LEAVES:7,100)
RandomBlock(-4,8,-5,quark:iron_plate:1,70,STAINED_CLAY:15,30,STAINED_CLAY:7,30,quark:iron_plate:1,100)
RandomBlock(-4,8,-4,quark:iron_plate:1,70,STAINED_CLAY:15,30,STAINED_CLAY:7,30,quark:iron_plate:1,100)
RandomBlock(-4,8,-3,quark:iron_plate:1,70,STAINED_CLAY:15,30,STAINED_CLAY:7,30,quark:iron_plate:1,100)
RandomBlock(-4,9,-6,IRON_FENCE:0,30,IRON_FENCE:0,30,LEAVES:7,30,quark:iron_plate_stairs:6,10,quark:iron_plate_stairs:0,10,quark:iron_plate_stairs:5,10,quark:iron_plate_stairs:3,10,quark:iron_plate_slab:8,10,quark:iron_plate_stairs:7,10,quark:iron_plate_stairs:1,10,quark:iron_plate_slab:0,10,quark:iron_plate_stairs:4,10,quark:iron_plate_stairs:2,10,IRON_FENCE:0,50,IRON_FENCE:0,50,LEAVES:7,100)
RandomBlock(-4,9,-5,IRON_FENCE:0,30,IRON_FENCE:0,30,LEAVES:7,30,quark:iron_plate_stairs:6,10,quark:iron_plate_stairs:0,10,quark:iron_plate_stairs:5,10,quark:iron_plate_stairs:3,10,quark:iron_plate_slab:8,10,quark:iron_plate_stairs:7,10,quark:iron_plate_stairs:1,10,quark:iron_plate_slab:0,10,quark:iron_plate_stairs:4,10,quark:iron_plate_stairs:2,10,IRON_FENCE:0,50,IRON_FENCE:0,50,LEAVES:7,100)
RandomBlock(-4,9,-4,quark:iron_plate:1,70,STAINED_CLAY:15,30,STAINED_CLAY:7,30,quark:iron_plate:1,100)
RandomBlock(-4,9,-3,quark:iron_plate:1,70,STAINED_CLAY:15,30,STAINED_CLAY:7,30,quark:iron_plate:1,100)
RandomBlock(-4,10,-6,IRON_FENCE:0,30,IRON_FENCE:0,30,LEAVES:7,30,quark:iron_plate_stairs:6,10,quark:iron_plate_stairs:0,10,quark:iron_plate_stairs:5,10,quark:iron_plate_stairs:3,10,quark:iron_plate_slab:8,10,quark:iron_plate_stairs:7,10,quark:iron_plate_stairs:1,10,quark:iron_plate_slab:0,10,quark:iron_plate_stairs:4,10,quark:iron_plate_stairs:2,10,IRON_FENCE:0,50,IRON_FENCE:0,50,LEAVES:7,100)
RandomBlock(-4,10,-5,quark:iron_plate:1,70,STAINED_CLAY:15,30,STAINED_CLAY:7,30,quark:iron_plate:1,100)
RandomBlock(-4,10,-4,quark:iron_plate:1,70,STAINED_CLAY:15,30,STAINED_CLAY:7,30,quark:iron_plate:1,100)
RandomBlock(-4,10,-3,quark:iron_plate:1,70,STAINED_CLAY:15,30,STAINED_CLAY:7,30,quark:iron_plate:1,100)
RandomBlock(-4,11,-6,quark:iron_plate:1,70,STAINED_CLAY:15,30,STAINED_CLAY:7,30,quark:iron_plate:1,100)
RandomBlock(-4,11,-5,quark:iron_plate:1,70,STAINED_CLAY:15,30,STAINED_CLAY:7,30,quark:iron_plate:1,100)
RandomBlock(-4,11,-4,quark:iron_plate:1,70,STAINED_CLAY:15,30,STAINED_CLAY:7,30,quark:iron_plate:1,100)
RandomBlock(-4,11,-3,quark:iron_plate:1,70,STAINED_CLAY:15,30,STAINED_CLAY:7,30,quark:iron_plate:1,100)
RandomBlock(-4,12,-6,quark:iron_plate:1,70,STAINED_CLAY:15,30,STAINED_CLAY:7,30,quark:iron_plate:1,100)
RandomBlock(-4,12,-5,quark:iron_plate:1,70,STAINED_CLAY:15,30,STAINED_CLAY:7,30,quark:iron_plate:1,100)
RandomBlock(-4,12,-4,quark:iron_plate:1,70,STAINED_CLAY:15,30,STAINED_CLAY:7,30,quark:iron_plate:1,100)
RandomBlock(-4,12,-3,quark:iron_plate:1,70,STAINED_CLAY:15,30,STAINED_CLAY:7,30,quark:iron_plate:1,100)
RandomBlock(-4,13,-6,quark:iron_plate:1,70,STAINED_CLAY:15,30,STAINED_CLAY:7,30,quark:iron_plate:1,100)
RandomBlock(-4,13,-5,quark:iron_plate:1,70,STAINED_CLAY:15,30,STAINED_CLAY:7,30,quark:iron_plate:1,100)
RandomBlock(-4,13,-4,quark:iron_plate:1,70,STAINED_CLAY:15,30,STAINED_CLAY:7,30,quark:iron_plate:1,100)
RandomBlock(-4,13,-3,quark:iron_plate:1,70,STAINED_CLAY:15,30,STAINED_CLAY:7,30,quark:iron_plate:1,100)
RandomBlock(-4,14,-6,IRON_FENCE:0,30,IRON_FENCE:0,30,LEAVES:7,30,quark:iron_plate_stairs:6,10,quark:iron_plate_stairs:0,10,quark:iron_plate_stairs:5,10,quark:iron_plate_stairs:3,10,quark:iron_plate_slab:8,10,quark:iron_plate_stairs:7,10,quark:iron_plate_stairs:1,10,quark:iron_plate_slab:0,10,quark:iron_plate_stairs:4,10,quark:iron_plate_stairs:2,10,IRON_FENCE:0,50,IRON_FENCE:0,50,LEAVES:7,100)
RandomBlock(-4,14,-5,IRON_FENCE:0,30,IRON_FENCE:0,30,LEAVES:7,30,quark:iron_plate_stairs:6,10,quark:iron_plate_stairs:0,10,quark:iron_plate_stairs:5,10,quark:iron_plate_stairs:3,10,quark:iron_plate_slab:8,10,quark:iron_plate_stairs:7,10,quark:iron_plate_stairs:1,10,quark:iron_plate_slab:0,10,quark:iron_plate_stairs:4,10,quark:iron_plate_stairs:2,10,IRON_FENCE:0,50,IRON_FENCE:0,50,LEAVES:7,100)
RandomBlock(-4,14,-4,quark:iron_plate:1,70,STAINED_CLAY:15,30,STAINED_CLAY:7,30,quark:iron_plate:1,100)
RandomBlock(-4,14,-3,quark:iron_plate:1,70,STAINED_CLAY:15,30,STAINED_CLAY:7,30,quark:iron_plate:1,100)
RandomBlock(-4,15,-6,IRON_FENCE:0,30,IRON_FENCE:0,30,LEAVES:7,30,quark:iron_plate_stairs:6,10,quark:iron_plate_stairs:0,10,quark:iron_plate_stairs:5,10,quark:iron_plate_stairs:3,10,quark:iron_plate_slab:8,10,quark:iron_plate_stairs:7,10,quark:iron_plate_stairs:1,10,quark:iron_plate_slab:0,10,quark:iron_plate_stairs:4,10,quark:iron_plate_stairs:2,10,IRON_FENCE:0,50,IRON_FENCE:0,50,LEAVES:7,100)
RandomBlock(-4,15,-5,IRON_FENCE:0,30,IRON_FENCE:0,30,LEAVES:7,30,quark:iron_plate_stairs:6,10,quark:iron_plate_stairs:0,10,quark:iron_plate_stairs:5,10,quark:iron_plate_stairs:3,10,quark:iron_plate_slab:8,10,quark:iron_plate_stairs:7,10,quark:iron_plate_stairs:1,10,quark:iron_plate_slab:0,10,quark:iron_plate_stairs:4,10,quark:iron_plate_stairs:2,10,IRON_FENCE:0,50,IRON_FENCE:0,50,LEAVES:7,100)
RandomBlock(-4,15,-4,quark:iron_plate:1,70,STAINED_CLAY:15,30,STAINED_CLAY:7,30,quark:iron_plate:1,100)
RandomBlock(-4,15,-3,quark:iron_plate:1,70,STAINED_CLAY:15,30,STAINED_CLAY:7,30,quark:iron_plate:1,100)
RandomBlock(-4,16,-6,IRON_FENCE:0,30,IRON_FENCE:0,30,LEAVES:7,30,quark:iron_plate_stairs:6,10,quark:iron_plate_stairs:0,10,quark:iron_plate_stairs:5,10,quark:iron_plate_stairs:3,10,quark:iron_plate_slab:8,10,quark:iron_plate_stairs:7,10,quark:iron_plate_stairs:1,10,quark:iron_plate_slab:0,10,quark:iron_plate_stairs:4,10,quark:iron_plate_stairs:2,10,IRON_FENCE:0,50,IRON_FENCE:0,50,LEAVES:7,100)
RandomBlock(-4,16,-5,IRON_FENCE:0,30,IRON_FENCE:0,30,LEAVES:7,30,quark:iron_plate_stairs:6,10,quark:iron_plate_stairs:0,10,quark:iron_plate_stairs:5,10,quark:iron_plate_stairs:3,10,quark:iron_plate_slab:8,10,quark:iron_plate_stairs:7,10,quark:iron_plate_stairs:1,10,quark:iron_plate_slab:0,10,quark:iron_plate_stairs:4,10,quark:iron_plate_stairs:2,10,IRON_FENCE:0,50,IRON_FENCE:0,50,LEAVES:7,100)
RandomBlock(-4,16,-4,quark:iron_plate:1,70,STAINED_CLAY:15,30,STAINED_CLAY:7,30,quark:iron_plate:1,100)
RandomBlock(-4,16,-3,quark:iron_plate:1,70,STAINED_CLAY:15,30,STAINED_CLAY:7,30,quark:iron_plate:1,100)
RandomBlock(-4,17,-6,quark:iron_plate:1,70,STAINED_CLAY:15,30,STAINED_CLAY:7,30,quark:iron_plate:1,100)
RandomBlock(-4,17,-5,IRON_FENCE:0,30,IRON_FENCE:0,30,LEAVES:7,30,quark:iron_plate_stairs:6,10,quark:iron_plate_stairs:0,10,quark:iron_plate_stairs:5,10,quark:iron_plate_stairs:3,10,quark:iron_plate_slab:8,10,quark:iron_plate_stairs:7,10,quark:iron_plate_stairs:1,10,quark:iron_plate_slab:0,10,quark:iron_plate_stairs:4,10,quark:iron_plate_stairs:2,10,IRON_FENCE:0,50,IRON_FENCE:0,50,LEAVES:7,100)
RandomBlock(-4,17,-4,IRON_FENCE:0,30,IRON_FENCE:0,30,LEAVES:7,30,quark:iron_plate_stairs:6,10,quark:iron_plate_stairs:0,10,quark:iron_plate_stairs:5,10,quark:iron_plate_stairs:3,10,quark:iron_plate_slab:8,10,quark:iron_plate_stairs:7,10,quark:iron_plate_stairs:1,10,quark:iron_plate_slab:0,10,quark:iron_plate_stairs:4,10,quark:iron_plate_stairs:2,10,IRON_FENCE:0,50,IRON_FENCE:0,50,LEAVES:7,100)
RandomBlock(-4,17,-3,IRON_FENCE:0,30,IRON_FENCE:0,30,LEAVES:7,30,quark:iron_plate_stairs:6,10,quark:iron_plate_stairs:0,10,quark:iron_plate_stairs:5,10,quark:iron_plate_stairs:3,10,quark:iron_plate_slab:8,10,quark:iron_plate_stairs:7,10,quark:iron_plate_stairs:1,10,quark:iron_plate_slab:0,10,quark:iron_plate_stairs:4,10,quark:iron_plate_stairs:2,10,IRON_FENCE:0,50,IRON_FENCE:0,50,LEAVES:7,100)
RandomBlock(-4,18,-6,quark:iron_plate:1,70,STAINED_CLAY:15,30,STAINED_CLAY:7,30,quark:iron_plate:1,100)
RandomBlock(-4,18,-5,IRON_FENCE:0,30,IRON_FENCE:0,30,LEAVES:7,30,quark:iron_plate_stairs:6,10,quark:iron_plate_stairs:0,10,quark:iron_plate_stairs:5,10,quark:iron_plate_stairs:3,10,quark:iron_plate_slab:8,10,quark:iron_plate_stairs:7,10,quark:iron_plate_stairs:1,10,quark:iron_plate_slab:0,10,quark:iron_plate_stairs:4,10,quark:iron_plate_stairs:2,10,IRON_FENCE:0,50,IRON_FENCE:0,50,LEAVES:7,100)
RandomBlock(-4,18,-4,IRON_FENCE:0,30,IRON_FENCE:0,30,LEAVES:7,30,quark:iron_plate_stairs:6,10,quark:iron_plate_stairs:0,10,quark:iron_plate_stairs:5,10,quark:iron_plate_stairs:3,10,quark:iron_plate_slab:8,10,quark:iron_plate_stairs:7,10,quark:iron_plate_stairs:1,10,quark:iron_plate_slab:0,10,quark:iron_plate_stairs:4,10,quark:iron_plate_stairs:2,10,IRON_FENCE:0,50,IRON_FENCE:0,50,LEAVES:7,100)
RandomBlock(-4,18,-3,IRON_FENCE:0,30,IRON_FENCE:0,30,LEAVES:7,30,quark:iron_plate_stairs:6,10,quark:iron_plate_stairs:0,10,quark:iron_plate_stairs:5,10,quark:iron_plate_stairs:3,10,quark:iron_plate_slab:8,10,quark:iron_plate_stairs:7,10,quark:iron_plate_stairs:1,10,quark:iron_plate_slab:0,10,quark:iron_plate_stairs:4,10,quark:iron_plate_stairs:2,10,IRON_FENCE:0,50,IRON_FENCE:0,50,LEAVES:7,100)
RandomBlock(-4,19,-6,quark:iron_plate:1,70,STAINED_CLAY:15,30,STAINED_CLAY:7,30,quark:iron_plate:1,100)
RandomBlock(-4,19,-5,IRON_FENCE:0,30,IRON_FENCE:0,30,LEAVES:7,30,quark:iron_plate_stairs:6,10,quark:iron_plate_stairs:0,10,quark:iron_plate_stairs:5,10,quark:iron_plate_stairs:3,10,quark:iron_plate_slab:8,10,quark:iron_plate_stairs:7,10,quark:iron_plate_stairs:1,10,quark:iron_plate_slab:0,10,quark:iron_plate_stairs:4,10,quark:iron_plate_stairs:2,10,IRON_FENCE:0,50,IRON_FENCE:0,50,LEAVES:7,100)
RandomBlock(-4,19,-4,IRON_FENCE:0,30,IRON_FENCE:0,30,LEAVES:7,30,quark:iron_plate_stairs:6,10,quark:iron_plate_stairs:0,10,quark:iron_plate_stairs:5,10,quark:iron_plate_stairs:3,10,quark:iron_plate_slab:8,10,quark:iron_plate_stairs:7,10,quark:iron_plate_stairs:1,10,quark:iron_plate_slab:0,10,quark:iron_plate_stairs:4,10,quark:iron_plate_stairs:2,10,IRON_FENCE:0,50,IRON_FENCE:0,50,LEAVES:7,100)
RandomBlock(-4,19,-3,IRON_FENCE:0,30,IRON_FENCE:0,30,LEAVES:7,30,quark:iron_plate_stairs:6,10,quark:iron_plate_stairs:0,10,quark:iron_plate_stairs:5,10,quark:iron_plate_stairs:3,10,quark:iron_plate_slab:8,10,quark:iron_plate_stairs:7,10,quark:iron_plate_stairs:1,10,quark:iron_plate_slab:0,10,quark:iron_plate_stairs:4,10,quark:iron_plate_stairs:2,10,IRON_FENCE:0,50,IRON_FENCE:0,50,LEAVES:7,100)

#######################################################################
# +-----------------------------------------------------------------+ #
# |                             Branches                            | #
# +-----------------------------------------------------------------+ #
#######################################################################

Branch(16,0,0,true,brutal_pipebig_04_D1C1R0,NORTH,100.0,0)

#######################################################################
# +-----------------------------------------------------------------+ #
# |                             Entities                            | #
# +-----------------------------------------------------------------+ #
#######################################################################


#######################################################################
# +-----------------------------------------------------------------+ #
# |                            Particles                            | #
# +-----------------------------------------------------------------+ #
#######################################################################


#######################################################################
# +-----------------------------------------------------------------+ #
# |                             Spawners                            | #
# +-----------------------------------------------------------------+ #
#######################################################################


#######################################################################
# +-----------------------------------------------------------------+ #
# |                             ModData                             | #
# +-----------------------------------------------------------------+ #
#######################################################################

