
#######################################################################
# +-----------------------------------------------------------------+ #
# |                            BO4 object                           | #
# +-----------------------------------------------------------------+ #
#######################################################################

Author: SRP Manhunt

Description: Four-wide city edge, bypass intersection and metro cap

SettingsMode: WriteWithoutComments


#######################################################################
# +-----------------------------------------------------------------+ #
# |                          Main settings                          | #
# +-----------------------------------------------------------------+ #
#######################################################################

FixedRotation: 

Frequency: 0

SpawnHeight: highestBlock

UseCenterForHighestBlock: true

##############################
# Height Limits for the BO4. #
##############################

MinHeight: 0

MaxHeight: 255

InheritBO3: 

InheritBO3Rotation: NORTH

OverrideChildSettings: true

OverrideParentHeight: false

CanOverride: true

BranchFrequency: 0

BranchFrequencyGroup: 

MustBeBelowOther: false

MustBeInside: 

CannotBeInside: 

ReplacesBO3: 

MustBeInsideWorldBorders: true

CanSpawnOnWater: true

SpawnOnWaterOnly: false

SpawnUnderWater: false

SpawnAtWaterLevel: false

HeightOffset: 0

RemoveAir: false

ReplaceAbove: 

ReplaceBelow: DIRT

ReplaceWithBiomeBlocks: false

ReplaceWithSurfaceBlock: GRASS

ReplaceWithGroundBlock: DIRT

ReplaceWithStoneBlock: STONE

SmoothRadius: 0

SmoothHeightOffset: 0

SmoothStartTop: false

SmoothStartWood: false

SmoothingSurfaceBlock: 

SmoothingGroundBlock: 

BO3Group: 

IsSpawnPoint: false

DoReplaceBlocks: true


#######################################################################
# +-----------------------------------------------------------------+ #
# |                              Blocks                             | #
# +-----------------------------------------------------------------+ #
#######################################################################

Block(-8,0,-7,CONCRETE:7)
Block(-7,0,-7,CONCRETE:7)
Block(-6,0,-7,CONCRETE:7)
Block(-5,0,-7,CONCRETE:7)
Block(-4,0,-7,CONCRETE:7)
Block(-3,0,-7,CONCRETE:7)
Block(-2,0,-7,CONCRETE:7)
Block(-1,0,-7,CONCRETE:7)
Block(0,0,-7,CONCRETE:7)
Block(1,0,-7,CONCRETE:7)
Block(2,0,-7,CONCRETE:7)
Block(3,0,-7,CONCRETE:7)
Block(4,0,-7,CONCRETE:7)
Block(5,0,-7,CONCRETE:7)
Block(6,0,-7,CONCRETE:7)
Block(7,0,-7,CONCRETE:7)
Block(-8,0,-6,CONCRETE:7)
Block(-7,0,-6,CONCRETE:7)
Block(-6,0,-6,CONCRETE:7)
Block(-5,0,-6,CONCRETE:7)
Block(-4,0,-6,CONCRETE:7)
Block(-3,0,-6,CONCRETE:7)
Block(-2,0,-6,CONCRETE:7)
Block(-1,0,-6,CONCRETE:7)
Block(0,0,-6,CONCRETE:7)
Block(1,0,-6,CONCRETE:7)
Block(2,0,-6,CONCRETE:7)
Block(3,0,-6,CONCRETE:7)
Block(4,0,-6,CONCRETE:7)
Block(5,0,-6,CONCRETE:7)
Block(6,0,-6,CONCRETE:7)
Block(7,0,-6,CONCRETE:7)
Block(-8,0,-5,CONCRETE:7)
Block(-7,0,-5,CONCRETE:7)
Block(-6,0,-5,CONCRETE:7)
Block(-5,0,-5,CONCRETE:7)
Block(-4,0,-5,CONCRETE:7)
Block(-3,0,-5,CONCRETE:7)
Block(-2,0,-5,CONCRETE:7)
Block(-1,0,-5,CONCRETE:7)
Block(0,0,-5,CONCRETE:7)
Block(1,0,-5,CONCRETE:7)
Block(2,0,-5,CONCRETE:7)
Block(3,0,-5,CONCRETE:7)
Block(4,0,-5,CONCRETE:7)
Block(5,0,-5,CONCRETE:7)
Block(6,0,-5,CONCRETE:7)
Block(7,0,-5,CONCRETE:7)
Block(-8,0,-4,CONCRETE:7)
Block(-7,0,-4,CONCRETE:7)
Block(-6,0,-4,CONCRETE:7)
Block(-5,0,-4,CONCRETE:7)
Block(-4,0,-4,CONCRETE:7)
Block(-3,0,-4,CONCRETE:7)
Block(-2,0,-4,CONCRETE:7)
Block(-1,0,-4,CONCRETE:7)
Block(0,0,-4,CONCRETE:7)
Block(1,0,-4,CONCRETE:7)
Block(2,0,-4,CONCRETE:7)
Block(3,0,-4,CONCRETE:7)
Block(4,0,-4,CONCRETE:7)
Block(5,0,-4,CONCRETE:7)
Block(6,0,-4,CONCRETE:7)
Block(7,0,-4,CONCRETE:7)
Block(-8,0,-3,CONCRETE:7)
Block(-7,0,-3,CONCRETE:7)
Block(-6,0,-3,CONCRETE:7)
Block(-5,0,-3,CONCRETE:7)
Block(-4,0,-3,CONCRETE:7)
Block(-3,0,-3,CONCRETE:7)
Block(-2,0,-3,CONCRETE:7)
Block(-1,0,-3,CONCRETE:7)
Block(0,0,-3,CONCRETE:7)
Block(1,0,-3,CONCRETE:7)
Block(2,0,-3,CONCRETE:7)
Block(3,0,-3,CONCRETE:7)
Block(4,0,-3,CONCRETE:7)
Block(5,0,-3,CONCRETE:7)
Block(6,0,-3,CONCRETE:7)
Block(7,0,-3,CONCRETE:7)
Block(-8,0,-2,CONCRETE:7)
Block(-7,0,-2,CONCRETE:7)
Block(-6,0,-2,CONCRETE:7)
Block(-5,0,-2,CONCRETE:7)
Block(-4,0,-2,CONCRETE:7)
Block(-3,0,-2,CONCRETE:7)
Block(-2,0,-2,CONCRETE:7)
Block(-1,0,-2,CONCRETE:7)
Block(0,0,-2,CONCRETE:7)
Block(1,0,-2,CONCRETE:7)
Block(2,0,-2,CONCRETE:7)
Block(3,0,-2,CONCRETE:7)
Block(4,0,-2,CONCRETE:7)
Block(5,0,-2,CONCRETE:7)
Block(6,0,-2,CONCRETE:7)
Block(7,0,-2,CONCRETE:7)
Block(-8,0,-1,CONCRETE:7)
Block(-7,0,-1,CONCRETE:7)
Block(-6,0,-1,CONCRETE:7)
Block(-5,0,-1,CONCRETE:7)
Block(-4,0,-1,CONCRETE:7)
Block(-3,0,-1,CONCRETE:7)
Block(-2,0,-1,CONCRETE:7)
Block(-1,0,-1,CONCRETE:7)
Block(0,0,-1,CONCRETE:7)
Block(1,0,-1,CONCRETE:7)
Block(2,0,-1,CONCRETE:7)
Block(3,0,-1,CONCRETE:7)
Block(4,0,-1,CONCRETE:7)
Block(5,0,-1,CONCRETE:7)
Block(6,0,-1,CONCRETE:7)
Block(7,0,-1,CONCRETE:7)
Block(-8,0,0,CONCRETE:7)
Block(-7,0,0,CONCRETE:7)
Block(-6,0,0,CONCRETE:7)
Block(-5,0,0,CONCRETE:7)
Block(-4,0,0,CONCRETE:7)
Block(-3,0,0,CONCRETE:7)
Block(-2,0,0,CONCRETE:7)
Block(-1,0,0,CONCRETE:7)
Block(0,0,0,CONCRETE:7)
Block(1,0,0,CONCRETE:7)
Block(2,0,0,CONCRETE:7)
Block(3,0,0,CONCRETE:7)
Block(4,0,0,CONCRETE:7)
Block(5,0,0,CONCRETE:7)
Block(6,0,0,CONCRETE:7)
Block(7,0,0,CONCRETE:7)
Block(-8,0,1,CONCRETE:7)
Block(-7,0,1,CONCRETE:7)
Block(-6,0,1,CONCRETE:7)
Block(-5,0,1,CONCRETE:7)
Block(-4,0,1,CONCRETE:7)
Block(-3,0,1,CONCRETE:7)
Block(-2,0,1,CONCRETE:7)
Block(-1,0,1,CONCRETE:7)
Block(0,0,1,CONCRETE:7)
Block(1,0,1,CONCRETE:7)
Block(2,0,1,CONCRETE:7)
Block(3,0,1,CONCRETE:7)
Block(4,0,1,CONCRETE:7)
Block(5,0,1,CONCRETE:7)
Block(6,0,1,CONCRETE:7)
Block(7,0,1,CONCRETE:7)
Block(-8,0,2,CONCRETE:7)
Block(-7,0,2,CONCRETE:7)
Block(-6,0,2,CONCRETE:7)
Block(-5,0,2,CONCRETE:7)
Block(-4,0,2,CONCRETE:7)
Block(-3,0,2,CONCRETE:7)
Block(-2,0,2,CONCRETE:7)
Block(-1,0,2,CONCRETE:7)
Block(0,0,2,CONCRETE:7)
Block(1,0,2,CONCRETE:7)
Block(2,0,2,CONCRETE:7)
Block(3,0,2,CONCRETE:7)
Block(4,0,2,CONCRETE:7)
Block(5,0,2,CONCRETE:7)
Block(6,0,2,CONCRETE:7)
Block(7,0,2,CONCRETE:7)
Block(-8,0,3,CONCRETE:7)
Block(-7,0,3,CONCRETE:7)
Block(-6,0,3,CONCRETE:7)
Block(-5,0,3,CONCRETE:7)
Block(-4,0,3,CONCRETE:7)
Block(-3,0,3,CONCRETE:7)
Block(-2,0,3,CONCRETE:7)
Block(-1,0,3,CONCRETE:7)
Block(0,0,3,CONCRETE:7)
Block(1,0,3,CONCRETE:7)
Block(2,0,3,CONCRETE:7)
Block(3,0,3,CONCRETE:7)
Block(4,0,3,CONCRETE:7)
Block(5,0,3,CONCRETE:7)
Block(6,0,3,CONCRETE:7)
Block(7,0,3,CONCRETE:7)
Block(-8,0,4,CONCRETE:7)
Block(-7,0,4,CONCRETE:7)
Block(-6,0,4,CONCRETE:7)
Block(-5,0,4,CONCRETE:7)
Block(-4,0,4,CONCRETE:7)
Block(-3,0,4,CONCRETE:7)
Block(-2,0,4,CONCRETE:7)
Block(-1,0,4,CONCRETE:7)
Block(0,0,4,CONCRETE:7)
Block(1,0,4,CONCRETE:7)
Block(2,0,4,CONCRETE:7)
Block(3,0,4,CONCRETE:7)
Block(4,0,4,CONCRETE:7)
Block(5,0,4,CONCRETE:7)
Block(6,0,4,CONCRETE:7)
Block(7,0,4,CONCRETE:7)
Block(-8,0,5,CONCRETE:7)
Block(-7,0,5,CONCRETE:7)
Block(-6,0,5,CONCRETE:7)
Block(-5,0,5,CONCRETE:7)
Block(-4,0,5,CONCRETE:7)
Block(-3,0,5,CONCRETE:7)
Block(-2,0,5,CONCRETE:7)
Block(-1,0,5,CONCRETE:7)
Block(0,0,5,CONCRETE:7)
Block(1,0,5,CONCRETE:7)
Block(2,0,5,CONCRETE:7)
Block(3,0,5,CONCRETE:7)
Block(4,0,5,CONCRETE:7)
Block(5,0,5,CONCRETE:7)
Block(6,0,5,CONCRETE:7)
Block(7,0,5,CONCRETE:7)
Block(-8,0,6,CONCRETE:7)
Block(-7,0,6,CONCRETE:7)
Block(-6,0,6,CONCRETE:7)
Block(-5,0,6,CONCRETE:7)
Block(-4,0,6,CONCRETE:7)
Block(-3,0,6,CONCRETE:7)
Block(-2,0,6,CONCRETE:7)
Block(-1,0,6,CONCRETE:7)
Block(0,0,6,CONCRETE:7)
Block(1,0,6,CONCRETE:7)
Block(2,0,6,CONCRETE:7)
Block(3,0,6,CONCRETE:7)
Block(4,0,6,CONCRETE:7)
Block(5,0,6,CONCRETE:7)
Block(6,0,6,CONCRETE:7)
Block(7,0,6,CONCRETE:7)
Block(-8,0,7,CONCRETE:7)
Block(-7,0,7,CONCRETE:7)
Block(-6,0,7,CONCRETE:7)
Block(-5,0,7,CONCRETE:7)
Block(-4,0,7,CONCRETE:7)
Block(-3,0,7,CONCRETE:7)
Block(-2,0,7,CONCRETE:7)
Block(-1,0,7,CONCRETE:7)
Block(0,0,7,CONCRETE:7)
Block(1,0,7,CONCRETE:7)
Block(2,0,7,CONCRETE:7)
Block(3,0,7,CONCRETE:7)
Block(4,0,7,CONCRETE:7)
Block(5,0,7,CONCRETE:7)
Block(6,0,7,CONCRETE:7)
Block(7,0,7,CONCRETE:7)
Block(-8,0,8,CONCRETE:7)
Block(-7,0,8,CONCRETE:7)
Block(-6,0,8,CONCRETE:7)
Block(-5,0,8,CONCRETE:7)
Block(-4,0,8,CONCRETE:7)
Block(-3,0,8,CONCRETE:7)
Block(-2,0,8,CONCRETE:7)
Block(-1,0,8,CONCRETE:7)
Block(0,0,8,CONCRETE:7)
Block(1,0,8,CONCRETE:7)
Block(2,0,8,CONCRETE:7)
Block(3,0,8,CONCRETE:7)
Block(4,0,8,CONCRETE:7)
Block(5,0,8,CONCRETE:7)
Block(6,0,8,CONCRETE:7)
Block(7,0,8,CONCRETE:7)
Block(-8,1,-7,CONCRETE:7)
Block(-7,1,-7,CONCRETE:7)
Block(-6,1,-7,CONCRETE:7)
Block(-5,1,-7,CONCRETE:7)
Block(-4,1,-7,CONCRETE:7)
Block(-3,1,-7,CONCRETE:7)
Block(-2,1,-7,CONCRETE:7)
Block(-1,1,-7,CONCRETE:7)
Block(0,1,-7,CONCRETE:7)
Block(1,1,-7,CONCRETE:7)
Block(2,1,-7,CONCRETE:7)
Block(3,1,-7,CONCRETE:7)
Block(4,1,-7,CONCRETE:7)
Block(5,1,-7,CONCRETE:7)
Block(6,1,-7,AIR:0)
Block(7,1,-7,AIR:0)
Block(-8,1,-6,CONCRETE:7)
Block(-7,1,-6,CONCRETE:7)
Block(-6,1,-6,CONCRETE:7)
Block(-5,1,-6,CONCRETE:7)
Block(-4,1,-6,CONCRETE:7)
Block(-3,1,-6,CONCRETE:7)
Block(-2,1,-6,CONCRETE:7)
Block(-1,1,-6,CONCRETE:7)
Block(0,1,-6,CONCRETE:7)
Block(1,1,-6,CONCRETE:7)
Block(2,1,-6,CONCRETE:7)
Block(3,1,-6,CONCRETE:7)
Block(4,1,-6,CONCRETE:7)
Block(5,1,-6,CONCRETE:7)
Block(6,1,-6,CONCRETE:7)
Block(7,1,-6,AIR:0)
Block(-8,1,-5,CONCRETE:7)
Block(-7,1,-5,CONCRETE:7)
Block(-6,1,-5,CONCRETE:7)
Block(-5,1,-5,CONCRETE:7)
Block(-4,1,-5,CONCRETE:7)
Block(-3,1,-5,CONCRETE:7)
Block(-2,1,-5,CONCRETE:7)
Block(-1,1,-5,CONCRETE:7)
Block(0,1,-5,CONCRETE:7)
Block(1,1,-5,CONCRETE:7)
Block(2,1,-5,CONCRETE:7)
Block(3,1,-5,CONCRETE:7)
Block(4,1,-5,CONCRETE:7)
Block(5,1,-5,CONCRETE:7)
Block(6,1,-5,AIR:0)
Block(7,1,-5,AIR:0)
Block(-8,1,-4,CONCRETE:7)
Block(-7,1,-4,CONCRETE:7)
Block(-6,1,-4,CONCRETE:7)
Block(-5,1,-4,CONCRETE:7)
Block(-4,1,-4,CONCRETE:7)
Block(-3,1,-4,CONCRETE:7)
Block(-2,1,-4,CONCRETE:7)
Block(-1,1,-4,CONCRETE:7)
Block(0,1,-4,CONCRETE:7)
Block(1,1,-4,CONCRETE:7)
Block(2,1,-4,CONCRETE:7)
Block(3,1,-4,CONCRETE:7)
Block(4,1,-4,CONCRETE:7)
Block(5,1,-4,CONCRETE:7)
Block(6,1,-4,AIR:0)
Block(7,1,-4,AIR:0)
Block(-8,1,-3,CONCRETE:7)
Block(-7,1,-3,CONCRETE:7)
Block(-6,1,-3,CONCRETE:7)
Block(-5,1,-3,CONCRETE:7)
Block(-4,1,-3,CONCRETE:7)
Block(-3,1,-3,CONCRETE:7)
Block(-2,1,-3,CONCRETE:7)
Block(-1,1,-3,CONCRETE:7)
Block(0,1,-3,CONCRETE:7)
Block(1,1,-3,CONCRETE:7)
Block(2,1,-3,CONCRETE:7)
Block(3,1,-3,CONCRETE:7)
Block(4,1,-3,CONCRETE:7)
Block(5,1,-3,CONCRETE:7)
Block(6,1,-3,CONCRETE:7)
Block(7,1,-3,AIR:0)
Block(-8,1,-2,CONCRETE:7)
Block(-7,1,-2,CONCRETE:7)
Block(-6,1,-2,CONCRETE:7)
Block(-5,1,-2,CONCRETE:7)
Block(-4,1,-2,CONCRETE:7)
Block(-3,1,-2,CONCRETE:7)
Block(-2,1,-2,CONCRETE:7)
Block(-1,1,-2,CONCRETE:7)
Block(0,1,-2,CONCRETE:7)
Block(1,1,-2,CONCRETE:7)
Block(2,1,-2,CONCRETE:7)
Block(3,1,-2,CONCRETE:7)
Block(4,1,-2,CONCRETE:7)
Block(5,1,-2,CONCRETE:7)
Block(6,1,-2,AIR:0)
Block(7,1,-2,AIR:0)
Block(-8,1,-1,CONCRETE:7)
Block(-7,1,-1,CONCRETE:7)
Block(-6,1,-1,CONCRETE:7)
Block(-5,1,-1,CONCRETE:7)
Block(-4,1,-1,CONCRETE:7)
Block(-3,1,-1,CONCRETE:7)
Block(-2,1,-1,CONCRETE:7)
Block(-1,1,-1,CONCRETE:7)
Block(0,1,-1,CONCRETE:7)
Block(1,1,-1,CONCRETE:7)
Block(2,1,-1,CONCRETE:7)
Block(3,1,-1,CONCRETE:7)
Block(4,1,-1,CONCRETE:7)
Block(5,1,-1,CONCRETE:7)
Block(6,1,-1,AIR:0)
Block(7,1,-1,AIR:0)
Block(-8,1,0,CONCRETE:7)
Block(-7,1,0,CONCRETE:7)
Block(-6,1,0,CONCRETE:7)
Block(-5,1,0,CONCRETE:7)
Block(-4,1,0,CONCRETE:7)
Block(-3,1,0,CONCRETE:7)
Block(-2,1,0,CONCRETE:7)
Block(-1,1,0,CONCRETE:7)
Block(0,1,0,CONCRETE:7)
Block(1,1,0,CONCRETE:7)
Block(2,1,0,CONCRETE:7)
Block(3,1,0,CONCRETE:7)
Block(4,1,0,CONCRETE:7)
Block(5,1,0,CONCRETE:7)
Block(6,1,0,CONCRETE:7)
Block(7,1,0,AIR:0)
Block(-8,1,1,CONCRETE:7)
Block(-7,1,1,CONCRETE:7)
Block(-6,1,1,CONCRETE:7)
Block(-5,1,1,CONCRETE:7)
Block(-4,1,1,CONCRETE:7)
Block(-3,1,1,CONCRETE:7)
Block(-2,1,1,CONCRETE:7)
Block(-1,1,1,CONCRETE:7)
Block(0,1,1,CONCRETE:7)
Block(1,1,1,CONCRETE:7)
Block(2,1,1,CONCRETE:7)
Block(3,1,1,CONCRETE:7)
Block(4,1,1,CONCRETE:7)
Block(5,1,1,CONCRETE:7)
Block(6,1,1,AIR:0)
Block(7,1,1,AIR:0)
Block(-8,1,2,CONCRETE:7)
Block(-7,1,2,CONCRETE:7)
Block(-6,1,2,CONCRETE:7)
Block(-5,1,2,CONCRETE:7)
Block(-4,1,2,CONCRETE:7)
Block(-3,1,2,CONCRETE:7)
Block(-2,1,2,CONCRETE:7)
Block(-1,1,2,CONCRETE:7)
Block(0,1,2,CONCRETE:7)
Block(1,1,2,CONCRETE:7)
Block(2,1,2,CONCRETE:7)
Block(3,1,2,CONCRETE:7)
Block(4,1,2,CONCRETE:7)
Block(5,1,2,CONCRETE:7)
Block(6,1,2,AIR:0)
Block(7,1,2,AIR:0)
Block(-8,1,3,AIR:0)
Block(-7,1,3,AIR:0)
Block(-6,1,3,AIR:0)
Block(-5,1,3,AIR:0)
Block(-4,1,3,AIR:0)
Block(-3,1,3,AIR:0)
Block(-2,1,3,AIR:0)
Block(-1,1,3,AIR:0)
Block(0,1,3,AIR:0)
Block(1,1,3,AIR:0)
Block(2,1,3,AIR:0)
Block(3,1,3,AIR:0)
Block(4,1,3,AIR:0)
Block(5,1,3,AIR:0)
Block(6,1,3,AIR:0)
Block(7,1,3,AIR:0)
Block(-8,1,4,AIR:0)
Block(-7,1,4,AIR:0)
Block(-6,1,4,AIR:0)
Block(-5,1,4,AIR:0)
Block(-4,1,4,AIR:0)
Block(-3,1,4,AIR:0)
Block(-2,1,4,AIR:0)
Block(-1,1,4,AIR:0)
Block(0,1,4,AIR:0)
Block(1,1,4,AIR:0)
Block(2,1,4,AIR:0)
Block(3,1,4,AIR:0)
Block(4,1,4,AIR:0)
Block(5,1,4,AIR:0)
Block(6,1,4,AIR:0)
Block(7,1,4,AIR:0)
Block(-8,1,5,CONCRETE:7)
Block(-7,1,5,CONCRETE:7)
Block(-6,1,5,CONCRETE:7)
Block(-5,1,5,CONCRETE:7)
Block(-4,1,5,CONCRETE:7)
Block(-3,1,5,CONCRETE:7)
Block(-2,1,5,CONCRETE:7)
Block(-1,1,5,CONCRETE:7)
Block(0,1,5,CONCRETE:7)
Block(1,1,5,CONCRETE:7)
Block(2,1,5,CONCRETE:7)
Block(3,1,5,CONCRETE:7)
Block(4,1,5,CONCRETE:7)
Block(5,1,5,AIR:0)
Block(6,1,5,AIR:0)
Block(7,1,5,AIR:0)
Block(-8,1,6,CONCRETE:7)
Block(-7,1,6,CONCRETE:7)
Block(-6,1,6,CONCRETE:7)
Block(-5,1,6,CONCRETE:7)
Block(-4,1,6,CONCRETE:7)
Block(-3,1,6,CONCRETE:7)
Block(-2,1,6,CONCRETE:7)
Block(-1,1,6,CONCRETE:7)
Block(0,1,6,CONCRETE:7)
Block(1,1,6,CONCRETE:7)
Block(2,1,6,CONCRETE:7)
Block(3,1,6,CONCRETE:7)
Block(4,1,6,CONCRETE:7)
Block(5,1,6,CONCRETE:7)
Block(6,1,6,CONCRETE:7)
Block(7,1,6,AIR:0)
Block(-8,1,7,CONCRETE:7)
Block(-7,1,7,CONCRETE:7)
Block(-6,1,7,CONCRETE:7)
Block(-5,1,7,CONCRETE:7)
Block(-4,1,7,CONCRETE:7)
Block(-3,1,7,CONCRETE:7)
Block(-2,1,7,CONCRETE:7)
Block(-1,1,7,CONCRETE:7)
Block(0,1,7,CONCRETE:7)
Block(1,1,7,CONCRETE:7)
Block(2,1,7,CONCRETE:7)
Block(3,1,7,CONCRETE:7)
Block(4,1,7,CONCRETE:7)
Block(5,1,7,CONCRETE:7)
Block(6,1,7,CONCRETE:7)
Block(7,1,7,AIR:0)
Block(-8,1,8,CONCRETE:7)
Block(-7,1,8,CONCRETE:7)
Block(-6,1,8,CONCRETE:7)
Block(-5,1,8,CONCRETE:7)
Block(-4,1,8,CONCRETE:7)
Block(-3,1,8,CONCRETE:7)
Block(-2,1,8,CONCRETE:7)
Block(-1,1,8,CONCRETE:7)
Block(0,1,8,CONCRETE:7)
Block(1,1,8,CONCRETE:7)
Block(2,1,8,CONCRETE:7)
Block(3,1,8,CONCRETE:7)
Block(4,1,8,CONCRETE:7)
Block(5,1,8,SMOOTH_STAIRS:3)
Block(6,1,8,CONCRETE:7)
Block(7,1,8,AIR:0)
Block(-8,2,-7,CONCRETE:7)
Block(-7,2,-7,CONCRETE:7)
Block(-6,2,-7,CONCRETE:7)
Block(-5,2,-7,CONCRETE:7)
Block(-4,2,-7,CONCRETE:7)
Block(-3,2,-7,CONCRETE:7)
Block(-2,2,-7,CONCRETE:7)
Block(-1,2,-7,CONCRETE:7)
Block(0,2,-7,CONCRETE:7)
Block(1,2,-7,CONCRETE:7)
Block(2,2,-7,CONCRETE:7)
Block(3,2,-7,CONCRETE:7)
Block(4,2,-7,CONCRETE:7)
Block(5,2,-7,CONCRETE:7)
Block(6,2,-7,CONCRETE:7)
Block(7,2,-7,CONCRETE:7)
Block(-8,2,-6,CONCRETE:7)
Block(-7,2,-6,CONCRETE:7)
Block(-6,2,-6,CONCRETE:7)
Block(-5,2,-6,CONCRETE:7)
Block(-4,2,-6,CONCRETE:7)
Block(-3,2,-6,CONCRETE:7)
Block(-2,2,-6,CONCRETE:7)
Block(-1,2,-6,CONCRETE:7)
Block(0,2,-6,CONCRETE:7)
Block(1,2,-6,CONCRETE:7)
Block(2,2,-6,CONCRETE:7)
Block(3,2,-6,CONCRETE:7)
Block(4,2,-6,CONCRETE:7)
Block(5,2,-6,AIR:0)
Block(6,2,-6,CONCRETE:7)
Block(7,2,-6,AIR:0)
Block(-8,2,-5,CONCRETE:7)
Block(-7,2,-5,CONCRETE:7)
Block(-6,2,-5,CONCRETE:7)
Block(-5,2,-5,CONCRETE:7)
Block(-4,2,-5,CONCRETE:7)
Block(-3,2,-5,CONCRETE:7)
Block(-2,2,-5,CONCRETE:7)
Block(-1,2,-5,CONCRETE:7)
Block(0,2,-5,CONCRETE:7)
Block(1,2,-5,CONCRETE:7)
Block(2,2,-5,CONCRETE:7)
Block(3,2,-5,CONCRETE:7)
Block(4,2,-5,CONCRETE:7)
Block(5,2,-5,AIR:0)
Block(6,2,-5,AIR:0)
Block(7,2,-5,AIR:0)
Block(-8,2,-4,CONCRETE:7)
Block(-7,2,-4,CONCRETE:7)
Block(-6,2,-4,CONCRETE:7)
Block(-5,2,-4,CONCRETE:7)
Block(-4,2,-4,CONCRETE:7)
Block(-3,2,-4,CONCRETE:7)
Block(-2,2,-4,CONCRETE:7)
Block(-1,2,-4,CONCRETE:7)
Block(0,2,-4,CONCRETE:7)
Block(1,2,-4,CONCRETE:7)
Block(2,2,-4,CONCRETE:7)
Block(3,2,-4,CONCRETE:7)
Block(4,2,-4,CONCRETE:7)
Block(5,2,-4,AIR:0)
Block(6,2,-4,AIR:0)
Block(7,2,-4,AIR:0)
Block(-8,2,-3,CONCRETE:7)
Block(-7,2,-3,CONCRETE:7)
Block(-6,2,-3,CONCRETE:7)
Block(-5,2,-3,CONCRETE:7)
Block(-4,2,-3,CONCRETE:7)
Block(-3,2,-3,CONCRETE:7)
Block(-2,2,-3,CONCRETE:7)
Block(-1,2,-3,CONCRETE:7)
Block(0,2,-3,CONCRETE:7)
Block(1,2,-3,CONCRETE:7)
Block(2,2,-3,CONCRETE:7)
Block(3,2,-3,CONCRETE:7)
Block(4,2,-3,CONCRETE:7)
Block(5,2,-3,AIR:0)
Block(6,2,-3,CONCRETE:7)
Block(7,2,-3,AIR:0)
Block(-8,2,-2,CONCRETE:7)
Block(-7,2,-2,CONCRETE:7)
Block(-6,2,-2,CONCRETE:7)
Block(-5,2,-2,CONCRETE:7)
Block(-4,2,-2,CONCRETE:7)
Block(-3,2,-2,CONCRETE:7)
Block(-2,2,-2,CONCRETE:7)
Block(-1,2,-2,CONCRETE:7)
Block(0,2,-2,CONCRETE:7)
Block(1,2,-2,CONCRETE:7)
Block(2,2,-2,CONCRETE:7)
Block(3,2,-2,CONCRETE:7)
Block(4,2,-2,CONCRETE:7)
Block(5,2,-2,AIR:0)
Block(6,2,-2,AIR:0)
Block(7,2,-2,AIR:0)
Block(-8,2,-1,AIR:0)
Block(-7,2,-1,LADDER:4)
Block(-6,2,-1,CONCRETE:7)
Block(-5,2,-1,CONCRETE:7)
Block(-4,2,-1,CONCRETE:7)
Block(-3,2,-1,CONCRETE:7)
Block(-2,2,-1,CONCRETE:7)
Block(-1,2,-1,CONCRETE:7)
Block(0,2,-1,CONCRETE:7)
Block(1,2,-1,CONCRETE:7)
Block(2,2,-1,CONCRETE:7)
Block(3,2,-1,CONCRETE:7)
Block(4,2,-1,CONCRETE:7)
Block(5,2,-1,AIR:0)
Block(6,2,-1,AIR:0)
Block(7,2,-1,AIR:0)
Block(-8,2,0,CONCRETE:7)
Block(-7,2,0,CONCRETE:7)
Block(-6,2,0,CONCRETE:7)
Block(-5,2,0,CONCRETE:7)
Block(-4,2,0,CONCRETE:7)
Block(-3,2,0,CONCRETE:7)
Block(-2,2,0,CONCRETE:7)
Block(-1,2,0,CONCRETE:7)
Block(0,2,0,CONCRETE:7)
Block(1,2,0,CONCRETE:7)
Block(2,2,0,CONCRETE:7)
Block(3,2,0,CONCRETE:7)
Block(4,2,0,CONCRETE:7)
Block(5,2,0,AIR:0)
Block(6,2,0,CONCRETE:7)
Block(7,2,0,AIR:0)
Block(-8,2,1,CONCRETE:7)
Block(-7,2,1,CONCRETE:7)
Block(-6,2,1,CONCRETE:7)
Block(-5,2,1,CONCRETE:7)
Block(-4,2,1,CONCRETE:7)
Block(-3,2,1,CONCRETE:7)
Block(-2,2,1,CONCRETE:7)
Block(-1,2,1,CONCRETE:7)
Block(0,2,1,CONCRETE:7)
Block(1,2,1,CONCRETE:7)
Block(2,2,1,CONCRETE:7)
Block(3,2,1,CONCRETE:7)
Block(4,2,1,CONCRETE:7)
Block(5,2,1,AIR:0)
Block(6,2,1,AIR:0)
Block(7,2,1,AIR:0)
Block(-8,2,2,CONCRETE:7)
Block(-7,2,2,SMOOTH_STAIRS:3)
Block(-6,2,2,SMOOTH_STAIRS:3)
Block(-5,2,2,SMOOTH_STAIRS:3)
Block(-4,2,2,SMOOTH_STAIRS:3)
Block(-3,2,2,SMOOTH_STAIRS:3)
Block(-2,2,2,SMOOTH_STAIRS:3)
Block(-1,2,2,SMOOTH_STAIRS:3)
Block(0,2,2,SMOOTH_STAIRS:3)
Block(1,2,2,SMOOTH_STAIRS:3)
Block(2,2,2,SMOOTH_STAIRS:3)
Block(3,2,2,SMOOTH_STAIRS:3)
Block(4,2,2,SMOOTH_STAIRS:3)
Block(5,2,2,IRON_TRAPDOOR:3)
Block(6,2,2,AIR:0)
Block(7,2,2,AIR:0)
Block(-8,2,3,AIR:0)
Block(-7,2,3,AIR:0)
Block(-6,2,3,AIR:0)
Block(-5,2,3,AIR:0)
Block(-4,2,3,AIR:0)
Block(-3,2,3,AIR:0)
Block(-2,2,3,AIR:0)
Block(-1,2,3,AIR:0)
Block(0,2,3,AIR:0)
Block(1,2,3,AIR:0)
Block(2,2,3,AIR:0)
Block(3,2,3,AIR:0)
Block(4,2,3,AIR:0)
Block(5,2,3,IRON_TRAPDOOR:0)
Block(6,2,3,AIR:0)
Block(7,2,3,AIR:0)
Block(-8,2,4,AIR:0)
Block(-7,2,4,AIR:0)
Block(-6,2,4,AIR:0)
Block(-5,2,4,AIR:0)
Block(-4,2,4,AIR:0)
Block(-3,2,4,AIR:0)
Block(-2,2,4,AIR:0)
Block(-1,2,4,AIR:0)
Block(0,2,4,AIR:0)
Block(1,2,4,AIR:0)
Block(2,2,4,AIR:0)
Block(3,2,4,AIR:0)
Block(4,2,4,AIR:0)
Block(5,2,4,IRON_TRAPDOOR:0)
Block(6,2,4,AIR:0)
Block(7,2,4,AIR:0)
Block(-8,2,5,SMOOTH_STAIRS:2)
Block(-7,2,5,SMOOTH_STAIRS:2)
Block(-6,2,5,SMOOTH_STAIRS:2)
Block(-5,2,5,SMOOTH_STAIRS:2)
Block(-4,2,5,SMOOTH_STAIRS:2)
Block(-3,2,5,SMOOTH_STAIRS:2)
Block(-2,2,5,SMOOTH_STAIRS:2)
Block(-1,2,5,SMOOTH_STAIRS:2)
Block(0,2,5,SMOOTH_STAIRS:2)
Block(1,2,5,SMOOTH_STAIRS:2)
Block(2,2,5,SMOOTH_STAIRS:2)
Block(3,2,5,SMOOTH_STAIRS:2)
Block(4,2,5,SMOOTH_STAIRS:2)
Block(5,2,5,IRON_TRAPDOOR:0)
Block(6,2,5,AIR:0)
Block(7,2,5,AIR:0)
Block(-8,2,6,CONCRETE:7)
Block(-7,2,6,CONCRETE:7)
Block(-6,2,6,CONCRETE:7)
Block(-5,2,6,CONCRETE:7)
Block(-4,2,6,CONCRETE:7)
Block(-3,2,6,CONCRETE:7)
Block(-2,2,6,CONCRETE:7)
Block(-1,2,6,CONCRETE:7)
Block(0,2,6,CONCRETE:7)
Block(1,2,6,CONCRETE:7)
Block(2,2,6,CONCRETE:7)
Block(3,2,6,CONCRETE:7)
Block(4,2,6,CONCRETE:7)
Block(5,2,6,IRON_TRAPDOOR:0)
Block(6,2,6,CONCRETE:7)
Block(7,2,6,AIR:0)
Block(-8,2,7,CONCRETE:7)
Block(-7,2,7,CONCRETE:7)
Block(-6,2,7,CONCRETE:7)
Block(-5,2,7,CONCRETE:7)
Block(-4,2,7,CONCRETE:7)
Block(-3,2,7,CONCRETE:7)
Block(-2,2,7,CONCRETE:7)
Block(-1,2,7,CONCRETE:7)
Block(0,2,7,CONCRETE:7)
Block(1,2,7,CONCRETE:7)
Block(2,2,7,CONCRETE:7)
Block(3,2,7,CONCRETE:7)
Block(4,2,7,CONCRETE:7)
Block(5,2,7,AIR:0)
Block(6,2,7,AIR:0)
Block(7,2,7,AIR:0)
Block(-8,2,8,CONCRETE:7)
Block(-7,2,8,CONCRETE:7)
Block(-6,2,8,CONCRETE:7)
Block(-5,2,8,CONCRETE:7)
Block(-4,2,8,CONCRETE:7)
Block(-3,2,8,CONCRETE:7)
Block(-2,2,8,CONCRETE:7)
Block(-1,2,8,CONCRETE:7)
Block(0,2,8,CONCRETE:7)
Block(1,2,8,CONCRETE:7)
Block(2,2,8,CONCRETE:7)
Block(3,2,8,CONCRETE:7)
Block(4,2,8,CONCRETE:7)
Block(5,2,8,AIR:0)
Block(6,2,8,AIR:0)
Block(7,2,8,AIR:0)
Block(-8,3,-7,CONCRETE:7)
Block(-7,3,-7,CONCRETE:7)
Block(-6,3,-7,CONCRETE:7)
Block(-5,3,-7,CONCRETE:7)
Block(-4,3,-7,CONCRETE:7)
Block(-3,3,-7,CONCRETE:7)
Block(-2,3,-7,CONCRETE:7)
Block(-1,3,-7,CONCRETE:7)
Block(0,3,-7,CONCRETE:7)
Block(1,3,-7,CONCRETE:7)
Block(2,3,-7,CONCRETE:7)
Block(3,3,-7,CONCRETE:7)
Block(4,3,-7,CONCRETE:7)
Block(5,3,-7,CONCRETE:7)
Block(6,3,-7,CONCRETE:7)
Block(7,3,-7,CONCRETE:7)
Block(-8,3,-6,CONCRETE:7)
Block(-7,3,-6,CONCRETE:7)
Block(-6,3,-6,CONCRETE:7)
Block(-5,3,-6,CONCRETE:7)
Block(-4,3,-6,CONCRETE:7)
Block(-3,3,-6,CONCRETE:7)
Block(-2,3,-6,CONCRETE:7)
Block(-1,3,-6,CONCRETE:7)
Block(0,3,-6,CONCRETE:7)
Block(1,3,-6,CONCRETE:7)
Block(2,3,-6,CONCRETE:7)
Block(3,3,-6,CONCRETE:7)
Block(4,3,-6,CONCRETE:7)
Block(5,3,-6,AIR:0)
Block(6,3,-6,CONCRETE:7)
Block(7,3,-6,STEP:8)
Block(-8,3,-5,CONCRETE:7)
Block(-7,3,-5,CONCRETE:7)
Block(-6,3,-5,CONCRETE:7)
Block(-5,3,-5,CONCRETE:7)
Block(-4,3,-5,CONCRETE:7)
Block(-3,3,-5,CONCRETE:7)
Block(-2,3,-5,CONCRETE:7)
Block(-1,3,-5,CONCRETE:7)
Block(0,3,-5,CONCRETE:7)
Block(1,3,-5,CONCRETE:7)
Block(2,3,-5,CONCRETE:7)
Block(3,3,-5,CONCRETE:7)
Block(4,3,-5,CONCRETE:7)
Block(5,3,-5,AIR:0)
Block(6,3,-5,AIR:0)
Block(7,3,-5,AIR:0)
Block(-8,3,-4,CONCRETE:7)
Block(-7,3,-4,CONCRETE:7)
Block(-6,3,-4,CONCRETE:7)
Block(-5,3,-4,CONCRETE:7)
Block(-4,3,-4,CONCRETE:7)
Block(-3,3,-4,CONCRETE:7)
Block(-2,3,-4,CONCRETE:7)
Block(-1,3,-4,CONCRETE:7)
Block(0,3,-4,CONCRETE:7)
Block(1,3,-4,CONCRETE:7)
Block(2,3,-4,CONCRETE:7)
Block(3,3,-4,CONCRETE:7)
Block(4,3,-4,CONCRETE:7)
Block(5,3,-4,AIR:0)
Block(6,3,-4,AIR:0)
Block(7,3,-4,AIR:0)
Block(-8,3,-3,CONCRETE:7)
Block(-7,3,-3,CONCRETE:7)
Block(-6,3,-3,CONCRETE:7)
Block(-5,3,-3,CONCRETE:7)
Block(-4,3,-3,CONCRETE:7)
Block(-3,3,-3,CONCRETE:7)
Block(-2,3,-3,CONCRETE:7)
Block(-1,3,-3,CONCRETE:7)
Block(0,3,-3,CONCRETE:7)
Block(1,3,-3,CONCRETE:7)
Block(2,3,-3,CONCRETE:7)
Block(3,3,-3,CONCRETE:7)
Block(4,3,-3,CONCRETE:7)
Block(5,3,-3,AIR:0)
Block(6,3,-3,CONCRETE:7)
Block(7,3,-3,STEP:8)
Block(-8,3,-2,CONCRETE:7)
Block(-7,3,-2,CONCRETE:7)
Block(-6,3,-2,CONCRETE:7)
Block(-5,3,-2,CONCRETE:7)
Block(-4,3,-2,CONCRETE:7)
Block(-3,3,-2,CONCRETE:7)
Block(-2,3,-2,CONCRETE:7)
Block(-1,3,-2,CONCRETE:7)
Block(0,3,-2,CONCRETE:7)
Block(1,3,-2,CONCRETE:7)
Block(2,3,-2,CONCRETE:7)
Block(3,3,-2,CONCRETE:7)
Block(4,3,-2,CONCRETE:7)
Block(5,3,-2,AIR:0)
Block(6,3,-2,AIR:0)
Block(7,3,-2,AIR:0)
Block(-8,3,-1,AIR:0)
Block(-7,3,-1,LADDER:4)
Block(-6,3,-1,CONCRETE:7)
Block(-5,3,-1,CONCRETE:7)
Block(-4,3,-1,CONCRETE:7)
Block(-3,3,-1,CONCRETE:7)
Block(-2,3,-1,CONCRETE:7)
Block(-1,3,-1,CONCRETE:7)
Block(0,3,-1,CONCRETE:7)
Block(1,3,-1,CONCRETE:7)
Block(2,3,-1,CONCRETE:7)
Block(3,3,-1,CONCRETE:7)
Block(4,3,-1,CONCRETE:7)
Block(5,3,-1,AIR:0)
Block(6,3,-1,AIR:0)
Block(7,3,-1,AIR:0)
Block(-8,3,0,CONCRETE:7)
Block(-7,3,0,CONCRETE:7)
Block(-6,3,0,CONCRETE:7)
Block(-5,3,0,CONCRETE:7)
Block(-4,3,0,CONCRETE:7)
Block(-3,3,0,CONCRETE:7)
Block(-2,3,0,CONCRETE:7)
Block(-1,3,0,CONCRETE:7)
Block(0,3,0,CONCRETE:7)
Block(1,3,0,CONCRETE:7)
Block(2,3,0,CONCRETE:7)
Block(3,3,0,CONCRETE:7)
Block(4,3,0,CONCRETE:7)
Block(5,3,0,AIR:0)
Block(6,3,0,CONCRETE:7)
Block(7,3,0,STEP:8)
Block(-8,3,1,CONCRETE:7)
Block(-7,3,1,CONCRETE:7)
Block(-6,3,1,CONCRETE:7)
Block(-5,3,1,CONCRETE:7)
Block(-4,3,1,CONCRETE:7)
Block(-3,3,1,CONCRETE:7)
Block(-2,3,1,CONCRETE:7)
Block(-1,3,1,CONCRETE:7)
Block(0,3,1,CONCRETE:7)
Block(1,3,1,CONCRETE:7)
Block(2,3,1,CONCRETE:7)
Block(3,3,1,CONCRETE:7)
Block(4,3,1,CONCRETE:7)
Block(5,3,1,AIR:0)
Block(6,3,1,AIR:0)
Block(7,3,1,AIR:0)
Block(-8,3,2,CONCRETE:7)
Block(-7,3,2,AIR:0)
Block(-6,3,2,AIR:0)
Block(-5,3,2,AIR:0)
Block(-4,3,2,AIR:0)
Block(-3,3,2,AIR:0)
Block(-2,3,2,AIR:0)
Block(-1,3,2,AIR:0)
Block(0,3,2,STEP:8)
Block(1,3,2,STEP:8)
Block(2,3,2,STEP:8)
Block(3,3,2,STEP:8)
Block(4,3,2,STEP:8)
Block(5,3,2,AIR:0)
Block(6,3,2,AIR:0)
Block(7,3,2,AIR:0)
Block(-8,3,3,AIR:0)
Block(-7,3,3,AIR:0)
Block(-6,3,3,AIR:0)
Block(-5,3,3,AIR:0)
Block(-4,3,3,AIR:0)
Block(-3,3,3,AIR:0)
Block(-2,3,3,AIR:0)
Block(-1,3,3,AIR:0)
Block(0,3,3,STEP:8)
Block(1,3,3,STEP:8)
Block(2,3,3,STEP:8)
Block(3,3,3,STEP:8)
Block(4,3,3,STEP:8)
Block(5,3,3,AIR:0)
Block(6,3,3,AIR:0)
Block(7,3,3,AIR:0)
Block(-8,3,4,AIR:0)
Block(-7,3,4,AIR:0)
Block(-6,3,4,AIR:0)
Block(-5,3,4,AIR:0)
Block(-4,3,4,AIR:0)
Block(-3,3,4,AIR:0)
Block(-2,3,4,AIR:0)
Block(-1,3,4,AIR:0)
Block(0,3,4,STEP:8)
Block(1,3,4,STEP:8)
Block(2,3,4,STEP:8)
Block(3,3,4,STEP:8)
Block(4,3,4,STEP:8)
Block(5,3,4,AIR:0)
Block(6,3,4,AIR:0)
Block(7,3,4,AIR:0)
Block(-8,3,5,AIR:0)
Block(-7,3,5,AIR:0)
Block(-6,3,5,AIR:0)
Block(-5,3,5,AIR:0)
Block(-4,3,5,AIR:0)
Block(-3,3,5,AIR:0)
Block(-2,3,5,AIR:0)
Block(-1,3,5,AIR:0)
Block(0,3,5,STEP:8)
Block(1,3,5,STEP:8)
Block(2,3,5,STEP:8)
Block(3,3,5,STEP:8)
Block(4,3,5,STEP:8)
Block(5,3,5,AIR:0)
Block(6,3,5,AIR:0)
Block(7,3,5,AIR:0)
Block(-8,3,6,CONCRETE:7)
Block(-7,3,6,CONCRETE:7)
Block(-6,3,6,CONCRETE:7)
Block(-5,3,6,CONCRETE:7)
Block(-4,3,6,CONCRETE:7)
Block(-3,3,6,CONCRETE:7)
Block(-2,3,6,CONCRETE:7)
Block(-1,3,6,CONCRETE:7)
Block(0,3,6,CONCRETE:7)
Block(1,3,6,CONCRETE:7)
Block(2,3,6,CONCRETE:7)
Block(3,3,6,CONCRETE:7)
Block(4,3,6,CONCRETE:7)
Block(5,3,6,AIR:0)
Block(6,3,6,CONCRETE:7)
Block(7,3,6,STEP:8)
Block(-8,3,7,CONCRETE:7)
Block(-7,3,7,CONCRETE:7)
Block(-6,3,7,CONCRETE:7)
Block(-5,3,7,CONCRETE:7)
Block(-4,3,7,CONCRETE:7)
Block(-3,3,7,CONCRETE:7)
Block(-2,3,7,CONCRETE:7)
Block(-1,3,7,CONCRETE:7)
Block(0,3,7,CONCRETE:7)
Block(1,3,7,CONCRETE:7)
Block(2,3,7,CONCRETE:7)
Block(3,3,7,CONCRETE:7)
Block(4,3,7,CONCRETE:7)
Block(5,3,7,AIR:0)
Block(6,3,7,AIR:0)
Block(7,3,7,AIR:0)
Block(-8,3,8,SMOOTH_STAIRS:3)
Block(-7,3,8,SMOOTH_STAIRS:3)
Block(-6,3,8,CONCRETE:7)
Block(-5,3,8,CONCRETE:7)
Block(-4,3,8,CONCRETE:7)
Block(-3,3,8,CONCRETE:7)
Block(-2,3,8,CONCRETE:7)
Block(-1,3,8,CONCRETE:7)
Block(0,3,8,CONCRETE:7)
Block(1,3,8,CONCRETE:7)
Block(2,3,8,CONCRETE:7)
Block(3,3,8,CONCRETE:7)
Block(4,3,8,CONCRETE:7)
Block(5,3,8,AIR:0)
Block(6,3,8,AIR:0)
Block(7,3,8,AIR:0)
Block(-8,4,-7,CONCRETE:7)
Block(-7,4,-7,CONCRETE:7)
Block(-6,4,-7,CONCRETE:7)
Block(-5,4,-7,CONCRETE:7)
Block(-4,4,-7,CONCRETE:7)
Block(-3,4,-7,CONCRETE:7)
Block(-2,4,-7,CONCRETE:7)
Block(-1,4,-7,CONCRETE:7)
Block(0,4,-7,CONCRETE:7)
Block(1,4,-7,CONCRETE:7)
Block(2,4,-7,CONCRETE:7)
Block(3,4,-7,CONCRETE:7)
Block(4,4,-7,CONCRETE:7)
Block(5,4,-7,CONCRETE:7)
Block(6,4,-7,CONCRETE:7)
Block(7,4,-7,CONCRETE:7)
Block(-8,4,-6,CONCRETE:7)
Block(-7,4,-6,CONCRETE:7)
Block(-6,4,-6,CONCRETE:4)
Block(-5,4,-6,CONCRETE:4)
Block(-4,4,-6,CONCRETE:4)
Block(-3,4,-6,CONCRETE:4)
Block(-2,4,-6,CONCRETE:4)
Block(0,4,-6,CONCRETE:4)
Block(1,4,-6,CONCRETE:4)
Block(2,4,-6,CONCRETE:4)
Block(3,4,-6,CONCRETE:4)
Block(4,4,-6,CONCRETE:4)
Block(5,4,-6,CONCRETE:4)
Block(6,4,-6,CONCRETE:7)
Block(7,4,-6,CONCRETE:7)
Block(-8,4,-5,CONCRETE:7)
Block(-7,4,-5,CONCRETE:7)
Block(-6,4,-5,CONCRETE:7)
Block(-5,4,-5,CONCRETE:7)
Block(-4,4,-5,CONCRETE:7)
Block(-3,4,-5,CONCRETE:7)
Block(-2,4,-5,CONCRETE:7)
Block(0,4,-5,SMOOTH_STAIRS:0)
Block(1,4,-5,STEP:0)
Block(2,4,-5,SMOOTH_STAIRS:1)
Block(3,4,-5,CONCRETE:4)
Block(4,4,-5,STEP:3)
Block(5,4,-5,CONCRETE:7)
Block(6,4,-5,CONCRETE:7)
Block(7,4,-5,CONCRETE:7)
Block(-8,4,-4,CONCRETE:7)
Block(-7,4,-4,CONCRETE:7)
Block(-6,4,-4,CONCRETE:7)
Block(-5,4,-4,CONCRETE:7)
Block(-4,4,-4,CONCRETE:7)
Block(-3,4,-4,CONCRETE:7)
Block(-2,4,-4,CONCRETE:7)
Block(0,4,-4,SMOOTH_STAIRS:0)
Block(1,4,-4,STEP:5)
Block(2,4,-4,SMOOTH_STAIRS:1)
Block(3,4,-4,CONCRETE:4)
Block(4,4,-4,STEP:3)
Block(5,4,-4,CONCRETE:7)
Block(6,4,-4,CONCRETE:7)
Block(7,4,-4,CONCRETE:7)
Block(-8,4,-3,CONCRETE:7)
Block(-7,4,-3,CONCRETE:7)
Block(-6,4,-3,CONCRETE:7)
Block(-5,4,-3,CONCRETE:7)
Block(-4,4,-3,CONCRETE:7)
Block(-3,4,-3,CONCRETE:7)
Block(-2,4,-3,CONCRETE:7)
Block(0,4,-3,SMOOTH_STAIRS:0)
Block(1,4,-3,STEP:0)
Block(2,4,-3,SMOOTH_STAIRS:1)
Block(3,4,-3,CONCRETE:4)
Block(4,4,-3,STEP:3)
Block(5,4,-3,CONCRETE:7)
Block(6,4,-3,CONCRETE:7)
Block(7,4,-3,CONCRETE:7)
Block(-8,4,-2,CONCRETE:7)
Block(-7,4,-2,CONCRETE:7)
Block(-6,4,-2,CONCRETE:7)
Block(-5,4,-2,CONCRETE:7)
Block(-4,4,-2,CONCRETE:7)
Block(-3,4,-2,CONCRETE:7)
Block(-2,4,-2,CONCRETE:7)
Block(0,4,-2,SMOOTH_STAIRS:0)
Block(1,4,-2,STEP:5)
Block(2,4,-2,SMOOTH_STAIRS:1)
Block(3,4,-2,CONCRETE:4)
Block(4,4,-2,STEP:3)
Block(5,4,-2,CONCRETE:7)
Block(6,4,-2,CONCRETE:7)
Block(7,4,-2,CONCRETE:7)
Block(-8,4,-1,CONCRETE:7)
Block(-7,4,-1,LADDER:4)
Block(-6,4,-1,CONCRETE:7)
Block(-5,4,-1,CONCRETE:7)
Block(-4,4,-1,CONCRETE:7)
Block(-3,4,-1,CONCRETE:7)
Block(-2,4,-1,CONCRETE:7)
Block(0,4,-1,SMOOTH_STAIRS:0)
Block(1,4,-1,STEP:0)
Block(2,4,-1,SMOOTH_STAIRS:1)
Block(3,4,-1,CONCRETE:4)
Block(4,4,-1,SMOOTH_STAIRS:1)
Block(5,4,-1,CONCRETE:7)
Block(6,4,-1,CONCRETE:7)
Block(7,4,-1,CONCRETE:7)
Block(-8,4,0,CONCRETE:7)
Block(-7,4,0,CONCRETE:7)
Block(-6,4,0,CONCRETE:7)
Block(-5,4,0,CONCRETE:7)
Block(-4,4,0,CONCRETE:7)
Block(-3,4,0,CONCRETE:7)
Block(-2,4,0,CONCRETE:7)
Block(0,4,0,SMOOTH_STAIRS:0)
Block(1,4,0,STEP:5)
Block(2,4,0,SMOOTH_STAIRS:1)
Block(3,4,0,CONCRETE:4)
Block(4,4,0,STEP:3)
Block(5,4,0,CONCRETE:7)
Block(6,4,0,CONCRETE:7)
Block(7,4,0,CONCRETE:7)
Block(-8,4,1,CONCRETE:7)
Block(-7,4,1,CONCRETE:7)
Block(-6,4,1,CONCRETE:7)
Block(-5,4,1,CONCRETE:7)
Block(-4,4,1,CONCRETE:7)
Block(-3,4,1,CONCRETE:7)
Block(-2,4,1,CONCRETE:7)
Block(0,4,1,SMOOTH_STAIRS:0)
Block(1,4,1,STEP:0)
Block(2,4,1,SMOOTH_STAIRS:1)
Block(3,4,1,CONCRETE:4)
Block(4,4,1,STEP:3)
Block(5,4,1,CONCRETE:7)
Block(6,4,1,CONCRETE:7)
Block(7,4,1,CONCRETE:7)
Block(-8,4,2,CONCRETE:7)
Block(-7,4,2,STEP:8)
Block(-6,4,2,STEP:8)
Block(-5,4,2,CONCRETE:7)
Block(-4,4,2,STEP:8)
Block(-3,4,2,STEP:8)
Block(-2,4,2,CONCRETE:7)
Block(0,4,2,SMOOTH_STAIRS:0)
Block(1,4,2,STEP:5)
Block(2,4,2,SMOOTH_STAIRS:1)
Block(3,4,2,CONCRETE:4)
Block(4,4,2,STEP:3)
Block(5,4,2,CONCRETE:7)
Block(6,4,2,CONCRETE:7)
Block(7,4,2,CONCRETE:7)
Block(-8,4,3,CONCRETE:7)
Block(-7,4,3,STEP:8)
Block(-6,4,3,STEP:8)
Block(-5,4,3,CONCRETE:7)
Block(-4,4,3,STEP:8)
Block(-3,4,3,STEP:8)
Block(-2,4,3,CONCRETE:7)
Block(0,4,3,SMOOTH_STAIRS:0)
Block(1,4,3,STEP:0)
Block(2,4,3,SMOOTH_STAIRS:1)
Block(3,4,3,CONCRETE:4)
Block(4,4,3,STEP:3)
Block(5,4,3,CONCRETE:7)
Block(6,4,3,CONCRETE:7)
Block(7,4,3,CONCRETE:7)
Block(-8,4,4,CONCRETE:7)
Block(-7,4,4,STEP:8)
Block(-6,4,4,STEP:8)
Block(-5,4,4,CONCRETE:7)
Block(-4,4,4,STEP:8)
Block(-3,4,4,STEP:8)
Block(-2,4,4,CONCRETE:7)
Block(0,4,4,SMOOTH_STAIRS:0)
Block(1,4,4,STEP:5)
Block(2,4,4,SMOOTH_STAIRS:1)
Block(3,4,4,CONCRETE:4)
Block(4,4,4,STEP:3)
Block(5,4,4,CONCRETE:7)
Block(6,4,4,CONCRETE:7)
Block(7,4,4,CONCRETE:7)
Block(-8,4,5,CONCRETE:7)
Block(-7,4,5,STEP:8)
Block(-6,4,5,STEP:8)
Block(-5,4,5,CONCRETE:7)
Block(-4,4,5,STEP:8)
Block(-3,4,5,STEP:8)
Block(-2,4,5,CONCRETE:7)
Block(0,4,5,SMOOTH_STAIRS:0)
Block(1,4,5,STEP:0)
Block(2,4,5,SMOOTH_STAIRS:1)
Block(3,4,5,CONCRETE:4)
Block(4,4,5,SMOOTH_STAIRS:1)
Block(5,4,5,CONCRETE:7)
Block(6,4,5,CONCRETE:7)
Block(7,4,5,CONCRETE:7)
Block(-8,4,6,CONCRETE:7)
Block(-7,4,6,CONCRETE:7)
Block(-6,4,6,CONCRETE:7)
Block(-5,4,6,CONCRETE:7)
Block(-4,4,6,CONCRETE:7)
Block(-3,4,6,CONCRETE:7)
Block(-2,4,6,CONCRETE:7)
Block(0,4,6,SMOOTH_STAIRS:0)
Block(1,4,6,STEP:5)
Block(2,4,6,SMOOTH_STAIRS:1)
Block(3,4,6,CONCRETE:4)
Block(4,4,6,STEP:3)
Block(5,4,6,CONCRETE:7)
Block(6,4,6,CONCRETE:7)
Block(7,4,6,CONCRETE:7)
Block(-8,4,7,CONCRETE:7)
Block(-7,4,7,CONCRETE:7)
Block(-6,4,7,CONCRETE:7)
Block(-5,4,7,CONCRETE:7)
Block(-4,4,7,CONCRETE:7)
Block(-3,4,7,CONCRETE:7)
Block(-2,4,7,CONCRETE:7)
Block(0,4,7,SMOOTH_STAIRS:0)
Block(1,4,7,STEP:0)
Block(2,4,7,SMOOTH_STAIRS:1)
Block(3,4,7,CONCRETE:4)
Block(4,4,7,STEP:3)
Block(5,4,7,CONCRETE:7)
Block(6,4,7,CONCRETE:7)
Block(7,4,7,CONCRETE:7)
Block(-8,4,8,COBBLE_WALL:0)
Block(-7,4,8,COBBLE_WALL:0)
Block(-6,4,8,CONCRETE:7)
Block(-5,4,8,CONCRETE:7)
Block(-4,4,8,CONCRETE:7)
Block(-3,4,8,CONCRETE:7)
Block(-2,4,8,CONCRETE:7)
Block(0,4,8,SMOOTH_STAIRS:0)
Block(1,4,8,STEP:5)
Block(2,4,8,SMOOTH_STAIRS:1)
Block(3,4,8,CONCRETE:4)
Block(4,4,8,STEP:3)
Block(5,4,8,CONCRETE:7)
Block(6,4,8,CONCRETE:7)
Block(7,4,8,CONCRETE:7)
Block(-8,5,-7,CONCRETE:7)
Block(-7,5,-7,CONCRETE:7)
Block(-6,5,-7,CONCRETE:7)
Block(-5,5,-7,CONCRETE:7)
Block(-4,5,-7,CONCRETE:7)
Block(-3,5,-7,CONCRETE:7)
Block(-2,5,-7,CONCRETE:7)
Block(-1,5,-7,IRON_FENCE:0)
Block(0,5,-7,IRON_FENCE:0)
Block(1,5,-7,CONCRETE:7)
Block(2,5,-7,CONCRETE:7)
Block(3,5,-7,CONCRETE:7)
Block(4,5,-7,CONCRETE:7)
Block(5,5,-7,CONCRETE:7)
Block(6,5,-7,CONCRETE:7)
Block(7,5,-7,CONCRETE:7)
Block(-8,5,-6,CONCRETE:7)
Block(-7,5,-6,CONCRETE:7)
Block(-6,5,-6,CONCRETE:7)
Block(-5,5,-6,CONCRETE:7)
Block(-4,5,-6,CONCRETE:7)
Block(-3,5,-6,CONCRETE:7)
Block(-2,5,-6,CONCRETE:7)
Block(0,5,-6,AIR:0)
Block(1,5,-6,AIR:0)
Block(2,5,-6,AIR:0)
Block(3,5,-6,AIR:0)
Block(4,5,-6,AIR:0)
Block(5,5,-6,STEP:0)
Block(6,5,-6,CONCRETE:7)
Block(7,5,-6,STEP:0)
Block(-8,5,-5,CONCRETE:7)
Block(-7,5,-5,CONCRETE:7)
Block(-6,5,-5,CONCRETE:7)
Block(-5,5,-5,CONCRETE:7)
Block(-4,5,-5,CONCRETE:7)
Block(-3,5,-5,CONCRETE:7)
Block(-2,5,-5,CONCRETE:7)
Block(0,5,-5,AIR:0)
Block(1,5,-5,AIR:0)
Block(2,5,-5,AIR:0)
Block(3,5,-5,AIR:0)
Block(4,5,-5,AIR:0)
Block(5,5,-5,AIR:0)
Block(6,5,-5,CONCRETE:7)
Block(7,5,-5,STEP:0)
Block(-8,5,-4,CONCRETE:7)
Block(-7,5,-4,CONCRETE:7)
Block(-6,5,-4,CONCRETE:7)
Block(-5,5,-4,CONCRETE:7)
Block(-4,5,-4,CONCRETE:7)
Block(-3,5,-4,CONCRETE:7)
Block(-2,5,-4,CONCRETE:7)
Block(0,5,-4,AIR:0)
Block(1,5,-4,AIR:0)
Block(2,5,-4,AIR:0)
Block(3,5,-4,AIR:0)
Block(4,5,-4,AIR:0)
Block(5,5,-4,AIR:0)
Block(6,5,-4,CONCRETE:7)
Block(7,5,-4,STEP:0)
Block(-8,5,-3,CONCRETE:7)
Block(-7,5,-3,CONCRETE:7)
Block(-6,5,-3,CONCRETE:7)
Block(-5,5,-3,CONCRETE:7)
Block(-4,5,-3,CONCRETE:7)
Block(-3,5,-3,CONCRETE:7)
Block(-2,5,-3,CONCRETE:7)
Block(0,5,-3,AIR:0)
Block(1,5,-3,AIR:0)
Block(2,5,-3,AIR:0)
Block(3,5,-3,AIR:0)
Block(4,5,-3,AIR:0)
Block(5,5,-3,AIR:0)
Block(6,5,-3,CONCRETE:7)
Block(7,5,-3,STEP:0)
Block(-8,5,-2,CONCRETE:7)
Block(-7,5,-2,CONCRETE:7)
Block(-6,5,-2,CONCRETE:7)
Block(-5,5,-2,CONCRETE:7)
Block(-4,5,-2,CONCRETE:7)
Block(-3,5,-2,CONCRETE:7)
Block(-2,5,-2,CONCRETE:7)
Block(0,5,-2,AIR:0)
Block(1,5,-2,AIR:0)
Block(2,5,-2,AIR:0)
Block(3,5,-2,AIR:0)
Block(4,5,-2,AIR:0)
Block(5,5,-2,STEP:0)
Block(6,5,-2,CONCRETE:7)
Block(7,5,-2,STEP:0)
Block(-8,5,-1,CONCRETE:7)
Block(-7,5,-1,LADDER:4)
Block(-6,5,-1,CONCRETE:7)
Block(-5,5,-1,CONCRETE:7)
Block(-4,5,-1,CONCRETE:7)
Block(-3,5,-1,CONCRETE:7)
Block(-2,5,-1,CONCRETE:7)
Block(0,5,-1,AIR:0)
Block(1,5,-1,AIR:0)
Block(2,5,-1,AIR:0)
Block(3,5,-1,AIR:0)
Block(4,5,-1,AIR:0)
Block(5,5,-1,SMOOTH_STAIRS:0)
Block(6,5,-1,CONCRETE:7)
Block(7,5,-1,STEP:0)
Block(-8,5,0,CONCRETE:7)
Block(-7,5,0,CONCRETE:7)
Block(-6,5,0,CONCRETE:7)
Block(-5,5,0,CONCRETE:7)
Block(-4,5,0,CONCRETE:7)
Block(-3,5,0,CONCRETE:7)
Block(-2,5,0,CONCRETE:7)
Block(0,5,0,AIR:0)
Block(1,5,0,AIR:0)
Block(2,5,0,AIR:0)
Block(3,5,0,AIR:0)
Block(4,5,0,AIR:0)
Block(5,5,0,STEP:0)
Block(6,5,0,CONCRETE:7)
Block(7,5,0,STEP:0)
Block(-8,5,1,CONCRETE:7)
Block(-7,5,1,CONCRETE:7)
Block(-6,5,1,CONCRETE:7)
Block(-5,5,1,CONCRETE:7)
Block(-4,5,1,CONCRETE:7)
Block(-3,5,1,CONCRETE:7)
Block(-2,5,1,CONCRETE:7)
Block(0,5,1,AIR:0)
Block(1,5,1,AIR:0)
Block(2,5,1,AIR:0)
Block(3,5,1,AIR:0)
Block(4,5,1,AIR:0)
Block(5,5,1,AIR:0)
Block(6,5,1,CONCRETE:7)
Block(7,5,1,STEP:0)
Block(-8,5,2,CONCRETE:7)
Block(-7,5,2,CONCRETE:7)
Block(-6,5,2,CONCRETE:7)
Block(-5,5,2,CONCRETE:7)
Block(-4,5,2,CONCRETE:7)
Block(-3,5,2,CONCRETE:7)
Block(-2,5,2,SMOOTH_STAIRS:1)
Block(0,5,2,AIR:0)
Block(1,5,2,AIR:0)
Block(2,5,2,AIR:0)
Block(3,5,2,AIR:0)
Block(4,5,2,AIR:0)
Block(5,5,2,AIR:0)
Block(6,5,2,CONCRETE:7)
Block(7,5,2,STEP:0)
Block(-8,5,3,CONCRETE:7)
Block(-7,5,3,CONCRETE:7)
Block(-6,5,3,CONCRETE:7)
Block(-5,5,3,CONCRETE:7)
Block(-4,5,3,CONCRETE:7)
Block(-3,5,3,CONCRETE:7)
Block(-2,5,3,CONCRETE:7)
Block(0,5,3,AIR:0)
Block(1,5,3,AIR:0)
Block(2,5,3,AIR:0)
Block(3,5,3,AIR:0)
Block(4,5,3,AIR:0)
Block(5,5,3,AIR:0)
Block(6,5,3,CONCRETE:7)
Block(7,5,3,STEP:0)
Block(-8,5,4,CONCRETE:7)
Block(-7,5,4,CONCRETE:7)
Block(-6,5,4,CONCRETE:7)
Block(-5,5,4,CONCRETE:7)
Block(-4,5,4,CONCRETE:7)
Block(-3,5,4,CONCRETE:7)
Block(-2,5,4,CONCRETE:7)
Block(0,5,4,AIR:0)
Block(1,5,4,AIR:0)
Block(2,5,4,AIR:0)
Block(3,5,4,AIR:0)
Block(4,5,4,AIR:0)
Block(5,5,4,STEP:0)
Block(6,5,4,CONCRETE:7)
Block(7,5,4,STEP:0)
Block(-8,5,5,CONCRETE:7)
Block(-7,5,5,CONCRETE:7)
Block(-6,5,5,CONCRETE:7)
Block(-5,5,5,CONCRETE:7)
Block(-4,5,5,CONCRETE:7)
Block(-3,5,5,CONCRETE:7)
Block(-2,5,5,CONCRETE:7)
Block(0,5,5,AIR:0)
Block(1,5,5,AIR:0)
Block(2,5,5,AIR:0)
Block(3,5,5,AIR:0)
Block(4,5,5,AIR:0)
Block(5,5,5,SMOOTH_STAIRS:0)
Block(6,5,5,CONCRETE:7)
Block(7,5,5,STEP:0)
Block(-8,5,6,CONCRETE:7)
Block(-7,5,6,CONCRETE:7)
Block(-6,5,6,CONCRETE:7)
Block(-5,5,6,CONCRETE:7)
Block(-4,5,6,CONCRETE:7)
Block(-3,5,6,CONCRETE:7)
Block(-2,5,6,CONCRETE:7)
Block(0,5,6,AIR:0)
Block(1,5,6,AIR:0)
Block(2,5,6,AIR:0)
Block(3,5,6,AIR:0)
Block(4,5,6,AIR:0)
Block(5,5,6,STEP:0)
Block(6,5,6,CONCRETE:7)
Block(7,5,6,STEP:0)
Block(-8,5,7,CONCRETE:7)
Block(-7,5,7,CONCRETE:7)
Block(-6,5,7,CONCRETE:7)
Block(-5,5,7,CONCRETE:7)
Block(-4,5,7,CONCRETE:7)
Block(-3,5,7,CONCRETE:7)
Block(-2,5,7,CONCRETE:7)
Block(0,5,7,AIR:0)
Block(1,5,7,AIR:0)
Block(2,5,7,AIR:0)
Block(3,5,7,AIR:0)
Block(4,5,7,AIR:0)
Block(5,5,7,AIR:0)
Block(6,5,7,CONCRETE:7)
Block(7,5,7,STEP:0)
Block(-8,5,8,SMOOTH_STAIRS:7)
Block(-7,5,8,SMOOTH_STAIRS:7)
Block(-6,5,8,CONCRETE:7)
Block(-5,5,8,CONCRETE:7)
Block(-4,5,8,CONCRETE:7)
Block(-3,5,8,CONCRETE:7)
Block(-2,5,8,CONCRETE:7)
Block(0,5,8,AIR:0)
Block(1,5,8,AIR:0)
Block(2,5,8,AIR:0)
Block(3,5,8,AIR:0)
Block(4,5,8,AIR:0)
Block(5,5,8,AIR:0)
Block(6,5,8,CONCRETE:7)
Block(7,5,8,STEP:0)
Block(-8,6,-7,CONCRETE:7)
Block(-7,6,-7,CONCRETE:7)
Block(-6,6,-7,CONCRETE:7)
Block(-5,6,-7,CONCRETE:7)
Block(-4,6,-7,CONCRETE:7)
Block(-3,6,-7,CONCRETE:7)
Block(-2,6,-7,CONCRETE:7)
Block(-1,6,-7,CONCRETE:7)
Block(0,6,-7,CONCRETE:7)
Block(1,6,-7,CONCRETE:7)
Block(2,6,-7,CONCRETE:7)
Block(3,6,-7,CONCRETE:7)
Block(4,6,-7,CONCRETE:7)
Block(5,6,-7,CONCRETE:7)
Block(6,6,-7,CONCRETE:7)
Block(7,6,-7,CONCRETE:7)
Block(-8,6,-6,CONCRETE:7)
Block(-7,6,-6,CONCRETE:7)
Block(-6,6,-6,CONCRETE:7)
Block(-5,6,-6,GLOWSTONE:0)
Block(-4,6,-6,CONCRETE:7)
Block(-3,6,-6,AIR:0)
Block(-2,6,-6,IRON_FENCE:0)
Block(-1,6,-6,AIR:0)
Block(0,6,-6,AIR:0)
Block(1,6,-6,AIR:0)
Block(2,6,-6,AIR:0)
Block(3,6,-6,AIR:0)
Block(4,6,-6,GLOWSTONE:0)
Block(5,6,-6,AIR:0)
Block(6,6,-6,IRON_FENCE:0)
Block(7,6,-6,AIR:0)
Block(-8,6,-5,CONCRETE:7)
Block(-7,6,-5,CONCRETE:7)
Block(-6,6,-5,CONCRETE:7)
Block(-5,6,-5,CONCRETE:7)
Block(-4,6,-5,CONCRETE:7)
Block(-3,6,-5,AIR:0)
Block(-2,6,-5,IRON_FENCE:0)
Block(-1,6,-5,AIR:0)
Block(0,6,-5,AIR:0)
Block(1,6,-5,AIR:0)
Block(2,6,-5,AIR:0)
Block(3,6,-5,AIR:0)
Block(4,6,-5,AIR:0)
Block(5,6,-5,AIR:0)
Block(6,6,-5,IRON_FENCE:0)
Block(7,6,-5,AIR:0)
Block(-8,6,-4,CONCRETE:7)
Block(-7,6,-4,CONCRETE:7)
Block(-6,6,-4,CONCRETE:7)
Block(-5,6,-4,CONCRETE:7)
Block(-4,6,-4,CONCRETE:7)
Block(-3,6,-4,AIR:0)
Block(-2,6,-4,IRON_FENCE:0)
Block(-1,6,-4,AIR:0)
Block(0,6,-4,AIR:0)
Block(1,6,-4,AIR:0)
Block(2,6,-4,AIR:0)
Block(3,6,-4,AIR:0)
Block(4,6,-4,AIR:0)
Block(5,6,-4,AIR:0)
Block(6,6,-4,IRON_FENCE:0)
Block(7,6,-4,AIR:0)
Block(-8,6,-3,CONCRETE:7)
Block(-7,6,-3,CONCRETE:7)
Block(-6,6,-3,CONCRETE:7)
Block(-5,6,-3,CONCRETE:7)
Block(-4,6,-3,CONCRETE:7)
Block(-3,6,-3,AIR:0)
Block(-2,6,-3,IRON_FENCE:0)
Block(-1,6,-3,AIR:0)
Block(0,6,-3,AIR:0)
Block(1,6,-3,AIR:0)
Block(2,6,-3,AIR:0)
Block(3,6,-3,AIR:0)
Block(4,6,-3,AIR:0)
Block(5,6,-3,AIR:0)
Block(6,6,-3,IRON_FENCE:0)
Block(7,6,-3,AIR:0)
Block(-8,6,-2,CONCRETE:7)
Block(-7,6,-2,CONCRETE:7)
Block(-6,6,-2,CONCRETE:7)
Block(-5,6,-2,CONCRETE:7)
Block(-4,6,-2,CONCRETE:7)
Block(-3,6,-2,AIR:0)
Block(-2,6,-2,IRON_FENCE:0)
Block(-1,6,-2,AIR:0)
Block(0,6,-2,AIR:0)
Block(1,6,-2,AIR:0)
Block(2,6,-2,AIR:0)
Block(3,6,-2,AIR:0)
Block(4,6,-2,AIR:0)
Block(5,6,-2,AIR:0)
Block(6,6,-2,IRON_FENCE:0)
Block(7,6,-2,AIR:0)
Block(-8,6,-1,CONCRETE:7)
Block(-7,6,-1,LADDER:4)
Block(-6,6,-1,CONCRETE:7)
Block(-5,6,-1,CONCRETE:7)
Block(-4,6,-1,CONCRETE:7)
Block(-3,6,-1,AIR:0)
Block(-2,6,-1,CONCRETE:7)
Block(-1,6,-1,AIR:0)
Block(0,6,-1,AIR:0)
Block(1,6,-1,AIR:0)
Block(2,6,-1,AIR:0)
Block(3,6,-1,AIR:0)
Block(4,6,-1,AIR:0)
Block(5,6,-1,AIR:0)
Block(6,6,-1,CONCRETE:7)
Block(7,6,-1,AIR:0)
Block(-8,6,0,CONCRETE:7)
Block(-7,6,0,CONCRETE:7)
Block(-6,6,0,CONCRETE:7)
Block(-5,6,0,CONCRETE:7)
Block(-4,6,0,CONCRETE:7)
Block(-3,6,0,AIR:0)
Block(-2,6,0,IRON_FENCE:0)
Block(-1,6,0,AIR:0)
Block(0,6,0,AIR:0)
Block(1,6,0,AIR:0)
Block(2,6,0,AIR:0)
Block(3,6,0,AIR:0)
Block(4,6,0,AIR:0)
Block(5,6,0,AIR:0)
Block(6,6,0,IRON_FENCE:0)
Block(7,6,0,AIR:0)
Block(-8,6,1,CONCRETE:7)
Block(-7,6,1,CONCRETE:7)
Block(-6,6,1,CONCRETE:7)
Block(-5,6,1,CONCRETE:7)
Block(-4,6,1,CONCRETE:7)
Block(-3,6,1,AIR:0)
Block(-2,6,1,IRON_FENCE:0)
Block(-1,6,1,AIR:0)
Block(0,6,1,AIR:0)
Block(1,6,1,AIR:0)
Block(2,6,1,AIR:0)
Block(3,6,1,AIR:0)
Block(4,6,1,AIR:0)
Block(5,6,1,AIR:0)
Block(6,6,1,IRON_FENCE:0)
Block(7,6,1,AIR:0)
Block(-8,6,2,CONCRETE:7)
Block(-7,6,2,CONCRETE:7)
Block(-6,6,2,CONCRETE:7)
Block(-5,6,2,CONCRETE:7)
Block(-4,6,2,CONCRETE:7)
Block(-3,6,2,AIR:0)
Block(-2,6,2,AIR:0)
Block(-1,6,2,AIR:0)
Block(0,6,2,AIR:0)
Block(1,6,2,AIR:0)
Block(2,6,2,AIR:0)
Block(3,6,2,AIR:0)
Block(4,6,2,AIR:0)
Block(5,6,2,AIR:0)
Block(6,6,2,IRON_FENCE:0)
Block(7,6,2,AIR:0)
Block(-8,6,3,CONCRETE:7)
Block(-7,6,3,CONCRETE:7)
Block(-6,6,3,CONCRETE:7)
Block(-5,6,3,CONCRETE:7)
Block(-4,6,3,CONCRETE:7)
Block(-3,6,3,AIR:0)
Block(-2,6,3,IRON_FENCE:0)
Block(-1,6,3,AIR:0)
Block(0,6,3,AIR:0)
Block(1,6,3,AIR:0)
Block(2,6,3,AIR:0)
Block(3,6,3,AIR:0)
Block(4,6,3,AIR:0)
Block(5,6,3,AIR:0)
Block(6,6,3,IRON_FENCE:0)
Block(7,6,3,AIR:0)
Block(-8,6,4,CONCRETE:7)
Block(-7,6,4,CONCRETE:7)
Block(-6,6,4,CONCRETE:7)
Block(-5,6,4,CONCRETE:7)
Block(-4,6,4,CONCRETE:7)
Block(-3,6,4,AIR:0)
Block(-2,6,4,IRON_FENCE:0)
Block(-1,6,4,AIR:0)
Block(0,6,4,AIR:0)
Block(1,6,4,AIR:0)
Block(2,6,4,AIR:0)
Block(3,6,4,AIR:0)
Block(4,6,4,AIR:0)
Block(5,6,4,AIR:0)
Block(6,6,4,IRON_FENCE:0)
Block(7,6,4,AIR:0)
Block(-8,6,5,CONCRETE:7)
Block(-7,6,5,CONCRETE:7)
Block(-6,6,5,CONCRETE:7)
Block(-5,6,5,CONCRETE:7)
Block(-4,6,5,CONCRETE:7)
Block(-3,6,5,AIR:0)
Block(-2,6,5,CONCRETE:7)
Block(-1,6,5,AIR:0)
Block(0,6,5,AIR:0)
Block(1,6,5,AIR:0)
Block(2,6,5,AIR:0)
Block(3,6,5,AIR:0)
Block(4,6,5,AIR:0)
Block(5,6,5,AIR:0)
Block(6,6,5,CONCRETE:7)
Block(7,6,5,AIR:0)
Block(-8,6,6,CONCRETE:7)
Block(-7,6,6,CONCRETE:7)
Block(-6,6,6,CONCRETE:7)
Block(-5,6,6,CONCRETE:7)
Block(-4,6,6,CONCRETE:7)
Block(-3,6,6,AIR:0)
Block(-2,6,6,IRON_FENCE:0)
Block(-1,6,6,AIR:0)
Block(0,6,6,AIR:0)
Block(1,6,6,AIR:0)
Block(2,6,6,AIR:0)
Block(3,6,6,AIR:0)
Block(4,6,6,AIR:0)
Block(5,6,6,AIR:0)
Block(6,6,6,IRON_FENCE:0)
Block(7,6,6,AIR:0)
Block(-8,6,7,CONCRETE:7)
Block(-7,6,7,CONCRETE:7)
Block(-6,6,7,CONCRETE:7)
Block(-5,6,7,CONCRETE:7)
Block(-4,6,7,CONCRETE:7)
Block(-3,6,7,AIR:0)
Block(-2,6,7,IRON_FENCE:0)
Block(-1,6,7,AIR:0)
Block(0,6,7,AIR:0)
Block(1,6,7,AIR:0)
Block(2,6,7,AIR:0)
Block(3,6,7,AIR:0)
Block(4,6,7,AIR:0)
Block(5,6,7,AIR:0)
Block(6,6,7,IRON_FENCE:0)
Block(7,6,7,AIR:0)
Block(-8,6,8,CONCRETE:7)
Block(-7,6,8,CONCRETE:7)
Block(-6,6,8,CONCRETE:7)
Block(-5,6,8,CONCRETE:7)
Block(-4,6,8,CONCRETE:7)
Block(-3,6,8,AIR:0)
Block(-2,6,8,IRON_FENCE:0)
Block(-1,6,8,AIR:0)
Block(0,6,8,AIR:0)
Block(1,6,8,AIR:0)
Block(2,6,8,AIR:0)
Block(3,6,8,AIR:0)
Block(4,6,8,AIR:0)
Block(5,6,8,AIR:0)
Block(6,6,8,IRON_FENCE:0)
Block(7,6,8,AIR:0)
Block(-8,7,-7,CONCRETE:7)
Block(-7,7,-7,CONCRETE:7)
Block(-6,7,-7,CONCRETE:7)
Block(-5,7,-7,CONCRETE:7)
Block(-4,7,-7,CONCRETE:7)
Block(-3,7,-7,CONCRETE:7)
Block(-2,7,-7,CONCRETE:7)
Block(-1,7,-7,CONCRETE:7)
Block(0,7,-7,CONCRETE:7)
Block(1,7,-7,CONCRETE:7)
Block(2,7,-7,CONCRETE:7)
Block(3,7,-7,CONCRETE:7)
Block(4,7,-7,CONCRETE:7)
Block(5,7,-7,CONCRETE:7)
Block(6,7,-7,CONCRETE:7)
Block(7,7,-7,CONCRETE:7)
Block(-8,7,-6,AIR:0)
Block(-7,7,-6,CONCRETE:7)
Block(-6,7,-6,CONCRETE:7)
Block(-5,7,-6,CONCRETE:7)
Block(-4,7,-6,CONCRETE:7)
Block(-3,7,-6,AIR:0)
Block(-2,7,-6,AIR:0)
Block(0,7,-6,AIR:0)
Block(1,7,-6,AIR:0)
Block(2,7,-6,AIR:0)
Block(3,7,-6,AIR:0)
Block(4,7,-6,AIR:0)
Block(5,7,-6,AIR:0)
Block(6,7,-6,IRON_FENCE:0)
Block(7,7,-6,AIR:0)
Block(-8,7,-5,AIR:0)
Block(-7,7,-5,AIR:0)
Block(-6,7,-5,CONCRETE:7)
Block(-5,7,-5,CONCRETE:7)
Block(-4,7,-5,CONCRETE:7)
Block(-3,7,-5,AIR:0)
Block(-2,7,-5,AIR:0)
Block(0,7,-5,AIR:0)
Block(1,7,-5,AIR:0)
Block(2,7,-5,AIR:0)
Block(3,7,-5,AIR:0)
Block(4,7,-5,AIR:0)
Block(5,7,-5,AIR:0)
Block(6,7,-5,IRON_FENCE:0)
Block(7,7,-5,AIR:0)
Block(-8,7,-4,AIR:0)
Block(-7,7,-4,CONCRETE:7)
Block(-6,7,-4,CONCRETE:7)
Block(-5,7,-4,CONCRETE:7)
Block(-4,7,-4,CONCRETE:7)
Block(-3,7,-4,AIR:0)
Block(-2,7,-4,AIR:0)
Block(0,7,-4,AIR:0)
Block(1,7,-4,AIR:0)
Block(2,7,-4,AIR:0)
Block(3,7,-4,AIR:0)
Block(4,7,-4,AIR:0)
Block(5,7,-4,AIR:0)
Block(6,7,-4,IRON_FENCE:0)
Block(7,7,-4,AIR:0)
Block(-8,7,-3,AIR:0)
Block(-7,7,-3,AIR:0)
Block(-6,7,-3,CONCRETE:7)
Block(-5,7,-3,CONCRETE:7)
Block(-4,7,-3,CONCRETE:7)
Block(-3,7,-3,AIR:0)
Block(-2,7,-3,AIR:0)
Block(0,7,-3,AIR:0)
Block(1,7,-3,AIR:0)
Block(2,7,-3,AIR:0)
Block(3,7,-3,AIR:0)
Block(4,7,-3,AIR:0)
Block(5,7,-3,AIR:0)
Block(6,7,-3,IRON_FENCE:0)
Block(7,7,-3,AIR:0)
Block(-8,7,-2,AIR:0)
Block(-7,7,-2,CONCRETE:7)
Block(-6,7,-2,CONCRETE:7)
Block(-5,7,-2,CONCRETE:7)
Block(-4,7,-2,CONCRETE:7)
Block(-3,7,-2,AIR:0)
Block(-2,7,-2,AIR:0)
Block(0,7,-2,AIR:0)
Block(1,7,-2,AIR:0)
Block(2,7,-2,AIR:0)
Block(3,7,-2,AIR:0)
Block(4,7,-2,AIR:0)
Block(5,7,-2,AIR:0)
Block(6,7,-2,IRON_FENCE:0)
Block(7,7,-2,AIR:0)
Block(-8,7,-1,AIR:0)
Block(-7,7,-1,LADDER:4)
Block(-6,7,-1,CONCRETE:7)
Block(-5,7,-1,CONCRETE:7)
Block(-4,7,-1,CONCRETE:7)
Block(-3,7,-1,AIR:0)
Block(-2,7,-1,CONCRETE:7)
Block(0,7,-1,AIR:0)
Block(1,7,-1,AIR:0)
Block(2,7,-1,AIR:0)
Block(3,7,-1,AIR:0)
Block(4,7,-1,AIR:0)
Block(5,7,-1,AIR:0)
Block(6,7,-1,CONCRETE:7)
Block(7,7,-1,AIR:0)
Block(-8,7,0,AIR:0)
Block(-7,7,0,CONCRETE:7)
Block(-6,7,0,CONCRETE:7)
Block(-5,7,0,CONCRETE:7)
Block(-4,7,0,CONCRETE:7)
Block(-3,7,0,AIR:0)
Block(-2,7,0,AIR:0)
Block(0,7,0,AIR:0)
Block(1,7,0,AIR:0)
Block(2,7,0,AIR:0)
Block(3,7,0,AIR:0)
Block(4,7,0,AIR:0)
Block(5,7,0,AIR:0)
Block(6,7,0,IRON_FENCE:0)
Block(7,7,0,AIR:0)
Block(-8,7,1,LEVER:4)
Block(-7,7,1,AIR:0)
Block(-6,7,1,CONCRETE:7)
Block(-5,7,1,CONCRETE:7)
Block(-4,7,1,CONCRETE:7)
Block(-3,7,1,AIR:0)
Block(-2,7,1,AIR:0)
Block(0,7,1,AIR:0)
Block(1,7,1,AIR:0)
Block(2,7,1,AIR:0)
Block(3,7,1,AIR:0)
Block(4,7,1,AIR:0)
Block(5,7,1,AIR:0)
Block(6,7,1,IRON_FENCE:0)
Block(7,7,1,AIR:0)
Block(-7,7,2,CONCRETE:7)
Block(-6,7,2,CONCRETE:7)
Block(-5,7,2,CONCRETE:7)
Block(-4,7,2,CONCRETE:7)
Block(-3,7,2,AIR:0)
Block(-2,7,2,AIR:0)
Block(0,7,2,AIR:0)
Block(1,7,2,AIR:0)
Block(2,7,2,AIR:0)
Block(3,7,2,AIR:0)
Block(4,7,2,AIR:0)
Block(5,7,2,AIR:0)
Block(6,7,2,IRON_FENCE:0)
Block(7,7,2,AIR:0)
Block(-8,7,3,CONCRETE:7)
Block(-7,7,3,CONCRETE:7)
Block(-6,7,3,CONCRETE:7)
Block(-5,7,3,CONCRETE:7)
Block(-4,7,3,CONCRETE:7)
Block(-3,7,3,AIR:0)
Block(-2,7,3,AIR:0)
Block(0,7,3,AIR:0)
Block(1,7,3,AIR:0)
Block(2,7,3,AIR:0)
Block(3,7,3,AIR:0)
Block(4,7,3,AIR:0)
Block(5,7,3,AIR:0)
Block(6,7,3,IRON_FENCE:0)
Block(7,7,3,AIR:0)
Block(-8,7,4,CONCRETE:7)
Block(-7,7,4,CONCRETE:7)
Block(-6,7,4,CONCRETE:7)
Block(-5,7,4,CONCRETE:7)
Block(-4,7,4,CONCRETE:7)
Block(-3,7,4,AIR:0)
Block(-2,7,4,AIR:0)
Block(0,7,4,AIR:0)
Block(1,7,4,AIR:0)
Block(2,7,4,AIR:0)
Block(3,7,4,AIR:0)
Block(4,7,4,AIR:0)
Block(5,7,4,AIR:0)
Block(6,7,4,IRON_FENCE:0)
Block(7,7,4,AIR:0)
Block(-8,7,5,CONCRETE:7)
Block(-7,7,5,CONCRETE:7)
Block(-6,7,5,CONCRETE:7)
Block(-5,7,5,CONCRETE:7)
Block(-4,7,5,CONCRETE:7)
Block(-3,7,5,AIR:0)
Block(-2,7,5,CONCRETE:7)
Block(0,7,5,AIR:0)
Block(1,7,5,AIR:0)
Block(2,7,5,AIR:0)
Block(3,7,5,AIR:0)
Block(4,7,5,AIR:0)
Block(5,7,5,AIR:0)
Block(6,7,5,CONCRETE:7)
Block(7,7,5,AIR:0)
Block(-8,7,6,CONCRETE:7)
Block(-7,7,6,CONCRETE:7)
Block(-6,7,6,CONCRETE:7)
Block(-5,7,6,CONCRETE:7)
Block(-4,7,6,CONCRETE:7)
Block(-3,7,6,AIR:0)
Block(-2,7,6,AIR:0)
Block(0,7,6,AIR:0)
Block(1,7,6,AIR:0)
Block(2,7,6,AIR:0)
Block(3,7,6,AIR:0)
Block(4,7,6,AIR:0)
Block(5,7,6,AIR:0)
Block(6,7,6,IRON_FENCE:0)
Block(7,7,6,AIR:0)
Block(-8,7,7,CONCRETE:7)
Block(-7,7,7,CONCRETE:7)
Block(-6,7,7,CONCRETE:7)
Block(-5,7,7,CONCRETE:7)
Block(-4,7,7,CONCRETE:7)
Block(-3,7,7,AIR:0)
Block(-2,7,7,AIR:0)
Block(0,7,7,AIR:0)
Block(1,7,7,AIR:0)
Block(2,7,7,AIR:0)
Block(3,7,7,AIR:0)
Block(4,7,7,AIR:0)
Block(5,7,7,AIR:0)
Block(6,7,7,IRON_FENCE:0)
Block(7,7,7,AIR:0)
Block(-8,7,8,CONCRETE:7)
Block(-7,7,8,CONCRETE:7)
Block(-6,7,8,CONCRETE:7)
Block(-5,7,8,CONCRETE:7)
Block(-4,7,8,CONCRETE:7)
Block(-3,7,8,AIR:0)
Block(-2,7,8,AIR:0)
Block(0,7,8,AIR:0)
Block(1,7,8,AIR:0)
Block(2,7,8,AIR:0)
Block(3,7,8,AIR:0)
Block(4,7,8,AIR:0)
Block(5,7,8,AIR:0)
Block(6,7,8,IRON_FENCE:0)
Block(7,7,8,AIR:0)
Block(-8,14,-7,DIRT:0)
Block(-7,14,-7,DIRT:0)
Block(-6,14,-7,DIRT:0)
Block(-5,14,-7,DIRT:0)
Block(-4,14,-7,DIRT:0)
Block(-3,14,-7,DIRT:0)
Block(-2,14,-7,DIRT:0)
Block(-1,14,-7,DIRT:0)
Block(0,14,-7,DIRT:0)
Block(1,14,-7,DIRT:0)
Block(2,14,-7,DIRT:0)
Block(3,14,-7,DIRT:0)
Block(4,14,-7,DIRT:0)
Block(5,14,-7,DIRT:0)
Block(6,14,-7,DIRT:0)
Block(7,14,-7,DIRT:0)
Block(-8,14,-6,DIRT:0)
Block(-7,14,-6,DIRT:0)
Block(-6,14,-6,DIRT:0)
Block(-5,14,-6,DIRT:0)
Block(-4,14,-6,DIRT:0)
Block(-3,14,-6,DIRT:0)
Block(-2,14,-6,DIRT:0)
Block(-1,14,-6,DIRT:0)
Block(0,14,-6,DIRT:0)
Block(1,14,-6,DIRT:0)
Block(2,14,-6,DIRT:0)
Block(3,14,-6,DIRT:0)
Block(4,14,-6,DIRT:0)
Block(5,14,-6,DIRT:0)
Block(6,14,-6,DIRT:0)
Block(7,14,-6,DIRT:0)
Block(-8,14,-5,DIRT:0)
Block(-7,14,-5,DIRT:0)
Block(-6,14,-5,DIRT:0)
Block(-5,14,-5,DIRT:0)
Block(-4,14,-5,DIRT:0)
Block(-3,14,-5,DIRT:0)
Block(-2,14,-5,DIRT:0)
Block(-1,14,-5,DIRT:0)
Block(0,14,-5,DIRT:0)
Block(1,14,-5,DIRT:0)
Block(2,14,-5,DIRT:0)
Block(3,14,-5,DIRT:0)
Block(4,14,-5,DIRT:0)
Block(5,14,-5,DIRT:0)
Block(6,14,-5,DIRT:0)
Block(7,14,-5,DIRT:0)
Block(-8,14,-4,DIRT:0)
Block(-7,14,-4,DIRT:0)
Block(-6,14,-4,DIRT:0)
Block(-5,14,-4,DIRT:0)
Block(-4,14,-4,DIRT:0)
Block(-3,14,-4,DIRT:0)
Block(-2,14,-4,DIRT:0)
Block(-1,14,-4,DIRT:0)
Block(0,14,-4,DIRT:0)
Block(1,14,-4,DIRT:0)
Block(2,14,-4,DIRT:0)
Block(3,14,-4,DIRT:0)
Block(4,14,-4,DIRT:0)
Block(5,14,-4,DIRT:0)
Block(6,14,-4,DIRT:0)
Block(7,14,-4,DIRT:0)
Block(-8,14,-3,DIRT:0)
Block(-7,14,-3,DIRT:0)
Block(-6,14,-3,DIRT:0)
Block(-5,14,-3,DIRT:0)
Block(-4,14,-3,DIRT:0)
Block(-3,14,-3,DIRT:0)
Block(-2,14,-3,DIRT:0)
Block(-1,14,-3,DIRT:0)
Block(0,14,-3,DIRT:0)
Block(1,14,-3,DIRT:0)
Block(2,14,-3,DIRT:0)
Block(3,14,-3,DIRT:0)
Block(4,14,-3,DIRT:0)
Block(5,14,-3,DIRT:0)
Block(6,14,-3,DIRT:0)
Block(7,14,-3,DIRT:0)
Block(-8,14,-2,DIRT:0)
Block(-7,14,-2,DIRT:0)
Block(-6,14,-2,DIRT:0)
Block(-5,14,-2,DIRT:0)
Block(-4,14,-2,DIRT:0)
Block(-3,14,-2,DIRT:0)
Block(-2,14,-2,DIRT:0)
Block(-1,14,-2,DIRT:0)
Block(0,14,-2,DIRT:0)
Block(1,14,-2,DIRT:0)
Block(2,14,-2,DIRT:0)
Block(3,14,-2,DIRT:0)
Block(4,14,-2,DIRT:0)
Block(5,14,-2,DIRT:0)
Block(6,14,-2,DIRT:0)
Block(7,14,-2,DIRT:0)
Block(-8,14,-1,DIRT:0)
Block(-7,14,-1,DIRT:0)
Block(-6,14,-1,DIRT:0)
Block(-5,14,-1,DIRT:0)
Block(-4,14,-1,DIRT:0)
Block(-3,14,-1,DIRT:0)
Block(-2,14,-1,DIRT:0)
Block(-1,14,-1,DIRT:0)
Block(0,14,-1,DIRT:0)
Block(1,14,-1,DIRT:0)
Block(2,14,-1,DIRT:0)
Block(3,14,-1,DIRT:0)
Block(4,14,-1,DIRT:0)
Block(5,14,-1,DIRT:0)
Block(6,14,-1,DIRT:0)
Block(7,14,-1,DIRT:0)
Block(-8,14,0,DIRT:0)
Block(-7,14,0,DIRT:0)
Block(-6,14,0,DIRT:0)
Block(-5,14,0,DIRT:0)
Block(-4,14,0,DIRT:0)
Block(-3,14,0,DIRT:0)
Block(-2,14,0,DIRT:0)
Block(-1,14,0,DIRT:0)
Block(0,14,0,DIRT:0)
Block(1,14,0,DIRT:0)
Block(2,14,0,DIRT:0)
Block(3,14,0,DIRT:0)
Block(4,14,0,DIRT:0)
Block(5,14,0,DIRT:0)
Block(6,14,0,DIRT:0)
Block(7,14,0,DIRT:0)
Block(-8,14,1,DIRT:0)
Block(-7,14,1,DIRT:0)
Block(-6,14,1,DIRT:0)
Block(-5,14,1,DIRT:0)
Block(-4,14,1,DIRT:0)
Block(-3,14,1,DIRT:0)
Block(-2,14,1,DIRT:0)
Block(-1,14,1,DIRT:0)
Block(0,14,1,DIRT:0)
Block(1,14,1,DIRT:0)
Block(2,14,1,DIRT:0)
Block(3,14,1,DIRT:0)
Block(4,14,1,DIRT:0)
Block(5,14,1,DIRT:0)
Block(6,14,1,DIRT:0)
Block(7,14,1,DIRT:0)
Block(-8,14,2,DIRT:0)
Block(-7,14,2,DIRT:0)
Block(-6,14,2,DIRT:0)
Block(-5,14,2,DIRT:0)
Block(-4,14,2,DIRT:0)
Block(-3,14,2,DIRT:0)
Block(-2,14,2,DIRT:0)
Block(-1,14,2,DIRT:0)
Block(0,14,2,DIRT:0)
Block(1,14,2,DIRT:0)
Block(2,14,2,DIRT:0)
Block(3,14,2,DIRT:0)
Block(4,14,2,DIRT:0)
Block(5,14,2,DIRT:0)
Block(6,14,2,DIRT:0)
Block(7,14,2,DIRT:0)
Block(-8,14,3,DIRT:0)
Block(-7,14,3,DIRT:0)
Block(-6,14,3,DIRT:0)
Block(-5,14,3,DIRT:0)
Block(-4,14,3,DIRT:0)
Block(-3,14,3,DIRT:0)
Block(-2,14,3,DIRT:0)
Block(-1,14,3,DIRT:0)
Block(0,14,3,DIRT:0)
Block(1,14,3,DIRT:0)
Block(2,14,3,DIRT:0)
Block(3,14,3,DIRT:0)
Block(4,14,3,DIRT:0)
Block(5,14,3,DIRT:0)
Block(6,14,3,DIRT:0)
Block(7,14,3,DIRT:0)
Block(-8,14,4,DIRT:0)
Block(-7,14,4,DIRT:0)
Block(-6,14,4,DIRT:0)
Block(-5,14,4,DIRT:0)
Block(-4,14,4,DIRT:0)
Block(-3,14,4,DIRT:0)
Block(-2,14,4,DIRT:0)
Block(-1,14,4,DIRT:0)
Block(0,14,4,DIRT:0)
Block(1,14,4,DIRT:0)
Block(2,14,4,DIRT:0)
Block(3,14,4,DIRT:0)
Block(4,14,4,DIRT:0)
Block(5,14,4,DIRT:0)
Block(6,14,4,DIRT:0)
Block(7,14,4,DIRT:0)
Block(-8,14,5,DIRT:0)
Block(-7,14,5,DIRT:0)
Block(-6,14,5,DIRT:0)
Block(-5,14,5,DIRT:0)
Block(-4,14,5,DIRT:0)
Block(-3,14,5,DIRT:0)
Block(-2,14,5,DIRT:0)
Block(-1,14,5,DIRT:0)
Block(0,14,5,DIRT:0)
Block(1,14,5,DIRT:0)
Block(2,14,5,DIRT:0)
Block(3,14,5,DIRT:0)
Block(4,14,5,DIRT:0)
Block(5,14,5,DIRT:0)
Block(6,14,5,DIRT:0)
Block(7,14,5,DIRT:0)
Block(-8,14,6,DIRT:0)
Block(-7,14,6,DIRT:0)
Block(-6,14,6,DIRT:0)
Block(-5,14,6,DIRT:0)
Block(-4,14,6,DIRT:0)
Block(-3,14,6,DIRT:0)
Block(-2,14,6,DIRT:0)
Block(-1,14,6,DIRT:0)
Block(0,14,6,DIRT:0)
Block(1,14,6,DIRT:0)
Block(2,14,6,DIRT:0)
Block(3,14,6,DIRT:0)
Block(4,14,6,DIRT:0)
Block(5,14,6,DIRT:0)
Block(6,14,6,DIRT:0)
Block(7,14,6,DIRT:0)
Block(-8,14,7,DIRT:0)
Block(-7,14,7,DIRT:0)
Block(-6,14,7,DIRT:0)
Block(-5,14,7,DIRT:0)
Block(-4,14,7,DIRT:0)
Block(-3,14,7,DIRT:0)
Block(-2,14,7,DIRT:0)
Block(-1,14,7,DIRT:0)
Block(0,14,7,DIRT:0)
Block(1,14,7,DIRT:0)
Block(2,14,7,DIRT:0)
Block(3,14,7,DIRT:0)
Block(4,14,7,DIRT:0)
Block(5,14,7,DIRT:0)
Block(6,14,7,DIRT:0)
Block(7,14,7,DIRT:0)
Block(-8,14,8,DIRT:0)
Block(-7,14,8,DIRT:0)
Block(-6,14,8,DIRT:0)
Block(-5,14,8,DIRT:0)
Block(-4,14,8,DIRT:0)
Block(-3,14,8,DIRT:0)
Block(-2,14,8,DIRT:0)
Block(-1,14,8,DIRT:0)
Block(0,14,8,DIRT:0)
Block(1,14,8,DIRT:0)
Block(2,14,8,DIRT:0)
Block(3,14,8,DIRT:0)
Block(4,14,8,DIRT:0)
Block(5,14,8,DIRT:0)
Block(6,14,8,DIRT:0)
Block(7,14,8,DIRT:0)
Block(-8,15,-7,DIRT:0)
Block(-7,15,-7,DIRT:0)
Block(-6,15,-7,DIRT:0)
Block(-5,15,-7,DIRT:0)
Block(-4,15,-7,DIRT:0)
Block(-3,15,-7,DIRT:0)
Block(-2,15,-7,DIRT:0)
Block(-1,15,-7,DIRT:0)
Block(0,15,-7,DIRT:0)
Block(1,15,-7,DIRT:0)
Block(2,15,-7,DIRT:0)
Block(3,15,-7,DIRT:0)
Block(4,15,-7,DIRT:0)
Block(5,15,-7,DIRT:0)
Block(6,15,-7,DIRT:0)
Block(7,15,-7,DIRT:0)
Block(-8,15,-6,DIRT:0)
Block(-7,15,-6,DIRT:0)
Block(-6,15,-6,DIRT:0)
Block(-5,15,-6,DIRT:0)
Block(-4,15,-6,DIRT:0)
Block(-3,15,-6,DIRT:0)
Block(-2,15,-6,DIRT:0)
Block(-1,15,-6,DIRT:0)
Block(0,15,-6,DIRT:0)
Block(1,15,-6,DIRT:0)
Block(2,15,-6,DIRT:0)
Block(3,15,-6,DIRT:0)
Block(4,15,-6,DIRT:0)
Block(5,15,-6,DIRT:0)
Block(6,15,-6,DIRT:0)
Block(7,15,-6,DIRT:0)
Block(-8,15,-5,DIRT:0)
Block(-7,15,-5,DIRT:0)
Block(-6,15,-5,DIRT:0)
Block(-5,15,-5,DIRT:0)
Block(-4,15,-5,DIRT:0)
Block(-3,15,-5,DIRT:0)
Block(-2,15,-5,DIRT:0)
Block(-1,15,-5,DIRT:0)
Block(0,15,-5,DIRT:0)
Block(1,15,-5,DIRT:0)
Block(2,15,-5,DIRT:0)
Block(3,15,-5,DIRT:0)
Block(4,15,-5,DIRT:0)
Block(5,15,-5,DIRT:0)
Block(6,15,-5,DIRT:0)
Block(7,15,-5,DIRT:0)
Block(-8,15,-4,DIRT:0)
Block(-7,15,-4,DIRT:0)
Block(-6,15,-4,DIRT:0)
Block(-5,15,-4,DIRT:0)
Block(-4,15,-4,DIRT:0)
Block(-3,15,-4,DIRT:0)
Block(-2,15,-4,DIRT:0)
Block(-1,15,-4,DIRT:0)
Block(0,15,-4,DIRT:0)
Block(1,15,-4,DIRT:0)
Block(2,15,-4,DIRT:0)
Block(3,15,-4,DIRT:0)
Block(4,15,-4,DIRT:0)
Block(5,15,-4,DIRT:0)
Block(6,15,-4,DIRT:0)
Block(7,15,-4,DIRT:0)
Block(-8,15,-3,DIRT:0)
Block(-7,15,-3,DIRT:0)
Block(-6,15,-3,DIRT:0)
Block(-5,15,-3,DIRT:0)
Block(-4,15,-3,DIRT:0)
Block(-3,15,-3,DIRT:0)
Block(-2,15,-3,DIRT:0)
Block(-1,15,-3,DIRT:0)
Block(0,15,-3,DIRT:0)
Block(1,15,-3,DIRT:0)
Block(2,15,-3,DIRT:0)
Block(3,15,-3,DIRT:0)
Block(4,15,-3,DIRT:0)
Block(5,15,-3,DIRT:0)
Block(6,15,-3,DIRT:0)
Block(7,15,-3,DIRT:0)
Block(-8,15,-2,DIRT:0)
Block(-7,15,-2,DIRT:0)
Block(-6,15,-2,DIRT:0)
Block(-5,15,-2,DIRT:0)
Block(-4,15,-2,DIRT:0)
Block(-3,15,-2,DIRT:0)
Block(-2,15,-2,DIRT:0)
Block(-1,15,-2,DIRT:0)
Block(0,15,-2,DIRT:0)
Block(1,15,-2,DIRT:0)
Block(2,15,-2,DIRT:0)
Block(3,15,-2,DIRT:0)
Block(4,15,-2,DIRT:0)
Block(5,15,-2,DIRT:0)
Block(6,15,-2,DIRT:0)
Block(7,15,-2,DIRT:0)
Block(-8,15,-1,DIRT:0)
Block(-7,15,-1,DIRT:0)
Block(-6,15,-1,DIRT:0)
Block(-5,15,-1,DIRT:0)
Block(-4,15,-1,DIRT:0)
Block(-3,15,-1,DIRT:0)
Block(-2,15,-1,DIRT:0)
Block(-1,15,-1,DIRT:0)
Block(0,15,-1,DIRT:0)
Block(1,15,-1,DIRT:0)
Block(2,15,-1,DIRT:0)
Block(3,15,-1,DIRT:0)
Block(4,15,-1,DIRT:0)
Block(5,15,-1,DIRT:0)
Block(6,15,-1,DIRT:0)
Block(7,15,-1,DIRT:0)
Block(-8,15,0,DIRT:0)
Block(-7,15,0,DIRT:0)
Block(-6,15,0,DIRT:0)
Block(-5,15,0,DIRT:0)
Block(-4,15,0,DIRT:0)
Block(-3,15,0,DIRT:0)
Block(-2,15,0,DIRT:0)
Block(-1,15,0,DIRT:0)
Block(0,15,0,DIRT:0)
Block(1,15,0,DIRT:0)
Block(2,15,0,DIRT:0)
Block(3,15,0,DIRT:0)
Block(4,15,0,DIRT:0)
Block(5,15,0,DIRT:0)
Block(6,15,0,DIRT:0)
Block(7,15,0,DIRT:0)
Block(-8,15,1,DIRT:0)
Block(-7,15,1,DIRT:0)
Block(-6,15,1,DIRT:0)
Block(-5,15,1,DIRT:0)
Block(-4,15,1,DIRT:0)
Block(-3,15,1,DIRT:0)
Block(-2,15,1,DIRT:0)
Block(-1,15,1,DIRT:0)
Block(0,15,1,DIRT:0)
Block(1,15,1,DIRT:0)
Block(2,15,1,DIRT:0)
Block(3,15,1,DIRT:0)
Block(4,15,1,DIRT:0)
Block(5,15,1,DIRT:0)
Block(6,15,1,DIRT:0)
Block(7,15,1,DIRT:0)
Block(-8,15,2,DIRT:0)
Block(-7,15,2,DIRT:0)
Block(-6,15,2,DIRT:0)
Block(-5,15,2,DIRT:0)
Block(-4,15,2,DIRT:0)
Block(-3,15,2,DIRT:0)
Block(-2,15,2,DIRT:0)
Block(-1,15,2,DIRT:0)
Block(0,15,2,DIRT:0)
Block(1,15,2,DIRT:0)
Block(2,15,2,DIRT:0)
Block(3,15,2,DIRT:0)
Block(4,15,2,DIRT:0)
Block(5,15,2,DIRT:0)
Block(6,15,2,DIRT:0)
Block(7,15,2,DIRT:0)
Block(-8,15,3,DIRT:0)
Block(-7,15,3,DIRT:0)
Block(-6,15,3,DIRT:0)
Block(-5,15,3,DIRT:0)
Block(-4,15,3,DIRT:0)
Block(-3,15,3,DIRT:0)
Block(-2,15,3,DIRT:0)
Block(-1,15,3,DIRT:0)
Block(0,15,3,DIRT:0)
Block(1,15,3,DIRT:0)
Block(2,15,3,DIRT:0)
Block(3,15,3,DIRT:0)
Block(4,15,3,DIRT:0)
Block(5,15,3,DIRT:0)
Block(6,15,3,DIRT:0)
Block(7,15,3,DIRT:0)
Block(-8,15,4,DIRT:0)
Block(-7,15,4,DIRT:0)
Block(-6,15,4,DIRT:0)
Block(-5,15,4,DIRT:0)
Block(-4,15,4,DIRT:0)
Block(-3,15,4,DIRT:0)
Block(-2,15,4,DIRT:0)
Block(-1,15,4,DIRT:0)
Block(0,15,4,DIRT:0)
Block(1,15,4,DIRT:0)
Block(2,15,4,DIRT:0)
Block(3,15,4,DIRT:0)
Block(4,15,4,DIRT:0)
Block(5,15,4,DIRT:0)
Block(6,15,4,DIRT:0)
Block(7,15,4,DIRT:0)
Block(-8,15,5,DIRT:0)
Block(-7,15,5,DIRT:0)
Block(-6,15,5,DIRT:0)
Block(-5,15,5,DIRT:0)
Block(-4,15,5,DIRT:0)
Block(-3,15,5,DIRT:0)
Block(-2,15,5,DIRT:0)
Block(-1,15,5,DIRT:0)
Block(0,15,5,DIRT:0)
Block(1,15,5,DIRT:0)
Block(2,15,5,DIRT:0)
Block(3,15,5,DIRT:0)
Block(4,15,5,DIRT:0)
Block(5,15,5,DIRT:0)
Block(6,15,5,DIRT:0)
Block(7,15,5,DIRT:0)
Block(-8,15,6,DIRT:0)
Block(-7,15,6,DIRT:0)
Block(-6,15,6,DIRT:0)
Block(-5,15,6,DIRT:0)
Block(-4,15,6,DIRT:0)
Block(-3,15,6,DIRT:0)
Block(-2,15,6,DIRT:0)
Block(-1,15,6,DIRT:0)
Block(0,15,6,DIRT:0)
Block(1,15,6,DIRT:0)
Block(2,15,6,DIRT:0)
Block(3,15,6,DIRT:0)
Block(4,15,6,DIRT:0)
Block(5,15,6,DIRT:0)
Block(6,15,6,DIRT:0)
Block(7,15,6,DIRT:0)
Block(-8,15,7,DIRT:0)
Block(-7,15,7,DIRT:0)
Block(-6,15,7,DIRT:0)
Block(-5,15,7,DIRT:0)
Block(-4,15,7,DIRT:0)
Block(-3,15,7,DIRT:0)
Block(-2,15,7,DIRT:0)
Block(-1,15,7,DIRT:0)
Block(0,15,7,DIRT:0)
Block(1,15,7,DIRT:0)
Block(2,15,7,DIRT:0)
Block(3,15,7,DIRT:0)
Block(4,15,7,DIRT:0)
Block(5,15,7,DIRT:0)
Block(6,15,7,DIRT:0)
Block(7,15,7,DIRT:0)
Block(-8,15,8,DIRT:0)
Block(-7,15,8,DIRT:0)
Block(-6,15,8,DIRT:0)
Block(-5,15,8,DIRT:0)
Block(-4,15,8,DIRT:0)
Block(-3,15,8,DIRT:0)
Block(-2,15,8,DIRT:0)
Block(-1,15,8,DIRT:0)
Block(0,15,8,DIRT:0)
Block(1,15,8,DIRT:0)
Block(2,15,8,DIRT:0)
Block(3,15,8,DIRT:0)
Block(4,15,8,DIRT:0)
Block(5,15,8,DIRT:0)
Block(6,15,8,DIRT:0)
Block(7,15,8,DIRT:0)
Block(-8,16,-7,CONCRETE:8)
Block(-7,16,-7,CONCRETE:8)
Block(-6,16,-7,CONCRETE:15)
Block(-5,16,-7,CONCRETE:0)
Block(-4,16,-7,CONCRETE:15)
Block(-3,16,-7,CONCRETE:15)
Block(-2,16,-7,CONCRETE:15)
Block(-1,16,-7,CONCRETE:4)
Block(0,16,-7,CONCRETE:4)
Block(1,16,-7,CONCRETE:15)
Block(2,16,-7,CONCRETE:15)
Block(3,16,-7,CONCRETE:15)
Block(4,16,-7,CONCRETE:0)
Block(5,16,-7,CONCRETE:15)
Block(6,16,-7,CONCRETE:8)
Block(7,16,-7,CONCRETE:8)
Block(-8,16,-6,CONCRETE:8)
Block(-7,16,-6,CONCRETE:8)
Block(-6,16,-6,CONCRETE:15)
Block(-5,16,-6,CONCRETE:0)
Block(-4,16,-6,CONCRETE:15)
Block(-3,16,-6,CONCRETE:15)
Block(-2,16,-6,CONCRETE:15)
Block(-1,16,-6,CONCRETE:4)
Block(0,16,-6,CONCRETE:4)
Block(1,16,-6,CONCRETE:15)
Block(2,16,-6,CONCRETE:15)
Block(3,16,-6,CONCRETE:15)
Block(4,16,-6,CONCRETE:0)
Block(5,16,-6,CONCRETE:15)
Block(6,16,-6,CONCRETE:8)
Block(7,16,-6,CONCRETE:8)
Block(-8,16,-5,CONCRETE:8)
Block(-7,16,-5,CONCRETE:8)
Block(-6,16,-5,CONCRETE:15)
Block(-5,16,-5,CONCRETE:0)
Block(-4,16,-5,CONCRETE:15)
Block(-3,16,-5,CONCRETE:15)
Block(-2,16,-5,CONCRETE:15)
Block(-1,16,-5,CONCRETE:4)
Block(0,16,-5,CONCRETE:4)
Block(1,16,-5,CONCRETE:15)
Block(2,16,-5,CONCRETE:15)
Block(3,16,-5,CONCRETE:15)
Block(4,16,-5,CONCRETE:0)
Block(5,16,-5,CONCRETE:15)
Block(6,16,-5,CONCRETE:8)
Block(7,16,-5,CONCRETE:8)
Block(-8,16,-4,CONCRETE:8)
Block(-7,16,-4,CONCRETE:8)
Block(-6,16,-4,CONCRETE:15)
Block(-5,16,-4,CONCRETE:0)
Block(-4,16,-4,CONCRETE:15)
Block(-3,16,-4,CONCRETE:15)
Block(-2,16,-4,CONCRETE:15)
Block(-1,16,-4,CONCRETE:4)
Block(0,16,-4,CONCRETE:4)
Block(1,16,-4,CONCRETE:15)
Block(2,16,-4,CONCRETE:15)
Block(3,16,-4,CONCRETE:15)
Block(4,16,-4,CONCRETE:0)
Block(5,16,-4,CONCRETE:15)
Block(6,16,-4,CONCRETE:8)
Block(7,16,-4,CONCRETE:8)
Block(-8,16,-3,CONCRETE:8)
Block(-7,16,-3,CONCRETE:8)
Block(-6,16,-3,CONCRETE:15)
Block(-5,16,-3,CONCRETE:0)
Block(-4,16,-3,CONCRETE:15)
Block(-3,16,-3,CONCRETE:15)
Block(-2,16,-3,CONCRETE:15)
Block(-1,16,-3,CONCRETE:4)
Block(0,16,-3,CONCRETE:4)
Block(1,16,-3,CONCRETE:15)
Block(2,16,-3,CONCRETE:15)
Block(3,16,-3,CONCRETE:15)
Block(4,16,-3,CONCRETE:0)
Block(5,16,-3,CONCRETE:15)
Block(6,16,-3,CONCRETE:8)
Block(7,16,-3,CONCRETE:8)
Block(-8,16,-2,CONCRETE:8)
Block(-7,16,-2,CONCRETE:8)
Block(-6,16,-2,CONCRETE:15)
Block(-5,16,-2,CONCRETE:0)
Block(-4,16,-2,CONCRETE:15)
Block(-3,16,-2,CONCRETE:15)
Block(-2,16,-2,CONCRETE:15)
Block(-1,16,-2,CONCRETE:4)
Block(0,16,-2,CONCRETE:4)
Block(1,16,-2,CONCRETE:15)
Block(2,16,-2,CONCRETE:15)
Block(3,16,-2,CONCRETE:15)
Block(4,16,-2,CONCRETE:0)
Block(5,16,-2,CONCRETE:15)
Block(6,16,-2,CONCRETE:8)
Block(7,16,-2,CONCRETE:8)
Block(-8,16,-1,CONCRETE:8)
Block(-7,16,-1,CONCRETE:8)
Block(-6,16,-1,CONCRETE:15)
Block(-5,16,-1,CONCRETE:0)
Block(-4,16,-1,CONCRETE:15)
Block(-3,16,-1,CONCRETE:15)
Block(-2,16,-1,CONCRETE:15)
Block(-1,16,-1,CONCRETE:4)
Block(0,16,-1,CONCRETE:4)
Block(1,16,-1,CONCRETE:15)
Block(2,16,-1,CONCRETE:15)
Block(3,16,-1,CONCRETE:15)
Block(4,16,-1,CONCRETE:0)
Block(5,16,-1,CONCRETE:15)
Block(6,16,-1,CONCRETE:8)
Block(7,16,-1,CONCRETE:8)
Block(-8,16,0,CONCRETE:8)
Block(-7,16,0,CONCRETE:8)
Block(-6,16,0,CONCRETE:15)
Block(-5,16,0,CONCRETE:0)
Block(-4,16,0,CONCRETE:15)
Block(-3,16,0,CONCRETE:15)
Block(-2,16,0,CONCRETE:15)
Block(-1,16,0,CONCRETE:4)
Block(0,16,0,CONCRETE:4)
Block(1,16,0,CONCRETE:15)
Block(2,16,0,CONCRETE:15)
Block(3,16,0,CONCRETE:15)
Block(4,16,0,CONCRETE:0)
Block(5,16,0,CONCRETE:15)
Block(6,16,0,CONCRETE:8)
Block(7,16,0,CONCRETE:8)
Block(-8,16,1,CONCRETE:8)
Block(-7,16,1,CONCRETE:8)
Block(-6,16,1,CONCRETE:15)
Block(-5,16,1,CONCRETE:0)
Block(-4,16,1,CONCRETE:15)
Block(-3,16,1,CONCRETE:15)
Block(-2,16,1,CONCRETE:15)
Block(-1,16,1,CONCRETE:4)
Block(0,16,1,CONCRETE:4)
Block(1,16,1,CONCRETE:15)
Block(2,16,1,CONCRETE:15)
Block(3,16,1,CONCRETE:15)
Block(4,16,1,CONCRETE:0)
Block(5,16,1,CONCRETE:15)
Block(6,16,1,CONCRETE:8)
Block(7,16,1,CONCRETE:8)
Block(-8,16,2,CONCRETE:8)
Block(-7,16,2,CONCRETE:8)
Block(-6,16,2,CONCRETE:15)
Block(-5,16,2,CONCRETE:0)
Block(-4,16,2,CONCRETE:15)
Block(-3,16,2,CONCRETE:15)
Block(-2,16,2,CONCRETE:15)
Block(-1,16,2,CONCRETE:4)
Block(0,16,2,CONCRETE:4)
Block(1,16,2,CONCRETE:15)
Block(2,16,2,CONCRETE:15)
Block(3,16,2,CONCRETE:15)
Block(4,16,2,CONCRETE:0)
Block(5,16,2,CONCRETE:15)
Block(6,16,2,CONCRETE:8)
Block(7,16,2,CONCRETE:8)
Block(-8,16,3,CONCRETE:8)
Block(-7,16,3,CONCRETE:8)
Block(-6,16,3,CONCRETE:15)
Block(-5,16,3,CONCRETE:0)
Block(-4,16,3,CONCRETE:15)
Block(-3,16,3,CONCRETE:15)
Block(-2,16,3,CONCRETE:15)
Block(-1,16,3,CONCRETE:4)
Block(0,16,3,CONCRETE:4)
Block(1,16,3,CONCRETE:15)
Block(2,16,3,CONCRETE:15)
Block(3,16,3,CONCRETE:15)
Block(4,16,3,CONCRETE:0)
Block(5,16,3,CONCRETE:15)
Block(6,16,3,CONCRETE:8)
Block(7,16,3,CONCRETE:8)
Block(-8,16,4,CONCRETE:8)
Block(-7,16,4,CONCRETE:8)
Block(-6,16,4,CONCRETE:15)
Block(-5,16,4,CONCRETE:0)
Block(-4,16,4,CONCRETE:15)
Block(-3,16,4,CONCRETE:15)
Block(-2,16,4,CONCRETE:15)
Block(-1,16,4,CONCRETE:4)
Block(0,16,4,CONCRETE:4)
Block(1,16,4,CONCRETE:15)
Block(2,16,4,CONCRETE:15)
Block(3,16,4,CONCRETE:15)
Block(4,16,4,CONCRETE:0)
Block(5,16,4,CONCRETE:15)
Block(6,16,4,CONCRETE:8)
Block(7,16,4,CONCRETE:8)
Block(-8,16,5,CONCRETE:8)
Block(-7,16,5,CONCRETE:8)
Block(-6,16,5,CONCRETE:15)
Block(-5,16,5,CONCRETE:0)
Block(-4,16,5,CONCRETE:15)
Block(-3,16,5,CONCRETE:15)
Block(-2,16,5,CONCRETE:15)
Block(-1,16,5,CONCRETE:4)
Block(0,16,5,CONCRETE:4)
Block(1,16,5,CONCRETE:15)
Block(2,16,5,CONCRETE:15)
Block(3,16,5,CONCRETE:15)
Block(4,16,5,CONCRETE:0)
Block(5,16,5,CONCRETE:15)
Block(6,16,5,CONCRETE:8)
Block(7,16,5,CONCRETE:8)
Block(-8,16,6,CONCRETE:8)
Block(-7,16,6,CONCRETE:8)
Block(-6,16,6,CONCRETE:15)
Block(-5,16,6,CONCRETE:0)
Block(-4,16,6,CONCRETE:15)
Block(-3,16,6,CONCRETE:15)
Block(-2,16,6,CONCRETE:15)
Block(-1,16,6,CONCRETE:4)
Block(0,16,6,CONCRETE:4)
Block(1,16,6,CONCRETE:15)
Block(2,16,6,CONCRETE:15)
Block(3,16,6,CONCRETE:15)
Block(4,16,6,CONCRETE:0)
Block(5,16,6,CONCRETE:15)
Block(6,16,6,CONCRETE:8)
Block(7,16,6,CONCRETE:8)
Block(-8,16,7,CONCRETE:8)
Block(-7,16,7,CONCRETE:8)
Block(-6,16,7,CONCRETE:15)
Block(-5,16,7,CONCRETE:0)
Block(-4,16,7,CONCRETE:15)
Block(-3,16,7,CONCRETE:15)
Block(-2,16,7,CONCRETE:15)
Block(-1,16,7,CONCRETE:4)
Block(0,16,7,CONCRETE:4)
Block(1,16,7,CONCRETE:15)
Block(2,16,7,CONCRETE:15)
Block(3,16,7,CONCRETE:15)
Block(4,16,7,CONCRETE:0)
Block(5,16,7,CONCRETE:15)
Block(6,16,7,CONCRETE:8)
Block(7,16,7,CONCRETE:8)
Block(-8,16,8,CONCRETE:8)
Block(-7,16,8,CONCRETE:8)
Block(-6,16,8,CONCRETE:15)
Block(-5,16,8,CONCRETE:0)
Block(-4,16,8,CONCRETE:15)
Block(-3,16,8,CONCRETE:15)
Block(-2,16,8,CONCRETE:15)
Block(-1,16,8,CONCRETE:4)
Block(0,16,8,CONCRETE:4)
Block(1,16,8,CONCRETE:15)
Block(2,16,8,CONCRETE:15)
Block(3,16,8,CONCRETE:15)
Block(4,16,8,CONCRETE:0)
Block(5,16,8,CONCRETE:15)
Block(6,16,8,CONCRETE:8)
Block(7,16,8,CONCRETE:8)
Block(-8,8,-7,CONCRETE:7)
Block(-8,8,-6,AIR:0)
Block(-8,8,-5,AIR:0)
Block(-8,8,-4,AIR:0)
Block(-8,8,-3,AIR:0)
Block(-8,8,-2,AIR:0)
Block(-8,8,-1,AIR:0)
Block(-8,8,0,AIR:0)
Block(-8,8,1,LEVER:4)
Block(-8,8,2,AIR:0)
Block(-8,8,3,CONCRETE:7)
Block(-8,8,4,CONCRETE:7)
Block(-8,8,5,CONCRETE:7)
Block(-8,8,6,CONCRETE:7)
Block(-8,8,7,CONCRETE:7)
Block(-8,8,8,CONCRETE:7)
Block(-8,9,-7,CONCRETE:7)
Block(-8,9,-6,AIR:0)
Block(-8,9,-5,AIR:0)
Block(-8,9,-4,AIR:0)
Block(-8,9,-3,CONCRETE:11)
Block(-8,9,-2,AIR:0)
Block(-8,9,-1,AIR:0)
Block(-8,9,0,AIR:0)
Block(-8,9,1,AIR:0)
Block(-8,9,2,REDSTONE_LAMP_OFF:0)
Block(-8,9,3,CONCRETE:7)
Block(-8,9,4,CONCRETE:7)
Block(-8,9,5,CONCRETE:7)
Block(-8,9,6,CONCRETE:7)
Block(-8,9,7,CONCRETE:7)
Block(-8,9,8,CONCRETE:7)
Block(-8,10,-7,CONCRETE:7)
Block(-8,10,-6,CONCRETE:7)
Block(-8,10,-5,CONCRETE:7)
Block(-8,10,-4,CONCRETE:7)
Block(-8,10,-3,CONCRETE:7)
Block(-8,10,-2,CONCRETE:7)
Block(-8,10,-1,CONCRETE:7)
Block(-8,10,0,CONCRETE:7)
Block(-8,10,1,CONCRETE:7)
Block(-8,10,2,CONCRETE:7)
Block(-8,10,3,CONCRETE:7)
Block(-8,10,4,CONCRETE:7)
Block(-8,10,5,CONCRETE:7)
Block(-8,10,6,CONCRETE:7)
Block(-8,10,7,CONCRETE:7)
Block(-8,10,8,CONCRETE:7)
Block(-8,11,-7,CONCRETE:7)
Block(-8,11,-6,CONCRETE:7)
Block(-8,11,-5,CONCRETE:7)
Block(-8,11,-4,CONCRETE:7)
Block(-8,11,-3,CONCRETE:7)
Block(-8,11,-2,CONCRETE:7)
Block(-8,11,-1,CONCRETE:7)
Block(-8,11,0,CONCRETE:7)
Block(-8,11,1,CONCRETE:7)
Block(-8,11,2,CONCRETE:7)
Block(-8,11,3,CONCRETE:7)
Block(-8,11,4,CONCRETE:7)
Block(-8,11,5,CONCRETE:7)
Block(-8,11,6,CONCRETE:7)
Block(-8,11,7,CONCRETE:7)
Block(-8,11,8,CONCRETE:7)
Block(-8,12,-7,CONCRETE:7)
Block(-8,12,-6,CONCRETE:7)
Block(-8,12,-5,CONCRETE:7)
Block(-8,12,-4,CONCRETE:7)
Block(-8,12,-3,CONCRETE:7)
Block(-8,12,-2,CONCRETE:7)
Block(-8,12,-1,CONCRETE:7)
Block(-8,12,0,CONCRETE:7)
Block(-8,12,1,CONCRETE:7)
Block(-8,12,2,CONCRETE:7)
Block(-8,12,3,CONCRETE:7)
Block(-8,12,4,CONCRETE:7)
Block(-8,12,5,CONCRETE:7)
Block(-8,12,6,CONCRETE:7)
Block(-8,12,7,CONCRETE:7)
Block(-8,12,8,CONCRETE:7)
Block(-8,13,-7,CONCRETE:7)
Block(-8,13,-6,AIR:0)
Block(-8,13,-5,AIR:0)
Block(-8,13,-4,CONCRETE:7)
Block(-8,13,-3,AIR:0)
Block(-8,13,-2,AIR:0)
Block(-8,13,-1,CONCRETE:7)
Block(-8,13,0,AIR:0)
Block(-8,13,1,LADDER:5)
Block(-8,13,2,CONCRETE:7)
Block(-8,13,3,AIR:0)
Block(-8,13,4,AIR:0)
Block(-8,13,5,CONCRETE:7)
Block(-8,13,6,AIR:0)
Block(-8,13,7,AIR:0)
Block(-8,13,8,CONCRETE:7)
Block(-7,8,-7,CONCRETE:7)
Block(-7,8,-6,CONCRETE:7)
Block(-7,8,-5,AIR:0)
Block(-7,8,-4,CONCRETE:7)
Block(-7,8,-3,AIR:0)
Block(-7,8,-2,CONCRETE:7)
Block(-7,8,-1,AIR:0)
Block(-7,8,0,CONCRETE:7)
Block(-7,8,1,AIR:0)
Block(-7,8,2,CONCRETE:7)
Block(-7,8,3,CONCRETE:7)
Block(-7,8,4,CONCRETE:7)
Block(-7,8,5,CONCRETE:7)
Block(-7,8,6,CONCRETE:7)
Block(-7,8,7,CONCRETE:7)
Block(-7,8,8,CONCRETE:7)
Block(-7,9,-7,CONCRETE:7)
Block(-7,9,-6,CONCRETE:7)
Block(-7,9,-5,AIR:0)
Block(-7,9,-4,CONCRETE:7)
Block(-7,9,-3,CONCRETE:11)
Block(-7,9,-2,CONCRETE:7)
Block(-7,9,-1,AIR:0)
Block(-7,9,0,CONCRETE:7)
Block(-7,9,1,AIR:0)
Block(-7,9,2,CONCRETE:7)
Block(-7,9,3,CONCRETE:7)
Block(-7,9,4,CONCRETE:7)
Block(-7,9,5,CONCRETE:7)
Block(-7,9,6,CONCRETE:7)
Block(-7,9,7,CONCRETE:7)
Block(-7,9,8,CONCRETE:7)
Block(-7,10,-7,CONCRETE:7)
Block(-7,10,-6,CONCRETE:7)
Block(-7,10,-5,CONCRETE:7)
Block(-7,10,-4,CONCRETE:7)
Block(-7,10,-3,CONCRETE:7)
Block(-7,10,-2,CONCRETE:7)
Block(-7,10,-1,CONCRETE:7)
Block(-7,10,0,CONCRETE:7)
Block(-7,10,1,CONCRETE:7)
Block(-7,10,2,CONCRETE:7)
Block(-7,10,3,CONCRETE:7)
Block(-7,10,4,CONCRETE:7)
Block(-7,10,5,CONCRETE:7)
Block(-7,10,6,CONCRETE:7)
Block(-7,10,7,CONCRETE:7)
Block(-7,10,8,CONCRETE:7)
Block(-7,11,-7,CONCRETE:7)
Block(-7,11,-6,CONCRETE:7)
Block(-7,11,-5,CONCRETE:7)
Block(-7,11,-4,CONCRETE:7)
Block(-7,11,-3,CONCRETE:7)
Block(-7,11,-2,CONCRETE:7)
Block(-7,11,-1,CONCRETE:7)
Block(-7,11,0,CONCRETE:7)
Block(-7,11,1,CONCRETE:7)
Block(-7,11,2,CONCRETE:7)
Block(-7,11,3,CONCRETE:7)
Block(-7,11,4,CONCRETE:7)
Block(-7,11,5,CONCRETE:7)
Block(-7,11,6,CONCRETE:7)
Block(-7,11,7,CONCRETE:7)
Block(-7,11,8,CONCRETE:7)
Block(-7,12,-7,SMOOTH_STAIRS:1)
Block(-7,12,-6,SMOOTH_STAIRS:1)
Block(-7,12,-5,SMOOTH_STAIRS:1)
Block(-7,12,-4,SMOOTH_STAIRS:1)
Block(-7,12,-3,SMOOTH_STAIRS:1)
Block(-7,12,-2,SMOOTH_STAIRS:1)
Block(-7,12,-1,SMOOTH_STAIRS:1)
Block(-7,12,0,SMOOTH_STAIRS:1)
Block(-7,12,1,SMOOTH_STAIRS:1)
Block(-7,12,2,SMOOTH_STAIRS:1)
Block(-7,12,3,SMOOTH_STAIRS:1)
Block(-7,12,4,SMOOTH_STAIRS:1)
Block(-7,12,5,SMOOTH_STAIRS:1)
Block(-7,12,6,SMOOTH_STAIRS:1)
Block(-7,12,7,SMOOTH_STAIRS:1)
Block(-7,12,8,SMOOTH_STAIRS:1)
Block(-7,13,-7,AIR:0)
Block(-7,13,-6,AIR:0)
Block(-7,13,-5,AIR:0)
Block(-7,13,-4,AIR:0)
Block(-7,13,-3,AIR:0)
Block(-7,13,-2,AIR:0)
Block(-7,13,-1,AIR:0)
Block(-7,13,0,AIR:0)
Block(-7,13,1,AIR:0)
Block(-7,13,2,AIR:0)
Block(-7,13,3,AIR:0)
Block(-7,13,4,AIR:0)
Block(-7,13,5,AIR:0)
Block(-7,13,6,AIR:0)
Block(-7,13,7,AIR:0)
Block(-7,13,8,AIR:0)
Block(-6,8,-7,CONCRETE:7)
Block(-6,8,-6,CONCRETE:7)
Block(-6,8,-5,CONCRETE:7)
Block(-6,8,-4,CONCRETE:7)
Block(-6,8,-3,CONCRETE:7)
Block(-6,8,-2,CONCRETE:7)
Block(-6,8,-1,CONCRETE:7)
Block(-6,8,0,CONCRETE:7)
Block(-6,8,1,CONCRETE:7)
Block(-6,8,2,CONCRETE:7)
Block(-6,8,3,CONCRETE:7)
Block(-6,8,4,CONCRETE:7)
Block(-6,8,5,CONCRETE:7)
Block(-6,8,6,CONCRETE:7)
Block(-6,8,7,CONCRETE:7)
Block(-6,8,8,CONCRETE:7)
Block(-6,9,-7,CONCRETE:7)
Block(-6,9,-6,CONCRETE:7)
Block(-6,9,-5,CONCRETE:7)
Block(-6,9,-4,CONCRETE:7)
Block(-6,9,-3,CONCRETE:7)
Block(-6,9,-2,CONCRETE:7)
Block(-6,9,-1,CONCRETE:7)
Block(-6,9,0,CONCRETE:7)
Block(-6,9,1,CONCRETE:7)
Block(-6,9,2,CONCRETE:7)
Block(-6,9,3,CONCRETE:7)
Block(-6,9,4,CONCRETE:7)
Block(-6,9,5,CONCRETE:7)
Block(-6,9,6,CONCRETE:7)
Block(-6,9,7,CONCRETE:7)
Block(-6,9,8,CONCRETE:7)
Block(-6,10,-7,CONCRETE:7)
Block(-6,10,-6,CONCRETE:7)
Block(-6,10,-5,CONCRETE:7)
Block(-6,10,-4,CONCRETE:7)
Block(-6,10,-3,CONCRETE:7)
Block(-6,10,-2,CONCRETE:7)
Block(-6,10,-1,CONCRETE:7)
Block(-6,10,0,CONCRETE:7)
Block(-6,10,1,CONCRETE:7)
Block(-6,10,2,CONCRETE:7)
Block(-6,10,3,CONCRETE:7)
Block(-6,10,4,CONCRETE:7)
Block(-6,10,5,CONCRETE:7)
Block(-6,10,6,CONCRETE:7)
Block(-6,10,7,CONCRETE:7)
Block(-6,10,8,CONCRETE:7)
Block(-6,11,-7,STATIONARY_WATER:0)
Block(-6,11,-6,STATIONARY_WATER:0)
Block(-6,11,-5,STATIONARY_WATER:0)
Block(-6,11,-4,STATIONARY_WATER:0)
Block(-6,11,-3,STATIONARY_WATER:0)
Block(-6,11,-2,STATIONARY_WATER:0)
Block(-6,11,-1,STATIONARY_WATER:0)
Block(-6,11,0,STATIONARY_WATER:0)
Block(-6,11,1,STATIONARY_WATER:0)
Block(-6,11,2,STATIONARY_WATER:0)
Block(-6,11,3,STATIONARY_WATER:0)
Block(-6,11,4,STATIONARY_WATER:0)
Block(-6,11,5,STATIONARY_WATER:0)
Block(-6,11,6,STATIONARY_WATER:0)
Block(-6,11,7,STATIONARY_WATER:0)
Block(-6,11,8,STATIONARY_WATER:0)
Block(-6,12,-7,AIR:0)
Block(-6,12,-6,AIR:0)
Block(-6,12,-5,AIR:0)
Block(-6,12,-4,AIR:0)
Block(-6,12,-3,AIR:0)
Block(-6,12,-2,AIR:0)
Block(-6,12,-1,AIR:0)
Block(-6,12,0,AIR:0)
Block(-6,12,1,AIR:0)
Block(-6,12,2,AIR:0)
Block(-6,12,3,AIR:0)
Block(-6,12,4,AIR:0)
Block(-6,12,5,AIR:0)
Block(-6,12,6,AIR:0)
Block(-6,12,7,AIR:0)
Block(-6,12,8,AIR:0)
Block(-6,13,-7,AIR:0)
Block(-6,13,-6,AIR:0)
Block(-6,13,-5,AIR:0)
Block(-6,13,-4,AIR:0)
Block(-6,13,-3,AIR:0)
Block(-6,13,-2,AIR:0)
Block(-6,13,-1,AIR:0)
Block(-6,13,0,AIR:0)
Block(-6,13,1,AIR:0)
Block(-6,13,2,AIR:0)
Block(-6,13,3,AIR:0)
Block(-6,13,4,AIR:0)
Block(-6,13,5,AIR:0)
Block(-6,13,6,AIR:0)
Block(-6,13,7,AIR:0)
Block(-6,13,8,AIR:0)
Block(-5,8,-7,CONCRETE:7)
Block(-5,8,-6,CONCRETE:7)
Block(-5,8,-5,CONCRETE:7)
Block(-5,8,-4,CONCRETE:7)
Block(-5,8,-3,CONCRETE:7)
Block(-5,8,-2,CONCRETE:7)
Block(-5,8,-1,CONCRETE:7)
Block(-5,8,0,CONCRETE:7)
Block(-5,8,1,CONCRETE:7)
Block(-5,8,2,CONCRETE:7)
Block(-5,8,3,CONCRETE:7)
Block(-5,8,4,CONCRETE:7)
Block(-5,8,5,CONCRETE:7)
Block(-5,8,6,CONCRETE:7)
Block(-5,8,7,CONCRETE:7)
Block(-5,8,8,CONCRETE:7)
Block(-5,9,-7,CONCRETE:7)
Block(-5,9,-6,CONCRETE:7)
Block(-5,9,-5,CONCRETE:7)
Block(-5,9,-4,CONCRETE:7)
Block(-5,9,-3,CONCRETE:7)
Block(-5,9,-2,CONCRETE:7)
Block(-5,9,-1,CONCRETE:7)
Block(-5,9,0,CONCRETE:7)
Block(-5,9,1,CONCRETE:7)
Block(-5,9,2,CONCRETE:7)
Block(-5,9,3,CONCRETE:7)
Block(-5,9,4,CONCRETE:7)
Block(-5,9,5,CONCRETE:7)
Block(-5,9,6,CONCRETE:7)
Block(-5,9,7,CONCRETE:7)
Block(-5,9,8,CONCRETE:7)
Block(-5,10,-7,CONCRETE:7)
Block(-5,10,-6,CONCRETE:7)
Block(-5,10,-5,CONCRETE:7)
Block(-5,10,-4,CONCRETE:7)
Block(-5,10,-3,CONCRETE:7)
Block(-5,10,-2,CONCRETE:7)
Block(-5,10,-1,CONCRETE:7)
Block(-5,10,0,CONCRETE:7)
Block(-5,10,1,CONCRETE:7)
Block(-5,10,2,CONCRETE:7)
Block(-5,10,3,CONCRETE:7)
Block(-5,10,4,CONCRETE:7)
Block(-5,10,5,CONCRETE:7)
Block(-5,10,6,CONCRETE:7)
Block(-5,10,7,CONCRETE:7)
Block(-5,10,8,CONCRETE:7)
Block(-5,11,-7,CONCRETE:7)
Block(-5,11,-6,CONCRETE:7)
Block(-5,11,-5,CONCRETE:7)
Block(-5,11,-4,CONCRETE:7)
Block(-5,11,-3,CONCRETE:7)
Block(-5,11,-2,CONCRETE:7)
Block(-5,11,-1,CONCRETE:7)
Block(-5,11,0,CONCRETE:7)
Block(-5,11,1,CONCRETE:7)
Block(-5,11,2,CONCRETE:7)
Block(-5,11,3,CONCRETE:7)
Block(-5,11,4,CONCRETE:7)
Block(-5,11,5,CONCRETE:7)
Block(-5,11,6,CONCRETE:7)
Block(-5,11,7,CONCRETE:7)
Block(-5,11,8,CONCRETE:7)
Block(-5,12,-7,CONCRETE:7)
Block(-5,12,-6,CONCRETE:7)
Block(-5,12,-5,CONCRETE:7)
Block(-5,12,-4,CONCRETE:7)
Block(-5,12,-3,CONCRETE:7)
Block(-5,12,-2,CONCRETE:7)
Block(-5,12,-1,CONCRETE:7)
Block(-5,12,0,CONCRETE:7)
Block(-5,12,1,CONCRETE:7)
Block(-5,12,2,CONCRETE:7)
Block(-5,12,3,CONCRETE:7)
Block(-5,12,4,CONCRETE:7)
Block(-5,12,5,CONCRETE:7)
Block(-5,12,6,CONCRETE:7)
Block(-5,12,7,CONCRETE:7)
Block(-5,12,8,CONCRETE:7)
Block(-5,13,-7,CONCRETE:7)
Block(-5,13,-6,CONCRETE:7)
Block(-5,13,-5,CONCRETE:7)
Block(-5,13,-4,CONCRETE:7)
Block(-5,13,-3,CONCRETE:7)
Block(-5,13,-2,CONCRETE:7)
Block(-5,13,-1,CONCRETE:7)
Block(-5,13,0,CONCRETE:7)
Block(-5,13,1,CONCRETE:7)
Block(-5,13,2,CONCRETE:7)
Block(-5,13,3,CONCRETE:7)
Block(-5,13,4,CONCRETE:7)
Block(-5,13,5,CONCRETE:7)
Block(-5,13,6,CONCRETE:7)
Block(-5,13,7,CONCRETE:7)
Block(-5,13,8,CONCRETE:7)
Block(-4,8,-7,CONCRETE:7)
Block(-4,8,-6,CONCRETE:7)
Block(-4,8,-5,CONCRETE:7)
Block(-4,8,-4,CONCRETE:7)
Block(-4,8,-3,CONCRETE:7)
Block(-4,8,-2,CONCRETE:7)
Block(-4,8,-1,CONCRETE:7)
Block(-4,8,0,CONCRETE:7)
Block(-4,8,1,CONCRETE:7)
Block(-4,8,2,CONCRETE:7)
Block(-4,8,3,CONCRETE:7)
Block(-4,8,4,CONCRETE:7)
Block(-4,8,5,CONCRETE:7)
Block(-4,8,6,CONCRETE:7)
Block(-4,8,7,CONCRETE:7)
Block(-4,8,8,CONCRETE:7)
Block(-4,9,-7,CONCRETE:7)
Block(-4,9,-6,CONCRETE:7)
Block(-4,9,-5,CONCRETE:7)
Block(-4,9,-4,CONCRETE:7)
Block(-4,9,-3,CONCRETE:7)
Block(-4,9,-2,CONCRETE:7)
Block(-4,9,-1,CONCRETE:7)
Block(-4,9,0,CONCRETE:7)
Block(-4,9,1,CONCRETE:7)
Block(-4,9,2,CONCRETE:7)
Block(-4,9,3,CONCRETE:7)
Block(-4,9,4,CONCRETE:7)
Block(-4,9,5,CONCRETE:7)
Block(-4,9,6,CONCRETE:7)
Block(-4,9,7,CONCRETE:7)
Block(-4,9,8,CONCRETE:7)
Block(-4,10,-7,CONCRETE:7)
Block(-4,10,-6,CONCRETE:7)
Block(-4,10,-5,CONCRETE:7)
Block(-4,10,-4,CONCRETE:7)
Block(-4,10,-3,CONCRETE:7)
Block(-4,10,-2,CONCRETE:7)
Block(-4,10,-1,CONCRETE:7)
Block(-4,10,0,CONCRETE:7)
Block(-4,10,1,CONCRETE:7)
Block(-4,10,2,CONCRETE:7)
Block(-4,10,3,CONCRETE:7)
Block(-4,10,4,CONCRETE:7)
Block(-4,10,5,CONCRETE:7)
Block(-4,10,6,CONCRETE:7)
Block(-4,10,7,CONCRETE:7)
Block(-4,10,8,CONCRETE:7)
Block(-4,11,-7,CONCRETE:7)
Block(-4,11,-6,CONCRETE:7)
Block(-4,11,-5,CONCRETE:7)
Block(-4,11,-4,CONCRETE:7)
Block(-4,11,-3,CONCRETE:7)
Block(-4,11,-2,CONCRETE:7)
Block(-4,11,-1,CONCRETE:7)
Block(-4,11,0,CONCRETE:7)
Block(-4,11,1,CONCRETE:7)
Block(-4,11,2,CONCRETE:7)
Block(-4,11,3,CONCRETE:7)
Block(-4,11,4,CONCRETE:7)
Block(-4,11,5,CONCRETE:7)
Block(-4,11,6,CONCRETE:7)
Block(-4,11,7,CONCRETE:7)
Block(-4,11,8,CONCRETE:7)
Block(-4,12,-7,CONCRETE:7)
Block(-4,12,-6,CONCRETE:7)
Block(-4,12,-5,CONCRETE:7)
Block(-4,12,-4,CONCRETE:7)
Block(-4,12,-3,CONCRETE:7)
Block(-4,12,-2,CONCRETE:7)
Block(-4,12,-1,CONCRETE:7)
Block(-4,12,0,CONCRETE:7)
Block(-4,12,1,CONCRETE:7)
Block(-4,12,2,CONCRETE:7)
Block(-4,12,3,CONCRETE:7)
Block(-4,12,4,CONCRETE:7)
Block(-4,12,5,CONCRETE:7)
Block(-4,12,6,CONCRETE:7)
Block(-4,12,7,CONCRETE:7)
Block(-4,12,8,CONCRETE:7)
Block(-4,13,-7,CONCRETE:7)
Block(-4,13,-6,CONCRETE:7)
Block(-4,13,-5,CONCRETE:7)
Block(-4,13,-4,CONCRETE:7)
Block(-4,13,-3,CONCRETE:7)
Block(-4,13,-2,CONCRETE:7)
Block(-4,13,-1,CONCRETE:7)
Block(-4,13,0,CONCRETE:7)
Block(-4,13,1,CONCRETE:7)
Block(-4,13,2,CONCRETE:7)
Block(-4,13,3,CONCRETE:7)
Block(-4,13,4,CONCRETE:7)
Block(-4,13,5,CONCRETE:7)
Block(-4,13,6,CONCRETE:7)
Block(-4,13,7,CONCRETE:7)
Block(-4,13,8,CONCRETE:7)
Block(-3,8,-7,AIR:0)
Block(-3,8,-6,AIR:0)
Block(-3,8,-5,AIR:0)
Block(-3,8,-4,AIR:0)
Block(-3,8,-3,AIR:0)
Block(-3,8,-2,AIR:0)
Block(-3,8,-1,AIR:0)
Block(-3,8,0,AIR:0)
Block(-3,8,1,AIR:0)
Block(-3,8,2,AIR:0)
Block(-3,8,3,AIR:0)
Block(-3,8,4,AIR:0)
Block(-3,8,5,AIR:0)
Block(-3,8,6,AIR:0)
Block(-3,8,7,AIR:0)
Block(-3,8,8,AIR:0)
Block(-3,9,-7,AIR:0)
Block(-3,9,-6,AIR:0)
Block(-3,9,-5,AIR:0)
Block(-3,9,-4,AIR:0)
Block(-3,9,-3,AIR:0)
Block(-3,9,-2,AIR:0)
Block(-3,9,-1,AIR:0)
Block(-3,9,0,AIR:0)
Block(-3,9,1,AIR:0)
Block(-3,9,2,AIR:0)
Block(-3,9,3,AIR:0)
Block(-3,9,4,AIR:0)
Block(-3,9,5,AIR:0)
Block(-3,9,6,AIR:0)
Block(-3,9,7,AIR:0)
Block(-3,9,8,AIR:0)
Block(-3,10,-7,AIR:0)
Block(-3,10,-6,AIR:0)
Block(-3,10,-5,AIR:0)
Block(-3,10,-4,AIR:0)
Block(-3,10,-3,AIR:0)
Block(-3,10,-2,AIR:0)
Block(-3,10,-1,AIR:0)
Block(-3,10,0,AIR:0)
Block(-3,10,1,AIR:0)
Block(-3,10,2,AIR:0)
Block(-3,10,3,AIR:0)
Block(-3,10,4,AIR:0)
Block(-3,10,5,AIR:0)
Block(-3,10,6,AIR:0)
Block(-3,10,7,AIR:0)
Block(-3,10,8,AIR:0)
Block(-3,11,-7,CONCRETE:7)
Block(-3,11,-6,CONCRETE:7)
Block(-3,11,-5,CONCRETE:7)
Block(-3,11,-4,CONCRETE:7)
Block(-3,11,-3,CONCRETE:7)
Block(-3,11,-2,CONCRETE:7)
Block(-3,11,-1,CONCRETE:7)
Block(-3,11,0,CONCRETE:7)
Block(-3,11,1,CONCRETE:7)
Block(-3,11,2,CONCRETE:7)
Block(-3,11,3,CONCRETE:7)
Block(-3,11,4,CONCRETE:7)
Block(-3,11,5,CONCRETE:7)
Block(-3,11,6,CONCRETE:7)
Block(-3,11,7,CONCRETE:7)
Block(-3,11,8,CONCRETE:7)
Block(-3,12,-7,CONCRETE:7)
Block(-3,12,-6,CONCRETE:7)
Block(-3,12,-5,CONCRETE:7)
Block(-3,12,-4,CONCRETE:7)
Block(-3,12,-3,CONCRETE:7)
Block(-3,12,-2,CONCRETE:7)
Block(-3,12,-1,CONCRETE:7)
Block(-3,12,0,CONCRETE:7)
Block(-3,12,1,CONCRETE:7)
Block(-3,12,2,CONCRETE:7)
Block(-3,12,3,CONCRETE:7)
Block(-3,12,4,CONCRETE:7)
Block(-3,12,5,CONCRETE:7)
Block(-3,12,6,CONCRETE:7)
Block(-3,12,7,CONCRETE:7)
Block(-3,12,8,CONCRETE:7)
Block(-3,13,-7,CONCRETE:7)
Block(-3,13,-6,CONCRETE:7)
Block(-3,13,-5,CONCRETE:7)
Block(-3,13,-4,CONCRETE:7)
Block(-3,13,-3,CONCRETE:7)
Block(-3,13,-2,CONCRETE:7)
Block(-3,13,-1,CONCRETE:7)
Block(-3,13,0,CONCRETE:7)
Block(-3,13,1,CONCRETE:7)
Block(-3,13,2,CONCRETE:7)
Block(-3,13,3,CONCRETE:7)
Block(-3,13,4,CONCRETE:7)
Block(-3,13,5,CONCRETE:7)
Block(-3,13,6,CONCRETE:7)
Block(-3,13,7,CONCRETE:7)
Block(-3,13,8,CONCRETE:7)
Block(-2,8,-7,AIR:0)
Block(-2,8,-6,AIR:0)
Block(-2,8,-5,CONCRETE:7)
Block(-2,8,-4,AIR:0)
Block(-2,8,-3,AIR:0)
Block(-2,8,-2,AIR:0)
Block(-2,8,-1,AIR:0)
Block(-2,8,0,CONCRETE:7)
Block(-2,8,1,AIR:0)
Block(-2,8,2,AIR:0)
Block(-2,8,3,AIR:0)
Block(-2,8,4,AIR:0)
Block(-2,8,5,AIR:0)
Block(-2,8,6,CONCRETE:7)
Block(-2,8,7,AIR:0)
Block(-2,8,8,AIR:0)
Block(-2,9,-7,AIR:0)
Block(-2,9,-6,AIR:0)
Block(-2,9,-5,CONCRETE:7)
Block(-2,9,-4,AIR:0)
Block(-2,9,-3,AIR:0)
Block(-2,9,-2,AIR:0)
Block(-2,9,-1,AIR:0)
Block(-2,9,0,CONCRETE:7)
Block(-2,9,1,AIR:0)
Block(-2,9,2,AIR:0)
Block(-2,9,3,AIR:0)
Block(-2,9,4,AIR:0)
Block(-2,9,5,AIR:0)
Block(-2,9,6,CONCRETE:7)
Block(-2,9,7,AIR:0)
Block(-2,9,8,AIR:0)
Block(-2,10,-7,STEP:13)
Block(-2,10,-6,SMOOTH_STAIRS:6)
Block(-2,10,-5,CONCRETE:7)
Block(-2,10,-4,SMOOTH_STAIRS:7)
Block(-2,10,-3,STEP:13)
Block(-2,10,-2,STEP:13)
Block(-2,10,-1,STEP:13)
Block(-2,10,0,CONCRETE:7)
Block(-2,10,1,SMOOTH_STAIRS:7)
Block(-2,10,2,STEP:13)
Block(-2,10,3,STEP:13)
Block(-2,10,4,STEP:13)
Block(-2,10,5,SMOOTH_STAIRS:6)
Block(-2,10,6,CONCRETE:7)
Block(-2,10,7,SMOOTH_STAIRS:7)
Block(-2,10,8,STEP:13)
Block(-2,11,-7,CONCRETE:7)
Block(-2,11,-6,CONCRETE:7)
Block(-2,11,-5,CONCRETE:7)
Block(-2,11,-4,CONCRETE:7)
Block(-2,11,-3,CONCRETE:7)
Block(-2,11,-2,CONCRETE:7)
Block(-2,11,-1,CONCRETE:7)
Block(-2,11,0,CONCRETE:7)
Block(-2,11,1,CONCRETE:7)
Block(-2,11,2,CONCRETE:7)
Block(-2,11,3,CONCRETE:7)
Block(-2,11,4,CONCRETE:7)
Block(-2,11,5,CONCRETE:7)
Block(-2,11,6,CONCRETE:7)
Block(-2,11,7,CONCRETE:7)
Block(-2,11,8,CONCRETE:7)
Block(-2,12,-7,CONCRETE:7)
Block(-2,12,-6,CONCRETE:7)
Block(-2,12,-5,CONCRETE:7)
Block(-2,12,-4,CONCRETE:7)
Block(-2,12,-3,CONCRETE:7)
Block(-2,12,-2,CONCRETE:7)
Block(-2,12,-1,CONCRETE:7)
Block(-2,12,0,CONCRETE:7)
Block(-2,12,1,CONCRETE:7)
Block(-2,12,2,CONCRETE:7)
Block(-2,12,3,CONCRETE:7)
Block(-2,12,4,CONCRETE:7)
Block(-2,12,5,CONCRETE:7)
Block(-2,12,6,CONCRETE:7)
Block(-2,12,7,CONCRETE:7)
Block(-2,12,8,CONCRETE:7)
Block(-2,13,-7,CONCRETE:7)
Block(-2,13,-6,CONCRETE:7)
Block(-2,13,-5,CONCRETE:7)
Block(-2,13,-4,CONCRETE:7)
Block(-2,13,-3,CONCRETE:7)
Block(-2,13,-2,CONCRETE:7)
Block(-2,13,-1,CONCRETE:7)
Block(-2,13,0,CONCRETE:7)
Block(-2,13,1,CONCRETE:7)
Block(-2,13,2,CONCRETE:7)
Block(-2,13,3,CONCRETE:7)
Block(-2,13,4,CONCRETE:7)
Block(-2,13,5,CONCRETE:7)
Block(-2,13,6,CONCRETE:7)
Block(-2,13,7,CONCRETE:7)
Block(-2,13,8,CONCRETE:7)
Block(-1,4,-6,REDSTONE_BLOCK:0)
Block(-1,4,-5,REDSTONE_BLOCK:0)
Block(-1,4,-4,REDSTONE_BLOCK:0)
Block(-1,4,-3,REDSTONE_BLOCK:0)
Block(-1,4,-2,REDSTONE_BLOCK:0)
Block(-1,4,-1,REDSTONE_BLOCK:0)
Block(-1,4,0,REDSTONE_BLOCK:0)
Block(-1,4,1,REDSTONE_BLOCK:0)
Block(-1,4,2,REDSTONE_BLOCK:0)
Block(-1,4,3,REDSTONE_BLOCK:0)
Block(-1,4,4,REDSTONE_BLOCK:0)
Block(-1,4,5,REDSTONE_BLOCK:0)
Block(-1,4,6,REDSTONE_BLOCK:0)
Block(-1,4,7,REDSTONE_BLOCK:0)
Block(-1,4,8,REDSTONE_BLOCK:0)
Block(-1,5,-6,POWERED_RAIL:8)
Block(-1,5,-5,POWERED_RAIL:8)
Block(-1,5,-4,POWERED_RAIL:8)
Block(-1,5,-3,POWERED_RAIL:8)
Block(-1,5,-2,POWERED_RAIL:8)
Block(-1,5,-1,POWERED_RAIL:8)
Block(-1,5,0,POWERED_RAIL:8)
Block(-1,5,1,POWERED_RAIL:8)
Block(-1,5,2,POWERED_RAIL:8)
Block(-1,5,3,POWERED_RAIL:8)
Block(-1,5,4,POWERED_RAIL:8)
Block(-1,5,5,POWERED_RAIL:8)
Block(-1,5,6,POWERED_RAIL:8)
Block(-1,5,7,POWERED_RAIL:8)
Block(-1,5,8,POWERED_RAIL:8)
Block(-1,7,-6,AIR:0)
Block(-1,7,-5,AIR:0)
Block(-1,7,-4,AIR:0)
Block(-1,7,-3,AIR:0)
Block(-1,7,-2,AIR:0)
Block(-1,7,-1,AIR:0)
Block(-1,7,0,AIR:0)
Block(-1,7,1,AIR:0)
Block(-1,7,2,AIR:0)
Block(-1,7,3,AIR:0)
Block(-1,7,4,AIR:0)
Block(-1,7,5,AIR:0)
Block(-1,7,6,AIR:0)
Block(-1,7,7,AIR:0)
Block(-1,7,8,AIR:0)
Block(-1,8,-7,AIR:0)
Block(-1,8,-6,AIR:0)
Block(-1,8,-5,AIR:0)
Block(-1,8,-4,AIR:0)
Block(-1,8,-3,AIR:0)
Block(-1,8,-2,AIR:0)
Block(-1,8,-1,AIR:0)
Block(-1,8,0,AIR:0)
Block(-1,8,1,AIR:0)
Block(-1,8,2,AIR:0)
Block(-1,8,3,AIR:0)
Block(-1,8,4,AIR:0)
Block(-1,8,5,AIR:0)
Block(-1,8,6,AIR:0)
Block(-1,8,7,AIR:0)
Block(-1,8,8,AIR:0)
Block(-1,9,-7,AIR:0)
Block(-1,9,-6,AIR:0)
Block(-1,9,-5,AIR:0)
Block(-1,9,-4,AIR:0)
Block(-1,9,-3,AIR:0)
Block(-1,9,-2,AIR:0)
Block(-1,9,-1,AIR:0)
Block(-1,9,0,AIR:0)
Block(-1,9,1,AIR:0)
Block(-1,9,2,AIR:0)
Block(-1,9,3,AIR:0)
Block(-1,9,4,AIR:0)
Block(-1,9,5,AIR:0)
Block(-1,9,6,AIR:0)
Block(-1,9,7,AIR:0)
Block(-1,9,8,AIR:0)
Block(-1,10,-7,AIR:0)
Block(-1,10,-6,AIR:0)
Block(-1,10,-5,STEP:13)
Block(-1,10,-4,AIR:0)
Block(-1,10,-3,AIR:0)
Block(-1,10,-2,AIR:0)
Block(-1,10,-1,AIR:0)
Block(-1,10,0,STEP:13)
Block(-1,10,1,AIR:0)
Block(-1,10,2,AIR:0)
Block(-1,10,3,AIR:0)
Block(-1,10,4,AIR:0)
Block(-1,10,5,AIR:0)
Block(-1,10,6,STEP:13)
Block(-1,10,7,AIR:0)
Block(-1,10,8,AIR:0)
Block(-1,11,-7,AIR:0)
Block(-1,11,-6,AIR:0)
Block(-1,11,-5,CONCRETE:7)
Block(-1,11,-4,AIR:0)
Block(-1,11,-3,AIR:0)
Block(-1,11,-2,AIR:0)
Block(-1,11,-1,AIR:0)
Block(-1,11,0,CONCRETE:7)
Block(-1,11,1,AIR:0)
Block(-1,11,2,AIR:0)
Block(-1,11,3,AIR:0)
Block(-1,11,4,AIR:0)
Block(-1,11,5,AIR:0)
Block(-1,11,6,CONCRETE:7)
Block(-1,11,7,AIR:0)
Block(-1,11,8,AIR:0)
Block(-1,12,-7,AIR:0)
Block(-1,12,-6,AIR:0)
Block(-1,12,-5,AIR:0)
Block(-1,12,-4,AIR:0)
Block(-1,12,-3,AIR:0)
Block(-1,12,-2,AIR:0)
Block(-1,12,-1,AIR:0)
Block(-1,12,0,AIR:0)
Block(-1,12,1,AIR:0)
Block(-1,12,2,AIR:0)
Block(-1,12,3,AIR:0)
Block(-1,12,4,AIR:0)
Block(-1,12,5,AIR:0)
Block(-1,12,6,AIR:0)
Block(-1,12,7,AIR:0)
Block(-1,12,8,AIR:0)
Block(-1,13,-7,AIR:0)
Block(-1,13,-6,AIR:0)
Block(-1,13,-5,AIR:0)
Block(-1,13,-4,AIR:0)
Block(-1,13,-3,AIR:0)
Block(-1,13,-2,AIR:0)
Block(-1,13,-1,AIR:0)
Block(-1,13,0,AIR:0)
Block(-1,13,1,AIR:0)
Block(-1,13,2,AIR:0)
Block(-1,13,3,AIR:0)
Block(-1,13,4,AIR:0)
Block(-1,13,5,AIR:0)
Block(-1,13,6,AIR:0)
Block(-1,13,7,AIR:0)
Block(-1,13,8,AIR:0)
Block(0,8,-7,AIR:0)
Block(0,8,-6,AIR:0)
Block(0,8,-5,AIR:0)
Block(0,8,-4,AIR:0)
Block(0,8,-3,AIR:0)
Block(0,8,-2,AIR:0)
Block(0,8,-1,AIR:0)
Block(0,8,0,AIR:0)
Block(0,8,1,AIR:0)
Block(0,8,2,AIR:0)
Block(0,8,3,AIR:0)
Block(0,8,4,AIR:0)
Block(0,8,5,AIR:0)
Block(0,8,6,AIR:0)
Block(0,8,7,AIR:0)
Block(0,8,8,AIR:0)
Block(0,9,-7,AIR:0)
Block(0,9,-6,AIR:0)
Block(0,9,-5,AIR:0)
Block(0,9,-4,AIR:0)
Block(0,9,-3,AIR:0)
Block(0,9,-2,AIR:0)
Block(0,9,-1,AIR:0)
Block(0,9,0,AIR:0)
Block(0,9,1,AIR:0)
Block(0,9,2,AIR:0)
Block(0,9,3,AIR:0)
Block(0,9,4,AIR:0)
Block(0,9,5,AIR:0)
Block(0,9,6,AIR:0)
Block(0,9,7,AIR:0)
Block(0,9,8,AIR:0)
Block(0,10,-7,AIR:0)
Block(0,10,-6,AIR:0)
Block(0,10,-5,STEP:13)
Block(0,10,-4,AIR:0)
Block(0,10,-3,AIR:0)
Block(0,10,-2,AIR:0)
Block(0,10,-1,AIR:0)
Block(0,10,0,STEP:13)
Block(0,10,1,AIR:0)
Block(0,10,2,AIR:0)
Block(0,10,3,AIR:0)
Block(0,10,4,AIR:0)
Block(0,10,5,AIR:0)
Block(0,10,6,STEP:13)
Block(0,10,7,AIR:0)
Block(0,10,8,AIR:0)
Block(0,11,-7,AIR:0)
Block(0,11,-6,AIR:0)
Block(0,11,-5,CONCRETE:7)
Block(0,11,-4,AIR:0)
Block(0,11,-3,AIR:0)
Block(0,11,-2,AIR:0)
Block(0,11,-1,AIR:0)
Block(0,11,0,CONCRETE:7)
Block(0,11,1,AIR:0)
Block(0,11,2,AIR:0)
Block(0,11,3,AIR:0)
Block(0,11,4,AIR:0)
Block(0,11,5,AIR:0)
Block(0,11,6,CONCRETE:7)
Block(0,11,7,AIR:0)
Block(0,11,8,AIR:0)
Block(0,12,-7,AIR:0)
Block(0,12,-6,AIR:0)
Block(0,12,-5,AIR:0)
Block(0,12,-4,AIR:0)
Block(0,12,-3,AIR:0)
Block(0,12,-2,AIR:0)
Block(0,12,-1,AIR:0)
Block(0,12,0,AIR:0)
Block(0,12,1,AIR:0)
Block(0,12,2,AIR:0)
Block(0,12,3,AIR:0)
Block(0,12,4,AIR:0)
Block(0,12,5,AIR:0)
Block(0,12,6,AIR:0)
Block(0,12,7,AIR:0)
Block(0,12,8,AIR:0)
Block(0,13,-7,AIR:0)
Block(0,13,-6,AIR:0)
Block(0,13,-5,AIR:0)
Block(0,13,-4,AIR:0)
Block(0,13,-3,AIR:0)
Block(0,13,-2,AIR:0)
Block(0,13,-1,AIR:0)
Block(0,13,0,AIR:0)
Block(0,13,1,AIR:0)
Block(0,13,2,AIR:0)
Block(0,13,3,AIR:0)
Block(0,13,4,AIR:0)
Block(0,13,5,AIR:0)
Block(0,13,6,AIR:0)
Block(0,13,7,AIR:0)
Block(0,13,8,AIR:0)
Block(1,8,-7,AIR:0)
Block(1,8,-6,AIR:0)
Block(1,8,-5,AIR:0)
Block(1,8,-4,AIR:0)
Block(1,8,-3,AIR:0)
Block(1,8,-2,AIR:0)
Block(1,8,-1,AIR:0)
Block(1,8,0,AIR:0)
Block(1,8,1,AIR:0)
Block(1,8,2,AIR:0)
Block(1,8,3,AIR:0)
Block(1,8,4,AIR:0)
Block(1,8,5,AIR:0)
Block(1,8,6,AIR:0)
Block(1,8,7,AIR:0)
Block(1,8,8,AIR:0)
Block(1,9,-7,AIR:0)
Block(1,9,-6,AIR:0)
Block(1,9,-5,AIR:0)
Block(1,9,-4,AIR:0)
Block(1,9,-3,AIR:0)
Block(1,9,-2,AIR:0)
Block(1,9,-1,AIR:0)
Block(1,9,0,AIR:0)
Block(1,9,1,AIR:0)
Block(1,9,2,AIR:0)
Block(1,9,3,AIR:0)
Block(1,9,4,AIR:0)
Block(1,9,5,AIR:0)
Block(1,9,6,AIR:0)
Block(1,9,7,AIR:0)
Block(1,9,8,AIR:0)
Block(1,10,-7,AIR:0)
Block(1,10,-6,AIR:0)
Block(1,10,-5,STEP:13)
Block(1,10,-4,AIR:0)
Block(1,10,-3,AIR:0)
Block(1,10,-2,AIR:0)
Block(1,10,-1,AIR:0)
Block(1,10,0,STEP:13)
Block(1,10,1,AIR:0)
Block(1,10,2,AIR:0)
Block(1,10,3,AIR:0)
Block(1,10,4,AIR:0)
Block(1,10,5,AIR:0)
Block(1,10,6,STEP:13)
Block(1,10,7,AIR:0)
Block(1,10,8,AIR:0)
Block(1,11,-7,AIR:0)
Block(1,11,-6,AIR:0)
Block(1,11,-5,CONCRETE:7)
Block(1,11,-4,AIR:0)
Block(1,11,-3,AIR:0)
Block(1,11,-2,AIR:0)
Block(1,11,-1,AIR:0)
Block(1,11,0,CONCRETE:7)
Block(1,11,1,AIR:0)
Block(1,11,2,AIR:0)
Block(1,11,3,AIR:0)
Block(1,11,4,AIR:0)
Block(1,11,5,AIR:0)
Block(1,11,6,CONCRETE:7)
Block(1,11,7,AIR:0)
Block(1,11,8,AIR:0)
Block(1,12,-7,AIR:0)
Block(1,12,-6,AIR:0)
Block(1,12,-5,AIR:0)
Block(1,12,-4,AIR:0)
Block(1,12,-3,AIR:0)
Block(1,12,-2,AIR:0)
Block(1,12,-1,AIR:0)
Block(1,12,0,AIR:0)
Block(1,12,1,AIR:0)
Block(1,12,2,AIR:0)
Block(1,12,3,AIR:0)
Block(1,12,4,AIR:0)
Block(1,12,5,AIR:0)
Block(1,12,6,AIR:0)
Block(1,12,7,AIR:0)
Block(1,12,8,AIR:0)
Block(1,13,-7,AIR:0)
Block(1,13,-6,AIR:0)
Block(1,13,-5,AIR:0)
Block(1,13,-4,AIR:0)
Block(1,13,-3,AIR:0)
Block(1,13,-2,AIR:0)
Block(1,13,-1,AIR:0)
Block(1,13,0,AIR:0)
Block(1,13,1,AIR:0)
Block(1,13,2,AIR:0)
Block(1,13,3,AIR:0)
Block(1,13,4,AIR:0)
Block(1,13,5,AIR:0)
Block(1,13,6,AIR:0)
Block(1,13,7,AIR:0)
Block(1,13,8,AIR:0)
Block(2,8,-7,AIR:0)
Block(2,8,-6,AIR:0)
Block(2,8,-5,AIR:0)
Block(2,8,-4,AIR:0)
Block(2,8,-3,AIR:0)
Block(2,8,-2,AIR:0)
Block(2,8,-1,AIR:0)
Block(2,8,0,AIR:0)
Block(2,8,1,AIR:0)
Block(2,8,2,AIR:0)
Block(2,8,3,AIR:0)
Block(2,8,4,AIR:0)
Block(2,8,5,AIR:0)
Block(2,8,6,AIR:0)
Block(2,8,7,AIR:0)
Block(2,8,8,AIR:0)
Block(2,9,-7,AIR:0)
Block(2,9,-6,AIR:0)
Block(2,9,-5,AIR:0)
Block(2,9,-4,AIR:0)
Block(2,9,-3,AIR:0)
Block(2,9,-2,AIR:0)
Block(2,9,-1,AIR:0)
Block(2,9,0,AIR:0)
Block(2,9,1,AIR:0)
Block(2,9,2,AIR:0)
Block(2,9,3,AIR:0)
Block(2,9,4,AIR:0)
Block(2,9,5,AIR:0)
Block(2,9,6,AIR:0)
Block(2,9,7,AIR:0)
Block(2,9,8,AIR:0)
Block(2,10,-7,AIR:0)
Block(2,10,-6,AIR:0)
Block(2,10,-5,STEP:13)
Block(2,10,-4,AIR:0)
Block(2,10,-3,AIR:0)
Block(2,10,-2,AIR:0)
Block(2,10,-1,AIR:0)
Block(2,10,0,STEP:13)
Block(2,10,1,AIR:0)
Block(2,10,2,AIR:0)
Block(2,10,3,AIR:0)
Block(2,10,4,AIR:0)
Block(2,10,5,AIR:0)
Block(2,10,6,STEP:13)
Block(2,10,7,AIR:0)
Block(2,10,8,AIR:0)
Block(2,11,-7,AIR:0)
Block(2,11,-6,AIR:0)
Block(2,11,-5,CONCRETE:7)
Block(2,11,-4,AIR:0)
Block(2,11,-3,AIR:0)
Block(2,11,-2,AIR:0)
Block(2,11,-1,AIR:0)
Block(2,11,0,CONCRETE:7)
Block(2,11,1,AIR:0)
Block(2,11,2,AIR:0)
Block(2,11,3,AIR:0)
Block(2,11,4,AIR:0)
Block(2,11,5,AIR:0)
Block(2,11,6,CONCRETE:7)
Block(2,11,7,AIR:0)
Block(2,11,8,AIR:0)
Block(2,12,-7,AIR:0)
Block(2,12,-6,AIR:0)
Block(2,12,-5,AIR:0)
Block(2,12,-4,AIR:0)
Block(2,12,-3,AIR:0)
Block(2,12,-2,AIR:0)
Block(2,12,-1,AIR:0)
Block(2,12,0,AIR:0)
Block(2,12,1,AIR:0)
Block(2,12,2,AIR:0)
Block(2,12,3,AIR:0)
Block(2,12,4,AIR:0)
Block(2,12,5,AIR:0)
Block(2,12,6,AIR:0)
Block(2,12,7,AIR:0)
Block(2,12,8,AIR:0)
Block(2,13,-7,AIR:0)
Block(2,13,-6,AIR:0)
Block(2,13,-5,AIR:0)
Block(2,13,-4,AIR:0)
Block(2,13,-3,AIR:0)
Block(2,13,-2,AIR:0)
Block(2,13,-1,AIR:0)
Block(2,13,0,AIR:0)
Block(2,13,1,AIR:0)
Block(2,13,2,AIR:0)
Block(2,13,3,AIR:0)
Block(2,13,4,AIR:0)
Block(2,13,5,AIR:0)
Block(2,13,6,AIR:0)
Block(2,13,7,AIR:0)
Block(2,13,8,AIR:0)
Block(3,8,-7,AIR:0)
Block(3,8,-6,AIR:0)
Block(3,8,-5,AIR:0)
Block(3,8,-4,AIR:0)
Block(3,8,-3,AIR:0)
Block(3,8,-2,AIR:0)
Block(3,8,-1,AIR:0)
Block(3,8,0,AIR:0)
Block(3,8,1,AIR:0)
Block(3,8,2,AIR:0)
Block(3,8,3,AIR:0)
Block(3,8,4,AIR:0)
Block(3,8,5,AIR:0)
Block(3,8,6,AIR:0)
Block(3,8,7,AIR:0)
Block(3,8,8,AIR:0)
Block(3,9,-7,AIR:0)
Block(3,9,-6,AIR:0)
Block(3,9,-5,AIR:0)
Block(3,9,-4,AIR:0)
Block(3,9,-3,AIR:0)
Block(3,9,-2,AIR:0)
Block(3,9,-1,AIR:0)
Block(3,9,0,AIR:0)
Block(3,9,1,AIR:0)
Block(3,9,2,AIR:0)
Block(3,9,3,AIR:0)
Block(3,9,4,AIR:0)
Block(3,9,5,AIR:0)
Block(3,9,6,AIR:0)
Block(3,9,7,AIR:0)
Block(3,9,8,AIR:0)
Block(3,10,-7,AIR:0)
Block(3,10,-6,AIR:0)
Block(3,10,-5,STEP:13)
Block(3,10,-4,AIR:0)
Block(3,10,-3,AIR:0)
Block(3,10,-2,AIR:0)
Block(3,10,-1,AIR:0)
Block(3,10,0,STEP:13)
Block(3,10,1,AIR:0)
Block(3,10,2,AIR:0)
Block(3,10,3,AIR:0)
Block(3,10,4,AIR:0)
Block(3,10,5,AIR:0)
Block(3,10,6,STEP:13)
Block(3,10,7,AIR:0)
Block(3,10,8,AIR:0)
Block(3,11,-7,AIR:0)
Block(3,11,-6,AIR:0)
Block(3,11,-5,CONCRETE:7)
Block(3,11,-4,AIR:0)
Block(3,11,-3,AIR:0)
Block(3,11,-2,AIR:0)
Block(3,11,-1,AIR:0)
Block(3,11,0,CONCRETE:7)
Block(3,11,1,AIR:0)
Block(3,11,2,AIR:0)
Block(3,11,3,AIR:0)
Block(3,11,4,AIR:0)
Block(3,11,5,AIR:0)
Block(3,11,6,CONCRETE:7)
Block(3,11,7,AIR:0)
Block(3,11,8,AIR:0)
Block(3,12,-7,AIR:0)
Block(3,12,-6,AIR:0)
Block(3,12,-5,AIR:0)
Block(3,12,-4,AIR:0)
Block(3,12,-3,AIR:0)
Block(3,12,-2,AIR:0)
Block(3,12,-1,AIR:0)
Block(3,12,0,AIR:0)
Block(3,12,1,AIR:0)
Block(3,12,2,AIR:0)
Block(3,12,3,AIR:0)
Block(3,12,4,AIR:0)
Block(3,12,5,AIR:0)
Block(3,12,6,AIR:0)
Block(3,12,7,AIR:0)
Block(3,12,8,AIR:0)
Block(3,13,-7,AIR:0)
Block(3,13,-6,AIR:0)
Block(3,13,-5,AIR:0)
Block(3,13,-4,AIR:0)
Block(3,13,-3,AIR:0)
Block(3,13,-2,AIR:0)
Block(3,13,-1,AIR:0)
Block(3,13,0,AIR:0)
Block(3,13,1,AIR:0)
Block(3,13,2,AIR:0)
Block(3,13,3,AIR:0)
Block(3,13,4,AIR:0)
Block(3,13,5,AIR:0)
Block(3,13,6,AIR:0)
Block(3,13,7,AIR:0)
Block(3,13,8,AIR:0)
Block(4,8,-7,AIR:0)
Block(4,8,-6,AIR:0)
Block(4,8,-5,AIR:0)
Block(4,8,-4,AIR:0)
Block(4,8,-3,AIR:0)
Block(4,8,-2,AIR:0)
Block(4,8,-1,AIR:0)
Block(4,8,0,AIR:0)
Block(4,8,1,AIR:0)
Block(4,8,2,AIR:0)
Block(4,8,3,AIR:0)
Block(4,8,4,AIR:0)
Block(4,8,5,AIR:0)
Block(4,8,6,AIR:0)
Block(4,8,7,AIR:0)
Block(4,8,8,AIR:0)
Block(4,9,-7,AIR:0)
Block(4,9,-6,AIR:0)
Block(4,9,-5,AIR:0)
Block(4,9,-4,AIR:0)
Block(4,9,-3,AIR:0)
