
#######################################################################
# +-----------------------------------------------------------------+ #
# |                            BO3 object                           | #
# +-----------------------------------------------------------------+ #
#######################################################################

Author: NLBlackEagle

Description: No description given

Version: 3

SettingsMode: WriteDisable


#######################################################################
# +-----------------------------------------------------------------+ #
# |                          Main settings                          | #
# +-----------------------------------------------------------------+ #
#######################################################################

Tree: true

Frequency: 0

Rarity: 100.0

RotateRandomly: true

SpawnHeight: highestSolidBlock

SpawnHeightOffset: 0

SpawnHeightVariance: 0

##############################
# Height Limits for the BO3. #
##############################

MinHeight: 0

MaxHeight: 60

######################
# Extrusion settings #
######################

ExtrudeMode: None

ExtrudeThroughBlocks: AIR

MaxBranchDepth: 10

ExcludedBiomes: All


#######################################################################
# +-----------------------------------------------------------------+ #
# |                      Source block settings                      | #
# +-----------------------------------------------------------------+ #
#######################################################################

SourceBlocks: AIR

MaxPercentageOutsideSourceBlock: 0

OutsideSourceBlock: placeAnyway

DoReplaceBlocks: true

IsOTGPlus: false


#######################################################################
# +-----------------------------------------------------------------+ #
# |                              Blocks                             | #
# +-----------------------------------------------------------------+ #
#######################################################################

Block(-3,28,0,srparasites:parasiterubbledense:1)
Block(-2,0,0,srparasites:parasiterubbledense:1)
Block(-2,0,1,srparasites:parasiterubbledense:1)
Block(-2,0,2,srparasites:parasiterubbledense:1)
Block(-2,1,1,srparasites:parasiterubbledense:1)
Block(-2,2,1,srparasites:parasiterubbledense:1)
Block(-2,26,0,srparasites:parasiterubbledense:1)
Block(-2,27,0,srparasites:parasiterubbledense:1)
Block(-1,0,0,srparasites:parasiterubbledense:1)
Block(-1,0,1,srparasites:parasiterubbledense:1)
Block(-1,0,2,srparasites:parasiterubbledense:1)
Block(-1,1,0,srparasites:parasiterubbledense:1)
Block(-1,1,1,srparasites:parasiterubbledense:2)
Block(-1,1,2,srparasites:parasiterubbledense:1)
Block(-1,2,0,srparasites:parasiterubbledense:1)
Block(-1,2,1,srparasites:parasiterubbledense:2)
Block(-1,2,2,srparasites:parasiterubbledense:1)
Block(-1,3,1,srparasites:parasiterubbledense:2)
Block(-1,4,1,srparasites:parasiterubbledense:2)
Block(-1,5,1,srparasites:parasiterubbledense:2)
Block(-1,6,0,srparasites:parasiterubbledense:2)
Block(-1,7,0,srparasites:parasiterubbledense:2)
Block(-1,8,0,srparasites:parasiterubbledense:2)
Block(-1,9,0,srparasites:parasiterubbledense:2)
Block(-1,10,0,srparasites:parasiterubbledense:2)
Block(-1,22,0,srparasites:parasiterubbledense:1)
Block(-1,23,0,srparasites:parasiterubbledense:1)
Block(-1,24,-2,srparasites:parasiterubbledense:1)
Block(-1,24,0,srparasites:parasiterubbledense:1)
Block(-1,24,2,srparasites:parasiterubbledense:1)
Block(-1,25,-2,srparasites:parasiterubbledense:1)
Block(-1,25,0,srparasites:parasiterubbledense:1)
Block(-1,25,2,srparasites:parasiterubbledense:1)
Block(-1,26,-2,srparasites:parasiterubbledense:1)
Block(-1,26,2,srparasites:parasiterubbledense:1)
Block(0,0,0,srparasites:parasiterubbledense:1)
Block(0,0,1,srparasites:parasiterubbledense:1)
Block(0,0,2,srparasites:parasiterubbledense:1)
Block(0,1,1,srparasites:parasiterubbledense:1)
Block(0,2,1,srparasites:parasiterubbledense:1)
Block(0,11,0,srparasites:parasiterubbledense:2)
Block(0,12,0,srparasites:parasiterubbledense:2)
Block(0,13,0,srparasites:parasiterubbledense:2)
Block(0,14,0,srparasites:parasiterubbledense:2)
Block(0,15,0,srparasites:parasiterubbledense:2)
Block(0,21,0,srparasites:parasiterubbledense:1)
Block(0,22,-1,srparasites:parasiterubbledense:1)
Block(0,22,0,srparasites:parasiterubbledense:1)
Block(0,22,1,srparasites:parasiterubbledense:1)
Block(0,23,-1,srparasites:parasiterubbledense:1)
Block(0,23,0,srparasites:parasiterubbledense:1)
Block(0,23,1,srparasites:parasiterubbledense:1)
Block(1,16,0,srparasites:parasiterubbledense:2)
Block(1,17,0,srparasites:parasiterubbledense:2)
Block(1,18,0,srparasites:parasiterubbledense:2)
Block(1,19,0,srparasites:parasiterubbledense:2)
Block(1,20,0,srparasites:parasiterubbledense:2)
Block(1,21,-1,srparasites:parasiterubbledense:1)
Block(1,21,0,srparasites:parasiterubbledense:1)
Block(1,21,1,srparasites:parasiterubbledense:1)
Block(1,22,-2,srparasites:parasiterubbledense:1)
Block(1,22,-1,srparasites:parasiterubbledense:1)
Block(1,22,0,srparasites:parasiterubbledense:1)
Block(1,22,1,srparasites:parasiterubbledense:1)
Block(1,22,2,srparasites:parasiterubbledense:1)
Block(1,23,-2,srparasites:parasiterubbledense:1)
Block(1,23,-1,srparasites:parasiterubbledense:1)
Block(1,23,0,srparasites:parasiterubbledense:1)
Block(1,23,1,srparasites:parasiterubbledense:1)
Block(1,23,2,srparasites:parasiterubbledense:1)
Block(1,24,-2,srparasites:parasiterubbledense:1)
Block(1,24,0,srparasites:parasiterubbledense:1)
Block(1,24,2,srparasites:parasiterubbledense:1)
Block(1,25,-2,srparasites:parasiterubbledense:1)
Block(1,25,2,srparasites:parasiterubbledense:1)
Block(1,26,-3,srparasites:parasiterubbledense:1)
Block(1,26,3,srparasites:parasiterubbledense:1)
Block(1,27,-3,srparasites:parasiterubbledense:1)
Block(1,27,3,srparasites:parasiterubbledense:1)
Block(1,28,-4,srparasites:parasiterubbledense:1)
Block(1,28,4,srparasites:parasiterubbledense:1)
Block(2,21,0,srparasites:parasiterubbledense:1)
Block(2,22,-1,srparasites:parasiterubbledense:1)
Block(2,22,0,srparasites:parasiterubbledense:1)
Block(2,22,1,srparasites:parasiterubbledense:1)
Block(2,23,-1,srparasites:parasiterubbledense:1)
Block(2,23,0,srparasites:parasiterubbledense:1)
Block(2,23,1,srparasites:parasiterubbledense:1)
Block(3,22,0,srparasites:parasiterubbledense:1)
Block(3,23,0,srparasites:parasiterubbledense:1)
Block(3,24,-2,srparasites:parasiterubbledense:1)
Block(3,24,0,srparasites:parasiterubbledense:1)
Block(3,24,2,srparasites:parasiterubbledense:1)
Block(3,25,-2,srparasites:parasiterubbledense:1)
Block(3,25,0,srparasites:parasiterubbledense:1)
Block(3,25,2,srparasites:parasiterubbledense:1)
Block(3,26,-2,srparasites:parasiterubbledense:1)
Block(3,26,2,srparasites:parasiterubbledense:1)
Block(4,26,0,srparasites:parasiterubbledense:1)
Block(4,27,0,srparasites:parasiterubbledense:1)
Block(5,28,0,srparasites:parasiterubbledense:1)

#######################################################################
# +-----------------------------------------------------------------+ #
# |                            BO3 checks                           | #
# +-----------------------------------------------------------------+ #
#######################################################################

BlockCheck(0,-1,0,Solid)

#######################################################################
# +-----------------------------------------------------------------+ #
# |                             Branches                            | #
# +-----------------------------------------------------------------+ #
#######################################################################


#######################################################################
# +-----------------------------------------------------------------+ #
# |                             Entities                            | #
# +-----------------------------------------------------------------+ #
#######################################################################


#######################################################################
# +-----------------------------------------------------------------+ #
# |                            Particles                            | #
# +-----------------------------------------------------------------+ #
#######################################################################


#######################################################################
# +-----------------------------------------------------------------+ #
# |                             Spawners                            | #
# +-----------------------------------------------------------------+ #
#######################################################################


#######################################################################
# +-----------------------------------------------------------------+ #
# |                             ModData                             | #
# +-----------------------------------------------------------------+ #
#######################################################################

