
#######################################################################
# +-----------------------------------------------------------------+ #
# |                            BO3 object                           | #
# +-----------------------------------------------------------------+ #
#######################################################################

Author: NLBlackEagle

Description: No description given

Version: 3

SettingsMode: WriteDisable


#######################################################################
# +-----------------------------------------------------------------+ #
# |                          Main settings                          | #
# +-----------------------------------------------------------------+ #
#######################################################################

Tree: true

Frequency: 0

Rarity: 100.0

RotateRandomly: true

SpawnHeight: highestSolidBlock

SpawnHeightOffset: 0

SpawnHeightVariance: 0

##############################
# Height Limits for the BO3. #
##############################

MinHeight: 0

MaxHeight: 60

######################
# Extrusion settings #
######################

ExtrudeMode: None

ExtrudeThroughBlocks: AIR

MaxBranchDepth: 10

ExcludedBiomes: All


#######################################################################
# +-----------------------------------------------------------------+ #
# |                      Source block settings                      | #
# +-----------------------------------------------------------------+ #
#######################################################################

SourceBlocks: AIR

MaxPercentageOutsideSourceBlock: 0

OutsideSourceBlock: placeAnyway

DoReplaceBlocks: true

IsOTGPlus: false


#######################################################################
# +-----------------------------------------------------------------+ #
# |                              Blocks                             | #
# +-----------------------------------------------------------------+ #
#######################################################################

Block(-2,0,-4,srparasites:parasiterubbledense:2)
Block(-2,0,-1,srparasites:parasiterubbledense:2)
Block(-1,0,-1,srparasites:parasiterubbledense:2)
Block(-1,0,0,srparasites:parasiterubbledense:2)
Block(-1,1,-1,srparasites:parasiterubbledense:2)
Block(-1,2,-1,srparasites:parasiterubbledense:2)
Block(-1,3,-1,srparasites:parasiterubbledense:2)
Block(-1,4,-1,srparasites:parasiterubbledense:2)
Block(-1,5,-1,srparasites:parasiterubbledense:2)
Block(-1,6,-1,srparasites:parasiterubbledense:2)
Block(-1,6,0,srparasites:parasiterubbledense:2)
Block(-1,7,0,srparasites:parasiterubbledense:2)
Block(-1,8,-4,srparasites:parasiterubbledense:2)
Block(-1,8,-1,srparasites:parasiterubbledense:2)
Block(-1,8,0,srparasites:parasiterubbledense:2)
Block(-1,8,1,srparasites:parasiterubbledense:2)
Block(-1,9,-3,srparasites:parasiterubbledense:2)
Block(-1,9,-2,srparasites:parasiterubbledense:2)
Block(-1,9,0,srparasites:parasiterubbledense:2)
Block(-1,9,2,srparasites:parasiterubbledense:2)
Block(-1,9,3,srparasites:parasiterubbledense:2)
Block(-1,10,0,srparasites:parasiterubbledense:2)
Block(-1,11,0,srparasites:parasiterubbledense:2)
Block(-1,12,0,srparasites:parasiterubbledense:2)
Block(-1,12,1,srparasites:parasiterubbledense:2)
Block(-1,13,0,srparasites:parasiterubbledense:2)
Block(-1,13,1,srparasites:parasiterubbledense:2)
Block(-1,14,1,srparasites:parasiterubbledense:2)
Block(-1,15,-3,srparasites:parasiterubbledense:2)
Block(-1,15,0,srparasites:parasiterubbledense:2)
Block(-1,15,1,srparasites:parasiterubbledense:2)
Block(-1,16,-2,srparasites:parasiterubbledense:2)
Block(-1,16,-1,srparasites:parasiterubbledense:2)
Block(-1,16,1,srparasites:parasiterubbledense:2)
Block(-1,17,1,srparasites:parasiterubbledense:2)
Block(-1,18,1,srparasites:parasiterubbledense:2)
Block(-1,19,1,srparasites:parasiterubbledense:2)
Block(-1,20,1,srparasites:parasiterubbledense:2)
Block(-1,20,2,srparasites:parasiterubbledense:2)
Block(-1,21,2,srparasites:parasiterubbledense:2)
Block(-1,22,1,srparasites:parasiterubbledense:2)
Block(-1,22,2,srparasites:parasiterubbledense:2)
Block(-1,23,0,srparasites:parasiterubbledense:2)
Block(-1,23,2,srparasites:parasiterubbledense:2)
Block(-1,24,2,srparasites:parasiterubbledense:2)
Block(-1,25,2,srparasites:parasiterubbledense:2)
Block(0,6,5,srparasites:parasiterubbledense:2)
Block(0,7,5,srparasites:parasiterubbledense:2)
Block(0,8,4,srparasites:parasiterubbledense:2)
Block(0,15,1,srparasites:parasiterubbledense:2)
Block(0,22,2,srparasites:parasiterubbledense:2)
Block(0,23,-1,srparasites:parasiterubbledense:2)
Block(1,16,1,srparasites:parasiterubbledense:2)
Block(1,22,-2,srparasites:parasiterubbledense:2)
Block(1,22,2,srparasites:parasiterubbledense:2)
Block(1,23,2,srparasites:parasiterubbledense:2)
Block(2,15,1,srparasites:parasiterubbledense:2)
Block(2,16,1,srparasites:parasiterubbledense:2)
Block(2,22,2,srparasites:parasiterubbledense:2)
Block(3,14,0,srparasites:parasiterubbledense:2)
Block(3,15,0,srparasites:parasiterubbledense:2)

#######################################################################
# +-----------------------------------------------------------------+ #
# |                            BO3 checks                           | #
# +-----------------------------------------------------------------+ #
#######################################################################

BlockCheck(0,-1,0,Solid)

#######################################################################
# +-----------------------------------------------------------------+ #
# |                             Branches                            | #
# +-----------------------------------------------------------------+ #
#######################################################################


#######################################################################
# +-----------------------------------------------------------------+ #
# |                             Entities                            | #
# +-----------------------------------------------------------------+ #
#######################################################################


#######################################################################
# +-----------------------------------------------------------------+ #
# |                            Particles                            | #
# +-----------------------------------------------------------------+ #
#######################################################################


#######################################################################
# +-----------------------------------------------------------------+ #
# |                             Spawners                            | #
# +-----------------------------------------------------------------+ #
#######################################################################


#######################################################################
# +-----------------------------------------------------------------+ #
# |                             ModData                             | #
# +-----------------------------------------------------------------+ #
#######################################################################

