
#######################################################################
# +-----------------------------------------------------------------+ #
# |                            BO3 object                           | #
# +-----------------------------------------------------------------+ #
#######################################################################

Author: NLBlackEagle

Description: No description given

Version: 3

SettingsMode: WriteDisable


#######################################################################
# +-----------------------------------------------------------------+ #
# |                          Main settings                          | #
# +-----------------------------------------------------------------+ #
#######################################################################

Tree: true

Frequency: 0

Rarity: 100.0

RotateRandomly: true

SpawnHeight: highestSolidBlock

SpawnHeightOffset: 0

SpawnHeightVariance: 0

##############################
# Height Limits for the BO3. #
##############################

MinHeight: 0

MaxHeight: 60

######################
# Extrusion settings #
######################

ExtrudeMode: None

ExtrudeThroughBlocks: AIR

MaxBranchDepth: 10

ExcludedBiomes: All


#######################################################################
# +-----------------------------------------------------------------+ #
# |                      Source block settings                      | #
# +-----------------------------------------------------------------+ #
#######################################################################

SourceBlocks: AIR

MaxPercentageOutsideSourceBlock: 0

OutsideSourceBlock: placeAnyway

DoReplaceBlocks: true

IsOTGPlus: false


#######################################################################
# +-----------------------------------------------------------------+ #
# |                              Blocks                             | #
# +-----------------------------------------------------------------+ #
#######################################################################

Block(-2,12,-5,srparasites:parasiterubbledense:2)
Block(-2,13,-5,srparasites:parasiterubbledense:2)
Block(-1,0,0,srparasites:parasiterubbledense:2)
Block(-1,0,1,srparasites:parasiterubbledense:2)
Block(-1,0,5,srparasites:parasitethin)
Block(-1,1,0,srparasites:parasiterubbledense:2)
Block(-1,2,0,srparasites:parasiterubbledense:2)
Block(-1,3,0,srparasites:parasiterubbledense:2)
Block(-1,4,0,srparasites:parasiterubbledense:2)
Block(-1,5,0,srparasites:parasiterubbledense:2)
Block(-1,6,0,srparasites:parasiterubbledense:2)
Block(-1,7,0,srparasites:parasiterubbledense:2)
Block(-1,14,-4,srparasites:parasiterubbledense:2)
Block(-1,19,3,srparasites:parasiterubbledense:2)
Block(-1,19,4,srparasites:parasiterubbledense:2)
Block(-1,20,3,srparasites:parasiterubbledense:2)
Block(0,0,3,srparasites:infestedbush:1)
Block(0,6,0,srparasites:parasiterubbledense:2)
Block(0,7,0,srparasites:parasiterubbledense:2)
Block(0,8,0,srparasites:parasiterubbledense:2)
Block(0,9,0,srparasites:parasiterubbledense:2)
Block(0,9,1,srparasites:parasiterubbledense:2)
Block(0,9,2,srparasites:parasiterubbledense:2)
Block(0,10,0,srparasites:parasiterubbledense:2)
Block(0,10,2,srparasites:parasiterubbledense:2)
Block(0,11,0,srparasites:parasiterubbledense:2)
Block(0,12,0,srparasites:parasiterubbledense:2)
Block(0,14,3,srparasites:parasiterubbledense:2)
Block(0,15,-3,srparasites:parasiterubbledense:2)
Block(0,17,0,srparasites:parasiterubbledense:2)
Block(0,18,0,srparasites:parasiterubbledense:2)
Block(0,19,0,srparasites:parasiterubbledense:2)
Block(0,20,-2,srparasites:parasiterubbledense:2)
Block(0,20,-1,srparasites:parasiterubbledense:2)
Block(0,20,0,srparasites:parasiterubbledense:2)
Block(0,20,1,srparasites:parasiterubbledense:2)
Block(0,21,-3,srparasites:parasiterubbledense:2)
Block(0,21,-2,srparasites:parasiterubbledense:2)
Block(0,21,0,srparasites:parasiterubbledense:2)
Block(0,21,2,srparasites:parasiterubbledense:2)
Block(0,22,0,srparasites:parasiterubbledense:2)
Block(0,23,0,srparasites:parasiterubbledense:2)
Block(0,24,0,srparasites:parasiterubbledense:2)
Block(1,9,0,srparasites:parasiterubbledense:2)
Block(1,10,3,srparasites:parasiterubbledense:2)
Block(1,11,0,srparasites:parasiterubbledense:2)
Block(1,12,0,srparasites:parasiterubbledense:2)
Block(1,13,0,srparasites:parasiterubbledense:2)
Block(1,14,-2,srparasites:parasiterubbledense:2)
Block(1,14,-1,srparasites:parasiterubbledense:2)
Block(1,14,0,srparasites:parasiterubbledense:2)
Block(1,14,1,srparasites:parasiterubbledense:2)
Block(1,15,-2,srparasites:parasiterubbledense:2)
Block(1,15,0,srparasites:parasiterubbledense:2)
Block(1,15,2,srparasites:parasiterubbledense:2)
Block(1,16,0,srparasites:parasiterubbledense:2)
Block(1,17,0,srparasites:parasiterubbledense:2)
Block(1,18,0,srparasites:parasiterubbledense:2)
Block(1,21,-4,srparasites:parasiterubbledense:2)
Block(2,8,5,srparasites:parasiterubbledense:2)
Block(2,9,4,srparasites:parasiterubbledense:2)
Block(2,10,0,srparasites:parasiterubbledense:2)
Block(2,20,-5,srparasites:parasiterubbledense:2)
Block(3,9,-1,srparasites:parasiterubbledense:2)

#######################################################################
# +-----------------------------------------------------------------+ #
# |                            BO3 checks                           | #
# +-----------------------------------------------------------------+ #
#######################################################################

BlockCheck(0,-1,0,Solid)

#######################################################################
# +-----------------------------------------------------------------+ #
# |                             Branches                            | #
# +-----------------------------------------------------------------+ #
#######################################################################


#######################################################################
# +-----------------------------------------------------------------+ #
# |                             Entities                            | #
# +-----------------------------------------------------------------+ #
#######################################################################


#######################################################################
# +-----------------------------------------------------------------+ #
# |                            Particles                            | #
# +-----------------------------------------------------------------+ #
#######################################################################


#######################################################################
# +-----------------------------------------------------------------+ #
# |                             Spawners                            | #
# +-----------------------------------------------------------------+ #
#######################################################################


#######################################################################
# +-----------------------------------------------------------------+ #
# |                             ModData                             | #
# +-----------------------------------------------------------------+ #
#######################################################################

