
#######################################################################
# +-----------------------------------------------------------------+ #
# |                            BO4 object                           | #
# +-----------------------------------------------------------------+ #
#######################################################################

Author: NLBlackEagle

Description: No description given

SettingsMode: WriteDisable


#######################################################################
# +-----------------------------------------------------------------+ #
# |                          Main settings                          | #
# +-----------------------------------------------------------------+ #
#######################################################################

FixedRotation: 

Frequency: 0

SpawnHeight: randomY

UseCenterForHighestBlock: true

##############################
# Height Limits for the BO4. #
##############################

MinHeight: 1

MaxHeight: 255

InheritBO3: 

InheritBO3Rotation: NORTH

OverrideChildSettings: true

OverrideParentHeight: false

CanOverride: false

BranchFrequency: 0

BranchFrequencyGroup: 

MustBeBelowOther: false

MustBeInside: 

CannotBeInside: 

ReplacesBO3: 

MustBeInsideWorldBorders: true
CanSpawnOnWater: true

SpawnOnWaterOnly: false

SpawnUnderWater: false

SpawnAtWaterLevel: false

HeightOffset: 0

RemoveAir: false

ReplaceAbove: 

ReplaceBelow: 

ReplaceWithBiomeBlocks: true

ReplaceWithSurfaceBlock: GRASS

ReplaceWithGroundBlock: DIRT

ReplaceWithStoneBlock: STONE

SmoothRadius: 0

SmoothHeightOffset: 0

SmoothStartTop: false

SmoothStartWood: false

SmoothingSurfaceBlock: 

SmoothingGroundBlock: 

BO3Group: 

IsSpawnPoint: false

DoReplaceBlocks: true


#######################################################################
# +-----------------------------------------------------------------+ #
# |                              Blocks                             | #
# +-----------------------------------------------------------------+ #
#######################################################################

RandomBlock(-7,0,1,CONCRETE:7,65,quark:iron_plate:0,10,quark:iron_plate:1,10,STAINED_CLAY:15,10,STAINED_CLAY:9,100)
RandomBlock(-7,0,2,CONCRETE:7,65,quark:iron_plate:0,10,quark:iron_plate:1,10,STAINED_CLAY:15,10,STAINED_CLAY:9,100)
RandomBlock(-7,0,8,CONCRETE:7,65,quark:iron_plate:0,10,quark:iron_plate:1,10,STAINED_CLAY:15,10,STAINED_CLAY:9,100)
RandomBlock(-7,0,9,CONCRETE:7,65,quark:iron_plate:0,10,quark:iron_plate:1,10,STAINED_CLAY:15,10,STAINED_CLAY:9,100)
RandomBlock(-7,1,1,CONCRETE:7,65,quark:iron_plate:0,10,quark:iron_plate:1,10,STAINED_CLAY:15,10,STAINED_CLAY:9,100)
RandomBlock(-7,1,2,CONCRETE:7,65,quark:iron_plate:0,10,quark:iron_plate:1,10,STAINED_CLAY:15,10,STAINED_CLAY:9,100)
RandomBlock(-7,1,8,CONCRETE:7,65,quark:iron_plate:0,10,quark:iron_plate:1,10,STAINED_CLAY:15,10,STAINED_CLAY:9,100)
RandomBlock(-7,1,9,CONCRETE:7,65,quark:iron_plate:0,10,quark:iron_plate:1,10,STAINED_CLAY:15,10,STAINED_CLAY:9,100)
RandomBlock(-7,2,1,CONCRETE:7,65,quark:iron_plate:0,10,quark:iron_plate:1,10,STAINED_CLAY:15,10,STAINED_CLAY:9,100)
RandomBlock(-7,2,2,CONCRETE:7,65,quark:iron_plate:0,10,quark:iron_plate:1,10,STAINED_CLAY:15,10,STAINED_CLAY:9,100)
RandomBlock(-7,2,8,CONCRETE:7,65,quark:iron_plate:0,10,quark:iron_plate:1,10,STAINED_CLAY:15,10,STAINED_CLAY:9,100)
RandomBlock(-7,2,9,CONCRETE:7,65,quark:iron_plate:0,10,quark:iron_plate:1,10,STAINED_CLAY:15,10,STAINED_CLAY:9,100)
RandomBlock(-7,3,1,CONCRETE:7,65,quark:iron_plate:0,10,quark:iron_plate:1,10,STAINED_CLAY:15,10,STAINED_CLAY:9,100)
RandomBlock(-7,3,2,CONCRETE:7,65,quark:iron_plate:0,10,quark:iron_plate:1,10,STAINED_CLAY:15,10,STAINED_CLAY:9,100)
RandomBlock(-7,3,8,CONCRETE:7,65,quark:iron_plate:0,10,quark:iron_plate:1,10,STAINED_CLAY:15,10,STAINED_CLAY:9,100)
RandomBlock(-7,3,9,CONCRETE:7,65,quark:iron_plate:0,10,quark:iron_plate:1,10,STAINED_CLAY:15,10,STAINED_CLAY:9,100)
RandomBlock(-7,4,1,CONCRETE:7,65,quark:iron_plate:0,10,quark:iron_plate:1,10,STAINED_CLAY:15,10,STAINED_CLAY:9,100)
RandomBlock(-7,4,2,CONCRETE:7,65,quark:iron_plate:0,10,quark:iron_plate:1,10,STAINED_CLAY:15,10,STAINED_CLAY:9,100)
RandomBlock(-7,4,8,CONCRETE:7,65,quark:iron_plate:0,10,quark:iron_plate:1,10,STAINED_CLAY:15,10,STAINED_CLAY:9,100)
RandomBlock(-7,4,9,CONCRETE:7,65,quark:iron_plate:0,10,quark:iron_plate:1,10,STAINED_CLAY:15,10,STAINED_CLAY:9,100)
RandomBlock(-7,5,1,CONCRETE:7,65,quark:iron_plate:0,10,quark:iron_plate:1,10,STAINED_CLAY:15,10,STAINED_CLAY:9,100)
RandomBlock(-7,5,2,CONCRETE:7,65,quark:iron_plate:0,10,quark:iron_plate:1,10,STAINED_CLAY:15,10,STAINED_CLAY:9,100)
RandomBlock(-7,5,8,CONCRETE:7,65,quark:iron_plate:0,10,quark:iron_plate:1,10,STAINED_CLAY:15,10,STAINED_CLAY:9,100)
RandomBlock(-7,5,9,CONCRETE:7,65,quark:iron_plate:0,10,quark:iron_plate:1,10,STAINED_CLAY:15,10,STAINED_CLAY:9,100)
RandomBlock(-7,6,1,CONCRETE:7,65,quark:iron_plate:0,10,quark:iron_plate:1,10,STAINED_CLAY:15,10,STAINED_CLAY:9,100)
RandomBlock(-7,6,2,CONCRETE:7,65,quark:iron_plate:0,10,quark:iron_plate:1,10,STAINED_CLAY:15,10,STAINED_CLAY:9,100)
RandomBlock(-7,6,8,CONCRETE:7,65,quark:iron_plate:0,10,quark:iron_plate:1,10,STAINED_CLAY:15,10,STAINED_CLAY:9,100)
RandomBlock(-7,6,9,CONCRETE:7,65,quark:iron_plate:0,10,quark:iron_plate:1,10,STAINED_CLAY:15,10,STAINED_CLAY:9,100)
RandomBlock(-7,7,1,CONCRETE:7,65,quark:iron_plate:0,10,quark:iron_plate:1,10,STAINED_CLAY:15,10,STAINED_CLAY:9,100)
RandomBlock(-7,7,2,CONCRETE:7,65,quark:iron_plate:0,10,quark:iron_plate:1,10,STAINED_CLAY:15,10,STAINED_CLAY:9,100)
RandomBlock(-7,7,8,CONCRETE:7,65,quark:iron_plate:0,10,quark:iron_plate:1,10,STAINED_CLAY:15,10,STAINED_CLAY:9,100)
RandomBlock(-7,7,9,CONCRETE:7,65,quark:iron_plate:0,10,quark:iron_plate:1,10,STAINED_CLAY:15,10,STAINED_CLAY:9,100)
RandomBlock(-7,8,1,CONCRETE:7,65,quark:iron_plate:0,10,quark:iron_plate:1,10,STAINED_CLAY:15,10,STAINED_CLAY:9,100)
RandomBlock(-7,8,2,CONCRETE:7,65,quark:iron_plate:0,10,quark:iron_plate:1,10,STAINED_CLAY:15,10,STAINED_CLAY:9,100)
RandomBlock(-7,8,8,CONCRETE:7,65,quark:iron_plate:0,10,quark:iron_plate:1,10,STAINED_CLAY:15,10,STAINED_CLAY:9,100)
RandomBlock(-7,8,9,CONCRETE:7,65,quark:iron_plate:0,10,quark:iron_plate:1,10,STAINED_CLAY:15,10,STAINED_CLAY:9,100)
RandomBlock(-7,9,1,CONCRETE:7,65,quark:iron_plate:0,10,quark:iron_plate:1,10,STAINED_CLAY:15,10,STAINED_CLAY:9,100)
RandomBlock(-7,9,2,CONCRETE:7,65,quark:iron_plate:0,10,quark:iron_plate:1,10,STAINED_CLAY:15,10,STAINED_CLAY:9,100)
RandomBlock(-7,9,4,CONCRETE:7,65,quark:iron_plate:0,10,quark:iron_plate:1,10,STAINED_CLAY:15,10,STAINED_CLAY:9,100)
RandomBlock(-7,9,6,CONCRETE:7,65,quark:iron_plate:0,10,quark:iron_plate:1,10,STAINED_CLAY:15,10,STAINED_CLAY:9,100)
RandomBlock(-7,9,8,CONCRETE:7,65,quark:iron_plate:0,10,quark:iron_plate:1,10,STAINED_CLAY:15,10,STAINED_CLAY:9,100)
RandomBlock(-7,9,9,CONCRETE:7,65,quark:iron_plate:0,10,quark:iron_plate:1,10,STAINED_CLAY:15,10,STAINED_CLAY:9,100)
RandomBlock(-7,10,1,CONCRETE:7,65,quark:iron_plate:0,10,quark:iron_plate:1,10,STAINED_CLAY:15,10,STAINED_CLAY:9,100)
RandomBlock(-7,10,2,CONCRETE:7,65,quark:iron_plate:0,10,quark:iron_plate:1,10,STAINED_CLAY:15,10,STAINED_CLAY:9,100)
RandomBlock(-7,10,4,CONCRETE:7,65,quark:iron_plate:0,10,quark:iron_plate:1,10,STAINED_CLAY:15,10,STAINED_CLAY:9,100)
RandomBlock(-7,10,6,CONCRETE:7,65,quark:iron_plate:0,10,quark:iron_plate:1,10,STAINED_CLAY:15,10,STAINED_CLAY:9,100)
RandomBlock(-7,10,8,CONCRETE:7,65,quark:iron_plate:0,10,quark:iron_plate:1,10,STAINED_CLAY:15,10,STAINED_CLAY:9,100)
RandomBlock(-7,10,9,CONCRETE:7,65,quark:iron_plate:0,10,quark:iron_plate:1,10,STAINED_CLAY:15,10,STAINED_CLAY:9,100)
RandomBlock(-7,11,1,CONCRETE:7,65,quark:iron_plate:0,10,quark:iron_plate:1,10,STAINED_CLAY:15,10,STAINED_CLAY:9,100)
RandomBlock(-7,11,2,CONCRETE:7,65,quark:iron_plate:0,10,quark:iron_plate:1,10,STAINED_CLAY:15,10,STAINED_CLAY:9,100)
RandomBlock(-7,11,4,CONCRETE:7,65,quark:iron_plate:0,10,quark:iron_plate:1,10,STAINED_CLAY:15,10,STAINED_CLAY:9,100)
RandomBlock(-7,11,6,CONCRETE:7,65,quark:iron_plate:0,10,quark:iron_plate:1,10,STAINED_CLAY:15,10,STAINED_CLAY:9,100)
RandomBlock(-7,11,8,CONCRETE:7,65,quark:iron_plate:0,10,quark:iron_plate:1,10,STAINED_CLAY:15,10,STAINED_CLAY:9,100)
RandomBlock(-7,11,9,CONCRETE:7,65,quark:iron_plate:0,10,quark:iron_plate:1,10,STAINED_CLAY:15,10,STAINED_CLAY:9,100)
RandomBlock(-7,12,1,CONCRETE:7,65,quark:iron_plate:0,10,quark:iron_plate:1,10,STAINED_CLAY:15,10,STAINED_CLAY:9,100)
RandomBlock(-7,12,2,CONCRETE:7,65,quark:iron_plate:0,10,quark:iron_plate:1,10,STAINED_CLAY:15,10,STAINED_CLAY:9,100)
RandomBlock(-7,12,4,CONCRETE:7,65,quark:iron_plate:0,10,quark:iron_plate:1,10,STAINED_CLAY:15,10,STAINED_CLAY:9,100)
RandomBlock(-7,12,6,CONCRETE:7,65,quark:iron_plate:0,10,quark:iron_plate:1,10,STAINED_CLAY:15,10,STAINED_CLAY:9,100)
RandomBlock(-7,12,8,CONCRETE:7,65,quark:iron_plate:0,10,quark:iron_plate:1,10,STAINED_CLAY:15,10,STAINED_CLAY:9,100)
RandomBlock(-7,12,9,CONCRETE:7,65,quark:iron_plate:0,10,quark:iron_plate:1,10,STAINED_CLAY:15,10,STAINED_CLAY:9,100)
RandomBlock(-7,13,1,CONCRETE:7,65,quark:iron_plate:0,10,quark:iron_plate:1,10,STAINED_CLAY:15,10,STAINED_CLAY:9,100)
RandomBlock(-7,13,2,CONCRETE:7,65,quark:iron_plate:0,10,quark:iron_plate:1,10,STAINED_CLAY:15,10,STAINED_CLAY:9,100)
RandomBlock(-7,13,4,CONCRETE:7,65,quark:iron_plate:0,10,quark:iron_plate:1,10,STAINED_CLAY:15,10,STAINED_CLAY:9,100)
RandomBlock(-7,13,6,CONCRETE:7,65,quark:iron_plate:0,10,quark:iron_plate:1,10,STAINED_CLAY:15,10,STAINED_CLAY:9,100)
RandomBlock(-7,13,8,CONCRETE:7,65,quark:iron_plate:0,10,quark:iron_plate:1,10,STAINED_CLAY:15,10,STAINED_CLAY:9,100)
RandomBlock(-7,13,9,CONCRETE:7,65,quark:iron_plate:0,10,quark:iron_plate:1,10,STAINED_CLAY:15,10,STAINED_CLAY:9,100)
RandomBlock(-7,14,1,CONCRETE:7,65,quark:iron_plate:0,10,quark:iron_plate:1,10,STAINED_CLAY:15,10,STAINED_CLAY:9,100)
RandomBlock(-7,14,2,CONCRETE:7,65,quark:iron_plate:0,10,quark:iron_plate:1,10,STAINED_CLAY:15,10,STAINED_CLAY:9,100)
RandomBlock(-7,14,4,CONCRETE:7,65,quark:iron_plate:0,10,quark:iron_plate:1,10,STAINED_CLAY:15,10,STAINED_CLAY:9,100)
RandomBlock(-7,14,6,CONCRETE:7,65,quark:iron_plate:0,10,quark:iron_plate:1,10,STAINED_CLAY:15,10,STAINED_CLAY:9,100)
RandomBlock(-7,14,8,CONCRETE:7,65,quark:iron_plate:0,10,quark:iron_plate:1,10,STAINED_CLAY:15,10,STAINED_CLAY:9,100)
RandomBlock(-7,14,9,CONCRETE:7,65,quark:iron_plate:0,10,quark:iron_plate:1,10,STAINED_CLAY:15,10,STAINED_CLAY:9,100)
RandomBlock(-7,15,1,CONCRETE:7,65,quark:iron_plate:0,10,quark:iron_plate:1,10,STAINED_CLAY:15,10,STAINED_CLAY:9,100)
RandomBlock(-7,15,2,CONCRETE:7,65,quark:iron_plate:0,10,quark:iron_plate:1,10,STAINED_CLAY:15,10,STAINED_CLAY:9,100)
RandomBlock(-7,15,4,CONCRETE:7,65,quark:iron_plate:0,10,quark:iron_plate:1,10,STAINED_CLAY:15,10,STAINED_CLAY:9,100)
RandomBlock(-7,15,6,CONCRETE:7,65,quark:iron_plate:0,10,quark:iron_plate:1,10,STAINED_CLAY:15,10,STAINED_CLAY:9,100)
RandomBlock(-7,15,8,CONCRETE:7,65,quark:iron_plate:0,10,quark:iron_plate:1,10,STAINED_CLAY:15,10,STAINED_CLAY:9,100)
RandomBlock(-7,15,9,CONCRETE:7,65,quark:iron_plate:0,10,quark:iron_plate:1,10,STAINED_CLAY:15,10,STAINED_CLAY:9,100)
RandomBlock(-6,0,1,CONCRETE:7,65,quark:iron_plate:0,10,quark:iron_plate:1,10,STAINED_CLAY:15,10,STAINED_CLAY:9,100)
RandomBlock(-6,0,2,CONCRETE:7,65,quark:iron_plate:0,10,quark:iron_plate:1,10,STAINED_CLAY:15,10,STAINED_CLAY:9,100)
RandomBlock(-6,0,8,CONCRETE:7,65,quark:iron_plate:0,10,quark:iron_plate:1,10,STAINED_CLAY:15,10,STAINED_CLAY:9,100)
RandomBlock(-6,0,9,CONCRETE:7,65,quark:iron_plate:0,10,quark:iron_plate:1,10,STAINED_CLAY:15,10,STAINED_CLAY:9,100)
RandomBlock(-6,1,1,CONCRETE:7,65,quark:iron_plate:0,10,quark:iron_plate:1,10,STAINED_CLAY:15,10,STAINED_CLAY:9,100)
RandomBlock(-6,1,2,CONCRETE:7,65,quark:iron_plate:0,10,quark:iron_plate:1,10,STAINED_CLAY:15,10,STAINED_CLAY:9,100)
RandomBlock(-6,1,8,CONCRETE:7,65,quark:iron_plate:0,10,quark:iron_plate:1,10,STAINED_CLAY:15,10,STAINED_CLAY:9,100)
RandomBlock(-6,1,9,CONCRETE:7,65,quark:iron_plate:0,10,quark:iron_plate:1,10,STAINED_CLAY:15,10,STAINED_CLAY:9,100)
RandomBlock(-6,2,1,CONCRETE:7,65,quark:iron_plate:0,10,quark:iron_plate:1,10,STAINED_CLAY:15,10,STAINED_CLAY:9,100)
RandomBlock(-6,2,2,CONCRETE:7,65,quark:iron_plate:0,10,quark:iron_plate:1,10,STAINED_CLAY:15,10,STAINED_CLAY:9,100)
RandomBlock(-6,2,8,CONCRETE:7,65,quark:iron_plate:0,10,quark:iron_plate:1,10,STAINED_CLAY:15,10,STAINED_CLAY:9,100)
RandomBlock(-6,2,9,CONCRETE:7,65,quark:iron_plate:0,10,quark:iron_plate:1,10,STAINED_CLAY:15,10,STAINED_CLAY:9,100)
RandomBlock(-6,3,1,CONCRETE:7,65,quark:iron_plate:0,10,quark:iron_plate:1,10,STAINED_CLAY:15,10,STAINED_CLAY:9,100)
RandomBlock(-6,3,2,CONCRETE:7,65,quark:iron_plate:0,10,quark:iron_plate:1,10,STAINED_CLAY:15,10,STAINED_CLAY:9,100)
RandomBlock(-6,3,8,CONCRETE:7,65,quark:iron_plate:0,10,quark:iron_plate:1,10,STAINED_CLAY:15,10,STAINED_CLAY:9,100)
RandomBlock(-6,3,9,CONCRETE:7,65,quark:iron_plate:0,10,quark:iron_plate:1,10,STAINED_CLAY:15,10,STAINED_CLAY:9,100)
RandomBlock(-6,4,1,CONCRETE:7,65,quark:iron_plate:0,10,quark:iron_plate:1,10,STAINED_CLAY:15,10,STAINED_CLAY:9,100)
RandomBlock(-6,4,2,CONCRETE:7,65,quark:iron_plate:0,10,quark:iron_plate:1,10,STAINED_CLAY:15,10,STAINED_CLAY:9,100)
RandomBlock(-6,4,8,CONCRETE:7,65,quark:iron_plate:0,10,quark:iron_plate:1,10,STAINED_CLAY:15,10,STAINED_CLAY:9,100)
RandomBlock(-6,4,9,CONCRETE:7,65,quark:iron_plate:0,10,quark:iron_plate:1,10,STAINED_CLAY:15,10,STAINED_CLAY:9,100)
RandomBlock(-6,5,1,CONCRETE:7,65,quark:iron_plate:0,10,quark:iron_plate:1,10,STAINED_CLAY:15,10,STAINED_CLAY:9,100)
RandomBlock(-6,5,2,CONCRETE:7,65,quark:iron_plate:0,10,quark:iron_plate:1,10,STAINED_CLAY:15,10,STAINED_CLAY:9,100)
RandomBlock(-6,5,8,CONCRETE:7,65,quark:iron_plate:0,10,quark:iron_plate:1,10,STAINED_CLAY:15,10,STAINED_CLAY:9,100)
RandomBlock(-6,5,9,CONCRETE:7,65,quark:iron_plate:0,10,quark:iron_plate:1,10,STAINED_CLAY:15,10,STAINED_CLAY:9,100)
RandomBlock(-6,6,1,CONCRETE:7,65,quark:iron_plate:0,10,quark:iron_plate:1,10,STAINED_CLAY:15,10,STAINED_CLAY:9,100)
RandomBlock(-6,6,2,CONCRETE:7,65,quark:iron_plate:0,10,quark:iron_plate:1,10,STAINED_CLAY:15,10,STAINED_CLAY:9,100)
RandomBlock(-6,6,8,CONCRETE:7,65,quark:iron_plate:0,10,quark:iron_plate:1,10,STAINED_CLAY:15,10,STAINED_CLAY:9,100)
RandomBlock(-6,6,9,CONCRETE:7,65,quark:iron_plate:0,10,quark:iron_plate:1,10,STAINED_CLAY:15,10,STAINED_CLAY:9,100)
RandomBlock(-6,7,1,CONCRETE:7,65,quark:iron_plate:0,10,quark:iron_plate:1,10,STAINED_CLAY:15,10,STAINED_CLAY:9,100)
RandomBlock(-6,7,2,CONCRETE:7,65,quark:iron_plate:0,10,quark:iron_plate:1,10,STAINED_CLAY:15,10,STAINED_CLAY:9,100)
RandomBlock(-6,7,8,CONCRETE:7,65,quark:iron_plate:0,10,quark:iron_plate:1,10,STAINED_CLAY:15,10,STAINED_CLAY:9,100)
RandomBlock(-6,7,9,CONCRETE:7,65,quark:iron_plate:0,10,quark:iron_plate:1,10,STAINED_CLAY:15,10,STAINED_CLAY:9,100)
RandomBlock(-6,8,1,CONCRETE:7,65,quark:iron_plate:0,10,quark:iron_plate:1,10,STAINED_CLAY:15,10,STAINED_CLAY:9,100)
RandomBlock(-6,8,2,CONCRETE:7,65,quark:iron_plate:0,10,quark:iron_plate:1,10,STAINED_CLAY:15,10,STAINED_CLAY:9,100)
RandomBlock(-6,8,8,CONCRETE:7,65,quark:iron_plate:0,10,quark:iron_plate:1,10,STAINED_CLAY:15,10,STAINED_CLAY:9,100)
RandomBlock(-6,8,9,CONCRETE:7,65,quark:iron_plate:0,10,quark:iron_plate:1,10,STAINED_CLAY:15,10,STAINED_CLAY:9,100)
RandomBlock(-6,9,1,CONCRETE:7,65,quark:iron_plate:0,10,quark:iron_plate:1,10,STAINED_CLAY:15,10,STAINED_CLAY:9,100)
RandomBlock(-6,9,2,CONCRETE:7,65,quark:iron_plate:0,10,quark:iron_plate:1,10,STAINED_CLAY:15,10,STAINED_CLAY:9,100)
RandomBlock(-6,9,4,CONCRETE:7,65,quark:iron_plate:0,10,quark:iron_plate:1,10,STAINED_CLAY:15,10,STAINED_CLAY:9,100)
RandomBlock(-6,9,6,CONCRETE:7,65,quark:iron_plate:0,10,quark:iron_plate:1,10,STAINED_CLAY:15,10,STAINED_CLAY:9,100)
RandomBlock(-6,9,8,CONCRETE:7,65,quark:iron_plate:0,10,quark:iron_plate:1,10,STAINED_CLAY:15,10,STAINED_CLAY:9,100)
RandomBlock(-6,9,9,CONCRETE:7,65,quark:iron_plate:0,10,quark:iron_plate:1,10,STAINED_CLAY:15,10,STAINED_CLAY:9,100)
RandomBlock(-6,10,1,CONCRETE:7,65,quark:iron_plate:0,10,quark:iron_plate:1,10,STAINED_CLAY:15,10,STAINED_CLAY:9,100)
RandomBlock(-6,10,2,CONCRETE:7,65,quark:iron_plate:0,10,quark:iron_plate:1,10,STAINED_CLAY:15,10,STAINED_CLAY:9,100)
RandomBlock(-6,10,3,CONCRETE:7,65,quark:iron_plate:0,10,quark:iron_plate:1,10,STAINED_CLAY:15,10,STAINED_CLAY:9,100)
RandomBlock(-6,10,4,CONCRETE:7,65,quark:iron_plate:0,10,quark:iron_plate:1,10,STAINED_CLAY:15,10,STAINED_CLAY:9,100)
RandomBlock(-6,10,5,CONCRETE:7,65,quark:iron_plate:0,10,quark:iron_plate:1,10,STAINED_CLAY:15,10,STAINED_CLAY:9,100)
RandomBlock(-6,10,6,CONCRETE:7,65,quark:iron_plate:0,10,quark:iron_plate:1,10,STAINED_CLAY:15,10,STAINED_CLAY:9,100)
RandomBlock(-6,10,7,CONCRETE:7,65,quark:iron_plate:0,10,quark:iron_plate:1,10,STAINED_CLAY:15,10,STAINED_CLAY:9,100)
RandomBlock(-6,10,8,CONCRETE:7,65,quark:iron_plate:0,10,quark:iron_plate:1,10,STAINED_CLAY:15,10,STAINED_CLAY:9,100)
RandomBlock(-6,10,9,CONCRETE:7,65,quark:iron_plate:0,10,quark:iron_plate:1,10,STAINED_CLAY:15,10,STAINED_CLAY:9,100)
RandomBlock(-6,11,1,CONCRETE:7,65,quark:iron_plate:0,10,quark:iron_plate:1,10,STAINED_CLAY:15,10,STAINED_CLAY:9,100)
RandomBlock(-6,11,2,CONCRETE:7,65,quark:iron_plate:0,10,quark:iron_plate:1,10,STAINED_CLAY:15,10,STAINED_CLAY:9,100)
Block(-6,11,3,STAINED_GLASS:15)
RandomBlock(-6,11,4,CONCRETE:7,65,quark:iron_plate:0,10,quark:iron_plate:1,10,STAINED_CLAY:15,10,STAINED_CLAY:9,100)
Block(-6,11,5,STAINED_GLASS:15)
RandomBlock(-6,11,6,CONCRETE:7,65,quark:iron_plate:0,10,quark:iron_plate:1,10,STAINED_CLAY:15,10,STAINED_CLAY:9,100)
Block(-6,11,7,STAINED_GLASS:15)
RandomBlock(-6,11,8,CONCRETE:7,65,quark:iron_plate:0,10,quark:iron_plate:1,10,STAINED_CLAY:15,10,STAINED_CLAY:9,100)
RandomBlock(-6,11,9,CONCRETE:7,65,quark:iron_plate:0,10,quark:iron_plate:1,10,STAINED_CLAY:15,10,STAINED_CLAY:9,100)
RandomBlock(-6,12,1,CONCRETE:7,65,quark:iron_plate:0,10,quark:iron_plate:1,10,STAINED_CLAY:15,10,STAINED_CLAY:9,100)
RandomBlock(-6,12,2,CONCRETE:7,65,quark:iron_plate:0,10,quark:iron_plate:1,10,STAINED_CLAY:15,10,STAINED_CLAY:9,100)
Block(-6,12,3,STAINED_GLASS:15)
RandomBlock(-6,12,4,CONCRETE:7,65,quark:iron_plate:0,10,quark:iron_plate:1,10,STAINED_CLAY:15,10,STAINED_CLAY:9,100)
Block(-6,12,5,STAINED_GLASS:15)
RandomBlock(-6,12,6,CONCRETE:7,65,quark:iron_plate:0,10,quark:iron_plate:1,10,STAINED_CLAY:15,10,STAINED_CLAY:9,100)
Block(-6,12,7,STAINED_GLASS:15)
RandomBlock(-6,12,8,CONCRETE:7,65,quark:iron_plate:0,10,quark:iron_plate:1,10,STAINED_CLAY:15,10,STAINED_CLAY:9,100)
RandomBlock(-6,12,9,CONCRETE:7,65,quark:iron_plate:0,10,quark:iron_plate:1,10,STAINED_CLAY:15,10,STAINED_CLAY:9,100)
RandomBlock(-6,13,1,CONCRETE:7,65,quark:iron_plate:0,10,quark:iron_plate:1,10,STAINED_CLAY:15,10,STAINED_CLAY:9,100)
RandomBlock(-6,13,2,CONCRETE:7,65,quark:iron_plate:0,10,quark:iron_plate:1,10,STAINED_CLAY:15,10,STAINED_CLAY:9,100)
Block(-6,13,3,STAINED_GLASS:15)
RandomBlock(-6,13,4,CONCRETE:7,65,quark:iron_plate:0,10,quark:iron_plate:1,10,STAINED_CLAY:15,10,STAINED_CLAY:9,100)
Block(-6,13,5,STAINED_GLASS:15)
RandomBlock(-6,13,6,CONCRETE:7,65,quark:iron_plate:0,10,quark:iron_plate:1,10,STAINED_CLAY:15,10,STAINED_CLAY:9,100)
Block(-6,13,7,STAINED_GLASS:15)
RandomBlock(-6,13,8,CONCRETE:7,65,quark:iron_plate:0,10,quark:iron_plate:1,10,STAINED_CLAY:15,10,STAINED_CLAY:9,100)
RandomBlock(-6,13,9,CONCRETE:7,65,quark:iron_plate:0,10,quark:iron_plate:1,10,STAINED_CLAY:15,10,STAINED_CLAY:9,100)
RandomBlock(-6,14,1,CONCRETE:7,65,quark:iron_plate:0,10,quark:iron_plate:1,10,STAINED_CLAY:15,10,STAINED_CLAY:9,100)
RandomBlock(-6,14,2,CONCRETE:7,65,quark:iron_plate:0,10,quark:iron_plate:1,10,STAINED_CLAY:15,10,STAINED_CLAY:9,100)
Block(-6,14,3,STAINED_GLASS:15)
RandomBlock(-6,14,4,CONCRETE:7,65,quark:iron_plate:0,10,quark:iron_plate:1,10,STAINED_CLAY:15,10,STAINED_CLAY:9,100)
Block(-6,14,5,STAINED_GLASS:15)
RandomBlock(-6,14,6,CONCRETE:7,65,quark:iron_plate:0,10,quark:iron_plate:1,10,STAINED_CLAY:15,10,STAINED_CLAY:9,100)
Block(-6,14,7,STAINED_GLASS:15)
RandomBlock(-6,14,8,CONCRETE:7,65,quark:iron_plate:0,10,quark:iron_plate:1,10,STAINED_CLAY:15,10,STAINED_CLAY:9,100)
RandomBlock(-6,14,9,CONCRETE:7,65,quark:iron_plate:0,10,quark:iron_plate:1,10,STAINED_CLAY:15,10,STAINED_CLAY:9,100)
RandomBlock(-6,15,1,CONCRETE:7,65,quark:iron_plate:0,10,quark:iron_plate:1,10,STAINED_CLAY:15,10,STAINED_CLAY:9,100)
RandomBlock(-6,15,2,CONCRETE:7,65,quark:iron_plate:0,10,quark:iron_plate:1,10,STAINED_CLAY:15,10,STAINED_CLAY:9,100)
Block(-6,15,3,STEP:0)
RandomBlock(-6,15,4,CONCRETE:7,65,quark:iron_plate:0,10,quark:iron_plate:1,10,STAINED_CLAY:15,10,STAINED_CLAY:9,100)
Block(-6,15,5,STEP:0)
RandomBlock(-6,15,6,CONCRETE:7,65,quark:iron_plate:0,10,quark:iron_plate:1,10,STAINED_CLAY:15,10,STAINED_CLAY:9,100)
Block(-6,15,7,STEP:0)
RandomBlock(-6,15,8,CONCRETE:7,65,quark:iron_plate:0,10,quark:iron_plate:1,10,STAINED_CLAY:15,10,STAINED_CLAY:9,100)
RandomBlock(-6,15,9,CONCRETE:7,65,quark:iron_plate:0,10,quark:iron_plate:1,10,STAINED_CLAY:15,10,STAINED_CLAY:9,100)
RandomBlock(-5,9,4,CONCRETE:7,65,quark:iron_plate:0,10,quark:iron_plate:1,10,STAINED_CLAY:15,10,STAINED_CLAY:9,100)
RandomBlock(-5,9,6,CONCRETE:7,65,quark:iron_plate:0,10,quark:iron_plate:1,10,STAINED_CLAY:15,10,STAINED_CLAY:9,100)
RandomBlock(-5,10,1,CONCRETE:7,65,quark:iron_plate:0,10,quark:iron_plate:1,10,STAINED_CLAY:15,10,STAINED_CLAY:9,100)
RandomBlock(-5,10,2,CONCRETE:7,65,quark:iron_plate:0,10,quark:iron_plate:1,10,STAINED_CLAY:15,10,STAINED_CLAY:9,100)
RandomBlock(-5,10,3,CONCRETE:7,65,quark:iron_plate:0,10,quark:iron_plate:1,10,STAINED_CLAY:15,10,STAINED_CLAY:9,100)
RandomBlock(-5,10,4,CONCRETE:7,65,quark:iron_plate:0,10,quark:iron_plate:1,10,STAINED_CLAY:15,10,STAINED_CLAY:9,100)
RandomBlock(-5,10,5,CONCRETE:7,65,quark:iron_plate:0,10,quark:iron_plate:1,10,STAINED_CLAY:15,10,STAINED_CLAY:9,100)
RandomBlock(-5,10,6,CONCRETE:7,65,quark:iron_plate:0,10,quark:iron_plate:1,10,STAINED_CLAY:15,10,STAINED_CLAY:9,100)
RandomBlock(-5,10,7,CONCRETE:7,65,quark:iron_plate:0,10,quark:iron_plate:1,10,STAINED_CLAY:15,10,STAINED_CLAY:9,100)
RandomBlock(-5,10,8,CONCRETE:7,65,quark:iron_plate:0,10,quark:iron_plate:1,10,STAINED_CLAY:15,10,STAINED_CLAY:9,100)
Block(-5,11,1,STAINED_GLASS:15)
Block(-5,11,2,AIR:0)
Block(-5,11,3,AIR:0)
Block(-5,11,4,AIR:0)
Block(-5,11,5,AIR:0)
Block(-5,11,6,AIR:0)
Block(-5,11,7,AIR:0)
Block(-5,11,8,STAINED_GLASS:15)
Block(-5,12,1,STAINED_GLASS:15)
Block(-5,12,2,AIR:0)
Block(-5,12,3,AIR:0)
Block(-5,12,4,AIR:0)
Block(-5,12,5,AIR:0)
Block(-5,12,6,AIR:0)
Block(-5,12,7,AIR:0)
Block(-5,12,8,STAINED_GLASS:15)
Block(-5,13,1,STAINED_GLASS:15)
Block(-5,13,2,AIR:0)
Block(-5,13,3,AIR:0)
Block(-5,13,4,AIR:0)
Block(-5,13,6,AIR:0)
Block(-5,13,7,AIR:0)
Block(-5,13,8,STAINED_GLASS:15)
Block(-5,14,1,STAINED_GLASS:15)
Block(-5,14,2,AIR:0)
Block(-5,14,3,AIR:0)
Block(-5,14,4,AIR:0)
Block(-5,14,5,AIR:0)
Block(-5,14,6,AIR:0)
Block(-5,14,7,AIR:0)
Block(-5,14,8,STAINED_GLASS:15)
RandomBlock(-5,15,1,CONCRETE:7,65,quark:iron_plate:0,10,quark:iron_plate:1,10,STAINED_CLAY:15,10,STAINED_CLAY:9,100)
RandomBlock(-5,15,2,CONCRETE:7,65,quark:iron_plate:0,10,quark:iron_plate:1,10,STAINED_CLAY:15,10,STAINED_CLAY:9,100)
Block(-5,15,3,STEP:0)
RandomBlock(-5,15,4,CONCRETE:7,65,quark:iron_plate:0,10,quark:iron_plate:1,10,STAINED_CLAY:15,10,STAINED_CLAY:9,100)
Block(-5,15,5,STEP:0)
RandomBlock(-5,15,6,CONCRETE:7,65,quark:iron_plate:0,10,quark:iron_plate:1,10,STAINED_CLAY:15,10,STAINED_CLAY:9,100)
Block(-5,15,7,STEP:0)
RandomBlock(-5,15,8,CONCRETE:7,65,quark:iron_plate:0,10,quark:iron_plate:1,10,STAINED_CLAY:15,10,STAINED_CLAY:9,100)
RandomBlock(-4,9,4,CONCRETE:7,65,quark:iron_plate:0,10,quark:iron_plate:1,10,STAINED_CLAY:15,10,STAINED_CLAY:9,100)
RandomBlock(-4,9,6,CONCRETE:7,65,quark:iron_plate:0,10,quark:iron_plate:1,10,STAINED_CLAY:15,10,STAINED_CLAY:9,100)
RandomBlock(-4,10,1,CONCRETE:7,65,quark:iron_plate:0,10,quark:iron_plate:1,10,STAINED_CLAY:15,10,STAINED_CLAY:9,100)
RandomBlock(-4,10,2,CONCRETE:7,65,quark:iron_plate:0,10,quark:iron_plate:1,10,STAINED_CLAY:15,10,STAINED_CLAY:9,100)
RandomBlock(-4,10,3,CONCRETE:7,65,quark:iron_plate:0,10,quark:iron_plate:1,10,STAINED_CLAY:15,10,STAINED_CLAY:9,100)
RandomBlock(-4,10,4,CONCRETE:7,65,quark:iron_plate:0,10,quark:iron_plate:1,10,STAINED_CLAY:15,10,STAINED_CLAY:9,100)
RandomBlock(-4,10,5,CONCRETE:7,65,quark:iron_plate:0,10,quark:iron_plate:1,10,STAINED_CLAY:15,10,STAINED_CLAY:9,100)
RandomBlock(-4,10,6,CONCRETE:7,65,quark:iron_plate:0,10,quark:iron_plate:1,10,STAINED_CLAY:15,10,STAINED_CLAY:9,100)
RandomBlock(-4,10,7,CONCRETE:7,65,quark:iron_plate:0,10,quark:iron_plate:1,10,STAINED_CLAY:15,10,STAINED_CLAY:9,100)
RandomBlock(-4,10,8,CONCRETE:7,65,quark:iron_plate:0,10,quark:iron_plate:1,10,STAINED_CLAY:15,10,STAINED_CLAY:9,100)
Block(-4,11,1,STAINED_GLASS:15)
Block(-4,11,2,AIR:0)
Block(-4,11,3,AIR:0)
Block(-4,11,4,IRON_TRAPDOOR:6)
Block(-4,11,5,IRON_TRAPDOOR:6)
Block(-4,11,6,IRON_TRAPDOOR:6)
Block(-4,11,7,SMOOTH_STAIRS:0)
Block(-4,11,8,STAINED_GLASS:15)
Block(-4,12,1,STAINED_GLASS:15)
Block(-4,12,2,AIR:0)
Block(-4,12,3,AIR:0)
Block(-4,12,4,IRON_TRAPDOOR:6)
Block(-4,12,5,IRON_TRAPDOOR:6)
Block(-4,12,6,IRON_TRAPDOOR:6)
Block(-4,12,7,AIR:0)
Block(-4,12,8,STAINED_GLASS:15)
Block(-4,13,1,STAINED_GLASS:15)
Block(-4,13,2,AIR:0)
Block(-4,13,3,AIR:0)
Block(-4,13,4,AIR:0)
Block(-4,13,5,AIR:0)
Block(-4,13,6,AIR:0)
Block(-4,13,7,AIR:0)
Block(-4,13,8,STAINED_GLASS:15)
Block(-4,14,1,STAINED_GLASS:15)
Block(-4,14,2,AIR:0)
Block(-4,14,3,AIR:0)
Block(-4,14,4,AIR:0)
Block(-4,14,5,AIR:0)
Block(-4,14,6,AIR:0)
Block(-4,14,7,AIR:0)
Block(-4,14,8,STAINED_GLASS:15)
RandomBlock(-4,15,1,CONCRETE:7,65,quark:iron_plate:0,10,quark:iron_plate:1,10,STAINED_CLAY:15,10,STAINED_CLAY:9,100)
RandomBlock(-4,15,2,CONCRETE:7,65,quark:iron_plate:0,10,quark:iron_plate:1,10,STAINED_CLAY:15,10,STAINED_CLAY:9,100)
Block(-4,15,3,STEP:0)
Block(-4,15,4,STEP:0)
Block(-4,15,5,STEP:0)
Block(-4,15,6,STEP:0)
Block(-4,15,7,STEP:0)
RandomBlock(-4,15,8,CONCRETE:7,65,quark:iron_plate:0,10,quark:iron_plate:1,10,STAINED_CLAY:15,10,STAINED_CLAY:9,100)
RandomBlock(-3,9,4,CONCRETE:7,65,quark:iron_plate:0,10,quark:iron_plate:1,10,STAINED_CLAY:15,10,STAINED_CLAY:9,100)
RandomBlock(-3,9,6,CONCRETE:7,65,quark:iron_plate:0,10,quark:iron_plate:1,10,STAINED_CLAY:15,10,STAINED_CLAY:9,100)
RandomBlock(-3,10,1,CONCRETE:7,65,quark:iron_plate:0,10,quark:iron_plate:1,10,STAINED_CLAY:15,10,STAINED_CLAY:9,100)
RandomBlock(-3,10,2,CONCRETE:7,65,quark:iron_plate:0,10,quark:iron_plate:1,10,STAINED_CLAY:15,10,STAINED_CLAY:9,100)
RandomBlock(-3,10,3,CONCRETE:7,65,quark:iron_plate:0,10,quark:iron_plate:1,10,STAINED_CLAY:15,10,STAINED_CLAY:9,100)
RandomBlock(-3,10,4,CONCRETE:7,65,quark:iron_plate:0,10,quark:iron_plate:1,10,STAINED_CLAY:15,10,STAINED_CLAY:9,100)
RandomBlock(-3,10,5,CONCRETE:7,65,quark:iron_plate:0,10,quark:iron_plate:1,10,STAINED_CLAY:15,10,STAINED_CLAY:9,100)
RandomBlock(-3,10,6,CONCRETE:7,65,quark:iron_plate:0,10,quark:iron_plate:1,10,STAINED_CLAY:15,10,STAINED_CLAY:9,100)
RandomBlock(-3,10,7,CONCRETE:7,65,quark:iron_plate:0,10,quark:iron_plate:1,10,STAINED_CLAY:15,10,STAINED_CLAY:9,100)
RandomBlock(-3,10,8,CONCRETE:7,65,quark:iron_plate:0,10,quark:iron_plate:1,10,STAINED_CLAY:15,10,STAINED_CLAY:9,100)
Block(-3,11,1,STAINED_GLASS:15)
Block(-3,11,2,AIR:0)
Block(-3,11,3,IRON_TRAPDOOR:4)
Block(-3,11,4,DOUBLE_STEP:0)
Block(-3,11,5,STEP:8)
Block(-3,11,6,STEP:8)
Block(-3,11,7,DOUBLE_STEP:0)
Block(-3,11,8,STAINED_GLASS:15)
Block(-3,12,1,STAINED_GLASS:15)
Block(-3,12,2,AIR:0)
Block(-3,12,3,IRON_TRAPDOOR:4)
Block(-3,12,4,AIR:0)
Block(-3,12,5,AIR:0)
Block(-3,12,6,AIR:0)
Block(-3,12,7,AIR:0)
Block(-3,12,8,STAINED_GLASS:15)
Block(-3,13,1,STAINED_GLASS:15)
Block(-3,13,2,AIR:0)
Block(-3,13,3,AIR:0)
Block(-3,13,4,AIR:0)
Block(-3,13,5,AIR:0)
Block(-3,13,6,AIR:0)
Block(-3,13,7,AIR:0)
Block(-3,13,8,STAINED_GLASS:15)
Block(-3,14,1,STAINED_GLASS:15)
Block(-3,14,2,AIR:0)
Block(-3,14,3,AIR:0)
Block(-3,14,4,AIR:0)
Block(-3,14,5,AIR:0)
Block(-3,14,6,AIR:0)
Block(-3,14,7,AIR:0)
Block(-3,14,8,STAINED_GLASS:15)
RandomBlock(-3,15,1,CONCRETE:7,65,quark:iron_plate:0,10,quark:iron_plate:1,10,STAINED_CLAY:15,10,STAINED_CLAY:9,100)
RandomBlock(-3,15,2,CONCRETE:7,65,quark:iron_plate:0,10,quark:iron_plate:1,10,STAINED_CLAY:15,10,STAINED_CLAY:9,100)
Block(-3,15,3,STEP:0)
Block(-3,15,4,STEP:0)
Block(-3,15,5,STEP:0)
Block(-3,15,6,STEP:0)
Block(-3,15,7,STEP:0)
RandomBlock(-3,15,8,CONCRETE:7,65,quark:iron_plate:0,10,quark:iron_plate:1,10,STAINED_CLAY:15,10,STAINED_CLAY:9,100)
RandomBlock(-2,0,1,CONCRETE:7,65,quark:iron_plate:0,10,quark:iron_plate:1,10,STAINED_CLAY:15,10,STAINED_CLAY:9,100)
RandomBlock(-2,0,2,CONCRETE:7,65,quark:iron_plate:0,10,quark:iron_plate:1,10,STAINED_CLAY:15,10,STAINED_CLAY:9,100)
RandomBlock(-2,0,8,CONCRETE:7,65,quark:iron_plate:0,10,quark:iron_plate:1,10,STAINED_CLAY:15,10,STAINED_CLAY:9,100)
RandomBlock(-2,0,9,CONCRETE:7,65,quark:iron_plate:0,10,quark:iron_plate:1,10,STAINED_CLAY:15,10,STAINED_CLAY:9,100)
RandomBlock(-2,1,1,CONCRETE:7,65,quark:iron_plate:0,10,quark:iron_plate:1,10,STAINED_CLAY:15,10,STAINED_CLAY:9,100)
RandomBlock(-2,1,2,CONCRETE:7,65,quark:iron_plate:0,10,quark:iron_plate:1,10,STAINED_CLAY:15,10,STAINED_CLAY:9,100)
RandomBlock(-2,1,8,CONCRETE:7,65,quark:iron_plate:0,10,quark:iron_plate:1,10,STAINED_CLAY:15,10,STAINED_CLAY:9,100)
RandomBlock(-2,1,9,CONCRETE:7,65,quark:iron_plate:0,10,quark:iron_plate:1,10,STAINED_CLAY:15,10,STAINED_CLAY:9,100)
RandomBlock(-2,2,1,CONCRETE:7,65,quark:iron_plate:0,10,quark:iron_plate:1,10,STAINED_CLAY:15,10,STAINED_CLAY:9,100)
RandomBlock(-2,2,2,CONCRETE:7,65,quark:iron_plate:0,10,quark:iron_plate:1,10,STAINED_CLAY:15,10,STAINED_CLAY:9,100)
RandomBlock(-2,2,8,CONCRETE:7,65,quark:iron_plate:0,10,quark:iron_plate:1,10,STAINED_CLAY:15,10,STAINED_CLAY:9,100)
RandomBlock(-2,2,9,CONCRETE:7,65,quark:iron_plate:0,10,quark:iron_plate:1,10,STAINED_CLAY:15,10,STAINED_CLAY:9,100)
RandomBlock(-2,3,1,CONCRETE:7,65,quark:iron_plate:0,10,quark:iron_plate:1,10,STAINED_CLAY:15,10,STAINED_CLAY:9,100)
RandomBlock(-2,3,2,CONCRETE:7,65,quark:iron_plate:0,10,quark:iron_plate:1,10,STAINED_CLAY:15,10,STAINED_CLAY:9,100)
RandomBlock(-2,3,8,CONCRETE:7,65,quark:iron_plate:0,10,quark:iron_plate:1,10,STAINED_CLAY:15,10,STAINED_CLAY:9,100)
RandomBlock(-2,3,9,CONCRETE:7,65,quark:iron_plate:0,10,quark:iron_plate:1,10,STAINED_CLAY:15,10,STAINED_CLAY:9,100)
RandomBlock(-2,4,1,CONCRETE:7,65,quark:iron_plate:0,10,quark:iron_plate:1,10,STAINED_CLAY:15,10,STAINED_CLAY:9,100)
RandomBlock(-2,4,2,CONCRETE:7,65,quark:iron_plate:0,10,quark:iron_plate:1,10,STAINED_CLAY:15,10,STAINED_CLAY:9,100)
RandomBlock(-2,4,8,CONCRETE:7,65,quark:iron_plate:0,10,quark:iron_plate:1,10,STAINED_CLAY:15,10,STAINED_CLAY:9,100)
RandomBlock(-2,4,9,CONCRETE:7,65,quark:iron_plate:0,10,quark:iron_plate:1,10,STAINED_CLAY:15,10,STAINED_CLAY:9,100)
RandomBlock(-2,5,1,CONCRETE:7,65,quark:iron_plate:0,10,quark:iron_plate:1,10,STAINED_CLAY:15,10,STAINED_CLAY:9,100)
RandomBlock(-2,5,2,CONCRETE:7,65,quark:iron_plate:0,10,quark:iron_plate:1,10,STAINED_CLAY:15,10,STAINED_CLAY:9,100)
RandomBlock(-2,5,8,CONCRETE:7,65,quark:iron_plate:0,10,quark:iron_plate:1,10,STAINED_CLAY:15,10,STAINED_CLAY:9,100)
RandomBlock(-2,5,9,CONCRETE:7,65,quark:iron_plate:0,10,quark:iron_plate:1,10,STAINED_CLAY:15,10,STAINED_CLAY:9,100)
RandomBlock(-2,6,1,CONCRETE:7,65,quark:iron_plate:0,10,quark:iron_plate:1,10,STAINED_CLAY:15,10,STAINED_CLAY:9,100)
RandomBlock(-2,6,2,CONCRETE:7,65,quark:iron_plate:0,10,quark:iron_plate:1,10,STAINED_CLAY:15,10,STAINED_CLAY:9,100)
RandomBlock(-2,6,8,CONCRETE:7,65,quark:iron_plate:0,10,quark:iron_plate:1,10,STAINED_CLAY:15,10,STAINED_CLAY:9,100)
RandomBlock(-2,6,9,CONCRETE:7,65,quark:iron_plate:0,10,quark:iron_plate:1,10,STAINED_CLAY:15,10,STAINED_CLAY:9,100)
RandomBlock(-2,7,1,CONCRETE:7,65,quark:iron_plate:0,10,quark:iron_plate:1,10,STAINED_CLAY:15,10,STAINED_CLAY:9,100)
RandomBlock(-2,7,2,CONCRETE:7,65,quark:iron_plate:0,10,quark:iron_plate:1,10,STAINED_CLAY:15,10,STAINED_CLAY:9,100)
RandomBlock(-2,7,8,CONCRETE:7,65,quark:iron_plate:0,10,quark:iron_plate:1,10,STAINED_CLAY:15,10,STAINED_CLAY:9,100)
RandomBlock(-2,7,9,CONCRETE:7,65,quark:iron_plate:0,10,quark:iron_plate:1,10,STAINED_CLAY:15,10,STAINED_CLAY:9,100)
RandomBlock(-2,8,1,CONCRETE:7,65,quark:iron_plate:0,10,quark:iron_plate:1,10,STAINED_CLAY:15,10,STAINED_CLAY:9,100)
RandomBlock(-2,8,2,CONCRETE:7,65,quark:iron_plate:0,10,quark:iron_plate:1,10,STAINED_CLAY:15,10,STAINED_CLAY:9,100)
RandomBlock(-2,8,8,CONCRETE:7,65,quark:iron_plate:0,10,quark:iron_plate:1,10,STAINED_CLAY:15,10,STAINED_CLAY:9,100)
RandomBlock(-2,8,9,CONCRETE:7,65,quark:iron_plate:0,10,quark:iron_plate:1,10,STAINED_CLAY:15,10,STAINED_CLAY:9,100)
RandomBlock(-2,9,1,CONCRETE:7,65,quark:iron_plate:0,10,quark:iron_plate:1,10,STAINED_CLAY:15,10,STAINED_CLAY:9,100)
RandomBlock(-2,9,2,CONCRETE:7,65,quark:iron_plate:0,10,quark:iron_plate:1,10,STAINED_CLAY:15,10,STAINED_CLAY:9,100)
RandomBlock(-2,9,4,CONCRETE:7,65,quark:iron_plate:0,10,quark:iron_plate:1,10,STAINED_CLAY:15,10,STAINED_CLAY:9,100)
RandomBlock(-2,9,6,CONCRETE:7,65,quark:iron_plate:0,10,quark:iron_plate:1,10,STAINED_CLAY:15,10,STAINED_CLAY:9,100)
RandomBlock(-2,9,8,CONCRETE:7,65,quark:iron_plate:0,10,quark:iron_plate:1,10,STAINED_CLAY:15,10,STAINED_CLAY:9,100)
RandomBlock(-2,9,9,CONCRETE:7,65,quark:iron_plate:0,10,quark:iron_plate:1,10,STAINED_CLAY:15,10,STAINED_CLAY:9,100)
RandomBlock(-2,10,1,CONCRETE:7,65,quark:iron_plate:0,10,quark:iron_plate:1,10,STAINED_CLAY:15,10,STAINED_CLAY:9,100)
RandomBlock(-2,10,2,CONCRETE:7,65,quark:iron_plate:0,10,quark:iron_plate:1,10,STAINED_CLAY:15,10,STAINED_CLAY:9,100)
RandomBlock(-2,10,3,CONCRETE:7,65,quark:iron_plate:0,10,quark:iron_plate:1,10,STAINED_CLAY:15,10,STAINED_CLAY:9,100)
RandomBlock(-2,10,4,CONCRETE:7,65,quark:iron_plate:0,10,quark:iron_plate:1,10,STAINED_CLAY:15,10,STAINED_CLAY:9,100)
RandomBlock(-2,10,5,CONCRETE:7,65,quark:iron_plate:0,10,quark:iron_plate:1,10,STAINED_CLAY:15,10,STAINED_CLAY:9,100)
RandomBlock(-2,10,6,CONCRETE:7,65,quark:iron_plate:0,10,quark:iron_plate:1,10,STAINED_CLAY:15,10,STAINED_CLAY:9,100)
RandomBlock(-2,10,7,CONCRETE:7,65,quark:iron_plate:0,10,quark:iron_plate:1,10,STAINED_CLAY:15,10,STAINED_CLAY:9,100)
RandomBlock(-2,10,8,CONCRETE:7,65,quark:iron_plate:0,10,quark:iron_plate:1,10,STAINED_CLAY:15,10,STAINED_CLAY:9,100)
RandomBlock(-2,10,9,CONCRETE:7,65,quark:iron_plate:0,10,quark:iron_plate:1,10,STAINED_CLAY:15,10,STAINED_CLAY:9,100)
Block(-2,11,1,STAINED_GLASS:15)
Block(-2,11,2,AIR:0)
Block(-2,11,3,IRON_TRAPDOOR:4)
Block(-2,11,4,STEP:8)
Block(-2,11,5,STEP:8)
Block(-2,11,6,STEP:8)
Block(-2,11,7,STEP:8)
RandomBlock(-2,11,8,CONCRETE:7,65,quark:iron_plate:0,10,quark:iron_plate:1,10,STAINED_CLAY:15,10,STAINED_CLAY:9,100)
RandomBlock(-2,11,9,CONCRETE:7,65,quark:iron_plate:0,10,quark:iron_plate:1,10,STAINED_CLAY:15,10,STAINED_CLAY:9,100)
Block(-2,12,1,STAINED_GLASS:15)
Block(-2,12,2,AIR:0)
Block(-2,12,3,IRON_TRAPDOOR:4)
Block(-2,12,4,AIR:0)
Block(-2,12,5,AIR:0)
RandomBlock(-2,12,8,CONCRETE:7,65,quark:iron_plate:0,10,quark:iron_plate:1,10,STAINED_CLAY:15,10,STAINED_CLAY:9,100)
RandomBlock(-2,12,9,CONCRETE:7,65,quark:iron_plate:0,10,quark:iron_plate:1,10,STAINED_CLAY:15,10,STAINED_CLAY:9,100)
Block(-2,13,1,STAINED_GLASS:15)
Block(-2,13,2,AIR:0)
Block(-2,13,3,AIR:0)
Block(-2,13,4,AIR:0)
Block(-2,13,5,AIR:0)
Block(-2,13,6,AIR:0)
Block(-2,13,7,AIR:0)
RandomBlock(-2,13,8,CONCRETE:7,65,quark:iron_plate:0,10,quark:iron_plate:1,10,STAINED_CLAY:15,10,STAINED_CLAY:9,100)
RandomBlock(-2,13,9,CONCRETE:7,65,quark:iron_plate:0,10,quark:iron_plate:1,10,STAINED_CLAY:15,10,STAINED_CLAY:9,100)
Block(-2,14,1,STAINED_GLASS:15)
Block(-2,14,2,AIR:0)
Block(-2,14,3,AIR:0)
Block(-2,14,4,AIR:0)
Block(-2,14,5,AIR:0)
Block(-2,14,6,AIR:0)
Block(-2,14,7,AIR:0)
RandomBlock(-2,14,8,CONCRETE:7,65,quark:iron_plate:0,10,quark:iron_plate:1,10,STAINED_CLAY:15,10,STAINED_CLAY:9,100)
RandomBlock(-2,14,9,CONCRETE:7,65,quark:iron_plate:0,10,quark:iron_plate:1,10,STAINED_CLAY:15,10,STAINED_CLAY:9,100)
RandomBlock(-2,15,1,CONCRETE:7,65,quark:iron_plate:0,10,quark:iron_plate:1,10,STAINED_CLAY:15,10,STAINED_CLAY:9,100)
RandomBlock(-2,15,2,CONCRETE:7,65,quark:iron_plate:0,10,quark:iron_plate:1,10,STAINED_CLAY:15,10,STAINED_CLAY:9,100)
Block(-2,15,3,STEP:0)
Block(-2,15,4,STEP:0)
Block(-2,15,5,STEP:0)
Block(-2,15,6,STEP:0)
Block(-2,15,7,STEP:0)
RandomBlock(-2,15,8,CONCRETE:7,65,quark:iron_plate:0,10,quark:iron_plate:1,10,STAINED_CLAY:15,10,STAINED_CLAY:9,100)
RandomBlock(-2,15,9,CONCRETE:7,65,quark:iron_plate:0,10,quark:iron_plate:1,10,STAINED_CLAY:15,10,STAINED_CLAY:9,100)
RandomBlock(-1,0,1,CONCRETE:7,65,quark:iron_plate:0,10,quark:iron_plate:1,10,STAINED_CLAY:15,10,STAINED_CLAY:9,100)
RandomBlock(-1,0,2,CONCRETE:7,65,quark:iron_plate:0,10,quark:iron_plate:1,10,STAINED_CLAY:15,10,STAINED_CLAY:9,100)
RandomBlock(-1,0,8,CONCRETE:7,65,quark:iron_plate:0,10,quark:iron_plate:1,10,STAINED_CLAY:15,10,STAINED_CLAY:9,100)
RandomBlock(-1,0,9,CONCRETE:7,65,quark:iron_plate:0,10,quark:iron_plate:1,10,STAINED_CLAY:15,10,STAINED_CLAY:9,100)
RandomBlock(-1,1,1,CONCRETE:7,65,quark:iron_plate:0,10,quark:iron_plate:1,10,STAINED_CLAY:15,10,STAINED_CLAY:9,100)
RandomBlock(-1,1,2,CONCRETE:7,65,quark:iron_plate:0,10,quark:iron_plate:1,10,STAINED_CLAY:15,10,STAINED_CLAY:9,100)
RandomBlock(-1,1,8,CONCRETE:7,65,quark:iron_plate:0,10,quark:iron_plate:1,10,STAINED_CLAY:15,10,STAINED_CLAY:9,100)
RandomBlock(-1,1,9,CONCRETE:7,65,quark:iron_plate:0,10,quark:iron_plate:1,10,STAINED_CLAY:15,10,STAINED_CLAY:9,100)
RandomBlock(-1,2,1,CONCRETE:7,65,quark:iron_plate:0,10,quark:iron_plate:1,10,STAINED_CLAY:15,10,STAINED_CLAY:9,100)
RandomBlock(-1,2,2,CONCRETE:7,65,quark:iron_plate:0,10,quark:iron_plate:1,10,STAINED_CLAY:15,10,STAINED_CLAY:9,100)
RandomBlock(-1,2,8,CONCRETE:7,65,quark:iron_plate:0,10,quark:iron_plate:1,10,STAINED_CLAY:15,10,STAINED_CLAY:9,100)
RandomBlock(-1,2,9,CONCRETE:7,65,quark:iron_plate:0,10,quark:iron_plate:1,10,STAINED_CLAY:15,10,STAINED_CLAY:9,100)
RandomBlock(-1,3,1,CONCRETE:7,65,quark:iron_plate:0,10,quark:iron_plate:1,10,STAINED_CLAY:15,10,STAINED_CLAY:9,100)
RandomBlock(-1,3,2,CONCRETE:7,65,quark:iron_plate:0,10,quark:iron_plate:1,10,STAINED_CLAY:15,10,STAINED_CLAY:9,100)
RandomBlock(-1,3,8,CONCRETE:7,65,quark:iron_plate:0,10,quark:iron_plate:1,10,STAINED_CLAY:15,10,STAINED_CLAY:9,100)
RandomBlock(-1,3,9,CONCRETE:7,65,quark:iron_plate:0,10,quark:iron_plate:1,10,STAINED_CLAY:15,10,STAINED_CLAY:9,100)
RandomBlock(-1,4,1,CONCRETE:7,65,quark:iron_plate:0,10,quark:iron_plate:1,10,STAINED_CLAY:15,10,STAINED_CLAY:9,100)
RandomBlock(-1,4,2,CONCRETE:7,65,quark:iron_plate:0,10,quark:iron_plate:1,10,STAINED_CLAY:15,10,STAINED_CLAY:9,100)
RandomBlock(-1,4,8,CONCRETE:7,65,quark:iron_plate:0,10,quark:iron_plate:1,10,STAINED_CLAY:15,10,STAINED_CLAY:9,100)
RandomBlock(-1,4,9,CONCRETE:7,65,quark:iron_plate:0,10,quark:iron_plate:1,10,STAINED_CLAY:15,10,STAINED_CLAY:9,100)
RandomBlock(-1,5,1,CONCRETE:7,65,quark:iron_plate:0,10,quark:iron_plate:1,10,STAINED_CLAY:15,10,STAINED_CLAY:9,100)
RandomBlock(-1,5,2,CONCRETE:7,65,quark:iron_plate:0,10,quark:iron_plate:1,10,STAINED_CLAY:15,10,STAINED_CLAY:9,100)
RandomBlock(-1,5,8,CONCRETE:7,65,quark:iron_plate:0,10,quark:iron_plate:1,10,STAINED_CLAY:15,10,STAINED_CLAY:9,100)
RandomBlock(-1,5,9,CONCRETE:7,65,quark:iron_plate:0,10,quark:iron_plate:1,10,STAINED_CLAY:15,10,STAINED_CLAY:9,100)
RandomBlock(-1,6,1,CONCRETE:7,65,quark:iron_plate:0,10,quark:iron_plate:1,10,STAINED_CLAY:15,10,STAINED_CLAY:9,100)
RandomBlock(-1,6,2,CONCRETE:7,65,quark:iron_plate:0,10,quark:iron_plate:1,10,STAINED_CLAY:15,10,STAINED_CLAY:9,100)
RandomBlock(-1,6,8,CONCRETE:7,65,quark:iron_plate:0,10,quark:iron_plate:1,10,STAINED_CLAY:15,10,STAINED_CLAY:9,100)
RandomBlock(-1,6,9,CONCRETE:7,65,quark:iron_plate:0,10,quark:iron_plate:1,10,STAINED_CLAY:15,10,STAINED_CLAY:9,100)
RandomBlock(-1,7,1,CONCRETE:7,65,quark:iron_plate:0,10,quark:iron_plate:1,10,STAINED_CLAY:15,10,STAINED_CLAY:9,100)
RandomBlock(-1,7,2,CONCRETE:7,65,quark:iron_plate:0,10,quark:iron_plate:1,10,STAINED_CLAY:15,10,STAINED_CLAY:9,100)
RandomBlock(-1,7,8,CONCRETE:7,65,quark:iron_plate:0,10,quark:iron_plate:1,10,STAINED_CLAY:15,10,STAINED_CLAY:9,100)
RandomBlock(-1,7,9,CONCRETE:7,65,quark:iron_plate:0,10,quark:iron_plate:1,10,STAINED_CLAY:15,10,STAINED_CLAY:9,100)
RandomBlock(-1,8,1,CONCRETE:7,65,quark:iron_plate:0,10,quark:iron_plate:1,10,STAINED_CLAY:15,10,STAINED_CLAY:9,100)
RandomBlock(-1,8,2,CONCRETE:7,65,quark:iron_plate:0,10,quark:iron_plate:1,10,STAINED_CLAY:15,10,STAINED_CLAY:9,100)
RandomBlock(-1,8,8,CONCRETE:7,65,quark:iron_plate:0,10,quark:iron_plate:1,10,STAINED_CLAY:15,10,STAINED_CLAY:9,100)
RandomBlock(-1,8,9,CONCRETE:7,65,quark:iron_plate:0,10,quark:iron_plate:1,10,STAINED_CLAY:15,10,STAINED_CLAY:9,100)
RandomBlock(-1,9,-6,CONCRETE:7,65,quark:iron_plate:0,10,quark:iron_plate:1,10,STAINED_CLAY:15,10,STAINED_CLAY:9,100)
RandomBlock(-1,9,-5,CONCRETE:7,65,quark:iron_plate:0,10,quark:iron_plate:1,10,STAINED_CLAY:15,10,STAINED_CLAY:9,100)
RandomBlock(-1,9,-4,CONCRETE:7,65,quark:iron_plate:0,10,quark:iron_plate:1,10,STAINED_CLAY:15,10,STAINED_CLAY:9,100)
RandomBlock(-1,9,-3,CONCRETE:7,65,quark:iron_plate:0,10,quark:iron_plate:1,10,STAINED_CLAY:15,10,STAINED_CLAY:9,100)
RandomBlock(-1,9,-2,CONCRETE:7,65,quark:iron_plate:0,10,quark:iron_plate:1,10,STAINED_CLAY:15,10,STAINED_CLAY:9,100)
RandomBlock(-1,9,-1,CONCRETE:7,65,quark:iron_plate:0,10,quark:iron_plate:1,10,STAINED_CLAY:15,10,STAINED_CLAY:9,100)
RandomBlock(-1,9,0,CONCRETE:7,65,quark:iron_plate:0,10,quark:iron_plate:1,10,STAINED_CLAY:15,10,STAINED_CLAY:9,100)
RandomBlock(-1,9,1,CONCRETE:7,65,quark:iron_plate:0,10,quark:iron_plate:1,10,STAINED_CLAY:15,10,STAINED_CLAY:9,100)
RandomBlock(-1,9,2,CONCRETE:7,65,quark:iron_plate:0,10,quark:iron_plate:1,10,STAINED_CLAY:15,10,STAINED_CLAY:9,100)
RandomBlock(-1,9,3,CONCRETE:7,65,quark:iron_plate:0,10,quark:iron_plate:1,10,STAINED_CLAY:15,10,STAINED_CLAY:9,100)
RandomBlock(-1,9,4,CONCRETE:7,65,quark:iron_plate:0,10,quark:iron_plate:1,10,STAINED_CLAY:15,10,STAINED_CLAY:9,100)
RandomBlock(-1,9,5,CONCRETE:7,65,quark:iron_plate:0,10,quark:iron_plate:1,10,STAINED_CLAY:15,10,STAINED_CLAY:9,100)
RandomBlock(-1,9,6,CONCRETE:7,65,quark:iron_plate:0,10,quark:iron_plate:1,10,STAINED_CLAY:15,10,STAINED_CLAY:9,100)
RandomBlock(-1,9,8,CONCRETE:7,65,quark:iron_plate:0,10,quark:iron_plate:1,10,STAINED_CLAY:15,10,STAINED_CLAY:9,100)
RandomBlock(-1,9,9,CONCRETE:7,65,quark:iron_plate:0,10,quark:iron_plate:1,10,STAINED_CLAY:15,10,STAINED_CLAY:9,100)
RandomBlock(-1,10,-6,CONCRETE:7,65,quark:iron_plate:0,10,quark:iron_plate:1,10,STAINED_CLAY:15,10,STAINED_CLAY:9,100)
RandomBlock(-1,10,-5,CONCRETE:7,65,quark:iron_plate:0,10,quark:iron_plate:1,10,STAINED_CLAY:15,10,STAINED_CLAY:9,100)
RandomBlock(-1,10,-4,CONCRETE:7,65,quark:iron_plate:0,10,quark:iron_plate:1,10,STAINED_CLAY:15,10,STAINED_CLAY:9,100)
RandomBlock(-1,10,-3,CONCRETE:7,65,quark:iron_plate:0,10,quark:iron_plate:1,10,STAINED_CLAY:15,10,STAINED_CLAY:9,100)
RandomBlock(-1,10,-2,CONCRETE:7,65,quark:iron_plate:0,10,quark:iron_plate:1,10,STAINED_CLAY:15,10,STAINED_CLAY:9,100)
RandomBlock(-1,10,-1,CONCRETE:7,65,quark:iron_plate:0,10,quark:iron_plate:1,10,STAINED_CLAY:15,10,STAINED_CLAY:9,100)
RandomBlock(-1,10,0,CONCRETE:7,65,quark:iron_plate:0,10,quark:iron_plate:1,10,STAINED_CLAY:15,10,STAINED_CLAY:9,100)
RandomBlock(-1,10,1,CONCRETE:7,65,quark:iron_plate:0,10,quark:iron_plate:1,10,STAINED_CLAY:15,10,STAINED_CLAY:9,100)
RandomBlock(-1,10,2,CONCRETE:7,65,quark:iron_plate:0,10,quark:iron_plate:1,10,STAINED_CLAY:15,10,STAINED_CLAY:9,100)
RandomBlock(-1,10,3,CONCRETE:7,65,quark:iron_plate:0,10,quark:iron_plate:1,10,STAINED_CLAY:15,10,STAINED_CLAY:9,100)
RandomBlock(-1,10,4,CONCRETE:7,65,quark:iron_plate:0,10,quark:iron_plate:1,10,STAINED_CLAY:15,10,STAINED_CLAY:9,100)
RandomBlock(-1,10,5,CONCRETE:7,65,quark:iron_plate:0,10,quark:iron_plate:1,10,STAINED_CLAY:15,10,STAINED_CLAY:9,100)
RandomBlock(-1,10,6,CONCRETE:7,65,quark:iron_plate:0,10,quark:iron_plate:1,10,STAINED_CLAY:15,10,STAINED_CLAY:9,100)
RandomBlock(-1,10,7,CONCRETE:7,65,quark:iron_plate:0,10,quark:iron_plate:1,10,STAINED_CLAY:15,10,STAINED_CLAY:9,100)
RandomBlock(-1,10,8,CONCRETE:7,65,quark:iron_plate:0,10,quark:iron_plate:1,10,STAINED_CLAY:15,10,STAINED_CLAY:9,100)
RandomBlock(-1,10,9,CONCRETE:7,65,quark:iron_plate:0,10,quark:iron_plate:1,10,STAINED_CLAY:15,10,STAINED_CLAY:9,100)
RandomBlock(-1,11,-6,CONCRETE:7,65,quark:iron_plate:0,10,quark:iron_plate:1,10,STAINED_CLAY:15,10,STAINED_CLAY:9,100)
Block(-1,11,-5,STAINED_GLASS:15)
Block(-1,11,-4,STAINED_GLASS:15)
Block(-1,11,-3,STAINED_GLASS:15)
Block(-1,11,-2,STAINED_GLASS:15)
Block(-1,11,-1,STAINED_GLASS:15)
Block(-1,11,0,STAINED_GLASS:15)
RandomBlock(-1,11,1,CONCRETE:7,65,quark:iron_plate:0,10,quark:iron_plate:1,10,STAINED_CLAY:15,10,STAINED_CLAY:9,100)
Block(-1,11,2,AIR:0)
Block(-1,11,3,IRON_TRAPDOOR:4)
Block(-1,11,4,STEP:8)
Block(-1,11,5,STEP:8)
Block(-1,11,6,STEP:8)
Block(-1,11,7,STEP:8)
RandomBlock(-1,11,8,CONCRETE:7,65,quark:iron_plate:0,10,quark:iron_plate:1,10,STAINED_CLAY:15,10,STAINED_CLAY:9,100)
RandomBlock(-1,11,9,CONCRETE:7,65,quark:iron_plate:0,10,quark:iron_plate:1,10,STAINED_CLAY:15,10,STAINED_CLAY:9,100)
RandomBlock(-1,12,-6,CONCRETE:7,65,quark:iron_plate:0,10,quark:iron_plate:1,10,STAINED_CLAY:15,10,STAINED_CLAY:9,100)
Block(-1,12,-5,STAINED_GLASS:15)
Block(-1,12,-4,STAINED_GLASS:15)
Block(-1,12,-3,STAINED_GLASS:15)
Block(-1,12,-2,STAINED_GLASS:15)
Block(-1,12,-1,STAINED_GLASS:15)
Block(-1,12,0,STAINED_GLASS:15)
RandomBlock(-1,12,1,CONCRETE:7,65,quark:iron_plate:0,10,quark:iron_plate:1,10,STAINED_CLAY:15,10,STAINED_CLAY:9,100)
Block(-1,12,2,AIR:0)
Block(-1,12,3,IRON_TRAPDOOR:4)
Block(-1,12,4,AIR:0)
Block(-1,12,5,AIR:0)
Block(-1,12,6,CONCRETE:15)
Block(-1,12,7,CONCRETE:15)
RandomBlock(-1,12,8,CONCRETE:7,65,quark:iron_plate:0,10,quark:iron_plate:1,10,STAINED_CLAY:15,10,STAINED_CLAY:9,100)
RandomBlock(-1,12,9,CONCRETE:7,65,quark:iron_plate:0,10,quark:iron_plate:1,10,STAINED_CLAY:15,10,STAINED_CLAY:9,100)
RandomBlock(-1,13,-6,CONCRETE:7,65,quark:iron_plate:0,10,quark:iron_plate:1,10,STAINED_CLAY:15,10,STAINED_CLAY:9,100)
Block(-1,13,-5,STAINED_GLASS:15)
Block(-1,13,-4,STAINED_GLASS:15)
Block(-1,13,-3,STAINED_GLASS:15)
Block(-1,13,-2,STAINED_GLASS:15)
Block(-1,13,-1,STAINED_GLASS:15)
Block(-1,13,0,STAINED_GLASS:15)
RandomBlock(-1,13,1,CONCRETE:7,65,quark:iron_plate:0,10,quark:iron_plate:1,10,STAINED_CLAY:15,10,STAINED_CLAY:9,100)
Block(-1,13,2,AIR:0)
Block(-1,13,3,AIR:0)
Block(-1,13,4,AIR:0)
Block(-1,13,5,AIR:0)
Block(-1,13,6,CONCRETE:15)
Block(-1,13,7,CONCRETE:15)
RandomBlock(-1,13,8,CONCRETE:7,65,quark:iron_plate:0,10,quark:iron_plate:1,10,STAINED_CLAY:15,10,STAINED_CLAY:9,100)
RandomBlock(-1,13,9,CONCRETE:7,65,quark:iron_plate:0,10,quark:iron_plate:1,10,STAINED_CLAY:15,10,STAINED_CLAY:9,100)
RandomBlock(-1,14,-6,CONCRETE:7,65,quark:iron_plate:0,10,quark:iron_plate:1,10,STAINED_CLAY:15,10,STAINED_CLAY:9,100)
Block(-1,14,-5,STAINED_GLASS:15)
Block(-1,14,-4,STAINED_GLASS:15)
Block(-1,14,-3,STAINED_GLASS:15)
Block(-1,14,-2,STAINED_GLASS:15)
Block(-1,14,-1,STAINED_GLASS:15)
Block(-1,14,0,STAINED_GLASS:15)
RandomBlock(-1,14,1,CONCRETE:7,65,quark:iron_plate:0,10,quark:iron_plate:1,10,STAINED_CLAY:15,10,STAINED_CLAY:9,100)
Block(-1,14,2,AIR:0)
Block(-1,14,3,AIR:0)
Block(-1,14,4,AIR:0)
Block(-1,14,5,AIR:0)
Block(-1,14,6,CONCRETE:15)
Block(-1,14,7,CONCRETE:15)
RandomBlock(-1,14,8,CONCRETE:7,65,quark:iron_plate:0,10,quark:iron_plate:1,10,STAINED_CLAY:15,10,STAINED_CLAY:9,100)
RandomBlock(-1,14,9,CONCRETE:7,65,quark:iron_plate:0,10,quark:iron_plate:1,10,STAINED_CLAY:15,10,STAINED_CLAY:9,100)
RandomBlock(-1,15,-6,CONCRETE:7,65,quark:iron_plate:0,10,quark:iron_plate:1,10,STAINED_CLAY:15,10,STAINED_CLAY:9,100)
Block(-1,15,-5,STEP:0)
Block(-1,15,-4,STEP:0)
Block(-1,15,-3,STEP:0)
Block(-1,15,-2,STEP:0)
Block(-1,15,-1,STEP:0)
Block(-1,15,0,STEP:0)
RandomBlock(-1,15,1,CONCRETE:7,65,quark:iron_plate:0,10,quark:iron_plate:1,10,STAINED_CLAY:15,10,STAINED_CLAY:9,100)
RandomBlock(-1,15,2,CONCRETE:7,65,quark:iron_plate:0,10,quark:iron_plate:1,10,STAINED_CLAY:15,10,STAINED_CLAY:9,100)
Block(-1,15,3,STEP:0)
Block(-1,15,4,STEP:0)
Block(-1,15,5,STEP:0)
Block(-1,15,6,STEP:0)
Block(-1,15,7,STEP:0)
RandomBlock(-1,15,8,CONCRETE:7,65,quark:iron_plate:0,10,quark:iron_plate:1,10,STAINED_CLAY:15,10,STAINED_CLAY:9,100)
RandomBlock(-1,15,9,CONCRETE:7,65,quark:iron_plate:0,10,quark:iron_plate:1,10,STAINED_CLAY:15,10,STAINED_CLAY:9,100)
Block(0,9,-6,DROPPER:1)
Block(0,9,-5,IRON_TRAPDOOR:9)
Block(0,9,-4,IRON_TRAPDOOR:9)
Block(0,9,-3,IRON_TRAPDOOR:9)
Block(0,9,-2,IRON_TRAPDOOR:9)
Block(0,9,-1,IRON_TRAPDOOR:9)
Block(0,9,0,IRON_TRAPDOOR:9)
Block(0,9,1,IRON_TRAPDOOR:9)
Block(0,9,2,IRON_TRAPDOOR:9)
Block(0,9,3,IRON_TRAPDOOR:9)
Block(0,9,4,IRON_TRAPDOOR:9)
Block(0,9,5,IRON_TRAPDOOR:9)
RandomBlock(0,9,6,CONCRETE:7,65,quark:iron_plate:0,10,quark:iron_plate:1,10,STAINED_CLAY:15,10,STAINED_CLAY:9,100)
Block(0,10,-6,IRON_TRAPDOOR:11)
RandomBlock(0,10,-5,CONCRETE:7,65,quark:iron_plate:0,10,quark:iron_plate:1,10,STAINED_CLAY:15,10,STAINED_CLAY:9,100)
RandomBlock(0,10,-4,CONCRETE:7,65,quark:iron_plate:0,10,quark:iron_plate:1,10,STAINED_CLAY:15,10,STAINED_CLAY:9,100)
RandomBlock(0,10,-3,CONCRETE:7,65,quark:iron_plate:0,10,quark:iron_plate:1,10,STAINED_CLAY:15,10,STAINED_CLAY:9,100)
RandomBlock(0,10,-2,CONCRETE:7,65,quark:iron_plate:0,10,quark:iron_plate:1,10,STAINED_CLAY:15,10,STAINED_CLAY:9,100)
RandomBlock(0,10,-1,CONCRETE:7,65,quark:iron_plate:0,10,quark:iron_plate:1,10,STAINED_CLAY:15,10,STAINED_CLAY:9,100)
RandomBlock(0,10,0,CONCRETE:7,65,quark:iron_plate:0,10,quark:iron_plate:1,10,STAINED_CLAY:15,10,STAINED_CLAY:9,100)
RandomBlock(0,10,1,CONCRETE:7,65,quark:iron_plate:0,10,quark:iron_plate:1,10,STAINED_CLAY:15,10,STAINED_CLAY:9,100)
RandomBlock(0,10,2,CONCRETE:7,65,quark:iron_plate:0,10,quark:iron_plate:1,10,STAINED_CLAY:15,10,STAINED_CLAY:9,100)
RandomBlock(0,10,3,CONCRETE:7,65,quark:iron_plate:0,10,quark:iron_plate:1,10,STAINED_CLAY:15,10,STAINED_CLAY:9,100)
RandomBlock(0,10,4,CONCRETE:7,65,quark:iron_plate:0,10,quark:iron_plate:1,10,STAINED_CLAY:15,10,STAINED_CLAY:9,100)
RandomBlock(0,10,5,CONCRETE:7,65,quark:iron_plate:0,10,quark:iron_plate:1,10,STAINED_CLAY:15,10,STAINED_CLAY:9,100)
RandomBlock(0,10,6,CONCRETE:7,65,quark:iron_plate:0,10,quark:iron_plate:1,10,STAINED_CLAY:15,10,STAINED_CLAY:9,100)
RandomBlock(0,10,7,CONCRETE:7,65,quark:iron_plate:0,10,quark:iron_plate:1,10,STAINED_CLAY:15,10,STAINED_CLAY:9,100)
RandomBlock(0,10,8,CONCRETE:7,65,quark:iron_plate:0,10,quark:iron_plate:1,10,STAINED_CLAY:15,10,STAINED_CLAY:9,100)
Block(0,11,-6,AIR:0)
Block(0,11,-5,AIR:0)
Block(0,11,-4,AIR:0)
Block(0,11,-3,AIR:0)
Block(0,11,-2,AIR:0)
Block(0,11,-1,AIR:0)
Block(0,11,0,AIR:0)
Block(0,11,1,AIR:0)
Block(0,11,2,AIR:0)
Block(0,11,3,IRON_TRAPDOOR:4)
Block(0,11,4,DOUBLE_STEP:0)
Block(0,11,5,STEP:8)
Block(0,11,6,STEP:8)
Block(0,11,7,STEP:8)
Block(0,11,8,STAINED_GLASS:15)
Block(0,12,-6,AIR:0)
Block(0,12,-5,AIR:0)
Block(0,12,-4,AIR:0)
Block(0,12,-3,AIR:0)
Block(0,12,-2,AIR:0)
Block(0,12,-1,AIR:0)
Block(0,12,0,AIR:0)
Block(0,12,1,AIR:0)
Block(0,12,2,AIR:0)
Block(0,12,3,IRON_TRAPDOOR:4)
Block(0,12,4,AIR:0)
Block(0,12,5,AIR:0)
Block(0,12,6,QUARTZ_STAIRS:2)
Block(0,12,7,CONCRETE:15)
Block(0,12,8,STAINED_GLASS:15)
Block(0,13,-6,IRON_TRAPDOOR:11)
Block(0,13,-5,AIR:0)
Block(0,13,-3,AIR:0)
Block(0,13,-2,AIR:0)
Block(0,13,-1,AIR:0)
Block(0,13,0,AIR:0)
Block(0,13,1,AIR:0)
Block(0,13,2,AIR:0)
Block(0,13,3,AIR:0)
Block(0,13,4,AIR:0)
Block(0,13,5,AIR:0)
Block(0,13,6,QUARTZ_STAIRS:6)
Block(0,13,7,CONCRETE:15)
Block(0,13,8,STAINED_GLASS:15)
Block(0,14,-6,DROPPER:0)
Block(0,14,-5,CONCRETE:4)
Block(0,14,-4,CONCRETE:4)
Block(0,14,-3,CONCRETE:4)
Block(0,14,-2,CONCRETE:4)
Block(0,14,-1,CONCRETE:4)
Block(0,14,0,CONCRETE:4)
Block(0,14,1,CONCRETE:4)
Block(0,14,2,CONCRETE:4)
Block(0,14,3,CONCRETE:4)
Block(0,14,4,CONCRETE:4)
Block(0,14,5,CONCRETE:4)
Block(0,14,6,CONCRETE:4)
Block(0,14,7,CONCRETE:15)
Block(0,14,8,STAINED_GLASS:15)
Block(0,15,-6,STEP:0)
Block(0,15,-5,STEP:0)
Block(0,15,-4,STEP:0)
Block(0,15,-3,STEP:0)
Block(0,15,-2,STEP:0)
Block(0,15,-1,STEP:0)
Block(0,15,0,STEP:0)
Block(0,15,1,STEP:0)
Block(0,15,2,STEP:0)
Block(0,15,3,STEP:0)
Block(0,15,4,STEP:0)
Block(0,15,5,STEP:0)
Block(0,15,6,STEP:0)
Block(0,15,7,STEP:0)
RandomBlock(0,15,8,CONCRETE:7,65,quark:iron_plate:0,10,quark:iron_plate:1,10,STAINED_CLAY:15,10,STAINED_CLAY:9,100)
Block(1,9,-6,DROPPER:1)
Block(1,9,-5,CONCRETE:14)
Block(1,9,-4,CONCRETE:14)
Block(1,9,-3,CONCRETE:14)
Block(1,9,-2,CONCRETE:14)
Block(1,9,-1,CONCRETE:14)
Block(1,9,0,CONCRETE:14)
Block(1,9,1,CONCRETE:14)
Block(1,9,2,CONCRETE:14)
Block(1,9,3,CONCRETE:14)
Block(1,9,4,CONCRETE:14)
Block(1,9,5,CONCRETE:14)
RandomBlock(1,9,6,CONCRETE:7,65,quark:iron_plate:0,10,quark:iron_plate:1,10,STAINED_CLAY:15,10,STAINED_CLAY:9,100)
Block(1,10,-6,IRON_TRAPDOOR:10)
RandomBlock(1,10,-5,CONCRETE:7,65,quark:iron_plate:0,10,quark:iron_plate:1,10,STAINED_CLAY:15,10,STAINED_CLAY:9,100)
RandomBlock(1,10,-4,CONCRETE:7,65,quark:iron_plate:0,10,quark:iron_plate:1,10,STAINED_CLAY:15,10,STAINED_CLAY:9,100)
RandomBlock(1,10,-3,CONCRETE:7,65,quark:iron_plate:0,10,quark:iron_plate:1,10,STAINED_CLAY:15,10,STAINED_CLAY:9,100)
RandomBlock(1,10,-2,CONCRETE:7,65,quark:iron_plate:0,10,quark:iron_plate:1,10,STAINED_CLAY:15,10,STAINED_CLAY:9,100)
RandomBlock(1,10,-1,CONCRETE:7,65,quark:iron_plate:0,10,quark:iron_plate:1,10,STAINED_CLAY:15,10,STAINED_CLAY:9,100)
RandomBlock(1,10,0,CONCRETE:7,65,quark:iron_plate:0,10,quark:iron_plate:1,10,STAINED_CLAY:15,10,STAINED_CLAY:9,100)
RandomBlock(1,10,1,CONCRETE:7,65,quark:iron_plate:0,10,quark:iron_plate:1,10,STAINED_CLAY:15,10,STAINED_CLAY:9,100)
RandomBlock(1,10,2,CONCRETE:7,65,quark:iron_plate:0,10,quark:iron_plate:1,10,STAINED_CLAY:15,10,STAINED_CLAY:9,100)
RandomBlock(1,10,3,CONCRETE:7,65,quark:iron_plate:0,10,quark:iron_plate:1,10,STAINED_CLAY:15,10,STAINED_CLAY:9,100)
RandomBlock(1,10,4,CONCRETE:7,65,quark:iron_plate:0,10,quark:iron_plate:1,10,STAINED_CLAY:15,10,STAINED_CLAY:9,100)
RandomBlock(1,10,5,CONCRETE:7,65,quark:iron_plate:0,10,quark:iron_plate:1,10,STAINED_CLAY:15,10,STAINED_CLAY:9,100)
RandomBlock(1,10,6,CONCRETE:7,65,quark:iron_plate:0,10,quark:iron_plate:1,10,STAINED_CLAY:15,10,STAINED_CLAY:9,100)
RandomBlock(1,10,7,CONCRETE:7,65,quark:iron_plate:0,10,quark:iron_plate:1,10,STAINED_CLAY:15,10,STAINED_CLAY:9,100)
RandomBlock(1,10,8,CONCRETE:7,65,quark:iron_plate:0,10,quark:iron_plate:1,10,STAINED_CLAY:15,10,STAINED_CLAY:9,100)
Block(1,11,-6,AIR:0)
Block(1,11,-5,AIR:0)
Block(1,11,-4,AIR:0)
Block(1,11,-3,AIR:0)
Block(1,11,-2,AIR:0)
Block(1,11,-1,AIR:0)
Block(1,11,0,AIR:0)
Block(1,11,1,AIR:0)
Block(1,11,2,AIR:0)
Block(1,11,3,IRON_TRAPDOOR:4)
Block(1,11,4,STEP:8)
Block(1,11,5,STEP:8)
Block(1,11,6,STEP:8)
Block(1,11,7,STEP:8)
Block(1,11,8,STAINED_GLASS:15)
Block(1,12,-6,AIR:0)
Block(1,12,-5,AIR:0)
Block(1,12,-4,AIR:0)
Block(1,12,-3,AIR:0)
Block(1,12,-2,AIR:0)
Block(1,12,-1,AIR:0)
Block(1,12,0,AIR:0)
Block(1,12,1,AIR:0)
Block(1,12,2,AIR:0)
Block(1,12,3,IRON_TRAPDOOR:4)
Block(1,12,4,AIR:0)
Block(1,12,5,AIR:0)
Block(1,12,6,CONCRETE:15)
Block(1,12,7,CONCRETE:15)
Block(1,12,8,STAINED_GLASS:15)
Block(1,13,-6,IRON_TRAPDOOR:10)
Block(1,13,-5,AIR:0)
Block(1,13,-4,AIR:0)
Block(1,13,-3,AIR:0)
Block(1,13,-2,AIR:0)
Block(1,13,-1,AIR:0)
Block(1,13,1,AIR:0)
Block(1,13,2,AIR:0)
Block(1,13,3,AIR:0)
Block(1,13,4,AIR:0)
Block(1,13,5,AIR:0)
Block(1,13,6,CONCRETE:15)
Block(1,13,7,CONCRETE:15)
Block(1,13,8,STAINED_GLASS:15)
Block(1,14,-6,DROPPER:0)
Block(1,14,-5,IRON_TRAPDOOR:9)
Block(1,14,-4,IRON_TRAPDOOR:10)
Block(1,14,-3,IRON_TRAPDOOR:8)
Block(1,14,-2,IRON_TRAPDOOR:8)
Block(1,14,-1,IRON_TRAPDOOR:8)
Block(1,14,0,IRON_TRAPDOOR:8)
Block(1,14,1,IRON_TRAPDOOR:9)
Block(1,14,2,IRON_TRAPDOOR:10)
Block(1,14,3,IRON_TRAPDOOR:8)
Block(1,14,4,IRON_TRAPDOOR:8)
Block(1,14,5,QUARTZ_STAIRS:6)
Block(1,14,6,CONCRETE:15)
Block(1,14,7,CONCRETE:15)
Block(1,14,8,STAINED_GLASS:15)
Block(1,15,-6,STEP:0)
Block(1,15,-5,STEP:0)
Block(1,15,-4,STEP:0)
Block(1,15,-3,STEP:0)
Block(1,15,-2,STEP:0)
Block(1,15,-1,STEP:0)
Block(1,15,0,STEP:0)
Block(1,15,1,STEP:0)
Block(1,15,2,STEP:0)
Block(1,15,3,STEP:0)
Block(1,15,4,STEP:0)
Block(1,15,5,STEP:0)
Block(1,15,6,STEP:0)
Block(1,15,7,STEP:0)
RandomBlock(1,15,8,CONCRETE:7,65,quark:iron_plate:0,10,quark:iron_plate:1,10,STAINED_CLAY:15,10,STAINED_CLAY:9,100)
RandomBlock(2,0,1,CONCRETE:7,65,quark:iron_plate:0,10,quark:iron_plate:1,10,STAINED_CLAY:15,10,STAINED_CLAY:9,100)
RandomBlock(2,0,2,CONCRETE:7,65,quark:iron_plate:0,10,quark:iron_plate:1,10,STAINED_CLAY:15,10,STAINED_CLAY:9,100)
RandomBlock(2,0,8,CONCRETE:7,65,quark:iron_plate:0,10,quark:iron_plate:1,10,STAINED_CLAY:15,10,STAINED_CLAY:9,100)
RandomBlock(2,0,9,CONCRETE:7,65,quark:iron_plate:0,10,quark:iron_plate:1,10,STAINED_CLAY:15,10,STAINED_CLAY:9,100)
RandomBlock(2,1,1,CONCRETE:7,65,quark:iron_plate:0,10,quark:iron_plate:1,10,STAINED_CLAY:15,10,STAINED_CLAY:9,100)
RandomBlock(2,1,2,CONCRETE:7,65,quark:iron_plate:0,10,quark:iron_plate:1,10,STAINED_CLAY:15,10,STAINED_CLAY:9,100)
RandomBlock(2,1,8,CONCRETE:7,65,quark:iron_plate:0,10,quark:iron_plate:1,10,STAINED_CLAY:15,10,STAINED_CLAY:9,100)
RandomBlock(2,1,9,CONCRETE:7,65,quark:iron_plate:0,10,quark:iron_plate:1,10,STAINED_CLAY:15,10,STAINED_CLAY:9,100)
RandomBlock(2,2,1,CONCRETE:7,65,quark:iron_plate:0,10,quark:iron_plate:1,10,STAINED_CLAY:15,10,STAINED_CLAY:9,100)
RandomBlock(2,2,2,CONCRETE:7,65,quark:iron_plate:0,10,quark:iron_plate:1,10,STAINED_CLAY:15,10,STAINED_CLAY:9,100)
RandomBlock(2,2,8,CONCRETE:7,65,quark:iron_plate:0,10,quark:iron_plate:1,10,STAINED_CLAY:15,10,STAINED_CLAY:9,100)
RandomBlock(2,2,9,CONCRETE:7,65,quark:iron_plate:0,10,quark:iron_plate:1,10,STAINED_CLAY:15,10,STAINED_CLAY:9,100)
RandomBlock(2,3,1,CONCRETE:7,65,quark:iron_plate:0,10,quark:iron_plate:1,10,STAINED_CLAY:15,10,STAINED_CLAY:9,100)
RandomBlock(2,3,2,CONCRETE:7,65,quark:iron_plate:0,10,quark:iron_plate:1,10,STAINED_CLAY:15,10,STAINED_CLAY:9,100)
RandomBlock(2,3,8,CONCRETE:7,65,quark:iron_plate:0,10,quark:iron_plate:1,10,STAINED_CLAY:15,10,STAINED_CLAY:9,100)
RandomBlock(2,3,9,CONCRETE:7,65,quark:iron_plate:0,10,quark:iron_plate:1,10,STAINED_CLAY:15,10,STAINED_CLAY:9,100)
RandomBlock(2,4,1,CONCRETE:7,65,quark:iron_plate:0,10,quark:iron_plate:1,10,STAINED_CLAY:15,10,STAINED_CLAY:9,100)
RandomBlock(2,4,2,CONCRETE:7,65,quark:iron_plate:0,10,quark:iron_plate:1,10,STAINED_CLAY:15,10,STAINED_CLAY:9,100)
RandomBlock(2,4,8,CONCRETE:7,65,quark:iron_plate:0,10,quark:iron_plate:1,10,STAINED_CLAY:15,10,STAINED_CLAY:9,100)
RandomBlock(2,4,9,CONCRETE:7,65,quark:iron_plate:0,10,quark:iron_plate:1,10,STAINED_CLAY:15,10,STAINED_CLAY:9,100)
RandomBlock(2,5,1,CONCRETE:7,65,quark:iron_plate:0,10,quark:iron_plate:1,10,STAINED_CLAY:15,10,STAINED_CLAY:9,100)
RandomBlock(2,5,2,CONCRETE:7,65,quark:iron_plate:0,10,quark:iron_plate:1,10,STAINED_CLAY:15,10,STAINED_CLAY:9,100)
RandomBlock(2,5,8,CONCRETE:7,65,quark:iron_plate:0,10,quark:iron_plate:1,10,STAINED_CLAY:15,10,STAINED_CLAY:9,100)
RandomBlock(2,5,9,CONCRETE:7,65,quark:iron_plate:0,10,quark:iron_plate:1,10,STAINED_CLAY:15,10,STAINED_CLAY:9,100)
RandomBlock(2,6,1,CONCRETE:7,65,quark:iron_plate:0,10,quark:iron_plate:1,10,STAINED_CLAY:15,10,STAINED_CLAY:9,100)
RandomBlock(2,6,2,CONCRETE:7,65,quark:iron_plate:0,10,quark:iron_plate:1,10,STAINED_CLAY:15,10,STAINED_CLAY:9,100)
RandomBlock(2,6,8,CONCRETE:7,65,quark:iron_plate:0,10,quark:iron_plate:1,10,STAINED_CLAY:15,10,STAINED_CLAY:9,100)
RandomBlock(2,6,9,CONCRETE:7,65,quark:iron_plate:0,10,quark:iron_plate:1,10,STAINED_CLAY:15,10,STAINED_CLAY:9,100)
RandomBlock(2,7,1,CONCRETE:7,65,quark:iron_plate:0,10,quark:iron_plate:1,10,STAINED_CLAY:15,10,STAINED_CLAY:9,100)
RandomBlock(2,7,2,CONCRETE:7,65,quark:iron_plate:0,10,quark:iron_plate:1,10,STAINED_CLAY:15,10,STAINED_CLAY:9,100)
RandomBlock(2,7,8,CONCRETE:7,65,quark:iron_plate:0,10,quark:iron_plate:1,10,STAINED_CLAY:15,10,STAINED_CLAY:9,100)
RandomBlock(2,7,9,CONCRETE:7,65,quark:iron_plate:0,10,quark:iron_plate:1,10,STAINED_CLAY:15,10,STAINED_CLAY:9,100)
RandomBlock(2,8,1,CONCRETE:7,65,quark:iron_plate:0,10,quark:iron_plate:1,10,STAINED_CLAY:15,10,STAINED_CLAY:9,100)
RandomBlock(2,8,2,CONCRETE:7,65,quark:iron_plate:0,10,quark:iron_plate:1,10,STAINED_CLAY:15,10,STAINED_CLAY:9,100)
RandomBlock(2,8,8,CONCRETE:7,65,quark:iron_plate:0,10,quark:iron_plate:1,10,STAINED_CLAY:15,10,STAINED_CLAY:9,100)
RandomBlock(2,8,9,CONCRETE:7,65,quark:iron_plate:0,10,quark:iron_plate:1,10,STAINED_CLAY:15,10,STAINED_CLAY:9,100)
RandomBlock(2,9,-6,CONCRETE:7,65,quark:iron_plate:0,10,quark:iron_plate:1,10,STAINED_CLAY:15,10,STAINED_CLAY:9,100)
RandomBlock(2,9,-5,CONCRETE:7,65,quark:iron_plate:0,10,quark:iron_plate:1,10,STAINED_CLAY:15,10,STAINED_CLAY:9,100)
RandomBlock(2,9,-4,CONCRETE:7,65,quark:iron_plate:0,10,quark:iron_plate:1,10,STAINED_CLAY:15,10,STAINED_CLAY:9,100)
RandomBlock(2,9,-3,CONCRETE:7,65,quark:iron_plate:0,10,quark:iron_plate:1,10,STAINED_CLAY:15,10,STAINED_CLAY:9,100)
RandomBlock(2,9,-2,CONCRETE:7,65,quark:iron_plate:0,10,quark:iron_plate:1,10,STAINED_CLAY:15,10,STAINED_CLAY:9,100)
RandomBlock(2,9,-1,CONCRETE:7,65,quark:iron_plate:0,10,quark:iron_plate:1,10,STAINED_CLAY:15,10,STAINED_CLAY:9,100)
RandomBlock(2,9,0,CONCRETE:7,65,quark:iron_plate:0,10,quark:iron_plate:1,10,STAINED_CLAY:15,10,STAINED_CLAY:9,100)
RandomBlock(2,9,1,CONCRETE:7,65,quark:iron_plate:0,10,quark:iron_plate:1,10,STAINED_CLAY:15,10,STAINED_CLAY:9,100)
RandomBlock(2,9,2,CONCRETE:7,65,quark:iron_plate:0,10,quark:iron_plate:1,10,STAINED_CLAY:15,10,STAINED_CLAY:9,100)
RandomBlock(2,9,3,CONCRETE:7,65,quark:iron_plate:0,10,quark:iron_plate:1,10,STAINED_CLAY:15,10,STAINED_CLAY:9,100)
RandomBlock(2,9,4,CONCRETE:7,65,quark:iron_plate:0,10,quark:iron_plate:1,10,STAINED_CLAY:15,10,STAINED_CLAY:9,100)
Block(2,9,5,CONCRETE:14)
RandomBlock(2,9,6,CONCRETE:7,65,quark:iron_plate:0,10,quark:iron_plate:1,10,STAINED_CLAY:15,10,STAINED_CLAY:9,100)
RandomBlock(2,9,8,CONCRETE:7,65,quark:iron_plate:0,10,quark:iron_plate:1,10,STAINED_CLAY:15,10,STAINED_CLAY:9,100)
RandomBlock(2,9,9,CONCRETE:7,65,quark:iron_plate:0,10,quark:iron_plate:1,10,STAINED_CLAY:15,10,STAINED_CLAY:9,100)
RandomBlock(2,10,-6,CONCRETE:7,65,quark:iron_plate:0,10,quark:iron_plate:1,10,STAINED_CLAY:15,10,STAINED_CLAY:9,100)
RandomBlock(2,10,-5,CONCRETE:7,65,quark:iron_plate:0,10,quark:iron_plate:1,10,STAINED_CLAY:15,10,STAINED_CLAY:9,100)
RandomBlock(2,10,-4,CONCRETE:7,65,quark:iron_plate:0,10,quark:iron_plate:1,10,STAINED_CLAY:15,10,STAINED_CLAY:9,100)
RandomBlock(2,10,-3,CONCRETE:7,65,quark:iron_plate:0,10,quark:iron_plate:1,10,STAINED_CLAY:15,10,STAINED_CLAY:9,100)
RandomBlock(2,10,-2,CONCRETE:7,65,quark:iron_plate:0,10,quark:iron_plate:1,10,STAINED_CLAY:15,10,STAINED_CLAY:9,100)
RandomBlock(2,10,-1,CONCRETE:7,65,quark:iron_plate:0,10,quark:iron_plate:1,10,STAINED_CLAY:15,10,STAINED_CLAY:9,100)
RandomBlock(2,10,0,CONCRETE:7,65,quark:iron_plate:0,10,quark:iron_plate:1,10,STAINED_CLAY:15,10,STAINED_CLAY:9,100)
RandomBlock(2,10,1,CONCRETE:7,65,quark:iron_plate:0,10,quark:iron_plate:1,10,STAINED_CLAY:15,10,STAINED_CLAY:9,100)
RandomBlock(2,10,2,CONCRETE:7,65,quark:iron_plate:0,10,quark:iron_plate:1,10,STAINED_CLAY:15,10,STAINED_CLAY:9,100)
RandomBlock(2,10,3,CONCRETE:7,65,quark:iron_plate:0,10,quark:iron_plate:1,10,STAINED_CLAY:15,10,STAINED_CLAY:9,100)
RandomBlock(2,10,4,CONCRETE:7,65,quark:iron_plate:0,10,quark:iron_plate:1,10,STAINED_CLAY:15,10,STAINED_CLAY:9,100)
RandomBlock(2,10,5,CONCRETE:7,65,quark:iron_plate:0,10,quark:iron_plate:1,10,STAINED_CLAY:15,10,STAINED_CLAY:9,100)
RandomBlock(2,10,6,CONCRETE:7,65,quark:iron_plate:0,10,quark:iron_plate:1,10,STAINED_CLAY:15,10,STAINED_CLAY:9,100)
RandomBlock(2,10,7,CONCRETE:7,65,quark:iron_plate:0,10,quark:iron_plate:1,10,STAINED_CLAY:15,10,STAINED_CLAY:9,100)
RandomBlock(2,10,8,CONCRETE:7,65,quark:iron_plate:0,10,quark:iron_plate:1,10,STAINED_CLAY:15,10,STAINED_CLAY:9,100)
RandomBlock(2,10,9,CONCRETE:7,65,quark:iron_plate:0,10,quark:iron_plate:1,10,STAINED_CLAY:15,10,STAINED_CLAY:9,100)
RandomBlock(2,11,-6,CONCRETE:7,65,quark:iron_plate:0,10,quark:iron_plate:1,10,STAINED_CLAY:15,10,STAINED_CLAY:9,100)
Block(2,11,-5,STAINED_GLASS:15)
Block(2,11,-4,STAINED_GLASS:15)
Block(2,11,-3,STAINED_GLASS:15)
Block(2,11,-2,STAINED_GLASS:15)
Block(2,11,-1,STAINED_GLASS:15)
Block(2,11,0,STAINED_GLASS:15)
RandomBlock(2,11,1,CONCRETE:7,65,quark:iron_plate:0,10,quark:iron_plate:1,10,STAINED_CLAY:15,10,STAINED_CLAY:9,100)
Block(2,11,2,AIR:0)
Block(2,11,3,IRON_TRAPDOOR:4)
Block(2,11,4,STEP:8)
Block(2,11,5,STEP:8)
Block(2,11,6,STEP:8)
Block(2,11,7,STEP:8)
RandomBlock(2,11,8,CONCRETE:7,65,quark:iron_plate:0,10,quark:iron_plate:1,10,STAINED_CLAY:15,10,STAINED_CLAY:9,100)
RandomBlock(2,11,9,CONCRETE:7,65,quark:iron_plate:0,10,quark:iron_plate:1,10,STAINED_CLAY:15,10,STAINED_CLAY:9,100)
RandomBlock(2,12,-6,CONCRETE:7,65,quark:iron_plate:0,10,quark:iron_plate:1,10,STAINED_CLAY:15,10,STAINED_CLAY:9,100)
Block(2,12,-5,STAINED_GLASS:15)
Block(2,12,-4,STAINED_GLASS:15)
Block(2,12,-3,STAINED_GLASS:15)
Block(2,12,-2,STAINED_GLASS:15)
Block(2,12,-1,STAINED_GLASS:15)
Block(2,12,0,STAINED_GLASS:15)
RandomBlock(2,12,1,CONCRETE:7,65,quark:iron_plate:0,10,quark:iron_plate:1,10,STAINED_CLAY:15,10,STAINED_CLAY:9,100)
Block(2,12,2,AIR:0)
Block(2,12,3,IRON_TRAPDOOR:4)
Block(2,12,4,AIR:0)
Block(2,12,5,AIR:0)
Block(2,12,6,OBSERVER:3)
Block(2,12,7,CONCRETE:15)
RandomBlock(2,12,8,CONCRETE:7,65,quark:iron_plate:0,10,quark:iron_plate:1,10,STAINED_CLAY:15,10,STAINED_CLAY:9,100)
RandomBlock(2,12,9,CONCRETE:7,65,quark:iron_plate:0,10,quark:iron_plate:1,10,STAINED_CLAY:15,10,STAINED_CLAY:9,100)
RandomBlock(2,13,-6,CONCRETE:7,65,quark:iron_plate:0,10,quark:iron_plate:1,10,STAINED_CLAY:15,10,STAINED_CLAY:9,100)
Block(2,13,-5,STAINED_GLASS:15)
Block(2,13,-4,STAINED_GLASS:15)
Block(2,13,-3,STAINED_GLASS:15)
Block(2,13,-2,STAINED_GLASS:15)
Block(2,13,-1,STAINED_GLASS:15)
Block(2,13,0,STAINED_GLASS:15)
RandomBlock(2,13,1,CONCRETE:7,65,quark:iron_plate:0,10,quark:iron_plate:1,10,STAINED_CLAY:15,10,STAINED_CLAY:9,100)
Block(2,13,3,AIR:0)
Block(2,13,4,AIR:0)
Block(2,13,5,AIR:0)
Block(2,13,6,OBSERVER:3)
Block(2,13,7,CONCRETE:15)
RandomBlock(2,13,8,CONCRETE:7,65,quark:iron_plate:0,10,quark:iron_plate:1,10,STAINED_CLAY:15,10,STAINED_CLAY:9,100)
RandomBlock(2,13,9,CONCRETE:7,65,quark:iron_plate:0,10,quark:iron_plate:1,10,STAINED_CLAY:15,10,STAINED_CLAY:9,100)
RandomBlock(2,14,-6,CONCRETE:7,65,quark:iron_plate:0,10,quark:iron_plate:1,10,STAINED_CLAY:15,10,STAINED_CLAY:9,100)
Block(2,14,-5,STAINED_GLASS:15)
Block(2,14,-4,STAINED_GLASS:15)
Block(2,14,-3,STAINED_GLASS:15)
Block(2,14,-2,STAINED_GLASS:15)
Block(2,14,-1,STAINED_GLASS:15)
Block(2,14,0,STAINED_GLASS:15)
RandomBlock(2,14,1,CONCRETE:7,65,quark:iron_plate:0,10,quark:iron_plate:1,10,STAINED_CLAY:15,10,STAINED_CLAY:9,100)
Block(2,14,2,IRON_TRAPDOOR:10)
Block(2,14,3,AIR:0)
Block(2,14,4,AIR:0)
Block(2,14,5,AIR:0)
Block(2,14,6,REDSTONE_LAMP_OFF:0)
Block(2,14,7,CONCRETE:15)
RandomBlock(2,14,8,CONCRETE:7,65,quark:iron_plate:0,10,quark:iron_plate:1,10,STAINED_CLAY:15,10,STAINED_CLAY:9,100)
RandomBlock(2,14,9,CONCRETE:7,65,quark:iron_plate:0,10,quark:iron_plate:1,10,STAINED_CLAY:15,10,STAINED_CLAY:9,100)
RandomBlock(2,15,-6,CONCRETE:7,65,quark:iron_plate:0,10,quark:iron_plate:1,10,STAINED_CLAY:15,10,STAINED_CLAY:9,100)
Block(2,15,-5,STEP:0)
Block(2,15,-4,STEP:0)
Block(2,15,-3,STEP:0)
Block(2,15,-2,STEP:0)
Block(2,15,-1,STEP:0)
Block(2,15,0,STEP:0)
RandomBlock(2,15,1,CONCRETE:7,65,quark:iron_plate:0,10,quark:iron_plate:1,10,STAINED_CLAY:15,10,STAINED_CLAY:9,100)
RandomBlock(2,15,2,CONCRETE:7,65,quark:iron_plate:0,10,quark:iron_plate:1,10,STAINED_CLAY:15,10,STAINED_CLAY:9,100)
Block(2,15,3,STEP:0)
Block(2,15,4,STEP:0)
Block(2,15,5,STEP:0)
Block(2,15,6,STEP:0)
Block(2,15,7,STEP:0)
RandomBlock(2,15,8,CONCRETE:7,65,quark:iron_plate:0,10,quark:iron_plate:1,10,STAINED_CLAY:15,10,STAINED_CLAY:9,100)
RandomBlock(2,15,9,CONCRETE:7,65,quark:iron_plate:0,10,quark:iron_plate:1,10,STAINED_CLAY:15,10,STAINED_CLAY:9,100)
RandomBlock(3,0,1,CONCRETE:7,65,quark:iron_plate:0,10,quark:iron_plate:1,10,STAINED_CLAY:15,10,STAINED_CLAY:9,100)
RandomBlock(3,0,2,CONCRETE:7,65,quark:iron_plate:0,10,quark:iron_plate:1,10,STAINED_CLAY:15,10,STAINED_CLAY:9,100)
RandomBlock(3,0,8,CONCRETE:7,65,quark:iron_plate:0,10,quark:iron_plate:1,10,STAINED_CLAY:15,10,STAINED_CLAY:9,100)
RandomBlock(3,0,9,CONCRETE:7,65,quark:iron_plate:0,10,quark:iron_plate:1,10,STAINED_CLAY:15,10,STAINED_CLAY:9,100)
RandomBlock(3,1,1,CONCRETE:7,65,quark:iron_plate:0,10,quark:iron_plate:1,10,STAINED_CLAY:15,10,STAINED_CLAY:9,100)
RandomBlock(3,1,2,CONCRETE:7,65,quark:iron_plate:0,10,quark:iron_plate:1,10,STAINED_CLAY:15,10,STAINED_CLAY:9,100)
RandomBlock(3,1,8,CONCRETE:7,65,quark:iron_plate:0,10,quark:iron_plate:1,10,STAINED_CLAY:15,10,STAINED_CLAY:9,100)
RandomBlock(3,1,9,CONCRETE:7,65,quark:iron_plate:0,10,quark:iron_plate:1,10,STAINED_CLAY:15,10,STAINED_CLAY:9,100)
RandomBlock(3,2,1,CONCRETE:7,65,quark:iron_plate:0,10,quark:iron_plate:1,10,STAINED_CLAY:15,10,STAINED_CLAY:9,100)
RandomBlock(3,2,2,CONCRETE:7,65,quark:iron_plate:0,10,quark:iron_plate:1,10,STAINED_CLAY:15,10,STAINED_CLAY:9,100)
RandomBlock(3,2,8,CONCRETE:7,65,quark:iron_plate:0,10,quark:iron_plate:1,10,STAINED_CLAY:15,10,STAINED_CLAY:9,100)
RandomBlock(3,2,9,CONCRETE:7,65,quark:iron_plate:0,10,quark:iron_plate:1,10,STAINED_CLAY:15,10,STAINED_CLAY:9,100)
RandomBlock(3,3,1,CONCRETE:7,65,quark:iron_plate:0,10,quark:iron_plate:1,10,STAINED_CLAY:15,10,STAINED_CLAY:9,100)
RandomBlock(3,3,2,CONCRETE:7,65,quark:iron_plate:0,10,quark:iron_plate:1,10,STAINED_CLAY:15,10,STAINED_CLAY:9,100)
RandomBlock(3,3,8,CONCRETE:7,65,quark:iron_plate:0,10,quark:iron_plate:1,10,STAINED_CLAY:15,10,STAINED_CLAY:9,100)
RandomBlock(3,3,9,CONCRETE:7,65,quark:iron_plate:0,10,quark:iron_plate:1,10,STAINED_CLAY:15,10,STAINED_CLAY:9,100)
RandomBlock(3,4,1,CONCRETE:7,65,quark:iron_plate:0,10,quark:iron_plate:1,10,STAINED_CLAY:15,10,STAINED_CLAY:9,100)
RandomBlock(3,4,2,CONCRETE:7,65,quark:iron_plate:0,10,quark:iron_plate:1,10,STAINED_CLAY:15,10,STAINED_CLAY:9,100)
RandomBlock(3,4,8,CONCRETE:7,65,quark:iron_plate:0,10,quark:iron_plate:1,10,STAINED_CLAY:15,10,STAINED_CLAY:9,100)
RandomBlock(3,4,9,CONCRETE:7,65,quark:iron_plate:0,10,quark:iron_plate:1,10,STAINED_CLAY:15,10,STAINED_CLAY:9,100)
RandomBlock(3,5,1,CONCRETE:7,65,quark:iron_plate:0,10,quark:iron_plate:1,10,STAINED_CLAY:15,10,STAINED_CLAY:9,100)
RandomBlock(3,5,2,CONCRETE:7,65,quark:iron_plate:0,10,quark:iron_plate:1,10,STAINED_CLAY:15,10,STAINED_CLAY:9,100)
RandomBlock(3,5,8,CONCRETE:7,65,quark:iron_plate:0,10,quark:iron_plate:1,10,STAINED_CLAY:15,10,STAINED_CLAY:9,100)
RandomBlock(3,5,9,CONCRETE:7,65,quark:iron_plate:0,10,quark:iron_plate:1,10,STAINED_CLAY:15,10,STAINED_CLAY:9,100)
RandomBlock(3,6,1,CONCRETE:7,65,quark:iron_plate:0,10,quark:iron_plate:1,10,STAINED_CLAY:15,10,STAINED_CLAY:9,100)
RandomBlock(3,6,2,CONCRETE:7,65,quark:iron_plate:0,10,quark:iron_plate:1,10,STAINED_CLAY:15,10,STAINED_CLAY:9,100)
RandomBlock(3,6,8,CONCRETE:7,65,quark:iron_plate:0,10,quark:iron_plate:1,10,STAINED_CLAY:15,10,STAINED_CLAY:9,100)
RandomBlock(3,6,9,CONCRETE:7,65,quark:iron_plate:0,10,quark:iron_plate:1,10,STAINED_CLAY:15,10,STAINED_CLAY:9,100)
RandomBlock(3,7,1,CONCRETE:7,65,quark:iron_plate:0,10,quark:iron_plate:1,10,STAINED_CLAY:15,10,STAINED_CLAY:9,100)
RandomBlock(3,7,2,CONCRETE:7,65,quark:iron_plate:0,10,quark:iron_plate:1,10,STAINED_CLAY:15,10,STAINED_CLAY:9,100)
RandomBlock(3,7,8,CONCRETE:7,65,quark:iron_plate:0,10,quark:iron_plate:1,10,STAINED_CLAY:15,10,STAINED_CLAY:9,100)
RandomBlock(3,7,9,CONCRETE:7,65,quark:iron_plate:0,10,quark:iron_plate:1,10,STAINED_CLAY:15,10,STAINED_CLAY:9,100)
RandomBlock(3,8,1,CONCRETE:7,65,quark:iron_plate:0,10,quark:iron_plate:1,10,STAINED_CLAY:15,10,STAINED_CLAY:9,100)
RandomBlock(3,8,2,CONCRETE:7,65,quark:iron_plate:0,10,quark:iron_plate:1,10,STAINED_CLAY:15,10,STAINED_CLAY:9,100)
RandomBlock(3,8,8,CONCRETE:7,65,quark:iron_plate:0,10,quark:iron_plate:1,10,STAINED_CLAY:15,10,STAINED_CLAY:9,100)
RandomBlock(3,8,9,CONCRETE:7,65,quark:iron_plate:0,10,quark:iron_plate:1,10,STAINED_CLAY:15,10,STAINED_CLAY:9,100)
RandomBlock(3,9,1,CONCRETE:7,65,quark:iron_plate:0,10,quark:iron_plate:1,10,STAINED_CLAY:15,10,STAINED_CLAY:9,100)
RandomBlock(3,9,2,CONCRETE:7,65,quark:iron_plate:0,10,quark:iron_plate:1,10,STAINED_CLAY:15,10,STAINED_CLAY:9,100)
RandomBlock(3,9,4,CONCRETE:7,65,quark:iron_plate:0,10,quark:iron_plate:1,10,STAINED_CLAY:15,10,STAINED_CLAY:9,100)
Block(3,9,5,CONCRETE:14)
RandomBlock(3,9,6,CONCRETE:7,65,quark:iron_plate:0,10,quark:iron_plate:1,10,STAINED_CLAY:15,10,STAINED_CLAY:9,100)
RandomBlock(3,9,8,CONCRETE:7,65,quark:iron_plate:0,10,quark:iron_plate:1,10,STAINED_CLAY:15,10,STAINED_CLAY:9,100)
RandomBlock(3,9,9,CONCRETE:7,65,quark:iron_plate:0,10,quark:iron_plate:1,10,STAINED_CLAY:15,10,STAINED_CLAY:9,100)
RandomBlock(3,10,1,CONCRETE:7,65,quark:iron_plate:0,10,quark:iron_plate:1,10,STAINED_CLAY:15,10,STAINED_CLAY:9,100)
RandomBlock(3,10,2,CONCRETE:7,65,quark:iron_plate:0,10,quark:iron_plate:1,10,STAINED_CLAY:15,10,STAINED_CLAY:9,100)
RandomBlock(3,10,3,CONCRETE:7,65,quark:iron_plate:0,10,quark:iron_plate:1,10,STAINED_CLAY:15,10,STAINED_CLAY:9,100)
RandomBlock(3,10,4,CONCRETE:7,65,quark:iron_plate:0,10,quark:iron_plate:1,10,STAINED_CLAY:15,10,STAINED_CLAY:9,100)
RandomBlock(3,10,5,CONCRETE:7,65,quark:iron_plate:0,10,quark:iron_plate:1,10,STAINED_CLAY:15,10,STAINED_CLAY:9,100)
RandomBlock(3,10,6,CONCRETE:7,65,quark:iron_plate:0,10,quark:iron_plate:1,10,STAINED_CLAY:15,10,STAINED_CLAY:9,100)
RandomBlock(3,10,7,CONCRETE:7,65,quark:iron_plate:0,10,quark:iron_plate:1,10,STAINED_CLAY:15,10,STAINED_CLAY:9,100)
RandomBlock(3,10,8,CONCRETE:7,65,quark:iron_plate:0,10,quark:iron_plate:1,10,STAINED_CLAY:15,10,STAINED_CLAY:9,100)
RandomBlock(3,10,9,CONCRETE:7,65,quark:iron_plate:0,10,quark:iron_plate:1,10,STAINED_CLAY:15,10,STAINED_CLAY:9,100)
Block(3,11,1,STAINED_GLASS:15)
Block(3,11,2,AIR:0)
Block(3,11,3,IRON_TRAPDOOR:4)
Block(3,11,4,DOUBLE_STEP:0)
Block(3,11,5,STEP:8)
Block(3,11,6,STEP:8)
Block(3,11,7,STEP:8)
RandomBlock(3,11,8,CONCRETE:7,65,quark:iron_plate:0,10,quark:iron_plate:1,10,STAINED_CLAY:15,10,STAINED_CLAY:9,100)
RandomBlock(3,11,9,CONCRETE:7,65,quark:iron_plate:0,10,quark:iron_plate:1,10,STAINED_CLAY:15,10,STAINED_CLAY:9,100)
Block(3,12,1,STAINED_GLASS:15)
Block(3,12,2,AIR:0)
Block(3,12,3,IRON_TRAPDOOR:4)
Block(3,12,4,AIR:0)
Block(3,12,5,AIR:0)
Block(3,12,6,CONCRETE:15)
Block(3,12,7,CONCRETE:15)
RandomBlock(3,12,8,CONCRETE:7,65,quark:iron_plate:0,10,quark:iron_plate:1,10,STAINED_CLAY:15,10,STAINED_CLAY:9,100)
RandomBlock(3,12,9,CONCRETE:7,65,quark:iron_plate:0,10,quark:iron_plate:1,10,STAINED_CLAY:15,10,STAINED_CLAY:9,100)
Block(3,13,1,STAINED_GLASS:15)
Block(3,13,2,AIR:0)
Block(3,13,3,AIR:0)
Block(3,13,4,AIR:0)
Block(3,13,5,STONE_BUTTON:4)
Block(3,13,6,CONCRETE:15)
Block(3,13,7,CONCRETE:15)
RandomBlock(3,13,8,CONCRETE:7,65,quark:iron_plate:0,10,quark:iron_plate:1,10,STAINED_CLAY:15,10,STAINED_CLAY:9,100)
RandomBlock(3,13,9,CONCRETE:7,65,quark:iron_plate:0,10,quark:iron_plate:1,10,STAINED_CLAY:15,10,STAINED_CLAY:9,100)
Block(3,14,1,STAINED_GLASS:15)
Block(3,14,2,IRON_TRAPDOOR:10)
Block(3,14,3,IRON_TRAPDOOR:8)
Block(3,14,4,IRON_TRAPDOOR:8)
Block(3,14,5,QUARTZ_STAIRS:6)
Block(3,14,6,CONCRETE:15)
Block(3,14,7,CONCRETE:15)
RandomBlock(3,14,8,CONCRETE:7,65,quark:iron_plate:0,10,quark:iron_plate:1,10,STAINED_CLAY:15,10,STAINED_CLAY:9,100)
RandomBlock(3,14,9,CONCRETE:7,65,quark:iron_plate:0,10,quark:iron_plate:1,10,STAINED_CLAY:15,10,STAINED_CLAY:9,100)
RandomBlock(3,15,1,CONCRETE:7,65,quark:iron_plate:0,10,quark:iron_plate:1,10,STAINED_CLAY:15,10,STAINED_CLAY:9,100)
RandomBlock(3,15,2,CONCRETE:7,65,quark:iron_plate:0,10,quark:iron_plate:1,10,STAINED_CLAY:15,10,STAINED_CLAY:9,100)
Block(3,15,3,STEP:0)
Block(3,15,4,STEP:0)
Block(3,15,5,STEP:0)
Block(3,15,6,STEP:0)
Block(3,15,7,STEP:0)
RandomBlock(3,15,8,CONCRETE:7,65,quark:iron_plate:0,10,quark:iron_plate:1,10,STAINED_CLAY:15,10,STAINED_CLAY:9,100)
RandomBlock(3,15,9,CONCRETE:7,65,quark:iron_plate:0,10,quark:iron_plate:1,10,STAINED_CLAY:15,10,STAINED_CLAY:9,100)
RandomBlock(4,9,4,CONCRETE:7,65,quark:iron_plate:0,10,quark:iron_plate:1,10,STAINED_CLAY:15,10,STAINED_CLAY:9,100)
Block(4,9,5,CONCRETE:14)
RandomBlock(4,9,6,CONCRETE:7,65,quark:iron_plate:0,10,quark:iron_plate:1,10,STAINED_CLAY:15,10,STAINED_CLAY:9,100)
RandomBlock(4,10,1,CONCRETE:7,65,quark:iron_plate:0,10,quark:iron_plate:1,10,STAINED_CLAY:15,10,STAINED_CLAY:9,100)
RandomBlock(4,10,2,CONCRETE:7,65,quark:iron_plate:0,10,quark:iron_plate:1,10,STAINED_CLAY:15,10,STAINED_CLAY:9,100)
RandomBlock(4,10,3,CONCRETE:7,65,quark:iron_plate:0,10,quark:iron_plate:1,10,STAINED_CLAY:15,10,STAINED_CLAY:9,100)
RandomBlock(4,10,4,CONCRETE:7,65,quark:iron_plate:0,10,quark:iron_plate:1,10,STAINED_CLAY:15,10,STAINED_CLAY:9,100)
RandomBlock(4,10,5,CONCRETE:7,65,quark:iron_plate:0,10,quark:iron_plate:1,10,STAINED_CLAY:15,10,STAINED_CLAY:9,100)
RandomBlock(4,10,6,CONCRETE:7,65,quark:iron_plate:0,10,quark:iron_plate:1,10,STAINED_CLAY:15,10,STAINED_CLAY:9,100)
RandomBlock(4,10,7,CONCRETE:7,65,quark:iron_plate:0,10,quark:iron_plate:1,10,STAINED_CLAY:15,10,STAINED_CLAY:9,100)
RandomBlock(4,10,8,CONCRETE:7,65,quark:iron_plate:0,10,quark:iron_plate:1,10,STAINED_CLAY:15,10,STAINED_CLAY:9,100)
Block(4,11,1,STAINED_GLASS:15)
Block(4,11,2,AIR:0)
Block(4,11,3,IRON_TRAPDOOR:4)
Block(4,11,4,STEP:8)
Block(4,11,5,STEP:8)
Block(4,11,6,STEP:8)
Block(4,11,7,STEP:8)
Block(4,11,8,STAINED_GLASS:15)
Block(4,12,1,STAINED_GLASS:15)
Block(4,12,2,AIR:0)
Block(4,12,3,IRON_TRAPDOOR:4)
Block(4,12,4,AIR:0)
Block(4,12,5,AIR:0)
Block(4,12,6,OBSERVER:3)
Block(4,12,7,CONCRETE:15)
Block(4,12,8,STAINED_GLASS:15)
Block(4,13,1,STAINED_GLASS:15)
Block(4,13,2,AIR:0)
Block(4,13,3,AIR:0)
Block(4,13,4,AIR:0)
Block(4,13,5,AIR:0)
Block(4,13,6,OBSERVER:3)
Block(4,13,7,CONCRETE:15)
Block(4,13,8,STAINED_GLASS:15)
Block(4,14,1,STAINED_GLASS:15)
Block(4,14,2,IRON_TRAPDOOR:10)
Block(4,14,3,AIR:0)
Block(4,14,4,AIR:0)
Block(4,14,5,AIR:0)
Block(4,14,6,REDSTONE_LAMP_OFF:0)
Block(4,14,7,CONCRETE:15)
Block(4,14,8,STAINED_GLASS:15)
RandomBlock(4,15,1,CONCRETE:7,65,quark:iron_plate:0,10,quark:iron_plate:1,10,STAINED_CLAY:15,10,STAINED_CLAY:9,100)
RandomBlock(4,15,2,CONCRETE:7,65,quark:iron_plate:0,10,quark:iron_plate:1,10,STAINED_CLAY:15,10,STAINED_CLAY:9,100)
Block(4,15,3,STEP:0)
Block(4,15,4,STEP:0)
Block(4,15,5,STEP:0)
Block(4,15,6,STEP:0)
Block(4,15,7,STEP:0)
RandomBlock(4,15,8,CONCRETE:7,65,quark:iron_plate:0,10,quark:iron_plate:1,10,STAINED_CLAY:15,10,STAINED_CLAY:9,100)
RandomBlock(5,9,4,CONCRETE:7,65,quark:iron_plate:0,10,quark:iron_plate:1,10,STAINED_CLAY:15,10,STAINED_CLAY:9,100)
Block(5,9,5,CONCRETE:14)
RandomBlock(5,9,6,CONCRETE:7,65,quark:iron_plate:0,10,quark:iron_plate:1,10,STAINED_CLAY:15,10,STAINED_CLAY:9,100)
RandomBlock(5,10,1,CONCRETE:7,65,quark:iron_plate:0,10,quark:iron_plate:1,10,STAINED_CLAY:15,10,STAINED_CLAY:9,100)
RandomBlock(5,10,2,CONCRETE:7,65,quark:iron_plate:0,10,quark:iron_plate:1,10,STAINED_CLAY:15,10,STAINED_CLAY:9,100)
RandomBlock(5,10,3,CONCRETE:7,65,quark:iron_plate:0,10,quark:iron_plate:1,10,STAINED_CLAY:15,10,STAINED_CLAY:9,100)
RandomBlock(5,10,4,CONCRETE:7,65,quark:iron_plate:0,10,quark:iron_plate:1,10,STAINED_CLAY:15,10,STAINED_CLAY:9,100)
RandomBlock(5,10,5,CONCRETE:7,65,quark:iron_plate:0,10,quark:iron_plate:1,10,STAINED_CLAY:15,10,STAINED_CLAY:9,100)
RandomBlock(5,10,6,CONCRETE:7,65,quark:iron_plate:0,10,quark:iron_plate:1,10,STAINED_CLAY:15,10,STAINED_CLAY:9,100)
RandomBlock(5,10,7,CONCRETE:7,65,quark:iron_plate:0,10,quark:iron_plate:1,10,STAINED_CLAY:15,10,STAINED_CLAY:9,100)
RandomBlock(5,10,8,CONCRETE:7,65,quark:iron_plate:0,10,quark:iron_plate:1,10,STAINED_CLAY:15,10,STAINED_CLAY:9,100)
Block(5,11,1,STAINED_GLASS:15)
Block(5,11,2,AIR:0)
Block(5,11,3,IRON_TRAPDOOR:4)
Block(5,11,4,STEP:8)
Block(5,11,5,STEP:8)
Block(5,11,6,STEP:8)
Block(5,11,7,STEP:8)
Block(5,11,8,STAINED_GLASS:15)
Block(5,12,1,STAINED_GLASS:15)
Block(5,12,2,AIR:0)
Block(5,12,3,IRON_TRAPDOOR:4)
Block(5,12,4,AIR:0)
Block(5,12,5,AIR:0)
Block(5,12,6,CONCRETE:15)
Block(5,12,7,CONCRETE:15)
Block(5,12,8,STAINED_GLASS:15)
Block(5,13,1,STAINED_GLASS:15)
Block(5,13,3,AIR:0)
Block(5,13,4,AIR:0)
Block(5,13,5,STONE_BUTTON:4)
Block(5,13,6,CONCRETE:15)
Block(5,13,7,CONCRETE:15)
Block(5,13,8,STAINED_GLASS:15)
Block(5,14,1,STAINED_GLASS:15)
Block(5,14,2,IRON_TRAPDOOR:10)
Block(5,14,3,IRON_TRAPDOOR:8)
Block(5,14,4,IRON_TRAPDOOR:8)
Block(5,14,5,QUARTZ_STAIRS:6)
Block(5,14,6,CONCRETE:15)
Block(5,14,7,CONCRETE:15)
Block(5,14,8,STAINED_GLASS:15)
RandomBlock(5,15,1,CONCRETE:7,65,quark:iron_plate:0,10,quark:iron_plate:1,10,STAINED_CLAY:15,10,STAINED_CLAY:9,100)
RandomBlock(5,15,2,CONCRETE:7,65,quark:iron_plate:0,10,quark:iron_plate:1,10,STAINED_CLAY:15,10,STAINED_CLAY:9,100)
Block(5,15,3,STEP:0)
Block(5,15,4,STEP:0)
Block(5,15,5,STEP:0)
Block(5,15,6,STEP:0)
Block(5,15,7,STEP:0)
RandomBlock(5,15,8,CONCRETE:7,65,quark:iron_plate:0,10,quark:iron_plate:1,10,STAINED_CLAY:15,10,STAINED_CLAY:9,100)
Block(6,9,2,CONCRETE:14)
Block(6,9,3,CONCRETE:14)
Block(6,9,4,CONCRETE:14)
Block(6,9,5,CONCRETE:14)
RandomBlock(6,9,6,CONCRETE:7,65,quark:iron_plate:0,10,quark:iron_plate:1,10,STAINED_CLAY:15,10,STAINED_CLAY:9,100)
RandomBlock(6,10,1,CONCRETE:7,65,quark:iron_plate:0,10,quark:iron_plate:1,10,STAINED_CLAY:15,10,STAINED_CLAY:9,100)
Block(6,10,2,CONCRETE:14)
RandomBlock(6,10,3,CONCRETE:7,65,quark:iron_plate:0,10,quark:iron_plate:1,10,STAINED_CLAY:15,10,STAINED_CLAY:9,100)
RandomBlock(6,10,4,CONCRETE:7,65,quark:iron_plate:0,10,quark:iron_plate:1,10,STAINED_CLAY:15,10,STAINED_CLAY:9,100)
RandomBlock(6,10,5,CONCRETE:7,65,quark:iron_plate:0,10,quark:iron_plate:1,10,STAINED_CLAY:15,10,STAINED_CLAY:9,100)
RandomBlock(6,10,6,CONCRETE:7,65,quark:iron_plate:0,10,quark:iron_plate:1,10,STAINED_CLAY:15,10,STAINED_CLAY:9,100)
RandomBlock(6,10,7,CONCRETE:7,65,quark:iron_plate:0,10,quark:iron_plate:1,10,STAINED_CLAY:15,10,STAINED_CLAY:9,100)
RandomBlock(6,10,8,CONCRETE:7,65,quark:iron_plate:0,10,quark:iron_plate:1,10,STAINED_CLAY:15,10,STAINED_CLAY:9,100)
Block(6,11,1,STAINED_GLASS:15)
Block(6,11,2,CONCRETE:14)
Block(6,11,3,IRON_TRAPDOOR:4)
Block(6,11,4,DOUBLE_STEP:0)
Block(6,11,5,STEP:8)
Block(6,11,6,STEP:8)
Block(6,11,7,STEP:8)
Block(6,11,8,STAINED_GLASS:15)
Block(6,12,1,STAINED_GLASS:15)
Block(6,12,2,CONCRETE:14)
Block(6,12,3,IRON_TRAPDOOR:4)
Block(6,12,4,AIR:0)
Block(6,12,5,AIR:0)
Block(6,12,6,OBSERVER:3)
Block(6,12,7,CONCRETE:15)
Block(6,12,8,STAINED_GLASS:15)
Block(6,13,1,STAINED_GLASS:15)
Block(6,13,2,CONCRETE:14)
Block(6,13,3,AIR:0)
Block(6,13,4,AIR:0)
Block(6,13,5,AIR:0)
Block(6,13,6,OBSERVER:3)
Block(6,13,7,CONCRETE:15)
Block(6,13,8,STAINED_GLASS:15)
Block(6,14,1,STAINED_GLASS:15)
Block(6,14,2,CONCRETE:14)
Block(6,14,3,CONCRETE:14)
Block(6,14,4,CONCRETE:14)
Block(6,14,5,CONCRETE:14)
Block(6,14,6,REDSTONE_LAMP_OFF:0)
Block(6,14,7,CONCRETE:15)
Block(6,14,8,STAINED_GLASS:15)
RandomBlock(6,15,1,CONCRETE:7,65,quark:iron_plate:0,10,quark:iron_plate:1,10,STAINED_CLAY:15,10,STAINED_CLAY:9,100)
RandomBlock(6,15,2,CONCRETE:7,65,quark:iron_plate:0,10,quark:iron_plate:1,10,STAINED_CLAY:15,10,STAINED_CLAY:9,100)
Block(6,15,3,STEP:0)
RandomBlock(6,15,4,CONCRETE:7,65,quark:iron_plate:0,10,quark:iron_plate:1,10,STAINED_CLAY:15,10,STAINED_CLAY:9,100)
Block(6,15,5,STEP:0)
RandomBlock(6,15,6,CONCRETE:7,65,quark:iron_plate:0,10,quark:iron_plate:1,10,STAINED_CLAY:15,10,STAINED_CLAY:9,100)
Block(6,15,7,STEP:0)
RandomBlock(6,15,8,CONCRETE:7,65,quark:iron_plate:0,10,quark:iron_plate:1,10,STAINED_CLAY:15,10,STAINED_CLAY:9,100)
RandomBlock(7,0,1,CONCRETE:7,65,quark:iron_plate:0,10,quark:iron_plate:1,10,STAINED_CLAY:15,10,STAINED_CLAY:9,100)
RandomBlock(7,0,2,CONCRETE:7,65,quark:iron_plate:0,10,quark:iron_plate:1,10,STAINED_CLAY:15,10,STAINED_CLAY:9,100)
RandomBlock(7,0,8,CONCRETE:7,65,quark:iron_plate:0,10,quark:iron_plate:1,10,STAINED_CLAY:15,10,STAINED_CLAY:9,100)
RandomBlock(7,0,9,CONCRETE:7,65,quark:iron_plate:0,10,quark:iron_plate:1,10,STAINED_CLAY:15,10,STAINED_CLAY:9,100)
RandomBlock(7,1,1,CONCRETE:7,65,quark:iron_plate:0,10,quark:iron_plate:1,10,STAINED_CLAY:15,10,STAINED_CLAY:9,100)
RandomBlock(7,1,2,CONCRETE:7,65,quark:iron_plate:0,10,quark:iron_plate:1,10,STAINED_CLAY:15,10,STAINED_CLAY:9,100)
RandomBlock(7,1,8,CONCRETE:7,65,quark:iron_plate:0,10,quark:iron_plate:1,10,STAINED_CLAY:15,10,STAINED_CLAY:9,100)
RandomBlock(7,1,9,CONCRETE:7,65,quark:iron_plate:0,10,quark:iron_plate:1,10,STAINED_CLAY:15,10,STAINED_CLAY:9,100)
RandomBlock(7,2,1,CONCRETE:7,65,quark:iron_plate:0,10,quark:iron_plate:1,10,STAINED_CLAY:15,10,STAINED_CLAY:9,100)
RandomBlock(7,2,2,CONCRETE:7,65,quark:iron_plate:0,10,quark:iron_plate:1,10,STAINED_CLAY:15,10,STAINED_CLAY:9,100)
RandomBlock(7,2,8,CONCRETE:7,65,quark:iron_plate:0,10,quark:iron_plate:1,10,STAINED_CLAY:15,10,STAINED_CLAY:9,100)
RandomBlock(7,2,9,CONCRETE:7,65,quark:iron_plate:0,10,quark:iron_plate:1,10,STAINED_CLAY:15,10,STAINED_CLAY:9,100)
RandomBlock(7,3,1,CONCRETE:7,65,quark:iron_plate:0,10,quark:iron_plate:1,10,STAINED_CLAY:15,10,STAINED_CLAY:9,100)
RandomBlock(7,3,2,CONCRETE:7,65,quark:iron_plate:0,10,quark:iron_plate:1,10,STAINED_CLAY:15,10,STAINED_CLAY:9,100)
RandomBlock(7,3,8,CONCRETE:7,65,quark:iron_plate:0,10,quark:iron_plate:1,10,STAINED_CLAY:15,10,STAINED_CLAY:9,100)
RandomBlock(7,3,9,CONCRETE:7,65,quark:iron_plate:0,10,quark:iron_plate:1,10,STAINED_CLAY:15,10,STAINED_CLAY:9,100)
RandomBlock(7,4,1,CONCRETE:7,65,quark:iron_plate:0,10,quark:iron_plate:1,10,STAINED_CLAY:15,10,STAINED_CLAY:9,100)
RandomBlock(7,4,2,CONCRETE:7,65,quark:iron_plate:0,10,quark:iron_plate:1,10,STAINED_CLAY:15,10,STAINED_CLAY:9,100)
RandomBlock(7,4,8,CONCRETE:7,65,quark:iron_plate:0,10,quark:iron_plate:1,10,STAINED_CLAY:15,10,STAINED_CLAY:9,100)
RandomBlock(7,4,9,CONCRETE:7,65,quark:iron_plate:0,10,quark:iron_plate:1,10,STAINED_CLAY:15,10,STAINED_CLAY:9,100)
RandomBlock(7,5,1,CONCRETE:7,65,quark:iron_plate:0,10,quark:iron_plate:1,10,STAINED_CLAY:15,10,STAINED_CLAY:9,100)
RandomBlock(7,5,2,CONCRETE:7,65,quark:iron_plate:0,10,quark:iron_plate:1,10,STAINED_CLAY:15,10,STAINED_CLAY:9,100)
RandomBlock(7,5,8,CONCRETE:7,65,quark:iron_plate:0,10,quark:iron_plate:1,10,STAINED_CLAY:15,10,STAINED_CLAY:9,100)
RandomBlock(7,5,9,CONCRETE:7,65,quark:iron_plate:0,10,quark:iron_plate:1,10,STAINED_CLAY:15,10,STAINED_CLAY:9,100)
RandomBlock(7,6,1,CONCRETE:7,65,quark:iron_plate:0,10,quark:iron_plate:1,10,STAINED_CLAY:15,10,STAINED_CLAY:9,100)
RandomBlock(7,6,2,CONCRETE:7,65,quark:iron_plate:0,10,quark:iron_plate:1,10,STAINED_CLAY:15,10,STAINED_CLAY:9,100)
RandomBlock(7,6,8,CONCRETE:7,65,quark:iron_plate:0,10,quark:iron_plate:1,10,STAINED_CLAY:15,10,STAINED_CLAY:9,100)
RandomBlock(7,6,9,CONCRETE:7,65,quark:iron_plate:0,10,quark:iron_plate:1,10,STAINED_CLAY:15,10,STAINED_CLAY:9,100)
RandomBlock(7,7,1,CONCRETE:7,65,quark:iron_plate:0,10,quark:iron_plate:1,10,STAINED_CLAY:15,10,STAINED_CLAY:9,100)
RandomBlock(7,7,2,CONCRETE:7,65,quark:iron_plate:0,10,quark:iron_plate:1,10,STAINED_CLAY:15,10,STAINED_CLAY:9,100)
RandomBlock(7,7,8,CONCRETE:7,65,quark:iron_plate:0,10,quark:iron_plate:1,10,STAINED_CLAY:15,10,STAINED_CLAY:9,100)
RandomBlock(7,7,9,CONCRETE:7,65,quark:iron_plate:0,10,quark:iron_plate:1,10,STAINED_CLAY:15,10,STAINED_CLAY:9,100)
RandomBlock(7,8,1,CONCRETE:7,65,quark:iron_plate:0,10,quark:iron_plate:1,10,STAINED_CLAY:15,10,STAINED_CLAY:9,100)
RandomBlock(7,8,2,CONCRETE:7,65,quark:iron_plate:0,10,quark:iron_plate:1,10,STAINED_CLAY:15,10,STAINED_CLAY:9,100)
RandomBlock(7,8,8,CONCRETE:7,65,quark:iron_plate:0,10,quark:iron_plate:1,10,STAINED_CLAY:15,10,STAINED_CLAY:9,100)
RandomBlock(7,8,9,CONCRETE:7,65,quark:iron_plate:0,10,quark:iron_plate:1,10,STAINED_CLAY:15,10,STAINED_CLAY:9,100)
RandomBlock(7,9,1,CONCRETE:7,65,quark:iron_plate:0,10,quark:iron_plate:1,10,STAINED_CLAY:15,10,STAINED_CLAY:9,100)
RandomBlock(7,9,2,CONCRETE:7,65,quark:iron_plate:0,10,quark:iron_plate:1,10,STAINED_CLAY:15,10,STAINED_CLAY:9,100)
RandomBlock(7,9,4,CONCRETE:7,65,quark:iron_plate:0,10,quark:iron_plate:1,10,STAINED_CLAY:15,10,STAINED_CLAY:9,100)
RandomBlock(7,9,6,CONCRETE:7,65,quark:iron_plate:0,10,quark:iron_plate:1,10,STAINED_CLAY:15,10,STAINED_CLAY:9,100)
RandomBlock(7,9,8,CONCRETE:7,65,quark:iron_plate:0,10,quark:iron_plate:1,10,STAINED_CLAY:15,10,STAINED_CLAY:9,100)
RandomBlock(7,9,9,CONCRETE:7,65,quark:iron_plate:0,10,quark:iron_plate:1,10,STAINED_CLAY:15,10,STAINED_CLAY:9,100)
RandomBlock(7,10,1,CONCRETE:7,65,quark:iron_plate:0,10,quark:iron_plate:1,10,STAINED_CLAY:15,10,STAINED_CLAY:9,100)
RandomBlock(7,10,2,CONCRETE:7,65,quark:iron_plate:0,10,quark:iron_plate:1,10,STAINED_CLAY:15,10,STAINED_CLAY:9,100)
RandomBlock(7,10,3,CONCRETE:7,65,quark:iron_plate:0,10,quark:iron_plate:1,10,STAINED_CLAY:15,10,STAINED_CLAY:9,100)
RandomBlock(7,10,4,CONCRETE:7,65,quark:iron_plate:0,10,quark:iron_plate:1,10,STAINED_CLAY:15,10,STAINED_CLAY:9,100)
RandomBlock(7,10,5,CONCRETE:7,65,quark:iron_plate:0,10,quark:iron_plate:1,10,STAINED_CLAY:15,10,STAINED_CLAY:9,100)
RandomBlock(7,10,6,CONCRETE:7,65,quark:iron_plate:0,10,quark:iron_plate:1,10,STAINED_CLAY:15,10,STAINED_CLAY:9,100)
RandomBlock(7,10,7,CONCRETE:7,65,quark:iron_plate:0,10,quark:iron_plate:1,10,STAINED_CLAY:15,10,STAINED_CLAY:9,100)
RandomBlock(7,10,8,CONCRETE:7,65,quark:iron_plate:0,10,quark:iron_plate:1,10,STAINED_CLAY:15,10,STAINED_CLAY:9,100)
RandomBlock(7,10,9,CONCRETE:7,65,quark:iron_plate:0,10,quark:iron_plate:1,10,STAINED_CLAY:15,10,STAINED_CLAY:9,100)
RandomBlock(7,11,1,CONCRETE:7,65,quark:iron_plate:0,10,quark:iron_plate:1,10,STAINED_CLAY:15,10,STAINED_CLAY:9,100)
RandomBlock(7,11,2,CONCRETE:7,65,quark:iron_plate:0,10,quark:iron_plate:1,10,STAINED_CLAY:15,10,STAINED_CLAY:9,100)
Block(7,11,3,STAINED_GLASS:15)
RandomBlock(7,11,4,CONCRETE:7,65,quark:iron_plate:0,10,quark:iron_plate:1,10,STAINED_CLAY:15,10,STAINED_CLAY:9,100)
Block(7,11,5,STAINED_GLASS:15)
RandomBlock(7,11,6,CONCRETE:7,65,quark:iron_plate:0,10,quark:iron_plate:1,10,STAINED_CLAY:15,10,STAINED_CLAY:9,100)
Block(7,11,7,STAINED_GLASS:15)
RandomBlock(7,11,8,CONCRETE:7,65,quark:iron_plate:0,10,quark:iron_plate:1,10,STAINED_CLAY:15,10,STAINED_CLAY:9,100)
RandomBlock(7,11,9,CONCRETE:7,65,quark:iron_plate:0,10,quark:iron_plate:1,10,STAINED_CLAY:15,10,STAINED_CLAY:9,100)
RandomBlock(7,12,1,CONCRETE:7,65,quark:iron_plate:0,10,quark:iron_plate:1,10,STAINED_CLAY:15,10,STAINED_CLAY:9,100)
RandomBlock(7,12,2,CONCRETE:7,65,quark:iron_plate:0,10,quark:iron_plate:1,10,STAINED_CLAY:15,10,STAINED_CLAY:9,100)
Block(7,12,3,STAINED_GLASS:15)
RandomBlock(7,12,4,CONCRETE:7,65,quark:iron_plate:0,10,quark:iron_plate:1,10,STAINED_CLAY:15,10,STAINED_CLAY:9,100)
Block(7,12,5,STAINED_GLASS:15)
RandomBlock(7,12,6,CONCRETE:7,65,quark:iron_plate:0,10,quark:iron_plate:1,10,STAINED_CLAY:15,10,STAINED_CLAY:9,100)
Block(7,12,7,STAINED_GLASS:15)
RandomBlock(7,12,8,CONCRETE:7,65,quark:iron_plate:0,10,quark:iron_plate:1,10,STAINED_CLAY:15,10,STAINED_CLAY:9,100)
RandomBlock(7,12,9,CONCRETE:7,65,quark:iron_plate:0,10,quark:iron_plate:1,10,STAINED_CLAY:15,10,STAINED_CLAY:9,100)
RandomBlock(7,13,1,CONCRETE:7,65,quark:iron_plate:0,10,quark:iron_plate:1,10,STAINED_CLAY:15,10,STAINED_CLAY:9,100)
RandomBlock(7,13,2,CONCRETE:7,65,quark:iron_plate:0,10,quark:iron_plate:1,10,STAINED_CLAY:15,10,STAINED_CLAY:9,100)
Block(7,13,3,STAINED_GLASS:15)
RandomBlock(7,13,4,CONCRETE:7,65,quark:iron_plate:0,10,quark:iron_plate:1,10,STAINED_CLAY:15,10,STAINED_CLAY:9,100)
Block(7,13,5,STAINED_GLASS:15)
RandomBlock(7,13,6,CONCRETE:7,65,quark:iron_plate:0,10,quark:iron_plate:1,10,STAINED_CLAY:15,10,STAINED_CLAY:9,100)
Block(7,13,7,STAINED_GLASS:15)
RandomBlock(7,13,8,CONCRETE:7,65,quark:iron_plate:0,10,quark:iron_plate:1,10,STAINED_CLAY:15,10,STAINED_CLAY:9,100)
RandomBlock(7,13,9,CONCRETE:7,65,quark:iron_plate:0,10,quark:iron_plate:1,10,STAINED_CLAY:15,10,STAINED_CLAY:9,100)
RandomBlock(7,14,1,CONCRETE:7,65,quark:iron_plate:0,10,quark:iron_plate:1,10,STAINED_CLAY:15,10,STAINED_CLAY:9,100)
RandomBlock(7,14,2,CONCRETE:7,65,quark:iron_plate:0,10,quark:iron_plate:1,10,STAINED_CLAY:15,10,STAINED_CLAY:9,100)
Block(7,14,3,STAINED_GLASS:15)
RandomBlock(7,14,4,CONCRETE:7,65,quark:iron_plate:0,10,quark:iron_plate:1,10,STAINED_CLAY:15,10,STAINED_CLAY:9,100)
Block(7,14,5,STAINED_GLASS:15)
RandomBlock(7,14,6,CONCRETE:7,65,quark:iron_plate:0,10,quark:iron_plate:1,10,STAINED_CLAY:15,10,STAINED_CLAY:9,100)
Block(7,14,7,STAINED_GLASS:15)
RandomBlock(7,14,8,CONCRETE:7,65,quark:iron_plate:0,10,quark:iron_plate:1,10,STAINED_CLAY:15,10,STAINED_CLAY:9,100)
RandomBlock(7,14,9,CONCRETE:7,65,quark:iron_plate:0,10,quark:iron_plate:1,10,STAINED_CLAY:15,10,STAINED_CLAY:9,100)
RandomBlock(7,15,1,CONCRETE:7,65,quark:iron_plate:0,10,quark:iron_plate:1,10,STAINED_CLAY:15,10,STAINED_CLAY:9,100)
RandomBlock(7,15,2,CONCRETE:7,65,quark:iron_plate:0,10,quark:iron_plate:1,10,STAINED_CLAY:15,10,STAINED_CLAY:9,100)
Block(7,15,3,STEP:0)
RandomBlock(7,15,4,CONCRETE:7,65,quark:iron_plate:0,10,quark:iron_plate:1,10,STAINED_CLAY:15,10,STAINED_CLAY:9,100)
Block(7,15,5,STEP:0)
RandomBlock(7,15,6,CONCRETE:7,65,quark:iron_plate:0,10,quark:iron_plate:1,10,STAINED_CLAY:15,10,STAINED_CLAY:9,100)
Block(7,15,7,STEP:0)
RandomBlock(7,15,8,CONCRETE:7,65,quark:iron_plate:0,10,quark:iron_plate:1,10,STAINED_CLAY:15,10,STAINED_CLAY:9,100)
RandomBlock(7,15,9,CONCRETE:7,65,quark:iron_plate:0,10,quark:iron_plate:1,10,STAINED_CLAY:15,10,STAINED_CLAY:9,100)
RandomBlock(8,0,1,CONCRETE:7,65,quark:iron_plate:0,10,quark:iron_plate:1,10,STAINED_CLAY:15,10,STAINED_CLAY:9,100)
RandomBlock(8,0,2,CONCRETE:7,65,quark:iron_plate:0,10,quark:iron_plate:1,10,STAINED_CLAY:15,10,STAINED_CLAY:9,100)
RandomBlock(8,0,8,CONCRETE:7,65,quark:iron_plate:0,10,quark:iron_plate:1,10,STAINED_CLAY:15,10,STAINED_CLAY:9,100)
RandomBlock(8,0,9,CONCRETE:7,65,quark:iron_plate:0,10,quark:iron_plate:1,10,STAINED_CLAY:15,10,STAINED_CLAY:9,100)
RandomBlock(8,1,1,CONCRETE:7,65,quark:iron_plate:0,10,quark:iron_plate:1,10,STAINED_CLAY:15,10,STAINED_CLAY:9,100)
RandomBlock(8,1,2,CONCRETE:7,65,quark:iron_plate:0,10,quark:iron_plate:1,10,STAINED_CLAY:15,10,STAINED_CLAY:9,100)
RandomBlock(8,1,8,CONCRETE:7,65,quark:iron_plate:0,10,quark:iron_plate:1,10,STAINED_CLAY:15,10,STAINED_CLAY:9,100)
RandomBlock(8,1,9,CONCRETE:7,65,quark:iron_plate:0,10,quark:iron_plate:1,10,STAINED_CLAY:15,10,STAINED_CLAY:9,100)
RandomBlock(8,2,1,CONCRETE:7,65,quark:iron_plate:0,10,quark:iron_plate:1,10,STAINED_CLAY:15,10,STAINED_CLAY:9,100)
RandomBlock(8,2,2,CONCRETE:7,65,quark:iron_plate:0,10,quark:iron_plate:1,10,STAINED_CLAY:15,10,STAINED_CLAY:9,100)
RandomBlock(8,2,8,CONCRETE:7,65,quark:iron_plate:0,10,quark:iron_plate:1,10,STAINED_CLAY:15,10,STAINED_CLAY:9,100)
RandomBlock(8,2,9,CONCRETE:7,65,quark:iron_plate:0,10,quark:iron_plate:1,10,STAINED_CLAY:15,10,STAINED_CLAY:9,100)
RandomBlock(8,3,1,CONCRETE:7,65,quark:iron_plate:0,10,quark:iron_plate:1,10,STAINED_CLAY:15,10,STAINED_CLAY:9,100)
RandomBlock(8,3,2,CONCRETE:7,65,quark:iron_plate:0,10,quark:iron_plate:1,10,STAINED_CLAY:15,10,STAINED_CLAY:9,100)
RandomBlock(8,3,8,CONCRETE:7,65,quark:iron_plate:0,10,quark:iron_plate:1,10,STAINED_CLAY:15,10,STAINED_CLAY:9,100)
RandomBlock(8,3,9,CONCRETE:7,65,quark:iron_plate:0,10,quark:iron_plate:1,10,STAINED_CLAY:15,10,STAINED_CLAY:9,100)
RandomBlock(8,4,1,CONCRETE:7,65,quark:iron_plate:0,10,quark:iron_plate:1,10,STAINED_CLAY:15,10,STAINED_CLAY:9,100)
RandomBlock(8,4,2,CONCRETE:7,65,quark:iron_plate:0,10,quark:iron_plate:1,10,STAINED_CLAY:15,10,STAINED_CLAY:9,100)
RandomBlock(8,4,8,CONCRETE:7,65,quark:iron_plate:0,10,quark:iron_plate:1,10,STAINED_CLAY:15,10,STAINED_CLAY:9,100)
RandomBlock(8,4,9,CONCRETE:7,65,quark:iron_plate:0,10,quark:iron_plate:1,10,STAINED_CLAY:15,10,STAINED_CLAY:9,100)
RandomBlock(8,5,1,CONCRETE:7,65,quark:iron_plate:0,10,quark:iron_plate:1,10,STAINED_CLAY:15,10,STAINED_CLAY:9,100)
RandomBlock(8,5,2,CONCRETE:7,65,quark:iron_plate:0,10,quark:iron_plate:1,10,STAINED_CLAY:15,10,STAINED_CLAY:9,100)
RandomBlock(8,5,8,CONCRETE:7,65,quark:iron_plate:0,10,quark:iron_plate:1,10,STAINED_CLAY:15,10,STAINED_CLAY:9,100)
RandomBlock(8,5,9,CONCRETE:7,65,quark:iron_plate:0,10,quark:iron_plate:1,10,STAINED_CLAY:15,10,STAINED_CLAY:9,100)
RandomBlock(8,6,1,CONCRETE:7,65,quark:iron_plate:0,10,quark:iron_plate:1,10,STAINED_CLAY:15,10,STAINED_CLAY:9,100)
RandomBlock(8,6,2,CONCRETE:7,65,quark:iron_plate:0,10,quark:iron_plate:1,10,STAINED_CLAY:15,10,STAINED_CLAY:9,100)
RandomBlock(8,6,8,CONCRETE:7,65,quark:iron_plate:0,10,quark:iron_plate:1,10,STAINED_CLAY:15,10,STAINED_CLAY:9,100)
RandomBlock(8,6,9,CONCRETE:7,65,quark:iron_plate:0,10,quark:iron_plate:1,10,STAINED_CLAY:15,10,STAINED_CLAY:9,100)
RandomBlock(8,7,1,CONCRETE:7,65,quark:iron_plate:0,10,quark:iron_plate:1,10,STAINED_CLAY:15,10,STAINED_CLAY:9,100)
RandomBlock(8,7,2,CONCRETE:7,65,quark:iron_plate:0,10,quark:iron_plate:1,10,STAINED_CLAY:15,10,STAINED_CLAY:9,100)
RandomBlock(8,7,8,CONCRETE:7,65,quark:iron_plate:0,10,quark:iron_plate:1,10,STAINED_CLAY:15,10,STAINED_CLAY:9,100)
RandomBlock(8,7,9,CONCRETE:7,65,quark:iron_plate:0,10,quark:iron_plate:1,10,STAINED_CLAY:15,10,STAINED_CLAY:9,100)
RandomBlock(8,8,1,CONCRETE:7,65,quark:iron_plate:0,10,quark:iron_plate:1,10,STAINED_CLAY:15,10,STAINED_CLAY:9,100)
RandomBlock(8,8,2,CONCRETE:7,65,quark:iron_plate:0,10,quark:iron_plate:1,10,STAINED_CLAY:15,10,STAINED_CLAY:9,100)
RandomBlock(8,8,8,CONCRETE:7,65,quark:iron_plate:0,10,quark:iron_plate:1,10,STAINED_CLAY:15,10,STAINED_CLAY:9,100)
RandomBlock(8,8,9,CONCRETE:7,65,quark:iron_plate:0,10,quark:iron_plate:1,10,STAINED_CLAY:15,10,STAINED_CLAY:9,100)
RandomBlock(8,9,1,CONCRETE:7,65,quark:iron_plate:0,10,quark:iron_plate:1,10,STAINED_CLAY:15,10,STAINED_CLAY:9,100)
RandomBlock(8,9,2,CONCRETE:7,65,quark:iron_plate:0,10,quark:iron_plate:1,10,STAINED_CLAY:15,10,STAINED_CLAY:9,100)
RandomBlock(8,9,4,CONCRETE:7,65,quark:iron_plate:0,10,quark:iron_plate:1,10,STAINED_CLAY:15,10,STAINED_CLAY:9,100)
RandomBlock(8,9,6,CONCRETE:7,65,quark:iron_plate:0,10,quark:iron_plate:1,10,STAINED_CLAY:15,10,STAINED_CLAY:9,100)
RandomBlock(8,9,8,CONCRETE:7,65,quark:iron_plate:0,10,quark:iron_plate:1,10,STAINED_CLAY:15,10,STAINED_CLAY:9,100)
RandomBlock(8,9,9,CONCRETE:7,65,quark:iron_plate:0,10,quark:iron_plate:1,10,STAINED_CLAY:15,10,STAINED_CLAY:9,100)
RandomBlock(8,10,1,CONCRETE:7,65,quark:iron_plate:0,10,quark:iron_plate:1,10,STAINED_CLAY:15,10,STAINED_CLAY:9,100)
RandomBlock(8,10,2,CONCRETE:7,65,quark:iron_plate:0,10,quark:iron_plate:1,10,STAINED_CLAY:15,10,STAINED_CLAY:9,100)
RandomBlock(8,10,4,CONCRETE:7,65,quark:iron_plate:0,10,quark:iron_plate:1,10,STAINED_CLAY:15,10,STAINED_CLAY:9,100)
RandomBlock(8,10,6,CONCRETE:7,65,quark:iron_plate:0,10,quark:iron_plate:1,10,STAINED_CLAY:15,10,STAINED_CLAY:9,100)
RandomBlock(8,10,8,CONCRETE:7,65,quark:iron_plate:0,10,quark:iron_plate:1,10,STAINED_CLAY:15,10,STAINED_CLAY:9,100)
RandomBlock(8,10,9,CONCRETE:7,65,quark:iron_plate:0,10,quark:iron_plate:1,10,STAINED_CLAY:15,10,STAINED_CLAY:9,100)
RandomBlock(8,11,1,CONCRETE:7,65,quark:iron_plate:0,10,quark:iron_plate:1,10,STAINED_CLAY:15,10,STAINED_CLAY:9,100)
RandomBlock(8,11,2,CONCRETE:7,65,quark:iron_plate:0,10,quark:iron_plate:1,10,STAINED_CLAY:15,10,STAINED_CLAY:9,100)
RandomBlock(8,11,4,CONCRETE:7,65,quark:iron_plate:0,10,quark:iron_plate:1,10,STAINED_CLAY:15,10,STAINED_CLAY:9,100)
RandomBlock(8,11,6,CONCRETE:7,65,quark:iron_plate:0,10,quark:iron_plate:1,10,STAINED_CLAY:15,10,STAINED_CLAY:9,100)
RandomBlock(8,11,8,CONCRETE:7,65,quark:iron_plate:0,10,quark:iron_plate:1,10,STAINED_CLAY:15,10,STAINED_CLAY:9,100)
RandomBlock(8,11,9,CONCRETE:7,65,quark:iron_plate:0,10,quark:iron_plate:1,10,STAINED_CLAY:15,10,STAINED_CLAY:9,100)
RandomBlock(8,12,1,CONCRETE:7,65,quark:iron_plate:0,10,quark:iron_plate:1,10,STAINED_CLAY:15,10,STAINED_CLAY:9,100)
RandomBlock(8,12,2,CONCRETE:7,65,quark:iron_plate:0,10,quark:iron_plate:1,10,STAINED_CLAY:15,10,STAINED_CLAY:9,100)
RandomBlock(8,12,4,CONCRETE:7,65,quark:iron_plate:0,10,quark:iron_plate:1,10,STAINED_CLAY:15,10,STAINED_CLAY:9,100)
RandomBlock(8,12,6,CONCRETE:7,65,quark:iron_plate:0,10,quark:iron_plate:1,10,STAINED_CLAY:15,10,STAINED_CLAY:9,100)
