
#######################################################################
# +-----------------------------------------------------------------+ #
# |                            BO4 object                           | #
# +-----------------------------------------------------------------+ #
#######################################################################

Author: NLBlackEagle

Description: No description given

SettingsMode: WriteWithoutComments


#######################################################################
# +-----------------------------------------------------------------+ #
# |                          Main settings                          | #
# +-----------------------------------------------------------------+ #
#######################################################################

FixedRotation: 

Frequency: 0

SpawnHeight: highestBlock

UseCenterForHighestBlock: true

##############################
# Height Limits for the BO4. #
##############################

MinHeight: 0

MaxHeight: 255

InheritBO3: 

InheritBO3Rotation: NORTH

OverrideChildSettings: true

OverrideParentHeight: false

CanOverride: true

BranchFrequency: 0

BranchFrequencyGroup: 

MustBeBelowOther: false

MustBeInside: 

CannotBeInside: 

ReplacesBO3: 

MustBeInsideWorldBorders: true
CanSpawnOnWater: false

SpawnOnWaterOnly: false

SpawnUnderWater: false

SpawnAtWaterLevel: false

HeightOffset: 0

RemoveAir: true

ReplaceAbove: 

ReplaceBelow: 

ReplaceWithBiomeBlocks: false

ReplaceWithSurfaceBlock: GRASS

ReplaceWithGroundBlock: DIRT

ReplaceWithStoneBlock: STONE

SmoothRadius: 0

SmoothHeightOffset: 0

SmoothStartTop: false

SmoothStartWood: false

SmoothingSurfaceBlock: 

SmoothingGroundBlock: 

BO3Group: 

IsSpawnPoint: false

DoReplaceBlocks: true


#######################################################################
# +-----------------------------------------------------------------+ #
# |                              Blocks                             | #
# +-----------------------------------------------------------------+ #
#######################################################################

RandomBlock(-8,0,-7,minecraft:concrete,40,SMOOTH_BRICK:1,30,SMOOTH_BRICK:2,30,SMOOTH_STAIRS:0,15,SMOOTH_STAIRS:1,15,SMOOTH_STAIRS:2,15,SMOOTH_STAIRS:3,15,STEP:5,15,STEP:13,15,COBBLE_WALL:0,10,COBBLESTONE_STAIRS:0,10,STEP:3,10,COBBLE_WALL:1,20,COBBLESTONE_STAIRS:2,20,COBBLESTONE_STAIRS:3,20,MOSSY_COBBLESTONE:0,60,COBBLESTONE_STAIRS:1,20,STEP:11,20,COBBLESTONE:0,100)
RandomBlock(-8,0,-6,minecraft:concrete,40,SMOOTH_BRICK:1,30,SMOOTH_BRICK:2,30,SMOOTH_STAIRS:0,15,SMOOTH_STAIRS:1,15,SMOOTH_STAIRS:2,15,SMOOTH_STAIRS:3,15,STEP:5,15,STEP:13,15,COBBLE_WALL:0,10,COBBLESTONE_STAIRS:0,10,STEP:3,10,COBBLE_WALL:1,20,COBBLESTONE_STAIRS:2,20,COBBLESTONE_STAIRS:3,20,MOSSY_COBBLESTONE:0,60,COBBLESTONE_STAIRS:1,20,STEP:11,20,COBBLESTONE:0,100)
RandomBlock(-8,0,-5,minecraft:concrete,40,SMOOTH_BRICK:1,30,SMOOTH_BRICK:2,30,SMOOTH_STAIRS:0,15,SMOOTH_STAIRS:1,15,SMOOTH_STAIRS:2,15,SMOOTH_STAIRS:3,15,STEP:5,15,STEP:13,15,COBBLE_WALL:0,10,COBBLESTONE_STAIRS:0,10,STEP:3,10,COBBLE_WALL:1,20,COBBLESTONE_STAIRS:2,20,COBBLESTONE_STAIRS:3,20,MOSSY_COBBLESTONE:0,60,COBBLESTONE_STAIRS:1,20,STEP:11,20,COBBLESTONE:0,100)
RandomBlock(-8,0,-4,minecraft:concrete,40,SMOOTH_BRICK:1,30,SMOOTH_BRICK:2,30,SMOOTH_STAIRS:0,15,SMOOTH_STAIRS:1,15,SMOOTH_STAIRS:2,15,SMOOTH_STAIRS:3,15,STEP:5,15,STEP:13,15,COBBLE_WALL:0,10,COBBLESTONE_STAIRS:0,10,STEP:3,10,COBBLE_WALL:1,20,COBBLESTONE_STAIRS:2,20,COBBLESTONE_STAIRS:3,20,MOSSY_COBBLESTONE:0,60,COBBLESTONE_STAIRS:1,20,STEP:11,20,COBBLESTONE:0,100)
RandomBlock(-8,0,-3,minecraft:concrete,40,SMOOTH_BRICK:1,30,SMOOTH_BRICK:2,30,SMOOTH_STAIRS:0,15,SMOOTH_STAIRS:1,15,SMOOTH_STAIRS:2,15,SMOOTH_STAIRS:3,15,STEP:5,15,STEP:13,15,COBBLE_WALL:0,10,COBBLESTONE_STAIRS:0,10,STEP:3,10,COBBLE_WALL:1,20,COBBLESTONE_STAIRS:2,20,COBBLESTONE_STAIRS:3,20,MOSSY_COBBLESTONE:0,60,COBBLESTONE_STAIRS:1,20,STEP:11,20,COBBLESTONE:0,100)
RandomBlock(-8,0,-2,minecraft:concrete,40,SMOOTH_BRICK:1,30,SMOOTH_BRICK:2,30,SMOOTH_STAIRS:0,15,SMOOTH_STAIRS:1,15,SMOOTH_STAIRS:2,15,SMOOTH_STAIRS:3,15,STEP:5,15,STEP:13,15,COBBLE_WALL:0,10,COBBLESTONE_STAIRS:0,10,STEP:3,10,COBBLE_WALL:1,20,COBBLESTONE_STAIRS:2,20,COBBLESTONE_STAIRS:3,20,MOSSY_COBBLESTONE:0,60,COBBLESTONE_STAIRS:1,20,STEP:11,20,COBBLESTONE:0,100)
RandomBlock(-8,1,-7,minecraft:concrete,40,SMOOTH_BRICK:1,30,SMOOTH_BRICK:2,30,SMOOTH_STAIRS:0,15,SMOOTH_STAIRS:1,15,SMOOTH_STAIRS:2,15,SMOOTH_STAIRS:3,15,STEP:5,15,STEP:13,15,COBBLE_WALL:0,10,COBBLESTONE_STAIRS:0,10,STEP:3,10,COBBLE_WALL:1,20,COBBLESTONE_STAIRS:2,20,COBBLESTONE_STAIRS:3,20,MOSSY_COBBLESTONE:0,60,COBBLESTONE_STAIRS:1,20,STEP:11,20,COBBLESTONE:0,100)
RandomBlock(-8,1,-6,minecraft:concrete,40,SMOOTH_BRICK:1,30,SMOOTH_BRICK:2,30,SMOOTH_STAIRS:0,15,SMOOTH_STAIRS:1,15,SMOOTH_STAIRS:2,15,SMOOTH_STAIRS:3,15,STEP:5,15,STEP:13,15,COBBLE_WALL:0,10,COBBLESTONE_STAIRS:0,10,STEP:3,10,COBBLE_WALL:1,20,COBBLESTONE_STAIRS:2,20,COBBLESTONE_STAIRS:3,20,MOSSY_COBBLESTONE:0,60,COBBLESTONE_STAIRS:1,20,STEP:11,20,COBBLESTONE:0,100)
RandomBlock(-8,1,-5,minecraft:concrete,40,SMOOTH_BRICK:1,30,SMOOTH_BRICK:2,30,SMOOTH_STAIRS:0,15,SMOOTH_STAIRS:1,15,SMOOTH_STAIRS:2,15,SMOOTH_STAIRS:3,15,STEP:5,15,STEP:13,15,COBBLE_WALL:0,10,COBBLESTONE_STAIRS:0,10,STEP:3,10,COBBLE_WALL:1,20,COBBLESTONE_STAIRS:2,20,COBBLESTONE_STAIRS:3,20,MOSSY_COBBLESTONE:0,60,COBBLESTONE_STAIRS:1,20,STEP:11,20,COBBLESTONE:0,100)
RandomBlock(-8,1,-4,minecraft:concrete,40,SMOOTH_BRICK:1,30,SMOOTH_BRICK:2,30,SMOOTH_STAIRS:0,15,SMOOTH_STAIRS:1,15,SMOOTH_STAIRS:2,15,SMOOTH_STAIRS:3,15,STEP:5,15,STEP:13,15,COBBLE_WALL:0,10,COBBLESTONE_STAIRS:0,10,STEP:3,10,COBBLE_WALL:1,20,COBBLESTONE_STAIRS:2,20,COBBLESTONE_STAIRS:3,20,MOSSY_COBBLESTONE:0,60,COBBLESTONE_STAIRS:1,20,STEP:11,20,COBBLESTONE:0,100)
RandomBlock(-8,1,-3,minecraft:concrete,40,SMOOTH_BRICK:1,30,SMOOTH_BRICK:2,30,SMOOTH_STAIRS:0,15,SMOOTH_STAIRS:1,15,SMOOTH_STAIRS:2,15,SMOOTH_STAIRS:3,15,STEP:5,15,STEP:13,15,COBBLE_WALL:0,10,COBBLESTONE_STAIRS:0,10,STEP:3,10,COBBLE_WALL:1,20,COBBLESTONE_STAIRS:2,20,COBBLESTONE_STAIRS:3,20,MOSSY_COBBLESTONE:0,60,COBBLESTONE_STAIRS:1,20,STEP:11,20,COBBLESTONE:0,100)
RandomBlock(-8,1,-2,minecraft:concrete,40,SMOOTH_BRICK:1,30,SMOOTH_BRICK:2,30,SMOOTH_STAIRS:0,15,SMOOTH_STAIRS:1,15,SMOOTH_STAIRS:2,15,SMOOTH_STAIRS:3,15,STEP:5,15,STEP:13,15,COBBLE_WALL:0,10,COBBLESTONE_STAIRS:0,10,STEP:3,10,COBBLE_WALL:1,20,COBBLESTONE_STAIRS:2,20,COBBLESTONE_STAIRS:3,20,MOSSY_COBBLESTONE:0,60,COBBLESTONE_STAIRS:1,20,STEP:11,20,COBBLESTONE:0,100)
RandomBlock(-8,2,-7,minecraft:concrete,40,SMOOTH_BRICK:1,30,SMOOTH_BRICK:2,30,SMOOTH_STAIRS:0,15,SMOOTH_STAIRS:1,15,SMOOTH_STAIRS:2,15,SMOOTH_STAIRS:3,15,STEP:5,15,STEP:13,15,COBBLE_WALL:0,10,COBBLESTONE_STAIRS:0,10,STEP:3,10,COBBLE_WALL:1,20,COBBLESTONE_STAIRS:2,20,COBBLESTONE_STAIRS:3,20,MOSSY_COBBLESTONE:0,60,COBBLESTONE_STAIRS:1,20,STEP:11,20,COBBLESTONE:0,100)
RandomBlock(-8,2,-6,minecraft:concrete,40,SMOOTH_BRICK:1,30,SMOOTH_BRICK:2,30,SMOOTH_STAIRS:0,15,SMOOTH_STAIRS:1,15,SMOOTH_STAIRS:2,15,SMOOTH_STAIRS:3,15,STEP:5,15,STEP:13,15,COBBLE_WALL:0,10,COBBLESTONE_STAIRS:0,10,STEP:3,10,COBBLE_WALL:1,20,COBBLESTONE_STAIRS:2,20,COBBLESTONE_STAIRS:3,20,MOSSY_COBBLESTONE:0,60,COBBLESTONE_STAIRS:1,20,STEP:11,20,COBBLESTONE:0,100)
RandomBlock(-8,2,-5,minecraft:concrete,40,SMOOTH_BRICK:1,30,SMOOTH_BRICK:2,30,SMOOTH_STAIRS:0,15,SMOOTH_STAIRS:1,15,SMOOTH_STAIRS:2,15,SMOOTH_STAIRS:3,15,STEP:5,15,STEP:13,15,COBBLE_WALL:0,10,COBBLESTONE_STAIRS:0,10,STEP:3,10,COBBLE_WALL:1,20,COBBLESTONE_STAIRS:2,20,COBBLESTONE_STAIRS:3,20,MOSSY_COBBLESTONE:0,60,COBBLESTONE_STAIRS:1,20,STEP:11,20,COBBLESTONE:0,100)
RandomBlock(-8,2,-4,minecraft:concrete,40,SMOOTH_BRICK:1,30,SMOOTH_BRICK:2,30,SMOOTH_STAIRS:0,15,SMOOTH_STAIRS:1,15,SMOOTH_STAIRS:2,15,SMOOTH_STAIRS:3,15,STEP:5,15,STEP:13,15,COBBLE_WALL:0,10,COBBLESTONE_STAIRS:0,10,STEP:3,10,COBBLE_WALL:1,20,COBBLESTONE_STAIRS:2,20,COBBLESTONE_STAIRS:3,20,MOSSY_COBBLESTONE:0,60,COBBLESTONE_STAIRS:1,20,STEP:11,20,COBBLESTONE:0,100)
RandomBlock(-8,2,-3,minecraft:concrete,40,SMOOTH_BRICK:1,30,SMOOTH_BRICK:2,30,SMOOTH_STAIRS:0,15,SMOOTH_STAIRS:1,15,SMOOTH_STAIRS:2,15,SMOOTH_STAIRS:3,15,STEP:5,15,STEP:13,15,COBBLE_WALL:0,10,COBBLESTONE_STAIRS:0,10,STEP:3,10,COBBLE_WALL:1,20,COBBLESTONE_STAIRS:2,20,COBBLESTONE_STAIRS:3,20,MOSSY_COBBLESTONE:0,60,COBBLESTONE_STAIRS:1,20,STEP:11,20,COBBLESTONE:0,100)
RandomBlock(-8,2,-2,minecraft:concrete,40,SMOOTH_BRICK:1,30,SMOOTH_BRICK:2,30,SMOOTH_STAIRS:0,15,SMOOTH_STAIRS:1,15,SMOOTH_STAIRS:2,15,SMOOTH_STAIRS:3,15,STEP:5,15,STEP:13,15,COBBLE_WALL:0,10,COBBLESTONE_STAIRS:0,10,STEP:3,10,COBBLE_WALL:1,20,COBBLESTONE_STAIRS:2,20,COBBLESTONE_STAIRS:3,20,MOSSY_COBBLESTONE:0,60,COBBLESTONE_STAIRS:1,20,STEP:11,20,COBBLESTONE:0,100)
RandomBlock(-8,3,-7,minecraft:concrete,40,SMOOTH_BRICK:1,30,SMOOTH_BRICK:2,30,SMOOTH_STAIRS:0,15,SMOOTH_STAIRS:1,15,SMOOTH_STAIRS:2,15,SMOOTH_STAIRS:3,15,STEP:5,15,STEP:13,15,COBBLE_WALL:0,10,COBBLESTONE_STAIRS:0,10,STEP:3,10,COBBLE_WALL:1,20,COBBLESTONE_STAIRS:2,20,COBBLESTONE_STAIRS:3,20,MOSSY_COBBLESTONE:0,60,COBBLESTONE_STAIRS:1,20,STEP:11,20,COBBLESTONE:0,100)
RandomBlock(-8,3,-6,minecraft:concrete,40,SMOOTH_BRICK:1,30,SMOOTH_BRICK:2,30,SMOOTH_STAIRS:0,15,SMOOTH_STAIRS:1,15,SMOOTH_STAIRS:2,15,SMOOTH_STAIRS:3,15,STEP:5,15,STEP:13,15,COBBLE_WALL:0,10,COBBLESTONE_STAIRS:0,10,STEP:3,10,COBBLE_WALL:1,20,COBBLESTONE_STAIRS:2,20,COBBLESTONE_STAIRS:3,20,MOSSY_COBBLESTONE:0,60,COBBLESTONE_STAIRS:1,20,STEP:11,20,COBBLESTONE:0,100)
RandomBlock(-8,3,-5,minecraft:concrete,40,SMOOTH_BRICK:1,30,SMOOTH_BRICK:2,30,SMOOTH_STAIRS:0,15,SMOOTH_STAIRS:1,15,SMOOTH_STAIRS:2,15,SMOOTH_STAIRS:3,15,STEP:5,15,STEP:13,15,COBBLE_WALL:0,10,COBBLESTONE_STAIRS:0,10,STEP:3,10,COBBLE_WALL:1,20,COBBLESTONE_STAIRS:2,20,COBBLESTONE_STAIRS:3,20,MOSSY_COBBLESTONE:0,60,COBBLESTONE_STAIRS:1,20,STEP:11,20,COBBLESTONE:0,100)
RandomBlock(-8,3,-4,minecraft:concrete,40,SMOOTH_BRICK:1,30,SMOOTH_BRICK:2,30,SMOOTH_STAIRS:0,15,SMOOTH_STAIRS:1,15,SMOOTH_STAIRS:2,15,SMOOTH_STAIRS:3,15,STEP:5,15,STEP:13,15,COBBLE_WALL:0,10,COBBLESTONE_STAIRS:0,10,STEP:3,10,COBBLE_WALL:1,20,COBBLESTONE_STAIRS:2,20,COBBLESTONE_STAIRS:3,20,MOSSY_COBBLESTONE:0,60,COBBLESTONE_STAIRS:1,20,STEP:11,20,COBBLESTONE:0,100)
RandomBlock(-8,3,-3,minecraft:concrete,40,SMOOTH_BRICK:1,30,SMOOTH_BRICK:2,30,SMOOTH_STAIRS:0,15,SMOOTH_STAIRS:1,15,SMOOTH_STAIRS:2,15,SMOOTH_STAIRS:3,15,STEP:5,15,STEP:13,15,COBBLE_WALL:0,10,COBBLESTONE_STAIRS:0,10,STEP:3,10,COBBLE_WALL:1,20,COBBLESTONE_STAIRS:2,20,COBBLESTONE_STAIRS:3,20,MOSSY_COBBLESTONE:0,60,COBBLESTONE_STAIRS:1,20,STEP:11,20,COBBLESTONE:0,100)
RandomBlock(-8,3,-2,minecraft:concrete,40,SMOOTH_BRICK:1,30,SMOOTH_BRICK:2,30,SMOOTH_STAIRS:0,15,SMOOTH_STAIRS:1,15,SMOOTH_STAIRS:2,15,SMOOTH_STAIRS:3,15,STEP:5,15,STEP:13,15,COBBLE_WALL:0,10,COBBLESTONE_STAIRS:0,10,STEP:3,10,COBBLE_WALL:1,20,COBBLESTONE_STAIRS:2,20,COBBLESTONE_STAIRS:3,20,MOSSY_COBBLESTONE:0,60,COBBLESTONE_STAIRS:1,20,STEP:11,20,COBBLESTONE:0,100)
RandomBlock(-8,4,-7,minecraft:concrete,40,SMOOTH_BRICK:1,30,SMOOTH_BRICK:2,30,SMOOTH_STAIRS:0,15,SMOOTH_STAIRS:1,15,SMOOTH_STAIRS:2,15,SMOOTH_STAIRS:3,15,STEP:5,15,STEP:13,15,COBBLE_WALL:0,10,COBBLESTONE_STAIRS:0,10,STEP:3,10,COBBLE_WALL:1,20,COBBLESTONE_STAIRS:2,20,COBBLESTONE_STAIRS:3,20,MOSSY_COBBLESTONE:0,60,COBBLESTONE_STAIRS:1,20,STEP:11,20,COBBLESTONE:0,100)
RandomBlock(-8,4,-6,minecraft:concrete,40,SMOOTH_BRICK:1,30,SMOOTH_BRICK:2,30,SMOOTH_STAIRS:0,15,SMOOTH_STAIRS:1,15,SMOOTH_STAIRS:2,15,SMOOTH_STAIRS:3,15,STEP:5,15,STEP:13,15,COBBLE_WALL:0,10,COBBLESTONE_STAIRS:0,10,STEP:3,10,COBBLE_WALL:1,20,COBBLESTONE_STAIRS:2,20,COBBLESTONE_STAIRS:3,20,MOSSY_COBBLESTONE:0,60,COBBLESTONE_STAIRS:1,20,STEP:11,20,COBBLESTONE:0,100)
RandomBlock(-8,4,-5,minecraft:concrete,40,SMOOTH_BRICK:1,30,SMOOTH_BRICK:2,30,SMOOTH_STAIRS:0,15,SMOOTH_STAIRS:1,15,SMOOTH_STAIRS:2,15,SMOOTH_STAIRS:3,15,STEP:5,15,STEP:13,15,COBBLE_WALL:0,10,COBBLESTONE_STAIRS:0,10,STEP:3,10,COBBLE_WALL:1,20,COBBLESTONE_STAIRS:2,20,COBBLESTONE_STAIRS:3,20,MOSSY_COBBLESTONE:0,60,COBBLESTONE_STAIRS:1,20,STEP:11,20,COBBLESTONE:0,100)
RandomBlock(-8,4,-4,minecraft:concrete,40,SMOOTH_BRICK:1,30,SMOOTH_BRICK:2,30,SMOOTH_STAIRS:0,15,SMOOTH_STAIRS:1,15,SMOOTH_STAIRS:2,15,SMOOTH_STAIRS:3,15,STEP:5,15,STEP:13,15,COBBLE_WALL:0,10,COBBLESTONE_STAIRS:0,10,STEP:3,10,COBBLE_WALL:1,20,COBBLESTONE_STAIRS:2,20,COBBLESTONE_STAIRS:3,20,MOSSY_COBBLESTONE:0,60,COBBLESTONE_STAIRS:1,20,STEP:11,20,COBBLESTONE:0,100)
RandomBlock(-8,4,-3,minecraft:concrete,40,SMOOTH_BRICK:1,30,SMOOTH_BRICK:2,30,SMOOTH_STAIRS:0,15,SMOOTH_STAIRS:1,15,SMOOTH_STAIRS:2,15,SMOOTH_STAIRS:3,15,STEP:5,15,STEP:13,15,COBBLE_WALL:0,10,COBBLESTONE_STAIRS:0,10,STEP:3,10,COBBLE_WALL:1,20,COBBLESTONE_STAIRS:2,20,COBBLESTONE_STAIRS:3,20,MOSSY_COBBLESTONE:0,60,COBBLESTONE_STAIRS:1,20,STEP:11,20,COBBLESTONE:0,100)
RandomBlock(-8,4,-2,minecraft:concrete,40,SMOOTH_BRICK:1,30,SMOOTH_BRICK:2,30,SMOOTH_STAIRS:0,15,SMOOTH_STAIRS:1,15,SMOOTH_STAIRS:2,15,SMOOTH_STAIRS:3,15,STEP:5,15,STEP:13,15,COBBLE_WALL:0,10,COBBLESTONE_STAIRS:0,10,STEP:3,10,COBBLE_WALL:1,20,COBBLESTONE_STAIRS:2,20,COBBLESTONE_STAIRS:3,20,MOSSY_COBBLESTONE:0,60,COBBLESTONE_STAIRS:1,20,STEP:11,20,COBBLESTONE:0,100)
RandomBlock(-8,5,-7,minecraft:concrete,40,SMOOTH_BRICK:1,30,SMOOTH_BRICK:2,30,SMOOTH_STAIRS:0,15,SMOOTH_STAIRS:1,15,SMOOTH_STAIRS:2,15,SMOOTH_STAIRS:3,15,STEP:5,15,STEP:13,15,COBBLE_WALL:0,10,COBBLESTONE_STAIRS:0,10,STEP:3,10,COBBLE_WALL:1,20,COBBLESTONE_STAIRS:2,20,COBBLESTONE_STAIRS:3,20,MOSSY_COBBLESTONE:0,60,COBBLESTONE_STAIRS:1,20,STEP:11,20,COBBLESTONE:0,100)
RandomBlock(-8,5,-6,minecraft:concrete,40,SMOOTH_BRICK:1,30,SMOOTH_BRICK:2,30,SMOOTH_STAIRS:0,15,SMOOTH_STAIRS:1,15,SMOOTH_STAIRS:2,15,SMOOTH_STAIRS:3,15,STEP:5,15,STEP:13,15,COBBLE_WALL:0,10,COBBLESTONE_STAIRS:0,10,STEP:3,10,COBBLE_WALL:1,20,COBBLESTONE_STAIRS:2,20,COBBLESTONE_STAIRS:3,20,MOSSY_COBBLESTONE:0,60,COBBLESTONE_STAIRS:1,20,STEP:11,20,COBBLESTONE:0,100)
RandomBlock(-8,5,-5,minecraft:concrete,40,SMOOTH_BRICK:1,30,SMOOTH_BRICK:2,30,SMOOTH_STAIRS:0,15,SMOOTH_STAIRS:1,15,SMOOTH_STAIRS:2,15,SMOOTH_STAIRS:3,15,STEP:5,15,STEP:13,15,COBBLE_WALL:0,10,COBBLESTONE_STAIRS:0,10,STEP:3,10,COBBLE_WALL:1,20,COBBLESTONE_STAIRS:2,20,COBBLESTONE_STAIRS:3,20,MOSSY_COBBLESTONE:0,60,COBBLESTONE_STAIRS:1,20,STEP:11,20,COBBLESTONE:0,100)
RandomBlock(-8,5,-4,minecraft:concrete,40,SMOOTH_BRICK:1,30,SMOOTH_BRICK:2,30,SMOOTH_STAIRS:0,15,SMOOTH_STAIRS:1,15,SMOOTH_STAIRS:2,15,SMOOTH_STAIRS:3,15,STEP:5,15,STEP:13,15,COBBLE_WALL:0,10,COBBLESTONE_STAIRS:0,10,STEP:3,10,COBBLE_WALL:1,20,COBBLESTONE_STAIRS:2,20,COBBLESTONE_STAIRS:3,20,MOSSY_COBBLESTONE:0,60,COBBLESTONE_STAIRS:1,20,STEP:11,20,COBBLESTONE:0,100)
RandomBlock(-8,5,-3,minecraft:concrete,40,SMOOTH_BRICK:1,30,SMOOTH_BRICK:2,30,SMOOTH_STAIRS:0,15,SMOOTH_STAIRS:1,15,SMOOTH_STAIRS:2,15,SMOOTH_STAIRS:3,15,STEP:5,15,STEP:13,15,COBBLE_WALL:0,10,COBBLESTONE_STAIRS:0,10,STEP:3,10,COBBLE_WALL:1,20,COBBLESTONE_STAIRS:2,20,COBBLESTONE_STAIRS:3,20,MOSSY_COBBLESTONE:0,60,COBBLESTONE_STAIRS:1,20,STEP:11,20,COBBLESTONE:0,100)
RandomBlock(-8,5,-2,minecraft:concrete,30,quark:limestone_wall,10,minecraft:concrete,100)
RandomBlock(-8,6,-7,minecraft:concrete,40,SMOOTH_BRICK:1,30,SMOOTH_BRICK:2,30,SMOOTH_STAIRS:0,15,SMOOTH_STAIRS:1,15,SMOOTH_STAIRS:2,15,SMOOTH_STAIRS:3,15,STEP:5,15,STEP:13,15,COBBLE_WALL:0,10,COBBLESTONE_STAIRS:0,10,STEP:3,10,COBBLE_WALL:1,20,COBBLESTONE_STAIRS:2,20,COBBLESTONE_STAIRS:3,20,MOSSY_COBBLESTONE:0,60,COBBLESTONE_STAIRS:1,20,STEP:11,20,COBBLESTONE:0,100)
RandomBlock(-8,6,-6,minecraft:concrete,40,SMOOTH_BRICK:1,30,SMOOTH_BRICK:2,30,SMOOTH_STAIRS:0,15,SMOOTH_STAIRS:1,15,SMOOTH_STAIRS:2,15,SMOOTH_STAIRS:3,15,STEP:5,15,STEP:13,15,COBBLE_WALL:0,10,COBBLESTONE_STAIRS:0,10,STEP:3,10,COBBLE_WALL:1,20,COBBLESTONE_STAIRS:2,20,COBBLESTONE_STAIRS:3,20,MOSSY_COBBLESTONE:0,60,COBBLESTONE_STAIRS:1,20,STEP:11,20,COBBLESTONE:0,100)
RandomBlock(-8,6,-5,minecraft:concrete,40,SMOOTH_BRICK:1,30,SMOOTH_BRICK:2,30,SMOOTH_STAIRS:0,15,SMOOTH_STAIRS:1,15,SMOOTH_STAIRS:2,15,SMOOTH_STAIRS:3,15,STEP:5,15,STEP:13,15,COBBLE_WALL:0,10,COBBLESTONE_STAIRS:0,10,STEP:3,10,COBBLE_WALL:1,20,COBBLESTONE_STAIRS:2,20,COBBLESTONE_STAIRS:3,20,MOSSY_COBBLESTONE:0,60,COBBLESTONE_STAIRS:1,20,STEP:11,20,COBBLESTONE:0,100)
RandomBlock(-8,6,-4,minecraft:concrete,40,SMOOTH_BRICK:1,30,SMOOTH_BRICK:2,30,SMOOTH_STAIRS:0,15,SMOOTH_STAIRS:1,15,SMOOTH_STAIRS:2,15,SMOOTH_STAIRS:3,15,STEP:5,15,STEP:13,15,COBBLE_WALL:0,10,COBBLESTONE_STAIRS:0,10,STEP:3,10,COBBLE_WALL:1,20,COBBLESTONE_STAIRS:2,20,COBBLESTONE_STAIRS:3,20,MOSSY_COBBLESTONE:0,60,COBBLESTONE_STAIRS:1,20,STEP:11,20,COBBLESTONE:0,100)
RandomBlock(-8,6,-3,minecraft:concrete,40,SMOOTH_BRICK:1,30,SMOOTH_BRICK:2,30,SMOOTH_STAIRS:0,15,SMOOTH_STAIRS:1,15,SMOOTH_STAIRS:2,15,SMOOTH_STAIRS:3,15,STEP:5,15,STEP:13,15,COBBLE_WALL:0,10,COBBLESTONE_STAIRS:0,10,STEP:3,10,COBBLE_WALL:1,20,COBBLESTONE_STAIRS:2,20,COBBLESTONE_STAIRS:3,20,MOSSY_COBBLESTONE:0,60,COBBLESTONE_STAIRS:1,20,STEP:11,20,COBBLESTONE:0,100)
RandomBlock(-8,6,-2,minecraft:concrete,30,quark:limestone_wall,10,minecraft:concrete,100)
RandomBlock(-8,7,-7,minecraft:concrete,40,SMOOTH_BRICK:1,30,SMOOTH_BRICK:2,30,SMOOTH_STAIRS:0,15,SMOOTH_STAIRS:1,15,SMOOTH_STAIRS:2,15,SMOOTH_STAIRS:3,15,STEP:5,15,STEP:13,15,COBBLE_WALL:0,10,COBBLESTONE_STAIRS:0,10,STEP:3,10,COBBLE_WALL:1,20,COBBLESTONE_STAIRS:2,20,COBBLESTONE_STAIRS:3,20,MOSSY_COBBLESTONE:0,60,COBBLESTONE_STAIRS:1,20,STEP:11,20,COBBLESTONE:0,100)
RandomBlock(-8,7,-6,minecraft:concrete,30,quark:limestone_wall,10,minecraft:concrete,100)
RandomBlock(-8,7,-5,minecraft:concrete,40,SMOOTH_BRICK:1,30,SMOOTH_BRICK:2,30,SMOOTH_STAIRS:0,15,SMOOTH_STAIRS:1,15,SMOOTH_STAIRS:2,15,SMOOTH_STAIRS:3,15,STEP:5,15,STEP:13,15,COBBLE_WALL:0,10,COBBLESTONE_STAIRS:0,10,STEP:3,10,COBBLE_WALL:1,20,COBBLESTONE_STAIRS:2,20,COBBLESTONE_STAIRS:3,20,MOSSY_COBBLESTONE:0,60,COBBLESTONE_STAIRS:1,20,STEP:11,20,COBBLESTONE:0,100)
RandomBlock(-8,7,-4,minecraft:concrete,40,SMOOTH_BRICK:1,30,SMOOTH_BRICK:2,30,SMOOTH_STAIRS:0,15,SMOOTH_STAIRS:1,15,SMOOTH_STAIRS:2,15,SMOOTH_STAIRS:3,15,STEP:5,15,STEP:13,15,COBBLE_WALL:0,10,COBBLESTONE_STAIRS:0,10,STEP:3,10,COBBLE_WALL:1,20,COBBLESTONE_STAIRS:2,20,COBBLESTONE_STAIRS:3,20,MOSSY_COBBLESTONE:0,60,COBBLESTONE_STAIRS:1,20,STEP:11,20,COBBLESTONE:0,100)
RandomBlock(-8,7,-3,minecraft:concrete,40,SMOOTH_BRICK:1,30,SMOOTH_BRICK:2,30,SMOOTH_STAIRS:0,15,SMOOTH_STAIRS:1,15,SMOOTH_STAIRS:2,15,SMOOTH_STAIRS:3,15,STEP:5,15,STEP:13,15,COBBLE_WALL:0,10,COBBLESTONE_STAIRS:0,10,STEP:3,10,COBBLE_WALL:1,20,COBBLESTONE_STAIRS:2,20,COBBLESTONE_STAIRS:3,20,MOSSY_COBBLESTONE:0,60,COBBLESTONE_STAIRS:1,20,STEP:11,20,COBBLESTONE:0,100)
RandomBlock(-8,7,-2,minecraft:concrete,30,quark:limestone_wall,10,minecraft:concrete,100)
RandomBlock(-8,8,-7,minecraft:concrete,30,quark:limestone_wall,10,minecraft:concrete,100)
RandomBlock(-8,8,-6,minecraft:concrete,30,quark:limestone_wall,10,minecraft:concrete,100)
RandomBlock(-8,8,-5,minecraft:concrete,30,quark:limestone_wall,10,minecraft:concrete,100)
RandomBlock(-8,8,-4,minecraft:concrete,30,quark:limestone_wall,10,minecraft:concrete,100)
RandomBlock(-8,8,-3,minecraft:iron_bars:0,30,minecraft:iron_bars:0,100)
RandomBlock(-8,9,-6,minecraft:concrete,30,quark:limestone_wall,10,minecraft:concrete,100)
RandomBlock(-8,9,-5,minecraft:concrete,30,quark:limestone_wall,10,minecraft:concrete,100)
RandomBlock(-8,10,-5,minecraft:concrete,30,quark:limestone_wall,10,minecraft:concrete,100)
RandomBlock(-8,11,-5,minecraft:iron_bars:0,30,minecraft:iron_bars:0,100)
RandomBlock(-8,12,-5,minecraft:iron_bars:0,30,minecraft:iron_bars:0,100)
RandomBlock(-7,0,-7,minecraft:concrete,40,SMOOTH_BRICK:1,30,SMOOTH_BRICK:2,30,SMOOTH_STAIRS:0,15,SMOOTH_STAIRS:1,15,SMOOTH_STAIRS:2,15,SMOOTH_STAIRS:3,15,STEP:5,15,STEP:13,15,COBBLE_WALL:0,10,COBBLESTONE_STAIRS:0,10,STEP:3,10,COBBLE_WALL:1,20,COBBLESTONE_STAIRS:2,20,COBBLESTONE_STAIRS:3,20,MOSSY_COBBLESTONE:0,60,COBBLESTONE_STAIRS:1,20,STEP:11,20,COBBLESTONE:0,100)
RandomBlock(-7,0,-6,minecraft:concrete,40,SMOOTH_BRICK:1,30,SMOOTH_BRICK:2,30,SMOOTH_STAIRS:0,15,SMOOTH_STAIRS:1,15,SMOOTH_STAIRS:2,15,SMOOTH_STAIRS:3,15,STEP:5,15,STEP:13,15,COBBLE_WALL:0,10,COBBLESTONE_STAIRS:0,10,STEP:3,10,COBBLE_WALL:1,20,COBBLESTONE_STAIRS:2,20,COBBLESTONE_STAIRS:3,20,MOSSY_COBBLESTONE:0,60,COBBLESTONE_STAIRS:1,20,STEP:11,20,COBBLESTONE:0,100)
RandomBlock(-7,0,-5,minecraft:concrete,40,SMOOTH_BRICK:1,30,SMOOTH_BRICK:2,30,SMOOTH_STAIRS:0,15,SMOOTH_STAIRS:1,15,SMOOTH_STAIRS:2,15,SMOOTH_STAIRS:3,15,STEP:5,15,STEP:13,15,COBBLE_WALL:0,10,COBBLESTONE_STAIRS:0,10,STEP:3,10,COBBLE_WALL:1,20,COBBLESTONE_STAIRS:2,20,COBBLESTONE_STAIRS:3,20,MOSSY_COBBLESTONE:0,60,COBBLESTONE_STAIRS:1,20,STEP:11,20,COBBLESTONE:0,100)
RandomBlock(-7,0,-4,minecraft:concrete,40,SMOOTH_BRICK:1,30,SMOOTH_BRICK:2,30,SMOOTH_STAIRS:0,15,SMOOTH_STAIRS:1,15,SMOOTH_STAIRS:2,15,SMOOTH_STAIRS:3,15,STEP:5,15,STEP:13,15,COBBLE_WALL:0,10,COBBLESTONE_STAIRS:0,10,STEP:3,10,COBBLE_WALL:1,20,COBBLESTONE_STAIRS:2,20,COBBLESTONE_STAIRS:3,20,MOSSY_COBBLESTONE:0,60,COBBLESTONE_STAIRS:1,20,STEP:11,20,COBBLESTONE:0,100)
RandomBlock(-7,0,-3,minecraft:concrete,40,SMOOTH_BRICK:1,30,SMOOTH_BRICK:2,30,SMOOTH_STAIRS:0,15,SMOOTH_STAIRS:1,15,SMOOTH_STAIRS:2,15,SMOOTH_STAIRS:3,15,STEP:5,15,STEP:13,15,COBBLE_WALL:0,10,COBBLESTONE_STAIRS:0,10,STEP:3,10,COBBLE_WALL:1,20,COBBLESTONE_STAIRS:2,20,COBBLESTONE_STAIRS:3,20,MOSSY_COBBLESTONE:0,60,COBBLESTONE_STAIRS:1,20,STEP:11,20,COBBLESTONE:0,100)
RandomBlock(-7,1,-7,minecraft:concrete,40,SMOOTH_BRICK:1,30,SMOOTH_BRICK:2,30,SMOOTH_STAIRS:0,15,SMOOTH_STAIRS:1,15,SMOOTH_STAIRS:2,15,SMOOTH_STAIRS:3,15,STEP:5,15,STEP:13,15,COBBLE_WALL:0,10,COBBLESTONE_STAIRS:0,10,STEP:3,10,COBBLE_WALL:1,20,COBBLESTONE_STAIRS:2,20,COBBLESTONE_STAIRS:3,20,MOSSY_COBBLESTONE:0,60,COBBLESTONE_STAIRS:1,20,STEP:11,20,COBBLESTONE:0,100)
RandomBlock(-7,1,-6,minecraft:concrete,40,SMOOTH_BRICK:1,30,SMOOTH_BRICK:2,30,SMOOTH_STAIRS:0,15,SMOOTH_STAIRS:1,15,SMOOTH_STAIRS:2,15,SMOOTH_STAIRS:3,15,STEP:5,15,STEP:13,15,COBBLE_WALL:0,10,COBBLESTONE_STAIRS:0,10,STEP:3,10,COBBLE_WALL:1,20,COBBLESTONE_STAIRS:2,20,COBBLESTONE_STAIRS:3,20,MOSSY_COBBLESTONE:0,60,COBBLESTONE_STAIRS:1,20,STEP:11,20,COBBLESTONE:0,100)
RandomBlock(-7,1,-5,minecraft:concrete,40,SMOOTH_BRICK:1,30,SMOOTH_BRICK:2,30,SMOOTH_STAIRS:0,15,SMOOTH_STAIRS:1,15,SMOOTH_STAIRS:2,15,SMOOTH_STAIRS:3,15,STEP:5,15,STEP:13,15,COBBLE_WALL:0,10,COBBLESTONE_STAIRS:0,10,STEP:3,10,COBBLE_WALL:1,20,COBBLESTONE_STAIRS:2,20,COBBLESTONE_STAIRS:3,20,MOSSY_COBBLESTONE:0,60,COBBLESTONE_STAIRS:1,20,STEP:11,20,COBBLESTONE:0,100)
RandomBlock(-7,1,-4,minecraft:concrete,40,SMOOTH_BRICK:1,30,SMOOTH_BRICK:2,30,SMOOTH_STAIRS:0,15,SMOOTH_STAIRS:1,15,SMOOTH_STAIRS:2,15,SMOOTH_STAIRS:3,15,STEP:5,15,STEP:13,15,COBBLE_WALL:0,10,COBBLESTONE_STAIRS:0,10,STEP:3,10,COBBLE_WALL:1,20,COBBLESTONE_STAIRS:2,20,COBBLESTONE_STAIRS:3,20,MOSSY_COBBLESTONE:0,60,COBBLESTONE_STAIRS:1,20,STEP:11,20,COBBLESTONE:0,100)
RandomBlock(-7,1,-3,minecraft:concrete,40,SMOOTH_BRICK:1,30,SMOOTH_BRICK:2,30,SMOOTH_STAIRS:0,15,SMOOTH_STAIRS:1,15,SMOOTH_STAIRS:2,15,SMOOTH_STAIRS:3,15,STEP:5,15,STEP:13,15,COBBLE_WALL:0,10,COBBLESTONE_STAIRS:0,10,STEP:3,10,COBBLE_WALL:1,20,COBBLESTONE_STAIRS:2,20,COBBLESTONE_STAIRS:3,20,MOSSY_COBBLESTONE:0,60,COBBLESTONE_STAIRS:1,20,STEP:11,20,COBBLESTONE:0,100)
RandomBlock(-7,2,-7,minecraft:concrete,40,SMOOTH_BRICK:1,30,SMOOTH_BRICK:2,30,SMOOTH_STAIRS:0,15,SMOOTH_STAIRS:1,15,SMOOTH_STAIRS:2,15,SMOOTH_STAIRS:3,15,STEP:5,15,STEP:13,15,COBBLE_WALL:0,10,COBBLESTONE_STAIRS:0,10,STEP:3,10,COBBLE_WALL:1,20,COBBLESTONE_STAIRS:2,20,COBBLESTONE_STAIRS:3,20,MOSSY_COBBLESTONE:0,60,COBBLESTONE_STAIRS:1,20,STEP:11,20,COBBLESTONE:0,100)
RandomBlock(-7,2,-6,minecraft:concrete,40,SMOOTH_BRICK:1,30,SMOOTH_BRICK:2,30,SMOOTH_STAIRS:0,15,SMOOTH_STAIRS:1,15,SMOOTH_STAIRS:2,15,SMOOTH_STAIRS:3,15,STEP:5,15,STEP:13,15,COBBLE_WALL:0,10,COBBLESTONE_STAIRS:0,10,STEP:3,10,COBBLE_WALL:1,20,COBBLESTONE_STAIRS:2,20,COBBLESTONE_STAIRS:3,20,MOSSY_COBBLESTONE:0,60,COBBLESTONE_STAIRS:1,20,STEP:11,20,COBBLESTONE:0,100)
RandomBlock(-7,2,-5,minecraft:concrete,40,SMOOTH_BRICK:1,30,SMOOTH_BRICK:2,30,SMOOTH_STAIRS:0,15,SMOOTH_STAIRS:1,15,SMOOTH_STAIRS:2,15,SMOOTH_STAIRS:3,15,STEP:5,15,STEP:13,15,COBBLE_WALL:0,10,COBBLESTONE_STAIRS:0,10,STEP:3,10,COBBLE_WALL:1,20,COBBLESTONE_STAIRS:2,20,COBBLESTONE_STAIRS:3,20,MOSSY_COBBLESTONE:0,60,COBBLESTONE_STAIRS:1,20,STEP:11,20,COBBLESTONE:0,100)
RandomBlock(-7,2,-4,minecraft:concrete,40,SMOOTH_BRICK:1,30,SMOOTH_BRICK:2,30,SMOOTH_STAIRS:0,15,SMOOTH_STAIRS:1,15,SMOOTH_STAIRS:2,15,SMOOTH_STAIRS:3,15,STEP:5,15,STEP:13,15,COBBLE_WALL:0,10,COBBLESTONE_STAIRS:0,10,STEP:3,10,COBBLE_WALL:1,20,COBBLESTONE_STAIRS:2,20,COBBLESTONE_STAIRS:3,20,MOSSY_COBBLESTONE:0,60,COBBLESTONE_STAIRS:1,20,STEP:11,20,COBBLESTONE:0,100)
RandomBlock(-7,2,-3,minecraft:concrete,40,SMOOTH_BRICK:1,30,SMOOTH_BRICK:2,30,SMOOTH_STAIRS:0,15,SMOOTH_STAIRS:1,15,SMOOTH_STAIRS:2,15,SMOOTH_STAIRS:3,15,STEP:5,15,STEP:13,15,COBBLE_WALL:0,10,COBBLESTONE_STAIRS:0,10,STEP:3,10,COBBLE_WALL:1,20,COBBLESTONE_STAIRS:2,20,COBBLESTONE_STAIRS:3,20,MOSSY_COBBLESTONE:0,60,COBBLESTONE_STAIRS:1,20,STEP:11,20,COBBLESTONE:0,100)
RandomBlock(-7,3,-7,minecraft:concrete,40,SMOOTH_BRICK:1,30,SMOOTH_BRICK:2,30,SMOOTH_STAIRS:0,15,SMOOTH_STAIRS:1,15,SMOOTH_STAIRS:2,15,SMOOTH_STAIRS:3,15,STEP:5,15,STEP:13,15,COBBLE_WALL:0,10,COBBLESTONE_STAIRS:0,10,STEP:3,10,COBBLE_WALL:1,20,COBBLESTONE_STAIRS:2,20,COBBLESTONE_STAIRS:3,20,MOSSY_COBBLESTONE:0,60,COBBLESTONE_STAIRS:1,20,STEP:11,20,COBBLESTONE:0,100)
RandomBlock(-7,3,-6,minecraft:concrete,40,SMOOTH_BRICK:1,30,SMOOTH_BRICK:2,30,SMOOTH_STAIRS:0,15,SMOOTH_STAIRS:1,15,SMOOTH_STAIRS:2,15,SMOOTH_STAIRS:3,15,STEP:5,15,STEP:13,15,COBBLE_WALL:0,10,COBBLESTONE_STAIRS:0,10,STEP:3,10,COBBLE_WALL:1,20,COBBLESTONE_STAIRS:2,20,COBBLESTONE_STAIRS:3,20,MOSSY_COBBLESTONE:0,60,COBBLESTONE_STAIRS:1,20,STEP:11,20,COBBLESTONE:0,100)
RandomBlock(-7,3,-5,minecraft:concrete,40,SMOOTH_BRICK:1,30,SMOOTH_BRICK:2,30,SMOOTH_STAIRS:0,15,SMOOTH_STAIRS:1,15,SMOOTH_STAIRS:2,15,SMOOTH_STAIRS:3,15,STEP:5,15,STEP:13,15,COBBLE_WALL:0,10,COBBLESTONE_STAIRS:0,10,STEP:3,10,COBBLE_WALL:1,20,COBBLESTONE_STAIRS:2,20,COBBLESTONE_STAIRS:3,20,MOSSY_COBBLESTONE:0,60,COBBLESTONE_STAIRS:1,20,STEP:11,20,COBBLESTONE:0,100)
RandomBlock(-7,3,-4,minecraft:concrete,40,SMOOTH_BRICK:1,30,SMOOTH_BRICK:2,30,SMOOTH_STAIRS:0,15,SMOOTH_STAIRS:1,15,SMOOTH_STAIRS:2,15,SMOOTH_STAIRS:3,15,STEP:5,15,STEP:13,15,COBBLE_WALL:0,10,COBBLESTONE_STAIRS:0,10,STEP:3,10,COBBLE_WALL:1,20,COBBLESTONE_STAIRS:2,20,COBBLESTONE_STAIRS:3,20,MOSSY_COBBLESTONE:0,60,COBBLESTONE_STAIRS:1,20,STEP:11,20,COBBLESTONE:0,100)
RandomBlock(-7,3,-3,minecraft:concrete,40,SMOOTH_BRICK:1,30,SMOOTH_BRICK:2,30,SMOOTH_STAIRS:0,15,SMOOTH_STAIRS:1,15,SMOOTH_STAIRS:2,15,SMOOTH_STAIRS:3,15,STEP:5,15,STEP:13,15,COBBLE_WALL:0,10,COBBLESTONE_STAIRS:0,10,STEP:3,10,COBBLE_WALL:1,20,COBBLESTONE_STAIRS:2,20,COBBLESTONE_STAIRS:3,20,MOSSY_COBBLESTONE:0,60,COBBLESTONE_STAIRS:1,20,STEP:11,20,COBBLESTONE:0,100)
RandomBlock(-7,4,-7,minecraft:concrete,40,SMOOTH_BRICK:1,30,SMOOTH_BRICK:2,30,SMOOTH_STAIRS:0,15,SMOOTH_STAIRS:1,15,SMOOTH_STAIRS:2,15,SMOOTH_STAIRS:3,15,STEP:5,15,STEP:13,15,COBBLE_WALL:0,10,COBBLESTONE_STAIRS:0,10,STEP:3,10,COBBLE_WALL:1,20,COBBLESTONE_STAIRS:2,20,COBBLESTONE_STAIRS:3,20,MOSSY_COBBLESTONE:0,60,COBBLESTONE_STAIRS:1,20,STEP:11,20,COBBLESTONE:0,100)
RandomBlock(-7,4,-6,minecraft:concrete,40,SMOOTH_BRICK:1,30,SMOOTH_BRICK:2,30,SMOOTH_STAIRS:0,15,SMOOTH_STAIRS:1,15,SMOOTH_STAIRS:2,15,SMOOTH_STAIRS:3,15,STEP:5,15,STEP:13,15,COBBLE_WALL:0,10,COBBLESTONE_STAIRS:0,10,STEP:3,10,COBBLE_WALL:1,20,COBBLESTONE_STAIRS:2,20,COBBLESTONE_STAIRS:3,20,MOSSY_COBBLESTONE:0,60,COBBLESTONE_STAIRS:1,20,STEP:11,20,COBBLESTONE:0,100)
RandomBlock(-7,4,-5,minecraft:concrete,40,SMOOTH_BRICK:1,30,SMOOTH_BRICK:2,30,SMOOTH_STAIRS:0,15,SMOOTH_STAIRS:1,15,SMOOTH_STAIRS:2,15,SMOOTH_STAIRS:3,15,STEP:5,15,STEP:13,15,COBBLE_WALL:0,10,COBBLESTONE_STAIRS:0,10,STEP:3,10,COBBLE_WALL:1,20,COBBLESTONE_STAIRS:2,20,COBBLESTONE_STAIRS:3,20,MOSSY_COBBLESTONE:0,60,COBBLESTONE_STAIRS:1,20,STEP:11,20,COBBLESTONE:0,100)
RandomBlock(-7,4,-4,minecraft:concrete,40,SMOOTH_BRICK:1,30,SMOOTH_BRICK:2,30,SMOOTH_STAIRS:0,15,SMOOTH_STAIRS:1,15,SMOOTH_STAIRS:2,15,SMOOTH_STAIRS:3,15,STEP:5,15,STEP:13,15,COBBLE_WALL:0,10,COBBLESTONE_STAIRS:0,10,STEP:3,10,COBBLE_WALL:1,20,COBBLESTONE_STAIRS:2,20,COBBLESTONE_STAIRS:3,20,MOSSY_COBBLESTONE:0,60,COBBLESTONE_STAIRS:1,20,STEP:11,20,COBBLESTONE:0,100)
RandomBlock(-7,4,-3,minecraft:concrete,40,SMOOTH_BRICK:1,30,SMOOTH_BRICK:2,30,SMOOTH_STAIRS:0,15,SMOOTH_STAIRS:1,15,SMOOTH_STAIRS:2,15,SMOOTH_STAIRS:3,15,STEP:5,15,STEP:13,15,COBBLE_WALL:0,10,COBBLESTONE_STAIRS:0,10,STEP:3,10,COBBLE_WALL:1,20,COBBLESTONE_STAIRS:2,20,COBBLESTONE_STAIRS:3,20,MOSSY_COBBLESTONE:0,60,COBBLESTONE_STAIRS:1,20,STEP:11,20,COBBLESTONE:0,100)
RandomBlock(-7,5,-7,minecraft:concrete,40,SMOOTH_BRICK:1,30,SMOOTH_BRICK:2,30,SMOOTH_STAIRS:0,15,SMOOTH_STAIRS:1,15,SMOOTH_STAIRS:2,15,SMOOTH_STAIRS:3,15,STEP:5,15,STEP:13,15,COBBLE_WALL:0,10,COBBLESTONE_STAIRS:0,10,STEP:3,10,COBBLE_WALL:1,20,COBBLESTONE_STAIRS:2,20,COBBLESTONE_STAIRS:3,20,MOSSY_COBBLESTONE:0,60,COBBLESTONE_STAIRS:1,20,STEP:11,20,COBBLESTONE:0,100)
RandomBlock(-7,5,-6,minecraft:concrete,40,SMOOTH_BRICK:1,30,SMOOTH_BRICK:2,30,SMOOTH_STAIRS:0,15,SMOOTH_STAIRS:1,15,SMOOTH_STAIRS:2,15,SMOOTH_STAIRS:3,15,STEP:5,15,STEP:13,15,COBBLE_WALL:0,10,COBBLESTONE_STAIRS:0,10,STEP:3,10,COBBLE_WALL:1,20,COBBLESTONE_STAIRS:2,20,COBBLESTONE_STAIRS:3,20,MOSSY_COBBLESTONE:0,60,COBBLESTONE_STAIRS:1,20,STEP:11,20,COBBLESTONE:0,100)
RandomBlock(-7,5,-5,minecraft:concrete,40,SMOOTH_BRICK:1,30,SMOOTH_BRICK:2,30,SMOOTH_STAIRS:0,15,SMOOTH_STAIRS:1,15,SMOOTH_STAIRS:2,15,SMOOTH_STAIRS:3,15,STEP:5,15,STEP:13,15,COBBLE_WALL:0,10,COBBLESTONE_STAIRS:0,10,STEP:3,10,COBBLE_WALL:1,20,COBBLESTONE_STAIRS:2,20,COBBLESTONE_STAIRS:3,20,MOSSY_COBBLESTONE:0,60,COBBLESTONE_STAIRS:1,20,STEP:11,20,COBBLESTONE:0,100)
RandomBlock(-7,5,-4,minecraft:concrete,40,SMOOTH_BRICK:1,30,SMOOTH_BRICK:2,30,SMOOTH_STAIRS:0,15,SMOOTH_STAIRS:1,15,SMOOTH_STAIRS:2,15,SMOOTH_STAIRS:3,15,STEP:5,15,STEP:13,15,COBBLE_WALL:0,10,COBBLESTONE_STAIRS:0,10,STEP:3,10,COBBLE_WALL:1,20,COBBLESTONE_STAIRS:2,20,COBBLESTONE_STAIRS:3,20,MOSSY_COBBLESTONE:0,60,COBBLESTONE_STAIRS:1,20,STEP:11,20,COBBLESTONE:0,100)
RandomBlock(-7,5,-3,minecraft:concrete,30,quark:limestone_wall,10,minecraft:concrete,100)
RandomBlock(-7,6,-7,minecraft:concrete,40,SMOOTH_BRICK:1,30,SMOOTH_BRICK:2,30,SMOOTH_STAIRS:0,15,SMOOTH_STAIRS:1,15,SMOOTH_STAIRS:2,15,SMOOTH_STAIRS:3,15,STEP:5,15,STEP:13,15,COBBLE_WALL:0,10,COBBLESTONE_STAIRS:0,10,STEP:3,10,COBBLE_WALL:1,20,COBBLESTONE_STAIRS:2,20,COBBLESTONE_STAIRS:3,20,MOSSY_COBBLESTONE:0,60,COBBLESTONE_STAIRS:1,20,STEP:11,20,COBBLESTONE:0,100)
RandomBlock(-7,6,-6,minecraft:concrete,40,SMOOTH_BRICK:1,30,SMOOTH_BRICK:2,30,SMOOTH_STAIRS:0,15,SMOOTH_STAIRS:1,15,SMOOTH_STAIRS:2,15,SMOOTH_STAIRS:3,15,STEP:5,15,STEP:13,15,COBBLE_WALL:0,10,COBBLESTONE_STAIRS:0,10,STEP:3,10,COBBLE_WALL:1,20,COBBLESTONE_STAIRS:2,20,COBBLESTONE_STAIRS:3,20,MOSSY_COBBLESTONE:0,60,COBBLESTONE_STAIRS:1,20,STEP:11,20,COBBLESTONE:0,100)
RandomBlock(-7,6,-5,minecraft:concrete,40,SMOOTH_BRICK:1,30,SMOOTH_BRICK:2,30,SMOOTH_STAIRS:0,15,SMOOTH_STAIRS:1,15,SMOOTH_STAIRS:2,15,SMOOTH_STAIRS:3,15,STEP:5,15,STEP:13,15,COBBLE_WALL:0,10,COBBLESTONE_STAIRS:0,10,STEP:3,10,COBBLE_WALL:1,20,COBBLESTONE_STAIRS:2,20,COBBLESTONE_STAIRS:3,20,MOSSY_COBBLESTONE:0,60,COBBLESTONE_STAIRS:1,20,STEP:11,20,COBBLESTONE:0,100)
RandomBlock(-7,6,-4,minecraft:concrete,40,SMOOTH_BRICK:1,30,SMOOTH_BRICK:2,30,SMOOTH_STAIRS:0,15,SMOOTH_STAIRS:1,15,SMOOTH_STAIRS:2,15,SMOOTH_STAIRS:3,15,STEP:5,15,STEP:13,15,COBBLE_WALL:0,10,COBBLESTONE_STAIRS:0,10,STEP:3,10,COBBLE_WALL:1,20,COBBLESTONE_STAIRS:2,20,COBBLESTONE_STAIRS:3,20,MOSSY_COBBLESTONE:0,60,COBBLESTONE_STAIRS:1,20,STEP:11,20,COBBLESTONE:0,100)
RandomBlock(-7,6,-3,minecraft:concrete,30,quark:limestone_wall,10,minecraft:concrete,100)
RandomBlock(-7,7,-7,minecraft:concrete,40,SMOOTH_BRICK:1,30,SMOOTH_BRICK:2,30,SMOOTH_STAIRS:0,15,SMOOTH_STAIRS:1,15,SMOOTH_STAIRS:2,15,SMOOTH_STAIRS:3,15,STEP:5,15,STEP:13,15,COBBLE_WALL:0,10,COBBLESTONE_STAIRS:0,10,STEP:3,10,COBBLE_WALL:1,20,COBBLESTONE_STAIRS:2,20,COBBLESTONE_STAIRS:3,20,MOSSY_COBBLESTONE:0,60,COBBLESTONE_STAIRS:1,20,STEP:11,20,COBBLESTONE:0,100)
RandomBlock(-7,7,-6,minecraft:concrete,40,SMOOTH_BRICK:1,30,SMOOTH_BRICK:2,30,SMOOTH_STAIRS:0,15,SMOOTH_STAIRS:1,15,SMOOTH_STAIRS:2,15,SMOOTH_STAIRS:3,15,STEP:5,15,STEP:13,15,COBBLE_WALL:0,10,COBBLESTONE_STAIRS:0,10,STEP:3,10,COBBLE_WALL:1,20,COBBLESTONE_STAIRS:2,20,COBBLESTONE_STAIRS:3,20,MOSSY_COBBLESTONE:0,60,COBBLESTONE_STAIRS:1,20,STEP:11,20,COBBLESTONE:0,100)
RandomBlock(-7,7,-5,minecraft:concrete,40,SMOOTH_BRICK:1,30,SMOOTH_BRICK:2,30,SMOOTH_STAIRS:0,15,SMOOTH_STAIRS:1,15,SMOOTH_STAIRS:2,15,SMOOTH_STAIRS:3,15,STEP:5,15,STEP:13,15,COBBLE_WALL:0,10,COBBLESTONE_STAIRS:0,10,STEP:3,10,COBBLE_WALL:1,20,COBBLESTONE_STAIRS:2,20,COBBLESTONE_STAIRS:3,20,MOSSY_COBBLESTONE:0,60,COBBLESTONE_STAIRS:1,20,STEP:11,20,COBBLESTONE:0,100)
RandomBlock(-7,7,-4,minecraft:concrete,40,SMOOTH_BRICK:1,30,SMOOTH_BRICK:2,30,SMOOTH_STAIRS:0,15,SMOOTH_STAIRS:1,15,SMOOTH_STAIRS:2,15,SMOOTH_STAIRS:3,15,STEP:5,15,STEP:13,15,COBBLE_WALL:0,10,COBBLESTONE_STAIRS:0,10,STEP:3,10,COBBLE_WALL:1,20,COBBLESTONE_STAIRS:2,20,COBBLESTONE_STAIRS:3,20,MOSSY_COBBLESTONE:0,60,COBBLESTONE_STAIRS:1,20,STEP:11,20,COBBLESTONE:0,100)
RandomBlock(-7,7,-3,minecraft:concrete,30,quark:limestone_wall,10,minecraft:concrete,100)
RandomBlock(-7,8,-7,minecraft:concrete,30,quark:limestone_wall,10,minecraft:concrete,100)
RandomBlock(-7,8,-6,minecraft:concrete,30,quark:limestone_wall,10,minecraft:concrete,100)
RandomBlock(-7,8,-5,minecraft:concrete,30,quark:limestone_wall,10,minecraft:concrete,100)
RandomBlock(-7,9,-6,minecraft:concrete,30,quark:limestone_wall,10,minecraft:concrete,100)
RandomBlock(-7,9,-5,minecraft:concrete,30,quark:limestone_wall,10,minecraft:concrete,100)
RandomBlock(-6,0,-7,minecraft:concrete,40,SMOOTH_BRICK:1,30,SMOOTH_BRICK:2,30,SMOOTH_STAIRS:0,15,SMOOTH_STAIRS:1,15,SMOOTH_STAIRS:2,15,SMOOTH_STAIRS:3,15,STEP:5,15,STEP:13,15,COBBLE_WALL:0,10,COBBLESTONE_STAIRS:0,10,STEP:3,10,COBBLE_WALL:1,20,COBBLESTONE_STAIRS:2,20,COBBLESTONE_STAIRS:3,20,MOSSY_COBBLESTONE:0,60,COBBLESTONE_STAIRS:1,20,STEP:11,20,COBBLESTONE:0,100)
RandomBlock(-6,0,-6,minecraft:concrete,40,SMOOTH_BRICK:1,30,SMOOTH_BRICK:2,30,SMOOTH_STAIRS:0,15,SMOOTH_STAIRS:1,15,SMOOTH_STAIRS:2,15,SMOOTH_STAIRS:3,15,STEP:5,15,STEP:13,15,COBBLE_WALL:0,10,COBBLESTONE_STAIRS:0,10,STEP:3,10,COBBLE_WALL:1,20,COBBLESTONE_STAIRS:2,20,COBBLESTONE_STAIRS:3,20,MOSSY_COBBLESTONE:0,60,COBBLESTONE_STAIRS:1,20,STEP:11,20,COBBLESTONE:0,100)
RandomBlock(-6,0,-5,minecraft:concrete,40,SMOOTH_BRICK:1,30,SMOOTH_BRICK:2,30,SMOOTH_STAIRS:0,15,SMOOTH_STAIRS:1,15,SMOOTH_STAIRS:2,15,SMOOTH_STAIRS:3,15,STEP:5,15,STEP:13,15,COBBLE_WALL:0,10,COBBLESTONE_STAIRS:0,10,STEP:3,10,COBBLE_WALL:1,20,COBBLESTONE_STAIRS:2,20,COBBLESTONE_STAIRS:3,20,MOSSY_COBBLESTONE:0,60,COBBLESTONE_STAIRS:1,20,STEP:11,20,COBBLESTONE:0,100)
RandomBlock(-6,0,-4,minecraft:concrete,40,SMOOTH_BRICK:1,30,SMOOTH_BRICK:2,30,SMOOTH_STAIRS:0,15,SMOOTH_STAIRS:1,15,SMOOTH_STAIRS:2,15,SMOOTH_STAIRS:3,15,STEP:5,15,STEP:13,15,COBBLE_WALL:0,10,COBBLESTONE_STAIRS:0,10,STEP:3,10,COBBLE_WALL:1,20,COBBLESTONE_STAIRS:2,20,COBBLESTONE_STAIRS:3,20,MOSSY_COBBLESTONE:0,60,COBBLESTONE_STAIRS:1,20,STEP:11,20,COBBLESTONE:0,100)
RandomBlock(-6,0,-3,minecraft:concrete,40,SMOOTH_BRICK:1,30,SMOOTH_BRICK:2,30,SMOOTH_STAIRS:0,15,SMOOTH_STAIRS:1,15,SMOOTH_STAIRS:2,15,SMOOTH_STAIRS:3,15,STEP:5,15,STEP:13,15,COBBLE_WALL:0,10,COBBLESTONE_STAIRS:0,10,STEP:3,10,COBBLE_WALL:1,20,COBBLESTONE_STAIRS:2,20,COBBLESTONE_STAIRS:3,20,MOSSY_COBBLESTONE:0,60,COBBLESTONE_STAIRS:1,20,STEP:11,20,COBBLESTONE:0,100)
RandomBlock(-6,1,-7,minecraft:concrete,40,SMOOTH_BRICK:1,30,SMOOTH_BRICK:2,30,SMOOTH_STAIRS:0,15,SMOOTH_STAIRS:1,15,SMOOTH_STAIRS:2,15,SMOOTH_STAIRS:3,15,STEP:5,15,STEP:13,15,COBBLE_WALL:0,10,COBBLESTONE_STAIRS:0,10,STEP:3,10,COBBLE_WALL:1,20,COBBLESTONE_STAIRS:2,20,COBBLESTONE_STAIRS:3,20,MOSSY_COBBLESTONE:0,60,COBBLESTONE_STAIRS:1,20,STEP:11,20,COBBLESTONE:0,100)
RandomBlock(-6,1,-6,minecraft:concrete,40,SMOOTH_BRICK:1,30,SMOOTH_BRICK:2,30,SMOOTH_STAIRS:0,15,SMOOTH_STAIRS:1,15,SMOOTH_STAIRS:2,15,SMOOTH_STAIRS:3,15,STEP:5,15,STEP:13,15,COBBLE_WALL:0,10,COBBLESTONE_STAIRS:0,10,STEP:3,10,COBBLE_WALL:1,20,COBBLESTONE_STAIRS:2,20,COBBLESTONE_STAIRS:3,20,MOSSY_COBBLESTONE:0,60,COBBLESTONE_STAIRS:1,20,STEP:11,20,COBBLESTONE:0,100)
RandomBlock(-6,1,-5,minecraft:concrete,40,SMOOTH_BRICK:1,30,SMOOTH_BRICK:2,30,SMOOTH_STAIRS:0,15,SMOOTH_STAIRS:1,15,SMOOTH_STAIRS:2,15,SMOOTH_STAIRS:3,15,STEP:5,15,STEP:13,15,COBBLE_WALL:0,10,COBBLESTONE_STAIRS:0,10,STEP:3,10,COBBLE_WALL:1,20,COBBLESTONE_STAIRS:2,20,COBBLESTONE_STAIRS:3,20,MOSSY_COBBLESTONE:0,60,COBBLESTONE_STAIRS:1,20,STEP:11,20,COBBLESTONE:0,100)
RandomBlock(-6,1,-4,minecraft:concrete,40,SMOOTH_BRICK:1,30,SMOOTH_BRICK:2,30,SMOOTH_STAIRS:0,15,SMOOTH_STAIRS:1,15,SMOOTH_STAIRS:2,15,SMOOTH_STAIRS:3,15,STEP:5,15,STEP:13,15,COBBLE_WALL:0,10,COBBLESTONE_STAIRS:0,10,STEP:3,10,COBBLE_WALL:1,20,COBBLESTONE_STAIRS:2,20,COBBLESTONE_STAIRS:3,20,MOSSY_COBBLESTONE:0,60,COBBLESTONE_STAIRS:1,20,STEP:11,20,COBBLESTONE:0,100)
RandomBlock(-6,1,-3,minecraft:concrete,40,SMOOTH_BRICK:1,30,SMOOTH_BRICK:2,30,SMOOTH_STAIRS:0,15,SMOOTH_STAIRS:1,15,SMOOTH_STAIRS:2,15,SMOOTH_STAIRS:3,15,STEP:5,15,STEP:13,15,COBBLE_WALL:0,10,COBBLESTONE_STAIRS:0,10,STEP:3,10,COBBLE_WALL:1,20,COBBLESTONE_STAIRS:2,20,COBBLESTONE_STAIRS:3,20,MOSSY_COBBLESTONE:0,60,COBBLESTONE_STAIRS:1,20,STEP:11,20,COBBLESTONE:0,100)
RandomBlock(-6,2,-7,minecraft:concrete,40,SMOOTH_BRICK:1,30,SMOOTH_BRICK:2,30,SMOOTH_STAIRS:0,15,SMOOTH_STAIRS:1,15,SMOOTH_STAIRS:2,15,SMOOTH_STAIRS:3,15,STEP:5,15,STEP:13,15,COBBLE_WALL:0,10,COBBLESTONE_STAIRS:0,10,STEP:3,10,COBBLE_WALL:1,20,COBBLESTONE_STAIRS:2,20,COBBLESTONE_STAIRS:3,20,MOSSY_COBBLESTONE:0,60,COBBLESTONE_STAIRS:1,20,STEP:11,20,COBBLESTONE:0,100)
RandomBlock(-6,2,-6,minecraft:concrete,40,SMOOTH_BRICK:1,30,SMOOTH_BRICK:2,30,SMOOTH_STAIRS:0,15,SMOOTH_STAIRS:1,15,SMOOTH_STAIRS:2,15,SMOOTH_STAIRS:3,15,STEP:5,15,STEP:13,15,COBBLE_WALL:0,10,COBBLESTONE_STAIRS:0,10,STEP:3,10,COBBLE_WALL:1,20,COBBLESTONE_STAIRS:2,20,COBBLESTONE_STAIRS:3,20,MOSSY_COBBLESTONE:0,60,COBBLESTONE_STAIRS:1,20,STEP:11,20,COBBLESTONE:0,100)
RandomBlock(-6,2,-5,minecraft:concrete,40,SMOOTH_BRICK:1,30,SMOOTH_BRICK:2,30,SMOOTH_STAIRS:0,15,SMOOTH_STAIRS:1,15,SMOOTH_STAIRS:2,15,SMOOTH_STAIRS:3,15,STEP:5,15,STEP:13,15,COBBLE_WALL:0,10,COBBLESTONE_STAIRS:0,10,STEP:3,10,COBBLE_WALL:1,20,COBBLESTONE_STAIRS:2,20,COBBLESTONE_STAIRS:3,20,MOSSY_COBBLESTONE:0,60,COBBLESTONE_STAIRS:1,20,STEP:11,20,COBBLESTONE:0,100)
RandomBlock(-6,2,-4,minecraft:concrete,40,SMOOTH_BRICK:1,30,SMOOTH_BRICK:2,30,SMOOTH_STAIRS:0,15,SMOOTH_STAIRS:1,15,SMOOTH_STAIRS:2,15,SMOOTH_STAIRS:3,15,STEP:5,15,STEP:13,15,COBBLE_WALL:0,10,COBBLESTONE_STAIRS:0,10,STEP:3,10,COBBLE_WALL:1,20,COBBLESTONE_STAIRS:2,20,COBBLESTONE_STAIRS:3,20,MOSSY_COBBLESTONE:0,60,COBBLESTONE_STAIRS:1,20,STEP:11,20,COBBLESTONE:0,100)
RandomBlock(-6,2,-3,minecraft:concrete,40,SMOOTH_BRICK:1,30,SMOOTH_BRICK:2,30,SMOOTH_STAIRS:0,15,SMOOTH_STAIRS:1,15,SMOOTH_STAIRS:2,15,SMOOTH_STAIRS:3,15,STEP:5,15,STEP:13,15,COBBLE_WALL:0,10,COBBLESTONE_STAIRS:0,10,STEP:3,10,COBBLE_WALL:1,20,COBBLESTONE_STAIRS:2,20,COBBLESTONE_STAIRS:3,20,MOSSY_COBBLESTONE:0,60,COBBLESTONE_STAIRS:1,20,STEP:11,20,COBBLESTONE:0,100)
RandomBlock(-6,3,-7,minecraft:concrete,40,SMOOTH_BRICK:1,30,SMOOTH_BRICK:2,30,SMOOTH_STAIRS:0,15,SMOOTH_STAIRS:1,15,SMOOTH_STAIRS:2,15,SMOOTH_STAIRS:3,15,STEP:5,15,STEP:13,15,COBBLE_WALL:0,10,COBBLESTONE_STAIRS:0,10,STEP:3,10,COBBLE_WALL:1,20,COBBLESTONE_STAIRS:2,20,COBBLESTONE_STAIRS:3,20,MOSSY_COBBLESTONE:0,60,COBBLESTONE_STAIRS:1,20,STEP:11,20,COBBLESTONE:0,100)
RandomBlock(-6,3,-6,minecraft:concrete,40,SMOOTH_BRICK:1,30,SMOOTH_BRICK:2,30,SMOOTH_STAIRS:0,15,SMOOTH_STAIRS:1,15,SMOOTH_STAIRS:2,15,SMOOTH_STAIRS:3,15,STEP:5,15,STEP:13,15,COBBLE_WALL:0,10,COBBLESTONE_STAIRS:0,10,STEP:3,10,COBBLE_WALL:1,20,COBBLESTONE_STAIRS:2,20,COBBLESTONE_STAIRS:3,20,MOSSY_COBBLESTONE:0,60,COBBLESTONE_STAIRS:1,20,STEP:11,20,COBBLESTONE:0,100)
RandomBlock(-6,3,-5,minecraft:concrete,40,SMOOTH_BRICK:1,30,SMOOTH_BRICK:2,30,SMOOTH_STAIRS:0,15,SMOOTH_STAIRS:1,15,SMOOTH_STAIRS:2,15,SMOOTH_STAIRS:3,15,STEP:5,15,STEP:13,15,COBBLE_WALL:0,10,COBBLESTONE_STAIRS:0,10,STEP:3,10,COBBLE_WALL:1,20,COBBLESTONE_STAIRS:2,20,COBBLESTONE_STAIRS:3,20,MOSSY_COBBLESTONE:0,60,COBBLESTONE_STAIRS:1,20,STEP:11,20,COBBLESTONE:0,100)
RandomBlock(-6,3,-4,minecraft:concrete,40,SMOOTH_BRICK:1,30,SMOOTH_BRICK:2,30,SMOOTH_STAIRS:0,15,SMOOTH_STAIRS:1,15,SMOOTH_STAIRS:2,15,SMOOTH_STAIRS:3,15,STEP:5,15,STEP:13,15,COBBLE_WALL:0,10,COBBLESTONE_STAIRS:0,10,STEP:3,10,COBBLE_WALL:1,20,COBBLESTONE_STAIRS:2,20,COBBLESTONE_STAIRS:3,20,MOSSY_COBBLESTONE:0,60,COBBLESTONE_STAIRS:1,20,STEP:11,20,COBBLESTONE:0,100)
RandomBlock(-6,3,-3,minecraft:concrete,40,SMOOTH_BRICK:1,30,SMOOTH_BRICK:2,30,SMOOTH_STAIRS:0,15,SMOOTH_STAIRS:1,15,SMOOTH_STAIRS:2,15,SMOOTH_STAIRS:3,15,STEP:5,15,STEP:13,15,COBBLE_WALL:0,10,COBBLESTONE_STAIRS:0,10,STEP:3,10,COBBLE_WALL:1,20,COBBLESTONE_STAIRS:2,20,COBBLESTONE_STAIRS:3,20,MOSSY_COBBLESTONE:0,60,COBBLESTONE_STAIRS:1,20,STEP:11,20,COBBLESTONE:0,100)
RandomBlock(-6,4,-7,minecraft:concrete,40,SMOOTH_BRICK:1,30,SMOOTH_BRICK:2,30,SMOOTH_STAIRS:0,15,SMOOTH_STAIRS:1,15,SMOOTH_STAIRS:2,15,SMOOTH_STAIRS:3,15,STEP:5,15,STEP:13,15,COBBLE_WALL:0,10,COBBLESTONE_STAIRS:0,10,STEP:3,10,COBBLE_WALL:1,20,COBBLESTONE_STAIRS:2,20,COBBLESTONE_STAIRS:3,20,MOSSY_COBBLESTONE:0,60,COBBLESTONE_STAIRS:1,20,STEP:11,20,COBBLESTONE:0,100)
RandomBlock(-6,4,-6,minecraft:concrete,40,SMOOTH_BRICK:1,30,SMOOTH_BRICK:2,30,SMOOTH_STAIRS:0,15,SMOOTH_STAIRS:1,15,SMOOTH_STAIRS:2,15,SMOOTH_STAIRS:3,15,STEP:5,15,STEP:13,15,COBBLE_WALL:0,10,COBBLESTONE_STAIRS:0,10,STEP:3,10,COBBLE_WALL:1,20,COBBLESTONE_STAIRS:2,20,COBBLESTONE_STAIRS:3,20,MOSSY_COBBLESTONE:0,60,COBBLESTONE_STAIRS:1,20,STEP:11,20,COBBLESTONE:0,100)
RandomBlock(-6,4,-5,minecraft:concrete,40,SMOOTH_BRICK:1,30,SMOOTH_BRICK:2,30,SMOOTH_STAIRS:0,15,SMOOTH_STAIRS:1,15,SMOOTH_STAIRS:2,15,SMOOTH_STAIRS:3,15,STEP:5,15,STEP:13,15,COBBLE_WALL:0,10,COBBLESTONE_STAIRS:0,10,STEP:3,10,COBBLE_WALL:1,20,COBBLESTONE_STAIRS:2,20,COBBLESTONE_STAIRS:3,20,MOSSY_COBBLESTONE:0,60,COBBLESTONE_STAIRS:1,20,STEP:11,20,COBBLESTONE:0,100)
RandomBlock(-6,4,-4,minecraft:concrete,40,SMOOTH_BRICK:1,30,SMOOTH_BRICK:2,30,SMOOTH_STAIRS:0,15,SMOOTH_STAIRS:1,15,SMOOTH_STAIRS:2,15,SMOOTH_STAIRS:3,15,STEP:5,15,STEP:13,15,COBBLE_WALL:0,10,COBBLESTONE_STAIRS:0,10,STEP:3,10,COBBLE_WALL:1,20,COBBLESTONE_STAIRS:2,20,COBBLESTONE_STAIRS:3,20,MOSSY_COBBLESTONE:0,60,COBBLESTONE_STAIRS:1,20,STEP:11,20,COBBLESTONE:0,100)
RandomBlock(-6,4,-3,minecraft:concrete,40,SMOOTH_BRICK:1,30,SMOOTH_BRICK:2,30,SMOOTH_STAIRS:0,15,SMOOTH_STAIRS:1,15,SMOOTH_STAIRS:2,15,SMOOTH_STAIRS:3,15,STEP:5,15,STEP:13,15,COBBLE_WALL:0,10,COBBLESTONE_STAIRS:0,10,STEP:3,10,COBBLE_WALL:1,20,COBBLESTONE_STAIRS:2,20,COBBLESTONE_STAIRS:3,20,MOSSY_COBBLESTONE:0,60,COBBLESTONE_STAIRS:1,20,STEP:11,20,COBBLESTONE:0,100)
RandomBlock(-6,5,-7,minecraft:concrete,40,SMOOTH_BRICK:1,30,SMOOTH_BRICK:2,30,SMOOTH_STAIRS:0,15,SMOOTH_STAIRS:1,15,SMOOTH_STAIRS:2,15,SMOOTH_STAIRS:3,15,STEP:5,15,STEP:13,15,COBBLE_WALL:0,10,COBBLESTONE_STAIRS:0,10,STEP:3,10,COBBLE_WALL:1,20,COBBLESTONE_STAIRS:2,20,COBBLESTONE_STAIRS:3,20,MOSSY_COBBLESTONE:0,60,COBBLESTONE_STAIRS:1,20,STEP:11,20,COBBLESTONE:0,100)
RandomBlock(-6,5,-6,minecraft:concrete,40,SMOOTH_BRICK:1,30,SMOOTH_BRICK:2,30,SMOOTH_STAIRS:0,15,SMOOTH_STAIRS:1,15,SMOOTH_STAIRS:2,15,SMOOTH_STAIRS:3,15,STEP:5,15,STEP:13,15,COBBLE_WALL:0,10,COBBLESTONE_STAIRS:0,10,STEP:3,10,COBBLE_WALL:1,20,COBBLESTONE_STAIRS:2,20,COBBLESTONE_STAIRS:3,20,MOSSY_COBBLESTONE:0,60,COBBLESTONE_STAIRS:1,20,STEP:11,20,COBBLESTONE:0,100)
RandomBlock(-6,5,-5,minecraft:concrete,40,SMOOTH_BRICK:1,30,SMOOTH_BRICK:2,30,SMOOTH_STAIRS:0,15,SMOOTH_STAIRS:1,15,SMOOTH_STAIRS:2,15,SMOOTH_STAIRS:3,15,STEP:5,15,STEP:13,15,COBBLE_WALL:0,10,COBBLESTONE_STAIRS:0,10,STEP:3,10,COBBLE_WALL:1,20,COBBLESTONE_STAIRS:2,20,COBBLESTONE_STAIRS:3,20,MOSSY_COBBLESTONE:0,60,COBBLESTONE_STAIRS:1,20,STEP:11,20,COBBLESTONE:0,100)
RandomBlock(-6,5,-4,minecraft:concrete,40,SMOOTH_BRICK:1,30,SMOOTH_BRICK:2,30,SMOOTH_STAIRS:0,15,SMOOTH_STAIRS:1,15,SMOOTH_STAIRS:2,15,SMOOTH_STAIRS:3,15,STEP:5,15,STEP:13,15,COBBLE_WALL:0,10,COBBLESTONE_STAIRS:0,10,STEP:3,10,COBBLE_WALL:1,20,COBBLESTONE_STAIRS:2,20,COBBLESTONE_STAIRS:3,20,MOSSY_COBBLESTONE:0,60,COBBLESTONE_STAIRS:1,20,STEP:11,20,COBBLESTONE:0,100)
RandomBlock(-6,5,-3,minecraft:concrete,30,quark:limestone_wall,10,minecraft:concrete,100)
RandomBlock(-6,6,-7,minecraft:concrete,40,SMOOTH_BRICK:1,30,SMOOTH_BRICK:2,30,SMOOTH_STAIRS:0,15,SMOOTH_STAIRS:1,15,SMOOTH_STAIRS:2,15,SMOOTH_STAIRS:3,15,STEP:5,15,STEP:13,15,COBBLE_WALL:0,10,COBBLESTONE_STAIRS:0,10,STEP:3,10,COBBLE_WALL:1,20,COBBLESTONE_STAIRS:2,20,COBBLESTONE_STAIRS:3,20,MOSSY_COBBLESTONE:0,60,COBBLESTONE_STAIRS:1,20,STEP:11,20,COBBLESTONE:0,100)
RandomBlock(-6,6,-6,minecraft:concrete,40,SMOOTH_BRICK:1,30,SMOOTH_BRICK:2,30,SMOOTH_STAIRS:0,15,SMOOTH_STAIRS:1,15,SMOOTH_STAIRS:2,15,SMOOTH_STAIRS:3,15,STEP:5,15,STEP:13,15,COBBLE_WALL:0,10,COBBLESTONE_STAIRS:0,10,STEP:3,10,COBBLE_WALL:1,20,COBBLESTONE_STAIRS:2,20,COBBLESTONE_STAIRS:3,20,MOSSY_COBBLESTONE:0,60,COBBLESTONE_STAIRS:1,20,STEP:11,20,COBBLESTONE:0,100)
RandomBlock(-6,6,-5,minecraft:concrete,40,SMOOTH_BRICK:1,30,SMOOTH_BRICK:2,30,SMOOTH_STAIRS:0,15,SMOOTH_STAIRS:1,15,SMOOTH_STAIRS:2,15,SMOOTH_STAIRS:3,15,STEP:5,15,STEP:13,15,COBBLE_WALL:0,10,COBBLESTONE_STAIRS:0,10,STEP:3,10,COBBLE_WALL:1,20,COBBLESTONE_STAIRS:2,20,COBBLESTONE_STAIRS:3,20,MOSSY_COBBLESTONE:0,60,COBBLESTONE_STAIRS:1,20,STEP:11,20,COBBLESTONE:0,100)
RandomBlock(-6,6,-4,minecraft:concrete,40,SMOOTH_BRICK:1,30,SMOOTH_BRICK:2,30,SMOOTH_STAIRS:0,15,SMOOTH_STAIRS:1,15,SMOOTH_STAIRS:2,15,SMOOTH_STAIRS:3,15,STEP:5,15,STEP:13,15,COBBLE_WALL:0,10,COBBLESTONE_STAIRS:0,10,STEP:3,10,COBBLE_WALL:1,20,COBBLESTONE_STAIRS:2,20,COBBLESTONE_STAIRS:3,20,MOSSY_COBBLESTONE:0,60,COBBLESTONE_STAIRS:1,20,STEP:11,20,COBBLESTONE:0,100)
RandomBlock(-6,6,-3,minecraft:concrete,30,quark:limestone_wall,10,minecraft:concrete,100)
RandomBlock(-6,7,-7,minecraft:concrete,40,SMOOTH_BRICK:1,30,SMOOTH_BRICK:2,30,SMOOTH_STAIRS:0,15,SMOOTH_STAIRS:1,15,SMOOTH_STAIRS:2,15,SMOOTH_STAIRS:3,15,STEP:5,15,STEP:13,15,COBBLE_WALL:0,10,COBBLESTONE_STAIRS:0,10,STEP:3,10,COBBLE_WALL:1,20,COBBLESTONE_STAIRS:2,20,COBBLESTONE_STAIRS:3,20,MOSSY_COBBLESTONE:0,60,COBBLESTONE_STAIRS:1,20,STEP:11,20,COBBLESTONE:0,100)
RandomBlock(-6,7,-6,minecraft:concrete,40,SMOOTH_BRICK:1,30,SMOOTH_BRICK:2,30,SMOOTH_STAIRS:0,15,SMOOTH_STAIRS:1,15,SMOOTH_STAIRS:2,15,SMOOTH_STAIRS:3,15,STEP:5,15,STEP:13,15,COBBLE_WALL:0,10,COBBLESTONE_STAIRS:0,10,STEP:3,10,COBBLE_WALL:1,20,COBBLESTONE_STAIRS:2,20,COBBLESTONE_STAIRS:3,20,MOSSY_COBBLESTONE:0,60,COBBLESTONE_STAIRS:1,20,STEP:11,20,COBBLESTONE:0,100)
RandomBlock(-6,7,-5,minecraft:concrete,40,SMOOTH_BRICK:1,30,SMOOTH_BRICK:2,30,SMOOTH_STAIRS:0,15,SMOOTH_STAIRS:1,15,SMOOTH_STAIRS:2,15,SMOOTH_STAIRS:3,15,STEP:5,15,STEP:13,15,COBBLE_WALL:0,10,COBBLESTONE_STAIRS:0,10,STEP:3,10,COBBLE_WALL:1,20,COBBLESTONE_STAIRS:2,20,COBBLESTONE_STAIRS:3,20,MOSSY_COBBLESTONE:0,60,COBBLESTONE_STAIRS:1,20,STEP:11,20,COBBLESTONE:0,100)
RandomBlock(-6,7,-4,minecraft:concrete,40,SMOOTH_BRICK:1,30,SMOOTH_BRICK:2,30,SMOOTH_STAIRS:0,15,SMOOTH_STAIRS:1,15,SMOOTH_STAIRS:2,15,SMOOTH_STAIRS:3,15,STEP:5,15,STEP:13,15,COBBLE_WALL:0,10,COBBLESTONE_STAIRS:0,10,STEP:3,10,COBBLE_WALL:1,20,COBBLESTONE_STAIRS:2,20,COBBLESTONE_STAIRS:3,20,MOSSY_COBBLESTONE:0,60,COBBLESTONE_STAIRS:1,20,STEP:11,20,COBBLESTONE:0,100)
RandomBlock(-6,7,-3,minecraft:concrete,30,quark:limestone_wall,10,minecraft:concrete,100)
RandomBlock(-6,8,-7,minecraft:concrete,30,quark:limestone_wall,10,minecraft:concrete,100)
RandomBlock(-6,8,-6,minecraft:concrete,30,quark:limestone_wall,10,minecraft:concrete,100)
RandomBlock(-6,8,-4,minecraft:concrete,30,quark:limestone_wall,10,minecraft:concrete,100)
RandomBlock(-6,9,-7,minecraft:concrete,30,quark:limestone_wall,10,minecraft:concrete,100)
RandomBlock(-5,0,-7,minecraft:concrete,40,SMOOTH_BRICK:1,30,SMOOTH_BRICK:2,30,SMOOTH_STAIRS:0,15,SMOOTH_STAIRS:1,15,SMOOTH_STAIRS:2,15,SMOOTH_STAIRS:3,15,STEP:5,15,STEP:13,15,COBBLE_WALL:0,10,COBBLESTONE_STAIRS:0,10,STEP:3,10,COBBLE_WALL:1,20,COBBLESTONE_STAIRS:2,20,COBBLESTONE_STAIRS:3,20,MOSSY_COBBLESTONE:0,60,COBBLESTONE_STAIRS:1,20,STEP:11,20,COBBLESTONE:0,100)
RandomBlock(-5,0,-6,minecraft:concrete,40,SMOOTH_BRICK:1,30,SMOOTH_BRICK:2,30,SMOOTH_STAIRS:0,15,SMOOTH_STAIRS:1,15,SMOOTH_STAIRS:2,15,SMOOTH_STAIRS:3,15,STEP:5,15,STEP:13,15,COBBLE_WALL:0,10,COBBLESTONE_STAIRS:0,10,STEP:3,10,COBBLE_WALL:1,20,COBBLESTONE_STAIRS:2,20,COBBLESTONE_STAIRS:3,20,MOSSY_COBBLESTONE:0,60,COBBLESTONE_STAIRS:1,20,STEP:11,20,COBBLESTONE:0,100)
RandomBlock(-5,0,-5,minecraft:concrete,40,SMOOTH_BRICK:1,30,SMOOTH_BRICK:2,30,SMOOTH_STAIRS:0,15,SMOOTH_STAIRS:1,15,SMOOTH_STAIRS:2,15,SMOOTH_STAIRS:3,15,STEP:5,15,STEP:13,15,COBBLE_WALL:0,10,COBBLESTONE_STAIRS:0,10,STEP:3,10,COBBLE_WALL:1,20,COBBLESTONE_STAIRS:2,20,COBBLESTONE_STAIRS:3,20,MOSSY_COBBLESTONE:0,60,COBBLESTONE_STAIRS:1,20,STEP:11,20,COBBLESTONE:0,100)
RandomBlock(-5,0,-4,minecraft:concrete,40,SMOOTH_BRICK:1,30,SMOOTH_BRICK:2,30,SMOOTH_STAIRS:0,15,SMOOTH_STAIRS:1,15,SMOOTH_STAIRS:2,15,SMOOTH_STAIRS:3,15,STEP:5,15,STEP:13,15,COBBLE_WALL:0,10,COBBLESTONE_STAIRS:0,10,STEP:3,10,COBBLE_WALL:1,20,COBBLESTONE_STAIRS:2,20,COBBLESTONE_STAIRS:3,20,MOSSY_COBBLESTONE:0,60,COBBLESTONE_STAIRS:1,20,STEP:11,20,COBBLESTONE:0,100)
RandomBlock(-5,1,-7,minecraft:concrete,40,SMOOTH_BRICK:1,30,SMOOTH_BRICK:2,30,SMOOTH_STAIRS:0,15,SMOOTH_STAIRS:1,15,SMOOTH_STAIRS:2,15,SMOOTH_STAIRS:3,15,STEP:5,15,STEP:13,15,COBBLE_WALL:0,10,COBBLESTONE_STAIRS:0,10,STEP:3,10,COBBLE_WALL:1,20,COBBLESTONE_STAIRS:2,20,COBBLESTONE_STAIRS:3,20,MOSSY_COBBLESTONE:0,60,COBBLESTONE_STAIRS:1,20,STEP:11,20,COBBLESTONE:0,100)
RandomBlock(-5,1,-6,minecraft:concrete,40,SMOOTH_BRICK:1,30,SMOOTH_BRICK:2,30,SMOOTH_STAIRS:0,15,SMOOTH_STAIRS:1,15,SMOOTH_STAIRS:2,15,SMOOTH_STAIRS:3,15,STEP:5,15,STEP:13,15,COBBLE_WALL:0,10,COBBLESTONE_STAIRS:0,10,STEP:3,10,COBBLE_WALL:1,20,COBBLESTONE_STAIRS:2,20,COBBLESTONE_STAIRS:3,20,MOSSY_COBBLESTONE:0,60,COBBLESTONE_STAIRS:1,20,STEP:11,20,COBBLESTONE:0,100)
RandomBlock(-5,1,-5,minecraft:concrete,40,SMOOTH_BRICK:1,30,SMOOTH_BRICK:2,30,SMOOTH_STAIRS:0,15,SMOOTH_STAIRS:1,15,SMOOTH_STAIRS:2,15,SMOOTH_STAIRS:3,15,STEP:5,15,STEP:13,15,COBBLE_WALL:0,10,COBBLESTONE_STAIRS:0,10,STEP:3,10,COBBLE_WALL:1,20,COBBLESTONE_STAIRS:2,20,COBBLESTONE_STAIRS:3,20,MOSSY_COBBLESTONE:0,60,COBBLESTONE_STAIRS:1,20,STEP:11,20,COBBLESTONE:0,100)
RandomBlock(-5,1,-4,minecraft:concrete,40,SMOOTH_BRICK:1,30,SMOOTH_BRICK:2,30,SMOOTH_STAIRS:0,15,SMOOTH_STAIRS:1,15,SMOOTH_STAIRS:2,15,SMOOTH_STAIRS:3,15,STEP:5,15,STEP:13,15,COBBLE_WALL:0,10,COBBLESTONE_STAIRS:0,10,STEP:3,10,COBBLE_WALL:1,20,COBBLESTONE_STAIRS:2,20,COBBLESTONE_STAIRS:3,20,MOSSY_COBBLESTONE:0,60,COBBLESTONE_STAIRS:1,20,STEP:11,20,COBBLESTONE:0,100)
RandomBlock(-5,2,-7,minecraft:concrete,40,SMOOTH_BRICK:1,30,SMOOTH_BRICK:2,30,SMOOTH_STAIRS:0,15,SMOOTH_STAIRS:1,15,SMOOTH_STAIRS:2,15,SMOOTH_STAIRS:3,15,STEP:5,15,STEP:13,15,COBBLE_WALL:0,10,COBBLESTONE_STAIRS:0,10,STEP:3,10,COBBLE_WALL:1,20,COBBLESTONE_STAIRS:2,20,COBBLESTONE_STAIRS:3,20,MOSSY_COBBLESTONE:0,60,COBBLESTONE_STAIRS:1,20,STEP:11,20,COBBLESTONE:0,100)
RandomBlock(-5,2,-6,minecraft:concrete,40,SMOOTH_BRICK:1,30,SMOOTH_BRICK:2,30,SMOOTH_STAIRS:0,15,SMOOTH_STAIRS:1,15,SMOOTH_STAIRS:2,15,SMOOTH_STAIRS:3,15,STEP:5,15,STEP:13,15,COBBLE_WALL:0,10,COBBLESTONE_STAIRS:0,10,STEP:3,10,COBBLE_WALL:1,20,COBBLESTONE_STAIRS:2,20,COBBLESTONE_STAIRS:3,20,MOSSY_COBBLESTONE:0,60,COBBLESTONE_STAIRS:1,20,STEP:11,20,COBBLESTONE:0,100)
RandomBlock(-5,2,-5,minecraft:concrete,40,SMOOTH_BRICK:1,30,SMOOTH_BRICK:2,30,SMOOTH_STAIRS:0,15,SMOOTH_STAIRS:1,15,SMOOTH_STAIRS:2,15,SMOOTH_STAIRS:3,15,STEP:5,15,STEP:13,15,COBBLE_WALL:0,10,COBBLESTONE_STAIRS:0,10,STEP:3,10,COBBLE_WALL:1,20,COBBLESTONE_STAIRS:2,20,COBBLESTONE_STAIRS:3,20,MOSSY_COBBLESTONE:0,60,COBBLESTONE_STAIRS:1,20,STEP:11,20,COBBLESTONE:0,100)
RandomBlock(-5,2,-4,minecraft:concrete,40,SMOOTH_BRICK:1,30,SMOOTH_BRICK:2,30,SMOOTH_STAIRS:0,15,SMOOTH_STAIRS:1,15,SMOOTH_STAIRS:2,15,SMOOTH_STAIRS:3,15,STEP:5,15,STEP:13,15,COBBLE_WALL:0,10,COBBLESTONE_STAIRS:0,10,STEP:3,10,COBBLE_WALL:1,20,COBBLESTONE_STAIRS:2,20,COBBLESTONE_STAIRS:3,20,MOSSY_COBBLESTONE:0,60,COBBLESTONE_STAIRS:1,20,STEP:11,20,COBBLESTONE:0,100)
RandomBlock(-5,3,-7,minecraft:concrete,40,SMOOTH_BRICK:1,30,SMOOTH_BRICK:2,30,SMOOTH_STAIRS:0,15,SMOOTH_STAIRS:1,15,SMOOTH_STAIRS:2,15,SMOOTH_STAIRS:3,15,STEP:5,15,STEP:13,15,COBBLE_WALL:0,10,COBBLESTONE_STAIRS:0,10,STEP:3,10,COBBLE_WALL:1,20,COBBLESTONE_STAIRS:2,20,COBBLESTONE_STAIRS:3,20,MOSSY_COBBLESTONE:0,60,COBBLESTONE_STAIRS:1,20,STEP:11,20,COBBLESTONE:0,100)
RandomBlock(-5,3,-6,minecraft:concrete,40,SMOOTH_BRICK:1,30,SMOOTH_BRICK:2,30,SMOOTH_STAIRS:0,15,SMOOTH_STAIRS:1,15,SMOOTH_STAIRS:2,15,SMOOTH_STAIRS:3,15,STEP:5,15,STEP:13,15,COBBLE_WALL:0,10,COBBLESTONE_STAIRS:0,10,STEP:3,10,COBBLE_WALL:1,20,COBBLESTONE_STAIRS:2,20,COBBLESTONE_STAIRS:3,20,MOSSY_COBBLESTONE:0,60,COBBLESTONE_STAIRS:1,20,STEP:11,20,COBBLESTONE:0,100)
RandomBlock(-5,3,-5,minecraft:concrete,40,SMOOTH_BRICK:1,30,SMOOTH_BRICK:2,30,SMOOTH_STAIRS:0,15,SMOOTH_STAIRS:1,15,SMOOTH_STAIRS:2,15,SMOOTH_STAIRS:3,15,STEP:5,15,STEP:13,15,COBBLE_WALL:0,10,COBBLESTONE_STAIRS:0,10,STEP:3,10,COBBLE_WALL:1,20,COBBLESTONE_STAIRS:2,20,COBBLESTONE_STAIRS:3,20,MOSSY_COBBLESTONE:0,60,COBBLESTONE_STAIRS:1,20,STEP:11,20,COBBLESTONE:0,100)
RandomBlock(-5,3,-4,minecraft:concrete,40,SMOOTH_BRICK:1,30,SMOOTH_BRICK:2,30,SMOOTH_STAIRS:0,15,SMOOTH_STAIRS:1,15,SMOOTH_STAIRS:2,15,SMOOTH_STAIRS:3,15,STEP:5,15,STEP:13,15,COBBLE_WALL:0,10,COBBLESTONE_STAIRS:0,10,STEP:3,10,COBBLE_WALL:1,20,COBBLESTONE_STAIRS:2,20,COBBLESTONE_STAIRS:3,20,MOSSY_COBBLESTONE:0,60,COBBLESTONE_STAIRS:1,20,STEP:11,20,COBBLESTONE:0,100)
RandomBlock(-5,4,-7,minecraft:concrete,40,SMOOTH_BRICK:1,30,SMOOTH_BRICK:2,30,SMOOTH_STAIRS:0,15,SMOOTH_STAIRS:1,15,SMOOTH_STAIRS:2,15,SMOOTH_STAIRS:3,15,STEP:5,15,STEP:13,15,COBBLE_WALL:0,10,COBBLESTONE_STAIRS:0,10,STEP:3,10,COBBLE_WALL:1,20,COBBLESTONE_STAIRS:2,20,COBBLESTONE_STAIRS:3,20,MOSSY_COBBLESTONE:0,60,COBBLESTONE_STAIRS:1,20,STEP:11,20,COBBLESTONE:0,100)
RandomBlock(-5,4,-6,minecraft:concrete,40,SMOOTH_BRICK:1,30,SMOOTH_BRICK:2,30,SMOOTH_STAIRS:0,15,SMOOTH_STAIRS:1,15,SMOOTH_STAIRS:2,15,SMOOTH_STAIRS:3,15,STEP:5,15,STEP:13,15,COBBLE_WALL:0,10,COBBLESTONE_STAIRS:0,10,STEP:3,10,COBBLE_WALL:1,20,COBBLESTONE_STAIRS:2,20,COBBLESTONE_STAIRS:3,20,MOSSY_COBBLESTONE:0,60,COBBLESTONE_STAIRS:1,20,STEP:11,20,COBBLESTONE:0,100)
RandomBlock(-5,4,-5,minecraft:concrete,40,SMOOTH_BRICK:1,30,SMOOTH_BRICK:2,30,SMOOTH_STAIRS:0,15,SMOOTH_STAIRS:1,15,SMOOTH_STAIRS:2,15,SMOOTH_STAIRS:3,15,STEP:5,15,STEP:13,15,COBBLE_WALL:0,10,COBBLESTONE_STAIRS:0,10,STEP:3,10,COBBLE_WALL:1,20,COBBLESTONE_STAIRS:2,20,COBBLESTONE_STAIRS:3,20,MOSSY_COBBLESTONE:0,60,COBBLESTONE_STAIRS:1,20,STEP:11,20,COBBLESTONE:0,100)
RandomBlock(-5,4,-4,minecraft:concrete,40,SMOOTH_BRICK:1,30,SMOOTH_BRICK:2,30,SMOOTH_STAIRS:0,15,SMOOTH_STAIRS:1,15,SMOOTH_STAIRS:2,15,SMOOTH_STAIRS:3,15,STEP:5,15,STEP:13,15,COBBLE_WALL:0,10,COBBLESTONE_STAIRS:0,10,STEP:3,10,COBBLE_WALL:1,20,COBBLESTONE_STAIRS:2,20,COBBLESTONE_STAIRS:3,20,MOSSY_COBBLESTONE:0,60,COBBLESTONE_STAIRS:1,20,STEP:11,20,COBBLESTONE:0,100)
RandomBlock(-5,5,-7,minecraft:concrete,40,SMOOTH_BRICK:1,30,SMOOTH_BRICK:2,30,SMOOTH_STAIRS:0,15,SMOOTH_STAIRS:1,15,SMOOTH_STAIRS:2,15,SMOOTH_STAIRS:3,15,STEP:5,15,STEP:13,15,COBBLE_WALL:0,10,COBBLESTONE_STAIRS:0,10,STEP:3,10,COBBLE_WALL:1,20,COBBLESTONE_STAIRS:2,20,COBBLESTONE_STAIRS:3,20,MOSSY_COBBLESTONE:0,60,COBBLESTONE_STAIRS:1,20,STEP:11,20,COBBLESTONE:0,100)
RandomBlock(-5,5,-6,minecraft:concrete,40,SMOOTH_BRICK:1,30,SMOOTH_BRICK:2,30,SMOOTH_STAIRS:0,15,SMOOTH_STAIRS:1,15,SMOOTH_STAIRS:2,15,SMOOTH_STAIRS:3,15,STEP:5,15,STEP:13,15,COBBLE_WALL:0,10,COBBLESTONE_STAIRS:0,10,STEP:3,10,COBBLE_WALL:1,20,COBBLESTONE_STAIRS:2,20,COBBLESTONE_STAIRS:3,20,MOSSY_COBBLESTONE:0,60,COBBLESTONE_STAIRS:1,20,STEP:11,20,COBBLESTONE:0,100)
RandomBlock(-5,5,-5,minecraft:concrete,40,SMOOTH_BRICK:1,30,SMOOTH_BRICK:2,30,SMOOTH_STAIRS:0,15,SMOOTH_STAIRS:1,15,SMOOTH_STAIRS:2,15,SMOOTH_STAIRS:3,15,STEP:5,15,STEP:13,15,COBBLE_WALL:0,10,COBBLESTONE_STAIRS:0,10,STEP:3,10,COBBLE_WALL:1,20,COBBLESTONE_STAIRS:2,20,COBBLESTONE_STAIRS:3,20,MOSSY_COBBLESTONE:0,60,COBBLESTONE_STAIRS:1,20,STEP:11,20,COBBLESTONE:0,100)
RandomBlock(-5,5,-4,minecraft:concrete,30,quark:limestone_wall,10,minecraft:concrete,100)
RandomBlock(-5,6,-7,minecraft:concrete,40,SMOOTH_BRICK:1,30,SMOOTH_BRICK:2,30,SMOOTH_STAIRS:0,15,SMOOTH_STAIRS:1,15,SMOOTH_STAIRS:2,15,SMOOTH_STAIRS:3,15,STEP:5,15,STEP:13,15,COBBLE_WALL:0,10,COBBLESTONE_STAIRS:0,10,STEP:3,10,COBBLE_WALL:1,20,COBBLESTONE_STAIRS:2,20,COBBLESTONE_STAIRS:3,20,MOSSY_COBBLESTONE:0,60,COBBLESTONE_STAIRS:1,20,STEP:11,20,COBBLESTONE:0,100)
RandomBlock(-5,6,-6,minecraft:concrete,40,SMOOTH_BRICK:1,30,SMOOTH_BRICK:2,30,SMOOTH_STAIRS:0,15,SMOOTH_STAIRS:1,15,SMOOTH_STAIRS:2,15,SMOOTH_STAIRS:3,15,STEP:5,15,STEP:13,15,COBBLE_WALL:0,10,COBBLESTONE_STAIRS:0,10,STEP:3,10,COBBLE_WALL:1,20,COBBLESTONE_STAIRS:2,20,COBBLESTONE_STAIRS:3,20,MOSSY_COBBLESTONE:0,60,COBBLESTONE_STAIRS:1,20,STEP:11,20,COBBLESTONE:0,100)
RandomBlock(-5,6,-5,minecraft:concrete,40,SMOOTH_BRICK:1,30,SMOOTH_BRICK:2,30,SMOOTH_STAIRS:0,15,SMOOTH_STAIRS:1,15,SMOOTH_STAIRS:2,15,SMOOTH_STAIRS:3,15,STEP:5,15,STEP:13,15,COBBLE_WALL:0,10,COBBLESTONE_STAIRS:0,10,STEP:3,10,COBBLE_WALL:1,20,COBBLESTONE_STAIRS:2,20,COBBLESTONE_STAIRS:3,20,MOSSY_COBBLESTONE:0,60,COBBLESTONE_STAIRS:1,20,STEP:11,20,COBBLESTONE:0,100)
RandomBlock(-5,6,-4,minecraft:concrete,30,quark:limestone_wall,10,minecraft:concrete,100)
RandomBlock(-5,7,-7,minecraft:concrete,40,SMOOTH_BRICK:1,30,SMOOTH_BRICK:2,30,SMOOTH_STAIRS:0,15,SMOOTH_STAIRS:1,15,SMOOTH_STAIRS:2,15,SMOOTH_STAIRS:3,15,STEP:5,15,STEP:13,15,COBBLE_WALL:0,10,COBBLESTONE_STAIRS:0,10,STEP:3,10,COBBLE_WALL:1,20,COBBLESTONE_STAIRS:2,20,COBBLESTONE_STAIRS:3,20,MOSSY_COBBLESTONE:0,60,COBBLESTONE_STAIRS:1,20,STEP:11,20,COBBLESTONE:0,100)
RandomBlock(-5,7,-6,minecraft:concrete,40,SMOOTH_BRICK:1,30,SMOOTH_BRICK:2,30,SMOOTH_STAIRS:0,15,SMOOTH_STAIRS:1,15,SMOOTH_STAIRS:2,15,SMOOTH_STAIRS:3,15,STEP:5,15,STEP:13,15,COBBLE_WALL:0,10,COBBLESTONE_STAIRS:0,10,STEP:3,10,COBBLE_WALL:1,20,COBBLESTONE_STAIRS:2,20,COBBLESTONE_STAIRS:3,20,MOSSY_COBBLESTONE:0,60,COBBLESTONE_STAIRS:1,20,STEP:11,20,COBBLESTONE:0,100)
RandomBlock(-5,7,-5,minecraft:concrete,40,SMOOTH_BRICK:1,30,SMOOTH_BRICK:2,30,SMOOTH_STAIRS:0,15,SMOOTH_STAIRS:1,15,SMOOTH_STAIRS:2,15,SMOOTH_STAIRS:3,15,STEP:5,15,STEP:13,15,COBBLE_WALL:0,10,COBBLESTONE_STAIRS:0,10,STEP:3,10,COBBLE_WALL:1,20,COBBLESTONE_STAIRS:2,20,COBBLESTONE_STAIRS:3,20,MOSSY_COBBLESTONE:0,60,COBBLESTONE_STAIRS:1,20,STEP:11,20,COBBLESTONE:0,100)
RandomBlock(-5,7,-4,minecraft:concrete,30,quark:limestone_wall,10,minecraft:concrete,100)
RandomBlock(-5,8,-7,minecraft:iron_bars:0,30,minecraft:iron_bars:0,100)
RandomBlock(-5,8,-6,minecraft:iron_bars:0,30,minecraft:iron_bars:0,100)
RandomBlock(-5,8,-5,minecraft:iron_bars:0,30,minecraft:iron_bars:0,100)
RandomBlock(-4,0,-7,minecraft:concrete,40,SMOOTH_BRICK:1,30,SMOOTH_BRICK:2,30,SMOOTH_STAIRS:0,15,SMOOTH_STAIRS:1,15,SMOOTH_STAIRS:2,15,SMOOTH_STAIRS:3,15,STEP:5,15,STEP:13,15,COBBLE_WALL:0,10,COBBLESTONE_STAIRS:0,10,STEP:3,10,COBBLE_WALL:1,20,COBBLESTONE_STAIRS:2,20,COBBLESTONE_STAIRS:3,20,MOSSY_COBBLESTONE:0,60,COBBLESTONE_STAIRS:1,20,STEP:11,20,COBBLESTONE:0,100)
RandomBlock(-4,0,-6,minecraft:concrete,40,SMOOTH_BRICK:1,30,SMOOTH_BRICK:2,30,SMOOTH_STAIRS:0,15,SMOOTH_STAIRS:1,15,SMOOTH_STAIRS:2,15,SMOOTH_STAIRS:3,15,STEP:5,15,STEP:13,15,COBBLE_WALL:0,10,COBBLESTONE_STAIRS:0,10,STEP:3,10,COBBLE_WALL:1,20,COBBLESTONE_STAIRS:2,20,COBBLESTONE_STAIRS:3,20,MOSSY_COBBLESTONE:0,60,COBBLESTONE_STAIRS:1,20,STEP:11,20,COBBLESTONE:0,100)
RandomBlock(-4,0,-5,minecraft:concrete,40,SMOOTH_BRICK:1,30,SMOOTH_BRICK:2,30,SMOOTH_STAIRS:0,15,SMOOTH_STAIRS:1,15,SMOOTH_STAIRS:2,15,SMOOTH_STAIRS:3,15,STEP:5,15,STEP:13,15,COBBLE_WALL:0,10,COBBLESTONE_STAIRS:0,10,STEP:3,10,COBBLE_WALL:1,20,COBBLESTONE_STAIRS:2,20,COBBLESTONE_STAIRS:3,20,MOSSY_COBBLESTONE:0,60,COBBLESTONE_STAIRS:1,20,STEP:11,20,COBBLESTONE:0,100)
RandomBlock(-4,1,-7,minecraft:concrete,40,SMOOTH_BRICK:1,30,SMOOTH_BRICK:2,30,SMOOTH_STAIRS:0,15,SMOOTH_STAIRS:1,15,SMOOTH_STAIRS:2,15,SMOOTH_STAIRS:3,15,STEP:5,15,STEP:13,15,COBBLE_WALL:0,10,COBBLESTONE_STAIRS:0,10,STEP:3,10,COBBLE_WALL:1,20,COBBLESTONE_STAIRS:2,20,COBBLESTONE_STAIRS:3,20,MOSSY_COBBLESTONE:0,60,COBBLESTONE_STAIRS:1,20,STEP:11,20,COBBLESTONE:0,100)
RandomBlock(-4,1,-6,minecraft:concrete,40,SMOOTH_BRICK:1,30,SMOOTH_BRICK:2,30,SMOOTH_STAIRS:0,15,SMOOTH_STAIRS:1,15,SMOOTH_STAIRS:2,15,SMOOTH_STAIRS:3,15,STEP:5,15,STEP:13,15,COBBLE_WALL:0,10,COBBLESTONE_STAIRS:0,10,STEP:3,10,COBBLE_WALL:1,20,COBBLESTONE_STAIRS:2,20,COBBLESTONE_STAIRS:3,20,MOSSY_COBBLESTONE:0,60,COBBLESTONE_STAIRS:1,20,STEP:11,20,COBBLESTONE:0,100)
RandomBlock(-4,1,-5,minecraft:concrete,40,SMOOTH_BRICK:1,30,SMOOTH_BRICK:2,30,SMOOTH_STAIRS:0,15,SMOOTH_STAIRS:1,15,SMOOTH_STAIRS:2,15,SMOOTH_STAIRS:3,15,STEP:5,15,STEP:13,15,COBBLE_WALL:0,10,COBBLESTONE_STAIRS:0,10,STEP:3,10,COBBLE_WALL:1,20,COBBLESTONE_STAIRS:2,20,COBBLESTONE_STAIRS:3,20,MOSSY_COBBLESTONE:0,60,COBBLESTONE_STAIRS:1,20,STEP:11,20,COBBLESTONE:0,100)
RandomBlock(-4,2,-7,minecraft:concrete,40,SMOOTH_BRICK:1,30,SMOOTH_BRICK:2,30,SMOOTH_STAIRS:0,15,SMOOTH_STAIRS:1,15,SMOOTH_STAIRS:2,15,SMOOTH_STAIRS:3,15,STEP:5,15,STEP:13,15,COBBLE_WALL:0,10,COBBLESTONE_STAIRS:0,10,STEP:3,10,COBBLE_WALL:1,20,COBBLESTONE_STAIRS:2,20,COBBLESTONE_STAIRS:3,20,MOSSY_COBBLESTONE:0,60,COBBLESTONE_STAIRS:1,20,STEP:11,20,COBBLESTONE:0,100)
RandomBlock(-4,2,-6,minecraft:concrete,40,SMOOTH_BRICK:1,30,SMOOTH_BRICK:2,30,SMOOTH_STAIRS:0,15,SMOOTH_STAIRS:1,15,SMOOTH_STAIRS:2,15,SMOOTH_STAIRS:3,15,STEP:5,15,STEP:13,15,COBBLE_WALL:0,10,COBBLESTONE_STAIRS:0,10,STEP:3,10,COBBLE_WALL:1,20,COBBLESTONE_STAIRS:2,20,COBBLESTONE_STAIRS:3,20,MOSSY_COBBLESTONE:0,60,COBBLESTONE_STAIRS:1,20,STEP:11,20,COBBLESTONE:0,100)
RandomBlock(-4,2,-5,minecraft:concrete,40,SMOOTH_BRICK:1,30,SMOOTH_BRICK:2,30,SMOOTH_STAIRS:0,15,SMOOTH_STAIRS:1,15,SMOOTH_STAIRS:2,15,SMOOTH_STAIRS:3,15,STEP:5,15,STEP:13,15,COBBLE_WALL:0,10,COBBLESTONE_STAIRS:0,10,STEP:3,10,COBBLE_WALL:1,20,COBBLESTONE_STAIRS:2,20,COBBLESTONE_STAIRS:3,20,MOSSY_COBBLESTONE:0,60,COBBLESTONE_STAIRS:1,20,STEP:11,20,COBBLESTONE:0,100)
RandomBlock(-4,3,-7,minecraft:concrete,40,SMOOTH_BRICK:1,30,SMOOTH_BRICK:2,30,SMOOTH_STAIRS:0,15,SMOOTH_STAIRS:1,15,SMOOTH_STAIRS:2,15,SMOOTH_STAIRS:3,15,STEP:5,15,STEP:13,15,COBBLE_WALL:0,10,COBBLESTONE_STAIRS:0,10,STEP:3,10,COBBLE_WALL:1,20,COBBLESTONE_STAIRS:2,20,COBBLESTONE_STAIRS:3,20,MOSSY_COBBLESTONE:0,60,COBBLESTONE_STAIRS:1,20,STEP:11,20,COBBLESTONE:0,100)
RandomBlock(-4,3,-6,minecraft:concrete,40,SMOOTH_BRICK:1,30,SMOOTH_BRICK:2,30,SMOOTH_STAIRS:0,15,SMOOTH_STAIRS:1,15,SMOOTH_STAIRS:2,15,SMOOTH_STAIRS:3,15,STEP:5,15,STEP:13,15,COBBLE_WALL:0,10,COBBLESTONE_STAIRS:0,10,STEP:3,10,COBBLE_WALL:1,20,COBBLESTONE_STAIRS:2,20,COBBLESTONE_STAIRS:3,20,MOSSY_COBBLESTONE:0,60,COBBLESTONE_STAIRS:1,20,STEP:11,20,COBBLESTONE:0,100)
RandomBlock(-4,3,-5,minecraft:concrete,40,SMOOTH_BRICK:1,30,SMOOTH_BRICK:2,30,SMOOTH_STAIRS:0,15,SMOOTH_STAIRS:1,15,SMOOTH_STAIRS:2,15,SMOOTH_STAIRS:3,15,STEP:5,15,STEP:13,15,COBBLE_WALL:0,10,COBBLESTONE_STAIRS:0,10,STEP:3,10,COBBLE_WALL:1,20,COBBLESTONE_STAIRS:2,20,COBBLESTONE_STAIRS:3,20,MOSSY_COBBLESTONE:0,60,COBBLESTONE_STAIRS:1,20,STEP:11,20,COBBLESTONE:0,100)
RandomBlock(-4,4,-7,minecraft:concrete,40,SMOOTH_BRICK:1,30,SMOOTH_BRICK:2,30,SMOOTH_STAIRS:0,15,SMOOTH_STAIRS:1,15,SMOOTH_STAIRS:2,15,SMOOTH_STAIRS:3,15,STEP:5,15,STEP:13,15,COBBLE_WALL:0,10,COBBLESTONE_STAIRS:0,10,STEP:3,10,COBBLE_WALL:1,20,COBBLESTONE_STAIRS:2,20,COBBLESTONE_STAIRS:3,20,MOSSY_COBBLESTONE:0,60,COBBLESTONE_STAIRS:1,20,STEP:11,20,COBBLESTONE:0,100)
RandomBlock(-4,4,-6,minecraft:concrete,40,SMOOTH_BRICK:1,30,SMOOTH_BRICK:2,30,SMOOTH_STAIRS:0,15,SMOOTH_STAIRS:1,15,SMOOTH_STAIRS:2,15,SMOOTH_STAIRS:3,15,STEP:5,15,STEP:13,15,COBBLE_WALL:0,10,COBBLESTONE_STAIRS:0,10,STEP:3,10,COBBLE_WALL:1,20,COBBLESTONE_STAIRS:2,20,COBBLESTONE_STAIRS:3,20,MOSSY_COBBLESTONE:0,60,COBBLESTONE_STAIRS:1,20,STEP:11,20,COBBLESTONE:0,100)
RandomBlock(-4,4,-5,minecraft:concrete,40,SMOOTH_BRICK:1,30,SMOOTH_BRICK:2,30,SMOOTH_STAIRS:0,15,SMOOTH_STAIRS:1,15,SMOOTH_STAIRS:2,15,SMOOTH_STAIRS:3,15,STEP:5,15,STEP:13,15,COBBLE_WALL:0,10,COBBLESTONE_STAIRS:0,10,STEP:3,10,COBBLE_WALL:1,20,COBBLESTONE_STAIRS:2,20,COBBLESTONE_STAIRS:3,20,MOSSY_COBBLESTONE:0,60,COBBLESTONE_STAIRS:1,20,STEP:11,20,COBBLESTONE:0,100)
RandomBlock(-4,5,-7,minecraft:concrete,40,SMOOTH_BRICK:1,30,SMOOTH_BRICK:2,30,SMOOTH_STAIRS:0,15,SMOOTH_STAIRS:1,15,SMOOTH_STAIRS:2,15,SMOOTH_STAIRS:3,15,STEP:5,15,STEP:13,15,COBBLE_WALL:0,10,COBBLESTONE_STAIRS:0,10,STEP:3,10,COBBLE_WALL:1,20,COBBLESTONE_STAIRS:2,20,COBBLESTONE_STAIRS:3,20,MOSSY_COBBLESTONE:0,60,COBBLESTONE_STAIRS:1,20,STEP:11,20,COBBLESTONE:0,100)
RandomBlock(-4,5,-6,minecraft:concrete,30,quark:limestone_wall,10,minecraft:concrete,100)
RandomBlock(-4,5,-5,minecraft:concrete,30,quark:limestone_wall,10,minecraft:concrete,100)
RandomBlock(-4,6,-7,minecraft:concrete,40,SMOOTH_BRICK:1,30,SMOOTH_BRICK:2,30,SMOOTH_STAIRS:0,15,SMOOTH_STAIRS:1,15,SMOOTH_STAIRS:2,15,SMOOTH_STAIRS:3,15,STEP:5,15,STEP:13,15,COBBLE_WALL:0,10,COBBLESTONE_STAIRS:0,10,STEP:3,10,COBBLE_WALL:1,20,COBBLESTONE_STAIRS:2,20,COBBLESTONE_STAIRS:3,20,MOSSY_COBBLESTONE:0,60,COBBLESTONE_STAIRS:1,20,STEP:11,20,COBBLESTONE:0,100)
RandomBlock(-4,6,-6,minecraft:concrete,30,quark:limestone_wall,10,minecraft:concrete,100)
RandomBlock(-4,6,-5,minecraft:concrete,30,quark:limestone_wall,10,minecraft:concrete,100)
RandomBlock(-4,7,-7,minecraft:concrete,40,SMOOTH_BRICK:1,30,SMOOTH_BRICK:2,30,SMOOTH_STAIRS:0,15,SMOOTH_STAIRS:1,15,SMOOTH_STAIRS:2,15,SMOOTH_STAIRS:3,15,STEP:5,15,STEP:13,15,COBBLE_WALL:0,10,COBBLESTONE_STAIRS:0,10,STEP:3,10,COBBLE_WALL:1,20,COBBLESTONE_STAIRS:2,20,COBBLESTONE_STAIRS:3,20,MOSSY_COBBLESTONE:0,60,COBBLESTONE_STAIRS:1,20,STEP:11,20,COBBLESTONE:0,100)
RandomBlock(-4,7,-6,minecraft:concrete,30,quark:limestone_wall,10,minecraft:concrete,100)
RandomBlock(-4,7,-5,minecraft:concrete,30,quark:limestone_wall,10,minecraft:concrete,100)
RandomBlock(-4,8,-7,minecraft:iron_bars:0,30,minecraft:iron_bars:0,100)
Block(-4,8,-5,minecraft:stone)
RandomBlock(-4,9,-7,minecraft:iron_bars:0,30,minecraft:iron_bars:0,100)
Block(-4,9,-5,minecraft:stone)
RandomBlock(-4,10,-5,minecraft:concrete,30,quark:limestone_wall,10,minecraft:concrete,100)
RandomBlock(-3,0,-7,minecraft:concrete,40,SMOOTH_BRICK:1,30,SMOOTH_BRICK:2,30,SMOOTH_STAIRS:0,15,SMOOTH_STAIRS:1,15,SMOOTH_STAIRS:2,15,SMOOTH_STAIRS:3,15,STEP:5,15,STEP:13,15,COBBLE_WALL:0,10,COBBLESTONE_STAIRS:0,10,STEP:3,10,COBBLE_WALL:1,20,COBBLESTONE_STAIRS:2,20,COBBLESTONE_STAIRS:3,20,MOSSY_COBBLESTONE:0,60,COBBLESTONE_STAIRS:1,20,STEP:11,20,COBBLESTONE:0,100)
RandomBlock(-3,1,-7,minecraft:concrete,40,SMOOTH_BRICK:1,30,SMOOTH_BRICK:2,30,SMOOTH_STAIRS:0,15,SMOOTH_STAIRS:1,15,SMOOTH_STAIRS:2,15,SMOOTH_STAIRS:3,15,STEP:5,15,STEP:13,15,COBBLE_WALL:0,10,COBBLESTONE_STAIRS:0,10,STEP:3,10,COBBLE_WALL:1,20,COBBLESTONE_STAIRS:2,20,COBBLESTONE_STAIRS:3,20,MOSSY_COBBLESTONE:0,60,COBBLESTONE_STAIRS:1,20,STEP:11,20,COBBLESTONE:0,100)
RandomBlock(-3,2,-7,minecraft:concrete,40,SMOOTH_BRICK:1,30,SMOOTH_BRICK:2,30,SMOOTH_STAIRS:0,15,SMOOTH_STAIRS:1,15,SMOOTH_STAIRS:2,15,SMOOTH_STAIRS:3,15,STEP:5,15,STEP:13,15,COBBLE_WALL:0,10,COBBLESTONE_STAIRS:0,10,STEP:3,10,COBBLE_WALL:1,20,COBBLESTONE_STAIRS:2,20,COBBLESTONE_STAIRS:3,20,MOSSY_COBBLESTONE:0,60,COBBLESTONE_STAIRS:1,20,STEP:11,20,COBBLESTONE:0,100)
RandomBlock(-3,3,-7,minecraft:concrete,40,SMOOTH_BRICK:1,30,SMOOTH_BRICK:2,30,SMOOTH_STAIRS:0,15,SMOOTH_STAIRS:1,15,SMOOTH_STAIRS:2,15,SMOOTH_STAIRS:3,15,STEP:5,15,STEP:13,15,COBBLE_WALL:0,10,COBBLESTONE_STAIRS:0,10,STEP:3,10,COBBLE_WALL:1,20,COBBLESTONE_STAIRS:2,20,COBBLESTONE_STAIRS:3,20,MOSSY_COBBLESTONE:0,60,COBBLESTONE_STAIRS:1,20,STEP:11,20,COBBLESTONE:0,100)
RandomBlock(-3,4,-7,minecraft:concrete,40,SMOOTH_BRICK:1,30,SMOOTH_BRICK:2,30,SMOOTH_STAIRS:0,15,SMOOTH_STAIRS:1,15,SMOOTH_STAIRS:2,15,SMOOTH_STAIRS:3,15,STEP:5,15,STEP:13,15,COBBLE_WALL:0,10,COBBLESTONE_STAIRS:0,10,STEP:3,10,COBBLE_WALL:1,20,COBBLESTONE_STAIRS:2,20,COBBLESTONE_STAIRS:3,20,MOSSY_COBBLESTONE:0,60,COBBLESTONE_STAIRS:1,20,STEP:11,20,COBBLESTONE:0,100)
RandomBlock(-3,5,-7,minecraft:concrete,30,quark:limestone_wall,10,minecraft:concrete,100)
RandomBlock(-3,6,-7,minecraft:concrete,30,quark:limestone_wall,10,minecraft:concrete,100)
RandomBlock(-3,7,-7,minecraft:concrete,30,quark:limestone_wall,10,minecraft:concrete,100)
Block(-3,8,-7,minecraft:stone)
Block(-3,9,-7,minecraft:stone)
RandomBlock(-3,10,-7,minecraft:concrete,30,quark:limestone_wall,10,minecraft:concrete,100)

#######################################################################
# +-----------------------------------------------------------------+ #
# |                             Branches                            | #
# +-----------------------------------------------------------------+ #
#######################################################################

Branch(-16,0,0,true,CoolingTower4C0R1,NORTH,100.0,0)

#######################################################################
# +-----------------------------------------------------------------+ #
# |                             Entities                            | #
# +-----------------------------------------------------------------+ #
#######################################################################


#######################################################################
# +-----------------------------------------------------------------+ #
# |                            Particles                            | #
# +-----------------------------------------------------------------+ #
#######################################################################


#######################################################################
# +-----------------------------------------------------------------+ #
# |                             Spawners                            | #
# +-----------------------------------------------------------------+ #
#######################################################################


#######################################################################
# +-----------------------------------------------------------------+ #
# |                             ModData                             | #
# +-----------------------------------------------------------------+ #
#######################################################################

