#######################################################################
# DregoraRL SRP Manhunt 3.10.65 finite-city object
#######################################################################
Author: SRP Manhunt
Description: Abandoned roadside checkpoint
SettingsMode: WriteWithoutComments
FixedRotation: 
Frequency: 0
SpawnHeight: highestBlock
UseCenterForHighestBlock: true
MinHeight: 0
MaxHeight: 255
InheritBO3: 
InheritBO3Rotation: NORTH
OverrideChildSettings: true
OverrideParentHeight: false
CanOverride: true
BranchFrequency: 0
BranchFrequencyGroup: 
MustBeBelowOther: false
MustBeInside: 
CannotBeInside: 
ReplacesBO3: 
MustBeInsideWorldBorders: true
CanSpawnOnWater: true
SpawnOnWaterOnly: false
SpawnUnderWater: false
SpawnAtWaterLevel: false
HeightOffset: 0
RemoveAir: false
ReplaceAbove: 
ReplaceBelow: DIRT
ReplaceWithBiomeBlocks: false
ReplaceWithSurfaceBlock: GRASS
ReplaceWithGroundBlock: DIRT
ReplaceWithStoneBlock: STONE
SmoothRadius: 0
SmoothHeightOffset: 0
SmoothStartTop: false
SmoothStartWood: false
SmoothingSurfaceBlock: 
SmoothingGroundBlock: 
BO3Group: 
IsSpawnPoint: false
DoReplaceBlocks: true

#######################################################################
# Blocks
#######################################################################
Block(-8,16,-7,GRAVEL:0)
Block(-7,16,-7,GRAVEL:0)
Block(-6,16,-7,GRAVEL:0)
Block(-5,16,-7,GRAVEL:0)
Block(-4,16,-7,GRAVEL:0)
Block(-3,16,-7,GRAVEL:0)
Block(-2,16,-7,GRAVEL:0)
Block(-1,16,-7,GRAVEL:0)
Block(0,16,-7,GRAVEL:0)
Block(1,16,-7,GRAVEL:0)
Block(2,16,-7,GRAVEL:0)
Block(3,16,-7,GRAVEL:0)
Block(4,16,-7,GRAVEL:0)
Block(5,16,-7,GRAVEL:0)
Block(6,16,-7,GRAVEL:0)
Block(7,16,-7,GRAVEL:0)
Block(-8,16,-6,GRAVEL:0)
Block(-7,16,-6,GRAVEL:0)
Block(-6,16,-6,GRAVEL:0)
Block(-5,16,-6,GRAVEL:0)
Block(-4,16,-6,GRAVEL:0)
Block(-3,16,-6,GRAVEL:0)
Block(-2,16,-6,GRAVEL:0)
Block(-1,16,-6,GRAVEL:0)
Block(0,16,-6,GRAVEL:0)
Block(1,16,-6,GRAVEL:0)
Block(2,16,-6,GRAVEL:0)
Block(3,16,-6,GRAVEL:0)
Block(4,16,-6,GRAVEL:0)
Block(5,16,-6,GRAVEL:0)
Block(6,16,-6,GRAVEL:0)
Block(7,16,-6,GRAVEL:0)
Block(-8,16,-5,GRAVEL:0)
Block(-7,16,-5,GRAVEL:0)
Block(-6,16,-5,GRAVEL:0)
Block(-5,16,-5,GRAVEL:0)
Block(-4,16,-5,GRAVEL:0)
Block(-3,16,-5,GRAVEL:0)
Block(-2,16,-5,GRAVEL:0)
Block(-1,16,-5,GRAVEL:0)
Block(0,16,-5,GRAVEL:0)
Block(1,16,-5,GRAVEL:0)
Block(2,16,-5,GRAVEL:0)
Block(3,16,-5,GRAVEL:0)
Block(4,16,-5,GRAVEL:0)
Block(5,16,-5,GRAVEL:0)
Block(6,16,-5,GRAVEL:0)
Block(7,16,-5,GRAVEL:0)
Block(-8,16,-4,GRAVEL:0)
Block(-7,16,-4,GRAVEL:0)
Block(-6,16,-4,GRAVEL:0)
Block(-5,16,-4,GRAVEL:0)
Block(-4,16,-4,GRAVEL:0)
Block(-3,16,-4,GRAVEL:0)
Block(-2,16,-4,GRAVEL:0)
Block(-1,16,-4,GRAVEL:0)
Block(0,16,-4,GRAVEL:0)
Block(1,16,-4,GRAVEL:0)
Block(2,16,-4,GRAVEL:0)
Block(3,16,-4,GRAVEL:0)
Block(4,16,-4,GRAVEL:0)
Block(5,16,-4,GRAVEL:0)
Block(6,16,-4,GRAVEL:0)
Block(7,16,-4,GRAVEL:0)
Block(-8,16,-3,GRAVEL:0)
Block(-7,16,-3,GRAVEL:0)
Block(-6,16,-3,GRAVEL:0)
Block(-5,16,-3,GRAVEL:0)
Block(-4,16,-3,GRAVEL:0)
Block(-3,16,-3,GRAVEL:0)
Block(-2,16,-3,GRAVEL:0)
Block(-1,16,-3,GRAVEL:0)
Block(0,16,-3,GRAVEL:0)
Block(1,16,-3,GRAVEL:0)
Block(2,16,-3,GRAVEL:0)
Block(3,16,-3,GRAVEL:0)
Block(4,16,-3,GRAVEL:0)
Block(5,16,-3,GRAVEL:0)
Block(6,16,-3,GRAVEL:0)
Block(7,16,-3,GRAVEL:0)
Block(-8,16,-2,GRAVEL:0)
Block(-7,16,-2,GRAVEL:0)
Block(-6,16,-2,GRAVEL:0)
Block(-5,16,-2,GRAVEL:0)
Block(-4,16,-2,GRAVEL:0)
Block(-3,16,-2,GRAVEL:0)
Block(-2,16,-2,GRAVEL:0)
Block(-1,16,-2,GRAVEL:0)
Block(0,16,-2,GRAVEL:0)
Block(1,16,-2,GRAVEL:0)
Block(2,16,-2,GRAVEL:0)
Block(3,16,-2,GRAVEL:0)
Block(4,16,-2,GRAVEL:0)
Block(5,16,-2,GRAVEL:0)
Block(6,16,-2,GRAVEL:0)
Block(7,16,-2,GRAVEL:0)
Block(-8,16,-1,GRAVEL:0)
Block(-7,16,-1,GRAVEL:0)
Block(-6,16,-1,GRAVEL:0)
Block(-5,16,-1,GRAVEL:0)
Block(-4,16,-1,GRAVEL:0)
Block(-3,16,-1,GRAVEL:0)
Block(-2,16,-1,GRAVEL:0)
Block(-1,16,-1,GRAVEL:0)
Block(0,16,-1,GRAVEL:0)
Block(1,16,-1,GRAVEL:0)
Block(2,16,-1,GRAVEL:0)
Block(3,16,-1,GRAVEL:0)
Block(4,16,-1,GRAVEL:0)
Block(5,16,-1,GRAVEL:0)
Block(6,16,-1,GRAVEL:0)
Block(7,16,-1,GRAVEL:0)
Block(-8,16,0,GRAVEL:0)
Block(-7,16,0,GRAVEL:0)
Block(-6,16,0,GRAVEL:0)
Block(-5,16,0,GRAVEL:0)
Block(-4,16,0,GRAVEL:0)
Block(-3,16,0,GRAVEL:0)
Block(-2,16,0,GRAVEL:0)
Block(-1,16,0,GRAVEL:0)
Block(0,16,0,GRAVEL:0)
Block(1,16,0,GRAVEL:0)
Block(2,16,0,GRAVEL:0)
Block(3,16,0,GRAVEL:0)
Block(4,16,0,GRAVEL:0)
Block(5,16,0,GRAVEL:0)
Block(6,16,0,GRAVEL:0)
Block(7,16,0,GRAVEL:0)
Block(-8,16,1,GRAVEL:0)
Block(-7,16,1,GRAVEL:0)
Block(-6,16,1,GRAVEL:0)
Block(-5,16,1,GRAVEL:0)
Block(-4,16,1,GRAVEL:0)
Block(-3,16,1,GRAVEL:0)
Block(-2,16,1,GRAVEL:0)
Block(-1,16,1,GRAVEL:0)
Block(0,16,1,GRAVEL:0)
Block(1,16,1,GRAVEL:0)
Block(2,16,1,GRAVEL:0)
Block(3,16,1,GRAVEL:0)
Block(4,16,1,GRAVEL:0)
Block(5,16,1,GRAVEL:0)
Block(6,16,1,GRAVEL:0)
Block(7,16,1,GRAVEL:0)
Block(-8,16,2,GRAVEL:0)
Block(-7,16,2,GRAVEL:0)
Block(-6,16,2,GRAVEL:0)
Block(-5,16,2,GRAVEL:0)
Block(-4,16,2,GRAVEL:0)
Block(-3,16,2,GRAVEL:0)
Block(-2,16,2,GRAVEL:0)
Block(-1,16,2,GRAVEL:0)
Block(0,16,2,GRAVEL:0)
Block(1,16,2,GRAVEL:0)
Block(2,16,2,GRAVEL:0)
Block(3,16,2,GRAVEL:0)
Block(4,16,2,GRAVEL:0)
Block(5,16,2,GRAVEL:0)
Block(6,16,2,GRAVEL:0)
Block(7,16,2,GRAVEL:0)
Block(-8,16,3,GRAVEL:0)
Block(-7,16,3,GRAVEL:0)
Block(-6,16,3,GRAVEL:0)
Block(-5,16,3,GRAVEL:0)
Block(-4,16,3,GRAVEL:0)
Block(-3,16,3,GRAVEL:0)
Block(-2,16,3,GRAVEL:0)
Block(-1,16,3,GRAVEL:0)
Block(0,16,3,GRAVEL:0)
Block(1,16,3,GRAVEL:0)
Block(2,16,3,GRAVEL:0)
Block(3,16,3,GRAVEL:0)
Block(4,16,3,GRAVEL:0)
Block(5,16,3,GRAVEL:0)
Block(6,16,3,GRAVEL:0)
Block(7,16,3,GRAVEL:0)
Block(-8,16,4,GRAVEL:0)
Block(-7,16,4,GRAVEL:0)
Block(-6,16,4,GRAVEL:0)
Block(-5,16,4,GRAVEL:0)
Block(-4,16,4,GRAVEL:0)
Block(-3,16,4,GRAVEL:0)
Block(-2,16,4,GRAVEL:0)
Block(-1,16,4,GRAVEL:0)
Block(0,16,4,GRAVEL:0)
Block(1,16,4,GRAVEL:0)
Block(2,16,4,GRAVEL:0)
Block(3,16,4,GRAVEL:0)
Block(4,16,4,GRAVEL:0)
Block(5,16,4,GRAVEL:0)
Block(6,16,4,GRAVEL:0)
Block(7,16,4,GRAVEL:0)
Block(-8,16,5,GRAVEL:0)
Block(-7,16,5,GRAVEL:0)
Block(-6,16,5,GRAVEL:0)
Block(-5,16,5,GRAVEL:0)
Block(-4,16,5,GRAVEL:0)
Block(-3,16,5,GRAVEL:0)
Block(-2,16,5,GRAVEL:0)
Block(-1,16,5,GRAVEL:0)
Block(0,16,5,GRAVEL:0)
Block(1,16,5,GRAVEL:0)
Block(2,16,5,GRAVEL:0)
Block(3,16,5,GRAVEL:0)
Block(4,16,5,GRAVEL:0)
Block(5,16,5,GRAVEL:0)
Block(6,16,5,GRAVEL:0)
Block(7,16,5,GRAVEL:0)
Block(-8,16,6,GRAVEL:0)
Block(-7,16,6,GRAVEL:0)
Block(-6,16,6,GRAVEL:0)
Block(-5,16,6,GRAVEL:0)
Block(-4,16,6,GRAVEL:0)
Block(-3,16,6,GRAVEL:0)
Block(-2,16,6,GRAVEL:0)
Block(-1,16,6,GRAVEL:0)
Block(0,16,6,GRAVEL:0)
Block(1,16,6,GRAVEL:0)
Block(2,16,6,GRAVEL:0)
Block(3,16,6,GRAVEL:0)
Block(4,16,6,GRAVEL:0)
Block(5,16,6,GRAVEL:0)
Block(6,16,6,GRAVEL:0)
Block(7,16,6,GRAVEL:0)
Block(-8,16,7,GRAVEL:0)
Block(-7,16,7,GRAVEL:0)
Block(-6,16,7,GRAVEL:0)
Block(-5,16,7,GRAVEL:0)
Block(-4,16,7,GRAVEL:0)
Block(-3,16,7,GRAVEL:0)
Block(-2,16,7,GRAVEL:0)
Block(-1,16,7,GRAVEL:0)
Block(0,16,7,GRAVEL:0)
Block(1,16,7,GRAVEL:0)
Block(2,16,7,GRAVEL:0)
Block(3,16,7,GRAVEL:0)
Block(4,16,7,GRAVEL:0)
Block(5,16,7,GRAVEL:0)
Block(6,16,7,GRAVEL:0)
Block(7,16,7,GRAVEL:0)
Block(-8,16,8,GRAVEL:0)
Block(-7,16,8,GRAVEL:0)
Block(-6,16,8,GRAVEL:0)
Block(-5,16,8,GRAVEL:0)
Block(-4,16,8,GRAVEL:0)
Block(-3,16,8,GRAVEL:0)
Block(-2,16,8,GRAVEL:0)
Block(-1,16,8,GRAVEL:0)
Block(0,16,8,GRAVEL:0)
Block(1,16,8,GRAVEL:0)
Block(2,16,8,GRAVEL:0)
Block(3,16,8,GRAVEL:0)
Block(4,16,8,GRAVEL:0)
Block(5,16,8,GRAVEL:0)
Block(6,16,8,GRAVEL:0)
Block(7,16,8,GRAVEL:0)
Block(-7,17,-3,IRON_FENCE:0)
Block(6,17,-3,IRON_FENCE:0)
Block(-8,17,0,CONCRETE:0)
Block(-7,17,0,CONCRETE:14)
Block(-6,17,0,CONCRETE:0)
Block(-5,17,0,CONCRETE:14)
Block(-4,17,0,CONCRETE:0)
Block(-3,17,0,CONCRETE:14)
Block(-2,17,0,CONCRETE:0)
Block(-1,17,0,CONCRETE:14)
Block(0,17,0,CONCRETE:0)
Block(1,17,0,CONCRETE:14)
Block(2,17,0,CONCRETE:0)
Block(3,17,0,CONCRETE:14)
Block(4,17,0,CONCRETE:0)
Block(5,17,0,CONCRETE:14)
Block(6,17,0,CONCRETE:0)
Block(7,17,0,CONCRETE:14)
Block(2,17,2,STONE_BRICKS:0)
Block(3,17,2,STONE_BRICKS:0)
Block(4,17,2,STONE_BRICKS:0)
Block(5,17,2,STONE_BRICKS:0)
Block(6,17,2,STONE_BRICKS:0)
Block(2,17,3,STONE_BRICKS:0)
Block(3,17,3,STONE_BRICKS:0)
Block(4,17,3,STONE_BRICKS:0)
Block(5,17,3,STONE_BRICKS:0)
Block(6,17,3,STONE_BRICKS:0)
Block(2,17,4,STONE_BRICKS:0)
Block(3,17,4,STONE_BRICKS:0)
Block(4,17,4,STONE_BRICKS:0)
Block(5,17,4,STONE_BRICKS:0)
Block(6,17,4,STONE_BRICKS:0)
Block(2,17,5,STONE_BRICKS:0)
Block(3,17,5,STONE_BRICKS:0)
Block(4,17,5,STONE_BRICKS:0)
Block(5,17,5,STONE_BRICKS:0)
Block(6,17,5,STONE_BRICKS:0)
Block(2,17,6,STONE_BRICKS:0)
Block(3,17,6,STONE_BRICKS:0)
Block(4,17,6,STONE_BRICKS:0)
Block(5,17,6,STONE_BRICKS:0)
Block(6,17,6,STONE_BRICKS:0)
Block(-7,18,-3,IRON_FENCE:0)
Block(6,18,-3,IRON_FENCE:0)
Block(2,18,2,STONE_BRICKS:0)
Block(3,18,2,STONE_BRICKS:0)
Block(4,18,2,STONE_BRICKS:0)
Block(5,18,2,STONE_BRICKS:0)
Block(6,18,2,STONE_BRICKS:0)
Block(2,18,3,STONE_BRICKS:0)
Block(6,18,3,STONE_BRICKS:0)
Block(2,18,4,STONE_BRICKS:0)
Block(6,18,4,STONE_BRICKS:0)
Block(2,18,5,STONE_BRICKS:0)
Block(6,18,5,STONE_BRICKS:0)
Block(2,18,6,STONE_BRICKS:0)
Block(3,18,6,STONE_BRICKS:0)
Block(4,18,6,STONE_BRICKS:0)
Block(5,18,6,STONE_BRICKS:0)
Block(6,18,6,STONE_BRICKS:0)
Block(-7,19,-3,IRON_FENCE:0)
Block(6,19,-3,IRON_FENCE:0)
Block(2,19,2,STONE_BRICKS:0)
Block(3,19,2,STONE_BRICKS:0)
Block(4,19,2,STONE_BRICKS:0)
Block(5,19,2,STONE_BRICKS:0)
Block(6,19,2,STONE_BRICKS:0)
Block(2,19,3,STONE_BRICKS:0)
Block(6,19,3,STONE_BRICKS:0)
Block(2,19,4,STONE_BRICKS:0)
Block(6,19,4,STONE_BRICKS:0)
Block(2,19,5,STONE_BRICKS:0)
Block(6,19,5,STONE_BRICKS:0)
Block(2,19,6,STONE_BRICKS:0)
Block(3,19,6,STONE_BRICKS:0)
Block(4,19,6,STONE_BRICKS:0)
Block(5,19,6,STONE_BRICKS:0)
Block(6,19,6,STONE_BRICKS:0)
Block(-7,20,-3,IRON_FENCE:0)
Block(6,20,-3,IRON_FENCE:0)
Block(2,20,2,STONE_BRICKS:0)
Block(3,20,2,STONE_BRICKS:0)
Block(4,20,2,STONE_BRICKS:0)
Block(5,20,2,STONE_BRICKS:0)
Block(6,20,2,STONE_BRICKS:0)
Block(2,20,3,STONE_BRICKS:0)
Block(6,20,3,STONE_BRICKS:0)
Block(2,20,4,STONE_BRICKS:0)
Block(6,20,4,STONE_BRICKS:0)
Block(2,20,5,STONE_BRICKS:0)
Block(6,20,5,STONE_BRICKS:0)
Block(2,20,6,STONE_BRICKS:0)
Block(3,20,6,STONE_BRICKS:0)
Block(4,20,6,STONE_BRICKS:0)
Block(5,20,6,STONE_BRICKS:0)
Block(6,20,6,STONE_BRICKS:0)
Block(-7,21,-3,GLOWSTONE:0)
Block(6,21,-3,GLOWSTONE:0)

#######################################################################
# Branches
#######################################################################
