
#######################################################################
# +-----------------------------------------------------------------+ #
# |                            BO4 object                           | #
# +-----------------------------------------------------------------+ #
#######################################################################

Author: SRP Manhunt

Description: Low warehouse and paved industrial yard

SettingsMode: WriteWithoutComments


#######################################################################
# +-----------------------------------------------------------------+ #
# |                          Main settings                          | #
# +-----------------------------------------------------------------+ #
#######################################################################

FixedRotation: 

Frequency: 0

SpawnHeight: highestBlock

UseCenterForHighestBlock: true

##############################
# Height Limits for the BO4. #
##############################

MinHeight: 0

MaxHeight: 255

InheritBO3: 

InheritBO3Rotation: NORTH

OverrideChildSettings: true

OverrideParentHeight: false

CanOverride: true

BranchFrequency: 0

BranchFrequencyGroup: 

MustBeBelowOther: false

MustBeInside: 

CannotBeInside: 

ReplacesBO3: 

MustBeInsideWorldBorders: true

CanSpawnOnWater: true

SpawnOnWaterOnly: false

SpawnUnderWater: false

SpawnAtWaterLevel: false

HeightOffset: 0

RemoveAir: false

ReplaceAbove: 

ReplaceBelow: DIRT

ReplaceWithBiomeBlocks: false

ReplaceWithSurfaceBlock: GRASS

ReplaceWithGroundBlock: DIRT

ReplaceWithStoneBlock: STONE

SmoothRadius: 0

SmoothHeightOffset: 0

SmoothStartTop: false

SmoothStartWood: false

SmoothingSurfaceBlock: 

SmoothingGroundBlock: 

BO3Group: 

IsSpawnPoint: false

DoReplaceBlocks: true


#######################################################################
# +-----------------------------------------------------------------+ #
# |                              Blocks                             | #
# +-----------------------------------------------------------------+ #
#######################################################################

Block(-8,0,-7,CONCRETE:7)
Block(-7,0,-7,CONCRETE:7)
Block(-6,0,-7,CONCRETE:7)
Block(-5,0,-7,CONCRETE:7)
Block(-4,0,-7,CONCRETE:7)
Block(-3,0,-7,CONCRETE:7)
Block(-2,0,-7,CONCRETE:7)
Block(-1,0,-7,CONCRETE:7)
Block(0,0,-7,CONCRETE:7)
Block(1,0,-7,CONCRETE:7)
Block(2,0,-7,CONCRETE:7)
Block(3,0,-7,CONCRETE:7)
Block(4,0,-7,CONCRETE:7)
Block(5,0,-7,CONCRETE:7)
Block(6,0,-7,CONCRETE:7)
Block(7,0,-7,CONCRETE:7)
Block(-8,0,-6,CONCRETE:7)
Block(-7,0,-6,CONCRETE:7)
Block(-6,0,-6,CONCRETE:7)
Block(-5,0,-6,CONCRETE:7)
Block(-4,0,-6,CONCRETE:7)
Block(-3,0,-6,CONCRETE:7)
Block(-2,0,-6,CONCRETE:7)
Block(-1,0,-6,CONCRETE:7)
Block(0,0,-6,CONCRETE:7)
Block(1,0,-6,CONCRETE:7)
Block(2,0,-6,CONCRETE:7)
Block(3,0,-6,CONCRETE:7)
Block(4,0,-6,CONCRETE:7)
Block(5,0,-6,CONCRETE:7)
Block(6,0,-6,CONCRETE:7)
Block(7,0,-6,CONCRETE:7)
Block(-8,0,-5,CONCRETE:7)
Block(-7,0,-5,CONCRETE:7)
Block(-6,0,-5,CONCRETE:7)
Block(-5,0,-5,CONCRETE:7)
Block(-4,0,-5,CONCRETE:7)
Block(-3,0,-5,CONCRETE:7)
Block(-2,0,-5,CONCRETE:7)
Block(-1,0,-5,CONCRETE:7)
Block(0,0,-5,CONCRETE:7)
Block(1,0,-5,CONCRETE:7)
Block(2,0,-5,CONCRETE:7)
Block(3,0,-5,CONCRETE:7)
Block(4,0,-5,CONCRETE:7)
Block(5,0,-5,CONCRETE:7)
Block(6,0,-5,CONCRETE:7)
Block(7,0,-5,CONCRETE:7)
Block(-8,0,-4,CONCRETE:7)
Block(-7,0,-4,CONCRETE:7)
Block(-6,0,-4,CONCRETE:7)
Block(-5,0,-4,CONCRETE:7)
Block(-4,0,-4,CONCRETE:7)
Block(-3,0,-4,CONCRETE:7)
Block(-2,0,-4,CONCRETE:7)
Block(-1,0,-4,CONCRETE:7)
Block(0,0,-4,CONCRETE:7)
Block(1,0,-4,CONCRETE:7)
Block(2,0,-4,CONCRETE:7)
Block(3,0,-4,CONCRETE:7)
Block(4,0,-4,CONCRETE:7)
Block(5,0,-4,CONCRETE:7)
Block(6,0,-4,CONCRETE:7)
Block(7,0,-4,CONCRETE:7)
Block(-8,0,-3,CONCRETE:7)
Block(-7,0,-3,CONCRETE:7)
Block(-6,0,-3,CONCRETE:7)
Block(-5,0,-3,CONCRETE:7)
Block(-4,0,-3,CONCRETE:7)
Block(-3,0,-3,CONCRETE:7)
Block(-2,0,-3,CONCRETE:7)
Block(-1,0,-3,CONCRETE:7)
Block(0,0,-3,CONCRETE:7)
Block(1,0,-3,CONCRETE:7)
Block(2,0,-3,CONCRETE:7)
Block(3,0,-3,CONCRETE:7)
Block(4,0,-3,CONCRETE:7)
Block(5,0,-3,CONCRETE:7)
Block(6,0,-3,CONCRETE:7)
Block(7,0,-3,CONCRETE:7)
Block(-8,0,-2,CONCRETE:7)
Block(-7,0,-2,CONCRETE:7)
Block(-6,0,-2,CONCRETE:7)
Block(-5,0,-2,CONCRETE:7)
Block(-4,0,-2,CONCRETE:7)
Block(-3,0,-2,CONCRETE:7)
Block(-2,0,-2,CONCRETE:7)
Block(-1,0,-2,CONCRETE:7)
Block(0,0,-2,CONCRETE:7)
Block(1,0,-2,CONCRETE:7)
Block(2,0,-2,CONCRETE:7)
Block(3,0,-2,CONCRETE:7)
Block(4,0,-2,CONCRETE:7)
Block(5,0,-2,CONCRETE:7)
Block(6,0,-2,CONCRETE:7)
Block(7,0,-2,CONCRETE:7)
Block(-8,0,-1,CONCRETE:7)
Block(-7,0,-1,CONCRETE:7)
Block(-6,0,-1,CONCRETE:7)
Block(-5,0,-1,CONCRETE:7)
Block(-4,0,-1,CONCRETE:7)
Block(-3,0,-1,CONCRETE:7)
Block(-2,0,-1,CONCRETE:7)
Block(-1,0,-1,CONCRETE:7)
Block(0,0,-1,CONCRETE:7)
Block(1,0,-1,CONCRETE:7)
Block(2,0,-1,CONCRETE:7)
Block(3,0,-1,CONCRETE:7)
Block(4,0,-1,CONCRETE:7)
Block(5,0,-1,CONCRETE:7)
Block(6,0,-1,CONCRETE:7)
Block(7,0,-1,CONCRETE:7)
Block(-8,0,0,CONCRETE:7)
Block(-7,0,0,CONCRETE:7)
Block(-6,0,0,CONCRETE:7)
Block(-5,0,0,CONCRETE:7)
Block(-4,0,0,CONCRETE:7)
Block(-3,0,0,CONCRETE:7)
Block(-2,0,0,CONCRETE:7)
Block(-1,0,0,CONCRETE:7)
Block(0,0,0,CONCRETE:7)
Block(1,0,0,CONCRETE:7)
Block(2,0,0,CONCRETE:7)
Block(3,0,0,CONCRETE:7)
Block(4,0,0,CONCRETE:7)
Block(5,0,0,CONCRETE:7)
Block(6,0,0,CONCRETE:7)
Block(7,0,0,CONCRETE:7)
Block(-8,0,1,CONCRETE:7)
Block(-7,0,1,CONCRETE:7)
Block(-6,0,1,CONCRETE:7)
Block(-5,0,1,CONCRETE:7)
Block(-4,0,1,CONCRETE:7)
Block(-3,0,1,CONCRETE:7)
Block(-2,0,1,CONCRETE:7)
Block(-1,0,1,CONCRETE:7)
Block(0,0,1,CONCRETE:7)
Block(1,0,1,CONCRETE:7)
Block(2,0,1,CONCRETE:7)
Block(3,0,1,CONCRETE:7)
Block(4,0,1,CONCRETE:7)
Block(5,0,1,CONCRETE:7)
Block(6,0,1,CONCRETE:7)
Block(7,0,1,CONCRETE:7)
Block(-8,0,2,CONCRETE:7)
Block(-7,0,2,CONCRETE:7)
Block(-6,0,2,CONCRETE:7)
Block(-5,0,2,CONCRETE:7)
Block(-4,0,2,CONCRETE:7)
Block(-3,0,2,CONCRETE:7)
Block(-2,0,2,CONCRETE:7)
Block(-1,0,2,CONCRETE:7)
Block(0,0,2,CONCRETE:7)
Block(1,0,2,CONCRETE:7)
Block(2,0,2,CONCRETE:7)
Block(3,0,2,CONCRETE:7)
Block(4,0,2,CONCRETE:7)
Block(5,0,2,CONCRETE:7)
Block(6,0,2,CONCRETE:7)
Block(7,0,2,CONCRETE:7)
Block(-8,0,3,CONCRETE:7)
Block(-7,0,3,CONCRETE:7)
Block(-6,0,3,CONCRETE:7)
Block(-5,0,3,CONCRETE:7)
Block(-4,0,3,CONCRETE:7)
Block(-3,0,3,CONCRETE:7)
Block(-2,0,3,CONCRETE:7)
Block(-1,0,3,CONCRETE:7)
Block(0,0,3,CONCRETE:7)
Block(1,0,3,CONCRETE:7)
Block(2,0,3,CONCRETE:7)
Block(3,0,3,CONCRETE:7)
Block(4,0,3,CONCRETE:7)
Block(5,0,3,CONCRETE:7)
Block(6,0,3,CONCRETE:7)
Block(7,0,3,CONCRETE:7)
Block(-8,0,4,CONCRETE:7)
Block(-7,0,4,CONCRETE:7)
Block(-6,0,4,CONCRETE:7)
Block(-5,0,4,CONCRETE:7)
Block(-4,0,4,CONCRETE:7)
Block(-3,0,4,CONCRETE:7)
Block(-2,0,4,CONCRETE:7)
Block(-1,0,4,CONCRETE:7)
Block(0,0,4,CONCRETE:7)
Block(1,0,4,CONCRETE:7)
Block(2,0,4,CONCRETE:7)
Block(3,0,4,CONCRETE:7)
Block(4,0,4,CONCRETE:7)
Block(5,0,4,CONCRETE:7)
Block(6,0,4,CONCRETE:7)
Block(7,0,4,CONCRETE:7)
Block(-8,0,5,CONCRETE:7)
Block(-7,0,5,CONCRETE:7)
Block(-6,0,5,CONCRETE:7)
Block(-5,0,5,CONCRETE:7)
Block(-4,0,5,CONCRETE:7)
Block(-3,0,5,CONCRETE:7)
Block(-2,0,5,CONCRETE:7)
Block(-1,0,5,CONCRETE:7)
Block(0,0,5,CONCRETE:7)
Block(1,0,5,CONCRETE:7)
Block(2,0,5,CONCRETE:7)
Block(3,0,5,CONCRETE:7)
Block(4,0,5,CONCRETE:7)
Block(5,0,5,CONCRETE:7)
Block(6,0,5,CONCRETE:7)
Block(7,0,5,CONCRETE:7)
Block(-8,0,6,CONCRETE:7)
Block(-7,0,6,CONCRETE:7)
Block(-6,0,6,CONCRETE:7)
Block(-5,0,6,CONCRETE:7)
Block(-4,0,6,CONCRETE:7)
Block(-3,0,6,CONCRETE:7)
Block(-2,0,6,CONCRETE:7)
Block(-1,0,6,CONCRETE:7)
Block(0,0,6,CONCRETE:7)
Block(1,0,6,CONCRETE:7)
Block(2,0,6,CONCRETE:7)
Block(3,0,6,CONCRETE:7)
Block(4,0,6,CONCRETE:7)
Block(5,0,6,CONCRETE:7)
Block(6,0,6,CONCRETE:7)
Block(7,0,6,CONCRETE:7)
Block(-8,0,7,CONCRETE:7)
Block(-7,0,7,CONCRETE:7)
Block(-6,0,7,CONCRETE:7)
Block(-5,0,7,CONCRETE:7)
Block(-4,0,7,CONCRETE:7)
Block(-3,0,7,CONCRETE:7)
Block(-2,0,7,CONCRETE:7)
Block(-1,0,7,CONCRETE:7)
Block(0,0,7,CONCRETE:7)
Block(1,0,7,CONCRETE:7)
Block(2,0,7,CONCRETE:7)
Block(3,0,7,CONCRETE:7)
Block(4,0,7,CONCRETE:7)
Block(5,0,7,CONCRETE:7)
Block(6,0,7,CONCRETE:7)
Block(7,0,7,CONCRETE:7)
Block(-8,0,8,CONCRETE:7)
Block(-7,0,8,CONCRETE:7)
Block(-6,0,8,CONCRETE:7)
Block(-5,0,8,CONCRETE:7)
Block(-4,0,8,CONCRETE:7)
Block(-3,0,8,CONCRETE:7)
Block(-2,0,8,CONCRETE:7)
Block(-1,0,8,CONCRETE:7)
Block(0,0,8,CONCRETE:7)
Block(1,0,8,CONCRETE:7)
Block(2,0,8,CONCRETE:7)
Block(3,0,8,CONCRETE:7)
Block(4,0,8,CONCRETE:7)
Block(5,0,8,CONCRETE:7)
Block(6,0,8,CONCRETE:7)
Block(7,0,8,CONCRETE:7)
Block(-6,1,-1,STONE_BRICKS:0)
Block(-5,1,-1,STONE_BRICKS:0)
Block(-4,1,-1,STONE_BRICKS:0)
Block(-3,1,-1,STONE_BRICKS:0)
Block(-2,1,-1,STONE_BRICKS:0)
Block(-1,1,-1,STONE_BRICKS:0)
Block(0,1,-1,STONE_BRICKS:0)
Block(1,1,-1,STONE_BRICKS:0)
Block(2,1,-1,STONE_BRICKS:0)
Block(3,1,-1,STONE_BRICKS:0)
Block(4,1,-1,STONE_BRICKS:0)
Block(5,1,-1,STONE_BRICKS:0)
Block(6,1,-1,STONE_BRICKS:0)
Block(-6,1,0,STONE_BRICKS:0)
Block(-5,1,0,STONE_BRICKS:0)
Block(-4,1,0,STONE_BRICKS:0)
Block(-3,1,0,STONE_BRICKS:0)
Block(-2,1,0,STONE_BRICKS:0)
Block(-1,1,0,STONE_BRICKS:0)
Block(0,1,0,STONE_BRICKS:0)
Block(1,1,0,STONE_BRICKS:0)
Block(2,1,0,STONE_BRICKS:0)
Block(3,1,0,STONE_BRICKS:0)
Block(4,1,0,STONE_BRICKS:0)
Block(5,1,0,STONE_BRICKS:0)
Block(6,1,0,STONE_BRICKS:0)
Block(-6,1,1,STONE_BRICKS:0)
Block(-5,1,1,STONE_BRICKS:0)
Block(-4,1,1,STONE_BRICKS:0)
Block(-3,1,1,STONE_BRICKS:0)
Block(-2,1,1,STONE_BRICKS:0)
Block(-1,1,1,STONE_BRICKS:0)
Block(0,1,1,STONE_BRICKS:0)
Block(1,1,1,STONE_BRICKS:0)
Block(2,1,1,STONE_BRICKS:0)
Block(3,1,1,STONE_BRICKS:0)
Block(4,1,1,STONE_BRICKS:0)
Block(5,1,1,STONE_BRICKS:0)
Block(6,1,1,STONE_BRICKS:0)
Block(-6,1,2,STONE_BRICKS:0)
Block(-5,1,2,STONE_BRICKS:0)
Block(-4,1,2,STONE_BRICKS:0)
Block(-3,1,2,STONE_BRICKS:0)
Block(-2,1,2,STONE_BRICKS:0)
Block(-1,1,2,STONE_BRICKS:0)
Block(0,1,2,STONE_BRICKS:0)
Block(1,1,2,STONE_BRICKS:0)
Block(2,1,2,STONE_BRICKS:0)
Block(3,1,2,STONE_BRICKS:0)
Block(4,1,2,STONE_BRICKS:0)
Block(5,1,2,STONE_BRICKS:0)
Block(6,1,2,STONE_BRICKS:0)
Block(-6,1,3,STONE_BRICKS:0)
Block(-5,1,3,STONE_BRICKS:0)
Block(-4,1,3,STONE_BRICKS:0)
Block(-3,1,3,STONE_BRICKS:0)
Block(-2,1,3,STONE_BRICKS:0)
Block(-1,1,3,STONE_BRICKS:0)
Block(0,1,3,STONE_BRICKS:0)
Block(1,1,3,STONE_BRICKS:0)
Block(2,1,3,STONE_BRICKS:0)
Block(3,1,3,STONE_BRICKS:0)
Block(4,1,3,STONE_BRICKS:0)
Block(5,1,3,STONE_BRICKS:0)
Block(6,1,3,STONE_BRICKS:0)
Block(-6,1,4,STONE_BRICKS:0)
Block(-5,1,4,STONE_BRICKS:0)
Block(-4,1,4,STONE_BRICKS:0)
Block(-3,1,4,STONE_BRICKS:0)
Block(-2,1,4,STONE_BRICKS:0)
Block(-1,1,4,STONE_BRICKS:0)
Block(0,1,4,STONE_BRICKS:0)
Block(1,1,4,STONE_BRICKS:0)
Block(2,1,4,STONE_BRICKS:0)
Block(3,1,4,STONE_BRICKS:0)
Block(4,1,4,STONE_BRICKS:0)
Block(5,1,4,STONE_BRICKS:0)
Block(6,1,4,STONE_BRICKS:0)
Block(-6,1,5,STONE_BRICKS:0)
Block(-5,1,5,STONE_BRICKS:0)
Block(-4,1,5,STONE_BRICKS:0)
Block(-3,1,5,STONE_BRICKS:0)
Block(-2,1,5,STONE_BRICKS:0)
Block(-1,1,5,STONE_BRICKS:0)
Block(0,1,5,STONE_BRICKS:0)
Block(1,1,5,STONE_BRICKS:0)
Block(2,1,5,STONE_BRICKS:0)
Block(3,1,5,STONE_BRICKS:0)
Block(4,1,5,STONE_BRICKS:0)
Block(5,1,5,STONE_BRICKS:0)
Block(6,1,5,STONE_BRICKS:0)
Block(-6,1,6,STONE_BRICKS:0)
Block(-5,1,6,STONE_BRICKS:0)
Block(-4,1,6,STONE_BRICKS:0)
Block(-3,1,6,STONE_BRICKS:0)
Block(-2,1,6,STONE_BRICKS:0)
Block(-1,1,6,STONE_BRICKS:0)
Block(0,1,6,STONE_BRICKS:0)
Block(1,1,6,STONE_BRICKS:0)
Block(2,1,6,STONE_BRICKS:0)
Block(3,1,6,STONE_BRICKS:0)
Block(4,1,6,STONE_BRICKS:0)
Block(5,1,6,STONE_BRICKS:0)
Block(6,1,6,STONE_BRICKS:0)
Block(-6,1,7,STONE_BRICKS:0)
Block(-5,1,7,STONE_BRICKS:0)
Block(-4,1,7,STONE_BRICKS:0)
Block(-3,1,7,STONE_BRICKS:0)
Block(-2,1,7,STONE_BRICKS:0)
Block(-1,1,7,STONE_BRICKS:0)
Block(0,1,7,STONE_BRICKS:0)
Block(1,1,7,STONE_BRICKS:0)
Block(2,1,7,STONE_BRICKS:0)
Block(3,1,7,STONE_BRICKS:0)
Block(4,1,7,STONE_BRICKS:0)
Block(5,1,7,STONE_BRICKS:0)
Block(6,1,7,STONE_BRICKS:0)
Block(-6,2,-1,BRICK:0)
Block(-5,2,-1,BRICK:0)
Block(-4,2,-1,BRICK:0)
Block(-3,2,-1,AIR:0)
Block(-2,2,-1,AIR:0)
Block(-1,2,-1,AIR:0)
Block(0,2,-1,AIR:0)
Block(1,2,-1,AIR:0)
Block(2,2,-1,AIR:0)
Block(3,2,-1,AIR:0)
Block(4,2,-1,BRICK:0)
Block(5,2,-1,BRICK:0)
Block(6,2,-1,BRICK:0)
Block(-6,2,0,BRICK:0)
Block(6,2,0,BRICK:0)
Block(-6,2,1,BRICK:0)
Block(6,2,1,BRICK:0)
Block(-6,2,2,BRICK:0)
Block(6,2,2,BRICK:0)
Block(-6,2,3,BRICK:0)
Block(6,2,3,BRICK:0)
Block(-6,2,4,BRICK:0)
Block(6,2,4,BRICK:0)
Block(-6,2,5,BRICK:0)
Block(6,2,5,BRICK:0)
Block(-6,2,6,BRICK:0)
Block(6,2,6,BRICK:0)
Block(-6,2,7,BRICK:0)
Block(-5,2,7,BRICK:0)
Block(-4,2,7,BRICK:0)
Block(-3,2,7,BRICK:0)
Block(-2,2,7,BRICK:0)
Block(-1,2,7,BRICK:0)
Block(0,2,7,BRICK:0)
Block(1,2,7,BRICK:0)
Block(2,2,7,BRICK:0)
Block(3,2,7,BRICK:0)
Block(4,2,7,BRICK:0)
Block(5,2,7,BRICK:0)
Block(6,2,7,BRICK:0)
Block(-6,3,-1,BRICK:0)
Block(-5,3,-1,BRICK:0)
Block(-4,3,-1,BRICK:0)
Block(-3,3,-1,AIR:0)
Block(-2,3,-1,AIR:0)
Block(-1,3,-1,AIR:0)
Block(0,3,-1,AIR:0)
Block(1,3,-1,AIR:0)
Block(2,3,-1,AIR:0)
Block(3,3,-1,AIR:0)
Block(4,3,-1,BRICK:0)
Block(5,3,-1,BRICK:0)
Block(6,3,-1,BRICK:0)
Block(-6,3,0,BRICK:0)
Block(6,3,0,BRICK:0)
Block(-6,3,1,BRICK:0)
Block(6,3,1,BRICK:0)
Block(-6,3,2,BRICK:0)
Block(6,3,2,BRICK:0)
Block(-6,3,3,BRICK:0)
Block(6,3,3,BRICK:0)
Block(-6,3,4,BRICK:0)
Block(6,3,4,BRICK:0)
Block(-6,3,5,BRICK:0)
Block(6,3,5,BRICK:0)
Block(-6,3,6,BRICK:0)
Block(6,3,6,BRICK:0)
Block(-6,3,7,BRICK:0)
Block(-5,3,7,BRICK:0)
Block(-4,3,7,BRICK:0)
Block(-3,3,7,BRICK:0)
Block(-2,3,7,BRICK:0)
Block(-1,3,7,BRICK:0)
Block(0,3,7,BRICK:0)
Block(1,3,7,BRICK:0)
Block(2,3,7,BRICK:0)
Block(3,3,7,BRICK:0)
Block(4,3,7,BRICK:0)
Block(5,3,7,BRICK:0)
Block(6,3,7,BRICK:0)
Block(-6,4,-1,BRICK:0)
Block(-5,4,-1,BRICK:0)
Block(-4,4,-1,BRICK:0)
Block(-3,4,-1,AIR:0)
Block(-2,4,-1,AIR:0)
Block(-1,4,-1,AIR:0)
Block(0,4,-1,AIR:0)
Block(1,4,-1,AIR:0)
Block(2,4,-1,AIR:0)
Block(3,4,-1,AIR:0)
Block(4,4,-1,BRICK:0)
Block(5,4,-1,BRICK:0)
Block(6,4,-1,BRICK:0)
Block(-6,4,0,BRICK:0)
Block(6,4,0,BRICK:0)
Block(-6,4,1,BRICK:0)
Block(6,4,1,BRICK:0)
Block(-6,4,2,BRICK:0)
Block(6,4,2,BRICK:0)
Block(-6,4,3,BRICK:0)
Block(6,4,3,BRICK:0)
Block(-6,4,4,BRICK:0)
Block(6,4,4,BRICK:0)
Block(-6,4,5,BRICK:0)
Block(6,4,5,BRICK:0)
Block(-6,4,6,BRICK:0)
Block(6,4,6,BRICK:0)
Block(-6,4,7,BRICK:0)
Block(-5,4,7,BRICK:0)
Block(-4,4,7,BRICK:0)
Block(-3,4,7,BRICK:0)
Block(-2,4,7,BRICK:0)
Block(-1,4,7,BRICK:0)
Block(0,4,7,BRICK:0)
Block(1,4,7,BRICK:0)
Block(2,4,7,BRICK:0)
Block(3,4,7,BRICK:0)
Block(4,4,7,BRICK:0)
Block(5,4,7,BRICK:0)
Block(6,4,7,BRICK:0)
Block(-6,5,-1,BRICK:0)
Block(-5,5,-1,BRICK:0)
Block(-4,5,-1,BRICK:0)
Block(-3,5,-1,AIR:0)
Block(-2,5,-1,AIR:0)
Block(-1,5,-1,AIR:0)
Block(0,5,-1,AIR:0)
Block(1,5,-1,AIR:0)
Block(2,5,-1,AIR:0)
Block(3,5,-1,AIR:0)
Block(4,5,-1,BRICK:0)
Block(5,5,-1,BRICK:0)
Block(6,5,-1,BRICK:0)
Block(-6,5,0,BRICK:0)
Block(6,5,0,BRICK:0)
Block(-6,5,1,BRICK:0)
Block(6,5,1,BRICK:0)
Block(-6,5,2,BRICK:0)
Block(6,5,2,BRICK:0)
Block(-6,5,3,BRICK:0)
Block(6,5,3,BRICK:0)
Block(-6,5,4,BRICK:0)
Block(6,5,4,BRICK:0)
Block(-6,5,5,BRICK:0)
Block(6,5,5,BRICK:0)
Block(-6,5,6,BRICK:0)
Block(6,5,6,BRICK:0)
Block(-6,5,7,BRICK:0)
Block(-5,5,7,BRICK:0)
Block(-4,5,7,BRICK:0)
Block(-3,5,7,BRICK:0)
Block(-2,5,7,BRICK:0)
Block(-1,5,7,BRICK:0)
Block(0,5,7,BRICK:0)
Block(1,5,7,BRICK:0)
Block(2,5,7,BRICK:0)
Block(3,5,7,BRICK:0)
Block(4,5,7,BRICK:0)
Block(5,5,7,BRICK:0)
Block(6,5,7,BRICK:0)
Block(-6,6,-1,BRICK:0)
Block(-5,6,-1,BRICK:0)
Block(-4,6,-1,BRICK:0)
Block(-3,6,-1,BRICK:0)
Block(-2,6,-1,BRICK:0)
Block(-1,6,-1,BRICK:0)
Block(0,6,-1,BRICK:0)
Block(1,6,-1,BRICK:0)
Block(2,6,-1,BRICK:0)
Block(3,6,-1,BRICK:0)
Block(4,6,-1,BRICK:0)
Block(5,6,-1,BRICK:0)
Block(6,6,-1,BRICK:0)
Block(-6,6,0,BRICK:0)
Block(6,6,0,BRICK:0)
Block(-6,6,1,BRICK:0)
Block(6,6,1,BRICK:0)
Block(-6,6,2,BRICK:0)
Block(6,6,2,BRICK:0)
Block(-6,6,3,BRICK:0)
Block(6,6,3,BRICK:0)
Block(-6,6,4,BRICK:0)
Block(6,6,4,BRICK:0)
Block(-6,6,5,BRICK:0)
Block(6,6,5,BRICK:0)
Block(-6,6,6,BRICK:0)
Block(6,6,6,BRICK:0)
Block(-6,6,7,BRICK:0)
Block(-5,6,7,BRICK:0)
Block(-4,6,7,BRICK:0)
Block(-3,6,7,BRICK:0)
Block(-2,6,7,BRICK:0)
Block(-1,6,7,BRICK:0)
Block(0,6,7,BRICK:0)
Block(1,6,7,BRICK:0)
Block(2,6,7,BRICK:0)
Block(3,6,7,BRICK:0)
Block(4,6,7,BRICK:0)
Block(5,6,7,BRICK:0)
Block(6,6,7,BRICK:0)
Block(-7,7,-2,CONCRETE:8)
Block(-6,7,-2,CONCRETE:8)
Block(-5,7,-2,CONCRETE:8)
Block(-4,7,-2,CONCRETE:8)
Block(-3,7,-2,CONCRETE:8)
Block(-2,7,-2,CONCRETE:8)
Block(-1,7,-2,CONCRETE:8)
Block(0,7,-2,CONCRETE:8)
Block(1,7,-2,CONCRETE:8)
Block(2,7,-2,CONCRETE:8)
Block(3,7,-2,CONCRETE:8)
Block(4,7,-2,CONCRETE:8)
Block(5,7,-2,CONCRETE:8)
Block(6,7,-2,CONCRETE:8)
Block(7,7,-2,CONCRETE:8)
Block(-7,7,-1,CONCRETE:8)
Block(-6,7,-1,CONCRETE:8)
Block(-5,7,-1,CONCRETE:8)
Block(-4,7,-1,CONCRETE:8)
Block(-3,7,-1,CONCRETE:8)
Block(-2,7,-1,CONCRETE:8)
Block(-1,7,-1,CONCRETE:8)
Block(0,7,-1,CONCRETE:8)
Block(1,7,-1,CONCRETE:8)
Block(2,7,-1,CONCRETE:8)
Block(3,7,-1,CONCRETE:8)
Block(4,7,-1,CONCRETE:8)
Block(5,7,-1,CONCRETE:8)
Block(6,7,-1,CONCRETE:8)
Block(7,7,-1,CONCRETE:8)
Block(-7,7,0,CONCRETE:8)
Block(-6,7,0,CONCRETE:8)
Block(-5,7,0,CONCRETE:8)
Block(-4,7,0,CONCRETE:8)
Block(-3,7,0,CONCRETE:8)
Block(-2,7,0,CONCRETE:8)
Block(-1,7,0,CONCRETE:8)
Block(0,7,0,CONCRETE:8)
Block(1,7,0,CONCRETE:8)
Block(2,7,0,CONCRETE:8)
Block(3,7,0,CONCRETE:8)
Block(4,7,0,CONCRETE:8)
Block(5,7,0,CONCRETE:8)
Block(6,7,0,CONCRETE:8)
Block(7,7,0,CONCRETE:8)
Block(-7,7,1,CONCRETE:8)
Block(-6,7,1,CONCRETE:8)
Block(-5,7,1,CONCRETE:8)
Block(-4,7,1,CONCRETE:8)
Block(-3,7,1,CONCRETE:8)
Block(-2,7,1,CONCRETE:8)
Block(-1,7,1,CONCRETE:8)
Block(0,7,1,CONCRETE:8)
Block(1,7,1,CONCRETE:8)
Block(2,7,1,CONCRETE:8)
Block(3,7,1,CONCRETE:8)
Block(4,7,1,CONCRETE:8)
Block(5,7,1,CONCRETE:8)
Block(6,7,1,CONCRETE:8)
Block(7,7,1,CONCRETE:8)
Block(-7,7,2,CONCRETE:8)
Block(-6,7,2,CONCRETE:8)
Block(-5,7,2,CONCRETE:8)
Block(-4,7,2,CONCRETE:8)
Block(-3,7,2,CONCRETE:8)
Block(-2,7,2,CONCRETE:8)
Block(-1,7,2,CONCRETE:8)
Block(0,7,2,CONCRETE:8)
Block(1,7,2,CONCRETE:8)
Block(2,7,2,CONCRETE:8)
Block(3,7,2,CONCRETE:8)
Block(4,7,2,CONCRETE:8)
Block(5,7,2,CONCRETE:8)
Block(6,7,2,CONCRETE:8)
Block(7,7,2,CONCRETE:8)
Block(-7,7,3,CONCRETE:8)
Block(-6,7,3,CONCRETE:8)
Block(-5,7,3,CONCRETE:8)
Block(-4,7,3,CONCRETE:8)
Block(-3,7,3,CONCRETE:8)
Block(-2,7,3,CONCRETE:8)
Block(-1,7,3,CONCRETE:8)
Block(0,7,3,CONCRETE:8)
Block(1,7,3,CONCRETE:8)
Block(2,7,3,CONCRETE:8)
Block(3,7,3,CONCRETE:8)
Block(4,7,3,CONCRETE:8)
Block(5,7,3,CONCRETE:8)
Block(6,7,3,CONCRETE:8)
Block(7,7,3,CONCRETE:8)
Block(-7,7,4,CONCRETE:8)
Block(-6,7,4,CONCRETE:8)
Block(-5,7,4,CONCRETE:8)
Block(-4,7,4,CONCRETE:8)
Block(-3,7,4,CONCRETE:8)
Block(-2,7,4,CONCRETE:8)
Block(-1,7,4,CONCRETE:8)
Block(0,7,4,CONCRETE:8)
Block(1,7,4,CONCRETE:8)
Block(2,7,4,CONCRETE:8)
Block(3,7,4,CONCRETE:8)
Block(4,7,4,CONCRETE:8)
Block(5,7,4,CONCRETE:8)
Block(6,7,4,CONCRETE:8)
Block(7,7,4,CONCRETE:8)
Block(-7,7,5,CONCRETE:8)
Block(-6,7,5,CONCRETE:8)
Block(-5,7,5,CONCRETE:8)
Block(-4,7,5,CONCRETE:8)
Block(-3,7,5,CONCRETE:8)
Block(-2,7,5,CONCRETE:8)
Block(-1,7,5,CONCRETE:8)
Block(0,7,5,CONCRETE:8)
Block(1,7,5,CONCRETE:8)
Block(2,7,5,CONCRETE:8)
Block(3,7,5,CONCRETE:8)
Block(4,7,5,CONCRETE:8)
Block(5,7,5,CONCRETE:8)
Block(6,7,5,CONCRETE:8)
Block(7,7,5,CONCRETE:8)
Block(-7,7,6,CONCRETE:8)
Block(-6,7,6,CONCRETE:8)
Block(-5,7,6,CONCRETE:8)
Block(-4,7,6,CONCRETE:8)
Block(-3,7,6,CONCRETE:8)
Block(-2,7,6,CONCRETE:8)
Block(-1,7,6,CONCRETE:8)
Block(0,7,6,CONCRETE:8)
Block(1,7,6,CONCRETE:8)
Block(2,7,6,CONCRETE:8)
Block(3,7,6,CONCRETE:8)
Block(4,7,6,CONCRETE:8)
Block(5,7,6,CONCRETE:8)
Block(6,7,6,CONCRETE:8)
Block(7,7,6,CONCRETE:8)
Block(-7,7,7,CONCRETE:8)
Block(-6,7,7,CONCRETE:8)
Block(-5,7,7,CONCRETE:8)
Block(-4,7,7,CONCRETE:8)
Block(-3,7,7,CONCRETE:8)
Block(-2,7,7,CONCRETE:8)
Block(-1,7,7,CONCRETE:8)
Block(0,7,7,CONCRETE:8)
Block(1,7,7,CONCRETE:8)
Block(2,7,7,CONCRETE:8)
Block(3,7,7,CONCRETE:8)
Block(4,7,7,CONCRETE:8)
Block(5,7,7,CONCRETE:8)
Block(6,7,7,CONCRETE:8)
Block(7,7,7,CONCRETE:8)
Block(-7,7,8,CONCRETE:8)
Block(-6,7,8,CONCRETE:8)
Block(-5,7,8,CONCRETE:8)
Block(-4,7,8,CONCRETE:8)
Block(-3,7,8,CONCRETE:8)
Block(-2,7,8,CONCRETE:8)
Block(-1,7,8,CONCRETE:8)
Block(0,7,8,CONCRETE:8)
Block(1,7,8,CONCRETE:8)
Block(2,7,8,CONCRETE:8)
Block(3,7,8,CONCRETE:8)
Block(4,7,8,CONCRETE:8)
Block(5,7,8,CONCRETE:8)
Block(6,7,8,CONCRETE:8)
Block(7,7,8,CONCRETE:8)

#######################################################################
# +-----------------------------------------------------------------+ #
# |                             Branches                            | #
# +-----------------------------------------------------------------+ #
#######################################################################


#######################################################################
# +-----------------------------------------------------------------+ #
# |                             Entities                            | #
# +-----------------------------------------------------------------+ #
#######################################################################


#######################################################################
# +-----------------------------------------------------------------+ #
# |                            Particles                            | #
# +-----------------------------------------------------------------+ #
#######################################################################


#######################################################################
# +-----------------------------------------------------------------+ #
# |                             Spawners                            | #
# +-----------------------------------------------------------------+ #
#######################################################################


#######################################################################
# +-----------------------------------------------------------------+ #
# |                             ModData                             | #
# +-----------------------------------------------------------------+ #
#######################################################################

