
#######################################################################
# +-----------------------------------------------------------------+ #
# |                            BO4 object                           | #
# +-----------------------------------------------------------------+ #
#######################################################################

Author: SRP Manhunt

Description: Small private house facing the outskirts road

SettingsMode: WriteWithoutComments


#######################################################################
# +-----------------------------------------------------------------+ #
# |                          Main settings                          | #
# +-----------------------------------------------------------------+ #
#######################################################################

FixedRotation: 

Frequency: 0

SpawnHeight: highestBlock

UseCenterForHighestBlock: true

##############################
# Height Limits for the BO4. #
##############################

MinHeight: 0

MaxHeight: 255

InheritBO3: 

InheritBO3Rotation: NORTH

OverrideChildSettings: true

OverrideParentHeight: false

CanOverride: true

BranchFrequency: 0

BranchFrequencyGroup: 

MustBeBelowOther: false

MustBeInside: 

CannotBeInside: 

ReplacesBO3: 

MustBeInsideWorldBorders: true

CanSpawnOnWater: true

SpawnOnWaterOnly: false

SpawnUnderWater: false

SpawnAtWaterLevel: false

HeightOffset: 0

RemoveAir: false

ReplaceAbove: 

ReplaceBelow: DIRT

ReplaceWithBiomeBlocks: false

ReplaceWithSurfaceBlock: GRASS

ReplaceWithGroundBlock: DIRT

ReplaceWithStoneBlock: STONE

SmoothRadius: 0

SmoothHeightOffset: 0

SmoothStartTop: false

SmoothStartWood: false

SmoothingSurfaceBlock: 

SmoothingGroundBlock: 

BO3Group: 

IsSpawnPoint: false

DoReplaceBlocks: true


#######################################################################
# +-----------------------------------------------------------------+ #
# |                              Blocks                             | #
# +-----------------------------------------------------------------+ #
#######################################################################

Block(-8,0,-7,GRASS:0)
Block(-7,0,-7,GRASS:0)
Block(-6,0,-7,GRASS:0)
Block(-5,0,-7,GRASS:0)
Block(-4,0,-7,GRASS:0)
Block(-3,0,-7,GRASS:0)
Block(-2,0,-7,GRAVEL:0)
Block(-1,0,-7,GRAVEL:0)
Block(0,0,-7,GRAVEL:0)
Block(1,0,-7,GRAVEL:0)
Block(2,0,-7,GRAVEL:0)
Block(3,0,-7,GRASS:0)
Block(4,0,-7,GRASS:0)
Block(5,0,-7,GRASS:0)
Block(6,0,-7,GRASS:0)
Block(7,0,-7,GRASS:0)
Block(-8,0,-6,GRASS:0)
Block(-7,0,-6,GRASS:0)
Block(-6,0,-6,GRASS:0)
Block(-5,0,-6,GRASS:0)
Block(-4,0,-6,GRASS:0)
Block(-3,0,-6,GRASS:0)
Block(-2,0,-6,GRAVEL:0)
Block(-1,0,-6,GRAVEL:0)
Block(0,0,-6,GRAVEL:0)
Block(1,0,-6,GRAVEL:0)
Block(2,0,-6,GRAVEL:0)
Block(3,0,-6,GRASS:0)
Block(4,0,-6,GRASS:0)
Block(5,0,-6,GRASS:0)
Block(6,0,-6,GRASS:0)
Block(7,0,-6,GRASS:0)
Block(-8,0,-5,GRASS:0)
Block(-7,0,-5,GRASS:0)
Block(-6,0,-5,GRASS:0)
Block(-5,0,-5,GRASS:0)
Block(-4,0,-5,GRASS:0)
Block(-3,0,-5,GRASS:0)
Block(-2,0,-5,GRAVEL:0)
Block(-1,0,-5,GRAVEL:0)
Block(0,0,-5,GRAVEL:0)
Block(1,0,-5,GRAVEL:0)
Block(2,0,-5,GRAVEL:0)
Block(3,0,-5,GRASS:0)
Block(4,0,-5,GRASS:0)
Block(5,0,-5,GRASS:0)
Block(6,0,-5,GRASS:0)
Block(7,0,-5,GRASS:0)
Block(-8,0,-4,GRASS:0)
Block(-7,0,-4,GRASS:0)
Block(-6,0,-4,GRASS:0)
Block(-5,0,-4,GRASS:0)
Block(-4,0,-4,GRASS:0)
Block(-3,0,-4,GRASS:0)
Block(-2,0,-4,GRAVEL:0)
Block(-1,0,-4,GRAVEL:0)
Block(0,0,-4,GRAVEL:0)
Block(1,0,-4,GRAVEL:0)
Block(2,0,-4,GRAVEL:0)
Block(3,0,-4,GRASS:0)
Block(4,0,-4,GRASS:0)
Block(5,0,-4,GRASS:0)
Block(6,0,-4,GRASS:0)
Block(7,0,-4,GRASS:0)
Block(-8,0,-3,GRASS:0)
Block(-7,0,-3,GRASS:0)
Block(-6,0,-3,GRASS:0)
Block(-5,0,-3,GRASS:0)
Block(-4,0,-3,GRASS:0)
Block(-3,0,-3,GRASS:0)
Block(-2,0,-3,GRAVEL:0)
Block(-1,0,-3,GRAVEL:0)
Block(0,0,-3,GRAVEL:0)
Block(1,0,-3,GRAVEL:0)
Block(2,0,-3,GRAVEL:0)
Block(3,0,-3,GRASS:0)
Block(4,0,-3,GRASS:0)
Block(5,0,-3,GRASS:0)
Block(6,0,-3,GRASS:0)
Block(7,0,-3,GRASS:0)
Block(-8,0,-2,GRASS:0)
Block(-7,0,-2,GRASS:0)
Block(-6,0,-2,GRASS:0)
Block(-5,0,-2,GRASS:0)
Block(-4,0,-2,GRASS:0)
Block(-3,0,-2,GRASS:0)
Block(-2,0,-2,GRAVEL:0)
Block(-1,0,-2,GRAVEL:0)
Block(0,0,-2,GRAVEL:0)
Block(1,0,-2,GRAVEL:0)
Block(2,0,-2,GRAVEL:0)
Block(3,0,-2,GRASS:0)
Block(4,0,-2,GRASS:0)
Block(5,0,-2,GRASS:0)
Block(6,0,-2,GRASS:0)
Block(7,0,-2,GRASS:0)
Block(-8,0,-1,GRASS:0)
Block(-7,0,-1,GRASS:0)
Block(-6,0,-1,GRASS:0)
Block(-5,0,-1,GRASS:0)
Block(-4,0,-1,GRASS:0)
Block(-3,0,-1,GRASS:0)
Block(-2,0,-1,GRASS:0)
Block(-1,0,-1,GRASS:0)
Block(0,0,-1,GRASS:0)
Block(1,0,-1,GRASS:0)
Block(2,0,-1,GRASS:0)
Block(3,0,-1,GRASS:0)
Block(4,0,-1,GRASS:0)
Block(5,0,-1,GRASS:0)
Block(6,0,-1,GRASS:0)
Block(7,0,-1,GRASS:0)
Block(-8,0,0,GRASS:0)
Block(-7,0,0,GRASS:0)
Block(-6,0,0,GRASS:0)
Block(-5,0,0,GRASS:0)
Block(-4,0,0,GRASS:0)
Block(-3,0,0,GRASS:0)
Block(-2,0,0,GRASS:0)
Block(-1,0,0,GRASS:0)
Block(0,0,0,GRASS:0)
Block(1,0,0,GRASS:0)
Block(2,0,0,GRASS:0)
Block(3,0,0,GRASS:0)
Block(4,0,0,GRASS:0)
Block(5,0,0,GRASS:0)
Block(6,0,0,GRASS:0)
Block(7,0,0,GRASS:0)
Block(-8,0,1,GRASS:0)
Block(-7,0,1,GRASS:0)
Block(-6,0,1,GRASS:0)
Block(-5,0,1,GRASS:0)
Block(-4,0,1,GRASS:0)
Block(-3,0,1,GRASS:0)
Block(-2,0,1,GRASS:0)
Block(-1,0,1,GRASS:0)
Block(0,0,1,GRASS:0)
Block(1,0,1,GRASS:0)
Block(2,0,1,GRASS:0)
Block(3,0,1,GRASS:0)
Block(4,0,1,GRASS:0)
Block(5,0,1,GRASS:0)
Block(6,0,1,GRASS:0)
Block(7,0,1,GRASS:0)
Block(-8,0,2,GRASS:0)
Block(-7,0,2,GRASS:0)
Block(-6,0,2,GRASS:0)
Block(-5,0,2,GRASS:0)
Block(-4,0,2,GRASS:0)
Block(-3,0,2,GRASS:0)
Block(-2,0,2,GRASS:0)
Block(-1,0,2,GRASS:0)
Block(0,0,2,GRASS:0)
Block(1,0,2,GRASS:0)
Block(2,0,2,GRASS:0)
Block(3,0,2,GRASS:0)
Block(4,0,2,GRASS:0)
Block(5,0,2,GRASS:0)
Block(6,0,2,GRASS:0)
Block(7,0,2,GRASS:0)
Block(-8,0,3,GRASS:0)
Block(-7,0,3,GRASS:0)
Block(-6,0,3,GRASS:0)
Block(-5,0,3,GRASS:0)
Block(-4,0,3,GRASS:0)
Block(-3,0,3,GRASS:0)
Block(-2,0,3,GRASS:0)
Block(-1,0,3,GRASS:0)
Block(0,0,3,GRASS:0)
Block(1,0,3,GRASS:0)
Block(2,0,3,GRASS:0)
Block(3,0,3,GRASS:0)
Block(4,0,3,GRASS:0)
Block(5,0,3,GRASS:0)
Block(6,0,3,GRASS:0)
Block(7,0,3,GRASS:0)
Block(-8,0,4,GRASS:0)
Block(-7,0,4,GRASS:0)
Block(-6,0,4,GRASS:0)
Block(-5,0,4,GRASS:0)
Block(-4,0,4,GRASS:0)
Block(-3,0,4,GRASS:0)
Block(-2,0,4,GRASS:0)
Block(-1,0,4,GRASS:0)
Block(0,0,4,GRASS:0)
Block(1,0,4,GRASS:0)
Block(2,0,4,GRASS:0)
Block(3,0,4,GRASS:0)
Block(4,0,4,GRASS:0)
Block(5,0,4,GRASS:0)
Block(6,0,4,GRASS:0)
Block(7,0,4,GRASS:0)
Block(-8,0,5,GRASS:0)
Block(-7,0,5,GRASS:0)
Block(-6,0,5,GRASS:0)
Block(-5,0,5,GRASS:0)
Block(-4,0,5,GRASS:0)
Block(-3,0,5,GRASS:0)
Block(-2,0,5,GRASS:0)
Block(-1,0,5,GRASS:0)
Block(0,0,5,GRASS:0)
Block(1,0,5,GRASS:0)
Block(2,0,5,GRASS:0)
Block(3,0,5,GRASS:0)
Block(4,0,5,GRASS:0)
Block(5,0,5,GRASS:0)
Block(6,0,5,GRASS:0)
Block(7,0,5,GRASS:0)
Block(-8,0,6,GRASS:0)
Block(-7,0,6,GRASS:0)
Block(-6,0,6,GRASS:0)
Block(-5,0,6,GRASS:0)
Block(-4,0,6,GRASS:0)
Block(-3,0,6,GRASS:0)
Block(-2,0,6,GRASS:0)
Block(-1,0,6,GRASS:0)
Block(0,0,6,GRASS:0)
Block(1,0,6,GRASS:0)
Block(2,0,6,GRASS:0)
Block(3,0,6,GRASS:0)
Block(4,0,6,GRASS:0)
Block(5,0,6,GRASS:0)
Block(6,0,6,GRASS:0)
Block(7,0,6,GRASS:0)
Block(-8,0,7,GRASS:0)
Block(-7,0,7,GRASS:0)
Block(-6,0,7,GRASS:0)
Block(-5,0,7,GRASS:0)
Block(-4,0,7,GRASS:0)
Block(-3,0,7,GRASS:0)
Block(-2,0,7,GRASS:0)
Block(-1,0,7,GRASS:0)
Block(0,0,7,GRASS:0)
Block(1,0,7,GRASS:0)
Block(2,0,7,GRASS:0)
Block(3,0,7,GRASS:0)
Block(4,0,7,GRASS:0)
Block(5,0,7,GRASS:0)
Block(6,0,7,GRASS:0)
Block(7,0,7,GRASS:0)
Block(-8,0,8,GRASS:0)
Block(-7,0,8,GRASS:0)
Block(-6,0,8,GRASS:0)
Block(-5,0,8,GRASS:0)
Block(-4,0,8,GRASS:0)
Block(-3,0,8,GRASS:0)
Block(-2,0,8,GRASS:0)
Block(-1,0,8,GRASS:0)
Block(0,0,8,GRASS:0)
Block(1,0,8,GRASS:0)
Block(2,0,8,GRASS:0)
Block(3,0,8,GRASS:0)
Block(4,0,8,GRASS:0)
Block(5,0,8,GRASS:0)
Block(6,0,8,GRASS:0)
Block(7,0,8,GRASS:0)
Block(-5,1,-1,STONE_BRICKS:0)
Block(-4,1,-1,STONE_BRICKS:0)
Block(-3,1,-1,STONE_BRICKS:0)
Block(-2,1,-1,STONE_BRICKS:0)
Block(-1,1,-1,STONE_BRICKS:0)
Block(0,1,-1,STONE_BRICKS:0)
Block(1,1,-1,STONE_BRICKS:0)
Block(2,1,-1,STONE_BRICKS:0)
Block(3,1,-1,STONE_BRICKS:0)
Block(4,1,-1,STONE_BRICKS:0)
Block(5,1,-1,STONE_BRICKS:0)
Block(-5,1,0,STONE_BRICKS:0)
Block(-4,1,0,STONE_BRICKS:0)
Block(-3,1,0,STONE_BRICKS:0)
Block(-2,1,0,STONE_BRICKS:0)
Block(-1,1,0,STONE_BRICKS:0)
Block(0,1,0,STONE_BRICKS:0)
Block(1,1,0,STONE_BRICKS:0)
Block(2,1,0,STONE_BRICKS:0)
Block(3,1,0,STONE_BRICKS:0)
Block(4,1,0,STONE_BRICKS:0)
Block(5,1,0,STONE_BRICKS:0)
Block(-5,1,1,STONE_BRICKS:0)
Block(-4,1,1,STONE_BRICKS:0)
Block(-3,1,1,STONE_BRICKS:0)
Block(-2,1,1,STONE_BRICKS:0)
Block(-1,1,1,STONE_BRICKS:0)
Block(0,1,1,STONE_BRICKS:0)
Block(1,1,1,STONE_BRICKS:0)
Block(2,1,1,STONE_BRICKS:0)
Block(3,1,1,STONE_BRICKS:0)
Block(4,1,1,STONE_BRICKS:0)
Block(5,1,1,STONE_BRICKS:0)
Block(-5,1,2,STONE_BRICKS:0)
Block(-4,1,2,STONE_BRICKS:0)
Block(-3,1,2,STONE_BRICKS:0)
Block(-2,1,2,STONE_BRICKS:0)
Block(-1,1,2,STONE_BRICKS:0)
Block(0,1,2,STONE_BRICKS:0)
Block(1,1,2,STONE_BRICKS:0)
Block(2,1,2,STONE_BRICKS:0)
Block(3,1,2,STONE_BRICKS:0)
Block(4,1,2,STONE_BRICKS:0)
Block(5,1,2,STONE_BRICKS:0)
Block(-5,1,3,STONE_BRICKS:0)
Block(-4,1,3,STONE_BRICKS:0)
Block(-3,1,3,STONE_BRICKS:0)
Block(-2,1,3,STONE_BRICKS:0)
Block(-1,1,3,STONE_BRICKS:0)
Block(0,1,3,STONE_BRICKS:0)
Block(1,1,3,STONE_BRICKS:0)
Block(2,1,3,STONE_BRICKS:0)
Block(3,1,3,STONE_BRICKS:0)
Block(4,1,3,STONE_BRICKS:0)
Block(5,1,3,STONE_BRICKS:0)
Block(-5,1,4,STONE_BRICKS:0)
Block(-4,1,4,STONE_BRICKS:0)
Block(-3,1,4,STONE_BRICKS:0)
Block(-2,1,4,STONE_BRICKS:0)
Block(-1,1,4,STONE_BRICKS:0)
Block(0,1,4,STONE_BRICKS:0)
Block(1,1,4,STONE_BRICKS:0)
Block(2,1,4,STONE_BRICKS:0)
Block(3,1,4,STONE_BRICKS:0)
Block(4,1,4,STONE_BRICKS:0)
Block(5,1,4,STONE_BRICKS:0)
Block(-5,1,5,STONE_BRICKS:0)
Block(-4,1,5,STONE_BRICKS:0)
Block(-3,1,5,STONE_BRICKS:0)
Block(-2,1,5,STONE_BRICKS:0)
Block(-1,1,5,STONE_BRICKS:0)
Block(0,1,5,STONE_BRICKS:0)
Block(1,1,5,STONE_BRICKS:0)
Block(2,1,5,STONE_BRICKS:0)
Block(3,1,5,STONE_BRICKS:0)
Block(4,1,5,STONE_BRICKS:0)
Block(5,1,5,STONE_BRICKS:0)
Block(-5,1,6,STONE_BRICKS:0)
Block(-4,1,6,STONE_BRICKS:0)
Block(-3,1,6,STONE_BRICKS:0)
Block(-2,1,6,STONE_BRICKS:0)
Block(-1,1,6,STONE_BRICKS:0)
Block(0,1,6,STONE_BRICKS:0)
Block(1,1,6,STONE_BRICKS:0)
Block(2,1,6,STONE_BRICKS:0)
Block(3,1,6,STONE_BRICKS:0)
Block(4,1,6,STONE_BRICKS:0)
Block(5,1,6,STONE_BRICKS:0)
Block(-5,2,-1,WOOD:0)
Block(-4,2,-1,WOOD:0)
Block(-3,2,-1,WOOD:0)
Block(-2,2,-1,WOOD:0)
Block(-1,2,-1,WOOD:0)
Block(0,2,-1,AIR:0)
Block(1,2,-1,WOOD:0)
Block(2,2,-1,WOOD:0)
Block(3,2,-1,WOOD:0)
Block(4,2,-1,WOOD:0)
Block(5,2,-1,WOOD:0)
Block(-5,2,0,WOOD:0)
Block(5,2,0,WOOD:0)
Block(-5,2,1,WOOD:0)
Block(5,2,1,WOOD:0)
Block(-5,2,2,WOOD:0)
Block(5,2,2,WOOD:0)
Block(-5,2,3,WOOD:0)
Block(5,2,3,WOOD:0)
Block(-5,2,4,WOOD:0)
Block(5,2,4,WOOD:0)
Block(-5,2,5,WOOD:0)
Block(5,2,5,WOOD:0)
Block(-5,2,6,WOOD:0)
Block(-4,2,6,WOOD:0)
Block(-3,2,6,WOOD:0)
Block(-2,2,6,WOOD:0)
Block(-1,2,6,WOOD:0)
Block(0,2,6,WOOD:0)
Block(1,2,6,WOOD:0)
Block(2,2,6,WOOD:0)
Block(3,2,6,WOOD:0)
Block(4,2,6,WOOD:0)
Block(5,2,6,WOOD:0)
Block(-5,3,-1,WOOD:0)
Block(-4,3,-1,WOOD:0)
Block(-3,3,-1,GLASS:0)
Block(-2,3,-1,WOOD:0)
Block(-1,3,-1,WOOD:0)
Block(0,3,-1,AIR:0)
Block(1,3,-1,WOOD:0)
Block(2,3,-1,WOOD:0)
Block(3,3,-1,GLASS:0)
Block(4,3,-1,WOOD:0)
Block(5,3,-1,WOOD:0)
Block(-5,3,0,WOOD:0)
Block(5,3,0,WOOD:0)
Block(-5,3,1,WOOD:0)
Block(5,3,1,WOOD:0)
Block(-5,3,2,WOOD:0)
Block(5,3,2,WOOD:0)
Block(-5,3,3,WOOD:0)
Block(5,3,3,WOOD:0)
Block(-5,3,4,WOOD:0)
Block(5,3,4,WOOD:0)
Block(-5,3,5,WOOD:0)
Block(5,3,5,WOOD:0)
Block(-5,3,6,WOOD:0)
Block(-4,3,6,WOOD:0)
Block(-3,3,6,WOOD:0)
Block(-2,3,6,WOOD:0)
Block(-1,3,6,WOOD:0)
Block(0,3,6,WOOD:0)
Block(1,3,6,WOOD:0)
Block(2,3,6,WOOD:0)
Block(3,3,6,WOOD:0)
Block(4,3,6,WOOD:0)
Block(5,3,6,WOOD:0)
Block(-5,4,-1,WOOD:0)
Block(-4,4,-1,WOOD:0)
Block(-3,4,-1,GLASS:0)
Block(-2,4,-1,WOOD:0)
Block(-1,4,-1,WOOD:0)
Block(0,4,-1,WOOD:0)
Block(1,4,-1,WOOD:0)
Block(2,4,-1,WOOD:0)
Block(3,4,-1,GLASS:0)
Block(4,4,-1,WOOD:0)
Block(5,4,-1,WOOD:0)
Block(-5,4,0,WOOD:0)
Block(5,4,0,WOOD:0)
Block(-5,4,1,WOOD:0)
Block(5,4,1,WOOD:0)
Block(-5,4,2,WOOD:0)
Block(5,4,2,WOOD:0)
Block(-5,4,3,WOOD:0)
Block(5,4,3,WOOD:0)
Block(-5,4,4,WOOD:0)
Block(5,4,4,WOOD:0)
Block(-5,4,5,WOOD:0)
Block(5,4,5,WOOD:0)
Block(-5,4,6,WOOD:0)
Block(-4,4,6,WOOD:0)
Block(-3,4,6,WOOD:0)
Block(-2,4,6,WOOD:0)
Block(-1,4,6,WOOD:0)
Block(0,4,6,WOOD:0)
Block(1,4,6,WOOD:0)
Block(2,4,6,WOOD:0)
Block(3,4,6,WOOD:0)
Block(4,4,6,WOOD:0)
Block(5,4,6,WOOD:0)
Block(-5,5,-1,WOOD:0)
Block(-4,5,-1,WOOD:0)
Block(-3,5,-1,WOOD:0)
Block(-2,5,-1,WOOD:0)
Block(-1,5,-1,WOOD:0)
Block(0,5,-1,WOOD:0)
Block(1,5,-1,WOOD:0)
Block(2,5,-1,WOOD:0)
Block(3,5,-1,WOOD:0)
Block(4,5,-1,WOOD:0)
Block(5,5,-1,WOOD:0)
Block(-5,5,0,WOOD:0)
Block(5,5,0,WOOD:0)
Block(-5,5,1,WOOD:0)
Block(5,5,1,WOOD:0)
Block(-5,5,2,WOOD:0)
Block(5,5,2,WOOD:0)
Block(-5,5,3,WOOD:0)
Block(5,5,3,WOOD:0)
Block(-5,5,4,WOOD:0)
Block(5,5,4,WOOD:0)
Block(-5,5,5,WOOD:0)
Block(5,5,5,WOOD:0)
Block(-5,5,6,WOOD:0)
Block(-4,5,6,WOOD:0)
Block(-3,5,6,WOOD:0)
Block(-2,5,6,WOOD:0)
Block(-1,5,6,WOOD:0)
Block(0,5,6,WOOD:0)
Block(1,5,6,WOOD:0)
Block(2,5,6,WOOD:0)
Block(3,5,6,WOOD:0)
Block(4,5,6,WOOD:0)
Block(5,5,6,WOOD:0)
Block(-6,6,-2,BRICK:0)
Block(-5,6,-2,BRICK:0)
Block(-4,6,-2,BRICK:0)
Block(-3,6,-2,BRICK:0)
Block(-2,6,-2,BRICK:0)
Block(-1,6,-2,BRICK:0)
Block(0,6,-2,BRICK:0)
Block(1,6,-2,BRICK:0)
Block(2,6,-2,BRICK:0)
Block(3,6,-2,BRICK:0)
Block(4,6,-2,BRICK:0)
Block(5,6,-2,BRICK:0)
Block(6,6,-2,BRICK:0)
Block(-6,6,-1,BRICK:0)
Block(-5,6,-1,BRICK:0)
Block(-4,6,-1,BRICK:0)
Block(-3,6,-1,BRICK:0)
Block(-2,6,-1,BRICK:0)
Block(-1,6,-1,BRICK:0)
Block(0,6,-1,BRICK:0)
Block(1,6,-1,BRICK:0)
Block(2,6,-1,BRICK:0)
Block(3,6,-1,BRICK:0)
Block(4,6,-1,BRICK:0)
Block(5,6,-1,BRICK:0)
Block(6,6,-1,BRICK:0)
Block(-6,6,0,BRICK:0)
Block(-5,6,0,BRICK:0)
Block(-4,6,0,BRICK:0)
Block(-3,6,0,BRICK:0)
Block(-2,6,0,BRICK:0)
Block(-1,6,0,BRICK:0)
Block(0,6,0,BRICK:0)
Block(1,6,0,BRICK:0)
Block(2,6,0,BRICK:0)
Block(3,6,0,BRICK:0)
Block(4,6,0,BRICK:0)
Block(5,6,0,BRICK:0)
Block(6,6,0,BRICK:0)
Block(-6,6,1,BRICK:0)
Block(-5,6,1,BRICK:0)
Block(-4,6,1,BRICK:0)
Block(-3,6,1,BRICK:0)
Block(-2,6,1,BRICK:0)
Block(-1,6,1,BRICK:0)
Block(0,6,1,BRICK:0)
Block(1,6,1,BRICK:0)
Block(2,6,1,BRICK:0)
Block(3,6,1,BRICK:0)
Block(4,6,1,BRICK:0)
Block(5,6,1,BRICK:0)
Block(6,6,1,BRICK:0)
Block(-6,6,2,BRICK:0)
Block(-5,6,2,BRICK:0)
Block(-4,6,2,BRICK:0)
Block(-3,6,2,BRICK:0)
Block(-2,6,2,BRICK:0)
Block(-1,6,2,BRICK:0)
Block(0,6,2,BRICK:0)
Block(1,6,2,BRICK:0)
Block(2,6,2,BRICK:0)
Block(3,6,2,BRICK:0)
Block(4,6,2,BRICK:0)
Block(5,6,2,BRICK:0)
Block(6,6,2,BRICK:0)
Block(-6,6,3,BRICK:0)
Block(-5,6,3,BRICK:0)
Block(-4,6,3,BRICK:0)
Block(-3,6,3,BRICK:0)
Block(-2,6,3,BRICK:0)
Block(-1,6,3,BRICK:0)
Block(0,6,3,BRICK:0)
Block(1,6,3,BRICK:0)
Block(2,6,3,BRICK:0)
Block(3,6,3,BRICK:0)
Block(4,6,3,BRICK:0)
Block(5,6,3,BRICK:0)
Block(6,6,3,BRICK:0)
Block(-6,6,4,BRICK:0)
Block(-5,6,4,BRICK:0)
Block(-4,6,4,BRICK:0)
Block(-3,6,4,BRICK:0)
Block(-2,6,4,BRICK:0)
Block(-1,6,4,BRICK:0)
Block(0,6,4,BRICK:0)
Block(1,6,4,BRICK:0)
Block(2,6,4,BRICK:0)
Block(3,6,4,BRICK:0)
Block(4,6,4,BRICK:0)
Block(5,6,4,BRICK:0)
Block(6,6,4,BRICK:0)
Block(-6,6,5,BRICK:0)
Block(-5,6,5,BRICK:0)
Block(-4,6,5,BRICK:0)
Block(-3,6,5,BRICK:0)
Block(-2,6,5,BRICK:0)
Block(-1,6,5,BRICK:0)
Block(0,6,5,BRICK:0)
Block(1,6,5,BRICK:0)
Block(2,6,5,BRICK:0)
Block(3,6,5,BRICK:0)
Block(4,6,5,BRICK:0)
Block(5,6,5,BRICK:0)
Block(6,6,5,BRICK:0)
Block(-6,6,6,BRICK:0)
Block(-5,6,6,BRICK:0)
Block(-4,6,6,BRICK:0)
Block(-3,6,6,BRICK:0)
Block(-2,6,6,BRICK:0)
Block(-1,6,6,BRICK:0)
Block(0,6,6,BRICK:0)
Block(1,6,6,BRICK:0)
Block(2,6,6,BRICK:0)
Block(3,6,6,BRICK:0)
Block(4,6,6,BRICK:0)
Block(5,6,6,BRICK:0)
Block(6,6,6,BRICK:0)
Block(-6,6,7,BRICK:0)
Block(-5,6,7,BRICK:0)
Block(-4,6,7,BRICK:0)
Block(-3,6,7,BRICK:0)
Block(-2,6,7,BRICK:0)
Block(-1,6,7,BRICK:0)
Block(0,6,7,BRICK:0)
Block(1,6,7,BRICK:0)
Block(2,6,7,BRICK:0)
Block(3,6,7,BRICK:0)
Block(4,6,7,BRICK:0)
Block(5,6,7,BRICK:0)
Block(6,6,7,BRICK:0)

#######################################################################
# +-----------------------------------------------------------------+ #
# |                             Branches                            | #
# +-----------------------------------------------------------------+ #
#######################################################################


#######################################################################
# +-----------------------------------------------------------------+ #
# |                             Entities                            | #
# +-----------------------------------------------------------------+ #
#######################################################################


#######################################################################
# +-----------------------------------------------------------------+ #
# |                            Particles                            | #
# +-----------------------------------------------------------------+ #
#######################################################################


#######################################################################
# +-----------------------------------------------------------------+ #
# |                             Spawners                            | #
# +-----------------------------------------------------------------+ #
#######################################################################


#######################################################################
# +-----------------------------------------------------------------+ #
# |                             ModData                             | #
# +-----------------------------------------------------------------+ #
#######################################################################

