
#######################################################################
# +-----------------------------------------------------------------+ #
# |                            BO4 object                           | #
# +-----------------------------------------------------------------+ #
#######################################################################

Author: NLBlackEagle

Description: No description given

SettingsMode: WriteWithoutComments


#######################################################################
# +-----------------------------------------------------------------+ #
# |                          Main settings                          | #
# +-----------------------------------------------------------------+ #
#######################################################################

FixedRotation: 

Frequency: 0

SpawnHeight: highestBlock

UseCenterForHighestBlock: true

##############################
# Height Limits for the BO4. #
##############################

MinHeight: 0

MaxHeight: 255

InheritBO3: 

InheritBO3Rotation: NORTH

OverrideChildSettings: true

OverrideParentHeight: false

CanOverride: true

BranchFrequency: 0

BranchFrequencyGroup: 

MustBeBelowOther: false

MustBeInside: 

CannotBeInside: 

ReplacesBO3: 

MustBeInsideWorldBorders: true

CanSpawnOnWater: true

SpawnOnWaterOnly: false

SpawnUnderWater: false

SpawnAtWaterLevel: false

HeightOffset: 0

RemoveAir: false

ReplaceAbove: 

ReplaceBelow: 

ReplaceWithBiomeBlocks: false

ReplaceWithSurfaceBlock: GRASS

ReplaceWithGroundBlock: DIRT

ReplaceWithStoneBlock: STONE

SmoothRadius: 0

SmoothHeightOffset: 0

SmoothStartTop: false

SmoothStartWood: false

SmoothingSurfaceBlock: 

SmoothingGroundBlock: 

BO3Group: 

IsSpawnPoint: false

DoReplaceBlocks: false


#######################################################################
# +-----------------------------------------------------------------+ #
# |                              Blocks                             | #
# +-----------------------------------------------------------------+ #
#######################################################################

Block(-8,10,1,STONE_BUTTON:2)
Block(-8,15,-2,STONE_BUTTON:2)
Block(-8,15,1,STONE_BUTTON:2)
Block(-8,19,-2,STONE_BUTTON:2)
Block(-8,19,1,STONE_BUTTON:2)
Block(-8,20,-3,STEP:13)
Block(-8,20,-2,STEP:13)
Block(-8,20,-1,DOUBLE_STEP:5)
Block(-8,20,0,DOUBLE_STEP:5)
Block(-8,20,1,STEP:13)
Block(-8,20,2,STEP:13)
Block(-8,21,-3,IRON_FENCE:0)
Block(-8,21,-2,IRON_FENCE:0)
Block(-8,21,0,IRON_FENCE:0)
Block(-8,21,1,IRON_FENCE:0)
Block(-8,21,2,IRON_FENCE:0)
RandomBlock(-7,0,-2,STAINED_CLAY:7,33,STAINED_CLAY:12,33,CONCRETE:12,33,STAINED_CLAY:7,50,STAINED_CLAY:12,100)
RandomBlock(-7,0,-1,STAINED_CLAY:7,33,STAINED_CLAY:12,33,CONCRETE:12,33,STAINED_CLAY:7,50,STAINED_CLAY:12,100)
RandomBlock(-7,0,0,STAINED_CLAY:7,33,STAINED_CLAY:12,33,CONCRETE:12,33,STAINED_CLAY:7,50,STAINED_CLAY:12,100)
RandomBlock(-7,0,1,STAINED_CLAY:7,33,STAINED_CLAY:12,33,CONCRETE:12,33,STAINED_CLAY:7,50,STAINED_CLAY:12,100)
RandomBlock(-7,1,-2,STAINED_CLAY:7,33,STAINED_CLAY:12,33,CONCRETE:12,33,STAINED_CLAY:7,50,STAINED_CLAY:12,100)
RandomBlock(-7,1,-1,STAINED_CLAY:7,33,STAINED_CLAY:12,33,CONCRETE:12,33,STAINED_CLAY:7,50,STAINED_CLAY:12,100)
RandomBlock(-7,1,0,STAINED_CLAY:7,33,STAINED_CLAY:12,33,CONCRETE:12,33,STAINED_CLAY:7,50,STAINED_CLAY:12,100)
RandomBlock(-7,1,1,STAINED_CLAY:7,33,STAINED_CLAY:12,33,CONCRETE:12,33,STAINED_CLAY:7,50,STAINED_CLAY:12,100)
RandomBlock(-7,2,-2,STAINED_CLAY:7,33,STAINED_CLAY:12,33,CONCRETE:12,33,STAINED_CLAY:7,50,STAINED_CLAY:12,100)
RandomBlock(-7,2,-1,STAINED_CLAY:7,33,STAINED_CLAY:12,33,CONCRETE:12,33,STAINED_CLAY:7,50,STAINED_CLAY:12,100)
RandomBlock(-7,2,0,STAINED_CLAY:7,33,STAINED_CLAY:12,33,CONCRETE:12,33,STAINED_CLAY:7,50,STAINED_CLAY:12,100)
RandomBlock(-7,2,1,STAINED_CLAY:7,33,STAINED_CLAY:12,33,CONCRETE:12,33,STAINED_CLAY:7,50,STAINED_CLAY:12,100)
RandomBlock(-7,3,-2,STAINED_CLAY:7,33,STAINED_CLAY:12,33,CONCRETE:12,33,STAINED_CLAY:7,50,STAINED_CLAY:12,100)
RandomBlock(-7,3,-1,STAINED_CLAY:7,33,STAINED_CLAY:12,33,CONCRETE:12,33,STAINED_CLAY:7,50,STAINED_CLAY:12,100)
RandomBlock(-7,3,0,STAINED_CLAY:7,33,STAINED_CLAY:12,33,CONCRETE:12,33,STAINED_CLAY:7,50,STAINED_CLAY:12,100)
RandomBlock(-7,3,1,STAINED_CLAY:7,33,STAINED_CLAY:12,33,CONCRETE:12,33,STAINED_CLAY:7,50,STAINED_CLAY:12,100)
RandomBlock(-7,4,-2,STAINED_CLAY:7,33,STAINED_CLAY:12,33,CONCRETE:12,33,STAINED_CLAY:7,50,STAINED_CLAY:12,100)
RandomBlock(-7,4,-1,STAINED_CLAY:7,33,STAINED_CLAY:12,33,CONCRETE:12,33,STAINED_CLAY:7,50,STAINED_CLAY:12,100)
RandomBlock(-7,4,0,STAINED_CLAY:7,33,STAINED_CLAY:12,33,CONCRETE:12,33,STAINED_CLAY:7,50,STAINED_CLAY:12,100)
RandomBlock(-7,4,1,STAINED_CLAY:7,33,STAINED_CLAY:12,33,CONCRETE:12,33,STAINED_CLAY:7,50,STAINED_CLAY:12,100)
RandomBlock(-7,5,-2,STAINED_CLAY:7,33,STAINED_CLAY:12,33,CONCRETE:12,33,STAINED_CLAY:7,50,STAINED_CLAY:12,100)
RandomBlock(-7,5,-1,STAINED_CLAY:7,33,STAINED_CLAY:12,33,CONCRETE:12,33,STAINED_CLAY:7,50,STAINED_CLAY:12,100)
RandomBlock(-7,5,0,STAINED_CLAY:7,33,STAINED_CLAY:12,33,CONCRETE:12,33,STAINED_CLAY:7,50,STAINED_CLAY:12,100)
RandomBlock(-7,5,1,STAINED_CLAY:7,33,STAINED_CLAY:12,33,CONCRETE:12,33,STAINED_CLAY:7,50,STAINED_CLAY:12,100)
RandomBlock(-7,6,-2,STAINED_CLAY:7,33,STAINED_CLAY:12,33,CONCRETE:12,33,STAINED_CLAY:7,50,STAINED_CLAY:12,100)
RandomBlock(-7,6,-1,STAINED_CLAY:7,33,STAINED_CLAY:12,33,CONCRETE:12,33,STAINED_CLAY:7,50,STAINED_CLAY:12,100)
RandomBlock(-7,6,0,STAINED_CLAY:7,33,STAINED_CLAY:12,33,CONCRETE:12,33,STAINED_CLAY:7,50,STAINED_CLAY:12,100)
RandomBlock(-7,6,1,STAINED_CLAY:7,33,STAINED_CLAY:12,33,CONCRETE:12,33,STAINED_CLAY:7,50,STAINED_CLAY:12,100)
RandomBlock(-7,7,-2,STAINED_CLAY:7,33,STAINED_CLAY:12,33,CONCRETE:12,33,STAINED_CLAY:7,50,STAINED_CLAY:12,100)
RandomBlock(-7,7,-1,STAINED_CLAY:7,33,STAINED_CLAY:12,33,CONCRETE:12,33,STAINED_CLAY:7,50,STAINED_CLAY:12,100)
RandomBlock(-7,7,0,STAINED_CLAY:7,33,STAINED_CLAY:12,33,CONCRETE:12,33,STAINED_CLAY:7,50,STAINED_CLAY:12,100)
RandomBlock(-7,7,1,STAINED_CLAY:7,33,STAINED_CLAY:12,33,CONCRETE:12,33,STAINED_CLAY:7,50,STAINED_CLAY:12,100)
RandomBlock(-7,8,0,STAINED_CLAY:7,33,STAINED_CLAY:12,33,CONCRETE:12,33,STAINED_CLAY:7,50,STAINED_CLAY:12,100)
RandomBlock(-7,8,1,STAINED_CLAY:7,33,STAINED_CLAY:12,33,CONCRETE:12,33,STAINED_CLAY:7,50,STAINED_CLAY:12,100)
RandomBlock(-7,9,-1,STAINED_CLAY:7,33,STAINED_CLAY:12,33,CONCRETE:12,33,STAINED_CLAY:7,50,STAINED_CLAY:12,100)
RandomBlock(-7,9,0,STAINED_CLAY:7,33,STAINED_CLAY:12,33,CONCRETE:12,33,STAINED_CLAY:7,50,STAINED_CLAY:12,100)
RandomBlock(-7,9,1,STAINED_CLAY:7,33,STAINED_CLAY:12,33,CONCRETE:12,33,STAINED_CLAY:7,50,STAINED_CLAY:12,100)
RandomBlock(-7,10,-1,STAINED_CLAY:7,33,STAINED_CLAY:12,33,CONCRETE:12,33,STAINED_CLAY:7,50,STAINED_CLAY:12,100)
RandomBlock(-7,10,0,STAINED_CLAY:7,33,STAINED_CLAY:12,33,CONCRETE:12,33,STAINED_CLAY:7,50,STAINED_CLAY:12,100)
RandomBlock(-7,10,1,STAINED_CLAY:7,33,STAINED_CLAY:12,33,CONCRETE:12,33,STAINED_CLAY:7,50,STAINED_CLAY:12,100)
RandomBlock(-7,11,-1,STAINED_CLAY:7,33,STAINED_CLAY:12,33,CONCRETE:12,33,STAINED_CLAY:7,50,STAINED_CLAY:12,100)
RandomBlock(-7,11,0,STAINED_CLAY:7,33,STAINED_CLAY:12,33,CONCRETE:12,33,STAINED_CLAY:7,50,STAINED_CLAY:12,100)
RandomBlock(-7,11,1,STAINED_CLAY:7,33,STAINED_CLAY:12,33,CONCRETE:12,33,STAINED_CLAY:7,50,STAINED_CLAY:12,100)
RandomBlock(-7,12,-1,STAINED_CLAY:7,33,STAINED_CLAY:12,33,CONCRETE:12,33,STAINED_CLAY:7,50,STAINED_CLAY:12,100)
RandomBlock(-7,12,0,STAINED_CLAY:7,33,STAINED_CLAY:12,33,CONCRETE:12,33,STAINED_CLAY:7,50,STAINED_CLAY:12,100)
RandomBlock(-7,12,1,STAINED_CLAY:7,33,STAINED_CLAY:12,33,CONCRETE:12,33,STAINED_CLAY:7,50,STAINED_CLAY:12,100)
RandomBlock(-7,13,-2,STAINED_CLAY:7,33,STAINED_CLAY:12,33,CONCRETE:12,33,STAINED_CLAY:7,50,STAINED_CLAY:12,100)
RandomBlock(-7,13,-1,STAINED_CLAY:7,33,STAINED_CLAY:12,33,CONCRETE:12,33,STAINED_CLAY:7,50,STAINED_CLAY:12,100)
RandomBlock(-7,13,0,STAINED_CLAY:7,33,STAINED_CLAY:12,33,CONCRETE:12,33,STAINED_CLAY:7,50,STAINED_CLAY:12,100)
RandomBlock(-7,13,1,STAINED_CLAY:7,33,STAINED_CLAY:12,33,CONCRETE:12,33,STAINED_CLAY:7,50,STAINED_CLAY:12,100)
RandomBlock(-7,14,-2,STAINED_CLAY:7,33,STAINED_CLAY:12,33,CONCRETE:12,33,STAINED_CLAY:7,50,STAINED_CLAY:12,100)
RandomBlock(-7,14,-1,STAINED_CLAY:7,33,STAINED_CLAY:12,33,CONCRETE:12,33,STAINED_CLAY:7,50,STAINED_CLAY:12,100)
RandomBlock(-7,14,0,STAINED_CLAY:7,33,STAINED_CLAY:12,33,CONCRETE:12,33,STAINED_CLAY:7,50,STAINED_CLAY:12,100)
RandomBlock(-7,14,1,STAINED_CLAY:7,33,STAINED_CLAY:12,33,CONCRETE:12,33,STAINED_CLAY:7,50,STAINED_CLAY:12,100)
RandomBlock(-7,15,-2,STAINED_CLAY:7,33,STAINED_CLAY:12,33,CONCRETE:12,33,STAINED_CLAY:7,50,STAINED_CLAY:12,100)
RandomBlock(-7,15,-1,STAINED_CLAY:7,33,STAINED_CLAY:12,33,CONCRETE:12,33,STAINED_CLAY:7,50,STAINED_CLAY:12,100)
RandomBlock(-7,15,0,STAINED_CLAY:7,33,STAINED_CLAY:12,33,CONCRETE:12,33,STAINED_CLAY:7,50,STAINED_CLAY:12,100)
RandomBlock(-7,15,1,STAINED_CLAY:7,33,STAINED_CLAY:12,33,CONCRETE:12,33,STAINED_CLAY:7,50,STAINED_CLAY:12,100)
RandomBlock(-7,16,-2,STAINED_CLAY:7,33,STAINED_CLAY:12,33,CONCRETE:12,33,STAINED_CLAY:7,50,STAINED_CLAY:12,100)
RandomBlock(-7,16,-1,STAINED_CLAY:7,33,STAINED_CLAY:12,33,CONCRETE:12,33,STAINED_CLAY:7,50,STAINED_CLAY:12,100)
RandomBlock(-7,16,0,STAINED_CLAY:7,33,STAINED_CLAY:12,33,CONCRETE:12,33,STAINED_CLAY:7,50,STAINED_CLAY:12,100)
RandomBlock(-7,16,1,STAINED_CLAY:7,33,STAINED_CLAY:12,33,CONCRETE:12,33,STAINED_CLAY:7,50,STAINED_CLAY:12,100)
RandomBlock(-7,17,-2,STAINED_CLAY:7,33,STAINED_CLAY:12,33,CONCRETE:12,33,STAINED_CLAY:7,50,STAINED_CLAY:12,100)
RandomBlock(-7,17,-1,STAINED_CLAY:7,33,STAINED_CLAY:12,33,CONCRETE:12,33,STAINED_CLAY:7,50,STAINED_CLAY:12,100)
RandomBlock(-7,17,0,STAINED_CLAY:7,33,STAINED_CLAY:12,33,CONCRETE:12,33,STAINED_CLAY:7,50,STAINED_CLAY:12,100)
RandomBlock(-7,17,1,STAINED_CLAY:7,33,STAINED_CLAY:12,33,CONCRETE:12,33,STAINED_CLAY:7,50,STAINED_CLAY:12,100)
RandomBlock(-7,18,-2,STAINED_CLAY:7,33,STAINED_CLAY:12,33,CONCRETE:12,33,STAINED_CLAY:7,50,STAINED_CLAY:12,100)
RandomBlock(-7,18,-1,STAINED_CLAY:7,33,STAINED_CLAY:12,33,CONCRETE:12,33,STAINED_CLAY:7,50,STAINED_CLAY:12,100)
RandomBlock(-7,18,0,STAINED_CLAY:7,33,STAINED_CLAY:12,33,CONCRETE:12,33,STAINED_CLAY:7,50,STAINED_CLAY:12,100)
RandomBlock(-7,18,1,STAINED_CLAY:7,33,STAINED_CLAY:12,33,CONCRETE:12,33,STAINED_CLAY:7,50,STAINED_CLAY:12,100)
RandomBlock(-7,19,-2,STAINED_CLAY:7,33,STAINED_CLAY:12,33,CONCRETE:12,33,STAINED_CLAY:7,50,STAINED_CLAY:12,100)
RandomBlock(-7,19,-1,STAINED_CLAY:7,33,STAINED_CLAY:12,33,CONCRETE:12,33,STAINED_CLAY:7,50,STAINED_CLAY:12,100)
RandomBlock(-7,19,0,STAINED_CLAY:7,33,STAINED_CLAY:12,33,CONCRETE:12,33,STAINED_CLAY:7,50,STAINED_CLAY:12,100)
RandomBlock(-7,19,1,STAINED_CLAY:7,33,STAINED_CLAY:12,33,CONCRETE:12,33,STAINED_CLAY:7,50,STAINED_CLAY:12,100)
Block(-7,20,-4,STEP:13)
Block(-7,20,-3,STEP:13)
RandomBlock(-7,20,-2,STAINED_CLAY:7,33,STAINED_CLAY:12,33,CONCRETE:12,33,STAINED_CLAY:7,50,STAINED_CLAY:12,100)
RandomBlock(-7,20,-1,STAINED_CLAY:7,33,STAINED_CLAY:12,33,CONCRETE:12,33,STAINED_CLAY:7,50,STAINED_CLAY:12,100)
RandomBlock(-7,20,0,STAINED_CLAY:7,33,STAINED_CLAY:12,33,CONCRETE:12,33,STAINED_CLAY:7,50,STAINED_CLAY:12,100)
RandomBlock(-7,20,1,STAINED_CLAY:7,33,STAINED_CLAY:12,33,CONCRETE:12,33,STAINED_CLAY:7,50,STAINED_CLAY:12,100)
Block(-7,20,2,STEP:13)
Block(-7,20,3,STEP:13)
Block(-7,21,-4,IRON_FENCE:0)
Block(-7,21,-3,IRON_FENCE:0)
Block(-7,21,2,IRON_FENCE:0)
Block(-7,21,3,IRON_FENCE:0)
RandomBlock(-6,0,-3,STAINED_CLAY:7,33,STAINED_CLAY:12,33,CONCRETE:12,33,STAINED_CLAY:7,50,STAINED_CLAY:12,100)
RandomBlock(-6,0,-2,STAINED_CLAY:7,33,STAINED_CLAY:12,33,CONCRETE:12,33,STAINED_CLAY:7,50,STAINED_CLAY:12,100)
RandomBlock(-6,0,-1,STAINED_CLAY:7,33,STAINED_CLAY:12,33,CONCRETE:12,33,STAINED_CLAY:7,50,STAINED_CLAY:12,100)
RandomBlock(-6,0,0,STAINED_CLAY:7,33,STAINED_CLAY:12,33,CONCRETE:12,33,STAINED_CLAY:7,50,STAINED_CLAY:12,100)
RandomBlock(-6,0,1,STAINED_CLAY:7,33,STAINED_CLAY:12,33,CONCRETE:12,33,STAINED_CLAY:7,50,STAINED_CLAY:12,100)
RandomBlock(-6,0,2,STAINED_CLAY:7,33,STAINED_CLAY:12,33,CONCRETE:12,33,STAINED_CLAY:7,50,STAINED_CLAY:12,100)
RandomBlock(-6,1,-3,STAINED_CLAY:7,33,STAINED_CLAY:12,33,CONCRETE:12,33,STAINED_CLAY:7,50,STAINED_CLAY:12,100)
RandomBlock(-6,1,-2,STAINED_CLAY:7,33,STAINED_CLAY:12,33,CONCRETE:12,33,STAINED_CLAY:7,50,STAINED_CLAY:12,100)
RandomBlock(-6,1,-1,STAINED_CLAY:7,33,STAINED_CLAY:12,33,CONCRETE:12,33,STAINED_CLAY:7,50,STAINED_CLAY:12,100)
RandomBlock(-6,1,0,STAINED_CLAY:7,33,STAINED_CLAY:12,33,CONCRETE:12,33,STAINED_CLAY:7,50,STAINED_CLAY:12,100)
RandomBlock(-6,1,1,STAINED_CLAY:7,33,STAINED_CLAY:12,33,CONCRETE:12,33,STAINED_CLAY:7,50,STAINED_CLAY:12,100)
RandomBlock(-6,1,2,STAINED_CLAY:7,33,STAINED_CLAY:12,33,CONCRETE:12,33,STAINED_CLAY:7,50,STAINED_CLAY:12,100)
RandomBlock(-6,2,-3,STAINED_CLAY:7,33,STAINED_CLAY:12,33,CONCRETE:12,33,STAINED_CLAY:7,50,STAINED_CLAY:12,100)
Block(-6,2,-2,DIRT)
Block(-6,2,1,DIRT)
RandomBlock(-6,2,2,STAINED_CLAY:7,33,STAINED_CLAY:12,33,CONCRETE:12,33,STAINED_CLAY:7,50,STAINED_CLAY:12,100)
RandomBlock(-6,3,-3,STAINED_CLAY:7,33,STAINED_CLAY:12,33,CONCRETE:12,33,STAINED_CLAY:7,50,STAINED_CLAY:12,100)
Block(-6,3,-2,DIRT)
Block(-6,3,1,DIRT)
RandomBlock(-6,3,2,STAINED_CLAY:7,33,STAINED_CLAY:12,33,CONCRETE:12,33,STAINED_CLAY:7,50,STAINED_CLAY:12,100)
RandomBlock(-6,4,-3,STAINED_CLAY:7,33,STAINED_CLAY:12,33,CONCRETE:12,33,STAINED_CLAY:7,50,STAINED_CLAY:12,100)
RandomBlock(-6,4,2,STAINED_CLAY:7,33,STAINED_CLAY:12,33,CONCRETE:12,33,STAINED_CLAY:7,50,STAINED_CLAY:12,100)
RandomBlock(-6,5,-3,STAINED_CLAY:7,33,STAINED_CLAY:12,33,CONCRETE:12,33,STAINED_CLAY:7,50,STAINED_CLAY:12,100)
RandomBlock(-6,5,2,STAINED_CLAY:7,33,STAINED_CLAY:12,33,CONCRETE:12,33,STAINED_CLAY:7,50,STAINED_CLAY:12,100)
RandomBlock(-6,6,-3,STAINED_CLAY:7,33,STAINED_CLAY:12,33,CONCRETE:12,33,STAINED_CLAY:7,50,STAINED_CLAY:12,100)
RandomBlock(-6,6,2,STAINED_CLAY:7,33,STAINED_CLAY:12,33,CONCRETE:12,33,STAINED_CLAY:7,50,STAINED_CLAY:12,100)
RandomBlock(-6,7,-3,STAINED_CLAY:7,33,STAINED_CLAY:12,33,CONCRETE:12,33,STAINED_CLAY:7,50,STAINED_CLAY:12,100)
RandomBlock(-6,7,2,STAINED_CLAY:7,33,STAINED_CLAY:12,33,CONCRETE:12,33,STAINED_CLAY:7,50,STAINED_CLAY:12,100)
RandomBlock(-6,8,2,STAINED_CLAY:7,33,STAINED_CLAY:12,33,CONCRETE:12,33,STAINED_CLAY:7,50,STAINED_CLAY:12,100)
RandomBlock(-6,9,2,STAINED_CLAY:7,33,STAINED_CLAY:12,33,CONCRETE:12,33,STAINED_CLAY:7,50,STAINED_CLAY:12,100)
RandomBlock(-6,10,2,STAINED_CLAY:7,33,STAINED_CLAY:12,33,CONCRETE:12,33,STAINED_CLAY:7,50,STAINED_CLAY:12,100)
Block(-6,10,3,STONE_BUTTON:3)
RandomBlock(-6,11,2,STAINED_CLAY:7,33,STAINED_CLAY:12,33,CONCRETE:12,33,STAINED_CLAY:7,50,STAINED_CLAY:12,100)
RandomBlock(-6,12,-3,STAINED_CLAY:7,33,STAINED_CLAY:12,33,CONCRETE:12,33,STAINED_CLAY:7,50,STAINED_CLAY:12,100)
RandomBlock(-6,12,2,STAINED_CLAY:7,33,STAINED_CLAY:12,33,CONCRETE:12,33,STAINED_CLAY:7,50,STAINED_CLAY:12,100)
Block(-6,12,3,quark:iron_plate:1)
RandomBlock(-6,12,4,STAINED_CLAY:7,33,STAINED_CLAY:12,33,CONCRETE:12,33,STAINED_CLAY:7,50,STAINED_CLAY:12,100)
RandomBlock(-6,13,-3,STAINED_CLAY:7,33,STAINED_CLAY:12,33,CONCRETE:12,33,STAINED_CLAY:7,50,STAINED_CLAY:12,100)
RandomBlock(-6,13,2,STAINED_CLAY:7,33,STAINED_CLAY:12,33,CONCRETE:12,33,STAINED_CLAY:7,50,STAINED_CLAY:12,100)
Block(-6,13,3,quark:iron_plate:1)
RandomBlock(-6,13,4,STAINED_CLAY:7,33,STAINED_CLAY:12,33,CONCRETE:12,33,STAINED_CLAY:7,50,STAINED_CLAY:12,100)
RandomBlock(-6,14,-3,STAINED_CLAY:7,33,STAINED_CLAY:12,33,CONCRETE:12,33,STAINED_CLAY:7,50,STAINED_CLAY:12,100)
RandomBlock(-6,14,2,STAINED_CLAY:7,33,STAINED_CLAY:12,33,CONCRETE:12,33,STAINED_CLAY:7,50,STAINED_CLAY:12,100)
Block(-6,15,-4,STONE_BUTTON:4)
RandomBlock(-6,15,-3,STAINED_CLAY:7,33,STAINED_CLAY:12,33,CONCRETE:12,33,STAINED_CLAY:7,50,STAINED_CLAY:12,100)
RandomBlock(-6,15,2,STAINED_CLAY:7,33,STAINED_CLAY:12,33,CONCRETE:12,33,STAINED_CLAY:7,50,STAINED_CLAY:12,100)
Block(-6,15,3,STONE_BUTTON:3)
RandomBlock(-6,16,-3,STAINED_CLAY:7,33,STAINED_CLAY:12,33,CONCRETE:12,33,STAINED_CLAY:7,50,STAINED_CLAY:12,100)
RandomBlock(-6,16,2,STAINED_CLAY:7,33,STAINED_CLAY:12,33,CONCRETE:12,33,STAINED_CLAY:7,50,STAINED_CLAY:12,100)
RandomBlock(-6,17,-3,STAINED_CLAY:7,33,STAINED_CLAY:12,33,CONCRETE:12,33,STAINED_CLAY:7,50,STAINED_CLAY:12,100)
RandomBlock(-6,17,2,STAINED_CLAY:7,33,STAINED_CLAY:12,33,CONCRETE:12,33,STAINED_CLAY:7,50,STAINED_CLAY:12,100)
RandomBlock(-6,18,-3,STAINED_CLAY:7,33,STAINED_CLAY:12,33,CONCRETE:12,33,STAINED_CLAY:7,50,STAINED_CLAY:12,100)
RandomBlock(-6,18,2,STAINED_CLAY:7,33,STAINED_CLAY:12,33,CONCRETE:12,33,STAINED_CLAY:7,50,STAINED_CLAY:12,100)
Block(-6,19,-4,STONE_BUTTON:4)
RandomBlock(-6,19,-3,STAINED_CLAY:7,33,STAINED_CLAY:12,33,CONCRETE:12,33,STAINED_CLAY:7,50,STAINED_CLAY:12,100)
RandomBlock(-6,19,2,STAINED_CLAY:7,33,STAINED_CLAY:12,33,CONCRETE:12,33,STAINED_CLAY:7,50,STAINED_CLAY:12,100)
Block(-6,19,3,STONE_BUTTON:3)
Block(-6,20,-4,STEP:13)
RandomBlock(-6,20,-3,STAINED_CLAY:7,33,STAINED_CLAY:12,33,CONCRETE:12,33,STAINED_CLAY:7,50,STAINED_CLAY:12,100)
RandomBlock(-6,20,-2,STAINED_CLAY:7,33,STAINED_CLAY:12,33,CONCRETE:12,33,STAINED_CLAY:7,50,STAINED_CLAY:12,100)
RandomBlock(-6,20,-1,STAINED_CLAY:7,33,STAINED_CLAY:12,33,CONCRETE:12,33,STAINED_CLAY:7,50,STAINED_CLAY:12,100)
RandomBlock(-6,20,0,STAINED_CLAY:7,33,STAINED_CLAY:12,33,CONCRETE:12,33,STAINED_CLAY:7,50,STAINED_CLAY:12,100)
RandomBlock(-6,20,1,STAINED_CLAY:7,33,STAINED_CLAY:12,33,CONCRETE:12,33,STAINED_CLAY:7,50,STAINED_CLAY:12,100)
RandomBlock(-6,20,2,STAINED_CLAY:7,33,STAINED_CLAY:12,33,CONCRETE:12,33,STAINED_CLAY:7,50,STAINED_CLAY:12,100)
Block(-6,20,3,STEP:13)
Block(-6,21,3,IRON_FENCE:0)
RandomBlock(-5,0,-3,STAINED_CLAY:7,33,STAINED_CLAY:12,33,CONCRETE:12,33,STAINED_CLAY:7,50,STAINED_CLAY:12,100)
RandomBlock(-5,0,-2,STAINED_CLAY:7,33,STAINED_CLAY:12,33,CONCRETE:12,33,STAINED_CLAY:7,50,STAINED_CLAY:12,100)
RandomBlock(-5,0,-1,STAINED_CLAY:7,33,STAINED_CLAY:12,33,CONCRETE:12,33,STAINED_CLAY:7,50,STAINED_CLAY:12,100)
RandomBlock(-5,0,0,STAINED_CLAY:7,33,STAINED_CLAY:12,33,CONCRETE:12,33,STAINED_CLAY:7,50,STAINED_CLAY:12,100)
RandomBlock(-5,0,1,STAINED_CLAY:7,33,STAINED_CLAY:12,33,CONCRETE:12,33,STAINED_CLAY:7,50,STAINED_CLAY:12,100)
RandomBlock(-5,0,2,STAINED_CLAY:7,33,STAINED_CLAY:12,33,CONCRETE:12,33,STAINED_CLAY:7,50,STAINED_CLAY:12,100)
RandomBlock(-5,1,-3,STAINED_CLAY:7,33,STAINED_CLAY:12,33,CONCRETE:12,33,STAINED_CLAY:7,50,STAINED_CLAY:12,100)
RandomBlock(-5,1,-2,STAINED_CLAY:7,33,STAINED_CLAY:12,33,CONCRETE:12,33,STAINED_CLAY:7,50,STAINED_CLAY:12,100)
RandomBlock(-5,1,-1,STAINED_CLAY:7,33,STAINED_CLAY:12,33,CONCRETE:12,33,STAINED_CLAY:7,50,STAINED_CLAY:12,100)
RandomBlock(-5,1,0,STAINED_CLAY:7,33,STAINED_CLAY:12,33,CONCRETE:12,33,STAINED_CLAY:7,50,STAINED_CLAY:12,100)
RandomBlock(-5,1,1,STAINED_CLAY:7,33,STAINED_CLAY:12,33,CONCRETE:12,33,STAINED_CLAY:7,50,STAINED_CLAY:12,100)
RandomBlock(-5,1,2,STAINED_CLAY:7,33,STAINED_CLAY:12,33,CONCRETE:12,33,STAINED_CLAY:7,50,STAINED_CLAY:12,100)
RandomBlock(-5,2,-3,STAINED_CLAY:7,33,STAINED_CLAY:12,33,CONCRETE:12,33,STAINED_CLAY:7,50,STAINED_CLAY:12,100)
Block(-5,2,-2,DIRT)
Block(-5,2,-1,DIRT)
Block(-5,2,0,DIRT)
Block(-5,2,1,DIRT)
RandomBlock(-5,2,2,STAINED_CLAY:7,33,STAINED_CLAY:12,33,CONCRETE:12,33,STAINED_CLAY:7,50,STAINED_CLAY:12,100)
RandomBlock(-5,3,-3,STAINED_CLAY:7,33,STAINED_CLAY:12,33,CONCRETE:12,33,STAINED_CLAY:7,50,STAINED_CLAY:12,100)
RandomBlock(-5,3,2,STAINED_CLAY:7,33,STAINED_CLAY:12,33,CONCRETE:12,33,STAINED_CLAY:7,50,STAINED_CLAY:12,100)
RandomBlock(-5,4,-3,STAINED_CLAY:7,33,STAINED_CLAY:12,33,CONCRETE:12,33,STAINED_CLAY:7,50,STAINED_CLAY:12,100)
RandomBlock(-5,4,2,STAINED_CLAY:7,33,STAINED_CLAY:12,33,CONCRETE:12,33,STAINED_CLAY:7,50,STAINED_CLAY:12,100)
RandomBlock(-5,5,-3,STAINED_CLAY:7,33,STAINED_CLAY:12,33,CONCRETE:12,33,STAINED_CLAY:7,50,STAINED_CLAY:12,100)
RandomBlock(-5,5,2,STAINED_CLAY:7,33,STAINED_CLAY:12,33,CONCRETE:12,33,STAINED_CLAY:7,50,STAINED_CLAY:12,100)
RandomBlock(-5,6,-3,STAINED_CLAY:7,33,STAINED_CLAY:12,33,CONCRETE:12,33,STAINED_CLAY:7,50,STAINED_CLAY:12,100)
RandomBlock(-5,6,2,STAINED_CLAY:7,33,STAINED_CLAY:12,33,CONCRETE:12,33,STAINED_CLAY:7,50,STAINED_CLAY:12,100)
RandomBlock(-5,7,-3,STAINED_CLAY:7,33,STAINED_CLAY:12,33,CONCRETE:12,33,STAINED_CLAY:7,50,STAINED_CLAY:12,100)
RandomBlock(-5,7,2,STAINED_CLAY:7,33,STAINED_CLAY:12,33,CONCRETE:12,33,STAINED_CLAY:7,50,STAINED_CLAY:12,100)
RandomBlock(-5,8,-3,STAINED_CLAY:7,33,STAINED_CLAY:12,33,CONCRETE:12,33,STAINED_CLAY:7,50,STAINED_CLAY:12,100)
RandomBlock(-5,8,2,STAINED_CLAY:7,33,STAINED_CLAY:12,33,CONCRETE:12,33,STAINED_CLAY:7,50,STAINED_CLAY:12,100)
RandomBlock(-5,9,-3,STAINED_CLAY:7,33,STAINED_CLAY:12,33,CONCRETE:12,33,STAINED_CLAY:7,50,STAINED_CLAY:12,100)
RandomBlock(-5,9,2,STAINED_CLAY:7,33,STAINED_CLAY:12,33,CONCRETE:12,33,STAINED_CLAY:7,50,STAINED_CLAY:12,100)
RandomBlock(-5,10,-3,STAINED_CLAY:7,33,STAINED_CLAY:12,33,CONCRETE:12,33,STAINED_CLAY:7,50,STAINED_CLAY:12,100)
RandomBlock(-5,10,2,STAINED_CLAY:7,33,STAINED_CLAY:12,33,CONCRETE:12,33,STAINED_CLAY:7,50,STAINED_CLAY:12,100)
RandomBlock(-5,11,-3,STAINED_CLAY:7,33,STAINED_CLAY:12,33,CONCRETE:12,33,STAINED_CLAY:7,50,STAINED_CLAY:12,100)
RandomBlock(-5,11,2,STAINED_CLAY:7,33,STAINED_CLAY:12,33,CONCRETE:12,33,STAINED_CLAY:7,50,STAINED_CLAY:12,100)
Block(-5,11,3,quark:iron_plate:1)
RandomBlock(-5,11,4,STAINED_CLAY:7,33,STAINED_CLAY:12,33,CONCRETE:12,33,STAINED_CLAY:7,50,STAINED_CLAY:12,100)
RandomBlock(-5,12,-3,STAINED_CLAY:7,33,STAINED_CLAY:12,33,CONCRETE:12,33,STAINED_CLAY:7,50,STAINED_CLAY:12,100)
Block(-5,12,4,IRON_FENCE:0)
RandomBlock(-5,13,-3,STAINED_CLAY:7,33,STAINED_CLAY:12,33,CONCRETE:12,33,STAINED_CLAY:7,50,STAINED_CLAY:12,100)
Block(-5,13,4,IRON_FENCE:0)
RandomBlock(-5,14,-3,STAINED_CLAY:7,33,STAINED_CLAY:12,33,CONCRETE:12,33,STAINED_CLAY:7,50,STAINED_CLAY:12,100)
RandomBlock(-5,14,2,STAINED_CLAY:7,33,STAINED_CLAY:12,33,CONCRETE:12,33,STAINED_CLAY:7,50,STAINED_CLAY:12,100)
Block(-5,14,3,quark:iron_plate:1)
RandomBlock(-5,14,4,STAINED_CLAY:7,33,STAINED_CLAY:12,33,CONCRETE:12,33,STAINED_CLAY:7,50,STAINED_CLAY:12,100)
Block(-5,15,-4,IRON_FENCE:0)
RandomBlock(-5,15,-3,STAINED_CLAY:7,33,STAINED_CLAY:12,33,CONCRETE:12,33,STAINED_CLAY:7,50,STAINED_CLAY:12,100)
RandomBlock(-5,15,2,STAINED_CLAY:7,33,STAINED_CLAY:12,33,CONCRETE:12,33,STAINED_CLAY:7,50,STAINED_CLAY:12,100)
RandomBlock(-5,16,-3,STAINED_CLAY:7,33,STAINED_CLAY:12,33,CONCRETE:12,33,STAINED_CLAY:7,50,STAINED_CLAY:12,100)
RandomBlock(-5,16,2,STAINED_CLAY:7,33,STAINED_CLAY:12,33,CONCRETE:12,33,STAINED_CLAY:7,50,STAINED_CLAY:12,100)
RandomBlock(-5,17,-3,STAINED_CLAY:7,33,STAINED_CLAY:12,33,CONCRETE:12,33,STAINED_CLAY:7,50,STAINED_CLAY:12,100)
RandomBlock(-5,17,2,STAINED_CLAY:7,33,STAINED_CLAY:12,33,CONCRETE:12,33,STAINED_CLAY:7,50,STAINED_CLAY:12,100)
RandomBlock(-5,18,-3,STAINED_CLAY:7,33,STAINED_CLAY:12,33,CONCRETE:12,33,STAINED_CLAY:7,50,STAINED_CLAY:12,100)
RandomBlock(-5,18,2,STAINED_CLAY:7,33,STAINED_CLAY:12,33,CONCRETE:12,33,STAINED_CLAY:7,50,STAINED_CLAY:12,100)
RandomBlock(-5,19,-3,STAINED_CLAY:7,33,STAINED_CLAY:12,33,CONCRETE:12,33,STAINED_CLAY:7,50,STAINED_CLAY:12,100)
RandomBlock(-5,19,2,STAINED_CLAY:7,33,STAINED_CLAY:12,33,CONCRETE:12,33,STAINED_CLAY:7,50,STAINED_CLAY:12,100)
Block(-5,20,-4,DOUBLE_STEP:5)
RandomBlock(-5,20,-3,STAINED_CLAY:7,33,STAINED_CLAY:12,33,CONCRETE:12,33,STAINED_CLAY:7,50,STAINED_CLAY:12,100)
RandomBlock(-5,20,-2,STAINED_CLAY:7,33,STAINED_CLAY:12,33,CONCRETE:12,33,STAINED_CLAY:7,50,STAINED_CLAY:12,100)
RandomBlock(-5,20,-1,STAINED_CLAY:7,33,STAINED_CLAY:12,33,CONCRETE:12,33,STAINED_CLAY:7,50,STAINED_CLAY:12,100)
RandomBlock(-5,20,0,STAINED_CLAY:7,33,STAINED_CLAY:12,33,CONCRETE:12,33,STAINED_CLAY:7,50,STAINED_CLAY:12,100)
RandomBlock(-5,20,1,STAINED_CLAY:7,33,STAINED_CLAY:12,33,CONCRETE:12,33,STAINED_CLAY:7,50,STAINED_CLAY:12,100)
RandomBlock(-5,20,2,STAINED_CLAY:7,33,STAINED_CLAY:12,33,CONCRETE:12,33,STAINED_CLAY:7,50,STAINED_CLAY:12,100)
Block(-5,20,3,STEP:13)
Block(-5,21,-4,IRON_FENCE:0)
Block(-5,21,3,IRON_FENCE:0)
Block(-4,0,-5,quark:iron_plate:1)
RandomBlock(-4,0,-3,STAINED_CLAY:7,33,STAINED_CLAY:12,33,CONCRETE:12,33,STAINED_CLAY:7,50,STAINED_CLAY:12,100)
RandomBlock(-4,0,-2,STAINED_CLAY:7,33,STAINED_CLAY:12,33,CONCRETE:12,33,STAINED_CLAY:7,50,STAINED_CLAY:12,100)
RandomBlock(-4,0,-1,STAINED_CLAY:7,33,STAINED_CLAY:12,33,CONCRETE:12,33,STAINED_CLAY:7,50,STAINED_CLAY:12,100)
RandomBlock(-4,0,0,STAINED_CLAY:7,33,STAINED_CLAY:12,33,CONCRETE:12,33,STAINED_CLAY:7,50,STAINED_CLAY:12,100)
RandomBlock(-4,0,1,STAINED_CLAY:7,33,STAINED_CLAY:12,33,CONCRETE:12,33,STAINED_CLAY:7,50,STAINED_CLAY:12,100)
RandomBlock(-4,0,2,STAINED_CLAY:7,33,STAINED_CLAY:12,33,CONCRETE:12,33,STAINED_CLAY:7,50,STAINED_CLAY:12,100)
Block(-4,1,-5,quark:iron_plate:1)
RandomBlock(-4,1,-3,STAINED_CLAY:7,33,STAINED_CLAY:12,33,CONCRETE:12,33,STAINED_CLAY:7,50,STAINED_CLAY:12,100)
RandomBlock(-4,1,-2,STAINED_CLAY:7,33,STAINED_CLAY:12,33,CONCRETE:12,33,STAINED_CLAY:7,50,STAINED_CLAY:12,100)
RandomBlock(-4,1,-1,STAINED_CLAY:7,33,STAINED_CLAY:12,33,CONCRETE:12,33,STAINED_CLAY:7,50,STAINED_CLAY:12,100)
RandomBlock(-4,1,0,STAINED_CLAY:7,33,STAINED_CLAY:12,33,CONCRETE:12,33,STAINED_CLAY:7,50,STAINED_CLAY:12,100)
RandomBlock(-4,1,1,STAINED_CLAY:7,33,STAINED_CLAY:12,33,CONCRETE:12,33,STAINED_CLAY:7,50,STAINED_CLAY:12,100)
RandomBlock(-4,1,2,STAINED_CLAY:7,33,STAINED_CLAY:12,33,CONCRETE:12,33,STAINED_CLAY:7,50,STAINED_CLAY:12,100)
Block(-4,2,-5,quark:iron_plate:1)
RandomBlock(-4,2,-3,STAINED_CLAY:7,33,STAINED_CLAY:12,33,CONCRETE:12,33,STAINED_CLAY:7,50,STAINED_CLAY:12,100)
Block(-4,2,-2,DIRT)
Block(-4,2,0,DIRT)
Block(-4,2,1,DIRT)
RandomBlock(-4,2,2,STAINED_CLAY:7,33,STAINED_CLAY:12,33,CONCRETE:12,33,STAINED_CLAY:7,50,STAINED_CLAY:12,100)
Block(-4,3,-5,quark:iron_plate:1)
RandomBlock(-4,3,-3,STAINED_CLAY:7,33,STAINED_CLAY:12,33,CONCRETE:12,33,STAINED_CLAY:7,50,STAINED_CLAY:12,100)
Block(-4,3,1,DIRT)
RandomBlock(-4,3,2,STAINED_CLAY:7,33,STAINED_CLAY:12,33,CONCRETE:12,33,STAINED_CLAY:7,50,STAINED_CLAY:12,100)
Block(-4,4,-5,quark:iron_plate:1)
RandomBlock(-4,4,-3,STAINED_CLAY:7,33,STAINED_CLAY:12,33,CONCRETE:12,33,STAINED_CLAY:7,50,STAINED_CLAY:12,100)
RandomBlock(-4,4,2,STAINED_CLAY:7,33,STAINED_CLAY:12,33,CONCRETE:12,33,STAINED_CLAY:7,50,STAINED_CLAY:12,100)
Block(-4,5,-5,quark:iron_plate:1)
RandomBlock(-4,5,-3,STAINED_CLAY:7,33,STAINED_CLAY:12,33,CONCRETE:12,33,STAINED_CLAY:7,50,STAINED_CLAY:12,100)
RandomBlock(-4,5,2,STAINED_CLAY:7,33,STAINED_CLAY:12,33,CONCRETE:12,33,STAINED_CLAY:7,50,STAINED_CLAY:12,100)
Block(-4,6,-5,quark:iron_plate:1)
RandomBlock(-4,6,-3,STAINED_CLAY:7,33,STAINED_CLAY:12,33,CONCRETE:12,33,STAINED_CLAY:7,50,STAINED_CLAY:12,100)
RandomBlock(-4,6,2,STAINED_CLAY:7,33,STAINED_CLAY:12,33,CONCRETE:12,33,STAINED_CLAY:7,50,STAINED_CLAY:12,100)
Block(-4,7,-5,quark:iron_plate:1)
RandomBlock(-4,7,-3,STAINED_CLAY:7,33,STAINED_CLAY:12,33,CONCRETE:12,33,STAINED_CLAY:7,50,STAINED_CLAY:12,100)
RandomBlock(-4,7,2,STAINED_CLAY:7,33,STAINED_CLAY:12,33,CONCRETE:12,33,STAINED_CLAY:7,50,STAINED_CLAY:12,100)
Block(-4,8,-5,quark:iron_plate:1)
RandomBlock(-4,8,-3,STAINED_CLAY:7,33,STAINED_CLAY:12,33,CONCRETE:12,33,STAINED_CLAY:7,50,STAINED_CLAY:12,100)
RandomBlock(-4,8,2,STAINED_CLAY:7,33,STAINED_CLAY:12,33,CONCRETE:12,33,STAINED_CLAY:7,50,STAINED_CLAY:12,100)
Block(-4,9,-5,quark:iron_plate:1)
RandomBlock(-4,9,-3,STAINED_CLAY:7,33,STAINED_CLAY:12,33,CONCRETE:12,33,STAINED_CLAY:7,50,STAINED_CLAY:12,100)
RandomBlock(-4,9,2,STAINED_CLAY:7,33,STAINED_CLAY:12,33,CONCRETE:12,33,STAINED_CLAY:7,50,STAINED_CLAY:12,100)
Block(-4,10,-5,quark:iron_plate:1)
RandomBlock(-4,10,-3,STAINED_CLAY:7,33,STAINED_CLAY:12,33,CONCRETE:12,33,STAINED_CLAY:7,50,STAINED_CLAY:12,100)
RandomBlock(-4,10,2,STAINED_CLAY:7,33,STAINED_CLAY:12,33,CONCRETE:12,33,STAINED_CLAY:7,50,STAINED_CLAY:12,100)
Block(-4,11,-5,quark:iron_plate:1)
RandomBlock(-4,11,-3,STAINED_CLAY:7,33,STAINED_CLAY:12,33,CONCRETE:12,33,STAINED_CLAY:7,50,STAINED_CLAY:12,100)
RandomBlock(-4,11,2,STAINED_CLAY:7,33,STAINED_CLAY:12,33,CONCRETE:12,33,STAINED_CLAY:7,50,STAINED_CLAY:12,100)
Block(-4,11,3,quark:iron_plate:1)
RandomBlock(-4,11,4,STAINED_CLAY:7,33,STAINED_CLAY:12,33,CONCRETE:12,33,STAINED_CLAY:7,50,STAINED_CLAY:12,100)
RandomBlock(-4,12,-3,STAINED_CLAY:7,33,STAINED_CLAY:12,33,CONCRETE:12,33,STAINED_CLAY:7,50,STAINED_CLAY:12,100)
Block(-4,12,4,IRON_FENCE:0)
RandomBlock(-4,13,-3,STAINED_CLAY:7,33,STAINED_CLAY:12,33,CONCRETE:12,33,STAINED_CLAY:7,50,STAINED_CLAY:12,100)
Block(-4,13,4,IRON_FENCE:0)
RandomBlock(-4,14,-3,STAINED_CLAY:7,33,STAINED_CLAY:12,33,CONCRETE:12,33,STAINED_CLAY:7,50,STAINED_CLAY:12,100)
RandomBlock(-4,14,2,STAINED_CLAY:7,33,STAINED_CLAY:12,33,CONCRETE:12,33,STAINED_CLAY:7,50,STAINED_CLAY:12,100)
Block(-4,14,3,quark:iron_plate:1)
RandomBlock(-4,14,4,STAINED_CLAY:7,33,STAINED_CLAY:12,33,CONCRETE:12,33,STAINED_CLAY:7,50,STAINED_CLAY:12,100)
Block(-4,15,-4,IRON_FENCE:0)
RandomBlock(-4,15,-3,STAINED_CLAY:7,33,STAINED_CLAY:12,33,CONCRETE:12,33,STAINED_CLAY:7,50,STAINED_CLAY:12,100)
RandomBlock(-4,15,2,STAINED_CLAY:7,33,STAINED_CLAY:12,33,CONCRETE:12,33,STAINED_CLAY:7,50,STAINED_CLAY:12,100)
Block(-4,16,-4,IRON_FENCE:0)
RandomBlock(-4,16,-3,STAINED_CLAY:7,33,STAINED_CLAY:12,33,CONCRETE:12,33,STAINED_CLAY:7,50,STAINED_CLAY:12,100)
RandomBlock(-4,16,2,STAINED_CLAY:7,33,STAINED_CLAY:12,33,CONCRETE:12,33,STAINED_CLAY:7,50,STAINED_CLAY:12,100)
RandomBlock(-4,17,-3,STAINED_CLAY:7,33,STAINED_CLAY:12,33,CONCRETE:12,33,STAINED_CLAY:7,50,STAINED_CLAY:12,100)
RandomBlock(-4,18,-3,STAINED_CLAY:7,33,STAINED_CLAY:12,33,CONCRETE:12,33,STAINED_CLAY:7,50,STAINED_CLAY:12,100)
RandomBlock(-4,18,2,STAINED_CLAY:7,33,STAINED_CLAY:12,33,CONCRETE:12,33,STAINED_CLAY:7,50,STAINED_CLAY:12,100)
RandomBlock(-4,19,-3,STAINED_CLAY:7,33,STAINED_CLAY:12,33,CONCRETE:12,33,STAINED_CLAY:7,50,STAINED_CLAY:12,100)
RandomBlock(-4,19,2,STAINED_CLAY:7,33,STAINED_CLAY:12,33,CONCRETE:12,33,STAINED_CLAY:7,50,STAINED_CLAY:12,100)
Block(-4,20,-4,DOUBLE_STEP:5)
RandomBlock(-4,20,-3,STAINED_CLAY:7,33,STAINED_CLAY:12,33,CONCRETE:12,33,STAINED_CLAY:7,50,STAINED_CLAY:12,100)
RandomBlock(-4,20,-2,STAINED_CLAY:7,33,STAINED_CLAY:12,33,CONCRETE:12,33,STAINED_CLAY:7,50,STAINED_CLAY:12,100)
RandomBlock(-4,20,-1,STAINED_CLAY:7,33,STAINED_CLAY:12,33,CONCRETE:12,33,STAINED_CLAY:7,50,STAINED_CLAY:12,100)
RandomBlock(-4,20,0,STAINED_CLAY:7,33,STAINED_CLAY:12,33,CONCRETE:12,33,STAINED_CLAY:7,50,STAINED_CLAY:12,100)
RandomBlock(-4,20,1,STAINED_CLAY:7,33,STAINED_CLAY:12,33,CONCRETE:12,33,STAINED_CLAY:7,50,STAINED_CLAY:12,100)
RandomBlock(-4,20,2,STAINED_CLAY:7,33,STAINED_CLAY:12,33,CONCRETE:12,33,STAINED_CLAY:7,50,STAINED_CLAY:12,100)
Block(-4,20,3,DOUBLE_STEP:5)
Block(-4,21,-4,IRON_FENCE:0)
RandomBlock(-3,0,-3,STAINED_CLAY:7,33,STAINED_CLAY:12,33,CONCRETE:12,33,STAINED_CLAY:7,50,STAINED_CLAY:12,100)
RandomBlock(-3,0,-2,STAINED_CLAY:7,33,STAINED_CLAY:12,33,CONCRETE:12,33,STAINED_CLAY:7,50,STAINED_CLAY:12,100)
RandomBlock(-3,0,-1,STAINED_CLAY:7,33,STAINED_CLAY:12,33,CONCRETE:12,33,STAINED_CLAY:7,50,STAINED_CLAY:12,100)
RandomBlock(-3,0,0,STAINED_CLAY:7,33,STAINED_CLAY:12,33,CONCRETE:12,33,STAINED_CLAY:7,50,STAINED_CLAY:12,100)
RandomBlock(-3,0,1,STAINED_CLAY:7,33,STAINED_CLAY:12,33,CONCRETE:12,33,STAINED_CLAY:7,50,STAINED_CLAY:12,100)
RandomBlock(-3,0,2,STAINED_CLAY:7,33,STAINED_CLAY:12,33,CONCRETE:12,33,STAINED_CLAY:7,50,STAINED_CLAY:12,100)
RandomBlock(-3,1,-3,STAINED_CLAY:7,33,STAINED_CLAY:12,33,CONCRETE:12,33,STAINED_CLAY:7,50,STAINED_CLAY:12,100)
RandomBlock(-3,1,-2,STAINED_CLAY:7,33,STAINED_CLAY:12,33,CONCRETE:12,33,STAINED_CLAY:7,50,STAINED_CLAY:12,100)
RandomBlock(-3,1,-1,STAINED_CLAY:7,33,STAINED_CLAY:12,33,CONCRETE:12,33,STAINED_CLAY:7,50,STAINED_CLAY:12,100)
RandomBlock(-3,1,0,STAINED_CLAY:7,33,STAINED_CLAY:12,33,CONCRETE:12,33,STAINED_CLAY:7,50,STAINED_CLAY:12,100)
RandomBlock(-3,1,1,STAINED_CLAY:7,33,STAINED_CLAY:12,33,CONCRETE:12,33,STAINED_CLAY:7,50,STAINED_CLAY:12,100)
RandomBlock(-3,1,2,STAINED_CLAY:7,33,STAINED_CLAY:12,33,CONCRETE:12,33,STAINED_CLAY:7,50,STAINED_CLAY:12,100)
RandomBlock(-3,2,-3,STAINED_CLAY:7,33,STAINED_CLAY:12,33,CONCRETE:12,33,STAINED_CLAY:7,50,STAINED_CLAY:12,100)
Block(-3,2,-1,DIRT)
Block(-3,2,1,DIRT)
RandomBlock(-3,2,2,STAINED_CLAY:7,33,STAINED_CLAY:12,33,CONCRETE:12,33,STAINED_CLAY:7,50,STAINED_CLAY:12,100)
RandomBlock(-3,3,-3,STAINED_CLAY:7,33,STAINED_CLAY:12,33,CONCRETE:12,33,STAINED_CLAY:7,50,STAINED_CLAY:12,100)
Block(-3,3,1,DIRT)
RandomBlock(-3,3,2,STAINED_CLAY:7,33,STAINED_CLAY:12,33,CONCRETE:12,33,STAINED_CLAY:7,50,STAINED_CLAY:12,100)
RandomBlock(-3,4,-3,STAINED_CLAY:7,33,STAINED_CLAY:12,33,CONCRETE:12,33,STAINED_CLAY:7,50,STAINED_CLAY:12,100)
Block(-3,4,1,DIRT)
RandomBlock(-3,4,2,STAINED_CLAY:7,33,STAINED_CLAY:12,33,CONCRETE:12,33,STAINED_CLAY:7,50,STAINED_CLAY:12,100)
RandomBlock(-3,5,-3,STAINED_CLAY:7,33,STAINED_CLAY:12,33,CONCRETE:12,33,STAINED_CLAY:7,50,STAINED_CLAY:12,100)
RandomBlock(-3,5,2,STAINED_CLAY:7,33,STAINED_CLAY:12,33,CONCRETE:12,33,STAINED_CLAY:7,50,STAINED_CLAY:12,100)
RandomBlock(-3,6,-3,STAINED_CLAY:7,33,STAINED_CLAY:12,33,CONCRETE:12,33,STAINED_CLAY:7,50,STAINED_CLAY:12,100)
RandomBlock(-3,6,2,STAINED_CLAY:7,33,STAINED_CLAY:12,33,CONCRETE:12,33,STAINED_CLAY:7,50,STAINED_CLAY:12,100)
RandomBlock(-3,7,-3,STAINED_CLAY:7,33,STAINED_CLAY:12,33,CONCRETE:12,33,STAINED_CLAY:7,50,STAINED_CLAY:12,100)
RandomBlock(-3,7,2,STAINED_CLAY:7,33,STAINED_CLAY:12,33,CONCRETE:12,33,STAINED_CLAY:7,50,STAINED_CLAY:12,100)
RandomBlock(-3,8,-3,STAINED_CLAY:7,33,STAINED_CLAY:12,33,CONCRETE:12,33,STAINED_CLAY:7,50,STAINED_CLAY:12,100)
RandomBlock(-3,8,2,STAINED_CLAY:7,33,STAINED_CLAY:12,33,CONCRETE:12,33,STAINED_CLAY:7,50,STAINED_CLAY:12,100)
RandomBlock(-3,9,-3,STAINED_CLAY:7,33,STAINED_CLAY:12,33,CONCRETE:12,33,STAINED_CLAY:7,50,STAINED_CLAY:12,100)
RandomBlock(-3,9,2,STAINED_CLAY:7,33,STAINED_CLAY:12,33,CONCRETE:12,33,STAINED_CLAY:7,50,STAINED_CLAY:12,100)
Block(-3,10,-4,STONE_BUTTON:4)
RandomBlock(-3,10,-3,STAINED_CLAY:7,33,STAINED_CLAY:12,33,CONCRETE:12,33,STAINED_CLAY:7,50,STAINED_CLAY:12,100)
RandomBlock(-3,10,2,STAINED_CLAY:7,33,STAINED_CLAY:12,33,CONCRETE:12,33,STAINED_CLAY:7,50,STAINED_CLAY:12,100)
Block(-3,10,3,STONE_BUTTON:3)
Block(-3,11,-6,quark:iron_plate:1)
Block(-3,11,-5,quark:iron_plate:1)
RandomBlock(-3,11,-3,STAINED_CLAY:7,33,STAINED_CLAY:12,33,CONCRETE:12,33,STAINED_CLAY:7,50,STAINED_CLAY:12,100)
RandomBlock(-3,11,2,STAINED_CLAY:7,33,STAINED_CLAY:12,33,CONCRETE:12,33,STAINED_CLAY:7,50,STAINED_CLAY:12,100)
RandomBlock(-3,12,-3,STAINED_CLAY:7,33,STAINED_CLAY:12,33,CONCRETE:12,33,STAINED_CLAY:7,50,STAINED_CLAY:12,100)
RandomBlock(-3,12,2,STAINED_CLAY:7,33,STAINED_CLAY:12,33,CONCRETE:12,33,STAINED_CLAY:7,50,STAINED_CLAY:12,100)
Block(-3,12,3,quark:iron_plate:1)
RandomBlock(-3,12,4,STAINED_CLAY:7,33,STAINED_CLAY:12,33,CONCRETE:12,33,STAINED_CLAY:7,50,STAINED_CLAY:12,100)
RandomBlock(-3,13,-3,STAINED_CLAY:7,33,STAINED_CLAY:12,33,CONCRETE:12,33,STAINED_CLAY:7,50,STAINED_CLAY:12,100)
RandomBlock(-3,13,2,STAINED_CLAY:7,33,STAINED_CLAY:12,33,CONCRETE:12,33,STAINED_CLAY:7,50,STAINED_CLAY:12,100)
Block(-3,13,3,quark:iron_plate:1)
RandomBlock(-3,13,4,STAINED_CLAY:7,33,STAINED_CLAY:12,33,CONCRETE:12,33,STAINED_CLAY:7,50,STAINED_CLAY:12,100)
RandomBlock(-3,14,-3,STAINED_CLAY:7,33,STAINED_CLAY:12,33,CONCRETE:12,33,STAINED_CLAY:7,50,STAINED_CLAY:12,100)
RandomBlock(-3,14,2,STAINED_CLAY:7,33,STAINED_CLAY:12,33,CONCRETE:12,33,STAINED_CLAY:7,50,STAINED_CLAY:12,100)
Block(-3,15,-4,STONE_BUTTON:4)
RandomBlock(-3,15,-3,STAINED_CLAY:7,33,STAINED_CLAY:12,33,CONCRETE:12,33,STAINED_CLAY:7,50,STAINED_CLAY:12,100)
RandomBlock(-3,15,2,STAINED_CLAY:7,33,STAINED_CLAY:12,33,CONCRETE:12,33,STAINED_CLAY:7,50,STAINED_CLAY:12,100)
Block(-3,15,3,STONE_BUTTON:3)
RandomBlock(-3,16,-3,STAINED_CLAY:7,33,STAINED_CLAY:12,33,CONCRETE:12,33,STAINED_CLAY:7,50,STAINED_CLAY:12,100)
RandomBlock(-3,16,2,STAINED_CLAY:7,33,STAINED_CLAY:12,33,CONCRETE:12,33,STAINED_CLAY:7,50,STAINED_CLAY:12,100)
RandomBlock(-3,17,-3,STAINED_CLAY:7,33,STAINED_CLAY:12,33,CONCRETE:12,33,STAINED_CLAY:7,50,STAINED_CLAY:12,100)
RandomBlock(-3,18,-3,STAINED_CLAY:7,33,STAINED_CLAY:12,33,CONCRETE:12,33,STAINED_CLAY:7,50,STAINED_CLAY:12,100)
RandomBlock(-3,18,2,STAINED_CLAY:7,33,STAINED_CLAY:12,33,CONCRETE:12,33,STAINED_CLAY:7,50,STAINED_CLAY:12,100)
Block(-3,19,-4,STONE_BUTTON:4)
RandomBlock(-3,19,-3,STAINED_CLAY:7,33,STAINED_CLAY:12,33,CONCRETE:12,33,STAINED_CLAY:7,50,STAINED_CLAY:12,100)
RandomBlock(-3,19,2,STAINED_CLAY:7,33,STAINED_CLAY:12,33,CONCRETE:12,33,STAINED_CLAY:7,50,STAINED_CLAY:12,100)
Block(-3,19,3,STONE_BUTTON:3)
Block(-3,20,-4,STEP:13)
RandomBlock(-3,20,-3,STAINED_CLAY:7,33,STAINED_CLAY:12,33,CONCRETE:12,33,STAINED_CLAY:7,50,STAINED_CLAY:12,100)
RandomBlock(-3,20,-2,STAINED_CLAY:7,33,STAINED_CLAY:12,33,CONCRETE:12,33,STAINED_CLAY:7,50,STAINED_CLAY:12,100)
RandomBlock(-3,20,-1,STAINED_CLAY:7,33,STAINED_CLAY:12,33,CONCRETE:12,33,STAINED_CLAY:7,50,STAINED_CLAY:12,100)
RandomBlock(-3,20,0,STAINED_CLAY:7,33,STAINED_CLAY:12,33,CONCRETE:12,33,STAINED_CLAY:7,50,STAINED_CLAY:12,100)
RandomBlock(-3,20,1,STAINED_CLAY:7,33,STAINED_CLAY:12,33,CONCRETE:12,33,STAINED_CLAY:7,50,STAINED_CLAY:12,100)
RandomBlock(-3,20,2,STAINED_CLAY:7,33,STAINED_CLAY:12,33,CONCRETE:12,33,STAINED_CLAY:7,50,STAINED_CLAY:12,100)
Block(-3,20,3,STEP:13)
Block(-3,21,-4,IRON_FENCE:0)
RandomBlock(-3,21,-2,MONSTER_EGGS:2,30,SMOOTH_BRICK:0,100)
RandomBlock(-3,21,-1,SMOOTH_BRICK:0,40,SMOOTH_BRICK:1,20,SMOOTH_BRICK:2,30,SMOOTH_BRICK:0,100)
RandomBlock(-3,21,0,MONSTER_EGGS:2,30,SMOOTH_BRICK:0,100)
RandomBlock(-3,21,1,SMOOTH_BRICK:0,40,SMOOTH_BRICK:1,20,SMOOTH_BRICK:2,30,SMOOTH_BRICK:0,100)
RandomBlock(-3,22,-2,SMOOTH_BRICK:0,40,SMOOTH_BRICK:1,20,SMOOTH_BRICK:2,30,SMOOTH_BRICK:0,100)
Block(-3,22,-1,SMOOTH_BRICK:2)
RandomBlock(-3,22,0,MONSTER_EGGS:4,30,SMOOTH_BRICK:2,100)
Block(-3,22,1,SMOOTH_BRICK:1)
RandomBlock(-3,23,-2,MONSTER_EGGS:2,30,SMOOTH_BRICK:0,100)
RandomBlock(-3,23,-1,MONSTER_EGGS:2,30,SMOOTH_BRICK:0,100)
RandomBlock(-3,23,0,SMOOTH_BRICK:0,40,SMOOTH_BRICK:1,20,SMOOTH_BRICK:2,30,SMOOTH_BRICK:0,100)
Block(-3,23,1,SMOOTH_BRICK:2)
Block(-3,24,-2,STEP:3)
Block(-3,24,-1,STEP:3)
Block(-3,24,0,STEP:3)
Block(-3,24,1,STEP:3)
Block(-2,0,-6,quark:iron_plate:1)
RandomBlock(-2,0,-2,STAINED_CLAY:7,33,STAINED_CLAY:12,33,CONCRETE:12,33,STAINED_CLAY:7,50,STAINED_CLAY:12,100)
RandomBlock(-2,0,-1,STAINED_CLAY:7,33,STAINED_CLAY:12,33,CONCRETE:12,33,STAINED_CLAY:7,50,STAINED_CLAY:12,100)
RandomBlock(-2,0,0,STAINED_CLAY:7,33,STAINED_CLAY:12,33,CONCRETE:12,33,STAINED_CLAY:7,50,STAINED_CLAY:12,100)
RandomBlock(-2,0,1,STAINED_CLAY:7,33,STAINED_CLAY:12,33,CONCRETE:12,33,STAINED_CLAY:7,50,STAINED_CLAY:12,100)
Block(-2,1,-6,quark:iron_plate:1)
RandomBlock(-2,1,-2,STAINED_CLAY:7,33,STAINED_CLAY:12,33,CONCRETE:12,33,STAINED_CLAY:7,50,STAINED_CLAY:12,100)
RandomBlock(-2,1,-1,STAINED_CLAY:7,33,STAINED_CLAY:12,33,CONCRETE:12,33,STAINED_CLAY:7,50,STAINED_CLAY:12,100)
RandomBlock(-2,1,0,STAINED_CLAY:7,33,STAINED_CLAY:12,33,CONCRETE:12,33,STAINED_CLAY:7,50,STAINED_CLAY:12,100)
RandomBlock(-2,1,1,STAINED_CLAY:7,33,STAINED_CLAY:12,33,CONCRETE:12,33,STAINED_CLAY:7,50,STAINED_CLAY:12,100)
Block(-2,2,-6,quark:iron_plate:1)
RandomBlock(-2,2,-2,STAINED_CLAY:7,33,STAINED_CLAY:12,33,CONCRETE:12,33,STAINED_CLAY:7,50,STAINED_CLAY:12,100)
RandomBlock(-2,2,-1,STAINED_CLAY:7,33,STAINED_CLAY:12,33,CONCRETE:12,33,STAINED_CLAY:7,50,STAINED_CLAY:12,100)
RandomBlock(-2,2,0,STAINED_CLAY:7,33,STAINED_CLAY:12,33,CONCRETE:12,33,STAINED_CLAY:7,50,STAINED_CLAY:12,100)
RandomBlock(-2,2,1,STAINED_CLAY:7,33,STAINED_CLAY:12,33,CONCRETE:12,33,STAINED_CLAY:7,50,STAINED_CLAY:12,100)
Block(-2,3,-6,quark:iron_plate:1)
RandomBlock(-2,3,-2,STAINED_CLAY:7,33,STAINED_CLAY:12,33,CONCRETE:12,33,STAINED_CLAY:7,50,STAINED_CLAY:12,100)
RandomBlock(-2,3,-1,STAINED_CLAY:7,33,STAINED_CLAY:12,33,CONCRETE:12,33,STAINED_CLAY:7,50,STAINED_CLAY:12,100)
RandomBlock(-2,3,0,STAINED_CLAY:7,33,STAINED_CLAY:12,33,CONCRETE:12,33,STAINED_CLAY:7,50,STAINED_CLAY:12,100)
RandomBlock(-2,3,1,STAINED_CLAY:7,33,STAINED_CLAY:12,33,CONCRETE:12,33,STAINED_CLAY:7,50,STAINED_CLAY:12,100)
Block(-2,4,-6,quark:iron_plate:1)
RandomBlock(-2,4,-2,STAINED_CLAY:7,33,STAINED_CLAY:12,33,CONCRETE:12,33,STAINED_CLAY:7,50,STAINED_CLAY:12,100)
RandomBlock(-2,4,-1,STAINED_CLAY:7,33,STAINED_CLAY:12,33,CONCRETE:12,33,STAINED_CLAY:7,50,STAINED_CLAY:12,100)
RandomBlock(-2,4,0,STAINED_CLAY:7,33,STAINED_CLAY:12,33,CONCRETE:12,33,STAINED_CLAY:7,50,STAINED_CLAY:12,100)
RandomBlock(-2,4,1,STAINED_CLAY:7,33,STAINED_CLAY:12,33,CONCRETE:12,33,STAINED_CLAY:7,50,STAINED_CLAY:12,100)
Block(-2,5,-6,quark:iron_plate:1)
RandomBlock(-2,5,-2,STAINED_CLAY:7,33,STAINED_CLAY:12,33,CONCRETE:12,33,STAINED_CLAY:7,50,STAINED_CLAY:12,100)
RandomBlock(-2,5,-1,STAINED_CLAY:7,33,STAINED_CLAY:12,33,CONCRETE:12,33,STAINED_CLAY:7,50,STAINED_CLAY:12,100)
RandomBlock(-2,5,0,STAINED_CLAY:7,33,STAINED_CLAY:12,33,CONCRETE:12,33,STAINED_CLAY:7,50,STAINED_CLAY:12,100)
RandomBlock(-2,5,1,STAINED_CLAY:7,33,STAINED_CLAY:12,33,CONCRETE:12,33,STAINED_CLAY:7,50,STAINED_CLAY:12,100)
Block(-2,6,-6,quark:iron_plate:1)
RandomBlock(-2,6,-2,STAINED_CLAY:7,33,STAINED_CLAY:12,33,CONCRETE:12,33,STAINED_CLAY:7,50,STAINED_CLAY:12,100)
RandomBlock(-2,6,-1,STAINED_CLAY:7,33,STAINED_CLAY:12,33,CONCRETE:12,33,STAINED_CLAY:7,50,STAINED_CLAY:12,100)
RandomBlock(-2,6,0,STAINED_CLAY:7,33,STAINED_CLAY:12,33,CONCRETE:12,33,STAINED_CLAY:7,50,STAINED_CLAY:12,100)
RandomBlock(-2,6,1,STAINED_CLAY:7,33,STAINED_CLAY:12,33,CONCRETE:12,33,STAINED_CLAY:7,50,STAINED_CLAY:12,100)
Block(-2,7,-6,quark:iron_plate:1)
RandomBlock(-2,7,-2,STAINED_CLAY:7,33,STAINED_CLAY:12,33,CONCRETE:12,33,STAINED_CLAY:7,50,STAINED_CLAY:12,100)
RandomBlock(-2,7,-1,STAINED_CLAY:7,33,STAINED_CLAY:12,33,CONCRETE:12,33,STAINED_CLAY:7,50,STAINED_CLAY:12,100)
RandomBlock(-2,7,0,STAINED_CLAY:7,33,STAINED_CLAY:12,33,CONCRETE:12,33,STAINED_CLAY:7,50,STAINED_CLAY:12,100)
RandomBlock(-2,7,1,STAINED_CLAY:7,33,STAINED_CLAY:12,33,CONCRETE:12,33,STAINED_CLAY:7,50,STAINED_CLAY:12,100)
Block(-2,8,-6,quark:iron_plate:1)
RandomBlock(-2,8,-2,STAINED_CLAY:7,33,STAINED_CLAY:12,33,CONCRETE:12,33,STAINED_CLAY:7,50,STAINED_CLAY:12,100)
RandomBlock(-2,8,-1,STAINED_CLAY:7,33,STAINED_CLAY:12,33,CONCRETE:12,33,STAINED_CLAY:7,50,STAINED_CLAY:12,100)
RandomBlock(-2,8,0,STAINED_CLAY:7,33,STAINED_CLAY:12,33,CONCRETE:12,33,STAINED_CLAY:7,50,STAINED_CLAY:12,100)
RandomBlock(-2,8,1,STAINED_CLAY:7,33,STAINED_CLAY:12,33,CONCRETE:12,33,STAINED_CLAY:7,50,STAINED_CLAY:12,100)
Block(-2,9,-6,quark:iron_plate:1)
RandomBlock(-2,9,-2,STAINED_CLAY:7,33,STAINED_CLAY:12,33,CONCRETE:12,33,STAINED_CLAY:7,50,STAINED_CLAY:12,100)
RandomBlock(-2,9,-1,STAINED_CLAY:7,33,STAINED_CLAY:12,33,CONCRETE:12,33,STAINED_CLAY:7,50,STAINED_CLAY:12,100)
RandomBlock(-2,9,0,STAINED_CLAY:7,33,STAINED_CLAY:12,33,CONCRETE:12,33,STAINED_CLAY:7,50,STAINED_CLAY:12,100)
RandomBlock(-2,9,1,STAINED_CLAY:7,33,STAINED_CLAY:12,33,CONCRETE:12,33,STAINED_CLAY:7,50,STAINED_CLAY:12,100)
Block(-2,10,-6,quark:iron_plate:1)
RandomBlock(-2,10,-2,STAINED_CLAY:7,33,STAINED_CLAY:12,33,CONCRETE:12,33,STAINED_CLAY:7,50,STAINED_CLAY:12,100)
RandomBlock(-2,10,-1,STAINED_CLAY:7,33,STAINED_CLAY:12,33,CONCRETE:12,33,STAINED_CLAY:7,50,STAINED_CLAY:12,100)
RandomBlock(-2,10,0,STAINED_CLAY:7,33,STAINED_CLAY:12,33,CONCRETE:12,33,STAINED_CLAY:7,50,STAINED_CLAY:12,100)
RandomBlock(-2,10,1,STAINED_CLAY:7,33,STAINED_CLAY:12,33,CONCRETE:12,33,STAINED_CLAY:7,50,STAINED_CLAY:12,100)
Block(-2,11,-6,quark:iron_plate:1)
RandomBlock(-2,11,-2,STAINED_CLAY:7,33,STAINED_CLAY:12,33,CONCRETE:12,33,STAINED_CLAY:7,50,STAINED_CLAY:12,100)
RandomBlock(-2,11,-1,STAINED_CLAY:7,33,STAINED_CLAY:12,33,CONCRETE:12,33,STAINED_CLAY:7,50,STAINED_CLAY:12,100)
RandomBlock(-2,11,0,STAINED_CLAY:7,33,STAINED_CLAY:12,33,CONCRETE:12,33,STAINED_CLAY:7,50,STAINED_CLAY:12,100)
RandomBlock(-2,11,1,STAINED_CLAY:7,33,STAINED_CLAY:12,33,CONCRETE:12,33,STAINED_CLAY:7,50,STAINED_CLAY:12,100)
Block(-2,12,-6,quark:iron_plate:1)
RandomBlock(-2,12,-2,STAINED_CLAY:7,33,STAINED_CLAY:12,33,CONCRETE:12,33,STAINED_CLAY:7,50,STAINED_CLAY:12,100)
RandomBlock(-2,12,-1,STAINED_CLAY:7,33,STAINED_CLAY:12,33,CONCRETE:12,33,STAINED_CLAY:7,50,STAINED_CLAY:12,100)
RandomBlock(-2,12,0,STAINED_CLAY:7,33,STAINED_CLAY:12,33,CONCRETE:12,33,STAINED_CLAY:7,50,STAINED_CLAY:12,100)
RandomBlock(-2,12,1,STAINED_CLAY:7,33,STAINED_CLAY:12,33,CONCRETE:12,33,STAINED_CLAY:7,50,STAINED_CLAY:12,100)
Block(-2,13,-6,quark:iron_plate:1)
RandomBlock(-2,13,-2,STAINED_CLAY:7,33,STAINED_CLAY:12,33,CONCRETE:12,33,STAINED_CLAY:7,50,STAINED_CLAY:12,100)
RandomBlock(-2,13,-1,STAINED_CLAY:7,33,STAINED_CLAY:12,33,CONCRETE:12,33,STAINED_CLAY:7,50,STAINED_CLAY:12,100)
RandomBlock(-2,13,0,STAINED_CLAY:7,33,STAINED_CLAY:12,33,CONCRETE:12,33,STAINED_CLAY:7,50,STAINED_CLAY:12,100)
RandomBlock(-2,13,1,STAINED_CLAY:7,33,STAINED_CLAY:12,33,CONCRETE:12,33,STAINED_CLAY:7,50,STAINED_CLAY:12,100)
Block(-2,14,-6,quark:iron_plate:1)
RandomBlock(-2,14,-2,STAINED_CLAY:7,33,STAINED_CLAY:12,33,CONCRETE:12,33,STAINED_CLAY:7,50,STAINED_CLAY:12,100)
RandomBlock(-2,14,-1,STAINED_CLAY:7,33,STAINED_CLAY:12,33,CONCRETE:12,33,STAINED_CLAY:7,50,STAINED_CLAY:12,100)
RandomBlock(-2,14,0,STAINED_CLAY:7,33,STAINED_CLAY:12,33,CONCRETE:12,33,STAINED_CLAY:7,50,STAINED_CLAY:12,100)
RandomBlock(-2,14,1,STAINED_CLAY:7,33,STAINED_CLAY:12,33,CONCRETE:12,33,STAINED_CLAY:7,50,STAINED_CLAY:12,100)
Block(-2,15,-6,quark:iron_plate:1)
RandomBlock(-2,15,-2,STAINED_CLAY:7,33,STAINED_CLAY:12,33,CONCRETE:12,33,STAINED_CLAY:7,50,STAINED_CLAY:12,100)
RandomBlock(-2,15,-1,STAINED_CLAY:7,33,STAINED_CLAY:12,33,CONCRETE:12,33,STAINED_CLAY:7,50,STAINED_CLAY:12,100)
RandomBlock(-2,15,0,STAINED_CLAY:7,33,STAINED_CLAY:12,33,CONCRETE:12,33,STAINED_CLAY:7,50,STAINED_CLAY:12,100)
RandomBlock(-2,15,1,STAINED_CLAY:7,33,STAINED_CLAY:12,33,CONCRETE:12,33,STAINED_CLAY:7,50,STAINED_CLAY:12,100)
Block(-2,16,-6,quark:iron_plate:1)
RandomBlock(-2,16,-2,STAINED_CLAY:7,33,STAINED_CLAY:12,33,CONCRETE:12,33,STAINED_CLAY:7,50,STAINED_CLAY:12,100)
RandomBlock(-2,16,0,STAINED_CLAY:7,33,STAINED_CLAY:12,33,CONCRETE:12,33,STAINED_CLAY:7,50,STAINED_CLAY:12,100)
RandomBlock(-2,16,1,STAINED_CLAY:7,33,STAINED_CLAY:12,33,CONCRETE:12,33,STAINED_CLAY:7,50,STAINED_CLAY:12,100)
Block(-2,17,-6,quark:iron_plate:1)
RandomBlock(-2,17,-2,STAINED_CLAY:7,33,STAINED_CLAY:12,33,CONCRETE:12,33,STAINED_CLAY:7,50,STAINED_CLAY:12,100)
RandomBlock(-2,17,-1,STAINED_CLAY:7,33,STAINED_CLAY:12,33,CONCRETE:12,33,STAINED_CLAY:7,50,STAINED_CLAY:12,100)
RandomBlock(-2,17,0,STAINED_CLAY:7,33,STAINED_CLAY:12,33,CONCRETE:12,33,STAINED_CLAY:7,50,STAINED_CLAY:12,100)
RandomBlock(-2,17,1,STAINED_CLAY:7,33,STAINED_CLAY:12,33,CONCRETE:12,33,STAINED_CLAY:7,50,STAINED_CLAY:12,100)
Block(-2,18,-6,quark:iron_plate:1)
RandomBlock(-2,18,-2,STAINED_CLAY:7,33,STAINED_CLAY:12,33,CONCRETE:12,33,STAINED_CLAY:7,50,STAINED_CLAY:12,100)
RandomBlock(-2,18,-1,STAINED_CLAY:7,33,STAINED_CLAY:12,33,CONCRETE:12,33,STAINED_CLAY:7,50,STAINED_CLAY:12,100)
RandomBlock(-2,18,0,STAINED_CLAY:7,33,STAINED_CLAY:12,33,CONCRETE:12,33,STAINED_CLAY:7,50,STAINED_CLAY:12,100)
Block(-2,19,-6,quark:iron_plate:1)
RandomBlock(-2,19,-2,STAINED_CLAY:7,33,STAINED_CLAY:12,33,CONCRETE:12,33,STAINED_CLAY:7,50,STAINED_CLAY:12,100)
RandomBlock(-2,19,-1,STAINED_CLAY:7,33,STAINED_CLAY:12,33,CONCRETE:12,33,STAINED_CLAY:7,50,STAINED_CLAY:12,100)
RandomBlock(-2,19,0,STAINED_CLAY:7,33,STAINED_CLAY:12,33,CONCRETE:12,33,STAINED_CLAY:7,50,STAINED_CLAY:12,100)
RandomBlock(-2,19,1,STAINED_CLAY:7,33,STAINED_CLAY:12,33,CONCRETE:12,33,STAINED_CLAY:7,50,STAINED_CLAY:12,100)
Block(-2,20,-6,quark:iron_plate:1)
Block(-2,20,-4,STEP:13)
Block(-2,20,-3,STEP:13)
RandomBlock(-2,20,-2,STAINED_CLAY:7,33,STAINED_CLAY:12,33,CONCRETE:12,33,STAINED_CLAY:7,50,STAINED_CLAY:12,100)
RandomBlock(-2,20,-1,STAINED_CLAY:7,33,STAINED_CLAY:12,33,CONCRETE:12,33,STAINED_CLAY:7,50,STAINED_CLAY:12,100)
RandomBlock(-2,20,0,STAINED_CLAY:7,33,STAINED_CLAY:12,33,CONCRETE:12,33,STAINED_CLAY:7,50,STAINED_CLAY:12,100)
RandomBlock(-2,20,1,STAINED_CLAY:7,33,STAINED_CLAY:12,33,CONCRETE:12,33,STAINED_CLAY:7,50,STAINED_CLAY:12,100)
Block(-2,20,2,STEP:13)
Block(-2,20,3,STEP:13)
Block(-2,21,-6,quark:iron_plate:1)
Block(-2,21,-2,SMOOTH_BRICK:2)
Block(-2,21,-1,CONCRETE:15)
Block(-2,21,0,CONCRETE:15)
RandomBlock(-2,21,1,SMOOTH_BRICK:0,40,SMOOTH_BRICK:1,20,SMOOTH_BRICK:2,30,SMOOTH_BRICK:0,100)
Block(-2,22,-6,quark:iron_plate:1)
RandomBlock(-2,22,-2,SMOOTH_BRICK:0,40,SMOOTH_BRICK:1,20,SMOOTH_BRICK:2,30,SMOOTH_BRICK:0,100)
Block(-2,22,-1,CONCRETE:15)
Block(-2,22,0,CONCRETE:15)
Block(-2,22,1,SMOOTH_BRICK:2)
Block(-2,23,-6,quark:iron_plate:1)
Block(-2,23,-5,quark:iron_plate:1)
Block(-2,23,-4,quark:iron_plate:1)
Block(-2,23,-3,quark:iron_plate:1)
Block(-2,23,-2,SMOOTH_BRICK:2)
Block(-2,23,-1,CONCRETE:15)
Block(-2,23,0,CONCRETE:15)
RandomBlock(-2,23,1,SMOOTH_BRICK:0,40,SMOOTH_BRICK:1,20,SMOOTH_BRICK:2,30,SMOOTH_BRICK:0,100)
Block(-2,24,-2,STEP:3)
Block(-2,24,-1,STEP:0)
Block(-2,24,0,STEP:0)
Block(-2,24,1,STEP:3)
RandomBlock(-1,5,-1,MONSTER_EGGS:4,30,SMOOTH_BRICK:2,100)
RandomBlock(-1,5,0,MONSTER_EGGS:3,30,SMOOTH_BRICK:1,100)
Block(-1,9,-6,quark:iron_plate:1)
Block(-1,10,-2,STONE_BUTTON:1)
RandomBlock(-1,10,-1,SMOOTH_BRICK:0,40,SMOOTH_BRICK:1,20,SMOOTH_BRICK:2,30,SMOOTH_BRICK:0,100)
RandomBlock(-1,10,0,SMOOTH_BRICK:0,40,SMOOTH_BRICK:1,20,SMOOTH_BRICK:2,30,SMOOTH_BRICK:0,100)
Block(-1,10,1,STONE_BUTTON:1)
Block(-1,15,-2,STONE_BUTTON:1)
RandomBlock(-1,15,-1,SMOOTH_BRICK:0,40,SMOOTH_BRICK:1,20,SMOOTH_BRICK:2,30,SMOOTH_BRICK:0,100)
RandomBlock(-1,15,0,MONSTER_EGGS:4,30,SMOOTH_BRICK:2,100)
Block(-1,15,1,STONE_BUTTON:1)
Block(-1,20,-4,STEP:13)
Block(-1,20,-3,STEP:13)
Block(-1,20,-2,STEP:13)
Block(-1,20,-1,SMOOTH_BRICK:1)
Block(-1,20,0,SMOOTH_BRICK:1)
Block(-1,20,1,STEP:13)
Block(-1,20,2,STEP:13)
Block(-1,20,3,STEP:13)
Block(-1,21,-4,IRON_FENCE:0)
RandomBlock(-1,21,-2,MONSTER_EGGS:4,30,SMOOTH_BRICK:2,100)
Block(-1,21,-1,STONE_BUTTON:1)
Block(-1,21,0,STONE_BUTTON:1)
Block(-1,21,1,SMOOTH_BRICK:2)
RandomBlock(-1,22,-2,MONSTER_EGGS:2,30,SMOOTH_BRICK:0,100)
Block(-1,22,-1,STONE_BUTTON:1)
Block(-1,22,0,STONE_BUTTON:1)
Block(-1,22,1,SMOOTH_BRICK:2)
RandomBlock(-1,23,-2,MONSTER_EGGS:3,30,SMOOTH_BRICK:1,100)
Block(-1,23,-1,STEP:11)
Block(-1,23,0,STEP:11)
Block(-1,23,1,SMOOTH_BRICK:2)
Block(-1,24,-2,STEP:3)
Block(-1,24,-1,STEP:0)
Block(-1,24,0,quark:iron_plate:1)
Block(-1,24,1,STEP:3)
Block(-1,25,0,COBBLE_WALL:0)
Block(0,0,-7,quark:iron_plate:1)
Block(0,1,-7,quark:iron_plate:1)
Block(0,2,-7,quark:iron_plate:1)
Block(0,3,-7,quark:iron_plate:1)
Block(0,4,-7,quark:iron_plate:1)
Block(0,5,-7,quark:iron_plate:1)
RandomBlock(0,5,-1,SMOOTH_BRICK:0,40,SMOOTH_BRICK:1,20,SMOOTH_BRICK:2,30,SMOOTH_BRICK:0,100)
RandomBlock(0,5,0,SMOOTH_BRICK:0,40,SMOOTH_BRICK:1,20,SMOOTH_BRICK:2,30,SMOOTH_BRICK:0,100)
Block(0,6,-7,quark:iron_plate:1)
Block(0,6,-6,quark:iron_plate:1)
Block(0,6,-5,quark:iron_plate:1)
Block(0,7,-7,quark:iron_plate:1)
Block(0,8,-7,quark:iron_plate:1)
Block(0,9,-7,quark:iron_plate:1)
Block(0,9,-6,quark:iron_plate:1)
Block(0,10,-1,SMOOTH_BRICK:1)
Block(0,10,0,SMOOTH_BRICK:1)
RandomBlock(0,15,-1,SMOOTH_BRICK:0,40,SMOOTH_BRICK:1,20,SMOOTH_BRICK:2,30,SMOOTH_BRICK:0,100)
RandomBlock(0,15,0,SMOOTH_BRICK:0,40,SMOOTH_BRICK:1,20,SMOOTH_BRICK:2,30,SMOOTH_BRICK:0,100)
Block(0,20,-4,STEP:13)
Block(0,20,-3,STEP:13)
Block(0,20,-2,STEP:13)
RandomBlock(0,20,-1,SMOOTH_BRICK:0,40,SMOOTH_BRICK:1,20,SMOOTH_BRICK:2,30,SMOOTH_BRICK:0,100)
RandomBlock(0,20,0,MONSTER_EGGS:2,30,SMOOTH_BRICK:0,100)
Block(0,20,1,STEP:13)
Block(0,20,2,STEP:13)
Block(0,20,3,STEP:13)
RandomBlock(0,21,-2,MONSTER_EGGS:2,30,SMOOTH_BRICK:0,100)
Block(0,21,1,SMOOTH_BRICK:2)
Block(0,21,3,IRON_FENCE:0)
RandomBlock(0,22,-2,MONSTER_EGGS:2,30,SMOOTH_BRICK:0,100)
Block(0,22,1,SMOOTH_BRICK:2)
RandomBlock(0,23,-2,MONSTER_EGGS:2,30,SMOOTH_BRICK:0,100)
Block(0,23,-1,STEP:11)
Block(0,23,0,STEP:11)
RandomBlock(0,23,1,MONSTER_EGGS:3,30,SMOOTH_BRICK:1,100)
Block(0,24,-2,STEP:3)
Block(0,24,-1,STEP:0)
Block(0,24,0,quark:iron_plate:1)
Block(0,24,1,STEP:3)
Block(0,25,0,COBBLE_WALL:0)
Block(1,0,-5,quark:iron_plate:1)
Block(1,1,-5,quark:iron_plate:1)
Block(1,2,-5,quark:iron_plate:1)
Block(1,3,-5,quark:iron_plate:1)
Block(1,4,-5,quark:iron_plate:1)
Block(1,5,-5,quark:iron_plate:1)
RandomBlock(1,5,-1,SMOOTH_BRICK:0,40,SMOOTH_BRICK:1,20,SMOOTH_BRICK:2,30,SMOOTH_BRICK:0,100)
Block(1,5,0,SMOOTH_BRICK:2)
Block(1,6,-5,quark:iron_plate:1)
Block(1,10,-2,STONE_BUTTON:2)
RandomBlock(1,10,-1,MONSTER_EGGS:2,30,SMOOTH_BRICK:0,100)
RandomBlock(1,10,0,SMOOTH_BRICK:0,40,SMOOTH_BRICK:1,20,SMOOTH_BRICK:2,30,SMOOTH_BRICK:0,100)
Block(1,10,1,STONE_BUTTON:2)
Block(1,15,-2,STONE_BUTTON:2)
RandomBlock(1,15,-1,MONSTER_EGGS:2,30,SMOOTH_BRICK:0,100)
RandomBlock(1,15,0,MONSTER_EGGS:3,30,SMOOTH_BRICK:1,100)
Block(1,15,1,STONE_BUTTON:2)
Block(1,20,-4,STEP:13)
Block(1,20,-3,STEP:13)
Block(1,20,-2,STEP:13)
Block(1,20,-1,SMOOTH_BRICK:1)
Block(1,20,0,SMOOTH_BRICK:1)
Block(1,20,1,STEP:13)
Block(1,20,2,STEP:13)
Block(1,20,3,STEP:13)
Block(1,21,-4,IRON_FENCE:0)
RandomBlock(1,21,-2,SMOOTH_BRICK:0,40,SMOOTH_BRICK:1,20,SMOOTH_BRICK:2,30,SMOOTH_BRICK:0,100)
RandomBlock(1,21,0,CHEST:4,../../../../Chests/Loot/moderncity_junk_loot.nbt,20,CHEST:4,../../../../Chests/Loot/moderncity_common_loot.nbt,10,CHEST:4,../../../../Chests/RLCraft/Ruins/industrial.nbt,50,CHEST:4,../../../../Chests/RLCraft/Ruins/rubble.nbt,100)
RandomBlock(1,21,1,SMOOTH_BRICK:0,40,SMOOTH_BRICK:1,20,SMOOTH_BRICK:2,30,SMOOTH_BRICK:0,100)
RandomBlock(1,22,-2,SMOOTH_BRICK:0,40,SMOOTH_BRICK:1,20,SMOOTH_BRICK:2,30,SMOOTH_BRICK:0,100)
Block(1,22,-1,STONE_BUTTON:3)
RandomBlock(1,22,1,SMOOTH_BRICK:0,40,SMOOTH_BRICK:1,20,SMOOTH_BRICK:2,30,SMOOTH_BRICK:0,100)
Block(1,23,-2,SMOOTH_BRICK:2)
Block(1,23,-1,STEP:11)
Block(1,23,0,STEP:11)
RandomBlock(1,23,1,SMOOTH_BRICK:0,40,SMOOTH_BRICK:1,20,SMOOTH_BRICK:2,30,SMOOTH_BRICK:0,100)
Block(1,24,-2,STEP:3)
Block(1,24,-1,STEP:0)
Block(1,24,0,STEP:0)
Block(1,24,1,STEP:3)
RandomBlock(2,0,-2,STAINED_CLAY:7,33,STAINED_CLAY:12,33,CONCRETE:12,33,STAINED_CLAY:7,50,STAINED_CLAY:12,100)
RandomBlock(2,0,-1,STAINED_CLAY:7,33,STAINED_CLAY:12,33,CONCRETE:12,33,STAINED_CLAY:7,50,STAINED_CLAY:12,100)
RandomBlock(2,0,0,STAINED_CLAY:7,33,STAINED_CLAY:12,33,CONCRETE:12,33,STAINED_CLAY:7,50,STAINED_CLAY:12,100)
RandomBlock(2,1,-2,STAINED_CLAY:7,33,STAINED_CLAY:12,33,CONCRETE:12,33,STAINED_CLAY:7,50,STAINED_CLAY:12,100)
RandomBlock(2,1,-1,STAINED_CLAY:7,33,STAINED_CLAY:12,33,CONCRETE:12,33,STAINED_CLAY:7,50,STAINED_CLAY:12,100)
RandomBlock(2,1,0,STAINED_CLAY:7,33,STAINED_CLAY:12,33,CONCRETE:12,33,STAINED_CLAY:7,50,STAINED_CLAY:12,100)
RandomBlock(2,2,-2,STAINED_CLAY:7,33,STAINED_CLAY:12,33,CONCRETE:12,33,STAINED_CLAY:7,50,STAINED_CLAY:12,100)
RandomBlock(2,2,-1,STAINED_CLAY:7,33,STAINED_CLAY:12,33,CONCRETE:12,33,STAINED_CLAY:7,50,STAINED_CLAY:12,100)
RandomBlock(2,2,0,STAINED_CLAY:7,33,STAINED_CLAY:12,33,CONCRETE:12,33,STAINED_CLAY:7,50,STAINED_CLAY:12,100)
RandomBlock(2,3,-2,STAINED_CLAY:7,33,STAINED_CLAY:12,33,CONCRETE:12,33,STAINED_CLAY:7,50,STAINED_CLAY:12,100)
RandomBlock(2,3,-1,STAINED_CLAY:7,33,STAINED_CLAY:12,33,CONCRETE:12,33,STAINED_CLAY:7,50,STAINED_CLAY:12,100)
RandomBlock(2,3,0,STAINED_CLAY:7,33,STAINED_CLAY:12,33,CONCRETE:12,33,STAINED_CLAY:7,50,STAINED_CLAY:12,100)
RandomBlock(2,4,-2,STAINED_CLAY:7,33,STAINED_CLAY:12,33,CONCRETE:12,33,STAINED_CLAY:7,50,STAINED_CLAY:12,100)
RandomBlock(2,4,-1,STAINED_CLAY:7,33,STAINED_CLAY:12,33,CONCRETE:12,33,STAINED_CLAY:7,50,STAINED_CLAY:12,100)
RandomBlock(2,4,0,STAINED_CLAY:7,33,STAINED_CLAY:12,33,CONCRETE:12,33,STAINED_CLAY:7,50,STAINED_CLAY:12,100)
RandomBlock(2,5,-2,STAINED_CLAY:7,33,STAINED_CLAY:12,33,CONCRETE:12,33,STAINED_CLAY:7,50,STAINED_CLAY:12,100)
RandomBlock(2,5,-1,STAINED_CLAY:7,33,STAINED_CLAY:12,33,CONCRETE:12,33,STAINED_CLAY:7,50,STAINED_CLAY:12,100)
RandomBlock(2,5,0,STAINED_CLAY:7,33,STAINED_CLAY:12,33,CONCRETE:12,33,STAINED_CLAY:7,50,STAINED_CLAY:12,100)
RandomBlock(2,5,1,STAINED_CLAY:7,33,STAINED_CLAY:12,33,CONCRETE:12,33,STAINED_CLAY:7,50,STAINED_CLAY:12,100)
RandomBlock(2,6,-2,STAINED_CLAY:7,33,STAINED_CLAY:12,33,CONCRETE:12,33,STAINED_CLAY:7,50,STAINED_CLAY:12,100)
RandomBlock(2,6,-1,STAINED_CLAY:7,33,STAINED_CLAY:12,33,CONCRETE:12,33,STAINED_CLAY:7,50,STAINED_CLAY:12,100)
RandomBlock(2,6,0,STAINED_CLAY:7,33,STAINED_CLAY:12,33,CONCRETE:12,33,STAINED_CLAY:7,50,STAINED_CLAY:12,100)
RandomBlock(2,6,1,STAINED_CLAY:7,33,STAINED_CLAY:12,33,CONCRETE:12,33,STAINED_CLAY:7,50,STAINED_CLAY:12,100)
RandomBlock(2,7,-2,STAINED_CLAY:7,33,STAINED_CLAY:12,33,CONCRETE:12,33,STAINED_CLAY:7,50,STAINED_CLAY:12,100)
RandomBlock(2,7,-1,STAINED_CLAY:7,33,STAINED_CLAY:12,33,CONCRETE:12,33,STAINED_CLAY:7,50,STAINED_CLAY:12,100)
RandomBlock(2,7,0,STAINED_CLAY:7,33,STAINED_CLAY:12,33,CONCRETE:12,33,STAINED_CLAY:7,50,STAINED_CLAY:12,100)
RandomBlock(2,7,1,STAINED_CLAY:7,33,STAINED_CLAY:12,33,CONCRETE:12,33,STAINED_CLAY:7,50,STAINED_CLAY:12,100)
RandomBlock(2,8,-2,STAINED_CLAY:7,33,STAINED_CLAY:12,33,CONCRETE:12,33,STAINED_CLAY:7,50,STAINED_CLAY:12,100)
RandomBlock(2,8,-1,STAINED_CLAY:7,33,STAINED_CLAY:12,33,CONCRETE:12,33,STAINED_CLAY:7,50,STAINED_CLAY:12,100)
RandomBlock(2,8,0,STAINED_CLAY:7,33,STAINED_CLAY:12,33,CONCRETE:12,33,STAINED_CLAY:7,50,STAINED_CLAY:12,100)
RandomBlock(2,8,1,STAINED_CLAY:7,33,STAINED_CLAY:12,33,CONCRETE:12,33,STAINED_CLAY:7,50,STAINED_CLAY:12,100)
RandomBlock(2,9,-2,STAINED_CLAY:7,33,STAINED_CLAY:12,33,CONCRETE:12,33,STAINED_CLAY:7,50,STAINED_CLAY:12,100)
RandomBlock(2,9,-1,STAINED_CLAY:7,33,STAINED_CLAY:12,33,CONCRETE:12,33,STAINED_CLAY:7,50,STAINED_CLAY:12,100)
RandomBlock(2,9,0,STAINED_CLAY:7,33,STAINED_CLAY:12,33,CONCRETE:12,33,STAINED_CLAY:7,50,STAINED_CLAY:12,100)
RandomBlock(2,9,1,STAINED_CLAY:7,33,STAINED_CLAY:12,33,CONCRETE:12,33,STAINED_CLAY:7,50,STAINED_CLAY:12,100)
RandomBlock(2,10,-2,STAINED_CLAY:7,33,STAINED_CLAY:12,33,CONCRETE:12,33,STAINED_CLAY:7,50,STAINED_CLAY:12,100)
RandomBlock(2,10,-1,STAINED_CLAY:7,33,STAINED_CLAY:12,33,CONCRETE:12,33,STAINED_CLAY:7,50,STAINED_CLAY:12,100)
RandomBlock(2,10,0,STAINED_CLAY:7,33,STAINED_CLAY:12,33,CONCRETE:12,33,STAINED_CLAY:7,50,STAINED_CLAY:12,100)
RandomBlock(2,10,1,STAINED_CLAY:7,33,STAINED_CLAY:12,33,CONCRETE:12,33,STAINED_CLAY:7,50,STAINED_CLAY:12,100)
RandomBlock(2,11,-2,STAINED_CLAY:7,33,STAINED_CLAY:12,33,CONCRETE:12,33,STAINED_CLAY:7,50,STAINED_CLAY:12,100)
RandomBlock(2,11,-1,STAINED_CLAY:7,33,STAINED_CLAY:12,33,CONCRETE:12,33,STAINED_CLAY:7,50,STAINED_CLAY:12,100)
RandomBlock(2,11,0,STAINED_CLAY:7,33,STAINED_CLAY:12,33,CONCRETE:12,33,STAINED_CLAY:7,50,STAINED_CLAY:12,100)
RandomBlock(2,11,1,STAINED_CLAY:7,33,STAINED_CLAY:12,33,CONCRETE:12,33,STAINED_CLAY:7,50,STAINED_CLAY:12,100)
RandomBlock(2,12,-2,STAINED_CLAY:7,33,STAINED_CLAY:12,33,CONCRETE:12,33,STAINED_CLAY:7,50,STAINED_CLAY:12,100)
RandomBlock(2,12,-1,STAINED_CLAY:7,33,STAINED_CLAY:12,33,CONCRETE:12,33,STAINED_CLAY:7,50,STAINED_CLAY:12,100)
RandomBlock(2,12,0,STAINED_CLAY:7,33,STAINED_CLAY:12,33,CONCRETE:12,33,STAINED_CLAY:7,50,STAINED_CLAY:12,100)
RandomBlock(2,12,1,STAINED_CLAY:7,33,STAINED_CLAY:12,33,CONCRETE:12,33,STAINED_CLAY:7,50,STAINED_CLAY:12,100)
RandomBlock(2,13,-2,STAINED_CLAY:7,33,STAINED_CLAY:12,33,CONCRETE:12,33,STAINED_CLAY:7,50,STAINED_CLAY:12,100)
RandomBlock(2,13,-1,STAINED_CLAY:7,33,STAINED_CLAY:12,33,CONCRETE:12,33,STAINED_CLAY:7,50,STAINED_CLAY:12,100)
RandomBlock(2,13,0,STAINED_CLAY:7,33,STAINED_CLAY:12,33,CONCRETE:12,33,STAINED_CLAY:7,50,STAINED_CLAY:12,100)
RandomBlock(2,13,1,STAINED_CLAY:7,33,STAINED_CLAY:12,33,CONCRETE:12,33,STAINED_CLAY:7,50,STAINED_CLAY:12,100)
RandomBlock(2,14,-2,STAINED_CLAY:7,33,STAINED_CLAY:12,33,CONCRETE:12,33,STAINED_CLAY:7,50,STAINED_CLAY:12,100)
RandomBlock(2,14,-1,STAINED_CLAY:7,33,STAINED_CLAY:12,33,CONCRETE:12,33,STAINED_CLAY:7,50,STAINED_CLAY:12,100)
RandomBlock(2,14,0,STAINED_CLAY:7,33,STAINED_CLAY:12,33,CONCRETE:12,33,STAINED_CLAY:7,50,STAINED_CLAY:12,100)
RandomBlock(2,14,1,STAINED_CLAY:7,33,STAINED_CLAY:12,33,CONCRETE:12,33,STAINED_CLAY:7,50,STAINED_CLAY:12,100)
RandomBlock(2,15,-2,STAINED_CLAY:7,33,STAINED_CLAY:12,33,CONCRETE:12,33,STAINED_CLAY:7,50,STAINED_CLAY:12,100)
RandomBlock(2,15,-1,STAINED_CLAY:7,33,STAINED_CLAY:12,33,CONCRETE:12,33,STAINED_CLAY:7,50,STAINED_CLAY:12,100)
RandomBlock(2,15,0,STAINED_CLAY:7,33,STAINED_CLAY:12,33,CONCRETE:12,33,STAINED_CLAY:7,50,STAINED_CLAY:12,100)
RandomBlock(2,15,1,STAINED_CLAY:7,33,STAINED_CLAY:12,33,CONCRETE:12,33,STAINED_CLAY:7,50,STAINED_CLAY:12,100)
RandomBlock(2,16,-2,STAINED_CLAY:7,33,STAINED_CLAY:12,33,CONCRETE:12,33,STAINED_CLAY:7,50,STAINED_CLAY:12,100)
RandomBlock(2,16,-1,STAINED_CLAY:7,33,STAINED_CLAY:12,33,CONCRETE:12,33,STAINED_CLAY:7,50,STAINED_CLAY:12,100)
RandomBlock(2,16,0,STAINED_CLAY:7,33,STAINED_CLAY:12,33,CONCRETE:12,33,STAINED_CLAY:7,50,STAINED_CLAY:12,100)
RandomBlock(2,16,1,STAINED_CLAY:7,33,STAINED_CLAY:12,33,CONCRETE:12,33,STAINED_CLAY:7,50,STAINED_CLAY:12,100)
RandomBlock(2,17,-2,STAINED_CLAY:7,33,STAINED_CLAY:12,33,CONCRETE:12,33,STAINED_CLAY:7,50,STAINED_CLAY:12,100)
RandomBlock(2,17,-1,STAINED_CLAY:7,33,STAINED_CLAY:12,33,CONCRETE:12,33,STAINED_CLAY:7,50,STAINED_CLAY:12,100)
RandomBlock(2,17,0,STAINED_CLAY:7,33,STAINED_CLAY:12,33,CONCRETE:12,33,STAINED_CLAY:7,50,STAINED_CLAY:12,100)
RandomBlock(2,17,1,STAINED_CLAY:7,33,STAINED_CLAY:12,33,CONCRETE:12,33,STAINED_CLAY:7,50,STAINED_CLAY:12,100)
RandomBlock(2,18,-2,STAINED_CLAY:7,33,STAINED_CLAY:12,33,CONCRETE:12,33,STAINED_CLAY:7,50,STAINED_CLAY:12,100)
RandomBlock(2,18,-1,STAINED_CLAY:7,33,STAINED_CLAY:12,33,CONCRETE:12,33,STAINED_CLAY:7,50,STAINED_CLAY:12,100)
RandomBlock(2,18,0,STAINED_CLAY:7,33,STAINED_CLAY:12,33,CONCRETE:12,33,STAINED_CLAY:7,50,STAINED_CLAY:12,100)
RandomBlock(2,18,1,STAINED_CLAY:7,33,STAINED_CLAY:12,33,CONCRETE:12,33,STAINED_CLAY:7,50,STAINED_CLAY:12,100)
RandomBlock(2,19,-2,STAINED_CLAY:7,33,STAINED_CLAY:12,33,CONCRETE:12,33,STAINED_CLAY:7,50,STAINED_CLAY:12,100)
RandomBlock(2,19,-1,STAINED_CLAY:7,33,STAINED_CLAY:12,33,CONCRETE:12,33,STAINED_CLAY:7,50,STAINED_CLAY:12,100)
RandomBlock(2,19,0,STAINED_CLAY:7,33,STAINED_CLAY:12,33,CONCRETE:12,33,STAINED_CLAY:7,50,STAINED_CLAY:12,100)
RandomBlock(2,19,1,STAINED_CLAY:7,33,STAINED_CLAY:12,33,CONCRETE:12,33,STAINED_CLAY:7,50,STAINED_CLAY:12,100)
Block(2,20,-4,STEP:13)
Block(2,20,-3,STEP:13)
RandomBlock(2,20,-2,STAINED_CLAY:7,33,STAINED_CLAY:12,33,CONCRETE:12,33,STAINED_CLAY:7,50,STAINED_CLAY:12,100)
RandomBlock(2,20,-1,STAINED_CLAY:7,33,STAINED_CLAY:12,33,CONCRETE:12,33,STAINED_CLAY:7,50,STAINED_CLAY:12,100)
RandomBlock(2,20,0,STAINED_CLAY:7,33,STAINED_CLAY:12,33,CONCRETE:12,33,STAINED_CLAY:7,50,STAINED_CLAY:12,100)
RandomBlock(2,20,1,STAINED_CLAY:7,33,STAINED_CLAY:12,33,CONCRETE:12,33,STAINED_CLAY:7,50,STAINED_CLAY:12,100)
Block(2,20,2,STEP:13)
Block(2,20,3,STEP:13)
Block(2,21,-4,IRON_FENCE:0)
RandomBlock(2,21,-2,SMOOTH_BRICK:0,40,SMOOTH_BRICK:1,20,SMOOTH_BRICK:2,30,SMOOTH_BRICK:0,100)
Block(2,21,0,SMOOTH_BRICK:1)
RandomBlock(2,21,1,SMOOTH_BRICK:0,40,SMOOTH_BRICK:1,20,SMOOTH_BRICK:2,30,SMOOTH_BRICK:0,100)
Block(2,22,-2,SMOOTH_BRICK:2)
Block(2,22,0,SMOOTH_BRICK:2)
Block(2,22,1,SMOOTH_BRICK:2)
RandomBlock(2,23,-2,MONSTER_EGGS:4,30,SMOOTH_BRICK:2,100)
RandomBlock(2,23,-1,SMOOTH_BRICK:0,40,SMOOTH_BRICK:1,20,SMOOTH_BRICK:2,30,SMOOTH_BRICK:0,100)
RandomBlock(2,23,0,SMOOTH_BRICK:0,40,SMOOTH_BRICK:1,20,SMOOTH_BRICK:2,30,SMOOTH_BRICK:0,100)
RandomBlock(2,23,1,SMOOTH_BRICK:0,40,SMOOTH_BRICK:1,20,SMOOTH_BRICK:2,30,SMOOTH_BRICK:0,100)
Block(2,24,-2,STEP:3)
Block(2,24,-1,STEP:3)
Block(2,24,0,STEP:3)
Block(2,24,1,STEP:3)
RandomBlock(3,0,-3,STAINED_CLAY:7,33,STAINED_CLAY:12,33,CONCRETE:12,33,STAINED_CLAY:7,50,STAINED_CLAY:12,100)
RandomBlock(3,0,-2,STAINED_CLAY:7,33,STAINED_CLAY:12,33,CONCRETE:12,33,STAINED_CLAY:7,50,STAINED_CLAY:12,100)
RandomBlock(3,0,-1,STAINED_CLAY:7,33,STAINED_CLAY:12,33,CONCRETE:12,33,STAINED_CLAY:7,50,STAINED_CLAY:12,100)
RandomBlock(3,0,0,STAINED_CLAY:7,33,STAINED_CLAY:12,33,CONCRETE:12,33,STAINED_CLAY:7,50,STAINED_CLAY:12,100)
RandomBlock(3,0,1,STAINED_CLAY:7,33,STAINED_CLAY:12,33,CONCRETE:12,33,STAINED_CLAY:7,50,STAINED_CLAY:12,100)
RandomBlock(3,1,-3,STAINED_CLAY:7,33,STAINED_CLAY:12,33,CONCRETE:12,33,STAINED_CLAY:7,50,STAINED_CLAY:12,100)
RandomBlock(3,1,-2,STAINED_CLAY:7,33,STAINED_CLAY:12,33,CONCRETE:12,33,STAINED_CLAY:7,50,STAINED_CLAY:12,100)
RandomBlock(3,1,-1,STAINED_CLAY:7,33,STAINED_CLAY:12,33,CONCRETE:12,33,STAINED_CLAY:7,50,STAINED_CLAY:12,100)
RandomBlock(3,1,0,STAINED_CLAY:7,33,STAINED_CLAY:12,33,CONCRETE:12,33,STAINED_CLAY:7,50,STAINED_CLAY:12,100)
RandomBlock(3,1,1,STAINED_CLAY:7,33,STAINED_CLAY:12,33,CONCRETE:12,33,STAINED_CLAY:7,50,STAINED_CLAY:12,100)
RandomBlock(3,2,-3,STAINED_CLAY:7,33,STAINED_CLAY:12,33,CONCRETE:12,33,STAINED_CLAY:7,50,STAINED_CLAY:12,100)
Block(3,2,-2,DIRT)
Block(3,2,-1,AIR:0)
Block(3,2,0,AIR:0)
Block(3,2,1,AIR:0)
RandomBlock(3,3,-3,STAINED_CLAY:7,33,STAINED_CLAY:12,33,CONCRETE:12,33,STAINED_CLAY:7,50,STAINED_CLAY:12,100)
Block(3,3,-2,AIR:0)
Block(3,3,-1,AIR:0)
Block(3,3,0,AIR:0)
Block(3,3,1,AIR:0)
RandomBlock(3,4,-3,STAINED_CLAY:7,33,STAINED_CLAY:12,33,CONCRETE:12,33,STAINED_CLAY:7,50,STAINED_CLAY:12,100)
Block(3,4,-2,AIR:0)
Block(3,4,-1,AIR:0)
Block(3,4,0,AIR:0)
Block(3,4,1,AIR:0)
RandomBlock(3,5,-3,STAINED_CLAY:7,33,STAINED_CLAY:12,33,CONCRETE:12,33,STAINED_CLAY:7,50,STAINED_CLAY:12,100)
Block(3,5,-2,AIR:0)
Block(3,5,-1,AIR:0)
Block(3,5,0,AIR:0)
Block(3,5,1,AIR:0)
RandomBlock(3,6,-3,STAINED_CLAY:7,33,STAINED_CLAY:12,33,CONCRETE:12,33,STAINED_CLAY:7,50,STAINED_CLAY:12,100)
Block(3,6,-2,AIR:0)
Block(3,6,-1,AIR:0)
Block(3,6,0,AIR:0)
Block(3,6,1,AIR:0)
RandomBlock(3,6,2,STAINED_CLAY:7,33,STAINED_CLAY:12,33,CONCRETE:12,33,STAINED_CLAY:7,50,STAINED_CLAY:12,100)
RandomBlock(3,7,-3,STAINED_CLAY:7,33,STAINED_CLAY:12,33,CONCRETE:12,33,STAINED_CLAY:7,50,STAINED_CLAY:12,100)
Block(3,7,-2,AIR:0)
Block(3,7,-1,AIR:0)
Block(3,7,0,AIR:0)
Block(3,7,1,AIR:0)
RandomBlock(3,7,2,STAINED_CLAY:7,33,STAINED_CLAY:12,33,CONCRETE:12,33,STAINED_CLAY:7,50,STAINED_CLAY:12,100)
RandomBlock(3,8,-3,STAINED_CLAY:7,33,STAINED_CLAY:12,33,CONCRETE:12,33,STAINED_CLAY:7,50,STAINED_CLAY:12,100)
Block(3,8,-2,AIR:0)
Block(3,8,-1,AIR:0)
Block(3,8,0,AIR:0)
Block(3,8,1,AIR:0)
RandomBlock(3,8,2,STAINED_CLAY:7,33,STAINED_CLAY:12,33,CONCRETE:12,33,STAINED_CLAY:7,50,STAINED_CLAY:12,100)
RandomBlock(3,9,-3,STAINED_CLAY:7,33,STAINED_CLAY:12,33,CONCRETE:12,33,STAINED_CLAY:7,50,STAINED_CLAY:12,100)
Block(3,9,-2,AIR:0)
Block(3,9,-1,AIR:0)
Block(3,9,0,AIR:0)
Block(3,9,1,AIR:0)
RandomBlock(3,9,2,STAINED_CLAY:7,33,STAINED_CLAY:12,33,CONCRETE:12,33,STAINED_CLAY:7,50,STAINED_CLAY:12,100)
Block(3,10,-4,STONE_BUTTON:4)
RandomBlock(3,10,-3,STAINED_CLAY:7,33,STAINED_CLAY:12,33,CONCRETE:12,33,STAINED_CLAY:7,50,STAINED_CLAY:12,100)
Block(3,10,-2,AIR:0)
Block(3,10,-1,AIR:0)
Block(3,10,0,AIR:0)
Block(3,10,1,AIR:0)
RandomBlock(3,10,2,STAINED_CLAY:7,33,STAINED_CLAY:12,33,CONCRETE:12,33,STAINED_CLAY:7,50,STAINED_CLAY:12,100)
Block(3,10,3,STONE_BUTTON:3)
RandomBlock(3,11,-3,STAINED_CLAY:7,33,STAINED_CLAY:12,33,CONCRETE:12,33,STAINED_CLAY:7,50,STAINED_CLAY:12,100)
Block(3,11,-2,AIR:0)
Block(3,11,-1,AIR:0)
Block(3,11,0,AIR:0)
Block(3,11,1,AIR:0)
RandomBlock(3,11,2,STAINED_CLAY:7,33,STAINED_CLAY:12,33,CONCRETE:12,33,STAINED_CLAY:7,50,STAINED_CLAY:12,100)
RandomBlock(3,12,-3,STAINED_CLAY:7,33,STAINED_CLAY:12,33,CONCRETE:12,33,STAINED_CLAY:7,50,STAINED_CLAY:12,100)
Block(3,12,-2,AIR:0)
Block(3,12,-1,AIR:0)
Block(3,12,0,AIR:0)
Block(3,12,1,AIR:0)
RandomBlock(3,12,2,STAINED_CLAY:7,33,STAINED_CLAY:12,33,CONCRETE:12,33,STAINED_CLAY:7,50,STAINED_CLAY:12,100)
Block(3,12,3,quark:iron_plate:1)
RandomBlock(3,12,4,STAINED_CLAY:7,33,STAINED_CLAY:12,33,CONCRETE:12,33,STAINED_CLAY:7,50,STAINED_CLAY:12,100)
RandomBlock(3,13,-3,STAINED_CLAY:7,33,STAINED_CLAY:12,33,CONCRETE:12,33,STAINED_CLAY:7,50,STAINED_CLAY:12,100)
Block(3,13,-2,AIR:0)
Block(3,13,-1,AIR:0)
Block(3,13,0,AIR:0)
Block(3,13,1,AIR:0)
RandomBlock(3,13,2,STAINED_CLAY:7,33,STAINED_CLAY:12,33,CONCRETE:12,33,STAINED_CLAY:7,50,STAINED_CLAY:12,100)
Block(3,13,3,quark:iron_plate:1)
RandomBlock(3,13,4,STAINED_CLAY:7,33,STAINED_CLAY:12,33,CONCRETE:12,33,STAINED_CLAY:7,50,STAINED_CLAY:12,100)
RandomBlock(3,14,-3,STAINED_CLAY:7,33,STAINED_CLAY:12,33,CONCRETE:12,33,STAINED_CLAY:7,50,STAINED_CLAY:12,100)
Block(3,14,-2,AIR:0)
Block(3,14,-1,AIR:0)
Block(3,14,0,AIR:0)
Block(3,14,1,AIR:0)
RandomBlock(3,14,2,STAINED_CLAY:7,33,STAINED_CLAY:12,33,CONCRETE:12,33,STAINED_CLAY:7,50,STAINED_CLAY:12,100)
Block(3,15,-4,STONE_BUTTON:4)
RandomBlock(3,15,-3,STAINED_CLAY:7,33,STAINED_CLAY:12,33,CONCRETE:12,33,STAINED_CLAY:7,50,STAINED_CLAY:12,100)
Block(3,15,-2,AIR:0)
Block(3,15,-1,AIR:0)
Block(3,15,0,AIR:0)
Block(3,15,1,AIR:0)
RandomBlock(3,15,2,STAINED_CLAY:7,33,STAINED_CLAY:12,33,CONCRETE:12,33,STAINED_CLAY:7,50,STAINED_CLAY:12,100)
Block(3,15,3,STONE_BUTTON:3)
RandomBlock(3,16,-3,STAINED_CLAY:7,33,STAINED_CLAY:12,33,CONCRETE:12,33,STAINED_CLAY:7,50,STAINED_CLAY:12,100)
Block(3,16,-2,AIR:0)
Block(3,16,-1,AIR:0)
Block(3,16,0,AIR:0)
Block(3,16,1,AIR:0)
RandomBlock(3,16,2,STAINED_CLAY:7,33,STAINED_CLAY:12,33,CONCRETE:12,33,STAINED_CLAY:7,50,STAINED_CLAY:12,100)
RandomBlock(3,17,-3,STAINED_CLAY:7,33,STAINED_CLAY:12,33,CONCRETE:12,33,STAINED_CLAY:7,50,STAINED_CLAY:12,100)
Block(3,17,-2,AIR:0)
Block(3,17,-1,AIR:0)
Block(3,17,0,AIR:0)
Block(3,17,1,AIR:0)
RandomBlock(3,17,2,STAINED_CLAY:7,33,STAINED_CLAY:12,33,CONCRETE:12,33,STAINED_CLAY:7,50,STAINED_CLAY:12,100)
RandomBlock(3,18,-3,STAINED_CLAY:7,33,STAINED_CLAY:12,33,CONCRETE:12,33,STAINED_CLAY:7,50,STAINED_CLAY:12,100)
Block(3,18,-2,AIR:0)
Block(3,18,-1,AIR:0)
Block(3,18,0,AIR:0)
Block(3,18,1,AIR:0)
RandomBlock(3,18,2,STAINED_CLAY:7,33,STAINED_CLAY:12,33,CONCRETE:12,33,STAINED_CLAY:7,50,STAINED_CLAY:12,100)
Block(3,19,-4,STONE_BUTTON:4)
RandomBlock(3,19,-3,STAINED_CLAY:7,33,STAINED_CLAY:12,33,CONCRETE:12,33,STAINED_CLAY:7,50,STAINED_CLAY:12,100)
Block(3,19,-2,AIR:0)
Block(3,19,-1,AIR:0)
Block(3,19,0,AIR:0)
Block(3,19,1,AIR:0)
RandomBlock(3,19,2,STAINED_CLAY:7,33,STAINED_CLAY:12,33,CONCRETE:12,33,STAINED_CLAY:7,50,STAINED_CLAY:12,100)
Block(3,19,3,STONE_BUTTON:3)
Block(3,20,-4,STEP:13)
RandomBlock(3,20,-3,STAINED_CLAY:7,33,STAINED_CLAY:12,33,CONCRETE:12,33,STAINED_CLAY:7,50,STAINED_CLAY:12,100)
RandomBlock(3,20,-2,STAINED_CLAY:7,33,STAINED_CLAY:12,33,CONCRETE:12,33,STAINED_CLAY:7,50,STAINED_CLAY:12,100)
RandomBlock(3,20,-1,STAINED_CLAY:7,33,STAINED_CLAY:12,33,CONCRETE:12,33,STAINED_CLAY:7,50,STAINED_CLAY:12,100)
RandomBlock(3,20,0,STAINED_CLAY:7,33,STAINED_CLAY:12,33,CONCRETE:12,33,STAINED_CLAY:7,50,STAINED_CLAY:12,100)
RandomBlock(3,20,1,STAINED_CLAY:7,33,STAINED_CLAY:12,33,CONCRETE:12,33,STAINED_CLAY:7,50,STAINED_CLAY:12,100)
RandomBlock(3,20,2,STAINED_CLAY:7,33,STAINED_CLAY:12,33,CONCRETE:12,33,STAINED_CLAY:7,50,STAINED_CLAY:12,100)
Block(3,20,3,STEP:13)
Block(3,21,-4,IRON_FENCE:0)
Block(3,21,3,IRON_FENCE:0)
RandomBlock(4,0,-3,STAINED_CLAY:7,33,STAINED_CLAY:12,33,CONCRETE:12,33,STAINED_CLAY:7,50,STAINED_CLAY:12,100)
RandomBlock(4,0,-2,STAINED_CLAY:7,33,STAINED_CLAY:12,33,CONCRETE:12,33,STAINED_CLAY:7,50,STAINED_CLAY:12,100)
RandomBlock(4,0,-1,STAINED_CLAY:7,33,STAINED_CLAY:12,33,CONCRETE:12,33,STAINED_CLAY:7,50,STAINED_CLAY:12,100)
RandomBlock(4,0,0,STAINED_CLAY:7,33,STAINED_CLAY:12,33,CONCRETE:12,33,STAINED_CLAY:7,50,STAINED_CLAY:12,100)
RandomBlock(4,0,1,STAINED_CLAY:7,33,STAINED_CLAY:12,33,CONCRETE:12,33,STAINED_CLAY:7,50,STAINED_CLAY:12,100)
RandomBlock(4,0,2,STAINED_CLAY:7,33,STAINED_CLAY:12,33,CONCRETE:12,33,STAINED_CLAY:7,50,STAINED_CLAY:12,100)
RandomBlock(4,1,-3,STAINED_CLAY:7,33,STAINED_CLAY:12,33,CONCRETE:12,33,STAINED_CLAY:7,50,STAINED_CLAY:12,100)
RandomBlock(4,1,-2,STAINED_CLAY:7,33,STAINED_CLAY:12,33,CONCRETE:12,33,STAINED_CLAY:7,50,STAINED_CLAY:12,100)
RandomBlock(4,1,-1,STAINED_CLAY:7,33,STAINED_CLAY:12,33,CONCRETE:12,33,STAINED_CLAY:7,50,STAINED_CLAY:12,100)
RandomBlock(4,1,0,STAINED_CLAY:7,33,STAINED_CLAY:12,33,CONCRETE:12,33,STAINED_CLAY:7,50,STAINED_CLAY:12,100)
RandomBlock(4,1,1,STAINED_CLAY:7,33,STAINED_CLAY:12,33,CONCRETE:12,33,STAINED_CLAY:7,50,STAINED_CLAY:12,100)
RandomBlock(4,1,2,STAINED_CLAY:7,33,STAINED_CLAY:12,33,CONCRETE:12,33,STAINED_CLAY:7,50,STAINED_CLAY:12,100)
RandomBlock(4,2,-3,STAINED_CLAY:7,33,STAINED_CLAY:12,33,CONCRETE:12,33,STAINED_CLAY:7,50,STAINED_CLAY:12,100)
Block(4,2,-2,DIRT)
Block(4,2,-1,DIRT)
Block(4,2,0,AIR:0)
Block(4,2,1,AIR:0)
RandomBlock(4,2,2,STAINED_CLAY:7,33,STAINED_CLAY:12,33,CONCRETE:12,33,STAINED_CLAY:7,50,STAINED_CLAY:12,100)
RandomBlock(4,3,-3,STAINED_CLAY:7,33,STAINED_CLAY:12,33,CONCRETE:12,33,STAINED_CLAY:7,50,STAINED_CLAY:12,100)
Block(4,3,-2,AIR:0)
Block(4,3,-1,AIR:0)
Block(4,3,0,AIR:0)
Block(4,3,1,AIR:0)
RandomBlock(4,4,-3,STAINED_CLAY:7,33,STAINED_CLAY:12,33,CONCRETE:12,33,STAINED_CLAY:7,50,STAINED_CLAY:12,100)
Block(4,4,-2,AIR:0)
Block(4,4,-1,AIR:0)
Block(4,4,0,AIR:0)
Block(4,4,1,AIR:0)
RandomBlock(4,5,-3,STAINED_CLAY:7,33,STAINED_CLAY:12,33,CONCRETE:12,33,STAINED_CLAY:7,50,STAINED_CLAY:12,100)
Block(4,5,-2,AIR:0)
Block(4,5,-1,AIR:0)
Block(4,5,0,AIR:0)
Block(4,5,1,AIR:0)
RandomBlock(4,5,2,STAINED_CLAY:7,33,STAINED_CLAY:12,33,CONCRETE:12,33,STAINED_CLAY:7,50,STAINED_CLAY:12,100)
RandomBlock(4,6,-3,STAINED_CLAY:7,33,STAINED_CLAY:12,33,CONCRETE:12,33,STAINED_CLAY:7,50,STAINED_CLAY:12,100)
Block(4,6,-2,AIR:0)
Block(4,6,-1,AIR:0)
Block(4,6,0,AIR:0)
Block(4,6,1,AIR:0)
RandomBlock(4,6,2,STAINED_CLAY:7,33,STAINED_CLAY:12,33,CONCRETE:12,33,STAINED_CLAY:7,50,STAINED_CLAY:12,100)
RandomBlock(4,7,-3,STAINED_CLAY:7,33,STAINED_CLAY:12,33,CONCRETE:12,33,STAINED_CLAY:7,50,STAINED_CLAY:12,100)
Block(4,7,-2,AIR:0)
Block(4,7,-1,AIR:0)
Block(4,7,0,AIR:0)
Block(4,7,1,AIR:0)
RandomBlock(4,7,2,STAINED_CLAY:7,33,STAINED_CLAY:12,33,CONCRETE:12,33,STAINED_CLAY:7,50,STAINED_CLAY:12,100)
RandomBlock(4,8,-3,STAINED_CLAY:7,33,STAINED_CLAY:12,33,CONCRETE:12,33,STAINED_CLAY:7,50,STAINED_CLAY:12,100)
Block(4,8,-2,AIR:0)
Block(4,8,-1,AIR:0)
Block(4,8,0,AIR:0)
Block(4,8,1,AIR:0)
RandomBlock(4,8,2,STAINED_CLAY:7,33,STAINED_CLAY:12,33,CONCRETE:12,33,STAINED_CLAY:7,50,STAINED_CLAY:12,100)
RandomBlock(4,9,-3,STAINED_CLAY:7,33,STAINED_CLAY:12,33,CONCRETE:12,33,STAINED_CLAY:7,50,STAINED_CLAY:12,100)
Block(4,9,-2,AIR:0)
Block(4,9,-1,AIR:0)
Block(4,9,0,AIR:0)
Block(4,9,1,AIR:0)
RandomBlock(4,9,2,STAINED_CLAY:7,33,STAINED_CLAY:12,33,CONCRETE:12,33,STAINED_CLAY:7,50,STAINED_CLAY:12,100)
RandomBlock(4,10,-3,STAINED_CLAY:7,33,STAINED_CLAY:12,33,CONCRETE:12,33,STAINED_CLAY:7,50,STAINED_CLAY:12,100)
Block(4,10,-2,AIR:0)
Block(4,10,-1,AIR:0)
Block(4,10,0,AIR:0)
Block(4,10,1,AIR:0)
RandomBlock(4,10,2,STAINED_CLAY:7,33,STAINED_CLAY:12,33,CONCRETE:12,33,STAINED_CLAY:7,50,STAINED_CLAY:12,100)
RandomBlock(4,11,-3,STAINED_CLAY:7,33,STAINED_CLAY:12,33,CONCRETE:12,33,STAINED_CLAY:7,50,STAINED_CLAY:12,100)
Block(4,11,-2,AIR:0)
Block(4,11,-1,AIR:0)
Block(4,11,0,AIR:0)
Block(4,11,1,AIR:0)
RandomBlock(4,11,2,STAINED_CLAY:7,33,STAINED_CLAY:12,33,CONCRETE:12,33,STAINED_CLAY:7,50,STAINED_CLAY:12,100)
Block(4,11,3,quark:iron_plate:1)
RandomBlock(4,11,4,STAINED_CLAY:7,33,STAINED_CLAY:12,33,CONCRETE:12,33,STAINED_CLAY:7,50,STAINED_CLAY:12,100)
RandomBlock(4,12,-3,STAINED_CLAY:7,33,STAINED_CLAY:12,33,CONCRETE:12,33,STAINED_CLAY:7,50,STAINED_CLAY:12,100)
Block(4,12,-2,AIR:0)
Block(4,12,-1,AIR:0)
Block(4,12,0,AIR:0)
Block(4,12,1,AIR:0)
Block(4,12,4,IRON_FENCE:0)
RandomBlock(4,13,-3,STAINED_CLAY:7,33,STAINED_CLAY:12,33,CONCRETE:12,33,STAINED_CLAY:7,50,STAINED_CLAY:12,100)
Block(4,13,-2,AIR:0)
Block(4,13,-1,AIR:0)
Block(4,13,0,AIR:0)
Block(4,13,1,AIR:0)
Block(4,13,4,IRON_FENCE:0)
RandomBlock(4,14,-3,STAINED_CLAY:7,33,STAINED_CLAY:12,33,CONCRETE:12,33,STAINED_CLAY:7,50,STAINED_CLAY:12,100)
Block(4,14,-2,AIR:0)
Block(4,14,-1,AIR:0)
Block(4,14,0,AIR:0)
Block(4,14,1,AIR:0)
RandomBlock(4,14,2,STAINED_CLAY:7,33,STAINED_CLAY:12,33,CONCRETE:12,33,STAINED_CLAY:7,50,STAINED_CLAY:12,100)
Block(4,14,3,quark:iron_plate:1)
RandomBlock(4,14,4,STAINED_CLAY:7,33,STAINED_CLAY:12,33,CONCRETE:12,33,STAINED_CLAY:7,50,STAINED_CLAY:12,100)
RandomBlock(4,15,-3,STAINED_CLAY:7,33,STAINED_CLAY:12,33,CONCRETE:12,33,STAINED_CLAY:7,50,STAINED_CLAY:12,100)
Block(4,15,-2,AIR:0)
Block(4,15,-1,AIR:0)
Block(4,15,0,AIR:0)
Block(4,15,1,AIR:0)
RandomBlock(4,15,2,STAINED_CLAY:7,33,STAINED_CLAY:12,33,CONCRETE:12,33,STAINED_CLAY:7,50,STAINED_CLAY:12,100)
RandomBlock(4,16,-3,STAINED_CLAY:7,33,STAINED_CLAY:12,33,CONCRETE:12,33,STAINED_CLAY:7,50,STAINED_CLAY:12,100)
Block(4,16,-2,AIR:0)
Block(4,16,-1,AIR:0)
Block(4,16,0,AIR:0)
Block(4,16,1,AIR:0)
RandomBlock(4,16,2,STAINED_CLAY:7,33,STAINED_CLAY:12,33,CONCRETE:12,33,STAINED_CLAY:7,50,STAINED_CLAY:12,100)
RandomBlock(4,17,-3,STAINED_CLAY:7,33,STAINED_CLAY:12,33,CONCRETE:12,33,STAINED_CLAY:7,50,STAINED_CLAY:12,100)
Block(4,17,-2,AIR:0)
Block(4,17,-1,AIR:0)
Block(4,17,0,AIR:0)
Block(4,17,1,AIR:0)
RandomBlock(4,17,2,STAINED_CLAY:7,33,STAINED_CLAY:12,33,CONCRETE:12,33,STAINED_CLAY:7,50,STAINED_CLAY:12,100)
RandomBlock(4,18,-3,STAINED_CLAY:7,33,STAINED_CLAY:12,33,CONCRETE:12,33,STAINED_CLAY:7,50,STAINED_CLAY:12,100)
Block(4,18,-2,AIR:0)
Block(4,18,-1,AIR:0)
Block(4,18,0,AIR:0)
Block(4,18,1,AIR:0)
RandomBlock(4,18,2,STAINED_CLAY:7,33,STAINED_CLAY:12,33,CONCRETE:12,33,STAINED_CLAY:7,50,STAINED_CLAY:12,100)
RandomBlock(4,19,-3,STAINED_CLAY:7,33,STAINED_CLAY:12,33,CONCRETE:12,33,STAINED_CLAY:7,50,STAINED_CLAY:12,100)
Block(4,19,-2,AIR:0)
Block(4,19,-1,AIR:0)
Block(4,19,0,AIR:0)
Block(4,19,1,AIR:0)
RandomBlock(4,19,2,STAINED_CLAY:7,33,STAINED_CLAY:12,33,CONCRETE:12,33,STAINED_CLAY:7,50,STAINED_CLAY:12,100)
Block(4,20,-4,DOUBLE_STEP:5)
RandomBlock(4,20,-3,STAINED_CLAY:7,33,STAINED_CLAY:12,33,CONCRETE:12,33,STAINED_CLAY:7,50,STAINED_CLAY:12,100)
RandomBlock(4,20,-2,STAINED_CLAY:7,33,STAINED_CLAY:12,33,CONCRETE:12,33,STAINED_CLAY:7,50,STAINED_CLAY:12,100)
RandomBlock(4,20,-1,STAINED_CLAY:7,33,STAINED_CLAY:12,33,CONCRETE:12,33,STAINED_CLAY:7,50,STAINED_CLAY:12,100)
RandomBlock(4,20,0,STAINED_CLAY:7,33,STAINED_CLAY:12,33,CONCRETE:12,33,STAINED_CLAY:7,50,STAINED_CLAY:12,100)
RandomBlock(4,20,1,STAINED_CLAY:7,33,STAINED_CLAY:12,33,CONCRETE:12,33,STAINED_CLAY:7,50,STAINED_CLAY:12,100)
RandomBlock(4,20,2,STAINED_CLAY:7,33,STAINED_CLAY:12,33,CONCRETE:12,33,STAINED_CLAY:7,50,STAINED_CLAY:12,100)
Block(4,20,3,DOUBLE_STEP:5)
Block(4,21,-4,IRON_FENCE:0)
Block(4,21,3,IRON_FENCE:0)
RandomBlock(5,0,-3,STAINED_CLAY:7,33,STAINED_CLAY:12,33,CONCRETE:12,33,STAINED_CLAY:7,50,STAINED_CLAY:12,100)
RandomBlock(5,0,-2,STAINED_CLAY:7,33,STAINED_CLAY:12,33,CONCRETE:12,33,STAINED_CLAY:7,50,STAINED_CLAY:12,100)
RandomBlock(5,0,-1,STAINED_CLAY:7,33,STAINED_CLAY:12,33,CONCRETE:12,33,STAINED_CLAY:7,50,STAINED_CLAY:12,100)
RandomBlock(5,0,0,STAINED_CLAY:7,33,STAINED_CLAY:12,33,CONCRETE:12,33,STAINED_CLAY:7,50,STAINED_CLAY:12,100)
RandomBlock(5,0,1,STAINED_CLAY:7,33,STAINED_CLAY:12,33,CONCRETE:12,33,STAINED_CLAY:7,50,STAINED_CLAY:12,100)
RandomBlock(5,0,2,STAINED_CLAY:7,33,STAINED_CLAY:12,33,CONCRETE:12,33,STAINED_CLAY:7,50,STAINED_CLAY:12,100)
RandomBlock(5,1,-3,STAINED_CLAY:7,33,STAINED_CLAY:12,33,CONCRETE:12,33,STAINED_CLAY:7,50,STAINED_CLAY:12,100)
RandomBlock(5,1,-2,STAINED_CLAY:7,33,STAINED_CLAY:12,33,CONCRETE:12,33,STAINED_CLAY:7,50,STAINED_CLAY:12,100)
RandomBlock(5,1,-1,STAINED_CLAY:7,33,STAINED_CLAY:12,33,CONCRETE:12,33,STAINED_CLAY:7,50,STAINED_CLAY:12,100)
RandomBlock(5,1,0,STAINED_CLAY:7,33,STAINED_CLAY:12,33,CONCRETE:12,33,STAINED_CLAY:7,50,STAINED_CLAY:12,100)
RandomBlock(5,1,1,STAINED_CLAY:7,33,STAINED_CLAY:12,33,CONCRETE:12,33,STAINED_CLAY:7,50,STAINED_CLAY:12,100)
RandomBlock(5,1,2,STAINED_CLAY:7,33,STAINED_CLAY:12,33,CONCRETE:12,33,STAINED_CLAY:7,50,STAINED_CLAY:12,100)
RandomBlock(5,2,-3,STAINED_CLAY:7,33,STAINED_CLAY:12,33,CONCRETE:12,33,STAINED_CLAY:7,50,STAINED_CLAY:12,100)
Block(5,2,-2,DIRT)
Block(5,2,-1,DIRT)
Block(5,2,0,AIR:0)
Block(5,2,1,AIR:0)
RandomBlock(5,2,2,STAINED_CLAY:7,33,STAINED_CLAY:12,33,CONCRETE:12,33,STAINED_CLAY:7,50,STAINED_CLAY:12,100)
RandomBlock(5,3,-3,STAINED_CLAY:7,33,STAINED_CLAY:12,33,CONCRETE:12,33,STAINED_CLAY:7,50,STAINED_CLAY:12,100)
Block(5,3,-2,DIRT)
Block(5,3,-1,AIR:0)
Block(5,3,0,AIR:0)
Block(5,3,1,AIR:0)
RandomBlock(5,4,-3,STAINED_CLAY:7,33,STAINED_CLAY:12,33,CONCRETE:12,33,STAINED_CLAY:7,50,STAINED_CLAY:12,100)
Block(5,4,-2,AIR:0)
Block(5,4,-1,AIR:0)
Block(5,4,0,AIR:0)
Block(5,4,1,AIR:0)
RandomBlock(5,5,-3,STAINED_CLAY:7,33,STAINED_CLAY:12,33,CONCRETE:12,33,STAINED_CLAY:7,50,STAINED_CLAY:12,100)
Block(5,5,-2,AIR:0)
Block(5,5,-1,AIR:0)
Block(5,5,0,AIR:0)
Block(5,5,1,AIR:0)
RandomBlock(5,5,2,STAINED_CLAY:7,33,STAINED_CLAY:12,33,CONCRETE:12,33,STAINED_CLAY:7,50,STAINED_CLAY:12,100)
RandomBlock(5,6,-3,STAINED_CLAY:7,33,STAINED_CLAY:12,33,CONCRETE:12,33,STAINED_CLAY:7,50,STAINED_CLAY:12,100)
Block(5,6,-2,AIR:0)
Block(5,6,-1,AIR:0)
Block(5,6,0,AIR:0)
Block(5,6,1,AIR:0)
RandomBlock(5,6,2,STAINED_CLAY:7,33,STAINED_CLAY:12,33,CONCRETE:12,33,STAINED_CLAY:7,50,STAINED_CLAY:12,100)
RandomBlock(5,7,-3,STAINED_CLAY:7,33,STAINED_CLAY:12,33,CONCRETE:12,33,STAINED_CLAY:7,50,STAINED_CLAY:12,100)
Block(5,7,-2,AIR:0)
Block(5,7,-1,AIR:0)
Block(5,7,0,AIR:0)
Block(5,7,1,AIR:0)
RandomBlock(5,7,2,STAINED_CLAY:7,33,STAINED_CLAY:12,33,CONCRETE:12,33,STAINED_CLAY:7,50,STAINED_CLAY:12,100)
RandomBlock(5,8,-3,STAINED_CLAY:7,33,STAINED_CLAY:12,33,CONCRETE:12,33,STAINED_CLAY:7,50,STAINED_CLAY:12,100)
Block(5,8,-2,AIR:0)
Block(5,8,-1,AIR:0)
Block(5,8,0,AIR:0)
Block(5,8,1,AIR:0)
RandomBlock(5,8,2,STAINED_CLAY:7,33,STAINED_CLAY:12,33,CONCRETE:12,33,STAINED_CLAY:7,50,STAINED_CLAY:12,100)
RandomBlock(5,9,-3,STAINED_CLAY:7,33,STAINED_CLAY:12,33,CONCRETE:12,33,STAINED_CLAY:7,50,STAINED_CLAY:12,100)
Block(5,9,-2,AIR:0)
Block(5,9,-1,AIR:0)
Block(5,9,0,AIR:0)
Block(5,9,1,AIR:0)
RandomBlock(5,9,2,STAINED_CLAY:7,33,STAINED_CLAY:12,33,CONCRETE:12,33,STAINED_CLAY:7,50,STAINED_CLAY:12,100)
RandomBlock(5,10,-3,STAINED_CLAY:7,33,STAINED_CLAY:12,33,CONCRETE:12,33,STAINED_CLAY:7,50,STAINED_CLAY:12,100)
Block(5,10,-2,AIR:0)
Block(5,10,-1,AIR:0)
Block(5,10,0,AIR:0)
Block(5,10,1,AIR:0)
RandomBlock(5,10,2,STAINED_CLAY:7,33,STAINED_CLAY:12,33,CONCRETE:12,33,STAINED_CLAY:7,50,STAINED_CLAY:12,100)
RandomBlock(5,11,-3,STAINED_CLAY:7,33,STAINED_CLAY:12,33,CONCRETE:12,33,STAINED_CLAY:7,50,STAINED_CLAY:12,100)
Block(5,11,-2,AIR:0)
Block(5,11,-1,AIR:0)
Block(5,11,0,AIR:0)
Block(5,11,1,AIR:0)
RandomBlock(5,11,2,STAINED_CLAY:7,33,STAINED_CLAY:12,33,CONCRETE:12,33,STAINED_CLAY:7,50,STAINED_CLAY:12,100)
Block(5,11,3,quark:iron_plate:1)
RandomBlock(5,11,4,STAINED_CLAY:7,33,STAINED_CLAY:12,33,CONCRETE:12,33,STAINED_CLAY:7,50,STAINED_CLAY:12,100)
Block(5,12,-2,AIR:0)
Block(5,12,-1,AIR:0)
Block(5,12,0,AIR:0)
Block(5,12,1,AIR:0)
Block(5,12,4,IRON_FENCE:0)
Block(5,13,-2,AIR:0)
Block(5,13,-1,AIR:0)
Block(5,13,0,AIR:0)
Block(5,13,1,AIR:0)
RandomBlock(5,14,-3,STAINED_CLAY:7,33,STAINED_CLAY:12,33,CONCRETE:12,33,STAINED_CLAY:7,50,STAINED_CLAY:12,100)
Block(5,14,-2,AIR:0)
Block(5,14,-1,AIR:0)
Block(5,14,0,AIR:0)
Block(5,14,1,AIR:0)
RandomBlock(5,14,2,STAINED_CLAY:7,33,STAINED_CLAY:12,33,CONCRETE:12,33,STAINED_CLAY:7,50,STAINED_CLAY:12,100)
Block(5,14,3,quark:iron_plate:1)
RandomBlock(5,14,4,STAINED_CLAY:7,33,STAINED_CLAY:12,33,CONCRETE:12,33,STAINED_CLAY:7,50,STAINED_CLAY:12,100)
RandomBlock(5,15,-3,STAINED_CLAY:7,33,STAINED_CLAY:12,33,CONCRETE:12,33,STAINED_CLAY:7,50,STAINED_CLAY:12,100)
Block(5,15,-2,AIR:0)
Block(5,15,-1,AIR:0)
Block(5,15,0,AIR:0)
Block(5,15,1,AIR:0)
RandomBlock(5,15,2,STAINED_CLAY:7,33,STAINED_CLAY:12,33,CONCRETE:12,33,STAINED_CLAY:7,50,STAINED_CLAY:12,100)
RandomBlock(5,16,-3,STAINED_CLAY:7,33,STAINED_CLAY:12,33,CONCRETE:12,33,STAINED_CLAY:7,50,STAINED_CLAY:12,100)
Block(5,16,-2,AIR:0)
Block(5,16,-1,AIR:0)
Block(5,16,0,AIR:0)
Block(5,16,1,AIR:0)
RandomBlock(5,16,2,STAINED_CLAY:7,33,STAINED_CLAY:12,33,CONCRETE:12,33,STAINED_CLAY:7,50,STAINED_CLAY:12,100)
RandomBlock(5,17,-3,STAINED_CLAY:7,33,STAINED_CLAY:12,33,CONCRETE:12,33,STAINED_CLAY:7,50,STAINED_CLAY:12,100)
Block(5,17,-2,AIR:0)
Block(5,17,-1,AIR:0)
Block(5,17,0,AIR:0)
Block(5,17,1,AIR:0)
RandomBlock(5,17,2,STAINED_CLAY:7,33,STAINED_CLAY:12,33,CONCRETE:12,33,STAINED_CLAY:7,50,STAINED_CLAY:12,100)
RandomBlock(5,18,-3,STAINED_CLAY:7,33,STAINED_CLAY:12,33,CONCRETE:12,33,STAINED_CLAY:7,50,STAINED_CLAY:12,100)
Block(5,18,-2,AIR:0)
Block(5,18,-1,AIR:0)
Block(5,18,0,AIR:0)
Block(5,18,1,AIR:0)
RandomBlock(5,18,2,STAINED_CLAY:7,33,STAINED_CLAY:12,33,CONCRETE:12,33,STAINED_CLAY:7,50,STAINED_CLAY:12,100)
RandomBlock(5,19,-3,STAINED_CLAY:7,33,STAINED_CLAY:12,33,CONCRETE:12,33,STAINED_CLAY:7,50,STAINED_CLAY:12,100)
Block(5,19,-2,AIR:0)
Block(5,19,-1,AIR:0)
Block(5,19,0,AIR:0)
Block(5,19,1,AIR:0)
RandomBlock(5,19,2,STAINED_CLAY:7,33,STAINED_CLAY:12,33,CONCRETE:12,33,STAINED_CLAY:7,50,STAINED_CLAY:12,100)
Block(5,20,-4,DOUBLE_STEP:5)
RandomBlock(5,20,-3,STAINED_CLAY:7,33,STAINED_CLAY:12,33,CONCRETE:12,33,STAINED_CLAY:7,50,STAINED_CLAY:12,100)
RandomBlock(5,20,-2,STAINED_CLAY:7,33,STAINED_CLAY:12,33,CONCRETE:12,33,STAINED_CLAY:7,50,STAINED_CLAY:12,100)
RandomBlock(5,20,-1,STAINED_CLAY:7,33,STAINED_CLAY:12,33,CONCRETE:12,33,STAINED_CLAY:7,50,STAINED_CLAY:12,100)
RandomBlock(5,20,0,STAINED_CLAY:7,33,STAINED_CLAY:12,33,CONCRETE:12,33,STAINED_CLAY:7,50,STAINED_CLAY:12,100)
RandomBlock(5,20,1,STAINED_CLAY:7,33,STAINED_CLAY:12,33,CONCRETE:12,33,STAINED_CLAY:7,50,STAINED_CLAY:12,100)
RandomBlock(5,20,2,STAINED_CLAY:7,33,STAINED_CLAY:12,33,CONCRETE:12,33,STAINED_CLAY:7,50,STAINED_CLAY:12,100)
Block(5,20,3,DOUBLE_STEP:5)
Block(5,21,3,IRON_FENCE:0)
RandomBlock(6,0,-3,STAINED_CLAY:7,33,STAINED_CLAY:12,33,CONCRETE:12,33,STAINED_CLAY:7,50,STAINED_CLAY:12,100)
RandomBlock(6,0,-2,STAINED_CLAY:7,33,STAINED_CLAY:12,33,CONCRETE:12,33,STAINED_CLAY:7,50,STAINED_CLAY:12,100)
RandomBlock(6,0,-1,STAINED_CLAY:7,33,STAINED_CLAY:12,33,CONCRETE:12,33,STAINED_CLAY:7,50,STAINED_CLAY:12,100)
RandomBlock(6,0,0,STAINED_CLAY:7,33,STAINED_CLAY:12,33,CONCRETE:12,33,STAINED_CLAY:7,50,STAINED_CLAY:12,100)
RandomBlock(6,0,1,STAINED_CLAY:7,33,STAINED_CLAY:12,33,CONCRETE:12,33,STAINED_CLAY:7,50,STAINED_CLAY:12,100)
RandomBlock(6,0,2,STAINED_CLAY:7,33,STAINED_CLAY:12,33,CONCRETE:12,33,STAINED_CLAY:7,50,STAINED_CLAY:12,100)
RandomBlock(6,1,-3,STAINED_CLAY:7,33,STAINED_CLAY:12,33,CONCRETE:12,33,STAINED_CLAY:7,50,STAINED_CLAY:12,100)
RandomBlock(6,1,-2,STAINED_CLAY:7,33,STAINED_CLAY:12,33,CONCRETE:12,33,STAINED_CLAY:7,50,STAINED_CLAY:12,100)
RandomBlock(6,1,-1,STAINED_CLAY:7,33,STAINED_CLAY:12,33,CONCRETE:12,33,STAINED_CLAY:7,50,STAINED_CLAY:12,100)
RandomBlock(6,1,0,STAINED_CLAY:7,33,STAINED_CLAY:12,33,CONCRETE:12,33,STAINED_CLAY:7,50,STAINED_CLAY:12,100)
RandomBlock(6,1,1,STAINED_CLAY:7,33,STAINED_CLAY:12,33,CONCRETE:12,33,STAINED_CLAY:7,50,STAINED_CLAY:12,100)
RandomBlock(6,1,2,STAINED_CLAY:7,33,STAINED_CLAY:12,33,CONCRETE:12,33,STAINED_CLAY:7,50,STAINED_CLAY:12,100)
RandomBlock(6,2,-3,STAINED_CLAY:7,33,STAINED_CLAY:12,33,CONCRETE:12,33,STAINED_CLAY:7,50,STAINED_CLAY:12,100)
Block(6,2,-2,DIRT)
Block(6,2,-1,DIRT)
Block(6,2,0,DIRT)
Block(6,2,1,DIRT)
RandomBlock(6,2,2,STAINED_CLAY:7,33,STAINED_CLAY:12,33,CONCRETE:12,33,STAINED_CLAY:7,50,STAINED_CLAY:12,100)
RandomBlock(6,3,-3,STAINED_CLAY:7,33,STAINED_CLAY:12,33,CONCRETE:12,33,STAINED_CLAY:7,50,STAINED_CLAY:12,100)
Block(6,3,-2,DIRT)
Block(6,3,-1,DIRT)
Block(6,3,0,AIR:0)
Block(6,3,1,AIR:0)
RandomBlock(6,3,2,STAINED_CLAY:7,33,STAINED_CLAY:12,33,CONCRETE:12,33,STAINED_CLAY:7,50,STAINED_CLAY:12,100)
RandomBlock(6,4,-3,STAINED_CLAY:7,33,STAINED_CLAY:12,33,CONCRETE:12,33,STAINED_CLAY:7,50,STAINED_CLAY:12,100)
Block(6,4,-2,DIRT)
Block(6,4,-1,AIR:0)
Block(6,4,0,AIR:0)
Block(6,4,1,AIR:0)
RandomBlock(6,4,2,STAINED_CLAY:7,33,STAINED_CLAY:12,33,CONCRETE:12,33,STAINED_CLAY:7,50,STAINED_CLAY:12,100)
RandomBlock(6,5,-3,STAINED_CLAY:7,33,STAINED_CLAY:12,33,CONCRETE:12,33,STAINED_CLAY:7,50,STAINED_CLAY:12,100)
Block(6,5,-2,AIR:0)
Block(6,5,-1,AIR:0)
Block(6,5,0,AIR:0)
Block(6,5,1,AIR:0)
RandomBlock(6,5,2,STAINED_CLAY:7,33,STAINED_CLAY:12,33,CONCRETE:12,33,STAINED_CLAY:7,50,STAINED_CLAY:12,100)
RandomBlock(6,6,-3,STAINED_CLAY:7,33,STAINED_CLAY:12,33,CONCRETE:12,33,STAINED_CLAY:7,50,STAINED_CLAY:12,100)
Block(6,6,-2,AIR:0)
Block(6,6,-1,AIR:0)
Block(6,6,0,AIR:0)
Block(6,6,1,AIR:0)
RandomBlock(6,6,2,STAINED_CLAY:7,33,STAINED_CLAY:12,33,CONCRETE:12,33,STAINED_CLAY:7,50,STAINED_CLAY:12,100)
RandomBlock(6,7,-3,STAINED_CLAY:7,33,STAINED_CLAY:12,33,CONCRETE:12,33,STAINED_CLAY:7,50,STAINED_CLAY:12,100)
Block(6,7,-2,AIR:0)
Block(6,7,-1,AIR:0)
Block(6,7,0,AIR:0)
Block(6,7,1,AIR:0)
RandomBlock(6,7,2,STAINED_CLAY:7,33,STAINED_CLAY:12,33,CONCRETE:12,33,STAINED_CLAY:7,50,STAINED_CLAY:12,100)
RandomBlock(6,8,-3,STAINED_CLAY:7,33,STAINED_CLAY:12,33,CONCRETE:12,33,STAINED_CLAY:7,50,STAINED_CLAY:12,100)
Block(6,8,-2,AIR:0)
Block(6,8,-1,AIR:0)
Block(6,8,0,AIR:0)
Block(6,8,1,AIR:0)
RandomBlock(6,8,2,STAINED_CLAY:7,33,STAINED_CLAY:12,33,CONCRETE:12,33,STAINED_CLAY:7,50,STAINED_CLAY:12,100)
RandomBlock(6,9,-3,STAINED_CLAY:7,33,STAINED_CLAY:12,33,CONCRETE:12,33,STAINED_CLAY:7,50,STAINED_CLAY:12,100)
Block(6,9,-2,AIR:0)
Block(6,9,-1,AIR:0)
Block(6,9,0,AIR:0)
Block(6,9,1,AIR:0)
RandomBlock(6,9,2,STAINED_CLAY:7,33,STAINED_CLAY:12,33,CONCRETE:12,33,STAINED_CLAY:7,50,STAINED_CLAY:12,100)
Block(6,10,-4,STONE_BUTTON:4)
RandomBlock(6,10,-3,STAINED_CLAY:7,33,STAINED_CLAY:12,33,CONCRETE:12,33,STAINED_CLAY:7,50,STAINED_CLAY:12,100)
Block(6,10,-2,AIR:0)
Block(6,10,-1,AIR:0)
Block(6,10,0,AIR:0)
Block(6,10,1,AIR:0)
RandomBlock(6,10,2,STAINED_CLAY:7,33,STAINED_CLAY:12,33,CONCRETE:12,33,STAINED_CLAY:7,50,STAINED_CLAY:12,100)
Block(6,10,3,STONE_BUTTON:3)
RandomBlock(6,11,-3,STAINED_CLAY:7,33,STAINED_CLAY:12,33,CONCRETE:12,33,STAINED_CLAY:7,50,STAINED_CLAY:12,100)
Block(6,11,-2,AIR:0)
Block(6,11,-1,AIR:0)
Block(6,11,0,AIR:0)
Block(6,11,1,AIR:0)
RandomBlock(6,11,2,STAINED_CLAY:7,33,STAINED_CLAY:12,33,CONCRETE:12,33,STAINED_CLAY:7,50,STAINED_CLAY:12,100)
RandomBlock(6,12,-3,STAINED_CLAY:7,33,STAINED_CLAY:12,33,CONCRETE:12,33,STAINED_CLAY:7,50,STAINED_CLAY:12,100)
Block(6,12,-2,AIR:0)
Block(6,12,-1,AIR:0)
Block(6,12,0,AIR:0)
Block(6,12,1,AIR:0)
RandomBlock(6,12,2,STAINED_CLAY:7,33,STAINED_CLAY:12,33,CONCRETE:12,33,STAINED_CLAY:7,50,STAINED_CLAY:12,100)
Block(6,12,3,quark:iron_plate:1)
RandomBlock(6,12,4,STAINED_CLAY:7,33,STAINED_CLAY:12,33,CONCRETE:12,33,STAINED_CLAY:7,50,STAINED_CLAY:12,100)
Block(6,13,-2,AIR:0)
Block(6,13,-1,AIR:0)
Block(6,13,0,AIR:0)
Block(6,13,1,AIR:0)
RandomBlock(6,13,2,STAINED_CLAY:7,33,STAINED_CLAY:12,33,CONCRETE:12,33,STAINED_CLAY:7,50,STAINED_CLAY:12,100)
Block(6,13,3,quark:iron_plate:1)
RandomBlock(6,13,4,STAINED_CLAY:7,33,STAINED_CLAY:12,33,CONCRETE:12,33,STAINED_CLAY:7,50,STAINED_CLAY:12,100)
Block(6,14,-2,AIR:0)
Block(6,14,-1,AIR:0)
Block(6,14,0,AIR:0)
Block(6,14,1,AIR:0)
RandomBlock(6,14,2,STAINED_CLAY:7,33,STAINED_CLAY:12,33,CONCRETE:12,33,STAINED_CLAY:7,50,STAINED_CLAY:12,100)
Block(6,15,-4,STONE_BUTTON:4)
RandomBlock(6,15,-3,STAINED_CLAY:7,33,STAINED_CLAY:12,33,CONCRETE:12,33,STAINED_CLAY:7,50,STAINED_CLAY:12,100)
Block(6,15,-2,AIR:0)
Block(6,15,-1,AIR:0)
Block(6,15,0,AIR:0)
Block(6,15,1,AIR:0)
RandomBlock(6,15,2,STAINED_CLAY:7,33,STAINED_CLAY:12,33,CONCRETE:12,33,STAINED_CLAY:7,50,STAINED_CLAY:12,100)
Block(6,15,3,STONE_BUTTON:3)
Block(6,16,-4,IRON_FENCE:0)
RandomBlock(6,16,-3,STAINED_CLAY:7,33,STAINED_CLAY:12,33,CONCRETE:12,33,STAINED_CLAY:7,50,STAINED_CLAY:12,100)
Block(6,16,-2,AIR:0)
Block(6,16,-1,AIR:0)
Block(6,16,0,AIR:0)
Block(6,16,1,AIR:0)
RandomBlock(6,16,2,STAINED_CLAY:7,33,STAINED_CLAY:12,33,CONCRETE:12,33,STAINED_CLAY:7,50,STAINED_CLAY:12,100)
Block(6,17,-4,IRON_FENCE:0)
RandomBlock(6,17,-3,STAINED_CLAY:7,33,STAINED_CLAY:12,33,CONCRETE:12,33,STAINED_CLAY:7,50,STAINED_CLAY:12,100)
Block(6,17,-2,AIR:0)
Block(6,17,-1,AIR:0)
Block(6,17,0,AIR:0)
Block(6,17,1,AIR:0)
RandomBlock(6,17,2,STAINED_CLAY:7,33,STAINED_CLAY:12,33,CONCRETE:12,33,STAINED_CLAY:7,50,STAINED_CLAY:12,100)
RandomBlock(6,18,-3,STAINED_CLAY:7,33,STAINED_CLAY:12,33,CONCRETE:12,33,STAINED_CLAY:7,50,STAINED_CLAY:12,100)
Block(6,18,-2,AIR:0)
Block(6,18,-1,AIR:0)
Block(6,18,0,AIR:0)
Block(6,18,1,AIR:0)
RandomBlock(6,18,2,STAINED_CLAY:7,33,STAINED_CLAY:12,33,CONCRETE:12,33,STAINED_CLAY:7,50,STAINED_CLAY:12,100)
Block(6,19,-4,STONE_BUTTON:4)
RandomBlock(6,19,-3,STAINED_CLAY:7,33,STAINED_CLAY:12,33,CONCRETE:12,33,STAINED_CLAY:7,50,STAINED_CLAY:12,100)
Block(6,19,-2,AIR:0)
Block(6,19,-1,AIR:0)
Block(6,19,0,AIR:0)
Block(6,19,1,AIR:0)
RandomBlock(6,19,2,STAINED_CLAY:7,33,STAINED_CLAY:12,33,CONCRETE:12,33,STAINED_CLAY:7,50,STAINED_CLAY:12,100)
Block(6,19,3,STONE_BUTTON:3)
Block(6,20,-4,STEP:13)
RandomBlock(6,20,-3,STAINED_CLAY:7,33,STAINED_CLAY:12,33,CONCRETE:12,33,STAINED_CLAY:7,50,STAINED_CLAY:12,100)
RandomBlock(6,20,-2,STAINED_CLAY:7,33,STAINED_CLAY:12,33,CONCRETE:12,33,STAINED_CLAY:7,50,STAINED_CLAY:12,100)
RandomBlock(6,20,-1,STAINED_CLAY:7,33,STAINED_CLAY:12,33,CONCRETE:12,33,STAINED_CLAY:7,50,STAINED_CLAY:12,100)
RandomBlock(6,20,0,STAINED_CLAY:7,33,STAINED_CLAY:12,33,CONCRETE:12,33,STAINED_CLAY:7,50,STAINED_CLAY:12,100)
RandomBlock(6,20,1,STAINED_CLAY:7,33,STAINED_CLAY:12,33,CONCRETE:12,33,STAINED_CLAY:7,50,STAINED_CLAY:12,100)
RandomBlock(6,20,2,STAINED_CLAY:7,33,STAINED_CLAY:12,33,CONCRETE:12,33,STAINED_CLAY:7,50,STAINED_CLAY:12,100)
Block(6,20,3,STEP:13)
Block(6,21,-4,IRON_FENCE:0)
Block(6,21,3,IRON_FENCE:0)
RandomBlock(7,0,-2,STAINED_CLAY:7,33,STAINED_CLAY:12,33,CONCRETE:12,33,STAINED_CLAY:7,50,STAINED_CLAY:12,100)
RandomBlock(7,0,-1,STAINED_CLAY:7,33,STAINED_CLAY:12,33,CONCRETE:12,33,STAINED_CLAY:7,50,STAINED_CLAY:12,100)
RandomBlock(7,0,0,STAINED_CLAY:7,33,STAINED_CLAY:12,33,CONCRETE:12,33,STAINED_CLAY:7,50,STAINED_CLAY:12,100)
RandomBlock(7,0,1,STAINED_CLAY:7,33,STAINED_CLAY:12,33,CONCRETE:12,33,STAINED_CLAY:7,50,STAINED_CLAY:12,100)
RandomBlock(7,1,-2,STAINED_CLAY:7,33,STAINED_CLAY:12,33,CONCRETE:12,33,STAINED_CLAY:7,50,STAINED_CLAY:12,100)
RandomBlock(7,1,-1,STAINED_CLAY:7,33,STAINED_CLAY:12,33,CONCRETE:12,33,STAINED_CLAY:7,50,STAINED_CLAY:12,100)
RandomBlock(7,1,0,STAINED_CLAY:7,33,STAINED_CLAY:12,33,CONCRETE:12,33,STAINED_CLAY:7,50,STAINED_CLAY:12,100)
RandomBlock(7,1,1,STAINED_CLAY:7,33,STAINED_CLAY:12,33,CONCRETE:12,33,STAINED_CLAY:7,50,STAINED_CLAY:12,100)
RandomBlock(7,2,-2,STAINED_CLAY:7,33,STAINED_CLAY:12,33,CONCRETE:12,33,STAINED_CLAY:7,50,STAINED_CLAY:12,100)
RandomBlock(7,2,-1,STAINED_CLAY:7,33,STAINED_CLAY:12,33,CONCRETE:12,33,STAINED_CLAY:7,50,STAINED_CLAY:12,100)
RandomBlock(7,2,0,STAINED_CLAY:7,33,STAINED_CLAY:12,33,CONCRETE:12,33,STAINED_CLAY:7,50,STAINED_CLAY:12,100)
RandomBlock(7,2,1,STAINED_CLAY:7,33,STAINED_CLAY:12,33,CONCRETE:12,33,STAINED_CLAY:7,50,STAINED_CLAY:12,100)
RandomBlock(7,3,-2,STAINED_CLAY:7,33,STAINED_CLAY:12,33,CONCRETE:12,33,STAINED_CLAY:7,50,STAINED_CLAY:12,100)
RandomBlock(7,3,-1,STAINED_CLAY:7,33,STAINED_CLAY:12,33,CONCRETE:12,33,STAINED_CLAY:7,50,STAINED_CLAY:12,100)
RandomBlock(7,3,0,STAINED_CLAY:7,33,STAINED_CLAY:12,33,CONCRETE:12,33,STAINED_CLAY:7,50,STAINED_CLAY:12,100)
RandomBlock(7,3,1,STAINED_CLAY:7,33,STAINED_CLAY:12,33,CONCRETE:12,33,STAINED_CLAY:7,50,STAINED_CLAY:12,100)
RandomBlock(7,4,-2,STAINED_CLAY:7,33,STAINED_CLAY:12,33,CONCRETE:12,33,STAINED_CLAY:7,50,STAINED_CLAY:12,100)
RandomBlock(7,4,-1,STAINED_CLAY:7,33,STAINED_CLAY:12,33,CONCRETE:12,33,STAINED_CLAY:7,50,STAINED_CLAY:12,100)
RandomBlock(7,4,0,STAINED_CLAY:7,33,STAINED_CLAY:12,33,CONCRETE:12,33,STAINED_CLAY:7,50,STAINED_CLAY:12,100)
RandomBlock(7,4,1,STAINED_CLAY:7,33,STAINED_CLAY:12,33,CONCRETE:12,33,STAINED_CLAY:7,50,STAINED_CLAY:12,100)
RandomBlock(7,5,-2,STAINED_CLAY:7,33,STAINED_CLAY:12,33,CONCRETE:12,33,STAINED_CLAY:7,50,STAINED_CLAY:12,100)
RandomBlock(7,5,-1,STAINED_CLAY:7,33,STAINED_CLAY:12,33,CONCRETE:12,33,STAINED_CLAY:7,50,STAINED_CLAY:12,100)
RandomBlock(7,5,0,STAINED_CLAY:7,33,STAINED_CLAY:12,33,CONCRETE:12,33,STAINED_CLAY:7,50,STAINED_CLAY:12,100)
RandomBlock(7,5,1,STAINED_CLAY:7,33,STAINED_CLAY:12,33,CONCRETE:12,33,STAINED_CLAY:7,50,STAINED_CLAY:12,100)
RandomBlock(7,6,-2,STAINED_CLAY:7,33,STAINED_CLAY:12,33,CONCRETE:12,33,STAINED_CLAY:7,50,STAINED_CLAY:12,100)
RandomBlock(7,6,-1,STAINED_CLAY:7,33,STAINED_CLAY:12,33,CONCRETE:12,33,STAINED_CLAY:7,50,STAINED_CLAY:12,100)
RandomBlock(7,6,0,STAINED_CLAY:7,33,STAINED_CLAY:12,33,CONCRETE:12,33,STAINED_CLAY:7,50,STAINED_CLAY:12,100)
RandomBlock(7,6,1,STAINED_CLAY:7,33,STAINED_CLAY:12,33,CONCRETE:12,33,STAINED_CLAY:7,50,STAINED_CLAY:12,100)
RandomBlock(7,7,-2,STAINED_CLAY:7,33,STAINED_CLAY:12,33,CONCRETE:12,33,STAINED_CLAY:7,50,STAINED_CLAY:12,100)
RandomBlock(7,7,-1,STAINED_CLAY:7,33,STAINED_CLAY:12,33,CONCRETE:12,33,STAINED_CLAY:7,50,STAINED_CLAY:12,100)
RandomBlock(7,7,0,STAINED_CLAY:7,33,STAINED_CLAY:12,33,CONCRETE:12,33,STAINED_CLAY:7,50,STAINED_CLAY:12,100)
RandomBlock(7,7,1,STAINED_CLAY:7,33,STAINED_CLAY:12,33,CONCRETE:12,33,STAINED_CLAY:7,50,STAINED_CLAY:12,100)
RandomBlock(7,8,-2,STAINED_CLAY:7,33,STAINED_CLAY:12,33,CONCRETE:12,33,STAINED_CLAY:7,50,STAINED_CLAY:12,100)
RandomBlock(7,8,-1,STAINED_CLAY:7,33,STAINED_CLAY:12,33,CONCRETE:12,33,STAINED_CLAY:7,50,STAINED_CLAY:12,100)
RandomBlock(7,8,0,STAINED_CLAY:7,33,STAINED_CLAY:12,33,CONCRETE:12,33,STAINED_CLAY:7,50,STAINED_CLAY:12,100)
RandomBlock(7,8,1,STAINED_CLAY:7,33,STAINED_CLAY:12,33,CONCRETE:12,33,STAINED_CLAY:7,50,STAINED_CLAY:12,100)
RandomBlock(7,9,-2,STAINED_CLAY:7,33,STAINED_CLAY:12,33,CONCRETE:12,33,STAINED_CLAY:7,50,STAINED_CLAY:12,100)
RandomBlock(7,9,-1,STAINED_CLAY:7,33,STAINED_CLAY:12,33,CONCRETE:12,33,STAINED_CLAY:7,50,STAINED_CLAY:12,100)
RandomBlock(7,9,0,STAINED_CLAY:7,33,STAINED_CLAY:12,33,CONCRETE:12,33,STAINED_CLAY:7,50,STAINED_CLAY:12,100)
RandomBlock(7,9,1,STAINED_CLAY:7,33,STAINED_CLAY:12,33,CONCRETE:12,33,STAINED_CLAY:7,50,STAINED_CLAY:12,100)
RandomBlock(7,10,-2,STAINED_CLAY:7,33,STAINED_CLAY:12,33,CONCRETE:12,33,STAINED_CLAY:7,50,STAINED_CLAY:12,100)
RandomBlock(7,10,-1,STAINED_CLAY:7,33,STAINED_CLAY:12,33,CONCRETE:12,33,STAINED_CLAY:7,50,STAINED_CLAY:12,100)
RandomBlock(7,10,0,STAINED_CLAY:7,33,STAINED_CLAY:12,33,CONCRETE:12,33,STAINED_CLAY:7,50,STAINED_CLAY:12,100)
RandomBlock(7,10,1,STAINED_CLAY:7,33,STAINED_CLAY:12,33,CONCRETE:12,33,STAINED_CLAY:7,50,STAINED_CLAY:12,100)
RandomBlock(7,11,-2,STAINED_CLAY:7,33,STAINED_CLAY:12,33,CONCRETE:12,33,STAINED_CLAY:7,50,STAINED_CLAY:12,100)
RandomBlock(7,11,-1,STAINED_CLAY:7,33,STAINED_CLAY:12,33,CONCRETE:12,33,STAINED_CLAY:7,50,STAINED_CLAY:12,100)
RandomBlock(7,11,0,STAINED_CLAY:7,33,STAINED_CLAY:12,33,CONCRETE:12,33,STAINED_CLAY:7,50,STAINED_CLAY:12,100)
RandomBlock(7,11,1,STAINED_CLAY:7,33,STAINED_CLAY:12,33,CONCRETE:12,33,STAINED_CLAY:7,50,STAINED_CLAY:12,100)
RandomBlock(7,12,-1,STAINED_CLAY:7,33,STAINED_CLAY:12,33,CONCRETE:12,33,STAINED_CLAY:7,50,STAINED_CLAY:12,100)
RandomBlock(7,12,0,STAINED_CLAY:7,33,STAINED_CLAY:12,33,CONCRETE:12,33,STAINED_CLAY:7,50,STAINED_CLAY:12,100)
RandomBlock(7,12,1,STAINED_CLAY:7,33,STAINED_CLAY:12,33,CONCRETE:12,33,STAINED_CLAY:7,50,STAINED_CLAY:12,100)
RandomBlock(7,13,-1,STAINED_CLAY:7,33,STAINED_CLAY:12,33,CONCRETE:12,33,STAINED_CLAY:7,50,STAINED_CLAY:12,100)
