
#######################################################################
# +-----------------------------------------------------------------+ #
# |                            BO4 object                           | #
# +-----------------------------------------------------------------+ #
#######################################################################

Author: NLBlackEagle

Description: No description given

SettingsMode: WriteWithoutComments


#######################################################################
# +-----------------------------------------------------------------+ #
# |                          Main settings                          | #
# +-----------------------------------------------------------------+ #
#######################################################################

FixedRotation: 

Frequency: 0

SpawnHeight: highestBlock

UseCenterForHighestBlock: true

##############################
# Height Limits for the BO4. #
##############################

MinHeight: 0

MaxHeight: 255

InheritBO3: 

InheritBO3Rotation: NORTH

OverrideChildSettings: true

OverrideParentHeight: false

CanOverride: true

BranchFrequency: 0

BranchFrequencyGroup: 

MustBeBelowOther: false

MustBeInside: 

CannotBeInside: 

ReplacesBO3: 

MustBeInsideWorldBorders: true

CanSpawnOnWater: true

SpawnOnWaterOnly: false

SpawnUnderWater: false

SpawnAtWaterLevel: false

HeightOffset: 0

RemoveAir: true

ReplaceAbove: 

ReplaceBelow: 

ReplaceWithBiomeBlocks: false

ReplaceWithSurfaceBlock: GRASS

ReplaceWithGroundBlock: DIRT

ReplaceWithStoneBlock: STONE

SmoothRadius: 0

SmoothHeightOffset: 0

SmoothStartTop: false

SmoothStartWood: false

SmoothingSurfaceBlock: 

SmoothingGroundBlock: 

BO3Group: 

IsSpawnPoint: false

DoReplaceBlocks: true


#######################################################################
# +-----------------------------------------------------------------+ #
# |                              Blocks                             | #
# +-----------------------------------------------------------------+ #
#######################################################################

Block(-8,14,-3,VINE:8)
Block(-8,14,-2,VINE:8)
Block(-8,14,3,VINE:8)
Block(-8,15,-3,VINE:8)
Block(-8,15,-2,VINE:8)
Block(-8,15,3,VINE:8)
Block(-8,16,-3,VINE:8)
Block(-8,16,-2,VINE:8)
Block(-8,16,3,VINE:8)
Block(-8,16,8,VINE:8)
Block(-8,17,-3,VINE:8)
Block(-8,17,-2,VINE:8)
Block(-8,17,3,VINE:8)
Block(-8,18,-3,VINE:8)
Block(-8,18,-2,VINE:8)
Block(-8,19,-2,VINE:8)
Block(-8,20,0,VINE:8)
Block(-8,20,4,VINE:8)
Block(-8,20,7,VINE:8)
Block(-8,21,0,VINE:8)
Block(-8,21,1,VINE:8)
Block(-8,21,4,VINE:8)
Block(-8,21,7,VINE:8)
Block(-8,22,4,VINE:8)
Block(-8,22,6,VINE:8)
Block(-8,22,7,VINE:8)
Block(-8,23,4,VINE:8)
Block(-8,23,6,VINE:8)
Block(-8,23,7,VINE:8)
Block(-8,24,6,VINE:8)
Block(-8,24,7,VINE:8)
Block(-8,25,6,VINE:8)
Block(-7,6,-2,VINE:8)
Block(-7,7,-2,VINE:8)
Block(-7,8,-2,VINE:8)
Block(-7,8,4,VINE:8)
Block(-7,9,-2,VINE:8)
Block(-7,9,4,VINE:8)
Block(-7,10,-2,VINE:8)
Block(-7,10,4,VINE:8)
Block(-7,10,5,IRON_FENCE:0)
Block(-7,11,-5,VINE:8)
Block(-7,11,-2,VINE:8)
Block(-7,11,2,VINE:8)
Block(-7,11,4,VINE:8)
Block(-7,11,5,IRON_FENCE:0)
Block(-7,11,8,VINE:1)
Block(-7,12,8,VINE:1)
Block(-7,13,0,VINE:8)
Block(-7,13,8,VINE:1)
Block(-7,14,-4,VINE:8)
Block(-7,14,0,VINE:8)
Block(-7,14,4,VINE:12)
Block(-7,14,6,VINE:8)
Block(-7,15,-4,VINE:8)
Block(-7,15,0,VINE:8)
Block(-7,15,4,VINE:12)
Block(-7,16,-5,VINE:8)
Block(-7,16,-4,VINE:9)
Block(-7,16,-3,IRON_FENCE:0)
Block(-7,16,0,VINE:8)
Block(-7,16,3,CONCRETE:7)
Block(-7,16,4,VINE:12)
Block(-7,16,8,CONCRETE:7)
Block(-7,17,-4,VINE:1)
Block(-7,17,-3,IRON_FENCE:0)
Block(-7,17,-2,IRON_FENCE:0)
Block(-7,17,3,CONCRETE:7)
Block(-7,17,4,VINE:4)
Block(-7,18,-4,VINE:1)
Block(-7,18,-3,CONCRETE:7)
Block(-7,18,-2,IRON_FENCE:0)
Block(-7,18,-1,IRON_FENCE:0)
Block(-7,18,3,CONCRETE:7)
Block(-7,18,4,VINE:4)
Block(-7,19,-3,VINE:1)
Block(-7,19,-2,CONCRETE:7)
Block(-7,19,-1,IRON_FENCE:0)
Block(-7,19,0,IRON_FENCE:0)
Block(-7,19,3,CONCRETE:7)
Block(-7,19,4,VINE:4)
Block(-7,20,-1,CONCRETE:7)
Block(-7,20,0,IRON_FENCE:0)
Block(-7,20,1,IRON_FENCE:0)
Block(-7,20,2,IRON_FENCE:0)
Block(-7,20,3,CONCRETE:7)
Block(-7,21,0,CONCRETE:7)
Block(-7,21,1,CONCRETE:7)
Block(-7,21,2,CONCRETE:7)
Block(-7,21,3,IRON_FENCE:0)
Block(-7,21,4,CONCRETE:7)
Block(-7,21,8,VINE:1)
Block(-7,22,3,CONCRETE:7)
Block(-7,22,4,IRON_FENCE:0)
Block(-7,22,5,CONCRETE:7)
Block(-7,22,8,VINE:1)
Block(-7,23,4,CONCRETE:7)
Block(-7,23,5,IRON_FENCE:0)
Block(-7,23,6,CONCRETE:7)
Block(-7,24,5,CONCRETE:7)
Block(-7,24,6,IRON_FENCE:0)
Block(-7,24,7,CONCRETE:7)
Block(-7,24,8,CONCRETE:7)
Block(-7,25,6,CONCRETE:7)
Block(-7,25,7,COBBLE_WALL:0)
Block(-7,25,8,CONCRETE:7)
Block(-6,10,5,CONCRETE:7)
Block(-6,11,-7,CONCRETE:7)
Block(-6,11,-6,CONCRETE:7)
Block(-6,11,-5,CONCRETE:7)
Block(-6,11,-4,CONCRETE:7)
Block(-6,11,-3,CONCRETE:7)
Block(-6,11,-2,CONCRETE:7)
Block(-6,11,-1,CONCRETE:7)
Block(-6,11,0,CONCRETE:7)
Block(-6,11,1,CONCRETE:7)
Block(-6,11,2,CONCRETE:7)
Block(-6,11,3,CONCRETE:7)
Block(-6,11,4,CONCRETE:7)
Block(-6,11,5,CONCRETE:7)
Block(-6,11,6,CONCRETE:7)
Block(-6,11,7,CONCRETE:7)
Block(-6,11,8,CONCRETE:7)
Block(-6,12,7,IRON_FENCE:0)
Block(-6,12,8,CONCRETE:8)
Block(-6,13,6,IRON_FENCE:0)
Block(-6,13,7,CONCRETE:8)
Block(-6,13,8,SMOOTH_STAIRS:3)
Block(-6,14,5,IRON_FENCE:0)
Block(-6,14,6,CONCRETE:8)
Block(-6,14,7,SMOOTH_STAIRS:3)
Block(-6,14,8,VINE:1)
Block(-6,15,3,CONCRETE:7)
Block(-6,15,4,IRON_FENCE:0)
Block(-6,15,5,CONCRETE:8)
Block(-6,15,6,SMOOTH_STAIRS:3)
Block(-6,15,8,VINE:1)
Block(-6,16,-7,CONCRETE:7)
Block(-6,16,-6,CONCRETE:7)
Block(-6,16,-5,CONCRETE:7)
Block(-6,16,-4,CONCRETE:7)
Block(-6,16,-3,CONCRETE:7)
Block(-6,16,-2,CONCRETE:7)
Block(-6,16,-1,CONCRETE:7)
Block(-6,16,0,CONCRETE:7)
Block(-6,16,1,CONCRETE:7)
Block(-6,16,2,CONCRETE:7)
Block(-6,16,3,CONCRETE:7)
Block(-6,16,4,CONCRETE:7)
Block(-6,16,5,CONCRETE:7)
Block(-6,16,6,CONCRETE:7)
Block(-6,16,7,CONCRETE:7)
Block(-6,16,8,CONCRETE:7)
Block(-6,17,-7,IRON_FENCE:0)
Block(-6,17,-6,IRON_FENCE:0)
Block(-6,17,-5,IRON_FENCE:0)
Block(-6,17,-4,IRON_FENCE:0)
Block(-6,17,-3,CONCRETE:7)
Block(-6,17,-2,IRON_FENCE:0)
Block(-6,17,-1,IRON_FENCE:0)
Block(-6,17,0,IRON_FENCE:0)
Block(-6,17,1,IRON_FENCE:0)
Block(-6,17,2,IRON_FENCE:0)
Block(-6,17,3,IRON_FENCE:0)
Block(-6,17,4,IRON_FENCE:0)
Block(-6,17,5,IRON_FENCE:0)
Block(-6,17,6,IRON_FENCE:0)
Block(-6,17,7,IRON_FENCE:0)
Block(-6,17,8,IRON_FENCE:0)
Block(-6,18,-2,VINE:2)
Block(-6,18,3,VINE:2)
Block(-6,19,-2,VINE:2)
Block(-6,19,3,VINE:2)
Block(-6,20,3,VINE:2)
Block(-6,21,0,VINE:2)
Block(-6,22,5,VINE:2)
Block(-6,23,5,VINE:2)
Block(-6,24,5,VINE:2)
Block(-6,24,7,CONCRETE:7)
Block(-6,25,7,CONCRETE:7)
Block(-5,8,2,VINE:2)
Block(-5,9,-3,VINE:8)
Block(-5,9,2,VINE:2)
Block(-5,10,-3,VINE:8)
Block(-5,10,-2,VINE:2)
Block(-5,10,2,VINE:10)
Block(-5,10,5,IRON_FENCE:0)
Block(-5,11,-4,VINE:2)
Block(-5,11,-3,VINE:8)
Block(-5,11,-2,VINE:2)
Block(-5,11,2,VINE:10)
Block(-5,11,5,CONCRETE:8)
Block(-5,12,-3,VINE:8)
Block(-5,12,2,VINE:8)
Block(-5,13,-6,VINE:8)
Block(-5,13,-3,VINE:8)
Block(-5,13,1,VINE:8)
Block(-5,13,2,VINE:8)
Block(-5,14,-6,VINE:8)
Block(-5,14,-3,VINE:8)
Block(-5,14,1,VINE:8)
Block(-5,14,2,VINE:8)
Block(-5,15,-6,VINE:8)
Block(-5,15,-3,VINE:8)
Block(-5,15,2,VINE:8)
Block(-5,15,3,IRON_FENCE:0)
Block(-5,16,-7,CONCRETE:7)
Block(-5,16,-6,CONCRETE:7)
Block(-5,16,-5,CONCRETE:7)
Block(-5,16,-4,CONCRETE:7)
Block(-5,16,-3,CONCRETE:7)
Block(-5,16,-2,CONCRETE:7)
Block(-5,16,-1,CONCRETE:7)
Block(-5,16,0,CONCRETE:7)
Block(-5,16,1,CONCRETE:7)
Block(-5,16,2,CONCRETE:7)
Block(-5,16,3,CONCRETE:7)
Block(-5,16,4,CONCRETE:7)
Block(-5,16,5,CONCRETE:7)
Block(-5,16,6,CONCRETE:7)
Block(-5,16,7,CONCRETE:7)
Block(-5,16,8,CONCRETE:7)
Block(-5,21,8,VINE:4)
Block(-5,22,8,VINE:4)
Block(-5,23,8,VINE:4)
Block(-5,24,7,VINE:2)
Block(-5,24,8,VINE:4)
Block(-5,25,7,CONCRETE:7)
Block(-5,25,8,VINE:4)
Block(-4,9,6,VINE:4)
Block(-4,10,6,VINE:4)
Block(-4,11,5,CONCRETE:8)
Block(-4,11,6,VINE:4)
Block(-4,12,-3,WOOD_STEP:13)
Block(-4,12,-2,WOOD_STEP:13)
Block(-4,13,-7,CONCRETE:7)
Block(-4,13,-6,CONCRETE:7)
Block(-4,13,-5,CONCRETE:7)
Block(-4,13,-4,CONCRETE:7)
Block(-4,13,-3,ACACIA_DOOR:2)
Block(-4,13,-2,ACACIA_DOOR:2)
Block(-4,13,-1,CONCRETE:7)
Block(-4,13,0,CONCRETE:7)
Block(-4,13,1,CONCRETE:7)
Block(-4,13,2,CONCRETE:7)
Block(-4,13,3,CONCRETE:7)
Block(-4,14,-7,CONCRETE:7)
Block(-4,14,-6,CONCRETE:7)
Block(-4,14,-5,CONCRETE:7)
Block(-4,14,-4,CONCRETE:7)
Block(-4,14,-3,ACACIA_DOOR:9)
Block(-4,14,-2,ACACIA_DOOR:8)
Block(-4,14,-1,CONCRETE:7)
Block(-4,14,0,CONCRETE:7)
Block(-4,14,1,CONCRETE:7)
Block(-4,14,2,CONCRETE:7)
Block(-4,14,3,CONCRETE:7)
Block(-4,15,-7,CONCRETE:7)
Block(-4,15,-6,CONCRETE:7)
Block(-4,15,-5,CONCRETE:7)
Block(-4,15,-4,CONCRETE:7)
Block(-4,15,-3,CONCRETE:7)
Block(-4,15,-2,CONCRETE:7)
Block(-4,15,-1,CONCRETE:7)
Block(-4,15,0,CONCRETE:7)
Block(-4,15,1,CONCRETE:7)
Block(-4,15,2,CONCRETE:7)
Block(-4,15,3,CONCRETE:7)
Block(-4,16,-7,SMOOTH_STAIRS:3)
Block(-4,16,2,SMOOTH_STAIRS:2)
Block(-4,16,3,IRON_FENCE:0)
Block(-4,16,4,IRON_FENCE:0)
Block(-4,16,5,IRON_FENCE:0)
Block(-4,16,6,IRON_FENCE:0)
Block(-4,16,7,IRON_FENCE:0)
Block(-4,16,8,IRON_FENCE:0)
Block(-4,25,7,CONCRETE:7)
Block(-3,11,5,IRON_FENCE:0)
Block(-3,11,8,VINE:1)
Block(-3,12,-7,WOOD_STEP:13)
Block(-3,12,-6,WOOD_STEP:13)
Block(-3,12,-5,WOOD_STEP:13)
Block(-3,12,-4,WOOD_STEP:13)
Block(-3,12,-3,WOOD_STEP:13)
Block(-3,12,-2,WOOD_STEP:13)
Block(-3,12,-1,WOOD_STEP:13)
Block(-3,12,0,WOOD_STEP:13)
Block(-3,12,1,WOOD_STEP:13)
Block(-3,12,2,WOOD_STEP:13)
Block(-3,12,3,WOOD_STEP:13)
Block(-3,12,5,CONCRETE:8)
Block(-3,13,-5,VINE:2)
RandomBlock(-3,13,2,WOOD:5,5,WOOD:5,10,WOOD:5,100)
Block(-3,13,3,FURNACE:3)
Block(-3,13,4,CONCRETE:7)
Block(-3,13,5,CONCRETE:7)
Block(-3,14,-5,VINE:2)
RandomBlock(-3,14,3,WOOD:5,5,WOOD:5,10,WOOD:5,100)
Block(-3,14,4,CONCRETE:7)
Block(-3,15,-5,VINE:2)
Block(-3,15,4,CONCRETE:7)
Block(-3,16,-7,CONCRETE:7)
Block(-3,16,-6,CONCRETE:7)
Block(-3,16,-5,CONCRETE:7)
Block(-3,16,-4,CONCRETE:7)
Block(-3,16,-3,CONCRETE:7)
Block(-3,16,-2,CONCRETE:7)
Block(-3,16,-1,CONCRETE:7)
Block(-3,16,0,CONCRETE:7)
Block(-3,16,1,CONCRETE:7)
Block(-3,16,2,CONCRETE:7)
Block(-3,16,3,CONCRETE:7)
Block(-3,17,8,VINE:1)
Block(-3,25,7,CONCRETE:7)
Block(-2,12,-7,WOOD_STEP:13)
Block(-2,12,-6,WOOD_STEP:13)
Block(-2,12,-5,WOOD_STEP:13)
Block(-2,12,-4,WOOD_STEP:13)
Block(-2,12,-3,WOOD_STEP:13)
Block(-2,12,-2,WOOD_STEP:13)
Block(-2,12,-1,WOOD_STEP:13)
Block(-2,12,0,WOOD_STEP:13)
Block(-2,12,1,WOOD_STEP:13)
Block(-2,12,2,WOOD_STEP:13)
Block(-2,12,3,WOOD_STEP:13)
Block(-2,12,4,WOOD_STEP:13)
Block(-2,12,5,IRON_FENCE:0)
Block(-2,13,-5,SMOOTH_STAIRS:6)
Block(-2,13,-4,SMOOTH_STAIRS:3)
RandomBlock(-2,13,3,CHEST:2,../../../../Chests/Loot/moderncity_junk_loot.nbt,20,CHEST:2,../../../../Chests/Loot/moderncity_common_loot.nbt,15,CHEST:2,../../../../Chests/Loot/moderncity_rare_loot.nbt,10,CHEST:2,../../../../Chests/Loot/moderncity_epic_loot.nbt,5,CHEST:2,../../../../Chests/RLCraft/Ruins/industrial.nbt,50,CHEST:2,../../../../Chests/RLCraft/Ruins/rubble.nbt,100)
Block(-2,13,4,CONCRETE:7)
Block(-2,13,5,IRON_FENCE:0)
Block(-2,14,-6,SMOOTH_STAIRS:6)
Block(-2,14,-5,SMOOTH_STAIRS:3)
Block(-2,14,4,CONCRETE:7)
Block(-2,15,-7,SMOOTH_STAIRS:6)
Block(-2,15,-6,SMOOTH_STAIRS:3)
Block(-2,15,-4,VINE:9)
Block(-2,15,4,CONCRETE:7)
Block(-2,16,-7,SMOOTH_STAIRS:3)
Block(-2,16,-4,VINE:9)
Block(-2,16,-3,CONCRETE:7)
Block(-2,16,-2,CONCRETE:7)
Block(-2,16,-1,CONCRETE:7)
Block(-2,16,0,CONCRETE:7)
Block(-2,16,1,CONCRETE:7)
Block(-2,16,2,CONCRETE:7)
Block(-2,16,3,CONCRETE:7)
Block(-2,25,7,CONCRETE:7)
Block(-1,11,5,IRON_FENCE:0)
Block(-1,12,-7,WOOD_STEP:13)
Block(-1,12,-6,WOOD_STEP:13)
Block(-1,12,-5,WOOD_STEP:13)
Block(-1,12,-4,WOOD_STEP:13)
Block(-1,12,-3,WOOD_STEP:13)
Block(-1,12,-2,WOOD_STEP:13)
Block(-1,12,-1,WOOD_STEP:13)
Block(-1,12,0,WOOD_STEP:13)
Block(-1,12,1,WOOD_STEP:13)
Block(-1,12,2,WOOD_STEP:13)
Block(-1,12,3,WOOD_STEP:13)
Block(-1,12,4,VINE:1)
Block(-1,12,5,CONCRETE:8)
Block(-1,13,-4,VINE:8)
RandomBlock(-1,13,3,WOOD:5,5,WOOD:5,10,WOOD:5,100)
Block(-1,13,4,CONCRETE:7)
Block(-1,13,5,CONCRETE:7)
Block(-1,13,6,VINE:4)
Block(-1,14,-4,VINE:8)
Block(-1,14,3,VINE:1)
Block(-1,14,4,CONCRETE:7)
Block(-1,15,3,VINE:1)
Block(-1,15,4,CONCRETE:7)
Block(-1,16,-7,CONCRETE:7)
Block(-1,16,-6,CONCRETE:7)
Block(-1,16,-5,CONCRETE:7)
Block(-1,16,-4,CONCRETE:7)
Block(-1,16,-3,CONCRETE:7)
Block(-1,16,-2,CONCRETE:7)
Block(-1,16,-1,CONCRETE:7)
Block(-1,16,0,CONCRETE:7)
Block(-1,16,1,CONCRETE:7)
Block(-1,16,2,CONCRETE:7)
Block(-1,16,3,CONCRETE:7)
Block(-1,17,8,VINE:1)
Block(-1,23,8,VINE:4)
Block(-1,24,8,VINE:4)
Block(-1,25,7,CONCRETE:7)
Block(-1,25,8,VINE:4)
Block(0,10,6,VINE:4)
Block(0,10,8,VINE:1)
Block(0,11,5,CONCRETE:8)
Block(0,11,6,VINE:4)
Block(0,11,8,VINE:1)
Block(0,12,-3,WOOD_STEP:13)
Block(0,12,-2,WOOD_STEP:13)
Block(0,13,-7,CONCRETE:7)
Block(0,13,-6,CONCRETE:7)
Block(0,13,-5,CONCRETE:7)
Block(0,13,-4,CONCRETE:7)
Block(0,13,-3,ACACIA_DOOR:4)
Block(0,13,-2,ACACIA_DOOR:4)
Block(0,13,-1,CONCRETE:7)
Block(0,13,0,CONCRETE:7)
Block(0,13,1,CONCRETE:7)
Block(0,13,2,CONCRETE:7)
Block(0,13,3,CONCRETE:7)
Block(0,14,-7,CONCRETE:7)
Block(0,14,-6,CONCRETE:7)
Block(0,14,-5,CONCRETE:7)
Block(0,14,-4,CONCRETE:7)
Block(0,14,-3,ACACIA_DOOR:8)
Block(0,14,-2,ACACIA_DOOR:9)
Block(0,14,-1,CONCRETE:7)
Block(0,14,0,CONCRETE:7)
Block(0,14,1,CONCRETE:7)
Block(0,14,2,CONCRETE:7)
Block(0,14,3,CONCRETE:7)
Block(0,15,-7,CONCRETE:7)
Block(0,15,-6,CONCRETE:7)
Block(0,15,-5,CONCRETE:7)
Block(0,15,-4,CONCRETE:7)
Block(0,15,-3,CONCRETE:7)
Block(0,15,-2,CONCRETE:7)
Block(0,15,-1,CONCRETE:7)
Block(0,15,0,CONCRETE:7)
Block(0,15,1,CONCRETE:7)
Block(0,15,2,CONCRETE:7)
Block(0,15,3,CONCRETE:7)
Block(0,16,-7,SMOOTH_STAIRS:3)
Block(0,16,2,SMOOTH_STAIRS:2)
Block(0,16,3,IRON_FENCE:0)
Block(0,16,4,IRON_FENCE:0)
Block(0,16,5,IRON_FENCE:0)
Block(0,16,6,IRON_FENCE:0)
Block(0,16,7,IRON_FENCE:0)
Block(0,16,8,IRON_FENCE:0)
Block(0,25,7,CONCRETE:7)
Block(1,6,-2,VINE:8)
Block(1,7,-5,VINE:8)
Block(1,7,-2,VINE:8)
Block(1,8,-5,VINE:8)
Block(1,8,-2,VINE:8)
Block(1,9,-5,VINE:8)
Block(1,9,-2,VINE:8)
Block(1,10,-5,VINE:8)
Block(1,10,-2,VINE:8)
Block(1,10,5,IRON_FENCE:0)
Block(1,11,-5,VINE:8)
Block(1,11,-2,VINE:8)
Block(1,11,2,VINE:8)
Block(1,11,5,CONCRETE:8)
Block(1,12,-3,WOOD_STEP:13)
Block(1,12,-2,WOOD_STEP:13)
Block(1,12,0,VINE:2)
Block(1,13,-3,VINE:2)
Block(1,13,0,VINE:2)
Block(1,14,-6,VINE:2)
Block(1,14,-3,VINE:2)
Block(1,14,0,VINE:2)
Block(1,15,-3,VINE:2)
Block(1,15,0,VINE:2)
Block(1,15,3,IRON_FENCE:0)
Block(1,16,-7,CONCRETE:7)
Block(1,16,-6,CONCRETE:7)
Block(1,16,-5,CONCRETE:7)
Block(1,16,-4,CONCRETE:7)
Block(1,16,-3,CONCRETE:7)
Block(1,16,-2,CONCRETE:7)
Block(1,16,-1,CONCRETE:7)
Block(1,16,0,CONCRETE:7)
Block(1,16,1,CONCRETE:7)
Block(1,16,2,CONCRETE:7)
Block(1,16,3,CONCRETE:7)
Block(1,16,4,CONCRETE:7)
Block(1,16,5,CONCRETE:7)
Block(1,16,6,CONCRETE:7)
Block(1,16,7,CONCRETE:7)
Block(1,16,8,CONCRETE:7)
Block(1,22,7,VINE:8)
Block(1,23,7,VINE:8)
Block(1,24,7,VINE:8)
Block(1,25,7,CONCRETE:7)
Block(2,7,4,VINE:1)
Block(2,8,4,VINE:1)
Block(2,9,4,VINE:1)
Block(2,10,4,VINE:1)
Block(2,10,5,CONCRETE:7)
Block(2,11,-7,CONCRETE:7)
Block(2,11,-6,CONCRETE:7)
Block(2,11,-5,CONCRETE:7)
Block(2,11,-4,CONCRETE:7)
Block(2,11,-3,CONCRETE:7)
Block(2,11,-2,CONCRETE:7)
Block(2,11,-1,CONCRETE:7)
Block(2,11,0,CONCRETE:7)
Block(2,11,1,CONCRETE:7)
Block(2,11,2,CONCRETE:7)
Block(2,11,3,CONCRETE:7)
Block(2,11,4,CONCRETE:7)
Block(2,11,5,CONCRETE:7)
Block(2,11,6,CONCRETE:7)
Block(2,11,7,CONCRETE:7)
Block(2,11,8,CONCRETE:7)
Block(2,12,-3,SMOOTH_STAIRS:1)
Block(2,12,-2,SMOOTH_STAIRS:1)
Block(2,12,7,IRON_FENCE:0)
Block(2,12,8,CONCRETE:8)
Block(2,13,6,IRON_FENCE:0)
Block(2,13,7,CONCRETE:8)
Block(2,13,8,SMOOTH_STAIRS:3)
Block(2,14,5,IRON_FENCE:0)
Block(2,14,6,CONCRETE:8)
Block(2,14,7,SMOOTH_STAIRS:3)
Block(2,15,3,CONCRETE:7)
Block(2,15,4,IRON_FENCE:0)
Block(2,15,5,CONCRETE:8)
Block(2,15,6,SMOOTH_STAIRS:3)
Block(2,16,-7,CONCRETE:7)
Block(2,16,-6,CONCRETE:7)
Block(2,16,-5,CONCRETE:7)
Block(2,16,-4,CONCRETE:7)
Block(2,16,-3,CONCRETE:7)
Block(2,16,-2,CONCRETE:7)
Block(2,16,-1,CONCRETE:7)
Block(2,16,0,CONCRETE:7)
Block(2,16,1,CONCRETE:7)
Block(2,16,2,CONCRETE:7)
Block(2,16,3,CONCRETE:7)
Block(2,16,4,CONCRETE:7)
Block(2,16,5,CONCRETE:7)
Block(2,16,6,CONCRETE:7)
Block(2,16,7,CONCRETE:7)
Block(2,16,8,CONCRETE:7)
Block(2,17,-7,IRON_FENCE:0)
Block(2,17,-6,IRON_FENCE:0)
Block(2,17,-5,IRON_FENCE:0)
Block(2,17,-4,IRON_FENCE:0)
Block(2,17,-3,CONCRETE:7)
Block(2,17,-2,IRON_FENCE:0)
Block(2,17,-1,IRON_FENCE:0)
Block(2,17,0,IRON_FENCE:0)
Block(2,17,1,IRON_FENCE:0)
Block(2,17,2,IRON_FENCE:0)
Block(2,17,3,IRON_FENCE:0)
Block(2,17,4,IRON_FENCE:0)
Block(2,17,5,IRON_FENCE:0)
Block(2,17,6,IRON_FENCE:0)
Block(2,17,7,IRON_FENCE:0)
Block(2,17,8,IRON_FENCE:0)
Block(2,18,0,VINE:8)
Block(2,18,3,VINE:8)
Block(2,18,8,VINE:1)
Block(2,19,0,VINE:8)
Block(2,20,0,VINE:8)
Block(2,20,3,VINE:8)
Block(2,21,0,VINE:8)
Block(2,21,3,VINE:8)
Block(2,22,3,VINE:8)
Block(2,24,7,CONCRETE:7)
Block(2,25,7,CONCRETE:7)
Block(2,25,8,VINE:8)
Block(3,9,8,VINE:1)
Block(3,10,-7,VINE:2)
Block(3,10,-3,SMOOTH_STAIRS:4)
Block(3,10,-2,SMOOTH_STAIRS:4)
Block(3,10,2,VINE:2)
Block(3,10,5,IRON_FENCE:0)
Block(3,10,6,VINE:2)
Block(3,10,8,VINE:1)
Block(3,11,-7,VINE:2)
Block(3,11,-3,SMOOTH_STAIRS:1)
Block(3,11,-2,SMOOTH_STAIRS:1)
Block(3,11,1,VINE:2)
Block(3,11,2,VINE:2)
Block(3,11,5,IRON_FENCE:0)
Block(3,11,6,VINE:2)
Block(3,11,8,VINE:1)
Block(3,12,8,VINE:1)
Block(3,13,8,VINE:1)
Block(3,14,3,VINE:2)
Block(3,14,6,VINE:2)
Block(3,14,8,VINE:1)
Block(3,15,3,VINE:2)
Block(3,15,8,VINE:1)
Block(3,16,-7,VINE:2)
Block(3,16,-3,IRON_FENCE:0)
Block(3,16,2,VINE:1)
Block(3,16,3,CONCRETE:7)
Block(3,16,4,VINE:4)
Block(3,16,8,CONCRETE:7)
Block(3,17,-3,IRON_FENCE:0)
Block(3,17,-2,IRON_FENCE:0)
Block(3,17,2,VINE:1)
Block(3,17,3,CONCRETE:7)
Block(3,17,4,VINE:4)
Block(3,18,-3,CONCRETE:7)
Block(3,18,-2,IRON_FENCE:0)
Block(3,18,-1,IRON_FENCE:0)
Block(3,18,2,VINE:1)
Block(3,18,3,CONCRETE:7)
Block(3,18,4,VINE:4)
Block(3,18,8,VINE:1)
Block(3,19,-2,CONCRETE:7)
Block(3,19,-1,IRON_FENCE:0)
Block(3,19,0,IRON_FENCE:0)
Block(3,19,3,CONCRETE:7)
Block(3,19,4,VINE:4)
Block(3,19,8,VINE:1)
Block(3,20,-1,CONCRETE:7)
Block(3,20,0,IRON_FENCE:0)
Block(3,20,1,IRON_FENCE:0)
Block(3,20,2,IRON_FENCE:0)
Block(3,20,3,CONCRETE:7)
Block(3,20,4,VINE:4)
Block(3,20,8,VINE:1)
Block(3,21,-1,VINE:1)
Block(3,21,0,CONCRETE:7)
Block(3,21,1,CONCRETE:7)
Block(3,21,2,CONCRETE:7)
Block(3,21,3,IRON_FENCE:0)
Block(3,21,4,CONCRETE:7)
Block(3,21,8,VINE:1)
Block(3,22,3,CONCRETE:7)
Block(3,22,4,IRON_FENCE:0)
Block(3,22,5,CONCRETE:7)
Block(3,23,4,CONCRETE:7)
Block(3,23,5,IRON_FENCE:0)
Block(3,23,6,CONCRETE:7)
Block(3,24,5,CONCRETE:7)
Block(3,24,6,IRON_FENCE:0)
Block(3,24,7,CONCRETE:7)
Block(3,24,8,CONCRETE:7)
Block(3,25,6,CONCRETE:7)
Block(3,25,7,COBBLE_WALL:0)
Block(3,25,8,CONCRETE:7)
Block(4,10,-7,STEP:13)
Block(4,10,-6,STEP:13)
Block(4,10,-5,STEP:13)
Block(4,10,-4,STEP:13)
Block(4,10,-3,STEP:13)
Block(4,10,-2,STEP:13)
Block(4,15,8,VINE:1)
Block(4,16,8,VINE:1)
Block(4,17,3,VINE:2)
Block(4,18,0,VINE:2)
Block(4,18,3,VINE:2)
Block(4,19,0,VINE:2)
Block(4,19,3,VINE:2)
Block(4,20,0,VINE:2)
Block(4,20,3,VINE:2)
Block(4,20,7,VINE:2)
Block(4,21,0,VINE:2)
Block(4,21,3,VINE:2)
Block(4,21,7,VINE:2)
Block(4,22,3,VINE:2)
Block(4,22,7,VINE:2)
Block(4,23,6,VINE:2)
Block(4,23,7,VINE:2)
Block(4,24,7,VINE:2)

#######################################################################
# +-----------------------------------------------------------------+ #
# |                             Branches                            | #
# +-----------------------------------------------------------------+ #
#######################################################################

Branch(0,0,-16,true,GantryCraneC1R0,NORTH,100.0,0)

#######################################################################
# +-----------------------------------------------------------------+ #
# |                             Entities                            | #
# +-----------------------------------------------------------------+ #
#######################################################################


#######################################################################
# +-----------------------------------------------------------------+ #
# |                            Particles                            | #
# +-----------------------------------------------------------------+ #
#######################################################################


#######################################################################
# +-----------------------------------------------------------------+ #
# |                             Spawners                            | #
# +-----------------------------------------------------------------+ #
#######################################################################


#######################################################################
# +-----------------------------------------------------------------+ #
# |                             ModData                             | #
# +-----------------------------------------------------------------+ #
#######################################################################

