
#######################################################################
# +-----------------------------------------------------------------+ #
# |                            BO4 object                           | #
# +-----------------------------------------------------------------+ #
#######################################################################

Author: NLBlackEagle

Description: No description given

SettingsMode: WriteWithoutComments


#######################################################################
# +-----------------------------------------------------------------+ #
# |                          Main settings                          | #
# +-----------------------------------------------------------------+ #
#######################################################################

FixedRotation: 

Frequency: 0

SpawnHeight: highestBlock

UseCenterForHighestBlock: true

##############################
# Height Limits for the BO4. #
##############################

MinHeight: 0

MaxHeight: 255

InheritBO3: 

InheritBO3Rotation: NORTH

OverrideChildSettings: true

OverrideParentHeight: false

CanOverride: true

BranchFrequency: 0

BranchFrequencyGroup: 

MustBeBelowOther: false

MustBeInside: 

CannotBeInside: 

ReplacesBO3: 

MustBeInsideWorldBorders: true

CanSpawnOnWater: true

SpawnOnWaterOnly: false

SpawnUnderWater: false

SpawnAtWaterLevel: false

HeightOffset: 0

RemoveAir: false

ReplaceAbove: 

ReplaceBelow: 

ReplaceWithBiomeBlocks: true

ReplaceWithSurfaceBlock: GRASS

ReplaceWithGroundBlock: DIRT

ReplaceWithStoneBlock: STONE

SmoothRadius: 0

SmoothHeightOffset: 0

SmoothStartTop: false

SmoothStartWood: false

SmoothingSurfaceBlock: 

SmoothingGroundBlock: 

BO3Group: 

IsSpawnPoint: false

DoReplaceBlocks: false


#######################################################################
# +-----------------------------------------------------------------+ #
# |                              Blocks                             | #
# +-----------------------------------------------------------------+ #
#######################################################################

Block(-8,0,-7,quark:limestone:0)
Block(-8,0,-6,quark:limestone:0)
Block(-8,0,-5,quark:limestone:0)
Block(-8,0,-4,quark:limestone:0)
Block(-8,0,-3,quark:limestone:0)
Block(-8,0,-2,quark:limestone:0)
Block(-8,0,-1,quark:limestone:0)
Block(-8,0,0,quark:limestone:0)
Block(-8,0,1,quark:limestone:0)
Block(-8,0,2,quark:limestone:0)
Block(-8,0,3,quark:limestone:0)
Block(-8,1,-7,quark:limestone:0)
Block(-8,1,-6,quark:limestone:0)
Block(-8,1,-5,quark:limestone:0)
Block(-8,1,-4,quark:limestone:0)
Block(-8,1,-3,quark:limestone:0)
Block(-8,1,-2,quark:limestone:0)
Block(-8,1,-1,quark:limestone:0)
Block(-8,1,0,quark:limestone:0)
Block(-8,1,1,quark:limestone:0)
Block(-8,1,2,quark:limestone:0)
Block(-8,1,3,quark:limestone:0)
Block(-8,1,4,quark:iron_plate_slab:8)
Block(-8,2,-7,quark:limestone:0)
Block(-8,2,-6,srparasites:deadblood)
Block(-8,2,-5,srparasites:deadblood:1)
Block(-8,2,-4,srparasites:deadblood:1)
Block(-8,2,-3,srparasites:deadblood:1)
Block(-8,2,-2,srparasites:deadblood)
Block(-8,2,-1,srparasites:deadblood:1)
Block(-8,2,0,srparasites:deadblood:1)
Block(-8,2,1,srparasites:deadblood:2)
Block(-8,2,2,srparasites:deadblood:1)
Block(-8,2,3,quark:limestone:0)
Block(-8,3,-7,quark:limestone:0)
Block(-8,3,-6,AIR:0)
Block(-8,3,-5,AIR:0)
Block(-8,3,-4,AIR:0)
Block(-8,3,-3,AIR:0)
Block(-8,3,-2,AIR:0)
Block(-8,3,-1,AIR:0)
Block(-8,3,0,AIR:0)
Block(-8,3,1,AIR:0)
Block(-8,3,2,AIR:0)
Block(-8,3,3,quark:limestone:0)
Block(-8,4,-7,quark:limestone:0)
Block(-8,4,-6,AIR:0)
Block(-8,4,-5,AIR:0)
Block(-8,4,-4,AIR:0)
Block(-8,4,-3,AIR:0)
Block(-8,4,-2,AIR:0)
Block(-8,4,-1,AIR:0)
Block(-8,4,0,AIR:0)
Block(-8,4,1,AIR:0)
Block(-8,4,2,AIR:0)
Block(-8,4,3,quark:limestone:0)
Block(-8,5,-7,quark:limestone:0)
Block(-8,5,-6,AIR:0)
Block(-8,5,-5,AIR:0)
Block(-8,5,-4,AIR:0)
Block(-8,5,-3,AIR:0)
Block(-8,5,-2,AIR:0)
Block(-8,5,-1,AIR:0)
Block(-8,5,0,AIR:0)
Block(-8,5,1,AIR:0)
Block(-8,5,2,AIR:0)
Block(-8,5,3,quark:limestone:0)
Block(-8,6,-7,quark:limestone:0)
Block(-8,6,-6,AIR:0)
Block(-8,6,-5,AIR:0)
Block(-8,6,-4,AIR:0)
Block(-8,6,-3,AIR:0)
Block(-8,6,-2,AIR:0)
Block(-8,6,-1,AIR:0)
Block(-8,6,0,AIR:0)
Block(-8,6,1,AIR:0)
Block(-8,6,2,AIR:0)
Block(-8,6,3,quark:limestone:0)
Block(-8,7,-7,quark:limestone:0)
Block(-8,7,-6,AIR:0)
Block(-8,7,-5,AIR:0)
Block(-8,7,-4,AIR:0)
Block(-8,7,-3,AIR:0)
Block(-8,7,-2,AIR:0)
Block(-8,7,-1,AIR:0)
Block(-8,7,0,AIR:0)
Block(-8,7,1,AIR:0)
Block(-8,7,2,AIR:0)
Block(-8,7,3,quark:limestone:0)
Block(-8,8,-7,quark:limestone:0)
Block(-8,8,-6,AIR:0)
Block(-8,8,-5,AIR:0)
Block(-8,8,-4,AIR:0)
Block(-8,8,-3,AIR:0)
Block(-8,8,-2,AIR:0)
Block(-8,8,-1,AIR:0)
Block(-8,8,0,AIR:0)
Block(-8,8,1,AIR:0)
Block(-8,8,2,AIR:0)
Block(-8,8,3,quark:limestone:0)
Block(-8,9,-7,quark:limestone:0)
Block(-8,9,-6,AIR:0)
Block(-8,9,-5,AIR:0)
Block(-8,9,-4,AIR:0)
Block(-8,9,-3,AIR:0)
Block(-8,9,-2,AIR:0)
Block(-8,9,-1,AIR:0)
Block(-8,9,0,AIR:0)
Block(-8,9,1,AIR:0)
Block(-8,9,2,AIR:0)
Block(-8,9,3,quark:limestone:0)
Block(-8,10,-7,quark:limestone:0)
Block(-8,10,-6,AIR:0)
Block(-8,10,-5,AIR:0)
Block(-8,10,-4,AIR:0)
Block(-8,10,-3,AIR:0)
Block(-8,10,-2,AIR:0)
Block(-8,10,-1,AIR:0)
Block(-8,10,0,AIR:0)
Block(-8,10,1,AIR:0)
Block(-8,10,2,AIR:0)
Block(-8,10,3,quark:limestone:0)
Block(-8,11,-7,quark:limestone:0)
Block(-8,11,-6,COBBLESTONE_STAIRS:1)
Block(-8,11,-5,COBBLESTONE_STAIRS:1)
Block(-8,11,-4,COBBLESTONE_STAIRS:1)
Block(-8,11,-3,COBBLESTONE_STAIRS:1)
Block(-8,11,-2,COBBLESTONE_STAIRS:1)
Block(-8,11,-1,COBBLESTONE_STAIRS:1)
Block(-8,11,0,COBBLESTONE_STAIRS:1)
Block(-8,11,1,COBBLESTONE_STAIRS:1)
Block(-8,11,2,COBBLESTONE_STAIRS:1)
Block(-8,11,3,quark:limestone:0)
RandomBlock(-8,12,-7,quark:iron_plate:1,70,STAINED_CLAY:15,30,STAINED_CLAY:7,30,quark:iron_plate:1,100)
RandomBlock(-8,12,3,quark:iron_plate:1,70,STAINED_CLAY:15,30,STAINED_CLAY:7,30,quark:iron_plate:1,100)
Block(-8,13,-7,IRON_FENCE:0)
Block(-8,13,3,IRON_FENCE:0)
Block(-7,0,-7,quark:limestone:0)
Block(-7,0,-6,quark:limestone:0)
Block(-7,0,-5,quark:limestone:0)
Block(-7,0,-4,quark:limestone:0)
Block(-7,0,-3,quark:limestone:0)
Block(-7,0,-2,quark:limestone:0)
Block(-7,0,-1,quark:limestone:0)
Block(-7,0,0,quark:limestone:0)
Block(-7,0,1,quark:limestone:0)
Block(-7,0,2,quark:limestone:0)
Block(-7,0,3,quark:limestone:0)
RandomBlock(-7,0,4,quark:iron_plate:1,70,STAINED_CLAY:15,30,STAINED_CLAY:7,30,quark:iron_plate:1,100)
Block(-7,1,-7,quark:limestone:0)
Block(-7,1,-6,quark:limestone:0)
Block(-7,1,-5,quark:limestone:0)
Block(-7,1,-4,quark:limestone:0)
Block(-7,1,-3,quark:limestone:0)
Block(-7,1,-2,quark:limestone:0)
Block(-7,1,-1,quark:limestone:0)
Block(-7,1,0,quark:limestone:0)
Block(-7,1,1,quark:limestone:0)
Block(-7,1,2,quark:limestone:0)
Block(-7,1,3,quark:limestone:0)
RandomBlock(-7,1,4,quark:iron_plate:1,70,STAINED_CLAY:15,30,STAINED_CLAY:7,30,quark:iron_plate:1,100)
Block(-7,1,5,quark:iron_plate_slab:8)
Block(-7,1,6,quark:iron_plate_slab:8)
Block(-7,2,-7,quark:limestone:0)
Block(-7,2,-6,srparasites:deadblood:1)
Block(-7,2,-5,SMOOTH_BRICK:0)
Block(-7,2,-4,srparasites:deadblood)
Block(-7,2,-3,SMOOTH_BRICK:0)
Block(-7,2,-2,srparasites:deadblood:1)
Block(-7,2,-1,SMOOTH_BRICK:0)
Block(-7,2,0,srparasites:deadblood)
Block(-7,2,1,SMOOTH_BRICK:0)
Block(-7,2,2,srparasites:deadblood)
Block(-7,2,3,quark:limestone:0)
Block(-7,2,6,IRON_FENCE:0)
Block(-7,3,-7,quark:limestone:0)
Block(-7,3,-6,AIR:0)
Block(-7,3,-5,IRON_FENCE:0)
Block(-7,3,-4,AIR:0)
Block(-7,3,-3,IRON_FENCE:0)
Block(-7,3,-2,AIR:0)
Block(-7,3,-1,IRON_FENCE:0)
Block(-7,3,0,AIR:0)
Block(-7,3,1,AIR:0)
Block(-7,3,2,AIR:0)
Block(-7,3,3,quark:limestone:0)
Block(-7,3,6,quark:basalt_wall:0)
Block(-7,4,-7,quark:limestone:0)
Block(-7,4,-6,AIR:0)
Block(-7,4,-5,IRON_FENCE:0)
Block(-7,4,-4,AIR:0)
Block(-7,4,-3,IRON_FENCE:0)
Block(-7,4,-2,AIR:0)
Block(-7,4,-1,IRON_FENCE:0)
Block(-7,4,0,AIR:0)
Block(-7,4,1,AIR:0)
Block(-7,4,2,AIR:0)
Block(-7,4,3,quark:limestone:0)
Block(-7,4,4,quark:basalt_wall:0)
Block(-7,4,5,quark:basalt_wall:0)
Block(-7,4,6,quark:basalt:1)
Block(-7,4,7,quark:iron_plate_slab:8)
Block(-7,5,-7,quark:limestone:0)
Block(-7,5,-6,AIR:0)
Block(-7,5,-5,IRON_FENCE:0)
Block(-7,5,-4,AIR:0)
Block(-7,5,-3,IRON_FENCE:0)
Block(-7,5,-2,AIR:0)
Block(-7,5,-1,IRON_FENCE:0)
Block(-7,5,0,AIR:0)
Block(-7,5,1,IRON_FENCE:0)
Block(-7,5,2,AIR:0)
Block(-7,5,3,quark:limestone:0)
Block(-7,5,4,IRON_FENCE:0)
Block(-7,5,5,IRON_FENCE:0)
Block(-7,5,6,quark:iron_plate_slab:0)
Block(-7,5,7,quark:basalt:1)
Block(-7,6,-7,quark:limestone:0)
Block(-7,6,-6,AIR:0)
Block(-7,6,-5,IRON_FENCE:0)
Block(-7,6,-4,AIR:0)
Block(-7,6,-3,IRON_FENCE:0)
Block(-7,6,-2,AIR:0)
Block(-7,6,-1,IRON_FENCE:0)
Block(-7,6,0,AIR:0)
Block(-7,6,1,IRON_FENCE:0)
Block(-7,6,2,AIR:0)
Block(-7,6,3,quark:limestone:0)
Block(-7,6,4,IRON_FENCE:0)
Block(-7,6,7,quark:basalt_wall:0)
Block(-7,7,-7,quark:limestone:0)
Block(-7,7,-6,AIR:0)
Block(-7,7,-5,IRON_FENCE:0)
Block(-7,7,-4,AIR:0)
Block(-7,7,-3,IRON_FENCE:0)
Block(-7,7,-2,AIR:0)
Block(-7,7,-1,IRON_FENCE:0)
Block(-7,7,0,AIR:0)
Block(-7,7,1,IRON_FENCE:0)
Block(-7,7,2,AIR:0)
Block(-7,7,3,quark:limestone:0)
Block(-7,7,4,IRON_FENCE:0)
Block(-7,7,7,IRON_FENCE:0)
Block(-7,8,-7,quark:limestone:0)
Block(-7,8,-6,AIR:0)
Block(-7,8,-5,IRON_FENCE:0)
Block(-7,8,-4,AIR:0)
Block(-7,8,-3,IRON_FENCE:0)
Block(-7,8,-2,AIR:0)
Block(-7,8,-1,IRON_FENCE:0)
Block(-7,8,0,AIR:0)
Block(-7,8,1,IRON_FENCE:0)
Block(-7,8,2,AIR:0)
Block(-7,8,3,quark:limestone:0)
Block(-7,8,5,IRON_FENCE:0)
Block(-7,8,6,IRON_FENCE:0)
Block(-7,8,7,quark:basalt_wall:0)
Block(-7,9,-7,quark:limestone:0)
Block(-7,9,-6,AIR:0)
RandomBlock(-7,9,-5,quark:iron_plate:1,70,STAINED_CLAY:15,30,STAINED_CLAY:7,30,quark:iron_plate:1,100)
Block(-7,9,-4,AIR:0)
RandomBlock(-7,9,-3,quark:iron_plate:1,70,STAINED_CLAY:15,30,STAINED_CLAY:7,30,quark:iron_plate:1,100)
Block(-7,9,-2,AIR:0)
RandomBlock(-7,9,-1,quark:iron_plate:1,70,STAINED_CLAY:15,30,STAINED_CLAY:7,30,quark:iron_plate:1,100)
Block(-7,9,0,AIR:0)
RandomBlock(-7,9,1,quark:iron_plate:1,70,STAINED_CLAY:15,30,STAINED_CLAY:7,30,quark:iron_plate:1,100)
Block(-7,9,2,AIR:0)
Block(-7,9,3,quark:limestone:0)
RandomBlock(-7,9,5,quark:iron_plate:1,70,STAINED_CLAY:15,30,STAINED_CLAY:7,30,quark:iron_plate:1,100)
RandomBlock(-7,9,6,quark:iron_plate:1,70,STAINED_CLAY:15,30,STAINED_CLAY:7,30,quark:iron_plate:1,100)
RandomBlock(-7,9,7,quark:iron_plate:1,70,STAINED_CLAY:15,30,STAINED_CLAY:7,30,quark:iron_plate:1,100)
Block(-7,9,8,IRON_FENCE:0)
Block(-7,10,-7,quark:limestone:0)
Block(-7,10,-6,AIR:0)
Block(-7,10,-5,AIR:0)
Block(-7,10,-4,AIR:0)
Block(-7,10,-3,AIR:0)
Block(-7,10,-2,AIR:0)
Block(-7,10,-1,AIR:0)
Block(-7,10,0,AIR:0)
Block(-7,10,1,AIR:0)
Block(-7,10,2,AIR:0)
Block(-7,10,3,quark:limestone:0)
Block(-7,10,6,quark:basalt_wall:0)
Block(-7,11,-7,quark:limestone:0)
Block(-7,11,-6,COBBLESTONE_STAIRS:3)
RandomBlock(-7,11,-5,quark:iron_plate:1,70,STAINED_CLAY:15,30,STAINED_CLAY:7,30,quark:iron_plate:1,100)
RandomBlock(-7,11,-4,quark:iron_plate:1,70,STAINED_CLAY:15,30,STAINED_CLAY:7,30,quark:iron_plate:1,100)
RandomBlock(-7,11,-3,quark:iron_plate:1,70,STAINED_CLAY:15,30,STAINED_CLAY:7,30,quark:iron_plate:1,100)
RandomBlock(-7,11,-2,quark:iron_plate:1,70,STAINED_CLAY:15,30,STAINED_CLAY:7,30,quark:iron_plate:1,100)
RandomBlock(-7,11,-1,quark:iron_plate:1,70,STAINED_CLAY:15,30,STAINED_CLAY:7,30,quark:iron_plate:1,100)
RandomBlock(-7,11,0,quark:iron_plate:1,70,STAINED_CLAY:15,30,STAINED_CLAY:7,30,quark:iron_plate:1,100)
RandomBlock(-7,11,1,quark:iron_plate:1,70,STAINED_CLAY:15,30,STAINED_CLAY:7,30,quark:iron_plate:1,100)
Block(-7,11,2,COBBLESTONE_STAIRS:2)
Block(-7,11,3,quark:limestone:0)
Block(-7,11,6,IRON_FENCE:0)
RandomBlock(-7,12,-7,quark:iron_plate:1,70,STAINED_CLAY:15,30,STAINED_CLAY:7,30,quark:iron_plate:1,100)
Block(-7,12,-5,quark:basalt_wall:0)
Block(-7,12,-4,quark:basalt_wall:0)
Block(-7,12,-3,quark:basalt_wall:0)
Block(-7,12,-2,quark:basalt_wall:0)
Block(-7,12,-1,quark:basalt_wall:0)
Block(-7,12,0,quark:basalt_wall:0)
Block(-7,12,1,quark:basalt_wall:0)
RandomBlock(-7,12,3,quark:iron_plate:1,70,STAINED_CLAY:15,30,STAINED_CLAY:7,30,quark:iron_plate:1,100)
Block(-7,12,4,quark:iron_plate_slab:0)
Block(-7,12,5,quark:iron_plate_slab:0)
Block(-7,12,6,quark:iron_plate_slab:0)
Block(-7,13,-7,IRON_FENCE:0)
Block(-7,13,-5,SMOOTH_BRICK:1)
Block(-7,13,-4,SMOOTH_BRICK:1)
Block(-7,13,-3,SMOOTH_BRICK:1)
Block(-7,13,-2,SMOOTH_BRICK:1)
Block(-7,13,-1,SMOOTH_BRICK:1)
Block(-7,13,0,SMOOTH_BRICK:1)
Block(-7,13,1,SMOOTH_BRICK:1)
Block(-7,13,3,IRON_FENCE:0)
Block(-7,14,-5,IRON_TRAPDOOR:1)
Block(-7,14,-4,IRON_TRAPDOOR:0)
Block(-7,14,-3,IRON_TRAPDOOR:0)
Block(-7,14,-2,IRON_TRAPDOOR:0)
Block(-7,14,-1,IRON_TRAPDOOR:0)
Block(-7,14,0,IRON_TRAPDOOR:0)
Block(-7,14,1,IRON_TRAPDOOR:0)
Block(-6,0,-7,quark:limestone:0)
Block(-6,0,-6,quark:limestone:0)
Block(-6,0,-5,quark:limestone:0)
Block(-6,0,-4,quark:limestone:0)
Block(-6,0,-3,quark:limestone:0)
Block(-6,0,-2,quark:limestone:0)
Block(-6,0,-1,quark:limestone:0)
Block(-6,0,0,quark:limestone:0)
Block(-6,0,1,quark:limestone:0)
Block(-6,0,2,quark:limestone:0)
Block(-6,0,3,quark:limestone:0)
Block(-6,1,-7,quark:limestone:0)
Block(-6,1,-6,quark:limestone:0)
Block(-6,1,-5,quark:limestone:0)
Block(-6,1,-4,quark:limestone:0)
Block(-6,1,-3,quark:limestone:0)
Block(-6,1,-2,quark:limestone:0)
Block(-6,1,-1,quark:limestone:0)
Block(-6,1,0,quark:limestone:0)
Block(-6,1,1,quark:limestone:0)
Block(-6,1,2,quark:limestone:0)
Block(-6,1,3,quark:limestone:0)
Block(-6,1,4,quark:iron_plate_slab:8)
Block(-6,2,-7,quark:limestone:0)
Block(-6,2,-6,srparasites:deadblood)
Block(-6,2,-5,srparasites:deadblood:1)
Block(-6,2,-4,srparasites:deadblood)
Block(-6,2,-3,srparasites:deadblood:1)
Block(-6,2,-2,srparasites:deadblood)
Block(-6,2,-1,srparasites:deadblood:1)
Block(-6,2,0,srparasites:deadblood:1)
Block(-6,2,1,srparasites:deadblood:2)
Block(-6,2,2,srparasites:deadblood:1)
Block(-6,2,3,quark:limestone:0)
Block(-6,3,-7,quark:limestone:0)
Block(-6,3,-6,AIR:0)
Block(-6,3,-5,AIR:0)
Block(-6,3,-4,AIR:0)
Block(-6,3,-3,AIR:0)
Block(-6,3,-2,AIR:0)
Block(-6,3,-1,AIR:0)
Block(-6,3,0,AIR:0)
Block(-6,3,1,AIR:0)
Block(-6,3,2,AIR:0)
Block(-6,3,3,quark:limestone:0)
Block(-6,4,-7,quark:limestone:0)
Block(-6,4,-6,AIR:0)
Block(-6,4,-5,AIR:0)
Block(-6,4,-4,AIR:0)
Block(-6,4,-3,AIR:0)
Block(-6,4,-2,AIR:0)
Block(-6,4,-1,AIR:0)
Block(-6,4,0,AIR:0)
Block(-6,4,1,AIR:0)
Block(-6,4,2,AIR:0)
Block(-6,4,3,quark:limestone:0)
Block(-6,5,-7,quark:limestone:0)
Block(-6,5,-6,AIR:0)
Block(-6,5,-5,AIR:0)
Block(-6,5,-4,AIR:0)
Block(-6,5,-3,AIR:0)
Block(-6,5,-2,AIR:0)
Block(-6,5,-1,AIR:0)
Block(-6,5,0,AIR:0)
Block(-6,5,1,AIR:0)
Block(-6,5,2,AIR:0)
Block(-6,5,3,quark:limestone:0)
Block(-6,6,-7,quark:limestone:0)
Block(-6,6,-6,AIR:0)
Block(-6,6,-5,AIR:0)
Block(-6,6,-4,AIR:0)
Block(-6,6,-3,AIR:0)
Block(-6,6,-2,AIR:0)
Block(-6,6,-1,AIR:0)
Block(-6,6,0,AIR:0)
Block(-6,6,1,AIR:0)
Block(-6,6,2,AIR:0)
Block(-6,6,3,quark:limestone:0)
Block(-6,7,-7,quark:limestone:0)
Block(-6,7,-6,AIR:0)
Block(-6,7,-5,AIR:0)
Block(-6,7,-4,AIR:0)
Block(-6,7,-3,AIR:0)
Block(-6,7,-2,AIR:0)
Block(-6,7,-1,AIR:0)
Block(-6,7,0,AIR:0)
Block(-6,7,1,AIR:0)
Block(-6,7,2,AIR:0)
Block(-6,7,3,quark:limestone:0)
Block(-6,8,-7,quark:limestone:0)
Block(-6,8,-6,AIR:0)
Block(-6,8,-5,AIR:0)
Block(-6,8,-4,AIR:0)
Block(-6,8,-3,AIR:0)
Block(-6,8,-2,AIR:0)
Block(-6,8,-1,AIR:0)
Block(-6,8,0,AIR:0)
Block(-6,8,1,AIR:0)
Block(-6,8,2,AIR:0)
Block(-6,8,3,quark:limestone:0)
Block(-6,8,5,IRON_FENCE:0)
Block(-6,9,-7,quark:limestone:0)
Block(-6,9,-6,AIR:0)
RandomBlock(-6,9,-5,quark:iron_plate:1,70,STAINED_CLAY:15,30,STAINED_CLAY:7,30,quark:iron_plate:1,100)
Block(-6,9,-4,AIR:0)
RandomBlock(-6,9,-3,quark:iron_plate:1,70,STAINED_CLAY:15,30,STAINED_CLAY:7,30,quark:iron_plate:1,100)
Block(-6,9,-2,AIR:0)
RandomBlock(-6,9,-1,quark:iron_plate:1,70,STAINED_CLAY:15,30,STAINED_CLAY:7,30,quark:iron_plate:1,100)
Block(-6,9,0,AIR:0)
RandomBlock(-6,9,1,quark:iron_plate:1,70,STAINED_CLAY:15,30,STAINED_CLAY:7,30,quark:iron_plate:1,100)
Block(-6,9,2,AIR:0)
Block(-6,9,3,quark:limestone:0)
RandomBlock(-6,9,5,quark:iron_plate:1,70,STAINED_CLAY:15,30,STAINED_CLAY:7,30,quark:iron_plate:1,100)
Block(-6,10,-7,quark:limestone:0)
Block(-6,10,-6,AIR:0)
Block(-6,10,-5,AIR:0)
Block(-6,10,-4,AIR:0)
Block(-6,10,-3,AIR:0)
Block(-6,10,-2,AIR:0)
Block(-6,10,-1,AIR:0)
Block(-6,10,0,AIR:0)
Block(-6,10,1,AIR:0)
Block(-6,10,2,AIR:0)
Block(-6,10,3,quark:limestone:0)
Block(-6,11,-7,quark:limestone:0)
Block(-6,11,-6,COBBLESTONE_STAIRS:3)
RandomBlock(-6,11,-5,quark:iron_plate:1,70,STAINED_CLAY:15,30,STAINED_CLAY:7,30,quark:iron_plate:1,100)
RandomBlock(-6,11,-4,quark:iron_plate:1,70,STAINED_CLAY:15,30,STAINED_CLAY:7,30,quark:iron_plate:1,100)
RandomBlock(-6,11,-3,quark:iron_plate:1,70,STAINED_CLAY:15,30,STAINED_CLAY:7,30,quark:iron_plate:1,100)
RandomBlock(-6,11,-2,quark:iron_plate:1,70,STAINED_CLAY:15,30,STAINED_CLAY:7,30,quark:iron_plate:1,100)
RandomBlock(-6,11,-1,quark:iron_plate:1,70,STAINED_CLAY:15,30,STAINED_CLAY:7,30,quark:iron_plate:1,100)
RandomBlock(-6,11,0,quark:iron_plate:1,70,STAINED_CLAY:15,30,STAINED_CLAY:7,30,quark:iron_plate:1,100)
RandomBlock(-6,11,1,quark:iron_plate:1,70,STAINED_CLAY:15,30,STAINED_CLAY:7,30,quark:iron_plate:1,100)
Block(-6,11,2,COBBLESTONE_STAIRS:2)
Block(-6,11,3,quark:limestone:0)
RandomBlock(-6,12,-7,quark:iron_plate:1,70,STAINED_CLAY:15,30,STAINED_CLAY:7,30,quark:iron_plate:1,100)
Block(-6,12,-5,quark:basalt_wall:0)
Block(-6,12,-4,quark:basalt_wall:0)
Block(-6,12,-3,quark:basalt_wall:0)
Block(-6,12,-2,quark:basalt_wall:0)
Block(-6,12,-1,quark:basalt_wall:0)
Block(-6,12,0,quark:basalt_wall:0)
Block(-6,12,1,quark:basalt_wall:0)
RandomBlock(-6,12,3,quark:iron_plate:1,70,STAINED_CLAY:15,30,STAINED_CLAY:7,30,quark:iron_plate:1,100)
Block(-6,13,-7,IRON_FENCE:0)
Block(-6,13,-5,SMOOTH_BRICK:1)
Block(-6,13,-4,SMOOTH_BRICK:1)
Block(-6,13,-3,SMOOTH_BRICK:1)
Block(-6,13,-2,SMOOTH_BRICK:1)
Block(-6,13,-1,SMOOTH_BRICK:1)
Block(-6,13,0,SMOOTH_BRICK:1)
Block(-6,13,1,SMOOTH_BRICK:1)
Block(-6,13,3,IRON_FENCE:0)
Block(-6,14,-5,IRON_TRAPDOOR:1)
Block(-6,14,-4,IRON_TRAPDOOR:0)
Block(-6,14,-3,IRON_TRAPDOOR:0)
Block(-6,14,-2,IRON_TRAPDOOR:0)
Block(-6,14,-1,IRON_TRAPDOOR:0)
Block(-6,14,0,IRON_TRAPDOOR:0)
Block(-6,14,1,IRON_TRAPDOOR:0)
Block(-5,0,-7,quark:limestone:0)
Block(-5,0,-6,quark:limestone:0)
Block(-5,0,-5,quark:limestone:0)
Block(-5,0,-4,quark:limestone:0)
Block(-5,0,-3,quark:limestone:0)
Block(-5,0,-2,quark:limestone:0)
Block(-5,0,-1,quark:limestone:0)
Block(-5,0,0,quark:limestone:0)
Block(-5,0,1,quark:limestone:0)
Block(-5,0,2,quark:limestone:0)
Block(-5,0,3,quark:limestone:0)
RandomBlock(-5,0,4,quark:iron_plate:1,70,STAINED_CLAY:15,30,STAINED_CLAY:7,30,quark:iron_plate:1,100)
Block(-5,1,-7,quark:limestone:0)
Block(-5,1,-6,quark:limestone:0)
Block(-5,1,-5,quark:limestone:0)
Block(-5,1,-4,quark:limestone:0)
Block(-5,1,-3,quark:limestone:0)
Block(-5,1,-2,quark:limestone:0)
Block(-5,1,-1,quark:limestone:0)
Block(-5,1,0,quark:limestone:0)
Block(-5,1,1,quark:limestone:0)
Block(-5,1,2,quark:limestone:0)
Block(-5,1,3,quark:limestone:0)
RandomBlock(-5,1,4,quark:iron_plate:1,70,STAINED_CLAY:15,30,STAINED_CLAY:7,30,quark:iron_plate:1,100)
Block(-5,1,5,quark:iron_plate_slab:8)
Block(-5,1,6,quark:iron_plate_slab:8)
Block(-5,2,-7,quark:limestone:0)
Block(-5,2,-6,srparasites:deadblood:1)
Block(-5,2,-5,SMOOTH_BRICK:0)
Block(-5,2,-4,srparasites:deadblood:1)
Block(-5,2,-3,SMOOTH_BRICK:0)
Block(-5,2,-2,srparasites:deadblood:1)
Block(-5,2,-1,SMOOTH_BRICK:0)
Block(-5,2,0,srparasites:deadblood:1)
Block(-5,2,1,SMOOTH_BRICK:0)
Block(-5,2,2,srparasites:deadblood)
Block(-5,2,3,quark:limestone:0)
Block(-5,2,6,IRON_FENCE:0)
Block(-5,3,-7,quark:limestone:0)
Block(-5,3,-6,AIR:0)
Block(-5,3,-5,IRON_FENCE:0)
Block(-5,3,-4,AIR:0)
Block(-5,3,-3,IRON_FENCE:0)
Block(-5,3,-2,AIR:0)
Block(-5,3,-1,IRON_FENCE:0)
Block(-5,3,0,AIR:0)
Block(-5,3,1,IRON_FENCE:0)
Block(-5,3,2,AIR:0)
Block(-5,3,3,quark:limestone:0)
Block(-5,3,6,quark:basalt_wall:0)
Block(-5,4,-7,quark:limestone:0)
Block(-5,4,-6,AIR:0)
Block(-5,4,-5,IRON_FENCE:0)
Block(-5,4,-4,AIR:0)
Block(-5,4,-3,IRON_FENCE:0)
Block(-5,4,-2,AIR:0)
Block(-5,4,-1,IRON_FENCE:0)
Block(-5,4,0,AIR:0)
Block(-5,4,1,IRON_FENCE:0)
Block(-5,4,2,AIR:0)
Block(-5,4,3,quark:limestone:0)
Block(-5,4,4,quark:basalt_wall:0)
Block(-5,4,5,quark:basalt_wall:0)
Block(-5,4,6,quark:basalt:1)
Block(-5,4,7,quark:iron_plate_slab:8)
Block(-5,5,-7,quark:limestone:0)
Block(-5,5,-6,AIR:0)
Block(-5,5,-5,IRON_FENCE:0)
Block(-5,5,-4,AIR:0)
Block(-5,5,-3,IRON_FENCE:0)
Block(-5,5,-2,AIR:0)
Block(-5,5,-1,IRON_FENCE:0)
Block(-5,5,0,AIR:0)
Block(-5,5,1,IRON_FENCE:0)
Block(-5,5,2,AIR:0)
Block(-5,5,3,quark:limestone:0)
Block(-5,5,4,IRON_FENCE:0)
Block(-5,5,5,IRON_FENCE:0)
Block(-5,5,6,quark:iron_plate_slab:0)
Block(-5,5,7,quark:basalt:1)
Block(-5,6,-7,quark:limestone:0)
Block(-5,6,-6,AIR:0)
Block(-5,6,-5,IRON_FENCE:0)
Block(-5,6,-4,AIR:0)
Block(-5,6,-3,IRON_FENCE:0)
Block(-5,6,-2,AIR:0)
Block(-5,6,-1,IRON_FENCE:0)
Block(-5,6,0,AIR:0)
Block(-5,6,1,IRON_FENCE:0)
Block(-5,6,2,AIR:0)
Block(-5,6,3,quark:limestone:0)
Block(-5,6,4,IRON_FENCE:0)
Block(-5,6,7,quark:basalt_wall:0)
Block(-5,7,-7,quark:limestone:0)
Block(-5,7,-6,AIR:0)
Block(-5,7,-5,IRON_FENCE:0)
Block(-5,7,-4,AIR:0)
Block(-5,7,-3,IRON_FENCE:0)
Block(-5,7,-2,AIR:0)
Block(-5,7,-1,IRON_FENCE:0)
Block(-5,7,0,AIR:0)
Block(-5,7,1,IRON_FENCE:0)
Block(-5,7,2,AIR:0)
Block(-5,7,3,quark:limestone:0)
Block(-5,7,4,IRON_FENCE:0)
Block(-5,7,7,IRON_FENCE:0)
Block(-5,8,-7,quark:limestone:0)
Block(-5,8,-6,AIR:0)
Block(-5,8,-5,IRON_FENCE:0)
Block(-5,8,-4,AIR:0)
Block(-5,8,-3,IRON_FENCE:0)
Block(-5,8,-2,AIR:0)
Block(-5,8,-1,IRON_FENCE:0)
Block(-5,8,0,AIR:0)
Block(-5,8,1,IRON_FENCE:0)
Block(-5,8,2,AIR:0)
Block(-5,8,3,quark:limestone:0)
Block(-5,8,5,IRON_FENCE:0)
Block(-5,8,6,IRON_FENCE:0)
Block(-5,8,7,quark:basalt_wall:0)
Block(-5,9,-7,quark:limestone:0)
Block(-5,9,-6,AIR:0)
RandomBlock(-5,9,-5,quark:iron_plate:1,70,STAINED_CLAY:15,30,STAINED_CLAY:7,30,quark:iron_plate:1,100)
Block(-5,9,-4,AIR:0)
RandomBlock(-5,9,-3,quark:iron_plate:1,70,STAINED_CLAY:15,30,STAINED_CLAY:7,30,quark:iron_plate:1,100)
Block(-5,9,-2,AIR:0)
RandomBlock(-5,9,-1,quark:iron_plate:1,70,STAINED_CLAY:15,30,STAINED_CLAY:7,30,quark:iron_plate:1,100)
Block(-5,9,0,AIR:0)
RandomBlock(-5,9,1,quark:iron_plate:1,70,STAINED_CLAY:15,30,STAINED_CLAY:7,30,quark:iron_plate:1,100)
Block(-5,9,2,AIR:0)
Block(-5,9,3,quark:limestone:0)
RandomBlock(-5,9,5,quark:iron_plate:1,70,STAINED_CLAY:15,30,STAINED_CLAY:7,30,quark:iron_plate:1,100)
RandomBlock(-5,9,6,quark:iron_plate:1,70,STAINED_CLAY:15,30,STAINED_CLAY:7,30,quark:iron_plate:1,100)
RandomBlock(-5,9,7,quark:iron_plate:1,70,STAINED_CLAY:15,30,STAINED_CLAY:7,30,quark:iron_plate:1,100)
Block(-5,9,8,IRON_FENCE:0)
Block(-5,10,-7,quark:limestone:0)
Block(-5,10,-6,AIR:0)
Block(-5,10,-5,AIR:0)
Block(-5,10,-4,AIR:0)
Block(-5,10,-3,AIR:0)
Block(-5,10,-2,AIR:0)
Block(-5,10,-1,AIR:0)
Block(-5,10,0,AIR:0)
Block(-5,10,1,AIR:0)
Block(-5,10,2,AIR:0)
Block(-5,10,3,quark:limestone:0)
Block(-5,10,6,quark:basalt_wall:0)
Block(-5,11,-7,quark:limestone:0)
Block(-5,11,-6,COBBLESTONE_STAIRS:3)
RandomBlock(-5,11,-5,quark:iron_plate:1,70,STAINED_CLAY:15,30,STAINED_CLAY:7,30,quark:iron_plate:1,100)
RandomBlock(-5,11,-4,quark:iron_plate:1,70,STAINED_CLAY:15,30,STAINED_CLAY:7,30,quark:iron_plate:1,100)
RandomBlock(-5,11,-3,quark:iron_plate:1,70,STAINED_CLAY:15,30,STAINED_CLAY:7,30,quark:iron_plate:1,100)
RandomBlock(-5,11,-2,quark:iron_plate:1,70,STAINED_CLAY:15,30,STAINED_CLAY:7,30,quark:iron_plate:1,100)
RandomBlock(-5,11,-1,quark:iron_plate:1,70,STAINED_CLAY:15,30,STAINED_CLAY:7,30,quark:iron_plate:1,100)
RandomBlock(-5,11,0,quark:iron_plate:1,70,STAINED_CLAY:15,30,STAINED_CLAY:7,30,quark:iron_plate:1,100)
RandomBlock(-5,11,1,quark:iron_plate:1,70,STAINED_CLAY:15,30,STAINED_CLAY:7,30,quark:iron_plate:1,100)
Block(-5,11,2,COBBLESTONE_STAIRS:2)
Block(-5,11,3,quark:limestone:0)
Block(-5,11,6,IRON_FENCE:0)
RandomBlock(-5,12,-7,quark:iron_plate:1,70,STAINED_CLAY:15,30,STAINED_CLAY:7,30,quark:iron_plate:1,100)
Block(-5,12,-5,quark:basalt_wall:0)
Block(-5,12,-4,quark:basalt_wall:0)
Block(-5,12,-3,quark:basalt_wall:0)
Block(-5,12,-2,quark:basalt_wall:0)
Block(-5,12,-1,quark:basalt_wall:0)
Block(-5,12,0,quark:basalt_wall:0)
Block(-5,12,1,quark:basalt_wall:0)
RandomBlock(-5,12,3,quark:iron_plate:1,70,STAINED_CLAY:15,30,STAINED_CLAY:7,30,quark:iron_plate:1,100)
Block(-5,12,4,quark:iron_plate_slab:0)
Block(-5,12,5,quark:iron_plate_slab:0)
Block(-5,12,6,quark:iron_plate_slab:0)
Block(-5,13,-7,IRON_FENCE:0)
Block(-5,13,-5,SMOOTH_BRICK:1)
Block(-5,13,-4,SMOOTH_BRICK:1)
Block(-5,13,-3,SMOOTH_BRICK:1)
Block(-5,13,-2,SMOOTH_BRICK:1)
Block(-5,13,-1,SMOOTH_BRICK:1)
Block(-5,13,0,SMOOTH_BRICK:1)
Block(-5,13,1,SMOOTH_BRICK:1)
Block(-5,13,3,IRON_FENCE:0)
Block(-5,14,-5,IRON_TRAPDOOR:1)
Block(-5,14,-4,IRON_TRAPDOOR:0)
Block(-5,14,-3,IRON_TRAPDOOR:0)
Block(-5,14,-2,IRON_TRAPDOOR:0)
Block(-5,14,-1,IRON_TRAPDOOR:0)
Block(-5,14,0,IRON_TRAPDOOR:0)
Block(-5,14,1,IRON_TRAPDOOR:0)
Block(-4,0,-7,quark:limestone:0)
Block(-4,0,-6,quark:limestone:0)
Block(-4,0,-5,quark:limestone:0)
Block(-4,0,-4,quark:limestone:0)
Block(-4,0,-3,quark:limestone:0)
Block(-4,0,-2,quark:limestone:0)
Block(-4,0,-1,quark:limestone:0)
Block(-4,0,0,quark:limestone:0)
Block(-4,0,1,quark:limestone:0)
Block(-4,0,2,quark:limestone:0)
Block(-4,0,3,quark:limestone:0)
Block(-4,1,-7,quark:limestone:0)
Block(-4,1,-6,quark:limestone:0)
Block(-4,1,-5,quark:limestone:0)
Block(-4,1,-4,quark:limestone:0)
Block(-4,1,-3,quark:limestone:0)
Block(-4,1,-2,quark:limestone:0)
Block(-4,1,-1,quark:limestone:0)
Block(-4,1,0,quark:limestone:0)
Block(-4,1,1,quark:limestone:0)
Block(-4,1,2,quark:limestone:0)
Block(-4,1,3,quark:limestone:0)
Block(-4,1,4,quark:iron_plate_slab:8)
Block(-4,2,-7,quark:limestone:0)
Block(-4,2,-6,srparasites:deadblood)
Block(-4,2,-5,srparasites:deadblood)
Block(-4,2,-4,srparasites:deadblood:1)
Block(-4,2,-3,srparasites:deadblood:2)
Block(-4,2,-2,srparasites:deadblood:1)
Block(-4,2,-1,srparasites:deadblood)
Block(-4,2,0,srparasites:deadblood)
Block(-4,2,1,srparasites:deadblood:1)
Block(-4,2,2,srparasites:deadblood:1)
Block(-4,2,3,quark:limestone:0)
Block(-4,3,-7,quark:limestone:0)
Block(-4,3,-6,AIR:0)
Block(-4,3,-5,AIR:0)
Block(-4,3,-4,AIR:0)
Block(-4,3,-3,AIR:0)
Block(-4,3,-2,AIR:0)
Block(-4,3,-1,AIR:0)
Block(-4,3,0,AIR:0)
Block(-4,3,1,AIR:0)
Block(-4,3,2,AIR:0)
Block(-4,3,3,quark:limestone:0)
Block(-4,4,-7,quark:limestone:0)
Block(-4,4,-6,AIR:0)
Block(-4,4,-5,AIR:0)
Block(-4,4,-4,AIR:0)
Block(-4,4,-3,AIR:0)
Block(-4,4,-2,AIR:0)
Block(-4,4,-1,AIR:0)
Block(-4,4,0,AIR:0)
Block(-4,4,1,AIR:0)
Block(-4,4,2,AIR:0)
Block(-4,4,3,quark:limestone:0)
Block(-4,5,-7,quark:limestone:0)
Block(-4,5,-6,AIR:0)
Block(-4,5,-5,AIR:0)
Block(-4,5,-4,AIR:0)
Block(-4,5,-3,AIR:0)
Block(-4,5,-2,AIR:0)
Block(-4,5,-1,AIR:0)
Block(-4,5,0,AIR:0)
Block(-4,5,1,AIR:0)
Block(-4,5,2,AIR:0)
Block(-4,5,3,quark:limestone:0)
Block(-4,6,-7,quark:limestone:0)
Block(-4,6,-6,AIR:0)
Block(-4,6,-5,AIR:0)
Block(-4,6,-4,AIR:0)
Block(-4,6,-3,AIR:0)
Block(-4,6,-2,AIR:0)
Block(-4,6,-1,AIR:0)
Block(-4,6,0,AIR:0)
Block(-4,6,1,AIR:0)
Block(-4,6,2,AIR:0)
Block(-4,6,3,quark:limestone:0)
Block(-4,7,-7,quark:limestone:0)
Block(-4,7,-6,AIR:0)
Block(-4,7,-5,AIR:0)
Block(-4,7,-4,AIR:0)
Block(-4,7,-3,AIR:0)
Block(-4,7,-2,AIR:0)
Block(-4,7,-1,AIR:0)
Block(-4,7,0,AIR:0)
Block(-4,7,1,AIR:0)
Block(-4,7,2,AIR:0)
Block(-4,7,3,quark:limestone:0)
Block(-4,8,-7,quark:limestone:0)
Block(-4,8,-6,AIR:0)
Block(-4,8,-5,AIR:0)
Block(-4,8,-4,AIR:0)
Block(-4,8,-3,AIR:0)
Block(-4,8,-2,AIR:0)
Block(-4,8,-1,AIR:0)
Block(-4,8,0,AIR:0)
Block(-4,8,1,AIR:0)
Block(-4,8,2,AIR:0)
Block(-4,8,3,quark:limestone:0)
Block(-4,8,5,IRON_FENCE:0)
Block(-4,9,-7,quark:limestone:0)
Block(-4,9,-6,AIR:0)
RandomBlock(-4,9,-5,quark:iron_plate:1,70,STAINED_CLAY:15,30,STAINED_CLAY:7,30,quark:iron_plate:1,100)
Block(-4,9,-4,AIR:0)
RandomBlock(-4,9,-3,quark:iron_plate:1,70,STAINED_CLAY:15,30,STAINED_CLAY:7,30,quark:iron_plate:1,100)
Block(-4,9,-2,AIR:0)
RandomBlock(-4,9,-1,quark:iron_plate:1,70,STAINED_CLAY:15,30,STAINED_CLAY:7,30,quark:iron_plate:1,100)
Block(-4,9,0,AIR:0)
RandomBlock(-4,9,1,quark:iron_plate:1,70,STAINED_CLAY:15,30,STAINED_CLAY:7,30,quark:iron_plate:1,100)
Block(-4,9,2,AIR:0)
Block(-4,9,3,quark:limestone:0)
RandomBlock(-4,9,5,quark:iron_plate:1,70,STAINED_CLAY:15,30,STAINED_CLAY:7,30,quark:iron_plate:1,100)
Block(-4,10,-7,quark:limestone:0)
Block(-4,10,-6,AIR:0)
Block(-4,10,-5,AIR:0)
Block(-4,10,-4,AIR:0)
Block(-4,10,-3,AIR:0)
Block(-4,10,-2,AIR:0)
Block(-4,10,-1,AIR:0)
Block(-4,10,0,AIR:0)
Block(-4,10,1,AIR:0)
Block(-4,10,2,AIR:0)
Block(-4,10,3,quark:limestone:0)
Block(-4,11,-7,quark:limestone:0)
Block(-4,11,-6,COBBLESTONE_STAIRS:3)
Block(-4,11,-5,COBBLESTONE_STAIRS:0)
Block(-4,11,-4,COBBLESTONE_STAIRS:0)
Block(-4,11,-3,COBBLESTONE_STAIRS:0)
Block(-4,11,-2,COBBLESTONE_STAIRS:0)
Block(-4,11,-1,COBBLESTONE_STAIRS:0)
Block(-4,11,0,COBBLESTONE_STAIRS:0)
Block(-4,11,1,COBBLESTONE_STAIRS:0)
Block(-4,11,2,COBBLESTONE_STAIRS:0)
Block(-4,11,3,quark:limestone:0)
RandomBlock(-4,12,-7,quark:iron_plate:1,70,STAINED_CLAY:15,30,STAINED_CLAY:7,30,quark:iron_plate:1,100)
RandomBlock(-4,12,3,quark:iron_plate:1,70,STAINED_CLAY:15,30,STAINED_CLAY:7,30,quark:iron_plate:1,100)
Block(-4,13,-7,IRON_FENCE:0)
Block(-4,13,3,IRON_FENCE:0)
RandomBlock(-3,0,-7,quark:iron_plate:1,70,STAINED_CLAY:15,30,STAINED_CLAY:7,30,quark:iron_plate:1,100)
Block(-3,0,-6,quark:limestone:0)
Block(-3,0,-5,quark:limestone:0)
Block(-3,0,-4,quark:limestone:0)
Block(-3,0,-3,quark:limestone:0)
Block(-3,0,-2,quark:limestone:0)
Block(-3,0,-1,quark:limestone:0)
Block(-3,0,0,quark:limestone:0)
Block(-3,0,1,quark:limestone:0)
Block(-3,0,2,quark:limestone:0)
RandomBlock(-3,0,3,quark:iron_plate:1,70,STAINED_CLAY:15,30,STAINED_CLAY:7,30,quark:iron_plate:1,100)
RandomBlock(-3,0,4,quark:iron_plate:1,70,STAINED_CLAY:15,30,STAINED_CLAY:7,30,quark:iron_plate:1,100)
RandomBlock(-3,1,-7,quark:iron_plate:1,70,STAINED_CLAY:15,30,STAINED_CLAY:7,30,quark:iron_plate:1,100)
Block(-3,1,-6,quark:limestone:0)
Block(-3,1,-5,quark:limestone:0)
Block(-3,1,-4,quark:limestone:0)
Block(-3,1,-3,quark:limestone:0)
Block(-3,1,-2,quark:limestone:0)
Block(-3,1,-1,quark:limestone:0)
Block(-3,1,0,quark:limestone:0)
Block(-3,1,1,quark:limestone:0)
Block(-3,1,2,quark:limestone:0)
RandomBlock(-3,1,3,quark:iron_plate:1,70,STAINED_CLAY:15,30,STAINED_CLAY:7,30,quark:iron_plate:1,100)
RandomBlock(-3,1,4,quark:iron_plate:1,70,STAINED_CLAY:15,30,STAINED_CLAY:7,30,quark:iron_plate:1,100)
Block(-3,1,5,quark:iron_plate_slab:8)
Block(-3,1,6,quark:iron_plate_slab:8)
RandomBlock(-3,2,-7,quark:iron_plate:1,70,STAINED_CLAY:15,30,STAINED_CLAY:7,30,quark:iron_plate:1,100)
Block(-3,2,-6,quark:limestone:0)
Block(-3,2,-5,quark:limestone:0)
Block(-3,2,-4,quark:limestone:0)
Block(-3,2,-3,quark:limestone:0)
Block(-3,2,-2,quark:limestone:0)
Block(-3,2,-1,quark:limestone:0)
Block(-3,2,0,quark:limestone:0)
Block(-3,2,1,quark:limestone:0)
Block(-3,2,2,quark:limestone:0)
RandomBlock(-3,2,3,quark:iron_plate:1,70,STAINED_CLAY:15,30,STAINED_CLAY:7,30,quark:iron_plate:1,100)
Block(-3,2,6,IRON_FENCE:0)
RandomBlock(-3,3,-7,quark:iron_plate:1,70,STAINED_CLAY:15,30,STAINED_CLAY:7,30,quark:iron_plate:1,100)
Block(-3,3,-6,quark:limestone:0)
Block(-3,3,-5,quark:limestone:0)
Block(-3,3,-4,quark:limestone:0)
Block(-3,3,-3,quark:limestone:0)
Block(-3,3,-2,quark:limestone:0)
Block(-3,3,-1,quark:limestone:0)
Block(-3,3,0,quark:limestone:0)
Block(-3,3,1,quark:limestone:0)
Block(-3,3,2,quark:limestone:0)
RandomBlock(-3,3,3,quark:iron_plate:1,70,STAINED_CLAY:15,30,STAINED_CLAY:7,30,quark:iron_plate:1,100)
Block(-3,3,6,quark:basalt_wall:0)
RandomBlock(-3,4,-7,quark:iron_plate:1,70,STAINED_CLAY:15,30,STAINED_CLAY:7,30,quark:iron_plate:1,100)
Block(-3,4,-6,quark:limestone:0)
Block(-3,4,-5,quark:limestone:0)
Block(-3,4,-4,quark:limestone:0)
Block(-3,4,-3,quark:limestone:0)
Block(-3,4,-2,quark:limestone:0)
Block(-3,4,-1,quark:limestone:0)
Block(-3,4,0,quark:limestone:0)
Block(-3,4,1,quark:limestone:0)
Block(-3,4,2,quark:limestone:0)
RandomBlock(-3,4,3,quark:iron_plate:1,70,STAINED_CLAY:15,30,STAINED_CLAY:7,30,quark:iron_plate:1,100)
Block(-3,4,4,quark:basalt_wall:0)
Block(-3,4,5,quark:basalt_wall:0)
Block(-3,4,6,quark:basalt:1)
Block(-3,4,7,quark:iron_plate_slab:8)
RandomBlock(-3,5,-7,quark:iron_plate:1,70,STAINED_CLAY:15,30,STAINED_CLAY:7,30,quark:iron_plate:1,100)
Block(-3,5,-6,quark:limestone:0)
Block(-3,5,-5,quark:limestone:0)
Block(-3,5,-4,quark:limestone:0)
Block(-3,5,-3,quark:limestone:0)
Block(-3,5,-2,quark:limestone:0)
Block(-3,5,-1,quark:limestone:0)
Block(-3,5,0,quark:limestone:0)
Block(-3,5,1,quark:limestone:0)
Block(-3,5,2,quark:limestone:0)
RandomBlock(-3,5,3,quark:iron_plate:1,70,STAINED_CLAY:15,30,STAINED_CLAY:7,30,quark:iron_plate:1,100)
Block(-3,5,4,IRON_FENCE:0)
Block(-3,5,5,IRON_FENCE:0)
Block(-3,5,6,quark:iron_plate_slab:0)
Block(-3,5,7,quark:basalt:1)
RandomBlock(-3,6,-7,quark:iron_plate:1,70,STAINED_CLAY:15,30,STAINED_CLAY:7,30,quark:iron_plate:1,100)
Block(-3,6,-6,quark:limestone:0)
Block(-3,6,-5,quark:limestone:0)
Block(-3,6,-4,quark:limestone:0)
Block(-3,6,-3,quark:limestone:0)
Block(-3,6,-2,quark:limestone:0)
Block(-3,6,-1,quark:limestone:0)
Block(-3,6,0,quark:limestone:0)
Block(-3,6,1,quark:limestone:0)
Block(-3,6,2,quark:limestone:0)
RandomBlock(-3,6,3,quark:iron_plate:1,70,STAINED_CLAY:15,30,STAINED_CLAY:7,30,quark:iron_plate:1,100)
Block(-3,6,4,IRON_FENCE:0)
Block(-3,6,7,quark:basalt_wall:0)
RandomBlock(-3,7,-7,quark:iron_plate:1,70,STAINED_CLAY:15,30,STAINED_CLAY:7,30,quark:iron_plate:1,100)
Block(-3,7,-6,quark:limestone:0)
Block(-3,7,-5,quark:limestone:0)
Block(-3,7,-4,quark:limestone:0)
Block(-3,7,-3,quark:limestone:0)
Block(-3,7,-2,quark:limestone:0)
Block(-3,7,-1,quark:limestone:0)
Block(-3,7,0,quark:limestone:0)
Block(-3,7,1,quark:limestone:0)
Block(-3,7,2,quark:limestone:0)
RandomBlock(-3,7,3,quark:iron_plate:1,70,STAINED_CLAY:15,30,STAINED_CLAY:7,30,quark:iron_plate:1,100)
Block(-3,7,4,IRON_FENCE:0)
Block(-3,7,7,IRON_FENCE:0)
RandomBlock(-3,8,-7,quark:iron_plate:1,70,STAINED_CLAY:15,30,STAINED_CLAY:7,30,quark:iron_plate:1,100)
Block(-3,8,-6,COBBLESTONE_STAIRS:1)
Block(-3,8,-5,COBBLESTONE_STAIRS:1)
Block(-3,8,-4,COBBLESTONE_STAIRS:1)
Block(-3,8,-3,COBBLESTONE_STAIRS:1)
Block(-3,8,-2,COBBLESTONE_STAIRS:1)
Block(-3,8,-1,COBBLESTONE_STAIRS:1)
Block(-3,8,0,COBBLESTONE_STAIRS:1)
Block(-3,8,1,COBBLESTONE_STAIRS:1)
Block(-3,8,2,COBBLESTONE_STAIRS:1)
RandomBlock(-3,8,3,quark:iron_plate:1,70,STAINED_CLAY:15,30,STAINED_CLAY:7,30,quark:iron_plate:1,100)
Block(-3,8,5,IRON_FENCE:0)
Block(-3,8,6,IRON_FENCE:0)
Block(-3,8,7,quark:basalt_wall:0)
RandomBlock(-3,9,-7,quark:iron_plate:1,70,STAINED_CLAY:15,30,STAINED_CLAY:7,30,quark:iron_plate:1,100)
Block(-3,9,-6,COBBLE_WALL:0)
RandomBlock(-3,9,-5,quark:iron_plate:1,70,STAINED_CLAY:15,30,STAINED_CLAY:7,30,quark:iron_plate:1,100)
Block(-3,9,-4,COBBLE_WALL:0)
RandomBlock(-3,9,-3,quark:iron_plate:1,70,STAINED_CLAY:15,30,STAINED_CLAY:7,30,quark:iron_plate:1,100)
Block(-3,9,-2,COBBLE_WALL:0)
RandomBlock(-3,9,-1,quark:iron_plate:1,70,STAINED_CLAY:15,30,STAINED_CLAY:7,30,quark:iron_plate:1,100)
Block(-3,9,0,COBBLE_WALL:0)
RandomBlock(-3,9,1,quark:iron_plate:1,70,STAINED_CLAY:15,30,STAINED_CLAY:7,30,quark:iron_plate:1,100)
Block(-3,9,2,COBBLE_WALL:0)
RandomBlock(-3,9,3,quark:iron_plate:1,70,STAINED_CLAY:15,30,STAINED_CLAY:7,30,quark:iron_plate:1,100)
RandomBlock(-3,9,5,quark:iron_plate:1,70,STAINED_CLAY:15,30,STAINED_CLAY:7,30,quark:iron_plate:1,100)
RandomBlock(-3,9,6,quark:iron_plate:1,70,STAINED_CLAY:15,30,STAINED_CLAY:7,30,quark:iron_plate:1,100)
RandomBlock(-3,9,7,quark:iron_plate:1,70,STAINED_CLAY:15,30,STAINED_CLAY:7,30,quark:iron_plate:1,100)
Block(-3,9,8,IRON_FENCE:0)
RandomBlock(-3,10,-7,quark:iron_plate:1,70,STAINED_CLAY:15,30,STAINED_CLAY:7,30,quark:iron_plate:1,100)
Block(-3,10,-6,COBBLESTONE_STAIRS:5)
Block(-3,10,-5,COBBLESTONE_STAIRS:5)
Block(-3,10,-4,COBBLESTONE_STAIRS:5)
Block(-3,10,-3,COBBLESTONE_STAIRS:5)
Block(-3,10,-2,COBBLESTONE_STAIRS:5)
Block(-3,10,-1,COBBLESTONE_STAIRS:5)
Block(-3,10,0,COBBLESTONE_STAIRS:5)
Block(-3,10,1,COBBLESTONE_STAIRS:5)
Block(-3,10,2,COBBLESTONE_STAIRS:5)
RandomBlock(-3,10,3,quark:iron_plate:1,70,STAINED_CLAY:15,30,STAINED_CLAY:7,30,quark:iron_plate:1,100)
Block(-3,10,6,quark:basalt_wall:0)
RandomBlock(-3,11,-7,quark:iron_plate:1,70,STAINED_CLAY:15,30,STAINED_CLAY:7,30,quark:iron_plate:1,100)
Block(-3,11,-6,quark:limestone:0)
Block(-3,11,-5,quark:limestone:0)
Block(-3,11,-4,quark:limestone:0)
Block(-3,11,-3,quark:limestone:0)
Block(-3,11,-2,quark:limestone:0)
Block(-3,11,-1,quark:limestone:0)
Block(-3,11,0,quark:limestone:0)
Block(-3,11,1,quark:limestone:0)
Block(-3,11,2,quark:limestone:0)
RandomBlock(-3,11,3,quark:iron_plate:1,70,STAINED_CLAY:15,30,STAINED_CLAY:7,30,quark:iron_plate:1,100)
Block(-3,11,6,IRON_FENCE:0)
RandomBlock(-3,12,-7,quark:iron_plate:1,70,STAINED_CLAY:15,30,STAINED_CLAY:7,30,quark:iron_plate:1,100)
RandomBlock(-3,12,-6,quark:iron_plate:1,70,STAINED_CLAY:15,30,STAINED_CLAY:7,30,quark:iron_plate:1,100)
RandomBlock(-3,12,-5,quark:iron_plate:1,70,STAINED_CLAY:15,30,STAINED_CLAY:7,30,quark:iron_plate:1,100)
RandomBlock(-3,12,-4,quark:iron_plate:1,70,STAINED_CLAY:15,30,STAINED_CLAY:7,30,quark:iron_plate:1,100)
RandomBlock(-3,12,-3,quark:iron_plate:1,70,STAINED_CLAY:15,30,STAINED_CLAY:7,30,quark:iron_plate:1,100)
RandomBlock(-3,12,-2,quark:iron_plate:1,70,STAINED_CLAY:15,30,STAINED_CLAY:7,30,quark:iron_plate:1,100)
RandomBlock(-3,12,-1,quark:iron_plate:1,70,STAINED_CLAY:15,30,STAINED_CLAY:7,30,quark:iron_plate:1,100)
RandomBlock(-3,12,0,quark:iron_plate:1,70,STAINED_CLAY:15,30,STAINED_CLAY:7,30,quark:iron_plate:1,100)
RandomBlock(-3,12,1,quark:iron_plate:1,70,STAINED_CLAY:15,30,STAINED_CLAY:7,30,quark:iron_plate:1,100)
RandomBlock(-3,12,2,quark:iron_plate:1,70,STAINED_CLAY:15,30,STAINED_CLAY:7,30,quark:iron_plate:1,100)
RandomBlock(-3,12,3,quark:iron_plate:1,70,STAINED_CLAY:15,30,STAINED_CLAY:7,30,quark:iron_plate:1,100)
Block(-3,12,4,quark:iron_plate_slab:0)
Block(-3,12,5,quark:iron_plate_slab:0)
Block(-3,12,6,quark:iron_plate_slab:0)
Block(-3,13,-7,IRON_FENCE:0)
Block(-3,13,-6,IRON_FENCE:0)
Block(-3,13,-5,IRON_FENCE:0)
Block(-3,13,-4,IRON_FENCE:0)
Block(-3,13,-3,IRON_FENCE:0)
Block(-3,13,-2,IRON_FENCE:0)
Block(-3,13,-1,IRON_FENCE:0)
Block(-3,13,0,IRON_FENCE:0)
Block(-3,13,1,IRON_FENCE:0)
Block(-3,13,2,IRON_FENCE:0)
Block(-3,13,3,IRON_FENCE:0)
Block(-2,7,-5,IRON_FENCE:0)
Block(-2,7,-3,IRON_FENCE:0)
Block(-2,7,-1,IRON_FENCE:0)
Block(-2,7,1,IRON_FENCE:0)
Block(-2,8,-5,IRON_FENCE:0)
Block(-2,8,-3,IRON_FENCE:0)
Block(-2,8,-1,IRON_FENCE:0)
Block(-2,8,1,IRON_FENCE:0)
Block(-2,8,5,IRON_FENCE:0)
RandomBlock(-2,9,-5,quark:iron_plate:1,70,STAINED_CLAY:15,30,STAINED_CLAY:7,30,quark:iron_plate:1,100)
RandomBlock(-2,9,-3,quark:iron_plate:1,70,STAINED_CLAY:15,30,STAINED_CLAY:7,30,quark:iron_plate:1,100)
RandomBlock(-2,9,-1,quark:iron_plate:1,70,STAINED_CLAY:15,30,STAINED_CLAY:7,30,quark:iron_plate:1,100)
RandomBlock(-2,9,1,quark:iron_plate:1,70,STAINED_CLAY:15,30,STAINED_CLAY:7,30,quark:iron_plate:1,100)
RandomBlock(-2,9,5,quark:iron_plate:1,70,STAINED_CLAY:15,30,STAINED_CLAY:7,30,quark:iron_plate:1,100)
Block(-2,10,-5,IRON_FENCE:0)
Block(-2,10,-3,IRON_FENCE:0)
Block(-2,10,-1,IRON_FENCE:0)
Block(-2,10,1,IRON_FENCE:0)
Block(-2,11,-5,IRON_FENCE:0)
Block(-2,11,-3,IRON_FENCE:0)
Block(-2,11,-1,IRON_FENCE:0)
Block(-2,11,1,IRON_FENCE:0)
Block(-2,12,3,quark:iron_plate_slab:0)
Block(-1,8,-5,IRON_FENCE:0)
Block(-1,8,-3,IRON_FENCE:0)
Block(-1,8,-1,IRON_FENCE:0)
Block(-1,8,1,IRON_FENCE:0)
Block(-1,8,2,IRON_FENCE:0)
Block(-1,8,3,IRON_FENCE:0)
Block(-1,8,4,IRON_FENCE:0)
Block(-1,8,5,IRON_FENCE:0)
RandomBlock(-1,9,-5,quark:iron_plate:1,70,STAINED_CLAY:15,30,STAINED_CLAY:7,30,quark:iron_plate:1,100)
RandomBlock(-1,9,-3,quark:iron_plate:1,70,STAINED_CLAY:15,30,STAINED_CLAY:7,30,quark:iron_plate:1,100)
RandomBlock(-1,9,-1,quark:iron_plate:1,70,STAINED_CLAY:15,30,STAINED_CLAY:7,30,quark:iron_plate:1,100)
RandomBlock(-1,9,1,quark:iron_plate:1,70,STAINED_CLAY:15,30,STAINED_CLAY:7,30,quark:iron_plate:1,100)
RandomBlock(-1,9,2,quark:iron_plate:1,70,STAINED_CLAY:15,30,STAINED_CLAY:7,30,quark:iron_plate:1,100)
RandomBlock(-1,9,3,quark:iron_plate:1,70,STAINED_CLAY:15,30,STAINED_CLAY:7,30,quark:iron_plate:1,100)
RandomBlock(-1,9,4,quark:iron_plate:1,70,STAINED_CLAY:15,30,STAINED_CLAY:7,30,quark:iron_plate:1,100)
RandomBlock(-1,9,5,quark:iron_plate:1,70,STAINED_CLAY:15,30,STAINED_CLAY:7,30,quark:iron_plate:1,100)
Block(-1,10,-5,IRON_FENCE:0)
Block(-1,10,-3,IRON_FENCE:0)
Block(-1,10,-1,IRON_FENCE:0)
Block(-1,10,1,IRON_FENCE:0)
Block(-1,10,3,quark:basalt_wall:0)
Block(-1,11,3,quark:basalt_wall:0)
Block(-1,12,3,quark:iron_plate_slab:0)
Block(0,7,-5,IRON_FENCE:0)
Block(0,7,-3,IRON_FENCE:0)
Block(0,7,-1,IRON_FENCE:0)
Block(0,7,1,IRON_FENCE:0)
Block(0,8,-5,IRON_FENCE:0)
Block(0,8,-3,IRON_FENCE:0)
Block(0,8,-1,IRON_FENCE:0)
Block(0,8,1,IRON_FENCE:0)
Block(0,8,5,IRON_FENCE:0)
RandomBlock(0,9,-5,quark:iron_plate:1,70,STAINED_CLAY:15,30,STAINED_CLAY:7,30,quark:iron_plate:1,100)
RandomBlock(0,9,-3,quark:iron_plate:1,70,STAINED_CLAY:15,30,STAINED_CLAY:7,30,quark:iron_plate:1,100)
RandomBlock(0,9,-1,quark:iron_plate:1,70,STAINED_CLAY:15,30,STAINED_CLAY:7,30,quark:iron_plate:1,100)
RandomBlock(0,9,1,quark:iron_plate:1,70,STAINED_CLAY:15,30,STAINED_CLAY:7,30,quark:iron_plate:1,100)
RandomBlock(0,9,5,quark:iron_plate:1,70,STAINED_CLAY:15,30,STAINED_CLAY:7,30,quark:iron_plate:1,100)
Block(0,10,-5,IRON_FENCE:0)
Block(0,10,-3,IRON_FENCE:0)
Block(0,10,-1,IRON_FENCE:0)
Block(0,10,1,IRON_FENCE:0)
Block(0,11,-5,IRON_FENCE:0)
Block(0,11,-3,IRON_FENCE:0)
Block(0,11,-1,IRON_FENCE:0)
Block(0,11,1,IRON_FENCE:0)
Block(0,12,3,quark:iron_plate_slab:0)
RandomBlock(1,0,-7,quark:iron_plate:1,70,STAINED_CLAY:15,30,STAINED_CLAY:7,30,quark:iron_plate:1,100)
Block(1,0,-6,quark:limestone:0)
Block(1,0,-5,quark:limestone:0)
Block(1,0,-4,quark:limestone:0)
Block(1,0,-3,quark:limestone:0)
Block(1,0,-2,quark:limestone:0)
Block(1,0,-1,quark:limestone:0)
Block(1,0,0,quark:limestone:0)
Block(1,0,1,quark:limestone:0)
Block(1,0,2,quark:limestone:0)
RandomBlock(1,0,3,quark:iron_plate:1,70,STAINED_CLAY:15,30,STAINED_CLAY:7,30,quark:iron_plate:1,100)
RandomBlock(1,0,4,quark:iron_plate:1,70,STAINED_CLAY:15,30,STAINED_CLAY:7,30,quark:iron_plate:1,100)
RandomBlock(1,1,-7,quark:iron_plate:1,70,STAINED_CLAY:15,30,STAINED_CLAY:7,30,quark:iron_plate:1,100)
Block(1,1,-6,quark:limestone:0)
Block(1,1,-5,quark:limestone:0)
Block(1,1,-4,quark:limestone:0)
Block(1,1,-3,quark:limestone:0)
Block(1,1,-2,quark:limestone:0)
Block(1,1,-1,quark:limestone:0)
Block(1,1,0,quark:limestone:0)
Block(1,1,1,quark:limestone:0)
Block(1,1,2,quark:limestone:0)
RandomBlock(1,1,3,quark:iron_plate:1,70,STAINED_CLAY:15,30,STAINED_CLAY:7,30,quark:iron_plate:1,100)
RandomBlock(1,1,4,quark:iron_plate:1,70,STAINED_CLAY:15,30,STAINED_CLAY:7,30,quark:iron_plate:1,100)
Block(1,1,5,quark:iron_plate_slab:8)
Block(1,1,6,quark:iron_plate_slab:8)
RandomBlock(1,2,-7,quark:iron_plate:1,70,STAINED_CLAY:15,30,STAINED_CLAY:7,30,quark:iron_plate:1,100)
Block(1,2,-6,quark:limestone:0)
Block(1,2,-5,quark:limestone:0)
Block(1,2,-4,quark:limestone:0)
Block(1,2,-3,quark:limestone:0)
Block(1,2,-2,quark:limestone:0)
Block(1,2,-1,quark:limestone:0)
Block(1,2,0,quark:limestone:0)
Block(1,2,1,quark:limestone:0)
Block(1,2,2,quark:limestone:0)
RandomBlock(1,2,3,quark:iron_plate:1,70,STAINED_CLAY:15,30,STAINED_CLAY:7,30,quark:iron_plate:1,100)
Block(1,2,6,IRON_FENCE:0)
RandomBlock(1,3,-7,quark:iron_plate:1,70,STAINED_CLAY:15,30,STAINED_CLAY:7,30,quark:iron_plate:1,100)
Block(1,3,-6,quark:limestone:0)
Block(1,3,-5,quark:limestone:0)
Block(1,3,-4,quark:limestone:0)
Block(1,3,-3,quark:limestone:0)
Block(1,3,-2,quark:limestone:0)
Block(1,3,-1,quark:limestone:0)
Block(1,3,0,quark:limestone:0)
Block(1,3,1,quark:limestone:0)
Block(1,3,2,quark:limestone:0)
RandomBlock(1,3,3,quark:iron_plate:1,70,STAINED_CLAY:15,30,STAINED_CLAY:7,30,quark:iron_plate:1,100)
Block(1,3,6,quark:basalt_wall:0)
RandomBlock(1,4,-7,quark:iron_plate:1,70,STAINED_CLAY:15,30,STAINED_CLAY:7,30,quark:iron_plate:1,100)
Block(1,4,-6,quark:limestone:0)
Block(1,4,-5,quark:limestone:0)
Block(1,4,-4,quark:limestone:0)
Block(1,4,-3,quark:limestone:0)
Block(1,4,-2,quark:limestone:0)
Block(1,4,-1,quark:limestone:0)
Block(1,4,0,quark:limestone:0)
Block(1,4,1,quark:limestone:0)
Block(1,4,2,quark:limestone:0)
RandomBlock(1,4,3,quark:iron_plate:1,70,STAINED_CLAY:15,30,STAINED_CLAY:7,30,quark:iron_plate:1,100)
Block(1,4,4,quark:basalt_wall:0)
Block(1,4,5,quark:basalt_wall:0)
Block(1,4,6,quark:basalt:1)
Block(1,4,7,quark:iron_plate_slab:8)
RandomBlock(1,5,-7,quark:iron_plate:1,70,STAINED_CLAY:15,30,STAINED_CLAY:7,30,quark:iron_plate:1,100)
Block(1,5,-6,quark:limestone:0)
Block(1,5,-5,quark:limestone:0)
Block(1,5,-4,quark:limestone:0)
Block(1,5,-3,quark:limestone:0)
Block(1,5,-2,quark:limestone:0)
Block(1,5,-1,quark:limestone:0)
Block(1,5,0,quark:limestone:0)
Block(1,5,1,quark:limestone:0)
Block(1,5,2,quark:limestone:0)
RandomBlock(1,5,3,quark:iron_plate:1,70,STAINED_CLAY:15,30,STAINED_CLAY:7,30,quark:iron_plate:1,100)
Block(1,5,4,IRON_FENCE:0)
Block(1,5,5,IRON_FENCE:0)
Block(1,5,6,quark:iron_plate_slab:0)
Block(1,5,7,quark:basalt:1)
RandomBlock(1,6,-7,quark:iron_plate:1,70,STAINED_CLAY:15,30,STAINED_CLAY:7,30,quark:iron_plate:1,100)
Block(1,6,-6,quark:limestone:0)
Block(1,6,-5,quark:limestone:0)
Block(1,6,-4,quark:limestone:0)
Block(1,6,-3,quark:limestone:0)
Block(1,6,-2,quark:limestone:0)
Block(1,6,-1,quark:limestone:0)
Block(1,6,0,quark:limestone:0)
Block(1,6,1,quark:limestone:0)
Block(1,6,2,quark:limestone:0)
RandomBlock(1,6,3,quark:iron_plate:1,70,STAINED_CLAY:15,30,STAINED_CLAY:7,30,quark:iron_plate:1,100)
Block(1,6,4,IRON_FENCE:0)
Block(1,6,7,quark:basalt_wall:0)
RandomBlock(1,7,-7,quark:iron_plate:1,70,STAINED_CLAY:15,30,STAINED_CLAY:7,30,quark:iron_plate:1,100)
Block(1,7,-6,quark:limestone:0)
Block(1,7,-5,quark:limestone:0)
Block(1,7,-4,quark:limestone:0)
Block(1,7,-3,quark:limestone:0)
Block(1,7,-2,quark:limestone:0)
Block(1,7,-1,quark:limestone:0)
Block(1,7,0,quark:limestone:0)
Block(1,7,1,quark:limestone:0)
Block(1,7,2,quark:limestone:0)
RandomBlock(1,7,3,quark:iron_plate:1,70,STAINED_CLAY:15,30,STAINED_CLAY:7,30,quark:iron_plate:1,100)
Block(1,7,4,IRON_FENCE:0)
Block(1,7,7,IRON_FENCE:0)
RandomBlock(1,8,-7,quark:iron_plate:1,70,STAINED_CLAY:15,30,STAINED_CLAY:7,30,quark:iron_plate:1,100)
Block(1,8,-6,COBBLESTONE_STAIRS:0)
Block(1,8,-5,COBBLESTONE_STAIRS:0)
Block(1,8,-4,COBBLESTONE_STAIRS:0)
Block(1,8,-3,COBBLESTONE_STAIRS:0)
Block(1,8,-2,COBBLESTONE_STAIRS:0)
Block(1,8,-1,COBBLESTONE_STAIRS:0)
Block(1,8,0,COBBLESTONE_STAIRS:0)
Block(1,8,1,COBBLESTONE_STAIRS:0)
Block(1,8,2,COBBLESTONE_STAIRS:0)
RandomBlock(1,8,3,quark:iron_plate:1,70,STAINED_CLAY:15,30,STAINED_CLAY:7,30,quark:iron_plate:1,100)
Block(1,8,5,IRON_FENCE:0)
Block(1,8,6,IRON_FENCE:0)
Block(1,8,7,quark:basalt_wall:0)
RandomBlock(1,9,-7,quark:iron_plate:1,70,STAINED_CLAY:15,30,STAINED_CLAY:7,30,quark:iron_plate:1,100)
Block(1,9,-6,COBBLE_WALL:0)
RandomBlock(1,9,-5,quark:iron_plate:1,70,STAINED_CLAY:15,30,STAINED_CLAY:7,30,quark:iron_plate:1,100)
Block(1,9,-4,COBBLE_WALL:0)
RandomBlock(1,9,-3,quark:iron_plate:1,70,STAINED_CLAY:15,30,STAINED_CLAY:7,30,quark:iron_plate:1,100)
Block(1,9,-2,COBBLE_WALL:0)
RandomBlock(1,9,-1,quark:iron_plate:1,70,STAINED_CLAY:15,30,STAINED_CLAY:7,30,quark:iron_plate:1,100)
Block(1,9,0,COBBLE_WALL:0)
RandomBlock(1,9,1,quark:iron_plate:1,70,STAINED_CLAY:15,30,STAINED_CLAY:7,30,quark:iron_plate:1,100)
Block(1,9,2,COBBLE_WALL:0)
RandomBlock(1,9,3,quark:iron_plate:1,70,STAINED_CLAY:15,30,STAINED_CLAY:7,30,quark:iron_plate:1,100)
RandomBlock(1,9,5,quark:iron_plate:1,70,STAINED_CLAY:15,30,STAINED_CLAY:7,30,quark:iron_plate:1,100)
RandomBlock(1,9,6,quark:iron_plate:1,70,STAINED_CLAY:15,30,STAINED_CLAY:7,30,quark:iron_plate:1,100)
RandomBlock(1,9,7,quark:iron_plate:1,70,STAINED_CLAY:15,30,STAINED_CLAY:7,30,quark:iron_plate:1,100)
Block(1,9,8,IRON_FENCE:0)
RandomBlock(1,10,-7,quark:iron_plate:1,70,STAINED_CLAY:15,30,STAINED_CLAY:7,30,quark:iron_plate:1,100)
Block(1,10,-6,COBBLESTONE_STAIRS:4)
Block(1,10,-5,COBBLESTONE_STAIRS:4)
Block(1,10,-4,COBBLESTONE_STAIRS:4)
Block(1,10,-3,COBBLESTONE_STAIRS:4)
Block(1,10,-2,COBBLESTONE_STAIRS:4)
Block(1,10,-1,COBBLESTONE_STAIRS:4)
Block(1,10,0,COBBLESTONE_STAIRS:4)
Block(1,10,1,COBBLESTONE_STAIRS:4)
Block(1,10,2,COBBLESTONE_STAIRS:4)
RandomBlock(1,10,3,quark:iron_plate:1,70,STAINED_CLAY:15,30,STAINED_CLAY:7,30,quark:iron_plate:1,100)
Block(1,10,6,quark:basalt_wall:0)
RandomBlock(1,11,-7,quark:iron_plate:1,70,STAINED_CLAY:15,30,STAINED_CLAY:7,30,quark:iron_plate:1,100)
Block(1,11,-6,quark:limestone:0)
Block(1,11,-5,quark:limestone:0)
Block(1,11,-4,quark:limestone:0)
Block(1,11,-3,quark:limestone:0)
Block(1,11,-2,quark:limestone:0)
Block(1,11,-1,quark:limestone:0)
Block(1,11,0,quark:limestone:0)
Block(1,11,1,quark:limestone:0)
Block(1,11,2,quark:limestone:0)
RandomBlock(1,11,3,quark:iron_plate:1,70,STAINED_CLAY:15,30,STAINED_CLAY:7,30,quark:iron_plate:1,100)
Block(1,11,6,IRON_FENCE:0)
RandomBlock(1,12,-7,quark:iron_plate:1,70,STAINED_CLAY:15,30,STAINED_CLAY:7,30,quark:iron_plate:1,100)
RandomBlock(1,12,-6,quark:iron_plate:1,70,STAINED_CLAY:15,30,STAINED_CLAY:7,30,quark:iron_plate:1,100)
RandomBlock(1,12,-5,quark:iron_plate:1,70,STAINED_CLAY:15,30,STAINED_CLAY:7,30,quark:iron_plate:1,100)
RandomBlock(1,12,-4,quark:iron_plate:1,70,STAINED_CLAY:15,30,STAINED_CLAY:7,30,quark:iron_plate:1,100)
RandomBlock(1,12,-3,quark:iron_plate:1,70,STAINED_CLAY:15,30,STAINED_CLAY:7,30,quark:iron_plate:1,100)
RandomBlock(1,12,-2,quark:iron_plate:1,70,STAINED_CLAY:15,30,STAINED_CLAY:7,30,quark:iron_plate:1,100)
RandomBlock(1,12,-1,quark:iron_plate:1,70,STAINED_CLAY:15,30,STAINED_CLAY:7,30,quark:iron_plate:1,100)
RandomBlock(1,12,0,quark:iron_plate:1,70,STAINED_CLAY:15,30,STAINED_CLAY:7,30,quark:iron_plate:1,100)
RandomBlock(1,12,1,quark:iron_plate:1,70,STAINED_CLAY:15,30,STAINED_CLAY:7,30,quark:iron_plate:1,100)
RandomBlock(1,12,2,quark:iron_plate:1,70,STAINED_CLAY:15,30,STAINED_CLAY:7,30,quark:iron_plate:1,100)
RandomBlock(1,12,3,quark:iron_plate:1,70,STAINED_CLAY:15,30,STAINED_CLAY:7,30,quark:iron_plate:1,100)
Block(1,12,4,quark:iron_plate_slab:0)
Block(1,12,5,quark:iron_plate_slab:0)
Block(1,12,6,quark:iron_plate_slab:0)
Block(1,13,-7,IRON_FENCE:0)
Block(1,13,-6,IRON_FENCE:0)
Block(1,13,-5,IRON_FENCE:0)
Block(1,13,-4,IRON_FENCE:0)
Block(1,13,-3,IRON_FENCE:0)
Block(1,13,-2,IRON_FENCE:0)
Block(1,13,-1,IRON_FENCE:0)
Block(1,13,0,IRON_FENCE:0)
Block(1,13,1,IRON_FENCE:0)
Block(1,13,2,IRON_FENCE:0)
Block(1,13,3,IRON_FENCE:0)
Block(2,0,-7,quark:limestone:0)
Block(2,0,-6,quark:limestone:0)
Block(2,0,-5,quark:limestone:0)
Block(2,0,-4,quark:limestone:0)
Block(2,0,-3,quark:limestone:0)
Block(2,0,-2,quark:limestone:0)
Block(2,0,-1,quark:limestone:0)
Block(2,0,0,quark:limestone:0)
Block(2,0,1,quark:limestone:0)
Block(2,0,2,quark:limestone:0)
Block(2,0,3,quark:limestone:0)
Block(2,1,-7,quark:limestone:0)
Block(2,1,-6,quark:limestone:0)
Block(2,1,-5,quark:limestone:0)
Block(2,1,-4,quark:limestone:0)
Block(2,1,-3,quark:limestone:0)
Block(2,1,-2,quark:limestone:0)
Block(2,1,-1,quark:limestone:0)
Block(2,1,0,quark:limestone:0)
Block(2,1,1,quark:limestone:0)
Block(2,1,2,quark:limestone:0)
Block(2,1,3,quark:limestone:0)
Block(2,1,4,quark:iron_plate_slab:8)
Block(2,2,-7,quark:limestone:0)
Block(2,2,-6,srparasites:deadblood)
Block(2,2,-5,srparasites:deadblood)
Block(2,2,-4,srparasites:deadblood)
Block(2,2,-3,srparasites:deadblood)
Block(2,2,-2,srparasites:deadblood)
Block(2,2,-1,srparasites:deadblood:1)
Block(2,2,0,srparasites:deadblood)
Block(2,2,1,srparasites:deadblood)
Block(2,2,2,srparasites:deadblood)
Block(2,2,3,quark:limestone:0)
Block(2,3,-7,quark:limestone:0)
Block(2,3,-6,AIR:0)
Block(2,3,-5,AIR:0)
Block(2,3,-4,AIR:0)
Block(2,3,-3,AIR:0)
Block(2,3,-2,AIR:0)
Block(2,3,-1,AIR:0)
Block(2,3,0,AIR:0)
Block(2,3,1,AIR:0)
Block(2,3,2,AIR:0)
Block(2,3,3,quark:limestone:0)
Block(2,4,-7,quark:limestone:0)
Block(2,4,-6,AIR:0)
Block(2,4,-5,AIR:0)
Block(2,4,-4,AIR:0)
Block(2,4,-3,AIR:0)
Block(2,4,-2,AIR:0)
Block(2,4,-1,AIR:0)
Block(2,4,0,AIR:0)
Block(2,4,1,AIR:0)
Block(2,4,2,AIR:0)
Block(2,4,3,quark:limestone:0)
Block(2,5,-7,quark:limestone:0)
Block(2,5,-6,AIR:0)
Block(2,5,-5,AIR:0)
Block(2,5,-4,AIR:0)
Block(2,5,-3,AIR:0)
Block(2,5,-2,AIR:0)
Block(2,5,-1,AIR:0)
Block(2,5,0,AIR:0)
Block(2,5,1,AIR:0)
Block(2,5,2,AIR:0)
Block(2,5,3,quark:limestone:0)
Block(2,6,-7,quark:limestone:0)
Block(2,6,-6,AIR:0)
Block(2,6,-5,AIR:0)
Block(2,6,-4,AIR:0)
Block(2,6,-3,AIR:0)
Block(2,6,-2,AIR:0)
Block(2,6,-1,AIR:0)
Block(2,6,0,AIR:0)
Block(2,6,1,AIR:0)
Block(2,6,2,AIR:0)
Block(2,6,3,quark:limestone:0)
Block(2,7,-7,quark:limestone:0)
Block(2,7,-6,AIR:0)
Block(2,7,-5,AIR:0)
Block(2,7,-4,AIR:0)
Block(2,7,-3,AIR:0)
Block(2,7,-2,AIR:0)
Block(2,7,-1,AIR:0)
Block(2,7,0,AIR:0)
Block(2,7,1,AIR:0)
Block(2,7,2,AIR:0)
Block(2,7,3,quark:limestone:0)
Block(2,8,-7,quark:limestone:0)
Block(2,8,-6,AIR:0)
Block(2,8,-5,AIR:0)
Block(2,8,-4,AIR:0)
Block(2,8,-3,AIR:0)
Block(2,8,-2,AIR:0)
Block(2,8,-1,AIR:0)
Block(2,8,0,AIR:0)
Block(2,8,1,AIR:0)
Block(2,8,2,AIR:0)
Block(2,8,3,quark:limestone:0)
Block(2,8,5,IRON_FENCE:0)
Block(2,9,-7,quark:limestone:0)
Block(2,9,-6,AIR:0)
Block(2,9,-5,AIR:0)
Block(2,9,-4,AIR:0)
Block(2,9,-3,AIR:0)
Block(2,9,-2,AIR:0)
Block(2,9,-1,AIR:0)
Block(2,9,0,AIR:0)
Block(2,9,1,AIR:0)
Block(2,9,2,AIR:0)
Block(2,9,3,quark:limestone:0)
RandomBlock(2,9,5,quark:iron_plate:1,70,STAINED_CLAY:15,30,STAINED_CLAY:7,30,quark:iron_plate:1,100)
Block(2,10,-7,quark:limestone:0)
Block(2,10,-6,AIR:0)
Block(2,10,-5,AIR:0)
Block(2,10,-4,AIR:0)
Block(2,10,-3,AIR:0)
Block(2,10,-2,AIR:0)
Block(2,10,-1,AIR:0)
Block(2,10,0,AIR:0)
Block(2,10,1,AIR:0)
Block(2,10,2,AIR:0)
Block(2,10,3,quark:limestone:0)
Block(2,11,-7,quark:limestone:0)
Block(2,11,-6,COBBLESTONE_STAIRS:1)
Block(2,11,-5,COBBLESTONE_STAIRS:1)
Block(2,11,-4,COBBLESTONE_STAIRS:1)
Block(2,11,-3,COBBLESTONE_STAIRS:1)
Block(2,11,-2,COBBLESTONE_STAIRS:1)
Block(2,11,-1,COBBLESTONE_STAIRS:1)
Block(2,11,0,COBBLESTONE_STAIRS:1)
Block(2,11,1,COBBLESTONE_STAIRS:1)
Block(2,11,2,COBBLESTONE_STAIRS:1)
Block(2,11,3,quark:limestone:0)
RandomBlock(2,12,-7,quark:iron_plate:1,70,STAINED_CLAY:15,30,STAINED_CLAY:7,30,quark:iron_plate:1,100)
RandomBlock(2,12,3,quark:iron_plate:1,70,STAINED_CLAY:15,30,STAINED_CLAY:7,30,quark:iron_plate:1,100)
Block(2,13,-7,IRON_FENCE:0)
Block(2,13,3,IRON_FENCE:0)
Block(3,0,-7,quark:limestone:0)
Block(3,0,-6,quark:limestone:0)
Block(3,0,-5,quark:limestone:0)
Block(3,0,-4,quark:limestone:0)
Block(3,0,-3,quark:limestone:0)
Block(3,0,-2,quark:limestone:0)
Block(3,0,-1,quark:limestone:0)
Block(3,0,0,quark:limestone:0)
Block(3,0,1,quark:limestone:0)
Block(3,0,2,quark:limestone:0)
Block(3,0,3,quark:limestone:0)
RandomBlock(3,0,4,quark:iron_plate:1,70,STAINED_CLAY:15,30,STAINED_CLAY:7,30,quark:iron_plate:1,100)
Block(3,1,-7,quark:limestone:0)
Block(3,1,-6,quark:limestone:0)
Block(3,1,-5,quark:limestone:0)
Block(3,1,-4,quark:limestone:0)
Block(3,1,-3,quark:limestone:0)
Block(3,1,-2,quark:limestone:0)
Block(3,1,-1,quark:limestone:0)
Block(3,1,0,quark:limestone:0)
Block(3,1,1,quark:limestone:0)
Block(3,1,2,quark:limestone:0)
Block(3,1,3,quark:limestone:0)
RandomBlock(3,1,4,quark:iron_plate:1,70,STAINED_CLAY:15,30,STAINED_CLAY:7,30,quark:iron_plate:1,100)
Block(3,1,5,quark:iron_plate_slab:8)
Block(3,1,6,quark:iron_plate_slab:8)
Block(3,2,-7,quark:limestone:0)
Block(3,2,-6,srparasites:deadblood)
Block(3,2,-5,SMOOTH_BRICK:0)
Block(3,2,-4,srparasites:deadblood)
Block(3,2,-3,SMOOTH_BRICK:0)
Block(3,2,-2,srparasites:deadblood)
Block(3,2,-1,SMOOTH_BRICK:0)
Block(3,2,0,srparasites:deadblood:1)
Block(3,2,1,SMOOTH_BRICK:0)
Block(3,2,2,srparasites:deadblood:1)
Block(3,2,3,quark:limestone:0)
Block(3,2,6,IRON_FENCE:0)
Block(3,3,-7,quark:limestone:0)
Block(3,3,-6,AIR:0)
Block(3,3,-5,IRON_FENCE:0)
Block(3,3,-4,AIR:0)
Block(3,3,-3,IRON_FENCE:0)
Block(3,3,-2,AIR:0)
Block(3,3,-1,IRON_FENCE:0)
Block(3,3,0,AIR:0)
Block(3,3,1,IRON_FENCE:0)
Block(3,3,2,AIR:0)
Block(3,3,3,quark:limestone:0)
Block(3,3,6,quark:basalt_wall:0)
Block(3,4,-7,quark:limestone:0)
Block(3,4,-6,AIR:0)
Block(3,4,-5,IRON_FENCE:0)
Block(3,4,-4,AIR:0)
Block(3,4,-3,IRON_FENCE:0)
Block(3,4,-2,AIR:0)
Block(3,4,-1,IRON_FENCE:0)
Block(3,4,0,AIR:0)
Block(3,4,1,IRON_FENCE:0)
Block(3,4,2,AIR:0)
Block(3,4,3,quark:limestone:0)
Block(3,4,4,quark:basalt_wall:0)
Block(3,4,5,quark:basalt_wall:0)
Block(3,4,6,quark:basalt:1)
Block(3,4,7,quark:iron_plate_slab:8)
Block(3,5,-7,quark:limestone:0)
Block(3,5,-6,AIR:0)
Block(3,5,-5,IRON_FENCE:0)
Block(3,5,-4,AIR:0)
Block(3,5,-3,IRON_FENCE:0)
Block(3,5,-2,AIR:0)
Block(3,5,-1,IRON_FENCE:0)
Block(3,5,0,AIR:0)
Block(3,5,1,IRON_FENCE:0)
Block(3,5,2,AIR:0)
Block(3,5,3,quark:limestone:0)
Block(3,5,4,IRON_FENCE:0)
Block(3,5,5,IRON_FENCE:0)
Block(3,5,6,quark:iron_plate_slab:0)
Block(3,5,7,quark:basalt:1)
Block(3,6,-7,quark:limestone:0)
Block(3,6,-6,AIR:0)
Block(3,6,-5,IRON_FENCE:0)
Block(3,6,-4,AIR:0)
Block(3,6,-3,IRON_FENCE:0)
Block(3,6,-2,AIR:0)
Block(3,6,-1,IRON_FENCE:0)
Block(3,6,0,AIR:0)
Block(3,6,1,IRON_FENCE:0)
Block(3,6,2,AIR:0)
Block(3,6,3,quark:limestone:0)
Block(3,6,4,IRON_FENCE:0)
Block(3,6,7,quark:basalt_wall:0)
Block(3,7,-7,quark:limestone:0)
Block(3,7,-6,AIR:0)
Block(3,7,-5,IRON_FENCE:0)
Block(3,7,-4,AIR:0)
Block(3,7,-3,IRON_FENCE:0)
Block(3,7,-2,AIR:0)
Block(3,7,-1,IRON_FENCE:0)
Block(3,7,0,AIR:0)
Block(3,7,1,IRON_FENCE:0)
Block(3,7,2,AIR:0)
Block(3,7,3,quark:limestone:0)
Block(3,7,4,IRON_FENCE:0)
Block(3,7,7,IRON_FENCE:0)
Block(3,8,-7,quark:limestone:0)
Block(3,8,-6,AIR:0)
Block(3,8,-5,IRON_FENCE:0)
Block(3,8,-4,AIR:0)
Block(3,8,-3,IRON_FENCE:0)
Block(3,8,-2,AIR:0)
Block(3,8,-1,IRON_FENCE:0)
Block(3,8,0,AIR:0)
Block(3,8,1,IRON_FENCE:0)
Block(3,8,2,AIR:0)
Block(3,8,3,quark:limestone:0)
Block(3,8,5,IRON_FENCE:0)
Block(3,8,6,IRON_FENCE:0)
Block(3,8,7,quark:basalt_wall:0)
Block(3,9,-7,quark:limestone:0)
Block(3,9,-6,AIR:0)
RandomBlock(3,9,-5,quark:iron_plate:1,70,STAINED_CLAY:15,30,STAINED_CLAY:7,30,quark:iron_plate:1,100)
Block(3,9,-4,AIR:0)
RandomBlock(3,9,-3,quark:iron_plate:1,70,STAINED_CLAY:15,30,STAINED_CLAY:7,30,quark:iron_plate:1,100)
Block(3,9,-2,AIR:0)
RandomBlock(3,9,-1,quark:iron_plate:1,70,STAINED_CLAY:15,30,STAINED_CLAY:7,30,quark:iron_plate:1,100)
Block(3,9,0,AIR:0)
RandomBlock(3,9,1,quark:iron_plate:1,70,STAINED_CLAY:15,30,STAINED_CLAY:7,30,quark:iron_plate:1,100)
Block(3,9,2,AIR:0)
Block(3,9,3,quark:limestone:0)
RandomBlock(3,9,5,quark:iron_plate:1,70,STAINED_CLAY:15,30,STAINED_CLAY:7,30,quark:iron_plate:1,100)
RandomBlock(3,9,6,quark:iron_plate:1,70,STAINED_CLAY:15,30,STAINED_CLAY:7,30,quark:iron_plate:1,100)
RandomBlock(3,9,7,quark:iron_plate:1,70,STAINED_CLAY:15,30,STAINED_CLAY:7,30,quark:iron_plate:1,100)
Block(3,9,8,IRON_FENCE:0)
Block(3,10,-7,quark:limestone:0)
Block(3,10,-6,AIR:0)
Block(3,10,-5,AIR:0)
Block(3,10,-4,AIR:0)
Block(3,10,-3,AIR:0)
Block(3,10,-2,AIR:0)
Block(3,10,-1,AIR:0)
Block(3,10,0,AIR:0)
Block(3,10,1,AIR:0)
Block(3,10,2,AIR:0)
Block(3,10,3,quark:limestone:0)
Block(3,10,6,quark:basalt_wall:0)
Block(3,11,-7,quark:limestone:0)
Block(3,11,-6,COBBLESTONE_STAIRS:3)
RandomBlock(3,11,-5,quark:iron_plate:1,70,STAINED_CLAY:15,30,STAINED_CLAY:7,30,quark:iron_plate:1,100)
RandomBlock(3,11,-4,quark:iron_plate:1,70,STAINED_CLAY:15,30,STAINED_CLAY:7,30,quark:iron_plate:1,100)
RandomBlock(3,11,-3,quark:iron_plate:1,70,STAINED_CLAY:15,30,STAINED_CLAY:7,30,quark:iron_plate:1,100)
RandomBlock(3,11,-2,quark:iron_plate:1,70,STAINED_CLAY:15,30,STAINED_CLAY:7,30,quark:iron_plate:1,100)
RandomBlock(3,11,-1,quark:iron_plate:1,70,STAINED_CLAY:15,30,STAINED_CLAY:7,30,quark:iron_plate:1,100)
RandomBlock(3,11,0,quark:iron_plate:1,70,STAINED_CLAY:15,30,STAINED_CLAY:7,30,quark:iron_plate:1,100)
RandomBlock(3,11,1,quark:iron_plate:1,70,STAINED_CLAY:15,30,STAINED_CLAY:7,30,quark:iron_plate:1,100)
Block(3,11,2,COBBLESTONE_STAIRS:2)
Block(3,11,3,quark:limestone:0)
Block(3,11,6,IRON_FENCE:0)
RandomBlock(3,12,-7,quark:iron_plate:1,70,STAINED_CLAY:15,30,STAINED_CLAY:7,30,quark:iron_plate:1,100)
Block(3,12,-5,quark:basalt_wall:0)
Block(3,12,-4,quark:basalt_wall:0)
Block(3,12,-3,quark:basalt_wall:0)
Block(3,12,-2,quark:basalt_wall:0)
Block(3,12,-1,quark:basalt_wall:0)
Block(3,12,0,quark:basalt_wall:0)
Block(3,12,1,quark:basalt_wall:0)
RandomBlock(3,12,3,quark:iron_plate:1,70,STAINED_CLAY:15,30,STAINED_CLAY:7,30,quark:iron_plate:1,100)
Block(3,12,4,quark:iron_plate_slab:0)
Block(3,12,5,quark:iron_plate_slab:0)
Block(3,12,6,quark:iron_plate_slab:0)
Block(3,13,-7,IRON_FENCE:0)
Block(3,13,-5,SMOOTH_BRICK:1)
Block(3,13,-4,SMOOTH_BRICK:1)
Block(3,13,-3,SMOOTH_BRICK:1)
Block(3,13,-2,SMOOTH_BRICK:1)
Block(3,13,-1,SMOOTH_BRICK:1)
Block(3,13,0,SMOOTH_BRICK:1)
Block(3,13,1,SMOOTH_BRICK:1)
Block(3,13,3,IRON_FENCE:0)
Block(3,14,-5,IRON_TRAPDOOR:1)
Block(3,14,-4,IRON_TRAPDOOR:0)
Block(3,14,-3,IRON_TRAPDOOR:0)
Block(3,14,-2,IRON_TRAPDOOR:0)
Block(3,14,-1,IRON_TRAPDOOR:0)
Block(3,14,0,IRON_TRAPDOOR:0)
Block(3,14,1,IRON_TRAPDOOR:0)
Block(4,0,-7,quark:limestone:0)
Block(4,0,-6,quark:limestone:0)
Block(4,0,-5,quark:limestone:0)
Block(4,0,-4,quark:limestone:0)
Block(4,0,-3,quark:limestone:0)
Block(4,0,-2,quark:limestone:0)
Block(4,0,-1,quark:limestone:0)
Block(4,0,0,quark:limestone:0)
Block(4,0,1,quark:limestone:0)
Block(4,0,2,quark:limestone:0)
Block(4,0,3,quark:limestone:0)
Block(4,1,-7,quark:limestone:0)
Block(4,1,-6,quark:limestone:0)
Block(4,1,-5,quark:limestone:0)
Block(4,1,-4,quark:limestone:0)
Block(4,1,-3,quark:limestone:0)
Block(4,1,-2,quark:limestone:0)
Block(4,1,-1,quark:limestone:0)
Block(4,1,0,quark:limestone:0)
Block(4,1,1,quark:limestone:0)
Block(4,1,2,quark:limestone:0)
Block(4,1,3,quark:limestone:0)
Block(4,1,4,quark:iron_plate_slab:8)
Block(4,2,-7,quark:limestone:0)
Block(4,2,-6,srparasites:deadblood)
Block(4,2,-5,srparasites:deadblood:1)
Block(4,2,-4,srparasites:deadblood:1)
Block(4,2,-3,srparasites:deadblood:2)
Block(4,2,-2,srparasites:deadblood:1)
Block(4,2,-1,srparasites:deadblood:2)
Block(4,2,0,srparasites:deadblood:1)
Block(4,2,1,srparasites:deadblood:2)
Block(4,2,2,srparasites:deadblood:1)
Block(4,2,3,quark:limestone:0)
Block(4,3,-7,quark:limestone:0)
Block(4,3,-6,AIR:0)
Block(4,3,-5,AIR:0)
Block(4,3,-4,AIR:0)
Block(4,3,-3,AIR:0)
Block(4,3,-2,AIR:0)
Block(4,3,-1,AIR:0)
Block(4,3,0,AIR:0)
Block(4,3,1,AIR:0)
Block(4,3,2,AIR:0)
Block(4,3,3,quark:limestone:0)
Block(4,4,-7,quark:limestone:0)
Block(4,4,-6,AIR:0)
Block(4,4,-5,AIR:0)
Block(4,4,-4,AIR:0)
Block(4,4,-3,AIR:0)
Block(4,4,-2,AIR:0)
Block(4,4,-1,AIR:0)
Block(4,4,0,AIR:0)
Block(4,4,1,AIR:0)
Block(4,4,2,AIR:0)
Block(4,4,3,quark:limestone:0)
Block(4,5,-7,quark:limestone:0)
Block(4,5,-6,AIR:0)
Block(4,5,-5,AIR:0)
Block(4,5,-4,AIR:0)
Block(4,5,-3,AIR:0)
Block(4,5,-2,AIR:0)
Block(4,5,-1,AIR:0)
Block(4,5,0,AIR:0)
Block(4,5,1,AIR:0)
Block(4,5,2,AIR:0)
Block(4,5,3,quark:limestone:0)
Block(4,6,-7,quark:limestone:0)
Block(4,6,-6,AIR:0)
Block(4,6,-5,AIR:0)
Block(4,6,-4,AIR:0)
Block(4,6,-3,AIR:0)
Block(4,6,-2,AIR:0)
Block(4,6,-1,AIR:0)
Block(4,6,0,AIR:0)
Block(4,6,1,AIR:0)
Block(4,6,2,AIR:0)
Block(4,6,3,quark:limestone:0)
Block(4,7,-7,quark:limestone:0)
Block(4,7,-6,AIR:0)
Block(4,7,-5,AIR:0)
Block(4,7,-4,AIR:0)
Block(4,7,-3,AIR:0)
Block(4,7,-2,AIR:0)
Block(4,7,-1,AIR:0)
Block(4,7,0,AIR:0)
Block(4,7,1,AIR:0)
Block(4,7,2,AIR:0)
Block(4,7,3,quark:limestone:0)
Block(4,8,-7,quark:limestone:0)
Block(4,8,-6,AIR:0)
Block(4,8,-5,AIR:0)
Block(4,8,-4,AIR:0)
Block(4,8,-3,AIR:0)
Block(4,8,-2,AIR:0)
Block(4,8,-1,AIR:0)
Block(4,8,0,AIR:0)
Block(4,8,1,AIR:0)
Block(4,8,2,AIR:0)
Block(4,8,3,quark:limestone:0)
Block(4,8,5,IRON_FENCE:0)
Block(4,9,-7,quark:limestone:0)
Block(4,9,-6,AIR:0)
RandomBlock(4,9,-5,quark:iron_plate:1,70,STAINED_CLAY:15,30,STAINED_CLAY:7,30,quark:iron_plate:1,100)
Block(4,9,-4,AIR:0)
RandomBlock(4,9,-3,quark:iron_plate:1,70,STAINED_CLAY:15,30,STAINED_CLAY:7,30,quark:iron_plate:1,100)
Block(4,9,-2,AIR:0)
RandomBlock(4,9,-1,quark:iron_plate:1,70,STAINED_CLAY:15,30,STAINED_CLAY:7,30,quark:iron_plate:1,100)
Block(4,9,0,AIR:0)
RandomBlock(4,9,1,quark:iron_plate:1,70,STAINED_CLAY:15,30,STAINED_CLAY:7,30,quark:iron_plate:1,100)
Block(4,9,2,AIR:0)
Block(4,9,3,quark:limestone:0)
RandomBlock(4,9,5,quark:iron_plate:1,70,STAINED_CLAY:15,30,STAINED_CLAY:7,30,quark:iron_plate:1,100)
Block(4,10,-7,quark:limestone:0)
Block(4,10,-6,AIR:0)
Block(4,10,-5,AIR:0)
Block(4,10,-4,AIR:0)
Block(4,10,-3,AIR:0)
Block(4,10,-2,AIR:0)
Block(4,10,-1,AIR:0)
Block(4,10,0,AIR:0)
Block(4,10,1,AIR:0)
Block(4,10,2,AIR:0)
Block(4,10,3,quark:limestone:0)
Block(4,11,-7,quark:limestone:0)
Block(4,11,-6,COBBLESTONE_STAIRS:3)
RandomBlock(4,11,-5,quark:iron_plate:1,70,STAINED_CLAY:15,30,STAINED_CLAY:7,30,quark:iron_plate:1,100)
RandomBlock(4,11,-4,quark:iron_plate:1,70,STAINED_CLAY:15,30,STAINED_CLAY:7,30,quark:iron_plate:1,100)
RandomBlock(4,11,-3,quark:iron_plate:1,70,STAINED_CLAY:15,30,STAINED_CLAY:7,30,quark:iron_plate:1,100)
RandomBlock(4,11,-2,quark:iron_plate:1,70,STAINED_CLAY:15,30,STAINED_CLAY:7,30,quark:iron_plate:1,100)
RandomBlock(4,11,-1,quark:iron_plate:1,70,STAINED_CLAY:15,30,STAINED_CLAY:7,30,quark:iron_plate:1,100)
RandomBlock(4,11,0,quark:iron_plate:1,70,STAINED_CLAY:15,30,STAINED_CLAY:7,30,quark:iron_plate:1,100)
RandomBlock(4,11,1,quark:iron_plate:1,70,STAINED_CLAY:15,30,STAINED_CLAY:7,30,quark:iron_plate:1,100)
Block(4,11,2,COBBLESTONE_STAIRS:2)
Block(4,11,3,quark:limestone:0)
RandomBlock(4,12,-7,quark:iron_plate:1,70,STAINED_CLAY:15,30,STAINED_CLAY:7,30,quark:iron_plate:1,100)
Block(4,12,-5,quark:basalt_wall:0)
Block(4,12,-4,quark:basalt_wall:0)
Block(4,12,-3,quark:basalt_wall:0)
Block(4,12,-2,quark:basalt_wall:0)
Block(4,12,-1,quark:basalt_wall:0)
Block(4,12,0,quark:basalt_wall:0)
Block(4,12,1,quark:basalt_wall:0)
RandomBlock(4,12,3,quark:iron_plate:1,70,STAINED_CLAY:15,30,STAINED_CLAY:7,30,quark:iron_plate:1,100)
Block(4,13,-7,IRON_FENCE:0)
Block(4,13,-5,SMOOTH_BRICK:1)
Block(4,13,-4,SMOOTH_BRICK:1)
Block(4,13,-3,SMOOTH_BRICK:1)
Block(4,13,-2,SMOOTH_BRICK:1)
Block(4,13,-1,SMOOTH_BRICK:1)
Block(4,13,0,SMOOTH_BRICK:1)
Block(4,13,1,SMOOTH_BRICK:1)
Block(4,13,3,IRON_FENCE:0)
Block(4,14,-5,IRON_TRAPDOOR:1)
Block(4,14,-4,IRON_TRAPDOOR:0)
Block(4,14,-3,IRON_TRAPDOOR:0)
Block(4,14,-2,IRON_TRAPDOOR:0)
Block(4,14,-1,IRON_TRAPDOOR:0)
Block(4,14,0,IRON_TRAPDOOR:0)
Block(4,14,1,IRON_TRAPDOOR:0)
Block(5,0,-7,quark:limestone:0)
Block(5,0,-6,quark:limestone:0)
Block(5,0,-5,quark:limestone:0)
Block(5,0,-4,quark:limestone:0)
Block(5,0,-3,quark:limestone:0)
Block(5,0,-2,quark:limestone:0)
Block(5,0,-1,quark:limestone:0)
Block(5,0,0,quark:limestone:0)
Block(5,0,1,quark:limestone:0)
Block(5,0,2,quark:limestone:0)
Block(5,0,3,quark:limestone:0)
RandomBlock(5,0,4,quark:iron_plate:1,70,STAINED_CLAY:15,30,STAINED_CLAY:7,30,quark:iron_plate:1,100)
Block(5,1,-7,quark:limestone:0)
Block(5,1,-6,quark:limestone:0)
Block(5,1,-5,quark:limestone:0)
Block(5,1,-4,quark:limestone:0)
Block(5,1,-3,quark:limestone:0)
Block(5,1,-2,quark:limestone:0)
Block(5,1,-1,quark:limestone:0)
Block(5,1,0,quark:limestone:0)
Block(5,1,1,quark:limestone:0)
Block(5,1,2,quark:limestone:0)
Block(5,1,3,quark:limestone:0)
RandomBlock(5,1,4,quark:iron_plate:1,70,STAINED_CLAY:15,30,STAINED_CLAY:7,30,quark:iron_plate:1,100)
Block(5,1,5,quark:iron_plate_slab:8)
Block(5,1,6,quark:iron_plate_slab:8)
Block(5,2,-7,quark:limestone:0)
Block(5,2,-6,srparasites:deadblood)
Block(5,2,-5,SMOOTH_BRICK:0)
Block(5,2,-4,srparasites:deadblood:1)
Block(5,2,-3,SMOOTH_BRICK:0)
Block(5,2,-2,srparasites:deadblood)
Block(5,2,-1,SMOOTH_BRICK:0)
Block(5,2,0,srparasites:deadblood)
Block(5,2,1,SMOOTH_BRICK:0)
Block(5,2,2,srparasites:deadblood)
Block(5,2,3,quark:limestone:0)
Block(5,2,6,IRON_FENCE:0)
Block(5,3,-7,quark:limestone:0)
Block(5,3,-6,AIR:0)
Block(5,3,-5,IRON_FENCE:0)
Block(5,3,-4,AIR:0)
Block(5,3,-3,IRON_FENCE:0)
Block(5,3,-2,AIR:0)
Block(5,3,-1,IRON_FENCE:0)
Block(5,3,0,AIR:0)
Block(5,3,1,IRON_FENCE:0)
Block(5,3,2,AIR:0)
Block(5,3,3,quark:limestone:0)
Block(5,3,6,quark:basalt_wall:0)
Block(5,4,-7,quark:limestone:0)
Block(5,4,-6,AIR:0)
Block(5,4,-5,IRON_FENCE:0)
Block(5,4,-4,AIR:0)
Block(5,4,-3,IRON_FENCE:0)
Block(5,4,-2,AIR:0)
Block(5,4,-1,IRON_FENCE:0)
Block(5,4,0,AIR:0)
Block(5,4,1,IRON_FENCE:0)
Block(5,4,2,AIR:0)
Block(5,4,3,quark:limestone:0)
Block(5,4,4,quark:basalt_wall:0)
Block(5,4,5,quark:basalt_wall:0)
Block(5,4,6,quark:basalt:1)
Block(5,4,7,quark:iron_plate_slab:8)
Block(5,5,-7,quark:limestone:0)
Block(5,5,-6,AIR:0)
Block(5,5,-5,IRON_FENCE:0)
Block(5,5,-4,AIR:0)
Block(5,5,-3,IRON_FENCE:0)
Block(5,5,-2,AIR:0)
Block(5,5,-1,IRON_FENCE:0)
Block(5,5,0,AIR:0)
Block(5,5,1,IRON_FENCE:0)
Block(5,5,2,AIR:0)
Block(5,5,3,quark:limestone:0)
Block(5,5,4,IRON_FENCE:0)
Block(5,5,5,IRON_FENCE:0)
Block(5,5,6,quark:iron_plate_slab:0)
Block(5,5,7,quark:basalt:1)
Block(5,6,-7,quark:limestone:0)
Block(5,6,-6,AIR:0)
Block(5,6,-5,IRON_FENCE:0)
Block(5,6,-4,AIR:0)
Block(5,6,-3,IRON_FENCE:0)
Block(5,6,-2,AIR:0)
Block(5,6,-1,IRON_FENCE:0)
Block(5,6,0,AIR:0)
Block(5,6,1,IRON_FENCE:0)
Block(5,6,2,AIR:0)
Block(5,6,3,quark:limestone:0)
Block(5,6,4,IRON_FENCE:0)
Block(5,6,7,quark:basalt_wall:0)
Block(5,7,-7,quark:limestone:0)
Block(5,7,-6,AIR:0)
Block(5,7,-5,IRON_FENCE:0)
Block(5,7,-4,AIR:0)
Block(5,7,-3,IRON_FENCE:0)
Block(5,7,-2,AIR:0)
Block(5,7,-1,IRON_FENCE:0)
Block(5,7,0,AIR:0)
Block(5,7,1,IRON_FENCE:0)
Block(5,7,2,AIR:0)
Block(5,7,3,quark:limestone:0)
Block(5,7,4,IRON_FENCE:0)
Block(5,7,7,IRON_FENCE:0)
Block(5,8,-7,quark:limestone:0)
Block(5,8,-6,AIR:0)
Block(5,8,-5,IRON_FENCE:0)
Block(5,8,-4,AIR:0)
Block(5,8,-3,IRON_FENCE:0)
Block(5,8,-2,AIR:0)
Block(5,8,-1,IRON_FENCE:0)
Block(5,8,0,AIR:0)
Block(5,8,1,IRON_FENCE:0)
Block(5,8,2,AIR:0)
Block(5,8,3,quark:limestone:0)
Block(5,8,5,IRON_FENCE:0)
Block(5,8,6,IRON_FENCE:0)
Block(5,8,7,quark:basalt_wall:0)
Block(5,9,-7,quark:limestone:0)
Block(5,9,-6,AIR:0)
RandomBlock(5,9,-5,quark:iron_plate:1,70,STAINED_CLAY:15,30,STAINED_CLAY:7,30,quark:iron_plate:1,100)
Block(5,9,-4,AIR:0)
RandomBlock(5,9,-3,quark:iron_plate:1,70,STAINED_CLAY:15,30,STAINED_CLAY:7,30,quark:iron_plate:1,100)
Block(5,9,-2,AIR:0)
RandomBlock(5,9,-1,quark:iron_plate:1,70,STAINED_CLAY:15,30,STAINED_CLAY:7,30,quark:iron_plate:1,100)
Block(5,9,0,AIR:0)
RandomBlock(5,9,1,quark:iron_plate:1,70,STAINED_CLAY:15,30,STAINED_CLAY:7,30,quark:iron_plate:1,100)
Block(5,9,2,AIR:0)
Block(5,9,3,quark:limestone:0)
RandomBlock(5,9,5,quark:iron_plate:1,70,STAINED_CLAY:15,30,STAINED_CLAY:7,30,quark:iron_plate:1,100)
RandomBlock(5,9,6,quark:iron_plate:1,70,STAINED_CLAY:15,30,STAINED_CLAY:7,30,quark:iron_plate:1,100)
RandomBlock(5,9,7,quark:iron_plate:1,70,STAINED_CLAY:15,30,STAINED_CLAY:7,30,quark:iron_plate:1,100)
Block(5,9,8,IRON_FENCE:0)
Block(5,10,-7,quark:limestone:0)
Block(5,10,-6,AIR:0)
Block(5,10,-5,AIR:0)
Block(5,10,-4,AIR:0)
Block(5,10,-3,AIR:0)
Block(5,10,-2,AIR:0)
Block(5,10,-1,AIR:0)
Block(5,10,0,AIR:0)
Block(5,10,1,AIR:0)
Block(5,10,2,AIR:0)
Block(5,10,3,quark:limestone:0)
Block(5,10,6,quark:basalt_wall:0)
Block(5,11,-7,quark:limestone:0)
Block(5,11,-6,COBBLESTONE_STAIRS:3)
RandomBlock(5,11,-5,quark:iron_plate:1,70,STAINED_CLAY:15,30,STAINED_CLAY:7,30,quark:iron_plate:1,100)
RandomBlock(5,11,-4,quark:iron_plate:1,70,STAINED_CLAY:15,30,STAINED_CLAY:7,30,quark:iron_plate:1,100)
RandomBlock(5,11,-3,quark:iron_plate:1,70,STAINED_CLAY:15,30,STAINED_CLAY:7,30,quark:iron_plate:1,100)
RandomBlock(5,11,-2,quark:iron_plate:1,70,STAINED_CLAY:15,30,STAINED_CLAY:7,30,quark:iron_plate:1,100)
RandomBlock(5,11,-1,quark:iron_plate:1,70,STAINED_CLAY:15,30,STAINED_CLAY:7,30,quark:iron_plate:1,100)
RandomBlock(5,11,0,quark:iron_plate:1,70,STAINED_CLAY:15,30,STAINED_CLAY:7,30,quark:iron_plate:1,100)
RandomBlock(5,11,1,quark:iron_plate:1,70,STAINED_CLAY:15,30,STAINED_CLAY:7,30,quark:iron_plate:1,100)
Block(5,11,2,COBBLESTONE_STAIRS:2)
Block(5,11,3,quark:limestone:0)
Block(5,11,6,IRON_FENCE:0)
RandomBlock(5,12,-7,quark:iron_plate:1,70,STAINED_CLAY:15,30,STAINED_CLAY:7,30,quark:iron_plate:1,100)
Block(5,12,-5,quark:basalt_wall:0)
Block(5,12,-4,quark:basalt_wall:0)
Block(5,12,-3,quark:basalt_wall:0)
Block(5,12,-2,quark:basalt_wall:0)
Block(5,12,-1,quark:basalt_wall:0)
Block(5,12,0,quark:basalt_wall:0)
Block(5,12,1,quark:basalt_wall:0)
RandomBlock(5,12,3,quark:iron_plate:1,70,STAINED_CLAY:15,30,STAINED_CLAY:7,30,quark:iron_plate:1,100)
Block(5,12,4,quark:iron_plate_slab:0)
Block(5,12,5,quark:iron_plate_slab:0)
Block(5,12,6,quark:iron_plate_slab:0)
Block(5,13,-7,IRON_FENCE:0)
Block(5,13,-5,SMOOTH_BRICK:1)
Block(5,13,-4,SMOOTH_BRICK:1)
Block(5,13,-3,SMOOTH_BRICK:1)
Block(5,13,-2,SMOOTH_BRICK:1)
Block(5,13,-1,SMOOTH_BRICK:1)
Block(5,13,0,SMOOTH_BRICK:1)
Block(5,13,1,SMOOTH_BRICK:1)
Block(5,13,3,IRON_FENCE:0)
Block(5,14,-5,IRON_TRAPDOOR:1)
Block(5,14,-4,IRON_TRAPDOOR:0)
Block(5,14,-3,IRON_TRAPDOOR:0)
Block(5,14,-2,IRON_TRAPDOOR:0)
Block(5,14,-1,IRON_TRAPDOOR:0)
Block(5,14,0,IRON_TRAPDOOR:0)
Block(5,14,1,IRON_TRAPDOOR:0)
Block(6,0,-7,quark:limestone:0)
Block(6,0,-6,quark:limestone:0)
Block(6,0,-5,quark:limestone:0)
Block(6,0,-4,quark:limestone:0)
Block(6,0,-3,quark:limestone:0)
Block(6,0,-2,quark:limestone:0)
Block(6,0,-1,quark:limestone:0)
Block(6,0,0,quark:limestone:0)
Block(6,0,1,quark:limestone:0)
Block(6,0,2,quark:limestone:0)
Block(6,0,3,quark:limestone:0)
Block(6,1,-7,quark:limestone:0)
Block(6,1,-6,quark:limestone:0)
Block(6,1,-5,quark:limestone:0)
Block(6,1,-4,quark:limestone:0)
Block(6,1,-3,quark:limestone:0)
Block(6,1,-2,quark:limestone:0)
Block(6,1,-1,quark:limestone:0)
Block(6,1,0,quark:limestone:0)
Block(6,1,1,quark:limestone:0)
Block(6,1,2,quark:limestone:0)
Block(6,1,3,quark:limestone:0)
Block(6,1,4,quark:iron_plate_slab:8)
Block(6,2,-7,quark:limestone:0)
Block(6,2,-6,srparasites:deadblood)
Block(6,2,-5,srparasites:deadblood)
Block(6,2,-4,srparasites:deadblood)
Block(6,2,-3,srparasites:deadblood:1)
Block(6,2,-2,srparasites:deadblood:1)
Block(6,2,-1,srparasites:deadblood:2)
Block(6,2,0,srparasites:deadblood:1)
Block(6,2,1,srparasites:deadblood)
Block(6,2,2,srparasites:deadblood)
Block(6,2,3,quark:limestone:0)
Block(6,3,-7,quark:limestone:0)
Block(6,3,-6,AIR:0)
Block(6,3,-5,AIR:0)
Block(6,3,-4,AIR:0)
Block(6,3,-3,AIR:0)
Block(6,3,-2,AIR:0)
Block(6,3,-1,AIR:0)
Block(6,3,0,AIR:0)
Block(6,3,1,AIR:0)
Block(6,3,2,AIR:0)
Block(6,3,3,quark:limestone:0)
Block(6,4,-7,quark:limestone:0)
Block(6,4,-6,AIR:0)
Block(6,4,-5,AIR:0)
Block(6,4,-4,AIR:0)
Block(6,4,-3,AIR:0)
Block(6,4,-2,AIR:0)
Block(6,4,-1,AIR:0)
Block(6,4,0,AIR:0)
Block(6,4,1,AIR:0)
Block(6,4,2,AIR:0)
Block(6,4,3,quark:limestone:0)
Block(6,5,-7,quark:limestone:0)
Block(6,5,-6,AIR:0)
Block(6,5,-5,AIR:0)
Block(6,5,-4,AIR:0)
Block(6,5,-3,AIR:0)
Block(6,5,-2,AIR:0)
Block(6,5,-1,AIR:0)
Block(6,5,0,AIR:0)
Block(6,5,1,AIR:0)
Block(6,5,2,AIR:0)
Block(6,5,3,quark:limestone:0)
Block(6,6,-7,quark:limestone:0)
Block(6,6,-6,AIR:0)
Block(6,6,-5,AIR:0)
Block(6,6,-4,AIR:0)
Block(6,6,-3,AIR:0)
Block(6,6,-2,AIR:0)
Block(6,6,-1,AIR:0)
Block(6,6,0,AIR:0)
Block(6,6,1,AIR:0)
Block(6,6,2,AIR:0)
Block(6,6,3,quark:limestone:0)
Block(6,7,-7,quark:limestone:0)
Block(6,7,-6,AIR:0)
Block(6,7,-5,AIR:0)
Block(6,7,-4,AIR:0)
Block(6,7,-3,AIR:0)
Block(6,7,-2,AIR:0)
Block(6,7,-1,AIR:0)
Block(6,7,0,AIR:0)
Block(6,7,1,AIR:0)
Block(6,7,2,AIR:0)
Block(6,7,3,quark:limestone:0)
Block(6,8,-7,quark:limestone:0)
Block(6,8,-6,AIR:0)
Block(6,8,-5,AIR:0)
Block(6,8,-4,AIR:0)
Block(6,8,-3,AIR:0)
Block(6,8,-2,AIR:0)
Block(6,8,-1,AIR:0)
Block(6,8,0,AIR:0)
Block(6,8,1,AIR:0)
Block(6,8,2,AIR:0)
Block(6,8,3,quark:limestone:0)
Block(6,9,-7,quark:limestone:0)
Block(6,9,-6,AIR:0)
RandomBlock(6,9,-5,quark:iron_plate:1,70,STAINED_CLAY:15,30,STAINED_CLAY:7,30,quark:iron_plate:1,100)
Block(6,9,-4,AIR:0)
RandomBlock(6,9,-3,quark:iron_plate:1,70,STAINED_CLAY:15,30,STAINED_CLAY:7,30,quark:iron_plate:1,100)
Block(6,9,-2,AIR:0)
RandomBlock(6,9,-1,quark:iron_plate:1,70,STAINED_CLAY:15,30,STAINED_CLAY:7,30,quark:iron_plate:1,100)
Block(6,9,0,AIR:0)
RandomBlock(6,9,1,quark:iron_plate:1,70,STAINED_CLAY:15,30,STAINED_CLAY:7,30,quark:iron_plate:1,100)
Block(6,9,2,AIR:0)
Block(6,9,3,quark:limestone:0)
Block(6,10,-7,quark:limestone:0)
Block(6,10,-6,AIR:0)
Block(6,10,-5,AIR:0)
Block(6,10,-4,AIR:0)
Block(6,10,-3,AIR:0)
Block(6,10,-2,AIR:0)
Block(6,10,-1,AIR:0)
Block(6,10,0,AIR:0)
Block(6,10,1,AIR:0)
Block(6,10,2,AIR:0)
Block(6,10,3,quark:limestone:0)
Block(6,11,-7,quark:limestone:0)
Block(6,11,-6,COBBLESTONE_STAIRS:3)
Block(6,11,-5,COBBLESTONE_STAIRS:0)
Block(6,11,-4,COBBLESTONE_STAIRS:0)
Block(6,11,-3,COBBLESTONE_STAIRS:0)
Block(6,11,-2,COBBLESTONE_STAIRS:0)
Block(6,11,-1,COBBLESTONE_STAIRS:0)
Block(6,11,0,COBBLESTONE_STAIRS:0)
Block(6,11,1,COBBLESTONE_STAIRS:0)
Block(6,11,2,COBBLESTONE_STAIRS:0)
Block(6,11,3,quark:limestone:0)
RandomBlock(6,12,-7,quark:iron_plate:1,70,STAINED_CLAY:15,30,STAINED_CLAY:7,30,quark:iron_plate:1,100)
RandomBlock(6,12,3,quark:iron_plate:1,70,STAINED_CLAY:15,30,STAINED_CLAY:7,30,quark:iron_plate:1,100)
Block(6,13,-7,IRON_FENCE:0)
Block(6,13,3,IRON_FENCE:0)
RandomBlock(7,0,-7,quark:iron_plate:1,70,STAINED_CLAY:15,30,STAINED_CLAY:7,30,quark:iron_plate:1,100)
Block(7,0,-6,quark:limestone:0)
Block(7,0,-5,quark:limestone:0)
Block(7,0,-4,quark:limestone:0)
Block(7,0,-3,quark:limestone:0)
Block(7,0,-2,quark:limestone:0)
Block(7,0,-1,quark:limestone:0)
Block(7,0,0,quark:limestone:0)
Block(7,0,1,quark:limestone:0)
Block(7,0,2,quark:limestone:0)
RandomBlock(7,0,3,quark:iron_plate:1,70,STAINED_CLAY:15,30,STAINED_CLAY:7,30,quark:iron_plate:1,100)
RandomBlock(7,1,-7,quark:iron_plate:1,70,STAINED_CLAY:15,30,STAINED_CLAY:7,30,quark:iron_plate:1,100)
Block(7,1,-6,quark:limestone:0)
Block(7,1,-5,quark:limestone:0)
Block(7,1,-4,quark:limestone:0)
Block(7,1,-3,quark:limestone:0)
Block(7,1,-2,quark:limestone:0)
Block(7,1,-1,quark:limestone:0)
Block(7,1,0,quark:limestone:0)
Block(7,1,1,quark:limestone:0)
Block(7,1,2,quark:limestone:0)
RandomBlock(7,1,3,quark:iron_plate:1,70,STAINED_CLAY:15,30,STAINED_CLAY:7,30,quark:iron_plate:1,100)
Block(7,1,4,quark:iron_plate_slab:8)
RandomBlock(7,2,-7,quark:iron_plate:1,70,STAINED_CLAY:15,30,STAINED_CLAY:7,30,quark:iron_plate:1,100)
Block(7,2,-6,quark:limestone:0)
Block(7,2,-5,quark:limestone:0)
Block(7,2,-4,quark:limestone:0)
Block(7,2,-3,quark:limestone:0)
Block(7,2,-2,quark:limestone:0)
Block(7,2,-1,quark:limestone:0)
Block(7,2,0,quark:limestone:0)
Block(7,2,1,quark:limestone:0)
Block(7,2,2,quark:limestone:0)
RandomBlock(7,2,3,quark:iron_plate:1,70,STAINED_CLAY:15,30,STAINED_CLAY:7,30,quark:iron_plate:1,100)
RandomBlock(7,3,-7,quark:iron_plate:1,70,STAINED_CLAY:15,30,STAINED_CLAY:7,30,quark:iron_plate:1,100)
Block(7,3,-6,quark:limestone:0)
Block(7,3,-5,quark:limestone:0)
Block(7,3,-4,quark:limestone:0)
Block(7,3,-3,quark:limestone:0)
Block(7,3,-2,quark:limestone:0)
Block(7,3,-1,quark:limestone:0)
Block(7,3,0,quark:limestone:0)
Block(7,3,1,quark:limestone:0)
Block(7,3,2,quark:limestone:0)
RandomBlock(7,3,3,quark:iron_plate:1,70,STAINED_CLAY:15,30,STAINED_CLAY:7,30,quark:iron_plate:1,100)
RandomBlock(7,4,-7,quark:iron_plate:1,70,STAINED_CLAY:15,30,STAINED_CLAY:7,30,quark:iron_plate:1,100)
Block(7,4,-6,quark:limestone:0)
Block(7,4,-5,quark:limestone:0)
Block(7,4,-4,quark:limestone:0)
Block(7,4,-3,quark:limestone:0)
Block(7,4,-2,quark:limestone:0)
Block(7,4,-1,quark:limestone:0)
Block(7,4,0,quark:limestone:0)
Block(7,4,1,quark:limestone:0)
Block(7,4,2,quark:limestone:0)
RandomBlock(7,4,3,quark:iron_plate:1,70,STAINED_CLAY:15,30,STAINED_CLAY:7,30,quark:iron_plate:1,100)
RandomBlock(7,5,-7,quark:iron_plate:1,70,STAINED_CLAY:15,30,STAINED_CLAY:7,30,quark:iron_plate:1,100)
Block(7,5,-6,quark:limestone:0)
Block(7,5,-5,quark:limestone:0)
RandomBlock(7,5,-4,quark:iron_plate:1,70,STAINED_CLAY:15,30,STAINED_CLAY:7,30,quark:iron_plate:1,100)
RandomBlock(7,5,-3,quark:iron_plate:1,70,STAINED_CLAY:15,30,STAINED_CLAY:7,30,quark:iron_plate:1,100)
RandomBlock(7,5,-2,quark:iron_plate:1,70,STAINED_CLAY:15,30,STAINED_CLAY:7,30,quark:iron_plate:1,100)
RandomBlock(7,5,-1,quark:iron_plate:1,70,STAINED_CLAY:15,30,STAINED_CLAY:7,30,quark:iron_plate:1,100)
Block(7,5,0,quark:limestone:0)
Block(7,5,1,quark:limestone:0)
Block(7,5,2,quark:limestone:0)
RandomBlock(7,5,3,quark:iron_plate:1,70,STAINED_CLAY:15,30,STAINED_CLAY:7,30,quark:iron_plate:1,100)
RandomBlock(7,6,-7,quark:iron_plate:1,70,STAINED_CLAY:15,30,STAINED_CLAY:7,30,quark:iron_plate:1,100)
Block(7,6,-6,quark:limestone:0)
Block(7,6,-5,quark:limestone:0)
RandomBlock(7,6,-4,quark:iron_plate:1,70,STAINED_CLAY:15,30,STAINED_CLAY:7,30,quark:iron_plate:1,100)
Block(7,6,-3,AIR:0)
Block(7,6,-2,AIR:0)
RandomBlock(7,6,-1,quark:iron_plate:1,70,STAINED_CLAY:15,30,STAINED_CLAY:7,30,quark:iron_plate:1,100)
Block(7,6,0,quark:limestone:0)
Block(7,6,1,quark:limestone:0)
Block(7,6,2,quark:limestone:0)
RandomBlock(7,6,3,quark:iron_plate:1,70,STAINED_CLAY:15,30,STAINED_CLAY:7,30,quark:iron_plate:1,100)
RandomBlock(7,7,-7,quark:iron_plate:1,70,STAINED_CLAY:15,30,STAINED_CLAY:7,30,quark:iron_plate:1,100)
Block(7,7,-6,quark:limestone:0)
Block(7,7,-5,quark:limestone:0)
RandomBlock(7,7,-4,quark:iron_plate:1,70,STAINED_CLAY:15,30,STAINED_CLAY:7,30,quark:iron_plate:1,100)
Block(7,7,-3,AIR:0)
Block(7,7,-2,AIR:0)
RandomBlock(7,7,-1,quark:iron_plate:1,70,STAINED_CLAY:15,30,STAINED_CLAY:7,30,quark:iron_plate:1,100)
Block(7,7,0,quark:limestone:0)
Block(7,7,1,quark:limestone:0)
Block(7,7,2,quark:limestone:0)
RandomBlock(7,7,3,quark:iron_plate:1,70,STAINED_CLAY:15,30,STAINED_CLAY:7,30,quark:iron_plate:1,100)
RandomBlock(7,8,-7,quark:iron_plate:1,70,STAINED_CLAY:15,30,STAINED_CLAY:7,30,quark:iron_plate:1,100)
Block(7,8,-6,quark:limestone:0)
Block(7,8,-5,quark:limestone:0)
RandomBlock(7,8,-4,quark:iron_plate:1,70,STAINED_CLAY:15,30,STAINED_CLAY:7,30,quark:iron_plate:1,100)
RandomBlock(7,8,-3,quark:iron_plate:1,70,STAINED_CLAY:15,30,STAINED_CLAY:7,30,quark:iron_plate:1,100)
RandomBlock(7,8,-2,quark:iron_plate:1,70,STAINED_CLAY:15,30,STAINED_CLAY:7,30,quark:iron_plate:1,100)
RandomBlock(7,8,-1,quark:iron_plate:1,70,STAINED_CLAY:15,30,STAINED_CLAY:7,30,quark:iron_plate:1,100)
Block(7,8,0,quark:limestone:0)
Block(7,8,1,quark:limestone:0)
Block(7,8,2,quark:limestone:0)
RandomBlock(7,8,3,quark:iron_plate:1,70,STAINED_CLAY:15,30,STAINED_CLAY:7,30,quark:iron_plate:1,100)
RandomBlock(7,9,-7,quark:iron_plate:1,70,STAINED_CLAY:15,30,STAINED_CLAY:7,30,quark:iron_plate:1,100)
Block(7,9,-6,quark:limestone:0)
Block(7,9,-5,quark:limestone:0)
Block(7,9,-4,quark:limestone:0)
Block(7,9,-3,quark:limestone:0)
Block(7,9,-2,quark:limestone:0)
Block(7,9,-1,quark:limestone:0)
Block(7,9,0,quark:limestone:0)
Block(7,9,1,quark:limestone:0)
Block(7,9,2,quark:limestone:0)
RandomBlock(7,9,3,quark:iron_plate:1,70,STAINED_CLAY:15,30,STAINED_CLAY:7,30,quark:iron_plate:1,100)
RandomBlock(7,10,-7,quark:iron_plate:1,70,STAINED_CLAY:15,30,STAINED_CLAY:7,30,quark:iron_plate:1,100)
Block(7,10,-6,quark:limestone:0)
Block(7,10,-5,quark:limestone:0)
Block(7,10,-4,quark:limestone:0)
Block(7,10,-3,quark:limestone:0)
Block(7,10,-2,quark:limestone:0)
Block(7,10,-1,quark:limestone:0)
Block(7,10,0,quark:limestone:0)
Block(7,10,1,quark:limestone:0)
Block(7,10,2,quark:limestone:0)
RandomBlock(7,10,3,quark:iron_plate:1,70,STAINED_CLAY:15,30,STAINED_CLAY:7,30,quark:iron_plate:1,100)
RandomBlock(7,11,-7,quark:iron_plate:1,70,STAINED_CLAY:15,30,STAINED_CLAY:7,30,quark:iron_plate:1,100)
Block(7,11,-6,quark:limestone:0)
Block(7,11,-5,quark:limestone:0)
Block(7,11,-4,quark:limestone:0)
Block(7,11,-3,quark:limestone:0)
Block(7,11,-2,quark:limestone:0)
Block(7,11,-1,quark:limestone:0)
Block(7,11,0,quark:limestone:0)
Block(7,11,1,quark:limestone:0)
Block(7,11,2,quark:limestone:0)
RandomBlock(7,11,3,quark:iron_plate:1,70,STAINED_CLAY:15,30,STAINED_CLAY:7,30,quark:iron_plate:1,100)
RandomBlock(7,12,-7,quark:iron_plate:1,70,STAINED_CLAY:15,30,STAINED_CLAY:7,30,quark:iron_plate:1,100)
RandomBlock(7,12,-6,quark:iron_plate:1,70,STAINED_CLAY:15,30,STAINED_CLAY:7,30,quark:iron_plate:1,100)
RandomBlock(7,12,-5,quark:iron_plate:1,70,STAINED_CLAY:15,30,STAINED_CLAY:7,30,quark:iron_plate:1,100)
RandomBlock(7,12,-4,quark:iron_plate:1,70,STAINED_CLAY:15,30,STAINED_CLAY:7,30,quark:iron_plate:1,100)
RandomBlock(7,12,-3,quark:iron_plate:1,70,STAINED_CLAY:15,30,STAINED_CLAY:7,30,quark:iron_plate:1,100)
RandomBlock(7,12,-2,quark:iron_plate:1,70,STAINED_CLAY:15,30,STAINED_CLAY:7,30,quark:iron_plate:1,100)
RandomBlock(7,12,-1,quark:iron_plate:1,70,STAINED_CLAY:15,30,STAINED_CLAY:7,30,quark:iron_plate:1,100)
RandomBlock(7,12,0,quark:iron_plate:1,70,STAINED_CLAY:15,30,STAINED_CLAY:7,30,quark:iron_plate:1,100)
RandomBlock(7,12,1,quark:iron_plate:1,70,STAINED_CLAY:15,30,STAINED_CLAY:7,30,quark:iron_plate:1,100)
RandomBlock(7,12,2,quark:iron_plate:1,70,STAINED_CLAY:15,30,STAINED_CLAY:7,30,quark:iron_plate:1,100)
RandomBlock(7,12,3,quark:iron_plate:1,70,STAINED_CLAY:15,30,STAINED_CLAY:7,30,quark:iron_plate:1,100)
Block(7,13,-7,IRON_FENCE:0)
Block(7,13,-6,IRON_FENCE:0)
Block(7,13,-5,IRON_FENCE:0)
Block(7,13,-4,IRON_FENCE:0)
Block(7,13,-3,IRON_FENCE:0)
Block(7,13,-2,IRON_FENCE:0)
Block(7,13,-1,IRON_FENCE:0)
Block(7,13,0,IRON_FENCE:0)
Block(7,13,1,IRON_FENCE:0)
Block(7,13,2,IRON_FENCE:0)
Block(7,13,3,IRON_FENCE:0)

#######################################################################
# +-----------------------------------------------------------------+ #
# |                             Branches                            | #
# +-----------------------------------------------------------------+ #
#######################################################################

Branch(16,0,0,true,brutal_pipebig_01C3R0,NORTH,100.0,0)

#######################################################################
# +-----------------------------------------------------------------+ #
# |                             Entities                            | #
# +-----------------------------------------------------------------+ #
#######################################################################


#######################################################################
# +-----------------------------------------------------------------+ #
# |                            Particles                            | #
# +-----------------------------------------------------------------+ #
#######################################################################


#######################################################################
# +-----------------------------------------------------------------+ #
# |                             Spawners                            | #
# +-----------------------------------------------------------------+ #
#######################################################################


#######################################################################
# +-----------------------------------------------------------------+ #
# |                             ModData                             | #
# +-----------------------------------------------------------------+ #
#######################################################################

