
#######################################################################
# +-----------------------------------------------------------------+ #
# |                            BO4 object                           | #
# +-----------------------------------------------------------------+ #
#######################################################################

Author: NLBlackEagle

Description: No description given

SettingsMode: WriteDisable


#######################################################################
# +-----------------------------------------------------------------+ #
# |                          Main settings                          | #
# +-----------------------------------------------------------------+ #
#######################################################################

FixedRotation: 

Frequency: 0

SpawnHeight: highestSolidBlock

UseCenterForHighestBlock: true

##############################
# Height Limits for the BO4. #
##############################

MinHeight: 0

MaxHeight: 255

InheritBO3: 

InheritBO3Rotation: NORTH

OverrideChildSettings: true

OverrideParentHeight: true

CanOverride: true

BranchFrequency: 0

BranchFrequencyGroup: 

MustBeBelowOther: false

MustBeInside: 

CannotBeInside: 

ReplacesBO3: 

MustBeInsideWorldBorders: true
CanSpawnOnWater: false

SpawnOnWaterOnly: false

SpawnUnderWater: false

SpawnAtWaterLevel: false

HeightOffset: 0

RemoveAir: false

ReplaceAbove: 

ReplaceBelow: COBBLESTONE

ReplaceWithBiomeBlocks: false

ReplaceWithSurfaceBlock: GRASS

ReplaceWithGroundBlock: DIRT

ReplaceWithStoneBlock: STONE

SmoothRadius: 0

SmoothHeightOffset: 0

SmoothStartTop: false

SmoothStartWood: false

SmoothingSurfaceBlock: 

SmoothingGroundBlock: 

BO3Group: 

IsSpawnPoint: false

DoReplaceBlocks: true


#######################################################################
# +-----------------------------------------------------------------+ #
# |                              Blocks                             | #
# +-----------------------------------------------------------------+ #
#######################################################################

Block(-4,5,-5,quark:stone_limestone_slab)
Block(-4,5,-4,DAYLIGHT_DETECTOR_INVERTED:11)
Block(-4,5,-3,DAYLIGHT_DETECTOR_INVERTED:11)
Block(-4,5,-2,DAYLIGHT_DETECTOR_INVERTED:11)
Block(-4,5,-1,DAYLIGHT_DETECTOR_INVERTED:11)
Block(-4,5,0,DAYLIGHT_DETECTOR_INVERTED:11)
Block(-4,5,1,DAYLIGHT_DETECTOR_INVERTED:11)
Block(-4,5,2,DAYLIGHT_DETECTOR_INVERTED:11)
Block(-4,5,3,DAYLIGHT_DETECTOR_INVERTED:11)
Block(-4,5,4,DAYLIGHT_DETECTOR_INVERTED:11)
Block(-4,5,5,quark:iron_plate_slab)
Block(-3,1,-5,quark:iron_plate:1)
Block(-3,1,5,quark:iron_plate:1)
Block(-3,2,-5,minecraft:iron_bars:0)
Block(-3,2,5,minecraft:iron_bars:0)
Block(-3,3,-5,minecraft:iron_bars:0)
Block(-3,3,5,minecraft:iron_bars:0)
Block(-3,4,-5,minecraft:iron_bars:0)
Block(-3,4,-4,minecraft:iron_bars:0)
Block(-3,4,-3,minecraft:iron_bars:0)
Block(-3,4,-2,minecraft:iron_bars:0)
Block(-3,4,-1,minecraft:iron_bars:0)
Block(-3,4,0,minecraft:iron_bars:0)
Block(-3,4,1,minecraft:iron_bars:0)
Block(-3,4,2,minecraft:iron_bars:0)
Block(-3,4,3,minecraft:iron_bars:0)
Block(-3,4,4,minecraft:iron_bars:0)
Block(-3,4,5,minecraft:iron_bars:0)
Block(-3,5,-5,quark:iron_plate_slab)
Block(-3,5,-4,DAYLIGHT_DETECTOR_INVERTED:11)
Block(-3,5,-3,DAYLIGHT_DETECTOR_INVERTED:11)
Block(-3,5,-2,DAYLIGHT_DETECTOR_INVERTED:11)
Block(-3,5,-1,DAYLIGHT_DETECTOR_INVERTED:11)
Block(-3,5,0,DAYLIGHT_DETECTOR_INVERTED:11)
Block(-3,5,1,DAYLIGHT_DETECTOR_INVERTED:11)
Block(-3,5,2,DAYLIGHT_DETECTOR_INVERTED:11)
Block(-3,5,3,DAYLIGHT_DETECTOR_INVERTED:11)
Block(-3,5,4,DAYLIGHT_DETECTOR_INVERTED:11)
Block(-3,5,5,quark:stone_limestone_slab)
Block(-2,4,-5,quark:iron_plate_stairs:4)
Block(-2,4,5,quark:stone_limestone_stairs:4)
Block(-2,5,-5,quark:iron_plate_slab)
Block(-2,5,-4,DAYLIGHT_DETECTOR_INVERTED:11)
Block(-2,5,-3,DAYLIGHT_DETECTOR_INVERTED:11)
Block(-2,5,-2,DAYLIGHT_DETECTOR_INVERTED:11)
Block(-2,5,-1,DAYLIGHT_DETECTOR_INVERTED:11)
Block(-2,5,0,DAYLIGHT_DETECTOR_INVERTED:11)
Block(-2,5,1,DAYLIGHT_DETECTOR_INVERTED:11)
Block(-2,5,2,DAYLIGHT_DETECTOR_INVERTED:11)
Block(-2,5,3,DAYLIGHT_DETECTOR_INVERTED:11)
Block(-2,5,4,DAYLIGHT_DETECTOR_INVERTED:11)
Block(-2,5,5,quark:stone_limestone_slab)
Block(-1,4,-5,quark:iron_plate_stairs:1)
Block(-1,4,-4,DAYLIGHT_DETECTOR_INVERTED:11)
Block(-1,4,-3,DAYLIGHT_DETECTOR_INVERTED:11)
Block(-1,4,-2,DAYLIGHT_DETECTOR_INVERTED:11)
Block(-1,4,-1,DAYLIGHT_DETECTOR_INVERTED:11)
Block(-1,4,0,DAYLIGHT_DETECTOR_INVERTED:11)
Block(-1,4,1,DAYLIGHT_DETECTOR_INVERTED:11)
Block(-1,4,2,DAYLIGHT_DETECTOR_INVERTED:11)
Block(-1,4,3,DAYLIGHT_DETECTOR_INVERTED:11)
Block(-1,4,4,DAYLIGHT_DETECTOR_INVERTED:11)
Block(-1,4,5,quark:stone_limestone_stairs:1)
Block(0,1,-5,quark:iron_plate:1)
Block(0,1,5,quark:iron_plate:1)
Block(0,2,-5,minecraft:iron_bars:0)
Block(0,2,5,minecraft:iron_bars:0)
Block(0,3,-5,minecraft:iron_bars:0)
Block(0,3,-4,minecraft:iron_bars:0)
Block(0,3,-3,minecraft:iron_bars:0)
Block(0,3,-2,minecraft:iron_bars:0)
Block(0,3,-1,minecraft:iron_bars:0)
Block(0,3,0,minecraft:iron_bars:0)
Block(0,3,1,minecraft:iron_bars:0)
Block(0,3,2,minecraft:iron_bars:0)
Block(0,3,3,minecraft:iron_bars:0)
Block(0,3,4,minecraft:iron_bars:0)
Block(0,3,5,minecraft:iron_bars:0)
Block(0,4,-5,quark:stone_limestone_slab)
Block(0,4,-4,DAYLIGHT_DETECTOR_INVERTED:11)
Block(0,4,-3,DAYLIGHT_DETECTOR_INVERTED:11)
Block(0,4,-2,DAYLIGHT_DETECTOR_INVERTED:11)
Block(0,4,-1,DAYLIGHT_DETECTOR_INVERTED:11)
Block(0,4,0,DAYLIGHT_DETECTOR_INVERTED:11)
Block(0,4,1,DAYLIGHT_DETECTOR_INVERTED:11)
Block(0,4,2,DAYLIGHT_DETECTOR_INVERTED:11)
Block(0,4,3,DAYLIGHT_DETECTOR_INVERTED:11)
Block(0,4,4,DAYLIGHT_DETECTOR_INVERTED:11)
Block(0,4,5,quark:stone_limestone_slab)
Block(1,3,-5,quark:stone_limestone_stairs:4)
Block(1,3,5,quark:iron_plate_stairs:4)
Block(1,4,-5,quark:stone_limestone_slab)
Block(1,4,-4,DAYLIGHT_DETECTOR_INVERTED:11)
Block(1,4,-3,DAYLIGHT_DETECTOR_INVERTED:11)
Block(1,4,-2,DAYLIGHT_DETECTOR_INVERTED:11)
Block(1,4,-1,DAYLIGHT_DETECTOR_INVERTED:11)
Block(1,4,0,DAYLIGHT_DETECTOR_INVERTED:11)
Block(1,4,1,DAYLIGHT_DETECTOR_INVERTED:11)
Block(1,4,2,DAYLIGHT_DETECTOR_INVERTED:11)
Block(1,4,3,DAYLIGHT_DETECTOR_INVERTED:11)
Block(1,4,4,DAYLIGHT_DETECTOR_INVERTED:11)
Block(1,4,5,quark:iron_plate_slab)
Block(2,3,-5,quark:stone_limestone_stairs:1)
Block(2,3,-4,DAYLIGHT_DETECTOR_INVERTED:11)
Block(2,3,-3,DAYLIGHT_DETECTOR_INVERTED:11)
Block(2,3,-2,DAYLIGHT_DETECTOR_INVERTED:11)
Block(2,3,-1,DAYLIGHT_DETECTOR_INVERTED:11)
Block(2,3,0,DAYLIGHT_DETECTOR_INVERTED:11)
Block(2,3,1,DAYLIGHT_DETECTOR_INVERTED:11)
Block(2,3,2,DAYLIGHT_DETECTOR_INVERTED:11)
Block(2,3,3,DAYLIGHT_DETECTOR_INVERTED:11)
Block(2,3,4,DAYLIGHT_DETECTOR_INVERTED:11)
Block(2,3,5,quark:iron_plate_stairs:1)
Block(3,1,-5,quark:iron_plate:1)
Block(3,1,5,quark:iron_plate:1)
Block(3,2,-5,minecraft:iron_bars:0)
Block(3,2,-4,minecraft:iron_bars:0)
Block(3,2,-3,minecraft:iron_bars:0)
Block(3,2,-2,minecraft:iron_bars:0)
Block(3,2,-1,minecraft:iron_bars:0)
Block(3,2,0,minecraft:iron_bars:0)
Block(3,2,1,minecraft:iron_bars:0)
Block(3,2,2,minecraft:iron_bars:0)
Block(3,2,3,minecraft:iron_bars:0)
Block(3,2,4,minecraft:iron_bars:0)
Block(3,2,5,minecraft:iron_bars:0)
Block(3,3,-5,quark:iron_plate_slab)
Block(3,3,-4,DAYLIGHT_DETECTOR_INVERTED:11)
Block(3,3,-3,DAYLIGHT_DETECTOR_INVERTED:11)
Block(3,3,-2,DAYLIGHT_DETECTOR_INVERTED:11)
Block(3,3,-1,DAYLIGHT_DETECTOR_INVERTED:11)
Block(3,3,0,DAYLIGHT_DETECTOR_INVERTED:11)
Block(3,3,1,DAYLIGHT_DETECTOR_INVERTED:11)
Block(3,3,2,DAYLIGHT_DETECTOR_INVERTED:11)
Block(3,3,3,DAYLIGHT_DETECTOR_INVERTED:11)
Block(3,3,4,DAYLIGHT_DETECTOR_INVERTED:11)
Block(3,3,5,quark:stone_limestone_slab)
Block(4,3,-5,quark:iron_plate_slab)
Block(4,3,-4,DAYLIGHT_DETECTOR_INVERTED:11)
Block(4,3,-3,DAYLIGHT_DETECTOR_INVERTED:11)
Block(4,3,-2,DAYLIGHT_DETECTOR_INVERTED:11)
Block(4,3,-1,DAYLIGHT_DETECTOR_INVERTED:11)
Block(4,3,0,DAYLIGHT_DETECTOR_INVERTED:11)
Block(4,3,1,DAYLIGHT_DETECTOR_INVERTED:11)
Block(4,3,2,DAYLIGHT_DETECTOR_INVERTED:11)
Block(4,3,3,DAYLIGHT_DETECTOR_INVERTED:11)
Block(4,3,4,DAYLIGHT_DETECTOR_INVERTED:11)
Block(4,3,5,quark:stone_limestone_slab)

Block(0,0,-5,quark:iron_plate:1)
Block(0,0,5,quark:iron_plate:1)
Block(3,0,-5,quark:iron_plate:1)
Block(3,0,5,quark:iron_plate:1)
Block(-3,0,-5,quark:iron_plate:1)
Block(-3,0,5,quark:iron_plate:1)

Block(0,-1,-5,COBBLESTONE)
Block(0,-1,5,COBBLESTONE)
Block(3,-1,-5,COBBLESTONE)
Block(3,-1,5,COBBLESTONE)
Block(-3,-1,-5,COBBLESTONE)
Block(-3,-1,5,COBBLESTONE)

#######################################################################
# +-----------------------------------------------------------------+ #
# |                             Branches                            | #
# +-----------------------------------------------------------------+ #
#######################################################################

Branch(0,-34,0,true,AdvancedUndergroundHouse,NORTH,25.0,0)

#######################################################################
# +-----------------------------------------------------------------+ #
# |                             Entities                            | #
# +-----------------------------------------------------------------+ #
#######################################################################


#######################################################################
# +-----------------------------------------------------------------+ #
# |                            Particles                            | #
# +-----------------------------------------------------------------+ #
#######################################################################


#######################################################################
# +-----------------------------------------------------------------+ #
# |                             Spawners                            | #
# +-----------------------------------------------------------------+ #
#######################################################################


#######################################################################
# +-----------------------------------------------------------------+ #
# |                             ModData                             | #
# +-----------------------------------------------------------------+ #
#######################################################################

