
#######################################################################
# +-----------------------------------------------------------------+ #
# |                            BO4 object                           | #
# +-----------------------------------------------------------------+ #
#######################################################################

Author: NLBlackEagle

Description: No description given

SettingsMode: WriteWithoutComments


#######################################################################
# +-----------------------------------------------------------------+ #
# |                          Main settings                          | #
# +-----------------------------------------------------------------+ #
#######################################################################

FixedRotation: NORTH

Frequency: 0

SpawnHeight: highestSolidBlock

UseCenterForHighestBlock: true

##############################
# Height Limits for the BO4. #
##############################

MinHeight: 0

MaxHeight: 255

InheritBO3: 

InheritBO3Rotation: NORTH

OverrideChildSettings: true

OverrideParentHeight: false

CanOverride: true

BranchFrequency: 0

BranchFrequencyGroup: 

MustBeBelowOther: false

MustBeInside: 

CannotBeInside: 

ReplacesBO3: 

MustBeInsideWorldBorders: true

CanSpawnOnWater: false

SpawnOnWaterOnly: false

SpawnUnderWater: false

SpawnAtWaterLevel: false

HeightOffset: 0

RemoveAir: false

ReplaceAbove: 

ReplaceBelow: 

ReplaceWithBiomeBlocks: false

ReplaceWithSurfaceBlock: GRASS

ReplaceWithGroundBlock: DIRT

ReplaceWithStoneBlock: STONE

SmoothRadius: 0

SmoothHeightOffset: 0

SmoothStartTop: false

SmoothStartWood: false

SmoothingSurfaceBlock: 

SmoothingGroundBlock: 

BO3Group: 

IsSpawnPoint: false

DoReplaceBlocks: true


#######################################################################
# +-----------------------------------------------------------------+ #
# |                              Blocks                             | #
# +-----------------------------------------------------------------+ #
#######################################################################

Block(-6,19,-7,IRON_TRAPDOOR:10)
Block(-6,19,-6,VINE:8)
Block(-6,19,-5,IRON_TRAPDOOR:10)
Block(-6,20,-6,VINE:8)
Block(-6,21,-6,VINE:8)
Block(-6,22,-6,VINE:8)
Block(-6,23,-6,VINE:8)
Block(-6,24,-6,VINE:8)
Block(-5,19,-7,STEP:8)
Block(-5,19,-6,STEP:8)
Block(-5,19,-5,STEP:8)
Block(-5,19,-4,IRON_TRAPDOOR:10)
Block(-5,19,-2,IRON_TRAPDOOR:10)
Block(-5,20,-7,COBBLE_WALL:0)
Block(-5,20,-5,COBBLE_WALL:0)
Block(-5,20,-3,VINE:8)
Block(-5,20,-2,VINE:8)
Block(-5,21,-7,quark:limestone:0)
Block(-5,21,-6,quark:limestone:0)
Block(-5,21,-5,CONCRETE:8)
Block(-5,21,-3,VINE:8)
Block(-5,21,-2,VINE:8)
Block(-5,22,-7,quark:limestone:0)
Block(-5,22,-6,CONCRETE:8)
Block(-5,22,-5,CONCRETE:8)
Block(-5,22,-2,VINE:8)
Block(-5,23,-7,CONCRETE:8)
Block(-5,23,-6,QUARTZ_BLOCK:0)
Block(-5,23,-5,CONCRETE:8)
Block(-5,23,-4,VINE:4)
Block(-5,23,-2,VINE:8)
Block(-5,24,-7,CONCRETE:8)
Block(-5,24,-6,QUARTZ_BLOCK:0)
Block(-5,24,-5,CONCRETE:8)
Block(-5,24,-4,VINE:4)
Block(-5,24,-2,VINE:8)
Block(-5,25,-7,quark:limestone:0)
Block(-5,25,-6,quark:limestone:0)
Block(-5,25,-5,CONCRETE:8)
Block(-4,19,-4,STEP:8)
Block(-4,19,-3,STEP:8)
Block(-4,19,-2,STEP:8)
Block(-4,19,-1,IRON_TRAPDOOR:10)
Block(-4,19,1,IRON_TRAPDOOR:10)
Block(-4,20,-7,STEP:8)
Block(-4,20,-6,STEP:8)
Block(-4,20,-5,STEP:8)
Block(-4,20,-4,COBBLE_WALL:0)
Block(-4,20,-2,COBBLE_WALL:0)
Block(-4,20,1,VINE:8)
Block(-4,21,-7,IRON_FENCE:0)
Block(-4,21,-6,VINE:2)
Block(-4,21,-5,IRON_FENCE:0)
Block(-4,21,-4,quark:limestone:0)
Block(-4,21,-3,CONCRETE:8)
Block(-4,21,-2,quark:limestone:0)
Block(-4,21,0,VINE:8)
Block(-4,21,1,VINE:8)
Block(-4,22,-7,IRON_FENCE:0)
Block(-4,22,-6,VINE:2)
Block(-4,22,-5,IRON_FENCE:0)
Block(-4,22,-4,quark:limestone:0)
Block(-4,22,-3,quark:limestone:0)
Block(-4,22,-2,quark:limestone:0)
Block(-4,23,-7,IRON_FENCE:0)
Block(-4,23,-6,VINE:2)
Block(-4,23,-5,IRON_FENCE:0)
Block(-4,23,-4,quark:limestone:0)
Block(-4,23,-3,CONCRETE:8)
Block(-4,23,-2,CONCRETE:8)
Block(-4,24,-7,IRON_FENCE:0)
Block(-4,24,-6,VINE:2)
Block(-4,24,-5,IRON_FENCE:0)
Block(-4,24,-4,quark:limestone:0)
Block(-4,24,-3,CONCRETE:8)
Block(-4,24,-2,QUARTZ_BLOCK:0)
Block(-4,25,-7,IRON_FENCE:0)
Block(-4,25,-6,VINE:2)
Block(-4,25,-5,IRON_FENCE:0)
Block(-4,25,-4,CONCRETE:8)
Block(-4,25,-3,CONCRETE:8)
Block(-4,25,-2,quark:limestone:0)
Block(-3,19,-1,STEP:8)
Block(-3,19,0,STEP:8)
Block(-3,19,1,STEP:8)
Block(-3,19,2,IRON_TRAPDOOR:10)
Block(-3,19,4,IRON_TRAPDOOR:10)
Block(-3,20,-4,STEP:8)
Block(-3,20,-3,STEP:8)
Block(-3,20,-2,STEP:8)
Block(-3,20,-1,COBBLE_WALL:0)
Block(-3,20,1,COBBLE_WALL:0)
Block(-3,20,3,VINE:8)
Block(-3,21,-4,IRON_FENCE:0)
Block(-3,21,-3,VINE:2)
Block(-3,21,-2,IRON_FENCE:0)
Block(-3,21,-1,CONCRETE:8)
Block(-3,21,0,QUARTZ_BLOCK:0)
Block(-3,21,1,CONCRETE:8)
Block(-3,21,3,VINE:8)
Block(-3,22,-4,IRON_FENCE:0)
Block(-3,22,-3,VINE:2)
Block(-3,22,-2,IRON_FENCE:0)
Block(-3,22,-1,quark:limestone:0)
Block(-3,22,0,quark:limestone:0)
Block(-3,22,1,CONCRETE:8)
Block(-3,22,3,VINE:8)
Block(-3,22,4,VINE:8)
Block(-3,23,-4,IRON_FENCE:0)
Block(-3,23,-3,VINE:2)
Block(-3,23,-2,IRON_FENCE:0)
Block(-3,23,-1,quark:limestone:0)
Block(-3,23,0,quark:limestone:0)
Block(-3,23,1,quark:limestone:0)
Block(-3,23,3,VINE:8)
Block(-3,24,-4,IRON_FENCE:0)
Block(-3,24,-2,IRON_FENCE:0)
Block(-3,24,-1,CONCRETE:8)
Block(-3,24,0,quark:limestone:0)
Block(-3,24,1,quark:limestone:0)
Block(-3,24,2,VINE:4)
Block(-3,25,-4,IRON_FENCE:0)
Block(-3,25,-2,IRON_FENCE:0)
Block(-3,25,-1,quark:limestone:0)
Block(-3,25,0,CONCRETE:8)
Block(-3,25,1,CONCRETE:8)
Block(-3,25,2,VINE:4)
Block(-2,19,2,STEP:8)
Block(-2,19,3,STEP:8)
Block(-2,19,4,STEP:8)
Block(-2,19,5,IRON_TRAPDOOR:10)
Block(-2,19,7,IRON_TRAPDOOR:10)
Block(-2,20,-2,STEP:8)
Block(-2,20,-1,STEP:8)
Block(-2,20,0,STEP:8)
Block(-2,20,1,STEP:8)
Block(-2,20,2,COBBLE_WALL:0)
Block(-2,20,4,COBBLE_WALL:0)
Block(-2,20,6,VINE:8)
Block(-2,21,-1,IRON_FENCE:0)
Block(-2,21,0,COBBLE_WALL:0)
Block(-2,21,1,IRON_FENCE:0)
Block(-2,21,2,quark:limestone:0)
Block(-2,21,3,quark:limestone:0)
Block(-2,21,4,CONCRETE:8)
Block(-2,21,6,VINE:8)
Block(-2,22,-1,IRON_FENCE:0)
Block(-2,22,1,IRON_FENCE:0)
Block(-2,22,2,CONCRETE:8)
Block(-2,22,3,CONCRETE:8)
Block(-2,22,4,QUARTZ_BLOCK:0)
Block(-2,22,6,VINE:8)
Block(-2,23,-1,IRON_FENCE:0)
Block(-2,23,1,IRON_FENCE:0)
Block(-2,23,2,quark:limestone:0)
Block(-2,23,3,QUARTZ_BLOCK:0)
Block(-2,23,4,quark:limestone:0)
Block(-2,23,6,VINE:8)
Block(-2,23,7,VINE:8)
Block(-2,24,-1,IRON_FENCE:0)
Block(-2,24,0,COBBLE_WALL:0)
Block(-2,24,1,IRON_FENCE:0)
Block(-2,24,2,quark:limestone:0)
Block(-2,24,3,quark:limestone:0)
Block(-2,24,4,CONCRETE:8)
Block(-2,24,7,VINE:8)
Block(-2,25,-1,IRON_FENCE:0)
Block(-2,25,0,VINE:2)
Block(-2,25,1,IRON_FENCE:0)
Block(-2,25,2,CONCRETE:8)
Block(-2,25,3,CONCRETE:8)
Block(-2,25,4,CONCRETE:8)
Block(-2,25,7,VINE:8)
Block(-1,9,0,VINE:8)
Block(-1,10,0,VINE:8)
Block(-1,11,0,VINE:8)
Block(-1,12,0,VINE:8)
Block(-1,13,0,VINE:8)
Block(-1,14,0,VINE:8)
Block(-1,15,0,VINE:8)
Block(-1,16,0,VINE:8)
Block(-1,18,0,VINE:8)
Block(-1,19,0,VINE:8)
Block(-1,19,5,STEP:8)
Block(-1,19,6,STEP:8)
Block(-1,19,7,STEP:8)
Block(-1,20,-2,STEP:8)
Block(-1,20,-1,STEP:8)
Block(-1,20,2,STEP:8)
Block(-1,20,3,STEP:8)
Block(-1,20,4,STEP:8)
Block(-1,20,5,COBBLE_WALL:0)
Block(-1,20,7,COBBLE_WALL:0)
Block(-1,21,-2,IRON_FENCE:0)
Block(-1,21,0,COBBLE_WALL:0)
Block(-1,21,2,IRON_FENCE:0)
Block(-1,21,4,IRON_FENCE:0)
Block(-1,21,5,quark:limestone:0)
Block(-1,21,6,CONCRETE:8)
Block(-1,21,7,quark:limestone:0)
Block(-1,22,2,IRON_FENCE:0)
Block(-1,22,4,IRON_FENCE:0)
Block(-1,22,5,quark:limestone:0)
Block(-1,22,6,QUARTZ_BLOCK:0)
Block(-1,22,7,quark:limestone:0)
Block(-1,23,2,IRON_FENCE:0)
Block(-1,23,4,IRON_FENCE:0)
Block(-1,23,5,CONCRETE:8)
Block(-1,23,6,QUARTZ_BLOCK:0)
Block(-1,23,7,quark:limestone:0)
Block(-1,24,0,COBBLE_WALL:0)
Block(-1,24,2,IRON_FENCE:0)
Block(-1,24,4,IRON_FENCE:0)
Block(-1,24,5,quark:limestone:0)
Block(-1,24,6,quark:limestone:0)
Block(-1,24,7,quark:limestone:0)
Block(-1,25,2,IRON_FENCE:0)
Block(-1,25,4,IRON_FENCE:0)
Block(-1,25,5,quark:limestone:0)
Block(-1,25,6,quark:limestone:0)
Block(-1,25,7,CONCRETE:8)
Block(0,0,0,STONE:5)
Block(0,1,0,STONE:6)
Block(0,2,-1,quark:iron_ladder:2)
Block(0,2,0,STONE:5)
Block(0,3,-1,quark:iron_ladder:2)
Block(0,3,0,STONE:6)
Block(0,4,-1,quark:iron_ladder:2)
Block(0,4,0,STONE:6)
Block(0,5,-1,quark:iron_ladder:2)
Block(0,5,0,STONE:6)
Block(0,6,-1,quark:iron_ladder:2)
Block(0,6,0,STONE:6)
Block(0,7,-1,quark:iron_ladder:2)
Block(0,7,0,STONE:6)
Block(0,8,-1,quark:iron_ladder:2)
Block(0,8,0,STONE:5)
Block(0,8,1,VINE:4)
Block(0,9,-1,quark:iron_ladder:2)
Block(0,9,0,STONE:5)
Block(0,9,1,VINE:4)
Block(0,10,-1,quark:iron_ladder:2)
Block(0,10,0,STONE:5)
Block(0,10,1,VINE:4)
Block(0,11,-1,quark:iron_ladder:2)
Block(0,11,0,STONE:6)
Block(0,11,1,VINE:4)
Block(0,12,-1,quark:iron_ladder:2)
Block(0,12,0,STONE:5)
Block(0,12,1,VINE:4)
Block(0,13,-1,quark:iron_ladder:2)
Block(0,13,0,STONE:6)
Block(0,13,1,VINE:4)
Block(0,14,-1,quark:iron_ladder:2)
Block(0,14,0,STONE:5)
Block(0,14,1,VINE:4)
Block(0,15,-1,quark:iron_ladder:2)
Block(0,15,0,STONE:6)
Block(0,15,1,VINE:4)
Block(0,16,-1,quark:iron_ladder:2)
Block(0,16,0,STONE:6)
Block(0,17,-1,quark:iron_ladder:2)
Block(0,17,0,STONE:6)
Block(0,17,1,VINE:4)
Block(0,18,-1,quark:iron_ladder:2)
Block(0,18,0,STONE:5)
Block(0,18,1,VINE:4)
Block(0,19,-1,quark:iron_ladder:2)
Block(0,19,0,STONE:5)
Block(0,20,-2,STEP:8)
Block(0,20,-1,quark:iron_ladder:2)
Block(0,20,0,STONE:6)
Block(0,20,1,VINE:4)
Block(0,21,-2,IRON_FENCE:0)
Block(0,21,-1,quark:iron_ladder:2)
Block(0,21,0,STONE:5)
Block(0,21,1,VINE:4)
Block(0,21,6,IRON_FENCE:0)
Block(0,22,-1,quark:iron_ladder:2)
Block(0,22,0,STONE:5)
Block(0,22,1,VINE:4)
Block(0,22,6,IRON_FENCE:0)
Block(0,23,-1,quark:iron_ladder:2)
Block(0,23,0,STONE:5)
Block(0,23,6,IRON_FENCE:0)
Block(0,24,-1,quark:iron_ladder:2)
Block(0,24,0,STONE:6)
Block(0,24,1,VINE:4)
Block(0,24,6,IRON_FENCE:0)
Block(0,25,0,STEP:0)
Block(0,25,6,IRON_FENCE:0)
Block(1,9,0,VINE:2)
Block(1,10,0,VINE:2)
Block(1,11,0,VINE:2)
Block(1,12,0,VINE:2)
Block(1,14,0,VINE:2)
Block(1,15,0,VINE:2)
Block(1,16,0,VINE:2)
Block(1,17,0,VINE:2)
Block(1,18,0,VINE:2)
Block(1,19,0,VINE:2)
Block(1,19,5,STEP:8)
Block(1,19,6,STEP:8)
Block(1,19,7,STEP:8)
Block(1,20,-2,STEP:8)
Block(1,20,-1,STEP:8)
Block(1,20,2,STEP:8)
Block(1,20,3,STEP:8)
Block(1,20,4,STEP:8)
Block(1,20,5,COBBLE_WALL:0)
Block(1,20,7,COBBLE_WALL:0)
Block(1,21,-2,IRON_FENCE:0)
Block(1,21,0,COBBLE_WALL:0)
Block(1,21,2,IRON_FENCE:0)
Block(1,21,4,IRON_FENCE:0)
Block(1,21,5,quark:limestone:0)
Block(1,21,6,CONCRETE:8)
Block(1,21,7,CONCRETE:8)
Block(1,22,0,VINE:2)
Block(1,22,2,IRON_FENCE:0)
Block(1,22,4,IRON_FENCE:0)
Block(1,22,5,QUARTZ_BLOCK:0)
Block(1,22,6,QUARTZ_BLOCK:0)
Block(1,22,7,quark:limestone:0)
Block(1,23,2,IRON_FENCE:0)
Block(1,23,4,IRON_FENCE:0)
Block(1,23,5,quark:limestone:0)
Block(1,23,6,QUARTZ_BLOCK:0)
Block(1,23,7,quark:limestone:0)
Block(1,24,0,COBBLE_WALL:0)
Block(1,24,2,IRON_FENCE:0)
Block(1,24,4,IRON_FENCE:0)
Block(1,24,5,quark:limestone:0)
Block(1,24,6,QUARTZ_BLOCK:0)
Block(1,24,7,CONCRETE:8)
Block(1,25,2,IRON_FENCE:0)
Block(1,25,4,IRON_FENCE:0)
Block(1,25,5,CONCRETE:8)
Block(1,25,6,CONCRETE:8)
Block(1,25,7,CONCRETE:8)
Block(2,19,2,STEP:8)
Block(2,19,3,STEP:8)
Block(2,19,4,STEP:8)
Block(2,19,5,IRON_TRAPDOOR:11)
Block(2,19,7,IRON_TRAPDOOR:11)
Block(2,20,-2,STEP:8)
Block(2,20,-1,STEP:8)
Block(2,20,0,STEP:8)
Block(2,20,1,STEP:8)
Block(2,20,2,COBBLE_WALL:0)
Block(2,20,4,COBBLE_WALL:0)
Block(2,20,5,VINE:4)
Block(2,21,-1,IRON_FENCE:0)
Block(2,21,0,COBBLE_WALL:0)
Block(2,21,1,IRON_FENCE:0)
Block(2,21,2,quark:limestone:0)
Block(2,21,3,quark:limestone:0)
Block(2,21,4,CONCRETE:8)
Block(2,21,5,VINE:6)
Block(2,22,-1,IRON_FENCE:0)
Block(2,22,1,IRON_FENCE:0)
Block(2,22,2,quark:limestone:0)
Block(2,22,3,CONCRETE:8)
Block(2,22,4,QUARTZ_BLOCK:0)
Block(2,22,5,VINE:2)
Block(2,22,6,VINE:2)
Block(2,23,-1,IRON_FENCE:0)
Block(2,23,1,IRON_FENCE:0)
Block(2,23,2,CONCRETE:8)
Block(2,23,3,CONCRETE:8)
Block(2,23,4,QUARTZ_BLOCK:0)
Block(2,23,6,VINE:2)
Block(2,24,-1,IRON_FENCE:0)
Block(2,24,0,COBBLE_WALL:0)
Block(2,24,1,IRON_FENCE:0)
Block(2,24,2,CONCRETE:8)
Block(2,24,3,QUARTZ_BLOCK:0)
Block(2,24,4,QUARTZ_BLOCK:0)
Block(2,24,5,VINE:6)
Block(2,24,6,VINE:2)
Block(2,25,-1,IRON_FENCE:0)
Block(2,25,1,IRON_FENCE:0)
Block(2,25,2,CONCRETE:8)
Block(2,25,3,QUARTZ_BLOCK:0)
Block(2,25,4,quark:limestone:0)
Block(2,25,5,VINE:6)
Block(3,18,3,VINE:2)
Block(3,19,-1,STEP:8)
Block(3,19,0,STEP:8)
Block(3,19,1,STEP:8)
Block(3,19,2,IRON_TRAPDOOR:11)
Block(3,19,3,VINE:2)
Block(3,19,4,IRON_TRAPDOOR:11)
Block(3,20,-4,STEP:8)
Block(3,20,-3,STEP:8)
Block(3,20,-2,STEP:8)
Block(3,20,-1,COBBLE_WALL:0)
Block(3,20,1,COBBLE_WALL:0)
Block(3,20,3,VINE:2)
Block(3,20,4,VINE:2)
Block(3,21,-4,IRON_FENCE:0)
Block(3,21,-2,IRON_FENCE:0)
Block(3,21,-1,CONCRETE:8)
Block(3,21,0,CONCRETE:8)
Block(3,21,1,quark:limestone:0)
Block(3,21,3,VINE:2)
Block(3,21,4,VINE:2)
Block(3,22,-4,IRON_FENCE:0)
Block(3,22,-2,IRON_FENCE:0)
Block(3,22,-1,CONCRETE:8)
Block(3,22,0,CONCRETE:8)
Block(3,22,1,CONCRETE:8)
Block(3,22,3,VINE:2)
Block(3,23,-4,IRON_FENCE:0)
Block(3,23,-2,IRON_FENCE:0)
Block(3,23,-1,CONCRETE:8)
Block(3,23,0,CONCRETE:8)
Block(3,23,1,quark:limestone:0)
Block(3,23,3,VINE:2)
Block(3,23,4,VINE:2)
Block(3,24,-4,IRON_FENCE:0)
Block(3,24,-2,IRON_FENCE:0)
Block(3,24,-1,QUARTZ_BLOCK:0)
Block(3,24,0,quark:limestone:0)
Block(3,24,1,quark:limestone:0)
Block(3,24,3,VINE:2)
Block(3,24,4,VINE:2)
Block(3,25,-4,IRON_FENCE:0)
Block(3,25,-2,IRON_FENCE:0)
Block(3,25,-1,quark:limestone:0)
Block(3,25,0,CONCRETE:8)
Block(3,25,1,CONCRETE:8)
Block(3,25,3,VINE:2)
Block(4,19,-4,STEP:8)
Block(4,19,-3,STEP:8)
Block(4,19,-2,STEP:8)
Block(4,19,-1,IRON_TRAPDOOR:11)
Block(4,19,1,IRON_TRAPDOOR:11)
Block(4,20,-7,STEP:8)
Block(4,20,-6,STEP:8)
Block(4,20,-5,STEP:8)
Block(4,20,-4,COBBLE_WALL:0)
Block(4,20,-2,COBBLE_WALL:0)
Block(4,21,-7,IRON_FENCE:0)
Block(4,21,-6,VINE:8)
Block(4,21,-5,IRON_FENCE:0)
Block(4,21,-4,CONCRETE:8)
Block(4,21,-3,CONCRETE:8)
Block(4,21,-2,CONCRETE:8)
Block(4,22,-7,IRON_FENCE:0)
Block(4,22,-6,VINE:8)
Block(4,22,-5,IRON_FENCE:0)
Block(4,22,-4,CONCRETE:8)
Block(4,22,-3,quark:limestone:0)
Block(4,22,-2,CONCRETE:8)
Block(4,22,-1,VINE:4)
Block(4,22,0,VINE:2)
Block(4,23,-7,IRON_FENCE:0)
Block(4,23,-6,VINE:8)
Block(4,23,-5,IRON_FENCE:0)
Block(4,23,-4,CONCRETE:8)
Block(4,23,-3,CONCRETE:8)
Block(4,23,-2,CONCRETE:8)
Block(4,23,-1,VINE:4)
Block(4,23,0,VINE:2)
Block(4,24,-7,IRON_FENCE:0)
Block(4,24,-6,VINE:8)
Block(4,24,-5,IRON_FENCE:0)
Block(4,24,-4,quark:limestone:0)
Block(4,24,-3,quark:limestone:0)
Block(4,24,-2,QUARTZ_BLOCK:0)
Block(4,24,-1,VINE:4)
Block(4,24,0,VINE:2)
Block(4,25,-7,IRON_FENCE:0)
Block(4,25,-5,IRON_FENCE:0)
Block(4,25,-4,quark:limestone:0)
Block(4,25,-3,quark:limestone:0)
Block(4,25,-2,CONCRETE:8)
Block(4,25,0,VINE:2)
Block(5,18,-3,VINE:2)
Block(5,19,-7,STEP:8)
Block(5,19,-6,STEP:8)
Block(5,19,-5,STEP:8)
Block(5,19,-4,IRON_TRAPDOOR:11)
Block(5,19,-3,VINE:2)
Block(5,19,-2,IRON_TRAPDOOR:11)
Block(5,20,-7,COBBLE_WALL:0)
Block(5,20,-5,COBBLE_WALL:0)
Block(5,20,-3,VINE:2)
Block(5,20,-2,VINE:2)
Block(5,21,-7,CONCRETE:8)
Block(5,21,-6,CONCRETE:8)
Block(5,21,-5,quark:limestone:0)
Block(5,21,-3,VINE:2)
Block(5,21,-2,VINE:2)
Block(5,22,-7,CONCRETE:8)
Block(5,22,-6,CONCRETE:8)
Block(5,22,-5,quark:limestone:0)
Block(5,22,-3,VINE:2)
Block(5,23,-7,quark:limestone:0)
Block(5,23,-6,CONCRETE:8)
Block(5,23,-5,CONCRETE:8)
Block(5,23,-3,VINE:2)
Block(5,24,-7,CONCRETE:8)
Block(5,24,-6,quark:limestone:0)
Block(5,24,-5,quark:limestone:0)
Block(5,24,-2,VINE:2)
Block(5,25,-7,CONCRETE:8)
Block(5,25,-6,CONCRETE:8)
Block(5,25,-5,quark:limestone:0)
Block(5,25,-2,VINE:2)
Block(6,17,-6,VINE:2)
Block(6,18,-6,VINE:2)
Block(6,19,-7,IRON_TRAPDOOR:11)
Block(6,19,-6,VINE:2)
Block(6,19,-5,IRON_TRAPDOOR:11)
Block(6,20,-7,VINE:2)
Block(6,20,-6,VINE:2)
Block(6,21,-7,VINE:2)
Block(6,21,-6,VINE:2)
Block(6,22,-7,VINE:2)
Block(6,23,-7,VINE:2)
Block(6,23,-6,VINE:2)
Block(6,24,-7,VINE:2)
Block(6,25,-6,VINE:2)

#######################################################################
# +-----------------------------------------------------------------+ #
# |                             Branches                            | #
# +-----------------------------------------------------------------+ #
#######################################################################


#######################################################################
# +-----------------------------------------------------------------+ #
# |                             Entities                            | #
# +-----------------------------------------------------------------+ #
#######################################################################


#######################################################################
# +-----------------------------------------------------------------+ #
# |                            Particles                            | #
# +-----------------------------------------------------------------+ #
#######################################################################


#######################################################################
# +-----------------------------------------------------------------+ #
# |                             Spawners                            | #
# +-----------------------------------------------------------------+ #
#######################################################################


#######################################################################
# +-----------------------------------------------------------------+ #
# |                             ModData                             | #
# +-----------------------------------------------------------------+ #
#######################################################################

