
#######################################################################
# +-----------------------------------------------------------------+ #
# |                            BO4 object                           | #
# +-----------------------------------------------------------------+ #
#######################################################################

Author: NLBlackEagle

Description: No description given

SettingsMode: WriteWithoutComments


#######################################################################
# +-----------------------------------------------------------------+ #
# |                          Main settings                          | #
# +-----------------------------------------------------------------+ #
#######################################################################

FixedRotation: 

Frequency: 0

SpawnHeight: highestSolidBlock

UseCenterForHighestBlock: true

##############################
# Height Limits for the BO4. #
##############################

MinHeight: 0

MaxHeight: 255

InheritBO3: 

InheritBO3Rotation: NORTH

OverrideChildSettings: true

OverrideParentHeight: true

CanOverride: true

BranchFrequency: 0

BranchFrequencyGroup: 

MustBeBelowOther: false

MustBeInside: 

CannotBeInside: 

ReplacesBO3: 

MustBeInsideWorldBorders: false

CanSpawnOnWater: false

SpawnOnWaterOnly: false

SpawnUnderWater: false

SpawnAtWaterLevel: false

HeightOffset: 0

RemoveAir: false

ReplaceAbove: 

ReplaceBelow: COBBLESTONE

ReplaceWithBiomeBlocks: false

ReplaceWithSurfaceBlock: GRASS

ReplaceWithGroundBlock: DIRT

ReplaceWithStoneBlock: STONE

SmoothRadius: 0

SmoothHeightOffset: 0

SmoothStartTop: false

SmoothStartWood: false

SmoothingSurfaceBlock: 

SmoothingGroundBlock: 

BO3Group: 

IsSpawnPoint: false

DoReplaceBlocks: true


#######################################################################
# +-----------------------------------------------------------------+ #
# |                              Blocks                             | #
# +-----------------------------------------------------------------+ #
#######################################################################

Block(-3,0,-4,COBBLESTONE:0)
Block(-3,0,-3,GRASS:0)
Block(-3,0,-2,GRASS:0)
Block(-3,0,-1,WOOD:0)
Block(-3,0,0,WOOD:0)
Block(-3,0,1,WOOD:0)
Block(-3,0,2,GRASS:0)
Block(-3,0,4,COBBLESTONE:0)
Block(-3,1,-4,SPRUCE_FENCE:0)
Block(-3,1,-3,LEAVES:4)
Block(-3,1,-2,LEAVES:4)
Block(-3,1,-1,FENCE:0)
Block(-3,1,1,FENCE:0)
Block(-3,1,2,LEAVES:4)
Block(-3,1,4,SPRUCE_FENCE:0)
Block(-3,2,-4,SPRUCE_FENCE:0)
Block(-3,2,-3,LEAVES:4)
Block(-3,2,-1,FENCE:0)
Block(-3,2,1,FENCE:0)
Block(-3,2,4,SPRUCE_FENCE:0)
Block(-3,3,-4,SPRUCE_FENCE:0)
Block(-3,3,-3,LEAVES:4)
Block(-3,3,-1,WOOD_STEP:0)
Block(-3,3,0,WOOD_STEP:0)
Block(-3,3,1,WOOD_STEP:0)
Block(-3,3,4,SPRUCE_FENCE:0)
Block(-3,4,-4,SPRUCE_FENCE:0)
Block(-3,4,-2,WOOD_STEP:0)
Block(-3,4,2,WOOD_STEP:0)
Block(-3,4,4,SPRUCE_FENCE:0)
Block(-3,5,-4,STEP:3)
Block(-3,5,-3,STEP:3)
Block(-3,5,-2,STEP:3)
Block(-3,5,-1,STEP:3)
Block(-3,5,0,STEP:3)
Block(-3,5,1,STEP:3)
Block(-3,5,2,STEP:3)
Block(-3,5,3,STEP:3)
Block(-3,5,4,STEP:3)
Block(-2,0,-3,COBBLESTONE:0)
Block(-2,0,-2,COBBLESTONE:0)
Block(-2,0,-1,COBBLESTONE:0)
Block(-2,0,0,WOOD:0)
Block(-2,0,1,COBBLESTONE:0)
Block(-2,0,2,COBBLESTONE:0)
Block(-2,0,3,COBBLESTONE:0)
Block(-2,1,-3,BRICK:0)
Block(-2,1,-2,BRICK:0)
Block(-2,1,-1,BRICK:0)
Block(-2,1,0,WOODEN_DOOR:0)
Block(-2,1,1,BRICK:0)
Block(-2,1,2,BRICK:0)
Block(-2,1,3,BRICK:0)
Block(-2,2,-3,BRICK:0)
Block(-2,2,-2,STAINED_GLASS_PANE:15)
Block(-2,2,-1,BRICK:0)
Block(-2,2,0,WOODEN_DOOR:8)
Block(-2,2,1,WOOD:0)
Block(-2,2,2,STAINED_GLASS_PANE:15)
Block(-2,2,3,BRICK:0)
Block(-2,3,-3,BRICK:0)
Block(-2,3,-2,STAINED_GLASS_PANE:15)
Block(-2,3,-1,BRICK:0)
Block(-2,3,0,WOOD:0)
Block(-2,3,1,WOOD:0)
Block(-2,3,2,STAINED_GLASS_PANE:15)
Block(-2,3,3,BRICK:0)
Block(-2,4,-3,WOOD:0)
Block(-2,4,-2,WOOD:0)
Block(-2,4,-1,WOOD:0)
Block(-2,4,0,WOOD:0)
Block(-2,4,1,WOOD_DOUBLE_STEP:0)
Block(-2,4,2,WOOD_DOUBLE_STEP:0)
Block(-2,4,3,WOOD:0)
Block(-2,5,-4,STEP:3)
Block(-2,5,-3,COBBLESTONE:0)
Block(-2,5,-2,COBBLESTONE:0)
Block(-2,5,-1,COBBLESTONE:0)
Block(-2,5,0,COBBLESTONE:0)
Block(-2,5,1,COBBLESTONE:0)
Block(-2,5,2,COBBLESTONE:0)
Block(-2,5,3,COBBLESTONE:0)
Block(-2,5,4,STEP:3)
Block(-1,0,-3,COBBLESTONE:0)
Block(-1,0,-2,LOG:0)
Block(-1,0,-1,LOG:0)
Block(-1,0,0,LOG:0)
Block(-1,0,1,LOG:0)
Block(-1,0,2,LOG:0)
Block(-1,0,3,COBBLESTONE:0)
Block(-1,0,4,GRASS:0)
Block(-1,1,-3,BRICK:0)
Block(-1,1,-2,BOOKSHELF:0)
Block(-1,1,-1,CARPET:12)
Block(-1,1,0,WOOD_PLATE:0)
Block(-1,1,2,WOOD:0)
Block(-1,1,3,BRICK:0)
Block(-1,1,4,LEAVES:4)
Block(-1,2,-3,BRICK:0)
Block(-1,2,-2,TORCH:5)
Block(-1,2,3,WOOD:0)
Block(-1,2,4,LEAVES:4)
Block(-1,3,-3,WOOD:0)
Block(-1,3,3,WOOD:0)
Block(-1,4,-3,WOOD:0)
Block(-1,4,-2,WOOD_DOUBLE_STEP:0)
Block(-1,4,-1,WOOD:0)
Block(-1,4,0,WOOD:0)
Block(-1,4,1,WOOD:0)
Block(-1,4,2,WOOD_DOUBLE_STEP:0)
Block(-1,4,3,WOOD:0)
Block(-1,5,-4,STEP:3)
Block(-1,5,-3,COBBLESTONE:0)
Block(-1,5,0,TORCH:5)
Block(-1,5,3,COBBLESTONE:0)
Block(-1,5,4,STEP:3)
Block(-1,6,-2,STEP:3)
Block(-1,6,-1,STEP:3)
Block(-1,6,0,STEP:3)
Block(-1,6,1,STEP:3)
Block(-1,6,2,STEP:3)
Block(0,0,-3,COBBLESTONE:0)
Block(0,0,-2,LOG:0)
Block(0,0,-1,WOOD:0)
Block(0,0,0,WOOD:0)
Block(0,0,1,WOOD:0)
Block(0,0,2,LOG:0)
Block(0,0,3,COBBLESTONE:0)
Block(0,0,4,GRASS:0)
Block(0,1,-3,BRICK:0)
Block(0,1,-2,CARPET:12)
Block(0,1,-1,CARPET:12)
Block(0,1,0,CARPET:12)
Block(0,1,1,FENCE:0)
Block(0,1,2,CARPET:12)
Block(0,1,3,BRICK:0)
Block(0,1,4,LEAVES:4)
Block(0,2,-3,STAINED_GLASS_PANE:15)
Block(0,2,1,WOOD_PLATE:0)
Block(0,2,3,STAINED_GLASS_PANE:15)
Block(0,3,-3,STAINED_GLASS_PANE:15)
Block(0,3,3,STAINED_GLASS_PANE:15)
Block(0,4,-4,WOOD_STEP:0)
Block(0,4,-3,WOOD:0)
Block(0,4,-2,WOOD_STEP:0)
Block(0,4,-1,LOG:0)
Block(0,4,0,LOG:0)
Block(0,4,1,LOG:0)
Block(0,4,2,WOOD_DOUBLE_STEP:0)
Block(0,4,3,WOOD:0)
Block(0,4,4,WOOD_STEP:0)
Block(0,5,-4,STEP:3)
Block(0,5,-3,COBBLESTONE:0)
Block(0,5,3,COBBLESTONE:0)
Block(0,5,4,STEP:3)
Block(0,6,-2,STEP:3)
Block(0,6,-1,DOUBLE_STEP:3)
Block(0,6,0,DOUBLE_STEP:3)
Block(0,6,1,DOUBLE_STEP:3)
Block(0,6,2,STEP:3)
Block(1,0,-3,COBBLESTONE:0)
Block(1,0,-2,LOG:0)
Block(1,0,-1,WOOD:0)
Block(1,0,0,WOOD:0)
Block(1,0,1,WOOD:0)
Block(1,0,2,LOG:0)
Block(1,0,3,COBBLESTONE:0)
Block(1,0,4,GRASS:0)
Block(1,1,-3,BRICK:0)
Block(1,1,-1,CARPET:12)
Block(1,1,0,CARPET:12)
Block(1,1,1,CARPET:12)
Block(1,1,3,BRICK:0)
Block(1,1,4,LEAVES:4)
Block(1,2,-3,STAINED_GLASS_PANE:15)
Block(1,2,3,STAINED_GLASS_PANE:15)
Block(1,3,-3,STAINED_GLASS_PANE:15)
Block(1,3,3,STAINED_GLASS_PANE:15)
Block(1,4,-4,WOOD_STEP:0)
Block(1,4,-3,WOOD:0)
Block(1,4,-2,WOOD_STEP:0)
Block(1,4,-1,LOG:0)
Block(1,4,0,LOG:0)
Block(1,4,1,LOG:0)
Block(1,4,2,WOOD_DOUBLE_STEP:0)
Block(1,4,3,WOOD:0)
Block(1,4,4,WOOD_STEP:0)
Block(1,5,-4,STEP:3)
Block(1,5,-3,COBBLESTONE:0)
Block(1,5,3,COBBLESTONE:0)
Block(1,5,4,STEP:3)
Block(1,6,-2,STEP:3)
Block(1,6,-1,DOUBLE_STEP:3)
Block(1,6,0,DOUBLE_STEP:3)
Block(1,6,1,DOUBLE_STEP:3)
Block(1,6,2,STEP:3)
Block(2,0,-3,COBBLESTONE:0)
Block(2,0,-2,LOG:0)
Block(2,0,-1,LOG:0)
Block(2,0,0,LOG:0)
Block(2,0,1,LOG:0)
Block(2,0,2,LOG:0)
Block(2,0,3,COBBLESTONE:0)
Block(2,1,-3,BRICK:0)
Block(2,1,-2,BED_BLOCK:10)
Block(2,1,-1,BED_BLOCK:2)
Block(2,1,0,CARPET:12)
RandomBlock(2,1,2,CHEST:2,../../../../Chests/Loot/junk_loot.nbt,20,CHEST:2,../../../../Chests/Loot/rare_loot.nbt,5,CHEST:2,../../../../Chests/Loot/food_loot.nbt,30,CHEST:2,../../../../Chests/Loot/common_loot.nbt,50,CHEST:2,../../../../Chests/Loot/junk_loot.nbt,100)
Block(2,1,3,BRICK:0)
Block(2,2,-3,WOOD:0)
Block(2,2,3,WOOD:0)
Block(2,3,-3,WOOD:0)
Block(2,3,3,WOOD:0)
Block(2,4,-3,WOOD:0)
Block(2,4,-2,WOOD_STEP:0)
Block(2,4,-1,WOOD_STEP:0)
Block(2,4,0,WOOD_STEP:0)
Block(2,4,1,WOOD_STEP:0)
Block(2,4,2,WOOD_STEP:0)
Block(2,4,3,WOOD:0)
Block(2,5,-4,STEP:3)
Block(2,5,-3,COBBLESTONE:0)
Block(2,5,0,DOUBLE_STEP:3)
Block(2,5,3,COBBLESTONE:0)
Block(2,5,4,STEP:3)
Block(2,6,-2,STEP:3)
Block(2,6,-1,STEP:3)
Block(2,6,0,STEP:3)
Block(2,6,1,STEP:3)
Block(2,6,2,STEP:3)
Block(3,0,-3,COBBLESTONE:0)
Block(3,0,-2,COBBLESTONE:0)
Block(3,0,-1,COBBLESTONE:0)
Block(3,0,0,COBBLESTONE:0)
Block(3,0,1,COBBLESTONE:0)
Block(3,0,2,COBBLESTONE:0)
Block(3,0,3,COBBLESTONE:0)
Block(3,1,-3,BRICK:0)
Block(3,1,-2,BRICK:0)
Block(3,1,-1,BRICK:0)
Block(3,1,0,BRICK:0)
Block(3,1,1,BRICK:0)
Block(3,1,2,BRICK:0)
Block(3,1,3,BRICK:0)
Block(3,2,-3,BRICK:0)
Block(3,2,-2,BRICK:0)
Block(3,2,-1,STAINED_GLASS_PANE:15)
Block(3,2,0,STAINED_GLASS_PANE:15)
Block(3,2,1,STAINED_GLASS_PANE:15)
Block(3,2,2,WOOD:0)
Block(3,2,3,BRICK:0)
Block(3,3,-3,BRICK:0)
Block(3,3,-2,WOOD:0)
Block(3,3,-1,STAINED_GLASS_PANE:15)
Block(3,3,0,STAINED_GLASS_PANE:15)
Block(3,3,1,STAINED_GLASS_PANE:15)
Block(3,3,2,WOOD:0)
Block(3,3,3,WOOD:0)
Block(3,4,-3,WOOD:0)
Block(3,4,-2,WOOD:0)
Block(3,4,-1,WOOD:0)
Block(3,4,0,WOOD:0)
Block(3,4,1,WOOD:0)
Block(3,4,2,WOOD:0)
Block(3,4,3,WOOD:0)
Block(3,5,-4,STEP:3)
Block(3,5,-3,COBBLESTONE:0)
Block(3,5,-2,COBBLESTONE:0)
Block(3,5,-1,COBBLESTONE:0)
Block(3,5,0,COBBLESTONE:0)
Block(3,5,1,COBBLESTONE:0)
Block(3,5,2,COBBLESTONE:0)
Block(3,5,3,COBBLESTONE:0)
Block(3,5,4,STEP:3)
Block(4,0,-4,COBBLESTONE:0)
Block(4,0,-2,GRASS:0)
Block(4,0,-1,GRASS:0)
Block(4,0,0,GRASS:0)
Block(4,0,1,GRASS:0)
Block(4,0,4,COBBLESTONE:0)
Block(4,1,-4,SPRUCE_FENCE:0)
Block(4,1,-2,LEAVES:4)
Block(4,1,-1,LEAVES:4)
Block(4,1,0,LEAVES:4)
Block(4,1,1,LEAVES:4)
Block(4,1,4,SPRUCE_FENCE:0)
Block(4,2,-4,SPRUCE_FENCE:0)
Block(4,2,-3,LEAVES:4)
Block(4,2,-2,LEAVES:4)
Block(4,2,4,SPRUCE_FENCE:0)
Block(4,3,-4,SPRUCE_FENCE:0)
Block(4,3,-3,LEAVES:4)
Block(4,3,4,SPRUCE_FENCE:0)
Block(4,4,-4,SPRUCE_FENCE:0)
Block(4,4,-1,WOOD_STEP:0)
Block(4,4,0,WOOD_STEP:0)
Block(4,4,1,WOOD_STEP:0)
Block(4,4,4,SPRUCE_FENCE:0)
Block(4,5,-4,STEP:3)
Block(4,5,-3,STEP:3)
Block(4,5,-2,STEP:3)
Block(4,5,-1,STEP:3)
Block(4,5,0,STEP:3)
Block(4,5,1,STEP:3)
Block(4,5,2,STEP:3)
Block(4,5,3,STEP:3)
Block(4,5,4,STEP:3)

#######################################################################
# +-----------------------------------------------------------------+ #
# |                             Branches                            | #
# +-----------------------------------------------------------------+ #
#######################################################################


#######################################################################
# +-----------------------------------------------------------------+ #
# |                             Entities                            | #
# +-----------------------------------------------------------------+ #
#######################################################################


#######################################################################
# +-----------------------------------------------------------------+ #
# |                            Particles                            | #
# +-----------------------------------------------------------------+ #
#######################################################################


#######################################################################
# +-----------------------------------------------------------------+ #
# |                             Spawners                            | #
# +-----------------------------------------------------------------+ #
#######################################################################


#######################################################################
# +-----------------------------------------------------------------+ #
# |                             ModData                             | #
# +-----------------------------------------------------------------+ #
#######################################################################

