
#######################################################################
# +-----------------------------------------------------------------+ #
# |                            BO4 object                           | #
# +-----------------------------------------------------------------+ #
#######################################################################

Author: NLBlackEagle

Description: No description given

SettingsMode: WriteWithoutComments


#######################################################################
# +-----------------------------------------------------------------+ #
# |                          Main settings                          | #
# +-----------------------------------------------------------------+ #
#######################################################################

FixedRotation: 

Frequency: 0

SpawnHeight: highestBlock

UseCenterForHighestBlock: true

##############################
# Height Limits for the BO4. #
##############################

MinHeight: 0

MaxHeight: 255

InheritBO3: 

InheritBO3Rotation: NORTH

OverrideChildSettings: true

OverrideParentHeight: false

CanOverride: true

BranchFrequency: 0

BranchFrequencyGroup: 

MustBeBelowOther: false

MustBeInside: 

CannotBeInside: 

ReplacesBO3: 

MustBeInsideWorldBorders: true
CanSpawnOnWater: true

SpawnOnWaterOnly: false

SpawnUnderWater: false

SpawnAtWaterLevel: false

HeightOffset: 0

RemoveAir: true

ReplaceAbove: 

ReplaceBelow: 

ReplaceWithBiomeBlocks: false

ReplaceWithSurfaceBlock: GRASS

ReplaceWithGroundBlock: DIRT

ReplaceWithStoneBlock: STONE

SmoothRadius: 0

SmoothHeightOffset: 0

SmoothStartTop: false

SmoothStartWood: false

SmoothingSurfaceBlock: 

SmoothingGroundBlock: 

BO3Group: 

IsSpawnPoint: false

DoReplaceBlocks: true


#######################################################################
# +-----------------------------------------------------------------+ #
# |                              Blocks                             | #
# +-----------------------------------------------------------------+ #
#######################################################################

Block(-8,40,4,STONE:6)
RandomBlock(-8,41,-4,minecraft:iron_bars:0,5,CONCRETE_POWDER:8,10,quark:limestone:1,15,quark:limestone,15,quark:world_stone_pavement:2,15,CONCRETE:8,100)
RandomBlock(-8,41,-3,minecraft:iron_bars:0,5,CONCRETE_POWDER:8,10,quark:limestone:1,15,quark:limestone,15,quark:world_stone_pavement:2,15,CONCRETE:8,100)
RandomBlock(-8,41,-2,minecraft:iron_bars:0,5,CONCRETE_POWDER:8,10,quark:limestone:1,15,quark:limestone,15,quark:world_stone_pavement:2,15,CONCRETE:8,100)
RandomBlock(-8,41,-1,minecraft:iron_bars:0,5,CONCRETE_POWDER:8,10,quark:limestone:1,15,quark:limestone,15,quark:world_stone_pavement:2,15,CONCRETE:8,100)
RandomBlock(-8,41,0,minecraft:iron_bars:0,5,CONCRETE_POWDER:8,10,quark:limestone:1,15,quark:limestone,15,quark:world_stone_pavement:2,15,CONCRETE:8,100)
RandomBlock(-8,41,1,minecraft:iron_bars:0,5,CONCRETE_POWDER:8,10,quark:limestone:1,15,quark:limestone,15,quark:world_stone_pavement:2,15,CONCRETE:8,100)
RandomBlock(-8,41,2,minecraft:iron_bars:0,5,CONCRETE_POWDER:8,10,quark:limestone:1,15,quark:limestone,15,quark:world_stone_pavement:2,15,CONCRETE:8,100)
RandomBlock(-8,41,3,minecraft:iron_bars:0,5,CONCRETE_POWDER:8,10,quark:limestone:1,15,quark:limestone,15,quark:world_stone_pavement:2,15,CONCRETE:8,100)
RandomBlock(-8,42,-4,minecraft:iron_bars:0,5,CONCRETE_POWDER:8,10,quark:limestone:1,15,quark:limestone,15,quark:world_stone_pavement:2,15,CONCRETE:8,100)
RandomBlock(-8,42,-3,minecraft:iron_bars:0,5,CONCRETE_POWDER:8,10,quark:limestone:1,15,quark:limestone,15,quark:world_stone_pavement:2,15,CONCRETE:8,100)
RandomBlock(-8,42,-2,minecraft:iron_bars:0,5,CONCRETE_POWDER:8,10,quark:limestone:1,15,quark:limestone,15,quark:world_stone_pavement:2,15,CONCRETE:8,100)
RandomBlock(-8,42,-1,minecraft:iron_bars:0,5,CONCRETE_POWDER:8,10,quark:limestone:1,15,quark:limestone,15,quark:world_stone_pavement:2,15,CONCRETE:8,100)
RandomBlock(-8,42,0,minecraft:iron_bars:0,5,CONCRETE_POWDER:8,10,quark:limestone:1,15,quark:limestone,15,quark:world_stone_pavement:2,15,CONCRETE:8,100)
RandomBlock(-8,42,1,minecraft:iron_bars:0,5,CONCRETE_POWDER:8,10,quark:limestone:1,15,quark:limestone,15,quark:world_stone_pavement:2,15,CONCRETE:8,100)
RandomBlock(-8,42,2,minecraft:iron_bars:0,5,CONCRETE_POWDER:8,10,quark:limestone:1,15,quark:limestone,15,quark:world_stone_pavement:2,15,CONCRETE:8,100)
RandomBlock(-8,42,3,minecraft:iron_bars:0,5,CONCRETE_POWDER:8,10,quark:limestone:1,15,quark:limestone,15,quark:world_stone_pavement:2,15,CONCRETE:8,100)
RandomBlock(-8,44,-5,minecraft:iron_bars:0,5,STAINED_CLAY:15,5,STAINED_CLAY:7,5,quark:iron_plate_slab:8,15,quark:world_stone_pavement:2,15,STAINED_CLAY:9,100)
RandomBlock(-8,44,-4,minecraft:iron_bars:0,5,STAINED_CLAY:15,5,STAINED_CLAY:7,5,quark:iron_plate_slab:8,15,quark:world_stone_pavement:2,15,STAINED_CLAY:9,100)
RandomBlock(-8,44,-3,minecraft:iron_bars:0,5,STAINED_CLAY:15,5,STAINED_CLAY:7,5,quark:iron_plate_slab:8,15,quark:world_stone_pavement:2,15,STAINED_CLAY:9,100)
RandomBlock(-8,44,-2,minecraft:iron_bars:0,5,STAINED_CLAY:15,5,STAINED_CLAY:7,5,quark:iron_plate_slab:8,15,quark:world_stone_pavement:2,15,STAINED_CLAY:9,100)
RandomBlock(-8,44,-1,minecraft:iron_bars:0,5,STAINED_CLAY:15,5,STAINED_CLAY:7,5,quark:iron_plate_slab:8,15,quark:world_stone_pavement:2,15,STAINED_CLAY:9,100)
RandomBlock(-8,44,0,minecraft:iron_bars:0,5,STAINED_CLAY:15,5,STAINED_CLAY:7,5,quark:iron_plate_slab:8,15,quark:world_stone_pavement:2,15,STAINED_CLAY:9,100)
RandomBlock(-8,44,1,minecraft:iron_bars:0,5,STAINED_CLAY:15,5,STAINED_CLAY:7,5,quark:iron_plate_slab:8,15,quark:world_stone_pavement:2,15,STAINED_CLAY:9,100)
RandomBlock(-8,44,2,minecraft:iron_bars:0,5,STAINED_CLAY:15,5,STAINED_CLAY:7,5,quark:iron_plate_slab:8,15,quark:world_stone_pavement:2,15,STAINED_CLAY:9,100)
RandomBlock(-8,44,3,minecraft:iron_bars:0,5,STAINED_CLAY:15,5,STAINED_CLAY:7,5,quark:iron_plate_slab:8,15,quark:world_stone_pavement:2,15,STAINED_CLAY:9,100)
RandomBlock(-8,44,4,minecraft:iron_bars:0,5,STAINED_CLAY:15,5,STAINED_CLAY:7,5,quark:iron_plate_slab:8,15,quark:world_stone_pavement:2,15,STAINED_CLAY:9,100)
RandomBlock(-8,44,5,minecraft:iron_bars:0,5,STAINED_CLAY:15,5,STAINED_CLAY:7,5,quark:iron_plate_slab:8,15,quark:world_stone_pavement:2,15,STAINED_CLAY:9,100)
RandomBlock(-8,44,6,minecraft:iron_bars:0,5,STAINED_CLAY:15,5,STAINED_CLAY:7,5,quark:iron_plate_slab:8,15,quark:world_stone_pavement:2,15,STAINED_CLAY:9,100)
RandomBlock(-8,44,7,minecraft:iron_bars:0,5,STAINED_CLAY:15,5,STAINED_CLAY:7,5,quark:iron_plate_slab:8,15,quark:world_stone_pavement:2,15,STAINED_CLAY:9,100)
RandomBlock(-8,44,8,minecraft:iron_bars:0,5,STAINED_CLAY:15,5,STAINED_CLAY:7,5,quark:iron_plate_slab:8,15,quark:world_stone_pavement:2,15,STAINED_CLAY:9,100)
Block(-8,45,-5,minecraft:iron_bars:0)
RandomBlock(-8,45,-3,minecraft:iron_bars:0,5,CONCRETE_POWDER:8,10,quark:limestone:1,15,quark:limestone,15,quark:world_stone_pavement:2,15,CONCRETE:8,100)
RandomBlock(-8,45,-2,minecraft:iron_bars:0,5,CONCRETE_POWDER:8,10,quark:limestone:1,15,quark:limestone,15,quark:world_stone_pavement:2,15,CONCRETE:8,100)
RandomBlock(-8,45,-1,minecraft:iron_bars:0,5,CONCRETE_POWDER:8,10,quark:limestone:1,15,quark:limestone,15,quark:world_stone_pavement:2,15,CONCRETE:8,100)
RandomBlock(-8,45,0,minecraft:iron_bars:0,5,CONCRETE_POWDER:8,10,quark:limestone:1,15,quark:limestone,15,quark:world_stone_pavement:2,15,CONCRETE:8,100)
RandomBlock(-8,45,1,minecraft:iron_bars:0,5,CONCRETE_POWDER:8,10,quark:limestone:1,15,quark:limestone,15,quark:world_stone_pavement:2,15,CONCRETE:8,100)
RandomBlock(-8,45,2,minecraft:iron_bars:0,5,CONCRETE_POWDER:8,10,quark:limestone:1,15,quark:limestone,15,quark:world_stone_pavement:2,15,CONCRETE:8,100)
RandomBlock(-8,45,3,minecraft:iron_bars:0,5,CONCRETE_POWDER:8,10,quark:limestone:1,15,quark:limestone,15,quark:world_stone_pavement:2,15,CONCRETE:8,100)
RandomBlock(-8,45,4,minecraft:iron_bars:0,5,CONCRETE_POWDER:8,10,quark:limestone:1,15,quark:limestone,15,quark:world_stone_pavement:2,15,CONCRETE:8,100)
Block(-8,46,-5,minecraft:iron_bars:0)
Block(-8,46,-3,CONCRETE:15)
Block(-8,46,-2,STAINED_GLASS_PANE:7)
Block(-8,46,-1,CONCRETE:15)
Block(-8,46,0,STAINED_GLASS_PANE:7)
Block(-8,46,1,CONCRETE:15)
Block(-8,46,2,STAINED_GLASS_PANE:7)
Block(-8,46,3,CONCRETE:15)
Block(-8,46,4,CONCRETE:15)
RandomBlock(-8,47,-3,minecraft:iron_bars:0,5,CONCRETE_POWDER:8,10,quark:limestone:1,15,quark:limestone,15,quark:world_stone_pavement:2,15,CONCRETE:8,100)
RandomBlock(-8,47,-2,minecraft:iron_bars:0,5,CONCRETE_POWDER:8,10,quark:limestone:1,15,quark:limestone,15,quark:world_stone_pavement:2,15,CONCRETE:8,100)
RandomBlock(-8,47,-1,minecraft:iron_bars:0,5,CONCRETE_POWDER:8,10,quark:limestone:1,15,quark:limestone,15,quark:world_stone_pavement:2,15,CONCRETE:8,100)
RandomBlock(-8,47,0,minecraft:iron_bars:0,5,CONCRETE_POWDER:8,10,quark:limestone:1,15,quark:limestone,15,quark:world_stone_pavement:2,15,CONCRETE:8,100)
RandomBlock(-8,47,1,minecraft:iron_bars:0,5,CONCRETE_POWDER:8,10,quark:limestone:1,15,quark:limestone,15,quark:world_stone_pavement:2,15,CONCRETE:8,100)
RandomBlock(-8,47,2,minecraft:iron_bars:0,5,CONCRETE_POWDER:8,10,quark:limestone:1,15,quark:limestone,15,quark:world_stone_pavement:2,15,CONCRETE:8,100)
RandomBlock(-8,47,3,minecraft:iron_bars:0,5,CONCRETE_POWDER:8,10,quark:limestone:1,15,quark:limestone,15,quark:world_stone_pavement:2,15,CONCRETE:8,100)
RandomBlock(-8,47,4,minecraft:iron_bars:0,5,CONCRETE_POWDER:8,10,quark:limestone:1,15,quark:limestone,15,quark:world_stone_pavement:2,15,CONCRETE:8,100)
RandomBlock(-8,48,-3,minecraft:iron_bars:0,5,CONCRETE_POWDER:8,10,quark:limestone:1,15,quark:limestone,15,quark:world_stone_pavement:2,15,CONCRETE:8,100)
RandomBlock(-8,48,-2,minecraft:iron_bars:0,5,CONCRETE_POWDER:8,10,quark:limestone:1,15,quark:limestone,15,quark:world_stone_pavement:2,15,CONCRETE:8,100)
RandomBlock(-8,48,-1,minecraft:iron_bars:0,5,CONCRETE_POWDER:8,10,quark:limestone:1,15,quark:limestone,15,quark:world_stone_pavement:2,15,CONCRETE:8,100)
RandomBlock(-8,48,0,minecraft:iron_bars:0,5,CONCRETE_POWDER:8,10,quark:limestone:1,15,quark:limestone,15,quark:world_stone_pavement:2,15,CONCRETE:8,100)
RandomBlock(-8,48,1,minecraft:iron_bars:0,5,CONCRETE_POWDER:8,10,quark:limestone:1,15,quark:limestone,15,quark:world_stone_pavement:2,15,CONCRETE:8,100)
RandomBlock(-8,48,2,minecraft:iron_bars:0,5,CONCRETE_POWDER:8,10,quark:limestone:1,15,quark:limestone,15,quark:world_stone_pavement:2,15,CONCRETE:8,100)
RandomBlock(-8,48,3,minecraft:iron_bars:0,5,CONCRETE_POWDER:8,10,quark:limestone:1,15,quark:limestone,15,quark:world_stone_pavement:2,15,CONCRETE:8,100)
RandomBlock(-8,48,4,minecraft:iron_bars:0,5,CONCRETE_POWDER:8,10,quark:limestone:1,15,quark:limestone,15,quark:world_stone_pavement:2,15,CONCRETE:8,100)
RandomBlock(-8,49,-3,minecraft:iron_bars:0,5,CONCRETE_POWDER:8,10,quark:limestone:1,15,quark:limestone,15,quark:world_stone_pavement:2,15,CONCRETE:8,100)
RandomBlock(-8,49,-2,minecraft:iron_bars:0,5,CONCRETE_POWDER:8,10,quark:limestone:1,15,quark:limestone,15,quark:world_stone_pavement:2,15,CONCRETE:8,100)
RandomBlock(-8,49,-1,minecraft:iron_bars:0,5,CONCRETE_POWDER:8,10,quark:limestone:1,15,quark:limestone,15,quark:world_stone_pavement:2,15,CONCRETE:8,100)
RandomBlock(-8,49,0,minecraft:iron_bars:0,5,CONCRETE_POWDER:8,10,quark:limestone:1,15,quark:limestone,15,quark:world_stone_pavement:2,15,CONCRETE:8,100)
RandomBlock(-8,49,1,minecraft:iron_bars:0,5,CONCRETE_POWDER:8,10,quark:limestone:1,15,quark:limestone,15,quark:world_stone_pavement:2,15,CONCRETE:8,100)
RandomBlock(-8,49,2,minecraft:iron_bars:0,5,CONCRETE_POWDER:8,10,quark:limestone:1,15,quark:limestone,15,quark:world_stone_pavement:2,15,CONCRETE:8,100)
RandomBlock(-8,49,3,minecraft:iron_bars:0,5,CONCRETE_POWDER:8,10,quark:limestone:1,15,quark:limestone,15,quark:world_stone_pavement:2,15,CONCRETE:8,100)
RandomBlock(-8,49,4,minecraft:iron_bars:0,5,CONCRETE_POWDER:8,10,quark:limestone:1,15,quark:limestone,15,quark:world_stone_pavement:2,15,CONCRETE:8,100)
RandomBlock(-8,50,-5,minecraft:iron_bars:0,5,CONCRETE_POWDER:8,10,quark:limestone:1,15,quark:limestone,15,quark:world_stone_pavement:2,15,CONCRETE:8,100)
RandomBlock(-8,50,-4,minecraft:iron_bars:0,5,STAINED_CLAY:15,5,STAINED_CLAY:7,5,quark:iron_plate_slab:8,15,quark:world_stone_pavement:2,15,STAINED_CLAY:9,100)
RandomBlock(-8,50,-3,minecraft:iron_bars:0,5,STAINED_CLAY:15,5,STAINED_CLAY:7,5,quark:iron_plate_slab:8,15,quark:world_stone_pavement:2,15,STAINED_CLAY:9,100)
RandomBlock(-8,50,-2,minecraft:iron_bars:0,5,STAINED_CLAY:15,5,STAINED_CLAY:7,5,quark:iron_plate_slab:8,15,quark:world_stone_pavement:2,15,STAINED_CLAY:9,100)
RandomBlock(-8,50,-1,minecraft:iron_bars:0,5,STAINED_CLAY:15,5,STAINED_CLAY:7,5,quark:iron_plate_slab:8,15,quark:world_stone_pavement:2,15,STAINED_CLAY:9,100)
RandomBlock(-8,50,0,minecraft:iron_bars:0,5,STAINED_CLAY:15,5,STAINED_CLAY:7,5,quark:iron_plate_slab:8,15,quark:world_stone_pavement:2,15,STAINED_CLAY:9,100)
RandomBlock(-8,50,1,minecraft:iron_bars:0,5,STAINED_CLAY:15,5,STAINED_CLAY:7,5,quark:iron_plate_slab:8,15,quark:world_stone_pavement:2,15,STAINED_CLAY:9,100)
RandomBlock(-8,50,2,minecraft:iron_bars:0,5,STAINED_CLAY:15,5,STAINED_CLAY:7,5,quark:iron_plate_slab:8,15,quark:world_stone_pavement:2,15,STAINED_CLAY:9,100)
RandomBlock(-8,50,3,minecraft:iron_bars:0,5,STAINED_CLAY:15,5,STAINED_CLAY:7,5,quark:iron_plate_slab:8,15,quark:world_stone_pavement:2,15,STAINED_CLAY:9,100)
RandomBlock(-8,50,4,minecraft:iron_bars:0,5,STAINED_CLAY:15,5,STAINED_CLAY:7,5,quark:iron_plate_slab:8,15,quark:world_stone_pavement:2,15,STAINED_CLAY:9,100)
RandomBlock(-8,50,5,minecraft:iron_bars:0,5,STAINED_CLAY:15,5,STAINED_CLAY:7,5,quark:iron_plate_slab:8,15,quark:world_stone_pavement:2,15,STAINED_CLAY:9,100)
RandomBlock(-8,50,6,minecraft:iron_bars:0,5,STAINED_CLAY:15,5,STAINED_CLAY:7,5,quark:iron_plate_slab:8,15,quark:world_stone_pavement:2,15,STAINED_CLAY:9,100)
RandomBlock(-8,50,7,minecraft:iron_bars:0,5,STAINED_CLAY:15,5,STAINED_CLAY:7,5,quark:iron_plate_slab:8,15,quark:world_stone_pavement:2,15,STAINED_CLAY:9,100)
RandomBlock(-8,50,8,minecraft:iron_bars:0,5,STAINED_CLAY:15,5,STAINED_CLAY:7,5,quark:iron_plate_slab:8,15,quark:world_stone_pavement:2,15,STAINED_CLAY:9,100)
Block(-8,51,-5,minecraft:iron_bars:0)
RandomBlock(-8,51,-2,minecraft:iron_bars:0,5,CONCRETE_POWDER:8,10,quark:limestone:1,15,quark:limestone,15,quark:world_stone_pavement:2,15,CONCRETE:8,100)
Block(-8,51,2,SMOOTH_STAIRS:6)
RandomBlock(-8,51,3,minecraft:iron_bars:0,5,CONCRETE_POWDER:8,10,quark:limestone:1,15,quark:limestone,15,quark:world_stone_pavement:2,15,CONCRETE:8,100)
Block(-8,52,-5,minecraft:iron_bars:0)
Block(-8,52,-2,STAINED_GLASS_PANE:7)
Block(-8,52,3,CONCRETE:15)
RandomBlock(-8,53,-2,minecraft:iron_bars:0,5,CONCRETE_POWDER:8,10,quark:limestone:1,15,quark:limestone,15,quark:world_stone_pavement:2,15,CONCRETE:8,100)
Block(-8,53,2,LEVER:4)
RandomBlock(-8,53,3,minecraft:iron_bars:0,5,CONCRETE_POWDER:8,10,quark:limestone:1,15,quark:limestone,15,quark:world_stone_pavement:2,15,CONCRETE:8,100)
RandomBlock(-8,54,-2,minecraft:iron_bars:0,5,CONCRETE_POWDER:8,10,quark:limestone:1,15,quark:limestone,15,quark:world_stone_pavement:2,15,CONCRETE:8,100)
Block(-8,54,-1,STEP:8)
Block(-8,54,0,STEP:8)
Block(-8,54,1,STEP:8)
Block(-8,54,2,STEP:8)
RandomBlock(-8,54,3,minecraft:iron_bars:0,5,CONCRETE_POWDER:8,10,quark:limestone:1,15,quark:limestone,15,quark:world_stone_pavement:2,15,CONCRETE:8,100)
Block(-8,54,4,STEP:8)
RandomBlock(-8,54,5,minecraft:iron_bars:0,5,CONCRETE_POWDER:8,10,quark:limestone:1,15,quark:limestone,15,quark:world_stone_pavement:2,15,CONCRETE:8,100)
RandomBlock(-8,54,7,minecraft:iron_bars:0,5,CONCRETE_POWDER:8,10,quark:limestone:1,15,quark:limestone,15,quark:world_stone_pavement:2,15,CONCRETE:8,100)
Block(-8,54,8,STEP:8)
RandomBlock(-8,55,-2,minecraft:iron_bars:0,5,CONCRETE_POWDER:8,10,quark:limestone:1,15,quark:limestone,15,quark:world_stone_pavement:2,15,CONCRETE:8,100)
Block(-8,55,-1,SMOOTH_STAIRS:7)
RandomBlock(-8,55,3,minecraft:iron_bars:0,5,CONCRETE_POWDER:8,10,quark:limestone:1,15,quark:limestone,15,quark:world_stone_pavement:2,15,CONCRETE:8,100)
Block(-8,55,5,minecraft:iron_bars:0)
Block(-8,55,7,minecraft:iron_bars:0)
Block(-8,56,-2,STAINED_GLASS_PANE:7)
Block(-8,56,2,LEVER:4)
RandomBlock(-8,56,3,minecraft:iron_bars:0,5,CONCRETE_POWDER:8,10,quark:limestone:1,15,quark:limestone,15,quark:world_stone_pavement:2,15,CONCRETE:8,100)
Block(-8,56,5,minecraft:iron_bars:0)
Block(-8,56,7,minecraft:iron_bars:0)
RandomBlock(-8,57,-2,minecraft:iron_bars:0,5,CONCRETE_POWDER:8,10,quark:limestone:1,15,quark:limestone,15,quark:world_stone_pavement:2,15,CONCRETE:8,100)
Block(-8,57,-1,STEP:8)
Block(-8,57,0,STEP:8)
Block(-8,57,1,STEP:8)
Block(-8,57,2,STEP:8)
RandomBlock(-8,57,3,minecraft:iron_bars:0,5,CONCRETE_POWDER:8,10,quark:limestone:1,15,quark:limestone,15,quark:world_stone_pavement:2,15,CONCRETE:8,100)
Block(-8,58,-2,minecraft:iron_bars:0)
Block(-8,58,3,minecraft:iron_bars:0)
Block(-8,59,-2,minecraft:iron_bars:0)
Block(-8,59,3,minecraft:iron_bars:0)
Block(-8,60,-1,SMOOTH_STAIRS:5)
Block(-8,60,0,SMOOTH_STAIRS:5)
Block(-8,60,1,SMOOTH_STAIRS:5)
Block(-8,61,-2,IRON_FENCE:0)
Block(-8,61,-1,SMOOTH_STAIRS:0)
Block(-8,61,0,SMOOTH_STAIRS:0)
Block(-8,61,1,SMOOTH_STAIRS:0)
Block(-8,61,2,IRON_FENCE:0)
Block(-8,62,-2,IRON_FENCE:0)
Block(-8,62,2,IRON_FENCE:0)
Block(-8,67,-3,minecraft:iron_bars:0)
Block(-8,67,-2,STEP:13)
Block(-8,67,-1,minecraft:iron_bars:0)
Block(-8,68,-3,IRON_FENCE:0)
RandomBlock(-8,68,-2,CONCRETE_POWDER:7,25,CONCRETE:7,100)
Block(-8,68,-1,IRON_FENCE:0)
Block(-8,69,-2,minecraft:iron_bars:0)
Block(-8,70,-2,minecraft:iron_bars:0)
Block(-7,40,4,STONE:6)
Block(-7,40,5,STONE:6)
RandomBlock(-7,44,-5,minecraft:iron_bars:0,5,STAINED_CLAY:15,5,STAINED_CLAY:7,5,quark:iron_plate_slab:8,15,quark:world_stone_pavement:2,15,STAINED_CLAY:9,100)
RandomBlock(-7,44,-4,minecraft:iron_bars:0,5,STAINED_CLAY:15,5,STAINED_CLAY:7,5,quark:iron_plate_slab:8,15,quark:world_stone_pavement:2,15,STAINED_CLAY:9,100)
RandomBlock(-7,44,-3,minecraft:iron_bars:0,5,STAINED_CLAY:15,5,STAINED_CLAY:7,5,quark:iron_plate_slab:8,15,quark:world_stone_pavement:2,15,STAINED_CLAY:9,100)
RandomBlock(-7,44,-2,minecraft:iron_bars:0,5,STAINED_CLAY:15,5,STAINED_CLAY:7,5,quark:iron_plate_slab:8,15,quark:world_stone_pavement:2,15,STAINED_CLAY:9,100)
RandomBlock(-7,44,-1,minecraft:iron_bars:0,5,STAINED_CLAY:15,5,STAINED_CLAY:7,5,quark:iron_plate_slab:8,15,quark:world_stone_pavement:2,15,STAINED_CLAY:9,100)
RandomBlock(-7,44,0,minecraft:iron_bars:0,5,STAINED_CLAY:15,5,STAINED_CLAY:7,5,quark:iron_plate_slab:8,15,quark:world_stone_pavement:2,15,STAINED_CLAY:9,100)
RandomBlock(-7,44,1,minecraft:iron_bars:0,5,STAINED_CLAY:15,5,STAINED_CLAY:7,5,quark:iron_plate_slab:8,15,quark:world_stone_pavement:2,15,STAINED_CLAY:9,100)
RandomBlock(-7,44,2,minecraft:iron_bars:0,5,STAINED_CLAY:15,5,STAINED_CLAY:7,5,quark:iron_plate_slab:8,15,quark:world_stone_pavement:2,15,STAINED_CLAY:9,100)
RandomBlock(-7,44,3,minecraft:iron_bars:0,5,STAINED_CLAY:15,5,STAINED_CLAY:7,5,quark:iron_plate_slab:8,15,quark:world_stone_pavement:2,15,STAINED_CLAY:9,100)
RandomBlock(-7,44,4,minecraft:iron_bars:0,5,STAINED_CLAY:15,5,STAINED_CLAY:7,5,quark:iron_plate_slab:8,15,quark:world_stone_pavement:2,15,STAINED_CLAY:9,100)
RandomBlock(-7,44,5,minecraft:iron_bars:0,5,STAINED_CLAY:15,5,STAINED_CLAY:7,5,quark:iron_plate_slab:8,15,quark:world_stone_pavement:2,15,STAINED_CLAY:9,100)
RandomBlock(-7,44,6,minecraft:iron_bars:0,5,STAINED_CLAY:15,5,STAINED_CLAY:7,5,quark:iron_plate_slab:8,15,quark:world_stone_pavement:2,15,STAINED_CLAY:9,100)
RandomBlock(-7,44,7,minecraft:iron_bars:0,5,STAINED_CLAY:15,5,STAINED_CLAY:7,5,quark:iron_plate_slab:8,15,quark:world_stone_pavement:2,15,STAINED_CLAY:9,100)
RandomBlock(-7,44,8,minecraft:iron_bars:0,5,STAINED_CLAY:15,5,STAINED_CLAY:7,5,quark:iron_plate_slab:8,15,quark:world_stone_pavement:2,15,STAINED_CLAY:9,100)
Block(-7,45,-5,minecraft:iron_bars:0)
RandomBlock(-7,45,-3,minecraft:iron_bars:0,5,CONCRETE_POWDER:8,10,quark:limestone:1,15,quark:limestone,15,quark:world_stone_pavement:2,15,CONCRETE:8,100)
Block(-7,45,3,IRON_PLATE:0)
Block(-7,45,4,IRON_DOOR_BLOCK:3)
Block(-7,45,5,IRON_PLATE:0)
Block(-7,46,-5,minecraft:iron_bars:0)
Block(-7,46,-3,CONCRETE:15)
Block(-7,46,4,IRON_DOOR_BLOCK:8)
RandomBlock(-7,47,-3,minecraft:iron_bars:0,5,CONCRETE_POWDER:8,10,quark:limestone:1,15,quark:limestone,15,quark:world_stone_pavement:2,15,CONCRETE:8,100)
RandomBlock(-7,47,4,minecraft:iron_bars:0,5,CONCRETE_POWDER:8,10,quark:limestone:1,15,quark:limestone,15,quark:world_stone_pavement:2,15,CONCRETE:8,100)
RandomBlock(-7,48,-3,minecraft:iron_bars:0,5,CONCRETE_POWDER:8,10,quark:limestone:1,15,quark:limestone,15,quark:world_stone_pavement:2,15,CONCRETE:8,100)
RandomBlock(-7,48,4,minecraft:iron_bars:0,5,CONCRETE_POWDER:8,10,quark:limestone:1,15,quark:limestone,15,quark:world_stone_pavement:2,15,CONCRETE:8,100)
RandomBlock(-7,49,-3,minecraft:iron_bars:0,5,CONCRETE_POWDER:8,10,quark:limestone:1,15,quark:limestone,15,quark:world_stone_pavement:2,15,CONCRETE:8,100)
RandomBlock(-7,49,4,minecraft:iron_bars:0,5,CONCRETE_POWDER:8,10,quark:limestone:1,15,quark:limestone,15,quark:world_stone_pavement:2,15,CONCRETE:8,100)
RandomBlock(-7,50,-5,minecraft:iron_bars:0,5,CONCRETE_POWDER:8,10,quark:limestone:1,15,quark:limestone,15,quark:world_stone_pavement:2,15,CONCRETE:8,100)
RandomBlock(-7,50,-4,minecraft:iron_bars:0,5,STAINED_CLAY:15,5,STAINED_CLAY:7,5,quark:iron_plate_slab:8,15,quark:world_stone_pavement:2,15,STAINED_CLAY:9,100)
RandomBlock(-7,50,-3,minecraft:iron_bars:0,5,STAINED_CLAY:15,5,STAINED_CLAY:7,5,quark:iron_plate_slab:8,15,quark:world_stone_pavement:2,15,STAINED_CLAY:9,100)
RandomBlock(-7,50,-2,minecraft:iron_bars:0,5,STAINED_CLAY:15,5,STAINED_CLAY:7,5,quark:iron_plate_slab:8,15,quark:world_stone_pavement:2,15,STAINED_CLAY:9,100)
RandomBlock(-7,50,-1,minecraft:iron_bars:0,5,STAINED_CLAY:15,5,STAINED_CLAY:7,5,quark:iron_plate_slab:8,15,quark:world_stone_pavement:2,15,STAINED_CLAY:9,100)
RandomBlock(-7,50,0,minecraft:iron_bars:0,5,STAINED_CLAY:15,5,STAINED_CLAY:7,5,quark:iron_plate_slab:8,15,quark:world_stone_pavement:2,15,STAINED_CLAY:9,100)
RandomBlock(-7,50,1,minecraft:iron_bars:0,5,STAINED_CLAY:15,5,STAINED_CLAY:7,5,quark:iron_plate_slab:8,15,quark:world_stone_pavement:2,15,STAINED_CLAY:9,100)
RandomBlock(-7,50,2,minecraft:iron_bars:0,5,STAINED_CLAY:15,5,STAINED_CLAY:7,5,quark:iron_plate_slab:8,15,quark:world_stone_pavement:2,15,STAINED_CLAY:9,100)
RandomBlock(-7,50,3,minecraft:iron_bars:0,5,STAINED_CLAY:15,5,STAINED_CLAY:7,5,quark:iron_plate_slab:8,15,quark:world_stone_pavement:2,15,STAINED_CLAY:9,100)
RandomBlock(-7,50,4,minecraft:iron_bars:0,5,STAINED_CLAY:15,5,STAINED_CLAY:7,5,quark:iron_plate_slab:8,15,quark:world_stone_pavement:2,15,STAINED_CLAY:9,100)
RandomBlock(-7,50,5,minecraft:iron_bars:0,5,STAINED_CLAY:15,5,STAINED_CLAY:7,5,quark:iron_plate_slab:8,15,quark:world_stone_pavement:2,15,STAINED_CLAY:9,100)
RandomBlock(-7,50,6,minecraft:iron_bars:0,5,STAINED_CLAY:15,5,STAINED_CLAY:7,5,quark:iron_plate_slab:8,15,quark:world_stone_pavement:2,15,STAINED_CLAY:9,100)
RandomBlock(-7,50,7,minecraft:iron_bars:0,5,STAINED_CLAY:15,5,STAINED_CLAY:7,5,quark:iron_plate_slab:8,15,quark:world_stone_pavement:2,15,STAINED_CLAY:9,100)
RandomBlock(-7,50,8,minecraft:iron_bars:0,5,STAINED_CLAY:15,5,STAINED_CLAY:7,5,quark:iron_plate_slab:8,15,quark:world_stone_pavement:2,15,STAINED_CLAY:9,100)
Block(-7,51,-5,minecraft:iron_bars:0)
RandomBlock(-7,51,-2,minecraft:iron_bars:0,5,CONCRETE_POWDER:8,10,quark:limestone:1,15,quark:limestone,15,quark:world_stone_pavement:2,15,CONCRETE:8,100)
Block(-7,51,2,SMOOTH_STAIRS:6)
RandomBlock(-7,51,3,minecraft:iron_bars:0,5,CONCRETE_POWDER:8,10,quark:limestone:1,15,quark:limestone,15,quark:world_stone_pavement:2,15,CONCRETE:8,100)
Block(-7,52,-5,minecraft:iron_bars:0)
Block(-7,52,-2,CONCRETE:15)
Block(-7,52,3,CONCRETE:15)
RandomBlock(-7,53,-2,minecraft:iron_bars:0,5,CONCRETE_POWDER:8,10,quark:limestone:1,15,quark:limestone,15,quark:world_stone_pavement:2,15,CONCRETE:8,100)
Block(-7,53,2,LEVER:4)
RandomBlock(-7,53,3,minecraft:iron_bars:0,5,CONCRETE_POWDER:8,10,quark:limestone:1,15,quark:limestone,15,quark:world_stone_pavement:2,15,CONCRETE:8,100)
RandomBlock(-7,54,-2,minecraft:iron_bars:0,5,CONCRETE_POWDER:8,10,quark:limestone:1,15,quark:limestone,15,quark:world_stone_pavement:2,15,CONCRETE:8,100)
Block(-7,54,-1,STEP:8)
Block(-7,54,0,STEP:8)
Block(-7,54,1,STEP:8)
Block(-7,54,2,STEP:8)
RandomBlock(-7,54,3,minecraft:iron_bars:0,5,CONCRETE_POWDER:8,10,quark:limestone:1,15,quark:limestone,15,quark:world_stone_pavement:2,15,CONCRETE:8,100)
Block(-7,54,4,STEP:8)
RandomBlock(-7,54,5,minecraft:iron_bars:0,5,CONCRETE_POWDER:8,10,quark:limestone:1,15,quark:limestone,15,quark:world_stone_pavement:2,15,CONCRETE:8,100)
RandomBlock(-7,54,7,minecraft:iron_bars:0,5,CONCRETE_POWDER:8,10,quark:limestone:1,15,quark:limestone,15,quark:world_stone_pavement:2,15,CONCRETE:8,100)
Block(-7,54,8,STEP:8)
RandomBlock(-7,55,-2,minecraft:iron_bars:0,5,CONCRETE_POWDER:8,10,quark:limestone:1,15,quark:limestone,15,quark:world_stone_pavement:2,15,CONCRETE:8,100)
Block(-7,55,-1,SMOOTH_STAIRS:7)
RandomBlock(-7,55,3,minecraft:iron_bars:0,5,CONCRETE_POWDER:8,10,quark:limestone:1,15,quark:limestone,15,quark:world_stone_pavement:2,15,CONCRETE:8,100)
Block(-7,55,5,minecraft:iron_bars:0)
Block(-7,55,7,minecraft:iron_bars:0)
RandomBlock(-7,56,-2,minecraft:iron_bars:0,5,CONCRETE_POWDER:8,10,quark:limestone:1,15,quark:limestone,15,quark:world_stone_pavement:2,15,CONCRETE:8,100)
Block(-7,56,2,LEVER:4)
RandomBlock(-7,56,3,minecraft:iron_bars:0,5,CONCRETE_POWDER:8,10,quark:limestone:1,15,quark:limestone,15,quark:world_stone_pavement:2,15,CONCRETE:8,100)
Block(-7,56,5,minecraft:iron_bars:0)
Block(-7,56,7,minecraft:iron_bars:0)
RandomBlock(-7,57,-2,minecraft:iron_bars:0,5,CONCRETE_POWDER:8,10,quark:limestone:1,15,quark:limestone,15,quark:world_stone_pavement:2,15,CONCRETE:8,100)
Block(-7,57,-1,STEP:8)
Block(-7,57,0,STEP:8)
Block(-7,57,1,STEP:8)
Block(-7,57,2,STEP:8)
RandomBlock(-7,57,3,minecraft:iron_bars:0,5,CONCRETE_POWDER:8,10,quark:limestone:1,15,quark:limestone,15,quark:world_stone_pavement:2,15,CONCRETE:8,100)
Block(-7,58,-2,minecraft:iron_bars:0)
Block(-7,58,3,minecraft:iron_bars:0)
Block(-7,59,-2,minecraft:iron_bars:0)
Block(-7,59,3,minecraft:iron_bars:0)
Block(-7,60,-3,STEP:13)
Block(-7,60,-2,STEP:13)
Block(-7,60,-1,STEP:13)
Block(-7,60,0,STEP:13)
Block(-7,60,1,STEP:13)
Block(-7,60,2,STEP:13)
Block(-7,60,3,STEP:13)
RandomBlock(-7,61,-3,CONCRETE_POWDER:7,25,CONCRETE:7,100)
RandomBlock(-7,61,-2,CONCRETE_POWDER:7,25,CONCRETE:7,100)
RandomBlock(-7,61,-1,CONCRETE_POWDER:7,25,CONCRETE:7,100)
RandomBlock(-7,61,0,CONCRETE_POWDER:7,25,CONCRETE:7,100)
RandomBlock(-7,61,1,CONCRETE_POWDER:7,25,CONCRETE:7,100)
RandomBlock(-7,61,2,CONCRETE_POWDER:7,25,CONCRETE:7,100)
RandomBlock(-7,61,3,CONCRETE_POWDER:7,25,CONCRETE:7,100)
Block(-7,62,-4,IRON_FENCE:0)
Block(-7,62,-3,IRON_FENCE:0)
Block(-7,62,-2,IRON_FENCE:0)
Block(-7,62,2,IRON_FENCE:0)
Block(-7,62,3,IRON_FENCE:0)
Block(-7,62,4,IRON_FENCE:0)
Block(-7,67,-2,STEP:13)
Block(-7,68,-2,SMOOTH_STAIRS:1)
RandomBlock(-6,0,1,minecraft:iron_bars:0,5,quark:iron_plate:1,15,STAINED_CLAY:15,15,STAINED_CLAY:7,100)
RandomBlock(-6,0,2,minecraft:iron_bars:0,5,quark:iron_plate:1,15,STAINED_CLAY:15,15,STAINED_CLAY:7,100)
RandomBlock(-6,0,3,minecraft:iron_bars:0,5,quark:iron_plate:1,15,STAINED_CLAY:15,15,STAINED_CLAY:7,100)
RandomBlock(-6,0,4,minecraft:iron_bars:0,5,quark:iron_plate:1,15,STAINED_CLAY:15,15,STAINED_CLAY:7,100)
RandomBlock(-6,1,1,minecraft:iron_bars:0,5,quark:iron_plate:1,15,STAINED_CLAY:15,15,STAINED_CLAY:7,100)
RandomBlock(-6,1,2,minecraft:iron_bars:0,5,quark:iron_plate:1,15,STAINED_CLAY:15,15,STAINED_CLAY:7,100)
RandomBlock(-6,1,3,minecraft:iron_bars:0,5,quark:iron_plate:1,15,STAINED_CLAY:15,15,STAINED_CLAY:7,100)
RandomBlock(-6,1,4,minecraft:iron_bars:0,5,quark:iron_plate:1,15,STAINED_CLAY:15,15,STAINED_CLAY:7,100)
RandomBlock(-6,2,1,minecraft:iron_bars:0,5,quark:iron_plate:1,15,STAINED_CLAY:15,15,STAINED_CLAY:7,100)
RandomBlock(-6,2,2,minecraft:iron_bars:0,5,quark:iron_plate:1,15,STAINED_CLAY:15,15,STAINED_CLAY:7,100)
RandomBlock(-6,2,3,minecraft:iron_bars:0,5,quark:iron_plate:1,15,STAINED_CLAY:15,15,STAINED_CLAY:7,100)
RandomBlock(-6,2,4,minecraft:iron_bars:0,5,quark:iron_plate:1,15,STAINED_CLAY:15,15,STAINED_CLAY:7,100)
RandomBlock(-6,3,1,minecraft:iron_bars:0,5,quark:iron_plate:1,15,STAINED_CLAY:15,15,STAINED_CLAY:7,100)
RandomBlock(-6,3,2,minecraft:iron_bars:0,5,quark:iron_plate:1,15,STAINED_CLAY:15,15,STAINED_CLAY:7,100)
RandomBlock(-6,3,3,minecraft:iron_bars:0,5,quark:iron_plate:1,15,STAINED_CLAY:15,15,STAINED_CLAY:7,100)
RandomBlock(-6,3,4,minecraft:iron_bars:0,5,quark:iron_plate:1,15,STAINED_CLAY:15,15,STAINED_CLAY:7,100)
RandomBlock(-6,4,1,minecraft:iron_bars:0,5,quark:iron_plate:1,15,STAINED_CLAY:15,15,STAINED_CLAY:7,100)
RandomBlock(-6,4,2,minecraft:iron_bars:0,5,quark:iron_plate:1,15,STAINED_CLAY:15,15,STAINED_CLAY:7,100)
RandomBlock(-6,4,3,minecraft:iron_bars:0,5,quark:iron_plate:1,15,STAINED_CLAY:15,15,STAINED_CLAY:7,100)
RandomBlock(-6,4,4,minecraft:iron_bars:0,5,quark:iron_plate:1,15,STAINED_CLAY:15,15,STAINED_CLAY:7,100)
RandomBlock(-6,5,1,minecraft:iron_bars:0,5,quark:iron_plate:1,15,STAINED_CLAY:15,15,STAINED_CLAY:7,100)
RandomBlock(-6,5,2,minecraft:iron_bars:0,5,quark:iron_plate:1,15,STAINED_CLAY:15,15,STAINED_CLAY:7,100)
RandomBlock(-6,5,3,minecraft:iron_bars:0,5,quark:iron_plate:1,15,STAINED_CLAY:15,15,STAINED_CLAY:7,100)
RandomBlock(-6,5,4,minecraft:iron_bars:0,5,quark:iron_plate:1,15,STAINED_CLAY:15,15,STAINED_CLAY:7,100)
RandomBlock(-6,6,1,minecraft:iron_bars:0,5,quark:iron_plate:1,15,STAINED_CLAY:15,15,STAINED_CLAY:7,100)
RandomBlock(-6,6,2,minecraft:iron_bars:0,5,quark:iron_plate:1,15,STAINED_CLAY:15,15,STAINED_CLAY:7,100)
RandomBlock(-6,6,3,minecraft:iron_bars:0,5,quark:iron_plate:1,15,STAINED_CLAY:15,15,STAINED_CLAY:7,100)
RandomBlock(-6,6,4,minecraft:iron_bars:0,5,quark:iron_plate:1,15,STAINED_CLAY:15,15,STAINED_CLAY:7,100)
RandomBlock(-6,7,1,minecraft:iron_bars:0,5,quark:iron_plate:1,15,STAINED_CLAY:15,15,STAINED_CLAY:7,100)
RandomBlock(-6,7,2,minecraft:iron_bars:0,5,quark:iron_plate:1,15,STAINED_CLAY:15,15,STAINED_CLAY:7,100)
RandomBlock(-6,7,3,minecraft:iron_bars:0,5,quark:iron_plate:1,15,STAINED_CLAY:15,15,STAINED_CLAY:7,100)
RandomBlock(-6,7,4,minecraft:iron_bars:0,5,quark:iron_plate:1,15,STAINED_CLAY:15,15,STAINED_CLAY:7,100)
RandomBlock(-6,8,1,minecraft:iron_bars:0,5,quark:iron_plate:1,15,STAINED_CLAY:15,15,STAINED_CLAY:7,100)
RandomBlock(-6,8,2,minecraft:iron_bars:0,5,quark:iron_plate:1,15,STAINED_CLAY:15,15,STAINED_CLAY:7,100)
RandomBlock(-6,8,3,minecraft:iron_bars:0,5,quark:iron_plate:1,15,STAINED_CLAY:15,15,STAINED_CLAY:7,100)
RandomBlock(-6,8,4,minecraft:iron_bars:0,5,quark:iron_plate:1,15,STAINED_CLAY:15,15,STAINED_CLAY:7,100)
RandomBlock(-6,9,1,minecraft:iron_bars:0,5,quark:iron_plate:1,15,STAINED_CLAY:15,15,STAINED_CLAY:7,100)
RandomBlock(-6,9,2,minecraft:iron_bars:0,5,quark:iron_plate:1,15,STAINED_CLAY:15,15,STAINED_CLAY:7,100)
RandomBlock(-6,9,3,minecraft:iron_bars:0,5,quark:iron_plate:1,15,STAINED_CLAY:15,15,STAINED_CLAY:7,100)
RandomBlock(-6,9,4,minecraft:iron_bars:0,5,quark:iron_plate:1,15,STAINED_CLAY:15,15,STAINED_CLAY:7,100)
RandomBlock(-6,10,1,minecraft:iron_bars:0,5,quark:iron_plate:1,15,STAINED_CLAY:15,15,STAINED_CLAY:7,100)
RandomBlock(-6,10,2,minecraft:iron_bars:0,5,quark:iron_plate:1,15,STAINED_CLAY:15,15,STAINED_CLAY:7,100)
RandomBlock(-6,10,3,minecraft:iron_bars:0,5,quark:iron_plate:1,15,STAINED_CLAY:15,15,STAINED_CLAY:7,100)
RandomBlock(-6,10,4,minecraft:iron_bars:0,5,quark:iron_plate:1,15,STAINED_CLAY:15,15,STAINED_CLAY:7,100)
RandomBlock(-6,11,1,minecraft:iron_bars:0,5,quark:iron_plate:1,15,STAINED_CLAY:15,15,STAINED_CLAY:7,100)
RandomBlock(-6,11,2,minecraft:iron_bars:0,5,quark:iron_plate:1,15,STAINED_CLAY:15,15,STAINED_CLAY:7,100)
RandomBlock(-6,11,3,minecraft:iron_bars:0,5,quark:iron_plate:1,15,STAINED_CLAY:15,15,STAINED_CLAY:7,100)
RandomBlock(-6,11,4,minecraft:iron_bars:0,5,quark:iron_plate:1,15,STAINED_CLAY:15,15,STAINED_CLAY:7,100)
RandomBlock(-6,12,1,minecraft:iron_bars:0,5,quark:iron_plate:1,15,STAINED_CLAY:15,15,STAINED_CLAY:7,100)
RandomBlock(-6,12,2,minecraft:iron_bars:0,5,quark:iron_plate:1,15,STAINED_CLAY:15,15,STAINED_CLAY:7,100)
RandomBlock(-6,12,3,minecraft:iron_bars:0,5,quark:iron_plate:1,15,STAINED_CLAY:15,15,STAINED_CLAY:7,100)
RandomBlock(-6,12,4,minecraft:iron_bars:0,5,quark:iron_plate:1,15,STAINED_CLAY:15,15,STAINED_CLAY:7,100)
RandomBlock(-6,13,1,minecraft:iron_bars:0,5,quark:iron_plate:1,15,STAINED_CLAY:15,15,STAINED_CLAY:7,100)
RandomBlock(-6,13,2,minecraft:iron_bars:0,5,quark:iron_plate:1,15,STAINED_CLAY:15,15,STAINED_CLAY:7,100)
RandomBlock(-6,13,3,minecraft:iron_bars:0,5,quark:iron_plate:1,15,STAINED_CLAY:15,15,STAINED_CLAY:7,100)
RandomBlock(-6,13,4,minecraft:iron_bars:0,5,quark:iron_plate:1,15,STAINED_CLAY:15,15,STAINED_CLAY:7,100)
RandomBlock(-6,14,1,minecraft:iron_bars:0,5,quark:iron_plate:1,15,STAINED_CLAY:15,15,STAINED_CLAY:7,100)
RandomBlock(-6,14,2,minecraft:iron_bars:0,5,quark:iron_plate:1,15,STAINED_CLAY:15,15,STAINED_CLAY:7,100)
RandomBlock(-6,14,3,minecraft:iron_bars:0,5,quark:iron_plate:1,15,STAINED_CLAY:15,15,STAINED_CLAY:7,100)
RandomBlock(-6,14,4,minecraft:iron_bars:0,5,quark:iron_plate:1,15,STAINED_CLAY:15,15,STAINED_CLAY:7,100)
RandomBlock(-6,15,1,minecraft:iron_bars:0,5,quark:iron_plate:1,15,STAINED_CLAY:15,15,STAINED_CLAY:7,100)
RandomBlock(-6,15,2,minecraft:iron_bars:0,5,quark:iron_plate:1,15,STAINED_CLAY:15,15,STAINED_CLAY:7,100)
RandomBlock(-6,15,3,minecraft:iron_bars:0,5,quark:iron_plate:1,15,STAINED_CLAY:15,15,STAINED_CLAY:7,100)
RandomBlock(-6,15,4,minecraft:iron_bars:0,5,quark:iron_plate:1,15,STAINED_CLAY:15,15,STAINED_CLAY:7,100)
RandomBlock(-6,16,1,minecraft:iron_bars:0,5,quark:iron_plate:1,15,STAINED_CLAY:15,15,STAINED_CLAY:7,100)
RandomBlock(-6,16,2,minecraft:iron_bars:0,5,quark:iron_plate:1,15,STAINED_CLAY:15,15,STAINED_CLAY:7,100)
RandomBlock(-6,16,3,minecraft:iron_bars:0,5,quark:iron_plate:1,15,STAINED_CLAY:15,15,STAINED_CLAY:7,100)
RandomBlock(-6,16,4,minecraft:iron_bars:0,5,quark:iron_plate:1,15,STAINED_CLAY:15,15,STAINED_CLAY:7,100)
RandomBlock(-6,17,1,minecraft:iron_bars:0,5,quark:iron_plate:1,15,STAINED_CLAY:15,15,STAINED_CLAY:7,100)
RandomBlock(-6,17,2,minecraft:iron_bars:0,5,quark:iron_plate:1,15,STAINED_CLAY:15,15,STAINED_CLAY:7,100)
RandomBlock(-6,17,3,minecraft:iron_bars:0,5,quark:iron_plate:1,15,STAINED_CLAY:15,15,STAINED_CLAY:7,100)
RandomBlock(-6,17,4,minecraft:iron_bars:0,5,quark:iron_plate:1,15,STAINED_CLAY:15,15,STAINED_CLAY:7,100)
RandomBlock(-6,18,1,minecraft:iron_bars:0,5,quark:iron_plate:1,15,STAINED_CLAY:15,15,STAINED_CLAY:7,100)
RandomBlock(-6,18,2,minecraft:iron_bars:0,5,quark:iron_plate:1,15,STAINED_CLAY:15,15,STAINED_CLAY:7,100)
RandomBlock(-6,18,3,minecraft:iron_bars:0,5,quark:iron_plate:1,15,STAINED_CLAY:15,15,STAINED_CLAY:7,100)
RandomBlock(-6,18,4,minecraft:iron_bars:0,5,quark:iron_plate:1,15,STAINED_CLAY:15,15,STAINED_CLAY:7,100)
RandomBlock(-6,19,1,minecraft:iron_bars:0,5,quark:iron_plate:1,15,STAINED_CLAY:15,15,STAINED_CLAY:7,100)
RandomBlock(-6,19,2,minecraft:iron_bars:0,5,quark:iron_plate:1,15,STAINED_CLAY:15,15,STAINED_CLAY:7,100)
RandomBlock(-6,19,3,minecraft:iron_bars:0,5,quark:iron_plate:1,15,STAINED_CLAY:15,15,STAINED_CLAY:7,100)
RandomBlock(-6,19,4,minecraft:iron_bars:0,5,quark:iron_plate:1,15,STAINED_CLAY:15,15,STAINED_CLAY:7,100)
RandomBlock(-6,20,1,minecraft:iron_bars:0,5,quark:iron_plate:1,15,STAINED_CLAY:15,15,STAINED_CLAY:7,100)
RandomBlock(-6,20,2,minecraft:iron_bars:0,5,quark:iron_plate:1,15,STAINED_CLAY:15,15,STAINED_CLAY:7,100)
RandomBlock(-6,20,3,minecraft:iron_bars:0,5,quark:iron_plate:1,15,STAINED_CLAY:15,15,STAINED_CLAY:7,100)
RandomBlock(-6,20,4,minecraft:iron_bars:0,5,quark:iron_plate:1,15,STAINED_CLAY:15,15,STAINED_CLAY:7,100)
RandomBlock(-6,21,1,minecraft:iron_bars:0,5,quark:iron_plate:1,15,STAINED_CLAY:15,15,STAINED_CLAY:7,100)
RandomBlock(-6,21,2,minecraft:iron_bars:0,5,quark:iron_plate:1,15,STAINED_CLAY:15,15,STAINED_CLAY:7,100)
RandomBlock(-6,21,3,minecraft:iron_bars:0,5,quark:iron_plate:1,15,STAINED_CLAY:15,15,STAINED_CLAY:7,100)
RandomBlock(-6,21,4,minecraft:iron_bars:0,5,quark:iron_plate:1,15,STAINED_CLAY:15,15,STAINED_CLAY:7,100)
RandomBlock(-6,22,1,minecraft:iron_bars:0,5,quark:iron_plate:1,15,STAINED_CLAY:15,15,STAINED_CLAY:7,100)
RandomBlock(-6,22,2,minecraft:iron_bars:0,5,quark:iron_plate:1,15,STAINED_CLAY:15,15,STAINED_CLAY:7,100)
RandomBlock(-6,22,3,minecraft:iron_bars:0,5,quark:iron_plate:1,15,STAINED_CLAY:15,15,STAINED_CLAY:7,100)
RandomBlock(-6,22,4,minecraft:iron_bars:0,5,quark:iron_plate:1,15,STAINED_CLAY:15,15,STAINED_CLAY:7,100)
RandomBlock(-6,23,1,minecraft:iron_bars:0,5,quark:iron_plate:1,15,STAINED_CLAY:15,15,STAINED_CLAY:7,100)
RandomBlock(-6,23,2,minecraft:iron_bars:0,5,quark:iron_plate:1,15,STAINED_CLAY:15,15,STAINED_CLAY:7,100)
RandomBlock(-6,23,3,minecraft:iron_bars:0,5,quark:iron_plate:1,15,STAINED_CLAY:15,15,STAINED_CLAY:7,100)
RandomBlock(-6,23,4,minecraft:iron_bars:0,5,quark:iron_plate:1,15,STAINED_CLAY:15,15,STAINED_CLAY:7,100)
RandomBlock(-6,24,1,minecraft:iron_bars:0,5,quark:iron_plate:1,15,STAINED_CLAY:15,15,STAINED_CLAY:7,100)
RandomBlock(-6,24,2,minecraft:iron_bars:0,5,quark:iron_plate:1,15,STAINED_CLAY:15,15,STAINED_CLAY:7,100)
RandomBlock(-6,24,3,minecraft:iron_bars:0,5,quark:iron_plate:1,15,STAINED_CLAY:15,15,STAINED_CLAY:7,100)
RandomBlock(-6,24,4,minecraft:iron_bars:0,5,quark:iron_plate:1,15,STAINED_CLAY:15,15,STAINED_CLAY:7,100)
RandomBlock(-6,25,1,minecraft:iron_bars:0,5,quark:iron_plate:1,15,STAINED_CLAY:15,15,STAINED_CLAY:7,100)
RandomBlock(-6,25,2,minecraft:iron_bars:0,5,quark:iron_plate:1,15,STAINED_CLAY:15,15,STAINED_CLAY:7,100)
RandomBlock(-6,25,3,minecraft:iron_bars:0,5,quark:iron_plate:1,15,STAINED_CLAY:15,15,STAINED_CLAY:7,100)
RandomBlock(-6,25,4,minecraft:iron_bars:0,5,quark:iron_plate:1,15,STAINED_CLAY:15,15,STAINED_CLAY:7,100)
RandomBlock(-6,26,1,minecraft:iron_bars:0,5,quark:iron_plate:1,15,STAINED_CLAY:15,15,STAINED_CLAY:7,100)
RandomBlock(-6,26,2,minecraft:iron_bars:0,5,quark:iron_plate:1,15,STAINED_CLAY:15,15,STAINED_CLAY:7,100)
RandomBlock(-6,26,3,minecraft:iron_bars:0,5,quark:iron_plate:1,15,STAINED_CLAY:15,15,STAINED_CLAY:7,100)
RandomBlock(-6,26,4,minecraft:iron_bars:0,5,quark:iron_plate:1,15,STAINED_CLAY:15,15,STAINED_CLAY:7,100)
RandomBlock(-6,27,1,minecraft:iron_bars:0,5,quark:iron_plate:1,15,STAINED_CLAY:15,15,STAINED_CLAY:7,100)
RandomBlock(-6,27,2,minecraft:iron_bars:0,5,quark:iron_plate:1,15,STAINED_CLAY:15,15,STAINED_CLAY:7,100)
RandomBlock(-6,27,3,minecraft:iron_bars:0,5,quark:iron_plate:1,15,STAINED_CLAY:15,15,STAINED_CLAY:7,100)
RandomBlock(-6,27,4,minecraft:iron_bars:0,5,quark:iron_plate:1,15,STAINED_CLAY:15,15,STAINED_CLAY:7,100)
RandomBlock(-6,28,1,minecraft:iron_bars:0,5,quark:iron_plate:1,15,STAINED_CLAY:15,15,STAINED_CLAY:7,100)
RandomBlock(-6,28,2,minecraft:iron_bars:0,5,quark:iron_plate:1,15,STAINED_CLAY:15,15,STAINED_CLAY:7,100)
RandomBlock(-6,28,3,minecraft:iron_bars:0,5,quark:iron_plate:1,15,STAINED_CLAY:15,15,STAINED_CLAY:7,100)
RandomBlock(-6,28,4,minecraft:iron_bars:0,5,quark:iron_plate:1,15,STAINED_CLAY:15,15,STAINED_CLAY:7,100)
RandomBlock(-6,29,1,minecraft:iron_bars:0,5,quark:iron_plate:1,15,STAINED_CLAY:15,15,STAINED_CLAY:7,100)
RandomBlock(-6,29,2,minecraft:iron_bars:0,5,quark:iron_plate:1,15,STAINED_CLAY:15,15,STAINED_CLAY:7,100)
RandomBlock(-6,29,3,minecraft:iron_bars:0,5,quark:iron_plate:1,15,STAINED_CLAY:15,15,STAINED_CLAY:7,100)
RandomBlock(-6,29,4,minecraft:iron_bars:0,5,quark:iron_plate:1,15,STAINED_CLAY:15,15,STAINED_CLAY:7,100)
RandomBlock(-6,30,1,minecraft:iron_bars:0,5,quark:iron_plate:1,15,STAINED_CLAY:15,15,STAINED_CLAY:7,100)
RandomBlock(-6,30,2,minecraft:iron_bars:0,5,quark:iron_plate:1,15,STAINED_CLAY:15,15,STAINED_CLAY:7,100)
RandomBlock(-6,30,3,minecraft:iron_bars:0,5,quark:iron_plate:1,15,STAINED_CLAY:15,15,STAINED_CLAY:7,100)
RandomBlock(-6,30,4,minecraft:iron_bars:0,5,quark:iron_plate:1,15,STAINED_CLAY:15,15,STAINED_CLAY:7,100)
RandomBlock(-6,31,1,minecraft:iron_bars:0,5,quark:iron_plate:1,15,STAINED_CLAY:15,15,STAINED_CLAY:7,100)
RandomBlock(-6,31,2,minecraft:iron_bars:0,5,quark:iron_plate:1,15,STAINED_CLAY:15,15,STAINED_CLAY:7,100)
RandomBlock(-6,31,3,minecraft:iron_bars:0,5,quark:iron_plate:1,15,STAINED_CLAY:15,15,STAINED_CLAY:7,100)
RandomBlock(-6,31,4,minecraft:iron_bars:0,5,quark:iron_plate:1,15,STAINED_CLAY:15,15,STAINED_CLAY:7,100)
RandomBlock(-6,32,1,minecraft:iron_bars:0,5,quark:iron_plate:1,15,STAINED_CLAY:15,15,STAINED_CLAY:7,100)
RandomBlock(-6,32,2,minecraft:iron_bars:0,5,quark:iron_plate:1,15,STAINED_CLAY:15,15,STAINED_CLAY:7,100)
RandomBlock(-6,32,3,minecraft:iron_bars:0,5,quark:iron_plate:1,15,STAINED_CLAY:15,15,STAINED_CLAY:7,100)
RandomBlock(-6,32,4,minecraft:iron_bars:0,5,quark:iron_plate:1,15,STAINED_CLAY:15,15,STAINED_CLAY:7,100)
RandomBlock(-6,33,1,minecraft:iron_bars:0,5,quark:iron_plate:1,15,STAINED_CLAY:15,15,STAINED_CLAY:7,100)
RandomBlock(-6,33,2,minecraft:iron_bars:0,5,quark:iron_plate:1,15,STAINED_CLAY:15,15,STAINED_CLAY:7,100)
RandomBlock(-6,33,3,minecraft:iron_bars:0,5,quark:iron_plate:1,15,STAINED_CLAY:15,15,STAINED_CLAY:7,100)
RandomBlock(-6,33,4,minecraft:iron_bars:0,5,quark:iron_plate:1,15,STAINED_CLAY:15,15,STAINED_CLAY:7,100)
RandomBlock(-6,34,1,minecraft:iron_bars:0,5,quark:iron_plate:1,15,STAINED_CLAY:15,15,STAINED_CLAY:7,100)
RandomBlock(-6,34,2,minecraft:iron_bars:0,5,quark:iron_plate:1,15,STAINED_CLAY:15,15,STAINED_CLAY:7,100)
RandomBlock(-6,34,3,minecraft:iron_bars:0,5,quark:iron_plate:1,15,STAINED_CLAY:15,15,STAINED_CLAY:7,100)
RandomBlock(-6,34,4,minecraft:iron_bars:0,5,quark:iron_plate:1,15,STAINED_CLAY:15,15,STAINED_CLAY:7,100)
RandomBlock(-6,35,1,minecraft:iron_bars:0,5,quark:iron_plate:1,15,STAINED_CLAY:15,15,STAINED_CLAY:7,100)
RandomBlock(-6,35,2,minecraft:iron_bars:0,5,quark:iron_plate:1,15,STAINED_CLAY:15,15,STAINED_CLAY:7,100)
RandomBlock(-6,35,3,minecraft:iron_bars:0,5,quark:iron_plate:1,15,STAINED_CLAY:15,15,STAINED_CLAY:7,100)
RandomBlock(-6,35,4,minecraft:iron_bars:0,5,quark:iron_plate:1,15,STAINED_CLAY:15,15,STAINED_CLAY:7,100)
RandomBlock(-6,36,1,minecraft:iron_bars:0,5,quark:iron_plate:1,15,STAINED_CLAY:15,15,STAINED_CLAY:7,100)
RandomBlock(-6,36,2,minecraft:iron_bars:0,5,quark:iron_plate:1,15,STAINED_CLAY:15,15,STAINED_CLAY:7,100)
RandomBlock(-6,36,3,minecraft:iron_bars:0,5,quark:iron_plate:1,15,STAINED_CLAY:15,15,STAINED_CLAY:7,100)
RandomBlock(-6,36,4,minecraft:iron_bars:0,5,quark:iron_plate:1,15,STAINED_CLAY:15,15,STAINED_CLAY:7,100)
RandomBlock(-6,37,1,minecraft:iron_bars:0,5,quark:iron_plate:1,15,STAINED_CLAY:15,15,STAINED_CLAY:7,100)
RandomBlock(-6,37,2,minecraft:iron_bars:0,5,quark:iron_plate:1,15,STAINED_CLAY:15,15,STAINED_CLAY:7,100)
RandomBlock(-6,37,3,minecraft:iron_bars:0,5,quark:iron_plate:1,15,STAINED_CLAY:15,15,STAINED_CLAY:7,100)
RandomBlock(-6,37,4,minecraft:iron_bars:0,5,quark:iron_plate:1,15,STAINED_CLAY:15,15,STAINED_CLAY:7,100)
RandomBlock(-6,38,1,minecraft:iron_bars:0,5,quark:iron_plate:1,15,STAINED_CLAY:15,15,STAINED_CLAY:7,100)
RandomBlock(-6,38,2,minecraft:iron_bars:0,5,quark:iron_plate:1,15,STAINED_CLAY:15,15,STAINED_CLAY:7,100)
RandomBlock(-6,38,3,minecraft:iron_bars:0,5,quark:iron_plate:1,15,STAINED_CLAY:15,15,STAINED_CLAY:7,100)
RandomBlock(-6,38,4,minecraft:iron_bars:0,5,quark:iron_plate:1,15,STAINED_CLAY:15,15,STAINED_CLAY:7,100)
RandomBlock(-6,39,1,minecraft:iron_bars:0,5,quark:iron_plate:1,15,STAINED_CLAY:15,15,STAINED_CLAY:7,100)
RandomBlock(-6,39,2,minecraft:iron_bars:0,5,quark:iron_plate:1,15,STAINED_CLAY:15,15,STAINED_CLAY:7,100)
RandomBlock(-6,39,3,minecraft:iron_bars:0,5,quark:iron_plate:1,15,STAINED_CLAY:15,15,STAINED_CLAY:7,100)
RandomBlock(-6,39,4,minecraft:iron_bars:0,5,quark:iron_plate:1,15,STAINED_CLAY:15,15,STAINED_CLAY:7,100)
RandomBlock(-6,40,1,minecraft:iron_bars:0,5,quark:iron_plate:1,15,STAINED_CLAY:15,15,STAINED_CLAY:7,100)
RandomBlock(-6,40,2,minecraft:iron_bars:0,5,quark:iron_plate:1,15,STAINED_CLAY:15,15,STAINED_CLAY:7,100)
RandomBlock(-6,40,3,minecraft:iron_bars:0,5,quark:iron_plate:1,15,STAINED_CLAY:15,15,STAINED_CLAY:7,100)
RandomBlock(-6,40,4,minecraft:iron_bars:0,5,quark:iron_plate:1,15,STAINED_CLAY:15,15,STAINED_CLAY:7,100)
Block(-6,40,5,STONE:6)
Block(-6,40,6,STONE:6)
RandomBlock(-6,41,1,minecraft:iron_bars:0,5,quark:iron_plate:1,15,STAINED_CLAY:15,15,STAINED_CLAY:7,100)
RandomBlock(-6,41,2,minecraft:iron_bars:0,5,quark:iron_plate:1,15,STAINED_CLAY:15,15,STAINED_CLAY:7,100)
RandomBlock(-6,41,3,minecraft:iron_bars:0,5,quark:iron_plate:1,15,STAINED_CLAY:15,15,STAINED_CLAY:7,100)
RandomBlock(-6,41,4,minecraft:iron_bars:0,5,quark:iron_plate:1,15,STAINED_CLAY:15,15,STAINED_CLAY:7,100)
Block(-6,41,6,STONE:6)
RandomBlock(-6,42,1,minecraft:iron_bars:0,5,quark:iron_plate:1,15,STAINED_CLAY:15,15,STAINED_CLAY:7,100)
RandomBlock(-6,42,2,minecraft:iron_bars:0,5,quark:iron_plate:1,15,STAINED_CLAY:15,15,STAINED_CLAY:7,100)
RandomBlock(-6,42,3,minecraft:iron_bars:0,5,quark:iron_plate:1,15,STAINED_CLAY:15,15,STAINED_CLAY:7,100)
RandomBlock(-6,42,4,minecraft:iron_bars:0,5,quark:iron_plate:1,15,STAINED_CLAY:15,15,STAINED_CLAY:7,100)
Block(-6,42,6,STONE:6)
Block(-6,43,-6,STONE:6)
Block(-6,43,-5,STONE:6)
Block(-6,43,-4,STONE:6)
Block(-6,43,-3,STONE:6)
Block(-6,43,-2,STONE:6)
Block(-6,43,-1,STONE:6)
Block(-6,43,0,STONE:6)
RandomBlock(-6,43,1,minecraft:iron_bars:0,5,quark:iron_plate:1,15,STAINED_CLAY:15,15,STAINED_CLAY:7,100)
RandomBlock(-6,43,2,minecraft:iron_bars:0,5,quark:iron_plate:1,15,STAINED_CLAY:15,15,STAINED_CLAY:7,100)
RandomBlock(-6,43,3,minecraft:iron_bars:0,5,quark:iron_plate:1,15,STAINED_CLAY:15,15,STAINED_CLAY:7,100)
RandomBlock(-6,43,4,minecraft:iron_bars:0,5,quark:iron_plate:1,15,STAINED_CLAY:15,15,STAINED_CLAY:7,100)
Block(-6,43,6,STONE:6)
Block(-6,44,-6,STONE:6)
RandomBlock(-6,44,-5,minecraft:iron_bars:0,5,STAINED_CLAY:15,5,STAINED_CLAY:7,5,quark:iron_plate_slab:8,15,quark:world_stone_pavement:2,15,STAINED_CLAY:9,100)
RandomBlock(-6,44,-4,minecraft:iron_bars:0,5,STAINED_CLAY:15,5,STAINED_CLAY:7,5,quark:iron_plate_slab:8,15,quark:world_stone_pavement:2,15,STAINED_CLAY:9,100)
RandomBlock(-6,44,-3,minecraft:iron_bars:0,5,STAINED_CLAY:15,5,STAINED_CLAY:7,5,quark:iron_plate_slab:8,15,quark:world_stone_pavement:2,15,STAINED_CLAY:9,100)
RandomBlock(-6,44,-2,minecraft:iron_bars:0,5,STAINED_CLAY:15,5,STAINED_CLAY:7,5,quark:iron_plate_slab:8,15,quark:world_stone_pavement:2,15,STAINED_CLAY:9,100)
RandomBlock(-6,44,-1,minecraft:iron_bars:0,5,STAINED_CLAY:15,5,STAINED_CLAY:7,5,quark:iron_plate_slab:8,15,quark:world_stone_pavement:2,15,STAINED_CLAY:9,100)
RandomBlock(-6,44,0,minecraft:iron_bars:0,5,STAINED_CLAY:15,5,STAINED_CLAY:7,5,quark:iron_plate_slab:8,15,quark:world_stone_pavement:2,15,STAINED_CLAY:9,100)
RandomBlock(-6,44,1,minecraft:iron_bars:0,5,STAINED_CLAY:15,5,STAINED_CLAY:7,5,quark:iron_plate_slab:8,15,quark:world_stone_pavement:2,15,STAINED_CLAY:9,100)
RandomBlock(-6,44,2,minecraft:iron_bars:0,5,STAINED_CLAY:15,5,STAINED_CLAY:7,5,quark:iron_plate_slab:8,15,quark:world_stone_pavement:2,15,STAINED_CLAY:9,100)
RandomBlock(-6,44,3,minecraft:iron_bars:0,5,STAINED_CLAY:15,5,STAINED_CLAY:7,5,quark:iron_plate_slab:8,15,quark:world_stone_pavement:2,15,STAINED_CLAY:9,100)
RandomBlock(-6,44,4,minecraft:iron_bars:0,5,STAINED_CLAY:15,5,STAINED_CLAY:7,5,quark:iron_plate_slab:8,15,quark:world_stone_pavement:2,15,STAINED_CLAY:9,100)
RandomBlock(-6,44,5,minecraft:iron_bars:0,5,STAINED_CLAY:15,5,STAINED_CLAY:7,5,quark:iron_plate_slab:8,15,quark:world_stone_pavement:2,15,STAINED_CLAY:9,100)
RandomBlock(-6,44,6,minecraft:iron_bars:0,5,STAINED_CLAY:15,5,STAINED_CLAY:7,5,quark:iron_plate_slab:8,15,quark:world_stone_pavement:2,15,STAINED_CLAY:9,100)
RandomBlock(-6,44,7,minecraft:iron_bars:0,5,STAINED_CLAY:15,5,STAINED_CLAY:7,5,quark:iron_plate_slab:8,15,quark:world_stone_pavement:2,15,STAINED_CLAY:9,100)
RandomBlock(-6,44,8,minecraft:iron_bars:0,5,STAINED_CLAY:15,5,STAINED_CLAY:7,5,quark:iron_plate_slab:8,15,quark:world_stone_pavement:2,15,STAINED_CLAY:9,100)
Block(-6,45,-6,STONE:6)
Block(-6,45,-5,minecraft:iron_bars:0)
RandomBlock(-6,45,-3,minecraft:iron_bars:0,5,CONCRETE_POWDER:8,10,quark:limestone:1,15,quark:limestone,15,quark:world_stone_pavement:2,15,CONCRETE:8,100)
Block(-6,45,-1,SMOOTH_STAIRS:0)
RandomBlock(-6,45,4,minecraft:iron_bars:0,5,CONCRETE_POWDER:8,10,quark:limestone:1,15,quark:limestone,15,quark:world_stone_pavement:2,15,CONCRETE:8,100)
Block(-6,46,-6,STONE:6)
Block(-6,46,-5,minecraft:iron_bars:0)
Block(-6,46,-3,CONCRETE:15)
Block(-6,46,4,CONCRETE:15)
Block(-6,47,-6,STONE:6)
Block(-6,47,-5,STONE:6)
Block(-6,47,-4,STONE:6)
RandomBlock(-6,47,-3,minecraft:iron_bars:0,5,CONCRETE_POWDER:8,10,quark:limestone:1,15,quark:limestone,15,quark:world_stone_pavement:2,15,CONCRETE:8,100)
RandomBlock(-6,47,4,minecraft:iron_bars:0,5,CONCRETE_POWDER:8,10,quark:limestone:1,15,quark:limestone,15,quark:world_stone_pavement:2,15,CONCRETE:8,100)
Block(-6,48,-4,STONE:6)
RandomBlock(-6,48,-3,minecraft:iron_bars:0,5,CONCRETE_POWDER:8,10,quark:limestone:1,15,quark:limestone,15,quark:world_stone_pavement:2,15,CONCRETE:8,100)
RandomBlock(-6,48,4,minecraft:iron_bars:0,5,CONCRETE_POWDER:8,10,quark:limestone:1,15,quark:limestone,15,quark:world_stone_pavement:2,15,CONCRETE:8,100)
Block(-6,49,-4,STONE:6)
RandomBlock(-6,49,-3,minecraft:iron_bars:0,5,CONCRETE_POWDER:8,10,quark:limestone:1,15,quark:limestone,15,quark:world_stone_pavement:2,15,CONCRETE:8,100)
RandomBlock(-6,49,4,minecraft:iron_bars:0,5,CONCRETE_POWDER:8,10,quark:limestone:1,15,quark:limestone,15,quark:world_stone_pavement:2,15,CONCRETE:8,100)
RandomBlock(-6,50,-5,minecraft:iron_bars:0,5,CONCRETE_POWDER:8,10,quark:limestone:1,15,quark:limestone,15,quark:world_stone_pavement:2,15,CONCRETE:8,100)
RandomBlock(-6,50,-4,minecraft:iron_bars:0,5,STAINED_CLAY:15,5,STAINED_CLAY:7,5,quark:iron_plate_slab:8,15,quark:world_stone_pavement:2,15,STAINED_CLAY:9,100)
RandomBlock(-6,50,-3,minecraft:iron_bars:0,5,STAINED_CLAY:15,5,STAINED_CLAY:7,5,quark:iron_plate_slab:8,15,quark:world_stone_pavement:2,15,STAINED_CLAY:9,100)
RandomBlock(-6,50,-2,minecraft:iron_bars:0,5,STAINED_CLAY:15,5,STAINED_CLAY:7,5,quark:iron_plate_slab:8,15,quark:world_stone_pavement:2,15,STAINED_CLAY:9,100)
RandomBlock(-6,50,-1,minecraft:iron_bars:0,5,STAINED_CLAY:15,5,STAINED_CLAY:7,5,quark:iron_plate_slab:8,15,quark:world_stone_pavement:2,15,STAINED_CLAY:9,100)
RandomBlock(-6,50,0,minecraft:iron_bars:0,5,STAINED_CLAY:15,5,STAINED_CLAY:7,5,quark:iron_plate_slab:8,15,quark:world_stone_pavement:2,15,STAINED_CLAY:9,100)
RandomBlock(-6,50,1,minecraft:iron_bars:0,5,STAINED_CLAY:15,5,STAINED_CLAY:7,5,quark:iron_plate_slab:8,15,quark:world_stone_pavement:2,15,STAINED_CLAY:9,100)
RandomBlock(-6,50,2,minecraft:iron_bars:0,5,STAINED_CLAY:15,5,STAINED_CLAY:7,5,quark:iron_plate_slab:8,15,quark:world_stone_pavement:2,15,STAINED_CLAY:9,100)
RandomBlock(-6,50,3,minecraft:iron_bars:0,5,STAINED_CLAY:15,5,STAINED_CLAY:7,5,quark:iron_plate_slab:8,15,quark:world_stone_pavement:2,15,STAINED_CLAY:9,100)
RandomBlock(-6,50,4,minecraft:iron_bars:0,5,STAINED_CLAY:15,5,STAINED_CLAY:7,5,quark:iron_plate_slab:8,15,quark:world_stone_pavement:2,15,STAINED_CLAY:9,100)
RandomBlock(-6,50,5,minecraft:iron_bars:0,5,STAINED_CLAY:15,5,STAINED_CLAY:7,5,quark:iron_plate_slab:8,15,quark:world_stone_pavement:2,15,STAINED_CLAY:9,100)
RandomBlock(-6,50,6,minecraft:iron_bars:0,5,STAINED_CLAY:15,5,STAINED_CLAY:7,5,quark:iron_plate_slab:8,15,quark:world_stone_pavement:2,15,STAINED_CLAY:9,100)
RandomBlock(-6,50,7,minecraft:iron_bars:0,5,STAINED_CLAY:15,5,STAINED_CLAY:7,5,quark:iron_plate_slab:8,15,quark:world_stone_pavement:2,15,STAINED_CLAY:9,100)
RandomBlock(-6,50,8,minecraft:iron_bars:0,5,STAINED_CLAY:15,5,STAINED_CLAY:7,5,quark:iron_plate_slab:8,15,quark:world_stone_pavement:2,15,STAINED_CLAY:9,100)
Block(-6,51,-5,minecraft:iron_bars:0)
Block(-6,51,-3,STONE:6)
RandomBlock(-6,51,-2,minecraft:iron_bars:0,5,CONCRETE_POWDER:8,10,quark:limestone:1,15,quark:limestone,15,quark:world_stone_pavement:2,15,CONCRETE:8,100)
Block(-6,51,-1,minecraft:iron_bars:0)
Block(-6,51,0,minecraft:iron_bars:0)
Block(-6,51,2,SMOOTH_STAIRS:6)
RandomBlock(-6,51,3,minecraft:iron_bars:0,5,CONCRETE_POWDER:8,10,quark:limestone:1,15,quark:limestone,15,quark:world_stone_pavement:2,15,CONCRETE:8,100)
Block(-6,52,-5,minecraft:iron_bars:0)
Block(-6,52,-3,STONE:6)
Block(-6,52,-2,CONCRETE:15)
Block(-6,52,3,CONCRETE:15)
Block(-6,53,-3,STONE:6)
RandomBlock(-6,53,-2,minecraft:iron_bars:0,5,CONCRETE_POWDER:8,10,quark:limestone:1,15,quark:limestone,15,quark:world_stone_pavement:2,15,CONCRETE:8,100)
Block(-6,53,2,LEVER:4)
RandomBlock(-6,53,3,minecraft:iron_bars:0,5,CONCRETE_POWDER:8,10,quark:limestone:1,15,quark:limestone,15,quark:world_stone_pavement:2,15,CONCRETE:8,100)
Block(-6,54,-3,STONE:6)
RandomBlock(-6,54,-2,minecraft:iron_bars:0,5,CONCRETE_POWDER:8,10,quark:limestone:1,15,quark:limestone,15,quark:world_stone_pavement:2,15,CONCRETE:8,100)
Block(-6,54,-1,STEP:8)
Block(-6,54,0,STEP:8)
Block(-6,54,1,STEP:8)
Block(-6,54,2,SMOOTH_STAIRS:4)
RandomBlock(-6,54,3,minecraft:iron_bars:0,5,CONCRETE_POWDER:8,10,quark:limestone:1,15,quark:limestone,15,quark:world_stone_pavement:2,15,CONCRETE:8,100)
Block(-6,54,4,STEP:8)
RandomBlock(-6,54,5,minecraft:iron_bars:0,5,CONCRETE_POWDER:8,10,quark:limestone:1,15,quark:limestone,15,quark:world_stone_pavement:2,15,CONCRETE:8,100)
RandomBlock(-6,54,6,minecraft:iron_bars:0,5,CONCRETE_POWDER:8,10,quark:limestone:1,15,quark:limestone,15,quark:world_stone_pavement:2,15,CONCRETE:8,100)
RandomBlock(-6,54,7,minecraft:iron_bars:0,5,CONCRETE_POWDER:8,10,quark:limestone:1,15,quark:limestone,15,quark:world_stone_pavement:2,15,CONCRETE:8,100)
Block(-6,54,8,STEP:8)
Block(-6,55,-3,STONE:6)
RandomBlock(-6,55,-2,minecraft:iron_bars:0,5,CONCRETE_POWDER:8,10,quark:limestone:1,15,quark:limestone,15,quark:world_stone_pavement:2,15,CONCRETE:8,100)
Block(-6,55,-1,LEVER:3)
RandomBlock(-6,55,3,minecraft:iron_bars:0,5,CONCRETE_POWDER:8,10,quark:limestone:1,15,quark:limestone,15,quark:world_stone_pavement:2,15,CONCRETE:8,100)
Block(-6,55,5,minecraft:iron_bars:0)
Block(-6,55,6,minecraft:iron_bars:0)
Block(-6,55,7,minecraft:iron_bars:0)
Block(-6,56,-3,STONE:6)
RandomBlock(-6,56,-2,minecraft:iron_bars:0,5,CONCRETE_POWDER:8,10,quark:limestone:1,15,quark:limestone,15,quark:world_stone_pavement:2,15,CONCRETE:8,100)
Block(-6,56,2,LEVER:4)
RandomBlock(-6,56,3,minecraft:iron_bars:0,5,CONCRETE_POWDER:8,10,quark:limestone:1,15,quark:limestone,15,quark:world_stone_pavement:2,15,CONCRETE:8,100)
Block(-6,56,5,minecraft:iron_bars:0)
Block(-6,56,6,minecraft:iron_bars:0)
Block(-6,56,7,minecraft:iron_bars:0)
Block(-6,57,-3,STONE:6)
RandomBlock(-6,57,-2,minecraft:iron_bars:0,5,CONCRETE_POWDER:8,10,quark:limestone:1,15,quark:limestone,15,quark:world_stone_pavement:2,15,CONCRETE:8,100)
Block(-6,57,-1,STEP:8)
Block(-6,57,0,STEP:8)
Block(-6,57,1,STEP:8)
Block(-6,57,2,STEP:8)
RandomBlock(-6,57,3,minecraft:iron_bars:0,5,CONCRETE_POWDER:8,10,quark:limestone:1,15,quark:limestone,15,quark:world_stone_pavement:2,15,CONCRETE:8,100)
Block(-6,57,4,minecraft:iron_bars:0)
Block(-6,57,5,minecraft:iron_bars:0)
Block(-6,58,-2,minecraft:iron_bars:0)
Block(-6,58,3,minecraft:iron_bars:0)
Block(-6,58,4,minecraft:iron_bars:0)
Block(-6,58,5,minecraft:iron_bars:0)
Block(-6,59,-2,minecraft:iron_bars:0)
Block(-6,59,3,minecraft:iron_bars:0)
Block(-6,59,4,minecraft:iron_bars:0)
Block(-6,59,5,minecraft:iron_bars:0)
Block(-6,60,-4,STEP:13)
Block(-6,60,-3,STEP:13)
Block(-6,60,-2,STEP:13)
Block(-6,60,-1,STEP:13)
Block(-6,60,0,STEP:13)
Block(-6,60,1,STEP:13)
Block(-6,60,2,STEP:13)
Block(-6,60,3,STEP:13)
Block(-6,60,4,STEP:13)
RandomBlock(-6,61,-4,CONCRETE_POWDER:7,25,CONCRETE:7,100)
Block(-6,61,-3,STAINED_CLAY:4)
Block(-6,61,-2,STAINED_CLAY:4)
Block(-6,61,-1,STAINED_CLAY:4)
Block(-6,61,0,STAINED_CLAY:4)
Block(-6,61,1,STAINED_CLAY:4)
Block(-6,61,2,STAINED_CLAY:4)
Block(-6,61,3,STAINED_CLAY:4)
RandomBlock(-6,61,4,CONCRETE_POWDER:7,25,CONCRETE:7,100)
Block(-6,62,-5,IRON_FENCE:0)
Block(-6,62,-4,IRON_FENCE:0)
Block(-6,62,4,IRON_FENCE:0)
Block(-6,62,5,IRON_FENCE:0)
RandomBlock(-5,0,0,minecraft:iron_bars:0,5,quark:iron_plate:1,15,STAINED_CLAY:15,15,STAINED_CLAY:7,100)
RandomBlock(-5,0,1,minecraft:iron_bars:0,5,quark:iron_plate:1,15,STAINED_CLAY:15,15,STAINED_CLAY:7,100)
RandomBlock(-5,0,2,minecraft:iron_bars:0,5,quark:iron_plate:1,15,STAINED_CLAY:15,15,STAINED_CLAY:7,100)
RandomBlock(-5,0,3,minecraft:iron_bars:0,5,quark:iron_plate:1,15,STAINED_CLAY:15,15,STAINED_CLAY:7,100)
RandomBlock(-5,0,4,minecraft:iron_bars:0,5,quark:iron_plate:1,15,STAINED_CLAY:15,15,STAINED_CLAY:7,100)
RandomBlock(-5,0,5,minecraft:iron_bars:0,5,quark:iron_plate:1,15,STAINED_CLAY:15,15,STAINED_CLAY:7,100)
RandomBlock(-5,1,0,minecraft:iron_bars:0,5,quark:iron_plate:1,15,STAINED_CLAY:15,15,STAINED_CLAY:7,100)
RandomBlock(-5,1,1,minecraft:iron_bars:0,5,quark:iron_plate:1,15,STAINED_CLAY:15,15,STAINED_CLAY:7,100)
RandomBlock(-5,1,2,minecraft:iron_bars:0,5,quark:iron_plate:1,15,STAINED_CLAY:15,15,STAINED_CLAY:7,100)
RandomBlock(-5,1,3,minecraft:iron_bars:0,5,quark:iron_plate:1,15,STAINED_CLAY:15,15,STAINED_CLAY:7,100)
RandomBlock(-5,1,4,minecraft:iron_bars:0,5,quark:iron_plate:1,15,STAINED_CLAY:15,15,STAINED_CLAY:7,100)
RandomBlock(-5,1,5,minecraft:iron_bars:0,5,quark:iron_plate:1,15,STAINED_CLAY:15,15,STAINED_CLAY:7,100)
RandomBlock(-5,2,0,minecraft:iron_bars:0,5,quark:iron_plate:1,15,STAINED_CLAY:15,15,STAINED_CLAY:7,100)
RandomBlock(-5,2,1,minecraft:iron_bars:0,5,quark:iron_plate:1,15,STAINED_CLAY:15,15,STAINED_CLAY:7,100)
RandomBlock(-5,2,2,minecraft:iron_bars:0,5,quark:iron_plate:1,15,STAINED_CLAY:15,15,STAINED_CLAY:7,100)
RandomBlock(-5,2,3,minecraft:iron_bars:0,5,quark:iron_plate:1,15,STAINED_CLAY:15,15,STAINED_CLAY:7,100)
RandomBlock(-5,2,4,minecraft:iron_bars:0,5,quark:iron_plate:1,15,STAINED_CLAY:15,15,STAINED_CLAY:7,100)
RandomBlock(-5,2,5,minecraft:iron_bars:0,5,quark:iron_plate:1,15,STAINED_CLAY:15,15,STAINED_CLAY:7,100)
RandomBlock(-5,3,0,minecraft:iron_bars:0,5,quark:iron_plate:1,15,STAINED_CLAY:15,15,STAINED_CLAY:7,100)
RandomBlock(-5,3,1,minecraft:iron_bars:0,5,quark:iron_plate:1,15,STAINED_CLAY:15,15,STAINED_CLAY:7,100)
RandomBlock(-5,3,2,minecraft:iron_bars:0,5,quark:iron_plate:1,15,STAINED_CLAY:15,15,STAINED_CLAY:7,100)
RandomBlock(-5,3,3,minecraft:iron_bars:0,5,quark:iron_plate:1,15,STAINED_CLAY:15,15,STAINED_CLAY:7,100)
RandomBlock(-5,3,4,minecraft:iron_bars:0,5,quark:iron_plate:1,15,STAINED_CLAY:15,15,STAINED_CLAY:7,100)
RandomBlock(-5,3,5,minecraft:iron_bars:0,5,quark:iron_plate:1,15,STAINED_CLAY:15,15,STAINED_CLAY:7,100)
RandomBlock(-5,4,0,minecraft:iron_bars:0,5,quark:iron_plate:1,15,STAINED_CLAY:15,15,STAINED_CLAY:7,100)
RandomBlock(-5,4,1,minecraft:iron_bars:0,5,quark:iron_plate:1,15,STAINED_CLAY:15,15,STAINED_CLAY:7,100)
RandomBlock(-5,4,2,minecraft:iron_bars:0,5,quark:iron_plate:1,15,STAINED_CLAY:15,15,STAINED_CLAY:7,100)
RandomBlock(-5,4,3,minecraft:iron_bars:0,5,quark:iron_plate:1,15,STAINED_CLAY:15,15,STAINED_CLAY:7,100)
RandomBlock(-5,4,4,minecraft:iron_bars:0,5,quark:iron_plate:1,15,STAINED_CLAY:15,15,STAINED_CLAY:7,100)
RandomBlock(-5,4,5,minecraft:iron_bars:0,5,quark:iron_plate:1,15,STAINED_CLAY:15,15,STAINED_CLAY:7,100)
RandomBlock(-5,5,0,minecraft:iron_bars:0,5,quark:iron_plate:1,15,STAINED_CLAY:15,15,STAINED_CLAY:7,100)
RandomBlock(-5,5,1,minecraft:iron_bars:0,5,quark:iron_plate:1,15,STAINED_CLAY:15,15,STAINED_CLAY:7,100)
RandomBlock(-5,5,2,minecraft:iron_bars:0,5,quark:iron_plate:1,15,STAINED_CLAY:15,15,STAINED_CLAY:7,100)
RandomBlock(-5,5,3,minecraft:iron_bars:0,5,quark:iron_plate:1,15,STAINED_CLAY:15,15,STAINED_CLAY:7,100)
RandomBlock(-5,5,4,minecraft:iron_bars:0,5,quark:iron_plate:1,15,STAINED_CLAY:15,15,STAINED_CLAY:7,100)
RandomBlock(-5,5,5,minecraft:iron_bars:0,5,quark:iron_plate:1,15,STAINED_CLAY:15,15,STAINED_CLAY:7,100)
RandomBlock(-5,6,0,minecraft:iron_bars:0,5,quark:iron_plate:1,15,STAINED_CLAY:15,15,STAINED_CLAY:7,100)
RandomBlock(-5,6,1,minecraft:iron_bars:0,5,quark:iron_plate:1,15,STAINED_CLAY:15,15,STAINED_CLAY:7,100)
RandomBlock(-5,6,2,minecraft:iron_bars:0,5,quark:iron_plate:1,15,STAINED_CLAY:15,15,STAINED_CLAY:7,100)
RandomBlock(-5,6,3,minecraft:iron_bars:0,5,quark:iron_plate:1,15,STAINED_CLAY:15,15,STAINED_CLAY:7,100)
RandomBlock(-5,6,4,minecraft:iron_bars:0,5,quark:iron_plate:1,15,STAINED_CLAY:15,15,STAINED_CLAY:7,100)
RandomBlock(-5,6,5,minecraft:iron_bars:0,5,quark:iron_plate:1,15,STAINED_CLAY:15,15,STAINED_CLAY:7,100)
RandomBlock(-5,7,0,minecraft:iron_bars:0,5,quark:iron_plate:1,15,STAINED_CLAY:15,15,STAINED_CLAY:7,100)
RandomBlock(-5,7,1,minecraft:iron_bars:0,5,quark:iron_plate:1,15,STAINED_CLAY:15,15,STAINED_CLAY:7,100)
RandomBlock(-5,7,2,minecraft:iron_bars:0,5,quark:iron_plate:1,15,STAINED_CLAY:15,15,STAINED_CLAY:7,100)
RandomBlock(-5,7,3,minecraft:iron_bars:0,5,quark:iron_plate:1,15,STAINED_CLAY:15,15,STAINED_CLAY:7,100)
RandomBlock(-5,7,4,minecraft:iron_bars:0,5,quark:iron_plate:1,15,STAINED_CLAY:15,15,STAINED_CLAY:7,100)
RandomBlock(-5,7,5,minecraft:iron_bars:0,5,quark:iron_plate:1,15,STAINED_CLAY:15,15,STAINED_CLAY:7,100)
RandomBlock(-5,8,0,minecraft:iron_bars:0,5,quark:iron_plate:1,15,STAINED_CLAY:15,15,STAINED_CLAY:7,100)
RandomBlock(-5,8,1,minecraft:iron_bars:0,5,quark:iron_plate:1,15,STAINED_CLAY:15,15,STAINED_CLAY:7,100)
RandomBlock(-5,8,2,minecraft:iron_bars:0,5,quark:iron_plate:1,15,STAINED_CLAY:15,15,STAINED_CLAY:7,100)
RandomBlock(-5,8,3,minecraft:iron_bars:0,5,quark:iron_plate:1,15,STAINED_CLAY:15,15,STAINED_CLAY:7,100)
RandomBlock(-5,8,4,minecraft:iron_bars:0,5,quark:iron_plate:1,15,STAINED_CLAY:15,15,STAINED_CLAY:7,100)
RandomBlock(-5,8,5,minecraft:iron_bars:0,5,quark:iron_plate:1,15,STAINED_CLAY:15,15,STAINED_CLAY:7,100)
RandomBlock(-5,9,0,minecraft:iron_bars:0,5,quark:iron_plate:1,15,STAINED_CLAY:15,15,STAINED_CLAY:7,100)
RandomBlock(-5,9,1,minecraft:iron_bars:0,5,quark:iron_plate:1,15,STAINED_CLAY:15,15,STAINED_CLAY:7,100)
RandomBlock(-5,9,2,minecraft:iron_bars:0,5,quark:iron_plate:1,15,STAINED_CLAY:15,15,STAINED_CLAY:7,100)
RandomBlock(-5,9,3,minecraft:iron_bars:0,5,quark:iron_plate:1,15,STAINED_CLAY:15,15,STAINED_CLAY:7,100)
RandomBlock(-5,9,4,minecraft:iron_bars:0,5,quark:iron_plate:1,15,STAINED_CLAY:15,15,STAINED_CLAY:7,100)
RandomBlock(-5,9,5,minecraft:iron_bars:0,5,quark:iron_plate:1,15,STAINED_CLAY:15,15,STAINED_CLAY:7,100)
RandomBlock(-5,10,0,minecraft:iron_bars:0,5,quark:iron_plate:1,15,STAINED_CLAY:15,15,STAINED_CLAY:7,100)
RandomBlock(-5,10,1,minecraft:iron_bars:0,5,quark:iron_plate:1,15,STAINED_CLAY:15,15,STAINED_CLAY:7,100)
RandomBlock(-5,10,2,minecraft:iron_bars:0,5,quark:iron_plate:1,15,STAINED_CLAY:15,15,STAINED_CLAY:7,100)
RandomBlock(-5,10,3,minecraft:iron_bars:0,5,quark:iron_plate:1,15,STAINED_CLAY:15,15,STAINED_CLAY:7,100)
RandomBlock(-5,10,4,minecraft:iron_bars:0,5,quark:iron_plate:1,15,STAINED_CLAY:15,15,STAINED_CLAY:7,100)
RandomBlock(-5,10,5,minecraft:iron_bars:0,5,quark:iron_plate:1,15,STAINED_CLAY:15,15,STAINED_CLAY:7,100)
RandomBlock(-5,11,0,minecraft:iron_bars:0,5,quark:iron_plate:1,15,STAINED_CLAY:15,15,STAINED_CLAY:7,100)
RandomBlock(-5,11,1,minecraft:iron_bars:0,5,quark:iron_plate:1,15,STAINED_CLAY:15,15,STAINED_CLAY:7,100)
RandomBlock(-5,11,2,minecraft:iron_bars:0,5,quark:iron_plate:1,15,STAINED_CLAY:15,15,STAINED_CLAY:7,100)
RandomBlock(-5,11,3,minecraft:iron_bars:0,5,quark:iron_plate:1,15,STAINED_CLAY:15,15,STAINED_CLAY:7,100)
RandomBlock(-5,11,4,minecraft:iron_bars:0,5,quark:iron_plate:1,15,STAINED_CLAY:15,15,STAINED_CLAY:7,100)
RandomBlock(-5,11,5,minecraft:iron_bars:0,5,quark:iron_plate:1,15,STAINED_CLAY:15,15,STAINED_CLAY:7,100)
RandomBlock(-5,12,0,minecraft:iron_bars:0,5,quark:iron_plate:1,15,STAINED_CLAY:15,15,STAINED_CLAY:7,100)
RandomBlock(-5,12,1,minecraft:iron_bars:0,5,quark:iron_plate:1,15,STAINED_CLAY:15,15,STAINED_CLAY:7,100)
RandomBlock(-5,12,2,minecraft:iron_bars:0,5,quark:iron_plate:1,15,STAINED_CLAY:15,15,STAINED_CLAY:7,100)
RandomBlock(-5,12,3,minecraft:iron_bars:0,5,quark:iron_plate:1,15,STAINED_CLAY:15,15,STAINED_CLAY:7,100)
RandomBlock(-5,12,4,minecraft:iron_bars:0,5,quark:iron_plate:1,15,STAINED_CLAY:15,15,STAINED_CLAY:7,100)
RandomBlock(-5,12,5,minecraft:iron_bars:0,5,quark:iron_plate:1,15,STAINED_CLAY:15,15,STAINED_CLAY:7,100)
RandomBlock(-5,13,0,minecraft:iron_bars:0,5,quark:iron_plate:1,15,STAINED_CLAY:15,15,STAINED_CLAY:7,100)
RandomBlock(-5,13,1,minecraft:iron_bars:0,5,quark:iron_plate:1,15,STAINED_CLAY:15,15,STAINED_CLAY:7,100)
RandomBlock(-5,13,2,minecraft:iron_bars:0,5,quark:iron_plate:1,15,STAINED_CLAY:15,15,STAINED_CLAY:7,100)
RandomBlock(-5,13,3,minecraft:iron_bars:0,5,quark:iron_plate:1,15,STAINED_CLAY:15,15,STAINED_CLAY:7,100)
RandomBlock(-5,13,4,minecraft:iron_bars:0,5,quark:iron_plate:1,15,STAINED_CLAY:15,15,STAINED_CLAY:7,100)
RandomBlock(-5,13,5,minecraft:iron_bars:0,5,quark:iron_plate:1,15,STAINED_CLAY:15,15,STAINED_CLAY:7,100)
RandomBlock(-5,14,0,minecraft:iron_bars:0,5,quark:iron_plate:1,15,STAINED_CLAY:15,15,STAINED_CLAY:7,100)
RandomBlock(-5,14,1,minecraft:iron_bars:0,5,quark:iron_plate:1,15,STAINED_CLAY:15,15,STAINED_CLAY:7,100)
RandomBlock(-5,14,2,minecraft:iron_bars:0,5,quark:iron_plate:1,15,STAINED_CLAY:15,15,STAINED_CLAY:7,100)
RandomBlock(-5,14,3,minecraft:iron_bars:0,5,quark:iron_plate:1,15,STAINED_CLAY:15,15,STAINED_CLAY:7,100)
RandomBlock(-5,14,4,minecraft:iron_bars:0,5,quark:iron_plate:1,15,STAINED_CLAY:15,15,STAINED_CLAY:7,100)
RandomBlock(-5,14,5,minecraft:iron_bars:0,5,quark:iron_plate:1,15,STAINED_CLAY:15,15,STAINED_CLAY:7,100)
RandomBlock(-5,15,0,minecraft:iron_bars:0,5,quark:iron_plate:1,15,STAINED_CLAY:15,15,STAINED_CLAY:7,100)
RandomBlock(-5,15,1,minecraft:iron_bars:0,5,quark:iron_plate:1,15,STAINED_CLAY:15,15,STAINED_CLAY:7,100)
RandomBlock(-5,15,2,minecraft:iron_bars:0,5,quark:iron_plate:1,15,STAINED_CLAY:15,15,STAINED_CLAY:7,100)
RandomBlock(-5,15,3,minecraft:iron_bars:0,5,quark:iron_plate:1,15,STAINED_CLAY:15,15,STAINED_CLAY:7,100)
RandomBlock(-5,15,4,minecraft:iron_bars:0,5,quark:iron_plate:1,15,STAINED_CLAY:15,15,STAINED_CLAY:7,100)
RandomBlock(-5,15,5,minecraft:iron_bars:0,5,quark:iron_plate:1,15,STAINED_CLAY:15,15,STAINED_CLAY:7,100)
RandomBlock(-5,16,0,minecraft:iron_bars:0,5,quark:iron_plate:1,15,STAINED_CLAY:15,15,STAINED_CLAY:7,100)
RandomBlock(-5,16,1,minecraft:iron_bars:0,5,quark:iron_plate:1,15,STAINED_CLAY:15,15,STAINED_CLAY:7,100)
RandomBlock(-5,16,2,minecraft:iron_bars:0,5,quark:iron_plate:1,15,STAINED_CLAY:15,15,STAINED_CLAY:7,100)
RandomBlock(-5,16,3,minecraft:iron_bars:0,5,quark:iron_plate:1,15,STAINED_CLAY:15,15,STAINED_CLAY:7,100)
RandomBlock(-5,16,4,minecraft:iron_bars:0,5,quark:iron_plate:1,15,STAINED_CLAY:15,15,STAINED_CLAY:7,100)
RandomBlock(-5,16,5,minecraft:iron_bars:0,5,quark:iron_plate:1,15,STAINED_CLAY:15,15,STAINED_CLAY:7,100)
RandomBlock(-5,17,0,minecraft:iron_bars:0,5,quark:iron_plate:1,15,STAINED_CLAY:15,15,STAINED_CLAY:7,100)
RandomBlock(-5,17,1,minecraft:iron_bars:0,5,quark:iron_plate:1,15,STAINED_CLAY:15,15,STAINED_CLAY:7,100)
RandomBlock(-5,17,2,minecraft:iron_bars:0,5,quark:iron_plate:1,15,STAINED_CLAY:15,15,STAINED_CLAY:7,100)
RandomBlock(-5,17,3,minecraft:iron_bars:0,5,quark:iron_plate:1,15,STAINED_CLAY:15,15,STAINED_CLAY:7,100)
RandomBlock(-5,17,4,minecraft:iron_bars:0,5,quark:iron_plate:1,15,STAINED_CLAY:15,15,STAINED_CLAY:7,100)
RandomBlock(-5,17,5,minecraft:iron_bars:0,5,quark:iron_plate:1,15,STAINED_CLAY:15,15,STAINED_CLAY:7,100)
RandomBlock(-5,18,0,minecraft:iron_bars:0,5,quark:iron_plate:1,15,STAINED_CLAY:15,15,STAINED_CLAY:7,100)
RandomBlock(-5,18,1,minecraft:iron_bars:0,5,quark:iron_plate:1,15,STAINED_CLAY:15,15,STAINED_CLAY:7,100)
RandomBlock(-5,18,2,minecraft:iron_bars:0,5,quark:iron_plate:1,15,STAINED_CLAY:15,15,STAINED_CLAY:7,100)
RandomBlock(-5,18,3,minecraft:iron_bars:0,5,quark:iron_plate:1,15,STAINED_CLAY:15,15,STAINED_CLAY:7,100)
RandomBlock(-5,18,4,minecraft:iron_bars:0,5,quark:iron_plate:1,15,STAINED_CLAY:15,15,STAINED_CLAY:7,100)
RandomBlock(-5,18,5,minecraft:iron_bars:0,5,quark:iron_plate:1,15,STAINED_CLAY:15,15,STAINED_CLAY:7,100)
RandomBlock(-5,19,0,minecraft:iron_bars:0,5,quark:iron_plate:1,15,STAINED_CLAY:15,15,STAINED_CLAY:7,100)
RandomBlock(-5,19,1,minecraft:iron_bars:0,5,quark:iron_plate:1,15,STAINED_CLAY:15,15,STAINED_CLAY:7,100)
RandomBlock(-5,19,2,minecraft:iron_bars:0,5,quark:iron_plate:1,15,STAINED_CLAY:15,15,STAINED_CLAY:7,100)
RandomBlock(-5,19,3,minecraft:iron_bars:0,5,quark:iron_plate:1,15,STAINED_CLAY:15,15,STAINED_CLAY:7,100)
RandomBlock(-5,19,4,minecraft:iron_bars:0,5,quark:iron_plate:1,15,STAINED_CLAY:15,15,STAINED_CLAY:7,100)
RandomBlock(-5,19,5,minecraft:iron_bars:0,5,quark:iron_plate:1,15,STAINED_CLAY:15,15,STAINED_CLAY:7,100)
RandomBlock(-5,20,0,minecraft:iron_bars:0,5,quark:iron_plate:1,15,STAINED_CLAY:15,15,STAINED_CLAY:7,100)
RandomBlock(-5,20,1,minecraft:iron_bars:0,5,quark:iron_plate:1,15,STAINED_CLAY:15,15,STAINED_CLAY:7,100)
RandomBlock(-5,20,2,minecraft:iron_bars:0,5,quark:iron_plate:1,15,STAINED_CLAY:15,15,STAINED_CLAY:7,100)
RandomBlock(-5,20,3,minecraft:iron_bars:0,5,quark:iron_plate:1,15,STAINED_CLAY:15,15,STAINED_CLAY:7,100)
RandomBlock(-5,20,4,minecraft:iron_bars:0,5,quark:iron_plate:1,15,STAINED_CLAY:15,15,STAINED_CLAY:7,100)
RandomBlock(-5,20,5,minecraft:iron_bars:0,5,quark:iron_plate:1,15,STAINED_CLAY:15,15,STAINED_CLAY:7,100)
RandomBlock(-5,21,0,minecraft:iron_bars:0,5,quark:iron_plate:1,15,STAINED_CLAY:15,15,STAINED_CLAY:7,100)
RandomBlock(-5,21,1,minecraft:iron_bars:0,5,quark:iron_plate:1,15,STAINED_CLAY:15,15,STAINED_CLAY:7,100)
RandomBlock(-5,21,2,minecraft:iron_bars:0,5,quark:iron_plate:1,15,STAINED_CLAY:15,15,STAINED_CLAY:7,100)
RandomBlock(-5,21,3,minecraft:iron_bars:0,5,quark:iron_plate:1,15,STAINED_CLAY:15,15,STAINED_CLAY:7,100)
RandomBlock(-5,21,4,minecraft:iron_bars:0,5,quark:iron_plate:1,15,STAINED_CLAY:15,15,STAINED_CLAY:7,100)
RandomBlock(-5,21,5,minecraft:iron_bars:0,5,quark:iron_plate:1,15,STAINED_CLAY:15,15,STAINED_CLAY:7,100)
RandomBlock(-5,22,0,minecraft:iron_bars:0,5,quark:iron_plate:1,15,STAINED_CLAY:15,15,STAINED_CLAY:7,100)
RandomBlock(-5,22,1,minecraft:iron_bars:0,5,quark:iron_plate:1,15,STAINED_CLAY:15,15,STAINED_CLAY:7,100)
RandomBlock(-5,22,2,minecraft:iron_bars:0,5,quark:iron_plate:1,15,STAINED_CLAY:15,15,STAINED_CLAY:7,100)
RandomBlock(-5,22,3,minecraft:iron_bars:0,5,quark:iron_plate:1,15,STAINED_CLAY:15,15,STAINED_CLAY:7,100)
RandomBlock(-5,22,4,minecraft:iron_bars:0,5,quark:iron_plate:1,15,STAINED_CLAY:15,15,STAINED_CLAY:7,100)
RandomBlock(-5,22,5,minecraft:iron_bars:0,5,quark:iron_plate:1,15,STAINED_CLAY:15,15,STAINED_CLAY:7,100)
RandomBlock(-5,23,0,minecraft:iron_bars:0,5,quark:iron_plate:1,15,STAINED_CLAY:15,15,STAINED_CLAY:7,100)
RandomBlock(-5,23,1,minecraft:iron_bars:0,5,quark:iron_plate:1,15,STAINED_CLAY:15,15,STAINED_CLAY:7,100)
RandomBlock(-5,23,2,minecraft:iron_bars:0,5,quark:iron_plate:1,15,STAINED_CLAY:15,15,STAINED_CLAY:7,100)
RandomBlock(-5,23,3,minecraft:iron_bars:0,5,quark:iron_plate:1,15,STAINED_CLAY:15,15,STAINED_CLAY:7,100)
RandomBlock(-5,23,4,minecraft:iron_bars:0,5,quark:iron_plate:1,15,STAINED_CLAY:15,15,STAINED_CLAY:7,100)
RandomBlock(-5,23,5,minecraft:iron_bars:0,5,quark:iron_plate:1,15,STAINED_CLAY:15,15,STAINED_CLAY:7,100)
RandomBlock(-5,24,0,minecraft:iron_bars:0,5,quark:iron_plate:1,15,STAINED_CLAY:15,15,STAINED_CLAY:7,100)
RandomBlock(-5,24,1,minecraft:iron_bars:0,5,quark:iron_plate:1,15,STAINED_CLAY:15,15,STAINED_CLAY:7,100)
RandomBlock(-5,24,2,minecraft:iron_bars:0,5,quark:iron_plate:1,15,STAINED_CLAY:15,15,STAINED_CLAY:7,100)
RandomBlock(-5,24,3,minecraft:iron_bars:0,5,quark:iron_plate:1,15,STAINED_CLAY:15,15,STAINED_CLAY:7,100)
RandomBlock(-5,24,4,minecraft:iron_bars:0,5,quark:iron_plate:1,15,STAINED_CLAY:15,15,STAINED_CLAY:7,100)
RandomBlock(-5,24,5,minecraft:iron_bars:0,5,quark:iron_plate:1,15,STAINED_CLAY:15,15,STAINED_CLAY:7,100)
RandomBlock(-5,25,0,minecraft:iron_bars:0,5,quark:iron_plate:1,15,STAINED_CLAY:15,15,STAINED_CLAY:7,100)
RandomBlock(-5,25,1,minecraft:iron_bars:0,5,quark:iron_plate:1,15,STAINED_CLAY:15,15,STAINED_CLAY:7,100)
RandomBlock(-5,25,2,minecraft:iron_bars:0,5,quark:iron_plate:1,15,STAINED_CLAY:15,15,STAINED_CLAY:7,100)
RandomBlock(-5,25,3,minecraft:iron_bars:0,5,quark:iron_plate:1,15,STAINED_CLAY:15,15,STAINED_CLAY:7,100)
RandomBlock(-5,25,4,minecraft:iron_bars:0,5,quark:iron_plate:1,15,STAINED_CLAY:15,15,STAINED_CLAY:7,100)
RandomBlock(-5,25,5,minecraft:iron_bars:0,5,quark:iron_plate:1,15,STAINED_CLAY:15,15,STAINED_CLAY:7,100)
RandomBlock(-5,26,0,minecraft:iron_bars:0,5,quark:iron_plate:1,15,STAINED_CLAY:15,15,STAINED_CLAY:7,100)
RandomBlock(-5,26,1,minecraft:iron_bars:0,5,quark:iron_plate:1,15,STAINED_CLAY:15,15,STAINED_CLAY:7,100)
RandomBlock(-5,26,2,minecraft:iron_bars:0,5,quark:iron_plate:1,15,STAINED_CLAY:15,15,STAINED_CLAY:7,100)
RandomBlock(-5,26,3,minecraft:iron_bars:0,5,quark:iron_plate:1,15,STAINED_CLAY:15,15,STAINED_CLAY:7,100)
RandomBlock(-5,26,4,minecraft:iron_bars:0,5,quark:iron_plate:1,15,STAINED_CLAY:15,15,STAINED_CLAY:7,100)
RandomBlock(-5,26,5,minecraft:iron_bars:0,5,quark:iron_plate:1,15,STAINED_CLAY:15,15,STAINED_CLAY:7,100)
RandomBlock(-5,27,0,minecraft:iron_bars:0,5,quark:iron_plate:1,15,STAINED_CLAY:15,15,STAINED_CLAY:7,100)
RandomBlock(-5,27,1,minecraft:iron_bars:0,5,quark:iron_plate:1,15,STAINED_CLAY:15,15,STAINED_CLAY:7,100)
RandomBlock(-5,27,2,minecraft:iron_bars:0,5,quark:iron_plate:1,15,STAINED_CLAY:15,15,STAINED_CLAY:7,100)
RandomBlock(-5,27,3,minecraft:iron_bars:0,5,quark:iron_plate:1,15,STAINED_CLAY:15,15,STAINED_CLAY:7,100)
RandomBlock(-5,27,4,minecraft:iron_bars:0,5,quark:iron_plate:1,15,STAINED_CLAY:15,15,STAINED_CLAY:7,100)
RandomBlock(-5,27,5,minecraft:iron_bars:0,5,quark:iron_plate:1,15,STAINED_CLAY:15,15,STAINED_CLAY:7,100)
RandomBlock(-5,28,0,minecraft:iron_bars:0,5,quark:iron_plate:1,15,STAINED_CLAY:15,15,STAINED_CLAY:7,100)
RandomBlock(-5,28,1,minecraft:iron_bars:0,5,quark:iron_plate:1,15,STAINED_CLAY:15,15,STAINED_CLAY:7,100)
RandomBlock(-5,28,2,minecraft:iron_bars:0,5,quark:iron_plate:1,15,STAINED_CLAY:15,15,STAINED_CLAY:7,100)
RandomBlock(-5,28,3,minecraft:iron_bars:0,5,quark:iron_plate:1,15,STAINED_CLAY:15,15,STAINED_CLAY:7,100)
RandomBlock(-5,28,4,minecraft:iron_bars:0,5,quark:iron_plate:1,15,STAINED_CLAY:15,15,STAINED_CLAY:7,100)
RandomBlock(-5,28,5,minecraft:iron_bars:0,5,quark:iron_plate:1,15,STAINED_CLAY:15,15,STAINED_CLAY:7,100)
RandomBlock(-5,29,0,minecraft:iron_bars:0,5,quark:iron_plate:1,15,STAINED_CLAY:15,15,STAINED_CLAY:7,100)
RandomBlock(-5,29,1,minecraft:iron_bars:0,5,quark:iron_plate:1,15,STAINED_CLAY:15,15,STAINED_CLAY:7,100)
RandomBlock(-5,29,2,minecraft:iron_bars:0,5,quark:iron_plate:1,15,STAINED_CLAY:15,15,STAINED_CLAY:7,100)
RandomBlock(-5,29,3,minecraft:iron_bars:0,5,quark:iron_plate:1,15,STAINED_CLAY:15,15,STAINED_CLAY:7,100)
RandomBlock(-5,29,4,minecraft:iron_bars:0,5,quark:iron_plate:1,15,STAINED_CLAY:15,15,STAINED_CLAY:7,100)
RandomBlock(-5,29,5,minecraft:iron_bars:0,5,quark:iron_plate:1,15,STAINED_CLAY:15,15,STAINED_CLAY:7,100)
RandomBlock(-5,30,0,minecraft:iron_bars:0,5,quark:iron_plate:1,15,STAINED_CLAY:15,15,STAINED_CLAY:7,100)
RandomBlock(-5,30,1,minecraft:iron_bars:0,5,quark:iron_plate:1,15,STAINED_CLAY:15,15,STAINED_CLAY:7,100)
RandomBlock(-5,30,2,minecraft:iron_bars:0,5,quark:iron_plate:1,15,STAINED_CLAY:15,15,STAINED_CLAY:7,100)
RandomBlock(-5,30,3,minecraft:iron_bars:0,5,quark:iron_plate:1,15,STAINED_CLAY:15,15,STAINED_CLAY:7,100)
RandomBlock(-5,30,4,minecraft:iron_bars:0,5,quark:iron_plate:1,15,STAINED_CLAY:15,15,STAINED_CLAY:7,100)
RandomBlock(-5,30,5,minecraft:iron_bars:0,5,quark:iron_plate:1,15,STAINED_CLAY:15,15,STAINED_CLAY:7,100)
RandomBlock(-5,31,0,minecraft:iron_bars:0,5,quark:iron_plate:1,15,STAINED_CLAY:15,15,STAINED_CLAY:7,100)
RandomBlock(-5,31,1,minecraft:iron_bars:0,5,quark:iron_plate:1,15,STAINED_CLAY:15,15,STAINED_CLAY:7,100)
RandomBlock(-5,31,2,minecraft:iron_bars:0,5,quark:iron_plate:1,15,STAINED_CLAY:15,15,STAINED_CLAY:7,100)
RandomBlock(-5,31,3,minecraft:iron_bars:0,5,quark:iron_plate:1,15,STAINED_CLAY:15,15,STAINED_CLAY:7,100)
RandomBlock(-5,31,4,minecraft:iron_bars:0,5,quark:iron_plate:1,15,STAINED_CLAY:15,15,STAINED_CLAY:7,100)
RandomBlock(-5,31,5,minecraft:iron_bars:0,5,quark:iron_plate:1,15,STAINED_CLAY:15,15,STAINED_CLAY:7,100)
RandomBlock(-5,32,0,minecraft:iron_bars:0,5,quark:iron_plate:1,15,STAINED_CLAY:15,15,STAINED_CLAY:7,100)
RandomBlock(-5,32,1,minecraft:iron_bars:0,5,quark:iron_plate:1,15,STAINED_CLAY:15,15,STAINED_CLAY:7,100)
RandomBlock(-5,32,2,minecraft:iron_bars:0,5,quark:iron_plate:1,15,STAINED_CLAY:15,15,STAINED_CLAY:7,100)
RandomBlock(-5,32,3,minecraft:iron_bars:0,5,quark:iron_plate:1,15,STAINED_CLAY:15,15,STAINED_CLAY:7,100)
RandomBlock(-5,32,4,minecraft:iron_bars:0,5,quark:iron_plate:1,15,STAINED_CLAY:15,15,STAINED_CLAY:7,100)
RandomBlock(-5,32,5,minecraft:iron_bars:0,5,quark:iron_plate:1,15,STAINED_CLAY:15,15,STAINED_CLAY:7,100)
RandomBlock(-5,33,0,minecraft:iron_bars:0,5,quark:iron_plate:1,15,STAINED_CLAY:15,15,STAINED_CLAY:7,100)
RandomBlock(-5,33,1,minecraft:iron_bars:0,5,quark:iron_plate:1,15,STAINED_CLAY:15,15,STAINED_CLAY:7,100)
RandomBlock(-5,33,2,minecraft:iron_bars:0,5,quark:iron_plate:1,15,STAINED_CLAY:15,15,STAINED_CLAY:7,100)
RandomBlock(-5,33,3,minecraft:iron_bars:0,5,quark:iron_plate:1,15,STAINED_CLAY:15,15,STAINED_CLAY:7,100)
RandomBlock(-5,33,4,minecraft:iron_bars:0,5,quark:iron_plate:1,15,STAINED_CLAY:15,15,STAINED_CLAY:7,100)
RandomBlock(-5,33,5,minecraft:iron_bars:0,5,quark:iron_plate:1,15,STAINED_CLAY:15,15,STAINED_CLAY:7,100)
RandomBlock(-5,34,0,minecraft:iron_bars:0,5,quark:iron_plate:1,15,STAINED_CLAY:15,15,STAINED_CLAY:7,100)
RandomBlock(-5,34,1,minecraft:iron_bars:0,5,quark:iron_plate:1,15,STAINED_CLAY:15,15,STAINED_CLAY:7,100)
RandomBlock(-5,34,2,minecraft:iron_bars:0,5,quark:iron_plate:1,15,STAINED_CLAY:15,15,STAINED_CLAY:7,100)
RandomBlock(-5,34,3,minecraft:iron_bars:0,5,quark:iron_plate:1,15,STAINED_CLAY:15,15,STAINED_CLAY:7,100)
RandomBlock(-5,34,4,minecraft:iron_bars:0,5,quark:iron_plate:1,15,STAINED_CLAY:15,15,STAINED_CLAY:7,100)
RandomBlock(-5,34,5,minecraft:iron_bars:0,5,quark:iron_plate:1,15,STAINED_CLAY:15,15,STAINED_CLAY:7,100)
RandomBlock(-5,35,0,minecraft:iron_bars:0,5,quark:iron_plate:1,15,STAINED_CLAY:15,15,STAINED_CLAY:7,100)
RandomBlock(-5,35,1,minecraft:iron_bars:0,5,quark:iron_plate:1,15,STAINED_CLAY:15,15,STAINED_CLAY:7,100)
RandomBlock(-5,35,2,minecraft:iron_bars:0,5,quark:iron_plate:1,15,STAINED_CLAY:15,15,STAINED_CLAY:7,100)
RandomBlock(-5,35,3,minecraft:iron_bars:0,5,quark:iron_plate:1,15,STAINED_CLAY:15,15,STAINED_CLAY:7,100)
RandomBlock(-5,35,4,minecraft:iron_bars:0,5,quark:iron_plate:1,15,STAINED_CLAY:15,15,STAINED_CLAY:7,100)
RandomBlock(-5,35,5,minecraft:iron_bars:0,5,quark:iron_plate:1,15,STAINED_CLAY:15,15,STAINED_CLAY:7,100)
RandomBlock(-5,36,0,minecraft:iron_bars:0,5,quark:iron_plate:1,15,STAINED_CLAY:15,15,STAINED_CLAY:7,100)
RandomBlock(-5,36,1,minecraft:iron_bars:0,5,quark:iron_plate:1,15,STAINED_CLAY:15,15,STAINED_CLAY:7,100)
RandomBlock(-5,36,2,minecraft:iron_bars:0,5,quark:iron_plate:1,15,STAINED_CLAY:15,15,STAINED_CLAY:7,100)
RandomBlock(-5,36,3,minecraft:iron_bars:0,5,quark:iron_plate:1,15,STAINED_CLAY:15,15,STAINED_CLAY:7,100)
RandomBlock(-5,36,4,minecraft:iron_bars:0,5,quark:iron_plate:1,15,STAINED_CLAY:15,15,STAINED_CLAY:7,100)
RandomBlock(-5,36,5,minecraft:iron_bars:0,5,quark:iron_plate:1,15,STAINED_CLAY:15,15,STAINED_CLAY:7,100)
RandomBlock(-5,37,0,minecraft:iron_bars:0,5,quark:iron_plate:1,15,STAINED_CLAY:15,15,STAINED_CLAY:7,100)
RandomBlock(-5,37,1,minecraft:iron_bars:0,5,quark:iron_plate:1,15,STAINED_CLAY:15,15,STAINED_CLAY:7,100)
RandomBlock(-5,37,2,minecraft:iron_bars:0,5,quark:iron_plate:1,15,STAINED_CLAY:15,15,STAINED_CLAY:7,100)
RandomBlock(-5,37,3,minecraft:iron_bars:0,5,quark:iron_plate:1,15,STAINED_CLAY:15,15,STAINED_CLAY:7,100)
RandomBlock(-5,37,4,minecraft:iron_bars:0,5,quark:iron_plate:1,15,STAINED_CLAY:15,15,STAINED_CLAY:7,100)
RandomBlock(-5,37,5,minecraft:iron_bars:0,5,quark:iron_plate:1,15,STAINED_CLAY:15,15,STAINED_CLAY:7,100)
RandomBlock(-5,38,0,minecraft:iron_bars:0,5,quark:iron_plate:1,15,STAINED_CLAY:15,15,STAINED_CLAY:7,100)
RandomBlock(-5,38,1,minecraft:iron_bars:0,5,quark:iron_plate:1,15,STAINED_CLAY:15,15,STAINED_CLAY:7,100)
RandomBlock(-5,38,2,minecraft:iron_bars:0,5,quark:iron_plate:1,15,STAINED_CLAY:15,15,STAINED_CLAY:7,100)
RandomBlock(-5,38,3,minecraft:iron_bars:0,5,quark:iron_plate:1,15,STAINED_CLAY:15,15,STAINED_CLAY:7,100)
RandomBlock(-5,38,4,minecraft:iron_bars:0,5,quark:iron_plate:1,15,STAINED_CLAY:15,15,STAINED_CLAY:7,100)
RandomBlock(-5,38,5,minecraft:iron_bars:0,5,quark:iron_plate:1,15,STAINED_CLAY:15,15,STAINED_CLAY:7,100)
RandomBlock(-5,39,0,minecraft:iron_bars:0,5,quark:iron_plate:1,15,STAINED_CLAY:15,15,STAINED_CLAY:7,100)
RandomBlock(-5,39,1,minecraft:iron_bars:0,5,quark:iron_plate:1,15,STAINED_CLAY:15,15,STAINED_CLAY:7,100)
RandomBlock(-5,39,2,minecraft:iron_bars:0,5,quark:iron_plate:1,15,STAINED_CLAY:15,15,STAINED_CLAY:7,100)
RandomBlock(-5,39,3,minecraft:iron_bars:0,5,quark:iron_plate:1,15,STAINED_CLAY:15,15,STAINED_CLAY:7,100)
RandomBlock(-5,39,4,minecraft:iron_bars:0,5,quark:iron_plate:1,15,STAINED_CLAY:15,15,STAINED_CLAY:7,100)
RandomBlock(-5,39,5,minecraft:iron_bars:0,5,quark:iron_plate:1,15,STAINED_CLAY:15,15,STAINED_CLAY:7,100)
RandomBlock(-5,40,0,minecraft:iron_bars:0,5,quark:iron_plate:1,15,STAINED_CLAY:15,15,STAINED_CLAY:7,100)
RandomBlock(-5,40,1,minecraft:iron_bars:0,5,quark:iron_plate:1,15,STAINED_CLAY:15,15,STAINED_CLAY:7,100)
RandomBlock(-5,40,2,minecraft:iron_bars:0,5,quark:iron_plate:1,15,STAINED_CLAY:15,15,STAINED_CLAY:7,100)
RandomBlock(-5,40,3,minecraft:iron_bars:0,5,quark:iron_plate:1,15,STAINED_CLAY:15,15,STAINED_CLAY:7,100)
RandomBlock(-5,40,4,minecraft:iron_bars:0,5,quark:iron_plate:1,15,STAINED_CLAY:15,15,STAINED_CLAY:7,100)
RandomBlock(-5,40,5,minecraft:iron_bars:0,5,quark:iron_plate:1,15,STAINED_CLAY:15,15,STAINED_CLAY:7,100)
RandomBlock(-5,41,0,minecraft:iron_bars:0,5,quark:iron_plate:1,15,STAINED_CLAY:15,15,STAINED_CLAY:7,100)
RandomBlock(-5,41,1,minecraft:iron_bars:0,5,quark:iron_plate:1,15,STAINED_CLAY:15,15,STAINED_CLAY:7,100)
RandomBlock(-5,41,2,minecraft:iron_bars:0,5,quark:iron_plate:1,15,STAINED_CLAY:15,15,STAINED_CLAY:7,100)
RandomBlock(-5,41,3,minecraft:iron_bars:0,5,quark:iron_plate:1,15,STAINED_CLAY:15,15,STAINED_CLAY:7,100)
RandomBlock(-5,41,4,minecraft:iron_bars:0,5,quark:iron_plate:1,15,STAINED_CLAY:15,15,STAINED_CLAY:7,100)
RandomBlock(-5,41,5,minecraft:iron_bars:0,5,quark:iron_plate:1,15,STAINED_CLAY:15,15,STAINED_CLAY:7,100)
RandomBlock(-5,42,0,minecraft:iron_bars:0,5,quark:iron_plate:1,15,STAINED_CLAY:15,15,STAINED_CLAY:7,100)
RandomBlock(-5,42,1,minecraft:iron_bars:0,5,quark:iron_plate:1,15,STAINED_CLAY:15,15,STAINED_CLAY:7,100)
RandomBlock(-5,42,2,minecraft:iron_bars:0,5,quark:iron_plate:1,15,STAINED_CLAY:15,15,STAINED_CLAY:7,100)
RandomBlock(-5,42,3,minecraft:iron_bars:0,5,quark:iron_plate:1,15,STAINED_CLAY:15,15,STAINED_CLAY:7,100)
RandomBlock(-5,42,4,minecraft:iron_bars:0,5,quark:iron_plate:1,15,STAINED_CLAY:15,15,STAINED_CLAY:7,100)
RandomBlock(-5,42,5,minecraft:iron_bars:0,5,quark:iron_plate:1,15,STAINED_CLAY:15,15,STAINED_CLAY:7,100)
RandomBlock(-5,43,0,minecraft:iron_bars:0,5,quark:iron_plate:1,15,STAINED_CLAY:15,15,STAINED_CLAY:7,100)
RandomBlock(-5,43,1,minecraft:iron_bars:0,5,quark:iron_plate:1,15,STAINED_CLAY:15,15,STAINED_CLAY:7,100)
RandomBlock(-5,43,2,minecraft:iron_bars:0,5,quark:iron_plate:1,15,STAINED_CLAY:15,15,STAINED_CLAY:7,100)
RandomBlock(-5,43,3,minecraft:iron_bars:0,5,quark:iron_plate:1,15,STAINED_CLAY:15,15,STAINED_CLAY:7,100)
RandomBlock(-5,43,4,minecraft:iron_bars:0,5,quark:iron_plate:1,15,STAINED_CLAY:15,15,STAINED_CLAY:7,100)
RandomBlock(-5,43,5,minecraft:iron_bars:0,5,quark:iron_plate:1,15,STAINED_CLAY:15,15,STAINED_CLAY:7,100)
RandomBlock(-5,44,-5,minecraft:iron_bars:0,5,STAINED_CLAY:15,5,STAINED_CLAY:7,5,quark:iron_plate_slab:8,15,quark:world_stone_pavement:2,15,STAINED_CLAY:9,100)
RandomBlock(-5,44,-4,minecraft:iron_bars:0,5,STAINED_CLAY:15,5,STAINED_CLAY:7,5,quark:iron_plate_slab:8,15,quark:world_stone_pavement:2,15,STAINED_CLAY:9,100)
RandomBlock(-5,44,-3,minecraft:iron_bars:0,5,STAINED_CLAY:15,5,STAINED_CLAY:7,5,quark:iron_plate_slab:8,15,quark:world_stone_pavement:2,15,STAINED_CLAY:9,100)
RandomBlock(-5,44,-2,minecraft:iron_bars:0,5,STAINED_CLAY:15,5,STAINED_CLAY:7,5,quark:iron_plate_slab:8,15,quark:world_stone_pavement:2,15,STAINED_CLAY:9,100)
RandomBlock(-5,44,-1,minecraft:iron_bars:0,5,STAINED_CLAY:15,5,STAINED_CLAY:7,5,quark:iron_plate_slab:8,15,quark:world_stone_pavement:2,15,STAINED_CLAY:9,100)
RandomBlock(-5,44,0,minecraft:iron_bars:0,5,STAINED_CLAY:15,5,STAINED_CLAY:7,5,quark:iron_plate_slab:8,15,quark:world_stone_pavement:2,15,STAINED_CLAY:9,100)
RandomBlock(-5,44,1,minecraft:iron_bars:0,5,STAINED_CLAY:15,5,STAINED_CLAY:7,5,quark:iron_plate_slab:8,15,quark:world_stone_pavement:2,15,STAINED_CLAY:9,100)
RandomBlock(-5,44,2,minecraft:iron_bars:0,5,STAINED_CLAY:15,5,STAINED_CLAY:7,5,quark:iron_plate_slab:8,15,quark:world_stone_pavement:2,15,STAINED_CLAY:9,100)
RandomBlock(-5,44,3,minecraft:iron_bars:0,5,STAINED_CLAY:15,5,STAINED_CLAY:7,5,quark:iron_plate_slab:8,15,quark:world_stone_pavement:2,15,STAINED_CLAY:9,100)
RandomBlock(-5,44,4,minecraft:iron_bars:0,5,STAINED_CLAY:15,5,STAINED_CLAY:7,5,quark:iron_plate_slab:8,15,quark:world_stone_pavement:2,15,STAINED_CLAY:9,100)
RandomBlock(-5,44,5,minecraft:iron_bars:0,5,STAINED_CLAY:15,5,STAINED_CLAY:7,5,quark:iron_plate_slab:8,15,quark:world_stone_pavement:2,15,STAINED_CLAY:9,100)
RandomBlock(-5,44,6,minecraft:iron_bars:0,5,STAINED_CLAY:15,5,STAINED_CLAY:7,5,quark:iron_plate_slab:8,15,quark:world_stone_pavement:2,15,STAINED_CLAY:9,100)
RandomBlock(-5,44,7,minecraft:iron_bars:0,5,STAINED_CLAY:15,5,STAINED_CLAY:7,5,quark:iron_plate_slab:8,15,quark:world_stone_pavement:2,15,STAINED_CLAY:9,100)
RandomBlock(-5,44,8,minecraft:iron_bars:0,5,STAINED_CLAY:15,5,STAINED_CLAY:7,5,quark:iron_plate_slab:8,15,quark:world_stone_pavement:2,15,STAINED_CLAY:9,100)
Block(-5,45,-5,minecraft:iron_bars:0)
RandomBlock(-5,45,-3,minecraft:iron_bars:0,5,CONCRETE_POWDER:8,10,quark:limestone:1,15,quark:limestone,15,quark:world_stone_pavement:2,15,CONCRETE:8,100)
RandomBlock(-5,45,-2,minecraft:planks:5,5,minecraft:planks:5,10,minecraft:planks:5,100)
Block(-5,45,-1,SMOOTH_STAIRS:5)
RandomBlock(-5,45,3,minecraft:planks:5,5,minecraft:planks:5,10,minecraft:planks:5,100)
RandomBlock(-5,45,4,minecraft:iron_bars:0,5,CONCRETE_POWDER:8,10,quark:limestone:1,15,quark:limestone,15,quark:world_stone_pavement:2,15,CONCRETE:8,100)
Block(-5,46,-5,minecraft:iron_bars:0)
Block(-5,46,-3,CONCRETE:15)
Block(-5,46,-1,SMOOTH_STAIRS:0)
Block(-5,46,3,LEVER:4)
Block(-5,46,4,CONCRETE:15)
RandomBlock(-5,47,-3,minecraft:iron_bars:0,5,CONCRETE_POWDER:8,10,quark:limestone:1,15,quark:limestone,15,quark:world_stone_pavement:2,15,CONCRETE:8,100)
RandomBlock(-5,47,4,minecraft:iron_bars:0,5,CONCRETE_POWDER:8,10,quark:limestone:1,15,quark:limestone,15,quark:world_stone_pavement:2,15,CONCRETE:8,100)
RandomBlock(-5,48,-3,minecraft:iron_bars:0,5,CONCRETE_POWDER:8,10,quark:limestone:1,15,quark:limestone,15,quark:world_stone_pavement:2,15,CONCRETE:8,100)
RandomBlock(-5,48,4,minecraft:iron_bars:0,5,CONCRETE_POWDER:8,10,quark:limestone:1,15,quark:limestone,15,quark:world_stone_pavement:2,15,CONCRETE:8,100)
RandomBlock(-5,49,-3,minecraft:iron_bars:0,5,CONCRETE_POWDER:8,10,quark:limestone:1,15,quark:limestone,15,quark:world_stone_pavement:2,15,CONCRETE:8,100)
RandomBlock(-5,49,4,minecraft:iron_bars:0,5,CONCRETE_POWDER:8,10,quark:limestone:1,15,quark:limestone,15,quark:world_stone_pavement:2,15,CONCRETE:8,100)
RandomBlock(-5,50,-5,minecraft:iron_bars:0,5,CONCRETE_POWDER:8,10,quark:limestone:1,15,quark:limestone,15,quark:world_stone_pavement:2,15,CONCRETE:8,100)
RandomBlock(-5,50,-4,minecraft:iron_bars:0,5,STAINED_CLAY:15,5,STAINED_CLAY:7,5,quark:iron_plate_slab:8,15,quark:world_stone_pavement:2,15,STAINED_CLAY:9,100)
RandomBlock(-5,50,-3,minecraft:iron_bars:0,5,STAINED_CLAY:15,5,STAINED_CLAY:7,5,quark:iron_plate_slab:8,15,quark:world_stone_pavement:2,15,STAINED_CLAY:9,100)
RandomBlock(-5,50,-2,minecraft:iron_bars:0,5,STAINED_CLAY:15,5,STAINED_CLAY:7,5,quark:iron_plate_slab:8,15,quark:world_stone_pavement:2,15,STAINED_CLAY:9,100)
RandomBlock(-5,50,0,minecraft:iron_bars:0,5,STAINED_CLAY:15,5,STAINED_CLAY:7,5,quark:iron_plate_slab:8,15,quark:world_stone_pavement:2,15,STAINED_CLAY:9,100)
RandomBlock(-5,50,1,minecraft:iron_bars:0,5,STAINED_CLAY:15,5,STAINED_CLAY:7,5,quark:iron_plate_slab:8,15,quark:world_stone_pavement:2,15,STAINED_CLAY:9,100)
RandomBlock(-5,50,2,minecraft:iron_bars:0,5,STAINED_CLAY:15,5,STAINED_CLAY:7,5,quark:iron_plate_slab:8,15,quark:world_stone_pavement:2,15,STAINED_CLAY:9,100)
RandomBlock(-5,50,3,minecraft:iron_bars:0,5,STAINED_CLAY:15,5,STAINED_CLAY:7,5,quark:iron_plate_slab:8,15,quark:world_stone_pavement:2,15,STAINED_CLAY:9,100)
RandomBlock(-5,50,4,minecraft:iron_bars:0,5,STAINED_CLAY:15,5,STAINED_CLAY:7,5,quark:iron_plate_slab:8,15,quark:world_stone_pavement:2,15,STAINED_CLAY:9,100)
RandomBlock(-5,50,5,minecraft:iron_bars:0,5,STAINED_CLAY:15,5,STAINED_CLAY:7,5,quark:iron_plate_slab:8,15,quark:world_stone_pavement:2,15,STAINED_CLAY:9,100)
RandomBlock(-5,50,6,minecraft:iron_bars:0,5,STAINED_CLAY:15,5,STAINED_CLAY:7,5,quark:iron_plate_slab:8,15,quark:world_stone_pavement:2,15,STAINED_CLAY:9,100)
RandomBlock(-5,50,7,minecraft:iron_bars:0,5,STAINED_CLAY:15,5,STAINED_CLAY:7,5,quark:iron_plate_slab:8,15,quark:world_stone_pavement:2,15,STAINED_CLAY:9,100)
RandomBlock(-5,50,8,minecraft:iron_bars:0,5,STAINED_CLAY:15,5,STAINED_CLAY:7,5,quark:iron_plate_slab:8,15,quark:world_stone_pavement:2,15,STAINED_CLAY:9,100)
Block(-5,51,-5,minecraft:iron_bars:0)
RandomBlock(-5,51,-2,minecraft:iron_bars:0,5,CONCRETE_POWDER:8,10,quark:limestone:1,15,quark:limestone,15,quark:world_stone_pavement:2,15,CONCRETE:8,100)
Block(-5,51,0,minecraft:iron_bars:0)
RandomBlock(-5,51,3,minecraft:iron_bars:0,5,CONCRETE_POWDER:8,10,quark:limestone:1,15,quark:limestone,15,quark:world_stone_pavement:2,15,CONCRETE:8,100)
Block(-5,52,-5,minecraft:iron_bars:0)
Block(-5,52,-2,CONCRETE:15)
Block(-5,52,3,STAINED_GLASS_PANE:7)
RandomBlock(-5,53,-2,minecraft:iron_bars:0,5,CONCRETE_POWDER:8,10,quark:limestone:1,15,quark:limestone,15,quark:world_stone_pavement:2,15,CONCRETE:8,100)
Block(-5,53,2,SMOOTH_STAIRS:4)
RandomBlock(-5,53,3,minecraft:iron_bars:0,5,CONCRETE_POWDER:8,10,quark:limestone:1,15,quark:limestone,15,quark:world_stone_pavement:2,15,CONCRETE:8,100)
RandomBlock(-5,54,-2,minecraft:iron_bars:0,5,CONCRETE_POWDER:8,10,quark:limestone:1,15,quark:limestone,15,quark:world_stone_pavement:2,15,CONCRETE:8,100)
Block(-5,54,-1,STEP:8)
Block(-5,54,0,STEP:8)
Block(-5,54,1,STEP:8)
Block(-5,54,2,SMOOTH_STAIRS:1)
RandomBlock(-5,54,3,minecraft:iron_bars:0,5,CONCRETE_POWDER:8,10,quark:limestone:1,15,quark:limestone,15,quark:world_stone_pavement:2,15,CONCRETE:8,100)
Block(-5,54,4,STEP:8)
Block(-5,54,5,STEP:8)
Block(-5,54,6,STEP:8)
Block(-5,54,7,STEP:8)
Block(-5,54,8,STEP:8)
RandomBlock(-5,55,-2,minecraft:iron_bars:0,5,CONCRETE_POWDER:8,10,quark:limestone:1,15,quark:limestone,15,quark:world_stone_pavement:2,15,CONCRETE:8,100)
Block(-5,55,-1,SMOOTH_STAIRS:7)
Block(-5,55,1,minecraft:iron_bars:0)
RandomBlock(-5,55,3,minecraft:iron_bars:0,5,CONCRETE_POWDER:8,10,quark:limestone:1,15,quark:limestone,15,quark:world_stone_pavement:2,15,CONCRETE:8,100)
RandomBlock(-5,56,-2,minecraft:iron_bars:0,5,CONCRETE_POWDER:8,10,quark:limestone:1,15,quark:limestone,15,quark:world_stone_pavement:2,15,CONCRETE:8,100)
RandomBlock(-5,56,3,minecraft:iron_bars:0,5,CONCRETE_POWDER:8,10,quark:limestone:1,15,quark:limestone,15,quark:world_stone_pavement:2,15,CONCRETE:8,100)
RandomBlock(-5,57,-2,minecraft:iron_bars:0,5,CONCRETE_POWDER:8,10,quark:limestone:1,15,quark:limestone,15,quark:world_stone_pavement:2,15,CONCRETE:8,100)
Block(-5,57,-1,STEP:8)
Block(-5,57,0,STEP:8)
Block(-5,57,1,STEP:8)
Block(-5,57,2,STEP:8)
RandomBlock(-5,57,3,minecraft:iron_bars:0,5,CONCRETE_POWDER:8,10,quark:limestone:1,15,quark:limestone,15,quark:world_stone_pavement:2,15,CONCRETE:8,100)
Block(-5,57,4,SMOOTH_STAIRS:4)
Block(-5,57,5,minecraft:iron_bars:0)
Block(-5,58,-2,minecraft:iron_bars:0)
Block(-5,58,5,minecraft:iron_bars:0)
Block(-5,59,-2,minecraft:iron_bars:0)
Block(-5,59,5,minecraft:iron_bars:0)
Block(-5,60,-5,STEP:13)
Block(-5,60,-4,STEP:13)
Block(-5,60,-3,STEP:13)
RandomBlock(-5,60,-2,SMOOTH_BRICK:0,40,SMOOTH_BRICK:1,20,SMOOTH_BRICK:2,30,SMOOTH_BRICK:0,100)
Block(-5,60,-1,STEP:13)
Block(-5,60,0,STEP:13)
Block(-5,60,1,STEP:13)
Block(-5,60,2,STEP:13)
RandomBlock(-5,60,3,SMOOTH_BRICK:0,40,SMOOTH_BRICK:1,20,SMOOTH_BRICK:2,30,SMOOTH_BRICK:0,100)
Block(-5,60,4,STEP:13)
Block(-5,60,5,STEP:13)
RandomBlock(-5,61,-5,CONCRETE_POWDER:7,25,CONCRETE:7,100)
Block(-5,61,-4,STAINED_CLAY:4)
RandomBlock(-5,61,-3,CONCRETE_POWDER:7,25,CONCRETE:7,100)
RandomBlock(-5,61,-2,CONCRETE_POWDER:7,25,CONCRETE:7,100)
RandomBlock(-5,61,-1,CONCRETE_POWDER:7,25,CONCRETE:7,100)
RandomBlock(-5,61,0,CONCRETE_POWDER:7,25,CONCRETE:7,100)
RandomBlock(-5,61,1,CONCRETE_POWDER:7,25,CONCRETE:7,100)
RandomBlock(-5,61,2,CONCRETE_POWDER:7,25,CONCRETE:7,100)
RandomBlock(-5,61,3,CONCRETE_POWDER:7,25,CONCRETE:7,100)
Block(-5,61,4,STAINED_CLAY:4)
RandomBlock(-5,61,5,CONCRETE_POWDER:7,25,CONCRETE:7,100)
Block(-5,62,-6,IRON_FENCE:0)
Block(-5,62,-5,IRON_FENCE:0)
Block(-5,62,5,IRON_FENCE:0)
Block(-5,62,6,IRON_FENCE:0)
RandomBlock(-4,0,-1,minecraft:iron_bars:0,5,quark:iron_plate:1,15,STAINED_CLAY:15,15,STAINED_CLAY:7,100)
RandomBlock(-4,0,0,minecraft:iron_bars:0,5,quark:iron_plate:1,15,STAINED_CLAY:15,15,STAINED_CLAY:7,100)
RandomBlock(-4,0,1,minecraft:iron_bars:0,5,quark:iron_plate:1,15,STAINED_CLAY:15,15,STAINED_CLAY:7,100)
RandomBlock(-4,0,2,minecraft:iron_bars:0,5,quark:iron_plate:1,15,STAINED_CLAY:15,15,STAINED_CLAY:7,100)
RandomBlock(-4,0,3,minecraft:iron_bars:0,5,quark:iron_plate:1,15,STAINED_CLAY:15,15,STAINED_CLAY:7,100)
RandomBlock(-4,0,4,minecraft:iron_bars:0,5,quark:iron_plate:1,15,STAINED_CLAY:15,15,STAINED_CLAY:7,100)
RandomBlock(-4,0,5,minecraft:iron_bars:0,5,quark:iron_plate:1,15,STAINED_CLAY:15,15,STAINED_CLAY:7,100)
RandomBlock(-4,0,6,minecraft:iron_bars:0,5,quark:iron_plate:1,15,STAINED_CLAY:15,15,STAINED_CLAY:7,100)
RandomBlock(-4,1,-1,minecraft:iron_bars:0,5,quark:iron_plate:1,15,STAINED_CLAY:15,15,STAINED_CLAY:7,100)
RandomBlock(-4,1,0,minecraft:iron_bars:0,5,quark:iron_plate:1,15,STAINED_CLAY:15,15,STAINED_CLAY:7,100)
RandomBlock(-4,1,1,minecraft:iron_bars:0,5,quark:iron_plate:1,15,STAINED_CLAY:15,15,STAINED_CLAY:7,100)
RandomBlock(-4,1,2,minecraft:iron_bars:0,5,quark:iron_plate:1,15,STAINED_CLAY:15,15,STAINED_CLAY:7,100)
RandomBlock(-4,1,3,minecraft:iron_bars:0,5,quark:iron_plate:1,15,STAINED_CLAY:15,15,STAINED_CLAY:7,100)
RandomBlock(-4,1,4,minecraft:iron_bars:0,5,quark:iron_plate:1,15,STAINED_CLAY:15,15,STAINED_CLAY:7,100)
RandomBlock(-4,1,5,minecraft:iron_bars:0,5,quark:iron_plate:1,15,STAINED_CLAY:15,15,STAINED_CLAY:7,100)
RandomBlock(-4,1,6,minecraft:iron_bars:0,5,quark:iron_plate:1,15,STAINED_CLAY:15,15,STAINED_CLAY:7,100)
RandomBlock(-4,2,-1,minecraft:iron_bars:0,5,quark:iron_plate:1,15,STAINED_CLAY:15,15,STAINED_CLAY:7,100)
RandomBlock(-4,2,0,minecraft:iron_bars:0,5,quark:iron_plate:1,15,STAINED_CLAY:15,15,STAINED_CLAY:7,100)
RandomBlock(-4,2,1,minecraft:iron_bars:0,5,quark:iron_plate:1,15,STAINED_CLAY:15,15,STAINED_CLAY:7,100)
RandomBlock(-4,2,2,minecraft:iron_bars:0,5,quark:iron_plate:1,15,STAINED_CLAY:15,15,STAINED_CLAY:7,100)
RandomBlock(-4,2,3,minecraft:iron_bars:0,5,quark:iron_plate:1,15,STAINED_CLAY:15,15,STAINED_CLAY:7,100)
RandomBlock(-4,2,4,minecraft:iron_bars:0,5,quark:iron_plate:1,15,STAINED_CLAY:15,15,STAINED_CLAY:7,100)
RandomBlock(-4,2,5,minecraft:iron_bars:0,5,quark:iron_plate:1,15,STAINED_CLAY:15,15,STAINED_CLAY:7,100)
RandomBlock(-4,2,6,minecraft:iron_bars:0,5,quark:iron_plate:1,15,STAINED_CLAY:15,15,STAINED_CLAY:7,100)
RandomBlock(-4,3,-1,minecraft:iron_bars:0,5,quark:iron_plate:1,15,STAINED_CLAY:15,15,STAINED_CLAY:7,100)
RandomBlock(-4,3,0,minecraft:iron_bars:0,5,quark:iron_plate:1,15,STAINED_CLAY:15,15,STAINED_CLAY:7,100)
RandomBlock(-4,3,1,minecraft:iron_bars:0,5,quark:iron_plate:1,15,STAINED_CLAY:15,15,STAINED_CLAY:7,100)
RandomBlock(-4,3,2,minecraft:iron_bars:0,5,quark:iron_plate:1,15,STAINED_CLAY:15,15,STAINED_CLAY:7,100)
RandomBlock(-4,3,3,minecraft:iron_bars:0,5,quark:iron_plate:1,15,STAINED_CLAY:15,15,STAINED_CLAY:7,100)
RandomBlock(-4,3,4,minecraft:iron_bars:0,5,quark:iron_plate:1,15,STAINED_CLAY:15,15,STAINED_CLAY:7,100)
RandomBlock(-4,3,5,minecraft:iron_bars:0,5,quark:iron_plate:1,15,STAINED_CLAY:15,15,STAINED_CLAY:7,100)
RandomBlock(-4,3,6,minecraft:iron_bars:0,5,quark:iron_plate:1,15,STAINED_CLAY:15,15,STAINED_CLAY:7,100)
RandomBlock(-4,4,-1,minecraft:iron_bars:0,5,quark:iron_plate:1,15,STAINED_CLAY:15,15,STAINED_CLAY:7,100)
RandomBlock(-4,4,0,minecraft:iron_bars:0,5,quark:iron_plate:1,15,STAINED_CLAY:15,15,STAINED_CLAY:7,100)
RandomBlock(-4,4,1,minecraft:iron_bars:0,5,quark:iron_plate:1,15,STAINED_CLAY:15,15,STAINED_CLAY:7,100)
RandomBlock(-4,4,2,minecraft:iron_bars:0,5,quark:iron_plate:1,15,STAINED_CLAY:15,15,STAINED_CLAY:7,100)
RandomBlock(-4,4,3,minecraft:iron_bars:0,5,quark:iron_plate:1,15,STAINED_CLAY:15,15,STAINED_CLAY:7,100)
RandomBlock(-4,4,4,minecraft:iron_bars:0,5,quark:iron_plate:1,15,STAINED_CLAY:15,15,STAINED_CLAY:7,100)
RandomBlock(-4,4,5,minecraft:iron_bars:0,5,quark:iron_plate:1,15,STAINED_CLAY:15,15,STAINED_CLAY:7,100)
RandomBlock(-4,4,6,minecraft:iron_bars:0,5,quark:iron_plate:1,15,STAINED_CLAY:15,15,STAINED_CLAY:7,100)
RandomBlock(-4,5,-1,minecraft:iron_bars:0,5,quark:iron_plate:1,15,STAINED_CLAY:15,15,STAINED_CLAY:7,100)
RandomBlock(-4,5,0,minecraft:iron_bars:0,5,quark:iron_plate:1,15,STAINED_CLAY:15,15,STAINED_CLAY:7,100)
RandomBlock(-4,5,1,minecraft:iron_bars:0,5,quark:iron_plate:1,15,STAINED_CLAY:15,15,STAINED_CLAY:7,100)
RandomBlock(-4,5,2,minecraft:iron_bars:0,5,quark:iron_plate:1,15,STAINED_CLAY:15,15,STAINED_CLAY:7,100)
RandomBlock(-4,5,3,minecraft:iron_bars:0,5,quark:iron_plate:1,15,STAINED_CLAY:15,15,STAINED_CLAY:7,100)
RandomBlock(-4,5,4,minecraft:iron_bars:0,5,quark:iron_plate:1,15,STAINED_CLAY:15,15,STAINED_CLAY:7,100)
RandomBlock(-4,5,5,minecraft:iron_bars:0,5,quark:iron_plate:1,15,STAINED_CLAY:15,15,STAINED_CLAY:7,100)
RandomBlock(-4,5,6,minecraft:iron_bars:0,5,quark:iron_plate:1,15,STAINED_CLAY:15,15,STAINED_CLAY:7,100)
RandomBlock(-4,6,-1,minecraft:iron_bars:0,5,quark:iron_plate:1,15,STAINED_CLAY:15,15,STAINED_CLAY:7,100)
RandomBlock(-4,6,0,minecraft:iron_bars:0,5,quark:iron_plate:1,15,STAINED_CLAY:15,15,STAINED_CLAY:7,100)
RandomBlock(-4,6,1,minecraft:iron_bars:0,5,quark:iron_plate:1,15,STAINED_CLAY:15,15,STAINED_CLAY:7,100)
RandomBlock(-4,6,2,minecraft:iron_bars:0,5,quark:iron_plate:1,15,STAINED_CLAY:15,15,STAINED_CLAY:7,100)
RandomBlock(-4,6,3,minecraft:iron_bars:0,5,quark:iron_plate:1,15,STAINED_CLAY:15,15,STAINED_CLAY:7,100)
RandomBlock(-4,6,4,minecraft:iron_bars:0,5,quark:iron_plate:1,15,STAINED_CLAY:15,15,STAINED_CLAY:7,100)
RandomBlock(-4,6,5,minecraft:iron_bars:0,5,quark:iron_plate:1,15,STAINED_CLAY:15,15,STAINED_CLAY:7,100)
RandomBlock(-4,6,6,minecraft:iron_bars:0,5,quark:iron_plate:1,15,STAINED_CLAY:15,15,STAINED_CLAY:7,100)
RandomBlock(-4,7,-1,minecraft:iron_bars:0,5,quark:iron_plate:1,15,STAINED_CLAY:15,15,STAINED_CLAY:7,100)
RandomBlock(-4,7,0,minecraft:iron_bars:0,5,quark:iron_plate:1,15,STAINED_CLAY:15,15,STAINED_CLAY:7,100)
RandomBlock(-4,7,1,minecraft:iron_bars:0,5,quark:iron_plate:1,15,STAINED_CLAY:15,15,STAINED_CLAY:7,100)
RandomBlock(-4,7,2,minecraft:iron_bars:0,5,quark:iron_plate:1,15,STAINED_CLAY:15,15,STAINED_CLAY:7,100)
RandomBlock(-4,7,3,minecraft:iron_bars:0,5,quark:iron_plate:1,15,STAINED_CLAY:15,15,STAINED_CLAY:7,100)
RandomBlock(-4,7,4,minecraft:iron_bars:0,5,quark:iron_plate:1,15,STAINED_CLAY:15,15,STAINED_CLAY:7,100)
RandomBlock(-4,7,5,minecraft:iron_bars:0,5,quark:iron_plate:1,15,STAINED_CLAY:15,15,STAINED_CLAY:7,100)
