
#######################################################################
# +-----------------------------------------------------------------+ #
# |                            BO4 object                           | #
# +-----------------------------------------------------------------+ #
#######################################################################

Author: NLBlackEagle

Description: No description given

SettingsMode: WriteWithoutComments


#######################################################################
# +-----------------------------------------------------------------+ #
# |                          Main settings                          | #
# +-----------------------------------------------------------------+ #
#######################################################################

FixedRotation: 

Frequency: 0

SpawnHeight: highestBlock

UseCenterForHighestBlock: true

##############################
# Height Limits for the BO4. #
##############################

MinHeight: 0

MaxHeight: 255

InheritBO3: 

InheritBO3Rotation: NORTH

OverrideChildSettings: true

OverrideParentHeight: false

CanOverride: true

BranchFrequency: 0

BranchFrequencyGroup: 

MustBeBelowOther: false

MustBeInside: 

CannotBeInside: 

ReplacesBO3: 

MustBeInsideWorldBorders: true
CanSpawnOnWater: true

SpawnOnWaterOnly: false

SpawnUnderWater: false

SpawnAtWaterLevel: false

HeightOffset: 0

RemoveAir: true

ReplaceAbove: 

ReplaceBelow: 

ReplaceWithBiomeBlocks: false

ReplaceWithSurfaceBlock: GRASS

ReplaceWithGroundBlock: DIRT

ReplaceWithStoneBlock: STONE

SmoothRadius: 0

SmoothHeightOffset: 0

SmoothStartTop: false

SmoothStartWood: false

SmoothingSurfaceBlock: 

SmoothingGroundBlock: 

BO3Group: 

IsSpawnPoint: false

DoReplaceBlocks: true


#######################################################################
# +-----------------------------------------------------------------+ #
# |                              Blocks                             | #
# +-----------------------------------------------------------------+ #
#######################################################################

RandomBlock(-8,0,3,minecraft:iron_bars:0,5,quark:iron_plate:1,15,STAINED_CLAY:15,15,STAINED_CLAY:7,100)
RandomBlock(-8,0,4,minecraft:iron_bars:0,5,quark:iron_plate:1,15,STAINED_CLAY:15,15,STAINED_CLAY:7,100)
RandomBlock(-8,0,5,minecraft:iron_bars:0,5,quark:iron_plate:1,15,STAINED_CLAY:15,15,STAINED_CLAY:7,100)
RandomBlock(-8,0,6,minecraft:iron_bars:0,5,quark:iron_plate:1,15,STAINED_CLAY:15,15,STAINED_CLAY:7,100)
RandomBlock(-8,0,7,minecraft:iron_bars:0,5,quark:iron_plate:1,15,STAINED_CLAY:15,15,STAINED_CLAY:7,100)
RandomBlock(-8,0,8,minecraft:iron_bars:0,5,quark:iron_plate:1,15,STAINED_CLAY:15,15,STAINED_CLAY:7,100)
RandomBlock(-8,1,3,minecraft:iron_bars:0,5,quark:iron_plate:1,15,STAINED_CLAY:15,15,STAINED_CLAY:7,100)
RandomBlock(-8,1,4,minecraft:iron_bars:0,5,quark:iron_plate:1,15,STAINED_CLAY:15,15,STAINED_CLAY:7,100)
RandomBlock(-8,1,5,minecraft:iron_bars:0,5,quark:iron_plate:1,15,STAINED_CLAY:15,15,STAINED_CLAY:7,100)
RandomBlock(-8,1,6,minecraft:iron_bars:0,5,quark:iron_plate:1,15,STAINED_CLAY:15,15,STAINED_CLAY:7,100)
RandomBlock(-8,1,7,minecraft:iron_bars:0,5,quark:iron_plate:1,15,STAINED_CLAY:15,15,STAINED_CLAY:7,100)
RandomBlock(-8,1,8,minecraft:iron_bars:0,5,quark:iron_plate:1,15,STAINED_CLAY:15,15,STAINED_CLAY:7,100)
RandomBlock(-8,2,3,minecraft:iron_bars:0,5,quark:iron_plate:1,15,STAINED_CLAY:15,15,STAINED_CLAY:7,100)
RandomBlock(-8,2,4,minecraft:iron_bars:0,5,quark:iron_plate:1,15,STAINED_CLAY:15,15,STAINED_CLAY:7,100)
RandomBlock(-8,2,5,minecraft:iron_bars:0,5,quark:iron_plate:1,15,STAINED_CLAY:15,15,STAINED_CLAY:7,100)
RandomBlock(-8,2,6,minecraft:iron_bars:0,5,quark:iron_plate:1,15,STAINED_CLAY:15,15,STAINED_CLAY:7,100)
RandomBlock(-8,2,7,minecraft:iron_bars:0,5,quark:iron_plate:1,15,STAINED_CLAY:15,15,STAINED_CLAY:7,100)
RandomBlock(-8,2,8,minecraft:iron_bars:0,5,quark:iron_plate:1,15,STAINED_CLAY:15,15,STAINED_CLAY:7,100)
RandomBlock(-8,3,3,minecraft:iron_bars:0,5,quark:iron_plate:1,15,STAINED_CLAY:15,15,STAINED_CLAY:7,100)
RandomBlock(-8,3,4,minecraft:iron_bars:0,5,quark:iron_plate:1,15,STAINED_CLAY:15,15,STAINED_CLAY:7,100)
RandomBlock(-8,3,5,minecraft:iron_bars:0,5,quark:iron_plate:1,15,STAINED_CLAY:15,15,STAINED_CLAY:7,100)
RandomBlock(-8,3,6,minecraft:iron_bars:0,5,quark:iron_plate:1,15,STAINED_CLAY:15,15,STAINED_CLAY:7,100)
RandomBlock(-8,3,7,minecraft:iron_bars:0,5,quark:iron_plate:1,15,STAINED_CLAY:15,15,STAINED_CLAY:7,100)
RandomBlock(-8,3,8,minecraft:iron_bars:0,5,quark:iron_plate:1,15,STAINED_CLAY:15,15,STAINED_CLAY:7,100)
RandomBlock(-8,4,3,minecraft:iron_bars:0,5,quark:iron_plate:1,15,STAINED_CLAY:15,15,STAINED_CLAY:7,100)
RandomBlock(-8,4,4,minecraft:iron_bars:0,5,quark:iron_plate:1,15,STAINED_CLAY:15,15,STAINED_CLAY:7,100)
RandomBlock(-8,4,5,minecraft:iron_bars:0,5,quark:iron_plate:1,15,STAINED_CLAY:15,15,STAINED_CLAY:7,100)
RandomBlock(-8,4,6,minecraft:iron_bars:0,5,quark:iron_plate:1,15,STAINED_CLAY:15,15,STAINED_CLAY:7,100)
RandomBlock(-8,4,7,minecraft:iron_bars:0,5,quark:iron_plate:1,15,STAINED_CLAY:15,15,STAINED_CLAY:7,100)
RandomBlock(-8,4,8,minecraft:iron_bars:0,5,quark:iron_plate:1,15,STAINED_CLAY:15,15,STAINED_CLAY:7,100)
RandomBlock(-8,5,3,minecraft:iron_bars:0,5,quark:iron_plate:1,15,STAINED_CLAY:15,15,STAINED_CLAY:7,100)
RandomBlock(-8,5,4,minecraft:iron_bars:0,5,quark:iron_plate:1,15,STAINED_CLAY:15,15,STAINED_CLAY:7,100)
RandomBlock(-8,5,5,minecraft:iron_bars:0,5,quark:iron_plate:1,15,STAINED_CLAY:15,15,STAINED_CLAY:7,100)
RandomBlock(-8,5,6,minecraft:iron_bars:0,5,quark:iron_plate:1,15,STAINED_CLAY:15,15,STAINED_CLAY:7,100)
RandomBlock(-8,5,7,minecraft:iron_bars:0,5,quark:iron_plate:1,15,STAINED_CLAY:15,15,STAINED_CLAY:7,100)
RandomBlock(-8,5,8,minecraft:iron_bars:0,5,quark:iron_plate:1,15,STAINED_CLAY:15,15,STAINED_CLAY:7,100)
RandomBlock(-8,6,3,minecraft:iron_bars:0,5,quark:iron_plate:1,15,STAINED_CLAY:15,15,STAINED_CLAY:7,100)
RandomBlock(-8,6,4,minecraft:iron_bars:0,5,quark:iron_plate:1,15,STAINED_CLAY:15,15,STAINED_CLAY:7,100)
RandomBlock(-8,6,5,minecraft:iron_bars:0,5,quark:iron_plate:1,15,STAINED_CLAY:15,15,STAINED_CLAY:7,100)
RandomBlock(-8,6,6,minecraft:iron_bars:0,5,quark:iron_plate:1,15,STAINED_CLAY:15,15,STAINED_CLAY:7,100)
RandomBlock(-8,6,7,minecraft:iron_bars:0,5,quark:iron_plate:1,15,STAINED_CLAY:15,15,STAINED_CLAY:7,100)
RandomBlock(-8,6,8,minecraft:iron_bars:0,5,quark:iron_plate:1,15,STAINED_CLAY:15,15,STAINED_CLAY:7,100)
RandomBlock(-8,7,3,minecraft:iron_bars:0,5,quark:iron_plate:1,15,STAINED_CLAY:15,15,STAINED_CLAY:7,100)
RandomBlock(-8,7,4,minecraft:iron_bars:0,5,quark:iron_plate:1,15,STAINED_CLAY:15,15,STAINED_CLAY:7,100)
RandomBlock(-8,7,5,minecraft:iron_bars:0,5,quark:iron_plate:1,15,STAINED_CLAY:15,15,STAINED_CLAY:7,100)
RandomBlock(-8,7,6,minecraft:iron_bars:0,5,quark:iron_plate:1,15,STAINED_CLAY:15,15,STAINED_CLAY:7,100)
RandomBlock(-8,7,7,minecraft:iron_bars:0,5,quark:iron_plate:1,15,STAINED_CLAY:15,15,STAINED_CLAY:7,100)
RandomBlock(-8,7,8,minecraft:iron_bars:0,5,quark:iron_plate:1,15,STAINED_CLAY:15,15,STAINED_CLAY:7,100)
RandomBlock(-8,8,3,minecraft:iron_bars:0,5,quark:iron_plate:1,15,STAINED_CLAY:15,15,STAINED_CLAY:7,100)
RandomBlock(-8,8,4,minecraft:iron_bars:0,5,quark:iron_plate:1,15,STAINED_CLAY:15,15,STAINED_CLAY:7,100)
RandomBlock(-8,8,5,minecraft:iron_bars:0,5,quark:iron_plate:1,15,STAINED_CLAY:15,15,STAINED_CLAY:7,100)
RandomBlock(-8,8,6,minecraft:iron_bars:0,5,quark:iron_plate:1,15,STAINED_CLAY:15,15,STAINED_CLAY:7,100)
RandomBlock(-8,8,7,minecraft:iron_bars:0,5,quark:iron_plate:1,15,STAINED_CLAY:15,15,STAINED_CLAY:7,100)
RandomBlock(-8,8,8,minecraft:iron_bars:0,5,quark:iron_plate:1,15,STAINED_CLAY:15,15,STAINED_CLAY:7,100)
RandomBlock(-8,9,3,minecraft:iron_bars:0,5,quark:iron_plate:1,15,STAINED_CLAY:15,15,STAINED_CLAY:7,100)
RandomBlock(-8,9,4,minecraft:iron_bars:0,5,quark:iron_plate:1,15,STAINED_CLAY:15,15,STAINED_CLAY:7,100)
RandomBlock(-8,9,5,minecraft:iron_bars:0,5,quark:iron_plate:1,15,STAINED_CLAY:15,15,STAINED_CLAY:7,100)
RandomBlock(-8,9,6,minecraft:iron_bars:0,5,quark:iron_plate:1,15,STAINED_CLAY:15,15,STAINED_CLAY:7,100)
RandomBlock(-8,9,7,minecraft:iron_bars:0,5,quark:iron_plate:1,15,STAINED_CLAY:15,15,STAINED_CLAY:7,100)
RandomBlock(-8,9,8,minecraft:iron_bars:0,5,quark:iron_plate:1,15,STAINED_CLAY:15,15,STAINED_CLAY:7,100)
RandomBlock(-8,10,3,minecraft:iron_bars:0,5,quark:iron_plate:1,15,STAINED_CLAY:15,15,STAINED_CLAY:7,100)
RandomBlock(-8,10,4,minecraft:iron_bars:0,5,quark:iron_plate:1,15,STAINED_CLAY:15,15,STAINED_CLAY:7,100)
RandomBlock(-8,10,5,minecraft:iron_bars:0,5,quark:iron_plate:1,15,STAINED_CLAY:15,15,STAINED_CLAY:7,100)
RandomBlock(-8,10,6,minecraft:iron_bars:0,5,quark:iron_plate:1,15,STAINED_CLAY:15,15,STAINED_CLAY:7,100)
RandomBlock(-8,10,7,minecraft:iron_bars:0,5,quark:iron_plate:1,15,STAINED_CLAY:15,15,STAINED_CLAY:7,100)
RandomBlock(-8,10,8,minecraft:iron_bars:0,5,quark:iron_plate:1,15,STAINED_CLAY:15,15,STAINED_CLAY:7,100)
RandomBlock(-8,11,3,minecraft:iron_bars:0,5,quark:iron_plate:1,15,STAINED_CLAY:15,15,STAINED_CLAY:7,100)
RandomBlock(-8,11,4,minecraft:iron_bars:0,5,quark:iron_plate:1,15,STAINED_CLAY:15,15,STAINED_CLAY:7,100)
RandomBlock(-8,11,5,minecraft:iron_bars:0,5,quark:iron_plate:1,15,STAINED_CLAY:15,15,STAINED_CLAY:7,100)
RandomBlock(-8,11,6,minecraft:iron_bars:0,5,quark:iron_plate:1,15,STAINED_CLAY:15,15,STAINED_CLAY:7,100)
RandomBlock(-8,11,7,minecraft:iron_bars:0,5,quark:iron_plate:1,15,STAINED_CLAY:15,15,STAINED_CLAY:7,100)
RandomBlock(-8,11,8,minecraft:iron_bars:0,5,quark:iron_plate:1,15,STAINED_CLAY:15,15,STAINED_CLAY:7,100)
RandomBlock(-8,12,3,minecraft:iron_bars:0,5,quark:iron_plate:1,15,STAINED_CLAY:15,15,STAINED_CLAY:7,100)
RandomBlock(-8,12,4,minecraft:iron_bars:0,5,quark:iron_plate:1,15,STAINED_CLAY:15,15,STAINED_CLAY:7,100)
RandomBlock(-8,12,5,minecraft:iron_bars:0,5,quark:iron_plate:1,15,STAINED_CLAY:15,15,STAINED_CLAY:7,100)
RandomBlock(-8,12,6,minecraft:iron_bars:0,5,quark:iron_plate:1,15,STAINED_CLAY:15,15,STAINED_CLAY:7,100)
RandomBlock(-8,12,7,minecraft:iron_bars:0,5,quark:iron_plate:1,15,STAINED_CLAY:15,15,STAINED_CLAY:7,100)
RandomBlock(-8,12,8,minecraft:iron_bars:0,5,quark:iron_plate:1,15,STAINED_CLAY:15,15,STAINED_CLAY:7,100)
RandomBlock(-8,13,3,minecraft:iron_bars:0,5,quark:iron_plate:1,15,STAINED_CLAY:15,15,STAINED_CLAY:7,100)
RandomBlock(-8,13,4,minecraft:iron_bars:0,5,quark:iron_plate:1,15,STAINED_CLAY:15,15,STAINED_CLAY:7,100)
RandomBlock(-8,13,5,minecraft:iron_bars:0,5,quark:iron_plate:1,15,STAINED_CLAY:15,15,STAINED_CLAY:7,100)
RandomBlock(-8,13,6,minecraft:iron_bars:0,5,quark:iron_plate:1,15,STAINED_CLAY:15,15,STAINED_CLAY:7,100)
RandomBlock(-8,13,7,minecraft:iron_bars:0,5,quark:iron_plate:1,15,STAINED_CLAY:15,15,STAINED_CLAY:7,100)
RandomBlock(-8,13,8,minecraft:iron_bars:0,5,quark:iron_plate:1,15,STAINED_CLAY:15,15,STAINED_CLAY:7,100)
RandomBlock(-8,14,3,minecraft:iron_bars:0,5,quark:iron_plate:1,15,STAINED_CLAY:15,15,STAINED_CLAY:7,100)
RandomBlock(-8,14,4,minecraft:iron_bars:0,5,quark:iron_plate:1,15,STAINED_CLAY:15,15,STAINED_CLAY:7,100)
RandomBlock(-8,14,5,minecraft:iron_bars:0,5,quark:iron_plate:1,15,STAINED_CLAY:15,15,STAINED_CLAY:7,100)
RandomBlock(-8,14,6,minecraft:iron_bars:0,5,quark:iron_plate:1,15,STAINED_CLAY:15,15,STAINED_CLAY:7,100)
RandomBlock(-8,14,7,minecraft:iron_bars:0,5,quark:iron_plate:1,15,STAINED_CLAY:15,15,STAINED_CLAY:7,100)
RandomBlock(-8,14,8,minecraft:iron_bars:0,5,quark:iron_plate:1,15,STAINED_CLAY:15,15,STAINED_CLAY:7,100)
RandomBlock(-8,15,3,minecraft:iron_bars:0,5,quark:iron_plate:1,15,STAINED_CLAY:15,15,STAINED_CLAY:7,100)
RandomBlock(-8,15,4,minecraft:iron_bars:0,5,quark:iron_plate:1,15,STAINED_CLAY:15,15,STAINED_CLAY:7,100)
RandomBlock(-8,15,5,minecraft:iron_bars:0,5,quark:iron_plate:1,15,STAINED_CLAY:15,15,STAINED_CLAY:7,100)
RandomBlock(-8,15,6,minecraft:iron_bars:0,5,quark:iron_plate:1,15,STAINED_CLAY:15,15,STAINED_CLAY:7,100)
RandomBlock(-8,15,7,minecraft:iron_bars:0,5,quark:iron_plate:1,15,STAINED_CLAY:15,15,STAINED_CLAY:7,100)
RandomBlock(-8,15,8,minecraft:iron_bars:0,5,quark:iron_plate:1,15,STAINED_CLAY:15,15,STAINED_CLAY:7,100)
RandomBlock(-8,16,3,minecraft:iron_bars:0,5,quark:iron_plate:1,15,STAINED_CLAY:15,15,STAINED_CLAY:7,100)
RandomBlock(-8,16,4,minecraft:iron_bars:0,5,quark:iron_plate:1,15,STAINED_CLAY:15,15,STAINED_CLAY:7,100)
RandomBlock(-8,16,5,minecraft:iron_bars:0,5,quark:iron_plate:1,15,STAINED_CLAY:15,15,STAINED_CLAY:7,100)
RandomBlock(-8,16,6,minecraft:iron_bars:0,5,quark:iron_plate:1,15,STAINED_CLAY:15,15,STAINED_CLAY:7,100)
RandomBlock(-8,16,7,minecraft:iron_bars:0,5,quark:iron_plate:1,15,STAINED_CLAY:15,15,STAINED_CLAY:7,100)
RandomBlock(-8,16,8,minecraft:iron_bars:0,5,quark:iron_plate:1,15,STAINED_CLAY:15,15,STAINED_CLAY:7,100)
RandomBlock(-8,17,3,minecraft:iron_bars:0,5,quark:iron_plate:1,15,STAINED_CLAY:15,15,STAINED_CLAY:7,100)
RandomBlock(-8,17,4,minecraft:iron_bars:0,5,quark:iron_plate:1,15,STAINED_CLAY:15,15,STAINED_CLAY:7,100)
RandomBlock(-8,17,5,minecraft:iron_bars:0,5,quark:iron_plate:1,15,STAINED_CLAY:15,15,STAINED_CLAY:7,100)
RandomBlock(-8,17,6,minecraft:iron_bars:0,5,quark:iron_plate:1,15,STAINED_CLAY:15,15,STAINED_CLAY:7,100)
RandomBlock(-8,17,7,minecraft:iron_bars:0,5,quark:iron_plate:1,15,STAINED_CLAY:15,15,STAINED_CLAY:7,100)
RandomBlock(-8,17,8,minecraft:iron_bars:0,5,quark:iron_plate:1,15,STAINED_CLAY:15,15,STAINED_CLAY:7,100)
RandomBlock(-8,18,3,minecraft:iron_bars:0,5,quark:iron_plate:1,15,STAINED_CLAY:15,15,STAINED_CLAY:7,100)
RandomBlock(-8,18,4,minecraft:iron_bars:0,5,quark:iron_plate:1,15,STAINED_CLAY:15,15,STAINED_CLAY:7,100)
RandomBlock(-8,18,5,minecraft:iron_bars:0,5,quark:iron_plate:1,15,STAINED_CLAY:15,15,STAINED_CLAY:7,100)
RandomBlock(-8,18,6,minecraft:iron_bars:0,5,quark:iron_plate:1,15,STAINED_CLAY:15,15,STAINED_CLAY:7,100)
RandomBlock(-8,18,7,minecraft:iron_bars:0,5,quark:iron_plate:1,15,STAINED_CLAY:15,15,STAINED_CLAY:7,100)
RandomBlock(-8,18,8,minecraft:iron_bars:0,5,quark:iron_plate:1,15,STAINED_CLAY:15,15,STAINED_CLAY:7,100)
RandomBlock(-8,19,3,minecraft:iron_bars:0,5,quark:iron_plate:1,15,STAINED_CLAY:15,15,STAINED_CLAY:7,100)
RandomBlock(-8,19,4,minecraft:iron_bars:0,5,quark:iron_plate:1,15,STAINED_CLAY:15,15,STAINED_CLAY:7,100)
RandomBlock(-8,19,5,minecraft:iron_bars:0,5,quark:iron_plate:1,15,STAINED_CLAY:15,15,STAINED_CLAY:7,100)
RandomBlock(-8,19,6,minecraft:iron_bars:0,5,quark:iron_plate:1,15,STAINED_CLAY:15,15,STAINED_CLAY:7,100)
RandomBlock(-8,19,7,minecraft:iron_bars:0,5,quark:iron_plate:1,15,STAINED_CLAY:15,15,STAINED_CLAY:7,100)
RandomBlock(-8,19,8,minecraft:iron_bars:0,5,quark:iron_plate:1,15,STAINED_CLAY:15,15,STAINED_CLAY:7,100)
RandomBlock(-8,20,3,minecraft:iron_bars:0,5,quark:iron_plate:1,15,STAINED_CLAY:15,15,STAINED_CLAY:7,100)
RandomBlock(-8,20,4,minecraft:iron_bars:0,5,quark:iron_plate:1,15,STAINED_CLAY:15,15,STAINED_CLAY:7,100)
RandomBlock(-8,20,5,minecraft:iron_bars:0,5,quark:iron_plate:1,15,STAINED_CLAY:15,15,STAINED_CLAY:7,100)
RandomBlock(-8,20,6,minecraft:iron_bars:0,5,quark:iron_plate:1,15,STAINED_CLAY:15,15,STAINED_CLAY:7,100)
RandomBlock(-8,20,7,minecraft:iron_bars:0,5,quark:iron_plate:1,15,STAINED_CLAY:15,15,STAINED_CLAY:7,100)
RandomBlock(-8,20,8,minecraft:iron_bars:0,5,quark:iron_plate:1,15,STAINED_CLAY:15,15,STAINED_CLAY:7,100)
RandomBlock(-8,21,3,minecraft:iron_bars:0,5,quark:iron_plate:1,15,STAINED_CLAY:15,15,STAINED_CLAY:7,100)
RandomBlock(-8,21,4,minecraft:iron_bars:0,5,quark:iron_plate:1,15,STAINED_CLAY:15,15,STAINED_CLAY:7,100)
RandomBlock(-8,21,5,minecraft:iron_bars:0,5,quark:iron_plate:1,15,STAINED_CLAY:15,15,STAINED_CLAY:7,100)
RandomBlock(-8,21,6,minecraft:iron_bars:0,5,quark:iron_plate:1,15,STAINED_CLAY:15,15,STAINED_CLAY:7,100)
RandomBlock(-8,21,7,minecraft:iron_bars:0,5,quark:iron_plate:1,15,STAINED_CLAY:15,15,STAINED_CLAY:7,100)
RandomBlock(-8,21,8,minecraft:iron_bars:0,5,quark:iron_plate:1,15,STAINED_CLAY:15,15,STAINED_CLAY:7,100)
RandomBlock(-8,22,3,minecraft:iron_bars:0,5,quark:iron_plate:1,15,STAINED_CLAY:15,15,STAINED_CLAY:7,100)
RandomBlock(-8,22,4,minecraft:iron_bars:0,5,quark:iron_plate:1,15,STAINED_CLAY:15,15,STAINED_CLAY:7,100)
RandomBlock(-8,22,5,minecraft:iron_bars:0,5,quark:iron_plate:1,15,STAINED_CLAY:15,15,STAINED_CLAY:7,100)
RandomBlock(-8,22,6,minecraft:iron_bars:0,5,quark:iron_plate:1,15,STAINED_CLAY:15,15,STAINED_CLAY:7,100)
RandomBlock(-8,22,7,minecraft:iron_bars:0,5,quark:iron_plate:1,15,STAINED_CLAY:15,15,STAINED_CLAY:7,100)
RandomBlock(-8,22,8,minecraft:iron_bars:0,5,quark:iron_plate:1,15,STAINED_CLAY:15,15,STAINED_CLAY:7,100)
RandomBlock(-8,23,3,minecraft:iron_bars:0,5,quark:iron_plate:1,15,STAINED_CLAY:15,15,STAINED_CLAY:7,100)
RandomBlock(-8,23,4,minecraft:iron_bars:0,5,quark:iron_plate:1,15,STAINED_CLAY:15,15,STAINED_CLAY:7,100)
RandomBlock(-8,23,5,minecraft:iron_bars:0,5,quark:iron_plate:1,15,STAINED_CLAY:15,15,STAINED_CLAY:7,100)
RandomBlock(-8,23,6,minecraft:iron_bars:0,5,quark:iron_plate:1,15,STAINED_CLAY:15,15,STAINED_CLAY:7,100)
RandomBlock(-8,23,7,minecraft:iron_bars:0,5,quark:iron_plate:1,15,STAINED_CLAY:15,15,STAINED_CLAY:7,100)
RandomBlock(-8,23,8,minecraft:iron_bars:0,5,quark:iron_plate:1,15,STAINED_CLAY:15,15,STAINED_CLAY:7,100)
RandomBlock(-8,24,3,minecraft:iron_bars:0,5,quark:iron_plate:1,15,STAINED_CLAY:15,15,STAINED_CLAY:7,100)
RandomBlock(-8,24,4,minecraft:iron_bars:0,5,quark:iron_plate:1,15,STAINED_CLAY:15,15,STAINED_CLAY:7,100)
RandomBlock(-8,24,5,minecraft:iron_bars:0,5,quark:iron_plate:1,15,STAINED_CLAY:15,15,STAINED_CLAY:7,100)
RandomBlock(-8,24,6,minecraft:iron_bars:0,5,quark:iron_plate:1,15,STAINED_CLAY:15,15,STAINED_CLAY:7,100)
RandomBlock(-8,24,7,minecraft:iron_bars:0,5,quark:iron_plate:1,15,STAINED_CLAY:15,15,STAINED_CLAY:7,100)
RandomBlock(-8,24,8,minecraft:iron_bars:0,5,quark:iron_plate:1,15,STAINED_CLAY:15,15,STAINED_CLAY:7,100)
RandomBlock(-8,25,3,minecraft:iron_bars:0,5,quark:iron_plate:1,15,STAINED_CLAY:15,15,STAINED_CLAY:7,100)
RandomBlock(-8,25,4,minecraft:iron_bars:0,5,quark:iron_plate:1,15,STAINED_CLAY:15,15,STAINED_CLAY:7,100)
RandomBlock(-8,25,5,minecraft:iron_bars:0,5,quark:iron_plate:1,15,STAINED_CLAY:15,15,STAINED_CLAY:7,100)
RandomBlock(-8,25,6,minecraft:iron_bars:0,5,quark:iron_plate:1,15,STAINED_CLAY:15,15,STAINED_CLAY:7,100)
RandomBlock(-8,25,7,minecraft:iron_bars:0,5,quark:iron_plate:1,15,STAINED_CLAY:15,15,STAINED_CLAY:7,100)
RandomBlock(-8,25,8,minecraft:iron_bars:0,5,quark:iron_plate:1,15,STAINED_CLAY:15,15,STAINED_CLAY:7,100)
RandomBlock(-8,26,3,minecraft:iron_bars:0,5,quark:iron_plate:1,15,STAINED_CLAY:15,15,STAINED_CLAY:7,100)
RandomBlock(-8,26,4,minecraft:iron_bars:0,5,quark:iron_plate:1,15,STAINED_CLAY:15,15,STAINED_CLAY:7,100)
RandomBlock(-8,26,5,minecraft:iron_bars:0,5,quark:iron_plate:1,15,STAINED_CLAY:15,15,STAINED_CLAY:7,100)
RandomBlock(-8,26,6,minecraft:iron_bars:0,5,quark:iron_plate:1,15,STAINED_CLAY:15,15,STAINED_CLAY:7,100)
RandomBlock(-8,26,7,minecraft:iron_bars:0,5,quark:iron_plate:1,15,STAINED_CLAY:15,15,STAINED_CLAY:7,100)
RandomBlock(-8,26,8,minecraft:iron_bars:0,5,quark:iron_plate:1,15,STAINED_CLAY:15,15,STAINED_CLAY:7,100)
RandomBlock(-8,27,3,minecraft:iron_bars:0,5,quark:iron_plate:1,15,STAINED_CLAY:15,15,STAINED_CLAY:7,100)
RandomBlock(-8,27,4,minecraft:iron_bars:0,5,quark:iron_plate:1,15,STAINED_CLAY:15,15,STAINED_CLAY:7,100)
RandomBlock(-8,27,5,minecraft:iron_bars:0,5,quark:iron_plate:1,15,STAINED_CLAY:15,15,STAINED_CLAY:7,100)
RandomBlock(-8,27,6,minecraft:iron_bars:0,5,quark:iron_plate:1,15,STAINED_CLAY:15,15,STAINED_CLAY:7,100)
RandomBlock(-8,27,7,minecraft:iron_bars:0,5,quark:iron_plate:1,15,STAINED_CLAY:15,15,STAINED_CLAY:7,100)
RandomBlock(-8,27,8,minecraft:iron_bars:0,5,quark:iron_plate:1,15,STAINED_CLAY:15,15,STAINED_CLAY:7,100)
RandomBlock(-8,28,3,minecraft:iron_bars:0,5,quark:iron_plate:1,15,STAINED_CLAY:15,15,STAINED_CLAY:7,100)
RandomBlock(-8,28,4,minecraft:iron_bars:0,5,quark:iron_plate:1,15,STAINED_CLAY:15,15,STAINED_CLAY:7,100)
RandomBlock(-8,28,5,minecraft:iron_bars:0,5,quark:iron_plate:1,15,STAINED_CLAY:15,15,STAINED_CLAY:7,100)
RandomBlock(-8,28,6,minecraft:iron_bars:0,5,quark:iron_plate:1,15,STAINED_CLAY:15,15,STAINED_CLAY:7,100)
RandomBlock(-8,28,7,minecraft:iron_bars:0,5,quark:iron_plate:1,15,STAINED_CLAY:15,15,STAINED_CLAY:7,100)
RandomBlock(-8,28,8,minecraft:iron_bars:0,5,quark:iron_plate:1,15,STAINED_CLAY:15,15,STAINED_CLAY:7,100)
RandomBlock(-8,29,3,minecraft:iron_bars:0,5,quark:iron_plate:1,15,STAINED_CLAY:15,15,STAINED_CLAY:7,100)
RandomBlock(-8,29,4,minecraft:iron_bars:0,5,quark:iron_plate:1,15,STAINED_CLAY:15,15,STAINED_CLAY:7,100)
RandomBlock(-8,29,5,minecraft:iron_bars:0,5,quark:iron_plate:1,15,STAINED_CLAY:15,15,STAINED_CLAY:7,100)
RandomBlock(-8,29,6,minecraft:iron_bars:0,5,quark:iron_plate:1,15,STAINED_CLAY:15,15,STAINED_CLAY:7,100)
RandomBlock(-8,29,7,minecraft:iron_bars:0,5,quark:iron_plate:1,15,STAINED_CLAY:15,15,STAINED_CLAY:7,100)
RandomBlock(-8,29,8,minecraft:iron_bars:0,5,quark:iron_plate:1,15,STAINED_CLAY:15,15,STAINED_CLAY:7,100)
RandomBlock(-8,30,3,minecraft:iron_bars:0,5,quark:iron_plate:1,15,STAINED_CLAY:15,15,STAINED_CLAY:7,100)
RandomBlock(-8,30,4,minecraft:iron_bars:0,5,quark:iron_plate:1,15,STAINED_CLAY:15,15,STAINED_CLAY:7,100)
RandomBlock(-8,30,5,minecraft:iron_bars:0,5,quark:iron_plate:1,15,STAINED_CLAY:15,15,STAINED_CLAY:7,100)
RandomBlock(-8,30,6,minecraft:iron_bars:0,5,quark:iron_plate:1,15,STAINED_CLAY:15,15,STAINED_CLAY:7,100)
RandomBlock(-8,30,7,minecraft:iron_bars:0,5,quark:iron_plate:1,15,STAINED_CLAY:15,15,STAINED_CLAY:7,100)
RandomBlock(-8,30,8,minecraft:iron_bars:0,5,quark:iron_plate:1,15,STAINED_CLAY:15,15,STAINED_CLAY:7,100)
RandomBlock(-8,31,3,minecraft:iron_bars:0,5,quark:iron_plate:1,15,STAINED_CLAY:15,15,STAINED_CLAY:7,100)
RandomBlock(-8,31,4,minecraft:iron_bars:0,5,quark:iron_plate:1,15,STAINED_CLAY:15,15,STAINED_CLAY:7,100)
RandomBlock(-8,31,5,minecraft:iron_bars:0,5,quark:iron_plate:1,15,STAINED_CLAY:15,15,STAINED_CLAY:7,100)
RandomBlock(-8,31,6,minecraft:iron_bars:0,5,quark:iron_plate:1,15,STAINED_CLAY:15,15,STAINED_CLAY:7,100)
RandomBlock(-8,31,7,minecraft:iron_bars:0,5,quark:iron_plate:1,15,STAINED_CLAY:15,15,STAINED_CLAY:7,100)
RandomBlock(-8,31,8,minecraft:iron_bars:0,5,quark:iron_plate:1,15,STAINED_CLAY:15,15,STAINED_CLAY:7,100)
RandomBlock(-8,32,3,minecraft:iron_bars:0,5,quark:iron_plate:1,15,STAINED_CLAY:15,15,STAINED_CLAY:7,100)
RandomBlock(-8,32,4,minecraft:iron_bars:0,5,quark:iron_plate:1,15,STAINED_CLAY:15,15,STAINED_CLAY:7,100)
RandomBlock(-8,32,5,minecraft:iron_bars:0,5,quark:iron_plate:1,15,STAINED_CLAY:15,15,STAINED_CLAY:7,100)
RandomBlock(-8,32,6,minecraft:iron_bars:0,5,quark:iron_plate:1,15,STAINED_CLAY:15,15,STAINED_CLAY:7,100)
RandomBlock(-8,32,7,minecraft:iron_bars:0,5,quark:iron_plate:1,15,STAINED_CLAY:15,15,STAINED_CLAY:7,100)
RandomBlock(-8,32,8,minecraft:iron_bars:0,5,quark:iron_plate:1,15,STAINED_CLAY:15,15,STAINED_CLAY:7,100)
RandomBlock(-8,33,3,minecraft:iron_bars:0,5,quark:iron_plate:1,15,STAINED_CLAY:15,15,STAINED_CLAY:7,100)
RandomBlock(-8,33,4,minecraft:iron_bars:0,5,quark:iron_plate:1,15,STAINED_CLAY:15,15,STAINED_CLAY:7,100)
RandomBlock(-8,33,5,minecraft:iron_bars:0,5,quark:iron_plate:1,15,STAINED_CLAY:15,15,STAINED_CLAY:7,100)
RandomBlock(-8,33,6,minecraft:iron_bars:0,5,quark:iron_plate:1,15,STAINED_CLAY:15,15,STAINED_CLAY:7,100)
RandomBlock(-8,33,7,minecraft:iron_bars:0,5,quark:iron_plate:1,15,STAINED_CLAY:15,15,STAINED_CLAY:7,100)
RandomBlock(-8,33,8,minecraft:iron_bars:0,5,quark:iron_plate:1,15,STAINED_CLAY:15,15,STAINED_CLAY:7,100)
RandomBlock(-8,34,3,minecraft:iron_bars:0,5,quark:iron_plate:1,15,STAINED_CLAY:15,15,STAINED_CLAY:7,100)
RandomBlock(-8,34,4,minecraft:iron_bars:0,5,quark:iron_plate:1,15,STAINED_CLAY:15,15,STAINED_CLAY:7,100)
RandomBlock(-8,34,5,minecraft:iron_bars:0,5,quark:iron_plate:1,15,STAINED_CLAY:15,15,STAINED_CLAY:7,100)
RandomBlock(-8,34,6,minecraft:iron_bars:0,5,quark:iron_plate:1,15,STAINED_CLAY:15,15,STAINED_CLAY:7,100)
RandomBlock(-8,34,7,minecraft:iron_bars:0,5,quark:iron_plate:1,15,STAINED_CLAY:15,15,STAINED_CLAY:7,100)
RandomBlock(-8,34,8,minecraft:iron_bars:0,5,quark:iron_plate:1,15,STAINED_CLAY:15,15,STAINED_CLAY:7,100)
RandomBlock(-8,35,3,minecraft:iron_bars:0,5,quark:iron_plate:1,15,STAINED_CLAY:15,15,STAINED_CLAY:7,100)
RandomBlock(-8,35,4,minecraft:iron_bars:0,5,quark:iron_plate:1,15,STAINED_CLAY:15,15,STAINED_CLAY:7,100)
RandomBlock(-8,35,5,minecraft:iron_bars:0,5,quark:iron_plate:1,15,STAINED_CLAY:15,15,STAINED_CLAY:7,100)
RandomBlock(-8,35,6,minecraft:iron_bars:0,5,quark:iron_plate:1,15,STAINED_CLAY:15,15,STAINED_CLAY:7,100)
RandomBlock(-8,35,7,minecraft:iron_bars:0,5,quark:iron_plate:1,15,STAINED_CLAY:15,15,STAINED_CLAY:7,100)
RandomBlock(-8,35,8,minecraft:iron_bars:0,5,quark:iron_plate:1,15,STAINED_CLAY:15,15,STAINED_CLAY:7,100)
RandomBlock(-8,36,3,minecraft:iron_bars:0,5,quark:iron_plate:1,15,STAINED_CLAY:15,15,STAINED_CLAY:7,100)
RandomBlock(-8,36,4,minecraft:iron_bars:0,5,quark:iron_plate:1,15,STAINED_CLAY:15,15,STAINED_CLAY:7,100)
RandomBlock(-8,36,5,minecraft:iron_bars:0,5,quark:iron_plate:1,15,STAINED_CLAY:15,15,STAINED_CLAY:7,100)
RandomBlock(-8,36,6,minecraft:iron_bars:0,5,quark:iron_plate:1,15,STAINED_CLAY:15,15,STAINED_CLAY:7,100)
RandomBlock(-8,36,7,minecraft:iron_bars:0,5,quark:iron_plate:1,15,STAINED_CLAY:15,15,STAINED_CLAY:7,100)
RandomBlock(-8,36,8,minecraft:iron_bars:0,5,quark:iron_plate:1,15,STAINED_CLAY:15,15,STAINED_CLAY:7,100)
RandomBlock(-8,37,3,minecraft:iron_bars:0,5,quark:iron_plate:1,15,STAINED_CLAY:15,15,STAINED_CLAY:7,100)
RandomBlock(-8,37,4,minecraft:iron_bars:0,5,quark:iron_plate:1,15,STAINED_CLAY:15,15,STAINED_CLAY:7,100)
RandomBlock(-8,37,5,minecraft:iron_bars:0,5,quark:iron_plate:1,15,STAINED_CLAY:15,15,STAINED_CLAY:7,100)
RandomBlock(-8,37,6,minecraft:iron_bars:0,5,quark:iron_plate:1,15,STAINED_CLAY:15,15,STAINED_CLAY:7,100)
RandomBlock(-8,37,7,minecraft:iron_bars:0,5,quark:iron_plate:1,15,STAINED_CLAY:15,15,STAINED_CLAY:7,100)
RandomBlock(-8,37,8,minecraft:iron_bars:0,5,quark:iron_plate:1,15,STAINED_CLAY:15,15,STAINED_CLAY:7,100)
RandomBlock(-8,38,3,minecraft:iron_bars:0,5,quark:iron_plate:1,15,STAINED_CLAY:15,15,STAINED_CLAY:7,100)
RandomBlock(-8,38,4,minecraft:iron_bars:0,5,quark:iron_plate:1,15,STAINED_CLAY:15,15,STAINED_CLAY:7,100)
RandomBlock(-8,38,5,minecraft:iron_bars:0,5,quark:iron_plate:1,15,STAINED_CLAY:15,15,STAINED_CLAY:7,100)
RandomBlock(-8,38,6,minecraft:iron_bars:0,5,quark:iron_plate:1,15,STAINED_CLAY:15,15,STAINED_CLAY:7,100)
RandomBlock(-8,38,7,minecraft:iron_bars:0,5,quark:iron_plate:1,15,STAINED_CLAY:15,15,STAINED_CLAY:7,100)
RandomBlock(-8,38,8,minecraft:iron_bars:0,5,quark:iron_plate:1,15,STAINED_CLAY:15,15,STAINED_CLAY:7,100)
RandomBlock(-8,39,3,minecraft:iron_bars:0,5,quark:iron_plate:1,15,STAINED_CLAY:15,15,STAINED_CLAY:7,100)
RandomBlock(-8,39,4,minecraft:iron_bars:0,5,quark:iron_plate:1,15,STAINED_CLAY:15,15,STAINED_CLAY:7,100)
RandomBlock(-8,39,5,minecraft:iron_bars:0,5,quark:iron_plate:1,15,STAINED_CLAY:15,15,STAINED_CLAY:7,100)
RandomBlock(-8,39,6,minecraft:iron_bars:0,5,quark:iron_plate:1,15,STAINED_CLAY:15,15,STAINED_CLAY:7,100)
RandomBlock(-8,39,7,minecraft:iron_bars:0,5,quark:iron_plate:1,15,STAINED_CLAY:15,15,STAINED_CLAY:7,100)
RandomBlock(-8,39,8,minecraft:iron_bars:0,5,quark:iron_plate:1,15,STAINED_CLAY:15,15,STAINED_CLAY:7,100)
RandomBlock(-8,40,3,minecraft:iron_bars:0,5,quark:iron_plate:1,15,STAINED_CLAY:15,15,STAINED_CLAY:7,100)
RandomBlock(-8,40,4,minecraft:iron_bars:0,5,quark:iron_plate:1,15,STAINED_CLAY:15,15,STAINED_CLAY:7,100)
RandomBlock(-8,40,5,minecraft:iron_bars:0,5,quark:iron_plate:1,15,STAINED_CLAY:15,15,STAINED_CLAY:7,100)
RandomBlock(-8,40,6,minecraft:iron_bars:0,5,quark:iron_plate:1,15,STAINED_CLAY:15,15,STAINED_CLAY:7,100)
RandomBlock(-8,40,7,minecraft:iron_bars:0,5,quark:iron_plate:1,15,STAINED_CLAY:15,15,STAINED_CLAY:7,100)
RandomBlock(-8,40,8,minecraft:iron_bars:0,5,quark:iron_plate:1,15,STAINED_CLAY:15,15,STAINED_CLAY:7,100)
RandomBlock(-8,41,3,minecraft:iron_bars:0,5,quark:iron_plate:1,15,STAINED_CLAY:15,15,STAINED_CLAY:7,100)
RandomBlock(-8,41,4,minecraft:iron_bars:0,5,quark:iron_plate:1,15,STAINED_CLAY:15,15,STAINED_CLAY:7,100)
RandomBlock(-8,41,5,minecraft:iron_bars:0,5,quark:iron_plate:1,15,STAINED_CLAY:15,15,STAINED_CLAY:7,100)
RandomBlock(-8,41,6,minecraft:iron_bars:0,5,quark:iron_plate:1,15,STAINED_CLAY:15,15,STAINED_CLAY:7,100)
RandomBlock(-8,41,7,minecraft:iron_bars:0,5,quark:iron_plate:1,15,STAINED_CLAY:15,15,STAINED_CLAY:7,100)
RandomBlock(-8,41,8,minecraft:iron_bars:0,5,quark:iron_plate:1,15,STAINED_CLAY:15,15,STAINED_CLAY:7,100)
RandomBlock(-8,42,3,minecraft:iron_bars:0,5,quark:iron_plate:1,15,STAINED_CLAY:15,15,STAINED_CLAY:7,100)
RandomBlock(-8,42,4,minecraft:iron_bars:0,5,quark:iron_plate:1,15,STAINED_CLAY:15,15,STAINED_CLAY:7,100)
RandomBlock(-8,42,5,minecraft:iron_bars:0,5,quark:iron_plate:1,15,STAINED_CLAY:15,15,STAINED_CLAY:7,100)
RandomBlock(-8,42,6,minecraft:iron_bars:0,5,quark:iron_plate:1,15,STAINED_CLAY:15,15,STAINED_CLAY:7,100)
RandomBlock(-8,42,7,minecraft:iron_bars:0,5,quark:iron_plate:1,15,STAINED_CLAY:15,15,STAINED_CLAY:7,100)
RandomBlock(-8,42,8,minecraft:iron_bars:0,5,quark:iron_plate:1,15,STAINED_CLAY:15,15,STAINED_CLAY:7,100)
RandomBlock(-8,43,3,minecraft:iron_bars:0,5,quark:iron_plate:1,15,STAINED_CLAY:15,15,STAINED_CLAY:7,100)
RandomBlock(-8,43,4,minecraft:iron_bars:0,5,quark:iron_plate:1,15,STAINED_CLAY:15,15,STAINED_CLAY:7,100)
RandomBlock(-8,43,5,minecraft:iron_bars:0,5,quark:iron_plate:1,15,STAINED_CLAY:15,15,STAINED_CLAY:7,100)
RandomBlock(-8,43,6,minecraft:iron_bars:0,5,quark:iron_plate:1,15,STAINED_CLAY:15,15,STAINED_CLAY:7,100)
RandomBlock(-8,43,7,minecraft:iron_bars:0,5,quark:iron_plate:1,15,STAINED_CLAY:15,15,STAINED_CLAY:7,100)
RandomBlock(-8,43,8,minecraft:iron_bars:0,5,quark:iron_plate:1,15,STAINED_CLAY:15,15,STAINED_CLAY:7,100)
RandomBlock(-8,44,-7,minecraft:iron_bars:0,5,STAINED_CLAY:15,5,STAINED_CLAY:7,5,quark:iron_plate_slab:8,15,quark:world_stone_pavement:2,15,STAINED_CLAY:9,100)
RandomBlock(-8,44,-6,minecraft:iron_bars:0,5,STAINED_CLAY:15,5,STAINED_CLAY:7,5,quark:iron_plate_slab:8,15,quark:world_stone_pavement:2,15,STAINED_CLAY:9,100)
RandomBlock(-8,44,-5,minecraft:iron_bars:0,5,STAINED_CLAY:15,5,STAINED_CLAY:7,5,quark:iron_plate_slab:8,15,quark:world_stone_pavement:2,15,STAINED_CLAY:9,100)
RandomBlock(-8,44,-4,minecraft:iron_bars:0,5,STAINED_CLAY:15,5,STAINED_CLAY:7,5,quark:iron_plate_slab:8,15,quark:world_stone_pavement:2,15,STAINED_CLAY:9,100)
RandomBlock(-8,44,-3,minecraft:iron_bars:0,5,STAINED_CLAY:15,5,STAINED_CLAY:7,5,quark:iron_plate_slab:8,15,quark:world_stone_pavement:2,15,STAINED_CLAY:9,100)
RandomBlock(-8,44,-2,minecraft:iron_bars:0,5,STAINED_CLAY:15,5,STAINED_CLAY:7,5,quark:iron_plate_slab:8,15,quark:world_stone_pavement:2,15,STAINED_CLAY:9,100)
RandomBlock(-8,44,-1,minecraft:iron_bars:0,5,STAINED_CLAY:15,5,STAINED_CLAY:7,5,quark:iron_plate_slab:8,15,quark:world_stone_pavement:2,15,STAINED_CLAY:9,100)
RandomBlock(-8,44,0,minecraft:iron_bars:0,5,STAINED_CLAY:15,5,STAINED_CLAY:7,5,quark:iron_plate_slab:8,15,quark:world_stone_pavement:2,15,STAINED_CLAY:9,100)
RandomBlock(-8,44,1,minecraft:iron_bars:0,5,STAINED_CLAY:15,5,STAINED_CLAY:7,5,quark:iron_plate_slab:8,15,quark:world_stone_pavement:2,15,STAINED_CLAY:9,100)
RandomBlock(-8,44,2,minecraft:iron_bars:0,5,STAINED_CLAY:15,5,STAINED_CLAY:7,5,quark:iron_plate_slab:8,15,quark:world_stone_pavement:2,15,STAINED_CLAY:9,100)
RandomBlock(-8,44,3,minecraft:iron_bars:0,5,STAINED_CLAY:15,5,STAINED_CLAY:7,5,quark:iron_plate_slab:8,15,quark:world_stone_pavement:2,15,STAINED_CLAY:9,100)
RandomBlock(-8,44,4,minecraft:iron_bars:0,5,STAINED_CLAY:15,5,STAINED_CLAY:7,5,quark:iron_plate_slab:8,15,quark:world_stone_pavement:2,15,STAINED_CLAY:9,100)
RandomBlock(-8,44,5,minecraft:iron_bars:0,5,STAINED_CLAY:15,5,STAINED_CLAY:7,5,quark:iron_plate_slab:8,15,quark:world_stone_pavement:2,15,STAINED_CLAY:9,100)
RandomBlock(-8,44,6,minecraft:iron_bars:0,5,STAINED_CLAY:15,5,STAINED_CLAY:7,5,quark:iron_plate_slab:8,15,quark:world_stone_pavement:2,15,STAINED_CLAY:9,100)
RandomBlock(-8,44,7,minecraft:iron_bars:0,5,STAINED_CLAY:15,5,STAINED_CLAY:7,5,quark:iron_plate_slab:8,15,quark:world_stone_pavement:2,15,STAINED_CLAY:9,100)
RandomBlock(-8,44,8,minecraft:iron_bars:0,5,STAINED_CLAY:15,5,STAINED_CLAY:7,5,quark:iron_plate_slab:8,15,quark:world_stone_pavement:2,15,STAINED_CLAY:9,100)
Block(-8,45,-6,quark:iron_plate:1)
Block(-8,45,-5,quark:iron_plate:1)
Block(-8,45,-3,minecraft:iron_bars:0)
Block(-8,45,5,minecraft:iron_bars:0)
Block(-8,46,-7,quark:iron_plate:1)
Block(-8,46,-6,COAL_BLOCK:0)
Block(-8,46,-5,COAL_BLOCK:0)
Block(-8,46,-4,quark:iron_plate:1)
Block(-8,46,-3,quark:iron_plate:1)
Block(-8,46,-2,quark:iron_plate:1)
Block(-8,46,-1,quark:iron_plate:1)
Block(-8,46,0,quark:iron_plate:1)
Block(-8,46,1,quark:iron_plate:1)
Block(-8,46,2,quark:iron_plate:1)
Block(-8,46,3,quark:iron_plate:1)
Block(-8,46,4,quark:iron_plate:1)
Block(-8,46,5,quark:iron_plate:1)
Block(-8,47,-7,quark:iron_plate:1)
Block(-8,47,-6,COAL_BLOCK:0)
Block(-8,47,-5,COAL_BLOCK:0)
Block(-8,47,-4,quark:iron_plate:1)
Block(-8,47,-3,quark:iron_plate:1)
Block(-8,47,-2,quark:iron_plate:1)
Block(-8,47,-1,quark:iron_plate:1)
Block(-8,47,0,quark:iron_plate:1)
Block(-8,47,1,quark:iron_plate:1)
Block(-8,47,2,quark:iron_plate:1)
Block(-8,47,3,quark:iron_plate:1)
Block(-8,47,4,quark:iron_plate:1)
Block(-8,47,5,quark:iron_plate:1)
Block(-8,48,-7,quark:iron_plate:1)
Block(-8,48,-6,COAL_BLOCK:0)
Block(-8,48,-5,COAL_BLOCK:0)
Block(-8,48,-4,quark:iron_plate:1)
Block(-8,48,5,minecraft:iron_bars:0)
Block(-8,49,-7,minecraft:iron_bars:0)
Block(-8,49,-6,STEP:0)
Block(-8,49,-5,STEP:0)
Block(-8,49,5,minecraft:iron_bars:0)
RandomBlock(-8,50,-7,minecraft:iron_bars:0,5,STAINED_CLAY:15,5,STAINED_CLAY:7,5,quark:iron_plate_slab:8,15,quark:world_stone_pavement:2,15,STAINED_CLAY:9,100)
RandomBlock(-8,50,-6,minecraft:iron_bars:0,5,STAINED_CLAY:15,5,STAINED_CLAY:7,5,quark:iron_plate_slab:8,15,quark:world_stone_pavement:2,15,STAINED_CLAY:9,100)
RandomBlock(-8,50,-5,minecraft:iron_bars:0,5,STAINED_CLAY:15,5,STAINED_CLAY:7,5,quark:iron_plate_slab:8,15,quark:world_stone_pavement:2,15,STAINED_CLAY:9,100)
RandomBlock(-8,50,-4,minecraft:iron_bars:0,5,STAINED_CLAY:15,5,STAINED_CLAY:7,5,quark:iron_plate_slab:8,15,quark:world_stone_pavement:2,15,STAINED_CLAY:9,100)
RandomBlock(-8,50,-3,minecraft:iron_bars:0,5,STAINED_CLAY:15,5,STAINED_CLAY:7,5,quark:iron_plate_slab:8,15,quark:world_stone_pavement:2,15,STAINED_CLAY:9,100)
RandomBlock(-8,50,-2,minecraft:iron_bars:0,5,STAINED_CLAY:15,5,STAINED_CLAY:7,5,quark:iron_plate_slab:8,15,quark:world_stone_pavement:2,15,STAINED_CLAY:9,100)
RandomBlock(-8,50,-1,minecraft:iron_bars:0,5,STAINED_CLAY:15,5,STAINED_CLAY:7,5,quark:iron_plate_slab:8,15,quark:world_stone_pavement:2,15,STAINED_CLAY:9,100)
RandomBlock(-8,50,0,minecraft:iron_bars:0,5,STAINED_CLAY:15,5,STAINED_CLAY:7,5,quark:iron_plate_slab:8,15,quark:world_stone_pavement:2,15,STAINED_CLAY:9,100)
RandomBlock(-8,50,1,minecraft:iron_bars:0,5,STAINED_CLAY:15,5,STAINED_CLAY:7,5,quark:iron_plate_slab:8,15,quark:world_stone_pavement:2,15,STAINED_CLAY:9,100)
RandomBlock(-8,50,2,minecraft:iron_bars:0,5,STAINED_CLAY:15,5,STAINED_CLAY:7,5,quark:iron_plate_slab:8,15,quark:world_stone_pavement:2,15,STAINED_CLAY:9,100)
RandomBlock(-8,50,3,minecraft:iron_bars:0,5,STAINED_CLAY:15,5,STAINED_CLAY:7,5,quark:iron_plate_slab:8,15,quark:world_stone_pavement:2,15,STAINED_CLAY:9,100)
RandomBlock(-8,50,4,minecraft:iron_bars:0,5,STAINED_CLAY:15,5,STAINED_CLAY:7,5,quark:iron_plate_slab:8,15,quark:world_stone_pavement:2,15,STAINED_CLAY:9,100)
RandomBlock(-8,50,5,minecraft:iron_bars:0,5,STAINED_CLAY:15,5,STAINED_CLAY:7,5,quark:iron_plate_slab:8,15,quark:world_stone_pavement:2,15,STAINED_CLAY:9,100)
RandomBlock(-8,50,6,minecraft:iron_bars:0,5,STAINED_CLAY:15,5,STAINED_CLAY:7,5,quark:iron_plate_slab:8,15,quark:world_stone_pavement:2,15,STAINED_CLAY:9,100)
RandomBlock(-8,50,7,minecraft:iron_bars:0,5,STAINED_CLAY:15,5,STAINED_CLAY:7,5,quark:iron_plate_slab:8,15,quark:world_stone_pavement:2,15,STAINED_CLAY:9,100)
RandomBlock(-8,50,8,minecraft:iron_bars:0,5,STAINED_CLAY:15,5,STAINED_CLAY:7,5,quark:iron_plate_slab:8,15,quark:world_stone_pavement:2,15,STAINED_CLAY:9,100)
Block(-8,51,0,quark:iron_plate:1)
Block(-8,52,0,quark:iron_plate:1)
Block(-8,53,0,quark:iron_plate:1)
Block(-8,54,0,quark:iron_plate:1)
Block(-8,55,0,quark:iron_plate:1)
Block(-8,56,0,quark:iron_plate:1)
Block(-8,57,0,quark:iron_plate:1)
Block(-8,58,0,quark:iron_plate:1)
Block(-8,59,0,quark:iron_plate:1)
Block(-8,65,8,minecraft:iron_bars:0)
Block(-8,66,8,IRON_FENCE:0)
RandomBlock(-7,0,3,minecraft:iron_bars:0,5,quark:iron_plate:1,15,STAINED_CLAY:15,15,STAINED_CLAY:7,100)
RandomBlock(-7,0,4,minecraft:iron_bars:0,5,quark:iron_plate:1,15,STAINED_CLAY:15,15,STAINED_CLAY:7,100)
RandomBlock(-7,0,5,minecraft:iron_bars:0,5,quark:iron_plate:1,15,STAINED_CLAY:15,15,STAINED_CLAY:7,100)
RandomBlock(-7,0,6,minecraft:iron_bars:0,5,quark:iron_plate:1,15,STAINED_CLAY:15,15,STAINED_CLAY:7,100)
RandomBlock(-7,0,7,minecraft:iron_bars:0,5,quark:iron_plate:1,15,STAINED_CLAY:15,15,STAINED_CLAY:7,100)
RandomBlock(-7,0,8,minecraft:iron_bars:0,5,quark:iron_plate:1,15,STAINED_CLAY:15,15,STAINED_CLAY:7,100)
RandomBlock(-7,1,3,minecraft:iron_bars:0,5,quark:iron_plate:1,15,STAINED_CLAY:15,15,STAINED_CLAY:7,100)
RandomBlock(-7,1,4,minecraft:iron_bars:0,5,quark:iron_plate:1,15,STAINED_CLAY:15,15,STAINED_CLAY:7,100)
RandomBlock(-7,1,5,minecraft:iron_bars:0,5,quark:iron_plate:1,15,STAINED_CLAY:15,15,STAINED_CLAY:7,100)
RandomBlock(-7,1,6,minecraft:iron_bars:0,5,quark:iron_plate:1,15,STAINED_CLAY:15,15,STAINED_CLAY:7,100)
RandomBlock(-7,1,7,minecraft:iron_bars:0,5,quark:iron_plate:1,15,STAINED_CLAY:15,15,STAINED_CLAY:7,100)
RandomBlock(-7,1,8,minecraft:iron_bars:0,5,quark:iron_plate:1,15,STAINED_CLAY:15,15,STAINED_CLAY:7,100)
RandomBlock(-7,2,3,minecraft:iron_bars:0,5,quark:iron_plate:1,15,STAINED_CLAY:15,15,STAINED_CLAY:7,100)
RandomBlock(-7,2,4,minecraft:iron_bars:0,5,quark:iron_plate:1,15,STAINED_CLAY:15,15,STAINED_CLAY:7,100)
RandomBlock(-7,2,5,minecraft:iron_bars:0,5,quark:iron_plate:1,15,STAINED_CLAY:15,15,STAINED_CLAY:7,100)
RandomBlock(-7,2,6,minecraft:iron_bars:0,5,quark:iron_plate:1,15,STAINED_CLAY:15,15,STAINED_CLAY:7,100)
RandomBlock(-7,2,7,minecraft:iron_bars:0,5,quark:iron_plate:1,15,STAINED_CLAY:15,15,STAINED_CLAY:7,100)
RandomBlock(-7,2,8,minecraft:iron_bars:0,5,quark:iron_plate:1,15,STAINED_CLAY:15,15,STAINED_CLAY:7,100)
RandomBlock(-7,3,3,minecraft:iron_bars:0,5,quark:iron_plate:1,15,STAINED_CLAY:15,15,STAINED_CLAY:7,100)
RandomBlock(-7,3,4,minecraft:iron_bars:0,5,quark:iron_plate:1,15,STAINED_CLAY:15,15,STAINED_CLAY:7,100)
RandomBlock(-7,3,5,minecraft:iron_bars:0,5,quark:iron_plate:1,15,STAINED_CLAY:15,15,STAINED_CLAY:7,100)
RandomBlock(-7,3,6,minecraft:iron_bars:0,5,quark:iron_plate:1,15,STAINED_CLAY:15,15,STAINED_CLAY:7,100)
RandomBlock(-7,3,7,minecraft:iron_bars:0,5,quark:iron_plate:1,15,STAINED_CLAY:15,15,STAINED_CLAY:7,100)
RandomBlock(-7,3,8,minecraft:iron_bars:0,5,quark:iron_plate:1,15,STAINED_CLAY:15,15,STAINED_CLAY:7,100)
RandomBlock(-7,4,3,minecraft:iron_bars:0,5,quark:iron_plate:1,15,STAINED_CLAY:15,15,STAINED_CLAY:7,100)
RandomBlock(-7,4,4,minecraft:iron_bars:0,5,quark:iron_plate:1,15,STAINED_CLAY:15,15,STAINED_CLAY:7,100)
RandomBlock(-7,4,5,minecraft:iron_bars:0,5,quark:iron_plate:1,15,STAINED_CLAY:15,15,STAINED_CLAY:7,100)
RandomBlock(-7,4,6,minecraft:iron_bars:0,5,quark:iron_plate:1,15,STAINED_CLAY:15,15,STAINED_CLAY:7,100)
RandomBlock(-7,4,7,minecraft:iron_bars:0,5,quark:iron_plate:1,15,STAINED_CLAY:15,15,STAINED_CLAY:7,100)
RandomBlock(-7,4,8,minecraft:iron_bars:0,5,quark:iron_plate:1,15,STAINED_CLAY:15,15,STAINED_CLAY:7,100)
RandomBlock(-7,5,3,minecraft:iron_bars:0,5,quark:iron_plate:1,15,STAINED_CLAY:15,15,STAINED_CLAY:7,100)
RandomBlock(-7,5,4,minecraft:iron_bars:0,5,quark:iron_plate:1,15,STAINED_CLAY:15,15,STAINED_CLAY:7,100)
RandomBlock(-7,5,5,minecraft:iron_bars:0,5,quark:iron_plate:1,15,STAINED_CLAY:15,15,STAINED_CLAY:7,100)
RandomBlock(-7,5,6,minecraft:iron_bars:0,5,quark:iron_plate:1,15,STAINED_CLAY:15,15,STAINED_CLAY:7,100)
RandomBlock(-7,5,7,minecraft:iron_bars:0,5,quark:iron_plate:1,15,STAINED_CLAY:15,15,STAINED_CLAY:7,100)
RandomBlock(-7,5,8,minecraft:iron_bars:0,5,quark:iron_plate:1,15,STAINED_CLAY:15,15,STAINED_CLAY:7,100)
RandomBlock(-7,6,3,minecraft:iron_bars:0,5,quark:iron_plate:1,15,STAINED_CLAY:15,15,STAINED_CLAY:7,100)
RandomBlock(-7,6,4,minecraft:iron_bars:0,5,quark:iron_plate:1,15,STAINED_CLAY:15,15,STAINED_CLAY:7,100)
RandomBlock(-7,6,5,minecraft:iron_bars:0,5,quark:iron_plate:1,15,STAINED_CLAY:15,15,STAINED_CLAY:7,100)
RandomBlock(-7,6,6,minecraft:iron_bars:0,5,quark:iron_plate:1,15,STAINED_CLAY:15,15,STAINED_CLAY:7,100)
RandomBlock(-7,6,7,minecraft:iron_bars:0,5,quark:iron_plate:1,15,STAINED_CLAY:15,15,STAINED_CLAY:7,100)
RandomBlock(-7,6,8,minecraft:iron_bars:0,5,quark:iron_plate:1,15,STAINED_CLAY:15,15,STAINED_CLAY:7,100)
RandomBlock(-7,7,3,minecraft:iron_bars:0,5,quark:iron_plate:1,15,STAINED_CLAY:15,15,STAINED_CLAY:7,100)
RandomBlock(-7,7,4,minecraft:iron_bars:0,5,quark:iron_plate:1,15,STAINED_CLAY:15,15,STAINED_CLAY:7,100)
RandomBlock(-7,7,5,minecraft:iron_bars:0,5,quark:iron_plate:1,15,STAINED_CLAY:15,15,STAINED_CLAY:7,100)
RandomBlock(-7,7,6,minecraft:iron_bars:0,5,quark:iron_plate:1,15,STAINED_CLAY:15,15,STAINED_CLAY:7,100)
RandomBlock(-7,7,7,minecraft:iron_bars:0,5,quark:iron_plate:1,15,STAINED_CLAY:15,15,STAINED_CLAY:7,100)
RandomBlock(-7,7,8,minecraft:iron_bars:0,5,quark:iron_plate:1,15,STAINED_CLAY:15,15,STAINED_CLAY:7,100)
RandomBlock(-7,8,3,minecraft:iron_bars:0,5,quark:iron_plate:1,15,STAINED_CLAY:15,15,STAINED_CLAY:7,100)
RandomBlock(-7,8,4,minecraft:iron_bars:0,5,quark:iron_plate:1,15,STAINED_CLAY:15,15,STAINED_CLAY:7,100)
RandomBlock(-7,8,5,minecraft:iron_bars:0,5,quark:iron_plate:1,15,STAINED_CLAY:15,15,STAINED_CLAY:7,100)
RandomBlock(-7,8,6,minecraft:iron_bars:0,5,quark:iron_plate:1,15,STAINED_CLAY:15,15,STAINED_CLAY:7,100)
RandomBlock(-7,8,7,minecraft:iron_bars:0,5,quark:iron_plate:1,15,STAINED_CLAY:15,15,STAINED_CLAY:7,100)
RandomBlock(-7,8,8,minecraft:iron_bars:0,5,quark:iron_plate:1,15,STAINED_CLAY:15,15,STAINED_CLAY:7,100)
RandomBlock(-7,9,3,minecraft:iron_bars:0,5,quark:iron_plate:1,15,STAINED_CLAY:15,15,STAINED_CLAY:7,100)
RandomBlock(-7,9,4,minecraft:iron_bars:0,5,quark:iron_plate:1,15,STAINED_CLAY:15,15,STAINED_CLAY:7,100)
RandomBlock(-7,9,5,minecraft:iron_bars:0,5,quark:iron_plate:1,15,STAINED_CLAY:15,15,STAINED_CLAY:7,100)
RandomBlock(-7,9,6,minecraft:iron_bars:0,5,quark:iron_plate:1,15,STAINED_CLAY:15,15,STAINED_CLAY:7,100)
RandomBlock(-7,9,7,minecraft:iron_bars:0,5,quark:iron_plate:1,15,STAINED_CLAY:15,15,STAINED_CLAY:7,100)
RandomBlock(-7,9,8,minecraft:iron_bars:0,5,quark:iron_plate:1,15,STAINED_CLAY:15,15,STAINED_CLAY:7,100)
RandomBlock(-7,10,3,minecraft:iron_bars:0,5,quark:iron_plate:1,15,STAINED_CLAY:15,15,STAINED_CLAY:7,100)
RandomBlock(-7,10,4,minecraft:iron_bars:0,5,quark:iron_plate:1,15,STAINED_CLAY:15,15,STAINED_CLAY:7,100)
RandomBlock(-7,10,5,minecraft:iron_bars:0,5,quark:iron_plate:1,15,STAINED_CLAY:15,15,STAINED_CLAY:7,100)
RandomBlock(-7,10,6,minecraft:iron_bars:0,5,quark:iron_plate:1,15,STAINED_CLAY:15,15,STAINED_CLAY:7,100)
RandomBlock(-7,10,7,minecraft:iron_bars:0,5,quark:iron_plate:1,15,STAINED_CLAY:15,15,STAINED_CLAY:7,100)
RandomBlock(-7,10,8,minecraft:iron_bars:0,5,quark:iron_plate:1,15,STAINED_CLAY:15,15,STAINED_CLAY:7,100)
RandomBlock(-7,11,3,minecraft:iron_bars:0,5,quark:iron_plate:1,15,STAINED_CLAY:15,15,STAINED_CLAY:7,100)
RandomBlock(-7,11,4,minecraft:iron_bars:0,5,quark:iron_plate:1,15,STAINED_CLAY:15,15,STAINED_CLAY:7,100)
RandomBlock(-7,11,5,minecraft:iron_bars:0,5,quark:iron_plate:1,15,STAINED_CLAY:15,15,STAINED_CLAY:7,100)
RandomBlock(-7,11,6,minecraft:iron_bars:0,5,quark:iron_plate:1,15,STAINED_CLAY:15,15,STAINED_CLAY:7,100)
RandomBlock(-7,11,7,minecraft:iron_bars:0,5,quark:iron_plate:1,15,STAINED_CLAY:15,15,STAINED_CLAY:7,100)
RandomBlock(-7,11,8,minecraft:iron_bars:0,5,quark:iron_plate:1,15,STAINED_CLAY:15,15,STAINED_CLAY:7,100)
RandomBlock(-7,12,3,minecraft:iron_bars:0,5,quark:iron_plate:1,15,STAINED_CLAY:15,15,STAINED_CLAY:7,100)
RandomBlock(-7,12,4,minecraft:iron_bars:0,5,quark:iron_plate:1,15,STAINED_CLAY:15,15,STAINED_CLAY:7,100)
RandomBlock(-7,12,5,minecraft:iron_bars:0,5,quark:iron_plate:1,15,STAINED_CLAY:15,15,STAINED_CLAY:7,100)
RandomBlock(-7,12,6,minecraft:iron_bars:0,5,quark:iron_plate:1,15,STAINED_CLAY:15,15,STAINED_CLAY:7,100)
RandomBlock(-7,12,7,minecraft:iron_bars:0,5,quark:iron_plate:1,15,STAINED_CLAY:15,15,STAINED_CLAY:7,100)
RandomBlock(-7,12,8,minecraft:iron_bars:0,5,quark:iron_plate:1,15,STAINED_CLAY:15,15,STAINED_CLAY:7,100)
RandomBlock(-7,13,3,minecraft:iron_bars:0,5,quark:iron_plate:1,15,STAINED_CLAY:15,15,STAINED_CLAY:7,100)
RandomBlock(-7,13,4,minecraft:iron_bars:0,5,quark:iron_plate:1,15,STAINED_CLAY:15,15,STAINED_CLAY:7,100)
RandomBlock(-7,13,5,minecraft:iron_bars:0,5,quark:iron_plate:1,15,STAINED_CLAY:15,15,STAINED_CLAY:7,100)
RandomBlock(-7,13,6,minecraft:iron_bars:0,5,quark:iron_plate:1,15,STAINED_CLAY:15,15,STAINED_CLAY:7,100)
RandomBlock(-7,13,7,minecraft:iron_bars:0,5,quark:iron_plate:1,15,STAINED_CLAY:15,15,STAINED_CLAY:7,100)
RandomBlock(-7,13,8,minecraft:iron_bars:0,5,quark:iron_plate:1,15,STAINED_CLAY:15,15,STAINED_CLAY:7,100)
RandomBlock(-7,14,3,minecraft:iron_bars:0,5,quark:iron_plate:1,15,STAINED_CLAY:15,15,STAINED_CLAY:7,100)
RandomBlock(-7,14,4,minecraft:iron_bars:0,5,quark:iron_plate:1,15,STAINED_CLAY:15,15,STAINED_CLAY:7,100)
RandomBlock(-7,14,5,minecraft:iron_bars:0,5,quark:iron_plate:1,15,STAINED_CLAY:15,15,STAINED_CLAY:7,100)
RandomBlock(-7,14,6,minecraft:iron_bars:0,5,quark:iron_plate:1,15,STAINED_CLAY:15,15,STAINED_CLAY:7,100)
RandomBlock(-7,14,7,minecraft:iron_bars:0,5,quark:iron_plate:1,15,STAINED_CLAY:15,15,STAINED_CLAY:7,100)
RandomBlock(-7,14,8,minecraft:iron_bars:0,5,quark:iron_plate:1,15,STAINED_CLAY:15,15,STAINED_CLAY:7,100)
RandomBlock(-7,15,3,minecraft:iron_bars:0,5,quark:iron_plate:1,15,STAINED_CLAY:15,15,STAINED_CLAY:7,100)
RandomBlock(-7,15,4,minecraft:iron_bars:0,5,quark:iron_plate:1,15,STAINED_CLAY:15,15,STAINED_CLAY:7,100)
RandomBlock(-7,15,5,minecraft:iron_bars:0,5,quark:iron_plate:1,15,STAINED_CLAY:15,15,STAINED_CLAY:7,100)
RandomBlock(-7,15,6,minecraft:iron_bars:0,5,quark:iron_plate:1,15,STAINED_CLAY:15,15,STAINED_CLAY:7,100)
RandomBlock(-7,15,7,minecraft:iron_bars:0,5,quark:iron_plate:1,15,STAINED_CLAY:15,15,STAINED_CLAY:7,100)
RandomBlock(-7,15,8,minecraft:iron_bars:0,5,quark:iron_plate:1,15,STAINED_CLAY:15,15,STAINED_CLAY:7,100)
RandomBlock(-7,16,3,minecraft:iron_bars:0,5,quark:iron_plate:1,15,STAINED_CLAY:15,15,STAINED_CLAY:7,100)
RandomBlock(-7,16,4,minecraft:iron_bars:0,5,quark:iron_plate:1,15,STAINED_CLAY:15,15,STAINED_CLAY:7,100)
RandomBlock(-7,16,5,minecraft:iron_bars:0,5,quark:iron_plate:1,15,STAINED_CLAY:15,15,STAINED_CLAY:7,100)
RandomBlock(-7,16,6,minecraft:iron_bars:0,5,quark:iron_plate:1,15,STAINED_CLAY:15,15,STAINED_CLAY:7,100)
RandomBlock(-7,16,7,minecraft:iron_bars:0,5,quark:iron_plate:1,15,STAINED_CLAY:15,15,STAINED_CLAY:7,100)
RandomBlock(-7,16,8,minecraft:iron_bars:0,5,quark:iron_plate:1,15,STAINED_CLAY:15,15,STAINED_CLAY:7,100)
RandomBlock(-7,17,3,minecraft:iron_bars:0,5,quark:iron_plate:1,15,STAINED_CLAY:15,15,STAINED_CLAY:7,100)
RandomBlock(-7,17,4,minecraft:iron_bars:0,5,quark:iron_plate:1,15,STAINED_CLAY:15,15,STAINED_CLAY:7,100)
RandomBlock(-7,17,5,minecraft:iron_bars:0,5,quark:iron_plate:1,15,STAINED_CLAY:15,15,STAINED_CLAY:7,100)
RandomBlock(-7,17,6,minecraft:iron_bars:0,5,quark:iron_plate:1,15,STAINED_CLAY:15,15,STAINED_CLAY:7,100)
RandomBlock(-7,17,7,minecraft:iron_bars:0,5,quark:iron_plate:1,15,STAINED_CLAY:15,15,STAINED_CLAY:7,100)
RandomBlock(-7,17,8,minecraft:iron_bars:0,5,quark:iron_plate:1,15,STAINED_CLAY:15,15,STAINED_CLAY:7,100)
RandomBlock(-7,18,3,minecraft:iron_bars:0,5,quark:iron_plate:1,15,STAINED_CLAY:15,15,STAINED_CLAY:7,100)
RandomBlock(-7,18,4,minecraft:iron_bars:0,5,quark:iron_plate:1,15,STAINED_CLAY:15,15,STAINED_CLAY:7,100)
RandomBlock(-7,18,5,minecraft:iron_bars:0,5,quark:iron_plate:1,15,STAINED_CLAY:15,15,STAINED_CLAY:7,100)
RandomBlock(-7,18,6,minecraft:iron_bars:0,5,quark:iron_plate:1,15,STAINED_CLAY:15,15,STAINED_CLAY:7,100)
RandomBlock(-7,18,7,minecraft:iron_bars:0,5,quark:iron_plate:1,15,STAINED_CLAY:15,15,STAINED_CLAY:7,100)
RandomBlock(-7,18,8,minecraft:iron_bars:0,5,quark:iron_plate:1,15,STAINED_CLAY:15,15,STAINED_CLAY:7,100)
RandomBlock(-7,19,3,minecraft:iron_bars:0,5,quark:iron_plate:1,15,STAINED_CLAY:15,15,STAINED_CLAY:7,100)
RandomBlock(-7,19,4,minecraft:iron_bars:0,5,quark:iron_plate:1,15,STAINED_CLAY:15,15,STAINED_CLAY:7,100)
RandomBlock(-7,19,5,minecraft:iron_bars:0,5,quark:iron_plate:1,15,STAINED_CLAY:15,15,STAINED_CLAY:7,100)
RandomBlock(-7,19,6,minecraft:iron_bars:0,5,quark:iron_plate:1,15,STAINED_CLAY:15,15,STAINED_CLAY:7,100)
RandomBlock(-7,19,7,minecraft:iron_bars:0,5,quark:iron_plate:1,15,STAINED_CLAY:15,15,STAINED_CLAY:7,100)
RandomBlock(-7,19,8,minecraft:iron_bars:0,5,quark:iron_plate:1,15,STAINED_CLAY:15,15,STAINED_CLAY:7,100)
RandomBlock(-7,20,3,minecraft:iron_bars:0,5,quark:iron_plate:1,15,STAINED_CLAY:15,15,STAINED_CLAY:7,100)
RandomBlock(-7,20,4,minecraft:iron_bars:0,5,quark:iron_plate:1,15,STAINED_CLAY:15,15,STAINED_CLAY:7,100)
RandomBlock(-7,20,5,minecraft:iron_bars:0,5,quark:iron_plate:1,15,STAINED_CLAY:15,15,STAINED_CLAY:7,100)
RandomBlock(-7,20,6,minecraft:iron_bars:0,5,quark:iron_plate:1,15,STAINED_CLAY:15,15,STAINED_CLAY:7,100)
RandomBlock(-7,20,7,minecraft:iron_bars:0,5,quark:iron_plate:1,15,STAINED_CLAY:15,15,STAINED_CLAY:7,100)
RandomBlock(-7,20,8,minecraft:iron_bars:0,5,quark:iron_plate:1,15,STAINED_CLAY:15,15,STAINED_CLAY:7,100)
RandomBlock(-7,21,3,minecraft:iron_bars:0,5,quark:iron_plate:1,15,STAINED_CLAY:15,15,STAINED_CLAY:7,100)
RandomBlock(-7,21,4,minecraft:iron_bars:0,5,quark:iron_plate:1,15,STAINED_CLAY:15,15,STAINED_CLAY:7,100)
RandomBlock(-7,21,5,minecraft:iron_bars:0,5,quark:iron_plate:1,15,STAINED_CLAY:15,15,STAINED_CLAY:7,100)
RandomBlock(-7,21,6,minecraft:iron_bars:0,5,quark:iron_plate:1,15,STAINED_CLAY:15,15,STAINED_CLAY:7,100)
RandomBlock(-7,21,7,minecraft:iron_bars:0,5,quark:iron_plate:1,15,STAINED_CLAY:15,15,STAINED_CLAY:7,100)
RandomBlock(-7,21,8,minecraft:iron_bars:0,5,quark:iron_plate:1,15,STAINED_CLAY:15,15,STAINED_CLAY:7,100)
RandomBlock(-7,22,3,minecraft:iron_bars:0,5,quark:iron_plate:1,15,STAINED_CLAY:15,15,STAINED_CLAY:7,100)
RandomBlock(-7,22,4,minecraft:iron_bars:0,5,quark:iron_plate:1,15,STAINED_CLAY:15,15,STAINED_CLAY:7,100)
RandomBlock(-7,22,5,minecraft:iron_bars:0,5,quark:iron_plate:1,15,STAINED_CLAY:15,15,STAINED_CLAY:7,100)
RandomBlock(-7,22,6,minecraft:iron_bars:0,5,quark:iron_plate:1,15,STAINED_CLAY:15,15,STAINED_CLAY:7,100)
RandomBlock(-7,22,7,minecraft:iron_bars:0,5,quark:iron_plate:1,15,STAINED_CLAY:15,15,STAINED_CLAY:7,100)
RandomBlock(-7,22,8,minecraft:iron_bars:0,5,quark:iron_plate:1,15,STAINED_CLAY:15,15,STAINED_CLAY:7,100)
RandomBlock(-7,23,3,minecraft:iron_bars:0,5,quark:iron_plate:1,15,STAINED_CLAY:15,15,STAINED_CLAY:7,100)
RandomBlock(-7,23,4,minecraft:iron_bars:0,5,quark:iron_plate:1,15,STAINED_CLAY:15,15,STAINED_CLAY:7,100)
RandomBlock(-7,23,5,minecraft:iron_bars:0,5,quark:iron_plate:1,15,STAINED_CLAY:15,15,STAINED_CLAY:7,100)
RandomBlock(-7,23,6,minecraft:iron_bars:0,5,quark:iron_plate:1,15,STAINED_CLAY:15,15,STAINED_CLAY:7,100)
RandomBlock(-7,23,7,minecraft:iron_bars:0,5,quark:iron_plate:1,15,STAINED_CLAY:15,15,STAINED_CLAY:7,100)
RandomBlock(-7,23,8,minecraft:iron_bars:0,5,quark:iron_plate:1,15,STAINED_CLAY:15,15,STAINED_CLAY:7,100)
RandomBlock(-7,24,3,minecraft:iron_bars:0,5,quark:iron_plate:1,15,STAINED_CLAY:15,15,STAINED_CLAY:7,100)
RandomBlock(-7,24,4,minecraft:iron_bars:0,5,quark:iron_plate:1,15,STAINED_CLAY:15,15,STAINED_CLAY:7,100)
RandomBlock(-7,24,5,minecraft:iron_bars:0,5,quark:iron_plate:1,15,STAINED_CLAY:15,15,STAINED_CLAY:7,100)
RandomBlock(-7,24,6,minecraft:iron_bars:0,5,quark:iron_plate:1,15,STAINED_CLAY:15,15,STAINED_CLAY:7,100)
RandomBlock(-7,24,7,minecraft:iron_bars:0,5,quark:iron_plate:1,15,STAINED_CLAY:15,15,STAINED_CLAY:7,100)
RandomBlock(-7,24,8,minecraft:iron_bars:0,5,quark:iron_plate:1,15,STAINED_CLAY:15,15,STAINED_CLAY:7,100)
RandomBlock(-7,25,3,minecraft:iron_bars:0,5,quark:iron_plate:1,15,STAINED_CLAY:15,15,STAINED_CLAY:7,100)
RandomBlock(-7,25,4,minecraft:iron_bars:0,5,quark:iron_plate:1,15,STAINED_CLAY:15,15,STAINED_CLAY:7,100)
RandomBlock(-7,25,5,minecraft:iron_bars:0,5,quark:iron_plate:1,15,STAINED_CLAY:15,15,STAINED_CLAY:7,100)
RandomBlock(-7,25,6,minecraft:iron_bars:0,5,quark:iron_plate:1,15,STAINED_CLAY:15,15,STAINED_CLAY:7,100)
RandomBlock(-7,25,7,minecraft:iron_bars:0,5,quark:iron_plate:1,15,STAINED_CLAY:15,15,STAINED_CLAY:7,100)
RandomBlock(-7,25,8,minecraft:iron_bars:0,5,quark:iron_plate:1,15,STAINED_CLAY:15,15,STAINED_CLAY:7,100)
RandomBlock(-7,26,3,minecraft:iron_bars:0,5,quark:iron_plate:1,15,STAINED_CLAY:15,15,STAINED_CLAY:7,100)
RandomBlock(-7,26,4,minecraft:iron_bars:0,5,quark:iron_plate:1,15,STAINED_CLAY:15,15,STAINED_CLAY:7,100)
RandomBlock(-7,26,5,minecraft:iron_bars:0,5,quark:iron_plate:1,15,STAINED_CLAY:15,15,STAINED_CLAY:7,100)
RandomBlock(-7,26,6,minecraft:iron_bars:0,5,quark:iron_plate:1,15,STAINED_CLAY:15,15,STAINED_CLAY:7,100)
RandomBlock(-7,26,7,minecraft:iron_bars:0,5,quark:iron_plate:1,15,STAINED_CLAY:15,15,STAINED_CLAY:7,100)
RandomBlock(-7,26,8,minecraft:iron_bars:0,5,quark:iron_plate:1,15,STAINED_CLAY:15,15,STAINED_CLAY:7,100)
RandomBlock(-7,27,3,minecraft:iron_bars:0,5,quark:iron_plate:1,15,STAINED_CLAY:15,15,STAINED_CLAY:7,100)
RandomBlock(-7,27,4,minecraft:iron_bars:0,5,quark:iron_plate:1,15,STAINED_CLAY:15,15,STAINED_CLAY:7,100)
RandomBlock(-7,27,5,minecraft:iron_bars:0,5,quark:iron_plate:1,15,STAINED_CLAY:15,15,STAINED_CLAY:7,100)
RandomBlock(-7,27,6,minecraft:iron_bars:0,5,quark:iron_plate:1,15,STAINED_CLAY:15,15,STAINED_CLAY:7,100)
RandomBlock(-7,27,7,minecraft:iron_bars:0,5,quark:iron_plate:1,15,STAINED_CLAY:15,15,STAINED_CLAY:7,100)
RandomBlock(-7,27,8,minecraft:iron_bars:0,5,quark:iron_plate:1,15,STAINED_CLAY:15,15,STAINED_CLAY:7,100)
RandomBlock(-7,28,3,minecraft:iron_bars:0,5,quark:iron_plate:1,15,STAINED_CLAY:15,15,STAINED_CLAY:7,100)
RandomBlock(-7,28,4,minecraft:iron_bars:0,5,quark:iron_plate:1,15,STAINED_CLAY:15,15,STAINED_CLAY:7,100)
RandomBlock(-7,28,5,minecraft:iron_bars:0,5,quark:iron_plate:1,15,STAINED_CLAY:15,15,STAINED_CLAY:7,100)
RandomBlock(-7,28,6,minecraft:iron_bars:0,5,quark:iron_plate:1,15,STAINED_CLAY:15,15,STAINED_CLAY:7,100)
RandomBlock(-7,28,7,minecraft:iron_bars:0,5,quark:iron_plate:1,15,STAINED_CLAY:15,15,STAINED_CLAY:7,100)
RandomBlock(-7,28,8,minecraft:iron_bars:0,5,quark:iron_plate:1,15,STAINED_CLAY:15,15,STAINED_CLAY:7,100)
RandomBlock(-7,29,3,minecraft:iron_bars:0,5,quark:iron_plate:1,15,STAINED_CLAY:15,15,STAINED_CLAY:7,100)
RandomBlock(-7,29,4,minecraft:iron_bars:0,5,quark:iron_plate:1,15,STAINED_CLAY:15,15,STAINED_CLAY:7,100)
RandomBlock(-7,29,5,minecraft:iron_bars:0,5,quark:iron_plate:1,15,STAINED_CLAY:15,15,STAINED_CLAY:7,100)
RandomBlock(-7,29,6,minecraft:iron_bars:0,5,quark:iron_plate:1,15,STAINED_CLAY:15,15,STAINED_CLAY:7,100)
RandomBlock(-7,29,7,minecraft:iron_bars:0,5,quark:iron_plate:1,15,STAINED_CLAY:15,15,STAINED_CLAY:7,100)
RandomBlock(-7,29,8,minecraft:iron_bars:0,5,quark:iron_plate:1,15,STAINED_CLAY:15,15,STAINED_CLAY:7,100)
RandomBlock(-7,30,3,minecraft:iron_bars:0,5,quark:iron_plate:1,15,STAINED_CLAY:15,15,STAINED_CLAY:7,100)
RandomBlock(-7,30,4,minecraft:iron_bars:0,5,quark:iron_plate:1,15,STAINED_CLAY:15,15,STAINED_CLAY:7,100)
RandomBlock(-7,30,5,minecraft:iron_bars:0,5,quark:iron_plate:1,15,STAINED_CLAY:15,15,STAINED_CLAY:7,100)
RandomBlock(-7,30,6,minecraft:iron_bars:0,5,quark:iron_plate:1,15,STAINED_CLAY:15,15,STAINED_CLAY:7,100)
RandomBlock(-7,30,7,minecraft:iron_bars:0,5,quark:iron_plate:1,15,STAINED_CLAY:15,15,STAINED_CLAY:7,100)
RandomBlock(-7,30,8,minecraft:iron_bars:0,5,quark:iron_plate:1,15,STAINED_CLAY:15,15,STAINED_CLAY:7,100)
RandomBlock(-7,31,3,minecraft:iron_bars:0,5,quark:iron_plate:1,15,STAINED_CLAY:15,15,STAINED_CLAY:7,100)
RandomBlock(-7,31,4,minecraft:iron_bars:0,5,quark:iron_plate:1,15,STAINED_CLAY:15,15,STAINED_CLAY:7,100)
RandomBlock(-7,31,5,minecraft:iron_bars:0,5,quark:iron_plate:1,15,STAINED_CLAY:15,15,STAINED_CLAY:7,100)
RandomBlock(-7,31,6,minecraft:iron_bars:0,5,quark:iron_plate:1,15,STAINED_CLAY:15,15,STAINED_CLAY:7,100)
RandomBlock(-7,31,7,minecraft:iron_bars:0,5,quark:iron_plate:1,15,STAINED_CLAY:15,15,STAINED_CLAY:7,100)
RandomBlock(-7,31,8,minecraft:iron_bars:0,5,quark:iron_plate:1,15,STAINED_CLAY:15,15,STAINED_CLAY:7,100)
RandomBlock(-7,32,3,minecraft:iron_bars:0,5,quark:iron_plate:1,15,STAINED_CLAY:15,15,STAINED_CLAY:7,100)
RandomBlock(-7,32,4,minecraft:iron_bars:0,5,quark:iron_plate:1,15,STAINED_CLAY:15,15,STAINED_CLAY:7,100)
RandomBlock(-7,32,5,minecraft:iron_bars:0,5,quark:iron_plate:1,15,STAINED_CLAY:15,15,STAINED_CLAY:7,100)
RandomBlock(-7,32,6,minecraft:iron_bars:0,5,quark:iron_plate:1,15,STAINED_CLAY:15,15,STAINED_CLAY:7,100)
RandomBlock(-7,32,7,minecraft:iron_bars:0,5,quark:iron_plate:1,15,STAINED_CLAY:15,15,STAINED_CLAY:7,100)
RandomBlock(-7,32,8,minecraft:iron_bars:0,5,quark:iron_plate:1,15,STAINED_CLAY:15,15,STAINED_CLAY:7,100)
RandomBlock(-7,33,3,minecraft:iron_bars:0,5,quark:iron_plate:1,15,STAINED_CLAY:15,15,STAINED_CLAY:7,100)
RandomBlock(-7,33,4,minecraft:iron_bars:0,5,quark:iron_plate:1,15,STAINED_CLAY:15,15,STAINED_CLAY:7,100)
RandomBlock(-7,33,5,minecraft:iron_bars:0,5,quark:iron_plate:1,15,STAINED_CLAY:15,15,STAINED_CLAY:7,100)
RandomBlock(-7,33,6,minecraft:iron_bars:0,5,quark:iron_plate:1,15,STAINED_CLAY:15,15,STAINED_CLAY:7,100)
RandomBlock(-7,33,7,minecraft:iron_bars:0,5,quark:iron_plate:1,15,STAINED_CLAY:15,15,STAINED_CLAY:7,100)
RandomBlock(-7,33,8,minecraft:iron_bars:0,5,quark:iron_plate:1,15,STAINED_CLAY:15,15,STAINED_CLAY:7,100)
RandomBlock(-7,34,3,minecraft:iron_bars:0,5,quark:iron_plate:1,15,STAINED_CLAY:15,15,STAINED_CLAY:7,100)
RandomBlock(-7,34,4,minecraft:iron_bars:0,5,quark:iron_plate:1,15,STAINED_CLAY:15,15,STAINED_CLAY:7,100)
RandomBlock(-7,34,5,minecraft:iron_bars:0,5,quark:iron_plate:1,15,STAINED_CLAY:15,15,STAINED_CLAY:7,100)
RandomBlock(-7,34,6,minecraft:iron_bars:0,5,quark:iron_plate:1,15,STAINED_CLAY:15,15,STAINED_CLAY:7,100)
RandomBlock(-7,34,7,minecraft:iron_bars:0,5,quark:iron_plate:1,15,STAINED_CLAY:15,15,STAINED_CLAY:7,100)
RandomBlock(-7,34,8,minecraft:iron_bars:0,5,quark:iron_plate:1,15,STAINED_CLAY:15,15,STAINED_CLAY:7,100)
RandomBlock(-7,35,3,minecraft:iron_bars:0,5,quark:iron_plate:1,15,STAINED_CLAY:15,15,STAINED_CLAY:7,100)
RandomBlock(-7,35,4,minecraft:iron_bars:0,5,quark:iron_plate:1,15,STAINED_CLAY:15,15,STAINED_CLAY:7,100)
RandomBlock(-7,35,5,minecraft:iron_bars:0,5,quark:iron_plate:1,15,STAINED_CLAY:15,15,STAINED_CLAY:7,100)
RandomBlock(-7,35,6,minecraft:iron_bars:0,5,quark:iron_plate:1,15,STAINED_CLAY:15,15,STAINED_CLAY:7,100)
RandomBlock(-7,35,7,minecraft:iron_bars:0,5,quark:iron_plate:1,15,STAINED_CLAY:15,15,STAINED_CLAY:7,100)
RandomBlock(-7,35,8,minecraft:iron_bars:0,5,quark:iron_plate:1,15,STAINED_CLAY:15,15,STAINED_CLAY:7,100)
RandomBlock(-7,36,3,minecraft:iron_bars:0,5,quark:iron_plate:1,15,STAINED_CLAY:15,15,STAINED_CLAY:7,100)
RandomBlock(-7,36,4,minecraft:iron_bars:0,5,quark:iron_plate:1,15,STAINED_CLAY:15,15,STAINED_CLAY:7,100)
RandomBlock(-7,36,5,minecraft:iron_bars:0,5,quark:iron_plate:1,15,STAINED_CLAY:15,15,STAINED_CLAY:7,100)
RandomBlock(-7,36,6,minecraft:iron_bars:0,5,quark:iron_plate:1,15,STAINED_CLAY:15,15,STAINED_CLAY:7,100)
RandomBlock(-7,36,7,minecraft:iron_bars:0,5,quark:iron_plate:1,15,STAINED_CLAY:15,15,STAINED_CLAY:7,100)
RandomBlock(-7,36,8,minecraft:iron_bars:0,5,quark:iron_plate:1,15,STAINED_CLAY:15,15,STAINED_CLAY:7,100)
RandomBlock(-7,37,3,minecraft:iron_bars:0,5,quark:iron_plate:1,15,STAINED_CLAY:15,15,STAINED_CLAY:7,100)
RandomBlock(-7,37,4,minecraft:iron_bars:0,5,quark:iron_plate:1,15,STAINED_CLAY:15,15,STAINED_CLAY:7,100)
RandomBlock(-7,37,5,minecraft:iron_bars:0,5,quark:iron_plate:1,15,STAINED_CLAY:15,15,STAINED_CLAY:7,100)
RandomBlock(-7,37,6,minecraft:iron_bars:0,5,quark:iron_plate:1,15,STAINED_CLAY:15,15,STAINED_CLAY:7,100)
RandomBlock(-7,37,7,minecraft:iron_bars:0,5,quark:iron_plate:1,15,STAINED_CLAY:15,15,STAINED_CLAY:7,100)
RandomBlock(-7,37,8,minecraft:iron_bars:0,5,quark:iron_plate:1,15,STAINED_CLAY:15,15,STAINED_CLAY:7,100)
RandomBlock(-7,38,3,minecraft:iron_bars:0,5,quark:iron_plate:1,15,STAINED_CLAY:15,15,STAINED_CLAY:7,100)
RandomBlock(-7,38,4,minecraft:iron_bars:0,5,quark:iron_plate:1,15,STAINED_CLAY:15,15,STAINED_CLAY:7,100)
RandomBlock(-7,38,5,minecraft:iron_bars:0,5,quark:iron_plate:1,15,STAINED_CLAY:15,15,STAINED_CLAY:7,100)
RandomBlock(-7,38,6,minecraft:iron_bars:0,5,quark:iron_plate:1,15,STAINED_CLAY:15,15,STAINED_CLAY:7,100)
RandomBlock(-7,38,7,minecraft:iron_bars:0,5,quark:iron_plate:1,15,STAINED_CLAY:15,15,STAINED_CLAY:7,100)
RandomBlock(-7,38,8,minecraft:iron_bars:0,5,quark:iron_plate:1,15,STAINED_CLAY:15,15,STAINED_CLAY:7,100)
RandomBlock(-7,39,3,minecraft:iron_bars:0,5,quark:iron_plate:1,15,STAINED_CLAY:15,15,STAINED_CLAY:7,100)
RandomBlock(-7,39,4,minecraft:iron_bars:0,5,quark:iron_plate:1,15,STAINED_CLAY:15,15,STAINED_CLAY:7,100)
RandomBlock(-7,39,5,minecraft:iron_bars:0,5,quark:iron_plate:1,15,STAINED_CLAY:15,15,STAINED_CLAY:7,100)
RandomBlock(-7,39,6,minecraft:iron_bars:0,5,quark:iron_plate:1,15,STAINED_CLAY:15,15,STAINED_CLAY:7,100)
RandomBlock(-7,39,7,minecraft:iron_bars:0,5,quark:iron_plate:1,15,STAINED_CLAY:15,15,STAINED_CLAY:7,100)
RandomBlock(-7,39,8,minecraft:iron_bars:0,5,quark:iron_plate:1,15,STAINED_CLAY:15,15,STAINED_CLAY:7,100)
RandomBlock(-7,40,3,minecraft:iron_bars:0,5,quark:iron_plate:1,15,STAINED_CLAY:15,15,STAINED_CLAY:7,100)
RandomBlock(-7,40,4,minecraft:iron_bars:0,5,quark:iron_plate:1,15,STAINED_CLAY:15,15,STAINED_CLAY:7,100)
RandomBlock(-7,40,5,minecraft:iron_bars:0,5,quark:iron_plate:1,15,STAINED_CLAY:15,15,STAINED_CLAY:7,100)
RandomBlock(-7,40,6,minecraft:iron_bars:0,5,quark:iron_plate:1,15,STAINED_CLAY:15,15,STAINED_CLAY:7,100)
RandomBlock(-7,40,7,minecraft:iron_bars:0,5,quark:iron_plate:1,15,STAINED_CLAY:15,15,STAINED_CLAY:7,100)
RandomBlock(-7,40,8,minecraft:iron_bars:0,5,quark:iron_plate:1,15,STAINED_CLAY:15,15,STAINED_CLAY:7,100)
RandomBlock(-7,41,3,minecraft:iron_bars:0,5,quark:iron_plate:1,15,STAINED_CLAY:15,15,STAINED_CLAY:7,100)
RandomBlock(-7,41,4,minecraft:iron_bars:0,5,quark:iron_plate:1,15,STAINED_CLAY:15,15,STAINED_CLAY:7,100)
RandomBlock(-7,41,5,minecraft:iron_bars:0,5,quark:iron_plate:1,15,STAINED_CLAY:15,15,STAINED_CLAY:7,100)
RandomBlock(-7,41,6,minecraft:iron_bars:0,5,quark:iron_plate:1,15,STAINED_CLAY:15,15,STAINED_CLAY:7,100)
RandomBlock(-7,41,7,minecraft:iron_bars:0,5,quark:iron_plate:1,15,STAINED_CLAY:15,15,STAINED_CLAY:7,100)
RandomBlock(-7,41,8,minecraft:iron_bars:0,5,quark:iron_plate:1,15,STAINED_CLAY:15,15,STAINED_CLAY:7,100)
RandomBlock(-7,42,3,minecraft:iron_bars:0,5,quark:iron_plate:1,15,STAINED_CLAY:15,15,STAINED_CLAY:7,100)
RandomBlock(-7,42,4,minecraft:iron_bars:0,5,quark:iron_plate:1,15,STAINED_CLAY:15,15,STAINED_CLAY:7,100)
RandomBlock(-7,42,5,minecraft:iron_bars:0,5,quark:iron_plate:1,15,STAINED_CLAY:15,15,STAINED_CLAY:7,100)
RandomBlock(-7,42,6,minecraft:iron_bars:0,5,quark:iron_plate:1,15,STAINED_CLAY:15,15,STAINED_CLAY:7,100)
RandomBlock(-7,42,7,minecraft:iron_bars:0,5,quark:iron_plate:1,15,STAINED_CLAY:15,15,STAINED_CLAY:7,100)
RandomBlock(-7,42,8,minecraft:iron_bars:0,5,quark:iron_plate:1,15,STAINED_CLAY:15,15,STAINED_CLAY:7,100)
RandomBlock(-7,43,3,minecraft:iron_bars:0,5,quark:iron_plate:1,15,STAINED_CLAY:15,15,STAINED_CLAY:7,100)
RandomBlock(-7,43,4,minecraft:iron_bars:0,5,quark:iron_plate:1,15,STAINED_CLAY:15,15,STAINED_CLAY:7,100)
RandomBlock(-7,43,5,minecraft:iron_bars:0,5,quark:iron_plate:1,15,STAINED_CLAY:15,15,STAINED_CLAY:7,100)
RandomBlock(-7,43,6,minecraft:iron_bars:0,5,quark:iron_plate:1,15,STAINED_CLAY:15,15,STAINED_CLAY:7,100)
RandomBlock(-7,43,7,minecraft:iron_bars:0,5,quark:iron_plate:1,15,STAINED_CLAY:15,15,STAINED_CLAY:7,100)
RandomBlock(-7,43,8,minecraft:iron_bars:0,5,quark:iron_plate:1,15,STAINED_CLAY:15,15,STAINED_CLAY:7,100)
RandomBlock(-7,44,-7,minecraft:iron_bars:0,5,STAINED_CLAY:15,5,STAINED_CLAY:7,5,quark:iron_plate_slab:8,15,quark:world_stone_pavement:2,15,STAINED_CLAY:9,100)
RandomBlock(-7,44,-6,minecraft:iron_bars:0,5,STAINED_CLAY:15,5,STAINED_CLAY:7,5,quark:iron_plate_slab:8,15,quark:world_stone_pavement:2,15,STAINED_CLAY:9,100)
RandomBlock(-7,44,-5,minecraft:iron_bars:0,5,STAINED_CLAY:15,5,STAINED_CLAY:7,5,quark:iron_plate_slab:8,15,quark:world_stone_pavement:2,15,STAINED_CLAY:9,100)
RandomBlock(-7,44,-4,minecraft:iron_bars:0,5,STAINED_CLAY:15,5,STAINED_CLAY:7,5,quark:iron_plate_slab:8,15,quark:world_stone_pavement:2,15,STAINED_CLAY:9,100)
RandomBlock(-7,44,-3,minecraft:iron_bars:0,5,STAINED_CLAY:15,5,STAINED_CLAY:7,5,quark:iron_plate_slab:8,15,quark:world_stone_pavement:2,15,STAINED_CLAY:9,100)
RandomBlock(-7,44,-2,minecraft:iron_bars:0,5,STAINED_CLAY:15,5,STAINED_CLAY:7,5,quark:iron_plate_slab:8,15,quark:world_stone_pavement:2,15,STAINED_CLAY:9,100)
RandomBlock(-7,44,-1,minecraft:iron_bars:0,5,STAINED_CLAY:15,5,STAINED_CLAY:7,5,quark:iron_plate_slab:8,15,quark:world_stone_pavement:2,15,STAINED_CLAY:9,100)
RandomBlock(-7,44,0,minecraft:iron_bars:0,5,STAINED_CLAY:15,5,STAINED_CLAY:7,5,quark:iron_plate_slab:8,15,quark:world_stone_pavement:2,15,STAINED_CLAY:9,100)
RandomBlock(-7,44,1,minecraft:iron_bars:0,5,STAINED_CLAY:15,5,STAINED_CLAY:7,5,quark:iron_plate_slab:8,15,quark:world_stone_pavement:2,15,STAINED_CLAY:9,100)
RandomBlock(-7,44,2,minecraft:iron_bars:0,5,STAINED_CLAY:15,5,STAINED_CLAY:7,5,quark:iron_plate_slab:8,15,quark:world_stone_pavement:2,15,STAINED_CLAY:9,100)
RandomBlock(-7,44,3,minecraft:iron_bars:0,5,STAINED_CLAY:15,5,STAINED_CLAY:7,5,quark:iron_plate_slab:8,15,quark:world_stone_pavement:2,15,STAINED_CLAY:9,100)
RandomBlock(-7,44,4,minecraft:iron_bars:0,5,STAINED_CLAY:15,5,STAINED_CLAY:7,5,quark:iron_plate_slab:8,15,quark:world_stone_pavement:2,15,STAINED_CLAY:9,100)
RandomBlock(-7,44,5,minecraft:iron_bars:0,5,STAINED_CLAY:15,5,STAINED_CLAY:7,5,quark:iron_plate_slab:8,15,quark:world_stone_pavement:2,15,STAINED_CLAY:9,100)
RandomBlock(-7,44,6,minecraft:iron_bars:0,5,STAINED_CLAY:15,5,STAINED_CLAY:7,5,quark:iron_plate_slab:8,15,quark:world_stone_pavement:2,15,STAINED_CLAY:9,100)
RandomBlock(-7,44,7,minecraft:iron_bars:0,5,STAINED_CLAY:15,5,STAINED_CLAY:7,5,quark:iron_plate_slab:8,15,quark:world_stone_pavement:2,15,STAINED_CLAY:9,100)
RandomBlock(-7,44,8,minecraft:iron_bars:0,5,STAINED_CLAY:15,5,STAINED_CLAY:7,5,quark:iron_plate_slab:8,15,quark:world_stone_pavement:2,15,STAINED_CLAY:9,100)
Block(-7,45,-6,quark:iron_plate:1)
Block(-7,45,-5,quark:iron_plate:1)
Block(-7,45,-4,quark:iron_plate:1)
Block(-7,45,-3,quark:iron_plate:1)
Block(-7,45,-2,quark:iron_plate:1)
Block(-7,45,-1,quark:iron_plate:1)
Block(-7,45,0,quark:iron_plate:1)
Block(-7,45,1,quark:iron_plate:1)
Block(-7,45,2,quark:iron_plate:1)
Block(-7,45,3,quark:iron_plate:1)
Block(-7,45,4,quark:iron_plate:1)
Block(-7,45,5,quark:iron_plate:1)
Block(-7,46,-7,quark:iron_plate:1)
Block(-7,46,-6,COAL_BLOCK:0)
Block(-7,46,-5,COAL_BLOCK:0)
Block(-7,46,-4,quark:iron_plate:1)
Block(-7,46,-3,SLIME_BLOCK:0)
Block(-7,46,-2,SLIME_BLOCK:0)
Block(-7,46,-1,SLIME_BLOCK:0)
Block(-7,46,0,SLIME_BLOCK:0)
Block(-7,46,1,SLIME_BLOCK:0)
Block(-7,46,2,SLIME_BLOCK:0)
Block(-7,46,3,SLIME_BLOCK:0)
Block(-7,46,4,quark:iron_plate:1)
Block(-7,46,5,SMOOTH_STAIRS:3)
Block(-7,47,-7,quark:iron_plate:1)
Block(-7,47,-6,COAL_BLOCK:0)
Block(-7,47,-5,COAL_BLOCK:0)
Block(-7,47,-4,quark:iron_plate:1)
Block(-7,47,-3,SLIME_BLOCK:0)
Block(-7,47,-2,SLIME_BLOCK:0)
Block(-7,47,-1,SLIME_BLOCK:0)
Block(-7,47,0,SLIME_BLOCK:0)
Block(-7,47,1,SLIME_BLOCK:0)
Block(-7,47,2,SLIME_BLOCK:0)
Block(-7,47,3,SLIME_BLOCK:0)
Block(-7,47,4,quark:iron_plate:1)
Block(-7,47,5,SMOOTH_STAIRS:7)
Block(-7,48,-7,quark:iron_plate:1)
Block(-7,48,-6,COAL_BLOCK:0)
Block(-7,48,-5,COAL_BLOCK:0)
Block(-7,48,-4,quark:iron_plate:1)
Block(-7,48,-3,quark:iron_plate:1)
Block(-7,48,-2,quark:iron_plate:1)
Block(-7,48,-1,quark:iron_plate:1)
Block(-7,48,0,quark:iron_plate:1)
Block(-7,48,1,quark:iron_plate:1)
Block(-7,48,2,quark:iron_plate:1)
Block(-7,48,3,quark:iron_plate:1)
Block(-7,48,4,quark:iron_plate:1)
Block(-7,48,5,quark:iron_plate:1)
Block(-7,49,-7,STEP:0)
Block(-7,49,-6,STEP:0)
Block(-7,49,-5,STEP:0)
Block(-7,49,-4,STEP:0)
RandomBlock(-7,50,-7,minecraft:iron_bars:0,5,STAINED_CLAY:15,5,STAINED_CLAY:7,5,quark:iron_plate_slab:8,15,quark:world_stone_pavement:2,15,STAINED_CLAY:9,100)
RandomBlock(-7,50,-6,minecraft:iron_bars:0,5,STAINED_CLAY:15,5,STAINED_CLAY:7,5,quark:iron_plate_slab:8,15,quark:world_stone_pavement:2,15,STAINED_CLAY:9,100)
RandomBlock(-7,50,-5,minecraft:iron_bars:0,5,STAINED_CLAY:15,5,STAINED_CLAY:7,5,quark:iron_plate_slab:8,15,quark:world_stone_pavement:2,15,STAINED_CLAY:9,100)
RandomBlock(-7,50,-4,minecraft:iron_bars:0,5,STAINED_CLAY:15,5,STAINED_CLAY:7,5,quark:iron_plate_slab:8,15,quark:world_stone_pavement:2,15,STAINED_CLAY:9,100)
RandomBlock(-7,50,-3,minecraft:iron_bars:0,5,STAINED_CLAY:15,5,STAINED_CLAY:7,5,quark:iron_plate_slab:8,15,quark:world_stone_pavement:2,15,STAINED_CLAY:9,100)
RandomBlock(-7,50,-2,minecraft:iron_bars:0,5,STAINED_CLAY:15,5,STAINED_CLAY:7,5,quark:iron_plate_slab:8,15,quark:world_stone_pavement:2,15,STAINED_CLAY:9,100)
RandomBlock(-7,50,-1,minecraft:iron_bars:0,5,STAINED_CLAY:15,5,STAINED_CLAY:7,5,quark:iron_plate_slab:8,15,quark:world_stone_pavement:2,15,STAINED_CLAY:9,100)
RandomBlock(-7,50,0,minecraft:iron_bars:0,5,STAINED_CLAY:15,5,STAINED_CLAY:7,5,quark:iron_plate_slab:8,15,quark:world_stone_pavement:2,15,STAINED_CLAY:9,100)
RandomBlock(-7,50,1,minecraft:iron_bars:0,5,STAINED_CLAY:15,5,STAINED_CLAY:7,5,quark:iron_plate_slab:8,15,quark:world_stone_pavement:2,15,STAINED_CLAY:9,100)
RandomBlock(-7,50,2,minecraft:iron_bars:0,5,STAINED_CLAY:15,5,STAINED_CLAY:7,5,quark:iron_plate_slab:8,15,quark:world_stone_pavement:2,15,STAINED_CLAY:9,100)
RandomBlock(-7,50,3,minecraft:iron_bars:0,5,STAINED_CLAY:15,5,STAINED_CLAY:7,5,quark:iron_plate_slab:8,15,quark:world_stone_pavement:2,15,STAINED_CLAY:9,100)
RandomBlock(-7,50,4,minecraft:iron_bars:0,5,STAINED_CLAY:15,5,STAINED_CLAY:7,5,quark:iron_plate_slab:8,15,quark:world_stone_pavement:2,15,STAINED_CLAY:9,100)
RandomBlock(-7,50,5,minecraft:iron_bars:0,5,STAINED_CLAY:15,5,STAINED_CLAY:7,5,quark:iron_plate_slab:8,15,quark:world_stone_pavement:2,15,STAINED_CLAY:9,100)
RandomBlock(-7,50,6,minecraft:iron_bars:0,5,STAINED_CLAY:15,5,STAINED_CLAY:7,5,quark:iron_plate_slab:8,15,quark:world_stone_pavement:2,15,STAINED_CLAY:9,100)
RandomBlock(-7,50,7,minecraft:iron_bars:0,5,STAINED_CLAY:15,5,STAINED_CLAY:7,5,quark:iron_plate_slab:8,15,quark:world_stone_pavement:2,15,STAINED_CLAY:9,100)
RandomBlock(-7,50,8,minecraft:iron_bars:0,5,STAINED_CLAY:15,5,STAINED_CLAY:7,5,quark:iron_plate_slab:8,15,quark:world_stone_pavement:2,15,STAINED_CLAY:9,100)
Block(-7,65,8,minecraft:iron_bars:0)
Block(-7,66,8,IRON_FENCE:0)
RandomBlock(-6,0,4,minecraft:iron_bars:0,5,quark:iron_plate:1,15,STAINED_CLAY:15,15,STAINED_CLAY:7,100)
RandomBlock(-6,0,5,minecraft:iron_bars:0,5,quark:iron_plate:1,15,STAINED_CLAY:15,15,STAINED_CLAY:7,100)
RandomBlock(-6,0,6,minecraft:iron_bars:0,5,quark:iron_plate:1,15,STAINED_CLAY:15,15,STAINED_CLAY:7,100)
RandomBlock(-6,0,7,minecraft:iron_bars:0,5,quark:iron_plate:1,15,STAINED_CLAY:15,15,STAINED_CLAY:7,100)
RandomBlock(-6,0,8,minecraft:iron_bars:0,5,quark:iron_plate:1,15,STAINED_CLAY:15,15,STAINED_CLAY:7,100)
RandomBlock(-6,1,4,minecraft:iron_bars:0,5,quark:iron_plate:1,15,STAINED_CLAY:15,15,STAINED_CLAY:7,100)
RandomBlock(-6,1,5,minecraft:iron_bars:0,5,quark:iron_plate:1,15,STAINED_CLAY:15,15,STAINED_CLAY:7,100)
RandomBlock(-6,1,6,minecraft:iron_bars:0,5,quark:iron_plate:1,15,STAINED_CLAY:15,15,STAINED_CLAY:7,100)
RandomBlock(-6,1,7,minecraft:iron_bars:0,5,quark:iron_plate:1,15,STAINED_CLAY:15,15,STAINED_CLAY:7,100)
RandomBlock(-6,1,8,minecraft:iron_bars:0,5,quark:iron_plate:1,15,STAINED_CLAY:15,15,STAINED_CLAY:7,100)
RandomBlock(-6,2,4,minecraft:iron_bars:0,5,quark:iron_plate:1,15,STAINED_CLAY:15,15,STAINED_CLAY:7,100)
RandomBlock(-6,2,5,minecraft:iron_bars:0,5,quark:iron_plate:1,15,STAINED_CLAY:15,15,STAINED_CLAY:7,100)
RandomBlock(-6,2,6,minecraft:iron_bars:0,5,quark:iron_plate:1,15,STAINED_CLAY:15,15,STAINED_CLAY:7,100)
RandomBlock(-6,2,7,minecraft:iron_bars:0,5,quark:iron_plate:1,15,STAINED_CLAY:15,15,STAINED_CLAY:7,100)
RandomBlock(-6,2,8,minecraft:iron_bars:0,5,quark:iron_plate:1,15,STAINED_CLAY:15,15,STAINED_CLAY:7,100)
RandomBlock(-6,3,4,minecraft:iron_bars:0,5,quark:iron_plate:1,15,STAINED_CLAY:15,15,STAINED_CLAY:7,100)
RandomBlock(-6,3,5,minecraft:iron_bars:0,5,quark:iron_plate:1,15,STAINED_CLAY:15,15,STAINED_CLAY:7,100)
RandomBlock(-6,3,6,minecraft:iron_bars:0,5,quark:iron_plate:1,15,STAINED_CLAY:15,15,STAINED_CLAY:7,100)
RandomBlock(-6,3,7,minecraft:iron_bars:0,5,quark:iron_plate:1,15,STAINED_CLAY:15,15,STAINED_CLAY:7,100)
RandomBlock(-6,3,8,minecraft:iron_bars:0,5,quark:iron_plate:1,15,STAINED_CLAY:15,15,STAINED_CLAY:7,100)
RandomBlock(-6,4,4,minecraft:iron_bars:0,5,quark:iron_plate:1,15,STAINED_CLAY:15,15,STAINED_CLAY:7,100)
RandomBlock(-6,4,5,minecraft:iron_bars:0,5,quark:iron_plate:1,15,STAINED_CLAY:15,15,STAINED_CLAY:7,100)
RandomBlock(-6,4,6,minecraft:iron_bars:0,5,quark:iron_plate:1,15,STAINED_CLAY:15,15,STAINED_CLAY:7,100)
RandomBlock(-6,4,7,minecraft:iron_bars:0,5,quark:iron_plate:1,15,STAINED_CLAY:15,15,STAINED_CLAY:7,100)
RandomBlock(-6,4,8,minecraft:iron_bars:0,5,quark:iron_plate:1,15,STAINED_CLAY:15,15,STAINED_CLAY:7,100)
RandomBlock(-6,5,4,minecraft:iron_bars:0,5,quark:iron_plate:1,15,STAINED_CLAY:15,15,STAINED_CLAY:7,100)
RandomBlock(-6,5,5,minecraft:iron_bars:0,5,quark:iron_plate:1,15,STAINED_CLAY:15,15,STAINED_CLAY:7,100)
RandomBlock(-6,5,6,minecraft:iron_bars:0,5,quark:iron_plate:1,15,STAINED_CLAY:15,15,STAINED_CLAY:7,100)
RandomBlock(-6,5,7,minecraft:iron_bars:0,5,quark:iron_plate:1,15,STAINED_CLAY:15,15,STAINED_CLAY:7,100)
RandomBlock(-6,5,8,minecraft:iron_bars:0,5,quark:iron_plate:1,15,STAINED_CLAY:15,15,STAINED_CLAY:7,100)
RandomBlock(-6,6,4,minecraft:iron_bars:0,5,quark:iron_plate:1,15,STAINED_CLAY:15,15,STAINED_CLAY:7,100)
RandomBlock(-6,6,5,minecraft:iron_bars:0,5,quark:iron_plate:1,15,STAINED_CLAY:15,15,STAINED_CLAY:7,100)
RandomBlock(-6,6,6,minecraft:iron_bars:0,5,quark:iron_plate:1,15,STAINED_CLAY:15,15,STAINED_CLAY:7,100)
RandomBlock(-6,6,7,minecraft:iron_bars:0,5,quark:iron_plate:1,15,STAINED_CLAY:15,15,STAINED_CLAY:7,100)
RandomBlock(-6,6,8,minecraft:iron_bars:0,5,quark:iron_plate:1,15,STAINED_CLAY:15,15,STAINED_CLAY:7,100)
RandomBlock(-6,7,4,minecraft:iron_bars:0,5,quark:iron_plate:1,15,STAINED_CLAY:15,15,STAINED_CLAY:7,100)
RandomBlock(-6,7,5,minecraft:iron_bars:0,5,quark:iron_plate:1,15,STAINED_CLAY:15,15,STAINED_CLAY:7,100)
RandomBlock(-6,7,6,minecraft:iron_bars:0,5,quark:iron_plate:1,15,STAINED_CLAY:15,15,STAINED_CLAY:7,100)
RandomBlock(-6,7,7,minecraft:iron_bars:0,5,quark:iron_plate:1,15,STAINED_CLAY:15,15,STAINED_CLAY:7,100)
RandomBlock(-6,7,8,minecraft:iron_bars:0,5,quark:iron_plate:1,15,STAINED_CLAY:15,15,STAINED_CLAY:7,100)
RandomBlock(-6,8,4,minecraft:iron_bars:0,5,quark:iron_plate:1,15,STAINED_CLAY:15,15,STAINED_CLAY:7,100)
RandomBlock(-6,8,5,minecraft:iron_bars:0,5,quark:iron_plate:1,15,STAINED_CLAY:15,15,STAINED_CLAY:7,100)
RandomBlock(-6,8,6,minecraft:iron_bars:0,5,quark:iron_plate:1,15,STAINED_CLAY:15,15,STAINED_CLAY:7,100)
RandomBlock(-6,8,7,minecraft:iron_bars:0,5,quark:iron_plate:1,15,STAINED_CLAY:15,15,STAINED_CLAY:7,100)
RandomBlock(-6,8,8,minecraft:iron_bars:0,5,quark:iron_plate:1,15,STAINED_CLAY:15,15,STAINED_CLAY:7,100)
RandomBlock(-6,9,4,minecraft:iron_bars:0,5,quark:iron_plate:1,15,STAINED_CLAY:15,15,STAINED_CLAY:7,100)
RandomBlock(-6,9,5,minecraft:iron_bars:0,5,quark:iron_plate:1,15,STAINED_CLAY:15,15,STAINED_CLAY:7,100)
RandomBlock(-6,9,6,minecraft:iron_bars:0,5,quark:iron_plate:1,15,STAINED_CLAY:15,15,STAINED_CLAY:7,100)
RandomBlock(-6,9,7,minecraft:iron_bars:0,5,quark:iron_plate:1,15,STAINED_CLAY:15,15,STAINED_CLAY:7,100)
RandomBlock(-6,9,8,minecraft:iron_bars:0,5,quark:iron_plate:1,15,STAINED_CLAY:15,15,STAINED_CLAY:7,100)
RandomBlock(-6,10,4,minecraft:iron_bars:0,5,quark:iron_plate:1,15,STAINED_CLAY:15,15,STAINED_CLAY:7,100)
RandomBlock(-6,10,5,minecraft:iron_bars:0,5,quark:iron_plate:1,15,STAINED_CLAY:15,15,STAINED_CLAY:7,100)
RandomBlock(-6,10,6,minecraft:iron_bars:0,5,quark:iron_plate:1,15,STAINED_CLAY:15,15,STAINED_CLAY:7,100)
RandomBlock(-6,10,7,minecraft:iron_bars:0,5,quark:iron_plate:1,15,STAINED_CLAY:15,15,STAINED_CLAY:7,100)
RandomBlock(-6,10,8,minecraft:iron_bars:0,5,quark:iron_plate:1,15,STAINED_CLAY:15,15,STAINED_CLAY:7,100)
RandomBlock(-6,11,4,minecraft:iron_bars:0,5,quark:iron_plate:1,15,STAINED_CLAY:15,15,STAINED_CLAY:7,100)
RandomBlock(-6,11,5,minecraft:iron_bars:0,5,quark:iron_plate:1,15,STAINED_CLAY:15,15,STAINED_CLAY:7,100)
RandomBlock(-6,11,6,minecraft:iron_bars:0,5,quark:iron_plate:1,15,STAINED_CLAY:15,15,STAINED_CLAY:7,100)
RandomBlock(-6,11,7,minecraft:iron_bars:0,5,quark:iron_plate:1,15,STAINED_CLAY:15,15,STAINED_CLAY:7,100)
RandomBlock(-6,11,8,minecraft:iron_bars:0,5,quark:iron_plate:1,15,STAINED_CLAY:15,15,STAINED_CLAY:7,100)
RandomBlock(-6,12,4,minecraft:iron_bars:0,5,quark:iron_plate:1,15,STAINED_CLAY:15,15,STAINED_CLAY:7,100)
RandomBlock(-6,12,5,minecraft:iron_bars:0,5,quark:iron_plate:1,15,STAINED_CLAY:15,15,STAINED_CLAY:7,100)
RandomBlock(-6,12,6,minecraft:iron_bars:0,5,quark:iron_plate:1,15,STAINED_CLAY:15,15,STAINED_CLAY:7,100)
RandomBlock(-6,12,7,minecraft:iron_bars:0,5,quark:iron_plate:1,15,STAINED_CLAY:15,15,STAINED_CLAY:7,100)
RandomBlock(-6,12,8,minecraft:iron_bars:0,5,quark:iron_plate:1,15,STAINED_CLAY:15,15,STAINED_CLAY:7,100)
RandomBlock(-6,13,4,minecraft:iron_bars:0,5,quark:iron_plate:1,15,STAINED_CLAY:15,15,STAINED_CLAY:7,100)
RandomBlock(-6,13,5,minecraft:iron_bars:0,5,quark:iron_plate:1,15,STAINED_CLAY:15,15,STAINED_CLAY:7,100)
RandomBlock(-6,13,6,minecraft:iron_bars:0,5,quark:iron_plate:1,15,STAINED_CLAY:15,15,STAINED_CLAY:7,100)
RandomBlock(-6,13,7,minecraft:iron_bars:0,5,quark:iron_plate:1,15,STAINED_CLAY:15,15,STAINED_CLAY:7,100)
RandomBlock(-6,13,8,minecraft:iron_bars:0,5,quark:iron_plate:1,15,STAINED_CLAY:15,15,STAINED_CLAY:7,100)
RandomBlock(-6,14,4,minecraft:iron_bars:0,5,quark:iron_plate:1,15,STAINED_CLAY:15,15,STAINED_CLAY:7,100)
RandomBlock(-6,14,5,minecraft:iron_bars:0,5,quark:iron_plate:1,15,STAINED_CLAY:15,15,STAINED_CLAY:7,100)
RandomBlock(-6,14,6,minecraft:iron_bars:0,5,quark:iron_plate:1,15,STAINED_CLAY:15,15,STAINED_CLAY:7,100)
RandomBlock(-6,14,7,minecraft:iron_bars:0,5,quark:iron_plate:1,15,STAINED_CLAY:15,15,STAINED_CLAY:7,100)
RandomBlock(-6,14,8,minecraft:iron_bars:0,5,quark:iron_plate:1,15,STAINED_CLAY:15,15,STAINED_CLAY:7,100)
RandomBlock(-6,15,4,minecraft:iron_bars:0,5,quark:iron_plate:1,15,STAINED_CLAY:15,15,STAINED_CLAY:7,100)
RandomBlock(-6,15,5,minecraft:iron_bars:0,5,quark:iron_plate:1,15,STAINED_CLAY:15,15,STAINED_CLAY:7,100)
RandomBlock(-6,15,6,minecraft:iron_bars:0,5,quark:iron_plate:1,15,STAINED_CLAY:15,15,STAINED_CLAY:7,100)
RandomBlock(-6,15,7,minecraft:iron_bars:0,5,quark:iron_plate:1,15,STAINED_CLAY:15,15,STAINED_CLAY:7,100)
RandomBlock(-6,15,8,minecraft:iron_bars:0,5,quark:iron_plate:1,15,STAINED_CLAY:15,15,STAINED_CLAY:7,100)
RandomBlock(-6,16,4,minecraft:iron_bars:0,5,quark:iron_plate:1,15,STAINED_CLAY:15,15,STAINED_CLAY:7,100)
RandomBlock(-6,16,5,minecraft:iron_bars:0,5,quark:iron_plate:1,15,STAINED_CLAY:15,15,STAINED_CLAY:7,100)
RandomBlock(-6,16,6,minecraft:iron_bars:0,5,quark:iron_plate:1,15,STAINED_CLAY:15,15,STAINED_CLAY:7,100)
RandomBlock(-6,16,7,minecraft:iron_bars:0,5,quark:iron_plate:1,15,STAINED_CLAY:15,15,STAINED_CLAY:7,100)
RandomBlock(-6,16,8,minecraft:iron_bars:0,5,quark:iron_plate:1,15,STAINED_CLAY:15,15,STAINED_CLAY:7,100)
RandomBlock(-6,17,4,minecraft:iron_bars:0,5,quark:iron_plate:1,15,STAINED_CLAY:15,15,STAINED_CLAY:7,100)
RandomBlock(-6,17,5,minecraft:iron_bars:0,5,quark:iron_plate:1,15,STAINED_CLAY:15,15,STAINED_CLAY:7,100)
RandomBlock(-6,17,6,minecraft:iron_bars:0,5,quark:iron_plate:1,15,STAINED_CLAY:15,15,STAINED_CLAY:7,100)
RandomBlock(-6,17,7,minecraft:iron_bars:0,5,quark:iron_plate:1,15,STAINED_CLAY:15,15,STAINED_CLAY:7,100)
RandomBlock(-6,17,8,minecraft:iron_bars:0,5,quark:iron_plate:1,15,STAINED_CLAY:15,15,STAINED_CLAY:7,100)
RandomBlock(-6,18,4,minecraft:iron_bars:0,5,quark:iron_plate:1,15,STAINED_CLAY:15,15,STAINED_CLAY:7,100)
RandomBlock(-6,18,5,minecraft:iron_bars:0,5,quark:iron_plate:1,15,STAINED_CLAY:15,15,STAINED_CLAY:7,100)
RandomBlock(-6,18,6,minecraft:iron_bars:0,5,quark:iron_plate:1,15,STAINED_CLAY:15,15,STAINED_CLAY:7,100)
RandomBlock(-6,18,7,minecraft:iron_bars:0,5,quark:iron_plate:1,15,STAINED_CLAY:15,15,STAINED_CLAY:7,100)
RandomBlock(-6,18,8,minecraft:iron_bars:0,5,quark:iron_plate:1,15,STAINED_CLAY:15,15,STAINED_CLAY:7,100)
RandomBlock(-6,19,4,minecraft:iron_bars:0,5,quark:iron_plate:1,15,STAINED_CLAY:15,15,STAINED_CLAY:7,100)
RandomBlock(-6,19,5,minecraft:iron_bars:0,5,quark:iron_plate:1,15,STAINED_CLAY:15,15,STAINED_CLAY:7,100)
RandomBlock(-6,19,6,minecraft:iron_bars:0,5,quark:iron_plate:1,15,STAINED_CLAY:15,15,STAINED_CLAY:7,100)
RandomBlock(-6,19,7,minecraft:iron_bars:0,5,quark:iron_plate:1,15,STAINED_CLAY:15,15,STAINED_CLAY:7,100)
RandomBlock(-6,19,8,minecraft:iron_bars:0,5,quark:iron_plate:1,15,STAINED_CLAY:15,15,STAINED_CLAY:7,100)
RandomBlock(-6,20,4,minecraft:iron_bars:0,5,quark:iron_plate:1,15,STAINED_CLAY:15,15,STAINED_CLAY:7,100)
RandomBlock(-6,20,5,minecraft:iron_bars:0,5,quark:iron_plate:1,15,STAINED_CLAY:15,15,STAINED_CLAY:7,100)
RandomBlock(-6,20,6,minecraft:iron_bars:0,5,quark:iron_plate:1,15,STAINED_CLAY:15,15,STAINED_CLAY:7,100)
RandomBlock(-6,20,7,minecraft:iron_bars:0,5,quark:iron_plate:1,15,STAINED_CLAY:15,15,STAINED_CLAY:7,100)
RandomBlock(-6,20,8,minecraft:iron_bars:0,5,quark:iron_plate:1,15,STAINED_CLAY:15,15,STAINED_CLAY:7,100)
RandomBlock(-6,21,4,minecraft:iron_bars:0,5,quark:iron_plate:1,15,STAINED_CLAY:15,15,STAINED_CLAY:7,100)
RandomBlock(-6,21,5,minecraft:iron_bars:0,5,quark:iron_plate:1,15,STAINED_CLAY:15,15,STAINED_CLAY:7,100)
RandomBlock(-6,21,6,minecraft:iron_bars:0,5,quark:iron_plate:1,15,STAINED_CLAY:15,15,STAINED_CLAY:7,100)
RandomBlock(-6,21,7,minecraft:iron_bars:0,5,quark:iron_plate:1,15,STAINED_CLAY:15,15,STAINED_CLAY:7,100)
RandomBlock(-6,21,8,minecraft:iron_bars:0,5,quark:iron_plate:1,15,STAINED_CLAY:15,15,STAINED_CLAY:7,100)
RandomBlock(-6,22,4,minecraft:iron_bars:0,5,quark:iron_plate:1,15,STAINED_CLAY:15,15,STAINED_CLAY:7,100)
RandomBlock(-6,22,5,minecraft:iron_bars:0,5,quark:iron_plate:1,15,STAINED_CLAY:15,15,STAINED_CLAY:7,100)
RandomBlock(-6,22,6,minecraft:iron_bars:0,5,quark:iron_plate:1,15,STAINED_CLAY:15,15,STAINED_CLAY:7,100)
RandomBlock(-6,22,7,minecraft:iron_bars:0,5,quark:iron_plate:1,15,STAINED_CLAY:15,15,STAINED_CLAY:7,100)
RandomBlock(-6,22,8,minecraft:iron_bars:0,5,quark:iron_plate:1,15,STAINED_CLAY:15,15,STAINED_CLAY:7,100)
RandomBlock(-6,23,4,minecraft:iron_bars:0,5,quark:iron_plate:1,15,STAINED_CLAY:15,15,STAINED_CLAY:7,100)
RandomBlock(-6,23,5,minecraft:iron_bars:0,5,quark:iron_plate:1,15,STAINED_CLAY:15,15,STAINED_CLAY:7,100)
RandomBlock(-6,23,6,minecraft:iron_bars:0,5,quark:iron_plate:1,15,STAINED_CLAY:15,15,STAINED_CLAY:7,100)
RandomBlock(-6,23,7,minecraft:iron_bars:0,5,quark:iron_plate:1,15,STAINED_CLAY:15,15,STAINED_CLAY:7,100)
RandomBlock(-6,23,8,minecraft:iron_bars:0,5,quark:iron_plate:1,15,STAINED_CLAY:15,15,STAINED_CLAY:7,100)
RandomBlock(-6,24,4,minecraft:iron_bars:0,5,quark:iron_plate:1,15,STAINED_CLAY:15,15,STAINED_CLAY:7,100)
RandomBlock(-6,24,5,minecraft:iron_bars:0,5,quark:iron_plate:1,15,STAINED_CLAY:15,15,STAINED_CLAY:7,100)
RandomBlock(-6,24,6,minecraft:iron_bars:0,5,quark:iron_plate:1,15,STAINED_CLAY:15,15,STAINED_CLAY:7,100)
RandomBlock(-6,24,7,minecraft:iron_bars:0,5,quark:iron_plate:1,15,STAINED_CLAY:15,15,STAINED_CLAY:7,100)
RandomBlock(-6,24,8,minecraft:iron_bars:0,5,quark:iron_plate:1,15,STAINED_CLAY:15,15,STAINED_CLAY:7,100)
RandomBlock(-6,25,4,minecraft:iron_bars:0,5,quark:iron_plate:1,15,STAINED_CLAY:15,15,STAINED_CLAY:7,100)
RandomBlock(-6,25,5,minecraft:iron_bars:0,5,quark:iron_plate:1,15,STAINED_CLAY:15,15,STAINED_CLAY:7,100)
RandomBlock(-6,25,6,minecraft:iron_bars:0,5,quark:iron_plate:1,15,STAINED_CLAY:15,15,STAINED_CLAY:7,100)
RandomBlock(-6,25,7,minecraft:iron_bars:0,5,quark:iron_plate:1,15,STAINED_CLAY:15,15,STAINED_CLAY:7,100)
RandomBlock(-6,25,8,minecraft:iron_bars:0,5,quark:iron_plate:1,15,STAINED_CLAY:15,15,STAINED_CLAY:7,100)
RandomBlock(-6,26,4,minecraft:iron_bars:0,5,quark:iron_plate:1,15,STAINED_CLAY:15,15,STAINED_CLAY:7,100)
RandomBlock(-6,26,5,minecraft:iron_bars:0,5,quark:iron_plate:1,15,STAINED_CLAY:15,15,STAINED_CLAY:7,100)
RandomBlock(-6,26,6,minecraft:iron_bars:0,5,quark:iron_plate:1,15,STAINED_CLAY:15,15,STAINED_CLAY:7,100)
RandomBlock(-6,26,7,minecraft:iron_bars:0,5,quark:iron_plate:1,15,STAINED_CLAY:15,15,STAINED_CLAY:7,100)
RandomBlock(-6,26,8,minecraft:iron_bars:0,5,quark:iron_plate:1,15,STAINED_CLAY:15,15,STAINED_CLAY:7,100)
RandomBlock(-6,27,4,minecraft:iron_bars:0,5,quark:iron_plate:1,15,STAINED_CLAY:15,15,STAINED_CLAY:7,100)
RandomBlock(-6,27,5,minecraft:iron_bars:0,5,quark:iron_plate:1,15,STAINED_CLAY:15,15,STAINED_CLAY:7,100)
RandomBlock(-6,27,6,minecraft:iron_bars:0,5,quark:iron_plate:1,15,STAINED_CLAY:15,15,STAINED_CLAY:7,100)
RandomBlock(-6,27,7,minecraft:iron_bars:0,5,quark:iron_plate:1,15,STAINED_CLAY:15,15,STAINED_CLAY:7,100)
RandomBlock(-6,27,8,minecraft:iron_bars:0,5,quark:iron_plate:1,15,STAINED_CLAY:15,15,STAINED_CLAY:7,100)
RandomBlock(-6,28,4,minecraft:iron_bars:0,5,quark:iron_plate:1,15,STAINED_CLAY:15,15,STAINED_CLAY:7,100)
RandomBlock(-6,28,5,minecraft:iron_bars:0,5,quark:iron_plate:1,15,STAINED_CLAY:15,15,STAINED_CLAY:7,100)
RandomBlock(-6,28,6,minecraft:iron_bars:0,5,quark:iron_plate:1,15,STAINED_CLAY:15,15,STAINED_CLAY:7,100)
RandomBlock(-6,28,7,minecraft:iron_bars:0,5,quark:iron_plate:1,15,STAINED_CLAY:15,15,STAINED_CLAY:7,100)
RandomBlock(-6,28,8,minecraft:iron_bars:0,5,quark:iron_plate:1,15,STAINED_CLAY:15,15,STAINED_CLAY:7,100)
RandomBlock(-6,29,4,minecraft:iron_bars:0,5,quark:iron_plate:1,15,STAINED_CLAY:15,15,STAINED_CLAY:7,100)
RandomBlock(-6,29,5,minecraft:iron_bars:0,5,quark:iron_plate:1,15,STAINED_CLAY:15,15,STAINED_CLAY:7,100)
RandomBlock(-6,29,6,minecraft:iron_bars:0,5,quark:iron_plate:1,15,STAINED_CLAY:15,15,STAINED_CLAY:7,100)
RandomBlock(-6,29,7,minecraft:iron_bars:0,5,quark:iron_plate:1,15,STAINED_CLAY:15,15,STAINED_CLAY:7,100)
RandomBlock(-6,29,8,minecraft:iron_bars:0,5,quark:iron_plate:1,15,STAINED_CLAY:15,15,STAINED_CLAY:7,100)
RandomBlock(-6,30,4,minecraft:iron_bars:0,5,quark:iron_plate:1,15,STAINED_CLAY:15,15,STAINED_CLAY:7,100)
RandomBlock(-6,30,5,minecraft:iron_bars:0,5,quark:iron_plate:1,15,STAINED_CLAY:15,15,STAINED_CLAY:7,100)
RandomBlock(-6,30,6,minecraft:iron_bars:0,5,quark:iron_plate:1,15,STAINED_CLAY:15,15,STAINED_CLAY:7,100)
RandomBlock(-6,30,7,minecraft:iron_bars:0,5,quark:iron_plate:1,15,STAINED_CLAY:15,15,STAINED_CLAY:7,100)
RandomBlock(-6,30,8,minecraft:iron_bars:0,5,quark:iron_plate:1,15,STAINED_CLAY:15,15,STAINED_CLAY:7,100)
RandomBlock(-6,31,4,minecraft:iron_bars:0,5,quark:iron_plate:1,15,STAINED_CLAY:15,15,STAINED_CLAY:7,100)
RandomBlock(-6,31,5,minecraft:iron_bars:0,5,quark:iron_plate:1,15,STAINED_CLAY:15,15,STAINED_CLAY:7,100)
RandomBlock(-6,31,6,minecraft:iron_bars:0,5,quark:iron_plate:1,15,STAINED_CLAY:15,15,STAINED_CLAY:7,100)
RandomBlock(-6,31,7,minecraft:iron_bars:0,5,quark:iron_plate:1,15,STAINED_CLAY:15,15,STAINED_CLAY:7,100)
RandomBlock(-6,31,8,minecraft:iron_bars:0,5,quark:iron_plate:1,15,STAINED_CLAY:15,15,STAINED_CLAY:7,100)
RandomBlock(-6,32,4,minecraft:iron_bars:0,5,quark:iron_plate:1,15,STAINED_CLAY:15,15,STAINED_CLAY:7,100)
RandomBlock(-6,32,5,minecraft:iron_bars:0,5,quark:iron_plate:1,15,STAINED_CLAY:15,15,STAINED_CLAY:7,100)
RandomBlock(-6,32,6,minecraft:iron_bars:0,5,quark:iron_plate:1,15,STAINED_CLAY:15,15,STAINED_CLAY:7,100)
RandomBlock(-6,32,7,minecraft:iron_bars:0,5,quark:iron_plate:1,15,STAINED_CLAY:15,15,STAINED_CLAY:7,100)
RandomBlock(-6,32,8,minecraft:iron_bars:0,5,quark:iron_plate:1,15,STAINED_CLAY:15,15,STAINED_CLAY:7,100)
RandomBlock(-6,33,4,minecraft:iron_bars:0,5,quark:iron_plate:1,15,STAINED_CLAY:15,15,STAINED_CLAY:7,100)
RandomBlock(-6,33,5,minecraft:iron_bars:0,5,quark:iron_plate:1,15,STAINED_CLAY:15,15,STAINED_CLAY:7,100)
RandomBlock(-6,33,6,minecraft:iron_bars:0,5,quark:iron_plate:1,15,STAINED_CLAY:15,15,STAINED_CLAY:7,100)
RandomBlock(-6,33,7,minecraft:iron_bars:0,5,quark:iron_plate:1,15,STAINED_CLAY:15,15,STAINED_CLAY:7,100)
RandomBlock(-6,33,8,minecraft:iron_bars:0,5,quark:iron_plate:1,15,STAINED_CLAY:15,15,STAINED_CLAY:7,100)
RandomBlock(-6,34,4,minecraft:iron_bars:0,5,quark:iron_plate:1,15,STAINED_CLAY:15,15,STAINED_CLAY:7,100)
RandomBlock(-6,34,5,minecraft:iron_bars:0,5,quark:iron_plate:1,15,STAINED_CLAY:15,15,STAINED_CLAY:7,100)
RandomBlock(-6,34,6,minecraft:iron_bars:0,5,quark:iron_plate:1,15,STAINED_CLAY:15,15,STAINED_CLAY:7,100)
RandomBlock(-6,34,7,minecraft:iron_bars:0,5,quark:iron_plate:1,15,STAINED_CLAY:15,15,STAINED_CLAY:7,100)
RandomBlock(-6,34,8,minecraft:iron_bars:0,5,quark:iron_plate:1,15,STAINED_CLAY:15,15,STAINED_CLAY:7,100)
RandomBlock(-6,35,4,minecraft:iron_bars:0,5,quark:iron_plate:1,15,STAINED_CLAY:15,15,STAINED_CLAY:7,100)
RandomBlock(-6,35,5,minecraft:iron_bars:0,5,quark:iron_plate:1,15,STAINED_CLAY:15,15,STAINED_CLAY:7,100)
RandomBlock(-6,35,6,minecraft:iron_bars:0,5,quark:iron_plate:1,15,STAINED_CLAY:15,15,STAINED_CLAY:7,100)
RandomBlock(-6,35,7,minecraft:iron_bars:0,5,quark:iron_plate:1,15,STAINED_CLAY:15,15,STAINED_CLAY:7,100)
RandomBlock(-6,35,8,minecraft:iron_bars:0,5,quark:iron_plate:1,15,STAINED_CLAY:15,15,STAINED_CLAY:7,100)
RandomBlock(-6,36,4,minecraft:iron_bars:0,5,quark:iron_plate:1,15,STAINED_CLAY:15,15,STAINED_CLAY:7,100)
RandomBlock(-6,36,5,minecraft:iron_bars:0,5,quark:iron_plate:1,15,STAINED_CLAY:15,15,STAINED_CLAY:7,100)
RandomBlock(-6,36,6,minecraft:iron_bars:0,5,quark:iron_plate:1,15,STAINED_CLAY:15,15,STAINED_CLAY:7,100)
RandomBlock(-6,36,7,minecraft:iron_bars:0,5,quark:iron_plate:1,15,STAINED_CLAY:15,15,STAINED_CLAY:7,100)
RandomBlock(-6,36,8,minecraft:iron_bars:0,5,quark:iron_plate:1,15,STAINED_CLAY:15,15,STAINED_CLAY:7,100)
RandomBlock(-6,37,4,minecraft:iron_bars:0,5,quark:iron_plate:1,15,STAINED_CLAY:15,15,STAINED_CLAY:7,100)
RandomBlock(-6,37,5,minecraft:iron_bars:0,5,quark:iron_plate:1,15,STAINED_CLAY:15,15,STAINED_CLAY:7,100)
RandomBlock(-6,37,6,minecraft:iron_bars:0,5,quark:iron_plate:1,15,STAINED_CLAY:15,15,STAINED_CLAY:7,100)
RandomBlock(-6,37,7,minecraft:iron_bars:0,5,quark:iron_plate:1,15,STAINED_CLAY:15,15,STAINED_CLAY:7,100)
RandomBlock(-6,37,8,minecraft:iron_bars:0,5,quark:iron_plate:1,15,STAINED_CLAY:15,15,STAINED_CLAY:7,100)
RandomBlock(-6,38,4,minecraft:iron_bars:0,5,quark:iron_plate:1,15,STAINED_CLAY:15,15,STAINED_CLAY:7,100)
RandomBlock(-6,38,5,minecraft:iron_bars:0,5,quark:iron_plate:1,15,STAINED_CLAY:15,15,STAINED_CLAY:7,100)
RandomBlock(-6,38,6,minecraft:iron_bars:0,5,quark:iron_plate:1,15,STAINED_CLAY:15,15,STAINED_CLAY:7,100)
RandomBlock(-6,38,7,minecraft:iron_bars:0,5,quark:iron_plate:1,15,STAINED_CLAY:15,15,STAINED_CLAY:7,100)
RandomBlock(-6,38,8,minecraft:iron_bars:0,5,quark:iron_plate:1,15,STAINED_CLAY:15,15,STAINED_CLAY:7,100)
RandomBlock(-6,39,4,minecraft:iron_bars:0,5,quark:iron_plate:1,15,STAINED_CLAY:15,15,STAINED_CLAY:7,100)
RandomBlock(-6,39,5,minecraft:iron_bars:0,5,quark:iron_plate:1,15,STAINED_CLAY:15,15,STAINED_CLAY:7,100)
RandomBlock(-6,39,6,minecraft:iron_bars:0,5,quark:iron_plate:1,15,STAINED_CLAY:15,15,STAINED_CLAY:7,100)
RandomBlock(-6,39,7,minecraft:iron_bars:0,5,quark:iron_plate:1,15,STAINED_CLAY:15,15,STAINED_CLAY:7,100)
RandomBlock(-6,39,8,minecraft:iron_bars:0,5,quark:iron_plate:1,15,STAINED_CLAY:15,15,STAINED_CLAY:7,100)
RandomBlock(-6,40,4,minecraft:iron_bars:0,5,quark:iron_plate:1,15,STAINED_CLAY:15,15,STAINED_CLAY:7,100)
RandomBlock(-6,40,5,minecraft:iron_bars:0,5,quark:iron_plate:1,15,STAINED_CLAY:15,15,STAINED_CLAY:7,100)
RandomBlock(-6,40,6,minecraft:iron_bars:0,5,quark:iron_plate:1,15,STAINED_CLAY:15,15,STAINED_CLAY:7,100)
RandomBlock(-6,40,7,minecraft:iron_bars:0,5,quark:iron_plate:1,15,STAINED_CLAY:15,15,STAINED_CLAY:7,100)
RandomBlock(-6,40,8,minecraft:iron_bars:0,5,quark:iron_plate:1,15,STAINED_CLAY:15,15,STAINED_CLAY:7,100)
RandomBlock(-6,41,4,minecraft:iron_bars:0,5,quark:iron_plate:1,15,STAINED_CLAY:15,15,STAINED_CLAY:7,100)
RandomBlock(-6,41,5,minecraft:iron_bars:0,5,quark:iron_plate:1,15,STAINED_CLAY:15,15,STAINED_CLAY:7,100)
RandomBlock(-6,41,6,minecraft:iron_bars:0,5,quark:iron_plate:1,15,STAINED_CLAY:15,15,STAINED_CLAY:7,100)
RandomBlock(-6,41,7,minecraft:iron_bars:0,5,quark:iron_plate:1,15,STAINED_CLAY:15,15,STAINED_CLAY:7,100)
RandomBlock(-6,41,8,minecraft:iron_bars:0,5,quark:iron_plate:1,15,STAINED_CLAY:15,15,STAINED_CLAY:7,100)
RandomBlock(-6,42,4,minecraft:iron_bars:0,5,quark:iron_plate:1,15,STAINED_CLAY:15,15,STAINED_CLAY:7,100)
RandomBlock(-6,42,5,minecraft:iron_bars:0,5,quark:iron_plate:1,15,STAINED_CLAY:15,15,STAINED_CLAY:7,100)
RandomBlock(-6,42,6,minecraft:iron_bars:0,5,quark:iron_plate:1,15,STAINED_CLAY:15,15,STAINED_CLAY:7,100)
RandomBlock(-6,42,7,minecraft:iron_bars:0,5,quark:iron_plate:1,15,STAINED_CLAY:15,15,STAINED_CLAY:7,100)
RandomBlock(-6,42,8,minecraft:iron_bars:0,5,quark:iron_plate:1,15,STAINED_CLAY:15,15,STAINED_CLAY:7,100)
RandomBlock(-6,43,4,minecraft:iron_bars:0,5,quark:iron_plate:1,15,STAINED_CLAY:15,15,STAINED_CLAY:7,100)
RandomBlock(-6,43,5,minecraft:iron_bars:0,5,quark:iron_plate:1,15,STAINED_CLAY:15,15,STAINED_CLAY:7,100)
RandomBlock(-6,43,6,minecraft:iron_bars:0,5,quark:iron_plate:1,15,STAINED_CLAY:15,15,STAINED_CLAY:7,100)
RandomBlock(-6,43,7,minecraft:iron_bars:0,5,quark:iron_plate:1,15,STAINED_CLAY:15,15,STAINED_CLAY:7,100)
RandomBlock(-6,43,8,minecraft:iron_bars:0,5,quark:iron_plate:1,15,STAINED_CLAY:15,15,STAINED_CLAY:7,100)
RandomBlock(-6,44,-7,minecraft:iron_bars:0,5,STAINED_CLAY:15,5,STAINED_CLAY:7,5,quark:iron_plate_slab:8,15,quark:world_stone_pavement:2,15,STAINED_CLAY:9,100)
RandomBlock(-6,44,-6,minecraft:iron_bars:0,5,STAINED_CLAY:15,5,STAINED_CLAY:7,5,quark:iron_plate_slab:8,15,quark:world_stone_pavement:2,15,STAINED_CLAY:9,100)
RandomBlock(-6,44,-5,minecraft:iron_bars:0,5,STAINED_CLAY:15,5,STAINED_CLAY:7,5,quark:iron_plate_slab:8,15,quark:world_stone_pavement:2,15,STAINED_CLAY:9,100)
RandomBlock(-6,44,-4,minecraft:iron_bars:0,5,STAINED_CLAY:15,5,STAINED_CLAY:7,5,quark:iron_plate_slab:8,15,quark:world_stone_pavement:2,15,STAINED_CLAY:9,100)
RandomBlock(-6,44,-3,minecraft:iron_bars:0,5,STAINED_CLAY:15,5,STAINED_CLAY:7,5,quark:iron_plate_slab:8,15,quark:world_stone_pavement:2,15,STAINED_CLAY:9,100)
RandomBlock(-6,44,-2,minecraft:iron_bars:0,5,STAINED_CLAY:15,5,STAINED_CLAY:7,5,quark:iron_plate_slab:8,15,quark:world_stone_pavement:2,15,STAINED_CLAY:9,100)
RandomBlock(-6,44,-1,minecraft:iron_bars:0,5,STAINED_CLAY:15,5,STAINED_CLAY:7,5,quark:iron_plate_slab:8,15,quark:world_stone_pavement:2,15,STAINED_CLAY:9,100)
RandomBlock(-6,44,0,minecraft:iron_bars:0,5,STAINED_CLAY:15,5,STAINED_CLAY:7,5,quark:iron_plate_slab:8,15,quark:world_stone_pavement:2,15,STAINED_CLAY:9,100)
RandomBlock(-6,44,1,minecraft:iron_bars:0,5,STAINED_CLAY:15,5,STAINED_CLAY:7,5,quark:iron_plate_slab:8,15,quark:world_stone_pavement:2,15,STAINED_CLAY:9,100)
RandomBlock(-6,44,2,minecraft:iron_bars:0,5,STAINED_CLAY:15,5,STAINED_CLAY:7,5,quark:iron_plate_slab:8,15,quark:world_stone_pavement:2,15,STAINED_CLAY:9,100)
RandomBlock(-6,44,3,minecraft:iron_bars:0,5,STAINED_CLAY:15,5,STAINED_CLAY:7,5,quark:iron_plate_slab:8,15,quark:world_stone_pavement:2,15,STAINED_CLAY:9,100)
RandomBlock(-6,44,4,minecraft:iron_bars:0,5,STAINED_CLAY:15,5,STAINED_CLAY:7,5,quark:iron_plate_slab:8,15,quark:world_stone_pavement:2,15,STAINED_CLAY:9,100)
RandomBlock(-6,44,5,minecraft:iron_bars:0,5,STAINED_CLAY:15,5,STAINED_CLAY:7,5,quark:iron_plate_slab:8,15,quark:world_stone_pavement:2,15,STAINED_CLAY:9,100)
RandomBlock(-6,44,6,minecraft:iron_bars:0,5,STAINED_CLAY:15,5,STAINED_CLAY:7,5,quark:iron_plate_slab:8,15,quark:world_stone_pavement:2,15,STAINED_CLAY:9,100)
RandomBlock(-6,44,7,minecraft:iron_bars:0,5,STAINED_CLAY:15,5,STAINED_CLAY:7,5,quark:iron_plate_slab:8,15,quark:world_stone_pavement:2,15,STAINED_CLAY:9,100)
RandomBlock(-6,44,8,minecraft:iron_bars:0,5,STAINED_CLAY:15,5,STAINED_CLAY:7,5,quark:iron_plate_slab:8,15,quark:world_stone_pavement:2,15,STAINED_CLAY:9,100)
Block(-6,45,-6,quark:iron_plate:1)
Block(-6,45,-5,quark:iron_plate:1)
Block(-6,45,-4,quark:iron_plate:1)
Block(-6,45,-3,quark:iron_plate:1)
Block(-6,45,-2,quark:iron_plate:1)
Block(-6,45,-1,quark:iron_plate:1)
Block(-6,45,0,quark:iron_plate:1)
Block(-6,45,1,quark:iron_plate:1)
Block(-6,45,2,quark:iron_plate:1)
Block(-6,45,3,quark:iron_plate:1)
Block(-6,45,4,quark:iron_plate:1)
Block(-6,45,5,quark:iron_plate:1)
Block(-6,46,-7,quark:iron_plate:1)
Block(-6,46,-6,COAL_BLOCK:0)
Block(-6,46,-5,COAL_BLOCK:0)
Block(-6,46,-4,quark:iron_plate:1)
Block(-6,46,-3,SLIME_BLOCK:0)
Block(-6,46,-2,SLIME_BLOCK:0)
Block(-6,46,-1,SLIME_BLOCK:0)
Block(-6,46,0,SLIME_BLOCK:0)
Block(-6,46,1,SLIME_BLOCK:0)
Block(-6,46,2,SLIME_BLOCK:0)
Block(-6,46,3,SLIME_BLOCK:0)
Block(-6,46,4,quark:iron_plate:1)
Block(-6,46,5,SMOOTH_STAIRS:3)
Block(-6,47,-7,quark:iron_plate:1)
Block(-6,47,-6,COAL_BLOCK:0)
Block(-6,47,-5,COAL_BLOCK:0)
Block(-6,47,-4,quark:iron_plate:1)
Block(-6,47,-3,SLIME_BLOCK:0)
Block(-6,47,-2,SLIME_BLOCK:0)
Block(-6,47,-1,SLIME_BLOCK:0)
Block(-6,47,0,SLIME_BLOCK:0)
Block(-6,47,1,SLIME_BLOCK:0)
Block(-6,47,2,SLIME_BLOCK:0)
Block(-6,47,3,SLIME_BLOCK:0)
Block(-6,47,4,quark:iron_plate:1)
Block(-6,47,5,SMOOTH_STAIRS:7)
Block(-6,48,-7,quark:iron_plate:1)
Block(-6,48,-6,COAL_BLOCK:0)
Block(-6,48,-5,COAL_BLOCK:0)
Block(-6,48,-4,quark:iron_plate:1)
Block(-6,48,-3,quark:iron_plate:1)
Block(-6,48,-2,quark:iron_plate:1)
Block(-6,48,-1,quark:iron_plate:1)
Block(-6,48,0,quark:iron_plate:1)
Block(-6,48,1,quark:iron_plate:1)
Block(-6,48,2,quark:iron_plate:1)
Block(-6,48,3,quark:iron_plate:1)
Block(-6,48,4,quark:iron_plate:1)
Block(-6,48,5,quark:iron_plate:1)
Block(-6,49,-7,STEP:0)
Block(-6,49,-6,STEP:0)
Block(-6,49,-5,STEP:0)
Block(-6,49,-4,STEP:0)
RandomBlock(-6,50,-7,minecraft:iron_bars:0,5,STAINED_CLAY:15,5,STAINED_CLAY:7,5,quark:iron_plate_slab:8,15,quark:world_stone_pavement:2,15,STAINED_CLAY:9,100)
RandomBlock(-6,50,-6,minecraft:iron_bars:0,5,STAINED_CLAY:15,5,STAINED_CLAY:7,5,quark:iron_plate_slab:8,15,quark:world_stone_pavement:2,15,STAINED_CLAY:9,100)
RandomBlock(-6,50,-5,minecraft:iron_bars:0,5,STAINED_CLAY:15,5,STAINED_CLAY:7,5,quark:iron_plate_slab:8,15,quark:world_stone_pavement:2,15,STAINED_CLAY:9,100)
RandomBlock(-6,50,-4,minecraft:iron_bars:0,5,STAINED_CLAY:15,5,STAINED_CLAY:7,5,quark:iron_plate_slab:8,15,quark:world_stone_pavement:2,15,STAINED_CLAY:9,100)
RandomBlock(-6,50,-3,minecraft:iron_bars:0,5,STAINED_CLAY:15,5,STAINED_CLAY:7,5,quark:iron_plate_slab:8,15,quark:world_stone_pavement:2,15,STAINED_CLAY:9,100)
RandomBlock(-6,50,-2,minecraft:iron_bars:0,5,STAINED_CLAY:15,5,STAINED_CLAY:7,5,quark:iron_plate_slab:8,15,quark:world_stone_pavement:2,15,STAINED_CLAY:9,100)
RandomBlock(-6,50,-1,minecraft:iron_bars:0,5,STAINED_CLAY:15,5,STAINED_CLAY:7,5,quark:iron_plate_slab:8,15,quark:world_stone_pavement:2,15,STAINED_CLAY:9,100)
RandomBlock(-6,50,0,minecraft:iron_bars:0,5,STAINED_CLAY:15,5,STAINED_CLAY:7,5,quark:iron_plate_slab:8,15,quark:world_stone_pavement:2,15,STAINED_CLAY:9,100)
RandomBlock(-6,50,1,minecraft:iron_bars:0,5,STAINED_CLAY:15,5,STAINED_CLAY:7,5,quark:iron_plate_slab:8,15,quark:world_stone_pavement:2,15,STAINED_CLAY:9,100)
RandomBlock(-6,50,2,minecraft:iron_bars:0,5,STAINED_CLAY:15,5,STAINED_CLAY:7,5,quark:iron_plate_slab:8,15,quark:world_stone_pavement:2,15,STAINED_CLAY:9,100)
