
#######################################################################
# +-----------------------------------------------------------------+ #
# |                            BO4 object                           | #
# +-----------------------------------------------------------------+ #
#######################################################################

Author: NLBlackEagle

Description: No description given

SettingsMode: WriteWithoutComments


#######################################################################
# +-----------------------------------------------------------------+ #
# |                          Main settings                          | #
# +-----------------------------------------------------------------+ #
#######################################################################

FixedRotation: 

Frequency: 0

SpawnHeight: highestBlock

UseCenterForHighestBlock: true

##############################
# Height Limits for the BO4. #
##############################

MinHeight: 0

MaxHeight: 255

InheritBO3: 

InheritBO3Rotation: NORTH

OverrideChildSettings: true

OverrideParentHeight: false

CanOverride: true

BranchFrequency: 0

BranchFrequencyGroup: 

MustBeBelowOther: false

MustBeInside: 

CannotBeInside: 

ReplacesBO3: 

MustBeInsideWorldBorders: true
CanSpawnOnWater: true

SpawnOnWaterOnly: false

SpawnUnderWater: false

SpawnAtWaterLevel: false

HeightOffset: 0

RemoveAir: true

ReplaceAbove: 

ReplaceBelow: 

ReplaceWithBiomeBlocks: false

ReplaceWithSurfaceBlock: GRASS

ReplaceWithGroundBlock: DIRT

ReplaceWithStoneBlock: STONE

SmoothRadius: 0

SmoothHeightOffset: 0

SmoothStartTop: false

SmoothStartWood: false

SmoothingSurfaceBlock: 

SmoothingGroundBlock: 

BO3Group: 

IsSpawnPoint: false

DoReplaceBlocks: true


#######################################################################
# +-----------------------------------------------------------------+ #
# |                              Blocks                             | #
# +-----------------------------------------------------------------+ #
#######################################################################

RandomBlock(-8,45,-2,minecraft:iron_bars:0,5,CONCRETE_POWDER:8,10,quark:limestone:1,15,quark:limestone,15,quark:world_stone_pavement:2,15,CONCRETE:8,100)
RandomBlock(-8,45,4,minecraft:iron_bars:0,5,CONCRETE_POWDER:8,10,quark:limestone:1,15,quark:limestone,15,quark:world_stone_pavement:2,15,CONCRETE:8,100)
RandomBlock(-8,46,-3,CONCRETE_POWDER:7,25,CONCRETE:7,100)
RandomBlock(-8,46,-2,CONCRETE_POWDER:7,25,CONCRETE:7,100)
RandomBlock(-8,46,-1,CONCRETE_POWDER:7,25,CONCRETE:7,100)
RandomBlock(-8,46,3,CONCRETE_POWDER:7,25,CONCRETE:7,100)
RandomBlock(-8,46,4,CONCRETE_POWDER:7,25,CONCRETE:7,100)
RandomBlock(-8,46,5,CONCRETE_POWDER:7,25,CONCRETE:7,100)
RandomBlock(-8,47,-3,CONCRETE_POWDER:7,25,CONCRETE:7,100)
RandomBlock(-8,47,-2,CONCRETE_POWDER:7,25,CONCRETE:7,100)
RandomBlock(-8,47,-1,CONCRETE_POWDER:7,25,CONCRETE:7,100)
RandomBlock(-8,47,3,CONCRETE_POWDER:7,25,CONCRETE:7,100)
RandomBlock(-8,47,4,CONCRETE_POWDER:7,25,CONCRETE:7,100)
RandomBlock(-8,47,5,CONCRETE_POWDER:7,25,CONCRETE:7,100)
RandomBlock(-8,48,-3,CONCRETE_POWDER:7,25,CONCRETE:7,100)
RandomBlock(-8,48,-2,CONCRETE_POWDER:7,25,CONCRETE:7,100)
RandomBlock(-8,48,-1,CONCRETE_POWDER:7,25,CONCRETE:7,100)
RandomBlock(-8,48,3,CONCRETE_POWDER:7,25,CONCRETE:7,100)
RandomBlock(-8,48,4,CONCRETE_POWDER:7,25,CONCRETE:7,100)
RandomBlock(-8,48,5,CONCRETE_POWDER:7,25,CONCRETE:7,100)
RandomBlock(-7,44,-2,minecraft:iron_bars:0,5,CONCRETE_POWDER:8,10,quark:limestone:1,15,quark:limestone,15,quark:world_stone_pavement:2,15,CONCRETE:8,100)
RandomBlock(-7,44,4,minecraft:iron_bars:0,5,CONCRETE_POWDER:8,10,quark:limestone:1,15,quark:limestone,15,quark:world_stone_pavement:2,15,CONCRETE:8,100)
RandomBlock(-7,45,-3,minecraft:iron_bars:0,5,CONCRETE_POWDER:8,10,quark:limestone:1,15,quark:limestone,15,quark:world_stone_pavement:2,15,CONCRETE:8,100)
RandomBlock(-7,45,-2,minecraft:iron_bars:0,5,CONCRETE_POWDER:8,10,quark:limestone:1,15,quark:limestone,15,quark:world_stone_pavement:2,15,CONCRETE:8,100)
RandomBlock(-7,45,-1,minecraft:iron_bars:0,5,CONCRETE_POWDER:8,10,quark:limestone:1,15,quark:limestone,15,quark:world_stone_pavement:2,15,CONCRETE:8,100)
RandomBlock(-7,45,3,minecraft:iron_bars:0,5,CONCRETE_POWDER:8,10,quark:limestone:1,15,quark:limestone,15,quark:world_stone_pavement:2,15,CONCRETE:8,100)
RandomBlock(-7,45,4,minecraft:iron_bars:0,5,CONCRETE_POWDER:8,10,quark:limestone:1,15,quark:limestone,15,quark:world_stone_pavement:2,15,CONCRETE:8,100)
RandomBlock(-7,45,5,minecraft:iron_bars:0,5,CONCRETE_POWDER:8,10,quark:limestone:1,15,quark:limestone,15,quark:world_stone_pavement:2,15,CONCRETE:8,100)
RandomBlock(-7,46,-4,minecraft:iron_bars:0,5,CONCRETE_POWDER:8,10,quark:limestone:1,15,quark:limestone,15,quark:world_stone_pavement:2,15,CONCRETE:8,100)
Block(-7,46,-3,QUARTZ_BLOCK:0)
RandomBlock(-7,46,-2,CONCRETE_POWDER:7,25,CONCRETE:7,100)
Block(-7,46,-1,QUARTZ_BLOCK:0)
RandomBlock(-7,46,0,minecraft:iron_bars:0,5,CONCRETE_POWDER:8,10,quark:limestone:1,15,quark:limestone,15,quark:world_stone_pavement:2,15,CONCRETE:8,100)
RandomBlock(-7,46,2,minecraft:iron_bars:0,5,CONCRETE_POWDER:8,10,quark:limestone:1,15,quark:limestone,15,quark:world_stone_pavement:2,15,CONCRETE:8,100)
Block(-7,46,3,QUARTZ_BLOCK:0)
RandomBlock(-7,46,4,CONCRETE_POWDER:7,25,CONCRETE:7,100)
Block(-7,46,5,QUARTZ_BLOCK:0)
RandomBlock(-7,46,6,minecraft:iron_bars:0,5,CONCRETE_POWDER:8,10,quark:limestone:1,15,quark:limestone,15,quark:world_stone_pavement:2,15,CONCRETE:8,100)
RandomBlock(-7,47,-4,minecraft:iron_bars:0,5,CONCRETE_POWDER:8,10,quark:limestone:1,15,quark:limestone,15,quark:world_stone_pavement:2,15,CONCRETE:8,100)
Block(-7,47,-3,QUARTZ_BLOCK:0)
Block(-7,47,-1,QUARTZ_BLOCK:0)
RandomBlock(-7,47,0,minecraft:iron_bars:0,5,CONCRETE_POWDER:8,10,quark:limestone:1,15,quark:limestone,15,quark:world_stone_pavement:2,15,CONCRETE:8,100)
RandomBlock(-7,47,2,minecraft:iron_bars:0,5,CONCRETE_POWDER:8,10,quark:limestone:1,15,quark:limestone,15,quark:world_stone_pavement:2,15,CONCRETE:8,100)
Block(-7,47,3,QUARTZ_BLOCK:0)
Block(-7,47,5,QUARTZ_BLOCK:0)
RandomBlock(-7,47,6,minecraft:iron_bars:0,5,CONCRETE_POWDER:8,10,quark:limestone:1,15,quark:limestone,15,quark:world_stone_pavement:2,15,CONCRETE:8,100)
RandomBlock(-7,48,-3,CONCRETE_POWDER:7,25,CONCRETE:7,100)
RandomBlock(-7,48,-1,CONCRETE_POWDER:7,25,CONCRETE:7,100)
RandomBlock(-7,48,3,CONCRETE_POWDER:7,25,CONCRETE:7,100)
RandomBlock(-7,48,5,CONCRETE_POWDER:7,25,CONCRETE:7,100)
RandomBlock(-7,49,-3,CONCRETE_POWDER:7,25,CONCRETE:7,100)
RandomBlock(-7,49,-2,CONCRETE_POWDER:7,25,CONCRETE:7,100)
RandomBlock(-7,49,-1,CONCRETE_POWDER:7,25,CONCRETE:7,100)
RandomBlock(-7,49,3,CONCRETE_POWDER:7,25,CONCRETE:7,100)
RandomBlock(-7,49,4,CONCRETE_POWDER:7,25,CONCRETE:7,100)
RandomBlock(-7,49,5,CONCRETE_POWDER:7,25,CONCRETE:7,100)
RandomBlock(-7,50,-3,CONCRETE_POWDER:7,25,CONCRETE:7,100)
RandomBlock(-7,50,-2,CONCRETE_POWDER:7,25,CONCRETE:7,100)
RandomBlock(-7,50,-1,CONCRETE_POWDER:7,25,CONCRETE:7,100)
RandomBlock(-7,50,3,CONCRETE_POWDER:7,25,CONCRETE:7,100)
RandomBlock(-7,50,4,CONCRETE_POWDER:7,25,CONCRETE:7,100)
RandomBlock(-7,50,5,CONCRETE_POWDER:7,25,CONCRETE:7,100)
RandomBlock(-6,43,-2,minecraft:iron_bars:0,5,CONCRETE_POWDER:8,10,quark:limestone:1,15,quark:limestone,15,quark:world_stone_pavement:2,15,CONCRETE:8,100)
RandomBlock(-6,43,4,minecraft:iron_bars:0,5,CONCRETE_POWDER:8,10,quark:limestone:1,15,quark:limestone,15,quark:world_stone_pavement:2,15,CONCRETE:8,100)
RandomBlock(-6,44,-2,minecraft:iron_bars:0,5,CONCRETE_POWDER:8,10,quark:limestone:1,15,quark:limestone,15,quark:world_stone_pavement:2,15,CONCRETE:8,100)
RandomBlock(-6,44,4,minecraft:iron_bars:0,5,CONCRETE_POWDER:8,10,quark:limestone:1,15,quark:limestone,15,quark:world_stone_pavement:2,15,CONCRETE:8,100)
RandomBlock(-6,45,-2,minecraft:iron_bars:0,5,CONCRETE_POWDER:8,10,quark:limestone:1,15,quark:limestone,15,quark:world_stone_pavement:2,15,CONCRETE:8,100)
RandomBlock(-6,45,4,minecraft:iron_bars:0,5,CONCRETE_POWDER:8,10,quark:limestone:1,15,quark:limestone,15,quark:world_stone_pavement:2,15,CONCRETE:8,100)
Block(-6,46,-2,QUARTZ_BLOCK:0)
Block(-6,46,4,QUARTZ_BLOCK:0)
RandomBlock(-6,47,-4,minecraft:iron_bars:0,5,CONCRETE_POWDER:8,10,quark:limestone:1,15,quark:limestone,15,quark:world_stone_pavement:2,15,CONCRETE:8,100)
Block(-6,47,-3,QUARTZ_BLOCK:0)
Block(-6,47,-1,QUARTZ_BLOCK:0)
RandomBlock(-6,47,0,minecraft:iron_bars:0,5,CONCRETE_POWDER:8,10,quark:limestone:1,15,quark:limestone,15,quark:world_stone_pavement:2,15,CONCRETE:8,100)
RandomBlock(-6,47,2,minecraft:iron_bars:0,5,CONCRETE_POWDER:8,10,quark:limestone:1,15,quark:limestone,15,quark:world_stone_pavement:2,15,CONCRETE:8,100)
Block(-6,47,3,QUARTZ_BLOCK:0)
Block(-6,47,5,QUARTZ_BLOCK:0)
RandomBlock(-6,47,6,minecraft:iron_bars:0,5,CONCRETE_POWDER:8,10,quark:limestone:1,15,quark:limestone,15,quark:world_stone_pavement:2,15,CONCRETE:8,100)
RandomBlock(-6,48,-4,minecraft:iron_bars:0,5,CONCRETE_POWDER:8,10,quark:limestone:1,15,quark:limestone,15,quark:world_stone_pavement:2,15,CONCRETE:8,100)
Block(-6,48,-3,QUARTZ_BLOCK:0)
Block(-6,48,-1,QUARTZ_BLOCK:0)
RandomBlock(-6,48,0,minecraft:iron_bars:0,5,CONCRETE_POWDER:8,10,quark:limestone:1,15,quark:limestone,15,quark:world_stone_pavement:2,15,CONCRETE:8,100)
RandomBlock(-6,48,2,minecraft:iron_bars:0,5,CONCRETE_POWDER:8,10,quark:limestone:1,15,quark:limestone,15,quark:world_stone_pavement:2,15,CONCRETE:8,100)
Block(-6,48,3,QUARTZ_BLOCK:0)
Block(-6,48,5,QUARTZ_BLOCK:0)
RandomBlock(-6,48,6,minecraft:iron_bars:0,5,CONCRETE_POWDER:8,10,quark:limestone:1,15,quark:limestone,15,quark:world_stone_pavement:2,15,CONCRETE:8,100)
RandomBlock(-6,49,-4,minecraft:iron_bars:0,5,CONCRETE_POWDER:8,10,quark:limestone:1,15,quark:limestone,15,quark:world_stone_pavement:2,15,CONCRETE:8,100)
RandomBlock(-6,49,-3,CONCRETE_POWDER:7,25,CONCRETE:7,100)
RandomBlock(-6,49,-1,CONCRETE_POWDER:7,25,CONCRETE:7,100)
RandomBlock(-6,49,0,minecraft:iron_bars:0,5,CONCRETE_POWDER:8,10,quark:limestone:1,15,quark:limestone,15,quark:world_stone_pavement:2,15,CONCRETE:8,100)
RandomBlock(-6,49,2,minecraft:iron_bars:0,5,CONCRETE_POWDER:8,10,quark:limestone:1,15,quark:limestone,15,quark:world_stone_pavement:2,15,CONCRETE:8,100)
RandomBlock(-6,49,3,CONCRETE_POWDER:7,25,CONCRETE:7,100)
RandomBlock(-6,49,5,CONCRETE_POWDER:7,25,CONCRETE:7,100)
RandomBlock(-6,49,6,minecraft:iron_bars:0,5,CONCRETE_POWDER:8,10,quark:limestone:1,15,quark:limestone,15,quark:world_stone_pavement:2,15,CONCRETE:8,100)
RandomBlock(-6,50,-3,CONCRETE_POWDER:7,25,CONCRETE:7,100)
RandomBlock(-6,50,-1,CONCRETE_POWDER:7,25,CONCRETE:7,100)
RandomBlock(-6,50,3,CONCRETE_POWDER:7,25,CONCRETE:7,100)
RandomBlock(-6,50,5,CONCRETE_POWDER:7,25,CONCRETE:7,100)
RandomBlock(-6,51,-3,CONCRETE_POWDER:7,25,CONCRETE:7,100)
RandomBlock(-6,51,-2,CONCRETE_POWDER:7,25,CONCRETE:7,100)
RandomBlock(-6,51,-1,CONCRETE_POWDER:7,25,CONCRETE:7,100)
RandomBlock(-6,51,3,CONCRETE_POWDER:7,25,CONCRETE:7,100)
RandomBlock(-6,51,4,CONCRETE_POWDER:7,25,CONCRETE:7,100)
RandomBlock(-6,51,5,CONCRETE_POWDER:7,25,CONCRETE:7,100)
RandomBlock(-6,52,-3,CONCRETE_POWDER:7,25,CONCRETE:7,100)
RandomBlock(-6,52,-2,CONCRETE_POWDER:7,25,CONCRETE:7,100)
RandomBlock(-6,52,-1,CONCRETE_POWDER:7,25,CONCRETE:7,100)
RandomBlock(-6,52,3,CONCRETE_POWDER:7,25,CONCRETE:7,100)
RandomBlock(-6,52,4,CONCRETE_POWDER:7,25,CONCRETE:7,100)
RandomBlock(-6,52,5,CONCRETE_POWDER:7,25,CONCRETE:7,100)
Block(-6,53,-7,quark:iron_plate:1)
Block(-6,54,-7,quark:iron_plate:1)
Block(-6,55,-7,quark:iron_plate:1)
Block(-6,56,-7,quark:iron_plate:1)
Block(-6,57,-7,quark:iron_plate:1)
Block(-6,58,-7,quark:iron_plate:1)
Block(-6,59,-7,quark:iron_plate:1)
RandomBlock(-5,43,-2,minecraft:iron_bars:0,5,CONCRETE_POWDER:8,10,quark:limestone:1,15,quark:limestone,15,quark:world_stone_pavement:2,15,CONCRETE:8,100)
RandomBlock(-5,43,4,minecraft:iron_bars:0,5,CONCRETE_POWDER:8,10,quark:limestone:1,15,quark:limestone,15,quark:world_stone_pavement:2,15,CONCRETE:8,100)
RandomBlock(-5,44,-7,minecraft:iron_bars:0,5,STAINED_CLAY:15,5,STAINED_CLAY:7,5,quark:iron_plate_slab:8,15,quark:world_stone_pavement:2,15,STAINED_CLAY:9,100)
RandomBlock(-5,44,-6,minecraft:iron_bars:0,5,STAINED_CLAY:15,5,STAINED_CLAY:7,5,quark:iron_plate_slab:8,15,quark:world_stone_pavement:2,15,STAINED_CLAY:9,100)
RandomBlock(-5,44,-5,minecraft:iron_bars:0,5,STAINED_CLAY:15,5,STAINED_CLAY:7,5,quark:iron_plate_slab:8,15,quark:world_stone_pavement:2,15,STAINED_CLAY:9,100)
RandomBlock(-5,44,-4,minecraft:iron_bars:0,5,STAINED_CLAY:15,5,STAINED_CLAY:7,5,quark:iron_plate_slab:8,15,quark:world_stone_pavement:2,15,STAINED_CLAY:9,100)
RandomBlock(-5,44,-3,minecraft:iron_bars:0,5,STAINED_CLAY:15,5,STAINED_CLAY:7,5,quark:iron_plate_slab:8,15,quark:world_stone_pavement:2,15,STAINED_CLAY:9,100)
RandomBlock(-5,44,-2,minecraft:iron_bars:0,5,STAINED_CLAY:15,5,STAINED_CLAY:7,5,quark:iron_plate_slab:8,15,quark:world_stone_pavement:2,15,STAINED_CLAY:9,100)
RandomBlock(-5,44,-1,minecraft:iron_bars:0,5,STAINED_CLAY:15,5,STAINED_CLAY:7,5,quark:iron_plate_slab:8,15,quark:world_stone_pavement:2,15,STAINED_CLAY:9,100)
RandomBlock(-5,44,0,minecraft:iron_bars:0,5,STAINED_CLAY:15,5,STAINED_CLAY:7,5,quark:iron_plate_slab:8,15,quark:world_stone_pavement:2,15,STAINED_CLAY:9,100)
RandomBlock(-5,44,1,minecraft:iron_bars:0,5,STAINED_CLAY:15,5,STAINED_CLAY:7,5,quark:iron_plate_slab:8,15,quark:world_stone_pavement:2,15,STAINED_CLAY:9,100)
RandomBlock(-5,44,2,minecraft:iron_bars:0,5,STAINED_CLAY:15,5,STAINED_CLAY:7,5,quark:iron_plate_slab:8,15,quark:world_stone_pavement:2,15,STAINED_CLAY:9,100)
RandomBlock(-5,44,3,minecraft:iron_bars:0,5,STAINED_CLAY:15,5,STAINED_CLAY:7,5,quark:iron_plate_slab:8,15,quark:world_stone_pavement:2,15,STAINED_CLAY:9,100)
RandomBlock(-5,44,4,minecraft:iron_bars:0,5,STAINED_CLAY:15,5,STAINED_CLAY:7,5,quark:iron_plate_slab:8,15,quark:world_stone_pavement:2,15,STAINED_CLAY:9,100)
RandomBlock(-5,44,5,minecraft:iron_bars:0,5,STAINED_CLAY:15,5,STAINED_CLAY:7,5,quark:iron_plate_slab:8,15,quark:world_stone_pavement:2,15,STAINED_CLAY:9,100)
RandomBlock(-5,44,6,minecraft:iron_bars:0,5,STAINED_CLAY:15,5,STAINED_CLAY:7,5,quark:iron_plate_slab:8,15,quark:world_stone_pavement:2,15,STAINED_CLAY:9,100)
RandomBlock(-5,44,7,minecraft:iron_bars:0,5,STAINED_CLAY:15,5,STAINED_CLAY:7,5,quark:iron_plate_slab:8,15,quark:world_stone_pavement:2,15,STAINED_CLAY:9,100)
RandomBlock(-5,44,8,minecraft:iron_bars:0,5,STAINED_CLAY:15,5,STAINED_CLAY:7,5,quark:iron_plate_slab:8,15,quark:world_stone_pavement:2,15,STAINED_CLAY:9,100)
RandomBlock(-5,45,-7,minecraft:iron_bars:0,5,CONCRETE_POWDER:8,10,quark:limestone:1,15,quark:limestone,15,quark:world_stone_pavement:2,15,CONCRETE:8,100)
RandomBlock(-5,45,-6,minecraft:iron_bars:0,5,CONCRETE_POWDER:8,10,quark:limestone:1,15,quark:limestone,15,quark:world_stone_pavement:2,15,CONCRETE:8,100)
RandomBlock(-5,45,-5,minecraft:iron_bars:0,5,CONCRETE_POWDER:8,10,quark:limestone:1,15,quark:limestone,15,quark:world_stone_pavement:2,15,CONCRETE:8,100)
Block(-5,45,-4,minecraft:iron_bars:0)
Block(-5,45,-3,minecraft:iron_bars:0)
RandomBlock(-5,45,-2,minecraft:iron_bars:0,5,CONCRETE_POWDER:8,10,quark:limestone:1,15,quark:limestone,15,quark:world_stone_pavement:2,15,CONCRETE:8,100)
Block(-5,45,-1,minecraft:iron_bars:0)
Block(-5,45,0,minecraft:iron_bars:0)
Block(-5,45,1,minecraft:iron_bars:0)
Block(-5,45,2,minecraft:iron_bars:0)
Block(-5,45,3,minecraft:iron_bars:0)
RandomBlock(-5,45,4,minecraft:iron_bars:0,5,CONCRETE_POWDER:8,10,quark:limestone:1,15,quark:limestone,15,quark:world_stone_pavement:2,15,CONCRETE:8,100)
Block(-5,45,5,minecraft:iron_bars:0)
Block(-5,45,6,minecraft:iron_bars:0)
Block(-5,45,7,minecraft:iron_bars:0)
Block(-5,45,8,minecraft:iron_bars:0)
Block(-5,46,-7,STAINED_GLASS_PANE:7)
Block(-5,46,-6,CONCRETE:15)
Block(-5,46,-5,CONCRETE:15)
Block(-5,46,-4,minecraft:iron_bars:0)
Block(-5,46,-3,minecraft:iron_bars:0)
Block(-5,46,-2,minecraft:iron_bars:0)
Block(-5,46,-1,minecraft:iron_bars:0)
Block(-5,46,0,minecraft:iron_bars:0)
Block(-5,46,1,minecraft:iron_bars:0)
Block(-5,46,2,minecraft:iron_bars:0)
Block(-5,46,3,minecraft:iron_bars:0)
Block(-5,46,4,minecraft:iron_bars:0)
Block(-5,46,5,minecraft:iron_bars:0)
Block(-5,46,6,minecraft:iron_bars:0)
Block(-5,46,7,minecraft:iron_bars:0)
Block(-5,46,8,minecraft:iron_bars:0)
RandomBlock(-5,47,-7,minecraft:iron_bars:0,5,CONCRETE_POWDER:8,10,quark:limestone:1,15,quark:limestone,15,quark:world_stone_pavement:2,15,CONCRETE:8,100)
RandomBlock(-5,47,-6,minecraft:iron_bars:0,5,CONCRETE_POWDER:8,10,quark:limestone:1,15,quark:limestone,15,quark:world_stone_pavement:2,15,CONCRETE:8,100)
RandomBlock(-5,47,-5,minecraft:iron_bars:0,5,CONCRETE_POWDER:8,10,quark:limestone:1,15,quark:limestone,15,quark:world_stone_pavement:2,15,CONCRETE:8,100)
RandomBlock(-5,47,-4,minecraft:iron_bars:0,5,CONCRETE_POWDER:8,10,quark:limestone:1,15,quark:limestone,15,quark:world_stone_pavement:2,15,CONCRETE:8,100)
Block(-5,47,-2,QUARTZ_BLOCK:0)
RandomBlock(-5,47,0,minecraft:iron_bars:0,5,CONCRETE_POWDER:8,10,quark:limestone:1,15,quark:limestone,15,quark:world_stone_pavement:2,15,CONCRETE:8,100)
RandomBlock(-5,47,2,minecraft:iron_bars:0,5,CONCRETE_POWDER:8,10,quark:limestone:1,15,quark:limestone,15,quark:world_stone_pavement:2,15,CONCRETE:8,100)
Block(-5,47,4,QUARTZ_BLOCK:0)
RandomBlock(-5,47,6,minecraft:iron_bars:0,5,CONCRETE_POWDER:8,10,quark:limestone:1,15,quark:limestone,15,quark:world_stone_pavement:2,15,CONCRETE:8,100)
RandomBlock(-5,48,-7,minecraft:iron_bars:0,5,CONCRETE_POWDER:8,10,quark:limestone:1,15,quark:limestone,15,quark:world_stone_pavement:2,15,CONCRETE:8,100)
RandomBlock(-5,48,-6,minecraft:iron_bars:0,5,CONCRETE_POWDER:8,10,quark:limestone:1,15,quark:limestone,15,quark:world_stone_pavement:2,15,CONCRETE:8,100)
RandomBlock(-5,48,-5,minecraft:iron_bars:0,5,CONCRETE_POWDER:8,10,quark:limestone:1,15,quark:limestone,15,quark:world_stone_pavement:2,15,CONCRETE:8,100)
RandomBlock(-5,48,-4,minecraft:iron_bars:0,5,CONCRETE_POWDER:8,10,quark:limestone:1,15,quark:limestone,15,quark:world_stone_pavement:2,15,CONCRETE:8,100)
Block(-5,48,-2,QUARTZ_BLOCK:0)
RandomBlock(-5,48,0,minecraft:iron_bars:0,5,CONCRETE_POWDER:8,10,quark:limestone:1,15,quark:limestone,15,quark:world_stone_pavement:2,15,CONCRETE:8,100)
RandomBlock(-5,48,2,minecraft:iron_bars:0,5,CONCRETE_POWDER:8,10,quark:limestone:1,15,quark:limestone,15,quark:world_stone_pavement:2,15,CONCRETE:8,100)
Block(-5,48,4,QUARTZ_BLOCK:0)
RandomBlock(-5,48,6,minecraft:iron_bars:0,5,CONCRETE_POWDER:8,10,quark:limestone:1,15,quark:limestone,15,quark:world_stone_pavement:2,15,CONCRETE:8,100)
RandomBlock(-5,49,-7,minecraft:iron_bars:0,5,CONCRETE_POWDER:8,10,quark:limestone:1,15,quark:limestone,15,quark:world_stone_pavement:2,15,CONCRETE:8,100)
RandomBlock(-5,49,-6,minecraft:iron_bars:0,5,CONCRETE_POWDER:8,10,quark:limestone:1,15,quark:limestone,15,quark:world_stone_pavement:2,15,CONCRETE:8,100)
RandomBlock(-5,49,-5,minecraft:iron_bars:0,5,CONCRETE_POWDER:8,10,quark:limestone:1,15,quark:limestone,15,quark:world_stone_pavement:2,15,CONCRETE:8,100)
Block(-5,49,-3,QUARTZ_BLOCK:0)
Block(-5,49,-1,QUARTZ_BLOCK:0)
Block(-5,49,3,QUARTZ_BLOCK:0)
Block(-5,49,5,QUARTZ_BLOCK:0)
RandomBlock(-5,50,-7,minecraft:iron_bars:0,5,CONCRETE_POWDER:8,10,quark:limestone:1,15,quark:limestone,15,quark:world_stone_pavement:2,15,CONCRETE:8,100)
RandomBlock(-5,50,-6,minecraft:iron_bars:0,5,CONCRETE_POWDER:8,10,quark:limestone:1,15,quark:limestone,15,quark:world_stone_pavement:2,15,CONCRETE:8,100)
RandomBlock(-5,50,-5,minecraft:iron_bars:0,5,CONCRETE_POWDER:8,10,quark:limestone:1,15,quark:limestone,15,quark:world_stone_pavement:2,15,CONCRETE:8,100)
RandomBlock(-5,50,-4,minecraft:iron_bars:0,5,CONCRETE_POWDER:8,10,quark:limestone:1,15,quark:limestone,15,quark:world_stone_pavement:2,15,CONCRETE:8,100)
Block(-5,50,-3,QUARTZ_BLOCK:0)
Block(-5,50,-1,QUARTZ_BLOCK:0)
RandomBlock(-5,50,0,minecraft:iron_bars:0,5,CONCRETE_POWDER:8,10,quark:limestone:1,15,quark:limestone,15,quark:world_stone_pavement:2,15,CONCRETE:8,100)
RandomBlock(-5,50,2,minecraft:iron_bars:0,5,CONCRETE_POWDER:8,10,quark:limestone:1,15,quark:limestone,15,quark:world_stone_pavement:2,15,CONCRETE:8,100)
Block(-5,50,3,QUARTZ_BLOCK:0)
Block(-5,50,5,QUARTZ_BLOCK:0)
RandomBlock(-5,50,6,minecraft:iron_bars:0,5,CONCRETE_POWDER:8,10,quark:limestone:1,15,quark:limestone,15,quark:world_stone_pavement:2,15,CONCRETE:8,100)
Block(-5,51,-7,minecraft:iron_bars:0)
Block(-5,51,-6,minecraft:iron_bars:0)
RandomBlock(-5,51,-5,minecraft:iron_bars:0,5,CONCRETE_POWDER:8,10,quark:limestone:1,15,quark:limestone,15,quark:world_stone_pavement:2,15,CONCRETE:8,100)
RandomBlock(-5,51,-4,minecraft:iron_bars:0,5,CONCRETE_POWDER:8,10,quark:limestone:1,15,quark:limestone,15,quark:world_stone_pavement:2,15,CONCRETE:8,100)
RandomBlock(-5,51,-3,CONCRETE_POWDER:7,25,CONCRETE:7,100)
RandomBlock(-5,51,-1,CONCRETE_POWDER:7,25,CONCRETE:7,100)
RandomBlock(-5,51,0,minecraft:iron_bars:0,5,CONCRETE_POWDER:8,10,quark:limestone:1,15,quark:limestone,15,quark:world_stone_pavement:2,15,CONCRETE:8,100)
RandomBlock(-5,51,2,minecraft:iron_bars:0,5,CONCRETE_POWDER:8,10,quark:limestone:1,15,quark:limestone,15,quark:world_stone_pavement:2,15,CONCRETE:8,100)
RandomBlock(-5,51,3,CONCRETE_POWDER:7,25,CONCRETE:7,100)
RandomBlock(-5,51,5,CONCRETE_POWDER:7,25,CONCRETE:7,100)
RandomBlock(-5,51,6,minecraft:iron_bars:0,5,CONCRETE_POWDER:8,10,quark:limestone:1,15,quark:limestone,15,quark:world_stone_pavement:2,15,CONCRETE:8,100)
Block(-5,52,-7,minecraft:iron_bars:0)
Block(-5,52,-6,minecraft:iron_bars:0)
Block(-5,52,-5,CONCRETE:15)
RandomBlock(-5,52,-3,CONCRETE_POWDER:7,25,CONCRETE:7,100)
RandomBlock(-5,52,-1,CONCRETE_POWDER:7,25,CONCRETE:7,100)
RandomBlock(-5,52,3,CONCRETE_POWDER:7,25,CONCRETE:7,100)
RandomBlock(-5,52,5,CONCRETE_POWDER:7,25,CONCRETE:7,100)
Block(-5,53,-7,quark:iron_plate:1)
RandomBlock(-5,53,-5,minecraft:iron_bars:0,5,CONCRETE_POWDER:8,10,quark:limestone:1,15,quark:limestone,15,quark:world_stone_pavement:2,15,CONCRETE:8,100)
RandomBlock(-5,53,-3,CONCRETE_POWDER:7,25,CONCRETE:7,100)
RandomBlock(-5,53,-2,CONCRETE_POWDER:7,25,CONCRETE:7,100)
RandomBlock(-5,53,-1,CONCRETE_POWDER:7,25,CONCRETE:7,100)
RandomBlock(-5,53,3,CONCRETE_POWDER:7,25,CONCRETE:7,100)
RandomBlock(-5,53,4,CONCRETE_POWDER:7,25,CONCRETE:7,100)
RandomBlock(-5,53,5,CONCRETE_POWDER:7,25,CONCRETE:7,100)
RandomBlock(-5,54,-7,minecraft:iron_bars:0,5,CONCRETE_POWDER:8,10,quark:limestone:1,15,quark:limestone,15,quark:world_stone_pavement:2,15,CONCRETE:8,100)
RandomBlock(-5,54,-6,minecraft:iron_bars:0,5,CONCRETE_POWDER:8,10,quark:limestone:1,15,quark:limestone,15,quark:world_stone_pavement:2,15,CONCRETE:8,100)
RandomBlock(-5,54,-5,minecraft:iron_bars:0,5,CONCRETE_POWDER:8,10,quark:limestone:1,15,quark:limestone,15,quark:world_stone_pavement:2,15,CONCRETE:8,100)
RandomBlock(-5,55,-7,minecraft:iron_bars:0,5,CONCRETE_POWDER:8,10,quark:limestone:1,15,quark:limestone,15,quark:world_stone_pavement:2,15,CONCRETE:8,100)
RandomBlock(-5,55,-6,minecraft:iron_bars:0,5,CONCRETE_POWDER:8,10,quark:limestone:1,15,quark:limestone,15,quark:world_stone_pavement:2,15,CONCRETE:8,100)
RandomBlock(-5,55,-5,minecraft:iron_bars:0,5,CONCRETE_POWDER:8,10,quark:limestone:1,15,quark:limestone,15,quark:world_stone_pavement:2,15,CONCRETE:8,100)
RandomBlock(-5,56,-7,minecraft:iron_bars:0,5,CONCRETE_POWDER:8,10,quark:limestone:1,15,quark:limestone,15,quark:world_stone_pavement:2,15,CONCRETE:8,100)
RandomBlock(-5,56,-6,minecraft:iron_bars:0,5,CONCRETE_POWDER:8,10,quark:limestone:1,15,quark:limestone,15,quark:world_stone_pavement:2,15,CONCRETE:8,100)
RandomBlock(-5,56,-5,minecraft:iron_bars:0,5,CONCRETE_POWDER:8,10,quark:limestone:1,15,quark:limestone,15,quark:world_stone_pavement:2,15,CONCRETE:8,100)
RandomBlock(-5,57,-7,minecraft:iron_bars:0,5,CONCRETE_POWDER:8,10,quark:limestone:1,15,quark:limestone,15,quark:world_stone_pavement:2,15,CONCRETE:8,100)
RandomBlock(-5,57,-6,minecraft:iron_bars:0,5,CONCRETE_POWDER:8,10,quark:limestone:1,15,quark:limestone,15,quark:world_stone_pavement:2,15,CONCRETE:8,100)
RandomBlock(-5,57,-5,minecraft:iron_bars:0,5,CONCRETE_POWDER:8,10,quark:limestone:1,15,quark:limestone,15,quark:world_stone_pavement:2,15,CONCRETE:8,100)
RandomBlock(-5,58,-6,minecraft:iron_bars:0,5,CONCRETE_POWDER:8,10,quark:limestone:1,15,quark:limestone,15,quark:world_stone_pavement:2,15,CONCRETE:8,100)
RandomBlock(-5,58,-5,minecraft:iron_bars:0,5,CONCRETE_POWDER:8,10,quark:limestone:1,15,quark:limestone,15,quark:world_stone_pavement:2,15,CONCRETE:8,100)
Block(-5,59,-7,quark:iron_plate:1)
Block(-5,59,-6,IRON_FENCE:0)
Block(-5,59,-5,IRON_FENCE:0)
RandomBlock(-4,43,-2,minecraft:iron_bars:0,5,CONCRETE_POWDER:8,10,quark:limestone:1,15,quark:limestone,15,quark:world_stone_pavement:2,15,CONCRETE:8,100)
RandomBlock(-4,43,4,minecraft:iron_bars:0,5,CONCRETE_POWDER:8,10,quark:limestone:1,15,quark:limestone,15,quark:world_stone_pavement:2,15,CONCRETE:8,100)
RandomBlock(-4,44,-7,minecraft:iron_bars:0,5,STAINED_CLAY:15,5,STAINED_CLAY:7,5,quark:iron_plate_slab:8,15,quark:world_stone_pavement:2,15,STAINED_CLAY:9,100)
RandomBlock(-4,44,-6,minecraft:iron_bars:0,5,STAINED_CLAY:15,5,STAINED_CLAY:7,5,quark:iron_plate_slab:8,15,quark:world_stone_pavement:2,15,STAINED_CLAY:9,100)
RandomBlock(-4,44,-5,minecraft:iron_bars:0,5,STAINED_CLAY:15,5,STAINED_CLAY:7,5,quark:iron_plate_slab:8,15,quark:world_stone_pavement:2,15,STAINED_CLAY:9,100)
RandomBlock(-4,44,-4,minecraft:iron_bars:0,5,STAINED_CLAY:15,5,STAINED_CLAY:7,5,quark:iron_plate_slab:8,15,quark:world_stone_pavement:2,15,STAINED_CLAY:9,100)
RandomBlock(-4,44,-3,minecraft:iron_bars:0,5,STAINED_CLAY:15,5,STAINED_CLAY:7,5,quark:iron_plate_slab:8,15,quark:world_stone_pavement:2,15,STAINED_CLAY:9,100)
RandomBlock(-4,44,-2,minecraft:iron_bars:0,5,CONCRETE_POWDER:8,10,quark:limestone:1,15,quark:limestone,15,quark:world_stone_pavement:2,15,CONCRETE:8,100)
RandomBlock(-4,44,-1,minecraft:iron_bars:0,5,STAINED_CLAY:15,5,STAINED_CLAY:7,5,quark:iron_plate_slab:8,15,quark:world_stone_pavement:2,15,STAINED_CLAY:9,100)
RandomBlock(-4,44,0,minecraft:iron_bars:0,5,STAINED_CLAY:15,5,STAINED_CLAY:7,5,quark:iron_plate_slab:8,15,quark:world_stone_pavement:2,15,STAINED_CLAY:9,100)
RandomBlock(-4,44,1,minecraft:iron_bars:0,5,STAINED_CLAY:15,5,STAINED_CLAY:7,5,quark:iron_plate_slab:8,15,quark:world_stone_pavement:2,15,STAINED_CLAY:9,100)
RandomBlock(-4,44,2,minecraft:iron_bars:0,5,STAINED_CLAY:15,5,STAINED_CLAY:7,5,quark:iron_plate_slab:8,15,quark:world_stone_pavement:2,15,STAINED_CLAY:9,100)
RandomBlock(-4,44,3,minecraft:iron_bars:0,5,STAINED_CLAY:15,5,STAINED_CLAY:7,5,quark:iron_plate_slab:8,15,quark:world_stone_pavement:2,15,STAINED_CLAY:9,100)
RandomBlock(-4,44,4,minecraft:iron_bars:0,5,CONCRETE_POWDER:8,10,quark:limestone:1,15,quark:limestone,15,quark:world_stone_pavement:2,15,CONCRETE:8,100)
RandomBlock(-4,44,5,minecraft:iron_bars:0,5,STAINED_CLAY:15,5,STAINED_CLAY:7,5,quark:iron_plate_slab:8,15,quark:world_stone_pavement:2,15,STAINED_CLAY:9,100)
RandomBlock(-4,44,6,minecraft:iron_bars:0,5,STAINED_CLAY:15,5,STAINED_CLAY:7,5,quark:iron_plate_slab:8,15,quark:world_stone_pavement:2,15,STAINED_CLAY:9,100)
RandomBlock(-4,44,7,minecraft:iron_bars:0,5,STAINED_CLAY:15,5,STAINED_CLAY:7,5,quark:iron_plate_slab:8,15,quark:world_stone_pavement:2,15,STAINED_CLAY:9,100)
RandomBlock(-4,44,8,minecraft:iron_bars:0,5,STAINED_CLAY:15,5,STAINED_CLAY:7,5,quark:iron_plate_slab:8,15,quark:world_stone_pavement:2,15,STAINED_CLAY:9,100)
RandomBlock(-4,45,-5,minecraft:iron_bars:0,5,CONCRETE_POWDER:8,10,quark:limestone:1,15,quark:limestone,15,quark:world_stone_pavement:2,15,CONCRETE:8,100)
Block(-4,45,-3,SMOOTH_STAIRS:2)
RandomBlock(-4,45,-2,minecraft:iron_bars:0,5,CONCRETE_POWDER:8,10,quark:limestone:1,15,quark:limestone,15,quark:world_stone_pavement:2,15,CONCRETE:8,100)
Block(-4,45,-1,SMOOTH_STAIRS:3)
Block(-4,45,3,SMOOTH_STAIRS:2)
RandomBlock(-4,45,4,minecraft:iron_bars:0,5,CONCRETE_POWDER:8,10,quark:limestone:1,15,quark:limestone,15,quark:world_stone_pavement:2,15,CONCRETE:8,100)
Block(-4,45,5,SMOOTH_STAIRS:3)
Block(-4,46,-6,quark:iron_button)
Block(-4,46,-5,CONCRETE:15)
Block(-4,46,-4,quark:iron_button:3)
RandomBlock(-4,47,-5,minecraft:iron_bars:0,5,CONCRETE_POWDER:8,10,quark:limestone:1,15,quark:limestone,15,quark:world_stone_pavement:2,15,CONCRETE:8,100)
RandomBlock(-4,48,-5,minecraft:iron_bars:0,5,CONCRETE_POWDER:8,10,quark:limestone:1,15,quark:limestone,15,quark:world_stone_pavement:2,15,CONCRETE:8,100)
RandomBlock(-4,48,-4,minecraft:iron_bars:0,5,CONCRETE_POWDER:8,10,quark:limestone:1,15,quark:limestone,15,quark:world_stone_pavement:2,15,CONCRETE:8,100)
RandomBlock(-4,48,0,minecraft:iron_bars:0,5,CONCRETE_POWDER:8,10,quark:limestone:1,15,quark:limestone,15,quark:world_stone_pavement:2,15,CONCRETE:8,100)
RandomBlock(-4,48,2,minecraft:iron_bars:0,5,CONCRETE_POWDER:8,10,quark:limestone:1,15,quark:limestone,15,quark:world_stone_pavement:2,15,CONCRETE:8,100)
RandomBlock(-4,48,6,minecraft:iron_bars:0,5,CONCRETE_POWDER:8,10,quark:limestone:1,15,quark:limestone,15,quark:world_stone_pavement:2,15,CONCRETE:8,100)
RandomBlock(-4,49,-5,minecraft:iron_bars:0,5,CONCRETE_POWDER:8,10,quark:limestone:1,15,quark:limestone,15,quark:world_stone_pavement:2,15,CONCRETE:8,100)
RandomBlock(-4,49,-4,minecraft:iron_bars:0,5,CONCRETE_POWDER:8,10,quark:limestone:1,15,quark:limestone,15,quark:world_stone_pavement:2,15,CONCRETE:8,100)
Block(-4,49,-2,QUARTZ_BLOCK:0)
RandomBlock(-4,49,0,minecraft:iron_bars:0,5,CONCRETE_POWDER:8,10,quark:limestone:1,15,quark:limestone,15,quark:world_stone_pavement:2,15,CONCRETE:8,100)
RandomBlock(-4,49,2,minecraft:iron_bars:0,5,CONCRETE_POWDER:8,10,quark:limestone:1,15,quark:limestone,15,quark:world_stone_pavement:2,15,CONCRETE:8,100)
Block(-4,49,4,QUARTZ_BLOCK:0)
RandomBlock(-4,49,6,minecraft:iron_bars:0,5,CONCRETE_POWDER:8,10,quark:limestone:1,15,quark:limestone,15,quark:world_stone_pavement:2,15,CONCRETE:8,100)
RandomBlock(-4,50,-7,minecraft:iron_bars:0,5,STAINED_CLAY:15,5,STAINED_CLAY:7,5,quark:iron_plate_slab:8,15,quark:world_stone_pavement:2,15,STAINED_CLAY:9,100)
RandomBlock(-4,50,-6,minecraft:iron_bars:0,5,STAINED_CLAY:15,5,STAINED_CLAY:7,5,quark:iron_plate_slab:8,15,quark:world_stone_pavement:2,15,STAINED_CLAY:9,100)
RandomBlock(-4,50,-5,minecraft:iron_bars:0,5,CONCRETE_POWDER:8,10,quark:limestone:1,15,quark:limestone,15,quark:world_stone_pavement:2,15,CONCRETE:8,100)
Block(-4,50,-2,QUARTZ_BLOCK:0)
Block(-4,50,4,QUARTZ_BLOCK:0)
RandomBlock(-4,51,-5,minecraft:iron_bars:0,5,CONCRETE_POWDER:8,10,quark:limestone:1,15,quark:limestone,15,quark:world_stone_pavement:2,15,CONCRETE:8,100)
Block(-4,51,-3,QUARTZ_BLOCK:0)
Block(-4,51,-1,QUARTZ_BLOCK:0)
Block(-4,51,3,QUARTZ_BLOCK:0)
Block(-4,51,5,QUARTZ_BLOCK:0)
Block(-4,52,-5,CONCRETE:15)
RandomBlock(-4,52,-4,minecraft:iron_bars:0,5,CONCRETE_POWDER:8,10,quark:limestone:1,15,quark:limestone,15,quark:world_stone_pavement:2,15,CONCRETE:8,100)
Block(-4,52,-3,QUARTZ_BLOCK:0)
Block(-4,52,-1,QUARTZ_BLOCK:0)
RandomBlock(-4,52,0,minecraft:iron_bars:0,5,CONCRETE_POWDER:8,10,quark:limestone:1,15,quark:limestone,15,quark:world_stone_pavement:2,15,CONCRETE:8,100)
RandomBlock(-4,52,2,minecraft:iron_bars:0,5,CONCRETE_POWDER:8,10,quark:limestone:1,15,quark:limestone,15,quark:world_stone_pavement:2,15,CONCRETE:8,100)
Block(-4,52,3,QUARTZ_BLOCK:0)
Block(-4,52,5,QUARTZ_BLOCK:0)
RandomBlock(-4,52,6,minecraft:iron_bars:0,5,CONCRETE_POWDER:8,10,quark:limestone:1,15,quark:limestone,15,quark:world_stone_pavement:2,15,CONCRETE:8,100)
Block(-4,53,-7,quark:iron_plate:1)
RandomBlock(-4,53,-5,minecraft:iron_bars:0,5,CONCRETE_POWDER:8,10,quark:limestone:1,15,quark:limestone,15,quark:world_stone_pavement:2,15,CONCRETE:8,100)
RandomBlock(-4,53,-4,minecraft:iron_bars:0,5,CONCRETE_POWDER:8,10,quark:limestone:1,15,quark:limestone,15,quark:world_stone_pavement:2,15,CONCRETE:8,100)
RandomBlock(-4,53,-3,CONCRETE_POWDER:7,25,CONCRETE:7,100)
RandomBlock(-4,53,-1,CONCRETE_POWDER:7,25,CONCRETE:7,100)
RandomBlock(-4,53,0,minecraft:iron_bars:0,5,CONCRETE_POWDER:8,10,quark:limestone:1,15,quark:limestone,15,quark:world_stone_pavement:2,15,CONCRETE:8,100)
RandomBlock(-4,53,2,minecraft:iron_bars:0,5,CONCRETE_POWDER:8,10,quark:limestone:1,15,quark:limestone,15,quark:world_stone_pavement:2,15,CONCRETE:8,100)
RandomBlock(-4,53,3,CONCRETE_POWDER:7,25,CONCRETE:7,100)
RandomBlock(-4,53,4,CONCRETE_POWDER:7,25,CONCRETE:7,100)
RandomBlock(-4,53,5,CONCRETE_POWDER:7,25,CONCRETE:7,100)
RandomBlock(-4,53,6,minecraft:iron_bars:0,5,CONCRETE_POWDER:8,10,quark:limestone:1,15,quark:limestone,15,quark:world_stone_pavement:2,15,CONCRETE:8,100)
RandomBlock(-4,54,-7,minecraft:iron_bars:0,5,CONCRETE_POWDER:8,10,quark:limestone:1,15,quark:limestone,15,quark:world_stone_pavement:2,15,CONCRETE:8,100)
RandomBlock(-4,54,-6,minecraft:iron_bars:0,5,CONCRETE_POWDER:8,10,quark:limestone:1,15,quark:limestone,15,quark:world_stone_pavement:2,15,CONCRETE:8,100)
RandomBlock(-4,54,-5,minecraft:iron_bars:0,5,CONCRETE_POWDER:8,10,quark:limestone:1,15,quark:limestone,15,quark:world_stone_pavement:2,15,CONCRETE:8,100)
RandomBlock(-4,54,-3,CONCRETE_POWDER:7,25,CONCRETE:7,100)
RandomBlock(-4,54,-2,CONCRETE_POWDER:7,25,CONCRETE:7,100)
RandomBlock(-4,54,-1,CONCRETE_POWDER:7,25,CONCRETE:7,100)
Block(-4,54,0,IRON_FENCE:0)
RandomBlock(-4,54,3,CONCRETE_POWDER:7,25,CONCRETE:7,100)
RandomBlock(-4,54,4,CONCRETE_POWDER:7,25,CONCRETE:7,100)
RandomBlock(-4,54,5,CONCRETE_POWDER:7,25,CONCRETE:7,100)
Block(-4,54,6,IRON_FENCE:0)
Block(-4,55,-7,MOB_SPAWNER:0,../../ruins_spawners/industrial_multi.nbt)
Block(-4,55,-6,WORKBENCH:0)
RandomBlock(-4,55,-5,minecraft:iron_bars:0,5,CONCRETE_POWDER:8,10,quark:limestone:1,15,quark:limestone,15,quark:world_stone_pavement:2,15,CONCRETE:8,100)
RandomBlock(-4,56,-6,minecraft:planks:5,5,minecraft:planks:5,10,minecraft:planks:5,100)
RandomBlock(-4,56,-5,minecraft:iron_bars:0,5,CONCRETE_POWDER:8,10,quark:limestone:1,15,quark:limestone,15,quark:world_stone_pavement:2,15,CONCRETE:8,100)
RandomBlock(-4,57,-6,minecraft:planks:5,5,minecraft:planks:5,10,minecraft:planks:5,100)
RandomBlock(-4,57,-5,minecraft:iron_bars:0,5,CONCRETE_POWDER:8,10,quark:limestone:1,15,quark:limestone,15,quark:world_stone_pavement:2,15,CONCRETE:8,100)
Block(-4,58,-7,STEP:5)
Block(-4,58,-6,STEP:5)
RandomBlock(-4,58,-5,minecraft:iron_bars:0,5,CONCRETE_POWDER:8,10,quark:limestone:1,15,quark:limestone,15,quark:world_stone_pavement:2,15,CONCRETE:8,100)
Block(-4,59,-7,quark:iron_plate:1)
Block(-4,59,-5,IRON_FENCE:0)
RandomBlock(-3,43,-2,minecraft:iron_bars:0,5,CONCRETE_POWDER:8,10,quark:limestone:1,15,quark:limestone,15,quark:world_stone_pavement:2,15,CONCRETE:8,100)
RandomBlock(-3,43,4,minecraft:iron_bars:0,5,CONCRETE_POWDER:8,10,quark:limestone:1,15,quark:limestone,15,quark:world_stone_pavement:2,15,CONCRETE:8,100)
RandomBlock(-3,44,-7,minecraft:iron_bars:0,5,STAINED_CLAY:15,5,STAINED_CLAY:7,5,quark:iron_plate_slab:8,15,quark:world_stone_pavement:2,15,STAINED_CLAY:9,100)
RandomBlock(-3,44,-6,minecraft:iron_bars:0,5,STAINED_CLAY:15,5,STAINED_CLAY:7,5,quark:iron_plate_slab:8,15,quark:world_stone_pavement:2,15,STAINED_CLAY:9,100)
RandomBlock(-3,44,-5,minecraft:iron_bars:0,5,STAINED_CLAY:15,5,STAINED_CLAY:7,5,quark:iron_plate_slab:8,15,quark:world_stone_pavement:2,15,STAINED_CLAY:9,100)
RandomBlock(-3,44,-4,minecraft:iron_bars:0,5,STAINED_CLAY:15,5,STAINED_CLAY:7,5,quark:iron_plate_slab:8,15,quark:world_stone_pavement:2,15,STAINED_CLAY:9,100)
RandomBlock(-3,44,-3,minecraft:iron_bars:0,5,STAINED_CLAY:15,5,STAINED_CLAY:7,5,quark:iron_plate_slab:8,15,quark:world_stone_pavement:2,15,STAINED_CLAY:9,100)
RandomBlock(-3,44,-2,minecraft:iron_bars:0,5,CONCRETE_POWDER:8,10,quark:limestone:1,15,quark:limestone,15,quark:world_stone_pavement:2,15,CONCRETE:8,100)
RandomBlock(-3,44,-1,minecraft:iron_bars:0,5,STAINED_CLAY:15,5,STAINED_CLAY:7,5,quark:iron_plate_slab:8,15,quark:world_stone_pavement:2,15,STAINED_CLAY:9,100)
RandomBlock(-3,44,0,minecraft:iron_bars:0,5,STAINED_CLAY:15,5,STAINED_CLAY:7,5,quark:iron_plate_slab:8,15,quark:world_stone_pavement:2,15,STAINED_CLAY:9,100)
RandomBlock(-3,44,1,minecraft:iron_bars:0,5,STAINED_CLAY:15,5,STAINED_CLAY:7,5,quark:iron_plate_slab:8,15,quark:world_stone_pavement:2,15,STAINED_CLAY:9,100)
RandomBlock(-3,44,2,minecraft:iron_bars:0,5,STAINED_CLAY:15,5,STAINED_CLAY:7,5,quark:iron_plate_slab:8,15,quark:world_stone_pavement:2,15,STAINED_CLAY:9,100)
RandomBlock(-3,44,3,minecraft:iron_bars:0,5,STAINED_CLAY:15,5,STAINED_CLAY:7,5,quark:iron_plate_slab:8,15,quark:world_stone_pavement:2,15,STAINED_CLAY:9,100)
RandomBlock(-3,44,4,minecraft:iron_bars:0,5,CONCRETE_POWDER:8,10,quark:limestone:1,15,quark:limestone,15,quark:world_stone_pavement:2,15,CONCRETE:8,100)
RandomBlock(-3,44,5,minecraft:iron_bars:0,5,STAINED_CLAY:15,5,STAINED_CLAY:7,5,quark:iron_plate_slab:8,15,quark:world_stone_pavement:2,15,STAINED_CLAY:9,100)
RandomBlock(-3,44,6,minecraft:iron_bars:0,5,STAINED_CLAY:15,5,STAINED_CLAY:7,5,quark:iron_plate_slab:8,15,quark:world_stone_pavement:2,15,STAINED_CLAY:9,100)
RandomBlock(-3,44,7,minecraft:iron_bars:0,5,STAINED_CLAY:15,5,STAINED_CLAY:7,5,quark:iron_plate_slab:8,15,quark:world_stone_pavement:2,15,STAINED_CLAY:9,100)
RandomBlock(-3,44,8,minecraft:iron_bars:0,5,STAINED_CLAY:15,5,STAINED_CLAY:7,5,quark:iron_plate_slab:8,15,quark:world_stone_pavement:2,15,STAINED_CLAY:9,100)
Block(-3,45,-5,IRON_DOOR_BLOCK:1)
RandomBlock(-3,45,-3,minecraft:iron_bars:0,5,CONCRETE_POWDER:8,10,quark:limestone:1,15,quark:limestone,15,quark:world_stone_pavement:2,15,CONCRETE:8,100)
RandomBlock(-3,45,-2,minecraft:iron_bars:0,5,CONCRETE_POWDER:8,10,quark:limestone:1,15,quark:limestone,15,quark:world_stone_pavement:2,15,CONCRETE:8,100)
RandomBlock(-3,45,-1,minecraft:iron_bars:0,5,CONCRETE_POWDER:8,10,quark:limestone:1,15,quark:limestone,15,quark:world_stone_pavement:2,15,CONCRETE:8,100)
RandomBlock(-3,45,1,CHEST:4,../../../../Chests/Loot/moderncity_junk_loot.nbt,20,CHEST:4,../../../../Chests/Loot/moderncity_rare_loot.nbt,10,CHEST:4,../../../../Chests/RLCraft/Ruins/industrial.nbt,50,CHEST:4,../../../../Chests/RLCraft/Ruins/rubble.nbt,100)
RandomBlock(-3,45,3,minecraft:iron_bars:0,5,CONCRETE_POWDER:8,10,quark:limestone:1,15,quark:limestone,15,quark:world_stone_pavement:2,15,CONCRETE:8,100)
RandomBlock(-3,45,4,minecraft:iron_bars:0,5,CONCRETE_POWDER:8,10,quark:limestone:1,15,quark:limestone,15,quark:world_stone_pavement:2,15,CONCRETE:8,100)
RandomBlock(-3,45,5,minecraft:iron_bars:0,5,CONCRETE_POWDER:8,10,quark:limestone:1,15,quark:limestone,15,quark:world_stone_pavement:2,15,CONCRETE:8,100)
Block(-3,46,-5,IRON_DOOR_BLOCK:9)
RandomBlock(-3,47,-5,minecraft:iron_bars:0,5,CONCRETE_POWDER:8,10,quark:limestone:1,15,quark:limestone,15,quark:world_stone_pavement:2,15,CONCRETE:8,100)
RandomBlock(-3,47,-3,minecraft:iron_bars:0,5,CONCRETE_POWDER:8,10,quark:limestone:1,15,quark:limestone,15,quark:world_stone_pavement:2,15,CONCRETE:8,100)
RandomBlock(-3,47,-1,minecraft:iron_bars:0,5,CONCRETE_POWDER:8,10,quark:limestone:1,15,quark:limestone,15,quark:world_stone_pavement:2,15,CONCRETE:8,100)
RandomBlock(-3,47,3,minecraft:iron_bars:0,5,CONCRETE_POWDER:8,10,quark:limestone:1,15,quark:limestone,15,quark:world_stone_pavement:2,15,CONCRETE:8,100)
RandomBlock(-3,47,5,minecraft:iron_bars:0,5,CONCRETE_POWDER:8,10,quark:limestone:1,15,quark:limestone,15,quark:world_stone_pavement:2,15,CONCRETE:8,100)
RandomBlock(-3,48,-5,minecraft:iron_bars:0,5,CONCRETE_POWDER:8,10,quark:limestone:1,15,quark:limestone,15,quark:world_stone_pavement:2,15,CONCRETE:8,100)
RandomBlock(-3,48,-4,minecraft:iron_bars:0,5,CONCRETE_POWDER:8,10,quark:limestone:1,15,quark:limestone,15,quark:world_stone_pavement:2,15,CONCRETE:8,100)
RandomBlock(-3,48,-3,minecraft:iron_bars:0,5,CONCRETE_POWDER:8,10,quark:limestone:1,15,quark:limestone,15,quark:world_stone_pavement:2,15,CONCRETE:8,100)
RandomBlock(-3,48,-2,minecraft:iron_bars:0,5,CONCRETE_POWDER:8,10,quark:limestone:1,15,quark:limestone,15,quark:world_stone_pavement:2,15,CONCRETE:8,100)
RandomBlock(-3,48,-1,minecraft:iron_bars:0,5,CONCRETE_POWDER:8,10,quark:limestone:1,15,quark:limestone,15,quark:world_stone_pavement:2,15,CONCRETE:8,100)
RandomBlock(-3,48,0,minecraft:iron_bars:0,5,CONCRETE_POWDER:8,10,quark:limestone:1,15,quark:limestone,15,quark:world_stone_pavement:2,15,CONCRETE:8,100)
RandomBlock(-3,48,2,minecraft:iron_bars:0,5,CONCRETE_POWDER:8,10,quark:limestone:1,15,quark:limestone,15,quark:world_stone_pavement:2,15,CONCRETE:8,100)
RandomBlock(-3,48,3,minecraft:iron_bars:0,5,CONCRETE_POWDER:8,10,quark:limestone:1,15,quark:limestone,15,quark:world_stone_pavement:2,15,CONCRETE:8,100)
RandomBlock(-3,48,4,minecraft:iron_bars:0,5,CONCRETE_POWDER:8,10,quark:limestone:1,15,quark:limestone,15,quark:world_stone_pavement:2,15,CONCRETE:8,100)
RandomBlock(-3,48,5,minecraft:iron_bars:0,5,CONCRETE_POWDER:8,10,quark:limestone:1,15,quark:limestone,15,quark:world_stone_pavement:2,15,CONCRETE:8,100)
RandomBlock(-3,48,6,minecraft:iron_bars:0,5,CONCRETE_POWDER:8,10,quark:limestone:1,15,quark:limestone,15,quark:world_stone_pavement:2,15,CONCRETE:8,100)
RandomBlock(-3,49,-5,minecraft:iron_bars:0,5,CONCRETE_POWDER:8,10,quark:limestone:1,15,quark:limestone,15,quark:world_stone_pavement:2,15,CONCRETE:8,100)
RandomBlock(-3,49,-4,minecraft:iron_bars:0,5,CONCRETE_POWDER:8,10,quark:limestone:1,15,quark:limestone,15,quark:world_stone_pavement:2,15,CONCRETE:8,100)
Block(-3,49,-3,IRON_FENCE:0)
Block(-3,49,-2,IRON_FENCE:0)
Block(-3,49,-1,IRON_FENCE:0)
RandomBlock(-3,49,0,minecraft:iron_bars:0,5,CONCRETE_POWDER:8,10,quark:limestone:1,15,quark:limestone,15,quark:world_stone_pavement:2,15,CONCRETE:8,100)
RandomBlock(-3,49,2,minecraft:iron_bars:0,5,CONCRETE_POWDER:8,10,quark:limestone:1,15,quark:limestone,15,quark:world_stone_pavement:2,15,CONCRETE:8,100)
Block(-3,49,3,IRON_FENCE:0)
Block(-3,49,4,IRON_FENCE:0)
Block(-3,49,5,IRON_FENCE:0)
RandomBlock(-3,49,6,minecraft:iron_bars:0,5,CONCRETE_POWDER:8,10,quark:limestone:1,15,quark:limestone,15,quark:world_stone_pavement:2,15,CONCRETE:8,100)
RandomBlock(-3,50,-7,minecraft:iron_bars:0,5,STAINED_CLAY:15,5,STAINED_CLAY:7,5,quark:iron_plate_slab:8,15,quark:world_stone_pavement:2,15,STAINED_CLAY:9,100)
RandomBlock(-3,50,-6,minecraft:iron_bars:0,5,STAINED_CLAY:15,5,STAINED_CLAY:7,5,quark:iron_plate_slab:8,15,quark:world_stone_pavement:2,15,STAINED_CLAY:9,100)
RandomBlock(-3,50,-5,minecraft:iron_bars:0,5,CONCRETE_POWDER:8,10,quark:limestone:1,15,quark:limestone,15,quark:world_stone_pavement:2,15,CONCRETE:8,100)
RandomBlock(-3,50,-4,minecraft:iron_bars:0,5,CONCRETE_POWDER:8,10,quark:limestone:1,15,quark:limestone,15,quark:world_stone_pavement:2,15,CONCRETE:8,100)
RandomBlock(-3,50,0,minecraft:iron_bars:0,5,CONCRETE_POWDER:8,10,quark:limestone:1,15,quark:limestone,15,quark:world_stone_pavement:2,15,CONCRETE:8,100)
RandomBlock(-3,50,2,minecraft:iron_bars:0,5,CONCRETE_POWDER:8,10,quark:limestone:1,15,quark:limestone,15,quark:world_stone_pavement:2,15,CONCRETE:8,100)
RandomBlock(-3,50,6,minecraft:iron_bars:0,5,CONCRETE_POWDER:8,10,quark:limestone:1,15,quark:limestone,15,quark:world_stone_pavement:2,15,CONCRETE:8,100)
RandomBlock(-3,51,-5,minecraft:iron_bars:0,5,CONCRETE_POWDER:8,10,quark:limestone:1,15,quark:limestone,15,quark:world_stone_pavement:2,15,CONCRETE:8,100)
Block(-3,51,-2,QUARTZ_BLOCK:0)
Block(-3,51,4,QUARTZ_BLOCK:0)
Block(-3,52,-5,CONCRETE:15)
Block(-3,52,-3,QUARTZ_BLOCK:0)
Block(-3,52,-2,QUARTZ_BLOCK:0)
Block(-3,52,-1,QUARTZ_BLOCK:0)
Block(-3,52,3,QUARTZ_BLOCK:0)
Block(-3,52,4,QUARTZ_BLOCK:0)
Block(-3,52,5,QUARTZ_BLOCK:0)
Block(-3,53,-7,quark:iron_plate:1)
RandomBlock(-3,53,-5,minecraft:iron_bars:0,5,CONCRETE_POWDER:8,10,quark:limestone:1,15,quark:limestone,15,quark:world_stone_pavement:2,15,CONCRETE:8,100)
RandomBlock(-3,53,-4,minecraft:iron_bars:0,5,CONCRETE_POWDER:8,10,quark:limestone:1,15,quark:limestone,15,quark:world_stone_pavement:2,15,CONCRETE:8,100)
Block(-3,53,-3,QUARTZ_BLOCK:0)
Block(-3,53,-1,QUARTZ_BLOCK:0)
RandomBlock(-3,53,0,minecraft:iron_bars:0,5,CONCRETE_POWDER:8,10,quark:limestone:1,15,quark:limestone,15,quark:world_stone_pavement:2,15,CONCRETE:8,100)
RandomBlock(-3,53,2,minecraft:iron_bars:0,5,CONCRETE_POWDER:8,10,quark:limestone:1,15,quark:limestone,15,quark:world_stone_pavement:2,15,CONCRETE:8,100)
Block(-3,53,3,QUARTZ_BLOCK:0)
Block(-3,53,5,QUARTZ_BLOCK:0)
RandomBlock(-3,53,6,minecraft:iron_bars:0,5,CONCRETE_POWDER:8,10,quark:limestone:1,15,quark:limestone,15,quark:world_stone_pavement:2,15,CONCRETE:8,100)
RandomBlock(-3,54,-7,minecraft:iron_bars:0,5,CONCRETE_POWDER:8,10,quark:limestone:1,15,quark:limestone,15,quark:world_stone_pavement:2,15,CONCRETE:8,100)
RandomBlock(-3,54,-6,minecraft:iron_bars:0,5,CONCRETE_POWDER:8,10,quark:limestone:1,15,quark:limestone,15,quark:world_stone_pavement:2,15,CONCRETE:8,100)
RandomBlock(-3,54,-5,minecraft:iron_bars:0,5,CONCRETE_POWDER:8,10,quark:limestone:1,15,quark:limestone,15,quark:world_stone_pavement:2,15,CONCRETE:8,100)
RandomBlock(-3,54,-4,minecraft:iron_bars:0,5,CONCRETE_POWDER:8,10,quark:limestone:1,15,quark:limestone,15,quark:world_stone_pavement:2,15,CONCRETE:8,100)
RandomBlock(-3,54,-3,CONCRETE_POWDER:7,25,CONCRETE:7,100)
RandomBlock(-3,54,-1,CONCRETE_POWDER:7,25,CONCRETE:7,100)
RandomBlock(-3,54,0,minecraft:iron_bars:0,5,CONCRETE_POWDER:8,10,quark:limestone:1,15,quark:limestone,15,quark:world_stone_pavement:2,15,CONCRETE:8,100)
RandomBlock(-3,54,2,minecraft:iron_bars:0,5,CONCRETE_POWDER:8,10,quark:limestone:1,15,quark:limestone,15,quark:world_stone_pavement:2,15,CONCRETE:8,100)
RandomBlock(-3,54,3,CONCRETE_POWDER:7,25,CONCRETE:7,100)
RandomBlock(-3,54,4,CONCRETE_POWDER:7,25,CONCRETE:7,100)
RandomBlock(-3,54,5,CONCRETE_POWDER:7,25,CONCRETE:7,100)
RandomBlock(-3,54,6,minecraft:iron_bars:0,5,CONCRETE_POWDER:8,10,quark:limestone:1,15,quark:limestone,15,quark:world_stone_pavement:2,15,CONCRETE:8,100)
Block(-3,55,-6,STEP:8)
RandomBlock(-3,55,-5,minecraft:iron_bars:0,5,CONCRETE_POWDER:8,10,quark:limestone:1,15,quark:limestone,15,quark:world_stone_pavement:2,15,CONCRETE:8,100)
RandomBlock(-3,55,-3,minecraft:iron_bars:0,5,CONCRETE_POWDER:8,10,quark:limestone:1,15,quark:limestone,15,quark:world_stone_pavement:2,15,CONCRETE:8,100)
RandomBlock(-3,55,-2,minecraft:iron_bars:0,5,CONCRETE_POWDER:8,10,quark:limestone:1,15,quark:limestone,15,quark:world_stone_pavement:2,15,CONCRETE:8,100)
RandomBlock(-3,55,-1,minecraft:iron_bars:0,5,CONCRETE_POWDER:8,10,quark:limestone:1,15,quark:limestone,15,quark:world_stone_pavement:2,15,CONCRETE:8,100)
RandomBlock(-3,55,3,minecraft:iron_bars:0,5,CONCRETE_POWDER:8,10,quark:limestone:1,15,quark:limestone,15,quark:world_stone_pavement:2,15,CONCRETE:8,100)
RandomBlock(-3,55,4,minecraft:iron_bars:0,5,CONCRETE_POWDER:8,10,quark:limestone:1,15,quark:limestone,15,quark:world_stone_pavement:2,15,CONCRETE:8,100)
RandomBlock(-3,55,5,minecraft:iron_bars:0,5,CONCRETE_POWDER:8,10,quark:limestone:1,15,quark:limestone,15,quark:world_stone_pavement:2,15,CONCRETE:8,100)
Block(-3,56,-6,LEVER:4)
RandomBlock(-3,56,-5,minecraft:iron_bars:0,5,CONCRETE_POWDER:8,10,quark:limestone:1,15,quark:limestone,15,quark:world_stone_pavement:2,15,CONCRETE:8,100)
RandomBlock(-3,56,-2,minecraft:iron_bars:0,5,CONCRETE_POWDER:8,10,quark:limestone:1,15,quark:limestone,15,quark:world_stone_pavement:2,15,CONCRETE:8,100)
RandomBlock(-3,56,4,minecraft:iron_bars:0,5,CONCRETE_POWDER:8,10,quark:limestone:1,15,quark:limestone,15,quark:world_stone_pavement:2,15,CONCRETE:8,100)
RandomBlock(-3,57,-5,minecraft:iron_bars:0,5,CONCRETE_POWDER:8,10,quark:limestone:1,15,quark:limestone,15,quark:world_stone_pavement:2,15,CONCRETE:8,100)
RandomBlock(-3,57,-2,minecraft:iron_bars:0,5,CONCRETE_POWDER:8,10,quark:limestone:1,15,quark:limestone,15,quark:world_stone_pavement:2,15,CONCRETE:8,100)
RandomBlock(-3,57,4,minecraft:iron_bars:0,5,CONCRETE_POWDER:8,10,quark:limestone:1,15,quark:limestone,15,quark:world_stone_pavement:2,15,CONCRETE:8,100)
Block(-3,58,-7,STEP:5)
Block(-3,58,-6,STEP:5)
RandomBlock(-3,58,-5,minecraft:iron_bars:0,5,CONCRETE_POWDER:8,10,quark:limestone:1,15,quark:limestone,15,quark:world_stone_pavement:2,15,CONCRETE:8,100)
RandomBlock(-3,58,-2,minecraft:iron_bars:0,5,CONCRETE_POWDER:8,10,quark:limestone:1,15,quark:limestone,15,quark:world_stone_pavement:2,15,CONCRETE:8,100)
RandomBlock(-3,58,4,minecraft:iron_bars:0,5,CONCRETE_POWDER:8,10,quark:limestone:1,15,quark:limestone,15,quark:world_stone_pavement:2,15,CONCRETE:8,100)
Block(-3,59,-7,quark:iron_plate:1)
Block(-3,59,-5,IRON_FENCE:0)
RandomBlock(-3,59,-2,minecraft:iron_bars:0,5,CONCRETE_POWDER:8,10,quark:limestone:1,15,quark:limestone,15,quark:world_stone_pavement:2,15,CONCRETE:8,100)
RandomBlock(-3,59,4,minecraft:iron_bars:0,5,CONCRETE_POWDER:8,10,quark:limestone:1,15,quark:limestone,15,quark:world_stone_pavement:2,15,CONCRETE:8,100)
Block(-2,43,-2,SMOOTH_STAIRS:5)
Block(-2,43,4,SMOOTH_STAIRS:5)
RandomBlock(-2,44,-7,minecraft:iron_bars:0,5,STAINED_CLAY:15,5,STAINED_CLAY:7,5,quark:iron_plate_slab:8,15,quark:world_stone_pavement:2,15,STAINED_CLAY:9,100)
RandomBlock(-2,44,-6,minecraft:iron_bars:0,5,STAINED_CLAY:15,5,STAINED_CLAY:7,5,quark:iron_plate_slab:8,15,quark:world_stone_pavement:2,15,STAINED_CLAY:9,100)
RandomBlock(-2,44,-5,minecraft:iron_bars:0,5,STAINED_CLAY:15,5,STAINED_CLAY:7,5,quark:iron_plate_slab:8,15,quark:world_stone_pavement:2,15,STAINED_CLAY:9,100)
RandomBlock(-2,44,-4,minecraft:iron_bars:0,5,STAINED_CLAY:15,5,STAINED_CLAY:7,5,quark:iron_plate_slab:8,15,quark:world_stone_pavement:2,15,STAINED_CLAY:9,100)
RandomBlock(-2,44,-3,minecraft:iron_bars:0,5,STAINED_CLAY:15,5,STAINED_CLAY:7,5,quark:iron_plate_slab:8,15,quark:world_stone_pavement:2,15,STAINED_CLAY:9,100)
RandomBlock(-2,44,-2,minecraft:iron_bars:0,5,STAINED_CLAY:15,5,STAINED_CLAY:7,5,quark:iron_plate_slab:8,15,quark:world_stone_pavement:2,15,STAINED_CLAY:9,100)
RandomBlock(-2,44,-1,minecraft:iron_bars:0,5,STAINED_CLAY:15,5,STAINED_CLAY:7,5,quark:iron_plate_slab:8,15,quark:world_stone_pavement:2,15,STAINED_CLAY:9,100)
RandomBlock(-2,44,0,minecraft:iron_bars:0,5,STAINED_CLAY:15,5,STAINED_CLAY:7,5,quark:iron_plate_slab:8,15,quark:world_stone_pavement:2,15,STAINED_CLAY:9,100)
RandomBlock(-2,44,1,minecraft:iron_bars:0,5,STAINED_CLAY:15,5,STAINED_CLAY:7,5,quark:iron_plate_slab:8,15,quark:world_stone_pavement:2,15,STAINED_CLAY:9,100)
RandomBlock(-2,44,2,minecraft:iron_bars:0,5,STAINED_CLAY:15,5,STAINED_CLAY:7,5,quark:iron_plate_slab:8,15,quark:world_stone_pavement:2,15,STAINED_CLAY:9,100)
RandomBlock(-2,44,3,minecraft:iron_bars:0,5,STAINED_CLAY:15,5,STAINED_CLAY:7,5,quark:iron_plate_slab:8,15,quark:world_stone_pavement:2,15,STAINED_CLAY:9,100)
RandomBlock(-2,44,4,minecraft:iron_bars:0,5,STAINED_CLAY:15,5,STAINED_CLAY:7,5,quark:iron_plate_slab:8,15,quark:world_stone_pavement:2,15,STAINED_CLAY:9,100)
RandomBlock(-2,44,5,minecraft:iron_bars:0,5,STAINED_CLAY:15,5,STAINED_CLAY:7,5,quark:iron_plate_slab:8,15,quark:world_stone_pavement:2,15,STAINED_CLAY:9,100)
RandomBlock(-2,44,6,minecraft:iron_bars:0,5,STAINED_CLAY:15,5,STAINED_CLAY:7,5,quark:iron_plate_slab:8,15,quark:world_stone_pavement:2,15,STAINED_CLAY:9,100)
RandomBlock(-2,44,7,minecraft:iron_bars:0,5,STAINED_CLAY:15,5,STAINED_CLAY:7,5,quark:iron_plate_slab:8,15,quark:world_stone_pavement:2,15,STAINED_CLAY:9,100)
RandomBlock(-2,44,8,minecraft:iron_bars:0,5,STAINED_CLAY:15,5,STAINED_CLAY:7,5,quark:iron_plate_slab:8,15,quark:world_stone_pavement:2,15,STAINED_CLAY:9,100)
Block(-2,45,-7,IRON_DOOR_BLOCK:2)
RandomBlock(-2,45,-6,minecraft:iron_bars:0,5,CONCRETE_POWDER:8,10,quark:limestone:1,15,quark:limestone,15,quark:world_stone_pavement:2,15,CONCRETE:8,100)
RandomBlock(-2,45,-5,minecraft:iron_bars:0,5,CONCRETE_POWDER:8,10,quark:limestone:1,15,quark:limestone,15,quark:world_stone_pavement:2,15,CONCRETE:8,100)
RandomBlock(-2,45,-4,minecraft:iron_bars:0,5,CONCRETE_POWDER:8,10,quark:limestone:1,15,quark:limestone,15,quark:world_stone_pavement:2,15,CONCRETE:8,100)
RandomBlock(-2,45,-3,minecraft:iron_bars:0,5,CONCRETE_POWDER:8,10,quark:limestone:1,15,quark:limestone,15,quark:world_stone_pavement:2,15,CONCRETE:8,100)
RandomBlock(-2,45,-2,minecraft:iron_bars:0,5,CONCRETE_POWDER:8,10,quark:limestone:1,15,quark:limestone,15,quark:world_stone_pavement:2,15,CONCRETE:8,100)
RandomBlock(-2,45,-1,minecraft:iron_bars:0,5,CONCRETE_POWDER:8,10,quark:limestone:1,15,quark:limestone,15,quark:world_stone_pavement:2,15,CONCRETE:8,100)
RandomBlock(-2,45,0,minecraft:iron_bars:0,5,CONCRETE_POWDER:8,10,quark:limestone:1,15,quark:limestone,15,quark:world_stone_pavement:2,15,CONCRETE:8,100)
RandomBlock(-2,45,1,minecraft:iron_bars:0,5,CONCRETE_POWDER:8,10,quark:limestone:1,15,quark:limestone,15,quark:world_stone_pavement:2,15,CONCRETE:8,100)
RandomBlock(-2,45,2,minecraft:iron_bars:0,5,CONCRETE_POWDER:8,10,quark:limestone:1,15,quark:limestone,15,quark:world_stone_pavement:2,15,CONCRETE:8,100)
RandomBlock(-2,45,3,minecraft:iron_bars:0,5,CONCRETE_POWDER:8,10,quark:limestone:1,15,quark:limestone,15,quark:world_stone_pavement:2,15,CONCRETE:8,100)
RandomBlock(-2,45,4,minecraft:iron_bars:0,5,CONCRETE_POWDER:8,10,quark:limestone:1,15,quark:limestone,15,quark:world_stone_pavement:2,15,CONCRETE:8,100)
RandomBlock(-2,45,5,minecraft:iron_bars:0,5,CONCRETE_POWDER:8,10,quark:limestone:1,15,quark:limestone,15,quark:world_stone_pavement:2,15,CONCRETE:8,100)
RandomBlock(-2,45,6,minecraft:iron_bars:0,5,CONCRETE_POWDER:8,10,quark:limestone:1,15,quark:limestone,15,quark:world_stone_pavement:2,15,CONCRETE:8,100)
RandomBlock(-2,45,7,minecraft:iron_bars:0,5,CONCRETE_POWDER:8,10,quark:limestone:1,15,quark:limestone,15,quark:world_stone_pavement:2,15,CONCRETE:8,100)
RandomBlock(-2,45,8,minecraft:iron_bars:0,5,CONCRETE_POWDER:8,10,quark:limestone:1,15,quark:limestone,15,quark:world_stone_pavement:2,15,CONCRETE:8,100)
Block(-2,46,-7,IRON_DOOR_BLOCK:9)
Block(-2,46,-6,CONCRETE:15)
Block(-2,46,-5,CONCRETE:15)
Block(-2,46,-4,CONCRETE:15)
Block(-2,46,-3,CONCRETE:15)
Block(-2,46,-2,CONCRETE:15)
Block(-2,46,-1,STAINED_GLASS_PANE:7)
Block(-2,46,0,STAINED_GLASS_PANE:7)
Block(-2,46,1,CONCRETE:15)
Block(-2,46,2,CONCRETE:15)
Block(-2,46,3,CONCRETE:15)
Block(-2,46,4,CONCRETE:15)
Block(-2,46,5,CONCRETE:15)
Block(-2,46,6,STAINED_GLASS_PANE:7)
Block(-2,46,7,STAINED_GLASS_PANE:7)
Block(-2,46,8,CONCRETE:15)
RandomBlock(-2,47,-7,minecraft:iron_bars:0,5,CONCRETE_POWDER:8,10,quark:limestone:1,15,quark:limestone,15,quark:world_stone_pavement:2,15,CONCRETE:8,100)
RandomBlock(-2,47,-6,minecraft:iron_bars:0,5,CONCRETE_POWDER:8,10,quark:limestone:1,15,quark:limestone,15,quark:world_stone_pavement:2,15,CONCRETE:8,100)
RandomBlock(-2,47,-5,minecraft:iron_bars:0,5,CONCRETE_POWDER:8,10,quark:limestone:1,15,quark:limestone,15,quark:world_stone_pavement:2,15,CONCRETE:8,100)
RandomBlock(-2,47,-4,minecraft:iron_bars:0,5,CONCRETE_POWDER:8,10,quark:limestone:1,15,quark:limestone,15,quark:world_stone_pavement:2,15,CONCRETE:8,100)
RandomBlock(-2,47,-3,minecraft:iron_bars:0,5,CONCRETE_POWDER:8,10,quark:limestone:1,15,quark:limestone,15,quark:world_stone_pavement:2,15,CONCRETE:8,100)
RandomBlock(-2,47,-2,minecraft:iron_bars:0,5,CONCRETE_POWDER:8,10,quark:limestone:1,15,quark:limestone,15,quark:world_stone_pavement:2,15,CONCRETE:8,100)
RandomBlock(-2,47,-1,minecraft:iron_bars:0,5,CONCRETE_POWDER:8,10,quark:limestone:1,15,quark:limestone,15,quark:world_stone_pavement:2,15,CONCRETE:8,100)
RandomBlock(-2,47,0,minecraft:iron_bars:0,5,CONCRETE_POWDER:8,10,quark:limestone:1,15,quark:limestone,15,quark:world_stone_pavement:2,15,CONCRETE:8,100)
RandomBlock(-2,47,1,minecraft:iron_bars:0,5,CONCRETE_POWDER:8,10,quark:limestone:1,15,quark:limestone,15,quark:world_stone_pavement:2,15,CONCRETE:8,100)
RandomBlock(-2,47,2,minecraft:iron_bars:0,5,CONCRETE_POWDER:8,10,quark:limestone:1,15,quark:limestone,15,quark:world_stone_pavement:2,15,CONCRETE:8,100)
RandomBlock(-2,47,3,minecraft:iron_bars:0,5,CONCRETE_POWDER:8,10,quark:limestone:1,15,quark:limestone,15,quark:world_stone_pavement:2,15,CONCRETE:8,100)
RandomBlock(-2,47,4,minecraft:iron_bars:0,5,CONCRETE_POWDER:8,10,quark:limestone:1,15,quark:limestone,15,quark:world_stone_pavement:2,15,CONCRETE:8,100)
RandomBlock(-2,47,5,minecraft:iron_bars:0,5,CONCRETE_POWDER:8,10,quark:limestone:1,15,quark:limestone,15,quark:world_stone_pavement:2,15,CONCRETE:8,100)
RandomBlock(-2,47,6,minecraft:iron_bars:0,5,CONCRETE_POWDER:8,10,quark:limestone:1,15,quark:limestone,15,quark:world_stone_pavement:2,15,CONCRETE:8,100)
RandomBlock(-2,47,7,minecraft:iron_bars:0,5,CONCRETE_POWDER:8,10,quark:limestone:1,15,quark:limestone,15,quark:world_stone_pavement:2,15,CONCRETE:8,100)
RandomBlock(-2,47,8,minecraft:iron_bars:0,5,CONCRETE_POWDER:8,10,quark:limestone:1,15,quark:limestone,15,quark:world_stone_pavement:2,15,CONCRETE:8,100)
RandomBlock(-2,48,-7,minecraft:iron_bars:0,5,CONCRETE_POWDER:8,10,quark:limestone:1,15,quark:limestone,15,quark:world_stone_pavement:2,15,CONCRETE:8,100)
RandomBlock(-2,48,-6,minecraft:iron_bars:0,5,CONCRETE_POWDER:8,10,quark:limestone:1,15,quark:limestone,15,quark:world_stone_pavement:2,15,CONCRETE:8,100)
RandomBlock(-2,48,-5,minecraft:iron_bars:0,5,CONCRETE_POWDER:8,10,quark:limestone:1,15,quark:limestone,15,quark:world_stone_pavement:2,15,CONCRETE:8,100)
RandomBlock(-2,48,-4,minecraft:iron_bars:0,5,CONCRETE_POWDER:8,10,quark:limestone:1,15,quark:limestone,15,quark:world_stone_pavement:2,15,CONCRETE:8,100)
RandomBlock(-2,48,-3,minecraft:iron_bars:0,5,CONCRETE_POWDER:8,10,quark:limestone:1,15,quark:limestone,15,quark:world_stone_pavement:2,15,CONCRETE:8,100)
RandomBlock(-2,48,-2,minecraft:iron_bars:0,5,CONCRETE_POWDER:8,10,quark:limestone:1,15,quark:limestone,15,quark:world_stone_pavement:2,15,CONCRETE:8,100)
RandomBlock(-2,48,-1,minecraft:iron_bars:0,5,CONCRETE_POWDER:8,10,quark:limestone:1,15,quark:limestone,15,quark:world_stone_pavement:2,15,CONCRETE:8,100)
RandomBlock(-2,48,0,minecraft:iron_bars:0,5,CONCRETE_POWDER:8,10,quark:limestone:1,15,quark:limestone,15,quark:world_stone_pavement:2,15,CONCRETE:8,100)
RandomBlock(-2,48,1,minecraft:iron_bars:0,5,CONCRETE_POWDER:8,10,quark:limestone:1,15,quark:limestone,15,quark:world_stone_pavement:2,15,CONCRETE:8,100)
RandomBlock(-2,48,2,minecraft:iron_bars:0,5,CONCRETE_POWDER:8,10,quark:limestone:1,15,quark:limestone,15,quark:world_stone_pavement:2,15,CONCRETE:8,100)
RandomBlock(-2,48,3,minecraft:iron_bars:0,5,CONCRETE_POWDER:8,10,quark:limestone:1,15,quark:limestone,15,quark:world_stone_pavement:2,15,CONCRETE:8,100)
RandomBlock(-2,48,4,minecraft:iron_bars:0,5,CONCRETE_POWDER:8,10,quark:limestone:1,15,quark:limestone,15,quark:world_stone_pavement:2,15,CONCRETE:8,100)
RandomBlock(-2,48,5,minecraft:iron_bars:0,5,CONCRETE_POWDER:8,10,quark:limestone:1,15,quark:limestone,15,quark:world_stone_pavement:2,15,CONCRETE:8,100)
RandomBlock(-2,48,6,minecraft:iron_bars:0,5,CONCRETE_POWDER:8,10,quark:limestone:1,15,quark:limestone,15,quark:world_stone_pavement:2,15,CONCRETE:8,100)
RandomBlock(-2,48,7,minecraft:iron_bars:0,5,CONCRETE_POWDER:8,10,quark:limestone:1,15,quark:limestone,15,quark:world_stone_pavement:2,15,CONCRETE:8,100)
RandomBlock(-2,48,8,minecraft:iron_bars:0,5,CONCRETE_POWDER:8,10,quark:limestone:1,15,quark:limestone,15,quark:world_stone_pavement:2,15,CONCRETE:8,100)
RandomBlock(-2,49,-7,minecraft:iron_bars:0,5,CONCRETE_POWDER:8,10,quark:limestone:1,15,quark:limestone,15,quark:world_stone_pavement:2,15,CONCRETE:8,100)
RandomBlock(-2,49,-6,minecraft:iron_bars:0,5,CONCRETE_POWDER:8,10,quark:limestone:1,15,quark:limestone,15,quark:world_stone_pavement:2,15,CONCRETE:8,100)
RandomBlock(-2,49,-5,minecraft:iron_bars:0,5,CONCRETE_POWDER:8,10,quark:limestone:1,15,quark:limestone,15,quark:world_stone_pavement:2,15,CONCRETE:8,100)
RandomBlock(-2,49,-4,minecraft:iron_bars:0,5,CONCRETE_POWDER:8,10,quark:limestone:1,15,quark:limestone,15,quark:world_stone_pavement:2,15,CONCRETE:8,100)
RandomBlock(-2,49,-3,minecraft:iron_bars:0,5,CONCRETE_POWDER:8,10,quark:limestone:1,15,quark:limestone,15,quark:world_stone_pavement:2,15,CONCRETE:8,100)
RandomBlock(-2,49,-2,minecraft:iron_bars:0,5,CONCRETE_POWDER:8,10,quark:limestone:1,15,quark:limestone,15,quark:world_stone_pavement:2,15,CONCRETE:8,100)
RandomBlock(-2,49,-1,minecraft:iron_bars:0,5,CONCRETE_POWDER:8,10,quark:limestone:1,15,quark:limestone,15,quark:world_stone_pavement:2,15,CONCRETE:8,100)
RandomBlock(-2,49,0,minecraft:iron_bars:0,5,CONCRETE_POWDER:8,10,quark:limestone:1,15,quark:limestone,15,quark:world_stone_pavement:2,15,CONCRETE:8,100)
RandomBlock(-2,49,1,minecraft:iron_bars:0,5,CONCRETE_POWDER:8,10,quark:limestone:1,15,quark:limestone,15,quark:world_stone_pavement:2,15,CONCRETE:8,100)
RandomBlock(-2,49,2,minecraft:iron_bars:0,5,CONCRETE_POWDER:8,10,quark:limestone:1,15,quark:limestone,15,quark:world_stone_pavement:2,15,CONCRETE:8,100)
RandomBlock(-2,49,3,minecraft:iron_bars:0,5,CONCRETE_POWDER:8,10,quark:limestone:1,15,quark:limestone,15,quark:world_stone_pavement:2,15,CONCRETE:8,100)
RandomBlock(-2,49,4,minecraft:iron_bars:0,5,CONCRETE_POWDER:8,10,quark:limestone:1,15,quark:limestone,15,quark:world_stone_pavement:2,15,CONCRETE:8,100)
RandomBlock(-2,49,5,minecraft:iron_bars:0,5,CONCRETE_POWDER:8,10,quark:limestone:1,15,quark:limestone,15,quark:world_stone_pavement:2,15,CONCRETE:8,100)
RandomBlock(-2,49,6,minecraft:iron_bars:0,5,CONCRETE_POWDER:8,10,quark:limestone:1,15,quark:limestone,15,quark:world_stone_pavement:2,15,CONCRETE:8,100)
RandomBlock(-2,49,7,minecraft:iron_bars:0,5,CONCRETE_POWDER:8,10,quark:limestone:1,15,quark:limestone,15,quark:world_stone_pavement:2,15,CONCRETE:8,100)
RandomBlock(-2,49,8,minecraft:iron_bars:0,5,CONCRETE_POWDER:8,10,quark:limestone:1,15,quark:limestone,15,quark:world_stone_pavement:2,15,CONCRETE:8,100)
RandomBlock(-2,50,-7,minecraft:iron_bars:0,5,STAINED_CLAY:15,5,STAINED_CLAY:7,5,quark:iron_plate_slab:8,15,quark:world_stone_pavement:2,15,STAINED_CLAY:9,100)
RandomBlock(-2,50,-6,minecraft:iron_bars:0,5,STAINED_CLAY:15,5,STAINED_CLAY:7,5,quark:iron_plate_slab:8,15,quark:world_stone_pavement:2,15,STAINED_CLAY:9,100)
RandomBlock(-2,50,-5,minecraft:iron_bars:0,5,CONCRETE_POWDER:8,10,quark:limestone:1,15,quark:limestone,15,quark:world_stone_pavement:2,15,CONCRETE:8,100)
RandomBlock(-2,50,-4,minecraft:iron_bars:0,5,CONCRETE_POWDER:8,10,quark:limestone:1,15,quark:limestone,15,quark:world_stone_pavement:2,15,CONCRETE:8,100)
RandomBlock(-2,50,-3,minecraft:iron_bars:0,5,CONCRETE_POWDER:8,10,quark:limestone:1,15,quark:limestone,15,quark:world_stone_pavement:2,15,CONCRETE:8,100)
RandomBlock(-2,50,-2,minecraft:iron_bars:0,5,CONCRETE_POWDER:8,10,quark:limestone:1,15,quark:limestone,15,quark:world_stone_pavement:2,15,CONCRETE:8,100)
RandomBlock(-2,50,-1,minecraft:iron_bars:0,5,CONCRETE_POWDER:8,10,quark:limestone:1,15,quark:limestone,15,quark:world_stone_pavement:2,15,CONCRETE:8,100)
RandomBlock(-2,50,0,minecraft:iron_bars:0,5,CONCRETE_POWDER:8,10,quark:limestone:1,15,quark:limestone,15,quark:world_stone_pavement:2,15,CONCRETE:8,100)
RandomBlock(-2,50,1,minecraft:iron_bars:0,5,CONCRETE_POWDER:8,10,quark:limestone:1,15,quark:limestone,15,quark:world_stone_pavement:2,15,CONCRETE:8,100)
RandomBlock(-2,50,2,minecraft:iron_bars:0,5,CONCRETE_POWDER:8,10,quark:limestone:1,15,quark:limestone,15,quark:world_stone_pavement:2,15,CONCRETE:8,100)
RandomBlock(-2,50,3,minecraft:iron_bars:0,5,CONCRETE_POWDER:8,10,quark:limestone:1,15,quark:limestone,15,quark:world_stone_pavement:2,15,CONCRETE:8,100)
RandomBlock(-2,50,4,minecraft:iron_bars:0,5,CONCRETE_POWDER:8,10,quark:limestone:1,15,quark:limestone,15,quark:world_stone_pavement:2,15,CONCRETE:8,100)
RandomBlock(-2,50,5,minecraft:iron_bars:0,5,CONCRETE_POWDER:8,10,quark:limestone:1,15,quark:limestone,15,quark:world_stone_pavement:2,15,CONCRETE:8,100)
RandomBlock(-2,50,6,minecraft:iron_bars:0,5,CONCRETE_POWDER:8,10,quark:limestone:1,15,quark:limestone,15,quark:world_stone_pavement:2,15,CONCRETE:8,100)
RandomBlock(-2,50,7,minecraft:iron_bars:0,5,CONCRETE_POWDER:8,10,quark:limestone:1,15,quark:limestone,15,quark:world_stone_pavement:2,15,CONCRETE:8,100)
RandomBlock(-2,50,8,minecraft:iron_bars:0,5,CONCRETE_POWDER:8,10,quark:limestone:1,15,quark:limestone,15,quark:world_stone_pavement:2,15,CONCRETE:8,100)
RandomBlock(-2,51,-5,minecraft:iron_bars:0,5,CONCRETE_POWDER:8,10,quark:limestone:1,15,quark:limestone,15,quark:world_stone_pavement:2,15,CONCRETE:8,100)
RandomBlock(-2,51,-4,minecraft:iron_bars:0,5,CONCRETE_POWDER:8,10,quark:limestone:1,15,quark:limestone,15,quark:world_stone_pavement:2,15,CONCRETE:8,100)
RandomBlock(-2,51,-3,minecraft:iron_bars:0,5,CONCRETE_POWDER:8,10,quark:limestone:1,15,quark:limestone,15,quark:world_stone_pavement:2,15,CONCRETE:8,100)
RandomBlock(-2,51,-2,minecraft:iron_bars:0,5,CONCRETE_POWDER:8,10,quark:limestone:1,15,quark:limestone,15,quark:world_stone_pavement:2,15,CONCRETE:8,100)
RandomBlock(-2,51,-1,minecraft:iron_bars:0,5,CONCRETE_POWDER:8,10,quark:limestone:1,15,quark:limestone,15,quark:world_stone_pavement:2,15,CONCRETE:8,100)
RandomBlock(-2,51,0,minecraft:iron_bars:0,5,CONCRETE_POWDER:8,10,quark:limestone:1,15,quark:limestone,15,quark:world_stone_pavement:2,15,CONCRETE:8,100)
RandomBlock(-2,51,1,minecraft:iron_bars:0,5,CONCRETE_POWDER:8,10,quark:limestone:1,15,quark:limestone,15,quark:world_stone_pavement:2,15,CONCRETE:8,100)
RandomBlock(-2,51,2,minecraft:iron_bars:0,5,CONCRETE_POWDER:8,10,quark:limestone:1,15,quark:limestone,15,quark:world_stone_pavement:2,15,CONCRETE:8,100)
RandomBlock(-2,51,3,minecraft:iron_bars:0,5,CONCRETE_POWDER:8,10,quark:limestone:1,15,quark:limestone,15,quark:world_stone_pavement:2,15,CONCRETE:8,100)
RandomBlock(-2,51,4,minecraft:iron_bars:0,5,CONCRETE_POWDER:8,10,quark:limestone:1,15,quark:limestone,15,quark:world_stone_pavement:2,15,CONCRETE:8,100)
RandomBlock(-2,51,5,minecraft:iron_bars:0,5,CONCRETE_POWDER:8,10,quark:limestone:1,15,quark:limestone,15,quark:world_stone_pavement:2,15,CONCRETE:8,100)
RandomBlock(-2,51,6,minecraft:iron_bars:0,5,CONCRETE_POWDER:8,10,quark:limestone:1,15,quark:limestone,15,quark:world_stone_pavement:2,15,CONCRETE:8,100)
RandomBlock(-2,51,7,minecraft:iron_bars:0,5,CONCRETE_POWDER:8,10,quark:limestone:1,15,quark:limestone,15,quark:world_stone_pavement:2,15,CONCRETE:8,100)
RandomBlock(-2,51,8,minecraft:iron_bars:0,5,CONCRETE_POWDER:8,10,quark:limestone:1,15,quark:limestone,15,quark:world_stone_pavement:2,15,CONCRETE:8,100)
Block(-2,52,-5,CONCRETE:15)
Block(-2,52,-4,CONCRETE:15)
Block(-2,52,-3,CONCRETE:15)
Block(-2,52,-2,CONCRETE:15)
Block(-2,52,-1,STAINED_GLASS_PANE:7)
Block(-2,52,0,STAINED_GLASS_PANE:7)
Block(-2,52,1,CONCRETE:15)
Block(-2,52,2,CONCRETE:15)
Block(-2,52,3,CONCRETE:15)
Block(-2,52,4,CONCRETE:15)
Block(-2,52,5,CONCRETE:15)
Block(-2,52,6,STAINED_GLASS_PANE:7)
Block(-2,52,7,STAINED_GLASS_PANE:7)
Block(-2,52,8,CONCRETE:15)
Block(-2,53,-7,quark:iron_plate:1)
RandomBlock(-2,53,-5,minecraft:iron_bars:0,5,CONCRETE_POWDER:8,10,quark:limestone:1,15,quark:limestone,15,quark:world_stone_pavement:2,15,CONCRETE:8,100)
RandomBlock(-2,53,-4,minecraft:iron_bars:0,5,CONCRETE_POWDER:8,10,quark:limestone:1,15,quark:limestone,15,quark:world_stone_pavement:2,15,CONCRETE:8,100)
RandomBlock(-2,53,-3,minecraft:iron_bars:0,5,CONCRETE_POWDER:8,10,quark:limestone:1,15,quark:limestone,15,quark:world_stone_pavement:2,15,CONCRETE:8,100)
RandomBlock(-2,53,-2,minecraft:iron_bars:0,5,CONCRETE_POWDER:8,10,quark:limestone:1,15,quark:limestone,15,quark:world_stone_pavement:2,15,CONCRETE:8,100)
RandomBlock(-2,53,-1,minecraft:iron_bars:0,5,CONCRETE_POWDER:8,10,quark:limestone:1,15,quark:limestone,15,quark:world_stone_pavement:2,15,CONCRETE:8,100)
RandomBlock(-2,53,0,minecraft:iron_bars:0,5,CONCRETE_POWDER:8,10,quark:limestone:1,15,quark:limestone,15,quark:world_stone_pavement:2,15,CONCRETE:8,100)
RandomBlock(-2,53,1,minecraft:iron_bars:0,5,CONCRETE_POWDER:8,10,quark:limestone:1,15,quark:limestone,15,quark:world_stone_pavement:2,15,CONCRETE:8,100)
RandomBlock(-2,53,2,minecraft:iron_bars:0,5,CONCRETE_POWDER:8,10,quark:limestone:1,15,quark:limestone,15,quark:world_stone_pavement:2,15,CONCRETE:8,100)
RandomBlock(-2,53,3,minecraft:iron_bars:0,5,CONCRETE_POWDER:8,10,quark:limestone:1,15,quark:limestone,15,quark:world_stone_pavement:2,15,CONCRETE:8,100)
RandomBlock(-2,53,4,minecraft:iron_bars:0,5,CONCRETE_POWDER:8,10,quark:limestone:1,15,quark:limestone,15,quark:world_stone_pavement:2,15,CONCRETE:8,100)
RandomBlock(-2,53,5,minecraft:iron_bars:0,5,CONCRETE_POWDER:8,10,quark:limestone:1,15,quark:limestone,15,quark:world_stone_pavement:2,15,CONCRETE:8,100)
RandomBlock(-2,53,6,minecraft:iron_bars:0,5,CONCRETE_POWDER:8,10,quark:limestone:1,15,quark:limestone,15,quark:world_stone_pavement:2,15,CONCRETE:8,100)
RandomBlock(-2,53,7,minecraft:iron_bars:0,5,CONCRETE_POWDER:8,10,quark:limestone:1,15,quark:limestone,15,quark:world_stone_pavement:2,15,CONCRETE:8,100)
RandomBlock(-2,53,8,minecraft:iron_bars:0,5,CONCRETE_POWDER:8,10,quark:limestone:1,15,quark:limestone,15,quark:world_stone_pavement:2,15,CONCRETE:8,100)
RandomBlock(-2,54,-7,minecraft:iron_bars:0,5,CONCRETE_POWDER:8,10,quark:limestone:1,15,quark:limestone,15,quark:world_stone_pavement:2,15,CONCRETE:8,100)
RandomBlock(-2,54,-6,minecraft:iron_bars:0,5,CONCRETE_POWDER:8,10,quark:limestone:1,15,quark:limestone,15,quark:world_stone_pavement:2,15,CONCRETE:8,100)
RandomBlock(-2,54,-5,minecraft:iron_bars:0,5,CONCRETE_POWDER:8,10,quark:limestone:1,15,quark:limestone,15,quark:world_stone_pavement:2,15,CONCRETE:8,100)
RandomBlock(-2,54,-4,minecraft:iron_bars:0,5,CONCRETE_POWDER:8,10,quark:limestone:1,15,quark:limestone,15,quark:world_stone_pavement:2,15,CONCRETE:8,100)
RandomBlock(-2,54,-3,minecraft:iron_bars:0,5,CONCRETE_POWDER:8,10,quark:limestone:1,15,quark:limestone,15,quark:world_stone_pavement:2,15,CONCRETE:8,100)
RandomBlock(-2,54,-2,minecraft:iron_bars:0,5,CONCRETE_POWDER:8,10,quark:limestone:1,15,quark:limestone,15,quark:world_stone_pavement:2,15,CONCRETE:8,100)
RandomBlock(-2,54,-1,minecraft:iron_bars:0,5,CONCRETE_POWDER:8,10,quark:limestone:1,15,quark:limestone,15,quark:world_stone_pavement:2,15,CONCRETE:8,100)
RandomBlock(-2,54,0,minecraft:iron_bars:0,5,CONCRETE_POWDER:8,10,quark:limestone:1,15,quark:limestone,15,quark:world_stone_pavement:2,15,CONCRETE:8,100)
RandomBlock(-2,54,1,minecraft:iron_bars:0,5,CONCRETE_POWDER:8,10,quark:limestone:1,15,quark:limestone,15,quark:world_stone_pavement:2,15,CONCRETE:8,100)
RandomBlock(-2,54,2,minecraft:iron_bars:0,5,CONCRETE_POWDER:8,10,quark:limestone:1,15,quark:limestone,15,quark:world_stone_pavement:2,15,CONCRETE:8,100)
RandomBlock(-2,54,3,minecraft:iron_bars:0,5,CONCRETE_POWDER:8,10,quark:limestone:1,15,quark:limestone,15,quark:world_stone_pavement:2,15,CONCRETE:8,100)
RandomBlock(-2,54,4,minecraft:iron_bars:0,5,CONCRETE_POWDER:8,10,quark:limestone:1,15,quark:limestone,15,quark:world_stone_pavement:2,15,CONCRETE:8,100)
RandomBlock(-2,54,5,minecraft:iron_bars:0,5,CONCRETE_POWDER:8,10,quark:limestone:1,15,quark:limestone,15,quark:world_stone_pavement:2,15,CONCRETE:8,100)
RandomBlock(-2,54,6,minecraft:iron_bars:0,5,CONCRETE_POWDER:8,10,quark:limestone:1,15,quark:limestone,15,quark:world_stone_pavement:2,15,CONCRETE:8,100)
RandomBlock(-2,54,7,minecraft:iron_bars:0,5,CONCRETE_POWDER:8,10,quark:limestone:1,15,quark:limestone,15,quark:world_stone_pavement:2,15,CONCRETE:8,100)
RandomBlock(-2,54,8,minecraft:iron_bars:0,5,CONCRETE_POWDER:8,10,quark:limestone:1,15,quark:limestone,15,quark:world_stone_pavement:2,15,CONCRETE:8,100)
Block(-2,55,-6,STEP:8)
RandomBlock(-2,55,-5,minecraft:iron_bars:0,5,CONCRETE_POWDER:8,10,quark:limestone:1,15,quark:limestone,15,quark:world_stone_pavement:2,15,CONCRETE:8,100)
RandomBlock(-2,55,-4,minecraft:iron_bars:0,5,CONCRETE_POWDER:8,10,quark:limestone:1,15,quark:limestone,15,quark:world_stone_pavement:2,15,CONCRETE:8,100)
RandomBlock(-2,55,-3,minecraft:iron_bars:0,5,CONCRETE_POWDER:8,10,quark:limestone:1,15,quark:limestone,15,quark:world_stone_pavement:2,15,CONCRETE:8,100)
RandomBlock(-2,55,-2,minecraft:iron_bars:0,5,CONCRETE_POWDER:8,10,quark:limestone:1,15,quark:limestone,15,quark:world_stone_pavement:2,15,CONCRETE:8,100)
RandomBlock(-2,55,-1,minecraft:iron_bars:0,5,CONCRETE_POWDER:8,10,quark:limestone:1,15,quark:limestone,15,quark:world_stone_pavement:2,15,CONCRETE:8,100)
RandomBlock(-2,55,0,minecraft:iron_bars:0,5,CONCRETE_POWDER:8,10,quark:limestone:1,15,quark:limestone,15,quark:world_stone_pavement:2,15,CONCRETE:8,100)
RandomBlock(-2,55,1,minecraft:iron_bars:0,5,CONCRETE_POWDER:8,10,quark:limestone:1,15,quark:limestone,15,quark:world_stone_pavement:2,15,CONCRETE:8,100)
RandomBlock(-2,55,2,minecraft:iron_bars:0,5,CONCRETE_POWDER:8,10,quark:limestone:1,15,quark:limestone,15,quark:world_stone_pavement:2,15,CONCRETE:8,100)
RandomBlock(-2,55,3,minecraft:iron_bars:0,5,CONCRETE_POWDER:8,10,quark:limestone:1,15,quark:limestone,15,quark:world_stone_pavement:2,15,CONCRETE:8,100)
RandomBlock(-2,55,4,minecraft:iron_bars:0,5,CONCRETE_POWDER:8,10,quark:limestone:1,15,quark:limestone,15,quark:world_stone_pavement:2,15,CONCRETE:8,100)
RandomBlock(-2,55,5,minecraft:iron_bars:0,5,CONCRETE_POWDER:8,10,quark:limestone:1,15,quark:limestone,15,quark:world_stone_pavement:2,15,CONCRETE:8,100)
RandomBlock(-2,55,6,minecraft:iron_bars:0,5,CONCRETE_POWDER:8,10,quark:limestone:1,15,quark:limestone,15,quark:world_stone_pavement:2,15,CONCRETE:8,100)
RandomBlock(-2,55,7,minecraft:iron_bars:0,5,CONCRETE_POWDER:8,10,quark:limestone:1,15,quark:limestone,15,quark:world_stone_pavement:2,15,CONCRETE:8,100)
RandomBlock(-2,55,8,minecraft:iron_bars:0,5,CONCRETE_POWDER:8,10,quark:limestone:1,15,quark:limestone,15,quark:world_stone_pavement:2,15,CONCRETE:8,100)
Block(-2,56,-6,LEVER:4)
RandomBlock(-2,56,-5,minecraft:iron_bars:0,5,CONCRETE_POWDER:8,10,quark:limestone:1,15,quark:limestone,15,quark:world_stone_pavement:2,15,CONCRETE:8,100)
RandomBlock(-2,56,-4,minecraft:iron_bars:0,5,CONCRETE_POWDER:8,10,quark:limestone:1,15,quark:limestone,15,quark:world_stone_pavement:2,15,CONCRETE:8,100)
RandomBlock(-2,56,-3,minecraft:iron_bars:0,5,CONCRETE_POWDER:8,10,quark:limestone:1,15,quark:limestone,15,quark:world_stone_pavement:2,15,CONCRETE:8,100)
RandomBlock(-2,56,-2,minecraft:iron_bars:0,5,CONCRETE_POWDER:8,10,quark:limestone:1,15,quark:limestone,15,quark:world_stone_pavement:2,15,CONCRETE:8,100)
Block(-2,56,-1,STAINED_GLASS_PANE:7)
Block(-2,56,0,STAINED_GLASS_PANE:7)
RandomBlock(-2,56,1,minecraft:iron_bars:0,5,CONCRETE_POWDER:8,10,quark:limestone:1,15,quark:limestone,15,quark:world_stone_pavement:2,15,CONCRETE:8,100)
RandomBlock(-2,56,2,minecraft:iron_bars:0,5,CONCRETE_POWDER:8,10,quark:limestone:1,15,quark:limestone,15,quark:world_stone_pavement:2,15,CONCRETE:8,100)
RandomBlock(-2,56,3,minecraft:iron_bars:0,5,CONCRETE_POWDER:8,10,quark:limestone:1,15,quark:limestone,15,quark:world_stone_pavement:2,15,CONCRETE:8,100)
RandomBlock(-2,56,4,minecraft:iron_bars:0,5,CONCRETE_POWDER:8,10,quark:limestone:1,15,quark:limestone,15,quark:world_stone_pavement:2,15,CONCRETE:8,100)
RandomBlock(-2,56,5,minecraft:iron_bars:0,5,CONCRETE_POWDER:8,10,quark:limestone:1,15,quark:limestone,15,quark:world_stone_pavement:2,15,CONCRETE:8,100)
Block(-2,56,6,STAINED_GLASS_PANE:7)
Block(-2,56,7,STAINED_GLASS_PANE:7)
RandomBlock(-2,56,8,minecraft:iron_bars:0,5,CONCRETE_POWDER:8,10,quark:limestone:1,15,quark:limestone,15,quark:world_stone_pavement:2,15,CONCRETE:8,100)
RandomBlock(-2,57,-5,minecraft:iron_bars:0,5,CONCRETE_POWDER:8,10,quark:limestone:1,15,quark:limestone,15,quark:world_stone_pavement:2,15,CONCRETE:8,100)
RandomBlock(-2,57,-4,minecraft:iron_bars:0,5,CONCRETE_POWDER:8,10,quark:limestone:1,15,quark:limestone,15,quark:world_stone_pavement:2,15,CONCRETE:8,100)
RandomBlock(-2,57,-3,minecraft:iron_bars:0,5,CONCRETE_POWDER:8,10,quark:limestone:1,15,quark:limestone,15,quark:world_stone_pavement:2,15,CONCRETE:8,100)
RandomBlock(-2,57,-2,minecraft:iron_bars:0,5,CONCRETE_POWDER:8,10,quark:limestone:1,15,quark:limestone,15,quark:world_stone_pavement:2,15,CONCRETE:8,100)
RandomBlock(-2,57,-1,minecraft:iron_bars:0,5,CONCRETE_POWDER:8,10,quark:limestone:1,15,quark:limestone,15,quark:world_stone_pavement:2,15,CONCRETE:8,100)
RandomBlock(-2,57,0,minecraft:iron_bars:0,5,CONCRETE_POWDER:8,10,quark:limestone:1,15,quark:limestone,15,quark:world_stone_pavement:2,15,CONCRETE:8,100)
RandomBlock(-2,57,1,minecraft:iron_bars:0,5,CONCRETE_POWDER:8,10,quark:limestone:1,15,quark:limestone,15,quark:world_stone_pavement:2,15,CONCRETE:8,100)
RandomBlock(-2,57,2,minecraft:iron_bars:0,5,CONCRETE_POWDER:8,10,quark:limestone:1,15,quark:limestone,15,quark:world_stone_pavement:2,15,CONCRETE:8,100)
RandomBlock(-2,57,3,minecraft:iron_bars:0,5,CONCRETE_POWDER:8,10,quark:limestone:1,15,quark:limestone,15,quark:world_stone_pavement:2,15,CONCRETE:8,100)
RandomBlock(-2,57,4,minecraft:iron_bars:0,5,CONCRETE_POWDER:8,10,quark:limestone:1,15,quark:limestone,15,quark:world_stone_pavement:2,15,CONCRETE:8,100)
RandomBlock(-2,57,5,minecraft:iron_bars:0,5,CONCRETE_POWDER:8,10,quark:limestone:1,15,quark:limestone,15,quark:world_stone_pavement:2,15,CONCRETE:8,100)
RandomBlock(-2,57,6,minecraft:iron_bars:0,5,CONCRETE_POWDER:8,10,quark:limestone:1,15,quark:limestone,15,quark:world_stone_pavement:2,15,CONCRETE:8,100)
RandomBlock(-2,57,7,minecraft:iron_bars:0,5,CONCRETE_POWDER:8,10,quark:limestone:1,15,quark:limestone,15,quark:world_stone_pavement:2,15,CONCRETE:8,100)
RandomBlock(-2,57,8,minecraft:iron_bars:0,5,CONCRETE_POWDER:8,10,quark:limestone:1,15,quark:limestone,15,quark:world_stone_pavement:2,15,CONCRETE:8,100)
Block(-2,58,-7,STEP:5)
Block(-2,58,-6,STEP:5)
RandomBlock(-2,58,-5,minecraft:iron_bars:0,5,CONCRETE_POWDER:8,10,quark:limestone:1,15,quark:limestone,15,quark:world_stone_pavement:2,15,CONCRETE:8,100)
RandomBlock(-2,58,-4,minecraft:iron_bars:0,5,CONCRETE_POWDER:8,10,quark:limestone:1,15,quark:limestone,15,quark:world_stone_pavement:2,15,CONCRETE:8,100)
RandomBlock(-2,58,-3,minecraft:iron_bars:0,5,CONCRETE_POWDER:8,10,quark:limestone:1,15,quark:limestone,15,quark:world_stone_pavement:2,15,CONCRETE:8,100)
RandomBlock(-2,58,-2,minecraft:iron_bars:0,5,CONCRETE_POWDER:8,10,quark:limestone:1,15,quark:limestone,15,quark:world_stone_pavement:2,15,CONCRETE:8,100)
RandomBlock(-2,58,-1,minecraft:iron_bars:0,5,CONCRETE_POWDER:8,10,quark:limestone:1,15,quark:limestone,15,quark:world_stone_pavement:2,15,CONCRETE:8,100)
RandomBlock(-2,58,0,minecraft:iron_bars:0,5,CONCRETE_POWDER:8,10,quark:limestone:1,15,quark:limestone,15,quark:world_stone_pavement:2,15,CONCRETE:8,100)
RandomBlock(-2,58,1,minecraft:iron_bars:0,5,CONCRETE_POWDER:8,10,quark:limestone:1,15,quark:limestone,15,quark:world_stone_pavement:2,15,CONCRETE:8,100)
RandomBlock(-2,58,2,minecraft:iron_bars:0,5,CONCRETE_POWDER:8,10,quark:limestone:1,15,quark:limestone,15,quark:world_stone_pavement:2,15,CONCRETE:8,100)
RandomBlock(-2,58,3,minecraft:iron_bars:0,5,CONCRETE_POWDER:8,10,quark:limestone:1,15,quark:limestone,15,quark:world_stone_pavement:2,15,CONCRETE:8,100)
RandomBlock(-2,58,4,minecraft:iron_bars:0,5,CONCRETE_POWDER:8,10,quark:limestone:1,15,quark:limestone,15,quark:world_stone_pavement:2,15,CONCRETE:8,100)
RandomBlock(-2,58,5,minecraft:iron_bars:0,5,CONCRETE_POWDER:8,10,quark:limestone:1,15,quark:limestone,15,quark:world_stone_pavement:2,15,CONCRETE:8,100)
RandomBlock(-2,58,6,minecraft:iron_bars:0,5,CONCRETE_POWDER:8,10,quark:limestone:1,15,quark:limestone,15,quark:world_stone_pavement:2,15,CONCRETE:8,100)
RandomBlock(-2,58,7,minecraft:iron_bars:0,5,CONCRETE_POWDER:8,10,quark:limestone:1,15,quark:limestone,15,quark:world_stone_pavement:2,15,CONCRETE:8,100)
RandomBlock(-2,58,8,minecraft:iron_bars:0,5,CONCRETE_POWDER:8,10,quark:limestone:1,15,quark:limestone,15,quark:world_stone_pavement:2,15,CONCRETE:8,100)
Block(-2,59,-7,quark:iron_plate:1)
Block(-2,59,-5,IRON_FENCE:0)
Block(-2,59,-4,IRON_FENCE:0)
Block(-2,59,-3,IRON_FENCE:0)
RandomBlock(-2,59,-2,minecraft:iron_bars:0,5,CONCRETE_POWDER:8,10,quark:limestone:1,15,quark:limestone,15,quark:world_stone_pavement:2,15,CONCRETE:8,100)
Block(-2,59,-1,IRON_FENCE:0)
Block(-2,59,0,IRON_FENCE:0)
Block(-2,59,1,IRON_FENCE:0)
Block(-2,59,2,IRON_FENCE:0)
Block(-2,59,3,IRON_FENCE:0)
RandomBlock(-2,59,4,minecraft:iron_bars:0,5,CONCRETE_POWDER:8,10,quark:limestone:1,15,quark:limestone,15,quark:world_stone_pavement:2,15,CONCRETE:8,100)
Block(-2,59,5,IRON_FENCE:0)
Block(-2,59,6,IRON_FENCE:0)
Block(-2,59,7,IRON_FENCE:0)
Block(-2,59,8,IRON_FENCE:0)
Block(-2,61,0,minecraft:iron_bars:0)
Block(-2,62,0,minecraft:iron_bars:0)
Block(-1,43,-2,STEP:13)
Block(-1,43,-1,STEP:8)
Block(-1,43,0,STEP:8)
Block(-1,43,1,STEP:8)
Block(-1,43,2,STEP:8)
Block(-1,43,3,STEP:8)
RandomBlock(-1,44,-7,minecraft:iron_bars:0,5,STAINED_CLAY:15,5,STAINED_CLAY:7,5,quark:iron_plate_slab:8,15,quark:world_stone_pavement:2,15,STAINED_CLAY:9,100)
RandomBlock(-1,44,-6,minecraft:iron_bars:0,5,STAINED_CLAY:15,5,STAINED_CLAY:7,5,quark:iron_plate_slab:8,15,quark:world_stone_pavement:2,15,STAINED_CLAY:9,100)
RandomBlock(-1,44,-5,minecraft:iron_bars:0,5,STAINED_CLAY:15,5,STAINED_CLAY:7,5,quark:iron_plate_slab:8,15,quark:world_stone_pavement:2,15,STAINED_CLAY:9,100)
RandomBlock(-1,44,-4,minecraft:iron_bars:0,5,STAINED_CLAY:15,5,STAINED_CLAY:7,5,quark:iron_plate_slab:8,15,quark:world_stone_pavement:2,15,STAINED_CLAY:9,100)
RandomBlock(-1,44,-3,minecraft:iron_bars:0,5,STAINED_CLAY:15,5,STAINED_CLAY:7,5,quark:iron_plate_slab:8,15,quark:world_stone_pavement:2,15,STAINED_CLAY:9,100)
RandomBlock(-1,44,-2,minecraft:iron_bars:0,5,STAINED_CLAY:15,5,STAINED_CLAY:7,5,quark:iron_plate_slab:8,15,quark:world_stone_pavement:2,15,STAINED_CLAY:9,100)
RandomBlock(-1,44,-1,minecraft:iron_bars:0,5,STAINED_CLAY:15,5,STAINED_CLAY:7,5,quark:iron_plate_slab:8,15,quark:world_stone_pavement:2,15,STAINED_CLAY:9,100)
RandomBlock(-1,44,0,minecraft:iron_bars:0,5,STAINED_CLAY:15,5,STAINED_CLAY:7,5,quark:iron_plate_slab:8,15,quark:world_stone_pavement:2,15,STAINED_CLAY:9,100)
RandomBlock(-1,44,1,minecraft:iron_bars:0,5,STAINED_CLAY:15,5,STAINED_CLAY:7,5,quark:iron_plate_slab:8,15,quark:world_stone_pavement:2,15,STAINED_CLAY:9,100)
RandomBlock(-1,44,2,minecraft:iron_bars:0,5,STAINED_CLAY:15,5,STAINED_CLAY:7,5,quark:iron_plate_slab:8,15,quark:world_stone_pavement:2,15,STAINED_CLAY:9,100)
RandomBlock(-1,44,3,minecraft:iron_bars:0,5,STAINED_CLAY:15,5,STAINED_CLAY:7,5,quark:iron_plate_slab:8,15,quark:world_stone_pavement:2,15,STAINED_CLAY:9,100)
Block(-1,45,2,STONE:6)
Block(-1,45,3,IRON_FENCE:0)
Block(-1,46,2,STONE:6)
Block(-1,47,2,STONE:6)
Block(-1,48,2,STONE:6)
Block(-1,49,-3,quark:iron_plate:1)
Block(-1,49,-1,STONE:6)
Block(-1,49,2,STONE:6)
Block(-1,49,7,STONE:6)
RandomBlock(-1,50,-7,minecraft:iron_bars:0,5,STAINED_CLAY:15,5,STAINED_CLAY:7,5,quark:iron_plate_slab:8,15,quark:world_stone_pavement:2,15,STAINED_CLAY:9,100)
RandomBlock(-1,50,-6,minecraft:iron_bars:0,5,STAINED_CLAY:15,5,STAINED_CLAY:7,5,quark:iron_plate_slab:8,15,quark:world_stone_pavement:2,15,STAINED_CLAY:9,100)
RandomBlock(-1,50,-5,minecraft:iron_bars:0,5,CONCRETE_POWDER:8,10,quark:limestone:1,15,quark:limestone,15,quark:world_stone_pavement:2,15,CONCRETE:8,100)
RandomBlock(-1,50,-4,minecraft:iron_bars:0,5,CONCRETE_POWDER:8,10,quark:limestone:1,15,quark:limestone,15,quark:world_stone_pavement:2,15,CONCRETE:8,100)
RandomBlock(-1,50,-3,minecraft:iron_bars:0,5,CONCRETE_POWDER:8,10,quark:limestone:1,15,quark:limestone,15,quark:world_stone_pavement:2,15,CONCRETE:8,100)
RandomBlock(-1,50,-2,minecraft:iron_bars:0,5,CONCRETE_POWDER:8,10,quark:limestone:1,15,quark:limestone,15,quark:world_stone_pavement:2,15,CONCRETE:8,100)
RandomBlock(-1,50,-1,minecraft:iron_bars:0,5,CONCRETE_POWDER:8,10,quark:limestone:1,15,quark:limestone,15,quark:world_stone_pavement:2,15,CONCRETE:8,100)
RandomBlock(-1,50,0,minecraft:iron_bars:0,5,CONCRETE_POWDER:8,10,quark:limestone:1,15,quark:limestone,15,quark:world_stone_pavement:2,15,CONCRETE:8,100)
RandomBlock(-1,50,1,minecraft:iron_bars:0,5,CONCRETE_POWDER:8,10,quark:limestone:1,15,quark:limestone,15,quark:world_stone_pavement:2,15,CONCRETE:8,100)
RandomBlock(-1,50,2,minecraft:iron_bars:0,5,CONCRETE_POWDER:8,10,quark:limestone:1,15,quark:limestone,15,quark:world_stone_pavement:2,15,CONCRETE:8,100)
RandomBlock(-1,50,3,minecraft:iron_bars:0,5,CONCRETE_POWDER:8,10,quark:limestone:1,15,quark:limestone,15,quark:world_stone_pavement:2,15,CONCRETE:8,100)
RandomBlock(-1,50,4,minecraft:iron_bars:0,5,CONCRETE_POWDER:8,10,quark:limestone:1,15,quark:limestone,15,quark:world_stone_pavement:2,15,CONCRETE:8,100)
RandomBlock(-1,50,5,minecraft:iron_bars:0,5,CONCRETE_POWDER:8,10,quark:limestone:1,15,quark:limestone,15,quark:world_stone_pavement:2,15,CONCRETE:8,100)
RandomBlock(-1,50,6,minecraft:iron_bars:0,5,CONCRETE_POWDER:8,10,quark:limestone:1,15,quark:limestone,15,quark:world_stone_pavement:2,15,CONCRETE:8,100)
RandomBlock(-1,50,7,minecraft:iron_bars:0,5,CONCRETE_POWDER:8,10,quark:limestone:1,15,quark:limestone,15,quark:world_stone_pavement:2,15,CONCRETE:8,100)
RandomBlock(-1,50,8,minecraft:iron_bars:0,5,CONCRETE_POWDER:8,10,quark:limestone:1,15,quark:limestone,15,quark:world_stone_pavement:2,15,CONCRETE:8,100)
RandomBlock(-1,51,-5,minecraft:iron_bars:0,5,CONCRETE_POWDER:8,10,quark:limestone:1,15,quark:limestone,15,quark:world_stone_pavement:2,15,CONCRETE:8,100)
Block(-1,51,-3,MOB_SPAWNER:0,../../ruins_spawners/industrial_multi.nbt)
Block(-1,51,-2,SMOOTH_STAIRS:6)
Block(-1,51,-1,SMOOTH_STAIRS:3)
Block(-1,52,-5,CONCRETE:15)
Block(-1,52,-3,SMOOTH_STAIRS:6)
Block(-1,52,-2,SMOOTH_STAIRS:3)
Block(-1,53,-7,quark:iron_plate:1)
RandomBlock(-1,53,-5,minecraft:iron_bars:0,5,CONCRETE_POWDER:8,10,quark:limestone:1,15,quark:limestone,15,quark:world_stone_pavement:2,15,CONCRETE:8,100)
Block(-1,53,-4,SMOOTH_STAIRS:6)
Block(-1,53,-3,SMOOTH_STAIRS:3)
RandomBlock(-1,54,-7,minecraft:iron_bars:0,5,CONCRETE_POWDER:8,10,quark:limestone:1,15,quark:limestone,15,quark:world_stone_pavement:2,15,CONCRETE:8,100)
RandomBlock(-1,54,-6,minecraft:iron_bars:0,5,CONCRETE_POWDER:8,10,quark:limestone:1,15,quark:limestone,15,quark:world_stone_pavement:2,15,CONCRETE:8,100)
RandomBlock(-1,54,-5,minecraft:iron_bars:0,5,CONCRETE_POWDER:8,10,quark:limestone:1,15,quark:limestone,15,quark:world_stone_pavement:2,15,CONCRETE:8,100)
Block(-1,54,-4,SMOOTH_STAIRS:3)
RandomBlock(-1,54,0,minecraft:iron_bars:0,5,CONCRETE_POWDER:8,10,quark:limestone:1,15,quark:limestone,15,quark:world_stone_pavement:2,15,CONCRETE:8,100)
RandomBlock(-1,54,1,minecraft:iron_bars:0,5,CONCRETE_POWDER:8,10,quark:limestone:1,15,quark:limestone,15,quark:world_stone_pavement:2,15,CONCRETE:8,100)
RandomBlock(-1,54,2,minecraft:iron_bars:0,5,CONCRETE_POWDER:8,10,quark:limestone:1,15,quark:limestone,15,quark:world_stone_pavement:2,15,CONCRETE:8,100)
RandomBlock(-1,54,3,minecraft:iron_bars:0,5,CONCRETE_POWDER:8,10,quark:limestone:1,15,quark:limestone,15,quark:world_stone_pavement:2,15,CONCRETE:8,100)
RandomBlock(-1,54,4,minecraft:iron_bars:0,5,CONCRETE_POWDER:8,10,quark:limestone:1,15,quark:limestone,15,quark:world_stone_pavement:2,15,CONCRETE:8,100)
RandomBlock(-1,54,5,minecraft:iron_bars:0,5,CONCRETE_POWDER:8,10,quark:limestone:1,15,quark:limestone,15,quark:world_stone_pavement:2,15,CONCRETE:8,100)
RandomBlock(-1,54,6,minecraft:iron_bars:0,5,CONCRETE_POWDER:8,10,quark:limestone:1,15,quark:limestone,15,quark:world_stone_pavement:2,15,CONCRETE:8,100)
RandomBlock(-1,54,7,minecraft:iron_bars:0,5,CONCRETE_POWDER:8,10,quark:limestone:1,15,quark:limestone,15,quark:world_stone_pavement:2,15,CONCRETE:8,100)
RandomBlock(-1,54,8,minecraft:iron_bars:0,5,CONCRETE_POWDER:8,10,quark:limestone:1,15,quark:limestone,15,quark:world_stone_pavement:2,15,CONCRETE:8,100)
RandomBlock(-1,55,-6,minecraft:iron_bars:0,5,CONCRETE_POWDER:8,10,quark:limestone:1,15,quark:limestone,15,quark:world_stone_pavement:2,15,CONCRETE:8,100)
Block(-1,55,0,IRON_FENCE:0)
Block(-1,55,2,quark:iron_plate_stairs:7)
Block(-1,55,3,quark:iron_plate_slab:8)
Block(-1,55,4,quark:iron_plate_slab:8)
Block(-1,55,5,quark:iron_plate_stairs:6)
Block(-1,55,6,ANVIL:0)
RandomBlock(-1,55,7,minecraft:planks:5,5,minecraft:planks:5,10,minecraft:planks:5,100)
Block(-1,55,8,quark:iron_plate_slab:8)
RandomBlock(-1,56,-6,minecraft:iron_bars:0,5,CONCRETE_POWDER:8,10,quark:limestone:1,15,quark:limestone,15,quark:world_stone_pavement:2,15,CONCRETE:8,100)
Block(-1,56,2,TRIPWIRE_HOOK:3)
Block(-1,56,3,TRIPWIRE_HOOK:3)
Block(-1,56,4,TRIPWIRE_HOOK:3)
RandomBlock(-1,57,-6,minecraft:iron_bars:0,5,CONCRETE_POWDER:8,10,quark:limestone:1,15,quark:limestone,15,quark:world_stone_pavement:2,15,CONCRETE:8,100)
Block(-1,58,-7,STEP:5)
Block(-1,58,-6,STEP:5)
Block(-1,58,-5,STEP:5)
Block(-1,58,-4,STEP:5)
Block(-1,58,-3,STEP:5)
RandomBlock(-1,58,-2,SMOOTH_BRICK:0,40,SMOOTH_BRICK:1,20,SMOOTH_BRICK:2,30,SMOOTH_BRICK:0,100)
RandomBlock(-1,58,-1,SMOOTH_BRICK:0,40,SMOOTH_BRICK:1,20,SMOOTH_BRICK:2,30,SMOOTH_BRICK:0,100)
Block(-1,58,0,STEP:5)
Block(-1,58,1,STEP:5)
RandomBlock(-1,58,2,SMOOTH_BRICK:0,40,SMOOTH_BRICK:1,20,SMOOTH_BRICK:2,30,SMOOTH_BRICK:0,100)
RandomBlock(-1,58,3,SMOOTH_BRICK:0,40,SMOOTH_BRICK:1,20,SMOOTH_BRICK:2,30,SMOOTH_BRICK:0,100)
Block(-1,58,4,STEP:5)
Block(-1,58,5,STEP:5)
RandomBlock(-1,58,6,SMOOTH_BRICK:0,40,SMOOTH_BRICK:1,20,SMOOTH_BRICK:2,30,SMOOTH_BRICK:0,100)
RandomBlock(-1,58,7,SMOOTH_BRICK:0,40,SMOOTH_BRICK:1,20,SMOOTH_BRICK:2,30,SMOOTH_BRICK:0,100)
Block(-1,58,8,STEP:5)
Block(-1,59,-7,quark:iron_plate:1)
RandomBlock(-1,59,0,minecraft:iron_bars:0,5,CONCRETE_POWDER:8,10,quark:limestone:1,15,quark:limestone,15,quark:world_stone_pavement:2,15,CONCRETE:8,100)
Block(-1,60,0,minecraft:iron_bars:0)
Block(-1,61,0,minecraft:iron_bars:0)
Block(-1,61,3,SMOOTH_STAIRS:7)
RandomBlock(-1,62,-7,CONCRETE_POWDER:7,25,CONCRETE:7,100)
RandomBlock(-1,62,-6,CONCRETE_POWDER:7,25,CONCRETE:7,100)
RandomBlock(-1,62,-5,CONCRETE_POWDER:7,25,CONCRETE:7,100)
RandomBlock(-1,62,-4,CONCRETE_POWDER:7,25,CONCRETE:7,100)
RandomBlock(-1,62,-3,CONCRETE_POWDER:7,25,CONCRETE:7,100)
RandomBlock(-1,62,-2,CONCRETE_POWDER:7,25,CONCRETE:7,100)
RandomBlock(-1,62,-1,CONCRETE_POWDER:7,25,CONCRETE:7,100)
RandomBlock(-1,62,0,CONCRETE_POWDER:7,25,CONCRETE:7,100)
RandomBlock(-1,62,1,CONCRETE_POWDER:7,25,CONCRETE:7,100)
RandomBlock(-1,62,2,CONCRETE_POWDER:7,25,CONCRETE:7,100)
Block(-1,62,3,SMOOTH_STAIRS:3)
Block(0,43,-1,STEP:8)
Block(0,43,0,STEP:8)
Block(0,43,1,STEP:8)
Block(0,43,2,STEP:8)
Block(0,43,3,STEP:8)
RandomBlock(0,44,-7,minecraft:iron_bars:0,5,STAINED_CLAY:15,5,STAINED_CLAY:7,5,quark:iron_plate_slab:8,15,quark:world_stone_pavement:2,15,STAINED_CLAY:9,100)
RandomBlock(0,44,-6,minecraft:iron_bars:0,5,STAINED_CLAY:15,5,STAINED_CLAY:7,5,quark:iron_plate_slab:8,15,quark:world_stone_pavement:2,15,STAINED_CLAY:9,100)
RandomBlock(0,44,-5,minecraft:iron_bars:0,5,STAINED_CLAY:15,5,STAINED_CLAY:7,5,quark:iron_plate_slab:8,15,quark:world_stone_pavement:2,15,STAINED_CLAY:9,100)
RandomBlock(0,44,-4,minecraft:iron_bars:0,5,STAINED_CLAY:15,5,STAINED_CLAY:7,5,quark:iron_plate_slab:8,15,quark:world_stone_pavement:2,15,STAINED_CLAY:9,100)
RandomBlock(0,44,-3,minecraft:iron_bars:0,5,STAINED_CLAY:15,5,STAINED_CLAY:7,5,quark:iron_plate_slab:8,15,quark:world_stone_pavement:2,15,STAINED_CLAY:9,100)
RandomBlock(0,44,-2,minecraft:iron_bars:0,5,STAINED_CLAY:15,5,STAINED_CLAY:7,5,quark:iron_plate_slab:8,15,quark:world_stone_pavement:2,15,STAINED_CLAY:9,100)
RandomBlock(0,44,-1,minecraft:iron_bars:0,5,STAINED_CLAY:15,5,STAINED_CLAY:7,5,quark:iron_plate_slab:8,15,quark:world_stone_pavement:2,15,STAINED_CLAY:9,100)
RandomBlock(0,44,0,minecraft:iron_bars:0,5,STAINED_CLAY:15,5,STAINED_CLAY:7,5,quark:iron_plate_slab:8,15,quark:world_stone_pavement:2,15,STAINED_CLAY:9,100)
RandomBlock(0,44,1,minecraft:iron_bars:0,5,STAINED_CLAY:15,5,STAINED_CLAY:7,5,quark:iron_plate_slab:8,15,quark:world_stone_pavement:2,15,STAINED_CLAY:9,100)
RandomBlock(0,44,2,minecraft:iron_bars:0,5,STAINED_CLAY:15,5,STAINED_CLAY:7,5,quark:iron_plate_slab:8,15,quark:world_stone_pavement:2,15,STAINED_CLAY:9,100)
RandomBlock(0,44,3,minecraft:iron_bars:0,5,STAINED_CLAY:15,5,STAINED_CLAY:7,5,quark:iron_plate_slab:8,15,quark:world_stone_pavement:2,15,STAINED_CLAY:9,100)
Block(0,45,-1,SMOOTH_STAIRS:5)
Block(0,45,0,SMOOTH_STAIRS:5)
Block(0,45,3,IRON_FENCE:0)
Block(0,49,-7,quark:iron_plate:1)
Block(0,49,-6,quark:iron_plate:1)
Block(0,49,-5,quark:iron_plate:1)
Block(0,49,-4,quark:iron_plate:1)
Block(0,49,-3,quark:iron_plate:1)
Block(0,49,-1,STONE:6)
Block(0,49,0,STONE:6)
Block(0,49,1,STONE:6)
Block(0,49,2,STONE:6)
Block(0,49,3,STONE:6)
Block(0,49,4,STONE:6)
Block(0,49,5,STONE:6)
Block(0,49,6,STONE:6)
Block(0,49,7,STONE:6)
RandomBlock(0,50,-7,minecraft:iron_bars:0,5,STAINED_CLAY:15,5,STAINED_CLAY:7,5,quark:iron_plate_slab:8,15,quark:world_stone_pavement:2,15,STAINED_CLAY:9,100)
RandomBlock(0,50,-6,minecraft:iron_bars:0,5,STAINED_CLAY:15,5,STAINED_CLAY:7,5,quark:iron_plate_slab:8,15,quark:world_stone_pavement:2,15,STAINED_CLAY:9,100)
RandomBlock(0,50,-5,minecraft:iron_bars:0,5,CONCRETE_POWDER:8,10,quark:limestone:1,15,quark:limestone,15,quark:world_stone_pavement:2,15,CONCRETE:8,100)
RandomBlock(0,50,-4,minecraft:iron_bars:0,5,CONCRETE_POWDER:8,10,quark:limestone:1,15,quark:limestone,15,quark:world_stone_pavement:2,15,CONCRETE:8,100)
RandomBlock(0,50,-3,minecraft:iron_bars:0,5,CONCRETE_POWDER:8,10,quark:limestone:1,15,quark:limestone,15,quark:world_stone_pavement:2,15,CONCRETE:8,100)
RandomBlock(0,50,-2,minecraft:iron_bars:0,5,CONCRETE_POWDER:8,10,quark:limestone:1,15,quark:limestone,15,quark:world_stone_pavement:2,15,CONCRETE:8,100)
RandomBlock(0,50,-1,minecraft:iron_bars:0,5,CONCRETE_POWDER:8,10,quark:limestone:1,15,quark:limestone,15,quark:world_stone_pavement:2,15,CONCRETE:8,100)
RandomBlock(0,50,0,minecraft:iron_bars:0,5,CONCRETE_POWDER:8,10,quark:limestone:1,15,quark:limestone,15,quark:world_stone_pavement:2,15,CONCRETE:8,100)
RandomBlock(0,50,1,minecraft:iron_bars:0,5,CONCRETE_POWDER:8,10,quark:limestone:1,15,quark:limestone,15,quark:world_stone_pavement:2,15,CONCRETE:8,100)
RandomBlock(0,50,2,minecraft:iron_bars:0,5,CONCRETE_POWDER:8,10,quark:limestone:1,15,quark:limestone,15,quark:world_stone_pavement:2,15,CONCRETE:8,100)
RandomBlock(0,50,3,minecraft:iron_bars:0,5,CONCRETE_POWDER:8,10,quark:limestone:1,15,quark:limestone,15,quark:world_stone_pavement:2,15,CONCRETE:8,100)
RandomBlock(0,50,4,minecraft:iron_bars:0,5,CONCRETE_POWDER:8,10,quark:limestone:1,15,quark:limestone,15,quark:world_stone_pavement:2,15,CONCRETE:8,100)
RandomBlock(0,50,5,minecraft:iron_bars:0,5,CONCRETE_POWDER:8,10,quark:limestone:1,15,quark:limestone,15,quark:world_stone_pavement:2,15,CONCRETE:8,100)
RandomBlock(0,50,6,minecraft:iron_bars:0,5,CONCRETE_POWDER:8,10,quark:limestone:1,15,quark:limestone,15,quark:world_stone_pavement:2,15,CONCRETE:8,100)
RandomBlock(0,50,7,minecraft:iron_bars:0,5,CONCRETE_POWDER:8,10,quark:limestone:1,15,quark:limestone,15,quark:world_stone_pavement:2,15,CONCRETE:8,100)
RandomBlock(0,50,8,minecraft:iron_bars:0,5,CONCRETE_POWDER:8,10,quark:limestone:1,15,quark:limestone,15,quark:world_stone_pavement:2,15,CONCRETE:8,100)
RandomBlock(0,51,-5,minecraft:iron_bars:0,5,CONCRETE_POWDER:8,10,quark:limestone:1,15,quark:limestone,15,quark:world_stone_pavement:2,15,CONCRETE:8,100)
RandomBlock(0,51,-1,minecraft:iron_bars:0,5,STAINED_CLAY:15,5,STAINED_CLAY:7,5,quark:iron_plate_slab:8,15,quark:world_stone_pavement:2,15,STAINED_CLAY:9,100)
RandomBlock(0,51,3,minecraft:iron_bars:0,5,STAINED_CLAY:15,5,STAINED_CLAY:7,5,quark:iron_plate_slab:8,15,quark:world_stone_pavement:2,15,STAINED_CLAY:9,100)
RandomBlock(0,51,7,minecraft:iron_bars:0,5,STAINED_CLAY:15,5,STAINED_CLAY:7,5,quark:iron_plate_slab:8,15,quark:world_stone_pavement:2,15,STAINED_CLAY:9,100)
Block(0,52,-5,CONCRETE:15)
Block(0,52,-1,IRON_FENCE:0)
Block(0,52,3,IRON_FENCE:0)
Block(0,52,7,IRON_FENCE:0)
Block(0,53,-7,quark:iron_plate:1)
RandomBlock(0,53,-5,minecraft:iron_bars:0,5,CONCRETE_POWDER:8,10,quark:limestone:1,15,quark:limestone,15,quark:world_stone_pavement:2,15,CONCRETE:8,100)
RandomBlock(0,54,-7,minecraft:iron_bars:0,5,CONCRETE_POWDER:8,10,quark:limestone:1,15,quark:limestone,15,quark:world_stone_pavement:2,15,CONCRETE:8,100)
RandomBlock(0,54,-6,minecraft:iron_bars:0,5,CONCRETE_POWDER:8,10,quark:limestone:1,15,quark:limestone,15,quark:world_stone_pavement:2,15,CONCRETE:8,100)
RandomBlock(0,54,-5,minecraft:iron_bars:0,5,CONCRETE_POWDER:8,10,quark:limestone:1,15,quark:limestone,15,quark:world_stone_pavement:2,15,CONCRETE:8,100)
RandomBlock(0,54,-4,minecraft:iron_bars:0,5,CONCRETE_POWDER:8,10,quark:limestone:1,15,quark:limestone,15,quark:world_stone_pavement:2,15,CONCRETE:8,100)
RandomBlock(0,54,-3,minecraft:iron_bars:0,5,CONCRETE_POWDER:8,10,quark:limestone:1,15,quark:limestone,15,quark:world_stone_pavement:2,15,CONCRETE:8,100)
RandomBlock(0,54,-2,minecraft:iron_bars:0,5,CONCRETE_POWDER:8,10,quark:limestone:1,15,quark:limestone,15,quark:world_stone_pavement:2,15,CONCRETE:8,100)
RandomBlock(0,54,-1,minecraft:iron_bars:0,5,CONCRETE_POWDER:8,10,quark:limestone:1,15,quark:limestone,15,quark:world_stone_pavement:2,15,CONCRETE:8,100)
RandomBlock(0,54,0,minecraft:iron_bars:0,5,CONCRETE_POWDER:8,10,quark:limestone:1,15,quark:limestone,15,quark:world_stone_pavement:2,15,CONCRETE:8,100)
RandomBlock(0,54,1,minecraft:iron_bars:0,5,CONCRETE_POWDER:8,10,quark:limestone:1,15,quark:limestone,15,quark:world_stone_pavement:2,15,CONCRETE:8,100)
RandomBlock(0,54,2,minecraft:iron_bars:0,5,CONCRETE_POWDER:8,10,quark:limestone:1,15,quark:limestone,15,quark:world_stone_pavement:2,15,CONCRETE:8,100)
RandomBlock(0,54,3,minecraft:iron_bars:0,5,CONCRETE_POWDER:8,10,quark:limestone:1,15,quark:limestone,15,quark:world_stone_pavement:2,15,CONCRETE:8,100)
RandomBlock(0,54,4,minecraft:iron_bars:0,5,CONCRETE_POWDER:8,10,quark:limestone:1,15,quark:limestone,15,quark:world_stone_pavement:2,15,CONCRETE:8,100)
RandomBlock(0,54,5,minecraft:iron_bars:0,5,CONCRETE_POWDER:8,10,quark:limestone:1,15,quark:limestone,15,quark:world_stone_pavement:2,15,CONCRETE:8,100)
RandomBlock(0,54,6,minecraft:iron_bars:0,5,CONCRETE_POWDER:8,10,quark:limestone:1,15,quark:limestone,15,quark:world_stone_pavement:2,15,CONCRETE:8,100)
RandomBlock(0,54,7,minecraft:iron_bars:0,5,CONCRETE_POWDER:8,10,quark:limestone:1,15,quark:limestone,15,quark:world_stone_pavement:2,15,CONCRETE:8,100)
RandomBlock(0,54,8,minecraft:iron_bars:0,5,CONCRETE_POWDER:8,10,quark:limestone:1,15,quark:limestone,15,quark:world_stone_pavement:2,15,CONCRETE:8,100)
Block(0,55,-6,IRON_FENCE:0)
Block(0,56,-6,IRON_FENCE:0)
Block(0,57,-6,IRON_FENCE:0)
RandomBlock(0,58,-7,SMOOTH_BRICK:0,40,SMOOTH_BRICK:1,20,SMOOTH_BRICK:2,30,SMOOTH_BRICK:0,100)
Block(0,58,-6,STEP:5)
Block(0,58,-5,STEP:5)
Block(0,58,-4,STEP:5)
RandomBlock(0,58,-3,SMOOTH_BRICK:0,40,SMOOTH_BRICK:1,20,SMOOTH_BRICK:2,30,SMOOTH_BRICK:0,100)
Block(0,58,-2,REDSTONE_LAMP_OFF:0)
Block(0,58,-1,REDSTONE_LAMP_OFF:0)
RandomBlock(0,58,0,SMOOTH_BRICK:0,40,SMOOTH_BRICK:1,20,SMOOTH_BRICK:2,30,SMOOTH_BRICK:0,100)
RandomBlock(0,58,1,SMOOTH_BRICK:0,40,SMOOTH_BRICK:1,20,SMOOTH_BRICK:2,30,SMOOTH_BRICK:0,100)
Block(0,58,2,REDSTONE_LAMP_OFF:0)
Block(0,58,3,REDSTONE_LAMP_OFF:0)
RandomBlock(0,58,4,SMOOTH_BRICK:0,40,SMOOTH_BRICK:1,20,SMOOTH_BRICK:2,30,SMOOTH_BRICK:0,100)
RandomBlock(0,58,5,SMOOTH_BRICK:0,40,SMOOTH_BRICK:1,20,SMOOTH_BRICK:2,30,SMOOTH_BRICK:0,100)
Block(0,58,6,REDSTONE_LAMP_OFF:0)
Block(0,58,7,REDSTONE_LAMP_OFF:0)
RandomBlock(0,58,8,SMOOTH_BRICK:0,40,SMOOTH_BRICK:1,20,SMOOTH_BRICK:2,30,SMOOTH_BRICK:0,100)
Block(0,59,-7,quark:iron_plate:1)
Block(0,59,-6,SMOOTH_STAIRS:3)
Block(0,59,-5,STEP:5)
Block(0,59,-4,STEP:5)
Block(0,59,-3,STEP:5)
Block(0,59,-2,STEP:5)
Block(0,59,-1,STEP:5)
Block(0,59,0,STEP:5)
Block(0,59,1,STEP:5)
Block(0,59,2,STEP:5)
Block(0,59,3,STEP:5)
Block(0,59,4,STEP:5)
Block(0,59,5,STEP:5)
Block(0,59,6,STEP:5)
Block(0,59,7,STEP:5)
Block(0,59,8,STEP:5)
Block(0,61,0,minecraft:iron_bars:0)
Block(0,62,0,minecraft:iron_bars:0)
Block(1,43,-1,STEP:8)
Block(1,43,0,STEP:8)
Block(1,43,1,STEP:8)
Block(1,43,2,STEP:8)
Block(1,43,3,STEP:8)
RandomBlock(1,44,-7,minecraft:iron_bars:0,5,STAINED_CLAY:15,5,STAINED_CLAY:7,5,quark:iron_plate_slab:8,15,quark:world_stone_pavement:2,15,STAINED_CLAY:9,100)
RandomBlock(1,44,-6,minecraft:iron_bars:0,5,STAINED_CLAY:15,5,STAINED_CLAY:7,5,quark:iron_plate_slab:8,15,quark:world_stone_pavement:2,15,STAINED_CLAY:9,100)
RandomBlock(1,44,-5,minecraft:iron_bars:0,5,STAINED_CLAY:15,5,STAINED_CLAY:7,5,quark:iron_plate_slab:8,15,quark:world_stone_pavement:2,15,STAINED_CLAY:9,100)
RandomBlock(1,44,-4,minecraft:iron_bars:0,5,STAINED_CLAY:15,5,STAINED_CLAY:7,5,quark:iron_plate_slab:8,15,quark:world_stone_pavement:2,15,STAINED_CLAY:9,100)
