
#######################################################################
# +-----------------------------------------------------------------+ #
# |                            BO4 object                           | #
# +-----------------------------------------------------------------+ #
#######################################################################

Author: NLBlackEagle

Description: No description given

SettingsMode: WriteWithoutComments


#######################################################################
# +-----------------------------------------------------------------+ #
# |                          Main settings                          | #
# +-----------------------------------------------------------------+ #
#######################################################################

FixedRotation: 

Frequency: 0

SpawnHeight: highestBlock

UseCenterForHighestBlock: true

##############################
# Height Limits for the BO4. #
##############################

MinHeight: 0

MaxHeight: 255

InheritBO3: 

InheritBO3Rotation: NORTH

OverrideChildSettings: true

OverrideParentHeight: false

CanOverride: true

BranchFrequency: 0

BranchFrequencyGroup: 

MustBeBelowOther: false

MustBeInside: 

CannotBeInside: 

ReplacesBO3: 

MustBeInsideWorldBorders: true
CanSpawnOnWater: true

SpawnOnWaterOnly: false

SpawnUnderWater: false

SpawnAtWaterLevel: false

HeightOffset: 0

RemoveAir: true

ReplaceAbove: 

ReplaceBelow: 

ReplaceWithBiomeBlocks: false

ReplaceWithSurfaceBlock: GRASS

ReplaceWithGroundBlock: DIRT

ReplaceWithStoneBlock: STONE

SmoothRadius: 0

SmoothHeightOffset: 0

SmoothStartTop: false

SmoothStartWood: false

SmoothingSurfaceBlock: 

SmoothingGroundBlock: 

BO3Group: 

IsSpawnPoint: false

DoReplaceBlocks: true


#######################################################################
# +-----------------------------------------------------------------+ #
# |                              Blocks                             | #
# +-----------------------------------------------------------------+ #
#######################################################################

RandomBlock(-8,44,-7,minecraft:iron_bars:0,5,STAINED_CLAY:15,5,STAINED_CLAY:7,5,quark:iron_plate_slab:8,15,quark:world_stone_pavement:2,15,STAINED_CLAY:9,100)
RandomBlock(-8,44,-6,minecraft:iron_bars:0,5,STAINED_CLAY:15,5,STAINED_CLAY:7,5,quark:iron_plate_slab:8,15,quark:world_stone_pavement:2,15,STAINED_CLAY:9,100)
RandomBlock(-8,44,-5,minecraft:iron_bars:0,5,STAINED_CLAY:15,5,STAINED_CLAY:7,5,quark:iron_plate_slab:8,15,quark:world_stone_pavement:2,15,STAINED_CLAY:9,100)
RandomBlock(-8,44,-4,minecraft:iron_bars:0,5,STAINED_CLAY:15,5,STAINED_CLAY:7,5,quark:iron_plate_slab:8,15,quark:world_stone_pavement:2,15,STAINED_CLAY:9,100)
RandomBlock(-8,44,-3,minecraft:iron_bars:0,5,STAINED_CLAY:15,5,STAINED_CLAY:7,5,quark:iron_plate_slab:8,15,quark:world_stone_pavement:2,15,STAINED_CLAY:9,100)
RandomBlock(-8,44,-2,minecraft:iron_bars:0,5,STAINED_CLAY:15,5,STAINED_CLAY:7,5,quark:iron_plate_slab:8,15,quark:world_stone_pavement:2,15,STAINED_CLAY:9,100)
RandomBlock(-8,45,-5,minecraft:iron_bars:0,5,CONCRETE_POWDER:8,10,quark:limestone:1,15,quark:limestone,15,quark:world_stone_pavement:2,15,CONCRETE:8,100)
Block(-8,45,-2,minecraft:iron_bars:0)
Block(-8,46,-7,STONE_BUTTON:2)
Block(-8,46,-5,CONCRETE:15)
Block(-8,46,-2,minecraft:iron_bars:0)
RandomBlock(-8,47,-5,minecraft:iron_bars:0,5,CONCRETE_POWDER:8,10,quark:limestone:1,15,quark:limestone,15,quark:world_stone_pavement:2,15,CONCRETE:8,100)
RandomBlock(-8,48,-5,minecraft:iron_bars:0,5,CONCRETE_POWDER:8,10,quark:limestone:1,15,quark:limestone,15,quark:world_stone_pavement:2,15,CONCRETE:8,100)
RandomBlock(-8,48,-4,minecraft:iron_bars:0,5,CONCRETE_POWDER:8,10,quark:limestone:1,15,quark:limestone,15,quark:world_stone_pavement:2,15,CONCRETE:8,100)
RandomBlock(-8,49,-7,minecraft:iron_bars:0,5,STAINED_CLAY:15,5,STAINED_CLAY:7,5,quark:iron_plate_slab:8,15,quark:world_stone_pavement:2,15,STAINED_CLAY:9,100)
RandomBlock(-8,49,-6,minecraft:iron_bars:0,5,STAINED_CLAY:15,5,STAINED_CLAY:7,5,quark:iron_plate_slab:8,15,quark:world_stone_pavement:2,15,STAINED_CLAY:9,100)
RandomBlock(-8,49,-5,minecraft:iron_bars:0,5,STAINED_CLAY:15,5,STAINED_CLAY:7,5,quark:iron_plate_slab:8,15,quark:world_stone_pavement:2,15,STAINED_CLAY:9,100)
RandomBlock(-8,49,-4,minecraft:iron_bars:0,5,STAINED_CLAY:15,5,STAINED_CLAY:7,5,quark:iron_plate_slab:8,15,quark:world_stone_pavement:2,15,STAINED_CLAY:9,100)
RandomBlock(-8,49,-3,minecraft:iron_bars:0,5,CONCRETE_POWDER:8,10,quark:limestone:1,15,quark:limestone,15,quark:world_stone_pavement:2,15,CONCRETE:8,100)
Block(-8,50,-6,quark:iron_plate:1)
Block(-8,50,-5,quark:iron_plate:1)
Block(-8,50,-3,minecraft:iron_bars:0)
Block(-8,51,-6,IRON_TRAPDOOR:1)
Block(-8,51,-5,IRON_TRAPDOOR:1)
Block(-8,51,-3,minecraft:iron_bars:0)
Block(-8,65,-7,STEP:13)
Block(-8,65,-6,minecraft:iron_bars:0)
RandomBlock(-8,66,-7,CONCRETE_POWDER:7,25,CONCRETE:7,100)
Block(-8,66,-6,IRON_FENCE:0)
Block(-8,67,-7,STEP:5)
Block(-8,68,-7,minecraft:iron_bars:0)
RandomBlock(-7,44,-7,minecraft:iron_bars:0,5,STAINED_CLAY:15,5,STAINED_CLAY:7,5,quark:iron_plate_slab:8,15,quark:world_stone_pavement:2,15,STAINED_CLAY:9,100)
RandomBlock(-7,44,-6,minecraft:iron_bars:0,5,STAINED_CLAY:15,5,STAINED_CLAY:7,5,quark:iron_plate_slab:8,15,quark:world_stone_pavement:2,15,STAINED_CLAY:9,100)
RandomBlock(-7,44,-5,minecraft:iron_bars:0,5,STAINED_CLAY:15,5,STAINED_CLAY:7,5,quark:iron_plate_slab:8,15,quark:world_stone_pavement:2,15,STAINED_CLAY:9,100)
RandomBlock(-7,44,-4,minecraft:iron_bars:0,5,STAINED_CLAY:15,5,STAINED_CLAY:7,5,quark:iron_plate_slab:8,15,quark:world_stone_pavement:2,15,STAINED_CLAY:9,100)
RandomBlock(-7,44,-3,minecraft:iron_bars:0,5,STAINED_CLAY:15,5,STAINED_CLAY:7,5,quark:iron_plate_slab:8,15,quark:world_stone_pavement:2,15,STAINED_CLAY:9,100)
RandomBlock(-7,44,-2,minecraft:iron_bars:0,5,STAINED_CLAY:15,5,STAINED_CLAY:7,5,quark:iron_plate_slab:8,15,quark:world_stone_pavement:2,15,STAINED_CLAY:9,100)
Block(-7,45,-7,DISPENSER:1)
RandomBlock(-7,45,-5,minecraft:iron_bars:0,5,CONCRETE_POWDER:8,10,quark:limestone:1,15,quark:limestone,15,quark:world_stone_pavement:2,15,CONCRETE:8,100)
Block(-7,45,-2,minecraft:iron_bars:0)
Block(-7,46,-7,DOUBLE_STEP:0)
Block(-7,46,-6,LEVER:3)
Block(-7,46,-5,STAINED_GLASS_PANE:7)
Block(-7,46,-2,minecraft:iron_bars:0)
RandomBlock(-7,47,-5,minecraft:iron_bars:0,5,CONCRETE_POWDER:8,10,quark:limestone:1,15,quark:limestone,15,quark:world_stone_pavement:2,15,CONCRETE:8,100)
RandomBlock(-7,48,-5,minecraft:iron_bars:0,5,CONCRETE_POWDER:8,10,quark:limestone:1,15,quark:limestone,15,quark:world_stone_pavement:2,15,CONCRETE:8,100)
RandomBlock(-7,48,-4,minecraft:iron_bars:0,5,CONCRETE_POWDER:8,10,quark:limestone:1,15,quark:limestone,15,quark:world_stone_pavement:2,15,CONCRETE:8,100)
RandomBlock(-7,49,-7,minecraft:iron_bars:0,5,STAINED_CLAY:15,5,STAINED_CLAY:7,5,quark:iron_plate_slab:8,15,quark:world_stone_pavement:2,15,STAINED_CLAY:9,100)
RandomBlock(-7,49,-6,minecraft:iron_bars:0,5,STAINED_CLAY:15,5,STAINED_CLAY:7,5,quark:iron_plate_slab:8,15,quark:world_stone_pavement:2,15,STAINED_CLAY:9,100)
RandomBlock(-7,49,-5,minecraft:iron_bars:0,5,STAINED_CLAY:15,5,STAINED_CLAY:7,5,quark:iron_plate_slab:8,15,quark:world_stone_pavement:2,15,STAINED_CLAY:9,100)
RandomBlock(-7,49,-4,minecraft:iron_bars:0,5,STAINED_CLAY:15,5,STAINED_CLAY:7,5,quark:iron_plate_slab:8,15,quark:world_stone_pavement:2,15,STAINED_CLAY:9,100)
RandomBlock(-7,49,-3,minecraft:iron_bars:0,5,CONCRETE_POWDER:8,10,quark:limestone:1,15,quark:limestone,15,quark:world_stone_pavement:2,15,CONCRETE:8,100)
Block(-7,50,-7,STONE:6)
Block(-7,50,-6,quark:iron_plate:1)
Block(-7,50,-5,quark:iron_plate:1)
Block(-7,50,-3,minecraft:iron_bars:0)
Block(-7,51,-6,IRON_TRAPDOOR:1)
Block(-7,51,-5,IRON_TRAPDOOR:1)
Block(-7,51,-3,minecraft:iron_bars:0)
Block(-7,65,-7,SMOOTH_STAIRS:4)
Block(-7,65,-6,minecraft:iron_bars:0)
RandomBlock(-7,66,-7,CONCRETE_POWDER:7,25,CONCRETE:7,100)
Block(-7,66,-6,IRON_FENCE:0)
Block(-7,67,-7,STEP:5)
Block(-7,68,-7,minecraft:iron_bars:0)
RandomBlock(-6,44,-7,minecraft:iron_bars:0,5,STAINED_CLAY:15,5,STAINED_CLAY:7,5,quark:iron_plate_slab:8,15,quark:world_stone_pavement:2,15,STAINED_CLAY:9,100)
RandomBlock(-6,44,-6,minecraft:iron_bars:0,5,STAINED_CLAY:15,5,STAINED_CLAY:7,5,quark:iron_plate_slab:8,15,quark:world_stone_pavement:2,15,STAINED_CLAY:9,100)
RandomBlock(-6,44,-5,minecraft:iron_bars:0,5,STAINED_CLAY:15,5,STAINED_CLAY:7,5,quark:iron_plate_slab:8,15,quark:world_stone_pavement:2,15,STAINED_CLAY:9,100)
RandomBlock(-6,44,-4,minecraft:iron_bars:0,5,STAINED_CLAY:15,5,STAINED_CLAY:7,5,quark:iron_plate_slab:8,15,quark:world_stone_pavement:2,15,STAINED_CLAY:9,100)
RandomBlock(-6,44,-3,minecraft:iron_bars:0,5,STAINED_CLAY:15,5,STAINED_CLAY:7,5,quark:iron_plate_slab:8,15,quark:world_stone_pavement:2,15,STAINED_CLAY:9,100)
RandomBlock(-6,44,-2,minecraft:iron_bars:0,5,STAINED_CLAY:15,5,STAINED_CLAY:7,5,quark:iron_plate_slab:8,15,quark:world_stone_pavement:2,15,STAINED_CLAY:9,100)
RandomBlock(-6,45,-5,minecraft:iron_bars:0,5,CONCRETE_POWDER:8,10,quark:limestone:1,15,quark:limestone,15,quark:world_stone_pavement:2,15,CONCRETE:8,100)
Block(-6,45,-2,minecraft:iron_bars:0)
Block(-6,46,-7,STONE_BUTTON:1)
Block(-6,46,-5,CONCRETE:15)
Block(-6,46,-2,minecraft:iron_bars:0)
RandomBlock(-6,47,-5,minecraft:iron_bars:0,5,CONCRETE_POWDER:8,10,quark:limestone:1,15,quark:limestone,15,quark:world_stone_pavement:2,15,CONCRETE:8,100)
RandomBlock(-6,48,-5,minecraft:iron_bars:0,5,CONCRETE_POWDER:8,10,quark:limestone:1,15,quark:limestone,15,quark:world_stone_pavement:2,15,CONCRETE:8,100)
RandomBlock(-6,48,-4,minecraft:iron_bars:0,5,CONCRETE_POWDER:8,10,quark:limestone:1,15,quark:limestone,15,quark:world_stone_pavement:2,15,CONCRETE:8,100)
RandomBlock(-6,49,-7,minecraft:iron_bars:0,5,STAINED_CLAY:15,5,STAINED_CLAY:7,5,quark:iron_plate_slab:8,15,quark:world_stone_pavement:2,15,STAINED_CLAY:9,100)
RandomBlock(-6,49,-6,minecraft:iron_bars:0,5,STAINED_CLAY:15,5,STAINED_CLAY:7,5,quark:iron_plate_slab:8,15,quark:world_stone_pavement:2,15,STAINED_CLAY:9,100)
RandomBlock(-6,49,-5,minecraft:iron_bars:0,5,STAINED_CLAY:15,5,STAINED_CLAY:7,5,quark:iron_plate_slab:8,15,quark:world_stone_pavement:2,15,STAINED_CLAY:9,100)
RandomBlock(-6,49,-4,minecraft:iron_bars:0,5,STAINED_CLAY:15,5,STAINED_CLAY:7,5,quark:iron_plate_slab:8,15,quark:world_stone_pavement:2,15,STAINED_CLAY:9,100)
RandomBlock(-6,49,-3,minecraft:iron_bars:0,5,CONCRETE_POWDER:8,10,quark:limestone:1,15,quark:limestone,15,quark:world_stone_pavement:2,15,CONCRETE:8,100)
Block(-6,50,-3,minecraft:iron_bars:0)
Block(-6,51,-3,minecraft:iron_bars:0)
Block(-6,64,-7,SMOOTH_STAIRS:4)
Block(-6,65,-7,SMOOTH_STAIRS:1)
Block(-6,65,-6,minecraft:iron_bars:0)
RandomBlock(-6,66,-7,CONCRETE_POWDER:7,25,CONCRETE:7,100)
Block(-6,66,-6,IRON_FENCE:0)
Block(-6,67,-7,STEP:5)
Block(-6,68,-7,minecraft:iron_bars:0)
RandomBlock(-5,44,-7,minecraft:iron_bars:0,5,STAINED_CLAY:15,5,STAINED_CLAY:7,5,quark:iron_plate_slab:8,15,quark:world_stone_pavement:2,15,STAINED_CLAY:9,100)
RandomBlock(-5,44,-6,minecraft:iron_bars:0,5,STAINED_CLAY:15,5,STAINED_CLAY:7,5,quark:iron_plate_slab:8,15,quark:world_stone_pavement:2,15,STAINED_CLAY:9,100)
RandomBlock(-5,44,-5,minecraft:iron_bars:0,5,STAINED_CLAY:15,5,STAINED_CLAY:7,5,quark:iron_plate_slab:8,15,quark:world_stone_pavement:2,15,STAINED_CLAY:9,100)
RandomBlock(-5,44,-4,minecraft:iron_bars:0,5,STAINED_CLAY:15,5,STAINED_CLAY:7,5,quark:iron_plate_slab:8,15,quark:world_stone_pavement:2,15,STAINED_CLAY:9,100)
RandomBlock(-5,44,-3,minecraft:iron_bars:0,5,STAINED_CLAY:15,5,STAINED_CLAY:7,5,quark:iron_plate_slab:8,15,quark:world_stone_pavement:2,15,STAINED_CLAY:9,100)
RandomBlock(-5,44,-2,minecraft:iron_bars:0,5,STAINED_CLAY:15,5,STAINED_CLAY:7,5,quark:iron_plate_slab:8,15,quark:world_stone_pavement:2,15,STAINED_CLAY:9,100)
Block(-5,45,-7,STONE_BUTTON:3)
RandomBlock(-5,45,-5,minecraft:iron_bars:0,5,CONCRETE_POWDER:8,10,quark:limestone:1,15,quark:limestone,15,quark:world_stone_pavement:2,15,CONCRETE:8,100)
Block(-5,45,-2,minecraft:iron_bars:0)
Block(-5,46,-5,CONCRETE:15)
Block(-5,46,-2,minecraft:iron_bars:0)
RandomBlock(-5,47,-5,minecraft:iron_bars:0,5,CONCRETE_POWDER:8,10,quark:limestone:1,15,quark:limestone,15,quark:world_stone_pavement:2,15,CONCRETE:8,100)
Block(-5,48,-5,REDSTONE_LAMP_OFF:0)
RandomBlock(-5,48,-4,minecraft:iron_bars:0,5,CONCRETE_POWDER:8,10,quark:limestone:1,15,quark:limestone,15,quark:world_stone_pavement:2,15,CONCRETE:8,100)
RandomBlock(-5,49,-7,minecraft:iron_bars:0,5,STAINED_CLAY:15,5,STAINED_CLAY:7,5,quark:iron_plate_slab:8,15,quark:world_stone_pavement:2,15,STAINED_CLAY:9,100)
RandomBlock(-5,49,-6,minecraft:iron_bars:0,5,STAINED_CLAY:15,5,STAINED_CLAY:7,5,quark:iron_plate_slab:8,15,quark:world_stone_pavement:2,15,STAINED_CLAY:9,100)
RandomBlock(-5,49,-5,minecraft:iron_bars:0,5,STAINED_CLAY:15,5,STAINED_CLAY:7,5,quark:iron_plate_slab:8,15,quark:world_stone_pavement:2,15,STAINED_CLAY:9,100)
RandomBlock(-5,49,-4,minecraft:iron_bars:0,5,STAINED_CLAY:15,5,STAINED_CLAY:7,5,quark:iron_plate_slab:8,15,quark:world_stone_pavement:2,15,STAINED_CLAY:9,100)
RandomBlock(-5,49,-3,minecraft:iron_bars:0,5,CONCRETE_POWDER:8,10,quark:limestone:1,15,quark:limestone,15,quark:world_stone_pavement:2,15,CONCRETE:8,100)
Block(-5,50,-3,minecraft:iron_bars:0)
Block(-5,51,-3,minecraft:iron_bars:0)
RandomBlock(-5,62,-7,minecraft:iron_bars:0,5,quark:iron_plate:1,15,STAINED_CLAY:15,15,STAINED_CLAY:7,100)
RandomBlock(-5,63,-7,CONCRETE_POWDER:7,25,CONCRETE:7,100)
Block(-5,64,-7,SMOOTH_STAIRS:1)
Block(-5,65,-6,minecraft:iron_bars:0)
RandomBlock(-5,66,-7,CONCRETE_POWDER:7,25,CONCRETE:7,100)
Block(-5,66,-6,IRON_FENCE:0)
Block(-5,67,-7,SMOOTH_STAIRS:0)
Block(-5,68,-7,minecraft:iron_bars:0)
RandomBlock(-4,44,-7,minecraft:iron_bars:0,5,STAINED_CLAY:15,5,STAINED_CLAY:7,5,quark:iron_plate_slab:8,15,quark:world_stone_pavement:2,15,STAINED_CLAY:9,100)
RandomBlock(-4,44,-6,minecraft:iron_bars:0,5,STAINED_CLAY:15,5,STAINED_CLAY:7,5,quark:iron_plate_slab:8,15,quark:world_stone_pavement:2,15,STAINED_CLAY:9,100)
RandomBlock(-4,44,-5,minecraft:iron_bars:0,5,STAINED_CLAY:15,5,STAINED_CLAY:7,5,quark:iron_plate_slab:8,15,quark:world_stone_pavement:2,15,STAINED_CLAY:9,100)
RandomBlock(-4,44,-4,minecraft:iron_bars:0,5,STAINED_CLAY:15,5,STAINED_CLAY:7,5,quark:iron_plate_slab:8,15,quark:world_stone_pavement:2,15,STAINED_CLAY:9,100)
RandomBlock(-4,44,-3,minecraft:iron_bars:0,5,STAINED_CLAY:15,5,STAINED_CLAY:7,5,quark:iron_plate_slab:8,15,quark:world_stone_pavement:2,15,STAINED_CLAY:9,100)
RandomBlock(-4,44,-2,minecraft:iron_bars:0,5,STAINED_CLAY:15,5,STAINED_CLAY:7,5,quark:iron_plate_slab:8,15,quark:world_stone_pavement:2,15,STAINED_CLAY:9,100)
RandomBlock(-4,45,-5,minecraft:iron_bars:0,5,CONCRETE_POWDER:8,10,quark:limestone:1,15,quark:limestone,15,quark:world_stone_pavement:2,15,CONCRETE:8,100)
Block(-4,45,-2,minecraft:iron_bars:0)
Block(-4,46,-5,CONCRETE:15)
Block(-4,46,-2,minecraft:iron_bars:0)
RandomBlock(-4,47,-5,minecraft:iron_bars:0,5,CONCRETE_POWDER:8,10,quark:limestone:1,15,quark:limestone,15,quark:world_stone_pavement:2,15,CONCRETE:8,100)
RandomBlock(-4,48,-5,minecraft:iron_bars:0,5,CONCRETE_POWDER:8,10,quark:limestone:1,15,quark:limestone,15,quark:world_stone_pavement:2,15,CONCRETE:8,100)
RandomBlock(-4,48,-4,minecraft:iron_bars:0,5,CONCRETE_POWDER:8,10,quark:limestone:1,15,quark:limestone,15,quark:world_stone_pavement:2,15,CONCRETE:8,100)
RandomBlock(-4,49,-7,minecraft:iron_bars:0,5,STAINED_CLAY:15,5,STAINED_CLAY:7,5,quark:iron_plate_slab:8,15,quark:world_stone_pavement:2,15,STAINED_CLAY:9,100)
RandomBlock(-4,49,-6,minecraft:iron_bars:0,5,STAINED_CLAY:15,5,STAINED_CLAY:7,5,quark:iron_plate_slab:8,15,quark:world_stone_pavement:2,15,STAINED_CLAY:9,100)
RandomBlock(-4,49,-5,minecraft:iron_bars:0,5,STAINED_CLAY:15,5,STAINED_CLAY:7,5,quark:iron_plate_slab:8,15,quark:world_stone_pavement:2,15,STAINED_CLAY:9,100)
RandomBlock(-4,49,-4,minecraft:iron_bars:0,5,STAINED_CLAY:15,5,STAINED_CLAY:7,5,quark:iron_plate_slab:8,15,quark:world_stone_pavement:2,15,STAINED_CLAY:9,100)
RandomBlock(-4,49,-3,minecraft:iron_bars:0,5,CONCRETE_POWDER:8,10,quark:limestone:1,15,quark:limestone,15,quark:world_stone_pavement:2,15,CONCRETE:8,100)
RandomBlock(-4,50,-7,minecraft:iron_bars:0,5,quark:iron_plate:1,15,STAINED_CLAY:15,15,STAINED_CLAY:7,100)
RandomBlock(-4,50,-6,minecraft:iron_bars:0,5,quark:iron_plate:1,15,STAINED_CLAY:15,15,STAINED_CLAY:7,100)
Block(-4,50,-3,minecraft:iron_bars:0)
RandomBlock(-4,51,-7,minecraft:iron_bars:0,5,quark:iron_plate:1,15,STAINED_CLAY:15,15,STAINED_CLAY:7,100)
RandomBlock(-4,51,-6,minecraft:iron_bars:0,5,quark:iron_plate:1,15,STAINED_CLAY:15,15,STAINED_CLAY:7,100)
Block(-4,51,-3,minecraft:iron_bars:0)
RandomBlock(-4,52,-7,minecraft:iron_bars:0,5,quark:iron_plate:1,15,STAINED_CLAY:15,15,STAINED_CLAY:7,100)
RandomBlock(-4,52,-6,minecraft:iron_bars:0,5,quark:iron_plate:1,15,STAINED_CLAY:15,15,STAINED_CLAY:7,100)
RandomBlock(-4,53,-7,minecraft:iron_bars:0,5,quark:iron_plate:1,15,STAINED_CLAY:15,15,STAINED_CLAY:7,100)
RandomBlock(-4,54,-7,minecraft:iron_bars:0,5,quark:iron_plate:1,15,STAINED_CLAY:15,15,STAINED_CLAY:7,100)
RandomBlock(-4,55,-7,minecraft:iron_bars:0,5,quark:iron_plate:1,15,STAINED_CLAY:15,15,STAINED_CLAY:7,100)
RandomBlock(-4,56,-7,minecraft:iron_bars:0,5,quark:iron_plate:1,15,STAINED_CLAY:15,15,STAINED_CLAY:7,100)
RandomBlock(-4,57,-7,minecraft:iron_bars:0,5,quark:iron_plate:1,15,STAINED_CLAY:15,15,STAINED_CLAY:7,100)
RandomBlock(-4,58,-7,minecraft:iron_bars:0,5,quark:iron_plate:1,15,STAINED_CLAY:15,15,STAINED_CLAY:7,100)
RandomBlock(-4,59,-7,minecraft:iron_bars:0,5,quark:iron_plate:1,15,STAINED_CLAY:15,15,STAINED_CLAY:7,100)
RandomBlock(-4,60,-7,minecraft:iron_bars:0,5,quark:iron_plate:1,15,STAINED_CLAY:15,15,STAINED_CLAY:7,100)
RandomBlock(-4,61,-7,minecraft:iron_bars:0,5,quark:iron_plate:1,15,STAINED_CLAY:15,15,STAINED_CLAY:7,100)
RandomBlock(-4,62,-7,minecraft:iron_bars:0,5,quark:iron_plate:1,15,STAINED_CLAY:15,15,STAINED_CLAY:7,100)
RandomBlock(-4,62,-6,minecraft:iron_bars:0,5,quark:iron_plate:1,15,STAINED_CLAY:15,15,STAINED_CLAY:7,100)
RandomBlock(-4,63,-7,CONCRETE_POWDER:7,25,CONCRETE:7,100)
Block(-4,63,-6,minecraft:iron_bars:0)
RandomBlock(-4,64,-7,CONCRETE_POWDER:7,25,CONCRETE:7,100)
Block(-4,64,-6,minecraft:iron_bars:0)
RandomBlock(-4,65,-7,CONCRETE_POWDER:7,25,CONCRETE:7,100)
Block(-4,65,-6,minecraft:iron_bars:0)
RandomBlock(-4,66,-7,CONCRETE_POWDER:7,25,CONCRETE:7,100)
RandomBlock(-4,66,-6,CONCRETE_POWDER:7,25,CONCRETE:7,100)
RandomBlock(-4,67,-7,SMOOTH_BRICK:0,40,SMOOTH_BRICK:1,20,SMOOTH_BRICK:2,30,SMOOTH_BRICK:0,100)
Block(-4,68,-7,minecraft:iron_bars:0)
RandomBlock(-3,44,-7,minecraft:iron_bars:0,5,STAINED_CLAY:15,5,STAINED_CLAY:7,5,quark:iron_plate_slab:8,15,quark:world_stone_pavement:2,15,STAINED_CLAY:9,100)
RandomBlock(-3,44,-6,minecraft:iron_bars:0,5,STAINED_CLAY:15,5,STAINED_CLAY:7,5,quark:iron_plate_slab:8,15,quark:world_stone_pavement:2,15,STAINED_CLAY:9,100)
RandomBlock(-3,44,-5,minecraft:iron_bars:0,5,STAINED_CLAY:15,5,STAINED_CLAY:7,5,quark:iron_plate_slab:8,15,quark:world_stone_pavement:2,15,STAINED_CLAY:9,100)
RandomBlock(-3,44,-4,minecraft:iron_bars:0,5,STAINED_CLAY:15,5,STAINED_CLAY:7,5,quark:iron_plate_slab:8,15,quark:world_stone_pavement:2,15,STAINED_CLAY:9,100)
RandomBlock(-3,44,-3,minecraft:iron_bars:0,5,STAINED_CLAY:15,5,STAINED_CLAY:7,5,quark:iron_plate_slab:8,15,quark:world_stone_pavement:2,15,STAINED_CLAY:9,100)
RandomBlock(-3,44,-2,minecraft:iron_bars:0,5,STAINED_CLAY:15,5,STAINED_CLAY:7,5,quark:iron_plate_slab:8,15,quark:world_stone_pavement:2,15,STAINED_CLAY:9,100)
Block(-3,45,-7,STONE_BUTTON:3)
Block(-3,45,-6,IRON_PLATE:0)
Block(-3,45,-5,IRON_DOOR_BLOCK:3)
Block(-3,45,-4,IRON_PLATE:0)
Block(-3,45,-2,minecraft:iron_bars:0)
Block(-3,46,-5,IRON_DOOR_BLOCK:8)
Block(-3,46,-2,minecraft:iron_bars:0)
RandomBlock(-3,47,-5,minecraft:iron_bars:0,5,CONCRETE_POWDER:8,10,quark:limestone:1,15,quark:limestone,15,quark:world_stone_pavement:2,15,CONCRETE:8,100)
RandomBlock(-3,48,-5,minecraft:iron_bars:0,5,CONCRETE_POWDER:8,10,quark:limestone:1,15,quark:limestone,15,quark:world_stone_pavement:2,15,CONCRETE:8,100)
RandomBlock(-3,48,-4,minecraft:iron_bars:0,5,CONCRETE_POWDER:8,10,quark:limestone:1,15,quark:limestone,15,quark:world_stone_pavement:2,15,CONCRETE:8,100)
RandomBlock(-3,49,-7,minecraft:iron_bars:0,5,STAINED_CLAY:15,5,STAINED_CLAY:7,5,quark:iron_plate_slab:8,15,quark:world_stone_pavement:2,15,STAINED_CLAY:9,100)
RandomBlock(-3,49,-6,minecraft:iron_bars:0,5,STAINED_CLAY:15,5,STAINED_CLAY:7,5,quark:iron_plate_slab:8,15,quark:world_stone_pavement:2,15,STAINED_CLAY:9,100)
RandomBlock(-3,49,-5,minecraft:iron_bars:0,5,STAINED_CLAY:15,5,STAINED_CLAY:7,5,quark:iron_plate_slab:8,15,quark:world_stone_pavement:2,15,STAINED_CLAY:9,100)
RandomBlock(-3,49,-4,minecraft:iron_bars:0,5,STAINED_CLAY:15,5,STAINED_CLAY:7,5,quark:iron_plate_slab:8,15,quark:world_stone_pavement:2,15,STAINED_CLAY:9,100)
RandomBlock(-3,49,-3,minecraft:iron_bars:0,5,CONCRETE_POWDER:8,10,quark:limestone:1,15,quark:limestone,15,quark:world_stone_pavement:2,15,CONCRETE:8,100)
Block(-3,50,-7,quark:iron_ladder:5)
Block(-3,50,-3,minecraft:iron_bars:0)
Block(-3,51,-7,quark:iron_ladder:5)
Block(-3,51,-3,minecraft:iron_bars:0)
Block(-3,52,-7,quark:iron_ladder:5)
RandomBlock(-3,52,-6,minecraft:iron_bars:0,5,quark:iron_plate:1,15,STAINED_CLAY:15,15,STAINED_CLAY:7,100)
Block(-3,53,-7,quark:iron_ladder:5)
RandomBlock(-3,53,-6,minecraft:iron_bars:0,5,quark:iron_plate:1,15,STAINED_CLAY:15,15,STAINED_CLAY:7,100)
Block(-3,54,-7,quark:iron_ladder:5)
RandomBlock(-3,54,-6,minecraft:iron_bars:0,5,quark:iron_plate:1,15,STAINED_CLAY:15,15,STAINED_CLAY:7,100)
Block(-3,55,-7,quark:iron_ladder:5)
RandomBlock(-3,55,-6,minecraft:iron_bars:0,5,quark:iron_plate:1,15,STAINED_CLAY:15,15,STAINED_CLAY:7,100)
Block(-3,56,-7,quark:iron_ladder:5)
RandomBlock(-3,56,-6,minecraft:iron_bars:0,5,quark:iron_plate:1,15,STAINED_CLAY:15,15,STAINED_CLAY:7,100)
Block(-3,57,-7,quark:iron_ladder:5)
RandomBlock(-3,57,-6,minecraft:iron_bars:0,5,quark:iron_plate:1,15,STAINED_CLAY:15,15,STAINED_CLAY:7,100)
Block(-3,58,-7,quark:iron_ladder:5)
RandomBlock(-3,58,-6,minecraft:iron_bars:0,5,quark:iron_plate:1,15,STAINED_CLAY:15,15,STAINED_CLAY:7,100)
Block(-3,59,-7,quark:iron_ladder:5)
RandomBlock(-3,59,-6,minecraft:iron_bars:0,5,quark:iron_plate:1,15,STAINED_CLAY:15,15,STAINED_CLAY:7,100)
Block(-3,60,-7,quark:iron_ladder:5)
RandomBlock(-3,60,-6,minecraft:iron_bars:0,5,quark:iron_plate:1,15,STAINED_CLAY:15,15,STAINED_CLAY:7,100)
Block(-3,61,-7,quark:iron_ladder:5)
RandomBlock(-3,61,-6,minecraft:iron_bars:0,5,quark:iron_plate:1,15,STAINED_CLAY:15,15,STAINED_CLAY:7,100)
Block(-3,62,-7,quark:iron_ladder:5)
RandomBlock(-3,62,-6,minecraft:iron_bars:0,5,quark:iron_plate:1,15,STAINED_CLAY:15,15,STAINED_CLAY:7,100)
RandomBlock(-3,62,-5,minecraft:iron_bars:0,5,quark:iron_plate:1,15,STAINED_CLAY:15,15,STAINED_CLAY:7,100)
Block(-3,63,-7,quark:iron_ladder:5)
RandomBlock(-3,63,-6,CONCRETE_POWDER:7,25,CONCRETE:7,100)
RandomBlock(-3,63,-5,CONCRETE_POWDER:7,25,CONCRETE:7,100)
RandomBlock(-3,64,-6,CONCRETE_POWDER:7,25,CONCRETE:7,100)
RandomBlock(-3,65,-6,CONCRETE_POWDER:7,25,CONCRETE:7,100)
RandomBlock(-3,66,-7,CONCRETE_POWDER:7,25,CONCRETE:7,100)
RandomBlock(-3,66,-6,CONCRETE_POWDER:7,25,CONCRETE:7,100)
RandomBlock(-3,67,-7,SMOOTH_BRICK:0,40,SMOOTH_BRICK:1,20,SMOOTH_BRICK:2,30,SMOOTH_BRICK:0,100)
Block(-3,68,-7,minecraft:iron_bars:0)
Block(-2,43,-7,quark:iron_plate:1)
Block(-2,43,-6,quark:iron_plate:1)
RandomBlock(-2,44,-7,minecraft:iron_bars:0,5,STAINED_CLAY:15,5,STAINED_CLAY:7,5,quark:iron_plate_slab:8,15,quark:world_stone_pavement:2,15,STAINED_CLAY:9,100)
RandomBlock(-2,44,-6,minecraft:iron_bars:0,5,STAINED_CLAY:15,5,STAINED_CLAY:7,5,quark:iron_plate_slab:8,15,quark:world_stone_pavement:2,15,STAINED_CLAY:9,100)
RandomBlock(-2,44,-5,minecraft:iron_bars:0,5,STAINED_CLAY:15,5,STAINED_CLAY:7,5,quark:iron_plate_slab:8,15,quark:world_stone_pavement:2,15,STAINED_CLAY:9,100)
RandomBlock(-2,44,-4,minecraft:iron_bars:0,5,STAINED_CLAY:15,5,STAINED_CLAY:7,5,quark:iron_plate_slab:8,15,quark:world_stone_pavement:2,15,STAINED_CLAY:9,100)
RandomBlock(-2,44,-3,minecraft:iron_bars:0,5,STAINED_CLAY:15,5,STAINED_CLAY:7,5,quark:iron_plate_slab:8,15,quark:world_stone_pavement:2,15,STAINED_CLAY:9,100)
RandomBlock(-2,44,-2,minecraft:iron_bars:0,5,STAINED_CLAY:15,5,STAINED_CLAY:7,5,quark:iron_plate_slab:8,15,quark:world_stone_pavement:2,15,STAINED_CLAY:9,100)
Block(-2,45,-7,STONE_BUTTON:3)
Block(-2,45,-6,IRON_PLATE:0)
Block(-2,45,-5,IRON_DOOR_BLOCK:3)
Block(-2,45,-4,IRON_PLATE:0)
Block(-2,45,-2,minecraft:iron_bars:0)
Block(-2,46,-5,IRON_DOOR_BLOCK:9)
Block(-2,46,-2,minecraft:iron_bars:0)
RandomBlock(-2,47,-5,minecraft:iron_bars:0,5,CONCRETE_POWDER:8,10,quark:limestone:1,15,quark:limestone,15,quark:world_stone_pavement:2,15,CONCRETE:8,100)
RandomBlock(-2,48,-5,minecraft:iron_bars:0,5,CONCRETE_POWDER:8,10,quark:limestone:1,15,quark:limestone,15,quark:world_stone_pavement:2,15,CONCRETE:8,100)
RandomBlock(-2,48,-4,minecraft:iron_bars:0,5,CONCRETE_POWDER:8,10,quark:limestone:1,15,quark:limestone,15,quark:world_stone_pavement:2,15,CONCRETE:8,100)
RandomBlock(-2,49,-7,minecraft:iron_bars:0,5,STAINED_CLAY:15,5,STAINED_CLAY:7,5,quark:iron_plate_slab:8,15,quark:world_stone_pavement:2,15,STAINED_CLAY:9,100)
RandomBlock(-2,49,-6,minecraft:iron_bars:0,5,STAINED_CLAY:15,5,STAINED_CLAY:7,5,quark:iron_plate_slab:8,15,quark:world_stone_pavement:2,15,STAINED_CLAY:9,100)
RandomBlock(-2,49,-5,minecraft:iron_bars:0,5,STAINED_CLAY:15,5,STAINED_CLAY:7,5,quark:iron_plate_slab:8,15,quark:world_stone_pavement:2,15,STAINED_CLAY:9,100)
RandomBlock(-2,49,-4,minecraft:iron_bars:0,5,STAINED_CLAY:15,5,STAINED_CLAY:7,5,quark:iron_plate_slab:8,15,quark:world_stone_pavement:2,15,STAINED_CLAY:9,100)
RandomBlock(-2,49,-3,minecraft:iron_bars:0,5,CONCRETE_POWDER:8,10,quark:limestone:1,15,quark:limestone,15,quark:world_stone_pavement:2,15,CONCRETE:8,100)
RandomBlock(-2,50,-7,minecraft:iron_bars:0,5,quark:iron_plate:1,15,STAINED_CLAY:15,15,STAINED_CLAY:7,100)
RandomBlock(-2,50,-6,minecraft:iron_bars:0,5,quark:iron_plate:1,15,STAINED_CLAY:15,15,STAINED_CLAY:7,100)
Block(-2,50,-3,minecraft:iron_bars:0)
RandomBlock(-2,51,-7,minecraft:iron_bars:0,5,quark:iron_plate:1,15,STAINED_CLAY:15,15,STAINED_CLAY:7,100)
RandomBlock(-2,51,-6,minecraft:iron_bars:0,5,quark:iron_plate:1,15,STAINED_CLAY:15,15,STAINED_CLAY:7,100)
Block(-2,51,-3,minecraft:iron_bars:0)
RandomBlock(-2,52,-7,minecraft:iron_bars:0,5,quark:iron_plate:1,15,STAINED_CLAY:15,15,STAINED_CLAY:7,100)
RandomBlock(-2,52,-6,minecraft:iron_bars:0,5,quark:iron_plate:1,15,STAINED_CLAY:15,15,STAINED_CLAY:7,100)
RandomBlock(-2,53,-7,minecraft:iron_bars:0,5,quark:iron_plate:1,15,STAINED_CLAY:15,15,STAINED_CLAY:7,100)
RandomBlock(-2,54,-7,minecraft:iron_bars:0,5,quark:iron_plate:1,15,STAINED_CLAY:15,15,STAINED_CLAY:7,100)
RandomBlock(-2,55,-7,minecraft:iron_bars:0,5,quark:iron_plate:1,15,STAINED_CLAY:15,15,STAINED_CLAY:7,100)
RandomBlock(-2,56,-7,minecraft:iron_bars:0,5,quark:iron_plate:1,15,STAINED_CLAY:15,15,STAINED_CLAY:7,100)
RandomBlock(-2,57,-7,minecraft:iron_bars:0,5,quark:iron_plate:1,15,STAINED_CLAY:15,15,STAINED_CLAY:7,100)
RandomBlock(-2,58,-7,minecraft:iron_bars:0,5,quark:iron_plate:1,15,STAINED_CLAY:15,15,STAINED_CLAY:7,100)
RandomBlock(-2,59,-7,minecraft:iron_bars:0,5,quark:iron_plate:1,15,STAINED_CLAY:15,15,STAINED_CLAY:7,100)
RandomBlock(-2,60,-7,minecraft:iron_bars:0,5,quark:iron_plate:1,15,STAINED_CLAY:15,15,STAINED_CLAY:7,100)
RandomBlock(-2,61,-7,minecraft:iron_bars:0,5,quark:iron_plate:1,15,STAINED_CLAY:15,15,STAINED_CLAY:7,100)
RandomBlock(-2,62,-7,minecraft:iron_bars:0,5,quark:iron_plate:1,15,STAINED_CLAY:15,15,STAINED_CLAY:7,100)
RandomBlock(-2,62,-6,minecraft:iron_bars:0,5,quark:iron_plate:1,15,STAINED_CLAY:15,15,STAINED_CLAY:7,100)
RandomBlock(-2,63,-7,CONCRETE_POWDER:7,25,CONCRETE:7,100)
Block(-2,63,-6,minecraft:iron_bars:0)
RandomBlock(-2,64,-7,CONCRETE_POWDER:7,25,CONCRETE:7,100)
Block(-2,64,-6,minecraft:iron_bars:0)
RandomBlock(-2,65,-7,CONCRETE_POWDER:7,25,CONCRETE:7,100)
Block(-2,65,-6,minecraft:iron_bars:0)
RandomBlock(-2,66,-7,CONCRETE_POWDER:7,25,CONCRETE:7,100)
RandomBlock(-2,66,-6,CONCRETE_POWDER:7,25,CONCRETE:7,100)
RandomBlock(-2,67,-7,SMOOTH_BRICK:0,40,SMOOTH_BRICK:1,20,SMOOTH_BRICK:2,30,SMOOTH_BRICK:0,100)
Block(-2,68,-7,minecraft:iron_bars:0)
Block(-1,43,-6,quark:iron_plate:1)
RandomBlock(-1,44,-7,minecraft:iron_bars:0,5,STAINED_CLAY:15,5,STAINED_CLAY:7,5,quark:iron_plate_slab:8,15,quark:world_stone_pavement:2,15,STAINED_CLAY:9,100)
RandomBlock(-1,44,-6,minecraft:iron_bars:0,5,STAINED_CLAY:15,5,STAINED_CLAY:7,5,quark:iron_plate_slab:8,15,quark:world_stone_pavement:2,15,STAINED_CLAY:9,100)
RandomBlock(-1,44,-5,minecraft:iron_bars:0,5,STAINED_CLAY:15,5,STAINED_CLAY:7,5,quark:iron_plate_slab:8,15,quark:world_stone_pavement:2,15,STAINED_CLAY:9,100)
RandomBlock(-1,44,-4,minecraft:iron_bars:0,5,STAINED_CLAY:15,5,STAINED_CLAY:7,5,quark:iron_plate_slab:8,15,quark:world_stone_pavement:2,15,STAINED_CLAY:9,100)
RandomBlock(-1,44,-3,minecraft:iron_bars:0,5,STAINED_CLAY:15,5,STAINED_CLAY:7,5,quark:iron_plate_slab:8,15,quark:world_stone_pavement:2,15,STAINED_CLAY:9,100)
RandomBlock(-1,44,-2,minecraft:iron_bars:0,5,STAINED_CLAY:15,5,STAINED_CLAY:7,5,quark:iron_plate_slab:8,15,quark:world_stone_pavement:2,15,STAINED_CLAY:9,100)
RandomBlock(-1,45,-5,minecraft:iron_bars:0,5,CONCRETE_POWDER:8,10,quark:limestone:1,15,quark:limestone,15,quark:world_stone_pavement:2,15,CONCRETE:8,100)
Block(-1,45,-2,minecraft:iron_bars:0)
Block(-1,46,-5,CONCRETE:15)
Block(-1,46,-2,minecraft:iron_bars:0)
RandomBlock(-1,47,-5,minecraft:iron_bars:0,5,CONCRETE_POWDER:8,10,quark:limestone:1,15,quark:limestone,15,quark:world_stone_pavement:2,15,CONCRETE:8,100)
Block(-1,48,-5,REDSTONE_LAMP_OFF:0)
RandomBlock(-1,48,-4,minecraft:iron_bars:0,5,CONCRETE_POWDER:8,10,quark:limestone:1,15,quark:limestone,15,quark:world_stone_pavement:2,15,CONCRETE:8,100)
RandomBlock(-1,49,-7,minecraft:iron_bars:0,5,STAINED_CLAY:15,5,STAINED_CLAY:7,5,quark:iron_plate_slab:8,15,quark:world_stone_pavement:2,15,STAINED_CLAY:9,100)
RandomBlock(-1,49,-6,minecraft:iron_bars:0,5,STAINED_CLAY:15,5,STAINED_CLAY:7,5,quark:iron_plate_slab:8,15,quark:world_stone_pavement:2,15,STAINED_CLAY:9,100)
RandomBlock(-1,49,-5,minecraft:iron_bars:0,5,STAINED_CLAY:15,5,STAINED_CLAY:7,5,quark:iron_plate_slab:8,15,quark:world_stone_pavement:2,15,STAINED_CLAY:9,100)
RandomBlock(-1,49,-4,minecraft:iron_bars:0,5,STAINED_CLAY:15,5,STAINED_CLAY:7,5,quark:iron_plate_slab:8,15,quark:world_stone_pavement:2,15,STAINED_CLAY:9,100)
RandomBlock(-1,49,-3,minecraft:iron_bars:0,5,CONCRETE_POWDER:8,10,quark:limestone:1,15,quark:limestone,15,quark:world_stone_pavement:2,15,CONCRETE:8,100)
Block(-1,50,-3,minecraft:iron_bars:0)
Block(-1,51,-3,minecraft:iron_bars:0)
RandomBlock(-1,62,-7,minecraft:iron_bars:0,5,quark:iron_plate:1,15,STAINED_CLAY:15,15,STAINED_CLAY:7,100)
RandomBlock(-1,63,-7,CONCRETE_POWDER:7,25,CONCRETE:7,100)
Block(-1,64,-7,SMOOTH_STAIRS:5)
RandomBlock(-1,65,-7,CONCRETE_POWDER:7,25,CONCRETE:7,100)
RandomBlock(-1,66,-7,CONCRETE_POWDER:7,25,CONCRETE:7,100)
Block(-1,67,-7,SMOOTH_STAIRS:1)
Block(-1,68,-7,minecraft:iron_bars:0)
Block(0,43,-6,quark:iron_plate:1)
RandomBlock(0,44,-7,minecraft:iron_bars:0,5,STAINED_CLAY:15,5,STAINED_CLAY:7,5,quark:iron_plate_slab:8,15,quark:world_stone_pavement:2,15,STAINED_CLAY:9,100)
RandomBlock(0,44,-6,minecraft:iron_bars:0,5,STAINED_CLAY:15,5,STAINED_CLAY:7,5,quark:iron_plate_slab:8,15,quark:world_stone_pavement:2,15,STAINED_CLAY:9,100)
RandomBlock(0,44,-5,minecraft:iron_bars:0,5,STAINED_CLAY:15,5,STAINED_CLAY:7,5,quark:iron_plate_slab:8,15,quark:world_stone_pavement:2,15,STAINED_CLAY:9,100)
RandomBlock(0,44,-4,minecraft:iron_bars:0,5,STAINED_CLAY:15,5,STAINED_CLAY:7,5,quark:iron_plate_slab:8,15,quark:world_stone_pavement:2,15,STAINED_CLAY:9,100)
RandomBlock(0,44,-3,minecraft:iron_bars:0,5,STAINED_CLAY:15,5,STAINED_CLAY:7,5,quark:iron_plate_slab:8,15,quark:world_stone_pavement:2,15,STAINED_CLAY:9,100)
RandomBlock(0,44,-2,minecraft:iron_bars:0,5,STAINED_CLAY:15,5,STAINED_CLAY:7,5,quark:iron_plate_slab:8,15,quark:world_stone_pavement:2,15,STAINED_CLAY:9,100)
RandomBlock(0,45,-7,minecraft:iron_bars:0,5,CONCRETE_POWDER:8,10,quark:limestone:1,15,quark:limestone,15,quark:world_stone_pavement:2,15,CONCRETE:8,100)
RandomBlock(0,45,-6,minecraft:iron_bars:0,5,CONCRETE_POWDER:8,10,quark:limestone:1,15,quark:limestone,15,quark:world_stone_pavement:2,15,CONCRETE:8,100)
RandomBlock(0,45,-5,minecraft:iron_bars:0,5,CONCRETE_POWDER:8,10,quark:limestone:1,15,quark:limestone,15,quark:world_stone_pavement:2,15,CONCRETE:8,100)
Block(0,45,-2,minecraft:iron_bars:0)
Block(0,46,-7,STAINED_GLASS_PANE:7)
Block(0,46,-6,CONCRETE:15)
Block(0,46,-5,CONCRETE:15)
Block(0,46,-2,minecraft:iron_bars:0)
RandomBlock(0,47,-7,minecraft:iron_bars:0,5,CONCRETE_POWDER:8,10,quark:limestone:1,15,quark:limestone,15,quark:world_stone_pavement:2,15,CONCRETE:8,100)
RandomBlock(0,47,-6,minecraft:iron_bars:0,5,CONCRETE_POWDER:8,10,quark:limestone:1,15,quark:limestone,15,quark:world_stone_pavement:2,15,CONCRETE:8,100)
RandomBlock(0,47,-5,minecraft:iron_bars:0,5,CONCRETE_POWDER:8,10,quark:limestone:1,15,quark:limestone,15,quark:world_stone_pavement:2,15,CONCRETE:8,100)
RandomBlock(0,48,-7,minecraft:iron_bars:0,5,CONCRETE_POWDER:8,10,quark:limestone:1,15,quark:limestone,15,quark:world_stone_pavement:2,15,CONCRETE:8,100)
RandomBlock(0,48,-6,minecraft:iron_bars:0,5,CONCRETE_POWDER:8,10,quark:limestone:1,15,quark:limestone,15,quark:world_stone_pavement:2,15,CONCRETE:8,100)
RandomBlock(0,48,-5,minecraft:iron_bars:0,5,CONCRETE_POWDER:8,10,quark:limestone:1,15,quark:limestone,15,quark:world_stone_pavement:2,15,CONCRETE:8,100)
RandomBlock(0,48,-4,minecraft:iron_bars:0,5,CONCRETE_POWDER:8,10,quark:limestone:1,15,quark:limestone,15,quark:world_stone_pavement:2,15,CONCRETE:8,100)
RandomBlock(0,49,-7,minecraft:iron_bars:0,5,CONCRETE_POWDER:8,10,quark:limestone:1,15,quark:limestone,15,quark:world_stone_pavement:2,15,CONCRETE:8,100)
RandomBlock(0,49,-6,minecraft:iron_bars:0,5,CONCRETE_POWDER:8,10,quark:limestone:1,15,quark:limestone,15,quark:world_stone_pavement:2,15,CONCRETE:8,100)
RandomBlock(0,49,-5,minecraft:iron_bars:0,5,CONCRETE_POWDER:8,10,quark:limestone:1,15,quark:limestone,15,quark:world_stone_pavement:2,15,CONCRETE:8,100)
RandomBlock(0,49,-4,minecraft:iron_bars:0,5,CONCRETE_POWDER:8,10,quark:limestone:1,15,quark:limestone,15,quark:world_stone_pavement:2,15,CONCRETE:8,100)
RandomBlock(0,49,-3,minecraft:iron_bars:0,5,CONCRETE_POWDER:8,10,quark:limestone:1,15,quark:limestone,15,quark:world_stone_pavement:2,15,CONCRETE:8,100)
Block(0,50,-7,minecraft:iron_bars:0)
Block(0,50,-6,minecraft:iron_bars:0)
Block(0,50,-5,minecraft:iron_bars:0)
Block(0,50,-4,minecraft:iron_bars:0)
Block(0,50,-3,minecraft:iron_bars:0)
Block(0,51,-7,minecraft:iron_bars:0)
Block(0,51,-6,minecraft:iron_bars:0)
Block(0,51,-5,minecraft:iron_bars:0)
Block(0,51,-4,minecraft:iron_bars:0)
Block(0,51,-3,minecraft:iron_bars:0)
RandomBlock(0,65,-7,CONCRETE_POWDER:7,25,CONCRETE:7,100)
RandomBlock(0,66,-7,CONCRETE_POWDER:7,25,CONCRETE:7,100)
Block(0,67,-7,minecraft:iron_bars:0)
Block(0,68,-7,minecraft:iron_bars:0)
Block(1,43,-6,quark:iron_plate:1)
RandomBlock(1,44,-7,minecraft:iron_bars:0,5,STAINED_CLAY:15,5,STAINED_CLAY:7,5,quark:iron_plate_slab:8,15,quark:world_stone_pavement:2,15,STAINED_CLAY:9,100)
RandomBlock(1,44,-6,minecraft:iron_bars:0,5,STAINED_CLAY:15,5,STAINED_CLAY:7,5,quark:iron_plate_slab:8,15,quark:world_stone_pavement:2,15,STAINED_CLAY:9,100)
RandomBlock(1,44,-5,minecraft:iron_bars:0,5,STAINED_CLAY:15,5,STAINED_CLAY:7,5,quark:iron_plate_slab:8,15,quark:world_stone_pavement:2,15,STAINED_CLAY:9,100)
RandomBlock(1,44,-4,minecraft:iron_bars:0,5,STAINED_CLAY:15,5,STAINED_CLAY:7,5,quark:iron_plate_slab:8,15,quark:world_stone_pavement:2,15,STAINED_CLAY:9,100)
RandomBlock(1,44,-3,minecraft:iron_bars:0,5,STAINED_CLAY:15,5,STAINED_CLAY:7,5,quark:iron_plate_slab:8,15,quark:world_stone_pavement:2,15,STAINED_CLAY:9,100)
RandomBlock(1,44,-2,minecraft:iron_bars:0,5,STAINED_CLAY:15,5,STAINED_CLAY:7,5,quark:iron_plate_slab:8,15,quark:world_stone_pavement:2,15,STAINED_CLAY:9,100)
Block(1,45,-2,minecraft:iron_bars:0)
Block(1,46,-2,minecraft:iron_bars:0)
Block(1,64,-7,STEP:13)
Block(1,64,-6,STEP:13)
RandomBlock(1,65,-7,CONCRETE_POWDER:7,25,CONCRETE:7,100)
Block(1,65,-6,quark:iron_plate:1)
RandomBlock(1,66,-7,CONCRETE_POWDER:7,25,CONCRETE:7,100)
Block(1,66,-6,quark:iron_plate:1)
Block(1,67,-7,minecraft:iron_bars:0)
Block(1,68,-7,minecraft:iron_bars:0)
Block(2,43,-6,quark:iron_plate:1)
RandomBlock(2,44,-7,minecraft:iron_bars:0,5,STAINED_CLAY:15,5,STAINED_CLAY:7,5,quark:iron_plate_slab:8,15,quark:world_stone_pavement:2,15,STAINED_CLAY:9,100)
RandomBlock(2,44,-6,minecraft:iron_bars:0,5,STAINED_CLAY:15,5,STAINED_CLAY:7,5,quark:iron_plate_slab:8,15,quark:world_stone_pavement:2,15,STAINED_CLAY:9,100)
RandomBlock(2,44,-5,minecraft:iron_bars:0,5,STAINED_CLAY:15,5,STAINED_CLAY:7,5,quark:iron_plate_slab:8,15,quark:world_stone_pavement:2,15,STAINED_CLAY:9,100)
RandomBlock(2,44,-4,minecraft:iron_bars:0,5,STAINED_CLAY:15,5,STAINED_CLAY:7,5,quark:iron_plate_slab:8,15,quark:world_stone_pavement:2,15,STAINED_CLAY:9,100)
RandomBlock(2,44,-3,minecraft:iron_bars:0,5,STAINED_CLAY:15,5,STAINED_CLAY:7,5,quark:iron_plate_slab:8,15,quark:world_stone_pavement:2,15,STAINED_CLAY:9,100)
RandomBlock(2,44,-2,minecraft:iron_bars:0,5,STAINED_CLAY:15,5,STAINED_CLAY:7,5,quark:iron_plate_slab:8,15,quark:world_stone_pavement:2,15,STAINED_CLAY:9,100)
Block(2,45,-7,quark:iron_plate:1)
Block(2,45,-6,quark:iron_plate:1)
Block(2,45,-2,minecraft:iron_bars:0)
Block(2,46,-2,minecraft:iron_bars:0)
Block(2,64,-7,STEP:13)
Block(2,64,-6,STEP:13)
RandomBlock(2,65,-7,CONCRETE_POWDER:7,25,CONCRETE:7,100)
Block(2,65,-6,quark:iron_plate:1)
RandomBlock(2,66,-7,CONCRETE_POWDER:7,25,CONCRETE:7,100)
Block(2,66,-6,quark:iron_plate:1)
Block(2,67,-7,minecraft:iron_bars:0)
Block(2,68,-7,minecraft:iron_bars:0)
Block(3,43,-6,quark:iron_plate:1)
RandomBlock(3,44,-7,minecraft:iron_bars:0,5,STAINED_CLAY:15,5,STAINED_CLAY:7,5,quark:iron_plate_slab:8,15,quark:world_stone_pavement:2,15,STAINED_CLAY:9,100)
RandomBlock(3,44,-6,minecraft:iron_bars:0,5,STAINED_CLAY:15,5,STAINED_CLAY:7,5,quark:iron_plate_slab:8,15,quark:world_stone_pavement:2,15,STAINED_CLAY:9,100)
RandomBlock(3,44,-5,minecraft:iron_bars:0,5,STAINED_CLAY:15,5,STAINED_CLAY:7,5,quark:iron_plate_slab:8,15,quark:world_stone_pavement:2,15,STAINED_CLAY:9,100)
RandomBlock(3,44,-4,minecraft:iron_bars:0,5,STAINED_CLAY:15,5,STAINED_CLAY:7,5,quark:iron_plate_slab:8,15,quark:world_stone_pavement:2,15,STAINED_CLAY:9,100)
RandomBlock(3,44,-3,minecraft:iron_bars:0,5,STAINED_CLAY:15,5,STAINED_CLAY:7,5,quark:iron_plate_slab:8,15,quark:world_stone_pavement:2,15,STAINED_CLAY:9,100)
RandomBlock(3,44,-2,minecraft:iron_bars:0,5,STAINED_CLAY:15,5,STAINED_CLAY:7,5,quark:iron_plate_slab:8,15,quark:world_stone_pavement:2,15,STAINED_CLAY:9,100)
Block(3,45,-6,quark:iron_plate:1)
Block(3,45,-2,minecraft:iron_bars:0)
Block(3,46,-2,minecraft:iron_bars:0)
Block(3,64,-7,STEP:13)
Block(3,64,-6,STEP:13)
Block(3,65,-7,quark:iron_plate:1)
Block(3,65,-6,quark:iron_plate:1)
Block(3,66,-7,quark:iron_plate:1)
Block(3,66,-6,quark:iron_plate:1)
Block(3,67,-7,minecraft:iron_bars:0)
Block(3,68,-7,minecraft:iron_bars:0)
Block(4,43,-6,quark:iron_plate:1)
RandomBlock(4,44,-7,minecraft:iron_bars:0,5,STAINED_CLAY:15,5,STAINED_CLAY:7,5,quark:iron_plate_slab:8,15,quark:world_stone_pavement:2,15,STAINED_CLAY:9,100)
RandomBlock(4,44,-6,minecraft:iron_bars:0,5,STAINED_CLAY:15,5,STAINED_CLAY:7,5,quark:iron_plate_slab:8,15,quark:world_stone_pavement:2,15,STAINED_CLAY:9,100)
RandomBlock(4,44,-5,minecraft:iron_bars:0,5,STAINED_CLAY:15,5,STAINED_CLAY:7,5,quark:iron_plate_slab:8,15,quark:world_stone_pavement:2,15,STAINED_CLAY:9,100)
RandomBlock(4,44,-4,minecraft:iron_bars:0,5,STAINED_CLAY:15,5,STAINED_CLAY:7,5,quark:iron_plate_slab:8,15,quark:world_stone_pavement:2,15,STAINED_CLAY:9,100)
RandomBlock(4,44,-3,minecraft:iron_bars:0,5,STAINED_CLAY:15,5,STAINED_CLAY:7,5,quark:iron_plate_slab:8,15,quark:world_stone_pavement:2,15,STAINED_CLAY:9,100)
RandomBlock(4,44,-2,minecraft:iron_bars:0,5,STAINED_CLAY:15,5,STAINED_CLAY:7,5,quark:iron_plate_slab:8,15,quark:world_stone_pavement:2,15,STAINED_CLAY:9,100)
Block(4,45,-7,minecraft:iron_bars:0)
Block(4,45,-6,quark:iron_plate:1)
Block(4,45,-5,minecraft:iron_bars:0)
Block(4,45,-4,minecraft:iron_bars:0)
Block(4,45,-3,minecraft:iron_bars:0)
Block(4,45,-2,minecraft:iron_bars:0)
Block(4,46,-7,minecraft:iron_bars:0)
Block(4,46,-6,minecraft:iron_bars:0)
Block(4,46,-5,minecraft:iron_bars:0)
Block(4,46,-4,minecraft:iron_bars:0)
Block(4,46,-3,minecraft:iron_bars:0)
Block(4,46,-2,minecraft:iron_bars:0)
Block(5,43,-6,quark:iron_plate:1)
Block(5,44,-6,quark:iron_plate:1)
Block(5,45,-6,quark:iron_plate:1)

#######################################################################
# +-----------------------------------------------------------------+ #
# |                             Branches                            | #
# +-----------------------------------------------------------------+ #
#######################################################################

Branch(-16,0,0,true,OilRigC1R2,NORTH,100.0,0)

#######################################################################
# +-----------------------------------------------------------------+ #
# |                             Entities                            | #
# +-----------------------------------------------------------------+ #
#######################################################################


#######################################################################
# +-----------------------------------------------------------------+ #
# |                            Particles                            | #
# +-----------------------------------------------------------------+ #
#######################################################################


#######################################################################
# +-----------------------------------------------------------------+ #
# |                             Spawners                            | #
# +-----------------------------------------------------------------+ #
#######################################################################


#######################################################################
# +-----------------------------------------------------------------+ #
# |                             ModData                             | #
# +-----------------------------------------------------------------+ #
#######################################################################

