
#######################################################################
# +-----------------------------------------------------------------+ #
# |                            BO4 object                           | #
# +-----------------------------------------------------------------+ #
#######################################################################

Author: NLBlackEagle

Description: No description given

SettingsMode: WriteWithoutComments


#######################################################################
# +-----------------------------------------------------------------+ #
# |                          Main settings                          | #
# +-----------------------------------------------------------------+ #
#######################################################################

FixedRotation: 

Frequency: 0

SpawnHeight: highestBlock

UseCenterForHighestBlock: true

##############################
# Height Limits for the BO4. #
##############################

MinHeight: 0

MaxHeight: 255

InheritBO3: 

InheritBO3Rotation: NORTH

OverrideChildSettings: true

OverrideParentHeight: false

CanOverride: true

BranchFrequency: 0

BranchFrequencyGroup: 

MustBeBelowOther: false

MustBeInside: 

CannotBeInside: 

ReplacesBO3: 

MustBeInsideWorldBorders: true
CanSpawnOnWater: true

SpawnOnWaterOnly: false

SpawnUnderWater: false

SpawnAtWaterLevel: false

HeightOffset: 0

RemoveAir: true

ReplaceAbove: 

ReplaceBelow: 

ReplaceWithBiomeBlocks: false

ReplaceWithSurfaceBlock: GRASS

ReplaceWithGroundBlock: DIRT

ReplaceWithStoneBlock: STONE

SmoothRadius: 0

SmoothHeightOffset: 0

SmoothStartTop: false

SmoothStartWood: false

SmoothingSurfaceBlock: 

SmoothingGroundBlock: 

BO3Group: 

IsSpawnPoint: false

DoReplaceBlocks: true


#######################################################################
# +-----------------------------------------------------------------+ #
# |                              Blocks                             | #
# +-----------------------------------------------------------------+ #
#######################################################################

Block(-8,43,5,STONE:6)
RandomBlock(-8,44,-7,minecraft:iron_bars:0,5,STAINED_CLAY:15,5,STAINED_CLAY:7,5,quark:iron_plate_slab:8,15,quark:world_stone_pavement:2,15,STAINED_CLAY:9,100)
RandomBlock(-8,44,-6,minecraft:iron_bars:0,5,STAINED_CLAY:15,5,STAINED_CLAY:7,5,quark:iron_plate_slab:8,15,quark:world_stone_pavement:2,15,STAINED_CLAY:9,100)
RandomBlock(-8,44,-5,minecraft:iron_bars:0,5,STAINED_CLAY:15,5,STAINED_CLAY:7,5,quark:iron_plate_slab:8,15,quark:world_stone_pavement:2,15,STAINED_CLAY:9,100)
RandomBlock(-8,44,-4,minecraft:iron_bars:0,5,STAINED_CLAY:15,5,STAINED_CLAY:7,5,quark:iron_plate_slab:8,15,quark:world_stone_pavement:2,15,STAINED_CLAY:9,100)
RandomBlock(-8,44,-3,minecraft:iron_bars:0,5,STAINED_CLAY:15,5,STAINED_CLAY:7,5,quark:iron_plate_slab:8,15,quark:world_stone_pavement:2,15,STAINED_CLAY:9,100)
RandomBlock(-8,44,-2,minecraft:iron_bars:0,5,STAINED_CLAY:15,5,STAINED_CLAY:7,5,quark:iron_plate_slab:8,15,quark:world_stone_pavement:2,15,STAINED_CLAY:9,100)
RandomBlock(-8,44,-1,minecraft:iron_bars:0,5,STAINED_CLAY:15,5,STAINED_CLAY:7,5,quark:iron_plate_slab:8,15,quark:world_stone_pavement:2,15,STAINED_CLAY:9,100)
RandomBlock(-8,44,0,minecraft:iron_bars:0,5,STAINED_CLAY:15,5,STAINED_CLAY:7,5,quark:iron_plate_slab:8,15,quark:world_stone_pavement:2,15,STAINED_CLAY:9,100)
RandomBlock(-8,44,1,minecraft:iron_bars:0,5,STAINED_CLAY:15,5,STAINED_CLAY:7,5,quark:iron_plate_slab:8,15,quark:world_stone_pavement:2,15,STAINED_CLAY:9,100)
RandomBlock(-8,44,2,minecraft:iron_bars:0,5,STAINED_CLAY:15,5,STAINED_CLAY:7,5,quark:iron_plate_slab:8,15,quark:world_stone_pavement:2,15,STAINED_CLAY:9,100)
RandomBlock(-8,44,3,minecraft:iron_bars:0,5,STAINED_CLAY:15,5,STAINED_CLAY:7,5,quark:iron_plate_slab:8,15,quark:world_stone_pavement:2,15,STAINED_CLAY:9,100)
RandomBlock(-8,44,4,minecraft:iron_bars:0,5,STAINED_CLAY:15,5,STAINED_CLAY:7,5,quark:iron_plate_slab:8,15,quark:world_stone_pavement:2,15,STAINED_CLAY:9,100)
RandomBlock(-8,44,5,minecraft:iron_bars:0,5,STAINED_CLAY:15,5,STAINED_CLAY:7,5,quark:iron_plate_slab:8,15,quark:world_stone_pavement:2,15,STAINED_CLAY:9,100)
RandomBlock(-8,44,6,minecraft:iron_bars:0,5,STAINED_CLAY:15,5,STAINED_CLAY:7,5,quark:iron_plate_slab:8,15,quark:world_stone_pavement:2,15,STAINED_CLAY:9,100)
RandomBlock(-8,44,7,minecraft:iron_bars:0,5,STAINED_CLAY:15,5,STAINED_CLAY:7,5,quark:iron_plate_slab:8,15,quark:world_stone_pavement:2,15,STAINED_CLAY:9,100)
RandomBlock(-8,44,8,minecraft:iron_bars:0,5,STAINED_CLAY:15,5,STAINED_CLAY:7,5,quark:iron_plate_slab:8,15,quark:world_stone_pavement:2,15,STAINED_CLAY:9,100)
RandomBlock(-8,45,5,minecraft:iron_bars:0,5,CONCRETE_POWDER:8,10,quark:limestone:1,15,quark:limestone,15,quark:world_stone_pavement:2,15,CONCRETE:8,100)
RandomBlock(-8,45,6,minecraft:iron_bars:0,5,CONCRETE_POWDER:8,10,quark:limestone:1,15,quark:limestone,15,quark:world_stone_pavement:2,15,CONCRETE:8,100)
RandomBlock(-8,46,-4,minecraft:iron_bars:0,5,CONCRETE_POWDER:8,10,quark:limestone:1,15,quark:limestone,15,quark:world_stone_pavement:2,15,CONCRETE:8,100)
RandomBlock(-8,46,-3,minecraft:iron_bars:0,5,CONCRETE_POWDER:8,10,quark:limestone:1,15,quark:limestone,15,quark:world_stone_pavement:2,15,CONCRETE:8,100)
RandomBlock(-8,46,1,minecraft:iron_bars:0,5,CONCRETE_POWDER:8,10,quark:limestone:1,15,quark:limestone,15,quark:world_stone_pavement:2,15,CONCRETE:8,100)
RandomBlock(-8,46,2,minecraft:iron_bars:0,5,CONCRETE_POWDER:8,10,quark:limestone:1,15,quark:limestone,15,quark:world_stone_pavement:2,15,CONCRETE:8,100)
Block(-8,46,5,CONCRETE:15)
Block(-8,46,6,CONCRETE:15)
Block(-8,46,8,STONE_BUTTON:2)
RandomBlock(-8,47,-4,minecraft:iron_bars:0,5,CONCRETE_POWDER:8,10,quark:limestone:1,15,quark:limestone,15,quark:world_stone_pavement:2,15,CONCRETE:8,100)
RandomBlock(-8,47,-3,minecraft:iron_bars:0,5,CONCRETE_POWDER:8,10,quark:limestone:1,15,quark:limestone,15,quark:world_stone_pavement:2,15,CONCRETE:8,100)
RandomBlock(-8,47,1,minecraft:iron_bars:0,5,CONCRETE_POWDER:8,10,quark:limestone:1,15,quark:limestone,15,quark:world_stone_pavement:2,15,CONCRETE:8,100)
RandomBlock(-8,47,2,minecraft:iron_bars:0,5,CONCRETE_POWDER:8,10,quark:limestone:1,15,quark:limestone,15,quark:world_stone_pavement:2,15,CONCRETE:8,100)
RandomBlock(-8,47,5,minecraft:iron_bars:0,5,CONCRETE_POWDER:8,10,quark:limestone:1,15,quark:limestone,15,quark:world_stone_pavement:2,15,CONCRETE:8,100)
RandomBlock(-8,47,6,minecraft:iron_bars:0,5,CONCRETE_POWDER:8,10,quark:limestone:1,15,quark:limestone,15,quark:world_stone_pavement:2,15,CONCRETE:8,100)
RandomBlock(-8,48,5,minecraft:iron_bars:0,5,CONCRETE_POWDER:8,10,quark:limestone:1,15,quark:limestone,15,quark:world_stone_pavement:2,15,CONCRETE:8,100)
RandomBlock(-8,48,6,minecraft:iron_bars:0,5,CONCRETE_POWDER:8,10,quark:limestone:1,15,quark:limestone,15,quark:world_stone_pavement:2,15,CONCRETE:8,100)
RandomBlock(-8,49,5,minecraft:iron_bars:0,5,CONCRETE_POWDER:8,10,quark:limestone:1,15,quark:limestone,15,quark:world_stone_pavement:2,15,CONCRETE:8,100)
RandomBlock(-8,49,6,minecraft:iron_bars:0,5,CONCRETE_POWDER:8,10,quark:limestone:1,15,quark:limestone,15,quark:world_stone_pavement:2,15,CONCRETE:8,100)
RandomBlock(-8,49,7,minecraft:iron_bars:0,5,STAINED_CLAY:15,5,STAINED_CLAY:7,5,quark:iron_plate_slab:8,15,quark:world_stone_pavement:2,15,STAINED_CLAY:9,100)
RandomBlock(-8,49,8,minecraft:iron_bars:0,5,STAINED_CLAY:15,5,STAINED_CLAY:7,5,quark:iron_plate_slab:8,15,quark:world_stone_pavement:2,15,STAINED_CLAY:9,100)
RandomBlock(-8,50,-7,minecraft:iron_bars:0,5,STAINED_CLAY:15,5,STAINED_CLAY:7,5,quark:iron_plate_slab:8,15,quark:world_stone_pavement:2,15,STAINED_CLAY:9,100)
RandomBlock(-8,50,-6,minecraft:iron_bars:0,5,STAINED_CLAY:15,5,STAINED_CLAY:7,5,quark:iron_plate_slab:8,15,quark:world_stone_pavement:2,15,STAINED_CLAY:9,100)
RandomBlock(-8,50,-5,minecraft:iron_bars:0,5,STAINED_CLAY:15,5,STAINED_CLAY:7,5,quark:iron_plate_slab:8,15,quark:world_stone_pavement:2,15,STAINED_CLAY:9,100)
RandomBlock(-8,50,-4,minecraft:iron_bars:0,5,STAINED_CLAY:15,5,STAINED_CLAY:7,5,quark:iron_plate_slab:8,15,quark:world_stone_pavement:2,15,STAINED_CLAY:9,100)
RandomBlock(-8,50,-3,minecraft:iron_bars:0,5,STAINED_CLAY:15,5,STAINED_CLAY:7,5,quark:iron_plate_slab:8,15,quark:world_stone_pavement:2,15,STAINED_CLAY:9,100)
RandomBlock(-8,50,-2,minecraft:iron_bars:0,5,STAINED_CLAY:15,5,STAINED_CLAY:7,5,quark:iron_plate_slab:8,15,quark:world_stone_pavement:2,15,STAINED_CLAY:9,100)
RandomBlock(-8,50,-1,minecraft:iron_bars:0,5,STAINED_CLAY:15,5,STAINED_CLAY:7,5,quark:iron_plate_slab:8,15,quark:world_stone_pavement:2,15,STAINED_CLAY:9,100)
RandomBlock(-8,50,0,minecraft:iron_bars:0,5,STAINED_CLAY:15,5,STAINED_CLAY:7,5,quark:iron_plate_slab:8,15,quark:world_stone_pavement:2,15,STAINED_CLAY:9,100)
RandomBlock(-8,50,1,minecraft:iron_bars:0,5,STAINED_CLAY:15,5,STAINED_CLAY:7,5,quark:iron_plate_slab:8,15,quark:world_stone_pavement:2,15,STAINED_CLAY:9,100)
RandomBlock(-8,50,2,minecraft:iron_bars:0,5,CONCRETE_POWDER:8,10,quark:limestone:1,15,quark:limestone,15,quark:world_stone_pavement:2,15,CONCRETE:8,100)
Block(-8,50,5,minecraft:iron_bars:0)
Block(-8,50,6,minecraft:iron_bars:0)
Block(-8,51,2,minecraft:iron_bars:0)
Block(-8,51,5,minecraft:iron_bars:0)
Block(-8,51,6,minecraft:iron_bars:0)
Block(-8,52,2,minecraft:iron_bars:0)
RandomBlock(-8,54,-7,minecraft:iron_bars:0,5,CONCRETE_POWDER:8,10,quark:limestone:1,15,quark:limestone,15,quark:world_stone_pavement:2,15,CONCRETE:8,100)
RandomBlock(-8,54,-6,minecraft:iron_bars:0,5,CONCRETE_POWDER:8,10,quark:limestone:1,15,quark:limestone,15,quark:world_stone_pavement:2,15,CONCRETE:8,100)
RandomBlock(-8,54,-5,minecraft:iron_bars:0,5,CONCRETE_POWDER:8,10,quark:limestone:1,15,quark:limestone,15,quark:world_stone_pavement:2,15,CONCRETE:8,100)
RandomBlock(-8,54,-4,minecraft:iron_bars:0,5,CONCRETE_POWDER:8,10,quark:limestone:1,15,quark:limestone,15,quark:world_stone_pavement:2,15,CONCRETE:8,100)
RandomBlock(-8,54,-3,minecraft:iron_bars:0,5,CONCRETE_POWDER:8,10,quark:limestone:1,15,quark:limestone,15,quark:world_stone_pavement:2,15,CONCRETE:8,100)
RandomBlock(-8,54,-2,minecraft:iron_bars:0,5,CONCRETE_POWDER:8,10,quark:limestone:1,15,quark:limestone,15,quark:world_stone_pavement:2,15,CONCRETE:8,100)
RandomBlock(-8,54,-1,minecraft:iron_bars:0,5,CONCRETE_POWDER:8,10,quark:limestone:1,15,quark:limestone,15,quark:world_stone_pavement:2,15,CONCRETE:8,100)
RandomBlock(-8,54,0,minecraft:iron_bars:0,5,CONCRETE_POWDER:8,10,quark:limestone:1,15,quark:limestone,15,quark:world_stone_pavement:2,15,CONCRETE:8,100)
RandomBlock(-8,54,1,minecraft:iron_bars:0,5,CONCRETE_POWDER:8,10,quark:limestone:1,15,quark:limestone,15,quark:world_stone_pavement:2,15,CONCRETE:8,100)
Block(-8,55,-7,minecraft:iron_bars:0)
Block(-8,55,-6,minecraft:iron_bars:0)
Block(-8,55,-5,minecraft:iron_bars:0)
Block(-8,55,-4,minecraft:iron_bars:0)
Block(-8,55,-3,minecraft:iron_bars:0)
Block(-8,55,-2,minecraft:iron_bars:0)
Block(-8,55,-1,minecraft:iron_bars:0)
Block(-8,55,0,minecraft:iron_bars:0)
Block(-8,55,1,minecraft:iron_bars:0)
Block(-8,56,-7,minecraft:iron_bars:0)
Block(-8,56,-6,minecraft:iron_bars:0)
Block(-8,56,-5,minecraft:iron_bars:0)
Block(-8,56,-4,minecraft:iron_bars:0)
Block(-8,56,-3,minecraft:iron_bars:0)
Block(-8,56,-2,minecraft:iron_bars:0)
Block(-8,56,-1,minecraft:iron_bars:0)
Block(-8,56,0,minecraft:iron_bars:0)
Block(-8,56,1,minecraft:iron_bars:0)
Block(-8,58,-7,STEP:13)
Block(-8,58,-6,minecraft:iron_bars:0)
Block(-8,58,-5,quark:basalt_wall)
Block(-8,58,-4,minecraft:iron_bars:0)
Block(-8,58,-3,quark:basalt_wall)
Block(-8,58,-2,minecraft:iron_bars:0)
Block(-8,58,-1,STEP:13)
Block(-8,59,-7,IRON_FENCE:0)
Block(-8,59,-6,STEP:0)
Block(-8,59,-5,STEP:0)
Block(-8,59,-3,STEP:0)
Block(-8,59,-2,STEP:0)
Block(-8,59,-1,IRON_FENCE:0)
Block(-8,65,8,minecraft:iron_bars:0)
Block(-8,66,8,IRON_FENCE:0)
Block(-7,43,5,STONE:6)
RandomBlock(-7,44,-7,minecraft:iron_bars:0,5,STAINED_CLAY:15,5,STAINED_CLAY:7,5,quark:iron_plate_slab:8,15,quark:world_stone_pavement:2,15,STAINED_CLAY:9,100)
RandomBlock(-7,44,-6,minecraft:iron_bars:0,5,STAINED_CLAY:15,5,STAINED_CLAY:7,5,quark:iron_plate_slab:8,15,quark:world_stone_pavement:2,15,STAINED_CLAY:9,100)
RandomBlock(-7,44,-5,minecraft:iron_bars:0,5,STAINED_CLAY:15,5,STAINED_CLAY:7,5,quark:iron_plate_slab:8,15,quark:world_stone_pavement:2,15,STAINED_CLAY:9,100)
RandomBlock(-7,44,-4,minecraft:iron_bars:0,5,STAINED_CLAY:15,5,STAINED_CLAY:7,5,quark:iron_plate_slab:8,15,quark:world_stone_pavement:2,15,STAINED_CLAY:9,100)
RandomBlock(-7,44,-3,minecraft:iron_bars:0,5,STAINED_CLAY:15,5,STAINED_CLAY:7,5,quark:iron_plate_slab:8,15,quark:world_stone_pavement:2,15,STAINED_CLAY:9,100)
RandomBlock(-7,44,-2,minecraft:iron_bars:0,5,STAINED_CLAY:15,5,STAINED_CLAY:7,5,quark:iron_plate_slab:8,15,quark:world_stone_pavement:2,15,STAINED_CLAY:9,100)
RandomBlock(-7,44,-1,minecraft:iron_bars:0,5,STAINED_CLAY:15,5,STAINED_CLAY:7,5,quark:iron_plate_slab:8,15,quark:world_stone_pavement:2,15,STAINED_CLAY:9,100)
RandomBlock(-7,44,0,minecraft:iron_bars:0,5,STAINED_CLAY:15,5,STAINED_CLAY:7,5,quark:iron_plate_slab:8,15,quark:world_stone_pavement:2,15,STAINED_CLAY:9,100)
RandomBlock(-7,44,1,minecraft:iron_bars:0,5,STAINED_CLAY:15,5,STAINED_CLAY:7,5,quark:iron_plate_slab:8,15,quark:world_stone_pavement:2,15,STAINED_CLAY:9,100)
RandomBlock(-7,44,2,minecraft:iron_bars:0,5,STAINED_CLAY:15,5,STAINED_CLAY:7,5,quark:iron_plate_slab:8,15,quark:world_stone_pavement:2,15,STAINED_CLAY:9,100)
RandomBlock(-7,44,3,minecraft:iron_bars:0,5,STAINED_CLAY:15,5,STAINED_CLAY:7,5,quark:iron_plate_slab:8,15,quark:world_stone_pavement:2,15,STAINED_CLAY:9,100)
RandomBlock(-7,44,4,minecraft:iron_bars:0,5,STAINED_CLAY:15,5,STAINED_CLAY:7,5,quark:iron_plate_slab:8,15,quark:world_stone_pavement:2,15,STAINED_CLAY:9,100)
RandomBlock(-7,44,5,minecraft:iron_bars:0,5,STAINED_CLAY:15,5,STAINED_CLAY:7,5,quark:iron_plate_slab:8,15,quark:world_stone_pavement:2,15,STAINED_CLAY:9,100)
RandomBlock(-7,44,6,minecraft:iron_bars:0,5,STAINED_CLAY:15,5,STAINED_CLAY:7,5,quark:iron_plate_slab:8,15,quark:world_stone_pavement:2,15,STAINED_CLAY:9,100)
RandomBlock(-7,44,7,minecraft:iron_bars:0,5,STAINED_CLAY:15,5,STAINED_CLAY:7,5,quark:iron_plate_slab:8,15,quark:world_stone_pavement:2,15,STAINED_CLAY:9,100)
RandomBlock(-7,44,8,minecraft:iron_bars:0,5,STAINED_CLAY:15,5,STAINED_CLAY:7,5,quark:iron_plate_slab:8,15,quark:world_stone_pavement:2,15,STAINED_CLAY:9,100)
Block(-7,45,-5,minecraft:iron_bars:0)
RandomBlock(-7,45,-4,minecraft:iron_bars:0,5,CONCRETE_POWDER:8,10,quark:limestone:1,15,quark:limestone,15,quark:world_stone_pavement:2,15,CONCRETE:8,100)
RandomBlock(-7,45,-3,minecraft:iron_bars:0,5,CONCRETE_POWDER:8,10,quark:limestone:1,15,quark:limestone,15,quark:world_stone_pavement:2,15,CONCRETE:8,100)
RandomBlock(-7,45,1,minecraft:iron_bars:0,5,CONCRETE_POWDER:8,10,quark:limestone:1,15,quark:limestone,15,quark:world_stone_pavement:2,15,CONCRETE:8,100)
RandomBlock(-7,45,2,minecraft:iron_bars:0,5,CONCRETE_POWDER:8,10,quark:limestone:1,15,quark:limestone,15,quark:world_stone_pavement:2,15,CONCRETE:8,100)
Block(-7,45,3,minecraft:iron_bars:0)
RandomBlock(-7,45,5,minecraft:iron_bars:0,5,CONCRETE_POWDER:8,10,quark:limestone:1,15,quark:limestone,15,quark:world_stone_pavement:2,15,CONCRETE:8,100)
Block(-7,45,6,MOB_SPAWNER:0,../../ruins_spawners/industrial_multi.nbt)
Block(-7,45,8,DISPENSER:1)
RandomBlock(-7,46,-5,minecraft:iron_bars:0,5,CONCRETE_POWDER:8,10,quark:limestone:1,15,quark:limestone,15,quark:world_stone_pavement:2,15,CONCRETE:8,100)
Block(-7,46,-4,COAL_BLOCK:0)
Block(-7,46,-3,COAL_BLOCK:0)
RandomBlock(-7,46,-2,minecraft:iron_bars:0,5,CONCRETE_POWDER:8,10,quark:limestone:1,15,quark:limestone,15,quark:world_stone_pavement:2,15,CONCRETE:8,100)
RandomBlock(-7,46,0,minecraft:iron_bars:0,5,CONCRETE_POWDER:8,10,quark:limestone:1,15,quark:limestone,15,quark:world_stone_pavement:2,15,CONCRETE:8,100)
Block(-7,46,1,COAL_BLOCK:0)
Block(-7,46,2,COAL_BLOCK:0)
RandomBlock(-7,46,3,minecraft:iron_bars:0,5,CONCRETE_POWDER:8,10,quark:limestone:1,15,quark:limestone,15,quark:world_stone_pavement:2,15,CONCRETE:8,100)
Block(-7,46,5,CONCRETE:15)
Block(-7,46,8,DOUBLE_STEP:0)
RandomBlock(-7,47,-5,minecraft:iron_bars:0,5,CONCRETE_POWDER:8,10,quark:limestone:1,15,quark:limestone,15,quark:world_stone_pavement:2,15,CONCRETE:8,100)
Block(-7,47,-4,COAL_BLOCK:0)
Block(-7,47,-3,COAL_BLOCK:0)
RandomBlock(-7,47,-2,minecraft:iron_bars:0,5,CONCRETE_POWDER:8,10,quark:limestone:1,15,quark:limestone,15,quark:world_stone_pavement:2,15,CONCRETE:8,100)
RandomBlock(-7,47,0,minecraft:iron_bars:0,5,CONCRETE_POWDER:8,10,quark:limestone:1,15,quark:limestone,15,quark:world_stone_pavement:2,15,CONCRETE:8,100)
Block(-7,47,1,COAL_BLOCK:0)
Block(-7,47,2,COAL_BLOCK:0)
RandomBlock(-7,47,3,minecraft:iron_bars:0,5,CONCRETE_POWDER:8,10,quark:limestone:1,15,quark:limestone,15,quark:world_stone_pavement:2,15,CONCRETE:8,100)
RandomBlock(-7,47,5,minecraft:iron_bars:0,5,CONCRETE_POWDER:8,10,quark:limestone:1,15,quark:limestone,15,quark:world_stone_pavement:2,15,CONCRETE:8,100)
Block(-7,47,8,quark:basalt_wall)
RandomBlock(-7,48,-4,minecraft:iron_bars:0,5,CONCRETE_POWDER:8,10,quark:limestone:1,15,quark:limestone,15,quark:world_stone_pavement:2,15,CONCRETE:8,100)
RandomBlock(-7,48,-3,minecraft:iron_bars:0,5,CONCRETE_POWDER:8,10,quark:limestone:1,15,quark:limestone,15,quark:world_stone_pavement:2,15,CONCRETE:8,100)
RandomBlock(-7,48,1,minecraft:iron_bars:0,5,CONCRETE_POWDER:8,10,quark:limestone:1,15,quark:limestone,15,quark:world_stone_pavement:2,15,CONCRETE:8,100)
RandomBlock(-7,48,2,minecraft:iron_bars:0,5,CONCRETE_POWDER:8,10,quark:limestone:1,15,quark:limestone,15,quark:world_stone_pavement:2,15,CONCRETE:8,100)
RandomBlock(-7,48,5,minecraft:iron_bars:0,5,CONCRETE_POWDER:8,10,quark:limestone:1,15,quark:limestone,15,quark:world_stone_pavement:2,15,CONCRETE:8,100)
Block(-7,48,8,quark:basalt_wall)
Block(-7,49,-4,quark:basalt_wall)
Block(-7,49,2,quark:basalt_wall)
RandomBlock(-7,49,5,minecraft:iron_bars:0,5,CONCRETE_POWDER:8,10,quark:limestone:1,15,quark:limestone,15,quark:world_stone_pavement:2,15,CONCRETE:8,100)
RandomBlock(-7,49,6,minecraft:iron_bars:0,5,STAINED_CLAY:15,5,STAINED_CLAY:7,5,quark:iron_plate_slab:8,15,quark:world_stone_pavement:2,15,STAINED_CLAY:9,100)
RandomBlock(-7,49,7,minecraft:iron_bars:0,5,STAINED_CLAY:15,5,STAINED_CLAY:7,5,quark:iron_plate_slab:8,15,quark:world_stone_pavement:2,15,STAINED_CLAY:9,100)
RandomBlock(-7,49,8,minecraft:iron_bars:0,5,STAINED_CLAY:15,5,STAINED_CLAY:7,5,quark:iron_plate_slab:8,15,quark:world_stone_pavement:2,15,STAINED_CLAY:9,100)
RandomBlock(-7,50,-7,minecraft:iron_bars:0,5,STAINED_CLAY:15,5,STAINED_CLAY:7,5,quark:iron_plate_slab:8,15,quark:world_stone_pavement:2,15,STAINED_CLAY:9,100)
RandomBlock(-7,50,-6,minecraft:iron_bars:0,5,STAINED_CLAY:15,5,STAINED_CLAY:7,5,quark:iron_plate_slab:8,15,quark:world_stone_pavement:2,15,STAINED_CLAY:9,100)
RandomBlock(-7,50,-5,minecraft:iron_bars:0,5,STAINED_CLAY:15,5,STAINED_CLAY:7,5,quark:iron_plate_slab:8,15,quark:world_stone_pavement:2,15,STAINED_CLAY:9,100)
RandomBlock(-7,50,-4,minecraft:iron_bars:0,5,STAINED_CLAY:15,5,STAINED_CLAY:7,5,quark:iron_plate_slab:8,15,quark:world_stone_pavement:2,15,STAINED_CLAY:9,100)
RandomBlock(-7,50,-3,minecraft:iron_bars:0,5,STAINED_CLAY:15,5,STAINED_CLAY:7,5,quark:iron_plate_slab:8,15,quark:world_stone_pavement:2,15,STAINED_CLAY:9,100)
RandomBlock(-7,50,-2,minecraft:iron_bars:0,5,STAINED_CLAY:15,5,STAINED_CLAY:7,5,quark:iron_plate_slab:8,15,quark:world_stone_pavement:2,15,STAINED_CLAY:9,100)
RandomBlock(-7,50,-1,minecraft:iron_bars:0,5,STAINED_CLAY:15,5,STAINED_CLAY:7,5,quark:iron_plate_slab:8,15,quark:world_stone_pavement:2,15,STAINED_CLAY:9,100)
RandomBlock(-7,50,0,minecraft:iron_bars:0,5,STAINED_CLAY:15,5,STAINED_CLAY:7,5,quark:iron_plate_slab:8,15,quark:world_stone_pavement:2,15,STAINED_CLAY:9,100)
RandomBlock(-7,50,1,minecraft:iron_bars:0,5,STAINED_CLAY:15,5,STAINED_CLAY:7,5,quark:iron_plate_slab:8,15,quark:world_stone_pavement:2,15,STAINED_CLAY:9,100)
RandomBlock(-7,50,2,minecraft:iron_bars:0,5,CONCRETE_POWDER:8,10,quark:limestone:1,15,quark:limestone,15,quark:world_stone_pavement:2,15,CONCRETE:8,100)
Block(-7,50,5,minecraft:iron_bars:0)
Block(-7,50,7,STONE:6)
Block(-7,50,8,STONE:6)
Block(-7,51,2,minecraft:iron_bars:0)
Block(-7,51,5,minecraft:iron_bars:0)
Block(-7,52,2,minecraft:iron_bars:0)
RandomBlock(-7,54,-7,minecraft:iron_bars:0,5,CONCRETE_POWDER:8,10,quark:limestone:1,15,quark:limestone,15,quark:world_stone_pavement:2,15,CONCRETE:8,100)
Block(-7,55,-7,minecraft:iron_bars:0)
Block(-7,56,-7,minecraft:iron_bars:0)
Block(-7,58,-7,STEP:13)
Block(-7,58,-6,minecraft:iron_bars:0)
Block(-7,58,-5,quark:basalt_wall)
Block(-7,58,-4,minecraft:iron_bars:0)
Block(-7,58,-3,quark:basalt_wall)
Block(-7,58,-2,minecraft:iron_bars:0)
Block(-7,58,-1,STEP:13)
Block(-7,59,-7,IRON_FENCE:0)
Block(-7,59,-6,STEP:0)
Block(-7,59,-5,STEP:0)
Block(-7,59,-3,STEP:0)
Block(-7,59,-2,STEP:0)
Block(-7,59,-1,IRON_FENCE:0)
Block(-7,65,8,minecraft:iron_bars:0)
Block(-7,66,8,IRON_FENCE:0)
RandomBlock(-6,0,3,minecraft:iron_bars:0,5,quark:iron_plate:1,15,STAINED_CLAY:15,15,STAINED_CLAY:7,100)
RandomBlock(-6,0,4,minecraft:iron_bars:0,5,quark:iron_plate:1,15,STAINED_CLAY:15,15,STAINED_CLAY:7,100)
RandomBlock(-6,0,5,minecraft:iron_bars:0,5,quark:iron_plate:1,15,STAINED_CLAY:15,15,STAINED_CLAY:7,100)
RandomBlock(-6,0,6,minecraft:iron_bars:0,5,quark:iron_plate:1,15,STAINED_CLAY:15,15,STAINED_CLAY:7,100)
RandomBlock(-6,1,3,minecraft:iron_bars:0,5,quark:iron_plate:1,15,STAINED_CLAY:15,15,STAINED_CLAY:7,100)
RandomBlock(-6,1,4,minecraft:iron_bars:0,5,quark:iron_plate:1,15,STAINED_CLAY:15,15,STAINED_CLAY:7,100)
RandomBlock(-6,1,5,minecraft:iron_bars:0,5,quark:iron_plate:1,15,STAINED_CLAY:15,15,STAINED_CLAY:7,100)
RandomBlock(-6,1,6,minecraft:iron_bars:0,5,quark:iron_plate:1,15,STAINED_CLAY:15,15,STAINED_CLAY:7,100)
RandomBlock(-6,2,3,minecraft:iron_bars:0,5,quark:iron_plate:1,15,STAINED_CLAY:15,15,STAINED_CLAY:7,100)
RandomBlock(-6,2,4,minecraft:iron_bars:0,5,quark:iron_plate:1,15,STAINED_CLAY:15,15,STAINED_CLAY:7,100)
RandomBlock(-6,2,5,minecraft:iron_bars:0,5,quark:iron_plate:1,15,STAINED_CLAY:15,15,STAINED_CLAY:7,100)
RandomBlock(-6,2,6,minecraft:iron_bars:0,5,quark:iron_plate:1,15,STAINED_CLAY:15,15,STAINED_CLAY:7,100)
RandomBlock(-6,3,3,minecraft:iron_bars:0,5,quark:iron_plate:1,15,STAINED_CLAY:15,15,STAINED_CLAY:7,100)
RandomBlock(-6,3,4,minecraft:iron_bars:0,5,quark:iron_plate:1,15,STAINED_CLAY:15,15,STAINED_CLAY:7,100)
RandomBlock(-6,3,5,minecraft:iron_bars:0,5,quark:iron_plate:1,15,STAINED_CLAY:15,15,STAINED_CLAY:7,100)
RandomBlock(-6,3,6,minecraft:iron_bars:0,5,quark:iron_plate:1,15,STAINED_CLAY:15,15,STAINED_CLAY:7,100)
RandomBlock(-6,4,3,minecraft:iron_bars:0,5,quark:iron_plate:1,15,STAINED_CLAY:15,15,STAINED_CLAY:7,100)
RandomBlock(-6,4,4,minecraft:iron_bars:0,5,quark:iron_plate:1,15,STAINED_CLAY:15,15,STAINED_CLAY:7,100)
RandomBlock(-6,4,5,minecraft:iron_bars:0,5,quark:iron_plate:1,15,STAINED_CLAY:15,15,STAINED_CLAY:7,100)
RandomBlock(-6,4,6,minecraft:iron_bars:0,5,quark:iron_plate:1,15,STAINED_CLAY:15,15,STAINED_CLAY:7,100)
RandomBlock(-6,5,3,minecraft:iron_bars:0,5,quark:iron_plate:1,15,STAINED_CLAY:15,15,STAINED_CLAY:7,100)
RandomBlock(-6,5,4,minecraft:iron_bars:0,5,quark:iron_plate:1,15,STAINED_CLAY:15,15,STAINED_CLAY:7,100)
RandomBlock(-6,5,5,minecraft:iron_bars:0,5,quark:iron_plate:1,15,STAINED_CLAY:15,15,STAINED_CLAY:7,100)
RandomBlock(-6,5,6,minecraft:iron_bars:0,5,quark:iron_plate:1,15,STAINED_CLAY:15,15,STAINED_CLAY:7,100)
RandomBlock(-6,6,3,minecraft:iron_bars:0,5,quark:iron_plate:1,15,STAINED_CLAY:15,15,STAINED_CLAY:7,100)
RandomBlock(-6,6,4,minecraft:iron_bars:0,5,quark:iron_plate:1,15,STAINED_CLAY:15,15,STAINED_CLAY:7,100)
RandomBlock(-6,6,5,minecraft:iron_bars:0,5,quark:iron_plate:1,15,STAINED_CLAY:15,15,STAINED_CLAY:7,100)
RandomBlock(-6,6,6,minecraft:iron_bars:0,5,quark:iron_plate:1,15,STAINED_CLAY:15,15,STAINED_CLAY:7,100)
RandomBlock(-6,7,3,minecraft:iron_bars:0,5,quark:iron_plate:1,15,STAINED_CLAY:15,15,STAINED_CLAY:7,100)
RandomBlock(-6,7,4,minecraft:iron_bars:0,5,quark:iron_plate:1,15,STAINED_CLAY:15,15,STAINED_CLAY:7,100)
RandomBlock(-6,7,5,minecraft:iron_bars:0,5,quark:iron_plate:1,15,STAINED_CLAY:15,15,STAINED_CLAY:7,100)
RandomBlock(-6,7,6,minecraft:iron_bars:0,5,quark:iron_plate:1,15,STAINED_CLAY:15,15,STAINED_CLAY:7,100)
RandomBlock(-6,8,3,minecraft:iron_bars:0,5,quark:iron_plate:1,15,STAINED_CLAY:15,15,STAINED_CLAY:7,100)
RandomBlock(-6,8,4,minecraft:iron_bars:0,5,quark:iron_plate:1,15,STAINED_CLAY:15,15,STAINED_CLAY:7,100)
RandomBlock(-6,8,5,minecraft:iron_bars:0,5,quark:iron_plate:1,15,STAINED_CLAY:15,15,STAINED_CLAY:7,100)
RandomBlock(-6,8,6,minecraft:iron_bars:0,5,quark:iron_plate:1,15,STAINED_CLAY:15,15,STAINED_CLAY:7,100)
RandomBlock(-6,9,3,minecraft:iron_bars:0,5,quark:iron_plate:1,15,STAINED_CLAY:15,15,STAINED_CLAY:7,100)
RandomBlock(-6,9,4,minecraft:iron_bars:0,5,quark:iron_plate:1,15,STAINED_CLAY:15,15,STAINED_CLAY:7,100)
RandomBlock(-6,9,5,minecraft:iron_bars:0,5,quark:iron_plate:1,15,STAINED_CLAY:15,15,STAINED_CLAY:7,100)
RandomBlock(-6,9,6,minecraft:iron_bars:0,5,quark:iron_plate:1,15,STAINED_CLAY:15,15,STAINED_CLAY:7,100)
RandomBlock(-6,10,3,minecraft:iron_bars:0,5,quark:iron_plate:1,15,STAINED_CLAY:15,15,STAINED_CLAY:7,100)
RandomBlock(-6,10,4,minecraft:iron_bars:0,5,quark:iron_plate:1,15,STAINED_CLAY:15,15,STAINED_CLAY:7,100)
RandomBlock(-6,10,5,minecraft:iron_bars:0,5,quark:iron_plate:1,15,STAINED_CLAY:15,15,STAINED_CLAY:7,100)
RandomBlock(-6,10,6,minecraft:iron_bars:0,5,quark:iron_plate:1,15,STAINED_CLAY:15,15,STAINED_CLAY:7,100)
RandomBlock(-6,11,3,minecraft:iron_bars:0,5,quark:iron_plate:1,15,STAINED_CLAY:15,15,STAINED_CLAY:7,100)
RandomBlock(-6,11,4,minecraft:iron_bars:0,5,quark:iron_plate:1,15,STAINED_CLAY:15,15,STAINED_CLAY:7,100)
RandomBlock(-6,11,5,minecraft:iron_bars:0,5,quark:iron_plate:1,15,STAINED_CLAY:15,15,STAINED_CLAY:7,100)
RandomBlock(-6,11,6,minecraft:iron_bars:0,5,quark:iron_plate:1,15,STAINED_CLAY:15,15,STAINED_CLAY:7,100)
RandomBlock(-6,12,3,minecraft:iron_bars:0,5,quark:iron_plate:1,15,STAINED_CLAY:15,15,STAINED_CLAY:7,100)
RandomBlock(-6,12,4,minecraft:iron_bars:0,5,quark:iron_plate:1,15,STAINED_CLAY:15,15,STAINED_CLAY:7,100)
RandomBlock(-6,12,5,minecraft:iron_bars:0,5,quark:iron_plate:1,15,STAINED_CLAY:15,15,STAINED_CLAY:7,100)
RandomBlock(-6,12,6,minecraft:iron_bars:0,5,quark:iron_plate:1,15,STAINED_CLAY:15,15,STAINED_CLAY:7,100)
RandomBlock(-6,13,3,minecraft:iron_bars:0,5,quark:iron_plate:1,15,STAINED_CLAY:15,15,STAINED_CLAY:7,100)
RandomBlock(-6,13,4,minecraft:iron_bars:0,5,quark:iron_plate:1,15,STAINED_CLAY:15,15,STAINED_CLAY:7,100)
RandomBlock(-6,13,5,minecraft:iron_bars:0,5,quark:iron_plate:1,15,STAINED_CLAY:15,15,STAINED_CLAY:7,100)
RandomBlock(-6,13,6,minecraft:iron_bars:0,5,quark:iron_plate:1,15,STAINED_CLAY:15,15,STAINED_CLAY:7,100)
RandomBlock(-6,14,3,minecraft:iron_bars:0,5,quark:iron_plate:1,15,STAINED_CLAY:15,15,STAINED_CLAY:7,100)
RandomBlock(-6,14,4,minecraft:iron_bars:0,5,quark:iron_plate:1,15,STAINED_CLAY:15,15,STAINED_CLAY:7,100)
RandomBlock(-6,14,5,minecraft:iron_bars:0,5,quark:iron_plate:1,15,STAINED_CLAY:15,15,STAINED_CLAY:7,100)
RandomBlock(-6,14,6,minecraft:iron_bars:0,5,quark:iron_plate:1,15,STAINED_CLAY:15,15,STAINED_CLAY:7,100)
RandomBlock(-6,15,3,minecraft:iron_bars:0,5,quark:iron_plate:1,15,STAINED_CLAY:15,15,STAINED_CLAY:7,100)
RandomBlock(-6,15,4,minecraft:iron_bars:0,5,quark:iron_plate:1,15,STAINED_CLAY:15,15,STAINED_CLAY:7,100)
RandomBlock(-6,15,5,minecraft:iron_bars:0,5,quark:iron_plate:1,15,STAINED_CLAY:15,15,STAINED_CLAY:7,100)
RandomBlock(-6,15,6,minecraft:iron_bars:0,5,quark:iron_plate:1,15,STAINED_CLAY:15,15,STAINED_CLAY:7,100)
RandomBlock(-6,16,3,minecraft:iron_bars:0,5,quark:iron_plate:1,15,STAINED_CLAY:15,15,STAINED_CLAY:7,100)
RandomBlock(-6,16,4,minecraft:iron_bars:0,5,quark:iron_plate:1,15,STAINED_CLAY:15,15,STAINED_CLAY:7,100)
RandomBlock(-6,16,5,minecraft:iron_bars:0,5,quark:iron_plate:1,15,STAINED_CLAY:15,15,STAINED_CLAY:7,100)
RandomBlock(-6,16,6,minecraft:iron_bars:0,5,quark:iron_plate:1,15,STAINED_CLAY:15,15,STAINED_CLAY:7,100)
RandomBlock(-6,17,3,minecraft:iron_bars:0,5,quark:iron_plate:1,15,STAINED_CLAY:15,15,STAINED_CLAY:7,100)
RandomBlock(-6,17,4,minecraft:iron_bars:0,5,quark:iron_plate:1,15,STAINED_CLAY:15,15,STAINED_CLAY:7,100)
RandomBlock(-6,17,5,minecraft:iron_bars:0,5,quark:iron_plate:1,15,STAINED_CLAY:15,15,STAINED_CLAY:7,100)
RandomBlock(-6,17,6,minecraft:iron_bars:0,5,quark:iron_plate:1,15,STAINED_CLAY:15,15,STAINED_CLAY:7,100)
RandomBlock(-6,18,3,minecraft:iron_bars:0,5,quark:iron_plate:1,15,STAINED_CLAY:15,15,STAINED_CLAY:7,100)
RandomBlock(-6,18,4,minecraft:iron_bars:0,5,quark:iron_plate:1,15,STAINED_CLAY:15,15,STAINED_CLAY:7,100)
RandomBlock(-6,18,5,minecraft:iron_bars:0,5,quark:iron_plate:1,15,STAINED_CLAY:15,15,STAINED_CLAY:7,100)
RandomBlock(-6,18,6,minecraft:iron_bars:0,5,quark:iron_plate:1,15,STAINED_CLAY:15,15,STAINED_CLAY:7,100)
RandomBlock(-6,19,3,minecraft:iron_bars:0,5,quark:iron_plate:1,15,STAINED_CLAY:15,15,STAINED_CLAY:7,100)
RandomBlock(-6,19,4,minecraft:iron_bars:0,5,quark:iron_plate:1,15,STAINED_CLAY:15,15,STAINED_CLAY:7,100)
RandomBlock(-6,19,5,minecraft:iron_bars:0,5,quark:iron_plate:1,15,STAINED_CLAY:15,15,STAINED_CLAY:7,100)
RandomBlock(-6,19,6,minecraft:iron_bars:0,5,quark:iron_plate:1,15,STAINED_CLAY:15,15,STAINED_CLAY:7,100)
RandomBlock(-6,20,3,minecraft:iron_bars:0,5,quark:iron_plate:1,15,STAINED_CLAY:15,15,STAINED_CLAY:7,100)
RandomBlock(-6,20,4,minecraft:iron_bars:0,5,quark:iron_plate:1,15,STAINED_CLAY:15,15,STAINED_CLAY:7,100)
RandomBlock(-6,20,5,minecraft:iron_bars:0,5,quark:iron_plate:1,15,STAINED_CLAY:15,15,STAINED_CLAY:7,100)
RandomBlock(-6,20,6,minecraft:iron_bars:0,5,quark:iron_plate:1,15,STAINED_CLAY:15,15,STAINED_CLAY:7,100)
RandomBlock(-6,21,3,minecraft:iron_bars:0,5,quark:iron_plate:1,15,STAINED_CLAY:15,15,STAINED_CLAY:7,100)
RandomBlock(-6,21,4,minecraft:iron_bars:0,5,quark:iron_plate:1,15,STAINED_CLAY:15,15,STAINED_CLAY:7,100)
RandomBlock(-6,21,5,minecraft:iron_bars:0,5,quark:iron_plate:1,15,STAINED_CLAY:15,15,STAINED_CLAY:7,100)
RandomBlock(-6,21,6,minecraft:iron_bars:0,5,quark:iron_plate:1,15,STAINED_CLAY:15,15,STAINED_CLAY:7,100)
RandomBlock(-6,22,3,minecraft:iron_bars:0,5,quark:iron_plate:1,15,STAINED_CLAY:15,15,STAINED_CLAY:7,100)
RandomBlock(-6,22,4,minecraft:iron_bars:0,5,quark:iron_plate:1,15,STAINED_CLAY:15,15,STAINED_CLAY:7,100)
RandomBlock(-6,22,5,minecraft:iron_bars:0,5,quark:iron_plate:1,15,STAINED_CLAY:15,15,STAINED_CLAY:7,100)
RandomBlock(-6,22,6,minecraft:iron_bars:0,5,quark:iron_plate:1,15,STAINED_CLAY:15,15,STAINED_CLAY:7,100)
RandomBlock(-6,23,3,minecraft:iron_bars:0,5,quark:iron_plate:1,15,STAINED_CLAY:15,15,STAINED_CLAY:7,100)
RandomBlock(-6,23,4,minecraft:iron_bars:0,5,quark:iron_plate:1,15,STAINED_CLAY:15,15,STAINED_CLAY:7,100)
RandomBlock(-6,23,5,minecraft:iron_bars:0,5,quark:iron_plate:1,15,STAINED_CLAY:15,15,STAINED_CLAY:7,100)
RandomBlock(-6,23,6,minecraft:iron_bars:0,5,quark:iron_plate:1,15,STAINED_CLAY:15,15,STAINED_CLAY:7,100)
RandomBlock(-6,24,3,minecraft:iron_bars:0,5,quark:iron_plate:1,15,STAINED_CLAY:15,15,STAINED_CLAY:7,100)
RandomBlock(-6,24,4,minecraft:iron_bars:0,5,quark:iron_plate:1,15,STAINED_CLAY:15,15,STAINED_CLAY:7,100)
RandomBlock(-6,24,5,minecraft:iron_bars:0,5,quark:iron_plate:1,15,STAINED_CLAY:15,15,STAINED_CLAY:7,100)
RandomBlock(-6,24,6,minecraft:iron_bars:0,5,quark:iron_plate:1,15,STAINED_CLAY:15,15,STAINED_CLAY:7,100)
RandomBlock(-6,25,3,minecraft:iron_bars:0,5,quark:iron_plate:1,15,STAINED_CLAY:15,15,STAINED_CLAY:7,100)
RandomBlock(-6,25,4,minecraft:iron_bars:0,5,quark:iron_plate:1,15,STAINED_CLAY:15,15,STAINED_CLAY:7,100)
RandomBlock(-6,25,5,minecraft:iron_bars:0,5,quark:iron_plate:1,15,STAINED_CLAY:15,15,STAINED_CLAY:7,100)
RandomBlock(-6,25,6,minecraft:iron_bars:0,5,quark:iron_plate:1,15,STAINED_CLAY:15,15,STAINED_CLAY:7,100)
RandomBlock(-6,26,3,minecraft:iron_bars:0,5,quark:iron_plate:1,15,STAINED_CLAY:15,15,STAINED_CLAY:7,100)
RandomBlock(-6,26,4,minecraft:iron_bars:0,5,quark:iron_plate:1,15,STAINED_CLAY:15,15,STAINED_CLAY:7,100)
RandomBlock(-6,26,5,minecraft:iron_bars:0,5,quark:iron_plate:1,15,STAINED_CLAY:15,15,STAINED_CLAY:7,100)
RandomBlock(-6,26,6,minecraft:iron_bars:0,5,quark:iron_plate:1,15,STAINED_CLAY:15,15,STAINED_CLAY:7,100)
RandomBlock(-6,27,3,minecraft:iron_bars:0,5,quark:iron_plate:1,15,STAINED_CLAY:15,15,STAINED_CLAY:7,100)
RandomBlock(-6,27,4,minecraft:iron_bars:0,5,quark:iron_plate:1,15,STAINED_CLAY:15,15,STAINED_CLAY:7,100)
RandomBlock(-6,27,5,minecraft:iron_bars:0,5,quark:iron_plate:1,15,STAINED_CLAY:15,15,STAINED_CLAY:7,100)
RandomBlock(-6,27,6,minecraft:iron_bars:0,5,quark:iron_plate:1,15,STAINED_CLAY:15,15,STAINED_CLAY:7,100)
RandomBlock(-6,28,3,minecraft:iron_bars:0,5,quark:iron_plate:1,15,STAINED_CLAY:15,15,STAINED_CLAY:7,100)
RandomBlock(-6,28,4,minecraft:iron_bars:0,5,quark:iron_plate:1,15,STAINED_CLAY:15,15,STAINED_CLAY:7,100)
RandomBlock(-6,28,5,minecraft:iron_bars:0,5,quark:iron_plate:1,15,STAINED_CLAY:15,15,STAINED_CLAY:7,100)
RandomBlock(-6,28,6,minecraft:iron_bars:0,5,quark:iron_plate:1,15,STAINED_CLAY:15,15,STAINED_CLAY:7,100)
RandomBlock(-6,29,3,minecraft:iron_bars:0,5,quark:iron_plate:1,15,STAINED_CLAY:15,15,STAINED_CLAY:7,100)
RandomBlock(-6,29,4,minecraft:iron_bars:0,5,quark:iron_plate:1,15,STAINED_CLAY:15,15,STAINED_CLAY:7,100)
RandomBlock(-6,29,5,minecraft:iron_bars:0,5,quark:iron_plate:1,15,STAINED_CLAY:15,15,STAINED_CLAY:7,100)
RandomBlock(-6,29,6,minecraft:iron_bars:0,5,quark:iron_plate:1,15,STAINED_CLAY:15,15,STAINED_CLAY:7,100)
RandomBlock(-6,30,3,minecraft:iron_bars:0,5,quark:iron_plate:1,15,STAINED_CLAY:15,15,STAINED_CLAY:7,100)
RandomBlock(-6,30,4,minecraft:iron_bars:0,5,quark:iron_plate:1,15,STAINED_CLAY:15,15,STAINED_CLAY:7,100)
RandomBlock(-6,30,5,minecraft:iron_bars:0,5,quark:iron_plate:1,15,STAINED_CLAY:15,15,STAINED_CLAY:7,100)
RandomBlock(-6,30,6,minecraft:iron_bars:0,5,quark:iron_plate:1,15,STAINED_CLAY:15,15,STAINED_CLAY:7,100)
RandomBlock(-6,31,3,minecraft:iron_bars:0,5,quark:iron_plate:1,15,STAINED_CLAY:15,15,STAINED_CLAY:7,100)
RandomBlock(-6,31,4,minecraft:iron_bars:0,5,quark:iron_plate:1,15,STAINED_CLAY:15,15,STAINED_CLAY:7,100)
RandomBlock(-6,31,5,minecraft:iron_bars:0,5,quark:iron_plate:1,15,STAINED_CLAY:15,15,STAINED_CLAY:7,100)
RandomBlock(-6,31,6,minecraft:iron_bars:0,5,quark:iron_plate:1,15,STAINED_CLAY:15,15,STAINED_CLAY:7,100)
RandomBlock(-6,32,3,minecraft:iron_bars:0,5,quark:iron_plate:1,15,STAINED_CLAY:15,15,STAINED_CLAY:7,100)
RandomBlock(-6,32,4,minecraft:iron_bars:0,5,quark:iron_plate:1,15,STAINED_CLAY:15,15,STAINED_CLAY:7,100)
RandomBlock(-6,32,5,minecraft:iron_bars:0,5,quark:iron_plate:1,15,STAINED_CLAY:15,15,STAINED_CLAY:7,100)
RandomBlock(-6,32,6,minecraft:iron_bars:0,5,quark:iron_plate:1,15,STAINED_CLAY:15,15,STAINED_CLAY:7,100)
RandomBlock(-6,33,3,minecraft:iron_bars:0,5,quark:iron_plate:1,15,STAINED_CLAY:15,15,STAINED_CLAY:7,100)
RandomBlock(-6,33,4,minecraft:iron_bars:0,5,quark:iron_plate:1,15,STAINED_CLAY:15,15,STAINED_CLAY:7,100)
RandomBlock(-6,33,5,minecraft:iron_bars:0,5,quark:iron_plate:1,15,STAINED_CLAY:15,15,STAINED_CLAY:7,100)
RandomBlock(-6,33,6,minecraft:iron_bars:0,5,quark:iron_plate:1,15,STAINED_CLAY:15,15,STAINED_CLAY:7,100)
RandomBlock(-6,34,3,minecraft:iron_bars:0,5,quark:iron_plate:1,15,STAINED_CLAY:15,15,STAINED_CLAY:7,100)
RandomBlock(-6,34,4,minecraft:iron_bars:0,5,quark:iron_plate:1,15,STAINED_CLAY:15,15,STAINED_CLAY:7,100)
RandomBlock(-6,34,5,minecraft:iron_bars:0,5,quark:iron_plate:1,15,STAINED_CLAY:15,15,STAINED_CLAY:7,100)
RandomBlock(-6,34,6,minecraft:iron_bars:0,5,quark:iron_plate:1,15,STAINED_CLAY:15,15,STAINED_CLAY:7,100)
RandomBlock(-6,35,3,minecraft:iron_bars:0,5,quark:iron_plate:1,15,STAINED_CLAY:15,15,STAINED_CLAY:7,100)
RandomBlock(-6,35,4,minecraft:iron_bars:0,5,quark:iron_plate:1,15,STAINED_CLAY:15,15,STAINED_CLAY:7,100)
RandomBlock(-6,35,5,minecraft:iron_bars:0,5,quark:iron_plate:1,15,STAINED_CLAY:15,15,STAINED_CLAY:7,100)
RandomBlock(-6,35,6,minecraft:iron_bars:0,5,quark:iron_plate:1,15,STAINED_CLAY:15,15,STAINED_CLAY:7,100)
RandomBlock(-6,36,3,minecraft:iron_bars:0,5,quark:iron_plate:1,15,STAINED_CLAY:15,15,STAINED_CLAY:7,100)
RandomBlock(-6,36,4,minecraft:iron_bars:0,5,quark:iron_plate:1,15,STAINED_CLAY:15,15,STAINED_CLAY:7,100)
RandomBlock(-6,36,5,minecraft:iron_bars:0,5,quark:iron_plate:1,15,STAINED_CLAY:15,15,STAINED_CLAY:7,100)
RandomBlock(-6,36,6,minecraft:iron_bars:0,5,quark:iron_plate:1,15,STAINED_CLAY:15,15,STAINED_CLAY:7,100)
RandomBlock(-6,37,3,minecraft:iron_bars:0,5,quark:iron_plate:1,15,STAINED_CLAY:15,15,STAINED_CLAY:7,100)
RandomBlock(-6,37,4,minecraft:iron_bars:0,5,quark:iron_plate:1,15,STAINED_CLAY:15,15,STAINED_CLAY:7,100)
RandomBlock(-6,37,5,minecraft:iron_bars:0,5,quark:iron_plate:1,15,STAINED_CLAY:15,15,STAINED_CLAY:7,100)
RandomBlock(-6,37,6,minecraft:iron_bars:0,5,quark:iron_plate:1,15,STAINED_CLAY:15,15,STAINED_CLAY:7,100)
RandomBlock(-6,38,3,minecraft:iron_bars:0,5,quark:iron_plate:1,15,STAINED_CLAY:15,15,STAINED_CLAY:7,100)
RandomBlock(-6,38,4,minecraft:iron_bars:0,5,quark:iron_plate:1,15,STAINED_CLAY:15,15,STAINED_CLAY:7,100)
RandomBlock(-6,38,5,minecraft:iron_bars:0,5,quark:iron_plate:1,15,STAINED_CLAY:15,15,STAINED_CLAY:7,100)
RandomBlock(-6,38,6,minecraft:iron_bars:0,5,quark:iron_plate:1,15,STAINED_CLAY:15,15,STAINED_CLAY:7,100)
RandomBlock(-6,39,3,minecraft:iron_bars:0,5,quark:iron_plate:1,15,STAINED_CLAY:15,15,STAINED_CLAY:7,100)
RandomBlock(-6,39,4,minecraft:iron_bars:0,5,quark:iron_plate:1,15,STAINED_CLAY:15,15,STAINED_CLAY:7,100)
RandomBlock(-6,39,5,minecraft:iron_bars:0,5,quark:iron_plate:1,15,STAINED_CLAY:15,15,STAINED_CLAY:7,100)
RandomBlock(-6,39,6,minecraft:iron_bars:0,5,quark:iron_plate:1,15,STAINED_CLAY:15,15,STAINED_CLAY:7,100)
RandomBlock(-6,40,3,minecraft:iron_bars:0,5,quark:iron_plate:1,15,STAINED_CLAY:15,15,STAINED_CLAY:7,100)
RandomBlock(-6,40,4,minecraft:iron_bars:0,5,quark:iron_plate:1,15,STAINED_CLAY:15,15,STAINED_CLAY:7,100)
RandomBlock(-6,40,5,minecraft:iron_bars:0,5,quark:iron_plate:1,15,STAINED_CLAY:15,15,STAINED_CLAY:7,100)
RandomBlock(-6,40,6,minecraft:iron_bars:0,5,quark:iron_plate:1,15,STAINED_CLAY:15,15,STAINED_CLAY:7,100)
RandomBlock(-6,41,3,minecraft:iron_bars:0,5,quark:iron_plate:1,15,STAINED_CLAY:15,15,STAINED_CLAY:7,100)
RandomBlock(-6,41,4,minecraft:iron_bars:0,5,quark:iron_plate:1,15,STAINED_CLAY:15,15,STAINED_CLAY:7,100)
RandomBlock(-6,41,5,minecraft:iron_bars:0,5,quark:iron_plate:1,15,STAINED_CLAY:15,15,STAINED_CLAY:7,100)
RandomBlock(-6,41,6,minecraft:iron_bars:0,5,quark:iron_plate:1,15,STAINED_CLAY:15,15,STAINED_CLAY:7,100)
RandomBlock(-6,42,3,minecraft:iron_bars:0,5,quark:iron_plate:1,15,STAINED_CLAY:15,15,STAINED_CLAY:7,100)
RandomBlock(-6,42,4,minecraft:iron_bars:0,5,quark:iron_plate:1,15,STAINED_CLAY:15,15,STAINED_CLAY:7,100)
RandomBlock(-6,42,5,minecraft:iron_bars:0,5,quark:iron_plate:1,15,STAINED_CLAY:15,15,STAINED_CLAY:7,100)
RandomBlock(-6,42,6,minecraft:iron_bars:0,5,quark:iron_plate:1,15,STAINED_CLAY:15,15,STAINED_CLAY:7,100)
RandomBlock(-6,43,3,minecraft:iron_bars:0,5,quark:iron_plate:1,15,STAINED_CLAY:15,15,STAINED_CLAY:7,100)
RandomBlock(-6,43,4,minecraft:iron_bars:0,5,quark:iron_plate:1,15,STAINED_CLAY:15,15,STAINED_CLAY:7,100)
RandomBlock(-6,43,5,minecraft:iron_bars:0,5,quark:iron_plate:1,15,STAINED_CLAY:15,15,STAINED_CLAY:7,100)
RandomBlock(-6,43,6,minecraft:iron_bars:0,5,quark:iron_plate:1,15,STAINED_CLAY:15,15,STAINED_CLAY:7,100)
RandomBlock(-6,44,-7,minecraft:iron_bars:0,5,STAINED_CLAY:15,5,STAINED_CLAY:7,5,quark:iron_plate_slab:8,15,quark:world_stone_pavement:2,15,STAINED_CLAY:9,100)
RandomBlock(-6,44,-6,minecraft:iron_bars:0,5,STAINED_CLAY:15,5,STAINED_CLAY:7,5,quark:iron_plate_slab:8,15,quark:world_stone_pavement:2,15,STAINED_CLAY:9,100)
RandomBlock(-6,44,-5,minecraft:iron_bars:0,5,STAINED_CLAY:15,5,STAINED_CLAY:7,5,quark:iron_plate_slab:8,15,quark:world_stone_pavement:2,15,STAINED_CLAY:9,100)
RandomBlock(-6,44,-4,minecraft:iron_bars:0,5,STAINED_CLAY:15,5,STAINED_CLAY:7,5,quark:iron_plate_slab:8,15,quark:world_stone_pavement:2,15,STAINED_CLAY:9,100)
RandomBlock(-6,44,-3,minecraft:iron_bars:0,5,STAINED_CLAY:15,5,STAINED_CLAY:7,5,quark:iron_plate_slab:8,15,quark:world_stone_pavement:2,15,STAINED_CLAY:9,100)
RandomBlock(-6,44,-2,minecraft:iron_bars:0,5,STAINED_CLAY:15,5,STAINED_CLAY:7,5,quark:iron_plate_slab:8,15,quark:world_stone_pavement:2,15,STAINED_CLAY:9,100)
RandomBlock(-6,44,-1,minecraft:iron_bars:0,5,STAINED_CLAY:15,5,STAINED_CLAY:7,5,quark:iron_plate_slab:8,15,quark:world_stone_pavement:2,15,STAINED_CLAY:9,100)
RandomBlock(-6,44,0,minecraft:iron_bars:0,5,STAINED_CLAY:15,5,STAINED_CLAY:7,5,quark:iron_plate_slab:8,15,quark:world_stone_pavement:2,15,STAINED_CLAY:9,100)
RandomBlock(-6,44,1,minecraft:iron_bars:0,5,STAINED_CLAY:15,5,STAINED_CLAY:7,5,quark:iron_plate_slab:8,15,quark:world_stone_pavement:2,15,STAINED_CLAY:9,100)
RandomBlock(-6,44,2,minecraft:iron_bars:0,5,STAINED_CLAY:15,5,STAINED_CLAY:7,5,quark:iron_plate_slab:8,15,quark:world_stone_pavement:2,15,STAINED_CLAY:9,100)
RandomBlock(-6,44,3,minecraft:iron_bars:0,5,STAINED_CLAY:15,5,STAINED_CLAY:7,5,quark:iron_plate_slab:8,15,quark:world_stone_pavement:2,15,STAINED_CLAY:9,100)
RandomBlock(-6,44,4,minecraft:iron_bars:0,5,STAINED_CLAY:15,5,STAINED_CLAY:7,5,quark:iron_plate_slab:8,15,quark:world_stone_pavement:2,15,STAINED_CLAY:9,100)
RandomBlock(-6,44,5,minecraft:iron_bars:0,5,STAINED_CLAY:15,5,STAINED_CLAY:7,5,quark:iron_plate_slab:8,15,quark:world_stone_pavement:2,15,STAINED_CLAY:9,100)
RandomBlock(-6,44,6,minecraft:iron_bars:0,5,STAINED_CLAY:15,5,STAINED_CLAY:7,5,quark:iron_plate_slab:8,15,quark:world_stone_pavement:2,15,STAINED_CLAY:9,100)
RandomBlock(-6,44,7,minecraft:iron_bars:0,5,STAINED_CLAY:15,5,STAINED_CLAY:7,5,quark:iron_plate_slab:8,15,quark:world_stone_pavement:2,15,STAINED_CLAY:9,100)
RandomBlock(-6,44,8,minecraft:iron_bars:0,5,STAINED_CLAY:15,5,STAINED_CLAY:7,5,quark:iron_plate_slab:8,15,quark:world_stone_pavement:2,15,STAINED_CLAY:9,100)
Block(-6,45,-5,STEP:5)
RandomBlock(-6,45,-4,minecraft:iron_bars:0,5,CONCRETE_POWDER:8,10,quark:limestone:1,15,quark:limestone,15,quark:world_stone_pavement:2,15,CONCRETE:8,100)
RandomBlock(-6,45,-3,minecraft:iron_bars:0,5,CONCRETE_POWDER:8,10,quark:limestone:1,15,quark:limestone,15,quark:world_stone_pavement:2,15,CONCRETE:8,100)
Block(-6,45,-2,minecraft:iron_bars:0)
Block(-6,45,0,minecraft:iron_bars:0)
RandomBlock(-6,45,1,minecraft:iron_bars:0,5,CONCRETE_POWDER:8,10,quark:limestone:1,15,quark:limestone,15,quark:world_stone_pavement:2,15,CONCRETE:8,100)
RandomBlock(-6,45,2,minecraft:iron_bars:0,5,CONCRETE_POWDER:8,10,quark:limestone:1,15,quark:limestone,15,quark:world_stone_pavement:2,15,CONCRETE:8,100)
Block(-6,45,3,STEP:5)
RandomBlock(-6,45,5,minecraft:iron_bars:0,5,CONCRETE_POWDER:8,10,quark:limestone:1,15,quark:limestone,15,quark:world_stone_pavement:2,15,CONCRETE:8,100)
Block(-6,45,7,STONE_BUTTON:2)
Block(-6,45,8,STONE_BUTTON:2)
RandomBlock(-6,46,-5,minecraft:iron_bars:0,5,CONCRETE_POWDER:8,10,quark:limestone:1,15,quark:limestone,15,quark:world_stone_pavement:2,15,CONCRETE:8,100)
Block(-6,46,-4,COAL_BLOCK:0)
Block(-6,46,-3,COAL_BLOCK:0)
RandomBlock(-6,46,-2,minecraft:iron_bars:0,5,CONCRETE_POWDER:8,10,quark:limestone:1,15,quark:limestone,15,quark:world_stone_pavement:2,15,CONCRETE:8,100)
RandomBlock(-6,46,0,minecraft:iron_bars:0,5,CONCRETE_POWDER:8,10,quark:limestone:1,15,quark:limestone,15,quark:world_stone_pavement:2,15,CONCRETE:8,100)
Block(-6,46,1,COAL_BLOCK:0)
Block(-6,46,2,COAL_BLOCK:0)
RandomBlock(-6,46,3,minecraft:iron_bars:0,5,CONCRETE_POWDER:8,10,quark:limestone:1,15,quark:limestone,15,quark:world_stone_pavement:2,15,CONCRETE:8,100)
Block(-6,46,5,CONCRETE:15)
Block(-6,46,8,STONE_BUTTON:1)
RandomBlock(-6,47,-5,minecraft:iron_bars:0,5,CONCRETE_POWDER:8,10,quark:limestone:1,15,quark:limestone,15,quark:world_stone_pavement:2,15,CONCRETE:8,100)
Block(-6,47,-4,COAL_BLOCK:0)
Block(-6,47,-3,COAL_BLOCK:0)
RandomBlock(-6,47,-2,minecraft:iron_bars:0,5,CONCRETE_POWDER:8,10,quark:limestone:1,15,quark:limestone,15,quark:world_stone_pavement:2,15,CONCRETE:8,100)
RandomBlock(-6,47,0,minecraft:iron_bars:0,5,CONCRETE_POWDER:8,10,quark:limestone:1,15,quark:limestone,15,quark:world_stone_pavement:2,15,CONCRETE:8,100)
Block(-6,47,1,COAL_BLOCK:0)
Block(-6,47,2,COAL_BLOCK:0)
RandomBlock(-6,47,3,minecraft:iron_bars:0,5,CONCRETE_POWDER:8,10,quark:limestone:1,15,quark:limestone,15,quark:world_stone_pavement:2,15,CONCRETE:8,100)
RandomBlock(-6,47,5,minecraft:iron_bars:0,5,CONCRETE_POWDER:8,10,quark:limestone:1,15,quark:limestone,15,quark:world_stone_pavement:2,15,CONCRETE:8,100)
RandomBlock(-6,48,-4,minecraft:iron_bars:0,5,CONCRETE_POWDER:8,10,quark:limestone:1,15,quark:limestone,15,quark:world_stone_pavement:2,15,CONCRETE:8,100)
RandomBlock(-6,48,-3,minecraft:iron_bars:0,5,CONCRETE_POWDER:8,10,quark:limestone:1,15,quark:limestone,15,quark:world_stone_pavement:2,15,CONCRETE:8,100)
RandomBlock(-6,48,1,minecraft:iron_bars:0,5,CONCRETE_POWDER:8,10,quark:limestone:1,15,quark:limestone,15,quark:world_stone_pavement:2,15,CONCRETE:8,100)
RandomBlock(-6,48,2,minecraft:iron_bars:0,5,CONCRETE_POWDER:8,10,quark:limestone:1,15,quark:limestone,15,quark:world_stone_pavement:2,15,CONCRETE:8,100)
RandomBlock(-6,48,5,minecraft:iron_bars:0,5,CONCRETE_POWDER:8,10,quark:limestone:1,15,quark:limestone,15,quark:world_stone_pavement:2,15,CONCRETE:8,100)
Block(-6,49,-3,quark:basalt_wall)
Block(-6,49,1,quark:basalt_wall)
RandomBlock(-6,49,5,minecraft:iron_bars:0,5,CONCRETE_POWDER:8,10,quark:limestone:1,15,quark:limestone,15,quark:world_stone_pavement:2,15,CONCRETE:8,100)
RandomBlock(-6,49,6,minecraft:iron_bars:0,5,STAINED_CLAY:15,5,STAINED_CLAY:7,5,quark:iron_plate_slab:8,15,quark:world_stone_pavement:2,15,STAINED_CLAY:9,100)
RandomBlock(-6,49,7,minecraft:iron_bars:0,5,STAINED_CLAY:15,5,STAINED_CLAY:7,5,quark:iron_plate_slab:8,15,quark:world_stone_pavement:2,15,STAINED_CLAY:9,100)
RandomBlock(-6,49,8,minecraft:iron_bars:0,5,STAINED_CLAY:15,5,STAINED_CLAY:7,5,quark:iron_plate_slab:8,15,quark:world_stone_pavement:2,15,STAINED_CLAY:9,100)
RandomBlock(-6,50,-7,minecraft:iron_bars:0,5,STAINED_CLAY:15,5,STAINED_CLAY:7,5,quark:iron_plate_slab:8,15,quark:world_stone_pavement:2,15,STAINED_CLAY:9,100)
RandomBlock(-6,50,-6,minecraft:iron_bars:0,5,STAINED_CLAY:15,5,STAINED_CLAY:7,5,quark:iron_plate_slab:8,15,quark:world_stone_pavement:2,15,STAINED_CLAY:9,100)
RandomBlock(-6,50,-5,minecraft:iron_bars:0,5,STAINED_CLAY:15,5,STAINED_CLAY:7,5,quark:iron_plate_slab:8,15,quark:world_stone_pavement:2,15,STAINED_CLAY:9,100)
RandomBlock(-6,50,-4,minecraft:iron_bars:0,5,STAINED_CLAY:15,5,STAINED_CLAY:7,5,quark:iron_plate_slab:8,15,quark:world_stone_pavement:2,15,STAINED_CLAY:9,100)
RandomBlock(-6,50,-3,minecraft:iron_bars:0,5,STAINED_CLAY:15,5,STAINED_CLAY:7,5,quark:iron_plate_slab:8,15,quark:world_stone_pavement:2,15,STAINED_CLAY:9,100)
RandomBlock(-6,50,-2,minecraft:iron_bars:0,5,STAINED_CLAY:15,5,STAINED_CLAY:7,5,quark:iron_plate_slab:8,15,quark:world_stone_pavement:2,15,STAINED_CLAY:9,100)
RandomBlock(-6,50,-1,minecraft:iron_bars:0,5,STAINED_CLAY:15,5,STAINED_CLAY:7,5,quark:iron_plate_slab:8,15,quark:world_stone_pavement:2,15,STAINED_CLAY:9,100)
RandomBlock(-6,50,0,minecraft:iron_bars:0,5,STAINED_CLAY:15,5,STAINED_CLAY:7,5,quark:iron_plate_slab:8,15,quark:world_stone_pavement:2,15,STAINED_CLAY:9,100)
RandomBlock(-6,50,1,minecraft:iron_bars:0,5,STAINED_CLAY:15,5,STAINED_CLAY:7,5,quark:iron_plate_slab:8,15,quark:world_stone_pavement:2,15,STAINED_CLAY:9,100)
RandomBlock(-6,50,2,minecraft:iron_bars:0,5,CONCRETE_POWDER:8,10,quark:limestone:1,15,quark:limestone,15,quark:world_stone_pavement:2,15,CONCRETE:8,100)
Block(-6,50,5,minecraft:iron_bars:0)
Block(-6,50,7,STONE:6)
Block(-6,51,2,minecraft:iron_bars:0)
Block(-6,51,5,minecraft:iron_bars:0)
Block(-6,52,2,minecraft:iron_bars:0)
RandomBlock(-6,54,-7,minecraft:iron_bars:0,5,CONCRETE_POWDER:8,10,quark:limestone:1,15,quark:limestone,15,quark:world_stone_pavement:2,15,CONCRETE:8,100)
Block(-6,55,-7,minecraft:iron_bars:0)
Block(-6,56,-7,minecraft:iron_bars:0)
Block(-6,58,-7,STEP:13)
Block(-6,58,-6,minecraft:iron_bars:0)
Block(-6,58,-5,quark:basalt_wall)
Block(-6,58,-4,minecraft:iron_bars:0)
Block(-6,58,-3,quark:basalt_wall)
Block(-6,58,-2,minecraft:iron_bars:0)
Block(-6,58,-1,STEP:13)
Block(-6,59,-7,IRON_FENCE:0)
Block(-6,59,-6,STEP:0)
Block(-6,59,-5,STEP:0)
Block(-6,59,-3,STEP:0)
Block(-6,59,-2,STEP:0)
Block(-6,59,-1,IRON_FENCE:0)
Block(-6,65,8,minecraft:iron_bars:0)
Block(-6,66,8,IRON_FENCE:0)
RandomBlock(-5,0,2,minecraft:iron_bars:0,5,quark:iron_plate:1,15,STAINED_CLAY:15,15,STAINED_CLAY:7,100)
RandomBlock(-5,0,3,minecraft:iron_bars:0,5,quark:iron_plate:1,15,STAINED_CLAY:15,15,STAINED_CLAY:7,100)
RandomBlock(-5,0,4,minecraft:iron_bars:0,5,quark:iron_plate:1,15,STAINED_CLAY:15,15,STAINED_CLAY:7,100)
RandomBlock(-5,0,5,minecraft:iron_bars:0,5,quark:iron_plate:1,15,STAINED_CLAY:15,15,STAINED_CLAY:7,100)
RandomBlock(-5,0,6,minecraft:iron_bars:0,5,quark:iron_plate:1,15,STAINED_CLAY:15,15,STAINED_CLAY:7,100)
RandomBlock(-5,0,7,minecraft:iron_bars:0,5,quark:iron_plate:1,15,STAINED_CLAY:15,15,STAINED_CLAY:7,100)
RandomBlock(-5,1,2,minecraft:iron_bars:0,5,quark:iron_plate:1,15,STAINED_CLAY:15,15,STAINED_CLAY:7,100)
RandomBlock(-5,1,3,minecraft:iron_bars:0,5,quark:iron_plate:1,15,STAINED_CLAY:15,15,STAINED_CLAY:7,100)
RandomBlock(-5,1,4,minecraft:iron_bars:0,5,quark:iron_plate:1,15,STAINED_CLAY:15,15,STAINED_CLAY:7,100)
RandomBlock(-5,1,5,minecraft:iron_bars:0,5,quark:iron_plate:1,15,STAINED_CLAY:15,15,STAINED_CLAY:7,100)
RandomBlock(-5,1,6,minecraft:iron_bars:0,5,quark:iron_plate:1,15,STAINED_CLAY:15,15,STAINED_CLAY:7,100)
RandomBlock(-5,1,7,minecraft:iron_bars:0,5,quark:iron_plate:1,15,STAINED_CLAY:15,15,STAINED_CLAY:7,100)
RandomBlock(-5,2,2,minecraft:iron_bars:0,5,quark:iron_plate:1,15,STAINED_CLAY:15,15,STAINED_CLAY:7,100)
RandomBlock(-5,2,3,minecraft:iron_bars:0,5,quark:iron_plate:1,15,STAINED_CLAY:15,15,STAINED_CLAY:7,100)
RandomBlock(-5,2,4,minecraft:iron_bars:0,5,quark:iron_plate:1,15,STAINED_CLAY:15,15,STAINED_CLAY:7,100)
RandomBlock(-5,2,5,minecraft:iron_bars:0,5,quark:iron_plate:1,15,STAINED_CLAY:15,15,STAINED_CLAY:7,100)
RandomBlock(-5,2,6,minecraft:iron_bars:0,5,quark:iron_plate:1,15,STAINED_CLAY:15,15,STAINED_CLAY:7,100)
RandomBlock(-5,2,7,minecraft:iron_bars:0,5,quark:iron_plate:1,15,STAINED_CLAY:15,15,STAINED_CLAY:7,100)
RandomBlock(-5,3,2,minecraft:iron_bars:0,5,quark:iron_plate:1,15,STAINED_CLAY:15,15,STAINED_CLAY:7,100)
RandomBlock(-5,3,3,minecraft:iron_bars:0,5,quark:iron_plate:1,15,STAINED_CLAY:15,15,STAINED_CLAY:7,100)
RandomBlock(-5,3,4,minecraft:iron_bars:0,5,quark:iron_plate:1,15,STAINED_CLAY:15,15,STAINED_CLAY:7,100)
RandomBlock(-5,3,5,minecraft:iron_bars:0,5,quark:iron_plate:1,15,STAINED_CLAY:15,15,STAINED_CLAY:7,100)
RandomBlock(-5,3,6,minecraft:iron_bars:0,5,quark:iron_plate:1,15,STAINED_CLAY:15,15,STAINED_CLAY:7,100)
RandomBlock(-5,3,7,minecraft:iron_bars:0,5,quark:iron_plate:1,15,STAINED_CLAY:15,15,STAINED_CLAY:7,100)
RandomBlock(-5,4,2,minecraft:iron_bars:0,5,quark:iron_plate:1,15,STAINED_CLAY:15,15,STAINED_CLAY:7,100)
RandomBlock(-5,4,3,minecraft:iron_bars:0,5,quark:iron_plate:1,15,STAINED_CLAY:15,15,STAINED_CLAY:7,100)
RandomBlock(-5,4,4,minecraft:iron_bars:0,5,quark:iron_plate:1,15,STAINED_CLAY:15,15,STAINED_CLAY:7,100)
RandomBlock(-5,4,5,minecraft:iron_bars:0,5,quark:iron_plate:1,15,STAINED_CLAY:15,15,STAINED_CLAY:7,100)
RandomBlock(-5,4,6,minecraft:iron_bars:0,5,quark:iron_plate:1,15,STAINED_CLAY:15,15,STAINED_CLAY:7,100)
RandomBlock(-5,4,7,minecraft:iron_bars:0,5,quark:iron_plate:1,15,STAINED_CLAY:15,15,STAINED_CLAY:7,100)
RandomBlock(-5,5,2,minecraft:iron_bars:0,5,quark:iron_plate:1,15,STAINED_CLAY:15,15,STAINED_CLAY:7,100)
RandomBlock(-5,5,3,minecraft:iron_bars:0,5,quark:iron_plate:1,15,STAINED_CLAY:15,15,STAINED_CLAY:7,100)
RandomBlock(-5,5,4,minecraft:iron_bars:0,5,quark:iron_plate:1,15,STAINED_CLAY:15,15,STAINED_CLAY:7,100)
RandomBlock(-5,5,5,minecraft:iron_bars:0,5,quark:iron_plate:1,15,STAINED_CLAY:15,15,STAINED_CLAY:7,100)
RandomBlock(-5,5,6,minecraft:iron_bars:0,5,quark:iron_plate:1,15,STAINED_CLAY:15,15,STAINED_CLAY:7,100)
RandomBlock(-5,5,7,minecraft:iron_bars:0,5,quark:iron_plate:1,15,STAINED_CLAY:15,15,STAINED_CLAY:7,100)
RandomBlock(-5,6,2,minecraft:iron_bars:0,5,quark:iron_plate:1,15,STAINED_CLAY:15,15,STAINED_CLAY:7,100)
RandomBlock(-5,6,3,minecraft:iron_bars:0,5,quark:iron_plate:1,15,STAINED_CLAY:15,15,STAINED_CLAY:7,100)
RandomBlock(-5,6,4,minecraft:iron_bars:0,5,quark:iron_plate:1,15,STAINED_CLAY:15,15,STAINED_CLAY:7,100)
RandomBlock(-5,6,5,minecraft:iron_bars:0,5,quark:iron_plate:1,15,STAINED_CLAY:15,15,STAINED_CLAY:7,100)
RandomBlock(-5,6,6,minecraft:iron_bars:0,5,quark:iron_plate:1,15,STAINED_CLAY:15,15,STAINED_CLAY:7,100)
RandomBlock(-5,6,7,minecraft:iron_bars:0,5,quark:iron_plate:1,15,STAINED_CLAY:15,15,STAINED_CLAY:7,100)
RandomBlock(-5,7,2,minecraft:iron_bars:0,5,quark:iron_plate:1,15,STAINED_CLAY:15,15,STAINED_CLAY:7,100)
RandomBlock(-5,7,3,minecraft:iron_bars:0,5,quark:iron_plate:1,15,STAINED_CLAY:15,15,STAINED_CLAY:7,100)
RandomBlock(-5,7,4,minecraft:iron_bars:0,5,quark:iron_plate:1,15,STAINED_CLAY:15,15,STAINED_CLAY:7,100)
RandomBlock(-5,7,5,minecraft:iron_bars:0,5,quark:iron_plate:1,15,STAINED_CLAY:15,15,STAINED_CLAY:7,100)
RandomBlock(-5,7,6,minecraft:iron_bars:0,5,quark:iron_plate:1,15,STAINED_CLAY:15,15,STAINED_CLAY:7,100)
RandomBlock(-5,7,7,minecraft:iron_bars:0,5,quark:iron_plate:1,15,STAINED_CLAY:15,15,STAINED_CLAY:7,100)
RandomBlock(-5,8,2,minecraft:iron_bars:0,5,quark:iron_plate:1,15,STAINED_CLAY:15,15,STAINED_CLAY:7,100)
RandomBlock(-5,8,3,minecraft:iron_bars:0,5,quark:iron_plate:1,15,STAINED_CLAY:15,15,STAINED_CLAY:7,100)
RandomBlock(-5,8,4,minecraft:iron_bars:0,5,quark:iron_plate:1,15,STAINED_CLAY:15,15,STAINED_CLAY:7,100)
RandomBlock(-5,8,5,minecraft:iron_bars:0,5,quark:iron_plate:1,15,STAINED_CLAY:15,15,STAINED_CLAY:7,100)
RandomBlock(-5,8,6,minecraft:iron_bars:0,5,quark:iron_plate:1,15,STAINED_CLAY:15,15,STAINED_CLAY:7,100)
RandomBlock(-5,8,7,minecraft:iron_bars:0,5,quark:iron_plate:1,15,STAINED_CLAY:15,15,STAINED_CLAY:7,100)
RandomBlock(-5,9,2,minecraft:iron_bars:0,5,quark:iron_plate:1,15,STAINED_CLAY:15,15,STAINED_CLAY:7,100)
RandomBlock(-5,9,3,minecraft:iron_bars:0,5,quark:iron_plate:1,15,STAINED_CLAY:15,15,STAINED_CLAY:7,100)
RandomBlock(-5,9,4,minecraft:iron_bars:0,5,quark:iron_plate:1,15,STAINED_CLAY:15,15,STAINED_CLAY:7,100)
RandomBlock(-5,9,5,minecraft:iron_bars:0,5,quark:iron_plate:1,15,STAINED_CLAY:15,15,STAINED_CLAY:7,100)
RandomBlock(-5,9,6,minecraft:iron_bars:0,5,quark:iron_plate:1,15,STAINED_CLAY:15,15,STAINED_CLAY:7,100)
RandomBlock(-5,9,7,minecraft:iron_bars:0,5,quark:iron_plate:1,15,STAINED_CLAY:15,15,STAINED_CLAY:7,100)
RandomBlock(-5,10,2,minecraft:iron_bars:0,5,quark:iron_plate:1,15,STAINED_CLAY:15,15,STAINED_CLAY:7,100)
RandomBlock(-5,10,3,minecraft:iron_bars:0,5,quark:iron_plate:1,15,STAINED_CLAY:15,15,STAINED_CLAY:7,100)
RandomBlock(-5,10,4,minecraft:iron_bars:0,5,quark:iron_plate:1,15,STAINED_CLAY:15,15,STAINED_CLAY:7,100)
RandomBlock(-5,10,5,minecraft:iron_bars:0,5,quark:iron_plate:1,15,STAINED_CLAY:15,15,STAINED_CLAY:7,100)
RandomBlock(-5,10,6,minecraft:iron_bars:0,5,quark:iron_plate:1,15,STAINED_CLAY:15,15,STAINED_CLAY:7,100)
RandomBlock(-5,10,7,minecraft:iron_bars:0,5,quark:iron_plate:1,15,STAINED_CLAY:15,15,STAINED_CLAY:7,100)
RandomBlock(-5,11,2,minecraft:iron_bars:0,5,quark:iron_plate:1,15,STAINED_CLAY:15,15,STAINED_CLAY:7,100)
RandomBlock(-5,11,3,minecraft:iron_bars:0,5,quark:iron_plate:1,15,STAINED_CLAY:15,15,STAINED_CLAY:7,100)
RandomBlock(-5,11,4,minecraft:iron_bars:0,5,quark:iron_plate:1,15,STAINED_CLAY:15,15,STAINED_CLAY:7,100)
RandomBlock(-5,11,5,minecraft:iron_bars:0,5,quark:iron_plate:1,15,STAINED_CLAY:15,15,STAINED_CLAY:7,100)
RandomBlock(-5,11,6,minecraft:iron_bars:0,5,quark:iron_plate:1,15,STAINED_CLAY:15,15,STAINED_CLAY:7,100)
RandomBlock(-5,11,7,minecraft:iron_bars:0,5,quark:iron_plate:1,15,STAINED_CLAY:15,15,STAINED_CLAY:7,100)
RandomBlock(-5,12,2,minecraft:iron_bars:0,5,quark:iron_plate:1,15,STAINED_CLAY:15,15,STAINED_CLAY:7,100)
RandomBlock(-5,12,3,minecraft:iron_bars:0,5,quark:iron_plate:1,15,STAINED_CLAY:15,15,STAINED_CLAY:7,100)
RandomBlock(-5,12,4,minecraft:iron_bars:0,5,quark:iron_plate:1,15,STAINED_CLAY:15,15,STAINED_CLAY:7,100)
RandomBlock(-5,12,5,minecraft:iron_bars:0,5,quark:iron_plate:1,15,STAINED_CLAY:15,15,STAINED_CLAY:7,100)
RandomBlock(-5,12,6,minecraft:iron_bars:0,5,quark:iron_plate:1,15,STAINED_CLAY:15,15,STAINED_CLAY:7,100)
RandomBlock(-5,12,7,minecraft:iron_bars:0,5,quark:iron_plate:1,15,STAINED_CLAY:15,15,STAINED_CLAY:7,100)
RandomBlock(-5,13,2,minecraft:iron_bars:0,5,quark:iron_plate:1,15,STAINED_CLAY:15,15,STAINED_CLAY:7,100)
RandomBlock(-5,13,3,minecraft:iron_bars:0,5,quark:iron_plate:1,15,STAINED_CLAY:15,15,STAINED_CLAY:7,100)
RandomBlock(-5,13,4,minecraft:iron_bars:0,5,quark:iron_plate:1,15,STAINED_CLAY:15,15,STAINED_CLAY:7,100)
RandomBlock(-5,13,5,minecraft:iron_bars:0,5,quark:iron_plate:1,15,STAINED_CLAY:15,15,STAINED_CLAY:7,100)
RandomBlock(-5,13,6,minecraft:iron_bars:0,5,quark:iron_plate:1,15,STAINED_CLAY:15,15,STAINED_CLAY:7,100)
RandomBlock(-5,13,7,minecraft:iron_bars:0,5,quark:iron_plate:1,15,STAINED_CLAY:15,15,STAINED_CLAY:7,100)
RandomBlock(-5,14,2,minecraft:iron_bars:0,5,quark:iron_plate:1,15,STAINED_CLAY:15,15,STAINED_CLAY:7,100)
RandomBlock(-5,14,3,minecraft:iron_bars:0,5,quark:iron_plate:1,15,STAINED_CLAY:15,15,STAINED_CLAY:7,100)
RandomBlock(-5,14,4,minecraft:iron_bars:0,5,quark:iron_plate:1,15,STAINED_CLAY:15,15,STAINED_CLAY:7,100)
RandomBlock(-5,14,5,minecraft:iron_bars:0,5,quark:iron_plate:1,15,STAINED_CLAY:15,15,STAINED_CLAY:7,100)
RandomBlock(-5,14,6,minecraft:iron_bars:0,5,quark:iron_plate:1,15,STAINED_CLAY:15,15,STAINED_CLAY:7,100)
RandomBlock(-5,14,7,minecraft:iron_bars:0,5,quark:iron_plate:1,15,STAINED_CLAY:15,15,STAINED_CLAY:7,100)
RandomBlock(-5,15,2,minecraft:iron_bars:0,5,quark:iron_plate:1,15,STAINED_CLAY:15,15,STAINED_CLAY:7,100)
RandomBlock(-5,15,3,minecraft:iron_bars:0,5,quark:iron_plate:1,15,STAINED_CLAY:15,15,STAINED_CLAY:7,100)
RandomBlock(-5,15,4,minecraft:iron_bars:0,5,quark:iron_plate:1,15,STAINED_CLAY:15,15,STAINED_CLAY:7,100)
RandomBlock(-5,15,5,minecraft:iron_bars:0,5,quark:iron_plate:1,15,STAINED_CLAY:15,15,STAINED_CLAY:7,100)
RandomBlock(-5,15,6,minecraft:iron_bars:0,5,quark:iron_plate:1,15,STAINED_CLAY:15,15,STAINED_CLAY:7,100)
RandomBlock(-5,15,7,minecraft:iron_bars:0,5,quark:iron_plate:1,15,STAINED_CLAY:15,15,STAINED_CLAY:7,100)
RandomBlock(-5,16,2,minecraft:iron_bars:0,5,quark:iron_plate:1,15,STAINED_CLAY:15,15,STAINED_CLAY:7,100)
RandomBlock(-5,16,3,minecraft:iron_bars:0,5,quark:iron_plate:1,15,STAINED_CLAY:15,15,STAINED_CLAY:7,100)
RandomBlock(-5,16,4,minecraft:iron_bars:0,5,quark:iron_plate:1,15,STAINED_CLAY:15,15,STAINED_CLAY:7,100)
RandomBlock(-5,16,5,minecraft:iron_bars:0,5,quark:iron_plate:1,15,STAINED_CLAY:15,15,STAINED_CLAY:7,100)
RandomBlock(-5,16,6,minecraft:iron_bars:0,5,quark:iron_plate:1,15,STAINED_CLAY:15,15,STAINED_CLAY:7,100)
RandomBlock(-5,16,7,minecraft:iron_bars:0,5,quark:iron_plate:1,15,STAINED_CLAY:15,15,STAINED_CLAY:7,100)
RandomBlock(-5,17,2,minecraft:iron_bars:0,5,quark:iron_plate:1,15,STAINED_CLAY:15,15,STAINED_CLAY:7,100)
RandomBlock(-5,17,3,minecraft:iron_bars:0,5,quark:iron_plate:1,15,STAINED_CLAY:15,15,STAINED_CLAY:7,100)
RandomBlock(-5,17,4,minecraft:iron_bars:0,5,quark:iron_plate:1,15,STAINED_CLAY:15,15,STAINED_CLAY:7,100)
RandomBlock(-5,17,5,minecraft:iron_bars:0,5,quark:iron_plate:1,15,STAINED_CLAY:15,15,STAINED_CLAY:7,100)
RandomBlock(-5,17,6,minecraft:iron_bars:0,5,quark:iron_plate:1,15,STAINED_CLAY:15,15,STAINED_CLAY:7,100)
RandomBlock(-5,17,7,minecraft:iron_bars:0,5,quark:iron_plate:1,15,STAINED_CLAY:15,15,STAINED_CLAY:7,100)
RandomBlock(-5,18,2,minecraft:iron_bars:0,5,quark:iron_plate:1,15,STAINED_CLAY:15,15,STAINED_CLAY:7,100)
RandomBlock(-5,18,3,minecraft:iron_bars:0,5,quark:iron_plate:1,15,STAINED_CLAY:15,15,STAINED_CLAY:7,100)
RandomBlock(-5,18,4,minecraft:iron_bars:0,5,quark:iron_plate:1,15,STAINED_CLAY:15,15,STAINED_CLAY:7,100)
RandomBlock(-5,18,5,minecraft:iron_bars:0,5,quark:iron_plate:1,15,STAINED_CLAY:15,15,STAINED_CLAY:7,100)
RandomBlock(-5,18,6,minecraft:iron_bars:0,5,quark:iron_plate:1,15,STAINED_CLAY:15,15,STAINED_CLAY:7,100)
RandomBlock(-5,18,7,minecraft:iron_bars:0,5,quark:iron_plate:1,15,STAINED_CLAY:15,15,STAINED_CLAY:7,100)
RandomBlock(-5,19,2,minecraft:iron_bars:0,5,quark:iron_plate:1,15,STAINED_CLAY:15,15,STAINED_CLAY:7,100)
RandomBlock(-5,19,3,minecraft:iron_bars:0,5,quark:iron_plate:1,15,STAINED_CLAY:15,15,STAINED_CLAY:7,100)
RandomBlock(-5,19,4,minecraft:iron_bars:0,5,quark:iron_plate:1,15,STAINED_CLAY:15,15,STAINED_CLAY:7,100)
RandomBlock(-5,19,5,minecraft:iron_bars:0,5,quark:iron_plate:1,15,STAINED_CLAY:15,15,STAINED_CLAY:7,100)
RandomBlock(-5,19,6,minecraft:iron_bars:0,5,quark:iron_plate:1,15,STAINED_CLAY:15,15,STAINED_CLAY:7,100)
RandomBlock(-5,19,7,minecraft:iron_bars:0,5,quark:iron_plate:1,15,STAINED_CLAY:15,15,STAINED_CLAY:7,100)
RandomBlock(-5,20,2,minecraft:iron_bars:0,5,quark:iron_plate:1,15,STAINED_CLAY:15,15,STAINED_CLAY:7,100)
RandomBlock(-5,20,3,minecraft:iron_bars:0,5,quark:iron_plate:1,15,STAINED_CLAY:15,15,STAINED_CLAY:7,100)
RandomBlock(-5,20,4,minecraft:iron_bars:0,5,quark:iron_plate:1,15,STAINED_CLAY:15,15,STAINED_CLAY:7,100)
RandomBlock(-5,20,5,minecraft:iron_bars:0,5,quark:iron_plate:1,15,STAINED_CLAY:15,15,STAINED_CLAY:7,100)
RandomBlock(-5,20,6,minecraft:iron_bars:0,5,quark:iron_plate:1,15,STAINED_CLAY:15,15,STAINED_CLAY:7,100)
RandomBlock(-5,20,7,minecraft:iron_bars:0,5,quark:iron_plate:1,15,STAINED_CLAY:15,15,STAINED_CLAY:7,100)
RandomBlock(-5,21,2,minecraft:iron_bars:0,5,quark:iron_plate:1,15,STAINED_CLAY:15,15,STAINED_CLAY:7,100)
RandomBlock(-5,21,3,minecraft:iron_bars:0,5,quark:iron_plate:1,15,STAINED_CLAY:15,15,STAINED_CLAY:7,100)
RandomBlock(-5,21,4,minecraft:iron_bars:0,5,quark:iron_plate:1,15,STAINED_CLAY:15,15,STAINED_CLAY:7,100)
RandomBlock(-5,21,5,minecraft:iron_bars:0,5,quark:iron_plate:1,15,STAINED_CLAY:15,15,STAINED_CLAY:7,100)
RandomBlock(-5,21,6,minecraft:iron_bars:0,5,quark:iron_plate:1,15,STAINED_CLAY:15,15,STAINED_CLAY:7,100)
RandomBlock(-5,21,7,minecraft:iron_bars:0,5,quark:iron_plate:1,15,STAINED_CLAY:15,15,STAINED_CLAY:7,100)
RandomBlock(-5,22,2,minecraft:iron_bars:0,5,quark:iron_plate:1,15,STAINED_CLAY:15,15,STAINED_CLAY:7,100)
RandomBlock(-5,22,3,minecraft:iron_bars:0,5,quark:iron_plate:1,15,STAINED_CLAY:15,15,STAINED_CLAY:7,100)
RandomBlock(-5,22,4,minecraft:iron_bars:0,5,quark:iron_plate:1,15,STAINED_CLAY:15,15,STAINED_CLAY:7,100)
RandomBlock(-5,22,5,minecraft:iron_bars:0,5,quark:iron_plate:1,15,STAINED_CLAY:15,15,STAINED_CLAY:7,100)
RandomBlock(-5,22,6,minecraft:iron_bars:0,5,quark:iron_plate:1,15,STAINED_CLAY:15,15,STAINED_CLAY:7,100)
RandomBlock(-5,22,7,minecraft:iron_bars:0,5,quark:iron_plate:1,15,STAINED_CLAY:15,15,STAINED_CLAY:7,100)
RandomBlock(-5,23,2,minecraft:iron_bars:0,5,quark:iron_plate:1,15,STAINED_CLAY:15,15,STAINED_CLAY:7,100)
RandomBlock(-5,23,3,minecraft:iron_bars:0,5,quark:iron_plate:1,15,STAINED_CLAY:15,15,STAINED_CLAY:7,100)
RandomBlock(-5,23,4,minecraft:iron_bars:0,5,quark:iron_plate:1,15,STAINED_CLAY:15,15,STAINED_CLAY:7,100)
RandomBlock(-5,23,5,minecraft:iron_bars:0,5,quark:iron_plate:1,15,STAINED_CLAY:15,15,STAINED_CLAY:7,100)
RandomBlock(-5,23,6,minecraft:iron_bars:0,5,quark:iron_plate:1,15,STAINED_CLAY:15,15,STAINED_CLAY:7,100)
RandomBlock(-5,23,7,minecraft:iron_bars:0,5,quark:iron_plate:1,15,STAINED_CLAY:15,15,STAINED_CLAY:7,100)
RandomBlock(-5,24,2,minecraft:iron_bars:0,5,quark:iron_plate:1,15,STAINED_CLAY:15,15,STAINED_CLAY:7,100)
RandomBlock(-5,24,3,minecraft:iron_bars:0,5,quark:iron_plate:1,15,STAINED_CLAY:15,15,STAINED_CLAY:7,100)
RandomBlock(-5,24,4,minecraft:iron_bars:0,5,quark:iron_plate:1,15,STAINED_CLAY:15,15,STAINED_CLAY:7,100)
RandomBlock(-5,24,5,minecraft:iron_bars:0,5,quark:iron_plate:1,15,STAINED_CLAY:15,15,STAINED_CLAY:7,100)
RandomBlock(-5,24,6,minecraft:iron_bars:0,5,quark:iron_plate:1,15,STAINED_CLAY:15,15,STAINED_CLAY:7,100)
RandomBlock(-5,24,7,minecraft:iron_bars:0,5,quark:iron_plate:1,15,STAINED_CLAY:15,15,STAINED_CLAY:7,100)
RandomBlock(-5,25,2,minecraft:iron_bars:0,5,quark:iron_plate:1,15,STAINED_CLAY:15,15,STAINED_CLAY:7,100)
RandomBlock(-5,25,3,minecraft:iron_bars:0,5,quark:iron_plate:1,15,STAINED_CLAY:15,15,STAINED_CLAY:7,100)
RandomBlock(-5,25,4,minecraft:iron_bars:0,5,quark:iron_plate:1,15,STAINED_CLAY:15,15,STAINED_CLAY:7,100)
RandomBlock(-5,25,5,minecraft:iron_bars:0,5,quark:iron_plate:1,15,STAINED_CLAY:15,15,STAINED_CLAY:7,100)
RandomBlock(-5,25,6,minecraft:iron_bars:0,5,quark:iron_plate:1,15,STAINED_CLAY:15,15,STAINED_CLAY:7,100)
RandomBlock(-5,25,7,minecraft:iron_bars:0,5,quark:iron_plate:1,15,STAINED_CLAY:15,15,STAINED_CLAY:7,100)
RandomBlock(-5,26,2,minecraft:iron_bars:0,5,quark:iron_plate:1,15,STAINED_CLAY:15,15,STAINED_CLAY:7,100)
RandomBlock(-5,26,3,minecraft:iron_bars:0,5,quark:iron_plate:1,15,STAINED_CLAY:15,15,STAINED_CLAY:7,100)
RandomBlock(-5,26,4,minecraft:iron_bars:0,5,quark:iron_plate:1,15,STAINED_CLAY:15,15,STAINED_CLAY:7,100)
RandomBlock(-5,26,5,minecraft:iron_bars:0,5,quark:iron_plate:1,15,STAINED_CLAY:15,15,STAINED_CLAY:7,100)
RandomBlock(-5,26,6,minecraft:iron_bars:0,5,quark:iron_plate:1,15,STAINED_CLAY:15,15,STAINED_CLAY:7,100)
RandomBlock(-5,26,7,minecraft:iron_bars:0,5,quark:iron_plate:1,15,STAINED_CLAY:15,15,STAINED_CLAY:7,100)
RandomBlock(-5,27,2,minecraft:iron_bars:0,5,quark:iron_plate:1,15,STAINED_CLAY:15,15,STAINED_CLAY:7,100)
RandomBlock(-5,27,3,minecraft:iron_bars:0,5,quark:iron_plate:1,15,STAINED_CLAY:15,15,STAINED_CLAY:7,100)
RandomBlock(-5,27,4,minecraft:iron_bars:0,5,quark:iron_plate:1,15,STAINED_CLAY:15,15,STAINED_CLAY:7,100)
RandomBlock(-5,27,5,minecraft:iron_bars:0,5,quark:iron_plate:1,15,STAINED_CLAY:15,15,STAINED_CLAY:7,100)
RandomBlock(-5,27,6,minecraft:iron_bars:0,5,quark:iron_plate:1,15,STAINED_CLAY:15,15,STAINED_CLAY:7,100)
RandomBlock(-5,27,7,minecraft:iron_bars:0,5,quark:iron_plate:1,15,STAINED_CLAY:15,15,STAINED_CLAY:7,100)
RandomBlock(-5,28,2,minecraft:iron_bars:0,5,quark:iron_plate:1,15,STAINED_CLAY:15,15,STAINED_CLAY:7,100)
RandomBlock(-5,28,3,minecraft:iron_bars:0,5,quark:iron_plate:1,15,STAINED_CLAY:15,15,STAINED_CLAY:7,100)
RandomBlock(-5,28,4,minecraft:iron_bars:0,5,quark:iron_plate:1,15,STAINED_CLAY:15,15,STAINED_CLAY:7,100)
RandomBlock(-5,28,5,minecraft:iron_bars:0,5,quark:iron_plate:1,15,STAINED_CLAY:15,15,STAINED_CLAY:7,100)
RandomBlock(-5,28,6,minecraft:iron_bars:0,5,quark:iron_plate:1,15,STAINED_CLAY:15,15,STAINED_CLAY:7,100)
RandomBlock(-5,28,7,minecraft:iron_bars:0,5,quark:iron_plate:1,15,STAINED_CLAY:15,15,STAINED_CLAY:7,100)
RandomBlock(-5,29,2,minecraft:iron_bars:0,5,quark:iron_plate:1,15,STAINED_CLAY:15,15,STAINED_CLAY:7,100)
RandomBlock(-5,29,3,minecraft:iron_bars:0,5,quark:iron_plate:1,15,STAINED_CLAY:15,15,STAINED_CLAY:7,100)
RandomBlock(-5,29,4,minecraft:iron_bars:0,5,quark:iron_plate:1,15,STAINED_CLAY:15,15,STAINED_CLAY:7,100)
RandomBlock(-5,29,5,minecraft:iron_bars:0,5,quark:iron_plate:1,15,STAINED_CLAY:15,15,STAINED_CLAY:7,100)
RandomBlock(-5,29,6,minecraft:iron_bars:0,5,quark:iron_plate:1,15,STAINED_CLAY:15,15,STAINED_CLAY:7,100)
RandomBlock(-5,29,7,minecraft:iron_bars:0,5,quark:iron_plate:1,15,STAINED_CLAY:15,15,STAINED_CLAY:7,100)
RandomBlock(-5,30,2,minecraft:iron_bars:0,5,quark:iron_plate:1,15,STAINED_CLAY:15,15,STAINED_CLAY:7,100)
RandomBlock(-5,30,3,minecraft:iron_bars:0,5,quark:iron_plate:1,15,STAINED_CLAY:15,15,STAINED_CLAY:7,100)
RandomBlock(-5,30,4,minecraft:iron_bars:0,5,quark:iron_plate:1,15,STAINED_CLAY:15,15,STAINED_CLAY:7,100)
RandomBlock(-5,30,5,minecraft:iron_bars:0,5,quark:iron_plate:1,15,STAINED_CLAY:15,15,STAINED_CLAY:7,100)
RandomBlock(-5,30,6,minecraft:iron_bars:0,5,quark:iron_plate:1,15,STAINED_CLAY:15,15,STAINED_CLAY:7,100)
RandomBlock(-5,30,7,minecraft:iron_bars:0,5,quark:iron_plate:1,15,STAINED_CLAY:15,15,STAINED_CLAY:7,100)
RandomBlock(-5,31,2,minecraft:iron_bars:0,5,quark:iron_plate:1,15,STAINED_CLAY:15,15,STAINED_CLAY:7,100)
RandomBlock(-5,31,3,minecraft:iron_bars:0,5,quark:iron_plate:1,15,STAINED_CLAY:15,15,STAINED_CLAY:7,100)
RandomBlock(-5,31,4,minecraft:iron_bars:0,5,quark:iron_plate:1,15,STAINED_CLAY:15,15,STAINED_CLAY:7,100)
RandomBlock(-5,31,5,minecraft:iron_bars:0,5,quark:iron_plate:1,15,STAINED_CLAY:15,15,STAINED_CLAY:7,100)
RandomBlock(-5,31,6,minecraft:iron_bars:0,5,quark:iron_plate:1,15,STAINED_CLAY:15,15,STAINED_CLAY:7,100)
RandomBlock(-5,31,7,minecraft:iron_bars:0,5,quark:iron_plate:1,15,STAINED_CLAY:15,15,STAINED_CLAY:7,100)
RandomBlock(-5,32,2,minecraft:iron_bars:0,5,quark:iron_plate:1,15,STAINED_CLAY:15,15,STAINED_CLAY:7,100)
RandomBlock(-5,32,3,minecraft:iron_bars:0,5,quark:iron_plate:1,15,STAINED_CLAY:15,15,STAINED_CLAY:7,100)
RandomBlock(-5,32,4,minecraft:iron_bars:0,5,quark:iron_plate:1,15,STAINED_CLAY:15,15,STAINED_CLAY:7,100)
RandomBlock(-5,32,5,minecraft:iron_bars:0,5,quark:iron_plate:1,15,STAINED_CLAY:15,15,STAINED_CLAY:7,100)
RandomBlock(-5,32,6,minecraft:iron_bars:0,5,quark:iron_plate:1,15,STAINED_CLAY:15,15,STAINED_CLAY:7,100)
RandomBlock(-5,32,7,minecraft:iron_bars:0,5,quark:iron_plate:1,15,STAINED_CLAY:15,15,STAINED_CLAY:7,100)
RandomBlock(-5,33,2,minecraft:iron_bars:0,5,quark:iron_plate:1,15,STAINED_CLAY:15,15,STAINED_CLAY:7,100)
RandomBlock(-5,33,3,minecraft:iron_bars:0,5,quark:iron_plate:1,15,STAINED_CLAY:15,15,STAINED_CLAY:7,100)
RandomBlock(-5,33,4,minecraft:iron_bars:0,5,quark:iron_plate:1,15,STAINED_CLAY:15,15,STAINED_CLAY:7,100)
RandomBlock(-5,33,5,minecraft:iron_bars:0,5,quark:iron_plate:1,15,STAINED_CLAY:15,15,STAINED_CLAY:7,100)
RandomBlock(-5,33,6,minecraft:iron_bars:0,5,quark:iron_plate:1,15,STAINED_CLAY:15,15,STAINED_CLAY:7,100)
RandomBlock(-5,33,7,minecraft:iron_bars:0,5,quark:iron_plate:1,15,STAINED_CLAY:15,15,STAINED_CLAY:7,100)
RandomBlock(-5,34,2,minecraft:iron_bars:0,5,quark:iron_plate:1,15,STAINED_CLAY:15,15,STAINED_CLAY:7,100)
RandomBlock(-5,34,3,minecraft:iron_bars:0,5,quark:iron_plate:1,15,STAINED_CLAY:15,15,STAINED_CLAY:7,100)
RandomBlock(-5,34,4,minecraft:iron_bars:0,5,quark:iron_plate:1,15,STAINED_CLAY:15,15,STAINED_CLAY:7,100)
RandomBlock(-5,34,5,minecraft:iron_bars:0,5,quark:iron_plate:1,15,STAINED_CLAY:15,15,STAINED_CLAY:7,100)
RandomBlock(-5,34,6,minecraft:iron_bars:0,5,quark:iron_plate:1,15,STAINED_CLAY:15,15,STAINED_CLAY:7,100)
RandomBlock(-5,34,7,minecraft:iron_bars:0,5,quark:iron_plate:1,15,STAINED_CLAY:15,15,STAINED_CLAY:7,100)
RandomBlock(-5,35,2,minecraft:iron_bars:0,5,quark:iron_plate:1,15,STAINED_CLAY:15,15,STAINED_CLAY:7,100)
RandomBlock(-5,35,3,minecraft:iron_bars:0,5,quark:iron_plate:1,15,STAINED_CLAY:15,15,STAINED_CLAY:7,100)
RandomBlock(-5,35,4,minecraft:iron_bars:0,5,quark:iron_plate:1,15,STAINED_CLAY:15,15,STAINED_CLAY:7,100)
RandomBlock(-5,35,5,minecraft:iron_bars:0,5,quark:iron_plate:1,15,STAINED_CLAY:15,15,STAINED_CLAY:7,100)
RandomBlock(-5,35,6,minecraft:iron_bars:0,5,quark:iron_plate:1,15,STAINED_CLAY:15,15,STAINED_CLAY:7,100)
RandomBlock(-5,35,7,minecraft:iron_bars:0,5,quark:iron_plate:1,15,STAINED_CLAY:15,15,STAINED_CLAY:7,100)
RandomBlock(-5,36,2,minecraft:iron_bars:0,5,quark:iron_plate:1,15,STAINED_CLAY:15,15,STAINED_CLAY:7,100)
RandomBlock(-5,36,3,minecraft:iron_bars:0,5,quark:iron_plate:1,15,STAINED_CLAY:15,15,STAINED_CLAY:7,100)
RandomBlock(-5,36,4,minecraft:iron_bars:0,5,quark:iron_plate:1,15,STAINED_CLAY:15,15,STAINED_CLAY:7,100)
RandomBlock(-5,36,5,minecraft:iron_bars:0,5,quark:iron_plate:1,15,STAINED_CLAY:15,15,STAINED_CLAY:7,100)
RandomBlock(-5,36,6,minecraft:iron_bars:0,5,quark:iron_plate:1,15,STAINED_CLAY:15,15,STAINED_CLAY:7,100)
RandomBlock(-5,36,7,minecraft:iron_bars:0,5,quark:iron_plate:1,15,STAINED_CLAY:15,15,STAINED_CLAY:7,100)
RandomBlock(-5,37,2,minecraft:iron_bars:0,5,quark:iron_plate:1,15,STAINED_CLAY:15,15,STAINED_CLAY:7,100)
RandomBlock(-5,37,3,minecraft:iron_bars:0,5,quark:iron_plate:1,15,STAINED_CLAY:15,15,STAINED_CLAY:7,100)
RandomBlock(-5,37,4,minecraft:iron_bars:0,5,quark:iron_plate:1,15,STAINED_CLAY:15,15,STAINED_CLAY:7,100)
RandomBlock(-5,37,5,minecraft:iron_bars:0,5,quark:iron_plate:1,15,STAINED_CLAY:15,15,STAINED_CLAY:7,100)
RandomBlock(-5,37,6,minecraft:iron_bars:0,5,quark:iron_plate:1,15,STAINED_CLAY:15,15,STAINED_CLAY:7,100)
RandomBlock(-5,37,7,minecraft:iron_bars:0,5,quark:iron_plate:1,15,STAINED_CLAY:15,15,STAINED_CLAY:7,100)
RandomBlock(-5,38,2,minecraft:iron_bars:0,5,quark:iron_plate:1,15,STAINED_CLAY:15,15,STAINED_CLAY:7,100)
RandomBlock(-5,38,3,minecraft:iron_bars:0,5,quark:iron_plate:1,15,STAINED_CLAY:15,15,STAINED_CLAY:7,100)
RandomBlock(-5,38,4,minecraft:iron_bars:0,5,quark:iron_plate:1,15,STAINED_CLAY:15,15,STAINED_CLAY:7,100)
RandomBlock(-5,38,5,minecraft:iron_bars:0,5,quark:iron_plate:1,15,STAINED_CLAY:15,15,STAINED_CLAY:7,100)
RandomBlock(-5,38,6,minecraft:iron_bars:0,5,quark:iron_plate:1,15,STAINED_CLAY:15,15,STAINED_CLAY:7,100)
RandomBlock(-5,38,7,minecraft:iron_bars:0,5,quark:iron_plate:1,15,STAINED_CLAY:15,15,STAINED_CLAY:7,100)
RandomBlock(-5,39,2,minecraft:iron_bars:0,5,quark:iron_plate:1,15,STAINED_CLAY:15,15,STAINED_CLAY:7,100)
RandomBlock(-5,39,3,minecraft:iron_bars:0,5,quark:iron_plate:1,15,STAINED_CLAY:15,15,STAINED_CLAY:7,100)
RandomBlock(-5,39,4,minecraft:iron_bars:0,5,quark:iron_plate:1,15,STAINED_CLAY:15,15,STAINED_CLAY:7,100)
RandomBlock(-5,39,5,minecraft:iron_bars:0,5,quark:iron_plate:1,15,STAINED_CLAY:15,15,STAINED_CLAY:7,100)
RandomBlock(-5,39,6,minecraft:iron_bars:0,5,quark:iron_plate:1,15,STAINED_CLAY:15,15,STAINED_CLAY:7,100)
RandomBlock(-5,39,7,minecraft:iron_bars:0,5,quark:iron_plate:1,15,STAINED_CLAY:15,15,STAINED_CLAY:7,100)
RandomBlock(-5,40,2,minecraft:iron_bars:0,5,quark:iron_plate:1,15,STAINED_CLAY:15,15,STAINED_CLAY:7,100)
RandomBlock(-5,40,3,minecraft:iron_bars:0,5,quark:iron_plate:1,15,STAINED_CLAY:15,15,STAINED_CLAY:7,100)
RandomBlock(-5,40,4,minecraft:iron_bars:0,5,quark:iron_plate:1,15,STAINED_CLAY:15,15,STAINED_CLAY:7,100)
RandomBlock(-5,40,5,minecraft:iron_bars:0,5,quark:iron_plate:1,15,STAINED_CLAY:15,15,STAINED_CLAY:7,100)
RandomBlock(-5,40,6,minecraft:iron_bars:0,5,quark:iron_plate:1,15,STAINED_CLAY:15,15,STAINED_CLAY:7,100)
RandomBlock(-5,40,7,minecraft:iron_bars:0,5,quark:iron_plate:1,15,STAINED_CLAY:15,15,STAINED_CLAY:7,100)
RandomBlock(-5,41,2,minecraft:iron_bars:0,5,quark:iron_plate:1,15,STAINED_CLAY:15,15,STAINED_CLAY:7,100)
RandomBlock(-5,41,3,minecraft:iron_bars:0,5,quark:iron_plate:1,15,STAINED_CLAY:15,15,STAINED_CLAY:7,100)
RandomBlock(-5,41,4,minecraft:iron_bars:0,5,quark:iron_plate:1,15,STAINED_CLAY:15,15,STAINED_CLAY:7,100)
RandomBlock(-5,41,5,minecraft:iron_bars:0,5,quark:iron_plate:1,15,STAINED_CLAY:15,15,STAINED_CLAY:7,100)
RandomBlock(-5,41,6,minecraft:iron_bars:0,5,quark:iron_plate:1,15,STAINED_CLAY:15,15,STAINED_CLAY:7,100)
RandomBlock(-5,41,7,minecraft:iron_bars:0,5,quark:iron_plate:1,15,STAINED_CLAY:15,15,STAINED_CLAY:7,100)
RandomBlock(-5,42,2,minecraft:iron_bars:0,5,quark:iron_plate:1,15,STAINED_CLAY:15,15,STAINED_CLAY:7,100)
RandomBlock(-5,42,3,minecraft:iron_bars:0,5,quark:iron_plate:1,15,STAINED_CLAY:15,15,STAINED_CLAY:7,100)
RandomBlock(-5,42,4,minecraft:iron_bars:0,5,quark:iron_plate:1,15,STAINED_CLAY:15,15,STAINED_CLAY:7,100)
RandomBlock(-5,42,5,minecraft:iron_bars:0,5,quark:iron_plate:1,15,STAINED_CLAY:15,15,STAINED_CLAY:7,100)
RandomBlock(-5,42,6,minecraft:iron_bars:0,5,quark:iron_plate:1,15,STAINED_CLAY:15,15,STAINED_CLAY:7,100)
RandomBlock(-5,42,7,minecraft:iron_bars:0,5,quark:iron_plate:1,15,STAINED_CLAY:15,15,STAINED_CLAY:7,100)
RandomBlock(-5,43,2,minecraft:iron_bars:0,5,quark:iron_plate:1,15,STAINED_CLAY:15,15,STAINED_CLAY:7,100)
RandomBlock(-5,43,3,minecraft:iron_bars:0,5,quark:iron_plate:1,15,STAINED_CLAY:15,15,STAINED_CLAY:7,100)
RandomBlock(-5,43,4,minecraft:iron_bars:0,5,quark:iron_plate:1,15,STAINED_CLAY:15,15,STAINED_CLAY:7,100)
RandomBlock(-5,43,5,minecraft:iron_bars:0,5,quark:iron_plate:1,15,STAINED_CLAY:15,15,STAINED_CLAY:7,100)
RandomBlock(-5,43,6,minecraft:iron_bars:0,5,quark:iron_plate:1,15,STAINED_CLAY:15,15,STAINED_CLAY:7,100)
RandomBlock(-5,43,7,minecraft:iron_bars:0,5,quark:iron_plate:1,15,STAINED_CLAY:15,15,STAINED_CLAY:7,100)
RandomBlock(-5,44,-7,minecraft:iron_bars:0,5,STAINED_CLAY:15,5,STAINED_CLAY:7,5,quark:iron_plate_slab:8,15,quark:world_stone_pavement:2,15,STAINED_CLAY:9,100)
RandomBlock(-5,44,-6,minecraft:iron_bars:0,5,STAINED_CLAY:15,5,STAINED_CLAY:7,5,quark:iron_plate_slab:8,15,quark:world_stone_pavement:2,15,STAINED_CLAY:9,100)
RandomBlock(-5,44,-5,minecraft:iron_bars:0,5,STAINED_CLAY:15,5,STAINED_CLAY:7,5,quark:iron_plate_slab:8,15,quark:world_stone_pavement:2,15,STAINED_CLAY:9,100)
RandomBlock(-5,44,-4,minecraft:iron_bars:0,5,STAINED_CLAY:15,5,STAINED_CLAY:7,5,quark:iron_plate_slab:8,15,quark:world_stone_pavement:2,15,STAINED_CLAY:9,100)
RandomBlock(-5,44,-3,minecraft:iron_bars:0,5,STAINED_CLAY:15,5,STAINED_CLAY:7,5,quark:iron_plate_slab:8,15,quark:world_stone_pavement:2,15,STAINED_CLAY:9,100)
RandomBlock(-5,44,-2,minecraft:iron_bars:0,5,STAINED_CLAY:15,5,STAINED_CLAY:7,5,quark:iron_plate_slab:8,15,quark:world_stone_pavement:2,15,STAINED_CLAY:9,100)
RandomBlock(-5,44,-1,minecraft:iron_bars:0,5,STAINED_CLAY:15,5,STAINED_CLAY:7,5,quark:iron_plate_slab:8,15,quark:world_stone_pavement:2,15,STAINED_CLAY:9,100)
RandomBlock(-5,44,0,minecraft:iron_bars:0,5,STAINED_CLAY:15,5,STAINED_CLAY:7,5,quark:iron_plate_slab:8,15,quark:world_stone_pavement:2,15,STAINED_CLAY:9,100)
RandomBlock(-5,44,1,minecraft:iron_bars:0,5,STAINED_CLAY:15,5,STAINED_CLAY:7,5,quark:iron_plate_slab:8,15,quark:world_stone_pavement:2,15,STAINED_CLAY:9,100)
RandomBlock(-5,44,2,minecraft:iron_bars:0,5,STAINED_CLAY:15,5,STAINED_CLAY:7,5,quark:iron_plate_slab:8,15,quark:world_stone_pavement:2,15,STAINED_CLAY:9,100)
RandomBlock(-5,44,3,minecraft:iron_bars:0,5,STAINED_CLAY:15,5,STAINED_CLAY:7,5,quark:iron_plate_slab:8,15,quark:world_stone_pavement:2,15,STAINED_CLAY:9,100)
RandomBlock(-5,44,4,minecraft:iron_bars:0,5,STAINED_CLAY:15,5,STAINED_CLAY:7,5,quark:iron_plate_slab:8,15,quark:world_stone_pavement:2,15,STAINED_CLAY:9,100)
RandomBlock(-5,44,5,minecraft:iron_bars:0,5,STAINED_CLAY:15,5,STAINED_CLAY:7,5,quark:iron_plate_slab:8,15,quark:world_stone_pavement:2,15,STAINED_CLAY:9,100)
RandomBlock(-5,44,6,minecraft:iron_bars:0,5,STAINED_CLAY:15,5,STAINED_CLAY:7,5,quark:iron_plate_slab:8,15,quark:world_stone_pavement:2,15,STAINED_CLAY:9,100)
RandomBlock(-5,44,7,minecraft:iron_bars:0,5,STAINED_CLAY:15,5,STAINED_CLAY:7,5,quark:iron_plate_slab:8,15,quark:world_stone_pavement:2,15,STAINED_CLAY:9,100)
RandomBlock(-5,44,8,minecraft:iron_bars:0,5,STAINED_CLAY:15,5,STAINED_CLAY:7,5,quark:iron_plate_slab:8,15,quark:world_stone_pavement:2,15,STAINED_CLAY:9,100)
Block(-5,45,-5,STEP:5)
RandomBlock(-5,45,-4,minecraft:iron_bars:0,5,CONCRETE_POWDER:8,10,quark:limestone:1,15,quark:limestone,15,quark:world_stone_pavement:2,15,CONCRETE:8,100)
RandomBlock(-5,45,-3,minecraft:iron_bars:0,5,CONCRETE_POWDER:8,10,quark:limestone:1,15,quark:limestone,15,quark:world_stone_pavement:2,15,CONCRETE:8,100)
Block(-5,45,-2,STEP:5)
Block(-5,45,0,STEP:5)
RandomBlock(-5,45,1,minecraft:iron_bars:0,5,CONCRETE_POWDER:8,10,quark:limestone:1,15,quark:limestone,15,quark:world_stone_pavement:2,15,CONCRETE:8,100)
RandomBlock(-5,45,2,minecraft:iron_bars:0,5,CONCRETE_POWDER:8,10,quark:limestone:1,15,quark:limestone,15,quark:world_stone_pavement:2,15,CONCRETE:8,100)
Block(-5,45,3,STEP:5)
RandomBlock(-5,45,5,minecraft:iron_bars:0,5,CONCRETE_POWDER:8,10,quark:limestone:1,15,quark:limestone,15,quark:world_stone_pavement:2,15,CONCRETE:8,100)
Block(-5,45,6,STONE_BUTTON:4)
Block(-5,45,7,DOUBLE_STEP:0)
Block(-5,45,8,DOUBLE_STEP:0)
RandomBlock(-5,46,-5,minecraft:iron_bars:0,5,CONCRETE_POWDER:8,10,quark:limestone:1,15,quark:limestone,15,quark:world_stone_pavement:2,15,CONCRETE:8,100)
Block(-5,46,-4,COAL_BLOCK:0)
Block(-5,46,-3,COAL_BLOCK:0)
RandomBlock(-5,46,-2,minecraft:iron_bars:0,5,CONCRETE_POWDER:8,10,quark:limestone:1,15,quark:limestone,15,quark:world_stone_pavement:2,15,CONCRETE:8,100)
RandomBlock(-5,46,0,minecraft:iron_bars:0,5,CONCRETE_POWDER:8,10,quark:limestone:1,15,quark:limestone,15,quark:world_stone_pavement:2,15,CONCRETE:8,100)
Block(-5,46,1,COAL_BLOCK:0)
Block(-5,46,2,COAL_BLOCK:0)
RandomBlock(-5,46,3,minecraft:iron_bars:0,5,CONCRETE_POWDER:8,10,quark:limestone:1,15,quark:limestone,15,quark:world_stone_pavement:2,15,CONCRETE:8,100)
Block(-5,46,5,CONCRETE:15)
Block(-5,46,7,minecraft:iron_bars:0)
Block(-5,46,8,minecraft:iron_bars:0)
RandomBlock(-5,47,-5,minecraft:iron_bars:0,5,CONCRETE_POWDER:8,10,quark:limestone:1,15,quark:limestone,15,quark:world_stone_pavement:2,15,CONCRETE:8,100)
Block(-5,47,-4,COAL_BLOCK:0)
Block(-5,47,-3,COAL_BLOCK:0)
RandomBlock(-5,47,-2,minecraft:iron_bars:0,5,CONCRETE_POWDER:8,10,quark:limestone:1,15,quark:limestone,15,quark:world_stone_pavement:2,15,CONCRETE:8,100)
RandomBlock(-5,47,0,minecraft:iron_bars:0,5,CONCRETE_POWDER:8,10,quark:limestone:1,15,quark:limestone,15,quark:world_stone_pavement:2,15,CONCRETE:8,100)
Block(-5,47,1,COAL_BLOCK:0)
Block(-5,47,2,COAL_BLOCK:0)
RandomBlock(-5,47,3,minecraft:iron_bars:0,5,CONCRETE_POWDER:8,10,quark:limestone:1,15,quark:limestone,15,quark:world_stone_pavement:2,15,CONCRETE:8,100)
RandomBlock(-5,47,5,minecraft:iron_bars:0,5,CONCRETE_POWDER:8,10,quark:limestone:1,15,quark:limestone,15,quark:world_stone_pavement:2,15,CONCRETE:8,100)
Block(-5,47,7,STEP:0)
Block(-5,47,8,STEP:0)
RandomBlock(-5,48,-4,minecraft:iron_bars:0,5,CONCRETE_POWDER:8,10,quark:limestone:1,15,quark:limestone,15,quark:world_stone_pavement:2,15,CONCRETE:8,100)
RandomBlock(-5,48,-3,minecraft:iron_bars:0,5,CONCRETE_POWDER:8,10,quark:limestone:1,15,quark:limestone,15,quark:world_stone_pavement:2,15,CONCRETE:8,100)
RandomBlock(-5,48,1,minecraft:iron_bars:0,5,CONCRETE_POWDER:8,10,quark:limestone:1,15,quark:limestone,15,quark:world_stone_pavement:2,15,CONCRETE:8,100)
RandomBlock(-5,48,2,minecraft:iron_bars:0,5,CONCRETE_POWDER:8,10,quark:limestone:1,15,quark:limestone,15,quark:world_stone_pavement:2,15,CONCRETE:8,100)
RandomBlock(-5,48,5,minecraft:iron_bars:0,5,CONCRETE_POWDER:8,10,quark:limestone:1,15,quark:limestone,15,quark:world_stone_pavement:2,15,CONCRETE:8,100)
Block(-5,49,-4,quark:basalt_wall)
Block(-5,49,2,quark:basalt_wall)
RandomBlock(-5,49,5,minecraft:iron_bars:0,5,CONCRETE_POWDER:8,10,quark:limestone:1,15,quark:limestone,15,quark:world_stone_pavement:2,15,CONCRETE:8,100)
RandomBlock(-5,49,6,minecraft:iron_bars:0,5,STAINED_CLAY:15,5,STAINED_CLAY:7,5,quark:iron_plate_slab:8,15,quark:world_stone_pavement:2,15,STAINED_CLAY:9,100)
RandomBlock(-5,49,7,minecraft:iron_bars:0,5,STAINED_CLAY:15,5,STAINED_CLAY:7,5,quark:iron_plate_slab:8,15,quark:world_stone_pavement:2,15,STAINED_CLAY:9,100)
RandomBlock(-5,49,8,minecraft:iron_bars:0,5,STAINED_CLAY:15,5,STAINED_CLAY:7,5,quark:iron_plate_slab:8,15,quark:world_stone_pavement:2,15,STAINED_CLAY:9,100)
RandomBlock(-5,50,-7,minecraft:iron_bars:0,5,STAINED_CLAY:15,5,STAINED_CLAY:7,5,quark:iron_plate_slab:8,15,quark:world_stone_pavement:2,15,STAINED_CLAY:9,100)
RandomBlock(-5,50,-6,minecraft:iron_bars:0,5,STAINED_CLAY:15,5,STAINED_CLAY:7,5,quark:iron_plate_slab:8,15,quark:world_stone_pavement:2,15,STAINED_CLAY:9,100)
RandomBlock(-5,50,-5,minecraft:iron_bars:0,5,STAINED_CLAY:15,5,STAINED_CLAY:7,5,quark:iron_plate_slab:8,15,quark:world_stone_pavement:2,15,STAINED_CLAY:9,100)
RandomBlock(-5,50,-4,minecraft:iron_bars:0,5,STAINED_CLAY:15,5,STAINED_CLAY:7,5,quark:iron_plate_slab:8,15,quark:world_stone_pavement:2,15,STAINED_CLAY:9,100)
RandomBlock(-5,50,-3,minecraft:iron_bars:0,5,STAINED_CLAY:15,5,STAINED_CLAY:7,5,quark:iron_plate_slab:8,15,quark:world_stone_pavement:2,15,STAINED_CLAY:9,100)
RandomBlock(-5,50,-2,minecraft:iron_bars:0,5,STAINED_CLAY:15,5,STAINED_CLAY:7,5,quark:iron_plate_slab:8,15,quark:world_stone_pavement:2,15,STAINED_CLAY:9,100)
RandomBlock(-5,50,-1,minecraft:iron_bars:0,5,STAINED_CLAY:15,5,STAINED_CLAY:7,5,quark:iron_plate_slab:8,15,quark:world_stone_pavement:2,15,STAINED_CLAY:9,100)
RandomBlock(-5,50,0,minecraft:iron_bars:0,5,STAINED_CLAY:15,5,STAINED_CLAY:7,5,quark:iron_plate_slab:8,15,quark:world_stone_pavement:2,15,STAINED_CLAY:9,100)
RandomBlock(-5,50,1,minecraft:iron_bars:0,5,STAINED_CLAY:15,5,STAINED_CLAY:7,5,quark:iron_plate_slab:8,15,quark:world_stone_pavement:2,15,STAINED_CLAY:9,100)
RandomBlock(-5,50,2,minecraft:iron_bars:0,5,CONCRETE_POWDER:8,10,quark:limestone:1,15,quark:limestone,15,quark:world_stone_pavement:2,15,CONCRETE:8,100)
Block(-5,50,5,minecraft:iron_bars:0)
Block(-5,50,7,STONE:6)
Block(-5,51,2,minecraft:iron_bars:0)
Block(-5,51,5,minecraft:iron_bars:0)
Block(-5,52,2,minecraft:iron_bars:0)
RandomBlock(-5,54,-7,minecraft:iron_bars:0,5,CONCRETE_POWDER:8,10,quark:limestone:1,15,quark:limestone,15,quark:world_stone_pavement:2,15,CONCRETE:8,100)
Block(-5,55,-7,minecraft:iron_bars:0)
Block(-5,56,-7,minecraft:iron_bars:0)
Block(-5,58,-7,STEP:13)
Block(-5,58,-6,minecraft:iron_bars:0)
Block(-5,58,-5,quark:basalt_wall)
Block(-5,58,-4,minecraft:iron_bars:0)
Block(-5,58,-3,quark:basalt_wall)
Block(-5,58,-2,minecraft:iron_bars:0)
Block(-5,58,-1,STEP:13)
Block(-5,59,-7,IRON_FENCE:0)
Block(-5,59,-6,STEP:0)
Block(-5,59,-5,STEP:0)
Block(-5,59,-3,STEP:0)
Block(-5,59,-2,STEP:0)
Block(-5,59,-1,IRON_FENCE:0)
Block(-5,65,8,minecraft:iron_bars:0)
Block(-5,66,8,IRON_FENCE:0)
RandomBlock(-4,0,1,minecraft:iron_bars:0,5,quark:iron_plate:1,15,STAINED_CLAY:15,15,STAINED_CLAY:7,100)
RandomBlock(-4,0,2,minecraft:iron_bars:0,5,quark:iron_plate:1,15,STAINED_CLAY:15,15,STAINED_CLAY:7,100)
RandomBlock(-4,0,3,minecraft:iron_bars:0,5,quark:iron_plate:1,15,STAINED_CLAY:15,15,STAINED_CLAY:7,100)
RandomBlock(-4,0,4,minecraft:iron_bars:0,5,quark:iron_plate:1,15,STAINED_CLAY:15,15,STAINED_CLAY:7,100)
RandomBlock(-4,0,5,minecraft:iron_bars:0,5,quark:iron_plate:1,15,STAINED_CLAY:15,15,STAINED_CLAY:7,100)
RandomBlock(-4,0,6,minecraft:iron_bars:0,5,quark:iron_plate:1,15,STAINED_CLAY:15,15,STAINED_CLAY:7,100)
RandomBlock(-4,0,7,minecraft:iron_bars:0,5,quark:iron_plate:1,15,STAINED_CLAY:15,15,STAINED_CLAY:7,100)
RandomBlock(-4,0,8,minecraft:iron_bars:0,5,quark:iron_plate:1,15,STAINED_CLAY:15,15,STAINED_CLAY:7,100)
RandomBlock(-4,1,1,minecraft:iron_bars:0,5,quark:iron_plate:1,15,STAINED_CLAY:15,15,STAINED_CLAY:7,100)
RandomBlock(-4,1,2,minecraft:iron_bars:0,5,quark:iron_plate:1,15,STAINED_CLAY:15,15,STAINED_CLAY:7,100)
RandomBlock(-4,1,3,minecraft:iron_bars:0,5,quark:iron_plate:1,15,STAINED_CLAY:15,15,STAINED_CLAY:7,100)
RandomBlock(-4,1,4,minecraft:iron_bars:0,5,quark:iron_plate:1,15,STAINED_CLAY:15,15,STAINED_CLAY:7,100)
RandomBlock(-4,1,5,minecraft:iron_bars:0,5,quark:iron_plate:1,15,STAINED_CLAY:15,15,STAINED_CLAY:7,100)
RandomBlock(-4,1,6,minecraft:iron_bars:0,5,quark:iron_plate:1,15,STAINED_CLAY:15,15,STAINED_CLAY:7,100)
RandomBlock(-4,1,7,minecraft:iron_bars:0,5,quark:iron_plate:1,15,STAINED_CLAY:15,15,STAINED_CLAY:7,100)
RandomBlock(-4,1,8,minecraft:iron_bars:0,5,quark:iron_plate:1,15,STAINED_CLAY:15,15,STAINED_CLAY:7,100)
RandomBlock(-4,2,1,minecraft:iron_bars:0,5,quark:iron_plate:1,15,STAINED_CLAY:15,15,STAINED_CLAY:7,100)
RandomBlock(-4,2,2,minecraft:iron_bars:0,5,quark:iron_plate:1,15,STAINED_CLAY:15,15,STAINED_CLAY:7,100)
RandomBlock(-4,2,3,minecraft:iron_bars:0,5,quark:iron_plate:1,15,STAINED_CLAY:15,15,STAINED_CLAY:7,100)
RandomBlock(-4,2,4,minecraft:iron_bars:0,5,quark:iron_plate:1,15,STAINED_CLAY:15,15,STAINED_CLAY:7,100)
RandomBlock(-4,2,5,minecraft:iron_bars:0,5,quark:iron_plate:1,15,STAINED_CLAY:15,15,STAINED_CLAY:7,100)
RandomBlock(-4,2,6,minecraft:iron_bars:0,5,quark:iron_plate:1,15,STAINED_CLAY:15,15,STAINED_CLAY:7,100)
RandomBlock(-4,2,7,minecraft:iron_bars:0,5,quark:iron_plate:1,15,STAINED_CLAY:15,15,STAINED_CLAY:7,100)
RandomBlock(-4,2,8,minecraft:iron_bars:0,5,quark:iron_plate:1,15,STAINED_CLAY:15,15,STAINED_CLAY:7,100)
RandomBlock(-4,3,1,minecraft:iron_bars:0,5,quark:iron_plate:1,15,STAINED_CLAY:15,15,STAINED_CLAY:7,100)
RandomBlock(-4,3,2,minecraft:iron_bars:0,5,quark:iron_plate:1,15,STAINED_CLAY:15,15,STAINED_CLAY:7,100)
RandomBlock(-4,3,3,minecraft:iron_bars:0,5,quark:iron_plate:1,15,STAINED_CLAY:15,15,STAINED_CLAY:7,100)
RandomBlock(-4,3,4,minecraft:iron_bars:0,5,quark:iron_plate:1,15,STAINED_CLAY:15,15,STAINED_CLAY:7,100)
RandomBlock(-4,3,5,minecraft:iron_bars:0,5,quark:iron_plate:1,15,STAINED_CLAY:15,15,STAINED_CLAY:7,100)
RandomBlock(-4,3,6,minecraft:iron_bars:0,5,quark:iron_plate:1,15,STAINED_CLAY:15,15,STAINED_CLAY:7,100)
RandomBlock(-4,3,7,minecraft:iron_bars:0,5,quark:iron_plate:1,15,STAINED_CLAY:15,15,STAINED_CLAY:7,100)
RandomBlock(-4,3,8,minecraft:iron_bars:0,5,quark:iron_plate:1,15,STAINED_CLAY:15,15,STAINED_CLAY:7,100)
RandomBlock(-4,4,1,minecraft:iron_bars:0,5,quark:iron_plate:1,15,STAINED_CLAY:15,15,STAINED_CLAY:7,100)
RandomBlock(-4,4,2,minecraft:iron_bars:0,5,quark:iron_plate:1,15,STAINED_CLAY:15,15,STAINED_CLAY:7,100)
RandomBlock(-4,4,3,minecraft:iron_bars:0,5,quark:iron_plate:1,15,STAINED_CLAY:15,15,STAINED_CLAY:7,100)
RandomBlock(-4,4,4,minecraft:iron_bars:0,5,quark:iron_plate:1,15,STAINED_CLAY:15,15,STAINED_CLAY:7,100)
RandomBlock(-4,4,5,minecraft:iron_bars:0,5,quark:iron_plate:1,15,STAINED_CLAY:15,15,STAINED_CLAY:7,100)
RandomBlock(-4,4,6,minecraft:iron_bars:0,5,quark:iron_plate:1,15,STAINED_CLAY:15,15,STAINED_CLAY:7,100)
RandomBlock(-4,4,7,minecraft:iron_bars:0,5,quark:iron_plate:1,15,STAINED_CLAY:15,15,STAINED_CLAY:7,100)
RandomBlock(-4,4,8,minecraft:iron_bars:0,5,quark:iron_plate:1,15,STAINED_CLAY:15,15,STAINED_CLAY:7,100)
RandomBlock(-4,5,1,minecraft:iron_bars:0,5,quark:iron_plate:1,15,STAINED_CLAY:15,15,STAINED_CLAY:7,100)
RandomBlock(-4,5,2,minecraft:iron_bars:0,5,quark:iron_plate:1,15,STAINED_CLAY:15,15,STAINED_CLAY:7,100)
RandomBlock(-4,5,3,minecraft:iron_bars:0,5,quark:iron_plate:1,15,STAINED_CLAY:15,15,STAINED_CLAY:7,100)
RandomBlock(-4,5,4,minecraft:iron_bars:0,5,quark:iron_plate:1,15,STAINED_CLAY:15,15,STAINED_CLAY:7,100)
RandomBlock(-4,5,5,minecraft:iron_bars:0,5,quark:iron_plate:1,15,STAINED_CLAY:15,15,STAINED_CLAY:7,100)
RandomBlock(-4,5,6,minecraft:iron_bars:0,5,quark:iron_plate:1,15,STAINED_CLAY:15,15,STAINED_CLAY:7,100)
RandomBlock(-4,5,7,minecraft:iron_bars:0,5,quark:iron_plate:1,15,STAINED_CLAY:15,15,STAINED_CLAY:7,100)
RandomBlock(-4,5,8,minecraft:iron_bars:0,5,quark:iron_plate:1,15,STAINED_CLAY:15,15,STAINED_CLAY:7,100)
RandomBlock(-4,6,1,minecraft:iron_bars:0,5,quark:iron_plate:1,15,STAINED_CLAY:15,15,STAINED_CLAY:7,100)
RandomBlock(-4,6,2,minecraft:iron_bars:0,5,quark:iron_plate:1,15,STAINED_CLAY:15,15,STAINED_CLAY:7,100)
RandomBlock(-4,6,3,minecraft:iron_bars:0,5,quark:iron_plate:1,15,STAINED_CLAY:15,15,STAINED_CLAY:7,100)
RandomBlock(-4,6,4,minecraft:iron_bars:0,5,quark:iron_plate:1,15,STAINED_CLAY:15,15,STAINED_CLAY:7,100)
RandomBlock(-4,6,5,minecraft:iron_bars:0,5,quark:iron_plate:1,15,STAINED_CLAY:15,15,STAINED_CLAY:7,100)
RandomBlock(-4,6,6,minecraft:iron_bars:0,5,quark:iron_plate:1,15,STAINED_CLAY:15,15,STAINED_CLAY:7,100)
RandomBlock(-4,6,7,minecraft:iron_bars:0,5,quark:iron_plate:1,15,STAINED_CLAY:15,15,STAINED_CLAY:7,100)
RandomBlock(-4,6,8,minecraft:iron_bars:0,5,quark:iron_plate:1,15,STAINED_CLAY:15,15,STAINED_CLAY:7,100)
RandomBlock(-4,7,1,minecraft:iron_bars:0,5,quark:iron_plate:1,15,STAINED_CLAY:15,15,STAINED_CLAY:7,100)
RandomBlock(-4,7,2,minecraft:iron_bars:0,5,quark:iron_plate:1,15,STAINED_CLAY:15,15,STAINED_CLAY:7,100)
RandomBlock(-4,7,3,minecraft:iron_bars:0,5,quark:iron_plate:1,15,STAINED_CLAY:15,15,STAINED_CLAY:7,100)
RandomBlock(-4,7,4,minecraft:iron_bars:0,5,quark:iron_plate:1,15,STAINED_CLAY:15,15,STAINED_CLAY:7,100)
RandomBlock(-4,7,5,minecraft:iron_bars:0,5,quark:iron_plate:1,15,STAINED_CLAY:15,15,STAINED_CLAY:7,100)
RandomBlock(-4,7,6,minecraft:iron_bars:0,5,quark:iron_plate:1,15,STAINED_CLAY:15,15,STAINED_CLAY:7,100)
RandomBlock(-4,7,7,minecraft:iron_bars:0,5,quark:iron_plate:1,15,STAINED_CLAY:15,15,STAINED_CLAY:7,100)
RandomBlock(-4,7,8,minecraft:iron_bars:0,5,quark:iron_plate:1,15,STAINED_CLAY:15,15,STAINED_CLAY:7,100)
RandomBlock(-4,8,1,minecraft:iron_bars:0,5,quark:iron_plate:1,15,STAINED_CLAY:15,15,STAINED_CLAY:7,100)
RandomBlock(-4,8,2,minecraft:iron_bars:0,5,quark:iron_plate:1,15,STAINED_CLAY:15,15,STAINED_CLAY:7,100)
RandomBlock(-4,8,3,minecraft:iron_bars:0,5,quark:iron_plate:1,15,STAINED_CLAY:15,15,STAINED_CLAY:7,100)
RandomBlock(-4,8,4,minecraft:iron_bars:0,5,quark:iron_plate:1,15,STAINED_CLAY:15,15,STAINED_CLAY:7,100)
RandomBlock(-4,8,5,minecraft:iron_bars:0,5,quark:iron_plate:1,15,STAINED_CLAY:15,15,STAINED_CLAY:7,100)
RandomBlock(-4,8,6,minecraft:iron_bars:0,5,quark:iron_plate:1,15,STAINED_CLAY:15,15,STAINED_CLAY:7,100)
RandomBlock(-4,8,7,minecraft:iron_bars:0,5,quark:iron_plate:1,15,STAINED_CLAY:15,15,STAINED_CLAY:7,100)
RandomBlock(-4,8,8,minecraft:iron_bars:0,5,quark:iron_plate:1,15,STAINED_CLAY:15,15,STAINED_CLAY:7,100)
RandomBlock(-4,9,1,minecraft:iron_bars:0,5,quark:iron_plate:1,15,STAINED_CLAY:15,15,STAINED_CLAY:7,100)
RandomBlock(-4,9,2,minecraft:iron_bars:0,5,quark:iron_plate:1,15,STAINED_CLAY:15,15,STAINED_CLAY:7,100)
RandomBlock(-4,9,3,minecraft:iron_bars:0,5,quark:iron_plate:1,15,STAINED_CLAY:15,15,STAINED_CLAY:7,100)
RandomBlock(-4,9,4,minecraft:iron_bars:0,5,quark:iron_plate:1,15,STAINED_CLAY:15,15,STAINED_CLAY:7,100)
RandomBlock(-4,9,5,minecraft:iron_bars:0,5,quark:iron_plate:1,15,STAINED_CLAY:15,15,STAINED_CLAY:7,100)
RandomBlock(-4,9,6,minecraft:iron_bars:0,5,quark:iron_plate:1,15,STAINED_CLAY:15,15,STAINED_CLAY:7,100)
RandomBlock(-4,9,7,minecraft:iron_bars:0,5,quark:iron_plate:1,15,STAINED_CLAY:15,15,STAINED_CLAY:7,100)
RandomBlock(-4,9,8,minecraft:iron_bars:0,5,quark:iron_plate:1,15,STAINED_CLAY:15,15,STAINED_CLAY:7,100)
RandomBlock(-4,10,1,minecraft:iron_bars:0,5,quark:iron_plate:1,15,STAINED_CLAY:15,15,STAINED_CLAY:7,100)
RandomBlock(-4,10,2,minecraft:iron_bars:0,5,quark:iron_plate:1,15,STAINED_CLAY:15,15,STAINED_CLAY:7,100)
RandomBlock(-4,10,3,minecraft:iron_bars:0,5,quark:iron_plate:1,15,STAINED_CLAY:15,15,STAINED_CLAY:7,100)
RandomBlock(-4,10,4,minecraft:iron_bars:0,5,quark:iron_plate:1,15,STAINED_CLAY:15,15,STAINED_CLAY:7,100)
RandomBlock(-4,10,5,minecraft:iron_bars:0,5,quark:iron_plate:1,15,STAINED_CLAY:15,15,STAINED_CLAY:7,100)
RandomBlock(-4,10,6,minecraft:iron_bars:0,5,quark:iron_plate:1,15,STAINED_CLAY:15,15,STAINED_CLAY:7,100)
RandomBlock(-4,10,7,minecraft:iron_bars:0,5,quark:iron_plate:1,15,STAINED_CLAY:15,15,STAINED_CLAY:7,100)
RandomBlock(-4,10,8,minecraft:iron_bars:0,5,quark:iron_plate:1,15,STAINED_CLAY:15,15,STAINED_CLAY:7,100)
RandomBlock(-4,11,1,minecraft:iron_bars:0,5,quark:iron_plate:1,15,STAINED_CLAY:15,15,STAINED_CLAY:7,100)
RandomBlock(-4,11,2,minecraft:iron_bars:0,5,quark:iron_plate:1,15,STAINED_CLAY:15,15,STAINED_CLAY:7,100)
RandomBlock(-4,11,3,minecraft:iron_bars:0,5,quark:iron_plate:1,15,STAINED_CLAY:15,15,STAINED_CLAY:7,100)
RandomBlock(-4,11,4,minecraft:iron_bars:0,5,quark:iron_plate:1,15,STAINED_CLAY:15,15,STAINED_CLAY:7,100)
RandomBlock(-4,11,5,minecraft:iron_bars:0,5,quark:iron_plate:1,15,STAINED_CLAY:15,15,STAINED_CLAY:7,100)
RandomBlock(-4,11,6,minecraft:iron_bars:0,5,quark:iron_plate:1,15,STAINED_CLAY:15,15,STAINED_CLAY:7,100)
RandomBlock(-4,11,7,minecraft:iron_bars:0,5,quark:iron_plate:1,15,STAINED_CLAY:15,15,STAINED_CLAY:7,100)
RandomBlock(-4,11,8,minecraft:iron_bars:0,5,quark:iron_plate:1,15,STAINED_CLAY:15,15,STAINED_CLAY:7,100)
RandomBlock(-4,12,1,minecraft:iron_bars:0,5,quark:iron_plate:1,15,STAINED_CLAY:15,15,STAINED_CLAY:7,100)
RandomBlock(-4,12,2,minecraft:iron_bars:0,5,quark:iron_plate:1,15,STAINED_CLAY:15,15,STAINED_CLAY:7,100)
RandomBlock(-4,12,3,minecraft:iron_bars:0,5,quark:iron_plate:1,15,STAINED_CLAY:15,15,STAINED_CLAY:7,100)
RandomBlock(-4,12,4,minecraft:iron_bars:0,5,quark:iron_plate:1,15,STAINED_CLAY:15,15,STAINED_CLAY:7,100)
RandomBlock(-4,12,5,minecraft:iron_bars:0,5,quark:iron_plate:1,15,STAINED_CLAY:15,15,STAINED_CLAY:7,100)
RandomBlock(-4,12,6,minecraft:iron_bars:0,5,quark:iron_plate:1,15,STAINED_CLAY:15,15,STAINED_CLAY:7,100)
RandomBlock(-4,12,7,minecraft:iron_bars:0,5,quark:iron_plate:1,15,STAINED_CLAY:15,15,STAINED_CLAY:7,100)
RandomBlock(-4,12,8,minecraft:iron_bars:0,5,quark:iron_plate:1,15,STAINED_CLAY:15,15,STAINED_CLAY:7,100)
RandomBlock(-4,13,1,minecraft:iron_bars:0,5,quark:iron_plate:1,15,STAINED_CLAY:15,15,STAINED_CLAY:7,100)
RandomBlock(-4,13,2,minecraft:iron_bars:0,5,quark:iron_plate:1,15,STAINED_CLAY:15,15,STAINED_CLAY:7,100)
RandomBlock(-4,13,3,minecraft:iron_bars:0,5,quark:iron_plate:1,15,STAINED_CLAY:15,15,STAINED_CLAY:7,100)
RandomBlock(-4,13,4,minecraft:iron_bars:0,5,quark:iron_plate:1,15,STAINED_CLAY:15,15,STAINED_CLAY:7,100)
RandomBlock(-4,13,5,minecraft:iron_bars:0,5,quark:iron_plate:1,15,STAINED_CLAY:15,15,STAINED_CLAY:7,100)
RandomBlock(-4,13,6,minecraft:iron_bars:0,5,quark:iron_plate:1,15,STAINED_CLAY:15,15,STAINED_CLAY:7,100)
RandomBlock(-4,13,7,minecraft:iron_bars:0,5,quark:iron_plate:1,15,STAINED_CLAY:15,15,STAINED_CLAY:7,100)
RandomBlock(-4,13,8,minecraft:iron_bars:0,5,quark:iron_plate:1,15,STAINED_CLAY:15,15,STAINED_CLAY:7,100)
RandomBlock(-4,14,1,minecraft:iron_bars:0,5,quark:iron_plate:1,15,STAINED_CLAY:15,15,STAINED_CLAY:7,100)
RandomBlock(-4,14,2,minecraft:iron_bars:0,5,quark:iron_plate:1,15,STAINED_CLAY:15,15,STAINED_CLAY:7,100)
RandomBlock(-4,14,3,minecraft:iron_bars:0,5,quark:iron_plate:1,15,STAINED_CLAY:15,15,STAINED_CLAY:7,100)
RandomBlock(-4,14,4,minecraft:iron_bars:0,5,quark:iron_plate:1,15,STAINED_CLAY:15,15,STAINED_CLAY:7,100)
RandomBlock(-4,14,5,minecraft:iron_bars:0,5,quark:iron_plate:1,15,STAINED_CLAY:15,15,STAINED_CLAY:7,100)
RandomBlock(-4,14,6,minecraft:iron_bars:0,5,quark:iron_plate:1,15,STAINED_CLAY:15,15,STAINED_CLAY:7,100)
RandomBlock(-4,14,7,minecraft:iron_bars:0,5,quark:iron_plate:1,15,STAINED_CLAY:15,15,STAINED_CLAY:7,100)
RandomBlock(-4,14,8,minecraft:iron_bars:0,5,quark:iron_plate:1,15,STAINED_CLAY:15,15,STAINED_CLAY:7,100)
RandomBlock(-4,15,1,minecraft:iron_bars:0,5,quark:iron_plate:1,15,STAINED_CLAY:15,15,STAINED_CLAY:7,100)
RandomBlock(-4,15,2,minecraft:iron_bars:0,5,quark:iron_plate:1,15,STAINED_CLAY:15,15,STAINED_CLAY:7,100)
RandomBlock(-4,15,3,minecraft:iron_bars:0,5,quark:iron_plate:1,15,STAINED_CLAY:15,15,STAINED_CLAY:7,100)
RandomBlock(-4,15,4,minecraft:iron_bars:0,5,quark:iron_plate:1,15,STAINED_CLAY:15,15,STAINED_CLAY:7,100)
RandomBlock(-4,15,5,minecraft:iron_bars:0,5,quark:iron_plate:1,15,STAINED_CLAY:15,15,STAINED_CLAY:7,100)
RandomBlock(-4,15,6,minecraft:iron_bars:0,5,quark:iron_plate:1,15,STAINED_CLAY:15,15,STAINED_CLAY:7,100)
RandomBlock(-4,15,7,minecraft:iron_bars:0,5,quark:iron_plate:1,15,STAINED_CLAY:15,15,STAINED_CLAY:7,100)
RandomBlock(-4,15,8,minecraft:iron_bars:0,5,quark:iron_plate:1,15,STAINED_CLAY:15,15,STAINED_CLAY:7,100)
RandomBlock(-4,16,1,minecraft:iron_bars:0,5,quark:iron_plate:1,15,STAINED_CLAY:15,15,STAINED_CLAY:7,100)
RandomBlock(-4,16,2,minecraft:iron_bars:0,5,quark:iron_plate:1,15,STAINED_CLAY:15,15,STAINED_CLAY:7,100)
RandomBlock(-4,16,3,minecraft:iron_bars:0,5,quark:iron_plate:1,15,STAINED_CLAY:15,15,STAINED_CLAY:7,100)
RandomBlock(-4,16,4,minecraft:iron_bars:0,5,quark:iron_plate:1,15,STAINED_CLAY:15,15,STAINED_CLAY:7,100)
RandomBlock(-4,16,5,minecraft:iron_bars:0,5,quark:iron_plate:1,15,STAINED_CLAY:15,15,STAINED_CLAY:7,100)
RandomBlock(-4,16,6,minecraft:iron_bars:0,5,quark:iron_plate:1,15,STAINED_CLAY:15,15,STAINED_CLAY:7,100)
RandomBlock(-4,16,7,minecraft:iron_bars:0,5,quark:iron_plate:1,15,STAINED_CLAY:15,15,STAINED_CLAY:7,100)
RandomBlock(-4,16,8,minecraft:iron_bars:0,5,quark:iron_plate:1,15,STAINED_CLAY:15,15,STAINED_CLAY:7,100)
RandomBlock(-4,17,1,minecraft:iron_bars:0,5,quark:iron_plate:1,15,STAINED_CLAY:15,15,STAINED_CLAY:7,100)
RandomBlock(-4,17,2,minecraft:iron_bars:0,5,quark:iron_plate:1,15,STAINED_CLAY:15,15,STAINED_CLAY:7,100)
RandomBlock(-4,17,3,minecraft:iron_bars:0,5,quark:iron_plate:1,15,STAINED_CLAY:15,15,STAINED_CLAY:7,100)
RandomBlock(-4,17,4,minecraft:iron_bars:0,5,quark:iron_plate:1,15,STAINED_CLAY:15,15,STAINED_CLAY:7,100)
RandomBlock(-4,17,5,minecraft:iron_bars:0,5,quark:iron_plate:1,15,STAINED_CLAY:15,15,STAINED_CLAY:7,100)
