
#######################################################################
# +-----------------------------------------------------------------+ #
# |                            BO4 object                           | #
# +-----------------------------------------------------------------+ #
#######################################################################

Author: NLBlackEagle

Description: No description given

SettingsMode: WriteDisable


#######################################################################
# +-----------------------------------------------------------------+ #
# |                          Main settings                          | #
# +-----------------------------------------------------------------+ #
#######################################################################

Frequency: 0

SpawnHeight: highestBlock

UseCenterForHighestBlock: true

##############################
# Height Limits for the BO4. #
##############################

MinHeight: 0

MaxHeight: 255

InheritBO3: 

InheritBO3Rotation: NORTH

OverrideChildSettings: true

OverrideParentHeight: false

CanOverride: true

BranchFrequency: 0

BranchFrequencyGroup: 

MustBeBelowOther: false

MustBeInside: 

CannotBeInside: 

ReplacesBO3: L4-M-CrossC0R0, L4-M-CrossC0R1, L4-M-CrossC0R2, L4-M-CrossC0R3, L4-M-CrossC1R0, L4-M-CrossC1R1, L4-M-CrossC1R2, L4-M-CrossC1R3, L4-M-CrossC2R0, L4-M-CrossC2R1, L4-M-CrossC2R2, L4-M-CrossC2R3, L4-M-CrossC3R0, L4-M-CrossC3R1, L4-M-CrossC3R2, L4-M-CrossC3R3, L4-M-Straigth-START_01-C0R0, L4-M-Straigth-START_01-C0R1, L4-M-Straigth-START_01-C1R0, L4-M-Straigth-START_01-C1R1, L4-M-Straigth-START_01-C2R0, L4-M-Straigth-START_01-C2R1, L4-M-Straigth-START_01-C3R0, L4-M-Straigth-START_01-C3R1, L4-M-Straigth-3CC0R0, L4-M-Straigth-3CC0R1, L4-M-Straigth-3CC0R2, L4-M-Straigth-3CC1R0, L4-M-Straigth-3CC1R1, L4-M-Straigth-3CC1R2, L4-M-Straigth-3CC2R0, L4-M-Straigth-3CC2R1, L4-M-Straigth-3CC2R2, L4-M-Straigth-3CC3R0, L4-M-Straigth-3CC3R1, L4-M-Straigth-3CC3R2, L4-M-Cross, skyscraper_2x2_01, skyscraper_2x2_02, skyscraper_2x2_03, skyscraper_2x2_04, skyscraper_2x2_05, skyscraper_3x3_01, skyscraper_3x3_02, skyscraper_3x3_03, L3-M-Straigth-2CC0R0, L3-M-Straigth-2CC0R1, L3-M-Straigth-2CC1R0, L3-M-Straigth-2CC1R1, L3-M-Straigth-2CC2R0, L3-M-Straigth-2CC2R1, L3-M-Straigth-2CC3R0, L3-M-Straigth-2CC3R1, L3-M-Straigth-3CC0R0, L3-M-Straigth-3CC0R1, L3-M-Straigth-3CC0R2, L3-M-Straigth-3CC1R0, L3-M-Straigth-3CC1R1, L3-M-Straigth-3CC1R2, L3-M-Straigth-3CC2R0, L3-M-Straigth-3CC2R1, L3-M-Straigth-3CC2R2, L3-M-Straigth-3CC3R0, L3-M-Straigth-3CC3R1, L3-M-Straigth-3CC3R2L4-M-CrossC0R0, L4-M-CrossC0R1, L4-M-CrossC0R2, L4-M-CrossC0R3, L4-M-CrossC1R0, L4-M-CrossC1R1, L4-M-CrossC1R2, L4-M-CrossC1R3, L4-M-CrossC2R0, L4-M-CrossC2R1, L4-M-CrossC2R2, L4-M-CrossC2R3, L4-M-CrossC3R0, L4-M-CrossC3R1, L4-M-CrossC3R2, L4-M-CrossC3R3, L4-M-Straigth-START_01-C0R0, L4-M-Straigth-START_01-C0R1, L4-M-Straigth-START_01-C1R0, L4-M-Straigth-START_01-C1R1, L4-M-Straigth-START_01-C2R0, L4-M-Straigth-START_01-C2R1, L4-M-Straigth-START_01-C3R0, L4-M-Straigth-START_01-C3R1, L4-M-Straigth-3CC0R0, L4-M-Straigth-3CC0R1, L4-M-Straigth-3CC0R2, L4-M-Straigth-3CC1R0, L4-M-Straigth-3CC1R1, L4-M-Straigth-3CC1R2, L4-M-Straigth-3CC2R0, L4-M-Straigth-3CC2R1, L4-M-Straigth-3CC2R2, L4-M-Straigth-3CC3R0, L4-M-Straigth-3CC3R1, L4-M-Straigth-3CC3R2, L4-M-Cross, skyscraper_2x2_01, skyscraper_2x2_02, skyscraper_2x2_03, skyscraper_2x2_04, skyscraper_2x2_05, skyscraper_3x3_01, skyscraper_3x3_02, skyscraper_3x3_03

MustBeInsideWorldBorders: true
CanSpawnOnWater: true

SpawnOnWaterOnly: false

SpawnUnderWater: false

SpawnAtWaterLevel: false

HeightOffset: 0

RemoveAir: false

ReplaceAbove: 

ReplaceBelow: 

ReplaceWithBiomeBlocks: true

ReplaceWithSurfaceBlock: GRASS

ReplaceWithGroundBlock: DIRT

ReplaceWithStoneBlock: STONE

SmoothRadius: 0

SmoothHeightOffset: 0

SmoothStartTop: false

SmoothStartWood: false

SmoothingSurfaceBlock: 

SmoothingGroundBlock: 

BO3Group: 

IsSpawnPoint: false

DoReplaceBlocks: true


#######################################################################
# +-----------------------------------------------------------------+ #
# |                              Blocks                             | #
# +-----------------------------------------------------------------+ #
#######################################################################

RandomBlock(-8,0,-7,CONCRETE:7,60,quark:iron_plate:1,20,STAINED_CLAY:12,15,STAINED_CLAY:15,5,AIR,7,IRON_BARS,12,CONCRETE:7,100)
RandomBlock(-8,0,-6,CONCRETE:7,60,quark:iron_plate:1,20,STAINED_CLAY:12,15,STAINED_CLAY:15,5,AIR,7,IRON_BARS,12,CONCRETE:7,100)
RandomBlock(-8,0,-5,CONCRETE:7,60,quark:iron_plate:1,20,STAINED_CLAY:12,15,STAINED_CLAY:15,5,AIR,7,IRON_BARS,12,CONCRETE:7,100)
RandomBlock(-8,0,-4,CONCRETE:7,60,quark:iron_plate:1,20,STAINED_CLAY:12,15,STAINED_CLAY:15,5,AIR,7,IRON_BARS,12,CONCRETE:7,100)
RandomBlock(-8,0,-3,CONCRETE:7,60,quark:iron_plate:1,20,STAINED_CLAY:12,15,STAINED_CLAY:15,5,AIR,7,IRON_BARS,12,CONCRETE:7,100)
RandomBlock(-8,0,-2,CONCRETE:7,60,quark:iron_plate:1,20,STAINED_CLAY:12,15,STAINED_CLAY:15,5,AIR,7,IRON_BARS,12,CONCRETE:7,100)
RandomBlock(-8,0,-1,CONCRETE:7,60,quark:iron_plate:1,20,STAINED_CLAY:12,15,STAINED_CLAY:15,5,AIR,7,IRON_BARS,12,CONCRETE:7,100)
RandomBlock(-8,0,0,CONCRETE:7,60,quark:iron_plate:1,20,STAINED_CLAY:12,15,STAINED_CLAY:15,5,AIR,7,IRON_BARS,12,CONCRETE:7,100)
RandomBlock(-8,0,1,CONCRETE:7,60,quark:iron_plate:1,20,STAINED_CLAY:12,15,STAINED_CLAY:15,5,AIR,7,IRON_BARS,12,CONCRETE:7,100)
RandomBlock(-8,0,2,CONCRETE:7,60,quark:iron_plate:1,20,STAINED_CLAY:12,15,STAINED_CLAY:15,5,AIR,7,IRON_BARS,12,CONCRETE:7,100)
RandomBlock(-8,0,3,CONCRETE:7,60,quark:iron_plate:1,20,STAINED_CLAY:12,15,STAINED_CLAY:15,5,AIR,7,IRON_BARS,12,CONCRETE:7,100)
RandomBlock(-8,0,4,CONCRETE:7,60,quark:iron_plate:1,20,STAINED_CLAY:12,15,STAINED_CLAY:15,5,AIR,7,IRON_BARS,12,CONCRETE:7,100)
RandomBlock(-8,0,5,CONCRETE:7,60,quark:iron_plate:1,20,STAINED_CLAY:12,15,STAINED_CLAY:15,5,AIR,7,IRON_BARS,12,CONCRETE:7,100)
RandomBlock(-8,0,6,CONCRETE:7,60,quark:iron_plate:1,20,STAINED_CLAY:12,15,STAINED_CLAY:15,5,AIR,7,IRON_BARS,12,CONCRETE:7,100)
RandomBlock(-8,0,7,CONCRETE:7,60,quark:iron_plate:1,20,STAINED_CLAY:12,15,STAINED_CLAY:15,5,AIR,7,IRON_BARS,12,CONCRETE:7,100)
RandomBlock(-8,0,8,CONCRETE:7,60,quark:iron_plate:1,20,STAINED_CLAY:12,15,STAINED_CLAY:15,5,AIR,7,IRON_BARS,12,CONCRETE:7,100)
RandomBlock(-8,1,-7,CONCRETE:7,60,quark:iron_plate:1,20,STAINED_CLAY:12,15,STAINED_CLAY:15,5,AIR,7,IRON_BARS,12,CONCRETE:7,100)
RandomBlock(-8,1,-6,CONCRETE:7,60,quark:iron_plate:1,20,STAINED_CLAY:12,15,STAINED_CLAY:15,5,AIR,7,IRON_BARS,12,CONCRETE:7,100)
RandomBlock(-8,1,-5,CONCRETE:7,60,quark:iron_plate:1,20,STAINED_CLAY:12,15,STAINED_CLAY:15,5,AIR,7,IRON_BARS,12,CONCRETE:7,100)
RandomBlock(-8,1,-4,CONCRETE:7,60,quark:iron_plate:1,20,STAINED_CLAY:12,15,STAINED_CLAY:15,5,AIR,7,IRON_BARS,12,CONCRETE:7,100)
Block(-8,1,-3,STATIONARY_WATER:0)
Block(-8,1,-2,STATIONARY_WATER:0)
RandomBlock(-8,1,-1,CONCRETE:7,60,quark:iron_plate:1,20,STAINED_CLAY:12,15,STAINED_CLAY:15,5,AIR,7,IRON_BARS,12,CONCRETE:7,100)
RandomBlock(-8,1,0,CONCRETE:7,60,quark:iron_plate:1,20,STAINED_CLAY:12,15,STAINED_CLAY:15,5,AIR,7,IRON_BARS,12,CONCRETE:7,100)
RandomBlock(-8,1,1,CONCRETE:7,60,quark:iron_plate:1,20,STAINED_CLAY:12,15,STAINED_CLAY:15,5,AIR,7,IRON_BARS,12,CONCRETE:7,100)
RandomBlock(-8,1,2,CONCRETE:7,60,quark:iron_plate:1,20,STAINED_CLAY:12,15,STAINED_CLAY:15,5,AIR,7,IRON_BARS,12,CONCRETE:7,100)
RandomBlock(-8,1,3,CONCRETE:7,60,quark:iron_plate:1,20,STAINED_CLAY:12,15,STAINED_CLAY:15,5,AIR,7,IRON_BARS,12,CONCRETE:7,100)
RandomBlock(-8,1,4,CONCRETE:7,60,quark:iron_plate:1,20,STAINED_CLAY:12,15,STAINED_CLAY:15,5,AIR,7,IRON_BARS,12,CONCRETE:7,100)
RandomBlock(-8,1,5,CONCRETE:7,60,quark:iron_plate:1,20,STAINED_CLAY:12,15,STAINED_CLAY:15,5,AIR,7,IRON_BARS,12,CONCRETE:7,100)
RandomBlock(-8,1,6,CONCRETE:7,60,quark:iron_plate:1,20,STAINED_CLAY:12,15,STAINED_CLAY:15,5,AIR,7,IRON_BARS,12,CONCRETE:7,100)
RandomBlock(-8,1,7,CONCRETE:7,60,quark:iron_plate:1,20,STAINED_CLAY:12,15,STAINED_CLAY:15,5,AIR,7,IRON_BARS,12,CONCRETE:7,100)
RandomBlock(-8,1,8,CONCRETE:7,60,quark:iron_plate:1,20,STAINED_CLAY:12,15,STAINED_CLAY:15,5,AIR,7,IRON_BARS,12,CONCRETE:7,100)
RandomBlock(-8,2,-7,CONCRETE:7,60,quark:iron_plate:1,20,STAINED_CLAY:12,15,STAINED_CLAY:15,5,AIR,7,IRON_BARS,12,CONCRETE:7,100)
RandomBlock(-8,2,-6,CONCRETE:7,60,quark:iron_plate:1,20,STAINED_CLAY:12,15,STAINED_CLAY:15,5,AIR,7,IRON_BARS,12,CONCRETE:7,100)
RandomBlock(-8,2,-5,CONCRETE:7,60,quark:iron_plate:1,20,STAINED_CLAY:12,15,STAINED_CLAY:15,5,AIR,7,IRON_BARS,12,CONCRETE:7,100)
Block(-8,2,-4,SMOOTH_STAIRS:3)
Block(-8,2,-3,AIR:0)
Block(-8,2,-2,AIR:0)
Block(-8,2,-1,SMOOTH_STAIRS:2)
RandomBlock(-8,2,0,CONCRETE:7,60,quark:iron_plate:1,20,STAINED_CLAY:12,15,STAINED_CLAY:15,5,AIR,7,IRON_BARS,12,CONCRETE:7,100)
RandomBlock(-8,2,1,CONCRETE:7,60,quark:iron_plate:1,20,STAINED_CLAY:12,15,STAINED_CLAY:15,5,AIR,7,IRON_BARS,12,CONCRETE:7,100)
RandomBlock(-8,2,2,CONCRETE:7,60,quark:iron_plate:1,20,STAINED_CLAY:12,15,STAINED_CLAY:15,5,AIR,7,IRON_BARS,12,CONCRETE:7,100)
RandomBlock(-8,2,3,CONCRETE:7,60,quark:iron_plate:1,20,STAINED_CLAY:12,15,STAINED_CLAY:15,5,AIR,7,IRON_BARS,12,CONCRETE:7,100)
RandomBlock(-8,2,4,CONCRETE:7,60,quark:iron_plate:1,20,STAINED_CLAY:12,15,STAINED_CLAY:15,5,AIR,7,IRON_BARS,12,CONCRETE:7,100)
RandomBlock(-8,2,5,CONCRETE:7,60,quark:iron_plate:1,20,STAINED_CLAY:12,15,STAINED_CLAY:15,5,AIR,7,IRON_BARS,12,CONCRETE:7,100)
RandomBlock(-8,2,6,CONCRETE:7,60,quark:iron_plate:1,20,STAINED_CLAY:12,15,STAINED_CLAY:15,5,AIR,7,IRON_BARS,12,CONCRETE:7,100)
RandomBlock(-8,2,7,CONCRETE:7,60,quark:iron_plate:1,20,STAINED_CLAY:12,15,STAINED_CLAY:15,5,AIR,7,IRON_BARS,12,CONCRETE:7,100)
RandomBlock(-8,2,8,CONCRETE:7,60,quark:iron_plate:1,20,STAINED_CLAY:12,15,STAINED_CLAY:15,5,AIR,7,IRON_BARS,12,CONCRETE:7,100)
Block(-8,3,-7,AIR:0)
Block(-8,3,-6,AIR:0)
Block(-8,3,-5,AIR:0)
Block(-8,3,-4,AIR:0)
Block(-8,3,-3,AIR:0)
Block(-8,3,-2,AIR:0)
Block(-8,3,-1,AIR:0)
Block(-8,3,0,AIR:0)
RandomBlock(-8,3,1,CONCRETE:7,60,quark:iron_plate:1,20,STAINED_CLAY:12,15,STAINED_CLAY:15,5,AIR,7,IRON_BARS,12,CONCRETE:7,100)
RandomBlock(-8,3,2,CONCRETE:7,60,quark:iron_plate:1,20,STAINED_CLAY:12,15,STAINED_CLAY:15,5,AIR,7,IRON_BARS,12,CONCRETE:7,100)
Block(-8,3,3,AIR:0)
Block(-8,3,4,LADDER:2)
RandomBlock(-8,3,5,CONCRETE:7,60,quark:iron_plate:1,20,STAINED_CLAY:12,15,STAINED_CLAY:15,5,AIR,7,IRON_BARS,12,CONCRETE:7,100)
RandomBlock(-8,3,6,CONCRETE:7,60,quark:iron_plate:1,20,STAINED_CLAY:12,15,STAINED_CLAY:15,5,AIR,7,IRON_BARS,12,CONCRETE:7,100)
Block(-8,3,7,AIR:0)
RandomBlock(-8,3,8,CONCRETE:7,60,quark:iron_plate:1,20,STAINED_CLAY:12,15,STAINED_CLAY:15,5,AIR,7,IRON_BARS,12,CONCRETE:7,100)
Block(-8,4,-7,AIR:0)
Block(-8,4,-6,AIR:0)
Block(-8,4,-5,AIR:0)
Block(-8,4,-4,AIR:0)
Block(-8,4,-3,AIR:0)
Block(-8,4,-2,AIR:0)
Block(-8,4,-1,AIR:0)
Block(-8,4,0,AIR:0)
RandomBlock(-8,4,1,CONCRETE:7,60,quark:iron_plate:1,20,STAINED_CLAY:12,15,STAINED_CLAY:15,5,AIR,7,IRON_BARS,12,CONCRETE:7,100)
RandomBlock(-8,4,2,CONCRETE:7,60,quark:iron_plate:1,20,STAINED_CLAY:12,15,STAINED_CLAY:15,5,AIR,7,IRON_BARS,12,CONCRETE:7,100)
Block(-8,4,3,AIR:0)
Block(-8,4,4,LADDER:2)
RandomBlock(-8,4,5,CONCRETE:7,60,quark:iron_plate:1,20,STAINED_CLAY:12,15,STAINED_CLAY:15,5,AIR,7,IRON_BARS,12,CONCRETE:7,100)
RandomBlock(-8,4,6,CONCRETE:7,60,quark:iron_plate:1,20,STAINED_CLAY:12,15,STAINED_CLAY:15,5,AIR,7,IRON_BARS,12,CONCRETE:7,100)
Block(-8,4,7,AIR:0)
RandomBlock(-8,4,8,CONCRETE:7,60,quark:iron_plate:1,20,STAINED_CLAY:12,15,STAINED_CLAY:15,5,AIR,7,IRON_BARS,12,CONCRETE:7,100)
Block(-8,5,-7,AIR:0)
Block(-8,5,-6,CONCRETE:4)
Block(-8,5,-5,CONCRETE:12)
Block(-8,5,-4,AIR:0)
Block(-8,5,-3,AIR:0)
Block(-8,5,-2,AIR:0)
Block(-8,5,-1,AIR:0)
Block(-8,5,0,AIR:0)
RandomBlock(-8,5,1,CONCRETE:7,60,quark:iron_plate:1,20,STAINED_CLAY:12,15,STAINED_CLAY:15,5,AIR,7,IRON_BARS,12,CONCRETE:7,100)
RandomBlock(-8,5,2,CONCRETE:7,60,quark:iron_plate:1,20,STAINED_CLAY:12,15,STAINED_CLAY:15,5,AIR,7,IRON_BARS,12,CONCRETE:7,100)
Block(-8,5,3,AIR:0)
Block(-8,5,4,LADDER:2)
RandomBlock(-8,5,5,CONCRETE:7,60,quark:iron_plate:1,20,STAINED_CLAY:12,15,STAINED_CLAY:15,5,AIR,7,IRON_BARS,12,CONCRETE:7,100)
RandomBlock(-8,5,6,CONCRETE:7,60,quark:iron_plate:1,20,STAINED_CLAY:12,15,STAINED_CLAY:15,5,AIR,7,IRON_BARS,12,CONCRETE:7,100)
Block(-8,5,7,AIR:0)
RandomBlock(-8,5,8,CONCRETE:7,60,quark:iron_plate:1,20,STAINED_CLAY:12,15,STAINED_CLAY:15,5,AIR,7,IRON_BARS,12,CONCRETE:7,100)
Block(-8,6,-7,AIR:0)
Block(-8,6,-6,AIR:0)
Block(-8,6,-5,AIR:0)
Block(-8,6,-4,AIR:0)
Block(-8,6,-3,AIR:0)
Block(-8,6,-2,AIR:0)
Block(-8,6,-1,AIR:0)
Block(-8,6,0,AIR:0)
RandomBlock(-8,6,1,CONCRETE:7,60,quark:iron_plate:1,20,STAINED_CLAY:12,15,STAINED_CLAY:15,5,AIR,7,IRON_BARS,12,CONCRETE:7,100)
RandomBlock(-8,6,2,CONCRETE:7,60,quark:iron_plate:1,20,STAINED_CLAY:12,15,STAINED_CLAY:15,5,AIR,7,IRON_BARS,12,CONCRETE:7,100)
Block(-8,6,3,AIR:0)
Block(-8,6,4,LADDER:2)
RandomBlock(-8,6,5,CONCRETE:7,60,quark:iron_plate:1,20,STAINED_CLAY:12,15,STAINED_CLAY:15,5,AIR,7,IRON_BARS,12,CONCRETE:7,100)
RandomBlock(-8,6,6,CONCRETE:7,60,quark:iron_plate:1,20,STAINED_CLAY:12,15,STAINED_CLAY:15,5,AIR,7,IRON_BARS,12,CONCRETE:7,100)
Block(-8,6,7,AIR:0)
RandomBlock(-8,6,8,CONCRETE:7,60,quark:iron_plate:1,20,STAINED_CLAY:12,15,STAINED_CLAY:15,5,AIR,7,IRON_BARS,12,CONCRETE:7,100)
RandomBlock(-8,7,-7,CONCRETE:7,60,quark:iron_plate:1,20,STAINED_CLAY:12,15,STAINED_CLAY:15,5,AIR,7,IRON_BARS,12,CONCRETE:7,100)
RandomBlock(-8,7,-6,CONCRETE:7,60,quark:iron_plate:1,20,STAINED_CLAY:12,15,STAINED_CLAY:15,5,AIR,7,IRON_BARS,12,CONCRETE:7,100)
RandomBlock(-8,7,-5,CONCRETE:7,60,quark:iron_plate:1,20,STAINED_CLAY:12,15,STAINED_CLAY:15,5,AIR,7,IRON_BARS,12,CONCRETE:7,100)
RandomBlock(-8,7,-4,CONCRETE:7,60,quark:iron_plate:1,20,STAINED_CLAY:12,15,STAINED_CLAY:15,5,AIR,7,IRON_BARS,12,CONCRETE:7,100)
RandomBlock(-8,7,-3,CONCRETE:7,60,quark:iron_plate:1,20,STAINED_CLAY:12,15,STAINED_CLAY:15,5,AIR,7,IRON_BARS,12,CONCRETE:7,100)
RandomBlock(-8,7,-2,CONCRETE:7,60,quark:iron_plate:1,20,STAINED_CLAY:12,15,STAINED_CLAY:15,5,AIR,7,IRON_BARS,12,CONCRETE:7,100)
RandomBlock(-8,7,-1,CONCRETE:7,60,quark:iron_plate:1,20,STAINED_CLAY:12,15,STAINED_CLAY:15,5,AIR,7,IRON_BARS,12,CONCRETE:7,100)
RandomBlock(-8,7,0,CONCRETE:7,60,quark:iron_plate:1,20,STAINED_CLAY:12,15,STAINED_CLAY:15,5,AIR,7,IRON_BARS,12,CONCRETE:7,100)
RandomBlock(-8,7,1,CONCRETE:7,60,quark:iron_plate:1,20,STAINED_CLAY:12,15,STAINED_CLAY:15,5,AIR,7,IRON_BARS,12,CONCRETE:7,100)
RandomBlock(-8,7,2,CONCRETE:7,60,quark:iron_plate:1,20,STAINED_CLAY:12,15,STAINED_CLAY:15,5,AIR,7,IRON_BARS,12,CONCRETE:7,100)
RandomBlock(-8,7,3,CONCRETE:7,60,quark:iron_plate:1,20,STAINED_CLAY:12,15,STAINED_CLAY:15,5,AIR,7,IRON_BARS,12,CONCRETE:7,100)
RandomBlock(-8,7,4,CONCRETE:7,60,quark:iron_plate:1,20,STAINED_CLAY:12,15,STAINED_CLAY:15,5,AIR,7,IRON_BARS,12,CONCRETE:7,100)
RandomBlock(-8,7,5,CONCRETE:7,60,quark:iron_plate:1,20,STAINED_CLAY:12,15,STAINED_CLAY:15,5,AIR,7,IRON_BARS,12,CONCRETE:7,100)
RandomBlock(-8,7,6,CONCRETE:7,60,quark:iron_plate:1,20,STAINED_CLAY:12,15,STAINED_CLAY:15,5,AIR,7,IRON_BARS,12,CONCRETE:7,100)
RandomBlock(-8,7,7,CONCRETE:7,60,quark:iron_plate:1,20,STAINED_CLAY:12,15,STAINED_CLAY:15,5,AIR,7,IRON_BARS,12,CONCRETE:7,100)
RandomBlock(-8,7,8,CONCRETE:7,60,quark:iron_plate:1,20,STAINED_CLAY:12,15,STAINED_CLAY:15,5,AIR,7,IRON_BARS,12,CONCRETE:7,100)
RandomBlock(-8,8,-7,CONCRETE:7,60,quark:iron_plate:1,20,STAINED_CLAY:12,15,STAINED_CLAY:15,5,AIR,7,IRON_BARS,12,CONCRETE:7,100)
RandomBlock(-8,8,-6,CONCRETE:7,60,quark:iron_plate:1,20,STAINED_CLAY:12,15,STAINED_CLAY:15,5,AIR,7,IRON_BARS,12,CONCRETE:7,100)
RandomBlock(-8,8,-5,CONCRETE:7,60,quark:iron_plate:1,20,STAINED_CLAY:12,15,STAINED_CLAY:15,5,AIR,7,IRON_BARS,12,CONCRETE:7,100)
RandomBlock(-8,8,-4,CONCRETE:7,60,quark:iron_plate:1,20,STAINED_CLAY:12,15,STAINED_CLAY:15,5,AIR,7,IRON_BARS,12,CONCRETE:7,100)
RandomBlock(-8,8,-3,CONCRETE:7,60,quark:iron_plate:1,20,STAINED_CLAY:12,15,STAINED_CLAY:15,5,AIR,7,IRON_BARS,12,CONCRETE:7,100)
RandomBlock(-8,8,-2,CONCRETE:7,60,quark:iron_plate:1,20,STAINED_CLAY:12,15,STAINED_CLAY:15,5,AIR,7,IRON_BARS,12,CONCRETE:7,100)
RandomBlock(-8,8,-1,CONCRETE:7,60,quark:iron_plate:1,20,STAINED_CLAY:12,15,STAINED_CLAY:15,5,AIR,7,IRON_BARS,12,CONCRETE:7,100)
RandomBlock(-8,8,0,CONCRETE:7,60,quark:iron_plate:1,20,STAINED_CLAY:12,15,STAINED_CLAY:15,5,AIR,7,IRON_BARS,12,CONCRETE:7,100)
RandomBlock(-8,8,1,CONCRETE:7,60,quark:iron_plate:1,20,STAINED_CLAY:12,15,STAINED_CLAY:15,5,AIR,7,IRON_BARS,12,CONCRETE:7,100)
RandomBlock(-8,8,2,CONCRETE:7,60,quark:iron_plate:1,20,STAINED_CLAY:12,15,STAINED_CLAY:15,5,AIR,7,IRON_BARS,12,CONCRETE:7,100)
RandomBlock(-8,8,3,CONCRETE:7,60,quark:iron_plate:1,20,STAINED_CLAY:12,15,STAINED_CLAY:15,5,AIR,7,IRON_BARS,12,CONCRETE:7,100)
RandomBlock(-8,8,4,CONCRETE:7,60,quark:iron_plate:1,20,STAINED_CLAY:12,15,STAINED_CLAY:15,5,AIR,7,IRON_BARS,12,CONCRETE:7,100)
RandomBlock(-8,8,5,CONCRETE:7,60,quark:iron_plate:1,20,STAINED_CLAY:12,15,STAINED_CLAY:15,5,AIR,7,IRON_BARS,12,CONCRETE:7,100)
RandomBlock(-8,8,6,CONCRETE:7,60,quark:iron_plate:1,20,STAINED_CLAY:12,15,STAINED_CLAY:15,5,AIR,7,IRON_BARS,12,CONCRETE:7,100)
RandomBlock(-8,8,7,CONCRETE:7,60,quark:iron_plate:1,20,STAINED_CLAY:12,15,STAINED_CLAY:15,5,AIR,7,IRON_BARS,12,CONCRETE:7,100)
RandomBlock(-8,8,8,CONCRETE:7,60,quark:iron_plate:1,20,STAINED_CLAY:12,15,STAINED_CLAY:15,5,AIR,7,IRON_BARS,12,CONCRETE:7,100)
RandomBlock(-8,9,-7,CONCRETE:7,60,quark:iron_plate:1,20,STAINED_CLAY:12,15,STAINED_CLAY:15,5,AIR,7,IRON_BARS,12,CONCRETE:7,100)
RandomBlock(-8,9,-6,CONCRETE:7,60,quark:iron_plate:1,20,STAINED_CLAY:12,15,STAINED_CLAY:15,5,AIR,7,IRON_BARS,12,CONCRETE:7,100)
RandomBlock(-8,9,-5,CONCRETE:7,60,quark:iron_plate:1,20,STAINED_CLAY:12,15,STAINED_CLAY:15,5,AIR,7,IRON_BARS,12,CONCRETE:7,100)
RandomBlock(-8,9,-4,CONCRETE:7,60,quark:iron_plate:1,20,STAINED_CLAY:12,15,STAINED_CLAY:15,5,AIR,7,IRON_BARS,12,CONCRETE:7,100)
RandomBlock(-8,9,-3,CONCRETE:7,60,quark:iron_plate:1,20,STAINED_CLAY:12,15,STAINED_CLAY:15,5,AIR,7,IRON_BARS,12,CONCRETE:7,100)
RandomBlock(-8,9,-2,CONCRETE:7,60,quark:iron_plate:1,20,STAINED_CLAY:12,15,STAINED_CLAY:15,5,AIR,7,IRON_BARS,12,CONCRETE:7,100)
RandomBlock(-8,9,-1,CONCRETE:7,60,quark:iron_plate:1,20,STAINED_CLAY:12,15,STAINED_CLAY:15,5,AIR,7,IRON_BARS,12,CONCRETE:7,100)
RandomBlock(-8,9,0,CONCRETE:7,60,quark:iron_plate:1,20,STAINED_CLAY:12,15,STAINED_CLAY:15,5,AIR,7,IRON_BARS,12,CONCRETE:7,100)
RandomBlock(-8,9,1,CONCRETE:7,60,quark:iron_plate:1,20,STAINED_CLAY:12,15,STAINED_CLAY:15,5,AIR,7,IRON_BARS,12,CONCRETE:7,100)
RandomBlock(-8,9,2,CONCRETE:7,60,quark:iron_plate:1,20,STAINED_CLAY:12,15,STAINED_CLAY:15,5,AIR,7,IRON_BARS,12,CONCRETE:7,100)
RandomBlock(-8,9,3,AIR,90,IRON_TRAPDOOR:9,100)
RandomBlock(-8,9,4,AIR,90,IRON_TRAPDOOR:11,100)
RandomBlock(-8,9,5,AIR,90,IRON_TRAPDOOR:11,100)
RandomBlock(-8,9,6,CONCRETE:7,60,quark:iron_plate:1,20,STAINED_CLAY:12,15,STAINED_CLAY:15,5,AIR,7,IRON_BARS,12,CONCRETE:7,100)
RandomBlock(-8,9,7,CONCRETE:7,60,quark:iron_plate:1,20,STAINED_CLAY:12,15,STAINED_CLAY:15,5,AIR,7,IRON_BARS,12,CONCRETE:7,100)
RandomBlock(-8,9,8,CONCRETE:7,60,quark:iron_plate:1,20,STAINED_CLAY:12,15,STAINED_CLAY:15,5,AIR,7,IRON_BARS,12,CONCRETE:7,100)
Block(-8,10,-7,CONCRETE:8)
Block(-8,10,-6,CONCRETE:8)
Block(-8,10,-5,CONCRETE:8)
Block(-8,10,-4,CONCRETE:8)
Block(-8,10,-3,CONCRETE:8)
Block(-8,10,-2,CONCRETE:8)
Block(-8,10,-1,CONCRETE:8)
Block(-8,10,0,CONCRETE:8)
Block(-8,10,1,CONCRETE:8)
Block(-8,10,2,CONCRETE:8)
Block(-8,10,3,AIR:0)
Block(-8,10,4,AIR:0)
Block(-8,10,5,AIR:0)
Block(-8,10,6,CONCRETE:8)
Block(-8,10,7,CONCRETE:8)
Block(-8,10,8,CONCRETE:8)
Block(-8,11,-7,CONCRETE:8)
Block(-8,11,-6,CONCRETE:8)
Block(-8,11,-5,CONCRETE:8)
Block(-8,11,-4,CONCRETE:8)
Block(-8,11,-3,CONCRETE:8)
Block(-8,11,-2,CONCRETE:8)
Block(-8,11,-1,CONCRETE:8)
Block(-8,11,0,CONCRETE:8)
Block(-8,11,1,CONCRETE:8)
Block(-8,11,2,CONCRETE:8)
Block(-8,11,3,AIR:0)
Block(-8,11,4,AIR:0)
Block(-8,11,5,AIR:0)
Block(-8,11,6,CONCRETE:8)
Block(-8,11,7,CONCRETE:8)
Block(-8,11,8,CONCRETE:8)
Block(-8,12,-7,CONCRETE:8)
Block(-8,12,-6,CONCRETE:8)
Block(-8,12,-5,CONCRETE:8)
Block(-8,12,-4,CONCRETE:8)
Block(-8,12,-3,CONCRETE:8)
Block(-8,12,-2,CONCRETE:8)
Block(-8,12,-1,CONCRETE:8)
Block(-8,12,0,CONCRETE:8)
Block(-8,12,1,CONCRETE:8)
Block(-8,12,2,CONCRETE:8)
Block(-8,12,3,AIR:0)
Block(-8,12,4,AIR:0)
Block(-8,12,5,AIR:0)
Block(-8,12,6,CONCRETE:8)
Block(-8,12,7,CONCRETE:8)
Block(-8,12,8,CONCRETE:8)
Block(-8,13,-7,CONCRETE:8)
Block(-8,13,-6,CONCRETE:8)
Block(-8,13,-5,CONCRETE:8)
Block(-8,13,-4,CONCRETE:8)
Block(-8,13,-3,CONCRETE:8)
Block(-8,13,-2,CONCRETE:8)
Block(-8,13,-1,CONCRETE:8)
Block(-8,13,0,CONCRETE:8)
Block(-8,13,1,CONCRETE:8)
Block(-8,13,2,CONCRETE:8)
Block(-8,13,3,CONCRETE:8)
Block(-8,13,4,CONCRETE:8)
Block(-8,13,5,CONCRETE:8)
Block(-8,13,6,CONCRETE:8)
Block(-8,13,7,CONCRETE:8)
Block(-8,13,8,CONCRETE:8)
Block(-8,14,-7,CONCRETE:8)
Block(-8,14,-6,CONCRETE:8)
Block(-8,14,-5,CONCRETE:8)
Block(-8,14,-4,CONCRETE:8)
Block(-8,14,-3,CONCRETE:8)
Block(-8,14,-2,CONCRETE:8)
Block(-8,14,-1,CONCRETE:8)
Block(-8,14,0,CONCRETE:8)
Block(-8,14,1,CONCRETE:8)
Block(-8,14,2,CONCRETE:8)
Block(-8,14,3,CONCRETE:8)
Block(-8,14,4,CONCRETE:8)
Block(-8,14,5,CONCRETE:8)
Block(-8,14,6,CONCRETE:8)
Block(-8,14,7,CONCRETE:8)
Block(-8,14,8,CONCRETE:8)
RandomBlock(-8,15,-7,CONCRETE:7,60,quark:iron_plate:1,20,STAINED_CLAY:12,15,STAINED_CLAY:15,5,AIR,7,IRON_BARS,12,CONCRETE:7,100)
RandomBlock(-8,15,-6,CONCRETE:7,60,quark:iron_plate:1,20,STAINED_CLAY:12,15,STAINED_CLAY:15,5,AIR,7,IRON_BARS,12,CONCRETE:7,100)
RandomBlock(-8,15,-5,CONCRETE:7,60,quark:iron_plate:1,20,STAINED_CLAY:12,15,STAINED_CLAY:15,5,AIR,7,IRON_BARS,12,CONCRETE:7,100)
RandomBlock(-8,15,-4,CONCRETE:7,60,quark:iron_plate:1,20,STAINED_CLAY:12,15,STAINED_CLAY:15,5,AIR,7,IRON_BARS,12,CONCRETE:7,100)
RandomBlock(-8,15,-3,CONCRETE:7,60,quark:iron_plate:1,20,STAINED_CLAY:12,15,STAINED_CLAY:15,5,AIR,7,IRON_BARS,12,CONCRETE:7,100)
RandomBlock(-8,15,-2,CONCRETE:7,60,quark:iron_plate:1,20,STAINED_CLAY:12,15,STAINED_CLAY:15,5,AIR,7,IRON_BARS,12,CONCRETE:7,100)
RandomBlock(-8,15,-1,CONCRETE:7,60,quark:iron_plate:1,20,STAINED_CLAY:12,15,STAINED_CLAY:15,5,AIR,7,IRON_BARS,12,CONCRETE:7,100)
RandomBlock(-8,15,0,CONCRETE:7,60,quark:iron_plate:1,20,STAINED_CLAY:12,15,STAINED_CLAY:15,5,AIR,7,IRON_BARS,12,CONCRETE:7,100)
RandomBlock(-8,15,1,CONCRETE:7,60,quark:iron_plate:1,20,STAINED_CLAY:12,15,STAINED_CLAY:15,5,AIR,7,IRON_BARS,12,CONCRETE:7,100)
RandomBlock(-8,15,2,CONCRETE:7,60,quark:iron_plate:1,20,STAINED_CLAY:12,15,STAINED_CLAY:15,5,AIR,7,IRON_BARS,12,CONCRETE:7,100)
RandomBlock(-8,15,3,CONCRETE:7,60,quark:iron_plate:1,20,STAINED_CLAY:12,15,STAINED_CLAY:15,5,AIR,7,IRON_BARS,12,CONCRETE:7,100)
RandomBlock(-8,15,4,CONCRETE:7,60,quark:iron_plate:1,20,STAINED_CLAY:12,15,STAINED_CLAY:15,5,AIR,7,IRON_BARS,12,CONCRETE:7,100)
RandomBlock(-8,15,5,CONCRETE:7,60,quark:iron_plate:1,20,STAINED_CLAY:12,15,STAINED_CLAY:15,5,AIR,7,IRON_BARS,12,CONCRETE:7,100)
RandomBlock(-8,15,6,CONCRETE:7,60,quark:iron_plate:1,20,STAINED_CLAY:12,15,STAINED_CLAY:15,5,AIR,7,IRON_BARS,12,CONCRETE:7,100)
RandomBlock(-8,15,7,CONCRETE:7,60,quark:iron_plate:1,20,STAINED_CLAY:12,15,STAINED_CLAY:15,5,AIR,7,IRON_BARS,12,CONCRETE:7,100)
RandomBlock(-8,15,8,CONCRETE:7,60,quark:iron_plate:1,20,STAINED_CLAY:12,15,STAINED_CLAY:15,5,AIR,7,IRON_BARS,12,CONCRETE:7,100)
Block(-8,16,-7,CONCRETE:15)
Block(-8,16,-6,CONCRETE:15)
Block(-8,16,-5,CONCRETE:15)
Block(-8,16,-4,CONCRETE:15)
Block(-8,16,-3,CONCRETE:15)
Block(-8,16,-2,CONCRETE:15)
Block(-8,16,-1,CONCRETE:15)
Block(-8,16,0,CONCRETE:15)
Block(-8,16,1,CONCRETE:15)
Block(-8,16,2,CONCRETE:15)
Block(-8,16,3,CONCRETE:15)
Block(-8,16,4,CONCRETE:15)
Block(-8,16,5,CONCRETE:15)
Block(-8,16,6,CONCRETE:15)
Block(-8,16,7,CONCRETE:15)
Block(-8,16,8,CONCRETE:15)
Block(-8,17,-7,CONCRETE:15)
Block(-8,17,-6,CONCRETE:15)
Block(-8,17,-5,CONCRETE:8)
Block(-8,17,-4,CONCRETE:8)
Block(-8,17,-3,CONCRETE:8)
Block(-8,17,-2,CONCRETE:8)
Block(-8,17,-1,CONCRETE:8)
Block(-8,17,0,CONCRETE:8)
Block(-8,17,1,CONCRETE:8)
Block(-8,17,2,CONCRETE:15)
Block(-8,17,3,CONCRETE:15)
Block(-8,17,4,CONCRETE:15)
Block(-8,17,5,CONCRETE:8)
Block(-8,17,6,CONCRETE:8)
Block(-8,17,7,CONCRETE:8)
Block(-8,17,8,CONCRETE:8)
Block(-8,18,-5,STAINED_GLASS_PANE:15)
Block(-8,18,-4,QUARTZ_STAIRS:0)
Block(-8,18,-3,CONCRETE:15)
Block(-8,18,-1,STAINED_GLASS_PANE:15)
Block(-8,18,6,STAINED_GLASS_PANE:15)
Block(-8,19,-5,STAINED_GLASS_PANE:15)
Block(-8,19,-3,CONCRETE:15)
Block(-8,19,-1,STAINED_GLASS_PANE:15)
Block(-8,19,0,STEP:15)
Block(-8,19,6,STAINED_GLASS_PANE:15)
Block(-8,20,-5,STAINED_GLASS_PANE:15)
Block(-8,20,-3,CONCRETE:15)
Block(-8,20,-2,QUARTZ_STAIRS:1)
Block(-8,20,-1,STAINED_GLASS_PANE:15)
Block(-8,20,0,STEP:15)
Block(-8,20,6,STAINED_GLASS_PANE:15)
Block(-8,21,-6,STEP:15)
Block(-8,21,-5,STAINED_GLASS_PANE:15)
Block(-8,21,-3,CONCRETE:15)
Block(-8,21,-1,STAINED_GLASS_PANE:15)
Block(-8,21,0,STEP:15)
Block(-8,21,6,STAINED_GLASS:15)
Block(-8,22,-6,STEP:15)
Block(-8,22,-5,STAINED_GLASS_PANE:15)
Block(-8,22,-4,QUARTZ_STAIRS:0)
Block(-8,22,-3,CONCRETE:15)
Block(-8,22,-1,STAINED_GLASS_PANE:15)
Block(-8,22,0,STEP:15)
RandomBlock(-8,22,6,CONCRETE:7,60,quark:iron_plate:1,20,STAINED_CLAY:12,15,STAINED_CLAY:15,5,AIR,7,IRON_BARS,12,CONCRETE:7,100)
Block(-8,23,-6,STEP:15)
Block(-8,23,-5,STAINED_GLASS_PANE:15)
Block(-8,23,-3,CONCRETE:15)
Block(-8,23,-1,STAINED_GLASS_PANE:15)
Block(-8,23,0,STEP:15)
RandomBlock(-8,23,6,CONCRETE:7,60,quark:iron_plate:1,20,STAINED_CLAY:12,15,STAINED_CLAY:15,5,AIR,7,IRON_BARS,12,CONCRETE:7,100)
Block(-8,24,-5,STAINED_GLASS_PANE:15)
Block(-8,24,-3,CONCRETE:15)
Block(-8,24,-2,QUARTZ_STAIRS:1)
Block(-8,24,-1,STAINED_GLASS_PANE:15)
Block(-8,24,1,STEP:15)
Block(-8,24,3,STEP:15)
RandomBlock(-8,24,6,CONCRETE:7,60,quark:iron_plate:1,20,STAINED_CLAY:12,15,STAINED_CLAY:15,5,AIR,7,IRON_BARS,12,CONCRETE:7,100)
Block(-8,25,-7,CONCRETE:8)
Block(-8,25,-6,CONCRETE:8)
Block(-8,25,-5,CONCRETE:8)
Block(-8,25,-3,CONCRETE:15)
Block(-8,25,-1,CONCRETE:8)
Block(-8,25,0,CONCRETE:8)
Block(-8,25,1,CONCRETE:8)
Block(-8,25,2,CONCRETE:8)
Block(-8,25,3,CONCRETE:8)
Block(-8,25,4,CONCRETE:8)
Block(-8,25,5,CONCRETE:8)
Block(-8,25,6,CONCRETE:8)
Block(-8,25,7,CONCRETE:8)
Block(-8,25,8,CONCRETE:8)
Block(-8,26,-5,STAINED_GLASS_PANE:15)
Block(-8,26,-4,QUARTZ_STAIRS:0)
Block(-8,26,-3,CONCRETE:15)
Block(-8,26,-1,CONCRETE:0)
RandomBlock(-8,26,1,AIR,90,TRAP_DOOR:7,100)
Block(-8,26,3,STAINED_GLASS:15)
RandomBlock(-8,26,6,CONCRETE:7,60,quark:iron_plate:1,20,STAINED_CLAY:12,15,STAINED_CLAY:15,5,AIR,7,IRON_BARS,12,CONCRETE:7,100)
Block(-8,26,7,QUARTZ_STAIRS:1)
Block(-8,27,-5,STAINED_GLASS_PANE:15)
Block(-8,27,-3,CONCRETE:15)
Block(-8,27,-1,CONCRETE:0)
RandomBlock(-8,27,1,AIR,90,TRAP_DOOR:7,100)
Block(-8,27,3,STAINED_GLASS:15)
RandomBlock(-8,27,6,CONCRETE:7,60,quark:iron_plate:1,20,STAINED_CLAY:12,15,STAINED_CLAY:15,5,AIR,7,IRON_BARS,12,CONCRETE:7,100)
Block(-8,27,7,QUARTZ_STAIRS:5)
Block(-8,28,-3,CONCRETE:15)
Block(-8,28,-2,QUARTZ_STAIRS:1)
Block(-8,28,-1,CONCRETE:0)
Block(-8,28,3,STAINED_GLASS:15)
RandomBlock(-8,28,6,CONCRETE:7,60,quark:iron_plate:1,20,STAINED_CLAY:12,15,STAINED_CLAY:15,5,AIR,7,IRON_BARS,12,CONCRETE:7,100)
Block(-8,28,7,CARPET:15)
Block(-8,29,-7,STEP:15)
Block(-8,29,-6,STEP:15)
Block(-8,29,-5,STEP:15)
Block(-8,29,-3,CONCRETE:15)
Block(-8,29,-1,CONCRETE:8)
Block(-8,29,0,STEP:15)
Block(-8,29,1,STEP:15)
Block(-8,29,2,STEP:15)
Block(-8,29,3,CONCRETE:8)
Block(-8,29,4,STEP:15)
Block(-8,29,5,STEP:15)
Block(-8,29,6,CONCRETE:8)
Block(-8,29,7,CONCRETE:8)
Block(-8,29,8,CONCRETE:8)
Block(-8,30,-5,STAINED_GLASS_PANE:15)
Block(-8,30,-4,QUARTZ_STAIRS:0)
Block(-8,30,-3,CONCRETE:15)
Block(-8,30,-1,CONCRETE:0)
RandomBlock(-8,30,1,AIR,90,TRAP_DOOR:7,100)
Block(-8,30,3,STAINED_GLASS:15)
RandomBlock(-8,30,6,CONCRETE:7,60,quark:iron_plate:1,20,STAINED_CLAY:12,15,STAINED_CLAY:15,5,AIR,7,IRON_BARS,12,CONCRETE:7,100)
Block(-8,30,7,QUARTZ_STAIRS:1)
Block(-8,31,-5,STAINED_GLASS_PANE:15)
Block(-8,31,-3,CONCRETE:15)
Block(-8,31,-1,CONCRETE:0)
RandomBlock(-8,31,1,AIR,90,TRAP_DOOR:7,100)
Block(-8,31,3,STAINED_GLASS:15)
RandomBlock(-8,31,6,CONCRETE:7,60,quark:iron_plate:1,20,STAINED_CLAY:12,15,STAINED_CLAY:15,5,AIR,7,IRON_BARS,12,CONCRETE:7,100)
Block(-8,31,7,QUARTZ_STAIRS:5)
Block(-8,32,-3,CONCRETE:15)
Block(-8,32,-2,QUARTZ_STAIRS:1)
Block(-8,32,-1,CONCRETE:0)
Block(-8,32,3,STAINED_GLASS:15)
RandomBlock(-8,32,6,CONCRETE:7,60,quark:iron_plate:1,20,STAINED_CLAY:12,15,STAINED_CLAY:15,5,AIR,7,IRON_BARS,12,CONCRETE:7,100)
Block(-8,32,7,CARPET:15)
Block(-8,33,-7,STEP:15)
Block(-8,33,-6,STEP:15)
Block(-8,33,-5,STEP:15)
Block(-8,33,-3,CONCRETE:15)
Block(-8,33,-1,CONCRETE:8)
Block(-8,33,0,STEP:15)
Block(-8,33,1,STEP:15)
Block(-8,33,2,STEP:15)
Block(-8,33,3,CONCRETE:8)
Block(-8,33,4,STEP:15)
Block(-8,33,5,STEP:15)
Block(-8,33,6,CONCRETE:8)
Block(-8,33,7,CONCRETE:8)
Block(-8,33,8,CONCRETE:8)
Block(-8,34,-5,STAINED_GLASS_PANE:15)
Block(-8,34,-4,QUARTZ_STAIRS:0)
Block(-8,34,-3,CONCRETE:15)
Block(-8,34,-1,CONCRETE:0)
RandomBlock(-8,34,1,AIR,90,TRAP_DOOR:7,100)
Block(-8,34,3,STAINED_GLASS:15)
RandomBlock(-8,34,6,CONCRETE:7,60,quark:iron_plate:1,20,STAINED_CLAY:12,15,STAINED_CLAY:15,5,AIR,7,IRON_BARS,12,CONCRETE:7,100)
Block(-8,34,7,QUARTZ_STAIRS:1)
Block(-8,35,-5,STAINED_GLASS_PANE:15)
Block(-8,35,-3,CONCRETE:15)
Block(-8,35,-1,CONCRETE:0)
RandomBlock(-8,35,1,AIR,90,TRAP_DOOR:7,100)
Block(-8,35,3,STAINED_GLASS:15)
RandomBlock(-8,35,6,CONCRETE:7,60,quark:iron_plate:1,20,STAINED_CLAY:12,15,STAINED_CLAY:15,5,AIR,7,IRON_BARS,12,CONCRETE:7,100)
Block(-8,35,7,QUARTZ_STAIRS:5)
Block(-8,36,-3,CONCRETE:15)
Block(-8,36,-2,QUARTZ_STAIRS:1)
Block(-8,36,-1,CONCRETE:0)
Block(-8,36,3,STAINED_GLASS:15)
RandomBlock(-8,36,6,CONCRETE:7,60,quark:iron_plate:1,20,STAINED_CLAY:12,15,STAINED_CLAY:15,5,AIR,7,IRON_BARS,12,CONCRETE:7,100)
Block(-8,36,7,CARPET:15)
Block(-8,37,-7,STEP:15)
Block(-8,37,-6,STEP:15)
Block(-8,37,-5,STEP:15)
Block(-8,37,-3,CONCRETE:15)
Block(-8,37,-1,CONCRETE:8)
Block(-8,37,0,STEP:15)
Block(-8,37,1,STEP:15)
Block(-8,37,2,STEP:15)
Block(-8,37,3,CONCRETE:8)
Block(-8,37,4,STEP:15)
Block(-8,37,5,STEP:15)
Block(-8,37,6,CONCRETE:8)
Block(-8,37,7,CONCRETE:8)
Block(-8,37,8,CONCRETE:8)
Block(-8,38,-5,STAINED_GLASS_PANE:15)
Block(-8,38,-4,QUARTZ_STAIRS:0)
Block(-8,38,-3,CONCRETE:15)
Block(-8,38,-1,CONCRETE:0)
RandomBlock(-8,38,1,AIR,90,TRAP_DOOR:7,100)
Block(-8,38,3,STAINED_GLASS:15)
RandomBlock(-8,38,6,CONCRETE:7,60,quark:iron_plate:1,20,STAINED_CLAY:12,15,STAINED_CLAY:15,5,AIR,7,IRON_BARS,12,CONCRETE:7,100)
Block(-8,38,7,QUARTZ_STAIRS:1)
Block(-8,39,-5,STAINED_GLASS_PANE:15)
Block(-8,39,-3,CONCRETE:15)
Block(-8,39,-1,CONCRETE:0)
RandomBlock(-8,39,1,AIR,90,TRAP_DOOR:7,100)
Block(-8,39,3,STAINED_GLASS:15)
RandomBlock(-8,39,6,CONCRETE:7,60,quark:iron_plate:1,20,STAINED_CLAY:12,15,STAINED_CLAY:15,5,AIR,7,IRON_BARS,12,CONCRETE:7,100)
Block(-8,39,7,QUARTZ_STAIRS:5)
Block(-8,40,-3,CONCRETE:15)
Block(-8,40,-2,QUARTZ_STAIRS:1)
Block(-8,40,-1,CONCRETE:0)
Block(-8,40,3,STAINED_GLASS:15)
RandomBlock(-8,40,6,CONCRETE:7,60,quark:iron_plate:1,20,STAINED_CLAY:12,15,STAINED_CLAY:15,5,AIR,7,IRON_BARS,12,CONCRETE:7,100)
Block(-8,40,7,CARPET:15)
Block(-8,41,-7,STEP:15)
Block(-8,41,-6,STEP:15)
Block(-8,41,-5,STEP:15)
Block(-8,41,-3,CONCRETE:15)
Block(-8,41,-1,CONCRETE:8)
Block(-8,41,0,STEP:15)
Block(-8,41,1,STEP:15)
Block(-8,41,2,STEP:15)
Block(-8,41,3,CONCRETE:8)
Block(-8,41,4,STEP:15)
Block(-8,41,5,STEP:15)
Block(-8,41,6,CONCRETE:8)
Block(-8,41,7,CONCRETE:8)
Block(-8,41,8,CONCRETE:8)
Block(-8,42,-5,STAINED_GLASS_PANE:15)
Block(-8,42,-4,QUARTZ_STAIRS:0)
Block(-8,42,-3,CONCRETE:15)
Block(-8,42,-1,CONCRETE:0)
RandomBlock(-8,42,1,AIR,90,TRAP_DOOR:7,100)
Block(-8,42,3,STAINED_GLASS:15)
RandomBlock(-8,42,6,CONCRETE:7,60,quark:iron_plate:1,20,STAINED_CLAY:12,15,STAINED_CLAY:15,5,AIR,7,IRON_BARS,12,CONCRETE:7,100)
Block(-8,42,7,QUARTZ_STAIRS:1)
Block(-8,43,-5,STAINED_GLASS_PANE:15)
Block(-8,43,-3,CONCRETE:15)
Block(-8,43,-1,CONCRETE:0)
RandomBlock(-8,43,1,AIR,90,TRAP_DOOR:7,100)
Block(-8,43,3,STAINED_GLASS:15)
RandomBlock(-8,43,6,CONCRETE:7,60,quark:iron_plate:1,20,STAINED_CLAY:12,15,STAINED_CLAY:15,5,AIR,7,IRON_BARS,12,CONCRETE:7,100)
Block(-8,43,7,QUARTZ_STAIRS:5)
Block(-8,44,-3,CONCRETE:15)
Block(-8,44,-2,QUARTZ_STAIRS:1)
Block(-8,44,-1,CONCRETE:0)
Block(-8,44,3,STAINED_GLASS:15)
RandomBlock(-8,44,6,CONCRETE:7,60,quark:iron_plate:1,20,STAINED_CLAY:12,15,STAINED_CLAY:15,5,AIR,7,IRON_BARS,12,CONCRETE:7,100)
Block(-8,44,7,CARPET:15)
Block(-8,45,-7,STEP:15)
Block(-8,45,-6,STEP:15)
Block(-8,45,-5,STEP:15)
Block(-8,45,-3,CONCRETE:15)
Block(-8,45,-1,CONCRETE:8)
Block(-8,45,0,STEP:15)
Block(-8,45,1,STEP:15)
Block(-8,45,2,STEP:15)
Block(-8,45,3,CONCRETE:8)
Block(-8,45,4,STEP:15)
Block(-8,45,5,STEP:15)
Block(-8,45,6,CONCRETE:8)
Block(-8,45,7,CONCRETE:8)
Block(-8,45,8,CONCRETE:8)
Block(-8,46,-5,STAINED_GLASS_PANE:15)
Block(-8,46,-4,QUARTZ_STAIRS:0)
Block(-8,46,-3,CONCRETE:15)
Block(-8,46,-1,CONCRETE:0)
RandomBlock(-8,46,1,AIR,90,TRAP_DOOR:7,100)
Block(-8,46,3,STAINED_GLASS:15)
RandomBlock(-8,46,6,CONCRETE:7,60,quark:iron_plate:1,20,STAINED_CLAY:12,15,STAINED_CLAY:15,5,AIR,7,IRON_BARS,12,CONCRETE:7,100)
Block(-8,46,7,QUARTZ_STAIRS:1)
Block(-8,47,-5,STAINED_GLASS_PANE:15)
Block(-8,47,-3,CONCRETE:15)
Block(-8,47,-1,CONCRETE:0)
RandomBlock(-8,47,1,AIR,90,TRAP_DOOR:7,100)
Block(-8,47,3,STAINED_GLASS:15)
RandomBlock(-8,47,6,CONCRETE:7,60,quark:iron_plate:1,20,STAINED_CLAY:12,15,STAINED_CLAY:15,5,AIR,7,IRON_BARS,12,CONCRETE:7,100)
Block(-8,47,7,QUARTZ_STAIRS:5)
Block(-8,48,-3,CONCRETE:15)
Block(-8,48,-2,QUARTZ_STAIRS:1)
Block(-8,48,-1,CONCRETE:0)
Block(-8,48,3,STAINED_GLASS:15)
RandomBlock(-8,48,6,CONCRETE:7,60,quark:iron_plate:1,20,STAINED_CLAY:12,15,STAINED_CLAY:15,5,AIR,7,IRON_BARS,12,CONCRETE:7,100)
Block(-8,48,7,CARPET:15)
Block(-8,49,-7,STEP:15)
Block(-8,49,-6,STEP:15)
Block(-8,49,-5,STEP:15)
Block(-8,49,-3,CONCRETE:15)
Block(-8,49,-1,CONCRETE:8)
Block(-8,49,0,STEP:15)
Block(-8,49,1,STEP:15)
Block(-8,49,2,STEP:15)
Block(-8,49,3,CONCRETE:8)
Block(-8,49,4,STEP:15)
Block(-8,49,5,STEP:15)
Block(-8,49,6,CONCRETE:8)
Block(-8,49,7,CONCRETE:8)
Block(-8,49,8,CONCRETE:8)
Block(-8,50,-5,STAINED_GLASS_PANE:15)
Block(-8,50,-4,QUARTZ_STAIRS:0)
Block(-8,50,-3,CONCRETE:15)
Block(-8,50,-1,CONCRETE:0)
RandomBlock(-8,50,1,AIR,90,TRAP_DOOR:7,100)
Block(-8,50,3,STAINED_GLASS:15)
RandomBlock(-8,50,6,CONCRETE:7,60,quark:iron_plate:1,20,STAINED_CLAY:12,15,STAINED_CLAY:15,5,AIR,7,IRON_BARS,12,CONCRETE:7,100)
Block(-8,50,7,QUARTZ_STAIRS:1)
Block(-8,51,-5,STAINED_GLASS_PANE:15)
Block(-8,51,-3,CONCRETE:15)
Block(-8,51,-1,CONCRETE:0)
RandomBlock(-8,51,1,AIR,90,TRAP_DOOR:7,100)
Block(-8,51,3,STAINED_GLASS:15)
RandomBlock(-8,51,6,CONCRETE:7,60,quark:iron_plate:1,20,STAINED_CLAY:12,15,STAINED_CLAY:15,5,AIR,7,IRON_BARS,12,CONCRETE:7,100)
Block(-8,51,7,QUARTZ_STAIRS:5)
Block(-8,52,-3,CONCRETE:15)
Block(-8,52,-2,QUARTZ_STAIRS:1)
Block(-8,52,-1,CONCRETE:0)
Block(-8,52,3,STAINED_GLASS:15)
RandomBlock(-8,52,6,CONCRETE:7,60,quark:iron_plate:1,20,STAINED_CLAY:12,15,STAINED_CLAY:15,5,AIR,7,IRON_BARS,12,CONCRETE:7,100)
Block(-8,52,7,CARPET:15)
Block(-8,53,-7,STEP:15)
Block(-8,53,-6,STEP:15)
Block(-8,53,-5,STEP:15)
Block(-8,53,-3,CONCRETE:15)
Block(-8,53,-1,CONCRETE:8)
Block(-8,53,0,STEP:15)
Block(-8,53,1,STEP:15)
Block(-8,53,2,STEP:15)
Block(-8,53,3,CONCRETE:8)
Block(-8,53,4,STEP:15)
Block(-8,53,5,STEP:15)
Block(-8,53,6,CONCRETE:8)
Block(-8,53,7,CONCRETE:8)
Block(-8,53,8,CONCRETE:8)
Block(-8,54,-5,STAINED_GLASS_PANE:15)
Block(-8,54,-4,QUARTZ_STAIRS:0)
Block(-8,54,-3,CONCRETE:15)
Block(-8,54,-1,CONCRETE:0)
RandomBlock(-8,54,1,AIR,90,TRAP_DOOR:7,100)
Block(-8,54,3,STAINED_GLASS:15)
RandomBlock(-8,54,6,CONCRETE:7,60,quark:iron_plate:1,20,STAINED_CLAY:12,15,STAINED_CLAY:15,5,AIR,7,IRON_BARS,12,CONCRETE:7,100)
Block(-8,54,7,QUARTZ_STAIRS:1)
Block(-8,55,-5,STAINED_GLASS_PANE:15)
Block(-8,55,-3,CONCRETE:15)
Block(-8,55,-1,CONCRETE:0)
RandomBlock(-8,55,1,AIR,90,TRAP_DOOR:7,100)
Block(-8,55,3,STAINED_GLASS:15)
RandomBlock(-8,55,6,CONCRETE:7,60,quark:iron_plate:1,20,STAINED_CLAY:12,15,STAINED_CLAY:15,5,AIR,7,IRON_BARS,12,CONCRETE:7,100)
Block(-8,55,7,QUARTZ_STAIRS:5)
Block(-8,56,-3,CONCRETE:15)
Block(-8,56,-2,QUARTZ_STAIRS:1)
Block(-8,56,-1,CONCRETE:0)
Block(-8,56,3,STAINED_GLASS:15)
RandomBlock(-8,56,6,CONCRETE:7,60,quark:iron_plate:1,20,STAINED_CLAY:12,15,STAINED_CLAY:15,5,AIR,7,IRON_BARS,12,CONCRETE:7,100)
Block(-8,56,7,CARPET:15)
Block(-8,57,-7,STEP:15)
Block(-8,57,-6,STEP:15)
Block(-8,57,-5,STEP:15)
Block(-8,57,-3,CONCRETE:15)
Block(-8,57,-1,CONCRETE:8)
Block(-8,57,0,STEP:15)
Block(-8,57,1,STEP:15)
Block(-8,57,2,STEP:15)
Block(-8,57,3,CONCRETE:8)
Block(-8,57,4,STEP:15)
Block(-8,57,5,STEP:15)
Block(-8,57,6,CONCRETE:8)
Block(-8,57,7,CONCRETE:8)
Block(-8,57,8,CONCRETE:8)
Block(-8,58,-5,STAINED_GLASS_PANE:15)
Block(-8,58,-4,QUARTZ_STAIRS:0)
Block(-8,58,-3,CONCRETE:15)
Block(-8,58,-1,CONCRETE:0)
RandomBlock(-8,58,1,AIR,90,TRAP_DOOR:7,100)
Block(-8,58,3,STAINED_GLASS:15)
RandomBlock(-8,58,6,CONCRETE:7,60,quark:iron_plate:1,20,STAINED_CLAY:12,15,STAINED_CLAY:15,5,AIR,7,IRON_BARS,12,CONCRETE:7,100)
Block(-8,58,7,QUARTZ_STAIRS:1)
Block(-8,59,-5,STAINED_GLASS_PANE:15)
Block(-8,59,-3,CONCRETE:15)
Block(-8,59,-1,CONCRETE:0)
RandomBlock(-8,59,1,AIR,90,TRAP_DOOR:7,100)
Block(-8,59,3,STAINED_GLASS:15)
RandomBlock(-8,59,6,CONCRETE:7,60,quark:iron_plate:1,20,STAINED_CLAY:12,15,STAINED_CLAY:15,5,AIR,7,IRON_BARS,12,CONCRETE:7,100)
Block(-8,59,7,QUARTZ_STAIRS:5)
Block(-8,60,-3,CONCRETE:15)
Block(-8,60,-2,QUARTZ_STAIRS:1)
Block(-8,60,-1,CONCRETE:0)
Block(-8,60,3,STAINED_GLASS:15)
RandomBlock(-8,60,6,CONCRETE:7,60,quark:iron_plate:1,20,STAINED_CLAY:12,15,STAINED_CLAY:15,5,AIR,7,IRON_BARS,12,CONCRETE:7,100)
Block(-8,60,7,CARPET:15)
Block(-8,61,-7,STEP:15)
Block(-8,61,-6,STEP:15)
Block(-8,61,-5,STEP:15)
Block(-8,61,-3,CONCRETE:15)
Block(-8,61,-1,CONCRETE:8)
Block(-8,61,0,STEP:15)
Block(-8,61,1,STEP:15)
Block(-8,61,2,STEP:15)
Block(-8,61,3,CONCRETE:8)
Block(-8,61,4,STEP:15)
Block(-8,61,5,STEP:15)
Block(-8,61,6,CONCRETE:8)
Block(-8,61,7,CONCRETE:8)
Block(-8,61,8,CONCRETE:8)
Block(-8,62,-5,STAINED_GLASS_PANE:15)
Block(-8,62,-4,QUARTZ_STAIRS:0)
Block(-8,62,-3,CONCRETE:15)
Block(-8,62,-1,CONCRETE:0)
RandomBlock(-8,62,1,AIR,90,TRAP_DOOR:7,100)
Block(-8,62,3,STAINED_GLASS:15)
RandomBlock(-8,62,6,CONCRETE:7,60,quark:iron_plate:1,20,STAINED_CLAY:12,15,STAINED_CLAY:15,5,AIR,7,IRON_BARS,12,CONCRETE:7,100)
Block(-8,62,7,QUARTZ_STAIRS:1)
Block(-8,63,-5,STAINED_GLASS_PANE:15)
Block(-8,63,-3,CONCRETE:15)
Block(-8,63,-1,CONCRETE:0)
RandomBlock(-8,63,1,AIR,90,TRAP_DOOR:7,100)
Block(-8,63,3,STAINED_GLASS:15)
RandomBlock(-8,63,6,CONCRETE:7,60,quark:iron_plate:1,20,STAINED_CLAY:12,15,STAINED_CLAY:15,5,AIR,7,IRON_BARS,12,CONCRETE:7,100)
Block(-8,63,7,QUARTZ_STAIRS:5)
Block(-8,64,-3,CONCRETE:15)
Block(-8,64,-2,QUARTZ_STAIRS:1)
Block(-8,64,-1,CONCRETE:0)
Block(-8,64,3,STAINED_GLASS:15)
RandomBlock(-8,64,6,CONCRETE:7,60,quark:iron_plate:1,20,STAINED_CLAY:12,15,STAINED_CLAY:15,5,AIR,7,IRON_BARS,12,CONCRETE:7,100)
Block(-8,64,7,CARPET:15)
Block(-8,65,-7,STEP:15)
Block(-8,65,-6,STEP:15)
Block(-8,65,-5,STEP:15)
Block(-8,65,-3,CONCRETE:15)
Block(-8,65,-1,CONCRETE:8)
Block(-8,65,0,STEP:15)
Block(-8,65,1,STEP:15)
Block(-8,65,2,STEP:15)
Block(-8,65,3,CONCRETE:8)
Block(-8,65,4,STEP:15)
Block(-8,65,5,STEP:15)
Block(-8,65,6,CONCRETE:8)
Block(-8,65,7,CONCRETE:8)
Block(-8,65,8,CONCRETE:8)
Block(-8,66,-5,STAINED_GLASS_PANE:15)
Block(-8,66,-4,QUARTZ_STAIRS:0)
Block(-8,66,-3,CONCRETE:15)
Block(-8,66,-1,CONCRETE:0)
RandomBlock(-8,66,1,AIR,90,TRAP_DOOR:7,100)
Block(-8,66,3,STAINED_GLASS:15)
RandomBlock(-8,66,6,CONCRETE:7,60,quark:iron_plate:1,20,STAINED_CLAY:12,15,STAINED_CLAY:15,5,AIR,7,IRON_BARS,12,CONCRETE:7,100)
Block(-8,66,7,QUARTZ_STAIRS:1)
Block(-8,67,-5,STAINED_GLASS_PANE:15)
Block(-8,67,-3,CONCRETE:15)
Block(-8,67,-1,CONCRETE:0)
RandomBlock(-8,67,1,AIR,90,TRAP_DOOR:7,100)
Block(-8,67,3,STAINED_GLASS:15)
RandomBlock(-8,67,6,CONCRETE:7,60,quark:iron_plate:1,20,STAINED_CLAY:12,15,STAINED_CLAY:15,5,AIR,7,IRON_BARS,12,CONCRETE:7,100)
Block(-8,67,7,QUARTZ_STAIRS:5)
Block(-8,68,-3,CONCRETE:15)
Block(-8,68,-2,QUARTZ_STAIRS:1)
Block(-8,68,-1,CONCRETE:0)
Block(-8,68,3,STAINED_GLASS:15)
RandomBlock(-8,68,6,CONCRETE:7,60,quark:iron_plate:1,20,STAINED_CLAY:12,15,STAINED_CLAY:15,5,AIR,7,IRON_BARS,12,CONCRETE:7,100)
Block(-8,68,7,CARPET:15)
Block(-8,69,-7,STEP:15)
Block(-8,69,-6,STEP:15)
Block(-8,69,-5,STEP:15)
Block(-8,69,-3,CONCRETE:15)
Block(-8,69,-1,CONCRETE:8)
Block(-8,69,0,STEP:15)
Block(-8,69,1,STEP:15)
Block(-8,69,2,STEP:15)
Block(-8,69,3,CONCRETE:8)
Block(-8,69,4,STEP:15)
Block(-8,69,5,STEP:15)
Block(-8,69,6,CONCRETE:8)
Block(-8,69,7,CONCRETE:8)
Block(-8,69,8,CONCRETE:8)
Block(-8,70,-5,STAINED_GLASS_PANE:15)
Block(-8,70,-4,QUARTZ_STAIRS:0)
Block(-8,70,-3,CONCRETE:15)
Block(-8,70,-1,CONCRETE:0)
RandomBlock(-8,70,1,AIR,90,TRAP_DOOR:7,100)
Block(-8,70,3,STAINED_GLASS:15)
RandomBlock(-8,70,6,CONCRETE:7,60,quark:iron_plate:1,20,STAINED_CLAY:12,15,STAINED_CLAY:15,5,AIR,7,IRON_BARS,12,CONCRETE:7,100)
Block(-8,70,7,QUARTZ_STAIRS:1)
Block(-8,71,-5,STAINED_GLASS_PANE:15)
Block(-8,71,-3,CONCRETE:15)
Block(-8,71,-1,CONCRETE:0)
RandomBlock(-8,71,1,AIR,90,TRAP_DOOR:7,100)
Block(-8,71,3,STAINED_GLASS:15)
RandomBlock(-8,71,6,CONCRETE:7,60,quark:iron_plate:1,20,STAINED_CLAY:12,15,STAINED_CLAY:15,5,AIR,7,IRON_BARS,12,CONCRETE:7,100)
Block(-8,71,7,QUARTZ_STAIRS:5)
Block(-8,72,-3,CONCRETE:15)
Block(-8,72,-2,QUARTZ_STAIRS:1)
Block(-8,72,-1,CONCRETE:0)
Block(-8,72,3,STAINED_GLASS:15)
RandomBlock(-8,72,6,CONCRETE:7,60,quark:iron_plate:1,20,STAINED_CLAY:12,15,STAINED_CLAY:15,5,AIR,7,IRON_BARS,12,CONCRETE:7,100)
Block(-8,72,7,CARPET:15)
Block(-8,73,-7,STEP:15)
Block(-8,73,-6,STEP:15)
Block(-8,73,-5,STEP:15)
Block(-8,73,-3,CONCRETE:15)
Block(-8,73,-1,CONCRETE:8)
Block(-8,73,0,STEP:15)
Block(-8,73,1,STEP:15)
Block(-8,73,2,STEP:15)
Block(-8,73,3,CONCRETE:8)
Block(-8,73,4,STEP:15)
Block(-8,73,5,STEP:15)
Block(-8,73,6,CONCRETE:8)
Block(-8,73,7,CONCRETE:8)
Block(-8,73,8,CONCRETE:8)
Block(-8,74,-5,STAINED_GLASS_PANE:15)
Block(-8,74,-4,QUARTZ_STAIRS:0)
Block(-8,74,-3,CONCRETE:15)
Block(-8,74,-1,CONCRETE:0)
RandomBlock(-8,74,1,AIR,90,TRAP_DOOR:7,100)
Block(-8,74,3,STAINED_GLASS:15)
RandomBlock(-8,74,6,CONCRETE:7,60,quark:iron_plate:1,20,STAINED_CLAY:12,15,STAINED_CLAY:15,5,AIR,7,IRON_BARS,12,CONCRETE:7,100)
Block(-8,74,7,QUARTZ_STAIRS:1)
Block(-8,75,-5,STAINED_GLASS_PANE:15)
Block(-8,75,-3,CONCRETE:15)
Block(-8,75,-1,CONCRETE:0)
RandomBlock(-8,75,1,AIR,90,TRAP_DOOR:7,100)
Block(-8,75,3,STAINED_GLASS:15)
RandomBlock(-8,75,6,CONCRETE:7,60,quark:iron_plate:1,20,STAINED_CLAY:12,15,STAINED_CLAY:15,5,AIR,7,IRON_BARS,12,CONCRETE:7,100)
Block(-8,75,7,QUARTZ_STAIRS:5)
Block(-8,76,-3,CONCRETE:15)
Block(-8,76,-2,QUARTZ_STAIRS:1)
Block(-8,76,-1,CONCRETE:0)
Block(-8,76,3,STAINED_GLASS:15)
RandomBlock(-8,76,6,CONCRETE:7,60,quark:iron_plate:1,20,STAINED_CLAY:12,15,STAINED_CLAY:15,5,AIR,7,IRON_BARS,12,CONCRETE:7,100)
Block(-8,76,7,CARPET:15)
Block(-8,77,-7,CONCRETE:8)
Block(-8,77,-6,CONCRETE:8)
Block(-8,77,-5,CONCRETE:8)
Block(-8,77,-3,CONCRETE:15)
Block(-8,77,-1,CONCRETE:8)
Block(-8,77,0,CONCRETE:8)
Block(-8,77,1,CONCRETE:8)
Block(-8,77,2,CONCRETE:8)
Block(-8,77,3,CONCRETE:8)
Block(-8,77,4,CONCRETE:8)
Block(-8,77,5,CONCRETE:8)
Block(-8,77,6,CONCRETE:8)
Block(-8,77,7,CONCRETE:8)
Block(-8,77,8,CONCRETE:8)
Block(-8,78,-7,CONCRETE:8)
Block(-8,78,-6,CONCRETE:8)
Block(-8,78,-5,CONCRETE:8)
Block(-8,78,-4,QUARTZ_STAIRS:0)
Block(-8,78,-3,CONCRETE:15)
Block(-8,78,-1,CONCRETE:8)
Block(-8,78,0,CONCRETE:8)
Block(-8,78,1,CONCRETE:8)
Block(-8,78,2,CONCRETE:8)
Block(-8,78,3,QUARTZ_STAIRS:3)
Block(-8,79,-6,STEP:7)
Block(-8,79,-5,CONCRETE:15)
Block(-8,79,-3,CONCRETE:15)
Block(-8,79,-1,CONCRETE:15)
Block(-8,79,0,STEP:7)
Block(-8,80,-6,STEP:7)
Block(-8,80,-5,CONCRETE:15)
Block(-8,80,-3,CONCRETE:15)
Block(-8,80,-1,CONCRETE:15)
Block(-8,80,0,STEP:7)
Block(-8,81,-6,STEP:7)
Block(-8,81,-5,CONCRETE:15)
Block(-8,81,-3,CONCRETE:15)
Block(-8,81,-1,CONCRETE:15)
Block(-8,81,0,QUARTZ_STAIRS:0)
Block(-8,82,-6,STEP:7)
Block(-8,82,-5,CONCRETE:15)
Block(-8,82,-4,STAINED_GLASS:10)
Block(-8,82,-3,CONCRETE:15)
Block(-8,82,-2,STAINED_GLASS:10)
Block(-8,82,-1,CONCRETE:15)
Block(-8,82,0,STEP:7)
Block(-8,83,-6,STEP:7)
Block(-8,83,-5,STEP:7)
RandomBlock(-8,83,-4,AIR,90,IRON_TRAPDOOR:2,100)
RandomBlock(-8,83,-3,AIR,90,IRON_TRAPDOOR:2,100)
RandomBlock(-8,83,-2,AIR,90,IRON_TRAPDOOR:3,100)
Block(-8,83,-1,STEP:7)
Block(-8,83,0,STEP:7)
RandomBlock(-7,0,-7,CONCRETE:7,60,quark:iron_plate:1,20,STAINED_CLAY:12,15,STAINED_CLAY:15,5,AIR,7,IRON_BARS,12,CONCRETE:7,100)
RandomBlock(-7,0,-6,CONCRETE:7,60,quark:iron_plate:1,20,STAINED_CLAY:12,15,STAINED_CLAY:15,5,AIR,7,IRON_BARS,12,CONCRETE:7,100)
RandomBlock(-7,0,-5,CONCRETE:7,60,quark:iron_plate:1,20,STAINED_CLAY:12,15,STAINED_CLAY:15,5,AIR,7,IRON_BARS,12,CONCRETE:7,100)
RandomBlock(-7,0,-4,CONCRETE:7,60,quark:iron_plate:1,20,STAINED_CLAY:12,15,STAINED_CLAY:15,5,AIR,7,IRON_BARS,12,CONCRETE:7,100)
RandomBlock(-7,0,-3,CONCRETE:7,60,quark:iron_plate:1,20,STAINED_CLAY:12,15,STAINED_CLAY:15,5,AIR,7,IRON_BARS,12,CONCRETE:7,100)
RandomBlock(-7,0,-2,CONCRETE:7,60,quark:iron_plate:1,20,STAINED_CLAY:12,15,STAINED_CLAY:15,5,AIR,7,IRON_BARS,12,CONCRETE:7,100)
RandomBlock(-7,0,-1,CONCRETE:7,60,quark:iron_plate:1,20,STAINED_CLAY:12,15,STAINED_CLAY:15,5,AIR,7,IRON_BARS,12,CONCRETE:7,100)
RandomBlock(-7,0,0,CONCRETE:7,60,quark:iron_plate:1,20,STAINED_CLAY:12,15,STAINED_CLAY:15,5,AIR,7,IRON_BARS,12,CONCRETE:7,100)
RandomBlock(-7,0,1,CONCRETE:7,60,quark:iron_plate:1,20,STAINED_CLAY:12,15,STAINED_CLAY:15,5,AIR,7,IRON_BARS,12,CONCRETE:7,100)
RandomBlock(-7,0,2,CONCRETE:7,60,quark:iron_plate:1,20,STAINED_CLAY:12,15,STAINED_CLAY:15,5,AIR,7,IRON_BARS,12,CONCRETE:7,100)
RandomBlock(-7,0,3,CONCRETE:7,60,quark:iron_plate:1,20,STAINED_CLAY:12,15,STAINED_CLAY:15,5,AIR,7,IRON_BARS,12,CONCRETE:7,100)
RandomBlock(-7,0,4,CONCRETE:7,60,quark:iron_plate:1,20,STAINED_CLAY:12,15,STAINED_CLAY:15,5,AIR,7,IRON_BARS,12,CONCRETE:7,100)
RandomBlock(-7,0,5,CONCRETE:7,60,quark:iron_plate:1,20,STAINED_CLAY:12,15,STAINED_CLAY:15,5,AIR,7,IRON_BARS,12,CONCRETE:7,100)
RandomBlock(-7,0,6,CONCRETE:7,60,quark:iron_plate:1,20,STAINED_CLAY:12,15,STAINED_CLAY:15,5,AIR,7,IRON_BARS,12,CONCRETE:7,100)
RandomBlock(-7,0,7,CONCRETE:7,60,quark:iron_plate:1,20,STAINED_CLAY:12,15,STAINED_CLAY:15,5,AIR,7,IRON_BARS,12,CONCRETE:7,100)
RandomBlock(-7,0,8,CONCRETE:7,60,quark:iron_plate:1,20,STAINED_CLAY:12,15,STAINED_CLAY:15,5,AIR,7,IRON_BARS,12,CONCRETE:7,100)
RandomBlock(-7,1,-7,CONCRETE:7,60,quark:iron_plate:1,20,STAINED_CLAY:12,15,STAINED_CLAY:15,5,AIR,7,IRON_BARS,12,CONCRETE:7,100)
RandomBlock(-7,1,-6,CONCRETE:7,60,quark:iron_plate:1,20,STAINED_CLAY:12,15,STAINED_CLAY:15,5,AIR,7,IRON_BARS,12,CONCRETE:7,100)
RandomBlock(-7,1,-5,CONCRETE:7,60,quark:iron_plate:1,20,STAINED_CLAY:12,15,STAINED_CLAY:15,5,AIR,7,IRON_BARS,12,CONCRETE:7,100)
RandomBlock(-7,1,-4,CONCRETE:7,60,quark:iron_plate:1,20,STAINED_CLAY:12,15,STAINED_CLAY:15,5,AIR,7,IRON_BARS,12,CONCRETE:7,100)
Block(-7,1,-3,STATIONARY_WATER:0)
Block(-7,1,-2,STATIONARY_WATER:0)
RandomBlock(-7,1,-1,CONCRETE:7,60,quark:iron_plate:1,20,STAINED_CLAY:12,15,STAINED_CLAY:15,5,AIR,7,IRON_BARS,12,CONCRETE:7,100)
RandomBlock(-7,1,0,CONCRETE:7,60,quark:iron_plate:1,20,STAINED_CLAY:12,15,STAINED_CLAY:15,5,AIR,7,IRON_BARS,12,CONCRETE:7,100)
RandomBlock(-7,1,1,CONCRETE:7,60,quark:iron_plate:1,20,STAINED_CLAY:12,15,STAINED_CLAY:15,5,AIR,7,IRON_BARS,12,CONCRETE:7,100)
RandomBlock(-7,1,2,CONCRETE:7,60,quark:iron_plate:1,20,STAINED_CLAY:12,15,STAINED_CLAY:15,5,AIR,7,IRON_BARS,12,CONCRETE:7,100)
RandomBlock(-7,1,3,CONCRETE:7,60,quark:iron_plate:1,20,STAINED_CLAY:12,15,STAINED_CLAY:15,5,AIR,7,IRON_BARS,12,CONCRETE:7,100)
RandomBlock(-7,1,4,CONCRETE:7,60,quark:iron_plate:1,20,STAINED_CLAY:12,15,STAINED_CLAY:15,5,AIR,7,IRON_BARS,12,CONCRETE:7,100)
RandomBlock(-7,1,5,CONCRETE:7,60,quark:iron_plate:1,20,STAINED_CLAY:12,15,STAINED_CLAY:15,5,AIR,7,IRON_BARS,12,CONCRETE:7,100)
RandomBlock(-7,1,6,CONCRETE:7,60,quark:iron_plate:1,20,STAINED_CLAY:12,15,STAINED_CLAY:15,5,AIR,7,IRON_BARS,12,CONCRETE:7,100)
RandomBlock(-7,1,7,CONCRETE:7,60,quark:iron_plate:1,20,STAINED_CLAY:12,15,STAINED_CLAY:15,5,AIR,7,IRON_BARS,12,CONCRETE:7,100)
RandomBlock(-7,1,8,CONCRETE:7,60,quark:iron_plate:1,20,STAINED_CLAY:12,15,STAINED_CLAY:15,5,AIR,7,IRON_BARS,12,CONCRETE:7,100)
RandomBlock(-7,2,-7,CONCRETE:7,60,quark:iron_plate:1,20,STAINED_CLAY:12,15,STAINED_CLAY:15,5,AIR,7,IRON_BARS,12,CONCRETE:7,100)
RandomBlock(-7,2,-6,CONCRETE:7,60,quark:iron_plate:1,20,STAINED_CLAY:12,15,STAINED_CLAY:15,5,AIR,7,IRON_BARS,12,CONCRETE:7,100)
RandomBlock(-7,2,-5,CONCRETE:7,60,quark:iron_plate:1,20,STAINED_CLAY:12,15,STAINED_CLAY:15,5,AIR,7,IRON_BARS,12,CONCRETE:7,100)
Block(-7,2,-4,SMOOTH_STAIRS:3)
Block(-7,2,-3,AIR:0)
Block(-7,2,-2,AIR:0)
Block(-7,2,-1,SMOOTH_STAIRS:2)
RandomBlock(-7,2,0,CONCRETE:7,60,quark:iron_plate:1,20,STAINED_CLAY:12,15,STAINED_CLAY:15,5,AIR,7,IRON_BARS,12,CONCRETE:7,100)
RandomBlock(-7,2,1,CONCRETE:7,60,quark:iron_plate:1,20,STAINED_CLAY:12,15,STAINED_CLAY:15,5,AIR,7,IRON_BARS,12,CONCRETE:7,100)
RandomBlock(-7,2,2,CONCRETE:7,60,quark:iron_plate:1,20,STAINED_CLAY:12,15,STAINED_CLAY:15,5,AIR,7,IRON_BARS,12,CONCRETE:7,100)
RandomBlock(-7,2,3,CONCRETE:7,60,quark:iron_plate:1,20,STAINED_CLAY:12,15,STAINED_CLAY:15,5,AIR,7,IRON_BARS,12,CONCRETE:7,100)
RandomBlock(-7,2,4,CONCRETE:7,60,quark:iron_plate:1,20,STAINED_CLAY:12,15,STAINED_CLAY:15,5,AIR,7,IRON_BARS,12,CONCRETE:7,100)
RandomBlock(-7,2,5,CONCRETE:7,60,quark:iron_plate:1,20,STAINED_CLAY:12,15,STAINED_CLAY:15,5,AIR,7,IRON_BARS,12,CONCRETE:7,100)
RandomBlock(-7,2,6,CONCRETE:7,60,quark:iron_plate:1,20,STAINED_CLAY:12,15,STAINED_CLAY:15,5,AIR,7,IRON_BARS,12,CONCRETE:7,100)
RandomBlock(-7,2,7,CONCRETE:7,60,quark:iron_plate:1,20,STAINED_CLAY:12,15,STAINED_CLAY:15,5,AIR,7,IRON_BARS,12,CONCRETE:7,100)
RandomBlock(-7,2,8,CONCRETE:7,60,quark:iron_plate:1,20,STAINED_CLAY:12,15,STAINED_CLAY:15,5,AIR,7,IRON_BARS,12,CONCRETE:7,100)
Block(-7,3,-7,AIR:0)
Block(-7,3,-6,AIR:0)
Block(-7,3,-5,AIR:0)
Block(-7,3,-4,AIR:0)
Block(-7,3,-3,AIR:0)
Block(-7,3,-2,AIR:0)
Block(-7,3,-1,AIR:0)
Block(-7,3,0,AIR:0)
RandomBlock(-7,3,1,CONCRETE:7,60,quark:iron_plate:1,20,STAINED_CLAY:12,15,STAINED_CLAY:15,5,AIR,7,IRON_BARS,12,CONCRETE:7,100)
RandomBlock(-7,3,2,CONCRETE:7,60,quark:iron_plate:1,20,STAINED_CLAY:12,15,STAINED_CLAY:15,5,AIR,7,IRON_BARS,12,CONCRETE:7,100)
Block(-7,3,3,AIR:0)
Block(-7,3,4,AIR:0)
RandomBlock(-7,3,5,CONCRETE:7,60,quark:iron_plate:1,20,STAINED_CLAY:12,15,STAINED_CLAY:15,5,AIR,7,IRON_BARS,12,CONCRETE:7,100)
RandomBlock(-7,3,6,CONCRETE:7,60,quark:iron_plate:1,20,STAINED_CLAY:12,15,STAINED_CLAY:15,5,AIR,7,IRON_BARS,12,CONCRETE:7,100)
Block(-7,3,7,AIR:0)
RandomBlock(-7,3,8,CONCRETE:7,60,quark:iron_plate:1,20,STAINED_CLAY:12,15,STAINED_CLAY:15,5,AIR,7,IRON_BARS,12,CONCRETE:7,100)
Block(-7,4,-7,AIR:0)
Block(-7,4,-6,AIR:0)
Block(-7,4,-5,AIR:0)
Block(-7,4,-4,AIR:0)
Block(-7,4,-3,AIR:0)
Block(-7,4,-2,AIR:0)
Block(-7,4,-1,AIR:0)
Block(-7,4,0,AIR:0)
RandomBlock(-7,4,1,CONCRETE:7,60,quark:iron_plate:1,20,STAINED_CLAY:12,15,STAINED_CLAY:15,5,AIR,7,IRON_BARS,12,CONCRETE:7,100)
RandomBlock(-7,4,2,CONCRETE:7,60,quark:iron_plate:1,20,STAINED_CLAY:12,15,STAINED_CLAY:15,5,AIR,7,IRON_BARS,12,CONCRETE:7,100)
Block(-7,4,3,AIR:0)
Block(-7,4,4,AIR:0)
RandomBlock(-7,4,5,CONCRETE:7,60,quark:iron_plate:1,20,STAINED_CLAY:12,15,STAINED_CLAY:15,5,AIR,7,IRON_BARS,12,CONCRETE:7,100)
RandomBlock(-7,4,6,CONCRETE:7,60,quark:iron_plate:1,20,STAINED_CLAY:12,15,STAINED_CLAY:15,5,AIR,7,IRON_BARS,12,CONCRETE:7,100)
Block(-7,4,7,AIR:0)
RandomBlock(-7,4,8,CONCRETE:7,60,quark:iron_plate:1,20,STAINED_CLAY:12,15,STAINED_CLAY:15,5,AIR,7,IRON_BARS,12,CONCRETE:7,100)
Block(-7,5,-7,AIR:0)
Block(-7,5,-6,CONCRETE:4)
Block(-7,5,-5,CONCRETE:12)
Block(-7,5,-4,CONCRETE:12)
Block(-7,5,-3,CONCRETE:12)
Block(-7,5,-2,CONCRETE:12)
Block(-7,5,-1,CONCRETE:12)
Block(-7,5,0,CONCRETE:12)
RandomBlock(-7,5,1,CONCRETE:7,60,quark:iron_plate:1,20,STAINED_CLAY:12,15,STAINED_CLAY:15,5,AIR,7,IRON_BARS,12,CONCRETE:7,100)
RandomBlock(-7,5,2,CONCRETE:7,60,quark:iron_plate:1,20,STAINED_CLAY:12,15,STAINED_CLAY:15,5,AIR,7,IRON_BARS,12,CONCRETE:7,100)
Block(-7,5,3,AIR:0)
Block(-7,5,4,AIR:0)
RandomBlock(-7,5,5,CONCRETE:7,60,quark:iron_plate:1,20,STAINED_CLAY:12,15,STAINED_CLAY:15,5,AIR,7,IRON_BARS,12,CONCRETE:7,100)
RandomBlock(-7,5,6,CONCRETE:7,60,quark:iron_plate:1,20,STAINED_CLAY:12,15,STAINED_CLAY:15,5,AIR,7,IRON_BARS,12,CONCRETE:7,100)
Block(-7,5,7,AIR:0)
RandomBlock(-7,5,8,CONCRETE:7,60,quark:iron_plate:1,20,STAINED_CLAY:12,15,STAINED_CLAY:15,5,AIR,7,IRON_BARS,12,CONCRETE:7,100)
Block(-7,6,-7,AIR:0)
Block(-7,6,-6,IRON_FENCE:0)
Block(-7,6,-5,AIR:0)
Block(-7,6,-4,AIR:0)
Block(-7,6,-3,AIR:0)
Block(-7,6,-2,IRON_FENCE:0)
Block(-7,6,-1,AIR:0)
Block(-7,6,0,CONCRETE:12)
RandomBlock(-7,6,1,CONCRETE:7,60,quark:iron_plate:1,20,STAINED_CLAY:12,15,STAINED_CLAY:15,5,AIR,7,IRON_BARS,12,CONCRETE:7,100)
RandomBlock(-7,6,2,CONCRETE:7,60,quark:iron_plate:1,20,STAINED_CLAY:12,15,STAINED_CLAY:15,5,AIR,7,IRON_BARS,12,CONCRETE:7,100)
Block(-7,6,3,AIR:0)
Block(-7,6,4,AIR:0)
RandomBlock(-7,6,5,CONCRETE:7,60,quark:iron_plate:1,20,STAINED_CLAY:12,15,STAINED_CLAY:15,5,AIR,7,IRON_BARS,12,CONCRETE:7,100)
RandomBlock(-7,6,6,CONCRETE:7,60,quark:iron_plate:1,20,STAINED_CLAY:12,15,STAINED_CLAY:15,5,AIR,7,IRON_BARS,12,CONCRETE:7,100)
Block(-7,6,7,AIR:0)
RandomBlock(-7,6,8,CONCRETE:7,60,quark:iron_plate:1,20,STAINED_CLAY:12,15,STAINED_CLAY:15,5,AIR,7,IRON_BARS,12,CONCRETE:7,100)
RandomBlock(-7,7,-7,CONCRETE:7,60,quark:iron_plate:1,20,STAINED_CLAY:12,15,STAINED_CLAY:15,5,AIR,7,IRON_BARS,12,CONCRETE:7,100)
RandomBlock(-7,7,-6,CONCRETE:7,60,quark:iron_plate:1,20,STAINED_CLAY:12,15,STAINED_CLAY:15,5,AIR,7,IRON_BARS,12,CONCRETE:7,100)
RandomBlock(-7,7,-5,CONCRETE:7,60,quark:iron_plate:1,20,STAINED_CLAY:12,15,STAINED_CLAY:15,5,AIR,7,IRON_BARS,12,CONCRETE:7,100)
RandomBlock(-7,7,-4,CONCRETE:7,60,quark:iron_plate:1,20,STAINED_CLAY:12,15,STAINED_CLAY:15,5,AIR,7,IRON_BARS,12,CONCRETE:7,100)
RandomBlock(-7,7,-3,CONCRETE:7,60,quark:iron_plate:1,20,STAINED_CLAY:12,15,STAINED_CLAY:15,5,AIR,7,IRON_BARS,12,CONCRETE:7,100)
RandomBlock(-7,7,-2,CONCRETE:7,60,quark:iron_plate:1,20,STAINED_CLAY:12,15,STAINED_CLAY:15,5,AIR,7,IRON_BARS,12,CONCRETE:7,100)
RandomBlock(-7,7,-1,CONCRETE:7,60,quark:iron_plate:1,20,STAINED_CLAY:12,15,STAINED_CLAY:15,5,AIR,7,IRON_BARS,12,CONCRETE:7,100)
RandomBlock(-7,7,0,CONCRETE:7,60,quark:iron_plate:1,20,STAINED_CLAY:12,15,STAINED_CLAY:15,5,AIR,7,IRON_BARS,12,CONCRETE:7,100)
RandomBlock(-7,7,1,CONCRETE:7,60,quark:iron_plate:1,20,STAINED_CLAY:12,15,STAINED_CLAY:15,5,AIR,7,IRON_BARS,12,CONCRETE:7,100)
RandomBlock(-7,7,2,CONCRETE:7,60,quark:iron_plate:1,20,STAINED_CLAY:12,15,STAINED_CLAY:15,5,AIR,7,IRON_BARS,12,CONCRETE:7,100)
RandomBlock(-7,7,3,CONCRETE:7,60,quark:iron_plate:1,20,STAINED_CLAY:12,15,STAINED_CLAY:15,5,AIR,7,IRON_BARS,12,CONCRETE:7,100)
Block(-7,7,4,LADDER:2)
RandomBlock(-7,7,5,CONCRETE:7,60,quark:iron_plate:1,20,STAINED_CLAY:12,15,STAINED_CLAY:15,5,AIR,7,IRON_BARS,12,CONCRETE:7,100)
RandomBlock(-7,7,6,CONCRETE:7,60,quark:iron_plate:1,20,STAINED_CLAY:12,15,STAINED_CLAY:15,5,AIR,7,IRON_BARS,12,CONCRETE:7,100)
RandomBlock(-7,7,7,CONCRETE:7,60,quark:iron_plate:1,20,STAINED_CLAY:12,15,STAINED_CLAY:15,5,AIR,7,IRON_BARS,12,CONCRETE:7,100)
RandomBlock(-7,7,8,CONCRETE:7,60,quark:iron_plate:1,20,STAINED_CLAY:12,15,STAINED_CLAY:15,5,AIR,7,IRON_BARS,12,CONCRETE:7,100)
RandomBlock(-7,8,-7,CONCRETE:7,60,quark:iron_plate:1,20,STAINED_CLAY:12,15,STAINED_CLAY:15,5,AIR,7,IRON_BARS,12,CONCRETE:7,100)
RandomBlock(-7,8,-6,CONCRETE:7,60,quark:iron_plate:1,20,STAINED_CLAY:12,15,STAINED_CLAY:15,5,AIR,7,IRON_BARS,12,CONCRETE:7,100)
RandomBlock(-7,8,-5,CONCRETE:7,60,quark:iron_plate:1,20,STAINED_CLAY:12,15,STAINED_CLAY:15,5,AIR,7,IRON_BARS,12,CONCRETE:7,100)
RandomBlock(-7,8,-4,CONCRETE:7,60,quark:iron_plate:1,20,STAINED_CLAY:12,15,STAINED_CLAY:15,5,AIR,7,IRON_BARS,12,CONCRETE:7,100)
RandomBlock(-7,8,-3,CONCRETE:7,60,quark:iron_plate:1,20,STAINED_CLAY:12,15,STAINED_CLAY:15,5,AIR,7,IRON_BARS,12,CONCRETE:7,100)
RandomBlock(-7,8,-2,CONCRETE:7,60,quark:iron_plate:1,20,STAINED_CLAY:12,15,STAINED_CLAY:15,5,AIR,7,IRON_BARS,12,CONCRETE:7,100)
RandomBlock(-7,8,-1,CONCRETE:7,60,quark:iron_plate:1,20,STAINED_CLAY:12,15,STAINED_CLAY:15,5,AIR,7,IRON_BARS,12,CONCRETE:7,100)
RandomBlock(-7,8,0,CONCRETE:7,60,quark:iron_plate:1,20,STAINED_CLAY:12,15,STAINED_CLAY:15,5,AIR,7,IRON_BARS,12,CONCRETE:7,100)
RandomBlock(-7,8,1,CONCRETE:7,60,quark:iron_plate:1,20,STAINED_CLAY:12,15,STAINED_CLAY:15,5,AIR,7,IRON_BARS,12,CONCRETE:7,100)
RandomBlock(-7,8,2,CONCRETE:7,60,quark:iron_plate:1,20,STAINED_CLAY:12,15,STAINED_CLAY:15,5,AIR,7,IRON_BARS,12,CONCRETE:7,100)
RandomBlock(-7,8,3,CONCRETE:7,60,quark:iron_plate:1,20,STAINED_CLAY:12,15,STAINED_CLAY:15,5,AIR,7,IRON_BARS,12,CONCRETE:7,100)
Block(-7,8,4,LADDER:2)
RandomBlock(-7,8,5,CONCRETE:7,60,quark:iron_plate:1,20,STAINED_CLAY:12,15,STAINED_CLAY:15,5,AIR,7,IRON_BARS,12,CONCRETE:7,100)
RandomBlock(-7,8,6,CONCRETE:7,60,quark:iron_plate:1,20,STAINED_CLAY:12,15,STAINED_CLAY:15,5,AIR,7,IRON_BARS,12,CONCRETE:7,100)
RandomBlock(-7,8,7,CONCRETE:7,60,quark:iron_plate:1,20,STAINED_CLAY:12,15,STAINED_CLAY:15,5,AIR,7,IRON_BARS,12,CONCRETE:7,100)
RandomBlock(-7,8,8,CONCRETE:7,60,quark:iron_plate:1,20,STAINED_CLAY:12,15,STAINED_CLAY:15,5,AIR,7,IRON_BARS,12,CONCRETE:7,100)
RandomBlock(-7,9,-7,CONCRETE:7,60,quark:iron_plate:1,20,STAINED_CLAY:12,15,STAINED_CLAY:15,5,AIR,7,IRON_BARS,12,CONCRETE:7,100)
RandomBlock(-7,9,-6,CONCRETE:7,60,quark:iron_plate:1,20,STAINED_CLAY:12,15,STAINED_CLAY:15,5,AIR,7,IRON_BARS,12,CONCRETE:7,100)
RandomBlock(-7,9,-5,CONCRETE:7,60,quark:iron_plate:1,20,STAINED_CLAY:12,15,STAINED_CLAY:15,5,AIR,7,IRON_BARS,12,CONCRETE:7,100)
RandomBlock(-7,9,-4,CONCRETE:7,60,quark:iron_plate:1,20,STAINED_CLAY:12,15,STAINED_CLAY:15,5,AIR,7,IRON_BARS,12,CONCRETE:7,100)
RandomBlock(-7,9,-3,CONCRETE:7,60,quark:iron_plate:1,20,STAINED_CLAY:12,15,STAINED_CLAY:15,5,AIR,7,IRON_BARS,12,CONCRETE:7,100)
RandomBlock(-7,9,-2,CONCRETE:7,60,quark:iron_plate:1,20,STAINED_CLAY:12,15,STAINED_CLAY:15,5,AIR,7,IRON_BARS,12,CONCRETE:7,100)
RandomBlock(-7,9,-1,CONCRETE:7,60,quark:iron_plate:1,20,STAINED_CLAY:12,15,STAINED_CLAY:15,5,AIR,7,IRON_BARS,12,CONCRETE:7,100)
RandomBlock(-7,9,0,CONCRETE:7,60,quark:iron_plate:1,20,STAINED_CLAY:12,15,STAINED_CLAY:15,5,AIR,7,IRON_BARS,12,CONCRETE:7,100)
RandomBlock(-7,9,1,CONCRETE:7,60,quark:iron_plate:1,20,STAINED_CLAY:12,15,STAINED_CLAY:15,5,AIR,7,IRON_BARS,12,CONCRETE:7,100)
RandomBlock(-7,9,2,CONCRETE:7,60,quark:iron_plate:1,20,STAINED_CLAY:12,15,STAINED_CLAY:15,5,AIR,7,IRON_BARS,12,CONCRETE:7,100)
RandomBlock(-7,9,3,AIR,90,IRON_TRAPDOOR:10,100)
Block(-7,9,4,LADDER:2)
RandomBlock(-7,9,5,CONCRETE:7,60,quark:iron_plate:1,20,STAINED_CLAY:12,15,STAINED_CLAY:15,5,AIR,7,IRON_BARS,12,CONCRETE:7,100)
RandomBlock(-7,9,6,CONCRETE:7,60,quark:iron_plate:1,20,STAINED_CLAY:12,15,STAINED_CLAY:15,5,AIR,7,IRON_BARS,12,CONCRETE:7,100)
RandomBlock(-7,9,7,CONCRETE:7,60,quark:iron_plate:1,20,STAINED_CLAY:12,15,STAINED_CLAY:15,5,AIR,7,IRON_BARS,12,CONCRETE:7,100)
RandomBlock(-7,9,8,CONCRETE:7,60,quark:iron_plate:1,20,STAINED_CLAY:12,15,STAINED_CLAY:15,5,AIR,7,IRON_BARS,12,CONCRETE:7,100)
Block(-7,10,-7,CONCRETE:8)
Block(-7,10,-6,CONCRETE:8)
Block(-7,10,-5,CONCRETE:8)
Block(-7,10,-4,CONCRETE:8)
Block(-7,10,-3,CONCRETE:8)
Block(-7,10,-2,CONCRETE:8)
Block(-7,10,-1,CONCRETE:8)
Block(-7,10,0,CONCRETE:8)
Block(-7,10,1,CONCRETE:8)
Block(-7,10,2,CONCRETE:8)
Block(-7,10,3,AIR:0)
Block(-7,10,4,AIR:0)
Block(-7,10,5,AIR:0)
Block(-7,10,6,CONCRETE:8)
Block(-7,10,7,CONCRETE:8)
Block(-7,10,8,CONCRETE:8)
Block(-7,11,-7,CONCRETE:8)
Block(-7,11,-6,CONCRETE:8)
Block(-7,11,-5,CONCRETE:8)
Block(-7,11,-4,CONCRETE:8)
Block(-7,11,-3,CONCRETE:8)
Block(-7,11,-2,CONCRETE:8)
Block(-7,11,-1,CONCRETE:8)
Block(-7,11,0,CONCRETE:8)
Block(-7,11,1,CONCRETE:8)
Block(-7,11,2,CONCRETE:8)
Block(-7,11,3,AIR:0)
Block(-7,11,4,AIR:0)
Block(-7,11,5,AIR:0)
Block(-7,11,6,CONCRETE:8)
Block(-7,11,7,CONCRETE:8)
Block(-7,11,8,CONCRETE:8)
Block(-7,12,-7,CONCRETE:8)
Block(-7,12,-6,CONCRETE:8)
Block(-7,12,-5,CONCRETE:8)
Block(-7,12,-4,CONCRETE:8)
Block(-7,12,-3,CONCRETE:8)
Block(-7,12,-2,CONCRETE:8)
Block(-7,12,-1,CONCRETE:8)
Block(-7,12,0,CONCRETE:8)
Block(-7,12,1,CONCRETE:8)
Block(-7,12,2,CONCRETE:8)
Block(-7,12,3,AIR:0)
Block(-7,12,4,AIR:0)
Block(-7,12,5,AIR:0)
Block(-7,12,6,CONCRETE:8)
Block(-7,12,7,CONCRETE:8)
Block(-7,12,8,CONCRETE:8)
Block(-7,13,-7,CONCRETE:8)
Block(-7,13,-6,CONCRETE:8)
Block(-7,13,-5,CONCRETE:8)
Block(-7,13,-4,CONCRETE:8)
Block(-7,13,-3,CONCRETE:8)
Block(-7,13,-2,CONCRETE:8)
Block(-7,13,-1,CONCRETE:8)
Block(-7,13,0,CONCRETE:8)
Block(-7,13,1,CONCRETE:8)
Block(-7,13,2,CONCRETE:8)
Block(-7,13,3,CONCRETE:8)
Block(-7,13,4,CONCRETE:8)
Block(-7,13,5,CONCRETE:8)
Block(-7,13,6,CONCRETE:8)
Block(-7,13,7,CONCRETE:8)
Block(-7,13,8,CONCRETE:8)
Block(-7,14,-7,CONCRETE:8)
Block(-7,14,-6,CONCRETE:8)
Block(-7,14,-5,CONCRETE:8)
Block(-7,14,-4,CONCRETE:8)
Block(-7,14,-3,CONCRETE:8)
Block(-7,14,-2,CONCRETE:8)
Block(-7,14,-1,CONCRETE:8)
Block(-7,14,0,CONCRETE:8)
Block(-7,14,1,CONCRETE:8)
Block(-7,14,2,CONCRETE:8)
Block(-7,14,3,CONCRETE:8)
Block(-7,14,4,CONCRETE:8)
Block(-7,14,5,CONCRETE:8)
Block(-7,14,6,CONCRETE:8)
Block(-7,14,7,CONCRETE:8)
Block(-7,14,8,CONCRETE:8)
RandomBlock(-7,15,-7,CONCRETE:7,60,quark:iron_plate:1,20,STAINED_CLAY:12,15,STAINED_CLAY:15,5,AIR,7,IRON_BARS,12,CONCRETE:7,100)
RandomBlock(-7,15,-6,CONCRETE:7,60,quark:iron_plate:1,20,STAINED_CLAY:12,15,STAINED_CLAY:15,5,AIR,7,IRON_BARS,12,CONCRETE:7,100)
RandomBlock(-7,15,-5,CONCRETE:7,60,quark:iron_plate:1,20,STAINED_CLAY:12,15,STAINED_CLAY:15,5,AIR,7,IRON_BARS,12,CONCRETE:7,100)
RandomBlock(-7,15,-4,CONCRETE:7,60,quark:iron_plate:1,20,STAINED_CLAY:12,15,STAINED_CLAY:15,5,AIR,7,IRON_BARS,12,CONCRETE:7,100)
RandomBlock(-7,15,-3,CONCRETE:7,60,quark:iron_plate:1,20,STAINED_CLAY:12,15,STAINED_CLAY:15,5,AIR,7,IRON_BARS,12,CONCRETE:7,100)
RandomBlock(-7,15,-2,CONCRETE:7,60,quark:iron_plate:1,20,STAINED_CLAY:12,15,STAINED_CLAY:15,5,AIR,7,IRON_BARS,12,CONCRETE:7,100)
RandomBlock(-7,15,-1,CONCRETE:7,60,quark:iron_plate:1,20,STAINED_CLAY:12,15,STAINED_CLAY:15,5,AIR,7,IRON_BARS,12,CONCRETE:7,100)
RandomBlock(-7,15,0,CONCRETE:7,60,quark:iron_plate:1,20,STAINED_CLAY:12,15,STAINED_CLAY:15,5,AIR,7,IRON_BARS,12,CONCRETE:7,100)
RandomBlock(-7,15,1,CONCRETE:7,60,quark:iron_plate:1,20,STAINED_CLAY:12,15,STAINED_CLAY:15,5,AIR,7,IRON_BARS,12,CONCRETE:7,100)
RandomBlock(-7,15,2,CONCRETE:7,60,quark:iron_plate:1,20,STAINED_CLAY:12,15,STAINED_CLAY:15,5,AIR,7,IRON_BARS,12,CONCRETE:7,100)
RandomBlock(-7,15,3,CONCRETE:7,60,quark:iron_plate:1,20,STAINED_CLAY:12,15,STAINED_CLAY:15,5,AIR,7,IRON_BARS,12,CONCRETE:7,100)
RandomBlock(-7,15,4,CONCRETE:7,60,quark:iron_plate:1,20,STAINED_CLAY:12,15,STAINED_CLAY:15,5,AIR,7,IRON_BARS,12,CONCRETE:7,100)
RandomBlock(-7,15,5,CONCRETE:7,60,quark:iron_plate:1,20,STAINED_CLAY:12,15,STAINED_CLAY:15,5,AIR,7,IRON_BARS,12,CONCRETE:7,100)
RandomBlock(-7,15,6,CONCRETE:7,60,quark:iron_plate:1,20,STAINED_CLAY:12,15,STAINED_CLAY:15,5,AIR,7,IRON_BARS,12,CONCRETE:7,100)
RandomBlock(-7,15,7,CONCRETE:7,60,quark:iron_plate:1,20,STAINED_CLAY:12,15,STAINED_CLAY:15,5,AIR,7,IRON_BARS,12,CONCRETE:7,100)
RandomBlock(-7,15,8,CONCRETE:7,60,quark:iron_plate:1,20,STAINED_CLAY:12,15,STAINED_CLAY:15,5,AIR,7,IRON_BARS,12,CONCRETE:7,100)
Block(-7,16,-7,CONCRETE:15)
Block(-7,16,-6,CONCRETE:15)
Block(-7,16,-5,CONCRETE:15)
Block(-7,16,-4,CONCRETE:15)
Block(-7,16,-3,CONCRETE:15)
Block(-7,16,-2,CONCRETE:15)
Block(-7,16,-1,CONCRETE:15)
Block(-7,16,0,CONCRETE:15)
Block(-7,16,1,CONCRETE:15)
Block(-7,16,2,CONCRETE:15)
Block(-7,16,3,CONCRETE:15)
Block(-7,16,4,CONCRETE:15)
Block(-7,16,5,CONCRETE:15)
Block(-7,16,6,CONCRETE:15)
Block(-7,16,7,CONCRETE:15)
Block(-7,16,8,CONCRETE:15)
Block(-7,17,-7,CONCRETE:15)
Block(-7,17,-6,PRISMARINE:0)
Block(-7,17,-5,CONCRETE:8)
Block(-7,17,-4,CONCRETE:8)
Block(-7,17,-3,CONCRETE:8)
Block(-7,17,-2,CONCRETE:8)
Block(-7,17,-1,CONCRETE:8)
Block(-7,17,0,CONCRETE:8)
Block(-7,17,1,CONCRETE:8)
Block(-7,17,2,CONCRETE:15)
Block(-7,17,3,CONCRETE:15)
Block(-7,17,4,PRISMARINE:0)
Block(-7,17,5,CONCRETE:8)
Block(-7,17,6,CONCRETE:8)
Block(-7,17,7,CONCRETE:8)
Block(-7,17,8,CONCRETE:8)
Block(-7,18,-5,STAINED_GLASS_PANE:15)
Block(-7,18,-4,STEP:15)
Block(-7,18,-1,STAINED_GLASS_PANE:15)
Block(-7,18,6,STAINED_GLASS:15)
Block(-7,19,-5,STAINED_GLASS_PANE:15)
Block(-7,19,-3,QUARTZ_STAIRS:2)
Block(-7,19,-2,STEP:15)
Block(-7,19,-1,STAINED_GLASS_PANE:15)
Block(-7,19,0,STEP:15)
Block(-7,19,6,STAINED_GLASS:15)
Block(-7,20,-5,STAINED_GLASS_PANE:15)
Block(-7,20,-1,STAINED_GLASS_PANE:15)
Block(-7,20,0,STEP:15)
Block(-7,20,6,STAINED_GLASS:15)
Block(-7,21,-5,STAINED_GLASS_PANE:15)
Block(-7,21,-1,STAINED_GLASS_PANE:15)
Block(-7,21,0,STEP:15)
Block(-7,21,6,STAINED_GLASS:15)
Block(-7,22,-5,STAINED_GLASS_PANE:15)
Block(-7,22,-4,STEP:15)
Block(-7,22,-1,STAINED_GLASS_PANE:15)
Block(-7,22,0,STEP:15)
Block(-7,22,6,STAINED_GLASS:15)
Block(-7,23,-5,STAINED_GLASS_PANE:15)
Block(-7,23,-3,QUARTZ_STAIRS:2)
Block(-7,23,-2,STEP:15)
Block(-7,23,-1,STAINED_GLASS_PANE:15)
Block(-7,23,0,STEP:15)
Block(-7,23,6,STAINED_GLASS:15)
Block(-7,24,-5,STAINED_GLASS_PANE:15)
Block(-7,24,-1,STAINED_GLASS_PANE:15)
Block(-7,24,2,STEP:15)
Block(-7,24,4,STEP:15)
Block(-7,24,6,STAINED_GLASS:15)
Block(-7,25,-7,CONCRETE:8)
Block(-7,25,-6,CONCRETE:8)
Block(-7,25,-5,CONCRETE:8)
Block(-7,25,-1,CONCRETE:8)
Block(-7,25,0,CONCRETE:8)
Block(-7,25,1,CONCRETE:8)
Block(-7,25,2,CONCRETE:8)
Block(-7,25,3,CONCRETE:8)
Block(-7,25,4,CONCRETE:8)
Block(-7,25,5,CONCRETE:8)
Block(-7,25,6,CONCRETE:8)
Block(-7,25,7,CONCRETE:8)
Block(-7,25,8,CONCRETE:8)
Block(-7,26,-5,STAINED_GLASS_PANE:15)
Block(-7,26,-4,STEP:15)
Block(-7,26,-1,CONCRETE:0)
Block(-7,26,0,CONCRETE:0)
Block(-7,26,1,CONCRETE:0)
Block(-7,26,2,CONCRETE:0)
Block(-7,26,3,CONCRETE:0)
Block(-7,26,6,STAINED_GLASS:15)
Block(-7,27,-5,STAINED_GLASS_PANE:15)
Block(-7,27,-3,QUARTZ_STAIRS:2)
Block(-7,27,-2,STEP:15)
Block(-7,27,-1,CONCRETE:0)
Block(-7,27,0,CONCRETE:0)
Block(-7,27,1,CONCRETE:0)
Block(-7,27,2,CONCRETE:0)
Block(-7,27,3,CONCRETE:0)
Block(-7,27,6,STAINED_GLASS:15)
Block(-7,28,-1,CONCRETE:0)
Block(-7,28,0,CONCRETE:0)
Block(-7,28,1,CONCRETE:0)
Block(-7,28,2,CONCRETE:0)
Block(-7,28,3,CONCRETE:0)
Block(-7,28,6,STAINED_GLASS:15)
Block(-7,29,-7,STEP:15)
Block(-7,29,-6,STEP:15)
Block(-7,29,-5,STEP:15)
Block(-7,29,-1,CONCRETE:8)
Block(-7,29,0,CONCRETE:8)
Block(-7,29,1,CONCRETE:8)
Block(-7,29,2,CONCRETE:8)
Block(-7,29,3,CONCRETE:8)
Block(-7,29,4,STEP:15)
Block(-7,29,5,STEP:15)
Block(-7,29,6,CONCRETE:8)
Block(-7,29,7,CONCRETE:8)
Block(-7,29,8,CONCRETE:8)
Block(-7,30,-5,STAINED_GLASS_PANE:15)
Block(-7,30,-4,STEP:15)
Block(-7,30,-1,CONCRETE:0)
Block(-7,30,0,CONCRETE:0)
Block(-7,30,1,CONCRETE:0)
Block(-7,30,2,CONCRETE:0)
Block(-7,30,3,CONCRETE:0)
Block(-7,30,6,STAINED_GLASS:15)
Block(-7,31,-5,STAINED_GLASS_PANE:15)
Block(-7,31,-3,QUARTZ_STAIRS:2)
Block(-7,31,-2,STEP:15)
Block(-7,31,-1,CONCRETE:0)
Block(-7,31,0,CONCRETE:0)
Block(-7,31,1,CONCRETE:0)
Block(-7,31,2,CONCRETE:0)
Block(-7,31,3,CONCRETE:0)
Block(-7,31,6,STAINED_GLASS:15)
Block(-7,32,-1,CONCRETE:0)
Block(-7,32,0,CONCRETE:0)
Block(-7,32,1,CONCRETE:0)
Block(-7,32,2,CONCRETE:0)
Block(-7,32,3,CONCRETE:0)
Block(-7,32,6,STAINED_GLASS:15)
Block(-7,33,-7,STEP:15)
Block(-7,33,-6,STEP:15)
Block(-7,33,-5,STEP:15)
Block(-7,33,-1,CONCRETE:8)
Block(-7,33,0,CONCRETE:8)
Block(-7,33,1,CONCRETE:8)
Block(-7,33,2,CONCRETE:8)
Block(-7,33,3,CONCRETE:8)
Block(-7,33,4,STEP:15)
Block(-7,33,5,STEP:15)
Block(-7,33,6,CONCRETE:8)
Block(-7,33,7,CONCRETE:8)
Block(-7,33,8,CONCRETE:8)
Block(-7,34,-5,STAINED_GLASS_PANE:15)
Block(-7,34,-4,STEP:15)
Block(-7,34,-1,CONCRETE:0)
Block(-7,34,0,CONCRETE:0)
Block(-7,34,1,CONCRETE:0)
Block(-7,34,2,CONCRETE:0)
Block(-7,34,3,CONCRETE:0)
Block(-7,34,6,STAINED_GLASS:15)
Block(-7,35,-5,STAINED_GLASS_PANE:15)
Block(-7,35,-3,QUARTZ_STAIRS:2)
Block(-7,35,-2,STEP:15)
Block(-7,35,-1,CONCRETE:0)
Block(-7,35,0,CONCRETE:0)
Block(-7,35,1,CONCRETE:0)
Block(-7,35,2,CONCRETE:0)
Block(-7,35,3,CONCRETE:0)
Block(-7,35,6,STAINED_GLASS:15)
Block(-7,36,-1,CONCRETE:0)
Block(-7,36,0,CONCRETE:0)
Block(-7,36,1,CONCRETE:0)
Block(-7,36,2,CONCRETE:0)
Block(-7,36,3,CONCRETE:0)
Block(-7,36,6,STAINED_GLASS:15)
Block(-7,37,-7,STEP:15)
Block(-7,37,-6,STEP:15)
Block(-7,37,-5,STEP:15)
Block(-7,37,-1,CONCRETE:8)
Block(-7,37,0,CONCRETE:8)
Block(-7,37,1,CONCRETE:8)
Block(-7,37,2,CONCRETE:8)
Block(-7,37,3,CONCRETE:8)
Block(-7,37,4,STEP:15)
Block(-7,37,5,STEP:15)
Block(-7,37,6,CONCRETE:8)
Block(-7,37,7,CONCRETE:8)
Block(-7,37,8,CONCRETE:8)
Block(-7,38,-5,STAINED_GLASS_PANE:15)
Block(-7,38,-4,STEP:15)
Block(-7,38,-1,CONCRETE:0)
Block(-7,38,0,CONCRETE:0)
Block(-7,38,1,CONCRETE:0)
Block(-7,38,2,CONCRETE:0)
Block(-7,38,3,CONCRETE:0)
Block(-7,38,6,STAINED_GLASS:15)
Block(-7,39,-5,STAINED_GLASS_PANE:15)
Block(-7,39,-3,QUARTZ_STAIRS:2)
Block(-7,39,-2,STEP:15)
Block(-7,39,-1,CONCRETE:0)
Block(-7,39,0,CONCRETE:0)
Block(-7,39,1,CONCRETE:0)
Block(-7,39,2,CONCRETE:0)
Block(-7,39,3,CONCRETE:0)
Block(-7,39,6,STAINED_GLASS:15)
Block(-7,40,-1,CONCRETE:0)
Block(-7,40,0,CONCRETE:0)
Block(-7,40,1,CONCRETE:0)
Block(-7,40,2,CONCRETE:0)
Block(-7,40,3,CONCRETE:0)
Block(-7,40,6,STAINED_GLASS:15)
Block(-7,41,-7,STEP:15)
Block(-7,41,-6,STEP:15)
Block(-7,41,-5,STEP:15)
Block(-7,41,-1,CONCRETE:8)
Block(-7,41,0,CONCRETE:8)
Block(-7,41,1,CONCRETE:8)
Block(-7,41,2,CONCRETE:8)
Block(-7,41,3,CONCRETE:8)
Block(-7,41,4,STEP:15)
Block(-7,41,5,STEP:15)
Block(-7,41,6,CONCRETE:8)
Block(-7,41,7,CONCRETE:8)
Block(-7,41,8,CONCRETE:8)
Block(-7,42,-5,STAINED_GLASS_PANE:15)
Block(-7,42,-4,STEP:15)
Block(-7,42,-1,CONCRETE:0)
Block(-7,42,0,CONCRETE:0)
Block(-7,42,1,CONCRETE:0)
Block(-7,42,2,CONCRETE:0)
Block(-7,42,3,CONCRETE:0)
Block(-7,42,6,STAINED_GLASS:15)
Block(-7,43,-5,STAINED_GLASS_PANE:15)
Block(-7,43,-3,QUARTZ_STAIRS:2)
Block(-7,43,-2,STEP:15)
Block(-7,43,-1,CONCRETE:0)
Block(-7,43,0,CONCRETE:0)
Block(-7,43,1,CONCRETE:0)
Block(-7,43,2,CONCRETE:0)
Block(-7,43,3,CONCRETE:0)
Block(-7,43,6,STAINED_GLASS:15)
Block(-7,44,-1,CONCRETE:0)
Block(-7,44,0,CONCRETE:0)
Block(-7,44,1,CONCRETE:0)
Block(-7,44,2,CONCRETE:0)
Block(-7,44,3,CONCRETE:0)
Block(-7,44,6,STAINED_GLASS:15)
Block(-7,45,-7,STEP:15)
Block(-7,45,-6,STEP:15)
Block(-7,45,-5,STEP:15)
Block(-7,45,-1,CONCRETE:8)
Block(-7,45,0,CONCRETE:8)
Block(-7,45,1,CONCRETE:8)
Block(-7,45,2,CONCRETE:8)
Block(-7,45,3,CONCRETE:8)
Block(-7,45,4,STEP:15)
Block(-7,45,5,STEP:15)
Block(-7,45,6,CONCRETE:8)
Block(-7,45,7,CONCRETE:8)
Block(-7,45,8,CONCRETE:8)
Block(-7,46,-5,STAINED_GLASS_PANE:15)
Block(-7,46,-4,STEP:15)
Block(-7,46,-1,CONCRETE:0)
Block(-7,46,0,CONCRETE:0)
Block(-7,46,1,CONCRETE:0)
Block(-7,46,2,CONCRETE:0)
Block(-7,46,3,CONCRETE:0)
Block(-7,46,6,STAINED_GLASS:15)
Block(-7,47,-5,STAINED_GLASS_PANE:15)
Block(-7,47,-3,QUARTZ_STAIRS:2)
Block(-7,47,-2,STEP:15)
Block(-7,47,-1,CONCRETE:0)
Block(-7,47,0,CONCRETE:0)
Block(-7,47,1,CONCRETE:0)
Block(-7,47,2,CONCRETE:0)
Block(-7,47,3,CONCRETE:0)
Block(-7,47,6,STAINED_GLASS:15)
Block(-7,48,-1,CONCRETE:0)
Block(-7,48,0,CONCRETE:0)
Block(-7,48,1,CONCRETE:0)
Block(-7,48,2,CONCRETE:0)
Block(-7,48,3,CONCRETE:0)
Block(-7,48,6,STAINED_GLASS:15)
Block(-7,49,-7,STEP:15)
Block(-7,49,-6,STEP:15)
Block(-7,49,-5,STEP:15)
Block(-7,49,-1,CONCRETE:8)
Block(-7,49,0,CONCRETE:8)
Block(-7,49,1,CONCRETE:8)
Block(-7,49,2,CONCRETE:8)
Block(-7,49,3,CONCRETE:8)
Block(-7,49,4,STEP:15)
Block(-7,49,5,STEP:15)
Block(-7,49,6,CONCRETE:8)
Block(-7,49,7,CONCRETE:8)
Block(-7,49,8,CONCRETE:8)
Block(-7,50,-5,STAINED_GLASS_PANE:15)
Block(-7,50,-4,STEP:15)
Block(-7,50,-1,CONCRETE:0)
Block(-7,50,0,CONCRETE:0)
Block(-7,50,1,CONCRETE:0)
Block(-7,50,2,CONCRETE:0)
Block(-7,50,3,CONCRETE:0)
Block(-7,50,6,STAINED_GLASS:15)
Block(-7,51,-5,STAINED_GLASS_PANE:15)
Block(-7,51,-3,QUARTZ_STAIRS:2)
Block(-7,51,-2,STEP:15)
Block(-7,51,-1,CONCRETE:0)
Block(-7,51,0,CONCRETE:0)
Block(-7,51,1,CONCRETE:0)
Block(-7,51,2,CONCRETE:0)
Block(-7,51,3,CONCRETE:0)
Block(-7,51,6,STAINED_GLASS:15)
Block(-7,52,-1,CONCRETE:0)
Block(-7,52,0,CONCRETE:0)
Block(-7,52,1,CONCRETE:0)
Block(-7,52,2,CONCRETE:0)
Block(-7,52,3,CONCRETE:0)
Block(-7,52,6,STAINED_GLASS:15)
Block(-7,53,-7,STEP:15)
Block(-7,53,-6,STEP:15)
Block(-7,53,-5,STEP:15)
Block(-7,53,-1,CONCRETE:8)
Block(-7,53,0,CONCRETE:8)
Block(-7,53,1,CONCRETE:8)
Block(-7,53,2,CONCRETE:8)
Block(-7,53,3,CONCRETE:8)
Block(-7,53,4,STEP:15)
Block(-7,53,5,STEP:15)
Block(-7,53,6,CONCRETE:8)
Block(-7,53,7,CONCRETE:8)
Block(-7,53,8,CONCRETE:8)
Block(-7,54,-5,STAINED_GLASS_PANE:15)
Block(-7,54,-4,STEP:15)
Block(-7,54,-1,CONCRETE:0)
Block(-7,54,0,CONCRETE:0)
Block(-7,54,1,CONCRETE:0)
Block(-7,54,2,CONCRETE:0)
Block(-7,54,3,CONCRETE:0)
Block(-7,54,6,STAINED_GLASS:15)
Block(-7,55,-5,STAINED_GLASS_PANE:15)
Block(-7,55,-3,QUARTZ_STAIRS:2)
Block(-7,55,-2,STEP:15)
Block(-7,55,-1,CONCRETE:0)
Block(-7,55,0,CONCRETE:0)
Block(-7,55,1,CONCRETE:0)
Block(-7,55,2,CONCRETE:0)
Block(-7,55,3,CONCRETE:0)
Block(-7,55,6,STAINED_GLASS:15)
Block(-7,56,-1,CONCRETE:0)
Block(-7,56,0,CONCRETE:0)
Block(-7,56,1,CONCRETE:0)
Block(-7,56,2,CONCRETE:0)
Block(-7,56,3,CONCRETE:0)
Block(-7,56,6,STAINED_GLASS:15)
Block(-7,57,-7,STEP:15)
Block(-7,57,-6,STEP:15)
Block(-7,57,-5,STEP:15)
Block(-7,57,-1,CONCRETE:8)
Block(-7,57,0,CONCRETE:8)
Block(-7,57,1,CONCRETE:8)
Block(-7,57,2,CONCRETE:8)
Block(-7,57,3,CONCRETE:8)
Block(-7,57,4,STEP:15)
Block(-7,57,5,STEP:15)
Block(-7,57,6,CONCRETE:8)
Block(-7,57,7,CONCRETE:8)
Block(-7,57,8,CONCRETE:8)
Block(-7,58,-5,STAINED_GLASS_PANE:15)
Block(-7,58,-4,STEP:15)
Block(-7,58,-1,CONCRETE:0)
Block(-7,58,0,CONCRETE:0)
Block(-7,58,1,CONCRETE:0)
Block(-7,58,2,CONCRETE:0)
Block(-7,58,3,CONCRETE:0)
Block(-7,58,6,STAINED_GLASS:15)
Block(-7,59,-5,STAINED_GLASS_PANE:15)
Block(-7,59,-3,QUARTZ_STAIRS:2)
Block(-7,59,-2,STEP:15)
Block(-7,59,-1,CONCRETE:0)
Block(-7,59,0,CONCRETE:0)
Block(-7,59,1,CONCRETE:0)
Block(-7,59,2,CONCRETE:0)
Block(-7,59,3,CONCRETE:0)
Block(-7,59,6,STAINED_GLASS:15)
Block(-7,60,-1,CONCRETE:0)
Block(-7,60,0,CONCRETE:0)
Block(-7,60,1,CONCRETE:0)
Block(-7,60,2,CONCRETE:0)
Block(-7,60,3,CONCRETE:0)
Block(-7,60,6,STAINED_GLASS:15)
Block(-7,61,-7,STEP:15)
Block(-7,61,-6,STEP:15)
Block(-7,61,-5,STEP:15)
Block(-7,61,-1,CONCRETE:8)
Block(-7,61,0,CONCRETE:8)
Block(-7,61,1,CONCRETE:8)
Block(-7,61,2,CONCRETE:8)
Block(-7,61,3,CONCRETE:8)
Block(-7,61,4,STEP:15)
Block(-7,61,5,STEP:15)
Block(-7,61,6,CONCRETE:8)
Block(-7,61,7,CONCRETE:8)
Block(-7,61,8,CONCRETE:8)
Block(-7,62,-5,STAINED_GLASS_PANE:15)
Block(-7,62,-4,STEP:15)
Block(-7,62,-1,CONCRETE:0)
Block(-7,62,0,CONCRETE:0)
Block(-7,62,1,CONCRETE:0)
Block(-7,62,2,CONCRETE:0)
Block(-7,62,3,CONCRETE:0)
Block(-7,62,6,STAINED_GLASS:15)
Block(-7,63,-5,STAINED_GLASS_PANE:15)
Block(-7,63,-3,QUARTZ_STAIRS:2)
Block(-7,63,-2,STEP:15)
Block(-7,63,-1,CONCRETE:0)
Block(-7,63,0,CONCRETE:0)
Block(-7,63,1,CONCRETE:0)
Block(-7,63,2,CONCRETE:0)
Block(-7,63,3,CONCRETE:0)
Block(-7,63,6,STAINED_GLASS:15)
Block(-7,64,-1,CONCRETE:0)
Block(-7,64,0,CONCRETE:0)
Block(-7,64,1,CONCRETE:0)
Block(-7,64,2,CONCRETE:0)
Block(-7,64,3,CONCRETE:0)
Block(-7,64,6,STAINED_GLASS:15)
Block(-7,65,-7,STEP:15)
Block(-7,65,-6,STEP:15)
Block(-7,65,-5,STEP:15)
Block(-7,65,-1,CONCRETE:8)
Block(-7,65,0,CONCRETE:8)
Block(-7,65,1,CONCRETE:8)
Block(-7,65,2,CONCRETE:8)
Block(-7,65,3,CONCRETE:8)
Block(-7,65,4,STEP:15)
Block(-7,65,5,STEP:15)
Block(-7,65,6,CONCRETE:8)
Block(-7,65,7,CONCRETE:8)
Block(-7,65,8,CONCRETE:8)
Block(-7,66,-5,STAINED_GLASS_PANE:15)
Block(-7,66,-4,STEP:15)
Block(-7,66,-1,CONCRETE:0)
Block(-7,66,0,CONCRETE:0)
Block(-7,66,1,CONCRETE:0)
Block(-7,66,2,CONCRETE:0)
Block(-7,66,3,CONCRETE:0)
Block(-7,66,6,STAINED_GLASS:15)
Block(-7,67,-5,STAINED_GLASS_PANE:15)
Block(-7,67,-3,QUARTZ_STAIRS:2)
Block(-7,67,-2,STEP:15)
Block(-7,67,-1,CONCRETE:0)
Block(-7,67,0,CONCRETE:0)
Block(-7,67,1,CONCRETE:0)
Block(-7,67,2,CONCRETE:0)
Block(-7,67,3,CONCRETE:0)
Block(-7,67,6,STAINED_GLASS:15)
Block(-7,68,-1,CONCRETE:0)
Block(-7,68,0,CONCRETE:0)
Block(-7,68,1,CONCRETE:0)
Block(-7,68,2,CONCRETE:0)
Block(-7,68,3,CONCRETE:0)
Block(-7,68,6,STAINED_GLASS:15)
Block(-7,69,-7,STEP:15)
Block(-7,69,-6,STEP:15)
Block(-7,69,-5,STEP:15)
Block(-7,69,-1,CONCRETE:8)
Block(-7,69,0,CONCRETE:8)
Block(-7,69,1,CONCRETE:8)
Block(-7,69,2,CONCRETE:8)
Block(-7,69,3,CONCRETE:8)
Block(-7,69,4,STEP:15)
Block(-7,69,5,STEP:15)
Block(-7,69,6,CONCRETE:8)
Block(-7,69,7,CONCRETE:8)
Block(-7,69,8,CONCRETE:8)
Block(-7,70,-5,STAINED_GLASS_PANE:15)
Block(-7,70,-4,STEP:15)
Block(-7,70,-1,CONCRETE:0)
Block(-7,70,0,CONCRETE:0)
Block(-7,70,1,CONCRETE:0)
Block(-7,70,2,CONCRETE:0)
Block(-7,70,3,CONCRETE:0)
Block(-7,70,6,STAINED_GLASS:15)
Block(-7,71,-5,STAINED_GLASS_PANE:15)
Block(-7,71,-3,QUARTZ_STAIRS:2)
Block(-7,71,-2,STEP:15)
Block(-7,71,-1,CONCRETE:0)
Block(-7,71,0,CONCRETE:0)
Block(-7,71,1,CONCRETE:0)
Block(-7,71,2,CONCRETE:0)
Block(-7,71,3,CONCRETE:0)
Block(-7,71,6,STAINED_GLASS:15)
Block(-7,72,-1,CONCRETE:0)
Block(-7,72,0,CONCRETE:0)
Block(-7,72,1,CONCRETE:0)
Block(-7,72,2,CONCRETE:0)
Block(-7,72,3,CONCRETE:0)
Block(-7,72,6,STAINED_GLASS:15)
Block(-7,73,-7,STEP:15)
Block(-7,73,-6,STEP:15)
Block(-7,73,-5,STEP:15)
Block(-7,73,-1,CONCRETE:8)
Block(-7,73,0,CONCRETE:8)
Block(-7,73,1,CONCRETE:8)
Block(-7,73,2,CONCRETE:8)
Block(-7,73,3,CONCRETE:8)
Block(-7,73,4,STEP:15)
Block(-7,73,5,STEP:15)
Block(-7,73,6,CONCRETE:8)
Block(-7,73,7,CONCRETE:8)
Block(-7,73,8,CONCRETE:8)
Block(-7,74,-5,STAINED_GLASS_PANE:15)
Block(-7,74,-4,STEP:15)
Block(-7,74,-1,CONCRETE:0)
Block(-7,74,0,CONCRETE:0)
Block(-7,74,1,CONCRETE:0)
Block(-7,74,2,CONCRETE:0)
Block(-7,74,3,CONCRETE:0)
Block(-7,74,6,STAINED_GLASS:15)
Block(-7,75,-5,STAINED_GLASS_PANE:15)
Block(-7,75,-3,QUARTZ_STAIRS:2)
Block(-7,75,-2,STEP:15)
Block(-7,75,-1,CONCRETE:0)
Block(-7,75,0,CONCRETE:0)
Block(-7,75,1,CONCRETE:0)
Block(-7,75,2,CONCRETE:0)
Block(-7,75,3,CONCRETE:0)
Block(-7,75,6,STAINED_GLASS:15)
Block(-7,76,-1,CONCRETE:0)
Block(-7,76,0,CONCRETE:0)
Block(-7,76,1,CONCRETE:0)
Block(-7,76,2,CONCRETE:0)
Block(-7,76,3,CONCRETE:0)
Block(-7,76,6,STAINED_GLASS:15)
Block(-7,77,-7,CONCRETE:8)
Block(-7,77,-6,CONCRETE:8)
Block(-7,77,-5,CONCRETE:8)
Block(-7,77,-1,CONCRETE:8)
Block(-7,77,0,CONCRETE:8)
Block(-7,77,1,CONCRETE:8)
Block(-7,77,2,CONCRETE:8)
Block(-7,77,3,CONCRETE:8)
Block(-7,77,4,CONCRETE:8)
Block(-7,77,5,CONCRETE:8)
Block(-7,77,6,CONCRETE:8)
Block(-7,77,7,CONCRETE:8)
Block(-7,77,8,CONCRETE:8)
Block(-7,78,-7,CONCRETE:8)
Block(-7,78,-6,CONCRETE:8)
Block(-7,78,-5,CONCRETE:8)
Block(-7,78,-4,STEP:15)
Block(-7,78,-1,CONCRETE:8)
Block(-7,78,0,CONCRETE:8)
Block(-7,78,1,CONCRETE:8)
Block(-7,78,2,CONCRETE:8)
Block(-7,78,3,CONCRETE:15)
Block(-7,79,-6,STEP:7)
Block(-7,79,-5,CONCRETE:15)
Block(-7,79,-1,CONCRETE:15)
Block(-7,79,0,STEP:7)
Block(-7,79,3,IRON_FENCE:0)
Block(-7,80,-6,STEP:7)
Block(-7,80,-5,CONCRETE:15)
Block(-7,80,-1,CONCRETE:15)
Block(-7,80,0,STEP:7)
Block(-7,81,-6,QUARTZ_STAIRS:0)
Block(-7,81,-5,CONCRETE:15)
Block(-7,81,-1,CONCRETE:15)
Block(-7,82,-6,STEP:7)
Block(-7,82,-5,CONCRETE:15)
Block(-7,82,-4,STAINED_GLASS:10)
Block(-7,82,-3,STAINED_GLASS:10)
Block(-7,82,-2,STAINED_GLASS:10)
Block(-7,82,-1,CONCRETE:15)
Block(-7,83,-6,STEP:7)
Block(-7,83,-5,STEP:7)
RandomBlock(-7,83,-4,AIR,90,IRON_TRAPDOOR:1,100)
RandomBlock(-7,83,-3,AIR,90,IRON_TRAPDOOR:3,100)
RandomBlock(-7,83,-2,AIR,90,IRON_TRAPDOOR:2,100)
Block(-7,83,-1,STEP:7)
Block(-7,83,0,STEP:7)
RandomBlock(-6,0,-7,CONCRETE:7,60,quark:iron_plate:1,20,STAINED_CLAY:12,15,STAINED_CLAY:15,5,AIR,7,IRON_BARS,12,CONCRETE:7,100)
RandomBlock(-6,0,-6,CONCRETE:7,60,quark:iron_plate:1,20,STAINED_CLAY:12,15,STAINED_CLAY:15,5,AIR,7,IRON_BARS,12,CONCRETE:7,100)
RandomBlock(-6,0,-5,CONCRETE:7,60,quark:iron_plate:1,20,STAINED_CLAY:12,15,STAINED_CLAY:15,5,AIR,7,IRON_BARS,12,CONCRETE:7,100)
RandomBlock(-6,0,-4,CONCRETE:7,60,quark:iron_plate:1,20,STAINED_CLAY:12,15,STAINED_CLAY:15,5,AIR,7,IRON_BARS,12,CONCRETE:7,100)
RandomBlock(-6,0,-3,CONCRETE:7,60,quark:iron_plate:1,20,STAINED_CLAY:12,15,STAINED_CLAY:15,5,AIR,7,IRON_BARS,12,CONCRETE:7,100)
RandomBlock(-6,0,-2,CONCRETE:7,60,quark:iron_plate:1,20,STAINED_CLAY:12,15,STAINED_CLAY:15,5,AIR,7,IRON_BARS,12,CONCRETE:7,100)
RandomBlock(-6,0,-1,CONCRETE:7,60,quark:iron_plate:1,20,STAINED_CLAY:12,15,STAINED_CLAY:15,5,AIR,7,IRON_BARS,12,CONCRETE:7,100)
RandomBlock(-6,0,0,CONCRETE:7,60,quark:iron_plate:1,20,STAINED_CLAY:12,15,STAINED_CLAY:15,5,AIR,7,IRON_BARS,12,CONCRETE:7,100)
RandomBlock(-6,0,1,CONCRETE:7,60,quark:iron_plate:1,20,STAINED_CLAY:12,15,STAINED_CLAY:15,5,AIR,7,IRON_BARS,12,CONCRETE:7,100)
RandomBlock(-6,0,2,CONCRETE:7,60,quark:iron_plate:1,20,STAINED_CLAY:12,15,STAINED_CLAY:15,5,AIR,7,IRON_BARS,12,CONCRETE:7,100)
RandomBlock(-6,0,3,CONCRETE:7,60,quark:iron_plate:1,20,STAINED_CLAY:12,15,STAINED_CLAY:15,5,AIR,7,IRON_BARS,12,CONCRETE:7,100)
RandomBlock(-6,0,4,CONCRETE:7,60,quark:iron_plate:1,20,STAINED_CLAY:12,15,STAINED_CLAY:15,5,AIR,7,IRON_BARS,12,CONCRETE:7,100)
RandomBlock(-6,0,5,CONCRETE:7,60,quark:iron_plate:1,20,STAINED_CLAY:12,15,STAINED_CLAY:15,5,AIR,7,IRON_BARS,12,CONCRETE:7,100)
RandomBlock(-6,0,6,CONCRETE:7,60,quark:iron_plate:1,20,STAINED_CLAY:12,15,STAINED_CLAY:15,5,AIR,7,IRON_BARS,12,CONCRETE:7,100)
RandomBlock(-6,0,7,CONCRETE:7,60,quark:iron_plate:1,20,STAINED_CLAY:12,15,STAINED_CLAY:15,5,AIR,7,IRON_BARS,12,CONCRETE:7,100)
RandomBlock(-6,0,8,CONCRETE:7,60,quark:iron_plate:1,20,STAINED_CLAY:12,15,STAINED_CLAY:15,5,AIR,7,IRON_BARS,12,CONCRETE:7,100)
RandomBlock(-6,1,-7,CONCRETE:7,60,quark:iron_plate:1,20,STAINED_CLAY:12,15,STAINED_CLAY:15,5,AIR,7,IRON_BARS,12,CONCRETE:7,100)
RandomBlock(-6,1,-6,CONCRETE:7,60,quark:iron_plate:1,20,STAINED_CLAY:12,15,STAINED_CLAY:15,5,AIR,7,IRON_BARS,12,CONCRETE:7,100)
RandomBlock(-6,1,-5,CONCRETE:7,60,quark:iron_plate:1,20,STAINED_CLAY:12,15,STAINED_CLAY:15,5,AIR,7,IRON_BARS,12,CONCRETE:7,100)
RandomBlock(-6,1,-4,CONCRETE:7,60,quark:iron_plate:1,20,STAINED_CLAY:12,15,STAINED_CLAY:15,5,AIR,7,IRON_BARS,12,CONCRETE:7,100)
Block(-6,1,-3,STATIONARY_WATER:0)
Block(-6,1,-2,STATIONARY_WATER:0)
RandomBlock(-6,1,-1,CONCRETE:7,60,quark:iron_plate:1,20,STAINED_CLAY:12,15,STAINED_CLAY:15,5,AIR,7,IRON_BARS,12,CONCRETE:7,100)
RandomBlock(-6,1,0,CONCRETE:7,60,quark:iron_plate:1,20,STAINED_CLAY:12,15,STAINED_CLAY:15,5,AIR,7,IRON_BARS,12,CONCRETE:7,100)
RandomBlock(-6,1,1,CONCRETE:7,60,quark:iron_plate:1,20,STAINED_CLAY:12,15,STAINED_CLAY:15,5,AIR,7,IRON_BARS,12,CONCRETE:7,100)
RandomBlock(-6,1,2,CONCRETE:7,60,quark:iron_plate:1,20,STAINED_CLAY:12,15,STAINED_CLAY:15,5,AIR,7,IRON_BARS,12,CONCRETE:7,100)
RandomBlock(-6,1,3,CONCRETE:7,60,quark:iron_plate:1,20,STAINED_CLAY:12,15,STAINED_CLAY:15,5,AIR,7,IRON_BARS,12,CONCRETE:7,100)
RandomBlock(-6,1,4,CONCRETE:7,60,quark:iron_plate:1,20,STAINED_CLAY:12,15,STAINED_CLAY:15,5,AIR,7,IRON_BARS,12,CONCRETE:7,100)
RandomBlock(-6,1,5,CONCRETE:7,60,quark:iron_plate:1,20,STAINED_CLAY:12,15,STAINED_CLAY:15,5,AIR,7,IRON_BARS,12,CONCRETE:7,100)
RandomBlock(-6,1,6,CONCRETE:7,60,quark:iron_plate:1,20,STAINED_CLAY:12,15,STAINED_CLAY:15,5,AIR,7,IRON_BARS,12,CONCRETE:7,100)
RandomBlock(-6,1,7,CONCRETE:7,60,quark:iron_plate:1,20,STAINED_CLAY:12,15,STAINED_CLAY:15,5,AIR,7,IRON_BARS,12,CONCRETE:7,100)
RandomBlock(-6,1,8,CONCRETE:7,60,quark:iron_plate:1,20,STAINED_CLAY:12,15,STAINED_CLAY:15,5,AIR,7,IRON_BARS,12,CONCRETE:7,100)
RandomBlock(-6,2,-7,CONCRETE:7,60,quark:iron_plate:1,20,STAINED_CLAY:12,15,STAINED_CLAY:15,5,AIR,7,IRON_BARS,12,CONCRETE:7,100)
RandomBlock(-6,2,-6,CONCRETE:7,60,quark:iron_plate:1,20,STAINED_CLAY:12,15,STAINED_CLAY:15,5,AIR,7,IRON_BARS,12,CONCRETE:7,100)
RandomBlock(-6,2,-5,CONCRETE:7,60,quark:iron_plate:1,20,STAINED_CLAY:12,15,STAINED_CLAY:15,5,AIR,7,IRON_BARS,12,CONCRETE:7,100)
Block(-6,2,-4,SMOOTH_STAIRS:3)
Block(-6,2,-3,AIR:0)
Block(-6,2,-2,AIR:0)
Block(-6,2,-1,SMOOTH_STAIRS:2)
RandomBlock(-6,2,0,CONCRETE:7,60,quark:iron_plate:1,20,STAINED_CLAY:12,15,STAINED_CLAY:15,5,AIR,7,IRON_BARS,12,CONCRETE:7,100)
RandomBlock(-6,2,1,CONCRETE:7,60,quark:iron_plate:1,20,STAINED_CLAY:12,15,STAINED_CLAY:15,5,AIR,7,IRON_BARS,12,CONCRETE:7,100)
RandomBlock(-6,2,2,CONCRETE:7,60,quark:iron_plate:1,20,STAINED_CLAY:12,15,STAINED_CLAY:15,5,AIR,7,IRON_BARS,12,CONCRETE:7,100)
RandomBlock(-6,2,3,CONCRETE:7,60,quark:iron_plate:1,20,STAINED_CLAY:12,15,STAINED_CLAY:15,5,AIR,7,IRON_BARS,12,CONCRETE:7,100)
RandomBlock(-6,2,4,CONCRETE:7,60,quark:iron_plate:1,20,STAINED_CLAY:12,15,STAINED_CLAY:15,5,AIR,7,IRON_BARS,12,CONCRETE:7,100)
RandomBlock(-6,2,5,CONCRETE:7,60,quark:iron_plate:1,20,STAINED_CLAY:12,15,STAINED_CLAY:15,5,AIR,7,IRON_BARS,12,CONCRETE:7,100)
RandomBlock(-6,2,6,CONCRETE:7,60,quark:iron_plate:1,20,STAINED_CLAY:12,15,STAINED_CLAY:15,5,AIR,7,IRON_BARS,12,CONCRETE:7,100)
RandomBlock(-6,2,7,CONCRETE:7,60,quark:iron_plate:1,20,STAINED_CLAY:12,15,STAINED_CLAY:15,5,AIR,7,IRON_BARS,12,CONCRETE:7,100)
RandomBlock(-6,2,8,CONCRETE:7,60,quark:iron_plate:1,20,STAINED_CLAY:12,15,STAINED_CLAY:15,5,AIR,7,IRON_BARS,12,CONCRETE:7,100)
RandomBlock(-6,3,-7,CONCRETE:7,60,quark:iron_plate:1,20,STAINED_CLAY:12,15,STAINED_CLAY:15,5,AIR,7,IRON_BARS,12,CONCRETE:7,100)
Block(-6,3,-6,AIR:0)
Block(-6,3,-5,AIR:0)
Block(-6,3,-4,AIR:0)
Block(-6,3,-3,AIR:0)
Block(-6,3,-2,AIR:0)
Block(-6,3,-1,AIR:0)
Block(-6,3,0,AIR:0)
Block(-6,3,1,AIR:0)
Block(-6,3,2,AIR:0)
Block(-6,3,3,AIR:0)
Block(-6,3,4,AIR:0)
Block(-6,3,5,AIR:0)
Block(-6,3,6,AIR:0)
Block(-6,3,7,AIR:0)
Block(-6,3,8,AIR:0)
RandomBlock(-6,4,-7,CONCRETE:7,60,quark:iron_plate:1,20,STAINED_CLAY:12,15,STAINED_CLAY:15,5,AIR,7,IRON_BARS,12,CONCRETE:7,100)
Block(-6,4,-6,AIR:0)
Block(-6,4,-5,AIR:0)
Block(-6,4,-4,AIR:0)
Block(-6,4,-3,AIR:0)
Block(-6,4,-2,AIR:0)
Block(-6,4,-1,AIR:0)
Block(-6,4,0,AIR:0)
Block(-6,4,1,AIR:0)
Block(-6,4,2,AIR:0)
Block(-6,4,3,AIR:0)
Block(-6,4,4,AIR:0)
Block(-6,4,5,AIR:0)
Block(-6,4,6,AIR:0)
Block(-6,4,7,AIR:0)
Block(-6,4,8,STEP:8)
RandomBlock(-6,5,-7,CONCRETE:7,60,quark:iron_plate:1,20,STAINED_CLAY:12,15,STAINED_CLAY:15,5,AIR,7,IRON_BARS,12,CONCRETE:7,100)
Block(-6,5,-6,CONCRETE:4)
Block(-6,5,-5,CONCRETE:12)
Block(-6,5,-4,AIR:0)
Block(-6,5,-3,AIR:0)
Block(-6,5,-2,AIR:0)
Block(-6,5,-1,AIR:0)
Block(-6,5,0,AIR:0)
Block(-6,5,1,AIR:0)
Block(-6,5,2,AIR:0)
Block(-6,5,3,AIR:0)
Block(-6,5,4,AIR:0)
Block(-6,5,5,AIR:0)
Block(-6,5,6,AIR:0)
Block(-6,5,7,AIR:0)
RandomBlock(-6,5,8,CONCRETE:7,60,quark:iron_plate:1,20,STAINED_CLAY:12,15,STAINED_CLAY:15,5,AIR,7,IRON_BARS,12,CONCRETE:7,100)
RandomBlock(-6,6,-7,CONCRETE:7,60,quark:iron_plate:1,20,STAINED_CLAY:12,15,STAINED_CLAY:15,5,AIR,7,IRON_BARS,12,CONCRETE:7,100)
Block(-6,6,-6,AIR:0)
Block(-6,6,-5,AIR:0)
Block(-6,6,-4,AIR:0)
Block(-6,6,-3,AIR:0)
Block(-6,6,-2,AIR:0)
Block(-6,6,-1,AIR:0)
Block(-6,6,0,AIR:0)
Block(-6,6,1,AIR:0)
Block(-6,6,2,AIR:0)
Block(-6,6,3,AIR:0)
Block(-6,6,4,AIR:0)
Block(-6,6,5,AIR:0)
Block(-6,6,6,AIR:0)
Block(-6,6,7,AIR:0)
RandomBlock(-6,6,8,CONCRETE:7,60,quark:iron_plate:1,20,STAINED_CLAY:12,15,STAINED_CLAY:15,5,AIR,7,IRON_BARS,12,CONCRETE:7,100)
RandomBlock(-6,7,-7,CONCRETE:7,60,quark:iron_plate:1,20,STAINED_CLAY:12,15,STAINED_CLAY:15,5,AIR,7,IRON_BARS,12,CONCRETE:7,100)
RandomBlock(-6,7,-6,CONCRETE:7,60,quark:iron_plate:1,20,STAINED_CLAY:12,15,STAINED_CLAY:15,5,AIR,7,IRON_BARS,12,CONCRETE:7,100)
RandomBlock(-6,7,-5,CONCRETE:7,60,quark:iron_plate:1,20,STAINED_CLAY:12,15,STAINED_CLAY:15,5,AIR,7,IRON_BARS,12,CONCRETE:7,100)
RandomBlock(-6,7,-4,CONCRETE:7,60,quark:iron_plate:1,20,STAINED_CLAY:12,15,STAINED_CLAY:15,5,AIR,7,IRON_BARS,12,CONCRETE:7,100)
RandomBlock(-6,7,-3,CONCRETE:7,60,quark:iron_plate:1,20,STAINED_CLAY:12,15,STAINED_CLAY:15,5,AIR,7,IRON_BARS,12,CONCRETE:7,100)
RandomBlock(-6,7,-2,CONCRETE:7,60,quark:iron_plate:1,20,STAINED_CLAY:12,15,STAINED_CLAY:15,5,AIR,7,IRON_BARS,12,CONCRETE:7,100)
RandomBlock(-6,7,-1,CONCRETE:7,60,quark:iron_plate:1,20,STAINED_CLAY:12,15,STAINED_CLAY:15,5,AIR,7,IRON_BARS,12,CONCRETE:7,100)
Block(-6,7,0,CONCRETE:12)
RandomBlock(-6,7,1,CONCRETE:7,60,quark:iron_plate:1,20,STAINED_CLAY:12,15,STAINED_CLAY:15,5,AIR,7,IRON_BARS,12,CONCRETE:7,100)
RandomBlock(-6,7,2,CONCRETE:7,60,quark:iron_plate:1,20,STAINED_CLAY:12,15,STAINED_CLAY:15,5,AIR,7,IRON_BARS,12,CONCRETE:7,100)
RandomBlock(-6,7,3,CONCRETE:7,60,quark:iron_plate:1,20,STAINED_CLAY:12,15,STAINED_CLAY:15,5,AIR,7,IRON_BARS,12,CONCRETE:7,100)
RandomBlock(-6,7,4,CONCRETE:7,60,quark:iron_plate:1,20,STAINED_CLAY:12,15,STAINED_CLAY:15,5,AIR,7,IRON_BARS,12,CONCRETE:7,100)
RandomBlock(-6,7,5,CONCRETE:7,60,quark:iron_plate:1,20,STAINED_CLAY:12,15,STAINED_CLAY:15,5,AIR,7,IRON_BARS,12,CONCRETE:7,100)
RandomBlock(-6,7,6,CONCRETE:7,60,quark:iron_plate:1,20,STAINED_CLAY:12,15,STAINED_CLAY:15,5,AIR,7,IRON_BARS,12,CONCRETE:7,100)
RandomBlock(-6,7,7,CONCRETE:7,60,quark:iron_plate:1,20,STAINED_CLAY:12,15,STAINED_CLAY:15,5,AIR,7,IRON_BARS,12,CONCRETE:7,100)
RandomBlock(-6,7,8,CONCRETE:7,60,quark:iron_plate:1,20,STAINED_CLAY:12,15,STAINED_CLAY:15,5,AIR,7,IRON_BARS,12,CONCRETE:7,100)
RandomBlock(-6,8,-7,CONCRETE:7,60,quark:iron_plate:1,20,STAINED_CLAY:12,15,STAINED_CLAY:15,5,AIR,7,IRON_BARS,12,CONCRETE:7,100)
RandomBlock(-6,8,-6,CONCRETE:7,60,quark:iron_plate:1,20,STAINED_CLAY:12,15,STAINED_CLAY:15,5,AIR,7,IRON_BARS,12,CONCRETE:7,100)
RandomBlock(-6,8,-5,CONCRETE:7,60,quark:iron_plate:1,20,STAINED_CLAY:12,15,STAINED_CLAY:15,5,AIR,7,IRON_BARS,12,CONCRETE:7,100)
RandomBlock(-6,8,-4,CONCRETE:7,60,quark:iron_plate:1,20,STAINED_CLAY:12,15,STAINED_CLAY:15,5,AIR,7,IRON_BARS,12,CONCRETE:7,100)
RandomBlock(-6,8,-3,CONCRETE:7,60,quark:iron_plate:1,20,STAINED_CLAY:12,15,STAINED_CLAY:15,5,AIR,7,IRON_BARS,12,CONCRETE:7,100)
RandomBlock(-6,8,-2,CONCRETE:7,60,quark:iron_plate:1,20,STAINED_CLAY:12,15,STAINED_CLAY:15,5,AIR,7,IRON_BARS,12,CONCRETE:7,100)
RandomBlock(-6,8,-1,CONCRETE:7,60,quark:iron_plate:1,20,STAINED_CLAY:12,15,STAINED_CLAY:15,5,AIR,7,IRON_BARS,12,CONCRETE:7,100)
RandomBlock(-6,8,0,CONCRETE:7,60,quark:iron_plate:1,20,STAINED_CLAY:12,15,STAINED_CLAY:15,5,AIR,7,IRON_BARS,12,CONCRETE:7,100)
RandomBlock(-6,8,1,CONCRETE:7,60,quark:iron_plate:1,20,STAINED_CLAY:12,15,STAINED_CLAY:15,5,AIR,7,IRON_BARS,12,CONCRETE:7,100)
RandomBlock(-6,8,2,CONCRETE:7,60,quark:iron_plate:1,20,STAINED_CLAY:12,15,STAINED_CLAY:15,5,AIR,7,IRON_BARS,12,CONCRETE:7,100)
RandomBlock(-6,8,3,CONCRETE:7,60,quark:iron_plate:1,20,STAINED_CLAY:12,15,STAINED_CLAY:15,5,AIR,7,IRON_BARS,12,CONCRETE:7,100)
RandomBlock(-6,8,4,CONCRETE:7,60,quark:iron_plate:1,20,STAINED_CLAY:12,15,STAINED_CLAY:15,5,AIR,7,IRON_BARS,12,CONCRETE:7,100)
RandomBlock(-6,8,5,CONCRETE:7,60,quark:iron_plate:1,20,STAINED_CLAY:12,15,STAINED_CLAY:15,5,AIR,7,IRON_BARS,12,CONCRETE:7,100)
RandomBlock(-6,8,6,CONCRETE:7,60,quark:iron_plate:1,20,STAINED_CLAY:12,15,STAINED_CLAY:15,5,AIR,7,IRON_BARS,12,CONCRETE:7,100)
RandomBlock(-6,8,7,CONCRETE:7,60,quark:iron_plate:1,20,STAINED_CLAY:12,15,STAINED_CLAY:15,5,AIR,7,IRON_BARS,12,CONCRETE:7,100)
RandomBlock(-6,8,8,CONCRETE:7,60,quark:iron_plate:1,20,STAINED_CLAY:12,15,STAINED_CLAY:15,5,AIR,7,IRON_BARS,12,CONCRETE:7,100)
RandomBlock(-6,9,-7,CONCRETE:7,60,quark:iron_plate:1,20,STAINED_CLAY:12,15,STAINED_CLAY:15,5,AIR,7,IRON_BARS,12,CONCRETE:7,100)
RandomBlock(-6,9,-6,CONCRETE:7,60,quark:iron_plate:1,20,STAINED_CLAY:12,15,STAINED_CLAY:15,5,AIR,7,IRON_BARS,12,CONCRETE:7,100)
RandomBlock(-6,9,-5,CONCRETE:7,60,quark:iron_plate:1,20,STAINED_CLAY:12,15,STAINED_CLAY:15,5,AIR,7,IRON_BARS,12,CONCRETE:7,100)
RandomBlock(-6,9,-4,CONCRETE:7,60,quark:iron_plate:1,20,STAINED_CLAY:12,15,STAINED_CLAY:15,5,AIR,7,IRON_BARS,12,CONCRETE:7,100)
RandomBlock(-6,9,-3,CONCRETE:7,60,quark:iron_plate:1,20,STAINED_CLAY:12,15,STAINED_CLAY:15,5,AIR,7,IRON_BARS,12,CONCRETE:7,100)
RandomBlock(-6,9,-2,CONCRETE:7,60,quark:iron_plate:1,20,STAINED_CLAY:12,15,STAINED_CLAY:15,5,AIR,7,IRON_BARS,12,CONCRETE:7,100)
RandomBlock(-6,9,-1,CONCRETE:7,60,quark:iron_plate:1,20,STAINED_CLAY:12,15,STAINED_CLAY:15,5,AIR,7,IRON_BARS,12,CONCRETE:7,100)
RandomBlock(-6,9,0,CONCRETE:7,60,quark:iron_plate:1,20,STAINED_CLAY:12,15,STAINED_CLAY:15,5,AIR,7,IRON_BARS,12,CONCRETE:7,100)
RandomBlock(-6,9,1,CONCRETE:7,60,quark:iron_plate:1,20,STAINED_CLAY:12,15,STAINED_CLAY:15,5,AIR,7,IRON_BARS,12,CONCRETE:7,100)
RandomBlock(-6,9,2,CONCRETE:7,60,quark:iron_plate:1,20,STAINED_CLAY:12,15,STAINED_CLAY:15,5,AIR,7,IRON_BARS,12,CONCRETE:7,100)
RandomBlock(-6,9,3,AIR,90,IRON_TRAPDOOR:10,100)
RandomBlock(-6,9,4,AIR,90,IRON_TRAPDOOR:9,100)
RandomBlock(-6,9,5,AIR,90,IRON_TRAPDOOR:8,100)
RandomBlock(-6,9,6,CONCRETE:7,60,quark:iron_plate:1,20,STAINED_CLAY:12,15,STAINED_CLAY:15,5,AIR,7,IRON_BARS,12,CONCRETE:7,100)
RandomBlock(-6,9,7,CONCRETE:7,60,quark:iron_plate:1,20,STAINED_CLAY:12,15,STAINED_CLAY:15,5,AIR,7,IRON_BARS,12,CONCRETE:7,100)
RandomBlock(-6,9,8,CONCRETE:7,60,quark:iron_plate:1,20,STAINED_CLAY:12,15,STAINED_CLAY:15,5,AIR,7,IRON_BARS,12,CONCRETE:7,100)
Block(-6,10,-7,CONCRETE:8)
Block(-6,10,-6,CONCRETE:8)
Block(-6,10,-5,CONCRETE:8)
Block(-6,10,-4,CONCRETE:8)
Block(-6,10,-3,CONCRETE:8)
Block(-6,10,-2,CONCRETE:8)
Block(-6,10,-1,CONCRETE:8)
Block(-6,10,0,CONCRETE:8)
Block(-6,10,1,CONCRETE:8)
Block(-6,10,2,CONCRETE:8)
Block(-6,10,3,AIR:0)
Block(-6,10,4,AIR:0)
Block(-6,10,5,AIR:0)
Block(-6,10,6,CONCRETE:8)
Block(-6,10,7,CONCRETE:8)
Block(-6,10,8,CONCRETE:8)
Block(-6,11,-7,CONCRETE:8)
Block(-6,11,-6,CONCRETE:8)
Block(-6,11,-5,CONCRETE:8)
Block(-6,11,-4,CONCRETE:8)
Block(-6,11,-3,CONCRETE:8)
Block(-6,11,-2,CONCRETE:8)
Block(-6,11,-1,CONCRETE:8)
Block(-6,11,0,CONCRETE:8)
Block(-6,11,1,CONCRETE:8)
Block(-6,11,2,CONCRETE:8)
Block(-6,11,3,AIR:0)
Block(-6,11,4,AIR:0)
Block(-6,11,5,AIR:0)
Block(-6,11,6,CONCRETE:8)
Block(-6,11,7,CONCRETE:8)
Block(-6,11,8,CONCRETE:8)
Block(-6,12,-7,CONCRETE:8)
Block(-6,12,-6,CONCRETE:8)
Block(-6,12,-5,CONCRETE:8)
Block(-6,12,-4,CONCRETE:8)
Block(-6,12,-3,CONCRETE:8)
Block(-6,12,-2,CONCRETE:8)
Block(-6,12,-1,CONCRETE:8)
Block(-6,12,0,CONCRETE:8)
Block(-6,12,1,CONCRETE:8)
Block(-6,12,2,CONCRETE:8)
Block(-6,12,3,AIR:0)
Block(-6,12,4,AIR:0)
Block(-6,12,5,AIR:0)
Block(-6,12,6,CONCRETE:8)
Block(-6,12,7,CONCRETE:8)
Block(-6,12,8,CONCRETE:8)
Block(-6,13,-7,CONCRETE:8)
Block(-6,13,-6,CONCRETE:8)
Block(-6,13,-5,CONCRETE:8)
Block(-6,13,-4,CONCRETE:8)
Block(-6,13,-3,CONCRETE:8)
Block(-6,13,-2,CONCRETE:8)
Block(-6,13,-1,CONCRETE:8)
Block(-6,13,0,CONCRETE:8)
Block(-6,13,1,CONCRETE:8)
Block(-6,13,2,CONCRETE:8)
Block(-6,13,3,CONCRETE:8)
Block(-6,13,4,CONCRETE:8)
Block(-6,13,5,CONCRETE:8)
Block(-6,13,6,CONCRETE:8)
Block(-6,13,7,CONCRETE:8)
Block(-6,13,8,CONCRETE:8)
Block(-6,14,-7,CONCRETE:8)
Block(-6,14,-6,CONCRETE:8)
Block(-6,14,-5,CONCRETE:8)
Block(-6,14,-4,CONCRETE:8)
Block(-6,14,-3,CONCRETE:8)
Block(-6,14,-2,CONCRETE:8)
Block(-6,14,-1,CONCRETE:8)
Block(-6,14,0,CONCRETE:8)
Block(-6,14,1,CONCRETE:8)
Block(-6,14,2,CONCRETE:8)
Block(-6,14,3,CONCRETE:8)
Block(-6,14,4,CONCRETE:8)
Block(-6,14,5,CONCRETE:8)
Block(-6,14,6,CONCRETE:8)
Block(-6,14,7,CONCRETE:8)
Block(-6,14,8,CONCRETE:8)
RandomBlock(-6,15,-7,CONCRETE:7,60,quark:iron_plate:1,20,STAINED_CLAY:12,15,STAINED_CLAY:15,5,AIR,7,IRON_BARS,12,CONCRETE:7,100)
RandomBlock(-6,15,-6,CONCRETE:7,60,quark:iron_plate:1,20,STAINED_CLAY:12,15,STAINED_CLAY:15,5,AIR,7,IRON_BARS,12,CONCRETE:7,100)
RandomBlock(-6,15,-5,CONCRETE:7,60,quark:iron_plate:1,20,STAINED_CLAY:12,15,STAINED_CLAY:15,5,AIR,7,IRON_BARS,12,CONCRETE:7,100)
RandomBlock(-6,15,-4,CONCRETE:7,60,quark:iron_plate:1,20,STAINED_CLAY:12,15,STAINED_CLAY:15,5,AIR,7,IRON_BARS,12,CONCRETE:7,100)
RandomBlock(-6,15,-3,CONCRETE:7,60,quark:iron_plate:1,20,STAINED_CLAY:12,15,STAINED_CLAY:15,5,AIR,7,IRON_BARS,12,CONCRETE:7,100)
RandomBlock(-6,15,-2,CONCRETE:7,60,quark:iron_plate:1,20,STAINED_CLAY:12,15,STAINED_CLAY:15,5,AIR,7,IRON_BARS,12,CONCRETE:7,100)
RandomBlock(-6,15,-1,CONCRETE:7,60,quark:iron_plate:1,20,STAINED_CLAY:12,15,STAINED_CLAY:15,5,AIR,7,IRON_BARS,12,CONCRETE:7,100)
RandomBlock(-6,15,0,CONCRETE:7,60,quark:iron_plate:1,20,STAINED_CLAY:12,15,STAINED_CLAY:15,5,AIR,7,IRON_BARS,12,CONCRETE:7,100)
RandomBlock(-6,15,1,CONCRETE:7,60,quark:iron_plate:1,20,STAINED_CLAY:12,15,STAINED_CLAY:15,5,AIR,7,IRON_BARS,12,CONCRETE:7,100)
RandomBlock(-6,15,2,CONCRETE:7,60,quark:iron_plate:1,20,STAINED_CLAY:12,15,STAINED_CLAY:15,5,AIR,7,IRON_BARS,12,CONCRETE:7,100)
RandomBlock(-6,15,3,CONCRETE:7,60,quark:iron_plate:1,20,STAINED_CLAY:12,15,STAINED_CLAY:15,5,AIR,7,IRON_BARS,12,CONCRETE:7,100)
RandomBlock(-6,15,4,CONCRETE:7,60,quark:iron_plate:1,20,STAINED_CLAY:12,15,STAINED_CLAY:15,5,AIR,7,IRON_BARS,12,CONCRETE:7,100)
RandomBlock(-6,15,5,CONCRETE:7,60,quark:iron_plate:1,20,STAINED_CLAY:12,15,STAINED_CLAY:15,5,AIR,7,IRON_BARS,12,CONCRETE:7,100)
RandomBlock(-6,15,6,CONCRETE:7,60,quark:iron_plate:1,20,STAINED_CLAY:12,15,STAINED_CLAY:15,5,AIR,7,IRON_BARS,12,CONCRETE:7,100)
RandomBlock(-6,15,7,CONCRETE:7,60,quark:iron_plate:1,20,STAINED_CLAY:12,15,STAINED_CLAY:15,5,AIR,7,IRON_BARS,12,CONCRETE:7,100)
RandomBlock(-6,15,8,CONCRETE:7,60,quark:iron_plate:1,20,STAINED_CLAY:12,15,STAINED_CLAY:15,5,AIR,7,IRON_BARS,12,CONCRETE:7,100)
Block(-6,16,-7,CONCRETE:15)
Block(-6,16,-6,CONCRETE:15)
Block(-6,16,-5,CONCRETE:15)
Block(-6,16,-4,CONCRETE:15)
Block(-6,16,-3,CONCRETE:15)
Block(-6,16,-2,CONCRETE:15)
Block(-6,16,-1,CONCRETE:15)
Block(-6,16,0,CONCRETE:15)
Block(-6,16,1,CONCRETE:15)
Block(-6,16,2,CONCRETE:15)
Block(-6,16,3,CONCRETE:15)
Block(-6,16,4,CONCRETE:15)
Block(-6,16,5,CONCRETE:15)
Block(-6,16,6,CONCRETE:15)
Block(-6,16,7,CONCRETE:15)
Block(-6,16,8,CONCRETE:15)
Block(-6,17,-7,CONCRETE:15)
Block(-6,17,-6,CONCRETE:8)
Block(-6,17,-5,CONCRETE:8)
Block(-6,17,-4,CONCRETE:8)
Block(-6,17,-3,CONCRETE:8)
Block(-6,17,-2,CONCRETE:8)
Block(-6,17,-1,CONCRETE:8)
Block(-6,17,0,CONCRETE:8)
Block(-6,17,1,CONCRETE:8)
Block(-6,17,2,CONCRETE:15)
Block(-6,17,3,CONCRETE:15)
Block(-6,17,4,CONCRETE:15)
Block(-6,17,5,CONCRETE:8)
Block(-6,17,6,CONCRETE:8)
Block(-6,17,7,GRASS:0)
Block(-6,17,8,DIRT:1)
Block(-6,18,-5,CONCRETE:15)
Block(-6,18,-4,STAINED_GLASS_PANE:15)
Block(-6,18,-3,STAINED_GLASS_PANE:15)
Block(-6,18,-2,STAINED_GLASS_PANE:15)
Block(-6,18,-1,STAINED_GLASS_PANE:15)
Block(-6,18,6,STAINED_GLASS:15)
Block(-6,19,-5,CONCRETE:15)
Block(-6,19,-4,STAINED_GLASS_PANE:15)
Block(-6,19,-3,STAINED_GLASS_PANE:15)
Block(-6,19,-2,STAINED_GLASS_PANE:15)
Block(-6,19,-1,STAINED_GLASS_PANE:15)
Block(-6,19,0,STEP:15)
Block(-6,19,6,STAINED_GLASS:15)
Block(-6,20,-5,CONCRETE:15)
Block(-6,20,-4,STAINED_GLASS_PANE:15)
Block(-6,20,-3,STAINED_GLASS_PANE:15)
Block(-6,20,-2,STAINED_GLASS_PANE:15)
Block(-6,20,-1,STAINED_GLASS_PANE:15)
Block(-6,20,0,STEP:15)
Block(-6,20,6,STAINED_GLASS:15)
Block(-6,21,-5,CONCRETE:15)
Block(-6,21,-4,STAINED_GLASS_PANE:15)
Block(-6,21,-3,STAINED_GLASS_PANE:15)
Block(-6,21,-2,STAINED_GLASS_PANE:15)
Block(-6,21,-1,STAINED_GLASS_PANE:15)
Block(-6,21,0,STEP:15)
Block(-6,21,6,STAINED_GLASS:15)
Block(-6,22,-5,CONCRETE:15)
Block(-6,22,-4,STAINED_GLASS_PANE:15)
Block(-6,22,-3,STAINED_GLASS_PANE:15)
Block(-6,22,-2,STAINED_GLASS_PANE:15)
Block(-6,22,-1,STAINED_GLASS_PANE:15)
Block(-6,22,0,STEP:15)
Block(-6,22,6,STAINED_GLASS:15)
Block(-6,23,-5,CONCRETE:15)
Block(-6,23,-4,STAINED_GLASS_PANE:15)
Block(-6,23,-3,STAINED_GLASS_PANE:15)
Block(-6,23,-2,STAINED_GLASS_PANE:15)
Block(-6,23,-1,STAINED_GLASS_PANE:15)
Block(-6,23,0,STEP:15)
Block(-6,23,6,STAINED_GLASS:15)
Block(-6,24,-5,CONCRETE:15)
Block(-6,24,-4,STAINED_GLASS_PANE:15)
Block(-6,24,-3,STAINED_GLASS_PANE:15)
Block(-6,24,-2,STAINED_GLASS_PANE:15)
Block(-6,24,-1,STAINED_GLASS_PANE:15)
Block(-6,24,1,STEP:15)
Block(-6,24,3,STEP:15)
Block(-6,24,6,STAINED_GLASS:15)
Block(-6,25,-7,CONCRETE:8)
Block(-6,25,-6,CONCRETE:8)
Block(-6,25,-5,CONCRETE:8)
Block(-6,25,-4,CONCRETE:8)
Block(-6,25,-3,CONCRETE:8)
Block(-6,25,-2,CONCRETE:8)
Block(-6,25,-1,CONCRETE:8)
Block(-6,25,0,CONCRETE:8)
Block(-6,25,1,CONCRETE:8)
Block(-6,25,2,CONCRETE:8)
Block(-6,25,3,CONCRETE:8)
Block(-6,25,4,CONCRETE:8)
Block(-6,25,5,CONCRETE:8)
Block(-6,25,6,CONCRETE:8)
Block(-6,25,7,CONCRETE:8)
Block(-6,25,8,CONCRETE:8)
Block(-6,26,-7,CONCRETE:0)
Block(-6,26,-6,CONCRETE:0)
Block(-6,26,-5,CONCRETE:0)
Block(-6,26,-4,CONCRETE:0)
Block(-6,26,-3,CONCRETE:0)
Block(-6,26,-2,CONCRETE:0)
Block(-6,26,-1,CONCRETE:0)
RandomBlock(-6,26,0,STONE:6,80,STONE:6,90,STONEBRICK:0,100)
Block(-6,26,1,STAINED_GLASS_PANE:3)
RandomBlock(-6,26,2,AIR,90,IRON_TRAPDOOR:3,100)
Block(-6,26,3,CONCRETE:0)
Block(-6,26,6,STAINED_GLASS_PANE:15)
Block(-6,26,7,STAINED_GLASS_PANE:0)
Block(-6,27,-7,CONCRETE:0)
Block(-6,27,-6,CONCRETE:0)
Block(-6,27,-5,CONCRETE:0)
Block(-6,27,-4,CONCRETE:0)
