
#######################################################################
# +-----------------------------------------------------------------+ #
# |                            BO4 object                           | #
# +-----------------------------------------------------------------+ #
#######################################################################

Author: NLBlackEagle

Description: No description given

SettingsMode: WriteDisable


#######################################################################
# +-----------------------------------------------------------------+ #
# |                          Main settings                          | #
# +-----------------------------------------------------------------+ #
#######################################################################

Frequency: 0

SpawnHeight: highestBlock

UseCenterForHighestBlock: true

##############################
# Height Limits for the BO4. #
##############################

MinHeight: 0

MaxHeight: 255

InheritBO3: 

InheritBO3Rotation: NORTH

OverrideChildSettings: true

OverrideParentHeight: false

CanOverride: true

BranchFrequency: 0

BranchFrequencyGroup: 

MustBeBelowOther: false

MustBeInside: 

CannotBeInside: 

ReplacesBO3: L4-M-CrossC0R0, L4-M-CrossC0R1, L4-M-CrossC0R2, L4-M-CrossC0R3, L4-M-CrossC1R0, L4-M-CrossC1R1, L4-M-CrossC1R2, L4-M-CrossC1R3, L4-M-CrossC2R0, L4-M-CrossC2R1, L4-M-CrossC2R2, L4-M-CrossC2R3, L4-M-CrossC3R0, L4-M-CrossC3R1, L4-M-CrossC3R2, L4-M-CrossC3R3, L4-M-Straigth-START_01-C0R0, L4-M-Straigth-START_01-C0R1, L4-M-Straigth-START_01-C1R0, L4-M-Straigth-START_01-C1R1, L4-M-Straigth-START_01-C2R0, L4-M-Straigth-START_01-C2R1, L4-M-Straigth-START_01-C3R0, L4-M-Straigth-START_01-C3R1, L4-M-Straigth-3CC0R0, L4-M-Straigth-3CC0R1, L4-M-Straigth-3CC0R2, L4-M-Straigth-3CC1R0, L4-M-Straigth-3CC1R1, L4-M-Straigth-3CC1R2, L4-M-Straigth-3CC2R0, L4-M-Straigth-3CC2R1, L4-M-Straigth-3CC2R2, L4-M-Straigth-3CC3R0, L4-M-Straigth-3CC3R1, L4-M-Straigth-3CC3R2, L4-M-Cross, skyscraper_2x2_01, skyscraper_2x2_02, skyscraper_2x2_03, skyscraper_2x2_04, skyscraper_2x2_05, skyscraper_3x3_01, skyscraper_3x3_02, skyscraper_3x3_03, L3-M-Straigth-2CC0R0, L3-M-Straigth-2CC0R1, L3-M-Straigth-2CC1R0, L3-M-Straigth-2CC1R1, L3-M-Straigth-2CC2R0, L3-M-Straigth-2CC2R1, L3-M-Straigth-2CC3R0, L3-M-Straigth-2CC3R1, L3-M-Straigth-3CC0R0, L3-M-Straigth-3CC0R1, L3-M-Straigth-3CC0R2, L3-M-Straigth-3CC1R0, L3-M-Straigth-3CC1R1, L3-M-Straigth-3CC1R2, L3-M-Straigth-3CC2R0, L3-M-Straigth-3CC2R1, L3-M-Straigth-3CC2R2, L3-M-Straigth-3CC3R0, L3-M-Straigth-3CC3R1, L3-M-Straigth-3CC3R2

MustBeInsideWorldBorders: true
CanSpawnOnWater: true

SpawnOnWaterOnly: false

SpawnUnderWater: false

SpawnAtWaterLevel: false

HeightOffset: 0

RemoveAir: false

ReplaceAbove: 

ReplaceBelow: 

ReplaceWithBiomeBlocks: true

ReplaceWithSurfaceBlock: GRASS

ReplaceWithGroundBlock: DIRT

ReplaceWithStoneBlock: STONE

SmoothRadius: 0

SmoothHeightOffset: 0

SmoothStartTop: false

SmoothStartWood: false

SmoothingSurfaceBlock: 

SmoothingGroundBlock: 

BO3Group: 

IsSpawnPoint: false

DoReplaceBlocks: true


#######################################################################
# +-----------------------------------------------------------------+ #
# |                              Blocks                             | #
# +-----------------------------------------------------------------+ #
#######################################################################

RandomBlock(-8,0,-7,CONCRETE:7,60,quark:iron_plate:1,20,STAINED_CLAY:12,15,STAINED_CLAY:15,5,AIR,7,IRON_BARS,12,CONCRETE:7,100)
RandomBlock(-8,0,-6,CONCRETE:7,60,quark:iron_plate:1,20,STAINED_CLAY:12,15,STAINED_CLAY:15,5,AIR,7,IRON_BARS,12,CONCRETE:7,100)
RandomBlock(-8,0,-5,CONCRETE:7,60,quark:iron_plate:1,20,STAINED_CLAY:12,15,STAINED_CLAY:15,5,AIR,7,IRON_BARS,12,CONCRETE:7,100)
RandomBlock(-8,0,-4,CONCRETE:7,60,quark:iron_plate:1,20,STAINED_CLAY:12,15,STAINED_CLAY:15,5,AIR,7,IRON_BARS,12,CONCRETE:7,100)
RandomBlock(-8,0,-3,CONCRETE:7,60,quark:iron_plate:1,20,STAINED_CLAY:12,15,STAINED_CLAY:15,5,AIR,7,IRON_BARS,12,CONCRETE:7,100)
RandomBlock(-8,0,-2,CONCRETE:7,60,quark:iron_plate:1,20,STAINED_CLAY:12,15,STAINED_CLAY:15,5,AIR,7,IRON_BARS,12,CONCRETE:7,100)
RandomBlock(-8,0,-1,CONCRETE:7,60,quark:iron_plate:1,20,STAINED_CLAY:12,15,STAINED_CLAY:15,5,AIR,7,IRON_BARS,12,CONCRETE:7,100)
RandomBlock(-8,0,0,CONCRETE:7,60,quark:iron_plate:1,20,STAINED_CLAY:12,15,STAINED_CLAY:15,5,AIR,7,IRON_BARS,12,CONCRETE:7,100)
RandomBlock(-8,0,1,CONCRETE:7,60,quark:iron_plate:1,20,STAINED_CLAY:12,15,STAINED_CLAY:15,5,AIR,7,IRON_BARS,12,CONCRETE:7,100)
RandomBlock(-8,0,2,CONCRETE:7,60,quark:iron_plate:1,20,STAINED_CLAY:12,15,STAINED_CLAY:15,5,AIR,7,IRON_BARS,12,CONCRETE:7,100)
RandomBlock(-8,0,3,CONCRETE:7,60,quark:iron_plate:1,20,STAINED_CLAY:12,15,STAINED_CLAY:15,5,AIR,7,IRON_BARS,12,CONCRETE:7,100)
RandomBlock(-8,0,4,CONCRETE:7,60,quark:iron_plate:1,20,STAINED_CLAY:12,15,STAINED_CLAY:15,5,AIR,7,IRON_BARS,12,CONCRETE:7,100)
RandomBlock(-8,0,5,CONCRETE:7,60,quark:iron_plate:1,20,STAINED_CLAY:12,15,STAINED_CLAY:15,5,AIR,7,IRON_BARS,12,CONCRETE:7,100)
RandomBlock(-8,0,6,CONCRETE:7,60,quark:iron_plate:1,20,STAINED_CLAY:12,15,STAINED_CLAY:15,5,AIR,7,IRON_BARS,12,CONCRETE:7,100)
RandomBlock(-8,0,7,CONCRETE:7,60,quark:iron_plate:1,20,STAINED_CLAY:12,15,STAINED_CLAY:15,5,AIR,7,IRON_BARS,12,CONCRETE:7,100)
RandomBlock(-8,0,8,CONCRETE:7,60,quark:iron_plate:1,20,STAINED_CLAY:12,15,STAINED_CLAY:15,5,AIR,7,IRON_BARS,12,CONCRETE:7,100)
Block(-8,1,-7,AIR:0)
Block(-8,1,-6,AIR:0)
Block(-8,1,-5,AIR:0)
Block(-8,1,-4,SMOOTH_STAIRS:2)
RandomBlock(-8,1,-3,CONCRETE:7,60,quark:iron_plate:1,20,STAINED_CLAY:12,15,STAINED_CLAY:15,5,AIR,7,IRON_BARS,12,CONCRETE:7,100)
RandomBlock(-8,1,-2,CONCRETE:7,60,quark:iron_plate:1,20,STAINED_CLAY:12,15,STAINED_CLAY:15,5,AIR,7,IRON_BARS,12,CONCRETE:7,100)
RandomBlock(-8,1,-1,CONCRETE:7,60,quark:iron_plate:1,20,STAINED_CLAY:12,15,STAINED_CLAY:15,5,AIR,7,IRON_BARS,12,CONCRETE:7,100)
RandomBlock(-8,1,0,CONCRETE:7,60,quark:iron_plate:1,20,STAINED_CLAY:12,15,STAINED_CLAY:15,5,AIR,7,IRON_BARS,12,CONCRETE:7,100)
RandomBlock(-8,1,1,CONCRETE:7,60,quark:iron_plate:1,20,STAINED_CLAY:12,15,STAINED_CLAY:15,5,AIR,7,IRON_BARS,12,CONCRETE:7,100)
RandomBlock(-8,1,2,CONCRETE:7,60,quark:iron_plate:1,20,STAINED_CLAY:12,15,STAINED_CLAY:15,5,AIR,7,IRON_BARS,12,CONCRETE:7,100)
Block(-8,1,3,STATIONARY_WATER:0)
Block(-8,1,4,STATIONARY_WATER:0)
RandomBlock(-8,1,5,CONCRETE:7,60,quark:iron_plate:1,20,STAINED_CLAY:12,15,STAINED_CLAY:15,5,AIR,7,IRON_BARS,12,CONCRETE:7,100)
RandomBlock(-8,1,6,CONCRETE:7,60,quark:iron_plate:1,20,STAINED_CLAY:12,15,STAINED_CLAY:15,5,AIR,7,IRON_BARS,12,CONCRETE:7,100)
RandomBlock(-8,1,7,CONCRETE:7,60,quark:iron_plate:1,20,STAINED_CLAY:12,15,STAINED_CLAY:15,5,AIR,7,IRON_BARS,12,CONCRETE:7,100)
RandomBlock(-8,1,8,CONCRETE:7,60,quark:iron_plate:1,20,STAINED_CLAY:12,15,STAINED_CLAY:15,5,AIR,7,IRON_BARS,12,CONCRETE:7,100)
RandomBlock(-8,2,-7,AIR,90,IRON_TRAPDOOR:9,100)
RandomBlock(-8,2,-6,AIR,90,IRON_TRAPDOOR:11,100)
Block(-8,2,-5,AIR:0)
Block(-8,2,-4,AIR:0)
Block(-8,2,-3,SMOOTH_STAIRS:2)
RandomBlock(-8,2,-2,CONCRETE:7,60,quark:iron_plate:1,20,STAINED_CLAY:12,15,STAINED_CLAY:15,5,AIR,7,IRON_BARS,12,CONCRETE:7,100)
RandomBlock(-8,2,-1,CONCRETE:7,60,quark:iron_plate:1,20,STAINED_CLAY:12,15,STAINED_CLAY:15,5,AIR,7,IRON_BARS,12,CONCRETE:7,100)
RandomBlock(-8,2,0,CONCRETE:7,60,quark:iron_plate:1,20,STAINED_CLAY:12,15,STAINED_CLAY:15,5,AIR,7,IRON_BARS,12,CONCRETE:7,100)
RandomBlock(-8,2,1,CONCRETE:7,60,quark:iron_plate:1,20,STAINED_CLAY:12,15,STAINED_CLAY:15,5,AIR,7,IRON_BARS,12,CONCRETE:7,100)
Block(-8,2,2,SMOOTH_STAIRS:3)
Block(-8,2,3,AIR:0)
Block(-8,2,4,AIR:0)
Block(-8,2,5,SMOOTH_STAIRS:2)
RandomBlock(-8,2,6,CONCRETE:7,60,quark:iron_plate:1,20,STAINED_CLAY:12,15,STAINED_CLAY:15,5,AIR,7,IRON_BARS,12,CONCRETE:7,100)
RandomBlock(-8,2,7,CONCRETE:7,60,quark:iron_plate:1,20,STAINED_CLAY:12,15,STAINED_CLAY:15,5,AIR,7,IRON_BARS,12,CONCRETE:7,100)
RandomBlock(-8,2,8,CONCRETE:7,60,quark:iron_plate:1,20,STAINED_CLAY:12,15,STAINED_CLAY:15,5,AIR,7,IRON_BARS,12,CONCRETE:7,100)
Block(-8,3,-7,AIR:0)
Block(-8,3,-6,AIR:0)
Block(-8,3,-5,AIR:0)
Block(-8,3,-4,AIR:0)
Block(-8,3,-3,AIR:0)
Block(-8,3,-2,AIR:0)
Block(-8,3,-1,AIR:0)
Block(-8,3,0,AIR:0)
Block(-8,3,1,AIR:0)
Block(-8,3,2,AIR:0)
Block(-8,3,3,AIR:0)
Block(-8,3,4,AIR:0)
Block(-8,3,5,AIR:0)
Block(-8,3,6,AIR:0)
Block(-8,3,7,AIR:0)
RandomBlock(-8,3,8,CONCRETE:7,60,quark:iron_plate:1,20,STAINED_CLAY:12,15,STAINED_CLAY:15,5,AIR,7,IRON_BARS,12,CONCRETE:7,100)
Block(-8,4,-7,AIR:0)
Block(-8,4,-6,AIR:0)
Block(-8,4,-5,AIR:0)
Block(-8,4,-4,AIR:0)
Block(-8,4,-3,AIR:0)
Block(-8,4,-2,AIR:0)
Block(-8,4,-1,AIR:0)
Block(-8,4,0,AIR:0)
Block(-8,4,1,AIR:0)
Block(-8,4,2,AIR:0)
Block(-8,4,3,AIR:0)
Block(-8,4,4,AIR:0)
Block(-8,4,5,AIR:0)
Block(-8,4,6,AIR:0)
Block(-8,4,7,AIR:0)
RandomBlock(-8,4,8,CONCRETE:7,60,quark:iron_plate:1,20,STAINED_CLAY:12,15,STAINED_CLAY:15,5,AIR,7,IRON_BARS,12,CONCRETE:7,100)
Block(-8,5,-7,AIR:0)
Block(-8,5,-6,AIR:0)
Block(-8,5,-5,AIR:0)
Block(-8,5,-4,AIR:0)
Block(-8,5,-3,AIR:0)
Block(-8,5,-2,AIR:0)
Block(-8,5,-1,AIR:0)
Block(-8,5,0,AIR:0)
Block(-8,5,1,AIR:0)
Block(-8,5,2,AIR:0)
Block(-8,5,3,AIR:0)
Block(-8,5,4,AIR:0)
Block(-8,5,5,AIR:0)
Block(-8,5,6,CONCRETE:12)
Block(-8,5,7,CONCRETE:4)
RandomBlock(-8,5,8,CONCRETE:7,60,quark:iron_plate:1,20,STAINED_CLAY:12,15,STAINED_CLAY:15,5,AIR,7,IRON_BARS,12,CONCRETE:7,100)
RandomBlock(-8,6,-7,CONCRETE:7,60,quark:iron_plate:1,20,STAINED_CLAY:12,15,STAINED_CLAY:15,5,AIR,7,IRON_BARS,12,CONCRETE:7,100)
Block(-8,6,-6,AIR:0)
Block(-8,6,-5,AIR:0)
Block(-8,6,-4,AIR:0)
Block(-8,6,-3,AIR:0)
Block(-8,6,-2,AIR:0)
Block(-8,6,-1,AIR:0)
Block(-8,6,0,AIR:0)
Block(-8,6,1,AIR:0)
Block(-8,6,2,AIR:0)
Block(-8,6,3,AIR:0)
Block(-8,6,4,AIR:0)
Block(-8,6,5,AIR:0)
Block(-8,6,6,AIR:0)
Block(-8,6,7,AIR:0)
RandomBlock(-8,6,8,CONCRETE:7,60,quark:iron_plate:1,20,STAINED_CLAY:12,15,STAINED_CLAY:15,5,AIR,7,IRON_BARS,12,CONCRETE:7,100)
RandomBlock(-8,7,-7,CONCRETE:7,60,quark:iron_plate:1,20,STAINED_CLAY:12,15,STAINED_CLAY:15,5,AIR,7,IRON_BARS,12,CONCRETE:7,100)
RandomBlock(-8,7,-6,CONCRETE:7,60,quark:iron_plate:1,20,STAINED_CLAY:12,15,STAINED_CLAY:15,5,AIR,7,IRON_BARS,12,CONCRETE:7,100)
RandomBlock(-8,7,-5,CONCRETE:7,60,quark:iron_plate:1,20,STAINED_CLAY:12,15,STAINED_CLAY:15,5,AIR,7,IRON_BARS,12,CONCRETE:7,100)
RandomBlock(-8,7,-4,CONCRETE:7,60,quark:iron_plate:1,20,STAINED_CLAY:12,15,STAINED_CLAY:15,5,AIR,7,IRON_BARS,12,CONCRETE:7,100)
RandomBlock(-8,7,-3,CONCRETE:7,60,quark:iron_plate:1,20,STAINED_CLAY:12,15,STAINED_CLAY:15,5,AIR,7,IRON_BARS,12,CONCRETE:7,100)
RandomBlock(-8,7,-2,CONCRETE:7,60,quark:iron_plate:1,20,STAINED_CLAY:12,15,STAINED_CLAY:15,5,AIR,7,IRON_BARS,12,CONCRETE:7,100)
RandomBlock(-8,7,-1,CONCRETE:7,60,quark:iron_plate:1,20,STAINED_CLAY:12,15,STAINED_CLAY:15,5,AIR,7,IRON_BARS,12,CONCRETE:7,100)
RandomBlock(-8,7,0,CONCRETE:7,60,quark:iron_plate:1,20,STAINED_CLAY:12,15,STAINED_CLAY:15,5,AIR,7,IRON_BARS,12,CONCRETE:7,100)
RandomBlock(-8,7,1,CONCRETE:7,60,quark:iron_plate:1,20,STAINED_CLAY:12,15,STAINED_CLAY:15,5,AIR,7,IRON_BARS,12,CONCRETE:7,100)
RandomBlock(-8,7,2,CONCRETE:7,60,quark:iron_plate:1,20,STAINED_CLAY:12,15,STAINED_CLAY:15,5,AIR,7,IRON_BARS,12,CONCRETE:7,100)
RandomBlock(-8,7,3,CONCRETE:7,60,quark:iron_plate:1,20,STAINED_CLAY:12,15,STAINED_CLAY:15,5,AIR,7,IRON_BARS,12,CONCRETE:7,100)
RandomBlock(-8,7,4,CONCRETE:7,60,quark:iron_plate:1,20,STAINED_CLAY:12,15,STAINED_CLAY:15,5,AIR,7,IRON_BARS,12,CONCRETE:7,100)
RandomBlock(-8,7,5,CONCRETE:7,60,quark:iron_plate:1,20,STAINED_CLAY:12,15,STAINED_CLAY:15,5,AIR,7,IRON_BARS,12,CONCRETE:7,100)
RandomBlock(-8,7,6,CONCRETE:7,60,quark:iron_plate:1,20,STAINED_CLAY:12,15,STAINED_CLAY:15,5,AIR,7,IRON_BARS,12,CONCRETE:7,100)
RandomBlock(-8,7,7,CONCRETE:7,60,quark:iron_plate:1,20,STAINED_CLAY:12,15,STAINED_CLAY:15,5,AIR,7,IRON_BARS,12,CONCRETE:7,100)
RandomBlock(-8,7,8,CONCRETE:7,60,quark:iron_plate:1,20,STAINED_CLAY:12,15,STAINED_CLAY:15,5,AIR,7,IRON_BARS,12,CONCRETE:7,100)
RandomBlock(-8,8,-7,CONCRETE:7,60,quark:iron_plate:1,20,STAINED_CLAY:12,15,STAINED_CLAY:15,5,AIR,7,IRON_BARS,12,CONCRETE:7,100)
RandomBlock(-8,8,-6,CONCRETE:7,60,quark:iron_plate:1,20,STAINED_CLAY:12,15,STAINED_CLAY:15,5,AIR,7,IRON_BARS,12,CONCRETE:7,100)
RandomBlock(-8,8,-5,CONCRETE:7,60,quark:iron_plate:1,20,STAINED_CLAY:12,15,STAINED_CLAY:15,5,AIR,7,IRON_BARS,12,CONCRETE:7,100)
RandomBlock(-8,8,-4,CONCRETE:7,60,quark:iron_plate:1,20,STAINED_CLAY:12,15,STAINED_CLAY:15,5,AIR,7,IRON_BARS,12,CONCRETE:7,100)
RandomBlock(-8,8,-3,CONCRETE:7,60,quark:iron_plate:1,20,STAINED_CLAY:12,15,STAINED_CLAY:15,5,AIR,7,IRON_BARS,12,CONCRETE:7,100)
RandomBlock(-8,8,-2,CONCRETE:7,60,quark:iron_plate:1,20,STAINED_CLAY:12,15,STAINED_CLAY:15,5,AIR,7,IRON_BARS,12,CONCRETE:7,100)
RandomBlock(-8,8,-1,CONCRETE:7,60,quark:iron_plate:1,20,STAINED_CLAY:12,15,STAINED_CLAY:15,5,AIR,7,IRON_BARS,12,CONCRETE:7,100)
Block(-8,8,0,AIR:0)
Block(-8,8,1,CONCRETE:12)
Block(-8,8,2,AIR:0)
RandomBlock(-8,8,3,CONCRETE:7,60,quark:iron_plate:1,20,STAINED_CLAY:12,15,STAINED_CLAY:15,5,AIR,7,IRON_BARS,12,CONCRETE:7,100)
Block(-8,8,4,AIR:0)
Block(-8,8,5,AIR:0)
RandomBlock(-8,8,6,CONCRETE:7,60,quark:iron_plate:1,20,STAINED_CLAY:12,15,STAINED_CLAY:15,5,AIR,7,IRON_BARS,12,CONCRETE:7,100)
RandomBlock(-8,8,7,CONCRETE:7,60,quark:iron_plate:1,20,STAINED_CLAY:12,15,STAINED_CLAY:15,5,AIR,7,IRON_BARS,12,CONCRETE:7,100)
RandomBlock(-8,8,8,CONCRETE:7,60,quark:iron_plate:1,20,STAINED_CLAY:12,15,STAINED_CLAY:15,5,AIR,7,IRON_BARS,12,CONCRETE:7,100)
Block(-8,9,-7,AIR:0)
Block(-8,9,-6,AIR:0)
Block(-8,9,-5,AIR:0)
Block(-8,9,-4,AIR:0)
Block(-8,9,-3,AIR:0)
RandomBlock(-8,9,-2,CONCRETE:7,60,quark:iron_plate:1,20,STAINED_CLAY:12,15,STAINED_CLAY:15,5,AIR,7,IRON_BARS,12,CONCRETE:7,100)
RandomBlock(-8,9,-1,CONCRETE:7,60,quark:iron_plate:1,20,STAINED_CLAY:12,15,STAINED_CLAY:15,5,AIR,7,IRON_BARS,12,CONCRETE:7,100)
Block(-8,9,0,AIR:0)
Block(-8,9,1,AIR:0)
Block(-8,9,2,AIR:0)
RandomBlock(-8,9,3,CONCRETE:7,60,quark:iron_plate:1,20,STAINED_CLAY:12,15,STAINED_CLAY:15,5,AIR,7,IRON_BARS,12,CONCRETE:7,100)
Block(-8,9,4,AIR:0)
Block(-8,9,5,AIR:0)
RandomBlock(-8,9,6,CONCRETE:7,60,quark:iron_plate:1,20,STAINED_CLAY:12,15,STAINED_CLAY:15,5,AIR,7,IRON_BARS,12,CONCRETE:7,100)
RandomBlock(-8,9,7,CONCRETE:7,60,quark:iron_plate:1,20,STAINED_CLAY:12,15,STAINED_CLAY:15,5,AIR,7,IRON_BARS,12,CONCRETE:7,100)
RandomBlock(-8,9,8,CONCRETE:7,60,quark:iron_plate:1,20,STAINED_CLAY:12,15,STAINED_CLAY:15,5,AIR,7,IRON_BARS,12,CONCRETE:7,100)
Block(-8,10,-7,AIR:0)
Block(-8,10,-6,AIR:0)
Block(-8,10,-5,AIR:0)
Block(-8,10,-4,AIR:0)
Block(-8,10,-3,AIR:0)
RandomBlock(-8,10,-2,CONCRETE:7,60,quark:iron_plate:1,20,STAINED_CLAY:12,15,STAINED_CLAY:15,5,AIR,7,IRON_BARS,12,CONCRETE:7,100)
RandomBlock(-8,10,-1,CONCRETE:7,60,quark:iron_plate:1,20,STAINED_CLAY:12,15,STAINED_CLAY:15,5,AIR,7,IRON_BARS,12,CONCRETE:7,100)
Block(-8,10,0,AIR:0)
Block(-8,10,1,AIR:0)
Block(-8,10,2,AIR:0)
RandomBlock(-8,10,3,CONCRETE:7,60,quark:iron_plate:1,20,STAINED_CLAY:12,15,STAINED_CLAY:15,5,AIR,7,IRON_BARS,12,CONCRETE:7,100)
Block(-8,10,4,AIR:0)
Block(-8,10,5,AIR:0)
RandomBlock(-8,10,6,CONCRETE:7,60,quark:iron_plate:1,20,STAINED_CLAY:12,15,STAINED_CLAY:15,5,AIR,7,IRON_BARS,12,CONCRETE:7,100)
RandomBlock(-8,10,7,CONCRETE:7,60,quark:iron_plate:1,20,STAINED_CLAY:12,15,STAINED_CLAY:15,5,AIR,7,IRON_BARS,12,CONCRETE:7,100)
RandomBlock(-8,10,8,CONCRETE:7,60,quark:iron_plate:1,20,STAINED_CLAY:12,15,STAINED_CLAY:15,5,AIR,7,IRON_BARS,12,CONCRETE:7,100)
Block(-8,11,-7,AIR:0)
Block(-8,11,-6,AIR:0)
Block(-8,11,-5,AIR:0)
Block(-8,11,-4,AIR:0)
Block(-8,11,-3,AIR:0)
RandomBlock(-8,11,-2,CONCRETE:7,60,quark:iron_plate:1,20,STAINED_CLAY:12,15,STAINED_CLAY:15,5,AIR,7,IRON_BARS,12,CONCRETE:7,100)
RandomBlock(-8,11,-1,CONCRETE:7,60,quark:iron_plate:1,20,STAINED_CLAY:12,15,STAINED_CLAY:15,5,AIR,7,IRON_BARS,12,CONCRETE:7,100)
Block(-8,11,0,AIR:0)
Block(-8,11,1,AIR:0)
Block(-8,11,2,AIR:0)
RandomBlock(-8,11,3,CONCRETE:7,60,quark:iron_plate:1,20,STAINED_CLAY:12,15,STAINED_CLAY:15,5,AIR,7,IRON_BARS,12,CONCRETE:7,100)
Block(-8,11,4,AIR:0)
Block(-8,11,5,AIR:0)
RandomBlock(-8,11,6,CONCRETE:7,60,quark:iron_plate:1,20,STAINED_CLAY:12,15,STAINED_CLAY:15,5,AIR,7,IRON_BARS,12,CONCRETE:7,100)
RandomBlock(-8,11,7,CONCRETE:7,60,quark:iron_plate:1,20,STAINED_CLAY:12,15,STAINED_CLAY:15,5,AIR,7,IRON_BARS,12,CONCRETE:7,100)
RandomBlock(-8,11,8,CONCRETE:7,60,quark:iron_plate:1,20,STAINED_CLAY:12,15,STAINED_CLAY:15,5,AIR,7,IRON_BARS,12,CONCRETE:7,100)
Block(-8,12,-7,AIR:0)
Block(-8,12,-6,AIR:0)
RandomBlock(-8,12,-5,CONCRETE:7,60,quark:iron_plate:1,20,STAINED_CLAY:12,15,STAINED_CLAY:15,5,AIR,7,IRON_BARS,12,CONCRETE:7,100)
RandomBlock(-8,12,-4,CONCRETE:7,60,quark:iron_plate:1,20,STAINED_CLAY:12,15,STAINED_CLAY:15,5,AIR,7,IRON_BARS,12,CONCRETE:7,100)
RandomBlock(-8,12,-3,CONCRETE:7,60,quark:iron_plate:1,20,STAINED_CLAY:12,15,STAINED_CLAY:15,5,AIR,7,IRON_BARS,12,CONCRETE:7,100)
RandomBlock(-8,12,-2,CONCRETE:7,60,quark:iron_plate:1,20,STAINED_CLAY:12,15,STAINED_CLAY:15,5,AIR,7,IRON_BARS,12,CONCRETE:7,100)
RandomBlock(-8,12,-1,CONCRETE:7,60,quark:iron_plate:1,20,STAINED_CLAY:12,15,STAINED_CLAY:15,5,AIR,7,IRON_BARS,12,CONCRETE:7,100)
RandomBlock(-8,12,0,CONCRETE:7,60,quark:iron_plate:1,20,STAINED_CLAY:12,15,STAINED_CLAY:15,5,AIR,7,IRON_BARS,12,CONCRETE:7,100)
RandomBlock(-8,12,1,CONCRETE:7,60,quark:iron_plate:1,20,STAINED_CLAY:12,15,STAINED_CLAY:15,5,AIR,7,IRON_BARS,12,CONCRETE:7,100)
RandomBlock(-8,12,2,CONCRETE:7,60,quark:iron_plate:1,20,STAINED_CLAY:12,15,STAINED_CLAY:15,5,AIR,7,IRON_BARS,12,CONCRETE:7,100)
RandomBlock(-8,12,3,CONCRETE:7,60,quark:iron_plate:1,20,STAINED_CLAY:12,15,STAINED_CLAY:15,5,AIR,7,IRON_BARS,12,CONCRETE:7,100)
RandomBlock(-8,12,4,CONCRETE:7,60,quark:iron_plate:1,20,STAINED_CLAY:12,15,STAINED_CLAY:15,5,AIR,7,IRON_BARS,12,CONCRETE:7,100)
RandomBlock(-8,12,5,CONCRETE:7,60,quark:iron_plate:1,20,STAINED_CLAY:12,15,STAINED_CLAY:15,5,AIR,7,IRON_BARS,12,CONCRETE:7,100)
RandomBlock(-8,12,6,CONCRETE:7,60,quark:iron_plate:1,20,STAINED_CLAY:12,15,STAINED_CLAY:15,5,AIR,7,IRON_BARS,12,CONCRETE:7,100)
RandomBlock(-8,12,7,CONCRETE:7,60,quark:iron_plate:1,20,STAINED_CLAY:12,15,STAINED_CLAY:15,5,AIR,7,IRON_BARS,12,CONCRETE:7,100)
RandomBlock(-8,12,8,CONCRETE:7,60,quark:iron_plate:1,20,STAINED_CLAY:12,15,STAINED_CLAY:15,5,AIR,7,IRON_BARS,12,CONCRETE:7,100)
Block(-8,13,-7,AIR:0)
Block(-8,13,-6,AIR:0)
Block(-8,13,-5,IRON_FENCE:0)
Block(-8,13,-4,AIR:0)
Block(-8,13,-3,AIR:0)
Block(-8,13,-2,STEP:5)
RandomBlock(-8,13,-1,CONCRETE:7,60,quark:iron_plate:1,20,STAINED_CLAY:12,15,STAINED_CLAY:15,5,AIR,7,IRON_BARS,12,CONCRETE:7,100)
Block(-8,13,0,CONCRETE:11)
Block(-8,13,1,CONCRETE:11)
RandomBlock(-8,13,2,CONCRETE:7,60,quark:iron_plate:1,20,STAINED_CLAY:12,15,STAINED_CLAY:15,5,AIR,7,IRON_BARS,12,CONCRETE:7,100)
Block(-8,13,3,STEP:5)
Block(-8,13,4,AIR:0)
Block(-8,13,5,STONE:6)
Block(-8,13,6,STATIONARY_WATER:0)
Block(-8,13,7,STATIONARY_WATER:0)
Block(-8,13,8,STATIONARY_WATER:0)
Block(-8,14,-7,AIR:0)
Block(-8,14,-6,AIR:0)
Block(-8,14,-5,AIR:0)
Block(-8,14,-4,AIR:0)
Block(-8,14,-3,AIR:0)
Block(-8,14,-2,AIR:0)
Block(-8,14,-1,STONE:6)
Block(-8,14,0,STATIONARY_WATER:8)
Block(-8,14,1,STATIONARY_WATER:8)
Block(-8,14,2,STONE:6)
Block(-8,14,3,AIR:0)
Block(-8,14,4,AIR:0)
Block(-8,14,5,CONCRETE:15)
Block(-8,14,6,STATIONARY_WATER:0)
Block(-8,14,7,STATIONARY_WATER:0)
Block(-8,14,8,STATIONARY_WATER:0)
Block(-8,15,-7,AIR:0)
Block(-8,15,-6,AIR:0)
Block(-8,15,-5,AIR:0)
Block(-8,15,-4,AIR:0)
Block(-8,15,-3,AIR:0)
Block(-8,15,-2,AIR:0)
Block(-8,15,-1,STONE:6)
Block(-8,15,0,STATIONARY_WATER:8)
Block(-8,15,1,STATIONARY_WATER:8)
Block(-8,15,2,STONE:6)
Block(-8,15,3,AIR:0)
Block(-8,15,4,AIR:0)
Block(-8,15,5,CONCRETE:15)
Block(-8,15,6,STATIONARY_WATER:0)
Block(-8,15,7,STATIONARY_WATER:0)
Block(-8,15,8,STATIONARY_WATER:0)
Block(-8,16,-7,AIR:0)
Block(-8,16,-6,AIR:0)
Block(-8,16,-5,AIR:0)
Block(-8,16,-4,AIR:0)
Block(-8,16,-3,AIR:0)
Block(-8,16,-2,AIR:0)
Block(-8,16,-1,STONE:6)
Block(-8,16,0,STATIONARY_WATER:0)
Block(-8,16,1,STATIONARY_WATER:0)
Block(-8,16,2,STONE:6)
Block(-8,16,3,AIR:0)
Block(-8,16,4,AIR:0)
Block(-8,16,5,STONE:6)
Block(-8,16,6,STATIONARY_WATER:0)
Block(-8,16,7,STATIONARY_WATER:0)
Block(-8,16,8,STATIONARY_WATER:0)
RandomBlock(-8,17,-7,CONCRETE:7,60,quark:iron_plate:1,20,STAINED_CLAY:12,15,STAINED_CLAY:15,5,AIR,7,IRON_BARS,12,CONCRETE:7,100)
RandomBlock(-8,17,-6,CONCRETE:7,60,quark:iron_plate:1,20,STAINED_CLAY:12,15,STAINED_CLAY:15,5,AIR,7,IRON_BARS,12,CONCRETE:7,100)
RandomBlock(-8,17,-5,CONCRETE:7,60,quark:iron_plate:1,20,STAINED_CLAY:12,15,STAINED_CLAY:15,5,AIR,7,IRON_BARS,12,CONCRETE:7,100)
RandomBlock(-8,17,-4,CONCRETE:7,60,quark:iron_plate:1,20,STAINED_CLAY:12,15,STAINED_CLAY:15,5,AIR,7,IRON_BARS,12,CONCRETE:7,100)
RandomBlock(-8,17,-3,CONCRETE:7,60,quark:iron_plate:1,20,STAINED_CLAY:12,15,STAINED_CLAY:15,5,AIR,7,IRON_BARS,12,CONCRETE:7,100)
RandomBlock(-8,17,-2,CONCRETE:7,60,quark:iron_plate:1,20,STAINED_CLAY:12,15,STAINED_CLAY:15,5,AIR,7,IRON_BARS,12,CONCRETE:7,100)
RandomBlock(-8,17,-1,CONCRETE:7,60,quark:iron_plate:1,20,STAINED_CLAY:12,15,STAINED_CLAY:15,5,AIR,7,IRON_BARS,12,CONCRETE:7,100)
RandomBlock(-8,17,0,CONCRETE:7,60,quark:iron_plate:1,20,STAINED_CLAY:12,15,STAINED_CLAY:15,5,AIR,7,IRON_BARS,12,CONCRETE:7,100)
RandomBlock(-8,17,1,CONCRETE:7,60,quark:iron_plate:1,20,STAINED_CLAY:12,15,STAINED_CLAY:15,5,AIR,7,IRON_BARS,12,CONCRETE:7,100)
RandomBlock(-8,17,2,CONCRETE:7,60,quark:iron_plate:1,20,STAINED_CLAY:12,15,STAINED_CLAY:15,5,AIR,7,IRON_BARS,12,CONCRETE:7,100)
RandomBlock(-8,17,3,CONCRETE:7,60,quark:iron_plate:1,20,STAINED_CLAY:12,15,STAINED_CLAY:15,5,AIR,7,IRON_BARS,12,CONCRETE:7,100)
RandomBlock(-8,17,4,CONCRETE:7,60,quark:iron_plate:1,20,STAINED_CLAY:12,15,STAINED_CLAY:15,5,AIR,7,IRON_BARS,12,CONCRETE:7,100)
RandomBlock(-8,17,5,CONCRETE:7,60,quark:iron_plate:1,20,STAINED_CLAY:12,15,STAINED_CLAY:15,5,AIR,7,IRON_BARS,12,CONCRETE:7,100)
RandomBlock(-8,17,6,CONCRETE:7,60,quark:iron_plate:1,20,STAINED_CLAY:12,15,STAINED_CLAY:15,5,AIR,7,IRON_BARS,12,CONCRETE:7,100)
RandomBlock(-8,17,7,CONCRETE:7,60,quark:iron_plate:1,20,STAINED_CLAY:12,15,STAINED_CLAY:15,5,AIR,7,IRON_BARS,12,CONCRETE:7,100)
RandomBlock(-8,17,8,CONCRETE:7,60,quark:iron_plate:1,20,STAINED_CLAY:12,15,STAINED_CLAY:15,5,AIR,7,IRON_BARS,12,CONCRETE:7,100)
Block(-8,18,-7,CONCRETE:15)
Block(-8,18,-6,CONCRETE:15)
Block(-8,18,-5,CONCRETE:15)
Block(-8,18,-4,CONCRETE:15)
Block(-8,18,-3,CONCRETE:15)
Block(-8,18,-2,CONCRETE:8)
Block(-8,18,-1,CONCRETE:8)
Block(-8,18,0,CONCRETE:8)
Block(-8,18,1,CONCRETE:8)
Block(-8,18,2,CONCRETE:8)
Block(-8,18,3,CONCRETE:8)
Block(-8,18,4,CONCRETE:15)
Block(-8,18,5,CONCRETE:15)
Block(-8,18,6,CONCRETE:15)
Block(-8,18,7,CONCRETE:15)
Block(-8,18,8,CONCRETE:15)
Block(-8,19,-7,STAINED_GLASS_PANE:15)
Block(-8,19,8,STAINED_GLASS_PANE:15)
Block(-8,24,-7,CONCRETE:15)
Block(-8,24,-6,CONCRETE:15)
Block(-8,24,-5,CONCRETE:15)
Block(-8,24,-4,CONCRETE:15)
Block(-8,24,-3,CONCRETE:15)
Block(-8,24,-2,CONCRETE:8)
Block(-8,24,-1,CONCRETE:8)
Block(-8,24,0,CONCRETE:8)
Block(-8,24,1,CONCRETE:8)
Block(-8,24,2,CONCRETE:8)
Block(-8,24,3,CONCRETE:8)
Block(-8,24,4,CONCRETE:15)
Block(-8,24,5,CONCRETE:15)
Block(-8,24,6,CONCRETE:15)
Block(-8,24,7,CONCRETE:15)
Block(-8,24,8,CONCRETE:15)
Block(-8,25,-7,STAINED_GLASS_PANE:15)
Block(-8,25,8,STAINED_GLASS_PANE:15)
Block(-8,30,-7,CONCRETE:15)
Block(-8,30,-6,CONCRETE:15)
Block(-8,30,-5,CONCRETE:15)
Block(-8,30,-4,CONCRETE:15)
Block(-8,30,-3,CONCRETE:15)
Block(-8,30,-2,CONCRETE:8)
Block(-8,30,-1,CONCRETE:8)
Block(-8,30,0,CONCRETE:8)
Block(-8,30,1,CONCRETE:8)
Block(-8,30,2,CONCRETE:8)
Block(-8,30,3,CONCRETE:8)
Block(-8,30,4,CONCRETE:15)
Block(-8,30,5,CONCRETE:15)
Block(-8,30,6,CONCRETE:15)
Block(-8,30,7,CONCRETE:15)
Block(-8,30,8,CONCRETE:15)
Block(-8,36,-7,CONCRETE:8)
Block(-8,36,-6,CONCRETE:8)
Block(-8,36,-5,CONCRETE:8)
Block(-8,36,-4,CONCRETE:8)
Block(-8,36,-3,CONCRETE:8)
Block(-8,36,-2,CONCRETE:8)
Block(-8,36,-1,CONCRETE:8)
Block(-8,36,0,CONCRETE:8)
Block(-8,36,1,CONCRETE:8)
Block(-8,36,2,CONCRETE:8)
Block(-8,36,3,CONCRETE:8)
Block(-8,36,4,CONCRETE:8)
Block(-8,36,5,CONCRETE:8)
Block(-8,36,6,CONCRETE:8)
Block(-8,36,7,CONCRETE:8)
Block(-8,36,8,CONCRETE:8)
Block(-8,42,-7,CONCRETE:8)
Block(-8,42,-6,CONCRETE:8)
Block(-8,42,-5,CONCRETE:8)
Block(-8,42,-4,CONCRETE:8)
Block(-8,42,-3,CONCRETE:8)
Block(-8,42,-2,CONCRETE:8)
Block(-8,42,-1,CONCRETE:8)
Block(-8,42,0,CONCRETE:8)
Block(-8,42,1,CONCRETE:8)
Block(-8,42,2,CONCRETE:8)
Block(-8,42,3,CONCRETE:8)
Block(-8,42,4,CONCRETE:8)
Block(-8,42,5,CONCRETE:8)
Block(-8,42,6,CONCRETE:8)
Block(-8,42,7,CONCRETE:8)
Block(-8,42,8,CONCRETE:8)
Block(-8,43,-2,PRISMARINE:2)
Block(-8,43,-1,CARPET:15)
Block(-8,43,0,CARPET:10)
Block(-8,43,1,CARPET:15)
Block(-8,43,2,CARPET:10)
Block(-8,43,3,CARPET:15)
Block(-8,43,4,CARPET:10)
Block(-8,43,5,COBBLE_WALL:0)
Block(-8,43,6,PRISMARINE:2)
Block(-8,43,8,STAINED_GLASS_PANE:15)
Block(-8,44,-2,PRISMARINE:2)
Block(-8,44,5,CONCRETE:15)
Block(-8,44,6,PRISMARINE:2)
RandomBlock(-8,45,-3,AIR,95,WALL_BANNER:2,../AllScraperData/skyscraper_3x3_01/2606-bannerC16R16.nbt,100)
Block(-8,45,-2,PRISMARINE:2)
RandomBlock(-8,45,4,AIR,95,WALL_BANNER:2,../AllScraperData/skyscraper_3x3_01/2607-bannerC16R16.nbt,100)
Block(-8,45,5,CONCRETE:15)
Block(-8,45,6,PRISMARINE:2)
Block(-8,46,-2,WOOD_STEP:5)
RandomBlock(-8,46,5,AIR,90,IRON_TRAPDOOR:0,100)
Block(-8,46,6,PRISMARINE:2)
Block(-8,47,-1,QUARTZ_STAIRS:6)
Block(-8,47,0,STAINED_GLASS:15)
Block(-8,47,1,STAINED_GLASS:15)
Block(-8,47,2,QUARTZ_STAIRS:7)
Block(-8,47,6,PRISMARINE:2)
Block(-8,48,-7,CONCRETE:8)
Block(-8,48,-6,CONCRETE:8)
Block(-8,48,-5,CONCRETE:8)
Block(-8,48,-4,CONCRETE:8)
Block(-8,48,-3,CONCRETE:8)
Block(-8,48,-2,CONCRETE:8)
Block(-8,48,-1,QUARTZ_STAIRS:3)
Block(-8,48,2,QUARTZ_STAIRS:2)
Block(-8,48,3,CONCRETE:8)
Block(-8,48,4,CONCRETE:8)
Block(-8,48,5,CONCRETE:8)
Block(-8,48,6,CONCRETE:8)
Block(-8,48,7,CONCRETE:8)
Block(-8,48,8,CONCRETE:8)
Block(-8,49,-7,CONCRETE:8)
Block(-8,49,-6,CONCRETE:8)
Block(-8,49,-5,CONCRETE:8)
Block(-8,49,-4,CONCRETE:8)
Block(-8,49,-3,CONCRETE:8)
Block(-8,49,-2,QUARTZ_STAIRS:3)
Block(-8,49,3,QUARTZ_STAIRS:2)
Block(-8,49,4,CONCRETE:8)
Block(-8,49,5,CONCRETE:8)
Block(-8,49,6,CONCRETE:8)
Block(-8,49,7,CONCRETE:8)
Block(-8,49,8,CONCRETE:8)
RandomBlock(-8,50,-7,AIR,90,IRON_TRAPDOOR:2,100)
Block(-8,50,-3,IRON_DOOR_BLOCK:3)
Block(-8,50,4,IRON_DOOR_BLOCK:1)
RandomBlock(-8,50,8,AIR,90,IRON_TRAPDOOR:1,100)
Block(-8,51,-3,IRON_DOOR_BLOCK:8)
Block(-8,51,4,IRON_DOOR_BLOCK:9)
Block(-8,52,-3,STAINED_GLASS:15)
Block(-8,52,-2,STAINED_GLASS:15)
Block(-8,52,-1,STAINED_GLASS:15)
Block(-8,52,0,STAINED_GLASS:15)
Block(-8,52,1,STAINED_GLASS:15)
Block(-8,52,2,STAINED_GLASS:15)
Block(-8,52,3,STAINED_GLASS:15)
Block(-8,52,4,STAINED_GLASS:15)
RandomBlock(-7,0,-7,CONCRETE:7,60,quark:iron_plate:1,20,STAINED_CLAY:12,15,STAINED_CLAY:15,5,AIR,7,IRON_BARS,12,CONCRETE:7,100)
RandomBlock(-7,0,-6,CONCRETE:7,60,quark:iron_plate:1,20,STAINED_CLAY:12,15,STAINED_CLAY:15,5,AIR,7,IRON_BARS,12,CONCRETE:7,100)
RandomBlock(-7,0,-5,CONCRETE:7,60,quark:iron_plate:1,20,STAINED_CLAY:12,15,STAINED_CLAY:15,5,AIR,7,IRON_BARS,12,CONCRETE:7,100)
RandomBlock(-7,0,-4,CONCRETE:7,60,quark:iron_plate:1,20,STAINED_CLAY:12,15,STAINED_CLAY:15,5,AIR,7,IRON_BARS,12,CONCRETE:7,100)
RandomBlock(-7,0,-3,CONCRETE:7,60,quark:iron_plate:1,20,STAINED_CLAY:12,15,STAINED_CLAY:15,5,AIR,7,IRON_BARS,12,CONCRETE:7,100)
RandomBlock(-7,0,-2,CONCRETE:7,60,quark:iron_plate:1,20,STAINED_CLAY:12,15,STAINED_CLAY:15,5,AIR,7,IRON_BARS,12,CONCRETE:7,100)
RandomBlock(-7,0,-1,CONCRETE:7,60,quark:iron_plate:1,20,STAINED_CLAY:12,15,STAINED_CLAY:15,5,AIR,7,IRON_BARS,12,CONCRETE:7,100)
RandomBlock(-7,0,0,CONCRETE:7,60,quark:iron_plate:1,20,STAINED_CLAY:12,15,STAINED_CLAY:15,5,AIR,7,IRON_BARS,12,CONCRETE:7,100)
RandomBlock(-7,0,1,CONCRETE:7,60,quark:iron_plate:1,20,STAINED_CLAY:12,15,STAINED_CLAY:15,5,AIR,7,IRON_BARS,12,CONCRETE:7,100)
RandomBlock(-7,0,2,CONCRETE:7,60,quark:iron_plate:1,20,STAINED_CLAY:12,15,STAINED_CLAY:15,5,AIR,7,IRON_BARS,12,CONCRETE:7,100)
RandomBlock(-7,0,3,CONCRETE:7,60,quark:iron_plate:1,20,STAINED_CLAY:12,15,STAINED_CLAY:15,5,AIR,7,IRON_BARS,12,CONCRETE:7,100)
RandomBlock(-7,0,4,CONCRETE:7,60,quark:iron_plate:1,20,STAINED_CLAY:12,15,STAINED_CLAY:15,5,AIR,7,IRON_BARS,12,CONCRETE:7,100)
RandomBlock(-7,0,5,CONCRETE:7,60,quark:iron_plate:1,20,STAINED_CLAY:12,15,STAINED_CLAY:15,5,AIR,7,IRON_BARS,12,CONCRETE:7,100)
RandomBlock(-7,0,6,CONCRETE:7,60,quark:iron_plate:1,20,STAINED_CLAY:12,15,STAINED_CLAY:15,5,AIR,7,IRON_BARS,12,CONCRETE:7,100)
RandomBlock(-7,0,7,CONCRETE:7,60,quark:iron_plate:1,20,STAINED_CLAY:12,15,STAINED_CLAY:15,5,AIR,7,IRON_BARS,12,CONCRETE:7,100)
RandomBlock(-7,0,8,CONCRETE:7,60,quark:iron_plate:1,20,STAINED_CLAY:12,15,STAINED_CLAY:15,5,AIR,7,IRON_BARS,12,CONCRETE:7,100)
RandomBlock(-7,1,-7,CONCRETE:7,60,quark:iron_plate:1,20,STAINED_CLAY:12,15,STAINED_CLAY:15,5,AIR,7,IRON_BARS,12,CONCRETE:7,100)
RandomBlock(-7,1,-6,CONCRETE:7,60,quark:iron_plate:1,20,STAINED_CLAY:12,15,STAINED_CLAY:15,5,AIR,7,IRON_BARS,12,CONCRETE:7,100)
RandomBlock(-7,1,-5,CONCRETE:7,60,quark:iron_plate:1,20,STAINED_CLAY:12,15,STAINED_CLAY:15,5,AIR,7,IRON_BARS,12,CONCRETE:7,100)
RandomBlock(-7,1,-4,CONCRETE:7,60,quark:iron_plate:1,20,STAINED_CLAY:12,15,STAINED_CLAY:15,5,AIR,7,IRON_BARS,12,CONCRETE:7,100)
RandomBlock(-7,1,-3,CONCRETE:7,60,quark:iron_plate:1,20,STAINED_CLAY:12,15,STAINED_CLAY:15,5,AIR,7,IRON_BARS,12,CONCRETE:7,100)
RandomBlock(-7,1,-2,CONCRETE:7,60,quark:iron_plate:1,20,STAINED_CLAY:12,15,STAINED_CLAY:15,5,AIR,7,IRON_BARS,12,CONCRETE:7,100)
RandomBlock(-7,1,-1,CONCRETE:7,60,quark:iron_plate:1,20,STAINED_CLAY:12,15,STAINED_CLAY:15,5,AIR,7,IRON_BARS,12,CONCRETE:7,100)
RandomBlock(-7,1,0,CONCRETE:7,60,quark:iron_plate:1,20,STAINED_CLAY:12,15,STAINED_CLAY:15,5,AIR,7,IRON_BARS,12,CONCRETE:7,100)
RandomBlock(-7,1,1,CONCRETE:7,60,quark:iron_plate:1,20,STAINED_CLAY:12,15,STAINED_CLAY:15,5,AIR,7,IRON_BARS,12,CONCRETE:7,100)
RandomBlock(-7,1,2,CONCRETE:7,60,quark:iron_plate:1,20,STAINED_CLAY:12,15,STAINED_CLAY:15,5,AIR,7,IRON_BARS,12,CONCRETE:7,100)
Block(-7,1,3,STATIONARY_WATER:0)
Block(-7,1,4,STATIONARY_WATER:0)
RandomBlock(-7,1,5,CONCRETE:7,60,quark:iron_plate:1,20,STAINED_CLAY:12,15,STAINED_CLAY:15,5,AIR,7,IRON_BARS,12,CONCRETE:7,100)
RandomBlock(-7,1,6,CONCRETE:7,60,quark:iron_plate:1,20,STAINED_CLAY:12,15,STAINED_CLAY:15,5,AIR,7,IRON_BARS,12,CONCRETE:7,100)
RandomBlock(-7,1,7,CONCRETE:7,60,quark:iron_plate:1,20,STAINED_CLAY:12,15,STAINED_CLAY:15,5,AIR,7,IRON_BARS,12,CONCRETE:7,100)
RandomBlock(-7,1,8,CONCRETE:7,60,quark:iron_plate:1,20,STAINED_CLAY:12,15,STAINED_CLAY:15,5,AIR,7,IRON_BARS,12,CONCRETE:7,100)
RandomBlock(-7,2,-7,CONCRETE:7,60,quark:iron_plate:1,20,STAINED_CLAY:12,15,STAINED_CLAY:15,5,AIR,7,IRON_BARS,12,CONCRETE:7,100)
RandomBlock(-7,2,-6,CONCRETE:7,60,quark:iron_plate:1,20,STAINED_CLAY:12,15,STAINED_CLAY:15,5,AIR,7,IRON_BARS,12,CONCRETE:7,100)
RandomBlock(-7,2,-5,CONCRETE:7,60,quark:iron_plate:1,20,STAINED_CLAY:12,15,STAINED_CLAY:15,5,AIR,7,IRON_BARS,12,CONCRETE:7,100)
RandomBlock(-7,2,-4,CONCRETE:7,60,quark:iron_plate:1,20,STAINED_CLAY:12,15,STAINED_CLAY:15,5,AIR,7,IRON_BARS,12,CONCRETE:7,100)
RandomBlock(-7,2,-3,CONCRETE:7,60,quark:iron_plate:1,20,STAINED_CLAY:12,15,STAINED_CLAY:15,5,AIR,7,IRON_BARS,12,CONCRETE:7,100)
RandomBlock(-7,2,-2,CONCRETE:7,60,quark:iron_plate:1,20,STAINED_CLAY:12,15,STAINED_CLAY:15,5,AIR,7,IRON_BARS,12,CONCRETE:7,100)
RandomBlock(-7,2,-1,CONCRETE:7,60,quark:iron_plate:1,20,STAINED_CLAY:12,15,STAINED_CLAY:15,5,AIR,7,IRON_BARS,12,CONCRETE:7,100)
RandomBlock(-7,2,0,CONCRETE:7,60,quark:iron_plate:1,20,STAINED_CLAY:12,15,STAINED_CLAY:15,5,AIR,7,IRON_BARS,12,CONCRETE:7,100)
RandomBlock(-7,2,1,CONCRETE:7,60,quark:iron_plate:1,20,STAINED_CLAY:12,15,STAINED_CLAY:15,5,AIR,7,IRON_BARS,12,CONCRETE:7,100)
Block(-7,2,2,SMOOTH_STAIRS:3)
Block(-7,2,3,AIR:0)
Block(-7,2,4,AIR:0)
Block(-7,2,5,SMOOTH_STAIRS:2)
RandomBlock(-7,2,6,CONCRETE:7,60,quark:iron_plate:1,20,STAINED_CLAY:12,15,STAINED_CLAY:15,5,AIR,7,IRON_BARS,12,CONCRETE:7,100)
RandomBlock(-7,2,7,CONCRETE:7,60,quark:iron_plate:1,20,STAINED_CLAY:12,15,STAINED_CLAY:15,5,AIR,7,IRON_BARS,12,CONCRETE:7,100)
RandomBlock(-7,2,8,CONCRETE:7,60,quark:iron_plate:1,20,STAINED_CLAY:12,15,STAINED_CLAY:15,5,AIR,7,IRON_BARS,12,CONCRETE:7,100)
Block(-7,3,-7,AIR:0)
Block(-7,3,-6,AIR:0)
Block(-7,3,-5,AIR:0)
Block(-7,3,-4,AIR:0)
Block(-7,3,-3,AIR:0)
Block(-7,3,-2,AIR:0)
Block(-7,3,-1,AIR:0)
Block(-7,3,0,AIR:0)
Block(-7,3,1,AIR:0)
Block(-7,3,2,AIR:0)
Block(-7,3,3,AIR:0)
Block(-7,3,4,AIR:0)
Block(-7,3,5,AIR:0)
Block(-7,3,6,AIR:0)
Block(-7,3,7,AIR:0)
RandomBlock(-7,3,8,CONCRETE:7,60,quark:iron_plate:1,20,STAINED_CLAY:12,15,STAINED_CLAY:15,5,AIR,7,IRON_BARS,12,CONCRETE:7,100)
Block(-7,4,-7,AIR:0)
Block(-7,4,-6,AIR:0)
Block(-7,4,-5,AIR:0)
Block(-7,4,-4,AIR:0)
Block(-7,4,-3,AIR:0)
Block(-7,4,-2,AIR:0)
Block(-7,4,-1,AIR:0)
Block(-7,4,0,AIR:0)
Block(-7,4,1,AIR:0)
Block(-7,4,2,AIR:0)
Block(-7,4,3,AIR:0)
Block(-7,4,4,AIR:0)
Block(-7,4,5,AIR:0)
Block(-7,4,6,AIR:0)
Block(-7,4,7,AIR:0)
RandomBlock(-7,4,8,CONCRETE:7,60,quark:iron_plate:1,20,STAINED_CLAY:12,15,STAINED_CLAY:15,5,AIR,7,IRON_BARS,12,CONCRETE:7,100)
Block(-7,5,-7,AIR:0)
Block(-7,5,-6,AIR:0)
Block(-7,5,-5,AIR:0)
Block(-7,5,-4,AIR:0)
Block(-7,5,-3,AIR:0)
Block(-7,5,-2,AIR:0)
Block(-7,5,-1,AIR:0)
Block(-7,5,0,AIR:0)
Block(-7,5,1,AIR:0)
Block(-7,5,2,AIR:0)
Block(-7,5,3,AIR:0)
Block(-7,5,4,AIR:0)
Block(-7,5,5,AIR:0)
Block(-7,5,6,CONCRETE:12)
Block(-7,5,7,CONCRETE:4)
RandomBlock(-7,5,8,CONCRETE:7,60,quark:iron_plate:1,20,STAINED_CLAY:12,15,STAINED_CLAY:15,5,AIR,7,IRON_BARS,12,CONCRETE:7,100)
RandomBlock(-7,6,-7,CONCRETE:7,60,quark:iron_plate:1,20,STAINED_CLAY:12,15,STAINED_CLAY:15,5,AIR,7,IRON_BARS,12,CONCRETE:7,100)
Block(-7,6,-6,AIR:0)
Block(-7,6,-5,AIR:0)
Block(-7,6,-4,AIR:0)
Block(-7,6,-3,AIR:0)
Block(-7,6,-2,AIR:0)
Block(-7,6,-1,AIR:0)
Block(-7,6,0,AIR:0)
Block(-7,6,1,AIR:0)
Block(-7,6,2,AIR:0)
Block(-7,6,3,AIR:0)
Block(-7,6,4,AIR:0)
Block(-7,6,5,AIR:0)
Block(-7,6,6,IRON_FENCE:0)
Block(-7,6,7,AIR:0)
RandomBlock(-7,6,8,CONCRETE:7,60,quark:iron_plate:1,20,STAINED_CLAY:12,15,STAINED_CLAY:15,5,AIR,7,IRON_BARS,12,CONCRETE:7,100)
RandomBlock(-7,7,-7,CONCRETE:7,60,quark:iron_plate:1,20,STAINED_CLAY:12,15,STAINED_CLAY:15,5,AIR,7,IRON_BARS,12,CONCRETE:7,100)
RandomBlock(-7,7,-6,CONCRETE:7,60,quark:iron_plate:1,20,STAINED_CLAY:12,15,STAINED_CLAY:15,5,AIR,7,IRON_BARS,12,CONCRETE:7,100)
RandomBlock(-7,7,-5,CONCRETE:7,60,quark:iron_plate:1,20,STAINED_CLAY:12,15,STAINED_CLAY:15,5,AIR,7,IRON_BARS,12,CONCRETE:7,100)
RandomBlock(-7,7,-4,CONCRETE:7,60,quark:iron_plate:1,20,STAINED_CLAY:12,15,STAINED_CLAY:15,5,AIR,7,IRON_BARS,12,CONCRETE:7,100)
RandomBlock(-7,7,-3,CONCRETE:7,60,quark:iron_plate:1,20,STAINED_CLAY:12,15,STAINED_CLAY:15,5,AIR,7,IRON_BARS,12,CONCRETE:7,100)
RandomBlock(-7,7,-2,CONCRETE:7,60,quark:iron_plate:1,20,STAINED_CLAY:12,15,STAINED_CLAY:15,5,AIR,7,IRON_BARS,12,CONCRETE:7,100)
RandomBlock(-7,7,-1,CONCRETE:7,60,quark:iron_plate:1,20,STAINED_CLAY:12,15,STAINED_CLAY:15,5,AIR,7,IRON_BARS,12,CONCRETE:7,100)
RandomBlock(-7,7,0,CONCRETE:7,60,quark:iron_plate:1,20,STAINED_CLAY:12,15,STAINED_CLAY:15,5,AIR,7,IRON_BARS,12,CONCRETE:7,100)
RandomBlock(-7,7,1,CONCRETE:7,60,quark:iron_plate:1,20,STAINED_CLAY:12,15,STAINED_CLAY:15,5,AIR,7,IRON_BARS,12,CONCRETE:7,100)
RandomBlock(-7,7,2,CONCRETE:7,60,quark:iron_plate:1,20,STAINED_CLAY:12,15,STAINED_CLAY:15,5,AIR,7,IRON_BARS,12,CONCRETE:7,100)
RandomBlock(-7,7,3,CONCRETE:7,60,quark:iron_plate:1,20,STAINED_CLAY:12,15,STAINED_CLAY:15,5,AIR,7,IRON_BARS,12,CONCRETE:7,100)
RandomBlock(-7,7,4,CONCRETE:7,60,quark:iron_plate:1,20,STAINED_CLAY:12,15,STAINED_CLAY:15,5,AIR,7,IRON_BARS,12,CONCRETE:7,100)
RandomBlock(-7,7,5,CONCRETE:7,60,quark:iron_plate:1,20,STAINED_CLAY:12,15,STAINED_CLAY:15,5,AIR,7,IRON_BARS,12,CONCRETE:7,100)
RandomBlock(-7,7,6,CONCRETE:7,60,quark:iron_plate:1,20,STAINED_CLAY:12,15,STAINED_CLAY:15,5,AIR,7,IRON_BARS,12,CONCRETE:7,100)
RandomBlock(-7,7,7,CONCRETE:7,60,quark:iron_plate:1,20,STAINED_CLAY:12,15,STAINED_CLAY:15,5,AIR,7,IRON_BARS,12,CONCRETE:7,100)
RandomBlock(-7,7,8,CONCRETE:7,60,quark:iron_plate:1,20,STAINED_CLAY:12,15,STAINED_CLAY:15,5,AIR,7,IRON_BARS,12,CONCRETE:7,100)
RandomBlock(-7,8,-7,CONCRETE:7,60,quark:iron_plate:1,20,STAINED_CLAY:12,15,STAINED_CLAY:15,5,AIR,7,IRON_BARS,12,CONCRETE:7,100)
RandomBlock(-7,8,-6,CONCRETE:7,60,quark:iron_plate:1,20,STAINED_CLAY:12,15,STAINED_CLAY:15,5,AIR,7,IRON_BARS,12,CONCRETE:7,100)
RandomBlock(-7,8,-5,CONCRETE:7,60,quark:iron_plate:1,20,STAINED_CLAY:12,15,STAINED_CLAY:15,5,AIR,7,IRON_BARS,12,CONCRETE:7,100)
RandomBlock(-7,8,-4,CONCRETE:7,60,quark:iron_plate:1,20,STAINED_CLAY:12,15,STAINED_CLAY:15,5,AIR,7,IRON_BARS,12,CONCRETE:7,100)
RandomBlock(-7,8,-3,CONCRETE:7,60,quark:iron_plate:1,20,STAINED_CLAY:12,15,STAINED_CLAY:15,5,AIR,7,IRON_BARS,12,CONCRETE:7,100)
RandomBlock(-7,8,-2,CONCRETE:7,60,quark:iron_plate:1,20,STAINED_CLAY:12,15,STAINED_CLAY:15,5,AIR,7,IRON_BARS,12,CONCRETE:7,100)
Block(-7,8,-1,AIR:0)
Block(-7,8,0,AIR:0)
Block(-7,8,1,CONCRETE:12)
Block(-7,8,2,AIR:0)
Block(-7,8,3,AIR:0)
Block(-7,8,4,AIR:0)
Block(-7,8,5,AIR:0)
Block(-7,8,6,AIR:0)
RandomBlock(-7,8,7,CONCRETE:7,60,quark:iron_plate:1,20,STAINED_CLAY:12,15,STAINED_CLAY:15,5,AIR,7,IRON_BARS,12,CONCRETE:7,100)
RandomBlock(-7,8,8,CONCRETE:7,60,quark:iron_plate:1,20,STAINED_CLAY:12,15,STAINED_CLAY:15,5,AIR,7,IRON_BARS,12,CONCRETE:7,100)
Block(-7,9,-7,SMOOTH_STAIRS:0)
Block(-7,9,-6,SMOOTH_STAIRS:0)
RandomBlock(-7,9,-5,CONCRETE:7,60,quark:iron_plate:1,20,STAINED_CLAY:12,15,STAINED_CLAY:15,5,AIR,7,IRON_BARS,12,CONCRETE:7,100)
Block(-7,9,-4,AIR:0)
Block(-7,9,-3,AIR:0)
RandomBlock(-7,9,-2,CONCRETE:7,60,quark:iron_plate:1,20,STAINED_CLAY:12,15,STAINED_CLAY:15,5,AIR,7,IRON_BARS,12,CONCRETE:7,100)
Block(-7,9,-1,AIR:0)
Block(-7,9,0,AIR:0)
Block(-7,9,1,AIR:0)
Block(-7,9,2,AIR:0)
Block(-7,9,3,AIR:0)
Block(-7,9,4,AIR:0)
Block(-7,9,5,AIR:0)
Block(-7,9,6,AIR:0)
RandomBlock(-7,9,7,CONCRETE:7,60,quark:iron_plate:1,20,STAINED_CLAY:12,15,STAINED_CLAY:15,5,AIR,7,IRON_BARS,12,CONCRETE:7,100)
RandomBlock(-7,9,8,CONCRETE:7,60,quark:iron_plate:1,20,STAINED_CLAY:12,15,STAINED_CLAY:15,5,AIR,7,IRON_BARS,12,CONCRETE:7,100)
Block(-7,10,-7,AIR:0)
Block(-7,10,-6,AIR:0)
RandomBlock(-7,10,-5,CONCRETE:7,60,quark:iron_plate:1,20,STAINED_CLAY:12,15,STAINED_CLAY:15,5,AIR,7,IRON_BARS,12,CONCRETE:7,100)
Block(-7,10,-4,AIR:0)
Block(-7,10,-3,AIR:0)
RandomBlock(-7,10,-2,CONCRETE:7,60,quark:iron_plate:1,20,STAINED_CLAY:12,15,STAINED_CLAY:15,5,AIR,7,IRON_BARS,12,CONCRETE:7,100)
Block(-7,10,-1,AIR:0)
Block(-7,10,0,AIR:0)
Block(-7,10,1,AIR:0)
Block(-7,10,2,AIR:0)
Block(-7,10,3,AIR:0)
Block(-7,10,4,AIR:0)
Block(-7,10,5,AIR:0)
Block(-7,10,6,AIR:0)
RandomBlock(-7,10,7,CONCRETE:7,60,quark:iron_plate:1,20,STAINED_CLAY:12,15,STAINED_CLAY:15,5,AIR,7,IRON_BARS,12,CONCRETE:7,100)
RandomBlock(-7,10,8,CONCRETE:7,60,quark:iron_plate:1,20,STAINED_CLAY:12,15,STAINED_CLAY:15,5,AIR,7,IRON_BARS,12,CONCRETE:7,100)
Block(-7,11,-7,AIR:0)
Block(-7,11,-6,AIR:0)
RandomBlock(-7,11,-5,CONCRETE:7,60,quark:iron_plate:1,20,STAINED_CLAY:12,15,STAINED_CLAY:15,5,AIR,7,IRON_BARS,12,CONCRETE:7,100)
Block(-7,11,-4,AIR:0)
Block(-7,11,-3,AIR:0)
RandomBlock(-7,11,-2,CONCRETE:7,60,quark:iron_plate:1,20,STAINED_CLAY:12,15,STAINED_CLAY:15,5,AIR,7,IRON_BARS,12,CONCRETE:7,100)
Block(-7,11,-1,AIR:0)
Block(-7,11,0,AIR:0)
Block(-7,11,1,AIR:0)
Block(-7,11,2,AIR:0)
Block(-7,11,3,AIR:0)
Block(-7,11,4,AIR:0)
Block(-7,11,5,AIR:0)
Block(-7,11,6,AIR:0)
RandomBlock(-7,11,7,CONCRETE:7,60,quark:iron_plate:1,20,STAINED_CLAY:12,15,STAINED_CLAY:15,5,AIR,7,IRON_BARS,12,CONCRETE:7,100)
RandomBlock(-7,11,8,CONCRETE:7,60,quark:iron_plate:1,20,STAINED_CLAY:12,15,STAINED_CLAY:15,5,AIR,7,IRON_BARS,12,CONCRETE:7,100)
Block(-7,12,-7,AIR:0)
Block(-7,12,-6,AIR:0)
RandomBlock(-7,12,-5,CONCRETE:7,60,quark:iron_plate:1,20,STAINED_CLAY:12,15,STAINED_CLAY:15,5,AIR,7,IRON_BARS,12,CONCRETE:7,100)
RandomBlock(-7,12,-4,CONCRETE:7,60,quark:iron_plate:1,20,STAINED_CLAY:12,15,STAINED_CLAY:15,5,AIR,7,IRON_BARS,12,CONCRETE:7,100)
RandomBlock(-7,12,-3,CONCRETE:7,60,quark:iron_plate:1,20,STAINED_CLAY:12,15,STAINED_CLAY:15,5,AIR,7,IRON_BARS,12,CONCRETE:7,100)
RandomBlock(-7,12,-2,CONCRETE:7,60,quark:iron_plate:1,20,STAINED_CLAY:12,15,STAINED_CLAY:15,5,AIR,7,IRON_BARS,12,CONCRETE:7,100)
RandomBlock(-7,12,-1,CONCRETE:7,60,quark:iron_plate:1,20,STAINED_CLAY:12,15,STAINED_CLAY:15,5,AIR,7,IRON_BARS,12,CONCRETE:7,100)
RandomBlock(-7,12,0,CONCRETE:7,60,quark:iron_plate:1,20,STAINED_CLAY:12,15,STAINED_CLAY:15,5,AIR,7,IRON_BARS,12,CONCRETE:7,100)
RandomBlock(-7,12,1,CONCRETE:7,60,quark:iron_plate:1,20,STAINED_CLAY:12,15,STAINED_CLAY:15,5,AIR,7,IRON_BARS,12,CONCRETE:7,100)
RandomBlock(-7,12,2,CONCRETE:7,60,quark:iron_plate:1,20,STAINED_CLAY:12,15,STAINED_CLAY:15,5,AIR,7,IRON_BARS,12,CONCRETE:7,100)
RandomBlock(-7,12,3,CONCRETE:7,60,quark:iron_plate:1,20,STAINED_CLAY:12,15,STAINED_CLAY:15,5,AIR,7,IRON_BARS,12,CONCRETE:7,100)
RandomBlock(-7,12,4,CONCRETE:7,60,quark:iron_plate:1,20,STAINED_CLAY:12,15,STAINED_CLAY:15,5,AIR,7,IRON_BARS,12,CONCRETE:7,100)
RandomBlock(-7,12,5,CONCRETE:7,60,quark:iron_plate:1,20,STAINED_CLAY:12,15,STAINED_CLAY:15,5,AIR,7,IRON_BARS,12,CONCRETE:7,100)
RandomBlock(-7,12,6,CONCRETE:7,60,quark:iron_plate:1,20,STAINED_CLAY:12,15,STAINED_CLAY:15,5,AIR,7,IRON_BARS,12,CONCRETE:7,100)
RandomBlock(-7,12,7,CONCRETE:7,60,quark:iron_plate:1,20,STAINED_CLAY:12,15,STAINED_CLAY:15,5,AIR,7,IRON_BARS,12,CONCRETE:7,100)
RandomBlock(-7,12,8,CONCRETE:7,60,quark:iron_plate:1,20,STAINED_CLAY:12,15,STAINED_CLAY:15,5,AIR,7,IRON_BARS,12,CONCRETE:7,100)
Block(-7,13,-7,AIR:0)
Block(-7,13,-6,AIR:0)
Block(-7,13,-5,IRON_FENCE:0)
Block(-7,13,-4,AIR:0)
Block(-7,13,-3,CONCRETE:11)
Block(-7,13,-2,CONCRETE:11)
RandomBlock(-7,13,-1,CONCRETE:7,60,quark:iron_plate:1,20,STAINED_CLAY:12,15,STAINED_CLAY:15,5,AIR,7,IRON_BARS,12,CONCRETE:7,100)
Block(-7,13,0,CONCRETE:11)
Block(-7,13,1,CONCRETE:11)
RandomBlock(-7,13,2,CONCRETE:7,60,quark:iron_plate:1,20,STAINED_CLAY:12,15,STAINED_CLAY:15,5,AIR,7,IRON_BARS,12,CONCRETE:7,100)
Block(-7,13,3,CONCRETE:11)
Block(-7,13,4,CONCRETE:11)
Block(-7,13,5,CONCRETE:11)
Block(-7,13,6,STATIONARY_WATER:0)
Block(-7,13,7,STATIONARY_WATER:0)
Block(-7,13,8,STATIONARY_WATER:0)
Block(-7,14,-7,AIR:0)
Block(-7,14,-6,AIR:0)
Block(-7,14,-5,AIR:0)
Block(-7,14,-4,AIR:0)
Block(-7,14,-3,AIR:0)
Block(-7,14,-2,COBBLE_WALL:0)
Block(-7,14,-1,STONE:6)
Block(-7,14,0,STATIONARY_WATER:8)
Block(-7,14,1,STATIONARY_WATER:8)
Block(-7,14,2,STONE:6)
Block(-7,14,3,COBBLE_WALL:0)
Block(-7,14,4,AIR:0)
Block(-7,14,5,CONCRETE:15)
Block(-7,14,6,STATIONARY_WATER:0)
Block(-7,14,7,STATIONARY_WATER:0)
Block(-7,14,8,STATIONARY_WATER:0)
Block(-7,15,-7,AIR:0)
Block(-7,15,-6,AIR:0)
Block(-7,15,-5,AIR:0)
Block(-7,15,-4,AIR:0)
Block(-7,15,-3,AIR:0)
Block(-7,15,-2,COBBLE_WALL:0)
Block(-7,15,-1,STONE:6)
Block(-7,15,0,STATIONARY_WATER:8)
Block(-7,15,1,STATIONARY_WATER:8)
Block(-7,15,2,STONE:6)
Block(-7,15,3,COBBLE_WALL:0)
Block(-7,15,4,AIR:0)
Block(-7,15,5,CONCRETE:15)
Block(-7,15,6,STATIONARY_WATER:0)
Block(-7,15,7,STATIONARY_WATER:0)
Block(-7,15,8,STATIONARY_WATER:0)
Block(-7,16,-7,AIR:0)
Block(-7,16,-6,AIR:0)
Block(-7,16,-5,AIR:0)
Block(-7,16,-4,AIR:0)
Block(-7,16,-3,AIR:0)
Block(-7,16,-2,SMOOTH_STAIRS:2)
Block(-7,16,-1,CONCRETE:11)
Block(-7,16,0,STATIONARY_WATER:0)
Block(-7,16,1,STATIONARY_WATER:0)
Block(-7,16,2,CONCRETE:11)
Block(-7,16,3,SMOOTH_STAIRS:3)
Block(-7,16,4,AIR:0)
Block(-7,16,5,STONE:6)
Block(-7,16,6,STATIONARY_WATER:0)
Block(-7,16,7,STATIONARY_WATER:0)
Block(-7,16,8,STATIONARY_WATER:0)
RandomBlock(-7,17,-7,CONCRETE:7,60,quark:iron_plate:1,20,STAINED_CLAY:12,15,STAINED_CLAY:15,5,AIR,7,IRON_BARS,12,CONCRETE:7,100)
RandomBlock(-7,17,-6,CONCRETE:7,60,quark:iron_plate:1,20,STAINED_CLAY:12,15,STAINED_CLAY:15,5,AIR,7,IRON_BARS,12,CONCRETE:7,100)
RandomBlock(-7,17,-5,CONCRETE:7,60,quark:iron_plate:1,20,STAINED_CLAY:12,15,STAINED_CLAY:15,5,AIR,7,IRON_BARS,12,CONCRETE:7,100)
RandomBlock(-7,17,-4,CONCRETE:7,60,quark:iron_plate:1,20,STAINED_CLAY:12,15,STAINED_CLAY:15,5,AIR,7,IRON_BARS,12,CONCRETE:7,100)
RandomBlock(-7,17,-3,CONCRETE:7,60,quark:iron_plate:1,20,STAINED_CLAY:12,15,STAINED_CLAY:15,5,AIR,7,IRON_BARS,12,CONCRETE:7,100)
RandomBlock(-7,17,-2,CONCRETE:7,60,quark:iron_plate:1,20,STAINED_CLAY:12,15,STAINED_CLAY:15,5,AIR,7,IRON_BARS,12,CONCRETE:7,100)
RandomBlock(-7,17,-1,CONCRETE:7,60,quark:iron_plate:1,20,STAINED_CLAY:12,15,STAINED_CLAY:15,5,AIR,7,IRON_BARS,12,CONCRETE:7,100)
RandomBlock(-7,17,0,CONCRETE:7,60,quark:iron_plate:1,20,STAINED_CLAY:12,15,STAINED_CLAY:15,5,AIR,7,IRON_BARS,12,CONCRETE:7,100)
RandomBlock(-7,17,1,CONCRETE:7,60,quark:iron_plate:1,20,STAINED_CLAY:12,15,STAINED_CLAY:15,5,AIR,7,IRON_BARS,12,CONCRETE:7,100)
RandomBlock(-7,17,2,CONCRETE:7,60,quark:iron_plate:1,20,STAINED_CLAY:12,15,STAINED_CLAY:15,5,AIR,7,IRON_BARS,12,CONCRETE:7,100)
RandomBlock(-7,17,3,CONCRETE:7,60,quark:iron_plate:1,20,STAINED_CLAY:12,15,STAINED_CLAY:15,5,AIR,7,IRON_BARS,12,CONCRETE:7,100)
RandomBlock(-7,17,4,CONCRETE:7,60,quark:iron_plate:1,20,STAINED_CLAY:12,15,STAINED_CLAY:15,5,AIR,7,IRON_BARS,12,CONCRETE:7,100)
RandomBlock(-7,17,5,CONCRETE:7,60,quark:iron_plate:1,20,STAINED_CLAY:12,15,STAINED_CLAY:15,5,AIR,7,IRON_BARS,12,CONCRETE:7,100)
RandomBlock(-7,17,6,CONCRETE:7,60,quark:iron_plate:1,20,STAINED_CLAY:12,15,STAINED_CLAY:15,5,AIR,7,IRON_BARS,12,CONCRETE:7,100)
RandomBlock(-7,17,7,CONCRETE:7,60,quark:iron_plate:1,20,STAINED_CLAY:12,15,STAINED_CLAY:15,5,AIR,7,IRON_BARS,12,CONCRETE:7,100)
RandomBlock(-7,17,8,CONCRETE:7,60,quark:iron_plate:1,20,STAINED_CLAY:12,15,STAINED_CLAY:15,5,AIR,7,IRON_BARS,12,CONCRETE:7,100)
Block(-7,18,-7,CONCRETE:15)
Block(-7,18,-6,CONCRETE:15)
Block(-7,18,-5,CONCRETE:15)
Block(-7,18,-4,CONCRETE:15)
Block(-7,18,-3,CONCRETE:15)
Block(-7,18,-2,CONCRETE:15)
Block(-7,18,-1,CONCRETE:15)
Block(-7,18,0,CONCRETE:8)
Block(-7,18,1,CONCRETE:8)
Block(-7,18,2,CONCRETE:15)
Block(-7,18,3,CONCRETE:15)
Block(-7,18,4,CONCRETE:15)
Block(-7,18,5,CONCRETE:15)
Block(-7,18,6,CONCRETE:15)
Block(-7,18,7,CONCRETE:15)
Block(-7,18,8,CONCRETE:15)
Block(-7,24,-7,CONCRETE:15)
Block(-7,24,-6,STAINED_GLASS:15)
Block(-7,24,-5,STAINED_GLASS:15)
Block(-7,24,-4,STAINED_GLASS:15)
Block(-7,24,-3,STAINED_GLASS:15)
Block(-7,24,-2,STAINED_GLASS:15)
Block(-7,24,-1,STAINED_GLASS:15)
Block(-7,24,0,STAINED_GLASS:15)
Block(-7,24,1,STAINED_GLASS:15)
Block(-7,24,2,STAINED_GLASS:15)
Block(-7,24,3,STAINED_GLASS:15)
Block(-7,24,4,STAINED_GLASS:15)
Block(-7,24,5,STAINED_GLASS:15)
Block(-7,24,6,STAINED_GLASS:15)
Block(-7,24,7,STAINED_GLASS:15)
Block(-7,24,8,CONCRETE:15)
Block(-7,30,-7,CONCRETE:15)
Block(-7,30,-6,STAINED_GLASS:15)
Block(-7,30,-5,STAINED_GLASS:15)
Block(-7,30,-4,STAINED_GLASS:15)
Block(-7,30,-3,STAINED_GLASS:15)
Block(-7,30,-2,STAINED_GLASS:15)
Block(-7,30,-1,STAINED_GLASS:15)
Block(-7,30,0,STAINED_GLASS:15)
Block(-7,30,1,STAINED_GLASS:15)
Block(-7,30,2,STAINED_GLASS:15)
Block(-7,30,3,STAINED_GLASS:15)
Block(-7,30,4,STAINED_GLASS:15)
Block(-7,30,5,STAINED_GLASS:15)
Block(-7,30,6,STAINED_GLASS:15)
Block(-7,30,7,STAINED_GLASS:15)
Block(-7,30,8,CONCRETE:15)
Block(-7,36,-7,CONCRETE:8)
Block(-7,36,-6,STAINED_GLASS:15)
Block(-7,36,-5,STAINED_GLASS:15)
Block(-7,36,-4,STAINED_GLASS:15)
Block(-7,36,-3,STAINED_GLASS:15)
Block(-7,36,-2,STAINED_GLASS:15)
Block(-7,36,-1,STAINED_GLASS:15)
Block(-7,36,0,STAINED_GLASS:15)
Block(-7,36,1,STAINED_GLASS:15)
Block(-7,36,2,STAINED_GLASS:15)
Block(-7,36,3,STAINED_GLASS:15)
Block(-7,36,4,STAINED_GLASS:15)
Block(-7,36,5,STAINED_GLASS:15)
Block(-7,36,6,STAINED_GLASS:15)
Block(-7,36,7,STAINED_GLASS:15)
Block(-7,36,8,CONCRETE:8)
Block(-7,42,-7,CONCRETE:8)
Block(-7,42,-6,CONCRETE:8)
Block(-7,42,-5,CONCRETE:8)
Block(-7,42,-4,CONCRETE:8)
Block(-7,42,-3,CONCRETE:8)
Block(-7,42,-2,CONCRETE:8)
Block(-7,42,-1,CONCRETE:8)
Block(-7,42,0,CONCRETE:8)
Block(-7,42,1,CONCRETE:8)
Block(-7,42,2,CONCRETE:8)
Block(-7,42,3,CONCRETE:8)
Block(-7,42,4,CONCRETE:8)
Block(-7,42,5,CONCRETE:8)
Block(-7,42,6,CONCRETE:8)
Block(-7,42,7,CONCRETE:8)
Block(-7,42,8,CONCRETE:8)
Block(-7,43,-2,PRISMARINE:2)
Block(-7,43,-1,CARPET:10)
Block(-7,43,0,CARPET:15)
Block(-7,43,1,CARPET:10)
Block(-7,43,2,CARPET:15)
Block(-7,43,3,CARPET:10)
Block(-7,43,4,CARPET:15)
Block(-7,43,6,QUARTZ_BLOCK:1)
Block(-7,43,8,STAINED_GLASS_PANE:15)
Block(-7,44,-2,PRISMARINE:2)
Block(-7,44,6,QUARTZ_STAIRS:6)
RandomBlock(-7,45,-3,AIR,95,WALL_BANNER:2,../AllScraperData/skyscraper_3x3_01/2665-bannerC16R16.nbt,100)
Block(-7,45,-2,PRISMARINE:2)
Block(-7,45,6,QUARTZ_STAIRS:6)
Block(-7,46,-2,WOOD_STEP:5)
Block(-7,46,6,QUARTZ_STAIRS:6)
Block(-7,47,-1,QUARTZ_STAIRS:6)
Block(-7,47,0,STAINED_GLASS:15)
Block(-7,47,1,STAINED_GLASS:15)
Block(-7,47,2,QUARTZ_STAIRS:7)
Block(-7,47,6,QUARTZ_STAIRS:6)
Block(-7,48,-7,CONCRETE:8)
Block(-7,48,-6,CONCRETE:8)
Block(-7,48,-5,CONCRETE:8)
Block(-7,48,-4,CONCRETE:8)
Block(-7,48,-3,CONCRETE:8)
Block(-7,48,-2,CONCRETE:8)
Block(-7,48,-1,QUARTZ_STAIRS:3)
Block(-7,48,2,QUARTZ_STAIRS:2)
Block(-7,48,3,CONCRETE:8)
Block(-7,48,4,CONCRETE:8)
Block(-7,48,5,CONCRETE:8)
Block(-7,48,6,CONCRETE:8)
Block(-7,48,7,CONCRETE:8)
Block(-7,48,8,CONCRETE:8)
Block(-7,49,-7,CONCRETE:8)
Block(-7,49,-6,CONCRETE:8)
Block(-7,49,-5,CONCRETE:8)
Block(-7,49,-4,CONCRETE:8)
Block(-7,49,-3,CONCRETE:8)
Block(-7,49,-2,QUARTZ_STAIRS:3)
Block(-7,49,3,QUARTZ_STAIRS:2)
Block(-7,49,4,CONCRETE:8)
Block(-7,49,5,CONCRETE:8)
Block(-7,49,6,CONCRETE:8)
Block(-7,49,7,CONCRETE:8)
Block(-7,49,8,CONCRETE:8)
Block(-7,50,-3,IRON_DOOR_BLOCK:3)
Block(-7,50,4,IRON_DOOR_BLOCK:1)
Block(-7,51,-3,IRON_DOOR_BLOCK:9)
Block(-7,51,4,IRON_DOOR_BLOCK:8)
Block(-7,52,-3,STAINED_GLASS:15)
Block(-7,52,-2,STAINED_GLASS:15)
Block(-7,52,-1,STAINED_GLASS:15)
Block(-7,52,0,STAINED_GLASS:15)
Block(-7,52,1,STAINED_GLASS:15)
Block(-7,52,2,STAINED_GLASS:15)
Block(-7,52,3,STAINED_GLASS:15)
Block(-7,52,4,STAINED_GLASS:15)
RandomBlock(-6,0,-7,CONCRETE:7,60,quark:iron_plate:1,20,STAINED_CLAY:12,15,STAINED_CLAY:15,5,AIR,7,IRON_BARS,12,CONCRETE:7,100)
RandomBlock(-6,0,-6,CONCRETE:7,60,quark:iron_plate:1,20,STAINED_CLAY:12,15,STAINED_CLAY:15,5,AIR,7,IRON_BARS,12,CONCRETE:7,100)
RandomBlock(-6,0,-5,CONCRETE:7,60,quark:iron_plate:1,20,STAINED_CLAY:12,15,STAINED_CLAY:15,5,AIR,7,IRON_BARS,12,CONCRETE:7,100)
RandomBlock(-6,0,-4,CONCRETE:7,60,quark:iron_plate:1,20,STAINED_CLAY:12,15,STAINED_CLAY:15,5,AIR,7,IRON_BARS,12,CONCRETE:7,100)
RandomBlock(-6,0,-3,CONCRETE:7,60,quark:iron_plate:1,20,STAINED_CLAY:12,15,STAINED_CLAY:15,5,AIR,7,IRON_BARS,12,CONCRETE:7,100)
RandomBlock(-6,0,-2,CONCRETE:7,60,quark:iron_plate:1,20,STAINED_CLAY:12,15,STAINED_CLAY:15,5,AIR,7,IRON_BARS,12,CONCRETE:7,100)
RandomBlock(-6,0,-1,CONCRETE:7,60,quark:iron_plate:1,20,STAINED_CLAY:12,15,STAINED_CLAY:15,5,AIR,7,IRON_BARS,12,CONCRETE:7,100)
RandomBlock(-6,0,0,CONCRETE:7,60,quark:iron_plate:1,20,STAINED_CLAY:12,15,STAINED_CLAY:15,5,AIR,7,IRON_BARS,12,CONCRETE:7,100)
RandomBlock(-6,0,1,CONCRETE:7,60,quark:iron_plate:1,20,STAINED_CLAY:12,15,STAINED_CLAY:15,5,AIR,7,IRON_BARS,12,CONCRETE:7,100)
RandomBlock(-6,0,2,CONCRETE:7,60,quark:iron_plate:1,20,STAINED_CLAY:12,15,STAINED_CLAY:15,5,AIR,7,IRON_BARS,12,CONCRETE:7,100)
RandomBlock(-6,0,3,CONCRETE:7,60,quark:iron_plate:1,20,STAINED_CLAY:12,15,STAINED_CLAY:15,5,AIR,7,IRON_BARS,12,CONCRETE:7,100)
RandomBlock(-6,0,4,CONCRETE:7,60,quark:iron_plate:1,20,STAINED_CLAY:12,15,STAINED_CLAY:15,5,AIR,7,IRON_BARS,12,CONCRETE:7,100)
RandomBlock(-6,0,5,CONCRETE:7,60,quark:iron_plate:1,20,STAINED_CLAY:12,15,STAINED_CLAY:15,5,AIR,7,IRON_BARS,12,CONCRETE:7,100)
RandomBlock(-6,0,6,CONCRETE:7,60,quark:iron_plate:1,20,STAINED_CLAY:12,15,STAINED_CLAY:15,5,AIR,7,IRON_BARS,12,CONCRETE:7,100)
RandomBlock(-6,0,7,CONCRETE:7,60,quark:iron_plate:1,20,STAINED_CLAY:12,15,STAINED_CLAY:15,5,AIR,7,IRON_BARS,12,CONCRETE:7,100)
RandomBlock(-6,0,8,CONCRETE:7,60,quark:iron_plate:1,20,STAINED_CLAY:12,15,STAINED_CLAY:15,5,AIR,7,IRON_BARS,12,CONCRETE:7,100)
RandomBlock(-6,1,-7,CONCRETE:7,60,quark:iron_plate:1,20,STAINED_CLAY:12,15,STAINED_CLAY:15,5,AIR,7,IRON_BARS,12,CONCRETE:7,100)
RandomBlock(-6,1,-6,CONCRETE:7,60,quark:iron_plate:1,20,STAINED_CLAY:12,15,STAINED_CLAY:15,5,AIR,7,IRON_BARS,12,CONCRETE:7,100)
RandomBlock(-6,1,-5,CONCRETE:7,60,quark:iron_plate:1,20,STAINED_CLAY:12,15,STAINED_CLAY:15,5,AIR,7,IRON_BARS,12,CONCRETE:7,100)
RandomBlock(-6,1,-4,CONCRETE:7,60,quark:iron_plate:1,20,STAINED_CLAY:12,15,STAINED_CLAY:15,5,AIR,7,IRON_BARS,12,CONCRETE:7,100)
RandomBlock(-6,1,-3,CONCRETE:7,60,quark:iron_plate:1,20,STAINED_CLAY:12,15,STAINED_CLAY:15,5,AIR,7,IRON_BARS,12,CONCRETE:7,100)
RandomBlock(-6,1,-2,CONCRETE:7,60,quark:iron_plate:1,20,STAINED_CLAY:12,15,STAINED_CLAY:15,5,AIR,7,IRON_BARS,12,CONCRETE:7,100)
RandomBlock(-6,1,-1,CONCRETE:7,60,quark:iron_plate:1,20,STAINED_CLAY:12,15,STAINED_CLAY:15,5,AIR,7,IRON_BARS,12,CONCRETE:7,100)
RandomBlock(-6,1,0,CONCRETE:7,60,quark:iron_plate:1,20,STAINED_CLAY:12,15,STAINED_CLAY:15,5,AIR,7,IRON_BARS,12,CONCRETE:7,100)
RandomBlock(-6,1,1,CONCRETE:7,60,quark:iron_plate:1,20,STAINED_CLAY:12,15,STAINED_CLAY:15,5,AIR,7,IRON_BARS,12,CONCRETE:7,100)
RandomBlock(-6,1,2,CONCRETE:7,60,quark:iron_plate:1,20,STAINED_CLAY:12,15,STAINED_CLAY:15,5,AIR,7,IRON_BARS,12,CONCRETE:7,100)
Block(-6,1,3,STATIONARY_WATER:0)
Block(-6,1,4,STATIONARY_WATER:0)
RandomBlock(-6,1,5,CONCRETE:7,60,quark:iron_plate:1,20,STAINED_CLAY:12,15,STAINED_CLAY:15,5,AIR,7,IRON_BARS,12,CONCRETE:7,100)
RandomBlock(-6,1,6,CONCRETE:7,60,quark:iron_plate:1,20,STAINED_CLAY:12,15,STAINED_CLAY:15,5,AIR,7,IRON_BARS,12,CONCRETE:7,100)
RandomBlock(-6,1,7,CONCRETE:7,60,quark:iron_plate:1,20,STAINED_CLAY:12,15,STAINED_CLAY:15,5,AIR,7,IRON_BARS,12,CONCRETE:7,100)
RandomBlock(-6,1,8,CONCRETE:7,60,quark:iron_plate:1,20,STAINED_CLAY:12,15,STAINED_CLAY:15,5,AIR,7,IRON_BARS,12,CONCRETE:7,100)
Block(-6,2,-7,SMOOTH_STAIRS:1)
Block(-6,2,-6,SMOOTH_STAIRS:1)
Block(-6,2,-5,SMOOTH_STAIRS:1)
Block(-6,2,-4,SMOOTH_STAIRS:1)
Block(-6,2,-3,SMOOTH_STAIRS:1)
Block(-6,2,-2,SMOOTH_STAIRS:1)
Block(-6,2,-1,SMOOTH_STAIRS:1)
Block(-6,2,0,SMOOTH_STAIRS:1)
Block(-6,2,1,SMOOTH_STAIRS:1)
Block(-6,2,2,SMOOTH_STAIRS:1)
Block(-6,2,3,AIR:0)
Block(-6,2,4,AIR:0)
Block(-6,2,5,SMOOTH_STAIRS:1)
Block(-6,2,6,SMOOTH_STAIRS:1)
Block(-6,2,7,SMOOTH_STAIRS:1)
Block(-6,2,8,SMOOTH_STAIRS:1)
Block(-6,3,-7,AIR:0)
Block(-6,3,-6,AIR:0)
Block(-6,3,-5,AIR:0)
Block(-6,3,-4,AIR:0)
Block(-6,3,-3,AIR:0)
Block(-6,3,-2,AIR:0)
Block(-6,3,-1,AIR:0)
Block(-6,3,0,AIR:0)
Block(-6,3,1,AIR:0)
Block(-6,3,2,AIR:0)
Block(-6,3,3,AIR:0)
Block(-6,3,4,AIR:0)
Block(-6,3,5,AIR:0)
Block(-6,3,6,AIR:0)
Block(-6,3,7,AIR:0)
Block(-6,3,8,AIR:0)
Block(-6,4,-7,AIR:0)
Block(-6,4,-6,AIR:0)
Block(-6,4,-5,AIR:0)
Block(-6,4,-4,AIR:0)
Block(-6,4,-3,AIR:0)
Block(-6,4,-2,AIR:0)
Block(-6,4,-1,AIR:0)
Block(-6,4,0,AIR:0)
Block(-6,4,1,AIR:0)
Block(-6,4,2,AIR:0)
Block(-6,4,3,AIR:0)
Block(-6,4,4,AIR:0)
Block(-6,4,5,AIR:0)
Block(-6,4,6,AIR:0)
Block(-6,4,7,AIR:0)
Block(-6,4,8,AIR:0)
Block(-6,5,-7,AIR:0)
Block(-6,5,-6,AIR:0)
Block(-6,5,-5,AIR:0)
Block(-6,5,-4,AIR:0)
Block(-6,5,-3,AIR:0)
Block(-6,5,-2,AIR:0)
Block(-6,5,-1,AIR:0)
Block(-6,5,0,AIR:0)
Block(-6,5,1,AIR:0)
Block(-6,5,2,AIR:0)
Block(-6,5,3,AIR:0)
Block(-6,5,4,AIR:0)
Block(-6,5,5,AIR:0)
Block(-6,5,6,CONCRETE:12)
Block(-6,5,7,CONCRETE:4)
Block(-6,5,8,AIR:0)
RandomBlock(-6,6,-7,CONCRETE:7,60,quark:iron_plate:1,20,STAINED_CLAY:12,15,STAINED_CLAY:15,5,AIR,7,IRON_BARS,12,CONCRETE:7,100)
Block(-6,6,-6,AIR:0)
Block(-6,6,-5,AIR:0)
Block(-6,6,-4,AIR:0)
Block(-6,6,-3,AIR:0)
Block(-6,6,-2,AIR:0)
Block(-6,6,-1,AIR:0)
Block(-6,6,0,AIR:0)
Block(-6,6,1,AIR:0)
Block(-6,6,2,AIR:0)
Block(-6,6,3,AIR:0)
Block(-6,6,4,AIR:0)
Block(-6,6,5,AIR:0)
Block(-6,6,6,AIR:0)
Block(-6,6,7,AIR:0)
Block(-6,6,8,AIR:0)
RandomBlock(-6,7,-7,CONCRETE:7,60,quark:iron_plate:1,20,STAINED_CLAY:12,15,STAINED_CLAY:15,5,AIR,7,IRON_BARS,12,CONCRETE:7,100)
RandomBlock(-6,7,-6,CONCRETE:7,60,quark:iron_plate:1,20,STAINED_CLAY:12,15,STAINED_CLAY:15,5,AIR,7,IRON_BARS,12,CONCRETE:7,100)
RandomBlock(-6,7,-5,CONCRETE:7,60,quark:iron_plate:1,20,STAINED_CLAY:12,15,STAINED_CLAY:15,5,AIR,7,IRON_BARS,12,CONCRETE:7,100)
RandomBlock(-6,7,-4,CONCRETE:7,60,quark:iron_plate:1,20,STAINED_CLAY:12,15,STAINED_CLAY:15,5,AIR,7,IRON_BARS,12,CONCRETE:7,100)
RandomBlock(-6,7,-3,CONCRETE:7,60,quark:iron_plate:1,20,STAINED_CLAY:12,15,STAINED_CLAY:15,5,AIR,7,IRON_BARS,12,CONCRETE:7,100)
RandomBlock(-6,7,-2,CONCRETE:7,60,quark:iron_plate:1,20,STAINED_CLAY:12,15,STAINED_CLAY:15,5,AIR,7,IRON_BARS,12,CONCRETE:7,100)
RandomBlock(-6,7,-1,CONCRETE:7,60,quark:iron_plate:1,20,STAINED_CLAY:12,15,STAINED_CLAY:15,5,AIR,7,IRON_BARS,12,CONCRETE:7,100)
RandomBlock(-6,7,0,CONCRETE:7,60,quark:iron_plate:1,20,STAINED_CLAY:12,15,STAINED_CLAY:15,5,AIR,7,IRON_BARS,12,CONCRETE:7,100)
RandomBlock(-6,7,1,CONCRETE:7,60,quark:iron_plate:1,20,STAINED_CLAY:12,15,STAINED_CLAY:15,5,AIR,7,IRON_BARS,12,CONCRETE:7,100)
RandomBlock(-6,7,2,CONCRETE:7,60,quark:iron_plate:1,20,STAINED_CLAY:12,15,STAINED_CLAY:15,5,AIR,7,IRON_BARS,12,CONCRETE:7,100)
RandomBlock(-6,7,3,CONCRETE:7,60,quark:iron_plate:1,20,STAINED_CLAY:12,15,STAINED_CLAY:15,5,AIR,7,IRON_BARS,12,CONCRETE:7,100)
RandomBlock(-6,7,4,CONCRETE:7,60,quark:iron_plate:1,20,STAINED_CLAY:12,15,STAINED_CLAY:15,5,AIR,7,IRON_BARS,12,CONCRETE:7,100)
RandomBlock(-6,7,5,CONCRETE:7,60,quark:iron_plate:1,20,STAINED_CLAY:12,15,STAINED_CLAY:15,5,AIR,7,IRON_BARS,12,CONCRETE:7,100)
RandomBlock(-6,7,6,CONCRETE:7,60,quark:iron_plate:1,20,STAINED_CLAY:12,15,STAINED_CLAY:15,5,AIR,7,IRON_BARS,12,CONCRETE:7,100)
RandomBlock(-6,7,7,CONCRETE:7,60,quark:iron_plate:1,20,STAINED_CLAY:12,15,STAINED_CLAY:15,5,AIR,7,IRON_BARS,12,CONCRETE:7,100)
RandomBlock(-6,7,8,CONCRETE:7,60,quark:iron_plate:1,20,STAINED_CLAY:12,15,STAINED_CLAY:15,5,AIR,7,IRON_BARS,12,CONCRETE:7,100)
RandomBlock(-6,8,-7,CONCRETE:7,60,quark:iron_plate:1,20,STAINED_CLAY:12,15,STAINED_CLAY:15,5,AIR,7,IRON_BARS,12,CONCRETE:7,100)
RandomBlock(-6,8,-6,CONCRETE:7,60,quark:iron_plate:1,20,STAINED_CLAY:12,15,STAINED_CLAY:15,5,AIR,7,IRON_BARS,12,CONCRETE:7,100)
RandomBlock(-6,8,-5,CONCRETE:7,60,quark:iron_plate:1,20,STAINED_CLAY:12,15,STAINED_CLAY:15,5,AIR,7,IRON_BARS,12,CONCRETE:7,100)
Block(-6,8,-4,SMOOTH_STAIRS:1)
Block(-6,8,-3,SMOOTH_STAIRS:1)
RandomBlock(-6,8,-2,CONCRETE:7,60,quark:iron_plate:1,20,STAINED_CLAY:12,15,STAINED_CLAY:15,5,AIR,7,IRON_BARS,12,CONCRETE:7,100)
Block(-6,8,-1,AIR:0)
Block(-6,8,0,AIR:0)
Block(-6,8,1,CONCRETE:12)
Block(-6,8,2,AIR:0)
Block(-6,8,3,AIR:0)
Block(-6,8,4,AIR:0)
Block(-6,8,5,AIR:0)
Block(-6,8,6,AIR:0)
RandomBlock(-6,8,7,CONCRETE:7,60,quark:iron_plate:1,20,STAINED_CLAY:12,15,STAINED_CLAY:15,5,AIR,7,IRON_BARS,12,CONCRETE:7,100)
RandomBlock(-6,8,8,CONCRETE:7,60,quark:iron_plate:1,20,STAINED_CLAY:12,15,STAINED_CLAY:15,5,AIR,7,IRON_BARS,12,CONCRETE:7,100)
RandomBlock(-6,9,-7,CONCRETE:7,60,quark:iron_plate:1,20,STAINED_CLAY:12,15,STAINED_CLAY:15,5,AIR,7,IRON_BARS,12,CONCRETE:7,100)
RandomBlock(-6,9,-6,CONCRETE:7,60,quark:iron_plate:1,20,STAINED_CLAY:12,15,STAINED_CLAY:15,5,AIR,7,IRON_BARS,12,CONCRETE:7,100)
RandomBlock(-6,9,-5,CONCRETE:7,60,quark:iron_plate:1,20,STAINED_CLAY:12,15,STAINED_CLAY:15,5,AIR,7,IRON_BARS,12,CONCRETE:7,100)
Block(-6,9,-4,AIR:0)
Block(-6,9,-3,AIR:0)
RandomBlock(-6,9,-2,CONCRETE:7,60,quark:iron_plate:1,20,STAINED_CLAY:12,15,STAINED_CLAY:15,5,AIR,7,IRON_BARS,12,CONCRETE:7,100)
Block(-6,9,-1,AIR:0)
Block(-6,9,0,AIR:0)
Block(-6,9,1,AIR:0)
Block(-6,9,2,AIR:0)
Block(-6,9,3,AIR:0)
Block(-6,9,4,AIR:0)
Block(-6,9,5,AIR:0)
Block(-6,9,6,AIR:0)
RandomBlock(-6,9,7,CONCRETE:7,60,quark:iron_plate:1,20,STAINED_CLAY:12,15,STAINED_CLAY:15,5,AIR,7,IRON_BARS,12,CONCRETE:7,100)
RandomBlock(-6,9,8,CONCRETE:7,60,quark:iron_plate:1,20,STAINED_CLAY:12,15,STAINED_CLAY:15,5,AIR,7,IRON_BARS,12,CONCRETE:7,100)
Block(-6,10,-7,SMOOTH_STAIRS:0)
Block(-6,10,-6,SMOOTH_STAIRS:0)
RandomBlock(-6,10,-5,CONCRETE:7,60,quark:iron_plate:1,20,STAINED_CLAY:12,15,STAINED_CLAY:15,5,AIR,7,IRON_BARS,12,CONCRETE:7,100)
Block(-6,10,-4,AIR:0)
Block(-6,10,-3,AIR:0)
RandomBlock(-6,10,-2,CONCRETE:7,60,quark:iron_plate:1,20,STAINED_CLAY:12,15,STAINED_CLAY:15,5,AIR,7,IRON_BARS,12,CONCRETE:7,100)
Block(-6,10,-1,AIR:0)
Block(-6,10,0,AIR:0)
Block(-6,10,1,AIR:0)
Block(-6,10,2,AIR:0)
Block(-6,10,3,AIR:0)
Block(-6,10,4,AIR:0)
Block(-6,10,5,AIR:0)
Block(-6,10,6,AIR:0)
RandomBlock(-6,10,7,CONCRETE:7,60,quark:iron_plate:1,20,STAINED_CLAY:12,15,STAINED_CLAY:15,5,AIR,7,IRON_BARS,12,CONCRETE:7,100)
RandomBlock(-6,10,8,CONCRETE:7,60,quark:iron_plate:1,20,STAINED_CLAY:12,15,STAINED_CLAY:15,5,AIR,7,IRON_BARS,12,CONCRETE:7,100)
Block(-6,11,-7,AIR:0)
Block(-6,11,-6,AIR:0)
RandomBlock(-6,11,-5,CONCRETE:7,60,quark:iron_plate:1,20,STAINED_CLAY:12,15,STAINED_CLAY:15,5,AIR,7,IRON_BARS,12,CONCRETE:7,100)
Block(-6,11,-4,AIR:0)
Block(-6,11,-3,AIR:0)
RandomBlock(-6,11,-2,CONCRETE:7,60,quark:iron_plate:1,20,STAINED_CLAY:12,15,STAINED_CLAY:15,5,AIR,7,IRON_BARS,12,CONCRETE:7,100)
Block(-6,11,-1,AIR:0)
Block(-6,11,0,AIR:0)
Block(-6,11,1,AIR:0)
Block(-6,11,2,AIR:0)
Block(-6,11,3,AIR:0)
Block(-6,11,4,AIR:0)
Block(-6,11,5,AIR:0)
Block(-6,11,6,AIR:0)
RandomBlock(-6,11,7,CONCRETE:7,60,quark:iron_plate:1,20,STAINED_CLAY:12,15,STAINED_CLAY:15,5,AIR,7,IRON_BARS,12,CONCRETE:7,100)
RandomBlock(-6,11,8,CONCRETE:7,60,quark:iron_plate:1,20,STAINED_CLAY:12,15,STAINED_CLAY:15,5,AIR,7,IRON_BARS,12,CONCRETE:7,100)
Block(-6,12,-7,AIR:0)
Block(-6,12,-6,AIR:0)
RandomBlock(-6,12,-5,CONCRETE:7,60,quark:iron_plate:1,20,STAINED_CLAY:12,15,STAINED_CLAY:15,5,AIR,7,IRON_BARS,12,CONCRETE:7,100)
RandomBlock(-6,12,-4,CONCRETE:7,60,quark:iron_plate:1,20,STAINED_CLAY:12,15,STAINED_CLAY:15,5,AIR,7,IRON_BARS,12,CONCRETE:7,100)
RandomBlock(-6,12,-3,CONCRETE:7,60,quark:iron_plate:1,20,STAINED_CLAY:12,15,STAINED_CLAY:15,5,AIR,7,IRON_BARS,12,CONCRETE:7,100)
RandomBlock(-6,12,-2,CONCRETE:7,60,quark:iron_plate:1,20,STAINED_CLAY:12,15,STAINED_CLAY:15,5,AIR,7,IRON_BARS,12,CONCRETE:7,100)
RandomBlock(-6,12,-1,CONCRETE:7,60,quark:iron_plate:1,20,STAINED_CLAY:12,15,STAINED_CLAY:15,5,AIR,7,IRON_BARS,12,CONCRETE:7,100)
RandomBlock(-6,12,0,CONCRETE:7,60,quark:iron_plate:1,20,STAINED_CLAY:12,15,STAINED_CLAY:15,5,AIR,7,IRON_BARS,12,CONCRETE:7,100)
RandomBlock(-6,12,1,CONCRETE:7,60,quark:iron_plate:1,20,STAINED_CLAY:12,15,STAINED_CLAY:15,5,AIR,7,IRON_BARS,12,CONCRETE:7,100)
RandomBlock(-6,12,2,CONCRETE:7,60,quark:iron_plate:1,20,STAINED_CLAY:12,15,STAINED_CLAY:15,5,AIR,7,IRON_BARS,12,CONCRETE:7,100)
RandomBlock(-6,12,3,CONCRETE:7,60,quark:iron_plate:1,20,STAINED_CLAY:12,15,STAINED_CLAY:15,5,AIR,7,IRON_BARS,12,CONCRETE:7,100)
RandomBlock(-6,12,4,CONCRETE:7,60,quark:iron_plate:1,20,STAINED_CLAY:12,15,STAINED_CLAY:15,5,AIR,7,IRON_BARS,12,CONCRETE:7,100)
RandomBlock(-6,12,5,CONCRETE:7,60,quark:iron_plate:1,20,STAINED_CLAY:12,15,STAINED_CLAY:15,5,AIR,7,IRON_BARS,12,CONCRETE:7,100)
RandomBlock(-6,12,6,CONCRETE:7,60,quark:iron_plate:1,20,STAINED_CLAY:12,15,STAINED_CLAY:15,5,AIR,7,IRON_BARS,12,CONCRETE:7,100)
RandomBlock(-6,12,7,CONCRETE:7,60,quark:iron_plate:1,20,STAINED_CLAY:12,15,STAINED_CLAY:15,5,AIR,7,IRON_BARS,12,CONCRETE:7,100)
RandomBlock(-6,12,8,CONCRETE:7,60,quark:iron_plate:1,20,STAINED_CLAY:12,15,STAINED_CLAY:15,5,AIR,7,IRON_BARS,12,CONCRETE:7,100)
Block(-6,13,-7,AIR:0)
Block(-6,13,-6,AIR:0)
Block(-6,13,-5,IRON_FENCE:0)
Block(-6,13,-4,AIR:0)
Block(-6,13,-3,CONCRETE:11)
Block(-6,13,-2,AIR:0)
RandomBlock(-6,13,-1,CONCRETE:7,60,quark:iron_plate:1,20,STAINED_CLAY:12,15,STAINED_CLAY:15,5,AIR,7,IRON_BARS,12,CONCRETE:7,100)
Block(-6,13,0,CONCRETE:11)
Block(-6,13,1,CONCRETE:11)
RandomBlock(-6,13,2,CONCRETE:7,60,quark:iron_plate:1,20,STAINED_CLAY:12,15,STAINED_CLAY:15,5,AIR,7,IRON_BARS,12,CONCRETE:7,100)
Block(-6,13,3,LEVER:1)
Block(-6,13,4,AIR:0)
Block(-6,13,5,STONE:6)
Block(-6,13,6,CONCRETE:15)
Block(-6,13,7,CONCRETE:15)
Block(-6,13,8,CONCRETE:15)
Block(-6,14,-7,AIR:0)
Block(-6,14,-6,AIR:0)
Block(-6,14,-5,AIR:0)
Block(-6,14,-4,AIR:0)
Block(-6,14,-3,AIR:0)
Block(-6,14,-2,AIR:0)
Block(-6,14,-1,STONE:6)
Block(-6,14,0,STATIONARY_WATER:1)
Block(-6,14,1,STATIONARY_WATER:1)
Block(-6,14,2,STONE:6)
Block(-6,14,3,AIR:0)
Block(-6,14,4,AIR:0)
Block(-6,14,5,STONE:6)
Block(-6,14,6,CONCRETE:15)
Block(-6,14,7,CONCRETE:15)
Block(-6,14,8,CONCRETE:15)
Block(-6,15,-7,AIR:0)
Block(-6,15,-6,AIR:0)
Block(-6,15,-5,AIR:0)
Block(-6,15,-4,AIR:0)
Block(-6,15,-3,AIR:0)
Block(-6,15,-2,AIR:0)
Block(-6,15,-1,STONE:6)
Block(-6,15,0,AIR:0)
Block(-6,15,1,AIR:0)
Block(-6,15,2,STONE:6)
Block(-6,15,3,AIR:0)
Block(-6,15,4,AIR:0)
Block(-6,15,5,STONE:6)
Block(-6,15,6,CONCRETE:15)
Block(-6,15,7,CONCRETE:15)
Block(-6,15,8,CONCRETE:11)
Block(-6,16,-7,AIR:0)
Block(-6,16,-6,AIR:0)
Block(-6,16,-5,AIR:0)
Block(-6,16,-4,AIR:0)
Block(-6,16,-3,AIR:0)
Block(-6,16,-2,AIR:0)
Block(-6,16,-1,STONE:6)
Block(-6,16,0,STONE:6)
Block(-6,16,1,STONE:6)
Block(-6,16,2,STONE:6)
Block(-6,16,3,AIR:0)
Block(-6,16,4,AIR:0)
Block(-6,16,5,STONE:6)
Block(-6,16,6,STONE:6)
Block(-6,16,7,STONE:6)
Block(-6,16,8,SMOOTH_STAIRS:1)
RandomBlock(-6,17,-7,CONCRETE:7,60,quark:iron_plate:1,20,STAINED_CLAY:12,15,STAINED_CLAY:15,5,AIR,7,IRON_BARS,12,CONCRETE:7,100)
RandomBlock(-6,17,-6,CONCRETE:7,60,quark:iron_plate:1,20,STAINED_CLAY:12,15,STAINED_CLAY:15,5,AIR,7,IRON_BARS,12,CONCRETE:7,100)
RandomBlock(-6,17,-5,CONCRETE:7,60,quark:iron_plate:1,20,STAINED_CLAY:12,15,STAINED_CLAY:15,5,AIR,7,IRON_BARS,12,CONCRETE:7,100)
RandomBlock(-6,17,-4,CONCRETE:7,60,quark:iron_plate:1,20,STAINED_CLAY:12,15,STAINED_CLAY:15,5,AIR,7,IRON_BARS,12,CONCRETE:7,100)
RandomBlock(-6,17,-3,CONCRETE:7,60,quark:iron_plate:1,20,STAINED_CLAY:12,15,STAINED_CLAY:15,5,AIR,7,IRON_BARS,12,CONCRETE:7,100)
RandomBlock(-6,17,-2,CONCRETE:7,60,quark:iron_plate:1,20,STAINED_CLAY:12,15,STAINED_CLAY:15,5,AIR,7,IRON_BARS,12,CONCRETE:7,100)
RandomBlock(-6,17,-1,CONCRETE:7,60,quark:iron_plate:1,20,STAINED_CLAY:12,15,STAINED_CLAY:15,5,AIR,7,IRON_BARS,12,CONCRETE:7,100)
RandomBlock(-6,17,0,CONCRETE:7,60,quark:iron_plate:1,20,STAINED_CLAY:12,15,STAINED_CLAY:15,5,AIR,7,IRON_BARS,12,CONCRETE:7,100)
RandomBlock(-6,17,1,CONCRETE:7,60,quark:iron_plate:1,20,STAINED_CLAY:12,15,STAINED_CLAY:15,5,AIR,7,IRON_BARS,12,CONCRETE:7,100)
RandomBlock(-6,17,2,CONCRETE:7,60,quark:iron_plate:1,20,STAINED_CLAY:12,15,STAINED_CLAY:15,5,AIR,7,IRON_BARS,12,CONCRETE:7,100)
RandomBlock(-6,17,3,CONCRETE:7,60,quark:iron_plate:1,20,STAINED_CLAY:12,15,STAINED_CLAY:15,5,AIR,7,IRON_BARS,12,CONCRETE:7,100)
RandomBlock(-6,17,4,CONCRETE:7,60,quark:iron_plate:1,20,STAINED_CLAY:12,15,STAINED_CLAY:15,5,AIR,7,IRON_BARS,12,CONCRETE:7,100)
RandomBlock(-6,17,5,CONCRETE:7,60,quark:iron_plate:1,20,STAINED_CLAY:12,15,STAINED_CLAY:15,5,AIR,7,IRON_BARS,12,CONCRETE:7,100)
RandomBlock(-6,17,6,CONCRETE:7,60,quark:iron_plate:1,20,STAINED_CLAY:12,15,STAINED_CLAY:15,5,AIR,7,IRON_BARS,12,CONCRETE:7,100)
RandomBlock(-6,17,7,CONCRETE:7,60,quark:iron_plate:1,20,STAINED_CLAY:12,15,STAINED_CLAY:15,5,AIR,7,IRON_BARS,12,CONCRETE:7,100)
RandomBlock(-6,17,8,CONCRETE:7,60,quark:iron_plate:1,20,STAINED_CLAY:12,15,STAINED_CLAY:15,5,AIR,7,IRON_BARS,12,CONCRETE:7,100)
Block(-6,18,-7,CONCRETE:15)
Block(-6,18,-6,CONCRETE:15)
Block(-6,18,-5,CONCRETE:15)
Block(-6,18,-4,CONCRETE:15)
Block(-6,18,-3,CONCRETE:15)
Block(-6,18,-2,CONCRETE:15)
Block(-6,18,-1,CONCRETE:15)
Block(-6,18,0,CONCRETE:8)
Block(-6,18,1,CONCRETE:8)
Block(-6,18,2,CONCRETE:15)
Block(-6,18,3,CONCRETE:15)
Block(-6,18,4,CONCRETE:15)
Block(-6,18,5,CONCRETE:15)
Block(-6,18,6,CONCRETE:15)
Block(-6,18,7,CONCRETE:15)
Block(-6,18,8,CONCRETE:15)
Block(-6,19,-5,CONCRETE:15)
Block(-6,19,-4,CONCRETE:15)
Block(-6,19,-3,CONCRETE:15)
Block(-6,19,-2,CONCRETE:15)
Block(-6,19,-1,CONCRETE:15)
Block(-6,19,2,CONCRETE:15)
Block(-6,19,3,CONCRETE:15)
Block(-6,19,4,CONCRETE:15)
Block(-6,19,5,CONCRETE:15)
Block(-6,19,6,CONCRETE:15)
Block(-6,20,-5,CONCRETE:15)
Block(-6,20,-4,CONCRETE:15)
Block(-6,20,-3,CONCRETE:15)
Block(-6,20,-2,CONCRETE:15)
Block(-6,20,-1,CONCRETE:15)
Block(-6,20,2,CONCRETE:15)
Block(-6,20,3,CONCRETE:15)
Block(-6,20,4,CONCRETE:15)
Block(-6,20,5,CONCRETE:15)
Block(-6,20,6,CONCRETE:15)
Block(-6,21,-5,CONCRETE:15)
Block(-6,21,-4,CONCRETE:15)
Block(-6,21,-3,CONCRETE:15)
Block(-6,21,-2,CONCRETE:15)
Block(-6,21,-1,CONCRETE:15)
Block(-6,21,2,CONCRETE:15)
Block(-6,21,3,CONCRETE:15)
Block(-6,21,4,CONCRETE:15)
Block(-6,21,5,CONCRETE:15)
Block(-6,21,6,CONCRETE:15)
Block(-6,22,-5,CONCRETE:15)
Block(-6,22,-4,CONCRETE:15)
Block(-6,22,-3,CONCRETE:15)
Block(-6,22,-2,CONCRETE:15)
Block(-6,22,-1,CONCRETE:15)
Block(-6,22,2,CONCRETE:15)
Block(-6,22,3,CONCRETE:15)
Block(-6,22,4,CONCRETE:15)
Block(-6,22,5,CONCRETE:15)
Block(-6,22,6,CONCRETE:15)
Block(-6,23,-5,CONCRETE:15)
Block(-6,23,-4,CONCRETE:15)
Block(-6,23,-3,CONCRETE:15)
Block(-6,23,-2,CONCRETE:15)
Block(-6,23,-1,CONCRETE:15)
Block(-6,23,0,STAINED_GLASS:15)
Block(-6,23,1,STAINED_GLASS:15)
Block(-6,23,2,CONCRETE:15)
Block(-6,23,3,CONCRETE:15)
Block(-6,23,4,CONCRETE:15)
Block(-6,23,5,CONCRETE:15)
Block(-6,23,6,CONCRETE:15)
Block(-6,24,-7,CONCRETE:15)
Block(-6,24,-6,STAINED_GLASS:15)
Block(-6,24,-5,CONCRETE:15)
Block(-6,24,-4,CONCRETE:15)
Block(-6,24,-3,CONCRETE:15)
Block(-6,24,-2,CONCRETE:15)
Block(-6,24,-1,CONCRETE:15)
Block(-6,24,0,QUARTZ_STAIRS:1)
Block(-6,24,1,QUARTZ_STAIRS:1)
Block(-6,24,2,CONCRETE:15)
Block(-6,24,3,CONCRETE:15)
Block(-6,24,4,CONCRETE:15)
Block(-6,24,5,CONCRETE:15)
Block(-6,24,6,CONCRETE:15)
Block(-6,24,7,STAINED_GLASS:15)
Block(-6,24,8,CONCRETE:15)
Block(-6,25,-5,CONCRETE:15)
Block(-6,25,-4,CONCRETE:15)
Block(-6,25,-3,CONCRETE:15)
Block(-6,25,-2,CONCRETE:15)
Block(-6,25,-1,CONCRETE:15)
Block(-6,25,2,CONCRETE:15)
Block(-6,25,3,CONCRETE:15)
Block(-6,25,4,CONCRETE:15)
Block(-6,25,5,CONCRETE:15)
Block(-6,25,6,CONCRETE:15)
Block(-6,26,-5,CONCRETE:15)
Block(-6,26,-4,CONCRETE:15)
Block(-6,26,-3,CONCRETE:15)
Block(-6,26,-2,CONCRETE:15)
Block(-6,26,-1,CONCRETE:15)
Block(-6,26,2,CONCRETE:15)
Block(-6,26,3,CONCRETE:15)
Block(-6,26,4,CONCRETE:15)
Block(-6,26,5,CONCRETE:15)
Block(-6,26,6,CONCRETE:15)
Block(-6,27,-5,CONCRETE:15)
Block(-6,27,-4,CONCRETE:15)
Block(-6,27,-3,CONCRETE:15)
Block(-6,27,-2,CONCRETE:15)
Block(-6,27,-1,CONCRETE:15)
Block(-6,27,2,CONCRETE:15)
Block(-6,27,3,CONCRETE:15)
Block(-6,27,4,CONCRETE:15)
Block(-6,27,5,CONCRETE:15)
Block(-6,27,6,CONCRETE:15)
Block(-6,28,-5,CONCRETE:15)
Block(-6,28,-4,CONCRETE:15)
Block(-6,28,-3,CONCRETE:15)
Block(-6,28,-2,CONCRETE:15)
Block(-6,28,-1,CONCRETE:15)
Block(-6,28,2,CONCRETE:15)
Block(-6,28,3,CONCRETE:15)
Block(-6,28,4,CONCRETE:15)
Block(-6,28,5,CONCRETE:15)
Block(-6,28,6,CONCRETE:15)
Block(-6,29,-5,CONCRETE:15)
Block(-6,29,-4,CONCRETE:15)
Block(-6,29,-3,CONCRETE:15)
Block(-6,29,-2,CONCRETE:15)
Block(-6,29,-1,CONCRETE:15)
Block(-6,29,0,STAINED_GLASS:15)
Block(-6,29,1,STAINED_GLASS:15)
Block(-6,29,2,CONCRETE:15)
Block(-6,29,3,CONCRETE:15)
Block(-6,29,4,CONCRETE:15)
Block(-6,29,5,CONCRETE:15)
Block(-6,29,6,CONCRETE:15)
Block(-6,30,-7,CONCRETE:15)
Block(-6,30,-6,STAINED_GLASS:15)
Block(-6,30,-5,CONCRETE:15)
Block(-6,30,-4,CONCRETE:15)
Block(-6,30,-3,CONCRETE:15)
Block(-6,30,-2,CONCRETE:15)
Block(-6,30,-1,CONCRETE:15)
Block(-6,30,0,QUARTZ_STAIRS:1)
Block(-6,30,1,QUARTZ_STAIRS:1)
Block(-6,30,2,CONCRETE:15)
Block(-6,30,3,CONCRETE:15)
Block(-6,30,4,CONCRETE:15)
Block(-6,30,5,CONCRETE:15)
Block(-6,30,6,CONCRETE:15)
Block(-6,30,7,STAINED_GLASS:15)
Block(-6,30,8,CONCRETE:15)
Block(-6,31,-5,CONCRETE:15)
Block(-6,31,-4,CONCRETE:15)
Block(-6,31,-3,CONCRETE:15)
Block(-6,31,-2,CONCRETE:15)
Block(-6,31,-1,CONCRETE:15)
Block(-6,31,2,CONCRETE:15)
Block(-6,31,3,CONCRETE:15)
Block(-6,31,4,CONCRETE:15)
Block(-6,31,5,CONCRETE:15)
Block(-6,31,6,CONCRETE:15)
Block(-6,32,-5,CONCRETE:15)
Block(-6,32,-4,CONCRETE:15)
Block(-6,32,-3,CONCRETE:15)
Block(-6,32,-2,CONCRETE:15)
Block(-6,32,-1,CONCRETE:15)
Block(-6,32,2,CONCRETE:15)
Block(-6,32,3,CONCRETE:15)
Block(-6,32,4,CONCRETE:15)
Block(-6,32,5,CONCRETE:15)
Block(-6,32,6,CONCRETE:15)
Block(-6,33,-5,CONCRETE:15)
Block(-6,33,-4,CONCRETE:15)
Block(-6,33,-3,CONCRETE:15)
Block(-6,33,-2,CONCRETE:15)
Block(-6,33,-1,CONCRETE:15)
Block(-6,33,2,CONCRETE:15)
Block(-6,33,3,CONCRETE:15)
Block(-6,33,4,CONCRETE:15)
Block(-6,33,5,CONCRETE:15)
Block(-6,33,6,CONCRETE:15)
Block(-6,34,-5,CONCRETE:15)
Block(-6,34,-4,CONCRETE:15)
Block(-6,34,-3,CONCRETE:15)
Block(-6,34,-2,CONCRETE:15)
Block(-6,34,-1,CONCRETE:15)
Block(-6,34,2,CONCRETE:15)
Block(-6,34,3,CONCRETE:15)
Block(-6,34,4,CONCRETE:15)
Block(-6,34,5,CONCRETE:15)
Block(-6,34,6,CONCRETE:15)
Block(-6,35,-5,CONCRETE:15)
Block(-6,35,-4,CONCRETE:15)
Block(-6,35,-3,CONCRETE:15)
Block(-6,35,-2,CONCRETE:15)
Block(-6,35,-1,CONCRETE:15)
Block(-6,35,0,STAINED_GLASS:15)
Block(-6,35,1,STAINED_GLASS:15)
Block(-6,35,2,CONCRETE:15)
Block(-6,35,3,CONCRETE:15)
Block(-6,35,4,CONCRETE:15)
Block(-6,35,5,CONCRETE:15)
Block(-6,35,6,CONCRETE:15)
Block(-6,36,-7,CONCRETE:8)
Block(-6,36,-6,STAINED_GLASS:15)
Block(-6,36,-5,CONCRETE:15)
Block(-6,36,-4,CONCRETE:15)
Block(-6,36,-3,CONCRETE:15)
Block(-6,36,-2,CONCRETE:15)
Block(-6,36,-1,CONCRETE:15)
Block(-6,36,0,QUARTZ_STAIRS:1)
Block(-6,36,1,QUARTZ_STAIRS:1)
Block(-6,36,2,CONCRETE:15)
Block(-6,36,3,CONCRETE:15)
Block(-6,36,4,CONCRETE:15)
Block(-6,36,5,CONCRETE:15)
Block(-6,36,6,CONCRETE:15)
Block(-6,36,7,STAINED_GLASS:15)
Block(-6,36,8,CONCRETE:8)
Block(-6,37,-5,CONCRETE:15)
Block(-6,37,-4,CONCRETE:15)
Block(-6,37,-3,CONCRETE:15)
Block(-6,37,-2,CONCRETE:15)
Block(-6,37,-1,CONCRETE:15)
Block(-6,37,2,CONCRETE:15)
Block(-6,37,3,CONCRETE:15)
Block(-6,37,4,CONCRETE:15)
Block(-6,37,5,CONCRETE:15)
Block(-6,37,6,CONCRETE:15)
Block(-6,38,-5,CONCRETE:15)
Block(-6,38,-4,CONCRETE:15)
Block(-6,38,-3,CONCRETE:15)
Block(-6,38,-2,CONCRETE:15)
Block(-6,38,-1,CONCRETE:15)
Block(-6,38,2,CONCRETE:15)
Block(-6,38,3,CONCRETE:15)
Block(-6,38,4,CONCRETE:15)
Block(-6,38,5,CONCRETE:15)
Block(-6,38,6,CONCRETE:15)
Block(-6,39,-5,CONCRETE:15)
Block(-6,39,-4,CONCRETE:15)
Block(-6,39,-3,CONCRETE:15)
Block(-6,39,-2,CONCRETE:15)
Block(-6,39,-1,CONCRETE:15)
Block(-6,39,2,CONCRETE:15)
Block(-6,39,3,CONCRETE:15)
Block(-6,39,4,CONCRETE:15)
Block(-6,39,5,CONCRETE:15)
Block(-6,39,6,CONCRETE:15)
Block(-6,40,-5,CONCRETE:15)
Block(-6,40,-4,CONCRETE:15)
Block(-6,40,-3,CONCRETE:15)
Block(-6,40,-2,CONCRETE:15)
Block(-6,40,-1,CONCRETE:15)
Block(-6,40,2,CONCRETE:15)
Block(-6,40,3,CONCRETE:15)
Block(-6,40,4,CONCRETE:15)
Block(-6,40,5,CONCRETE:15)
Block(-6,40,6,CONCRETE:15)
Block(-6,41,-5,CONCRETE:15)
Block(-6,41,-4,CONCRETE:15)
Block(-6,41,-3,CONCRETE:15)
Block(-6,41,-2,CONCRETE:15)
Block(-6,41,-1,CONCRETE:15)
Block(-6,41,0,STAINED_GLASS:15)
Block(-6,41,1,STAINED_GLASS:15)
Block(-6,41,2,CONCRETE:15)
Block(-6,41,3,CONCRETE:15)
Block(-6,41,4,CONCRETE:15)
Block(-6,41,5,CONCRETE:15)
Block(-6,41,6,CONCRETE:15)
Block(-6,42,-7,CONCRETE:8)
Block(-6,42,-6,CONCRETE:8)
Block(-6,42,-5,CONCRETE:8)
Block(-6,42,-4,CONCRETE:8)
Block(-6,42,-3,CONCRETE:8)
Block(-6,42,-2,CONCRETE:8)
Block(-6,42,-1,CONCRETE:8)
Block(-6,42,0,CONCRETE:8)
Block(-6,42,1,CONCRETE:8)
Block(-6,42,2,CONCRETE:8)
Block(-6,42,3,CONCRETE:8)
Block(-6,42,4,CONCRETE:8)
Block(-6,42,5,CONCRETE:8)
Block(-6,42,6,CONCRETE:8)
Block(-6,42,7,CONCRETE:8)
Block(-6,42,8,CONCRETE:8)
Block(-6,43,-7,SPRUCE_DOOR:1)
Block(-6,43,-5,CONCRETE:15)
Block(-6,43,-2,PRISMARINE:2)
Block(-6,43,-1,CARPET:15)
Block(-6,43,0,CARPET:10)
Block(-6,43,1,CARPET:15)
Block(-6,43,2,CARPET:10)
Block(-6,43,3,CARPET:15)
Block(-6,43,4,CARPET:10)
Block(-6,43,5,PLANKS:0)
Block(-6,43,6,PRISMARINE:2)
Block(-6,43,8,STAINED_GLASS_PANE:15)
Block(-6,44,-7,SPRUCE_DOOR:8)
Block(-6,44,-5,CONCRETE:15)
Block(-6,44,-2,PRISMARINE:2)
Block(-6,44,6,PRISMARINE:2)
Block(-6,45,-5,CONCRETE:15)
Block(-6,45,-2,PRISMARINE:2)
Block(-6,45,6,PRISMARINE:2)
Block(-6,46,-5,CONCRETE:15)
Block(-6,46,-2,WOOD_STEP:5)
RandomBlock(-6,46,5,AIR,95,WALL_BANNER:2,../AllScraperData/skyscraper_3x3_01/2705-bannerC16R16.nbt,100)
Block(-6,46,6,PRISMARINE:2)
Block(-6,47,-5,CONCRETE:15)
Block(-6,47,0,STAINED_GLASS:15)
Block(-6,47,1,STAINED_GLASS:15)
Block(-6,47,6,PRISMARINE:2)
Block(-6,48,-7,CONCRETE:8)
Block(-6,48,-6,CONCRETE:8)
Block(-6,48,-5,CONCRETE:15)
Block(-6,48,-4,CONCRETE:15)
Block(-6,48,-3,CONCRETE:15)
Block(-6,48,-2,CONCRETE:15)
Block(-6,48,-1,CONCRETE:15)
Block(-6,48,2,CONCRETE:15)
Block(-6,48,3,CONCRETE:15)
Block(-6,48,4,CONCRETE:15)
Block(-6,48,5,CONCRETE:15)
Block(-6,48,6,CONCRETE:15)
Block(-6,48,7,CONCRETE:8)
Block(-6,48,8,CONCRETE:8)
Block(-6,49,-7,CONCRETE:8)
Block(-6,49,-6,CONCRETE:8)
Block(-6,49,-5,CONCRETE:8)
Block(-6,49,-4,CONCRETE:8)
Block(-6,49,-3,CONCRETE:8)
Block(-6,49,-2,CONCRETE:8)
Block(-6,49,-1,CONCRETE:8)
Block(-6,49,2,CONCRETE:8)
Block(-6,49,3,CONCRETE:8)
Block(-6,49,4,CONCRETE:8)
Block(-6,49,5,CONCRETE:8)
Block(-6,49,6,CONCRETE:8)
Block(-6,49,7,CONCRETE:8)
Block(-6,49,8,CONCRETE:8)
Block(-6,50,-5,CONCRETE:8)
Block(-6,50,-4,CONCRETE:8)
Block(-6,50,-3,CONCRETE:8)
Block(-6,50,-2,CONCRETE:8)
Block(-6,50,-1,CONCRETE:8)
Block(-6,50,2,CONCRETE:8)
Block(-6,50,3,CONCRETE:8)
Block(-6,50,4,CONCRETE:8)
Block(-6,50,5,CONCRETE:8)
Block(-6,50,6,CONCRETE:8)
Block(-6,51,-5,CONCRETE:8)
Block(-6,51,-4,CONCRETE:8)
Block(-6,51,-3,CONCRETE:8)
Block(-6,51,-2,CONCRETE:8)
Block(-6,51,-1,CONCRETE:8)
Block(-6,51,2,CONCRETE:8)
Block(-6,51,3,CONCRETE:8)
Block(-6,51,4,CONCRETE:8)
Block(-6,51,5,CONCRETE:8)
Block(-6,51,6,CONCRETE:8)
Block(-6,52,-5,CONCRETE:8)
Block(-6,52,-4,CONCRETE:8)
Block(-6,52,-3,CONCRETE:8)
Block(-6,52,-2,CONCRETE:8)
Block(-6,52,-1,CONCRETE:8)
Block(-6,52,0,STAINED_GLASS:15)
Block(-6,52,1,STAINED_GLASS:15)
Block(-6,52,2,CONCRETE:8)
Block(-6,52,3,CONCRETE:8)
Block(-6,52,4,CONCRETE:8)
Block(-6,52,5,CONCRETE:8)
Block(-6,52,6,CONCRETE:8)
RandomBlock(-5,0,-7,CONCRETE:7,60,quark:iron_plate:1,20,STAINED_CLAY:12,15,STAINED_CLAY:15,5,AIR,7,IRON_BARS,12,CONCRETE:7,100)
RandomBlock(-5,0,-6,CONCRETE:7,60,quark:iron_plate:1,20,STAINED_CLAY:12,15,STAINED_CLAY:15,5,AIR,7,IRON_BARS,12,CONCRETE:7,100)
RandomBlock(-5,0,-5,CONCRETE:7,60,quark:iron_plate:1,20,STAINED_CLAY:12,15,STAINED_CLAY:15,5,AIR,7,IRON_BARS,12,CONCRETE:7,100)
RandomBlock(-5,0,-4,CONCRETE:7,60,quark:iron_plate:1,20,STAINED_CLAY:12,15,STAINED_CLAY:15,5,AIR,7,IRON_BARS,12,CONCRETE:7,100)
RandomBlock(-5,0,-3,CONCRETE:7,60,quark:iron_plate:1,20,STAINED_CLAY:12,15,STAINED_CLAY:15,5,AIR,7,IRON_BARS,12,CONCRETE:7,100)
RandomBlock(-5,0,-2,CONCRETE:7,60,quark:iron_plate:1,20,STAINED_CLAY:12,15,STAINED_CLAY:15,5,AIR,7,IRON_BARS,12,CONCRETE:7,100)
RandomBlock(-5,0,-1,CONCRETE:7,60,quark:iron_plate:1,20,STAINED_CLAY:12,15,STAINED_CLAY:15,5,AIR,7,IRON_BARS,12,CONCRETE:7,100)
RandomBlock(-5,0,0,CONCRETE:7,60,quark:iron_plate:1,20,STAINED_CLAY:12,15,STAINED_CLAY:15,5,AIR,7,IRON_BARS,12,CONCRETE:7,100)
RandomBlock(-5,0,1,CONCRETE:7,60,quark:iron_plate:1,20,STAINED_CLAY:12,15,STAINED_CLAY:15,5,AIR,7,IRON_BARS,12,CONCRETE:7,100)
RandomBlock(-5,0,2,CONCRETE:7,60,quark:iron_plate:1,20,STAINED_CLAY:12,15,STAINED_CLAY:15,5,AIR,7,IRON_BARS,12,CONCRETE:7,100)
RandomBlock(-5,0,3,CONCRETE:7,60,quark:iron_plate:1,20,STAINED_CLAY:12,15,STAINED_CLAY:15,5,AIR,7,IRON_BARS,12,CONCRETE:7,100)
RandomBlock(-5,0,4,CONCRETE:7,60,quark:iron_plate:1,20,STAINED_CLAY:12,15,STAINED_CLAY:15,5,AIR,7,IRON_BARS,12,CONCRETE:7,100)
RandomBlock(-5,0,5,CONCRETE:7,60,quark:iron_plate:1,20,STAINED_CLAY:12,15,STAINED_CLAY:15,5,AIR,7,IRON_BARS,12,CONCRETE:7,100)
RandomBlock(-5,0,6,CONCRETE:7,60,quark:iron_plate:1,20,STAINED_CLAY:12,15,STAINED_CLAY:15,5,AIR,7,IRON_BARS,12,CONCRETE:7,100)
RandomBlock(-5,0,7,CONCRETE:7,60,quark:iron_plate:1,20,STAINED_CLAY:12,15,STAINED_CLAY:15,5,AIR,7,IRON_BARS,12,CONCRETE:7,100)
RandomBlock(-5,0,8,CONCRETE:7,60,quark:iron_plate:1,20,STAINED_CLAY:12,15,STAINED_CLAY:15,5,AIR,7,IRON_BARS,12,CONCRETE:7,100)
Block(-5,1,-7,STATIONARY_WATER:0)
Block(-5,1,-6,STATIONARY_WATER:0)
Block(-5,1,-5,STATIONARY_WATER:0)
Block(-5,1,-4,STATIONARY_WATER:0)
Block(-5,1,-3,STATIONARY_WATER:0)
Block(-5,1,-2,STATIONARY_WATER:0)
Block(-5,1,-1,STATIONARY_WATER:0)
Block(-5,1,0,STATIONARY_WATER:0)
Block(-5,1,1,STATIONARY_WATER:0)
Block(-5,1,2,STATIONARY_WATER:0)
Block(-5,1,3,STATIONARY_WATER:0)
Block(-5,1,4,STATIONARY_WATER:0)
Block(-5,1,5,STATIONARY_WATER:0)
Block(-5,1,6,STATIONARY_WATER:0)
Block(-5,1,7,STATIONARY_WATER:0)
Block(-5,1,8,STATIONARY_WATER:0)
Block(-5,2,-7,AIR:0)
Block(-5,2,-6,AIR:0)
Block(-5,2,-5,AIR:0)
Block(-5,2,-4,AIR:0)
Block(-5,2,-3,AIR:0)
Block(-5,2,-2,AIR:0)
Block(-5,2,-1,AIR:0)
Block(-5,2,0,AIR:0)
Block(-5,2,1,AIR:0)
Block(-5,2,2,AIR:0)
Block(-5,2,3,AIR:0)
Block(-5,2,4,AIR:0)
Block(-5,2,5,AIR:0)
Block(-5,2,6,AIR:0)
Block(-5,2,7,AIR:0)
Block(-5,2,8,AIR:0)
Block(-5,3,-7,AIR:0)
Block(-5,3,-6,AIR:0)
Block(-5,3,-5,AIR:0)
Block(-5,3,-4,AIR:0)
Block(-5,3,-3,AIR:0)
Block(-5,3,-2,AIR:0)
Block(-5,3,-1,AIR:0)
Block(-5,3,0,AIR:0)
Block(-5,3,1,AIR:0)
Block(-5,3,2,AIR:0)
Block(-5,3,3,AIR:0)
Block(-5,3,4,AIR:0)
Block(-5,3,5,AIR:0)
Block(-5,3,6,AIR:0)
Block(-5,3,7,AIR:0)
Block(-5,3,8,AIR:0)
Block(-5,4,-7,AIR:0)
Block(-5,4,-6,AIR:0)
Block(-5,4,-5,AIR:0)
Block(-5,4,-4,AIR:0)
Block(-5,4,-3,AIR:0)
Block(-5,4,-2,AIR:0)
Block(-5,4,-1,AIR:0)
Block(-5,4,0,AIR:0)
Block(-5,4,1,AIR:0)
Block(-5,4,2,AIR:0)
Block(-5,4,3,AIR:0)
Block(-5,4,4,AIR:0)
Block(-5,4,5,AIR:0)
Block(-5,4,6,AIR:0)
Block(-5,4,7,AIR:0)
Block(-5,4,8,AIR:0)
Block(-5,5,-7,AIR:0)
Block(-5,5,-6,AIR:0)
Block(-5,5,-5,AIR:0)
Block(-5,5,-4,AIR:0)
Block(-5,5,-3,AIR:0)
Block(-5,5,-2,AIR:0)
Block(-5,5,-1,AIR:0)
Block(-5,5,0,AIR:0)
Block(-5,5,1,AIR:0)
Block(-5,5,2,AIR:0)
Block(-5,5,3,AIR:0)
Block(-5,5,4,AIR:0)
Block(-5,5,5,AIR:0)
Block(-5,5,6,CONCRETE:12)
Block(-5,5,7,CONCRETE:4)
Block(-5,5,8,AIR:0)
RandomBlock(-5,6,-7,CONCRETE:7,60,quark:iron_plate:1,20,STAINED_CLAY:12,15,STAINED_CLAY:15,5,AIR,7,IRON_BARS,12,CONCRETE:7,100)
Block(-5,6,-6,AIR:0)
Block(-5,6,-5,AIR:0)
Block(-5,6,-4,AIR:0)
Block(-5,6,-3,AIR:0)
Block(-5,6,-2,AIR:0)
Block(-5,6,-1,AIR:0)
Block(-5,6,0,AIR:0)
Block(-5,6,1,AIR:0)
Block(-5,6,2,AIR:0)
Block(-5,6,3,AIR:0)
Block(-5,6,4,AIR:0)
Block(-5,6,5,AIR:0)
Block(-5,6,6,AIR:0)
Block(-5,6,7,IRON_FENCE:0)
Block(-5,6,8,AIR:0)
RandomBlock(-5,7,-7,CONCRETE:7,60,quark:iron_plate:1,20,STAINED_CLAY:12,15,STAINED_CLAY:15,5,AIR,7,IRON_BARS,12,CONCRETE:7,100)
RandomBlock(-5,7,-6,CONCRETE:7,60,quark:iron_plate:1,20,STAINED_CLAY:12,15,STAINED_CLAY:15,5,AIR,7,IRON_BARS,12,CONCRETE:7,100)
RandomBlock(-5,7,-5,CONCRETE:7,60,quark:iron_plate:1,20,STAINED_CLAY:12,15,STAINED_CLAY:15,5,AIR,7,IRON_BARS,12,CONCRETE:7,100)
RandomBlock(-5,7,-4,CONCRETE:7,60,quark:iron_plate:1,20,STAINED_CLAY:12,15,STAINED_CLAY:15,5,AIR,7,IRON_BARS,12,CONCRETE:7,100)
RandomBlock(-5,7,-3,CONCRETE:7,60,quark:iron_plate:1,20,STAINED_CLAY:12,15,STAINED_CLAY:15,5,AIR,7,IRON_BARS,12,CONCRETE:7,100)
RandomBlock(-5,7,-2,CONCRETE:7,60,quark:iron_plate:1,20,STAINED_CLAY:12,15,STAINED_CLAY:15,5,AIR,7,IRON_BARS,12,CONCRETE:7,100)
RandomBlock(-5,7,-1,CONCRETE:7,60,quark:iron_plate:1,20,STAINED_CLAY:12,15,STAINED_CLAY:15,5,AIR,7,IRON_BARS,12,CONCRETE:7,100)
RandomBlock(-5,7,0,CONCRETE:7,60,quark:iron_plate:1,20,STAINED_CLAY:12,15,STAINED_CLAY:15,5,AIR,7,IRON_BARS,12,CONCRETE:7,100)
RandomBlock(-5,7,1,CONCRETE:7,60,quark:iron_plate:1,20,STAINED_CLAY:12,15,STAINED_CLAY:15,5,AIR,7,IRON_BARS,12,CONCRETE:7,100)
RandomBlock(-5,7,2,CONCRETE:7,60,quark:iron_plate:1,20,STAINED_CLAY:12,15,STAINED_CLAY:15,5,AIR,7,IRON_BARS,12,CONCRETE:7,100)
RandomBlock(-5,7,3,CONCRETE:7,60,quark:iron_plate:1,20,STAINED_CLAY:12,15,STAINED_CLAY:15,5,AIR,7,IRON_BARS,12,CONCRETE:7,100)
RandomBlock(-5,7,4,CONCRETE:7,60,quark:iron_plate:1,20,STAINED_CLAY:12,15,STAINED_CLAY:15,5,AIR,7,IRON_BARS,12,CONCRETE:7,100)
RandomBlock(-5,7,5,CONCRETE:7,60,quark:iron_plate:1,20,STAINED_CLAY:12,15,STAINED_CLAY:15,5,AIR,7,IRON_BARS,12,CONCRETE:7,100)
RandomBlock(-5,7,6,CONCRETE:7,60,quark:iron_plate:1,20,STAINED_CLAY:12,15,STAINED_CLAY:15,5,AIR,7,IRON_BARS,12,CONCRETE:7,100)
RandomBlock(-5,7,7,CONCRETE:7,60,quark:iron_plate:1,20,STAINED_CLAY:12,15,STAINED_CLAY:15,5,AIR,7,IRON_BARS,12,CONCRETE:7,100)
RandomBlock(-5,7,8,CONCRETE:7,60,quark:iron_plate:1,20,STAINED_CLAY:12,15,STAINED_CLAY:15,5,AIR,7,IRON_BARS,12,CONCRETE:7,100)
RandomBlock(-5,8,-7,CONCRETE:7,60,quark:iron_plate:1,20,STAINED_CLAY:12,15,STAINED_CLAY:15,5,AIR,7,IRON_BARS,12,CONCRETE:7,100)
RandomBlock(-5,8,-6,CONCRETE:7,60,quark:iron_plate:1,20,STAINED_CLAY:12,15,STAINED_CLAY:15,5,AIR,7,IRON_BARS,12,CONCRETE:7,100)
RandomBlock(-5,8,-5,CONCRETE:7,60,quark:iron_plate:1,20,STAINED_CLAY:12,15,STAINED_CLAY:15,5,AIR,7,IRON_BARS,12,CONCRETE:7,100)
Block(-5,8,-4,AIR:0)
Block(-5,8,-3,AIR:0)
RandomBlock(-5,8,-2,CONCRETE:7,60,quark:iron_plate:1,20,STAINED_CLAY:12,15,STAINED_CLAY:15,5,AIR,7,IRON_BARS,12,CONCRETE:7,100)
RandomBlock(-5,8,-1,CONCRETE:7,60,quark:iron_plate:1,20,STAINED_CLAY:12,15,STAINED_CLAY:15,5,AIR,7,IRON_BARS,12,CONCRETE:7,100)
Block(-5,8,0,AIR:0)
Block(-5,8,1,CONCRETE:12)
Block(-5,8,2,AIR:0)
Block(-5,8,3,AIR:0)
RandomBlock(-5,8,4,CONCRETE:7,60,quark:iron_plate:1,20,STAINED_CLAY:12,15,STAINED_CLAY:15,5,AIR,7,IRON_BARS,12,CONCRETE:7,100)
Block(-5,8,5,AIR:0)
RandomBlock(-5,8,6,CONCRETE:7,60,quark:iron_plate:1,20,STAINED_CLAY:12,15,STAINED_CLAY:15,5,AIR,7,IRON_BARS,12,CONCRETE:7,100)
RandomBlock(-5,8,7,CONCRETE:7,60,quark:iron_plate:1,20,STAINED_CLAY:12,15,STAINED_CLAY:15,5,AIR,7,IRON_BARS,12,CONCRETE:7,100)
RandomBlock(-5,8,8,CONCRETE:7,60,quark:iron_plate:1,20,STAINED_CLAY:12,15,STAINED_CLAY:15,5,AIR,7,IRON_BARS,12,CONCRETE:7,100)
RandomBlock(-5,9,-7,CONCRETE:7,60,quark:iron_plate:1,20,STAINED_CLAY:12,15,STAINED_CLAY:15,5,AIR,7,IRON_BARS,12,CONCRETE:7,100)
RandomBlock(-5,9,-6,CONCRETE:7,60,quark:iron_plate:1,20,STAINED_CLAY:12,15,STAINED_CLAY:15,5,AIR,7,IRON_BARS,12,CONCRETE:7,100)
RandomBlock(-5,9,-5,CONCRETE:7,60,quark:iron_plate:1,20,STAINED_CLAY:12,15,STAINED_CLAY:15,5,AIR,7,IRON_BARS,12,CONCRETE:7,100)
Block(-5,9,-4,AIR:0)
Block(-5,9,-3,AIR:0)
RandomBlock(-5,9,-2,CONCRETE:7,60,quark:iron_plate:1,20,STAINED_CLAY:12,15,STAINED_CLAY:15,5,AIR,7,IRON_BARS,12,CONCRETE:7,100)
RandomBlock(-5,9,-1,CONCRETE:7,60,quark:iron_plate:1,20,STAINED_CLAY:12,15,STAINED_CLAY:15,5,AIR,7,IRON_BARS,12,CONCRETE:7,100)
Block(-5,9,0,AIR:0)
Block(-5,9,1,AIR:0)
Block(-5,9,2,AIR:0)
Block(-5,9,3,AIR:0)
RandomBlock(-5,9,4,CONCRETE:7,60,quark:iron_plate:1,20,STAINED_CLAY:12,15,STAINED_CLAY:15,5,AIR,7,IRON_BARS,12,CONCRETE:7,100)
Block(-5,9,5,AIR:0)
RandomBlock(-5,9,6,CONCRETE:7,60,quark:iron_plate:1,20,STAINED_CLAY:12,15,STAINED_CLAY:15,5,AIR,7,IRON_BARS,12,CONCRETE:7,100)
RandomBlock(-5,9,7,CONCRETE:7,60,quark:iron_plate:1,20,STAINED_CLAY:12,15,STAINED_CLAY:15,5,AIR,7,IRON_BARS,12,CONCRETE:7,100)
RandomBlock(-5,9,8,CONCRETE:7,60,quark:iron_plate:1,20,STAINED_CLAY:12,15,STAINED_CLAY:15,5,AIR,7,IRON_BARS,12,CONCRETE:7,100)
RandomBlock(-5,10,-7,CONCRETE:7,60,quark:iron_plate:1,20,STAINED_CLAY:12,15,STAINED_CLAY:15,5,AIR,7,IRON_BARS,12,CONCRETE:7,100)
RandomBlock(-5,10,-6,CONCRETE:7,60,quark:iron_plate:1,20,STAINED_CLAY:12,15,STAINED_CLAY:15,5,AIR,7,IRON_BARS,12,CONCRETE:7,100)
RandomBlock(-5,10,-5,CONCRETE:7,60,quark:iron_plate:1,20,STAINED_CLAY:12,15,STAINED_CLAY:15,5,AIR,7,IRON_BARS,12,CONCRETE:7,100)
Block(-5,10,-4,AIR:0)
Block(-5,10,-3,AIR:0)
RandomBlock(-5,10,-2,CONCRETE:7,60,quark:iron_plate:1,20,STAINED_CLAY:12,15,STAINED_CLAY:15,5,AIR,7,IRON_BARS,12,CONCRETE:7,100)
RandomBlock(-5,10,-1,CONCRETE:7,60,quark:iron_plate:1,20,STAINED_CLAY:12,15,STAINED_CLAY:15,5,AIR,7,IRON_BARS,12,CONCRETE:7,100)
Block(-5,10,0,AIR:0)
Block(-5,10,1,AIR:0)
Block(-5,10,2,AIR:0)
Block(-5,10,3,AIR:0)
RandomBlock(-5,10,4,CONCRETE:7,60,quark:iron_plate:1,20,STAINED_CLAY:12,15,STAINED_CLAY:15,5,AIR,7,IRON_BARS,12,CONCRETE:7,100)
Block(-5,10,5,AIR:0)
RandomBlock(-5,10,6,CONCRETE:7,60,quark:iron_plate:1,20,STAINED_CLAY:12,15,STAINED_CLAY:15,5,AIR,7,IRON_BARS,12,CONCRETE:7,100)
RandomBlock(-5,10,7,CONCRETE:7,60,quark:iron_plate:1,20,STAINED_CLAY:12,15,STAINED_CLAY:15,5,AIR,7,IRON_BARS,12,CONCRETE:7,100)
RandomBlock(-5,10,8,CONCRETE:7,60,quark:iron_plate:1,20,STAINED_CLAY:12,15,STAINED_CLAY:15,5,AIR,7,IRON_BARS,12,CONCRETE:7,100)
Block(-5,11,-7,SMOOTH_STAIRS:0)
Block(-5,11,-6,SMOOTH_STAIRS:0)
RandomBlock(-5,11,-5,CONCRETE:7,60,quark:iron_plate:1,20,STAINED_CLAY:12,15,STAINED_CLAY:15,5,AIR,7,IRON_BARS,12,CONCRETE:7,100)
Block(-5,11,-4,AIR:0)
Block(-5,11,-3,AIR:0)
RandomBlock(-5,11,-2,CONCRETE:7,60,quark:iron_plate:1,20,STAINED_CLAY:12,15,STAINED_CLAY:15,5,AIR,7,IRON_BARS,12,CONCRETE:7,100)
RandomBlock(-5,11,-1,CONCRETE:7,60,quark:iron_plate:1,20,STAINED_CLAY:12,15,STAINED_CLAY:15,5,AIR,7,IRON_BARS,12,CONCRETE:7,100)
Block(-5,11,0,AIR:0)
Block(-5,11,1,AIR:0)
Block(-5,11,2,AIR:0)
Block(-5,11,3,AIR:0)
RandomBlock(-5,11,4,CONCRETE:7,60,quark:iron_plate:1,20,STAINED_CLAY:12,15,STAINED_CLAY:15,5,AIR,7,IRON_BARS,12,CONCRETE:7,100)
Block(-5,11,5,AIR:0)
RandomBlock(-5,11,6,CONCRETE:7,60,quark:iron_plate:1,20,STAINED_CLAY:12,15,STAINED_CLAY:15,5,AIR,7,IRON_BARS,12,CONCRETE:7,100)
RandomBlock(-5,11,7,CONCRETE:7,60,quark:iron_plate:1,20,STAINED_CLAY:12,15,STAINED_CLAY:15,5,AIR,7,IRON_BARS,12,CONCRETE:7,100)
RandomBlock(-5,11,8,CONCRETE:7,60,quark:iron_plate:1,20,STAINED_CLAY:12,15,STAINED_CLAY:15,5,AIR,7,IRON_BARS,12,CONCRETE:7,100)
Block(-5,12,-7,AIR:0)
Block(-5,12,-6,AIR:0)
RandomBlock(-5,12,-5,CONCRETE:7,60,quark:iron_plate:1,20,STAINED_CLAY:12,15,STAINED_CLAY:15,5,AIR,7,IRON_BARS,12,CONCRETE:7,100)
RandomBlock(-5,12,-4,CONCRETE:7,60,quark:iron_plate:1,20,STAINED_CLAY:12,15,STAINED_CLAY:15,5,AIR,7,IRON_BARS,12,CONCRETE:7,100)
RandomBlock(-5,12,-3,CONCRETE:7,60,quark:iron_plate:1,20,STAINED_CLAY:12,15,STAINED_CLAY:15,5,AIR,7,IRON_BARS,12,CONCRETE:7,100)
RandomBlock(-5,12,-2,CONCRETE:7,60,quark:iron_plate:1,20,STAINED_CLAY:12,15,STAINED_CLAY:15,5,AIR,7,IRON_BARS,12,CONCRETE:7,100)
RandomBlock(-5,12,-1,CONCRETE:7,60,quark:iron_plate:1,20,STAINED_CLAY:12,15,STAINED_CLAY:15,5,AIR,7,IRON_BARS,12,CONCRETE:7,100)
RandomBlock(-5,12,0,CONCRETE:7,60,quark:iron_plate:1,20,STAINED_CLAY:12,15,STAINED_CLAY:15,5,AIR,7,IRON_BARS,12,CONCRETE:7,100)
RandomBlock(-5,12,1,CONCRETE:7,60,quark:iron_plate:1,20,STAINED_CLAY:12,15,STAINED_CLAY:15,5,AIR,7,IRON_BARS,12,CONCRETE:7,100)
RandomBlock(-5,12,2,CONCRETE:7,60,quark:iron_plate:1,20,STAINED_CLAY:12,15,STAINED_CLAY:15,5,AIR,7,IRON_BARS,12,CONCRETE:7,100)
RandomBlock(-5,12,3,CONCRETE:7,60,quark:iron_plate:1,20,STAINED_CLAY:12,15,STAINED_CLAY:15,5,AIR,7,IRON_BARS,12,CONCRETE:7,100)
RandomBlock(-5,12,4,CONCRETE:7,60,quark:iron_plate:1,20,STAINED_CLAY:12,15,STAINED_CLAY:15,5,AIR,7,IRON_BARS,12,CONCRETE:7,100)
RandomBlock(-5,12,5,CONCRETE:7,60,quark:iron_plate:1,20,STAINED_CLAY:12,15,STAINED_CLAY:15,5,AIR,7,IRON_BARS,12,CONCRETE:7,100)
RandomBlock(-5,12,6,CONCRETE:7,60,quark:iron_plate:1,20,STAINED_CLAY:12,15,STAINED_CLAY:15,5,AIR,7,IRON_BARS,12,CONCRETE:7,100)
RandomBlock(-5,12,7,CONCRETE:7,60,quark:iron_plate:1,20,STAINED_CLAY:12,15,STAINED_CLAY:15,5,AIR,7,IRON_BARS,12,CONCRETE:7,100)
RandomBlock(-5,12,8,CONCRETE:7,60,quark:iron_plate:1,20,STAINED_CLAY:12,15,STAINED_CLAY:15,5,AIR,7,IRON_BARS,12,CONCRETE:7,100)
Block(-5,13,-7,AIR:0)
Block(-5,13,-6,AIR:0)
Block(-5,13,-5,IRON_FENCE:0)
Block(-5,13,-4,AIR:0)
Block(-5,13,-3,CONCRETE:11)
Block(-5,13,-2,AIR:0)
RandomBlock(-5,13,-1,CONCRETE:7,60,quark:iron_plate:1,20,STAINED_CLAY:12,15,STAINED_CLAY:15,5,AIR,7,IRON_BARS,12,CONCRETE:7,100)
Block(-5,13,0,COBBLE_WALL:0)
Block(-5,13,1,COBBLE_WALL:0)
RandomBlock(-5,13,2,CONCRETE:7,60,quark:iron_plate:1,20,STAINED_CLAY:12,15,STAINED_CLAY:15,5,AIR,7,IRON_BARS,12,CONCRETE:7,100)
Block(-5,13,3,AIR:0)
Block(-5,13,4,AIR:0)
Block(-5,13,5,STONE:6)
Block(-5,13,6,CONCRETE:15)
Block(-5,13,7,CONCRETE:15)
Block(-5,13,8,CONCRETE:15)
Block(-5,14,-7,AIR:0)
Block(-5,14,-6,AIR:0)
Block(-5,14,-5,AIR:0)
Block(-5,14,-4,AIR:0)
Block(-5,14,-3,CONCRETE:11)
Block(-5,14,-2,AIR:0)
Block(-5,14,-1,CONCRETE:11)
RandomBlock(-5,14,0,COBBLESTONE,65,STONEBRICK:0,100)
RandomBlock(-5,14,1,COBBLESTONE,65,STONEBRICK:0,100)
Block(-5,14,2,CONCRETE:11)
Block(-5,14,3,AIR:0)
Block(-5,14,4,AIR:0)
Block(-5,14,5,SMOOTH_STAIRS:1)
Block(-5,14,6,SMOOTH_STAIRS:1)
Block(-5,14,7,SMOOTH_STAIRS:1)
Block(-5,14,8,SMOOTH_STAIRS:1)
Block(-5,15,-7,CONCRETE:11)
Block(-5,15,-6,CONCRETE:11)
Block(-5,15,-5,CONCRETE:11)
Block(-5,15,-4,CONCRETE:11)
Block(-5,15,-3,CONCRETE:11)
Block(-5,15,-2,AIR:0)
Block(-5,15,-1,CONCRETE:11)
Block(-5,15,0,SMOOTH_STAIRS:5)
Block(-5,15,1,SMOOTH_STAIRS:5)
Block(-5,15,2,CONCRETE:11)
Block(-5,15,3,AIR:0)
Block(-5,15,4,AIR:0)
Block(-5,15,5,AIR:0)
Block(-5,15,6,AIR:0)
Block(-5,15,7,AIR:0)
Block(-5,15,8,CONCRETE:11)
Block(-5,16,-7,AIR:0)
Block(-5,16,-6,IRON_FENCE:0)
Block(-5,16,-5,AIR:0)
Block(-5,16,-4,AIR:0)
Block(-5,16,-3,IRON_FENCE:0)
Block(-5,16,-2,AIR:0)
Block(-5,16,-1,SMOOTH_STAIRS:1)
Block(-5,16,0,STEP:5)
Block(-5,16,1,COBBLE_WALL:0)
Block(-5,16,2,SMOOTH_STAIRS:1)
Block(-5,16,3,AIR:0)
Block(-5,16,4,AIR:0)
Block(-5,16,5,AIR:0)
Block(-5,16,6,AIR:0)
Block(-5,16,7,AIR:0)
Block(-5,16,8,AIR:0)
RandomBlock(-5,17,-7,CONCRETE:7,60,quark:iron_plate:1,20,STAINED_CLAY:12,15,STAINED_CLAY:15,5,AIR,7,IRON_BARS,12,CONCRETE:7,100)
RandomBlock(-5,17,-6,CONCRETE:7,60,quark:iron_plate:1,20,STAINED_CLAY:12,15,STAINED_CLAY:15,5,AIR,7,IRON_BARS,12,CONCRETE:7,100)
RandomBlock(-5,17,-5,CONCRETE:7,60,quark:iron_plate:1,20,STAINED_CLAY:12,15,STAINED_CLAY:15,5,AIR,7,IRON_BARS,12,CONCRETE:7,100)
RandomBlock(-5,17,-4,CONCRETE:7,60,quark:iron_plate:1,20,STAINED_CLAY:12,15,STAINED_CLAY:15,5,AIR,7,IRON_BARS,12,CONCRETE:7,100)
RandomBlock(-5,17,-3,CONCRETE:7,60,quark:iron_plate:1,20,STAINED_CLAY:12,15,STAINED_CLAY:15,5,AIR,7,IRON_BARS,12,CONCRETE:7,100)
RandomBlock(-5,17,-2,CONCRETE:7,60,quark:iron_plate:1,20,STAINED_CLAY:12,15,STAINED_CLAY:15,5,AIR,7,IRON_BARS,12,CONCRETE:7,100)
RandomBlock(-5,17,-1,CONCRETE:7,60,quark:iron_plate:1,20,STAINED_CLAY:12,15,STAINED_CLAY:15,5,AIR,7,IRON_BARS,12,CONCRETE:7,100)
RandomBlock(-5,17,0,CONCRETE:7,60,quark:iron_plate:1,20,STAINED_CLAY:12,15,STAINED_CLAY:15,5,AIR,7,IRON_BARS,12,CONCRETE:7,100)
RandomBlock(-5,17,1,CONCRETE:7,60,quark:iron_plate:1,20,STAINED_CLAY:12,15,STAINED_CLAY:15,5,AIR,7,IRON_BARS,12,CONCRETE:7,100)
RandomBlock(-5,17,2,CONCRETE:7,60,quark:iron_plate:1,20,STAINED_CLAY:12,15,STAINED_CLAY:15,5,AIR,7,IRON_BARS,12,CONCRETE:7,100)
RandomBlock(-5,17,3,CONCRETE:7,60,quark:iron_plate:1,20,STAINED_CLAY:12,15,STAINED_CLAY:15,5,AIR,7,IRON_BARS,12,CONCRETE:7,100)
RandomBlock(-5,17,4,CONCRETE:7,60,quark:iron_plate:1,20,STAINED_CLAY:12,15,STAINED_CLAY:15,5,AIR,7,IRON_BARS,12,CONCRETE:7,100)
RandomBlock(-5,17,5,CONCRETE:7,60,quark:iron_plate:1,20,STAINED_CLAY:12,15,STAINED_CLAY:15,5,AIR,7,IRON_BARS,12,CONCRETE:7,100)
RandomBlock(-5,17,6,CONCRETE:7,60,quark:iron_plate:1,20,STAINED_CLAY:12,15,STAINED_CLAY:15,5,AIR,7,IRON_BARS,12,CONCRETE:7,100)
RandomBlock(-5,17,7,CONCRETE:7,60,quark:iron_plate:1,20,STAINED_CLAY:12,15,STAINED_CLAY:15,5,AIR,7,IRON_BARS,12,CONCRETE:7,100)
RandomBlock(-5,17,8,CONCRETE:7,60,quark:iron_plate:1,20,STAINED_CLAY:12,15,STAINED_CLAY:15,5,AIR,7,IRON_BARS,12,CONCRETE:7,100)
Block(-5,18,-7,CONCRETE:15)
Block(-5,18,-6,CONCRETE:15)
Block(-5,18,-5,CONCRETE:15)
Block(-5,18,-4,STEP:7)
Block(-5,18,-2,STEP:7)
Block(-5,18,-1,CONCRETE:15)
Block(-5,18,0,CONCRETE:8)
Block(-5,18,1,CONCRETE:8)
Block(-5,18,2,CONCRETE:15)
Block(-5,18,6,CONCRETE:15)
Block(-5,18,7,CONCRETE:15)
Block(-5,18,8,CONCRETE:15)
Block(-5,19,-5,CONCRETE:15)
Block(-5,19,-1,CONCRETE:0)
Block(-5,19,2,CONCRETE:0)
Block(-5,19,6,CONCRETE:15)
Block(-5,20,-5,CONCRETE:15)
Block(-5,20,-1,CONCRETE:0)
Block(-5,20,2,CONCRETE:0)
Block(-5,20,6,CONCRETE:15)
Block(-5,21,-5,CONCRETE:15)
Block(-5,21,-1,CONCRETE:0)
Block(-5,21,2,CONCRETE:0)
Block(-5,21,6,CONCRETE:15)
Block(-5,22,-5,CONCRETE:15)
Block(-5,22,-1,CONCRETE:15)
Block(-5,22,2,CONCRETE:15)
Block(-5,22,6,CONCRETE:15)
Block(-5,23,-5,CONCRETE:15)
Block(-5,23,-1,CONCRETE:15)
Block(-5,23,0,STAINED_GLASS:15)
Block(-5,23,1,STAINED_GLASS:15)
Block(-5,23,2,CONCRETE:15)
Block(-5,23,6,CONCRETE:15)
Block(-5,24,-7,CONCRETE:15)
Block(-5,24,-6,STAINED_GLASS:15)
Block(-5,24,-5,CONCRETE:15)
Block(-5,24,-1,CONCRETE:0)
Block(-5,24,2,CONCRETE:0)
Block(-5,24,6,CONCRETE:15)
Block(-5,24,7,STAINED_GLASS:15)
Block(-5,24,8,CONCRETE:15)
Block(-5,25,-5,CONCRETE:15)
Block(-5,25,-1,CONCRETE:0)
Block(-5,25,2,CONCRETE:0)
Block(-5,25,6,CONCRETE:15)
Block(-5,26,-5,CONCRETE:15)
Block(-5,26,-1,CONCRETE:0)
Block(-5,26,2,CONCRETE:0)
Block(-5,26,6,CONCRETE:15)
Block(-5,27,-5,CONCRETE:15)
Block(-5,27,-1,CONCRETE:15)
Block(-5,27,2,CONCRETE:15)
Block(-5,27,6,CONCRETE:15)
Block(-5,28,-5,CONCRETE:15)
Block(-5,28,-1,CONCRETE:15)
Block(-5,28,2,CONCRETE:15)
Block(-5,28,6,CONCRETE:15)
Block(-5,29,-5,CONCRETE:15)
Block(-5,29,-1,CONCRETE:15)
Block(-5,29,0,STAINED_GLASS:15)
Block(-5,29,1,STAINED_GLASS:15)
Block(-5,29,2,CONCRETE:15)
Block(-5,29,6,CONCRETE:15)
Block(-5,30,-7,CONCRETE:15)
Block(-5,30,-6,STAINED_GLASS:15)
Block(-5,30,-5,CONCRETE:15)
Block(-5,30,-1,CONCRETE:0)
Block(-5,30,2,CONCRETE:0)
Block(-5,30,6,CONCRETE:15)
Block(-5,30,7,STAINED_GLASS:15)
Block(-5,30,8,CONCRETE:15)
Block(-5,31,-5,CONCRETE:15)
Block(-5,31,-1,CONCRETE:0)
Block(-5,31,2,CONCRETE:0)
Block(-5,31,6,CONCRETE:15)
Block(-5,32,-5,CONCRETE:15)
Block(-5,32,-1,CONCRETE:0)
Block(-5,32,2,CONCRETE:0)
Block(-5,32,6,CONCRETE:15)
Block(-5,33,-5,CONCRETE:15)
Block(-5,33,-4,IRON_FENCE:0)
Block(-5,33,-2,IRON_FENCE:0)
Block(-5,33,-1,CONCRETE:15)
Block(-5,33,2,CONCRETE:15)
Block(-5,33,3,IRON_FENCE:0)
Block(-5,33,5,IRON_FENCE:0)
Block(-5,33,6,CONCRETE:15)
Block(-5,34,-5,CONCRETE:15)
Block(-5,34,-4,IRON_FENCE:0)
Block(-5,34,-2,IRON_FENCE:0)
Block(-5,34,-1,CONCRETE:15)
Block(-5,34,2,CONCRETE:15)
Block(-5,34,3,IRON_FENCE:0)
Block(-5,34,5,IRON_FENCE:0)
Block(-5,34,6,CONCRETE:15)
Block(-5,35,-5,CONCRETE:15)
Block(-5,35,-4,IRON_FENCE:0)
Block(-5,35,-2,IRON_FENCE:0)
Block(-5,35,-1,CONCRETE:15)
Block(-5,35,0,STAINED_GLASS:15)
Block(-5,35,1,STAINED_GLASS:15)
Block(-5,35,2,CONCRETE:15)
Block(-5,35,3,IRON_FENCE:0)
Block(-5,35,5,IRON_FENCE:0)
Block(-5,35,6,CONCRETE:15)
Block(-5,36,-7,CONCRETE:8)
Block(-5,36,-6,STAINED_GLASS:15)
Block(-5,36,-5,CONCRETE:15)
Block(-5,36,-4,IRON_FENCE:0)
Block(-5,36,-2,IRON_FENCE:0)
Block(-5,36,-1,CONCRETE:0)
Block(-5,36,2,CONCRETE:0)
Block(-5,36,3,IRON_FENCE:0)
Block(-5,36,5,IRON_FENCE:0)
Block(-5,36,6,CONCRETE:15)
Block(-5,36,7,STAINED_GLASS:15)
Block(-5,36,8,CONCRETE:8)
Block(-5,37,-5,CONCRETE:15)
Block(-5,37,-4,IRON_FENCE:0)
Block(-5,37,-2,IRON_FENCE:0)
Block(-5,37,-1,CONCRETE:0)
Block(-5,37,2,CONCRETE:0)
Block(-5,37,3,IRON_FENCE:0)
Block(-5,37,5,IRON_FENCE:0)
Block(-5,37,6,CONCRETE:15)
Block(-5,38,-5,CONCRETE:15)
Block(-5,38,-4,IRON_FENCE:0)
RandomBlock(-5,38,-3,AIR,90,IRON_TRAPDOOR:11,100)
Block(-5,38,-2,IRON_FENCE:0)
Block(-5,38,-1,CONCRETE:0)
Block(-5,38,2,CONCRETE:0)
Block(-5,38,3,IRON_FENCE:0)
Block(-5,38,5,IRON_FENCE:0)
Block(-5,38,6,CONCRETE:15)
Block(-5,39,-5,CONCRETE:15)
Block(-5,39,-4,IRON_FENCE:0)
Block(-5,39,-3,STONE_BUTTON:1)
Block(-5,39,-2,IRON_FENCE:0)
Block(-5,39,-1,CONCRETE:15)
Block(-5,39,2,CONCRETE:15)
Block(-5,39,3,IRON_FENCE:0)
Block(-5,39,4,STONE_BUTTON:1)
Block(-5,39,5,IRON_FENCE:0)
Block(-5,39,6,CONCRETE:15)
Block(-5,40,-5,CONCRETE:15)
Block(-5,40,-4,IRON_FENCE:0)
Block(-5,40,-3,STONE_BUTTON:1)
Block(-5,40,-2,IRON_FENCE:0)
Block(-5,40,-1,CONCRETE:15)
Block(-5,40,2,CONCRETE:15)
Block(-5,40,3,IRON_FENCE:0)
Block(-5,40,4,STONE_BUTTON:1)
Block(-5,40,5,IRON_FENCE:0)
Block(-5,40,6,CONCRETE:15)
Block(-5,41,-5,CONCRETE:15)
Block(-5,41,-4,IRON_FENCE:0)
Block(-5,41,-3,CONCRETE:14)
Block(-5,41,-2,IRON_FENCE:0)
Block(-5,41,-1,CONCRETE:15)
Block(-5,41,0,STAINED_GLASS:15)
Block(-5,41,1,STAINED_GLASS:15)
Block(-5,41,2,CONCRETE:15)
Block(-5,41,3,IRON_FENCE:0)
Block(-5,41,4,CONCRETE:14)
Block(-5,41,5,IRON_FENCE:0)
Block(-5,41,6,CONCRETE:15)
Block(-5,42,-7,CONCRETE:8)
Block(-5,42,-6,CONCRETE:8)
Block(-5,42,-5,CONCRETE:8)
Block(-5,42,-4,CONCRETE:8)
Block(-5,42,-3,CONCRETE:8)
Block(-5,42,-2,CONCRETE:8)
Block(-5,42,-1,CONCRETE:8)
Block(-5,42,0,CONCRETE:8)
Block(-5,42,1,CONCRETE:8)
Block(-5,42,2,CONCRETE:8)
Block(-5,42,3,CONCRETE:8)
Block(-5,42,4,CONCRETE:8)
Block(-5,42,5,CONCRETE:8)
Block(-5,42,6,CONCRETE:8)
Block(-5,42,7,CONCRETE:8)
Block(-5,42,8,CONCRETE:8)
Block(-5,43,-5,CONCRETE:15)
Block(-5,43,-3,CARPET:10)
Block(-5,43,-2,CARPET:15)
Block(-5,43,-1,CARPET:10)
Block(-5,43,0,CARPET:15)
Block(-5,43,1,CARPET:10)
Block(-5,43,2,CARPET:15)
Block(-5,43,3,CARPET:10)
Block(-5,43,4,CARPET:15)
Block(-5,43,5,PLANKS:0)
Block(-5,43,6,PRISMARINE:2)
Block(-5,43,8,STAINED_GLASS_PANE:15)
Block(-5,44,-5,CONCRETE:15)
Block(-5,44,6,PRISMARINE:2)
Block(-5,45,-5,DARK_OAK_STAIRS:0)
Block(-5,45,6,PRISMARINE:2)
Block(-5,46,-2,WOOD_STEP:5)
RandomBlock(-5,46,5,AIR,95,WALL_BANNER:2,../AllScraperData/skyscraper_3x3_01/2750-bannerC16R16.nbt,100)
Block(-5,46,6,PRISMARINE:2)
Block(-5,47,0,STAINED_GLASS:15)
Block(-5,47,1,STAINED_GLASS:15)
Block(-5,47,6,PRISMARINE:2)
Block(-5,48,-7,CONCRETE:8)
Block(-5,48,-6,CONCRETE:8)
Block(-5,48,-5,CONCRETE:15)
