
#######################################################################
# +-----------------------------------------------------------------+ #
# |                            BO4 object                           | #
# +-----------------------------------------------------------------+ #
#######################################################################

Author: NLBlackEagle

Description: No description given

SettingsMode: WriteDisable


#######################################################################
# +-----------------------------------------------------------------+ #
# |                          Main settings                          | #
# +-----------------------------------------------------------------+ #
#######################################################################

Frequency: 0

SpawnHeight: highestBlock

UseCenterForHighestBlock: true

##############################
# Height Limits for the BO4. #
##############################

MinHeight: 0

MaxHeight: 255

InheritBO3: 

InheritBO3Rotation: NORTH

OverrideChildSettings: true

OverrideParentHeight: false

CanOverride: true

BranchFrequency: 0

BranchFrequencyGroup: 

MustBeBelowOther: false

MustBeInside: 

CannotBeInside: 

ReplacesBO3: L4-M-CrossC0R0, L4-M-CrossC0R1, L4-M-CrossC0R2, L4-M-CrossC0R3, L4-M-CrossC1R0, L4-M-CrossC1R1, L4-M-CrossC1R2, L4-M-CrossC1R3, L4-M-CrossC2R0, L4-M-CrossC2R1, L4-M-CrossC2R2, L4-M-CrossC2R3, L4-M-CrossC3R0, L4-M-CrossC3R1, L4-M-CrossC3R2, L4-M-CrossC3R3, L4-M-Straigth-START_01-C0R0, L4-M-Straigth-START_01-C0R1, L4-M-Straigth-START_01-C1R0, L4-M-Straigth-START_01-C1R1, L4-M-Straigth-START_01-C2R0, L4-M-Straigth-START_01-C2R1, L4-M-Straigth-START_01-C3R0, L4-M-Straigth-START_01-C3R1, L4-M-Straigth-3CC0R0, L4-M-Straigth-3CC0R1, L4-M-Straigth-3CC0R2, L4-M-Straigth-3CC1R0, L4-M-Straigth-3CC1R1, L4-M-Straigth-3CC1R2, L4-M-Straigth-3CC2R0, L4-M-Straigth-3CC2R1, L4-M-Straigth-3CC2R2, L4-M-Straigth-3CC3R0, L4-M-Straigth-3CC3R1, L4-M-Straigth-3CC3R2, L4-M-Cross, skyscraper_2x2_01, skyscraper_2x2_02, skyscraper_2x2_03, skyscraper_2x2_04, skyscraper_2x2_05, skyscraper_3x3_01, skyscraper_3x3_02, skyscraper_3x3_03, L3-M-Straigth-2CC0R0, L3-M-Straigth-2CC0R1, L3-M-Straigth-2CC1R0, L3-M-Straigth-2CC1R1, L3-M-Straigth-2CC2R0, L3-M-Straigth-2CC2R1, L3-M-Straigth-2CC3R0, L3-M-Straigth-2CC3R1, L3-M-Straigth-3CC0R0, L3-M-Straigth-3CC0R1, L3-M-Straigth-3CC0R2, L3-M-Straigth-3CC1R0, L3-M-Straigth-3CC1R1, L3-M-Straigth-3CC1R2, L3-M-Straigth-3CC2R0, L3-M-Straigth-3CC2R1, L3-M-Straigth-3CC2R2, L3-M-Straigth-3CC3R0, L3-M-Straigth-3CC3R1, L3-M-Straigth-3CC3R2L4-M-CrossC0R0, L4-M-CrossC0R1, L4-M-CrossC0R2, L4-M-CrossC0R3, L4-M-CrossC1R0, L4-M-CrossC1R1, L4-M-CrossC1R2, L4-M-CrossC1R3, L4-M-CrossC2R0, L4-M-CrossC2R1, L4-M-CrossC2R2, L4-M-CrossC2R3, L4-M-CrossC3R0, L4-M-CrossC3R1, L4-M-CrossC3R2, L4-M-CrossC3R3, L4-M-Straigth-START_01-C0R0, L4-M-Straigth-START_01-C0R1, L4-M-Straigth-START_01-C1R0, L4-M-Straigth-START_01-C1R1, L4-M-Straigth-START_01-C2R0, L4-M-Straigth-START_01-C2R1, L4-M-Straigth-START_01-C3R0, L4-M-Straigth-START_01-C3R1, L4-M-Straigth-3CC0R0, L4-M-Straigth-3CC0R1, L4-M-Straigth-3CC0R2, L4-M-Straigth-3CC1R0, L4-M-Straigth-3CC1R1, L4-M-Straigth-3CC1R2, L4-M-Straigth-3CC2R0, L4-M-Straigth-3CC2R1, L4-M-Straigth-3CC2R2, L4-M-Straigth-3CC3R0, L4-M-Straigth-3CC3R1, L4-M-Straigth-3CC3R2, L4-M-Cross, skyscraper_2x2_01, skyscraper_2x2_02, skyscraper_2x2_03, skyscraper_2x2_04, skyscraper_2x2_05, skyscraper_3x3_01, skyscraper_3x3_02, skyscraper_3x3_03

MustBeInsideWorldBorders: true
CanSpawnOnWater: true

SpawnOnWaterOnly: false

SpawnUnderWater: false

SpawnAtWaterLevel: false

HeightOffset: 0

RemoveAir: false

ReplaceAbove: 

ReplaceBelow: 

ReplaceWithBiomeBlocks: true

ReplaceWithSurfaceBlock: GRASS

ReplaceWithGroundBlock: DIRT

ReplaceWithStoneBlock: STONE

SmoothRadius: 0

SmoothHeightOffset: 0

SmoothStartTop: false

SmoothStartWood: false

SmoothingSurfaceBlock: 

SmoothingGroundBlock: 

BO3Group: 

IsSpawnPoint: false

DoReplaceBlocks: true


#######################################################################
# +-----------------------------------------------------------------+ #
# |                              Blocks                             | #
# +-----------------------------------------------------------------+ #
#######################################################################

RandomBlock(-8,0,-7,CONCRETE:7,60,quark:iron_plate:1,20,STAINED_CLAY:12,15,STAINED_CLAY:15,5,AIR,7,IRON_BARS,12,CONCRETE:7,100)
RandomBlock(-8,0,-6,CONCRETE:7,60,quark:iron_plate:1,20,STAINED_CLAY:12,15,STAINED_CLAY:15,5,AIR,7,IRON_BARS,12,CONCRETE:7,100)
RandomBlock(-8,0,-5,CONCRETE:7,60,quark:iron_plate:1,20,STAINED_CLAY:12,15,STAINED_CLAY:15,5,AIR,7,IRON_BARS,12,CONCRETE:7,100)
RandomBlock(-8,0,-4,CONCRETE:7,60,quark:iron_plate:1,20,STAINED_CLAY:12,15,STAINED_CLAY:15,5,AIR,7,IRON_BARS,12,CONCRETE:7,100)
RandomBlock(-8,0,-3,CONCRETE:7,60,quark:iron_plate:1,20,STAINED_CLAY:12,15,STAINED_CLAY:15,5,AIR,7,IRON_BARS,12,CONCRETE:7,100)
RandomBlock(-8,0,-2,CONCRETE:7,60,quark:iron_plate:1,20,STAINED_CLAY:12,15,STAINED_CLAY:15,5,AIR,7,IRON_BARS,12,CONCRETE:7,100)
RandomBlock(-8,0,-1,CONCRETE:7,60,quark:iron_plate:1,20,STAINED_CLAY:12,15,STAINED_CLAY:15,5,AIR,7,IRON_BARS,12,CONCRETE:7,100)
RandomBlock(-8,0,0,CONCRETE:7,60,quark:iron_plate:1,20,STAINED_CLAY:12,15,STAINED_CLAY:15,5,AIR,7,IRON_BARS,12,CONCRETE:7,100)
RandomBlock(-8,0,1,CONCRETE:7,60,quark:iron_plate:1,20,STAINED_CLAY:12,15,STAINED_CLAY:15,5,AIR,7,IRON_BARS,12,CONCRETE:7,100)
RandomBlock(-8,0,2,CONCRETE:7,60,quark:iron_plate:1,20,STAINED_CLAY:12,15,STAINED_CLAY:15,5,AIR,7,IRON_BARS,12,CONCRETE:7,100)
RandomBlock(-8,0,3,CONCRETE:7,60,quark:iron_plate:1,20,STAINED_CLAY:12,15,STAINED_CLAY:15,5,AIR,7,IRON_BARS,12,CONCRETE:7,100)
RandomBlock(-8,0,4,CONCRETE:7,60,quark:iron_plate:1,20,STAINED_CLAY:12,15,STAINED_CLAY:15,5,AIR,7,IRON_BARS,12,CONCRETE:7,100)
RandomBlock(-8,0,5,CONCRETE:7,60,quark:iron_plate:1,20,STAINED_CLAY:12,15,STAINED_CLAY:15,5,AIR,7,IRON_BARS,12,CONCRETE:7,100)
RandomBlock(-8,0,6,CONCRETE:7,60,quark:iron_plate:1,20,STAINED_CLAY:12,15,STAINED_CLAY:15,5,AIR,7,IRON_BARS,12,CONCRETE:7,100)
RandomBlock(-8,0,7,CONCRETE:7,60,quark:iron_plate:1,20,STAINED_CLAY:12,15,STAINED_CLAY:15,5,AIR,7,IRON_BARS,12,CONCRETE:7,100)
RandomBlock(-8,0,8,CONCRETE:7,60,quark:iron_plate:1,20,STAINED_CLAY:12,15,STAINED_CLAY:15,5,AIR,7,IRON_BARS,12,CONCRETE:7,100)
RandomBlock(-8,1,-7,CONCRETE:7,60,quark:iron_plate:1,20,STAINED_CLAY:12,15,STAINED_CLAY:15,5,AIR,7,IRON_BARS,12,CONCRETE:7,100)
RandomBlock(-8,1,-6,CONCRETE:7,60,quark:iron_plate:1,20,STAINED_CLAY:12,15,STAINED_CLAY:15,5,AIR,7,IRON_BARS,12,CONCRETE:7,100)
RandomBlock(-8,1,-5,CONCRETE:7,60,quark:iron_plate:1,20,STAINED_CLAY:12,15,STAINED_CLAY:15,5,AIR,7,IRON_BARS,12,CONCRETE:7,100)
RandomBlock(-8,1,-4,CONCRETE:7,60,quark:iron_plate:1,20,STAINED_CLAY:12,15,STAINED_CLAY:15,5,AIR,7,IRON_BARS,12,CONCRETE:7,100)
RandomBlock(-8,1,-3,CONCRETE:7,60,quark:iron_plate:1,20,STAINED_CLAY:12,15,STAINED_CLAY:15,5,AIR,7,IRON_BARS,12,CONCRETE:7,100)
RandomBlock(-8,1,-2,CONCRETE:7,60,quark:iron_plate:1,20,STAINED_CLAY:12,15,STAINED_CLAY:15,5,AIR,7,IRON_BARS,12,CONCRETE:7,100)
RandomBlock(-8,1,-1,CONCRETE:7,60,quark:iron_plate:1,20,STAINED_CLAY:12,15,STAINED_CLAY:15,5,AIR,7,IRON_BARS,12,CONCRETE:7,100)
RandomBlock(-8,1,0,CONCRETE:7,60,quark:iron_plate:1,20,STAINED_CLAY:12,15,STAINED_CLAY:15,5,AIR,7,IRON_BARS,12,CONCRETE:7,100)
RandomBlock(-8,1,1,CONCRETE:7,60,quark:iron_plate:1,20,STAINED_CLAY:12,15,STAINED_CLAY:15,5,AIR,7,IRON_BARS,12,CONCRETE:7,100)
RandomBlock(-8,1,2,CONCRETE:7,60,quark:iron_plate:1,20,STAINED_CLAY:12,15,STAINED_CLAY:15,5,AIR,7,IRON_BARS,12,CONCRETE:7,100)
RandomBlock(-8,1,3,CONCRETE:7,60,quark:iron_plate:1,20,STAINED_CLAY:12,15,STAINED_CLAY:15,5,AIR,7,IRON_BARS,12,CONCRETE:7,100)
RandomBlock(-8,1,4,CONCRETE:7,60,quark:iron_plate:1,20,STAINED_CLAY:12,15,STAINED_CLAY:15,5,AIR,7,IRON_BARS,12,CONCRETE:7,100)
RandomBlock(-8,1,5,CONCRETE:7,60,quark:iron_plate:1,20,STAINED_CLAY:12,15,STAINED_CLAY:15,5,AIR,7,IRON_BARS,12,CONCRETE:7,100)
RandomBlock(-8,1,6,CONCRETE:7,60,quark:iron_plate:1,20,STAINED_CLAY:12,15,STAINED_CLAY:15,5,AIR,7,IRON_BARS,12,CONCRETE:7,100)
RandomBlock(-8,1,7,CONCRETE:7,60,quark:iron_plate:1,20,STAINED_CLAY:12,15,STAINED_CLAY:15,5,AIR,7,IRON_BARS,12,CONCRETE:7,100)
RandomBlock(-8,1,8,CONCRETE:7,60,quark:iron_plate:1,20,STAINED_CLAY:12,15,STAINED_CLAY:15,5,AIR,7,IRON_BARS,12,CONCRETE:7,100)
RandomBlock(-8,2,-7,CONCRETE:7,60,quark:iron_plate:1,20,STAINED_CLAY:12,15,STAINED_CLAY:15,5,AIR,7,IRON_BARS,12,CONCRETE:7,100)
RandomBlock(-8,2,-6,CONCRETE:7,60,quark:iron_plate:1,20,STAINED_CLAY:12,15,STAINED_CLAY:15,5,AIR,7,IRON_BARS,12,CONCRETE:7,100)
RandomBlock(-8,2,-5,CONCRETE:7,60,quark:iron_plate:1,20,STAINED_CLAY:12,15,STAINED_CLAY:15,5,AIR,7,IRON_BARS,12,CONCRETE:7,100)
RandomBlock(-8,2,-4,CONCRETE:7,60,quark:iron_plate:1,20,STAINED_CLAY:12,15,STAINED_CLAY:15,5,AIR,7,IRON_BARS,12,CONCRETE:7,100)
RandomBlock(-8,2,-3,CONCRETE:7,60,quark:iron_plate:1,20,STAINED_CLAY:12,15,STAINED_CLAY:15,5,AIR,7,IRON_BARS,12,CONCRETE:7,100)
RandomBlock(-8,2,-2,CONCRETE:7,60,quark:iron_plate:1,20,STAINED_CLAY:12,15,STAINED_CLAY:15,5,AIR,7,IRON_BARS,12,CONCRETE:7,100)
RandomBlock(-8,2,-1,CONCRETE:7,60,quark:iron_plate:1,20,STAINED_CLAY:12,15,STAINED_CLAY:15,5,AIR,7,IRON_BARS,12,CONCRETE:7,100)
RandomBlock(-8,2,0,CONCRETE:7,60,quark:iron_plate:1,20,STAINED_CLAY:12,15,STAINED_CLAY:15,5,AIR,7,IRON_BARS,12,CONCRETE:7,100)
RandomBlock(-8,2,1,CONCRETE:7,60,quark:iron_plate:1,20,STAINED_CLAY:12,15,STAINED_CLAY:15,5,AIR,7,IRON_BARS,12,CONCRETE:7,100)
RandomBlock(-8,2,2,CONCRETE:7,60,quark:iron_plate:1,20,STAINED_CLAY:12,15,STAINED_CLAY:15,5,AIR,7,IRON_BARS,12,CONCRETE:7,100)
RandomBlock(-8,2,3,CONCRETE:7,60,quark:iron_plate:1,20,STAINED_CLAY:12,15,STAINED_CLAY:15,5,AIR,7,IRON_BARS,12,CONCRETE:7,100)
RandomBlock(-8,2,4,CONCRETE:7,60,quark:iron_plate:1,20,STAINED_CLAY:12,15,STAINED_CLAY:15,5,AIR,7,IRON_BARS,12,CONCRETE:7,100)
RandomBlock(-8,2,5,CONCRETE:7,60,quark:iron_plate:1,20,STAINED_CLAY:12,15,STAINED_CLAY:15,5,AIR,7,IRON_BARS,12,CONCRETE:7,100)
RandomBlock(-8,2,6,CONCRETE:7,60,quark:iron_plate:1,20,STAINED_CLAY:12,15,STAINED_CLAY:15,5,AIR,7,IRON_BARS,12,CONCRETE:7,100)
RandomBlock(-8,2,7,CONCRETE:7,60,quark:iron_plate:1,20,STAINED_CLAY:12,15,STAINED_CLAY:15,5,AIR,7,IRON_BARS,12,CONCRETE:7,100)
RandomBlock(-8,2,8,CONCRETE:7,60,quark:iron_plate:1,20,STAINED_CLAY:12,15,STAINED_CLAY:15,5,AIR,7,IRON_BARS,12,CONCRETE:7,100)
RandomBlock(-8,3,-7,CONCRETE:7,60,quark:iron_plate:1,20,STAINED_CLAY:12,15,STAINED_CLAY:15,5,AIR,7,IRON_BARS,12,CONCRETE:7,100)
RandomBlock(-8,3,-6,CONCRETE:7,60,quark:iron_plate:1,20,STAINED_CLAY:12,15,STAINED_CLAY:15,5,AIR,7,IRON_BARS,12,CONCRETE:7,100)
RandomBlock(-8,3,-5,CONCRETE:7,60,quark:iron_plate:1,20,STAINED_CLAY:12,15,STAINED_CLAY:15,5,AIR,7,IRON_BARS,12,CONCRETE:7,100)
RandomBlock(-8,3,-4,CONCRETE:7,60,quark:iron_plate:1,20,STAINED_CLAY:12,15,STAINED_CLAY:15,5,AIR,7,IRON_BARS,12,CONCRETE:7,100)
RandomBlock(-8,3,-3,CONCRETE:7,60,quark:iron_plate:1,20,STAINED_CLAY:12,15,STAINED_CLAY:15,5,AIR,7,IRON_BARS,12,CONCRETE:7,100)
RandomBlock(-8,3,-2,CONCRETE:7,60,quark:iron_plate:1,20,STAINED_CLAY:12,15,STAINED_CLAY:15,5,AIR,7,IRON_BARS,12,CONCRETE:7,100)
RandomBlock(-8,3,-1,CONCRETE:7,60,quark:iron_plate:1,20,STAINED_CLAY:12,15,STAINED_CLAY:15,5,AIR,7,IRON_BARS,12,CONCRETE:7,100)
RandomBlock(-8,3,0,CONCRETE:7,60,quark:iron_plate:1,20,STAINED_CLAY:12,15,STAINED_CLAY:15,5,AIR,7,IRON_BARS,12,CONCRETE:7,100)
RandomBlock(-8,3,1,CONCRETE:7,60,quark:iron_plate:1,20,STAINED_CLAY:12,15,STAINED_CLAY:15,5,AIR,7,IRON_BARS,12,CONCRETE:7,100)
RandomBlock(-8,3,2,CONCRETE:7,60,quark:iron_plate:1,20,STAINED_CLAY:12,15,STAINED_CLAY:15,5,AIR,7,IRON_BARS,12,CONCRETE:7,100)
RandomBlock(-8,3,3,CONCRETE:7,60,quark:iron_plate:1,20,STAINED_CLAY:12,15,STAINED_CLAY:15,5,AIR,7,IRON_BARS,12,CONCRETE:7,100)
RandomBlock(-8,3,4,CONCRETE:7,60,quark:iron_plate:1,20,STAINED_CLAY:12,15,STAINED_CLAY:15,5,AIR,7,IRON_BARS,12,CONCRETE:7,100)
RandomBlock(-8,3,5,CONCRETE:7,60,quark:iron_plate:1,20,STAINED_CLAY:12,15,STAINED_CLAY:15,5,AIR,7,IRON_BARS,12,CONCRETE:7,100)
RandomBlock(-8,3,6,CONCRETE:7,60,quark:iron_plate:1,20,STAINED_CLAY:12,15,STAINED_CLAY:15,5,AIR,7,IRON_BARS,12,CONCRETE:7,100)
RandomBlock(-8,3,7,CONCRETE:7,60,quark:iron_plate:1,20,STAINED_CLAY:12,15,STAINED_CLAY:15,5,AIR,7,IRON_BARS,12,CONCRETE:7,100)
RandomBlock(-8,3,8,CONCRETE:7,60,quark:iron_plate:1,20,STAINED_CLAY:12,15,STAINED_CLAY:15,5,AIR,7,IRON_BARS,12,CONCRETE:7,100)
RandomBlock(-8,4,-7,CONCRETE:7,60,quark:iron_plate:1,20,STAINED_CLAY:12,15,STAINED_CLAY:15,5,AIR,7,IRON_BARS,12,CONCRETE:7,100)
RandomBlock(-8,4,-6,CONCRETE:7,60,quark:iron_plate:1,20,STAINED_CLAY:12,15,STAINED_CLAY:15,5,AIR,7,IRON_BARS,12,CONCRETE:7,100)
RandomBlock(-8,4,-5,CONCRETE:7,60,quark:iron_plate:1,20,STAINED_CLAY:12,15,STAINED_CLAY:15,5,AIR,7,IRON_BARS,12,CONCRETE:7,100)
RandomBlock(-8,4,-4,CONCRETE:7,60,quark:iron_plate:1,20,STAINED_CLAY:12,15,STAINED_CLAY:15,5,AIR,7,IRON_BARS,12,CONCRETE:7,100)
RandomBlock(-8,4,-3,CONCRETE:7,60,quark:iron_plate:1,20,STAINED_CLAY:12,15,STAINED_CLAY:15,5,AIR,7,IRON_BARS,12,CONCRETE:7,100)
RandomBlock(-8,4,-2,CONCRETE:7,60,quark:iron_plate:1,20,STAINED_CLAY:12,15,STAINED_CLAY:15,5,AIR,7,IRON_BARS,12,CONCRETE:7,100)
RandomBlock(-8,4,-1,CONCRETE:7,60,quark:iron_plate:1,20,STAINED_CLAY:12,15,STAINED_CLAY:15,5,AIR,7,IRON_BARS,12,CONCRETE:7,100)
RandomBlock(-8,4,0,CONCRETE:7,60,quark:iron_plate:1,20,STAINED_CLAY:12,15,STAINED_CLAY:15,5,AIR,7,IRON_BARS,12,CONCRETE:7,100)
RandomBlock(-8,4,1,CONCRETE:7,60,quark:iron_plate:1,20,STAINED_CLAY:12,15,STAINED_CLAY:15,5,AIR,7,IRON_BARS,12,CONCRETE:7,100)
RandomBlock(-8,4,2,CONCRETE:7,60,quark:iron_plate:1,20,STAINED_CLAY:12,15,STAINED_CLAY:15,5,AIR,7,IRON_BARS,12,CONCRETE:7,100)
RandomBlock(-8,4,3,CONCRETE:7,60,quark:iron_plate:1,20,STAINED_CLAY:12,15,STAINED_CLAY:15,5,AIR,7,IRON_BARS,12,CONCRETE:7,100)
RandomBlock(-8,4,4,CONCRETE:7,60,quark:iron_plate:1,20,STAINED_CLAY:12,15,STAINED_CLAY:15,5,AIR,7,IRON_BARS,12,CONCRETE:7,100)
RandomBlock(-8,4,5,CONCRETE:7,60,quark:iron_plate:1,20,STAINED_CLAY:12,15,STAINED_CLAY:15,5,AIR,7,IRON_BARS,12,CONCRETE:7,100)
RandomBlock(-8,4,6,CONCRETE:7,60,quark:iron_plate:1,20,STAINED_CLAY:12,15,STAINED_CLAY:15,5,AIR,7,IRON_BARS,12,CONCRETE:7,100)
RandomBlock(-8,4,7,CONCRETE:7,60,quark:iron_plate:1,20,STAINED_CLAY:12,15,STAINED_CLAY:15,5,AIR,7,IRON_BARS,12,CONCRETE:7,100)
RandomBlock(-8,4,8,CONCRETE:7,60,quark:iron_plate:1,20,STAINED_CLAY:12,15,STAINED_CLAY:15,5,AIR,7,IRON_BARS,12,CONCRETE:7,100)
RandomBlock(-8,5,-7,CONCRETE:7,60,quark:iron_plate:1,20,STAINED_CLAY:12,15,STAINED_CLAY:15,5,AIR,7,IRON_BARS,12,CONCRETE:7,100)
RandomBlock(-8,5,-6,CONCRETE:7,60,quark:iron_plate:1,20,STAINED_CLAY:12,15,STAINED_CLAY:15,5,AIR,7,IRON_BARS,12,CONCRETE:7,100)
RandomBlock(-8,5,-5,CONCRETE:7,60,quark:iron_plate:1,20,STAINED_CLAY:12,15,STAINED_CLAY:15,5,AIR,7,IRON_BARS,12,CONCRETE:7,100)
RandomBlock(-8,5,-4,CONCRETE:7,60,quark:iron_plate:1,20,STAINED_CLAY:12,15,STAINED_CLAY:15,5,AIR,7,IRON_BARS,12,CONCRETE:7,100)
RandomBlock(-8,5,-3,CONCRETE:7,60,quark:iron_plate:1,20,STAINED_CLAY:12,15,STAINED_CLAY:15,5,AIR,7,IRON_BARS,12,CONCRETE:7,100)
RandomBlock(-8,5,-2,CONCRETE:7,60,quark:iron_plate:1,20,STAINED_CLAY:12,15,STAINED_CLAY:15,5,AIR,7,IRON_BARS,12,CONCRETE:7,100)
RandomBlock(-8,5,-1,CONCRETE:7,60,quark:iron_plate:1,20,STAINED_CLAY:12,15,STAINED_CLAY:15,5,AIR,7,IRON_BARS,12,CONCRETE:7,100)
RandomBlock(-8,5,0,CONCRETE:7,60,quark:iron_plate:1,20,STAINED_CLAY:12,15,STAINED_CLAY:15,5,AIR,7,IRON_BARS,12,CONCRETE:7,100)
RandomBlock(-8,5,1,CONCRETE:7,60,quark:iron_plate:1,20,STAINED_CLAY:12,15,STAINED_CLAY:15,5,AIR,7,IRON_BARS,12,CONCRETE:7,100)
RandomBlock(-8,5,2,CONCRETE:7,60,quark:iron_plate:1,20,STAINED_CLAY:12,15,STAINED_CLAY:15,5,AIR,7,IRON_BARS,12,CONCRETE:7,100)
RandomBlock(-8,5,3,CONCRETE:7,60,quark:iron_plate:1,20,STAINED_CLAY:12,15,STAINED_CLAY:15,5,AIR,7,IRON_BARS,12,CONCRETE:7,100)
RandomBlock(-8,5,4,CONCRETE:7,60,quark:iron_plate:1,20,STAINED_CLAY:12,15,STAINED_CLAY:15,5,AIR,7,IRON_BARS,12,CONCRETE:7,100)
RandomBlock(-8,5,5,CONCRETE:7,60,quark:iron_plate:1,20,STAINED_CLAY:12,15,STAINED_CLAY:15,5,AIR,7,IRON_BARS,12,CONCRETE:7,100)
RandomBlock(-8,5,6,CONCRETE:7,60,quark:iron_plate:1,20,STAINED_CLAY:12,15,STAINED_CLAY:15,5,AIR,7,IRON_BARS,12,CONCRETE:7,100)
RandomBlock(-8,5,7,CONCRETE:7,60,quark:iron_plate:1,20,STAINED_CLAY:12,15,STAINED_CLAY:15,5,AIR,7,IRON_BARS,12,CONCRETE:7,100)
RandomBlock(-8,5,8,CONCRETE:7,60,quark:iron_plate:1,20,STAINED_CLAY:12,15,STAINED_CLAY:15,5,AIR,7,IRON_BARS,12,CONCRETE:7,100)
RandomBlock(-8,6,-7,CONCRETE:7,60,quark:iron_plate:1,20,STAINED_CLAY:12,15,STAINED_CLAY:15,5,AIR,7,IRON_BARS,12,CONCRETE:7,100)
RandomBlock(-8,6,-6,CONCRETE:7,60,quark:iron_plate:1,20,STAINED_CLAY:12,15,STAINED_CLAY:15,5,AIR,7,IRON_BARS,12,CONCRETE:7,100)
RandomBlock(-8,6,-5,CONCRETE:7,60,quark:iron_plate:1,20,STAINED_CLAY:12,15,STAINED_CLAY:15,5,AIR,7,IRON_BARS,12,CONCRETE:7,100)
RandomBlock(-8,6,-4,CONCRETE:7,60,quark:iron_plate:1,20,STAINED_CLAY:12,15,STAINED_CLAY:15,5,AIR,7,IRON_BARS,12,CONCRETE:7,100)
RandomBlock(-8,6,-3,CONCRETE:7,60,quark:iron_plate:1,20,STAINED_CLAY:12,15,STAINED_CLAY:15,5,AIR,7,IRON_BARS,12,CONCRETE:7,100)
RandomBlock(-8,6,-2,CONCRETE:7,60,quark:iron_plate:1,20,STAINED_CLAY:12,15,STAINED_CLAY:15,5,AIR,7,IRON_BARS,12,CONCRETE:7,100)
RandomBlock(-8,6,-1,CONCRETE:7,60,quark:iron_plate:1,20,STAINED_CLAY:12,15,STAINED_CLAY:15,5,AIR,7,IRON_BARS,12,CONCRETE:7,100)
RandomBlock(-8,6,0,CONCRETE:7,60,quark:iron_plate:1,20,STAINED_CLAY:12,15,STAINED_CLAY:15,5,AIR,7,IRON_BARS,12,CONCRETE:7,100)
RandomBlock(-8,6,1,CONCRETE:7,60,quark:iron_plate:1,20,STAINED_CLAY:12,15,STAINED_CLAY:15,5,AIR,7,IRON_BARS,12,CONCRETE:7,100)
RandomBlock(-8,6,2,CONCRETE:7,60,quark:iron_plate:1,20,STAINED_CLAY:12,15,STAINED_CLAY:15,5,AIR,7,IRON_BARS,12,CONCRETE:7,100)
RandomBlock(-8,6,3,CONCRETE:7,60,quark:iron_plate:1,20,STAINED_CLAY:12,15,STAINED_CLAY:15,5,AIR,7,IRON_BARS,12,CONCRETE:7,100)
RandomBlock(-8,6,4,CONCRETE:7,60,quark:iron_plate:1,20,STAINED_CLAY:12,15,STAINED_CLAY:15,5,AIR,7,IRON_BARS,12,CONCRETE:7,100)
RandomBlock(-8,6,5,CONCRETE:7,60,quark:iron_plate:1,20,STAINED_CLAY:12,15,STAINED_CLAY:15,5,AIR,7,IRON_BARS,12,CONCRETE:7,100)
RandomBlock(-8,6,6,CONCRETE:7,60,quark:iron_plate:1,20,STAINED_CLAY:12,15,STAINED_CLAY:15,5,AIR,7,IRON_BARS,12,CONCRETE:7,100)
RandomBlock(-8,6,7,CONCRETE:7,60,quark:iron_plate:1,20,STAINED_CLAY:12,15,STAINED_CLAY:15,5,AIR,7,IRON_BARS,12,CONCRETE:7,100)
RandomBlock(-8,6,8,CONCRETE:7,60,quark:iron_plate:1,20,STAINED_CLAY:12,15,STAINED_CLAY:15,5,AIR,7,IRON_BARS,12,CONCRETE:7,100)
RandomBlock(-8,7,-7,CONCRETE:7,60,quark:iron_plate:1,20,STAINED_CLAY:12,15,STAINED_CLAY:15,5,AIR,7,IRON_BARS,12,CONCRETE:7,100)
RandomBlock(-8,7,-6,CONCRETE:7,60,quark:iron_plate:1,20,STAINED_CLAY:12,15,STAINED_CLAY:15,5,AIR,7,IRON_BARS,12,CONCRETE:7,100)
RandomBlock(-8,7,-5,CONCRETE:7,60,quark:iron_plate:1,20,STAINED_CLAY:12,15,STAINED_CLAY:15,5,AIR,7,IRON_BARS,12,CONCRETE:7,100)
RandomBlock(-8,7,-4,CONCRETE:7,60,quark:iron_plate:1,20,STAINED_CLAY:12,15,STAINED_CLAY:15,5,AIR,7,IRON_BARS,12,CONCRETE:7,100)
RandomBlock(-8,7,-3,CONCRETE:7,60,quark:iron_plate:1,20,STAINED_CLAY:12,15,STAINED_CLAY:15,5,AIR,7,IRON_BARS,12,CONCRETE:7,100)
RandomBlock(-8,7,-2,CONCRETE:7,60,quark:iron_plate:1,20,STAINED_CLAY:12,15,STAINED_CLAY:15,5,AIR,7,IRON_BARS,12,CONCRETE:7,100)
RandomBlock(-8,7,-1,CONCRETE:7,60,quark:iron_plate:1,20,STAINED_CLAY:12,15,STAINED_CLAY:15,5,AIR,7,IRON_BARS,12,CONCRETE:7,100)
RandomBlock(-8,7,0,CONCRETE:7,60,quark:iron_plate:1,20,STAINED_CLAY:12,15,STAINED_CLAY:15,5,AIR,7,IRON_BARS,12,CONCRETE:7,100)
RandomBlock(-8,7,1,CONCRETE:7,60,quark:iron_plate:1,20,STAINED_CLAY:12,15,STAINED_CLAY:15,5,AIR,7,IRON_BARS,12,CONCRETE:7,100)
RandomBlock(-8,7,2,CONCRETE:7,60,quark:iron_plate:1,20,STAINED_CLAY:12,15,STAINED_CLAY:15,5,AIR,7,IRON_BARS,12,CONCRETE:7,100)
RandomBlock(-8,7,3,CONCRETE:7,60,quark:iron_plate:1,20,STAINED_CLAY:12,15,STAINED_CLAY:15,5,AIR,7,IRON_BARS,12,CONCRETE:7,100)
RandomBlock(-8,7,4,CONCRETE:7,60,quark:iron_plate:1,20,STAINED_CLAY:12,15,STAINED_CLAY:15,5,AIR,7,IRON_BARS,12,CONCRETE:7,100)
RandomBlock(-8,7,5,CONCRETE:7,60,quark:iron_plate:1,20,STAINED_CLAY:12,15,STAINED_CLAY:15,5,AIR,7,IRON_BARS,12,CONCRETE:7,100)
RandomBlock(-8,7,6,CONCRETE:7,60,quark:iron_plate:1,20,STAINED_CLAY:12,15,STAINED_CLAY:15,5,AIR,7,IRON_BARS,12,CONCRETE:7,100)
RandomBlock(-8,7,7,CONCRETE:7,60,quark:iron_plate:1,20,STAINED_CLAY:12,15,STAINED_CLAY:15,5,AIR,7,IRON_BARS,12,CONCRETE:7,100)
RandomBlock(-8,7,8,CONCRETE:7,60,quark:iron_plate:1,20,STAINED_CLAY:12,15,STAINED_CLAY:15,5,AIR,7,IRON_BARS,12,CONCRETE:7,100)
RandomBlock(-8,8,-7,CONCRETE:7,60,quark:iron_plate:1,20,STAINED_CLAY:12,15,STAINED_CLAY:15,5,AIR,7,IRON_BARS,12,CONCRETE:7,100)
RandomBlock(-8,8,-6,CONCRETE:7,60,quark:iron_plate:1,20,STAINED_CLAY:12,15,STAINED_CLAY:15,5,AIR,7,IRON_BARS,12,CONCRETE:7,100)
RandomBlock(-8,8,-5,CONCRETE:7,60,quark:iron_plate:1,20,STAINED_CLAY:12,15,STAINED_CLAY:15,5,AIR,7,IRON_BARS,12,CONCRETE:7,100)
RandomBlock(-8,8,-4,CONCRETE:7,60,quark:iron_plate:1,20,STAINED_CLAY:12,15,STAINED_CLAY:15,5,AIR,7,IRON_BARS,12,CONCRETE:7,100)
RandomBlock(-8,8,-3,CONCRETE:7,60,quark:iron_plate:1,20,STAINED_CLAY:12,15,STAINED_CLAY:15,5,AIR,7,IRON_BARS,12,CONCRETE:7,100)
RandomBlock(-8,8,-2,CONCRETE:7,60,quark:iron_plate:1,20,STAINED_CLAY:12,15,STAINED_CLAY:15,5,AIR,7,IRON_BARS,12,CONCRETE:7,100)
RandomBlock(-8,8,-1,CONCRETE:7,60,quark:iron_plate:1,20,STAINED_CLAY:12,15,STAINED_CLAY:15,5,AIR,7,IRON_BARS,12,CONCRETE:7,100)
RandomBlock(-8,8,0,CONCRETE:7,60,quark:iron_plate:1,20,STAINED_CLAY:12,15,STAINED_CLAY:15,5,AIR,7,IRON_BARS,12,CONCRETE:7,100)
RandomBlock(-8,8,1,CONCRETE:7,60,quark:iron_plate:1,20,STAINED_CLAY:12,15,STAINED_CLAY:15,5,AIR,7,IRON_BARS,12,CONCRETE:7,100)
RandomBlock(-8,8,2,CONCRETE:7,60,quark:iron_plate:1,20,STAINED_CLAY:12,15,STAINED_CLAY:15,5,AIR,7,IRON_BARS,12,CONCRETE:7,100)
RandomBlock(-8,8,3,CONCRETE:7,60,quark:iron_plate:1,20,STAINED_CLAY:12,15,STAINED_CLAY:15,5,AIR,7,IRON_BARS,12,CONCRETE:7,100)
RandomBlock(-8,8,4,CONCRETE:7,60,quark:iron_plate:1,20,STAINED_CLAY:12,15,STAINED_CLAY:15,5,AIR,7,IRON_BARS,12,CONCRETE:7,100)
RandomBlock(-8,8,5,CONCRETE:7,60,quark:iron_plate:1,20,STAINED_CLAY:12,15,STAINED_CLAY:15,5,AIR,7,IRON_BARS,12,CONCRETE:7,100)
RandomBlock(-8,8,6,CONCRETE:7,60,quark:iron_plate:1,20,STAINED_CLAY:12,15,STAINED_CLAY:15,5,AIR,7,IRON_BARS,12,CONCRETE:7,100)
RandomBlock(-8,8,7,CONCRETE:7,60,quark:iron_plate:1,20,STAINED_CLAY:12,15,STAINED_CLAY:15,5,AIR,7,IRON_BARS,12,CONCRETE:7,100)
RandomBlock(-8,8,8,CONCRETE:7,60,quark:iron_plate:1,20,STAINED_CLAY:12,15,STAINED_CLAY:15,5,AIR,7,IRON_BARS,12,CONCRETE:7,100)
RandomBlock(-8,9,-7,CONCRETE:7,60,quark:iron_plate:1,20,STAINED_CLAY:12,15,STAINED_CLAY:15,5,AIR,7,IRON_BARS,12,CONCRETE:7,100)
RandomBlock(-8,9,-6,CONCRETE:7,60,quark:iron_plate:1,20,STAINED_CLAY:12,15,STAINED_CLAY:15,5,AIR,7,IRON_BARS,12,CONCRETE:7,100)
RandomBlock(-8,9,-5,CONCRETE:7,60,quark:iron_plate:1,20,STAINED_CLAY:12,15,STAINED_CLAY:15,5,AIR,7,IRON_BARS,12,CONCRETE:7,100)
RandomBlock(-8,9,-4,CONCRETE:7,60,quark:iron_plate:1,20,STAINED_CLAY:12,15,STAINED_CLAY:15,5,AIR,7,IRON_BARS,12,CONCRETE:7,100)
RandomBlock(-8,9,-3,CONCRETE:7,60,quark:iron_plate:1,20,STAINED_CLAY:12,15,STAINED_CLAY:15,5,AIR,7,IRON_BARS,12,CONCRETE:7,100)
RandomBlock(-8,9,-2,CONCRETE:7,60,quark:iron_plate:1,20,STAINED_CLAY:12,15,STAINED_CLAY:15,5,AIR,7,IRON_BARS,12,CONCRETE:7,100)
RandomBlock(-8,9,-1,CONCRETE:7,60,quark:iron_plate:1,20,STAINED_CLAY:12,15,STAINED_CLAY:15,5,AIR,7,IRON_BARS,12,CONCRETE:7,100)
RandomBlock(-8,9,0,CONCRETE:7,60,quark:iron_plate:1,20,STAINED_CLAY:12,15,STAINED_CLAY:15,5,AIR,7,IRON_BARS,12,CONCRETE:7,100)
RandomBlock(-8,9,1,CONCRETE:7,60,quark:iron_plate:1,20,STAINED_CLAY:12,15,STAINED_CLAY:15,5,AIR,7,IRON_BARS,12,CONCRETE:7,100)
RandomBlock(-8,9,2,CONCRETE:7,60,quark:iron_plate:1,20,STAINED_CLAY:12,15,STAINED_CLAY:15,5,AIR,7,IRON_BARS,12,CONCRETE:7,100)
RandomBlock(-8,9,3,CONCRETE:7,60,quark:iron_plate:1,20,STAINED_CLAY:12,15,STAINED_CLAY:15,5,AIR,7,IRON_BARS,12,CONCRETE:7,100)
RandomBlock(-8,9,4,CONCRETE:7,60,quark:iron_plate:1,20,STAINED_CLAY:12,15,STAINED_CLAY:15,5,AIR,7,IRON_BARS,12,CONCRETE:7,100)
RandomBlock(-8,9,5,CONCRETE:7,60,quark:iron_plate:1,20,STAINED_CLAY:12,15,STAINED_CLAY:15,5,AIR,7,IRON_BARS,12,CONCRETE:7,100)
RandomBlock(-8,9,6,CONCRETE:7,60,quark:iron_plate:1,20,STAINED_CLAY:12,15,STAINED_CLAY:15,5,AIR,7,IRON_BARS,12,CONCRETE:7,100)
RandomBlock(-8,9,7,CONCRETE:7,60,quark:iron_plate:1,20,STAINED_CLAY:12,15,STAINED_CLAY:15,5,AIR,7,IRON_BARS,12,CONCRETE:7,100)
RandomBlock(-8,9,8,CONCRETE:7,60,quark:iron_plate:1,20,STAINED_CLAY:12,15,STAINED_CLAY:15,5,AIR,7,IRON_BARS,12,CONCRETE:7,100)
RandomBlock(-8,10,-7,CONCRETE:7,60,quark:iron_plate:1,20,STAINED_CLAY:12,15,STAINED_CLAY:15,5,AIR,7,IRON_BARS,12,CONCRETE:7,100)
RandomBlock(-8,10,-6,CONCRETE:7,60,quark:iron_plate:1,20,STAINED_CLAY:12,15,STAINED_CLAY:15,5,AIR,7,IRON_BARS,12,CONCRETE:7,100)
RandomBlock(-8,10,-5,CONCRETE:7,60,quark:iron_plate:1,20,STAINED_CLAY:12,15,STAINED_CLAY:15,5,AIR,7,IRON_BARS,12,CONCRETE:7,100)
RandomBlock(-8,10,-4,CONCRETE:7,60,quark:iron_plate:1,20,STAINED_CLAY:12,15,STAINED_CLAY:15,5,AIR,7,IRON_BARS,12,CONCRETE:7,100)
RandomBlock(-8,10,-3,CONCRETE:7,60,quark:iron_plate:1,20,STAINED_CLAY:12,15,STAINED_CLAY:15,5,AIR,7,IRON_BARS,12,CONCRETE:7,100)
RandomBlock(-8,10,-2,CONCRETE:7,60,quark:iron_plate:1,20,STAINED_CLAY:12,15,STAINED_CLAY:15,5,AIR,7,IRON_BARS,12,CONCRETE:7,100)
RandomBlock(-8,10,-1,CONCRETE:7,60,quark:iron_plate:1,20,STAINED_CLAY:12,15,STAINED_CLAY:15,5,AIR,7,IRON_BARS,12,CONCRETE:7,100)
RandomBlock(-8,10,0,CONCRETE:7,60,quark:iron_plate:1,20,STAINED_CLAY:12,15,STAINED_CLAY:15,5,AIR,7,IRON_BARS,12,CONCRETE:7,100)
RandomBlock(-8,10,1,CONCRETE:7,60,quark:iron_plate:1,20,STAINED_CLAY:12,15,STAINED_CLAY:15,5,AIR,7,IRON_BARS,12,CONCRETE:7,100)
RandomBlock(-8,10,2,CONCRETE:7,60,quark:iron_plate:1,20,STAINED_CLAY:12,15,STAINED_CLAY:15,5,AIR,7,IRON_BARS,12,CONCRETE:7,100)
RandomBlock(-8,10,3,CONCRETE:7,60,quark:iron_plate:1,20,STAINED_CLAY:12,15,STAINED_CLAY:15,5,AIR,7,IRON_BARS,12,CONCRETE:7,100)
RandomBlock(-8,10,4,CONCRETE:7,60,quark:iron_plate:1,20,STAINED_CLAY:12,15,STAINED_CLAY:15,5,AIR,7,IRON_BARS,12,CONCRETE:7,100)
RandomBlock(-8,10,5,CONCRETE:7,60,quark:iron_plate:1,20,STAINED_CLAY:12,15,STAINED_CLAY:15,5,AIR,7,IRON_BARS,12,CONCRETE:7,100)
RandomBlock(-8,10,6,CONCRETE:7,60,quark:iron_plate:1,20,STAINED_CLAY:12,15,STAINED_CLAY:15,5,AIR,7,IRON_BARS,12,CONCRETE:7,100)
RandomBlock(-8,10,7,CONCRETE:7,60,quark:iron_plate:1,20,STAINED_CLAY:12,15,STAINED_CLAY:15,5,AIR,7,IRON_BARS,12,CONCRETE:7,100)
RandomBlock(-8,10,8,CONCRETE:7,60,quark:iron_plate:1,20,STAINED_CLAY:12,15,STAINED_CLAY:15,5,AIR,7,IRON_BARS,12,CONCRETE:7,100)
RandomBlock(-8,11,-7,CONCRETE:7,60,quark:iron_plate:1,20,STAINED_CLAY:12,15,STAINED_CLAY:15,5,AIR,7,IRON_BARS,12,CONCRETE:7,100)
RandomBlock(-8,11,-6,CONCRETE:7,60,quark:iron_plate:1,20,STAINED_CLAY:12,15,STAINED_CLAY:15,5,AIR,7,IRON_BARS,12,CONCRETE:7,100)
RandomBlock(-8,11,-5,CONCRETE:7,60,quark:iron_plate:1,20,STAINED_CLAY:12,15,STAINED_CLAY:15,5,AIR,7,IRON_BARS,12,CONCRETE:7,100)
RandomBlock(-8,11,-4,CONCRETE:7,60,quark:iron_plate:1,20,STAINED_CLAY:12,15,STAINED_CLAY:15,5,AIR,7,IRON_BARS,12,CONCRETE:7,100)
RandomBlock(-8,11,-3,CONCRETE:7,60,quark:iron_plate:1,20,STAINED_CLAY:12,15,STAINED_CLAY:15,5,AIR,7,IRON_BARS,12,CONCRETE:7,100)
RandomBlock(-8,11,-2,CONCRETE:7,60,quark:iron_plate:1,20,STAINED_CLAY:12,15,STAINED_CLAY:15,5,AIR,7,IRON_BARS,12,CONCRETE:7,100)
RandomBlock(-8,11,-1,CONCRETE:7,60,quark:iron_plate:1,20,STAINED_CLAY:12,15,STAINED_CLAY:15,5,AIR,7,IRON_BARS,12,CONCRETE:7,100)
RandomBlock(-8,11,0,CONCRETE:7,60,quark:iron_plate:1,20,STAINED_CLAY:12,15,STAINED_CLAY:15,5,AIR,7,IRON_BARS,12,CONCRETE:7,100)
RandomBlock(-8,11,1,CONCRETE:7,60,quark:iron_plate:1,20,STAINED_CLAY:12,15,STAINED_CLAY:15,5,AIR,7,IRON_BARS,12,CONCRETE:7,100)
RandomBlock(-8,11,2,CONCRETE:7,60,quark:iron_plate:1,20,STAINED_CLAY:12,15,STAINED_CLAY:15,5,AIR,7,IRON_BARS,12,CONCRETE:7,100)
RandomBlock(-8,11,3,CONCRETE:7,60,quark:iron_plate:1,20,STAINED_CLAY:12,15,STAINED_CLAY:15,5,AIR,7,IRON_BARS,12,CONCRETE:7,100)
RandomBlock(-8,11,4,CONCRETE:7,60,quark:iron_plate:1,20,STAINED_CLAY:12,15,STAINED_CLAY:15,5,AIR,7,IRON_BARS,12,CONCRETE:7,100)
RandomBlock(-8,11,5,CONCRETE:7,60,quark:iron_plate:1,20,STAINED_CLAY:12,15,STAINED_CLAY:15,5,AIR,7,IRON_BARS,12,CONCRETE:7,100)
RandomBlock(-8,11,6,CONCRETE:7,60,quark:iron_plate:1,20,STAINED_CLAY:12,15,STAINED_CLAY:15,5,AIR,7,IRON_BARS,12,CONCRETE:7,100)
RandomBlock(-8,11,7,CONCRETE:7,60,quark:iron_plate:1,20,STAINED_CLAY:12,15,STAINED_CLAY:15,5,AIR,7,IRON_BARS,12,CONCRETE:7,100)
RandomBlock(-8,11,8,CONCRETE:7,60,quark:iron_plate:1,20,STAINED_CLAY:12,15,STAINED_CLAY:15,5,AIR,7,IRON_BARS,12,CONCRETE:7,100)
RandomBlock(-8,12,-7,CONCRETE:7,60,quark:iron_plate:1,20,STAINED_CLAY:12,15,STAINED_CLAY:15,5,AIR,7,IRON_BARS,12,CONCRETE:7,100)
RandomBlock(-8,12,-6,CONCRETE:7,60,quark:iron_plate:1,20,STAINED_CLAY:12,15,STAINED_CLAY:15,5,AIR,7,IRON_BARS,12,CONCRETE:7,100)
RandomBlock(-8,12,-5,CONCRETE:7,60,quark:iron_plate:1,20,STAINED_CLAY:12,15,STAINED_CLAY:15,5,AIR,7,IRON_BARS,12,CONCRETE:7,100)
RandomBlock(-8,12,-4,CONCRETE:7,60,quark:iron_plate:1,20,STAINED_CLAY:12,15,STAINED_CLAY:15,5,AIR,7,IRON_BARS,12,CONCRETE:7,100)
RandomBlock(-8,12,-3,CONCRETE:7,60,quark:iron_plate:1,20,STAINED_CLAY:12,15,STAINED_CLAY:15,5,AIR,7,IRON_BARS,12,CONCRETE:7,100)
RandomBlock(-8,12,-2,CONCRETE:7,60,quark:iron_plate:1,20,STAINED_CLAY:12,15,STAINED_CLAY:15,5,AIR,7,IRON_BARS,12,CONCRETE:7,100)
RandomBlock(-8,12,-1,CONCRETE:7,60,quark:iron_plate:1,20,STAINED_CLAY:12,15,STAINED_CLAY:15,5,AIR,7,IRON_BARS,12,CONCRETE:7,100)
RandomBlock(-8,12,0,CONCRETE:7,60,quark:iron_plate:1,20,STAINED_CLAY:12,15,STAINED_CLAY:15,5,AIR,7,IRON_BARS,12,CONCRETE:7,100)
RandomBlock(-8,12,1,CONCRETE:7,60,quark:iron_plate:1,20,STAINED_CLAY:12,15,STAINED_CLAY:15,5,AIR,7,IRON_BARS,12,CONCRETE:7,100)
RandomBlock(-8,12,2,CONCRETE:7,60,quark:iron_plate:1,20,STAINED_CLAY:12,15,STAINED_CLAY:15,5,AIR,7,IRON_BARS,12,CONCRETE:7,100)
RandomBlock(-8,12,3,CONCRETE:7,60,quark:iron_plate:1,20,STAINED_CLAY:12,15,STAINED_CLAY:15,5,AIR,7,IRON_BARS,12,CONCRETE:7,100)
RandomBlock(-8,12,4,CONCRETE:7,60,quark:iron_plate:1,20,STAINED_CLAY:12,15,STAINED_CLAY:15,5,AIR,7,IRON_BARS,12,CONCRETE:7,100)
RandomBlock(-8,12,5,CONCRETE:7,60,quark:iron_plate:1,20,STAINED_CLAY:12,15,STAINED_CLAY:15,5,AIR,7,IRON_BARS,12,CONCRETE:7,100)
RandomBlock(-8,12,6,CONCRETE:7,60,quark:iron_plate:1,20,STAINED_CLAY:12,15,STAINED_CLAY:15,5,AIR,7,IRON_BARS,12,CONCRETE:7,100)
RandomBlock(-8,12,7,CONCRETE:7,60,quark:iron_plate:1,20,STAINED_CLAY:12,15,STAINED_CLAY:15,5,AIR,7,IRON_BARS,12,CONCRETE:7,100)
RandomBlock(-8,12,8,CONCRETE:7,60,quark:iron_plate:1,20,STAINED_CLAY:12,15,STAINED_CLAY:15,5,AIR,7,IRON_BARS,12,CONCRETE:7,100)
RandomBlock(-8,13,-7,CONCRETE:7,60,quark:iron_plate:1,20,STAINED_CLAY:12,15,STAINED_CLAY:15,5,AIR,7,IRON_BARS,12,CONCRETE:7,100)
RandomBlock(-8,13,-6,CONCRETE:7,60,quark:iron_plate:1,20,STAINED_CLAY:12,15,STAINED_CLAY:15,5,AIR,7,IRON_BARS,12,CONCRETE:7,100)
RandomBlock(-8,13,-5,CONCRETE:7,60,quark:iron_plate:1,20,STAINED_CLAY:12,15,STAINED_CLAY:15,5,AIR,7,IRON_BARS,12,CONCRETE:7,100)
RandomBlock(-8,13,-4,CONCRETE:7,60,quark:iron_plate:1,20,STAINED_CLAY:12,15,STAINED_CLAY:15,5,AIR,7,IRON_BARS,12,CONCRETE:7,100)
RandomBlock(-8,13,-3,CONCRETE:7,60,quark:iron_plate:1,20,STAINED_CLAY:12,15,STAINED_CLAY:15,5,AIR,7,IRON_BARS,12,CONCRETE:7,100)
RandomBlock(-8,13,-2,CONCRETE:7,60,quark:iron_plate:1,20,STAINED_CLAY:12,15,STAINED_CLAY:15,5,AIR,7,IRON_BARS,12,CONCRETE:7,100)
RandomBlock(-8,13,-1,CONCRETE:7,60,quark:iron_plate:1,20,STAINED_CLAY:12,15,STAINED_CLAY:15,5,AIR,7,IRON_BARS,12,CONCRETE:7,100)
RandomBlock(-8,13,0,CONCRETE:7,60,quark:iron_plate:1,20,STAINED_CLAY:12,15,STAINED_CLAY:15,5,AIR,7,IRON_BARS,12,CONCRETE:7,100)
RandomBlock(-8,13,1,CONCRETE:7,60,quark:iron_plate:1,20,STAINED_CLAY:12,15,STAINED_CLAY:15,5,AIR,7,IRON_BARS,12,CONCRETE:7,100)
RandomBlock(-8,13,2,CONCRETE:7,60,quark:iron_plate:1,20,STAINED_CLAY:12,15,STAINED_CLAY:15,5,AIR,7,IRON_BARS,12,CONCRETE:7,100)
RandomBlock(-8,13,3,CONCRETE:7,60,quark:iron_plate:1,20,STAINED_CLAY:12,15,STAINED_CLAY:15,5,AIR,7,IRON_BARS,12,CONCRETE:7,100)
RandomBlock(-8,13,4,CONCRETE:7,60,quark:iron_plate:1,20,STAINED_CLAY:12,15,STAINED_CLAY:15,5,AIR,7,IRON_BARS,12,CONCRETE:7,100)
RandomBlock(-8,13,5,CONCRETE:7,60,quark:iron_plate:1,20,STAINED_CLAY:12,15,STAINED_CLAY:15,5,AIR,7,IRON_BARS,12,CONCRETE:7,100)
RandomBlock(-8,13,6,CONCRETE:7,60,quark:iron_plate:1,20,STAINED_CLAY:12,15,STAINED_CLAY:15,5,AIR,7,IRON_BARS,12,CONCRETE:7,100)
RandomBlock(-8,13,7,CONCRETE:7,60,quark:iron_plate:1,20,STAINED_CLAY:12,15,STAINED_CLAY:15,5,AIR,7,IRON_BARS,12,CONCRETE:7,100)
RandomBlock(-8,13,8,CONCRETE:7,60,quark:iron_plate:1,20,STAINED_CLAY:12,15,STAINED_CLAY:15,5,AIR,7,IRON_BARS,12,CONCRETE:7,100)
RandomBlock(-8,14,-7,CONCRETE:7,60,quark:iron_plate:1,20,STAINED_CLAY:12,15,STAINED_CLAY:15,5,AIR,7,IRON_BARS,12,CONCRETE:7,100)
RandomBlock(-8,14,-6,CONCRETE:7,60,quark:iron_plate:1,20,STAINED_CLAY:12,15,STAINED_CLAY:15,5,AIR,7,IRON_BARS,12,CONCRETE:7,100)
RandomBlock(-8,14,-5,CONCRETE:7,60,quark:iron_plate:1,20,STAINED_CLAY:12,15,STAINED_CLAY:15,5,AIR,7,IRON_BARS,12,CONCRETE:7,100)
RandomBlock(-8,14,-4,CONCRETE:7,60,quark:iron_plate:1,20,STAINED_CLAY:12,15,STAINED_CLAY:15,5,AIR,7,IRON_BARS,12,CONCRETE:7,100)
RandomBlock(-8,14,-3,CONCRETE:7,60,quark:iron_plate:1,20,STAINED_CLAY:12,15,STAINED_CLAY:15,5,AIR,7,IRON_BARS,12,CONCRETE:7,100)
RandomBlock(-8,14,-2,CONCRETE:7,60,quark:iron_plate:1,20,STAINED_CLAY:12,15,STAINED_CLAY:15,5,AIR,7,IRON_BARS,12,CONCRETE:7,100)
RandomBlock(-8,14,-1,CONCRETE:7,60,quark:iron_plate:1,20,STAINED_CLAY:12,15,STAINED_CLAY:15,5,AIR,7,IRON_BARS,12,CONCRETE:7,100)
RandomBlock(-8,14,0,CONCRETE:7,60,quark:iron_plate:1,20,STAINED_CLAY:12,15,STAINED_CLAY:15,5,AIR,7,IRON_BARS,12,CONCRETE:7,100)
RandomBlock(-8,14,1,CONCRETE:7,60,quark:iron_plate:1,20,STAINED_CLAY:12,15,STAINED_CLAY:15,5,AIR,7,IRON_BARS,12,CONCRETE:7,100)
RandomBlock(-8,14,2,CONCRETE:7,60,quark:iron_plate:1,20,STAINED_CLAY:12,15,STAINED_CLAY:15,5,AIR,7,IRON_BARS,12,CONCRETE:7,100)
RandomBlock(-8,14,3,CONCRETE:7,60,quark:iron_plate:1,20,STAINED_CLAY:12,15,STAINED_CLAY:15,5,AIR,7,IRON_BARS,12,CONCRETE:7,100)
RandomBlock(-8,14,4,CONCRETE:7,60,quark:iron_plate:1,20,STAINED_CLAY:12,15,STAINED_CLAY:15,5,AIR,7,IRON_BARS,12,CONCRETE:7,100)
RandomBlock(-8,14,5,CONCRETE:7,60,quark:iron_plate:1,20,STAINED_CLAY:12,15,STAINED_CLAY:15,5,AIR,7,IRON_BARS,12,CONCRETE:7,100)
RandomBlock(-8,14,6,CONCRETE:7,60,quark:iron_plate:1,20,STAINED_CLAY:12,15,STAINED_CLAY:15,5,AIR,7,IRON_BARS,12,CONCRETE:7,100)
RandomBlock(-8,14,7,CONCRETE:7,60,quark:iron_plate:1,20,STAINED_CLAY:12,15,STAINED_CLAY:15,5,AIR,7,IRON_BARS,12,CONCRETE:7,100)
RandomBlock(-8,14,8,CONCRETE:7,60,quark:iron_plate:1,20,STAINED_CLAY:12,15,STAINED_CLAY:15,5,AIR,7,IRON_BARS,12,CONCRETE:7,100)
RandomBlock(-8,15,-7,CONCRETE:7,60,quark:iron_plate:1,20,STAINED_CLAY:12,15,STAINED_CLAY:15,5,AIR,7,IRON_BARS,12,CONCRETE:7,100)
RandomBlock(-8,15,-6,CONCRETE:7,60,quark:iron_plate:1,20,STAINED_CLAY:12,15,STAINED_CLAY:15,5,AIR,7,IRON_BARS,12,CONCRETE:7,100)
RandomBlock(-8,15,-5,CONCRETE:7,60,quark:iron_plate:1,20,STAINED_CLAY:12,15,STAINED_CLAY:15,5,AIR,7,IRON_BARS,12,CONCRETE:7,100)
RandomBlock(-8,15,-4,CONCRETE:7,60,quark:iron_plate:1,20,STAINED_CLAY:12,15,STAINED_CLAY:15,5,AIR,7,IRON_BARS,12,CONCRETE:7,100)
RandomBlock(-8,15,-3,CONCRETE:7,60,quark:iron_plate:1,20,STAINED_CLAY:12,15,STAINED_CLAY:15,5,AIR,7,IRON_BARS,12,CONCRETE:7,100)
RandomBlock(-8,15,-2,CONCRETE:7,60,quark:iron_plate:1,20,STAINED_CLAY:12,15,STAINED_CLAY:15,5,AIR,7,IRON_BARS,12,CONCRETE:7,100)
RandomBlock(-8,15,-1,CONCRETE:7,60,quark:iron_plate:1,20,STAINED_CLAY:12,15,STAINED_CLAY:15,5,AIR,7,IRON_BARS,12,CONCRETE:7,100)
RandomBlock(-8,15,0,CONCRETE:7,60,quark:iron_plate:1,20,STAINED_CLAY:12,15,STAINED_CLAY:15,5,AIR,7,IRON_BARS,12,CONCRETE:7,100)
RandomBlock(-8,15,1,CONCRETE:7,60,quark:iron_plate:1,20,STAINED_CLAY:12,15,STAINED_CLAY:15,5,AIR,7,IRON_BARS,12,CONCRETE:7,100)
RandomBlock(-8,15,2,CONCRETE:7,60,quark:iron_plate:1,20,STAINED_CLAY:12,15,STAINED_CLAY:15,5,AIR,7,IRON_BARS,12,CONCRETE:7,100)
RandomBlock(-8,15,3,CONCRETE:7,60,quark:iron_plate:1,20,STAINED_CLAY:12,15,STAINED_CLAY:15,5,AIR,7,IRON_BARS,12,CONCRETE:7,100)
RandomBlock(-8,15,4,CONCRETE:7,60,quark:iron_plate:1,20,STAINED_CLAY:12,15,STAINED_CLAY:15,5,AIR,7,IRON_BARS,12,CONCRETE:7,100)
RandomBlock(-8,15,5,CONCRETE:7,60,quark:iron_plate:1,20,STAINED_CLAY:12,15,STAINED_CLAY:15,5,AIR,7,IRON_BARS,12,CONCRETE:7,100)
RandomBlock(-8,15,6,CONCRETE:7,60,quark:iron_plate:1,20,STAINED_CLAY:12,15,STAINED_CLAY:15,5,AIR,7,IRON_BARS,12,CONCRETE:7,100)
RandomBlock(-8,15,7,CONCRETE:7,60,quark:iron_plate:1,20,STAINED_CLAY:12,15,STAINED_CLAY:15,5,AIR,7,IRON_BARS,12,CONCRETE:7,100)
RandomBlock(-8,15,8,CONCRETE:7,60,quark:iron_plate:1,20,STAINED_CLAY:12,15,STAINED_CLAY:15,5,AIR,7,IRON_BARS,12,CONCRETE:7,100)
RandomBlock(-8,16,-7,CONCRETE:7,60,quark:iron_plate:1,20,STAINED_CLAY:12,15,STAINED_CLAY:15,5,AIR,7,IRON_BARS,12,CONCRETE:7,100)
RandomBlock(-8,16,-6,CONCRETE:7,60,quark:iron_plate:1,20,STAINED_CLAY:12,15,STAINED_CLAY:15,5,AIR,7,IRON_BARS,12,CONCRETE:7,100)
RandomBlock(-8,16,-5,CONCRETE:7,60,quark:iron_plate:1,20,STAINED_CLAY:12,15,STAINED_CLAY:15,5,AIR,7,IRON_BARS,12,CONCRETE:7,100)
RandomBlock(-8,16,-4,CONCRETE:7,60,quark:iron_plate:1,20,STAINED_CLAY:12,15,STAINED_CLAY:15,5,AIR,7,IRON_BARS,12,CONCRETE:7,100)
RandomBlock(-8,16,-3,CONCRETE:7,60,quark:iron_plate:1,20,STAINED_CLAY:12,15,STAINED_CLAY:15,5,AIR,7,IRON_BARS,12,CONCRETE:7,100)
RandomBlock(-8,16,-2,CONCRETE:7,60,quark:iron_plate:1,20,STAINED_CLAY:12,15,STAINED_CLAY:15,5,AIR,7,IRON_BARS,12,CONCRETE:7,100)
RandomBlock(-8,16,-1,CONCRETE:7,60,quark:iron_plate:1,20,STAINED_CLAY:12,15,STAINED_CLAY:15,5,AIR,7,IRON_BARS,12,CONCRETE:7,100)
RandomBlock(-8,16,0,CONCRETE:7,60,quark:iron_plate:1,20,STAINED_CLAY:12,15,STAINED_CLAY:15,5,AIR,7,IRON_BARS,12,CONCRETE:7,100)
RandomBlock(-8,16,1,CONCRETE:7,60,quark:iron_plate:1,20,STAINED_CLAY:12,15,STAINED_CLAY:15,5,AIR,7,IRON_BARS,12,CONCRETE:7,100)
RandomBlock(-8,16,2,CONCRETE:7,60,quark:iron_plate:1,20,STAINED_CLAY:12,15,STAINED_CLAY:15,5,AIR,7,IRON_BARS,12,CONCRETE:7,100)
RandomBlock(-8,16,3,CONCRETE:7,60,quark:iron_plate:1,20,STAINED_CLAY:12,15,STAINED_CLAY:15,5,AIR,7,IRON_BARS,12,CONCRETE:7,100)
RandomBlock(-8,16,4,CONCRETE:7,60,quark:iron_plate:1,20,STAINED_CLAY:12,15,STAINED_CLAY:15,5,AIR,7,IRON_BARS,12,CONCRETE:7,100)
RandomBlock(-8,16,5,CONCRETE:7,60,quark:iron_plate:1,20,STAINED_CLAY:12,15,STAINED_CLAY:15,5,AIR,7,IRON_BARS,12,CONCRETE:7,100)
RandomBlock(-8,16,6,CONCRETE:7,60,quark:iron_plate:1,20,STAINED_CLAY:12,15,STAINED_CLAY:15,5,AIR,7,IRON_BARS,12,CONCRETE:7,100)
RandomBlock(-8,16,7,CONCRETE:7,60,quark:iron_plate:1,20,STAINED_CLAY:12,15,STAINED_CLAY:15,5,AIR,7,IRON_BARS,12,CONCRETE:7,100)
RandomBlock(-8,16,8,CONCRETE:7,60,quark:iron_plate:1,20,STAINED_CLAY:12,15,STAINED_CLAY:15,5,AIR,7,IRON_BARS,12,CONCRETE:7,100)
Block(-8,17,-7,DOUBLE_STEP:0)
Block(-8,17,-6,DOUBLE_STEP:0)
Block(-8,17,-5,DOUBLE_STEP:0)
Block(-8,17,-4,DOUBLE_STEP:0)
Block(-8,17,-3,DOUBLE_STEP:0)
Block(-8,17,-2,DOUBLE_STEP:0)
Block(-8,17,-1,DOUBLE_STEP:0)
Block(-8,17,0,DOUBLE_STEP:0)
Block(-8,17,1,DOUBLE_STEP:0)
Block(-8,17,2,DOUBLE_STEP:0)
Block(-8,17,3,DOUBLE_STEP:0)
Block(-8,17,4,DOUBLE_STEP:0)
Block(-8,17,5,DOUBLE_STEP:0)
Block(-8,17,6,DOUBLE_STEP:0)
Block(-8,17,7,DOUBLE_STEP:0)
Block(-8,17,8,DOUBLE_STEP:0)
RandomBlock(-7,0,-7,CONCRETE:7,60,quark:iron_plate:1,20,STAINED_CLAY:12,15,STAINED_CLAY:15,5,AIR,7,IRON_BARS,12,CONCRETE:7,100)
RandomBlock(-7,0,-6,CONCRETE:7,60,quark:iron_plate:1,20,STAINED_CLAY:12,15,STAINED_CLAY:15,5,AIR,7,IRON_BARS,12,CONCRETE:7,100)
RandomBlock(-7,0,-5,CONCRETE:7,60,quark:iron_plate:1,20,STAINED_CLAY:12,15,STAINED_CLAY:15,5,AIR,7,IRON_BARS,12,CONCRETE:7,100)
RandomBlock(-7,0,-4,CONCRETE:7,60,quark:iron_plate:1,20,STAINED_CLAY:12,15,STAINED_CLAY:15,5,AIR,7,IRON_BARS,12,CONCRETE:7,100)
RandomBlock(-7,0,-3,CONCRETE:7,60,quark:iron_plate:1,20,STAINED_CLAY:12,15,STAINED_CLAY:15,5,AIR,7,IRON_BARS,12,CONCRETE:7,100)
RandomBlock(-7,0,-2,CONCRETE:7,60,quark:iron_plate:1,20,STAINED_CLAY:12,15,STAINED_CLAY:15,5,AIR,7,IRON_BARS,12,CONCRETE:7,100)
RandomBlock(-7,0,-1,CONCRETE:7,60,quark:iron_plate:1,20,STAINED_CLAY:12,15,STAINED_CLAY:15,5,AIR,7,IRON_BARS,12,CONCRETE:7,100)
RandomBlock(-7,0,0,CONCRETE:7,60,quark:iron_plate:1,20,STAINED_CLAY:12,15,STAINED_CLAY:15,5,AIR,7,IRON_BARS,12,CONCRETE:7,100)
RandomBlock(-7,0,1,CONCRETE:7,60,quark:iron_plate:1,20,STAINED_CLAY:12,15,STAINED_CLAY:15,5,AIR,7,IRON_BARS,12,CONCRETE:7,100)
RandomBlock(-7,0,2,CONCRETE:7,60,quark:iron_plate:1,20,STAINED_CLAY:12,15,STAINED_CLAY:15,5,AIR,7,IRON_BARS,12,CONCRETE:7,100)
RandomBlock(-7,0,3,CONCRETE:7,60,quark:iron_plate:1,20,STAINED_CLAY:12,15,STAINED_CLAY:15,5,AIR,7,IRON_BARS,12,CONCRETE:7,100)
RandomBlock(-7,0,4,CONCRETE:7,60,quark:iron_plate:1,20,STAINED_CLAY:12,15,STAINED_CLAY:15,5,AIR,7,IRON_BARS,12,CONCRETE:7,100)
RandomBlock(-7,0,5,CONCRETE:7,60,quark:iron_plate:1,20,STAINED_CLAY:12,15,STAINED_CLAY:15,5,AIR,7,IRON_BARS,12,CONCRETE:7,100)
RandomBlock(-7,0,6,CONCRETE:7,60,quark:iron_plate:1,20,STAINED_CLAY:12,15,STAINED_CLAY:15,5,AIR,7,IRON_BARS,12,CONCRETE:7,100)
RandomBlock(-7,0,7,CONCRETE:7,60,quark:iron_plate:1,20,STAINED_CLAY:12,15,STAINED_CLAY:15,5,AIR,7,IRON_BARS,12,CONCRETE:7,100)
RandomBlock(-7,0,8,CONCRETE:7,60,quark:iron_plate:1,20,STAINED_CLAY:12,15,STAINED_CLAY:15,5,AIR,7,IRON_BARS,12,CONCRETE:7,100)
RandomBlock(-7,1,-7,CONCRETE:7,60,quark:iron_plate:1,20,STAINED_CLAY:12,15,STAINED_CLAY:15,5,AIR,7,IRON_BARS,12,CONCRETE:7,100)
RandomBlock(-7,1,-6,CONCRETE:7,60,quark:iron_plate:1,20,STAINED_CLAY:12,15,STAINED_CLAY:15,5,AIR,7,IRON_BARS,12,CONCRETE:7,100)
RandomBlock(-7,1,-5,CONCRETE:7,60,quark:iron_plate:1,20,STAINED_CLAY:12,15,STAINED_CLAY:15,5,AIR,7,IRON_BARS,12,CONCRETE:7,100)
RandomBlock(-7,1,-4,CONCRETE:7,60,quark:iron_plate:1,20,STAINED_CLAY:12,15,STAINED_CLAY:15,5,AIR,7,IRON_BARS,12,CONCRETE:7,100)
RandomBlock(-7,1,-3,CONCRETE:7,60,quark:iron_plate:1,20,STAINED_CLAY:12,15,STAINED_CLAY:15,5,AIR,7,IRON_BARS,12,CONCRETE:7,100)
RandomBlock(-7,1,-2,CONCRETE:7,60,quark:iron_plate:1,20,STAINED_CLAY:12,15,STAINED_CLAY:15,5,AIR,7,IRON_BARS,12,CONCRETE:7,100)
RandomBlock(-7,1,-1,CONCRETE:7,60,quark:iron_plate:1,20,STAINED_CLAY:12,15,STAINED_CLAY:15,5,AIR,7,IRON_BARS,12,CONCRETE:7,100)
RandomBlock(-7,1,0,CONCRETE:7,60,quark:iron_plate:1,20,STAINED_CLAY:12,15,STAINED_CLAY:15,5,AIR,7,IRON_BARS,12,CONCRETE:7,100)
RandomBlock(-7,1,1,CONCRETE:7,60,quark:iron_plate:1,20,STAINED_CLAY:12,15,STAINED_CLAY:15,5,AIR,7,IRON_BARS,12,CONCRETE:7,100)
RandomBlock(-7,1,2,CONCRETE:7,60,quark:iron_plate:1,20,STAINED_CLAY:12,15,STAINED_CLAY:15,5,AIR,7,IRON_BARS,12,CONCRETE:7,100)
RandomBlock(-7,1,3,CONCRETE:7,60,quark:iron_plate:1,20,STAINED_CLAY:12,15,STAINED_CLAY:15,5,AIR,7,IRON_BARS,12,CONCRETE:7,100)
RandomBlock(-7,1,4,CONCRETE:7,60,quark:iron_plate:1,20,STAINED_CLAY:12,15,STAINED_CLAY:15,5,AIR,7,IRON_BARS,12,CONCRETE:7,100)
RandomBlock(-7,1,5,CONCRETE:7,60,quark:iron_plate:1,20,STAINED_CLAY:12,15,STAINED_CLAY:15,5,AIR,7,IRON_BARS,12,CONCRETE:7,100)
RandomBlock(-7,1,6,CONCRETE:7,60,quark:iron_plate:1,20,STAINED_CLAY:12,15,STAINED_CLAY:15,5,AIR,7,IRON_BARS,12,CONCRETE:7,100)
RandomBlock(-7,1,7,CONCRETE:7,60,quark:iron_plate:1,20,STAINED_CLAY:12,15,STAINED_CLAY:15,5,AIR,7,IRON_BARS,12,CONCRETE:7,100)
RandomBlock(-7,1,8,CONCRETE:7,60,quark:iron_plate:1,20,STAINED_CLAY:12,15,STAINED_CLAY:15,5,AIR,7,IRON_BARS,12,CONCRETE:7,100)
RandomBlock(-7,2,-7,CONCRETE:7,60,quark:iron_plate:1,20,STAINED_CLAY:12,15,STAINED_CLAY:15,5,AIR,7,IRON_BARS,12,CONCRETE:7,100)
RandomBlock(-7,2,-6,CONCRETE:7,60,quark:iron_plate:1,20,STAINED_CLAY:12,15,STAINED_CLAY:15,5,AIR,7,IRON_BARS,12,CONCRETE:7,100)
RandomBlock(-7,2,-5,CONCRETE:7,60,quark:iron_plate:1,20,STAINED_CLAY:12,15,STAINED_CLAY:15,5,AIR,7,IRON_BARS,12,CONCRETE:7,100)
RandomBlock(-7,2,-4,CONCRETE:7,60,quark:iron_plate:1,20,STAINED_CLAY:12,15,STAINED_CLAY:15,5,AIR,7,IRON_BARS,12,CONCRETE:7,100)
RandomBlock(-7,2,-3,CONCRETE:7,60,quark:iron_plate:1,20,STAINED_CLAY:12,15,STAINED_CLAY:15,5,AIR,7,IRON_BARS,12,CONCRETE:7,100)
RandomBlock(-7,2,-2,CONCRETE:7,60,quark:iron_plate:1,20,STAINED_CLAY:12,15,STAINED_CLAY:15,5,AIR,7,IRON_BARS,12,CONCRETE:7,100)
RandomBlock(-7,2,-1,CONCRETE:7,60,quark:iron_plate:1,20,STAINED_CLAY:12,15,STAINED_CLAY:15,5,AIR,7,IRON_BARS,12,CONCRETE:7,100)
RandomBlock(-7,2,0,CONCRETE:7,60,quark:iron_plate:1,20,STAINED_CLAY:12,15,STAINED_CLAY:15,5,AIR,7,IRON_BARS,12,CONCRETE:7,100)
RandomBlock(-7,2,1,CONCRETE:7,60,quark:iron_plate:1,20,STAINED_CLAY:12,15,STAINED_CLAY:15,5,AIR,7,IRON_BARS,12,CONCRETE:7,100)
RandomBlock(-7,2,2,CONCRETE:7,60,quark:iron_plate:1,20,STAINED_CLAY:12,15,STAINED_CLAY:15,5,AIR,7,IRON_BARS,12,CONCRETE:7,100)
RandomBlock(-7,2,3,CONCRETE:7,60,quark:iron_plate:1,20,STAINED_CLAY:12,15,STAINED_CLAY:15,5,AIR,7,IRON_BARS,12,CONCRETE:7,100)
RandomBlock(-7,2,4,CONCRETE:7,60,quark:iron_plate:1,20,STAINED_CLAY:12,15,STAINED_CLAY:15,5,AIR,7,IRON_BARS,12,CONCRETE:7,100)
RandomBlock(-7,2,5,CONCRETE:7,60,quark:iron_plate:1,20,STAINED_CLAY:12,15,STAINED_CLAY:15,5,AIR,7,IRON_BARS,12,CONCRETE:7,100)
RandomBlock(-7,2,6,CONCRETE:7,60,quark:iron_plate:1,20,STAINED_CLAY:12,15,STAINED_CLAY:15,5,AIR,7,IRON_BARS,12,CONCRETE:7,100)
RandomBlock(-7,2,7,CONCRETE:7,60,quark:iron_plate:1,20,STAINED_CLAY:12,15,STAINED_CLAY:15,5,AIR,7,IRON_BARS,12,CONCRETE:7,100)
RandomBlock(-7,2,8,CONCRETE:7,60,quark:iron_plate:1,20,STAINED_CLAY:12,15,STAINED_CLAY:15,5,AIR,7,IRON_BARS,12,CONCRETE:7,100)
RandomBlock(-7,3,-7,CONCRETE:7,60,quark:iron_plate:1,20,STAINED_CLAY:12,15,STAINED_CLAY:15,5,AIR,7,IRON_BARS,12,CONCRETE:7,100)
RandomBlock(-7,3,-6,CONCRETE:7,60,quark:iron_plate:1,20,STAINED_CLAY:12,15,STAINED_CLAY:15,5,AIR,7,IRON_BARS,12,CONCRETE:7,100)
RandomBlock(-7,3,-5,CONCRETE:7,60,quark:iron_plate:1,20,STAINED_CLAY:12,15,STAINED_CLAY:15,5,AIR,7,IRON_BARS,12,CONCRETE:7,100)
RandomBlock(-7,3,-4,CONCRETE:7,60,quark:iron_plate:1,20,STAINED_CLAY:12,15,STAINED_CLAY:15,5,AIR,7,IRON_BARS,12,CONCRETE:7,100)
RandomBlock(-7,3,-3,CONCRETE:7,60,quark:iron_plate:1,20,STAINED_CLAY:12,15,STAINED_CLAY:15,5,AIR,7,IRON_BARS,12,CONCRETE:7,100)
RandomBlock(-7,3,-2,CONCRETE:7,60,quark:iron_plate:1,20,STAINED_CLAY:12,15,STAINED_CLAY:15,5,AIR,7,IRON_BARS,12,CONCRETE:7,100)
RandomBlock(-7,3,-1,CONCRETE:7,60,quark:iron_plate:1,20,STAINED_CLAY:12,15,STAINED_CLAY:15,5,AIR,7,IRON_BARS,12,CONCRETE:7,100)
RandomBlock(-7,3,0,CONCRETE:7,60,quark:iron_plate:1,20,STAINED_CLAY:12,15,STAINED_CLAY:15,5,AIR,7,IRON_BARS,12,CONCRETE:7,100)
RandomBlock(-7,3,1,CONCRETE:7,60,quark:iron_plate:1,20,STAINED_CLAY:12,15,STAINED_CLAY:15,5,AIR,7,IRON_BARS,12,CONCRETE:7,100)
RandomBlock(-7,3,2,CONCRETE:7,60,quark:iron_plate:1,20,STAINED_CLAY:12,15,STAINED_CLAY:15,5,AIR,7,IRON_BARS,12,CONCRETE:7,100)
RandomBlock(-7,3,3,CONCRETE:7,60,quark:iron_plate:1,20,STAINED_CLAY:12,15,STAINED_CLAY:15,5,AIR,7,IRON_BARS,12,CONCRETE:7,100)
RandomBlock(-7,3,4,CONCRETE:7,60,quark:iron_plate:1,20,STAINED_CLAY:12,15,STAINED_CLAY:15,5,AIR,7,IRON_BARS,12,CONCRETE:7,100)
RandomBlock(-7,3,5,CONCRETE:7,60,quark:iron_plate:1,20,STAINED_CLAY:12,15,STAINED_CLAY:15,5,AIR,7,IRON_BARS,12,CONCRETE:7,100)
RandomBlock(-7,3,6,CONCRETE:7,60,quark:iron_plate:1,20,STAINED_CLAY:12,15,STAINED_CLAY:15,5,AIR,7,IRON_BARS,12,CONCRETE:7,100)
RandomBlock(-7,3,7,CONCRETE:7,60,quark:iron_plate:1,20,STAINED_CLAY:12,15,STAINED_CLAY:15,5,AIR,7,IRON_BARS,12,CONCRETE:7,100)
RandomBlock(-7,3,8,CONCRETE:7,60,quark:iron_plate:1,20,STAINED_CLAY:12,15,STAINED_CLAY:15,5,AIR,7,IRON_BARS,12,CONCRETE:7,100)
RandomBlock(-7,4,-7,CONCRETE:7,60,quark:iron_plate:1,20,STAINED_CLAY:12,15,STAINED_CLAY:15,5,AIR,7,IRON_BARS,12,CONCRETE:7,100)
RandomBlock(-7,4,-6,CONCRETE:7,60,quark:iron_plate:1,20,STAINED_CLAY:12,15,STAINED_CLAY:15,5,AIR,7,IRON_BARS,12,CONCRETE:7,100)
RandomBlock(-7,4,-5,CONCRETE:7,60,quark:iron_plate:1,20,STAINED_CLAY:12,15,STAINED_CLAY:15,5,AIR,7,IRON_BARS,12,CONCRETE:7,100)
RandomBlock(-7,4,-4,CONCRETE:7,60,quark:iron_plate:1,20,STAINED_CLAY:12,15,STAINED_CLAY:15,5,AIR,7,IRON_BARS,12,CONCRETE:7,100)
RandomBlock(-7,4,-3,CONCRETE:7,60,quark:iron_plate:1,20,STAINED_CLAY:12,15,STAINED_CLAY:15,5,AIR,7,IRON_BARS,12,CONCRETE:7,100)
RandomBlock(-7,4,-2,CONCRETE:7,60,quark:iron_plate:1,20,STAINED_CLAY:12,15,STAINED_CLAY:15,5,AIR,7,IRON_BARS,12,CONCRETE:7,100)
RandomBlock(-7,4,-1,CONCRETE:7,60,quark:iron_plate:1,20,STAINED_CLAY:12,15,STAINED_CLAY:15,5,AIR,7,IRON_BARS,12,CONCRETE:7,100)
RandomBlock(-7,4,0,CONCRETE:7,60,quark:iron_plate:1,20,STAINED_CLAY:12,15,STAINED_CLAY:15,5,AIR,7,IRON_BARS,12,CONCRETE:7,100)
RandomBlock(-7,4,1,CONCRETE:7,60,quark:iron_plate:1,20,STAINED_CLAY:12,15,STAINED_CLAY:15,5,AIR,7,IRON_BARS,12,CONCRETE:7,100)
RandomBlock(-7,4,2,CONCRETE:7,60,quark:iron_plate:1,20,STAINED_CLAY:12,15,STAINED_CLAY:15,5,AIR,7,IRON_BARS,12,CONCRETE:7,100)
RandomBlock(-7,4,3,CONCRETE:7,60,quark:iron_plate:1,20,STAINED_CLAY:12,15,STAINED_CLAY:15,5,AIR,7,IRON_BARS,12,CONCRETE:7,100)
RandomBlock(-7,4,4,CONCRETE:7,60,quark:iron_plate:1,20,STAINED_CLAY:12,15,STAINED_CLAY:15,5,AIR,7,IRON_BARS,12,CONCRETE:7,100)
RandomBlock(-7,4,5,CONCRETE:7,60,quark:iron_plate:1,20,STAINED_CLAY:12,15,STAINED_CLAY:15,5,AIR,7,IRON_BARS,12,CONCRETE:7,100)
RandomBlock(-7,4,6,CONCRETE:7,60,quark:iron_plate:1,20,STAINED_CLAY:12,15,STAINED_CLAY:15,5,AIR,7,IRON_BARS,12,CONCRETE:7,100)
RandomBlock(-7,4,7,CONCRETE:7,60,quark:iron_plate:1,20,STAINED_CLAY:12,15,STAINED_CLAY:15,5,AIR,7,IRON_BARS,12,CONCRETE:7,100)
RandomBlock(-7,4,8,CONCRETE:7,60,quark:iron_plate:1,20,STAINED_CLAY:12,15,STAINED_CLAY:15,5,AIR,7,IRON_BARS,12,CONCRETE:7,100)
RandomBlock(-7,5,-7,CONCRETE:7,60,quark:iron_plate:1,20,STAINED_CLAY:12,15,STAINED_CLAY:15,5,AIR,7,IRON_BARS,12,CONCRETE:7,100)
RandomBlock(-7,5,-6,CONCRETE:7,60,quark:iron_plate:1,20,STAINED_CLAY:12,15,STAINED_CLAY:15,5,AIR,7,IRON_BARS,12,CONCRETE:7,100)
RandomBlock(-7,5,-5,CONCRETE:7,60,quark:iron_plate:1,20,STAINED_CLAY:12,15,STAINED_CLAY:15,5,AIR,7,IRON_BARS,12,CONCRETE:7,100)
RandomBlock(-7,5,-4,CONCRETE:7,60,quark:iron_plate:1,20,STAINED_CLAY:12,15,STAINED_CLAY:15,5,AIR,7,IRON_BARS,12,CONCRETE:7,100)
RandomBlock(-7,5,-3,CONCRETE:7,60,quark:iron_plate:1,20,STAINED_CLAY:12,15,STAINED_CLAY:15,5,AIR,7,IRON_BARS,12,CONCRETE:7,100)
RandomBlock(-7,5,-2,CONCRETE:7,60,quark:iron_plate:1,20,STAINED_CLAY:12,15,STAINED_CLAY:15,5,AIR,7,IRON_BARS,12,CONCRETE:7,100)
RandomBlock(-7,5,-1,CONCRETE:7,60,quark:iron_plate:1,20,STAINED_CLAY:12,15,STAINED_CLAY:15,5,AIR,7,IRON_BARS,12,CONCRETE:7,100)
RandomBlock(-7,5,0,CONCRETE:7,60,quark:iron_plate:1,20,STAINED_CLAY:12,15,STAINED_CLAY:15,5,AIR,7,IRON_BARS,12,CONCRETE:7,100)
RandomBlock(-7,5,1,CONCRETE:7,60,quark:iron_plate:1,20,STAINED_CLAY:12,15,STAINED_CLAY:15,5,AIR,7,IRON_BARS,12,CONCRETE:7,100)
RandomBlock(-7,5,2,CONCRETE:7,60,quark:iron_plate:1,20,STAINED_CLAY:12,15,STAINED_CLAY:15,5,AIR,7,IRON_BARS,12,CONCRETE:7,100)
RandomBlock(-7,5,3,CONCRETE:7,60,quark:iron_plate:1,20,STAINED_CLAY:12,15,STAINED_CLAY:15,5,AIR,7,IRON_BARS,12,CONCRETE:7,100)
RandomBlock(-7,5,4,CONCRETE:7,60,quark:iron_plate:1,20,STAINED_CLAY:12,15,STAINED_CLAY:15,5,AIR,7,IRON_BARS,12,CONCRETE:7,100)
RandomBlock(-7,5,5,CONCRETE:7,60,quark:iron_plate:1,20,STAINED_CLAY:12,15,STAINED_CLAY:15,5,AIR,7,IRON_BARS,12,CONCRETE:7,100)
RandomBlock(-7,5,6,CONCRETE:7,60,quark:iron_plate:1,20,STAINED_CLAY:12,15,STAINED_CLAY:15,5,AIR,7,IRON_BARS,12,CONCRETE:7,100)
RandomBlock(-7,5,7,CONCRETE:7,60,quark:iron_plate:1,20,STAINED_CLAY:12,15,STAINED_CLAY:15,5,AIR,7,IRON_BARS,12,CONCRETE:7,100)
RandomBlock(-7,5,8,CONCRETE:7,60,quark:iron_plate:1,20,STAINED_CLAY:12,15,STAINED_CLAY:15,5,AIR,7,IRON_BARS,12,CONCRETE:7,100)
RandomBlock(-7,6,-7,CONCRETE:7,60,quark:iron_plate:1,20,STAINED_CLAY:12,15,STAINED_CLAY:15,5,AIR,7,IRON_BARS,12,CONCRETE:7,100)
RandomBlock(-7,6,-6,CONCRETE:7,60,quark:iron_plate:1,20,STAINED_CLAY:12,15,STAINED_CLAY:15,5,AIR,7,IRON_BARS,12,CONCRETE:7,100)
RandomBlock(-7,6,-5,CONCRETE:7,60,quark:iron_plate:1,20,STAINED_CLAY:12,15,STAINED_CLAY:15,5,AIR,7,IRON_BARS,12,CONCRETE:7,100)
RandomBlock(-7,6,-4,CONCRETE:7,60,quark:iron_plate:1,20,STAINED_CLAY:12,15,STAINED_CLAY:15,5,AIR,7,IRON_BARS,12,CONCRETE:7,100)
RandomBlock(-7,6,-3,CONCRETE:7,60,quark:iron_plate:1,20,STAINED_CLAY:12,15,STAINED_CLAY:15,5,AIR,7,IRON_BARS,12,CONCRETE:7,100)
RandomBlock(-7,6,-2,CONCRETE:7,60,quark:iron_plate:1,20,STAINED_CLAY:12,15,STAINED_CLAY:15,5,AIR,7,IRON_BARS,12,CONCRETE:7,100)
RandomBlock(-7,6,-1,CONCRETE:7,60,quark:iron_plate:1,20,STAINED_CLAY:12,15,STAINED_CLAY:15,5,AIR,7,IRON_BARS,12,CONCRETE:7,100)
RandomBlock(-7,6,0,CONCRETE:7,60,quark:iron_plate:1,20,STAINED_CLAY:12,15,STAINED_CLAY:15,5,AIR,7,IRON_BARS,12,CONCRETE:7,100)
RandomBlock(-7,6,1,CONCRETE:7,60,quark:iron_plate:1,20,STAINED_CLAY:12,15,STAINED_CLAY:15,5,AIR,7,IRON_BARS,12,CONCRETE:7,100)
RandomBlock(-7,6,2,CONCRETE:7,60,quark:iron_plate:1,20,STAINED_CLAY:12,15,STAINED_CLAY:15,5,AIR,7,IRON_BARS,12,CONCRETE:7,100)
RandomBlock(-7,6,3,CONCRETE:7,60,quark:iron_plate:1,20,STAINED_CLAY:12,15,STAINED_CLAY:15,5,AIR,7,IRON_BARS,12,CONCRETE:7,100)
RandomBlock(-7,6,4,CONCRETE:7,60,quark:iron_plate:1,20,STAINED_CLAY:12,15,STAINED_CLAY:15,5,AIR,7,IRON_BARS,12,CONCRETE:7,100)
RandomBlock(-7,6,5,CONCRETE:7,60,quark:iron_plate:1,20,STAINED_CLAY:12,15,STAINED_CLAY:15,5,AIR,7,IRON_BARS,12,CONCRETE:7,100)
RandomBlock(-7,6,6,CONCRETE:7,60,quark:iron_plate:1,20,STAINED_CLAY:12,15,STAINED_CLAY:15,5,AIR,7,IRON_BARS,12,CONCRETE:7,100)
RandomBlock(-7,6,7,CONCRETE:7,60,quark:iron_plate:1,20,STAINED_CLAY:12,15,STAINED_CLAY:15,5,AIR,7,IRON_BARS,12,CONCRETE:7,100)
RandomBlock(-7,6,8,CONCRETE:7,60,quark:iron_plate:1,20,STAINED_CLAY:12,15,STAINED_CLAY:15,5,AIR,7,IRON_BARS,12,CONCRETE:7,100)
RandomBlock(-7,7,-7,CONCRETE:7,60,quark:iron_plate:1,20,STAINED_CLAY:12,15,STAINED_CLAY:15,5,AIR,7,IRON_BARS,12,CONCRETE:7,100)
RandomBlock(-7,7,-6,CONCRETE:7,60,quark:iron_plate:1,20,STAINED_CLAY:12,15,STAINED_CLAY:15,5,AIR,7,IRON_BARS,12,CONCRETE:7,100)
RandomBlock(-7,7,-5,CONCRETE:7,60,quark:iron_plate:1,20,STAINED_CLAY:12,15,STAINED_CLAY:15,5,AIR,7,IRON_BARS,12,CONCRETE:7,100)
RandomBlock(-7,7,-4,CONCRETE:7,60,quark:iron_plate:1,20,STAINED_CLAY:12,15,STAINED_CLAY:15,5,AIR,7,IRON_BARS,12,CONCRETE:7,100)
RandomBlock(-7,7,-3,CONCRETE:7,60,quark:iron_plate:1,20,STAINED_CLAY:12,15,STAINED_CLAY:15,5,AIR,7,IRON_BARS,12,CONCRETE:7,100)
RandomBlock(-7,7,-2,CONCRETE:7,60,quark:iron_plate:1,20,STAINED_CLAY:12,15,STAINED_CLAY:15,5,AIR,7,IRON_BARS,12,CONCRETE:7,100)
RandomBlock(-7,7,-1,CONCRETE:7,60,quark:iron_plate:1,20,STAINED_CLAY:12,15,STAINED_CLAY:15,5,AIR,7,IRON_BARS,12,CONCRETE:7,100)
RandomBlock(-7,7,0,CONCRETE:7,60,quark:iron_plate:1,20,STAINED_CLAY:12,15,STAINED_CLAY:15,5,AIR,7,IRON_BARS,12,CONCRETE:7,100)
RandomBlock(-7,7,1,CONCRETE:7,60,quark:iron_plate:1,20,STAINED_CLAY:12,15,STAINED_CLAY:15,5,AIR,7,IRON_BARS,12,CONCRETE:7,100)
RandomBlock(-7,7,2,CONCRETE:7,60,quark:iron_plate:1,20,STAINED_CLAY:12,15,STAINED_CLAY:15,5,AIR,7,IRON_BARS,12,CONCRETE:7,100)
RandomBlock(-7,7,3,CONCRETE:7,60,quark:iron_plate:1,20,STAINED_CLAY:12,15,STAINED_CLAY:15,5,AIR,7,IRON_BARS,12,CONCRETE:7,100)
RandomBlock(-7,7,4,CONCRETE:7,60,quark:iron_plate:1,20,STAINED_CLAY:12,15,STAINED_CLAY:15,5,AIR,7,IRON_BARS,12,CONCRETE:7,100)
RandomBlock(-7,7,5,CONCRETE:7,60,quark:iron_plate:1,20,STAINED_CLAY:12,15,STAINED_CLAY:15,5,AIR,7,IRON_BARS,12,CONCRETE:7,100)
RandomBlock(-7,7,6,CONCRETE:7,60,quark:iron_plate:1,20,STAINED_CLAY:12,15,STAINED_CLAY:15,5,AIR,7,IRON_BARS,12,CONCRETE:7,100)
RandomBlock(-7,7,7,CONCRETE:7,60,quark:iron_plate:1,20,STAINED_CLAY:12,15,STAINED_CLAY:15,5,AIR,7,IRON_BARS,12,CONCRETE:7,100)
RandomBlock(-7,7,8,CONCRETE:7,60,quark:iron_plate:1,20,STAINED_CLAY:12,15,STAINED_CLAY:15,5,AIR,7,IRON_BARS,12,CONCRETE:7,100)
RandomBlock(-7,8,-7,CONCRETE:7,60,quark:iron_plate:1,20,STAINED_CLAY:12,15,STAINED_CLAY:15,5,AIR,7,IRON_BARS,12,CONCRETE:7,100)
RandomBlock(-7,8,-6,CONCRETE:7,60,quark:iron_plate:1,20,STAINED_CLAY:12,15,STAINED_CLAY:15,5,AIR,7,IRON_BARS,12,CONCRETE:7,100)
RandomBlock(-7,8,-5,CONCRETE:7,60,quark:iron_plate:1,20,STAINED_CLAY:12,15,STAINED_CLAY:15,5,AIR,7,IRON_BARS,12,CONCRETE:7,100)
RandomBlock(-7,8,-4,CONCRETE:7,60,quark:iron_plate:1,20,STAINED_CLAY:12,15,STAINED_CLAY:15,5,AIR,7,IRON_BARS,12,CONCRETE:7,100)
RandomBlock(-7,8,-3,CONCRETE:7,60,quark:iron_plate:1,20,STAINED_CLAY:12,15,STAINED_CLAY:15,5,AIR,7,IRON_BARS,12,CONCRETE:7,100)
RandomBlock(-7,8,-2,CONCRETE:7,60,quark:iron_plate:1,20,STAINED_CLAY:12,15,STAINED_CLAY:15,5,AIR,7,IRON_BARS,12,CONCRETE:7,100)
RandomBlock(-7,8,-1,CONCRETE:7,60,quark:iron_plate:1,20,STAINED_CLAY:12,15,STAINED_CLAY:15,5,AIR,7,IRON_BARS,12,CONCRETE:7,100)
RandomBlock(-7,8,0,CONCRETE:7,60,quark:iron_plate:1,20,STAINED_CLAY:12,15,STAINED_CLAY:15,5,AIR,7,IRON_BARS,12,CONCRETE:7,100)
RandomBlock(-7,8,1,CONCRETE:7,60,quark:iron_plate:1,20,STAINED_CLAY:12,15,STAINED_CLAY:15,5,AIR,7,IRON_BARS,12,CONCRETE:7,100)
RandomBlock(-7,8,2,CONCRETE:7,60,quark:iron_plate:1,20,STAINED_CLAY:12,15,STAINED_CLAY:15,5,AIR,7,IRON_BARS,12,CONCRETE:7,100)
RandomBlock(-7,8,3,CONCRETE:7,60,quark:iron_plate:1,20,STAINED_CLAY:12,15,STAINED_CLAY:15,5,AIR,7,IRON_BARS,12,CONCRETE:7,100)
RandomBlock(-7,8,4,CONCRETE:7,60,quark:iron_plate:1,20,STAINED_CLAY:12,15,STAINED_CLAY:15,5,AIR,7,IRON_BARS,12,CONCRETE:7,100)
RandomBlock(-7,8,5,CONCRETE:7,60,quark:iron_plate:1,20,STAINED_CLAY:12,15,STAINED_CLAY:15,5,AIR,7,IRON_BARS,12,CONCRETE:7,100)
RandomBlock(-7,8,6,CONCRETE:7,60,quark:iron_plate:1,20,STAINED_CLAY:12,15,STAINED_CLAY:15,5,AIR,7,IRON_BARS,12,CONCRETE:7,100)
RandomBlock(-7,8,7,CONCRETE:7,60,quark:iron_plate:1,20,STAINED_CLAY:12,15,STAINED_CLAY:15,5,AIR,7,IRON_BARS,12,CONCRETE:7,100)
RandomBlock(-7,8,8,CONCRETE:7,60,quark:iron_plate:1,20,STAINED_CLAY:12,15,STAINED_CLAY:15,5,AIR,7,IRON_BARS,12,CONCRETE:7,100)
RandomBlock(-7,9,-7,CONCRETE:7,60,quark:iron_plate:1,20,STAINED_CLAY:12,15,STAINED_CLAY:15,5,AIR,7,IRON_BARS,12,CONCRETE:7,100)
RandomBlock(-7,9,-6,CONCRETE:7,60,quark:iron_plate:1,20,STAINED_CLAY:12,15,STAINED_CLAY:15,5,AIR,7,IRON_BARS,12,CONCRETE:7,100)
RandomBlock(-7,9,-5,CONCRETE:7,60,quark:iron_plate:1,20,STAINED_CLAY:12,15,STAINED_CLAY:15,5,AIR,7,IRON_BARS,12,CONCRETE:7,100)
RandomBlock(-7,9,-4,CONCRETE:7,60,quark:iron_plate:1,20,STAINED_CLAY:12,15,STAINED_CLAY:15,5,AIR,7,IRON_BARS,12,CONCRETE:7,100)
RandomBlock(-7,9,-3,CONCRETE:7,60,quark:iron_plate:1,20,STAINED_CLAY:12,15,STAINED_CLAY:15,5,AIR,7,IRON_BARS,12,CONCRETE:7,100)
RandomBlock(-7,9,-2,CONCRETE:7,60,quark:iron_plate:1,20,STAINED_CLAY:12,15,STAINED_CLAY:15,5,AIR,7,IRON_BARS,12,CONCRETE:7,100)
RandomBlock(-7,9,-1,CONCRETE:7,60,quark:iron_plate:1,20,STAINED_CLAY:12,15,STAINED_CLAY:15,5,AIR,7,IRON_BARS,12,CONCRETE:7,100)
RandomBlock(-7,9,0,CONCRETE:7,60,quark:iron_plate:1,20,STAINED_CLAY:12,15,STAINED_CLAY:15,5,AIR,7,IRON_BARS,12,CONCRETE:7,100)
RandomBlock(-7,9,1,CONCRETE:7,60,quark:iron_plate:1,20,STAINED_CLAY:12,15,STAINED_CLAY:15,5,AIR,7,IRON_BARS,12,CONCRETE:7,100)
RandomBlock(-7,9,2,CONCRETE:7,60,quark:iron_plate:1,20,STAINED_CLAY:12,15,STAINED_CLAY:15,5,AIR,7,IRON_BARS,12,CONCRETE:7,100)
RandomBlock(-7,9,3,CONCRETE:7,60,quark:iron_plate:1,20,STAINED_CLAY:12,15,STAINED_CLAY:15,5,AIR,7,IRON_BARS,12,CONCRETE:7,100)
RandomBlock(-7,9,4,CONCRETE:7,60,quark:iron_plate:1,20,STAINED_CLAY:12,15,STAINED_CLAY:15,5,AIR,7,IRON_BARS,12,CONCRETE:7,100)
RandomBlock(-7,9,5,CONCRETE:7,60,quark:iron_plate:1,20,STAINED_CLAY:12,15,STAINED_CLAY:15,5,AIR,7,IRON_BARS,12,CONCRETE:7,100)
RandomBlock(-7,9,6,CONCRETE:7,60,quark:iron_plate:1,20,STAINED_CLAY:12,15,STAINED_CLAY:15,5,AIR,7,IRON_BARS,12,CONCRETE:7,100)
RandomBlock(-7,9,7,CONCRETE:7,60,quark:iron_plate:1,20,STAINED_CLAY:12,15,STAINED_CLAY:15,5,AIR,7,IRON_BARS,12,CONCRETE:7,100)
RandomBlock(-7,9,8,CONCRETE:7,60,quark:iron_plate:1,20,STAINED_CLAY:12,15,STAINED_CLAY:15,5,AIR,7,IRON_BARS,12,CONCRETE:7,100)
RandomBlock(-7,10,-7,CONCRETE:7,60,quark:iron_plate:1,20,STAINED_CLAY:12,15,STAINED_CLAY:15,5,AIR,7,IRON_BARS,12,CONCRETE:7,100)
RandomBlock(-7,10,-6,CONCRETE:7,60,quark:iron_plate:1,20,STAINED_CLAY:12,15,STAINED_CLAY:15,5,AIR,7,IRON_BARS,12,CONCRETE:7,100)
RandomBlock(-7,10,-5,CONCRETE:7,60,quark:iron_plate:1,20,STAINED_CLAY:12,15,STAINED_CLAY:15,5,AIR,7,IRON_BARS,12,CONCRETE:7,100)
RandomBlock(-7,10,-4,CONCRETE:7,60,quark:iron_plate:1,20,STAINED_CLAY:12,15,STAINED_CLAY:15,5,AIR,7,IRON_BARS,12,CONCRETE:7,100)
RandomBlock(-7,10,-3,CONCRETE:7,60,quark:iron_plate:1,20,STAINED_CLAY:12,15,STAINED_CLAY:15,5,AIR,7,IRON_BARS,12,CONCRETE:7,100)
RandomBlock(-7,10,-2,CONCRETE:7,60,quark:iron_plate:1,20,STAINED_CLAY:12,15,STAINED_CLAY:15,5,AIR,7,IRON_BARS,12,CONCRETE:7,100)
RandomBlock(-7,10,-1,CONCRETE:7,60,quark:iron_plate:1,20,STAINED_CLAY:12,15,STAINED_CLAY:15,5,AIR,7,IRON_BARS,12,CONCRETE:7,100)
RandomBlock(-7,10,0,CONCRETE:7,60,quark:iron_plate:1,20,STAINED_CLAY:12,15,STAINED_CLAY:15,5,AIR,7,IRON_BARS,12,CONCRETE:7,100)
RandomBlock(-7,10,1,CONCRETE:7,60,quark:iron_plate:1,20,STAINED_CLAY:12,15,STAINED_CLAY:15,5,AIR,7,IRON_BARS,12,CONCRETE:7,100)
RandomBlock(-7,10,2,CONCRETE:7,60,quark:iron_plate:1,20,STAINED_CLAY:12,15,STAINED_CLAY:15,5,AIR,7,IRON_BARS,12,CONCRETE:7,100)
RandomBlock(-7,10,3,CONCRETE:7,60,quark:iron_plate:1,20,STAINED_CLAY:12,15,STAINED_CLAY:15,5,AIR,7,IRON_BARS,12,CONCRETE:7,100)
RandomBlock(-7,10,4,CONCRETE:7,60,quark:iron_plate:1,20,STAINED_CLAY:12,15,STAINED_CLAY:15,5,AIR,7,IRON_BARS,12,CONCRETE:7,100)
RandomBlock(-7,10,5,CONCRETE:7,60,quark:iron_plate:1,20,STAINED_CLAY:12,15,STAINED_CLAY:15,5,AIR,7,IRON_BARS,12,CONCRETE:7,100)
RandomBlock(-7,10,6,CONCRETE:7,60,quark:iron_plate:1,20,STAINED_CLAY:12,15,STAINED_CLAY:15,5,AIR,7,IRON_BARS,12,CONCRETE:7,100)
RandomBlock(-7,10,7,CONCRETE:7,60,quark:iron_plate:1,20,STAINED_CLAY:12,15,STAINED_CLAY:15,5,AIR,7,IRON_BARS,12,CONCRETE:7,100)
RandomBlock(-7,10,8,CONCRETE:7,60,quark:iron_plate:1,20,STAINED_CLAY:12,15,STAINED_CLAY:15,5,AIR,7,IRON_BARS,12,CONCRETE:7,100)
RandomBlock(-7,11,-7,CONCRETE:7,60,quark:iron_plate:1,20,STAINED_CLAY:12,15,STAINED_CLAY:15,5,AIR,7,IRON_BARS,12,CONCRETE:7,100)
RandomBlock(-7,11,-6,CONCRETE:7,60,quark:iron_plate:1,20,STAINED_CLAY:12,15,STAINED_CLAY:15,5,AIR,7,IRON_BARS,12,CONCRETE:7,100)
RandomBlock(-7,11,-5,CONCRETE:7,60,quark:iron_plate:1,20,STAINED_CLAY:12,15,STAINED_CLAY:15,5,AIR,7,IRON_BARS,12,CONCRETE:7,100)
RandomBlock(-7,11,-4,CONCRETE:7,60,quark:iron_plate:1,20,STAINED_CLAY:12,15,STAINED_CLAY:15,5,AIR,7,IRON_BARS,12,CONCRETE:7,100)
RandomBlock(-7,11,-3,CONCRETE:7,60,quark:iron_plate:1,20,STAINED_CLAY:12,15,STAINED_CLAY:15,5,AIR,7,IRON_BARS,12,CONCRETE:7,100)
RandomBlock(-7,11,-2,CONCRETE:7,60,quark:iron_plate:1,20,STAINED_CLAY:12,15,STAINED_CLAY:15,5,AIR,7,IRON_BARS,12,CONCRETE:7,100)
RandomBlock(-7,11,-1,CONCRETE:7,60,quark:iron_plate:1,20,STAINED_CLAY:12,15,STAINED_CLAY:15,5,AIR,7,IRON_BARS,12,CONCRETE:7,100)
RandomBlock(-7,11,0,CONCRETE:7,60,quark:iron_plate:1,20,STAINED_CLAY:12,15,STAINED_CLAY:15,5,AIR,7,IRON_BARS,12,CONCRETE:7,100)
RandomBlock(-7,11,1,CONCRETE:7,60,quark:iron_plate:1,20,STAINED_CLAY:12,15,STAINED_CLAY:15,5,AIR,7,IRON_BARS,12,CONCRETE:7,100)
RandomBlock(-7,11,2,CONCRETE:7,60,quark:iron_plate:1,20,STAINED_CLAY:12,15,STAINED_CLAY:15,5,AIR,7,IRON_BARS,12,CONCRETE:7,100)
RandomBlock(-7,11,3,CONCRETE:7,60,quark:iron_plate:1,20,STAINED_CLAY:12,15,STAINED_CLAY:15,5,AIR,7,IRON_BARS,12,CONCRETE:7,100)
RandomBlock(-7,11,4,CONCRETE:7,60,quark:iron_plate:1,20,STAINED_CLAY:12,15,STAINED_CLAY:15,5,AIR,7,IRON_BARS,12,CONCRETE:7,100)
RandomBlock(-7,11,5,CONCRETE:7,60,quark:iron_plate:1,20,STAINED_CLAY:12,15,STAINED_CLAY:15,5,AIR,7,IRON_BARS,12,CONCRETE:7,100)
RandomBlock(-7,11,6,CONCRETE:7,60,quark:iron_plate:1,20,STAINED_CLAY:12,15,STAINED_CLAY:15,5,AIR,7,IRON_BARS,12,CONCRETE:7,100)
RandomBlock(-7,11,7,CONCRETE:7,60,quark:iron_plate:1,20,STAINED_CLAY:12,15,STAINED_CLAY:15,5,AIR,7,IRON_BARS,12,CONCRETE:7,100)
RandomBlock(-7,11,8,CONCRETE:7,60,quark:iron_plate:1,20,STAINED_CLAY:12,15,STAINED_CLAY:15,5,AIR,7,IRON_BARS,12,CONCRETE:7,100)
RandomBlock(-7,12,-7,CONCRETE:7,60,quark:iron_plate:1,20,STAINED_CLAY:12,15,STAINED_CLAY:15,5,AIR,7,IRON_BARS,12,CONCRETE:7,100)
RandomBlock(-7,12,-6,CONCRETE:7,60,quark:iron_plate:1,20,STAINED_CLAY:12,15,STAINED_CLAY:15,5,AIR,7,IRON_BARS,12,CONCRETE:7,100)
RandomBlock(-7,12,-5,CONCRETE:7,60,quark:iron_plate:1,20,STAINED_CLAY:12,15,STAINED_CLAY:15,5,AIR,7,IRON_BARS,12,CONCRETE:7,100)
RandomBlock(-7,12,-4,CONCRETE:7,60,quark:iron_plate:1,20,STAINED_CLAY:12,15,STAINED_CLAY:15,5,AIR,7,IRON_BARS,12,CONCRETE:7,100)
RandomBlock(-7,12,-3,CONCRETE:7,60,quark:iron_plate:1,20,STAINED_CLAY:12,15,STAINED_CLAY:15,5,AIR,7,IRON_BARS,12,CONCRETE:7,100)
RandomBlock(-7,12,-2,CONCRETE:7,60,quark:iron_plate:1,20,STAINED_CLAY:12,15,STAINED_CLAY:15,5,AIR,7,IRON_BARS,12,CONCRETE:7,100)
RandomBlock(-7,12,-1,CONCRETE:7,60,quark:iron_plate:1,20,STAINED_CLAY:12,15,STAINED_CLAY:15,5,AIR,7,IRON_BARS,12,CONCRETE:7,100)
RandomBlock(-7,12,0,CONCRETE:7,60,quark:iron_plate:1,20,STAINED_CLAY:12,15,STAINED_CLAY:15,5,AIR,7,IRON_BARS,12,CONCRETE:7,100)
RandomBlock(-7,12,1,CONCRETE:7,60,quark:iron_plate:1,20,STAINED_CLAY:12,15,STAINED_CLAY:15,5,AIR,7,IRON_BARS,12,CONCRETE:7,100)
RandomBlock(-7,12,2,CONCRETE:7,60,quark:iron_plate:1,20,STAINED_CLAY:12,15,STAINED_CLAY:15,5,AIR,7,IRON_BARS,12,CONCRETE:7,100)
RandomBlock(-7,12,3,CONCRETE:7,60,quark:iron_plate:1,20,STAINED_CLAY:12,15,STAINED_CLAY:15,5,AIR,7,IRON_BARS,12,CONCRETE:7,100)
RandomBlock(-7,12,4,CONCRETE:7,60,quark:iron_plate:1,20,STAINED_CLAY:12,15,STAINED_CLAY:15,5,AIR,7,IRON_BARS,12,CONCRETE:7,100)
RandomBlock(-7,12,5,CONCRETE:7,60,quark:iron_plate:1,20,STAINED_CLAY:12,15,STAINED_CLAY:15,5,AIR,7,IRON_BARS,12,CONCRETE:7,100)
RandomBlock(-7,12,6,CONCRETE:7,60,quark:iron_plate:1,20,STAINED_CLAY:12,15,STAINED_CLAY:15,5,AIR,7,IRON_BARS,12,CONCRETE:7,100)
RandomBlock(-7,12,7,CONCRETE:7,60,quark:iron_plate:1,20,STAINED_CLAY:12,15,STAINED_CLAY:15,5,AIR,7,IRON_BARS,12,CONCRETE:7,100)
RandomBlock(-7,12,8,CONCRETE:7,60,quark:iron_plate:1,20,STAINED_CLAY:12,15,STAINED_CLAY:15,5,AIR,7,IRON_BARS,12,CONCRETE:7,100)
RandomBlock(-7,13,-7,CONCRETE:7,60,quark:iron_plate:1,20,STAINED_CLAY:12,15,STAINED_CLAY:15,5,AIR,7,IRON_BARS,12,CONCRETE:7,100)
RandomBlock(-7,13,-6,CONCRETE:7,60,quark:iron_plate:1,20,STAINED_CLAY:12,15,STAINED_CLAY:15,5,AIR,7,IRON_BARS,12,CONCRETE:7,100)
RandomBlock(-7,13,-5,CONCRETE:7,60,quark:iron_plate:1,20,STAINED_CLAY:12,15,STAINED_CLAY:15,5,AIR,7,IRON_BARS,12,CONCRETE:7,100)
RandomBlock(-7,13,-4,CONCRETE:7,60,quark:iron_plate:1,20,STAINED_CLAY:12,15,STAINED_CLAY:15,5,AIR,7,IRON_BARS,12,CONCRETE:7,100)
RandomBlock(-7,13,-3,CONCRETE:7,60,quark:iron_plate:1,20,STAINED_CLAY:12,15,STAINED_CLAY:15,5,AIR,7,IRON_BARS,12,CONCRETE:7,100)
RandomBlock(-7,13,-2,CONCRETE:7,60,quark:iron_plate:1,20,STAINED_CLAY:12,15,STAINED_CLAY:15,5,AIR,7,IRON_BARS,12,CONCRETE:7,100)
RandomBlock(-7,13,-1,CONCRETE:7,60,quark:iron_plate:1,20,STAINED_CLAY:12,15,STAINED_CLAY:15,5,AIR,7,IRON_BARS,12,CONCRETE:7,100)
RandomBlock(-7,13,0,CONCRETE:7,60,quark:iron_plate:1,20,STAINED_CLAY:12,15,STAINED_CLAY:15,5,AIR,7,IRON_BARS,12,CONCRETE:7,100)
RandomBlock(-7,13,1,CONCRETE:7,60,quark:iron_plate:1,20,STAINED_CLAY:12,15,STAINED_CLAY:15,5,AIR,7,IRON_BARS,12,CONCRETE:7,100)
RandomBlock(-7,13,2,CONCRETE:7,60,quark:iron_plate:1,20,STAINED_CLAY:12,15,STAINED_CLAY:15,5,AIR,7,IRON_BARS,12,CONCRETE:7,100)
RandomBlock(-7,13,3,CONCRETE:7,60,quark:iron_plate:1,20,STAINED_CLAY:12,15,STAINED_CLAY:15,5,AIR,7,IRON_BARS,12,CONCRETE:7,100)
RandomBlock(-7,13,4,CONCRETE:7,60,quark:iron_plate:1,20,STAINED_CLAY:12,15,STAINED_CLAY:15,5,AIR,7,IRON_BARS,12,CONCRETE:7,100)
RandomBlock(-7,13,5,CONCRETE:7,60,quark:iron_plate:1,20,STAINED_CLAY:12,15,STAINED_CLAY:15,5,AIR,7,IRON_BARS,12,CONCRETE:7,100)
RandomBlock(-7,13,6,CONCRETE:7,60,quark:iron_plate:1,20,STAINED_CLAY:12,15,STAINED_CLAY:15,5,AIR,7,IRON_BARS,12,CONCRETE:7,100)
RandomBlock(-7,13,7,CONCRETE:7,60,quark:iron_plate:1,20,STAINED_CLAY:12,15,STAINED_CLAY:15,5,AIR,7,IRON_BARS,12,CONCRETE:7,100)
RandomBlock(-7,13,8,CONCRETE:7,60,quark:iron_plate:1,20,STAINED_CLAY:12,15,STAINED_CLAY:15,5,AIR,7,IRON_BARS,12,CONCRETE:7,100)
Block(-7,14,-7,BOOKSHELF:0)
Block(-7,14,-6,BOOKSHELF:0)
RandomBlock(-7,14,-5,CONCRETE:7,60,quark:iron_plate:1,20,STAINED_CLAY:12,15,STAINED_CLAY:15,5,AIR,7,IRON_BARS,12,CONCRETE:7,100)
Block(-7,14,-4,BOOKSHELF:0)
Block(-7,14,-3,AIR:0)
Block(-7,14,-2,QUARTZ_STAIRS:6)
RandomBlock(-7,14,-1,CONCRETE:7,60,quark:iron_plate:1,20,STAINED_CLAY:12,15,STAINED_CLAY:15,5,AIR,7,IRON_BARS,12,CONCRETE:7,100)
Block(-7,14,0,QUARTZ_STAIRS:7)
Block(-7,14,1,AIR:0)
RandomBlock(-7,14,2,AIR,90,IRON_TRAPDOOR:8,100)
RandomBlock(-7,14,3,CONCRETE:7,60,quark:iron_plate:1,20,STAINED_CLAY:12,15,STAINED_CLAY:15,5,AIR,7,IRON_BARS,12,CONCRETE:7,100)
RandomBlock(-7,14,4,CONCRETE:7,60,quark:iron_plate:1,20,STAINED_CLAY:12,15,STAINED_CLAY:15,5,AIR,7,IRON_BARS,12,CONCRETE:7,100)
RandomBlock(-7,14,5,CONCRETE:7,60,quark:iron_plate:1,20,STAINED_CLAY:12,15,STAINED_CLAY:15,5,AIR,7,IRON_BARS,12,CONCRETE:7,100)
RandomBlock(-7,14,6,CONCRETE:7,60,quark:iron_plate:1,20,STAINED_CLAY:12,15,STAINED_CLAY:15,5,AIR,7,IRON_BARS,12,CONCRETE:7,100)
RandomBlock(-7,14,7,CONCRETE:7,60,quark:iron_plate:1,20,STAINED_CLAY:12,15,STAINED_CLAY:15,5,AIR,7,IRON_BARS,12,CONCRETE:7,100)
RandomBlock(-7,14,8,CONCRETE:7,60,quark:iron_plate:1,20,STAINED_CLAY:12,15,STAINED_CLAY:15,5,AIR,7,IRON_BARS,12,CONCRETE:7,100)
Block(-7,15,-7,BOOKSHELF:0)
Block(-7,15,-6,BOOKSHELF:0)
RandomBlock(-7,15,-5,CONCRETE:7,60,quark:iron_plate:1,20,STAINED_CLAY:12,15,STAINED_CLAY:15,5,AIR,7,IRON_BARS,12,CONCRETE:7,100)
Block(-7,15,-4,BOOKSHELF:0)
Block(-7,15,-3,AIR:0)
Block(-7,15,-2,QUARTZ_STAIRS:6)
RandomBlock(-7,15,-1,CONCRETE:7,60,quark:iron_plate:1,20,STAINED_CLAY:12,15,STAINED_CLAY:15,5,AIR,7,IRON_BARS,12,CONCRETE:7,100)
Block(-7,15,0,QUARTZ_STAIRS:7)
Block(-7,15,1,AIR:0)
#RandomBlock(-7,15,2,AIR:0,30,CHEST:5,../../../../../Chests/Loot/manhunt_urban_junk.nbt,10,CHEST:5,../../../../../Chests/Loot/manhunt_infected_cache.nbt,5,CHEST:5,../../../../../Chests/Loot/manhunt_urban_junk.nbt,65,CHEST:5,../../../../../Chests/Loot/manhunt_urban_junk.nbt,20,CHEST:5,../../../../../Chests/Loot/manhunt_residential_common.nbt,5,CHEST:5,../../../../../Chests/Loot/manhunt_residential_useful.nbt,3,CHEST:5,../../../../../Chests/Loot/manhunt_human_strategic_cache.nbt,1,CHEST:5,../../../../../Chests/Loot/manhunt_urban_junk.nbt,100)
RandomBlock(-7,15,3,CONCRETE:7,60,quark:iron_plate:1,20,STAINED_CLAY:12,15,STAINED_CLAY:15,5,AIR,7,IRON_BARS,12,CONCRETE:7,100)
RandomBlock(-7,15,4,CONCRETE:7,60,quark:iron_plate:1,20,STAINED_CLAY:12,15,STAINED_CLAY:15,5,AIR,7,IRON_BARS,12,CONCRETE:7,100)
RandomBlock(-7,15,5,CONCRETE:7,60,quark:iron_plate:1,20,STAINED_CLAY:12,15,STAINED_CLAY:15,5,AIR,7,IRON_BARS,12,CONCRETE:7,100)
RandomBlock(-7,15,6,CONCRETE:7,60,quark:iron_plate:1,20,STAINED_CLAY:12,15,STAINED_CLAY:15,5,AIR,7,IRON_BARS,12,CONCRETE:7,100)
RandomBlock(-7,15,7,CONCRETE:7,60,quark:iron_plate:1,20,STAINED_CLAY:12,15,STAINED_CLAY:15,5,AIR,7,IRON_BARS,12,CONCRETE:7,100)
RandomBlock(-7,15,8,CONCRETE:7,60,quark:iron_plate:1,20,STAINED_CLAY:12,15,STAINED_CLAY:15,5,AIR,7,IRON_BARS,12,CONCRETE:7,100)
Block(-7,16,-7,STEP:8)
Block(-7,16,-6,STEP:8)
RandomBlock(-7,16,-5,CONCRETE:7,60,quark:iron_plate:1,20,STAINED_CLAY:12,15,STAINED_CLAY:15,5,AIR,7,IRON_BARS,12,CONCRETE:7,100)
Block(-7,16,-4,STEP:8)
Block(-7,16,-3,STEP:8)
Block(-7,16,-2,STEP:8)
RandomBlock(-7,16,-1,CONCRETE:7,60,quark:iron_plate:1,20,STAINED_CLAY:12,15,STAINED_CLAY:15,5,AIR,7,IRON_BARS,12,CONCRETE:7,100)
Block(-7,16,0,STEP:8)
Block(-7,16,1,STEP:8)
Block(-7,16,2,STEP:8)
RandomBlock(-7,16,3,CONCRETE:7,60,quark:iron_plate:1,20,STAINED_CLAY:12,15,STAINED_CLAY:15,5,AIR,7,IRON_BARS,12,CONCRETE:7,100)
RandomBlock(-7,16,4,CONCRETE:7,60,quark:iron_plate:1,20,STAINED_CLAY:12,15,STAINED_CLAY:15,5,AIR,7,IRON_BARS,12,CONCRETE:7,100)
RandomBlock(-7,16,5,CONCRETE:7,60,quark:iron_plate:1,20,STAINED_CLAY:12,15,STAINED_CLAY:15,5,AIR,7,IRON_BARS,12,CONCRETE:7,100)
RandomBlock(-7,16,6,CONCRETE:7,60,quark:iron_plate:1,20,STAINED_CLAY:12,15,STAINED_CLAY:15,5,AIR,7,IRON_BARS,12,CONCRETE:7,100)
RandomBlock(-7,16,7,CONCRETE:7,60,quark:iron_plate:1,20,STAINED_CLAY:12,15,STAINED_CLAY:15,5,AIR,7,IRON_BARS,12,CONCRETE:7,100)
RandomBlock(-7,16,8,CONCRETE:7,60,quark:iron_plate:1,20,STAINED_CLAY:12,15,STAINED_CLAY:15,5,AIR,7,IRON_BARS,12,CONCRETE:7,100)
RandomBlock(-7,17,-7,CONCRETE:7,60,quark:iron_plate:1,20,STAINED_CLAY:12,15,STAINED_CLAY:15,5,AIR,7,IRON_BARS,12,CONCRETE:7,100)
RandomBlock(-7,17,-6,CONCRETE:7,60,quark:iron_plate:1,20,STAINED_CLAY:12,15,STAINED_CLAY:15,5,AIR,7,IRON_BARS,12,CONCRETE:7,100)
RandomBlock(-7,17,-5,CONCRETE:7,60,quark:iron_plate:1,20,STAINED_CLAY:12,15,STAINED_CLAY:15,5,AIR,7,IRON_BARS,12,CONCRETE:7,100)
RandomBlock(-7,17,-4,CONCRETE:7,60,quark:iron_plate:1,20,STAINED_CLAY:12,15,STAINED_CLAY:15,5,AIR,7,IRON_BARS,12,CONCRETE:7,100)
RandomBlock(-7,17,-3,CONCRETE:7,60,quark:iron_plate:1,20,STAINED_CLAY:12,15,STAINED_CLAY:15,5,AIR,7,IRON_BARS,12,CONCRETE:7,100)
RandomBlock(-7,17,-2,CONCRETE:7,60,quark:iron_plate:1,20,STAINED_CLAY:12,15,STAINED_CLAY:15,5,AIR,7,IRON_BARS,12,CONCRETE:7,100)
Block(-7,17,-1,SMOOTH_BRICK:0)
Block(-7,17,0,SMOOTH_BRICK:0)
Block(-7,17,1,SMOOTH_BRICK:0)
Block(-7,17,2,SMOOTH_BRICK:0)
Block(-7,17,3,SMOOTH_BRICK:0)
Block(-7,17,4,STAINED_CLAY:9)
Block(-7,17,5,STAINED_CLAY:9)
Block(-7,17,6,STAINED_CLAY:9)
Block(-7,17,7,SMOOTH_BRICK:0)
Block(-7,17,8,DOUBLE_STEP:0)
RandomBlock(-7,18,-7,CONCRETE:7,60,quark:iron_plate:1,20,STAINED_CLAY:12,15,STAINED_CLAY:15,5,AIR,7,IRON_BARS,12,CONCRETE:7,100)
RandomBlock(-7,18,-6,CONCRETE:7,60,quark:iron_plate:1,20,STAINED_CLAY:12,15,STAINED_CLAY:15,5,AIR,7,IRON_BARS,12,CONCRETE:7,100)
RandomBlock(-7,18,-5,CONCRETE:7,60,quark:iron_plate:1,20,STAINED_CLAY:12,15,STAINED_CLAY:15,5,AIR,7,IRON_BARS,12,CONCRETE:7,100)
RandomBlock(-7,18,-4,CONCRETE:7,60,quark:iron_plate:1,20,STAINED_CLAY:12,15,STAINED_CLAY:15,5,AIR,7,IRON_BARS,12,CONCRETE:7,100)
RandomBlock(-7,18,-3,CONCRETE:7,60,quark:iron_plate:1,20,STAINED_CLAY:12,15,STAINED_CLAY:15,5,AIR,7,IRON_BARS,12,CONCRETE:7,100)
Block(-7,18,-2,SMOOTH_STAIRS:0)
Block(-7,18,-1,SMOOTH_STAIRS:0)
Block(-7,18,0,SMOOTH_STAIRS:0)
Block(-7,18,1,SMOOTH_STAIRS:0)
Block(-7,18,2,SMOOTH_STAIRS:0)
Block(-7,18,3,COBBLE_WALL:0)
Block(-7,18,5,COBBLE_WALL:0)
Block(-7,19,-7,STAINED_GLASS_PANE:15)
RandomBlock(-7,19,-6,CONCRETE:7,60,quark:iron_plate:1,20,STAINED_CLAY:12,15,STAINED_CLAY:15,5,AIR,7,IRON_BARS,12,CONCRETE:7,100)
Block(-7,19,-5,STAINED_GLASS_PANE:15)
RandomBlock(-7,19,-4,CONCRETE:7,60,quark:iron_plate:1,20,STAINED_CLAY:12,15,STAINED_CLAY:15,5,AIR,7,IRON_BARS,12,CONCRETE:7,100)
RandomBlock(-7,19,-3,CONCRETE:7,60,quark:iron_plate:1,20,STAINED_CLAY:12,15,STAINED_CLAY:15,5,AIR,7,IRON_BARS,12,CONCRETE:7,100)
Block(-7,20,-7,STAINED_GLASS_PANE:15)
RandomBlock(-7,20,-6,CONCRETE:7,60,quark:iron_plate:1,20,STAINED_CLAY:12,15,STAINED_CLAY:15,5,AIR,7,IRON_BARS,12,CONCRETE:7,100)
Block(-7,20,-5,STAINED_GLASS_PANE:15)
RandomBlock(-7,20,-4,CONCRETE:7,60,quark:iron_plate:1,20,STAINED_CLAY:12,15,STAINED_CLAY:15,5,AIR,7,IRON_BARS,12,CONCRETE:7,100)
RandomBlock(-7,20,-3,CONCRETE:7,60,quark:iron_plate:1,20,STAINED_CLAY:12,15,STAINED_CLAY:15,5,AIR,7,IRON_BARS,12,CONCRETE:7,100)
RandomBlock(-7,21,-7,CONCRETE:7,60,quark:iron_plate:1,20,STAINED_CLAY:12,15,STAINED_CLAY:15,5,AIR,7,IRON_BARS,12,CONCRETE:7,100)
RandomBlock(-7,21,-6,CONCRETE:7,60,quark:iron_plate:1,20,STAINED_CLAY:12,15,STAINED_CLAY:15,5,AIR,7,IRON_BARS,12,CONCRETE:7,100)
RandomBlock(-7,21,-5,CONCRETE:7,60,quark:iron_plate:1,20,STAINED_CLAY:12,15,STAINED_CLAY:15,5,AIR,7,IRON_BARS,12,CONCRETE:7,100)
RandomBlock(-7,21,-4,CONCRETE:7,60,quark:iron_plate:1,20,STAINED_CLAY:12,15,STAINED_CLAY:15,5,AIR,7,IRON_BARS,12,CONCRETE:7,100)
RandomBlock(-7,21,-3,CONCRETE:7,60,quark:iron_plate:1,20,STAINED_CLAY:12,15,STAINED_CLAY:15,5,AIR,7,IRON_BARS,12,CONCRETE:7,100)
RandomBlock(-7,22,-7,CONCRETE:7,60,quark:iron_plate:1,20,STAINED_CLAY:12,15,STAINED_CLAY:15,5,AIR,7,IRON_BARS,12,CONCRETE:7,100)
RandomBlock(-7,22,-6,CONCRETE:7,60,quark:iron_plate:1,20,STAINED_CLAY:12,15,STAINED_CLAY:15,5,AIR,7,IRON_BARS,12,CONCRETE:7,100)
RandomBlock(-7,22,-5,CONCRETE:7,60,quark:iron_plate:1,20,STAINED_CLAY:12,15,STAINED_CLAY:15,5,AIR,7,IRON_BARS,12,CONCRETE:7,100)
RandomBlock(-7,22,-4,CONCRETE:7,60,quark:iron_plate:1,20,STAINED_CLAY:12,15,STAINED_CLAY:15,5,AIR,7,IRON_BARS,12,CONCRETE:7,100)
RandomBlock(-7,22,-3,CONCRETE:7,60,quark:iron_plate:1,20,STAINED_CLAY:12,15,STAINED_CLAY:15,5,AIR,7,IRON_BARS,12,CONCRETE:7,100)
Block(-7,23,-7,STAINED_GLASS_PANE:15)
RandomBlock(-7,23,-6,CONCRETE:7,60,quark:iron_plate:1,20,STAINED_CLAY:12,15,STAINED_CLAY:15,5,AIR,7,IRON_BARS,12,CONCRETE:7,100)
Block(-7,23,-5,STAINED_GLASS_PANE:15)
RandomBlock(-7,23,-4,CONCRETE:7,60,quark:iron_plate:1,20,STAINED_CLAY:12,15,STAINED_CLAY:15,5,AIR,7,IRON_BARS,12,CONCRETE:7,100)
RandomBlock(-7,23,-3,CONCRETE:7,60,quark:iron_plate:1,20,STAINED_CLAY:12,15,STAINED_CLAY:15,5,AIR,7,IRON_BARS,12,CONCRETE:7,100)
Block(-7,24,-7,STAINED_GLASS_PANE:15)
RandomBlock(-7,24,-6,CONCRETE:7,60,quark:iron_plate:1,20,STAINED_CLAY:12,15,STAINED_CLAY:15,5,AIR,7,IRON_BARS,12,CONCRETE:7,100)
Block(-7,24,-5,STAINED_GLASS_PANE:15)
RandomBlock(-7,24,-4,CONCRETE:7,60,quark:iron_plate:1,20,STAINED_CLAY:12,15,STAINED_CLAY:15,5,AIR,7,IRON_BARS,12,CONCRETE:7,100)
RandomBlock(-7,24,-3,CONCRETE:7,60,quark:iron_plate:1,20,STAINED_CLAY:12,15,STAINED_CLAY:15,5,AIR,7,IRON_BARS,12,CONCRETE:7,100)
RandomBlock(-7,25,-7,CONCRETE:7,60,quark:iron_plate:1,20,STAINED_CLAY:12,15,STAINED_CLAY:15,5,AIR,7,IRON_BARS,12,CONCRETE:7,100)
RandomBlock(-7,25,-6,CONCRETE:7,60,quark:iron_plate:1,20,STAINED_CLAY:12,15,STAINED_CLAY:15,5,AIR,7,IRON_BARS,12,CONCRETE:7,100)
RandomBlock(-7,25,-5,CONCRETE:7,60,quark:iron_plate:1,20,STAINED_CLAY:12,15,STAINED_CLAY:15,5,AIR,7,IRON_BARS,12,CONCRETE:7,100)
RandomBlock(-7,25,-4,CONCRETE:7,60,quark:iron_plate:1,20,STAINED_CLAY:12,15,STAINED_CLAY:15,5,AIR,7,IRON_BARS,12,CONCRETE:7,100)
RandomBlock(-7,25,-3,CONCRETE:7,60,quark:iron_plate:1,20,STAINED_CLAY:12,15,STAINED_CLAY:15,5,AIR,7,IRON_BARS,12,CONCRETE:7,100)
RandomBlock(-7,26,-7,CONCRETE:7,60,quark:iron_plate:1,20,STAINED_CLAY:12,15,STAINED_CLAY:15,5,AIR,7,IRON_BARS,12,CONCRETE:7,100)
RandomBlock(-7,26,-6,CONCRETE:7,60,quark:iron_plate:1,20,STAINED_CLAY:12,15,STAINED_CLAY:15,5,AIR,7,IRON_BARS,12,CONCRETE:7,100)
RandomBlock(-7,26,-5,CONCRETE:7,60,quark:iron_plate:1,20,STAINED_CLAY:12,15,STAINED_CLAY:15,5,AIR,7,IRON_BARS,12,CONCRETE:7,100)
RandomBlock(-7,26,-4,CONCRETE:7,60,quark:iron_plate:1,20,STAINED_CLAY:12,15,STAINED_CLAY:15,5,AIR,7,IRON_BARS,12,CONCRETE:7,100)
RandomBlock(-7,26,-3,CONCRETE:7,60,quark:iron_plate:1,20,STAINED_CLAY:12,15,STAINED_CLAY:15,5,AIR,7,IRON_BARS,12,CONCRETE:7,100)
Block(-7,27,-7,STAINED_GLASS_PANE:15)
RandomBlock(-7,27,-6,CONCRETE:7,60,quark:iron_plate:1,20,STAINED_CLAY:12,15,STAINED_CLAY:15,5,AIR,7,IRON_BARS,12,CONCRETE:7,100)
Block(-7,27,-5,STAINED_GLASS_PANE:15)
RandomBlock(-7,27,-4,CONCRETE:7,60,quark:iron_plate:1,20,STAINED_CLAY:12,15,STAINED_CLAY:15,5,AIR,7,IRON_BARS,12,CONCRETE:7,100)
RandomBlock(-7,27,-3,CONCRETE:7,60,quark:iron_plate:1,20,STAINED_CLAY:12,15,STAINED_CLAY:15,5,AIR,7,IRON_BARS,12,CONCRETE:7,100)
Block(-7,28,-7,STAINED_GLASS_PANE:15)
RandomBlock(-7,28,-6,CONCRETE:7,60,quark:iron_plate:1,20,STAINED_CLAY:12,15,STAINED_CLAY:15,5,AIR,7,IRON_BARS,12,CONCRETE:7,100)
Block(-7,28,-5,STAINED_GLASS_PANE:15)
RandomBlock(-7,28,-4,CONCRETE:7,60,quark:iron_plate:1,20,STAINED_CLAY:12,15,STAINED_CLAY:15,5,AIR,7,IRON_BARS,12,CONCRETE:7,100)
RandomBlock(-7,28,-3,CONCRETE:7,60,quark:iron_plate:1,20,STAINED_CLAY:12,15,STAINED_CLAY:15,5,AIR,7,IRON_BARS,12,CONCRETE:7,100)
RandomBlock(-7,29,-7,CONCRETE:7,60,quark:iron_plate:1,20,STAINED_CLAY:12,15,STAINED_CLAY:15,5,AIR,7,IRON_BARS,12,CONCRETE:7,100)
RandomBlock(-7,29,-6,CONCRETE:7,60,quark:iron_plate:1,20,STAINED_CLAY:12,15,STAINED_CLAY:15,5,AIR,7,IRON_BARS,12,CONCRETE:7,100)
RandomBlock(-7,29,-5,CONCRETE:7,60,quark:iron_plate:1,20,STAINED_CLAY:12,15,STAINED_CLAY:15,5,AIR,7,IRON_BARS,12,CONCRETE:7,100)
RandomBlock(-7,29,-4,CONCRETE:7,60,quark:iron_plate:1,20,STAINED_CLAY:12,15,STAINED_CLAY:15,5,AIR,7,IRON_BARS,12,CONCRETE:7,100)
RandomBlock(-7,29,-3,CONCRETE:7,60,quark:iron_plate:1,20,STAINED_CLAY:12,15,STAINED_CLAY:15,5,AIR,7,IRON_BARS,12,CONCRETE:7,100)
Block(-7,30,-7,CONCRETE:8)
Block(-7,30,-6,CONCRETE:8)
Block(-7,30,-5,CONCRETE:8)
Block(-7,30,-4,CONCRETE:8)
Block(-7,30,-3,CONCRETE:8)
Block(-7,31,-7,STAINED_GLASS_PANE:15)
Block(-7,31,-6,CONCRETE:8)
Block(-7,31,-5,STAINED_GLASS_PANE:15)
Block(-7,31,-4,CONCRETE:8)
Block(-7,31,-3,CONCRETE:8)
Block(-7,32,-7,STAINED_GLASS_PANE:15)
Block(-7,32,-6,CONCRETE:8)
Block(-7,32,-5,STAINED_GLASS_PANE:15)
Block(-7,32,-4,CONCRETE:8)
Block(-7,32,-3,CONCRETE:8)
Block(-7,33,-7,CONCRETE:8)
Block(-7,33,-6,CONCRETE:8)
Block(-7,33,-5,CONCRETE:8)
Block(-7,33,-4,CONCRETE:8)
Block(-7,33,-3,CONCRETE:8)
Block(-7,34,-7,IRON_FENCE:0)
Block(-7,34,-6,IRON_FENCE:0)
Block(-7,34,-5,IRON_FENCE:0)
Block(-7,34,-4,IRON_FENCE:0)
RandomBlock(-7,34,-3,CONCRETE:7,60,quark:iron_plate:1,20,STAINED_CLAY:12,15,STAINED_CLAY:15,5,AIR,7,IRON_BARS,12,CONCRETE:7,100)
RandomBlock(-6,0,-7,CONCRETE:7,60,quark:iron_plate:1,20,STAINED_CLAY:12,15,STAINED_CLAY:15,5,AIR,7,IRON_BARS,12,CONCRETE:7,100)
RandomBlock(-6,0,-6,CONCRETE:7,60,quark:iron_plate:1,20,STAINED_CLAY:12,15,STAINED_CLAY:15,5,AIR,7,IRON_BARS,12,CONCRETE:7,100)
RandomBlock(-6,0,-5,CONCRETE:7,60,quark:iron_plate:1,20,STAINED_CLAY:12,15,STAINED_CLAY:15,5,AIR,7,IRON_BARS,12,CONCRETE:7,100)
RandomBlock(-6,0,-4,CONCRETE:7,60,quark:iron_plate:1,20,STAINED_CLAY:12,15,STAINED_CLAY:15,5,AIR,7,IRON_BARS,12,CONCRETE:7,100)
RandomBlock(-6,0,-3,CONCRETE:7,60,quark:iron_plate:1,20,STAINED_CLAY:12,15,STAINED_CLAY:15,5,AIR,7,IRON_BARS,12,CONCRETE:7,100)
RandomBlock(-6,0,-2,CONCRETE:7,60,quark:iron_plate:1,20,STAINED_CLAY:12,15,STAINED_CLAY:15,5,AIR,7,IRON_BARS,12,CONCRETE:7,100)
RandomBlock(-6,0,-1,CONCRETE:7,60,quark:iron_plate:1,20,STAINED_CLAY:12,15,STAINED_CLAY:15,5,AIR,7,IRON_BARS,12,CONCRETE:7,100)
RandomBlock(-6,0,0,CONCRETE:7,60,quark:iron_plate:1,20,STAINED_CLAY:12,15,STAINED_CLAY:15,5,AIR,7,IRON_BARS,12,CONCRETE:7,100)
RandomBlock(-6,0,1,CONCRETE:7,60,quark:iron_plate:1,20,STAINED_CLAY:12,15,STAINED_CLAY:15,5,AIR,7,IRON_BARS,12,CONCRETE:7,100)
RandomBlock(-6,0,2,CONCRETE:7,60,quark:iron_plate:1,20,STAINED_CLAY:12,15,STAINED_CLAY:15,5,AIR,7,IRON_BARS,12,CONCRETE:7,100)
RandomBlock(-6,0,3,CONCRETE:7,60,quark:iron_plate:1,20,STAINED_CLAY:12,15,STAINED_CLAY:15,5,AIR,7,IRON_BARS,12,CONCRETE:7,100)
RandomBlock(-6,0,4,CONCRETE:7,60,quark:iron_plate:1,20,STAINED_CLAY:12,15,STAINED_CLAY:15,5,AIR,7,IRON_BARS,12,CONCRETE:7,100)
RandomBlock(-6,0,5,CONCRETE:7,60,quark:iron_plate:1,20,STAINED_CLAY:12,15,STAINED_CLAY:15,5,AIR,7,IRON_BARS,12,CONCRETE:7,100)
RandomBlock(-6,0,6,CONCRETE:7,60,quark:iron_plate:1,20,STAINED_CLAY:12,15,STAINED_CLAY:15,5,AIR,7,IRON_BARS,12,CONCRETE:7,100)
RandomBlock(-6,0,7,CONCRETE:7,60,quark:iron_plate:1,20,STAINED_CLAY:12,15,STAINED_CLAY:15,5,AIR,7,IRON_BARS,12,CONCRETE:7,100)
RandomBlock(-6,0,8,CONCRETE:7,60,quark:iron_plate:1,20,STAINED_CLAY:12,15,STAINED_CLAY:15,5,AIR,7,IRON_BARS,12,CONCRETE:7,100)
RandomBlock(-6,1,-7,CONCRETE:7,60,quark:iron_plate:1,20,STAINED_CLAY:12,15,STAINED_CLAY:15,5,AIR,7,IRON_BARS,12,CONCRETE:7,100)
RandomBlock(-6,1,-6,CONCRETE:7,60,quark:iron_plate:1,20,STAINED_CLAY:12,15,STAINED_CLAY:15,5,AIR,7,IRON_BARS,12,CONCRETE:7,100)
RandomBlock(-6,1,-5,CONCRETE:7,60,quark:iron_plate:1,20,STAINED_CLAY:12,15,STAINED_CLAY:15,5,AIR,7,IRON_BARS,12,CONCRETE:7,100)
RandomBlock(-6,1,-4,CONCRETE:7,60,quark:iron_plate:1,20,STAINED_CLAY:12,15,STAINED_CLAY:15,5,AIR,7,IRON_BARS,12,CONCRETE:7,100)
RandomBlock(-6,1,-3,CONCRETE:7,60,quark:iron_plate:1,20,STAINED_CLAY:12,15,STAINED_CLAY:15,5,AIR,7,IRON_BARS,12,CONCRETE:7,100)
RandomBlock(-6,1,-2,CONCRETE:7,60,quark:iron_plate:1,20,STAINED_CLAY:12,15,STAINED_CLAY:15,5,AIR,7,IRON_BARS,12,CONCRETE:7,100)
RandomBlock(-6,1,-1,CONCRETE:7,60,quark:iron_plate:1,20,STAINED_CLAY:12,15,STAINED_CLAY:15,5,AIR,7,IRON_BARS,12,CONCRETE:7,100)
RandomBlock(-6,1,0,CONCRETE:7,60,quark:iron_plate:1,20,STAINED_CLAY:12,15,STAINED_CLAY:15,5,AIR,7,IRON_BARS,12,CONCRETE:7,100)
RandomBlock(-6,1,1,CONCRETE:7,60,quark:iron_plate:1,20,STAINED_CLAY:12,15,STAINED_CLAY:15,5,AIR,7,IRON_BARS,12,CONCRETE:7,100)
RandomBlock(-6,1,2,CONCRETE:7,60,quark:iron_plate:1,20,STAINED_CLAY:12,15,STAINED_CLAY:15,5,AIR,7,IRON_BARS,12,CONCRETE:7,100)
RandomBlock(-6,1,3,CONCRETE:7,60,quark:iron_plate:1,20,STAINED_CLAY:12,15,STAINED_CLAY:15,5,AIR,7,IRON_BARS,12,CONCRETE:7,100)
RandomBlock(-6,1,4,CONCRETE:7,60,quark:iron_plate:1,20,STAINED_CLAY:12,15,STAINED_CLAY:15,5,AIR,7,IRON_BARS,12,CONCRETE:7,100)
RandomBlock(-6,1,5,CONCRETE:7,60,quark:iron_plate:1,20,STAINED_CLAY:12,15,STAINED_CLAY:15,5,AIR,7,IRON_BARS,12,CONCRETE:7,100)
RandomBlock(-6,1,6,CONCRETE:7,60,quark:iron_plate:1,20,STAINED_CLAY:12,15,STAINED_CLAY:15,5,AIR,7,IRON_BARS,12,CONCRETE:7,100)
RandomBlock(-6,1,7,CONCRETE:7,60,quark:iron_plate:1,20,STAINED_CLAY:12,15,STAINED_CLAY:15,5,AIR,7,IRON_BARS,12,CONCRETE:7,100)
RandomBlock(-6,1,8,CONCRETE:7,60,quark:iron_plate:1,20,STAINED_CLAY:12,15,STAINED_CLAY:15,5,AIR,7,IRON_BARS,12,CONCRETE:7,100)
RandomBlock(-6,2,-7,CONCRETE:7,60,quark:iron_plate:1,20,STAINED_CLAY:12,15,STAINED_CLAY:15,5,AIR,7,IRON_BARS,12,CONCRETE:7,100)
RandomBlock(-6,2,-6,CONCRETE:7,60,quark:iron_plate:1,20,STAINED_CLAY:12,15,STAINED_CLAY:15,5,AIR,7,IRON_BARS,12,CONCRETE:7,100)
RandomBlock(-6,2,-5,CONCRETE:7,60,quark:iron_plate:1,20,STAINED_CLAY:12,15,STAINED_CLAY:15,5,AIR,7,IRON_BARS,12,CONCRETE:7,100)
RandomBlock(-6,2,-4,CONCRETE:7,60,quark:iron_plate:1,20,STAINED_CLAY:12,15,STAINED_CLAY:15,5,AIR,7,IRON_BARS,12,CONCRETE:7,100)
RandomBlock(-6,2,-3,CONCRETE:7,60,quark:iron_plate:1,20,STAINED_CLAY:12,15,STAINED_CLAY:15,5,AIR,7,IRON_BARS,12,CONCRETE:7,100)
RandomBlock(-6,2,-2,CONCRETE:7,60,quark:iron_plate:1,20,STAINED_CLAY:12,15,STAINED_CLAY:15,5,AIR,7,IRON_BARS,12,CONCRETE:7,100)
RandomBlock(-6,2,-1,CONCRETE:7,60,quark:iron_plate:1,20,STAINED_CLAY:12,15,STAINED_CLAY:15,5,AIR,7,IRON_BARS,12,CONCRETE:7,100)
RandomBlock(-6,2,0,CONCRETE:7,60,quark:iron_plate:1,20,STAINED_CLAY:12,15,STAINED_CLAY:15,5,AIR,7,IRON_BARS,12,CONCRETE:7,100)
RandomBlock(-6,2,1,CONCRETE:7,60,quark:iron_plate:1,20,STAINED_CLAY:12,15,STAINED_CLAY:15,5,AIR,7,IRON_BARS,12,CONCRETE:7,100)
RandomBlock(-6,2,2,CONCRETE:7,60,quark:iron_plate:1,20,STAINED_CLAY:12,15,STAINED_CLAY:15,5,AIR,7,IRON_BARS,12,CONCRETE:7,100)
RandomBlock(-6,2,3,CONCRETE:7,60,quark:iron_plate:1,20,STAINED_CLAY:12,15,STAINED_CLAY:15,5,AIR,7,IRON_BARS,12,CONCRETE:7,100)
RandomBlock(-6,2,4,CONCRETE:7,60,quark:iron_plate:1,20,STAINED_CLAY:12,15,STAINED_CLAY:15,5,AIR,7,IRON_BARS,12,CONCRETE:7,100)
RandomBlock(-6,2,5,CONCRETE:7,60,quark:iron_plate:1,20,STAINED_CLAY:12,15,STAINED_CLAY:15,5,AIR,7,IRON_BARS,12,CONCRETE:7,100)
RandomBlock(-6,2,6,CONCRETE:7,60,quark:iron_plate:1,20,STAINED_CLAY:12,15,STAINED_CLAY:15,5,AIR,7,IRON_BARS,12,CONCRETE:7,100)
RandomBlock(-6,2,7,CONCRETE:7,60,quark:iron_plate:1,20,STAINED_CLAY:12,15,STAINED_CLAY:15,5,AIR,7,IRON_BARS,12,CONCRETE:7,100)
RandomBlock(-6,2,8,CONCRETE:7,60,quark:iron_plate:1,20,STAINED_CLAY:12,15,STAINED_CLAY:15,5,AIR,7,IRON_BARS,12,CONCRETE:7,100)
RandomBlock(-6,3,-7,CONCRETE:7,60,quark:iron_plate:1,20,STAINED_CLAY:12,15,STAINED_CLAY:15,5,AIR,7,IRON_BARS,12,CONCRETE:7,100)
RandomBlock(-6,3,-6,CONCRETE:7,60,quark:iron_plate:1,20,STAINED_CLAY:12,15,STAINED_CLAY:15,5,AIR,7,IRON_BARS,12,CONCRETE:7,100)
RandomBlock(-6,3,-5,CONCRETE:7,60,quark:iron_plate:1,20,STAINED_CLAY:12,15,STAINED_CLAY:15,5,AIR,7,IRON_BARS,12,CONCRETE:7,100)
RandomBlock(-6,3,-4,CONCRETE:7,60,quark:iron_plate:1,20,STAINED_CLAY:12,15,STAINED_CLAY:15,5,AIR,7,IRON_BARS,12,CONCRETE:7,100)
RandomBlock(-6,3,-3,CONCRETE:7,60,quark:iron_plate:1,20,STAINED_CLAY:12,15,STAINED_CLAY:15,5,AIR,7,IRON_BARS,12,CONCRETE:7,100)
RandomBlock(-6,3,-2,CONCRETE:7,60,quark:iron_plate:1,20,STAINED_CLAY:12,15,STAINED_CLAY:15,5,AIR,7,IRON_BARS,12,CONCRETE:7,100)
RandomBlock(-6,3,-1,CONCRETE:7,60,quark:iron_plate:1,20,STAINED_CLAY:12,15,STAINED_CLAY:15,5,AIR,7,IRON_BARS,12,CONCRETE:7,100)
RandomBlock(-6,3,0,CONCRETE:7,60,quark:iron_plate:1,20,STAINED_CLAY:12,15,STAINED_CLAY:15,5,AIR,7,IRON_BARS,12,CONCRETE:7,100)
RandomBlock(-6,3,1,CONCRETE:7,60,quark:iron_plate:1,20,STAINED_CLAY:12,15,STAINED_CLAY:15,5,AIR,7,IRON_BARS,12,CONCRETE:7,100)
RandomBlock(-6,3,2,CONCRETE:7,60,quark:iron_plate:1,20,STAINED_CLAY:12,15,STAINED_CLAY:15,5,AIR,7,IRON_BARS,12,CONCRETE:7,100)
RandomBlock(-6,3,3,CONCRETE:7,60,quark:iron_plate:1,20,STAINED_CLAY:12,15,STAINED_CLAY:15,5,AIR,7,IRON_BARS,12,CONCRETE:7,100)
RandomBlock(-6,3,4,CONCRETE:7,60,quark:iron_plate:1,20,STAINED_CLAY:12,15,STAINED_CLAY:15,5,AIR,7,IRON_BARS,12,CONCRETE:7,100)
RandomBlock(-6,3,5,CONCRETE:7,60,quark:iron_plate:1,20,STAINED_CLAY:12,15,STAINED_CLAY:15,5,AIR,7,IRON_BARS,12,CONCRETE:7,100)
RandomBlock(-6,3,6,CONCRETE:7,60,quark:iron_plate:1,20,STAINED_CLAY:12,15,STAINED_CLAY:15,5,AIR,7,IRON_BARS,12,CONCRETE:7,100)
RandomBlock(-6,3,7,CONCRETE:7,60,quark:iron_plate:1,20,STAINED_CLAY:12,15,STAINED_CLAY:15,5,AIR,7,IRON_BARS,12,CONCRETE:7,100)
RandomBlock(-6,3,8,CONCRETE:7,60,quark:iron_plate:1,20,STAINED_CLAY:12,15,STAINED_CLAY:15,5,AIR,7,IRON_BARS,12,CONCRETE:7,100)
RandomBlock(-6,4,-7,CONCRETE:7,60,quark:iron_plate:1,20,STAINED_CLAY:12,15,STAINED_CLAY:15,5,AIR,7,IRON_BARS,12,CONCRETE:7,100)
RandomBlock(-6,4,-6,CONCRETE:7,60,quark:iron_plate:1,20,STAINED_CLAY:12,15,STAINED_CLAY:15,5,AIR,7,IRON_BARS,12,CONCRETE:7,100)
RandomBlock(-6,4,-5,CONCRETE:7,60,quark:iron_plate:1,20,STAINED_CLAY:12,15,STAINED_CLAY:15,5,AIR,7,IRON_BARS,12,CONCRETE:7,100)
RandomBlock(-6,4,-4,CONCRETE:7,60,quark:iron_plate:1,20,STAINED_CLAY:12,15,STAINED_CLAY:15,5,AIR,7,IRON_BARS,12,CONCRETE:7,100)
RandomBlock(-6,4,-3,CONCRETE:7,60,quark:iron_plate:1,20,STAINED_CLAY:12,15,STAINED_CLAY:15,5,AIR,7,IRON_BARS,12,CONCRETE:7,100)
RandomBlock(-6,4,-2,CONCRETE:7,60,quark:iron_plate:1,20,STAINED_CLAY:12,15,STAINED_CLAY:15,5,AIR,7,IRON_BARS,12,CONCRETE:7,100)
RandomBlock(-6,4,-1,CONCRETE:7,60,quark:iron_plate:1,20,STAINED_CLAY:12,15,STAINED_CLAY:15,5,AIR,7,IRON_BARS,12,CONCRETE:7,100)
RandomBlock(-6,4,0,CONCRETE:7,60,quark:iron_plate:1,20,STAINED_CLAY:12,15,STAINED_CLAY:15,5,AIR,7,IRON_BARS,12,CONCRETE:7,100)
RandomBlock(-6,4,1,CONCRETE:7,60,quark:iron_plate:1,20,STAINED_CLAY:12,15,STAINED_CLAY:15,5,AIR,7,IRON_BARS,12,CONCRETE:7,100)
RandomBlock(-6,4,2,CONCRETE:7,60,quark:iron_plate:1,20,STAINED_CLAY:12,15,STAINED_CLAY:15,5,AIR,7,IRON_BARS,12,CONCRETE:7,100)
RandomBlock(-6,4,3,CONCRETE:7,60,quark:iron_plate:1,20,STAINED_CLAY:12,15,STAINED_CLAY:15,5,AIR,7,IRON_BARS,12,CONCRETE:7,100)
RandomBlock(-6,4,4,CONCRETE:7,60,quark:iron_plate:1,20,STAINED_CLAY:12,15,STAINED_CLAY:15,5,AIR,7,IRON_BARS,12,CONCRETE:7,100)
RandomBlock(-6,4,5,CONCRETE:7,60,quark:iron_plate:1,20,STAINED_CLAY:12,15,STAINED_CLAY:15,5,AIR,7,IRON_BARS,12,CONCRETE:7,100)
RandomBlock(-6,4,6,CONCRETE:7,60,quark:iron_plate:1,20,STAINED_CLAY:12,15,STAINED_CLAY:15,5,AIR,7,IRON_BARS,12,CONCRETE:7,100)
RandomBlock(-6,4,7,CONCRETE:7,60,quark:iron_plate:1,20,STAINED_CLAY:12,15,STAINED_CLAY:15,5,AIR,7,IRON_BARS,12,CONCRETE:7,100)
RandomBlock(-6,4,8,CONCRETE:7,60,quark:iron_plate:1,20,STAINED_CLAY:12,15,STAINED_CLAY:15,5,AIR,7,IRON_BARS,12,CONCRETE:7,100)
RandomBlock(-6,5,-7,CONCRETE:7,60,quark:iron_plate:1,20,STAINED_CLAY:12,15,STAINED_CLAY:15,5,AIR,7,IRON_BARS,12,CONCRETE:7,100)
RandomBlock(-6,5,-6,CONCRETE:7,60,quark:iron_plate:1,20,STAINED_CLAY:12,15,STAINED_CLAY:15,5,AIR,7,IRON_BARS,12,CONCRETE:7,100)
RandomBlock(-6,5,-5,CONCRETE:7,60,quark:iron_plate:1,20,STAINED_CLAY:12,15,STAINED_CLAY:15,5,AIR,7,IRON_BARS,12,CONCRETE:7,100)
RandomBlock(-6,5,-4,CONCRETE:7,60,quark:iron_plate:1,20,STAINED_CLAY:12,15,STAINED_CLAY:15,5,AIR,7,IRON_BARS,12,CONCRETE:7,100)
RandomBlock(-6,5,-3,CONCRETE:7,60,quark:iron_plate:1,20,STAINED_CLAY:12,15,STAINED_CLAY:15,5,AIR,7,IRON_BARS,12,CONCRETE:7,100)
RandomBlock(-6,5,-2,CONCRETE:7,60,quark:iron_plate:1,20,STAINED_CLAY:12,15,STAINED_CLAY:15,5,AIR,7,IRON_BARS,12,CONCRETE:7,100)
RandomBlock(-6,5,-1,CONCRETE:7,60,quark:iron_plate:1,20,STAINED_CLAY:12,15,STAINED_CLAY:15,5,AIR,7,IRON_BARS,12,CONCRETE:7,100)
RandomBlock(-6,5,0,CONCRETE:7,60,quark:iron_plate:1,20,STAINED_CLAY:12,15,STAINED_CLAY:15,5,AIR,7,IRON_BARS,12,CONCRETE:7,100)
RandomBlock(-6,5,1,CONCRETE:7,60,quark:iron_plate:1,20,STAINED_CLAY:12,15,STAINED_CLAY:15,5,AIR,7,IRON_BARS,12,CONCRETE:7,100)
RandomBlock(-6,5,2,CONCRETE:7,60,quark:iron_plate:1,20,STAINED_CLAY:12,15,STAINED_CLAY:15,5,AIR,7,IRON_BARS,12,CONCRETE:7,100)
RandomBlock(-6,5,3,CONCRETE:7,60,quark:iron_plate:1,20,STAINED_CLAY:12,15,STAINED_CLAY:15,5,AIR,7,IRON_BARS,12,CONCRETE:7,100)
RandomBlock(-6,5,4,CONCRETE:7,60,quark:iron_plate:1,20,STAINED_CLAY:12,15,STAINED_CLAY:15,5,AIR,7,IRON_BARS,12,CONCRETE:7,100)
RandomBlock(-6,5,5,CONCRETE:7,60,quark:iron_plate:1,20,STAINED_CLAY:12,15,STAINED_CLAY:15,5,AIR,7,IRON_BARS,12,CONCRETE:7,100)
RandomBlock(-6,5,6,CONCRETE:7,60,quark:iron_plate:1,20,STAINED_CLAY:12,15,STAINED_CLAY:15,5,AIR,7,IRON_BARS,12,CONCRETE:7,100)
RandomBlock(-6,5,7,CONCRETE:7,60,quark:iron_plate:1,20,STAINED_CLAY:12,15,STAINED_CLAY:15,5,AIR,7,IRON_BARS,12,CONCRETE:7,100)
RandomBlock(-6,5,8,CONCRETE:7,60,quark:iron_plate:1,20,STAINED_CLAY:12,15,STAINED_CLAY:15,5,AIR,7,IRON_BARS,12,CONCRETE:7,100)
RandomBlock(-6,6,-7,CONCRETE:7,60,quark:iron_plate:1,20,STAINED_CLAY:12,15,STAINED_CLAY:15,5,AIR,7,IRON_BARS,12,CONCRETE:7,100)
RandomBlock(-6,6,-6,CONCRETE:7,60,quark:iron_plate:1,20,STAINED_CLAY:12,15,STAINED_CLAY:15,5,AIR,7,IRON_BARS,12,CONCRETE:7,100)
RandomBlock(-6,6,-5,CONCRETE:7,60,quark:iron_plate:1,20,STAINED_CLAY:12,15,STAINED_CLAY:15,5,AIR,7,IRON_BARS,12,CONCRETE:7,100)
RandomBlock(-6,6,-4,CONCRETE:7,60,quark:iron_plate:1,20,STAINED_CLAY:12,15,STAINED_CLAY:15,5,AIR,7,IRON_BARS,12,CONCRETE:7,100)
RandomBlock(-6,6,-3,CONCRETE:7,60,quark:iron_plate:1,20,STAINED_CLAY:12,15,STAINED_CLAY:15,5,AIR,7,IRON_BARS,12,CONCRETE:7,100)
RandomBlock(-6,6,-2,CONCRETE:7,60,quark:iron_plate:1,20,STAINED_CLAY:12,15,STAINED_CLAY:15,5,AIR,7,IRON_BARS,12,CONCRETE:7,100)
RandomBlock(-6,6,-1,CONCRETE:7,60,quark:iron_plate:1,20,STAINED_CLAY:12,15,STAINED_CLAY:15,5,AIR,7,IRON_BARS,12,CONCRETE:7,100)
RandomBlock(-6,6,0,CONCRETE:7,60,quark:iron_plate:1,20,STAINED_CLAY:12,15,STAINED_CLAY:15,5,AIR,7,IRON_BARS,12,CONCRETE:7,100)
RandomBlock(-6,6,1,CONCRETE:7,60,quark:iron_plate:1,20,STAINED_CLAY:12,15,STAINED_CLAY:15,5,AIR,7,IRON_BARS,12,CONCRETE:7,100)
RandomBlock(-6,6,2,CONCRETE:7,60,quark:iron_plate:1,20,STAINED_CLAY:12,15,STAINED_CLAY:15,5,AIR,7,IRON_BARS,12,CONCRETE:7,100)
RandomBlock(-6,6,3,CONCRETE:7,60,quark:iron_plate:1,20,STAINED_CLAY:12,15,STAINED_CLAY:15,5,AIR,7,IRON_BARS,12,CONCRETE:7,100)
RandomBlock(-6,6,4,CONCRETE:7,60,quark:iron_plate:1,20,STAINED_CLAY:12,15,STAINED_CLAY:15,5,AIR,7,IRON_BARS,12,CONCRETE:7,100)
RandomBlock(-6,6,5,CONCRETE:7,60,quark:iron_plate:1,20,STAINED_CLAY:12,15,STAINED_CLAY:15,5,AIR,7,IRON_BARS,12,CONCRETE:7,100)
RandomBlock(-6,6,6,CONCRETE:7,60,quark:iron_plate:1,20,STAINED_CLAY:12,15,STAINED_CLAY:15,5,AIR,7,IRON_BARS,12,CONCRETE:7,100)
RandomBlock(-6,6,7,CONCRETE:7,60,quark:iron_plate:1,20,STAINED_CLAY:12,15,STAINED_CLAY:15,5,AIR,7,IRON_BARS,12,CONCRETE:7,100)
RandomBlock(-6,6,8,CONCRETE:7,60,quark:iron_plate:1,20,STAINED_CLAY:12,15,STAINED_CLAY:15,5,AIR,7,IRON_BARS,12,CONCRETE:7,100)
RandomBlock(-6,7,-7,CONCRETE:7,60,quark:iron_plate:1,20,STAINED_CLAY:12,15,STAINED_CLAY:15,5,AIR,7,IRON_BARS,12,CONCRETE:7,100)
RandomBlock(-6,7,-6,CONCRETE:7,60,quark:iron_plate:1,20,STAINED_CLAY:12,15,STAINED_CLAY:15,5,AIR,7,IRON_BARS,12,CONCRETE:7,100)
RandomBlock(-6,7,-5,CONCRETE:7,60,quark:iron_plate:1,20,STAINED_CLAY:12,15,STAINED_CLAY:15,5,AIR,7,IRON_BARS,12,CONCRETE:7,100)
RandomBlock(-6,7,-4,CONCRETE:7,60,quark:iron_plate:1,20,STAINED_CLAY:12,15,STAINED_CLAY:15,5,AIR,7,IRON_BARS,12,CONCRETE:7,100)
RandomBlock(-6,7,-3,CONCRETE:7,60,quark:iron_plate:1,20,STAINED_CLAY:12,15,STAINED_CLAY:15,5,AIR,7,IRON_BARS,12,CONCRETE:7,100)
RandomBlock(-6,7,-2,CONCRETE:7,60,quark:iron_plate:1,20,STAINED_CLAY:12,15,STAINED_CLAY:15,5,AIR,7,IRON_BARS,12,CONCRETE:7,100)
RandomBlock(-6,7,-1,CONCRETE:7,60,quark:iron_plate:1,20,STAINED_CLAY:12,15,STAINED_CLAY:15,5,AIR,7,IRON_BARS,12,CONCRETE:7,100)
RandomBlock(-6,7,0,CONCRETE:7,60,quark:iron_plate:1,20,STAINED_CLAY:12,15,STAINED_CLAY:15,5,AIR,7,IRON_BARS,12,CONCRETE:7,100)
RandomBlock(-6,7,1,CONCRETE:7,60,quark:iron_plate:1,20,STAINED_CLAY:12,15,STAINED_CLAY:15,5,AIR,7,IRON_BARS,12,CONCRETE:7,100)
RandomBlock(-6,7,2,CONCRETE:7,60,quark:iron_plate:1,20,STAINED_CLAY:12,15,STAINED_CLAY:15,5,AIR,7,IRON_BARS,12,CONCRETE:7,100)
RandomBlock(-6,7,3,CONCRETE:7,60,quark:iron_plate:1,20,STAINED_CLAY:12,15,STAINED_CLAY:15,5,AIR,7,IRON_BARS,12,CONCRETE:7,100)
RandomBlock(-6,7,4,CONCRETE:7,60,quark:iron_plate:1,20,STAINED_CLAY:12,15,STAINED_CLAY:15,5,AIR,7,IRON_BARS,12,CONCRETE:7,100)
RandomBlock(-6,7,5,CONCRETE:7,60,quark:iron_plate:1,20,STAINED_CLAY:12,15,STAINED_CLAY:15,5,AIR,7,IRON_BARS,12,CONCRETE:7,100)
RandomBlock(-6,7,6,CONCRETE:7,60,quark:iron_plate:1,20,STAINED_CLAY:12,15,STAINED_CLAY:15,5,AIR,7,IRON_BARS,12,CONCRETE:7,100)
RandomBlock(-6,7,7,CONCRETE:7,60,quark:iron_plate:1,20,STAINED_CLAY:12,15,STAINED_CLAY:15,5,AIR,7,IRON_BARS,12,CONCRETE:7,100)
RandomBlock(-6,7,8,CONCRETE:7,60,quark:iron_plate:1,20,STAINED_CLAY:12,15,STAINED_CLAY:15,5,AIR,7,IRON_BARS,12,CONCRETE:7,100)
RandomBlock(-6,8,-7,CONCRETE:7,60,quark:iron_plate:1,20,STAINED_CLAY:12,15,STAINED_CLAY:15,5,AIR,7,IRON_BARS,12,CONCRETE:7,100)
RandomBlock(-6,8,-6,CONCRETE:7,60,quark:iron_plate:1,20,STAINED_CLAY:12,15,STAINED_CLAY:15,5,AIR,7,IRON_BARS,12,CONCRETE:7,100)
RandomBlock(-6,8,-5,CONCRETE:7,60,quark:iron_plate:1,20,STAINED_CLAY:12,15,STAINED_CLAY:15,5,AIR,7,IRON_BARS,12,CONCRETE:7,100)
RandomBlock(-6,8,-4,CONCRETE:7,60,quark:iron_plate:1,20,STAINED_CLAY:12,15,STAINED_CLAY:15,5,AIR,7,IRON_BARS,12,CONCRETE:7,100)
RandomBlock(-6,8,-3,CONCRETE:7,60,quark:iron_plate:1,20,STAINED_CLAY:12,15,STAINED_CLAY:15,5,AIR,7,IRON_BARS,12,CONCRETE:7,100)
RandomBlock(-6,8,-2,CONCRETE:7,60,quark:iron_plate:1,20,STAINED_CLAY:12,15,STAINED_CLAY:15,5,AIR,7,IRON_BARS,12,CONCRETE:7,100)
RandomBlock(-6,8,-1,CONCRETE:7,60,quark:iron_plate:1,20,STAINED_CLAY:12,15,STAINED_CLAY:15,5,AIR,7,IRON_BARS,12,CONCRETE:7,100)
RandomBlock(-6,8,0,CONCRETE:7,60,quark:iron_plate:1,20,STAINED_CLAY:12,15,STAINED_CLAY:15,5,AIR,7,IRON_BARS,12,CONCRETE:7,100)
RandomBlock(-6,8,1,CONCRETE:7,60,quark:iron_plate:1,20,STAINED_CLAY:12,15,STAINED_CLAY:15,5,AIR,7,IRON_BARS,12,CONCRETE:7,100)
RandomBlock(-6,8,2,CONCRETE:7,60,quark:iron_plate:1,20,STAINED_CLAY:12,15,STAINED_CLAY:15,5,AIR,7,IRON_BARS,12,CONCRETE:7,100)
RandomBlock(-6,8,3,CONCRETE:7,60,quark:iron_plate:1,20,STAINED_CLAY:12,15,STAINED_CLAY:15,5,AIR,7,IRON_BARS,12,CONCRETE:7,100)
RandomBlock(-6,8,4,CONCRETE:7,60,quark:iron_plate:1,20,STAINED_CLAY:12,15,STAINED_CLAY:15,5,AIR,7,IRON_BARS,12,CONCRETE:7,100)
RandomBlock(-6,8,5,CONCRETE:7,60,quark:iron_plate:1,20,STAINED_CLAY:12,15,STAINED_CLAY:15,5,AIR,7,IRON_BARS,12,CONCRETE:7,100)
RandomBlock(-6,8,6,CONCRETE:7,60,quark:iron_plate:1,20,STAINED_CLAY:12,15,STAINED_CLAY:15,5,AIR,7,IRON_BARS,12,CONCRETE:7,100)
RandomBlock(-6,8,7,CONCRETE:7,60,quark:iron_plate:1,20,STAINED_CLAY:12,15,STAINED_CLAY:15,5,AIR,7,IRON_BARS,12,CONCRETE:7,100)
RandomBlock(-6,8,8,CONCRETE:7,60,quark:iron_plate:1,20,STAINED_CLAY:12,15,STAINED_CLAY:15,5,AIR,7,IRON_BARS,12,CONCRETE:7,100)
RandomBlock(-6,9,-7,CONCRETE:7,60,quark:iron_plate:1,20,STAINED_CLAY:12,15,STAINED_CLAY:15,5,AIR,7,IRON_BARS,12,CONCRETE:7,100)
RandomBlock(-6,9,-6,CONCRETE:7,60,quark:iron_plate:1,20,STAINED_CLAY:12,15,STAINED_CLAY:15,5,AIR,7,IRON_BARS,12,CONCRETE:7,100)
RandomBlock(-6,9,-5,CONCRETE:7,60,quark:iron_plate:1,20,STAINED_CLAY:12,15,STAINED_CLAY:15,5,AIR,7,IRON_BARS,12,CONCRETE:7,100)
