
#######################################################################
# +-----------------------------------------------------------------+ #
# |                            BO4 object                           | #
# +-----------------------------------------------------------------+ #
#######################################################################

Author: NLBlackEagle

Description: No description given

SettingsMode: WriteDisable


#######################################################################
# +-----------------------------------------------------------------+ #
# |                          Main settings                          | #
# +-----------------------------------------------------------------+ #
#######################################################################

Frequency: 0

SpawnHeight: highestBlock

UseCenterForHighestBlock: true

##############################
# Height Limits for the BO4. #
##############################

MinHeight: 0

MaxHeight: 255

InheritBO3: 

InheritBO3Rotation: NORTH

OverrideChildSettings: true

OverrideParentHeight: false

CanOverride: true

BranchFrequency: 0

BranchFrequencyGroup: 

MustBeBelowOther: false

MustBeInside: 

CannotBeInside: 

ReplacesBO3: L4-M-CrossC0R0, L4-M-CrossC0R1, L4-M-CrossC0R2, L4-M-CrossC0R3, L4-M-CrossC1R0, L4-M-CrossC1R1, L4-M-CrossC1R2, L4-M-CrossC1R3, L4-M-CrossC2R0, L4-M-CrossC2R1, L4-M-CrossC2R2, L4-M-CrossC2R3, L4-M-CrossC3R0, L4-M-CrossC3R1, L4-M-CrossC3R2, L4-M-CrossC3R3, L4-M-Straigth-START_01-C0R0, L4-M-Straigth-START_01-C0R1, L4-M-Straigth-START_01-C1R0, L4-M-Straigth-START_01-C1R1, L4-M-Straigth-START_01-C2R0, L4-M-Straigth-START_01-C2R1, L4-M-Straigth-START_01-C3R0, L4-M-Straigth-START_01-C3R1, L4-M-Straigth-3CC0R0, L4-M-Straigth-3CC0R1, L4-M-Straigth-3CC0R2, L4-M-Straigth-3CC1R0, L4-M-Straigth-3CC1R1, L4-M-Straigth-3CC1R2, L4-M-Straigth-3CC2R0, L4-M-Straigth-3CC2R1, L4-M-Straigth-3CC2R2, L4-M-Straigth-3CC3R0, L4-M-Straigth-3CC3R1, L4-M-Straigth-3CC3R2, L4-M-Cross, skyscraper_2x2_01, skyscraper_2x2_02, skyscraper_2x2_03, skyscraper_2x2_04, skyscraper_2x2_05, skyscraper_3x3_01, skyscraper_3x3_02, skyscraper_3x3_03, L3-M-Straigth-2CC0R0, L3-M-Straigth-2CC0R1, L3-M-Straigth-2CC1R0, L3-M-Straigth-2CC1R1, L3-M-Straigth-2CC2R0, L3-M-Straigth-2CC2R1, L3-M-Straigth-2CC3R0, L3-M-Straigth-2CC3R1, L3-M-Straigth-3CC0R0, L3-M-Straigth-3CC0R1, L3-M-Straigth-3CC0R2, L3-M-Straigth-3CC1R0, L3-M-Straigth-3CC1R1, L3-M-Straigth-3CC1R2, L3-M-Straigth-3CC2R0, L3-M-Straigth-3CC2R1, L3-M-Straigth-3CC2R2, L3-M-Straigth-3CC3R0, L3-M-Straigth-3CC3R1, L3-M-Straigth-3CC3R2L4-M-CrossC0R0, L4-M-CrossC0R1, L4-M-CrossC0R2, L4-M-CrossC0R3, L4-M-CrossC1R0, L4-M-CrossC1R1, L4-M-CrossC1R2, L4-M-CrossC1R3, L4-M-CrossC2R0, L4-M-CrossC2R1, L4-M-CrossC2R2, L4-M-CrossC2R3, L4-M-CrossC3R0, L4-M-CrossC3R1, L4-M-CrossC3R2, L4-M-CrossC3R3, L4-M-Straigth-START_01-C0R0, L4-M-Straigth-START_01-C0R1, L4-M-Straigth-START_01-C1R0, L4-M-Straigth-START_01-C1R1, L4-M-Straigth-START_01-C2R0, L4-M-Straigth-START_01-C2R1, L4-M-Straigth-START_01-C3R0, L4-M-Straigth-START_01-C3R1, L4-M-Straigth-3CC0R0, L4-M-Straigth-3CC0R1, L4-M-Straigth-3CC0R2, L4-M-Straigth-3CC1R0, L4-M-Straigth-3CC1R1, L4-M-Straigth-3CC1R2, L4-M-Straigth-3CC2R0, L4-M-Straigth-3CC2R1, L4-M-Straigth-3

MustBeInsideWorldBorders: true
CanSpawnOnWater: true

SpawnOnWaterOnly: false

SpawnUnderWater: false

SpawnAtWaterLevel: false

HeightOffset: 0

RemoveAir: false

ReplaceAbove: 

ReplaceBelow: 

ReplaceWithBiomeBlocks: true

ReplaceWithSurfaceBlock: GRASS

ReplaceWithGroundBlock: DIRT

ReplaceWithStoneBlock: STONE

SmoothRadius: 0

SmoothHeightOffset: 0

SmoothStartTop: false

SmoothStartWood: false

SmoothingSurfaceBlock: 

SmoothingGroundBlock: 

BO3Group: 

IsSpawnPoint: false

DoReplaceBlocks: true


#######################################################################
# +-----------------------------------------------------------------+ #
# |                              Blocks                             | #
# +-----------------------------------------------------------------+ #
#######################################################################

RandomBlock(-8,0,-7,CONCRETE:7,60,quark:iron_plate:1,20,STAINED_CLAY:12,15,STAINED_CLAY:15,5,AIR,7,IRON_BARS,12,CONCRETE:7,100)
RandomBlock(-8,0,-6,CONCRETE:7,60,quark:iron_plate:1,20,STAINED_CLAY:12,15,STAINED_CLAY:15,5,AIR,7,IRON_BARS,12,CONCRETE:7,100)
RandomBlock(-8,0,-5,CONCRETE:7,60,quark:iron_plate:1,20,STAINED_CLAY:12,15,STAINED_CLAY:15,5,AIR,7,IRON_BARS,12,CONCRETE:7,100)
RandomBlock(-8,0,-4,CONCRETE:7,60,quark:iron_plate:1,20,STAINED_CLAY:12,15,STAINED_CLAY:15,5,AIR,7,IRON_BARS,12,CONCRETE:7,100)
RandomBlock(-8,0,-3,CONCRETE:7,60,quark:iron_plate:1,20,STAINED_CLAY:12,15,STAINED_CLAY:15,5,AIR,7,IRON_BARS,12,CONCRETE:7,100)
RandomBlock(-8,0,-2,CONCRETE:7,60,quark:iron_plate:1,20,STAINED_CLAY:12,15,STAINED_CLAY:15,5,AIR,7,IRON_BARS,12,CONCRETE:7,100)
RandomBlock(-8,0,-1,CONCRETE:7,60,quark:iron_plate:1,20,STAINED_CLAY:12,15,STAINED_CLAY:15,5,AIR,7,IRON_BARS,12,CONCRETE:7,100)
RandomBlock(-8,0,0,CONCRETE:7,60,quark:iron_plate:1,20,STAINED_CLAY:12,15,STAINED_CLAY:15,5,AIR,7,IRON_BARS,12,CONCRETE:7,100)
RandomBlock(-8,0,1,CONCRETE:7,60,quark:iron_plate:1,20,STAINED_CLAY:12,15,STAINED_CLAY:15,5,AIR,7,IRON_BARS,12,CONCRETE:7,100)
RandomBlock(-8,0,2,CONCRETE:7,60,quark:iron_plate:1,20,STAINED_CLAY:12,15,STAINED_CLAY:15,5,AIR,7,IRON_BARS,12,CONCRETE:7,100)
RandomBlock(-8,0,3,CONCRETE:7,60,quark:iron_plate:1,20,STAINED_CLAY:12,15,STAINED_CLAY:15,5,AIR,7,IRON_BARS,12,CONCRETE:7,100)
RandomBlock(-8,0,4,CONCRETE:7,60,quark:iron_plate:1,20,STAINED_CLAY:12,15,STAINED_CLAY:15,5,AIR,7,IRON_BARS,12,CONCRETE:7,100)
RandomBlock(-8,0,5,CONCRETE:7,60,quark:iron_plate:1,20,STAINED_CLAY:12,15,STAINED_CLAY:15,5,AIR,7,IRON_BARS,12,CONCRETE:7,100)
RandomBlock(-8,0,6,CONCRETE:7,60,quark:iron_plate:1,20,STAINED_CLAY:12,15,STAINED_CLAY:15,5,AIR,7,IRON_BARS,12,CONCRETE:7,100)
RandomBlock(-8,0,7,CONCRETE:7,60,quark:iron_plate:1,20,STAINED_CLAY:12,15,STAINED_CLAY:15,5,AIR,7,IRON_BARS,12,CONCRETE:7,100)
RandomBlock(-8,0,8,CONCRETE:7,60,quark:iron_plate:1,20,STAINED_CLAY:12,15,STAINED_CLAY:15,5,AIR,7,IRON_BARS,12,CONCRETE:7,100)
Block(-8,1,-7,AIR:0)
Block(-8,1,-6,AIR:0)
Block(-8,1,-5,AIR:0)
Block(-8,1,-4,SMOOTH_STAIRS:2)
RandomBlock(-8,1,-3,CONCRETE:7,60,quark:iron_plate:1,20,STAINED_CLAY:12,15,STAINED_CLAY:15,5,AIR,7,IRON_BARS,12,CONCRETE:7,100)
RandomBlock(-8,1,-2,CONCRETE:7,60,quark:iron_plate:1,20,STAINED_CLAY:12,15,STAINED_CLAY:15,5,AIR,7,IRON_BARS,12,CONCRETE:7,100)
RandomBlock(-8,1,-1,CONCRETE:7,60,quark:iron_plate:1,20,STAINED_CLAY:12,15,STAINED_CLAY:15,5,AIR,7,IRON_BARS,12,CONCRETE:7,100)
RandomBlock(-8,1,0,CONCRETE:7,60,quark:iron_plate:1,20,STAINED_CLAY:12,15,STAINED_CLAY:15,5,AIR,7,IRON_BARS,12,CONCRETE:7,100)
RandomBlock(-8,1,1,CONCRETE:7,60,quark:iron_plate:1,20,STAINED_CLAY:12,15,STAINED_CLAY:15,5,AIR,7,IRON_BARS,12,CONCRETE:7,100)
RandomBlock(-8,1,2,CONCRETE:7,60,quark:iron_plate:1,20,STAINED_CLAY:12,15,STAINED_CLAY:15,5,AIR,7,IRON_BARS,12,CONCRETE:7,100)
Block(-8,1,3,STATIONARY_WATER:0)
Block(-8,1,4,STATIONARY_WATER:0)
RandomBlock(-8,1,5,CONCRETE:7,60,quark:iron_plate:1,20,STAINED_CLAY:12,15,STAINED_CLAY:15,5,AIR,7,IRON_BARS,12,CONCRETE:7,100)
RandomBlock(-8,1,6,CONCRETE:7,60,quark:iron_plate:1,20,STAINED_CLAY:12,15,STAINED_CLAY:15,5,AIR,7,IRON_BARS,12,CONCRETE:7,100)
RandomBlock(-8,1,7,CONCRETE:7,60,quark:iron_plate:1,20,STAINED_CLAY:12,15,STAINED_CLAY:15,5,AIR,7,IRON_BARS,12,CONCRETE:7,100)
RandomBlock(-8,1,8,CONCRETE:7,60,quark:iron_plate:1,20,STAINED_CLAY:12,15,STAINED_CLAY:15,5,AIR,7,IRON_BARS,12,CONCRETE:7,100)
RandomBlock(-8,2,-7,AIR,90,IRON_TRAPDOOR:9,100)
RandomBlock(-8,2,-6,AIR,90,IRON_TRAPDOOR:11,100)
Block(-8,2,-5,AIR:0)
Block(-8,2,-4,AIR:0)
Block(-8,2,-3,SMOOTH_STAIRS:2)
RandomBlock(-8,2,-2,CONCRETE:7,60,quark:iron_plate:1,20,STAINED_CLAY:12,15,STAINED_CLAY:15,5,AIR,7,IRON_BARS,12,CONCRETE:7,100)
RandomBlock(-8,2,-1,CONCRETE:7,60,quark:iron_plate:1,20,STAINED_CLAY:12,15,STAINED_CLAY:15,5,AIR,7,IRON_BARS,12,CONCRETE:7,100)
RandomBlock(-8,2,0,CONCRETE:7,60,quark:iron_plate:1,20,STAINED_CLAY:12,15,STAINED_CLAY:15,5,AIR,7,IRON_BARS,12,CONCRETE:7,100)
RandomBlock(-8,2,1,CONCRETE:7,60,quark:iron_plate:1,20,STAINED_CLAY:12,15,STAINED_CLAY:15,5,AIR,7,IRON_BARS,12,CONCRETE:7,100)
Block(-8,2,2,SMOOTH_STAIRS:3)
Block(-8,2,3,AIR:0)
Block(-8,2,4,AIR:0)
Block(-8,2,5,SMOOTH_STAIRS:2)
RandomBlock(-8,2,6,CONCRETE:7,60,quark:iron_plate:1,20,STAINED_CLAY:12,15,STAINED_CLAY:15,5,AIR,7,IRON_BARS,12,CONCRETE:7,100)
RandomBlock(-8,2,7,CONCRETE:7,60,quark:iron_plate:1,20,STAINED_CLAY:12,15,STAINED_CLAY:15,5,AIR,7,IRON_BARS,12,CONCRETE:7,100)
RandomBlock(-8,2,8,CONCRETE:7,60,quark:iron_plate:1,20,STAINED_CLAY:12,15,STAINED_CLAY:15,5,AIR,7,IRON_BARS,12,CONCRETE:7,100)
Block(-8,3,-7,AIR:0)
Block(-8,3,-6,AIR:0)
Block(-8,3,-5,AIR:0)
Block(-8,3,-4,AIR:0)
Block(-8,3,-3,AIR:0)
Block(-8,3,-2,AIR:0)
Block(-8,3,-1,AIR:0)
Block(-8,3,0,AIR:0)
Block(-8,3,1,AIR:0)
Block(-8,3,2,AIR:0)
Block(-8,3,3,AIR:0)
Block(-8,3,4,AIR:0)
Block(-8,3,5,AIR:0)
Block(-8,3,6,AIR:0)
Block(-8,3,7,AIR:0)
RandomBlock(-8,3,8,CONCRETE:7,60,quark:iron_plate:1,20,STAINED_CLAY:12,15,STAINED_CLAY:15,5,AIR,7,IRON_BARS,12,CONCRETE:7,100)
Block(-8,4,-7,AIR:0)
Block(-8,4,-6,AIR:0)
Block(-8,4,-5,AIR:0)
Block(-8,4,-4,AIR:0)
Block(-8,4,-3,AIR:0)
Block(-8,4,-2,AIR:0)
Block(-8,4,-1,AIR:0)
Block(-8,4,0,AIR:0)
Block(-8,4,1,AIR:0)
Block(-8,4,2,AIR:0)
Block(-8,4,3,AIR:0)
Block(-8,4,4,AIR:0)
Block(-8,4,5,AIR:0)
Block(-8,4,6,AIR:0)
Block(-8,4,7,AIR:0)
RandomBlock(-8,4,8,CONCRETE:7,60,quark:iron_plate:1,20,STAINED_CLAY:12,15,STAINED_CLAY:15,5,AIR,7,IRON_BARS,12,CONCRETE:7,100)
Block(-8,5,-7,AIR:0)
Block(-8,5,-6,AIR:0)
Block(-8,5,-5,AIR:0)
Block(-8,5,-4,AIR:0)
Block(-8,5,-3,AIR:0)
Block(-8,5,-2,AIR:0)
Block(-8,5,-1,AIR:0)
Block(-8,5,0,AIR:0)
Block(-8,5,1,AIR:0)
Block(-8,5,2,AIR:0)
Block(-8,5,3,AIR:0)
Block(-8,5,4,AIR:0)
Block(-8,5,5,AIR:0)
Block(-8,5,6,CONCRETE:12)
Block(-8,5,7,CONCRETE:4)
RandomBlock(-8,5,8,CONCRETE:7,60,quark:iron_plate:1,20,STAINED_CLAY:12,15,STAINED_CLAY:15,5,AIR,7,IRON_BARS,12,CONCRETE:7,100)
RandomBlock(-8,6,-7,CONCRETE:7,60,quark:iron_plate:1,20,STAINED_CLAY:12,15,STAINED_CLAY:15,5,AIR,7,IRON_BARS,12,CONCRETE:7,100)
Block(-8,6,-6,AIR:0)
Block(-8,6,-5,AIR:0)
Block(-8,6,-4,AIR:0)
Block(-8,6,-3,AIR:0)
Block(-8,6,-2,AIR:0)
Block(-8,6,-1,AIR:0)
Block(-8,6,0,AIR:0)
Block(-8,6,1,AIR:0)
Block(-8,6,2,AIR:0)
Block(-8,6,3,AIR:0)
Block(-8,6,4,AIR:0)
Block(-8,6,5,AIR:0)
Block(-8,6,6,AIR:0)
Block(-8,6,7,AIR:0)
RandomBlock(-8,6,8,CONCRETE:7,60,quark:iron_plate:1,20,STAINED_CLAY:12,15,STAINED_CLAY:15,5,AIR,7,IRON_BARS,12,CONCRETE:7,100)
RandomBlock(-8,7,-7,CONCRETE:7,60,quark:iron_plate:1,20,STAINED_CLAY:12,15,STAINED_CLAY:15,5,AIR,7,IRON_BARS,12,CONCRETE:7,100)
RandomBlock(-8,7,-6,CONCRETE:7,60,quark:iron_plate:1,20,STAINED_CLAY:12,15,STAINED_CLAY:15,5,AIR,7,IRON_BARS,12,CONCRETE:7,100)
RandomBlock(-8,7,-5,CONCRETE:7,60,quark:iron_plate:1,20,STAINED_CLAY:12,15,STAINED_CLAY:15,5,AIR,7,IRON_BARS,12,CONCRETE:7,100)
RandomBlock(-8,7,-4,CONCRETE:7,60,quark:iron_plate:1,20,STAINED_CLAY:12,15,STAINED_CLAY:15,5,AIR,7,IRON_BARS,12,CONCRETE:7,100)
RandomBlock(-8,7,-3,CONCRETE:7,60,quark:iron_plate:1,20,STAINED_CLAY:12,15,STAINED_CLAY:15,5,AIR,7,IRON_BARS,12,CONCRETE:7,100)
RandomBlock(-8,7,-2,CONCRETE:7,60,quark:iron_plate:1,20,STAINED_CLAY:12,15,STAINED_CLAY:15,5,AIR,7,IRON_BARS,12,CONCRETE:7,100)
RandomBlock(-8,7,-1,CONCRETE:7,60,quark:iron_plate:1,20,STAINED_CLAY:12,15,STAINED_CLAY:15,5,AIR,7,IRON_BARS,12,CONCRETE:7,100)
RandomBlock(-8,7,0,CONCRETE:7,60,quark:iron_plate:1,20,STAINED_CLAY:12,15,STAINED_CLAY:15,5,AIR,7,IRON_BARS,12,CONCRETE:7,100)
RandomBlock(-8,7,1,CONCRETE:7,60,quark:iron_plate:1,20,STAINED_CLAY:12,15,STAINED_CLAY:15,5,AIR,7,IRON_BARS,12,CONCRETE:7,100)
RandomBlock(-8,7,2,CONCRETE:7,60,quark:iron_plate:1,20,STAINED_CLAY:12,15,STAINED_CLAY:15,5,AIR,7,IRON_BARS,12,CONCRETE:7,100)
RandomBlock(-8,7,3,CONCRETE:7,60,quark:iron_plate:1,20,STAINED_CLAY:12,15,STAINED_CLAY:15,5,AIR,7,IRON_BARS,12,CONCRETE:7,100)
RandomBlock(-8,7,4,CONCRETE:7,60,quark:iron_plate:1,20,STAINED_CLAY:12,15,STAINED_CLAY:15,5,AIR,7,IRON_BARS,12,CONCRETE:7,100)
RandomBlock(-8,7,5,CONCRETE:7,60,quark:iron_plate:1,20,STAINED_CLAY:12,15,STAINED_CLAY:15,5,AIR,7,IRON_BARS,12,CONCRETE:7,100)
RandomBlock(-8,7,6,CONCRETE:7,60,quark:iron_plate:1,20,STAINED_CLAY:12,15,STAINED_CLAY:15,5,AIR,7,IRON_BARS,12,CONCRETE:7,100)
RandomBlock(-8,7,7,CONCRETE:7,60,quark:iron_plate:1,20,STAINED_CLAY:12,15,STAINED_CLAY:15,5,AIR,7,IRON_BARS,12,CONCRETE:7,100)
RandomBlock(-8,7,8,CONCRETE:7,60,quark:iron_plate:1,20,STAINED_CLAY:12,15,STAINED_CLAY:15,5,AIR,7,IRON_BARS,12,CONCRETE:7,100)
RandomBlock(-8,8,-7,CONCRETE:7,60,quark:iron_plate:1,20,STAINED_CLAY:12,15,STAINED_CLAY:15,5,AIR,7,IRON_BARS,12,CONCRETE:7,100)
RandomBlock(-8,8,-6,CONCRETE:7,60,quark:iron_plate:1,20,STAINED_CLAY:12,15,STAINED_CLAY:15,5,AIR,7,IRON_BARS,12,CONCRETE:7,100)
RandomBlock(-8,8,-5,CONCRETE:7,60,quark:iron_plate:1,20,STAINED_CLAY:12,15,STAINED_CLAY:15,5,AIR,7,IRON_BARS,12,CONCRETE:7,100)
RandomBlock(-8,8,-4,CONCRETE:7,60,quark:iron_plate:1,20,STAINED_CLAY:12,15,STAINED_CLAY:15,5,AIR,7,IRON_BARS,12,CONCRETE:7,100)
RandomBlock(-8,8,-3,CONCRETE:7,60,quark:iron_plate:1,20,STAINED_CLAY:12,15,STAINED_CLAY:15,5,AIR,7,IRON_BARS,12,CONCRETE:7,100)
RandomBlock(-8,8,-2,CONCRETE:7,60,quark:iron_plate:1,20,STAINED_CLAY:12,15,STAINED_CLAY:15,5,AIR,7,IRON_BARS,12,CONCRETE:7,100)
RandomBlock(-8,8,-1,CONCRETE:7,60,quark:iron_plate:1,20,STAINED_CLAY:12,15,STAINED_CLAY:15,5,AIR,7,IRON_BARS,12,CONCRETE:7,100)
RandomBlock(-8,8,0,CONCRETE:7,60,quark:iron_plate:1,20,STAINED_CLAY:12,15,STAINED_CLAY:15,5,AIR,7,IRON_BARS,12,CONCRETE:7,100)
RandomBlock(-8,8,1,CONCRETE:7,60,quark:iron_plate:1,20,STAINED_CLAY:12,15,STAINED_CLAY:15,5,AIR,7,IRON_BARS,12,CONCRETE:7,100)
RandomBlock(-8,8,2,CONCRETE:7,60,quark:iron_plate:1,20,STAINED_CLAY:12,15,STAINED_CLAY:15,5,AIR,7,IRON_BARS,12,CONCRETE:7,100)
RandomBlock(-8,8,3,CONCRETE:7,60,quark:iron_plate:1,20,STAINED_CLAY:12,15,STAINED_CLAY:15,5,AIR,7,IRON_BARS,12,CONCRETE:7,100)
RandomBlock(-8,8,4,CONCRETE:7,60,quark:iron_plate:1,20,STAINED_CLAY:12,15,STAINED_CLAY:15,5,AIR,7,IRON_BARS,12,CONCRETE:7,100)
Block(-8,8,5,STEP:0)
Block(-8,8,6,STEP:0)
Block(-8,8,7,STEP:0)
Block(-8,8,8,STEP:0)
RandomBlock(-8,9,-7,CONCRETE:7,60,quark:iron_plate:1,20,STAINED_CLAY:12,15,STAINED_CLAY:15,5,AIR,7,IRON_BARS,12,CONCRETE:7,100)
RandomBlock(-8,9,-6,CONCRETE:7,60,quark:iron_plate:1,20,STAINED_CLAY:12,15,STAINED_CLAY:15,5,AIR,7,IRON_BARS,12,CONCRETE:7,100)
RandomBlock(-8,9,-5,CONCRETE:7,60,quark:iron_plate:1,20,STAINED_CLAY:12,15,STAINED_CLAY:15,5,AIR,7,IRON_BARS,12,CONCRETE:7,100)
RandomBlock(-8,9,-4,CONCRETE:7,60,quark:iron_plate:1,20,STAINED_CLAY:12,15,STAINED_CLAY:15,5,AIR,7,IRON_BARS,12,CONCRETE:7,100)
RandomBlock(-8,9,-3,CONCRETE:7,60,quark:iron_plate:1,20,STAINED_CLAY:12,15,STAINED_CLAY:15,5,AIR,7,IRON_BARS,12,CONCRETE:7,100)
RandomBlock(-8,9,-2,CONCRETE:7,60,quark:iron_plate:1,20,STAINED_CLAY:12,15,STAINED_CLAY:15,5,AIR,7,IRON_BARS,12,CONCRETE:7,100)
RandomBlock(-8,9,-1,CONCRETE:7,60,quark:iron_plate:1,20,STAINED_CLAY:12,15,STAINED_CLAY:15,5,AIR,7,IRON_BARS,12,CONCRETE:7,100)
RandomBlock(-8,9,0,CONCRETE:7,60,quark:iron_plate:1,20,STAINED_CLAY:12,15,STAINED_CLAY:15,5,AIR,7,IRON_BARS,12,CONCRETE:7,100)
RandomBlock(-8,9,1,CONCRETE:7,60,quark:iron_plate:1,20,STAINED_CLAY:12,15,STAINED_CLAY:15,5,AIR,7,IRON_BARS,12,CONCRETE:7,100)
RandomBlock(-8,9,2,CONCRETE:7,60,quark:iron_plate:1,20,STAINED_CLAY:12,15,STAINED_CLAY:15,5,AIR,7,IRON_BARS,12,CONCRETE:7,100)
RandomBlock(-8,9,3,CONCRETE:7,60,quark:iron_plate:1,20,STAINED_CLAY:12,15,STAINED_CLAY:15,5,AIR,7,IRON_BARS,12,CONCRETE:7,100)
RandomBlock(-8,9,4,CONCRETE:7,60,quark:iron_plate:1,20,STAINED_CLAY:12,15,STAINED_CLAY:15,5,AIR,7,IRON_BARS,12,CONCRETE:7,100)
Block(-8,9,5,AIR:0)
Block(-8,9,6,AIR:0)
RandomBlock(-8,9,7,AIR,90,IRON_TRAPDOOR:8,100)
RandomBlock(-8,9,8,AIR,90,IRON_TRAPDOOR:10,100)
RandomBlock(-8,10,-7,CONCRETE:7,60,quark:iron_plate:1,20,STAINED_CLAY:12,15,STAINED_CLAY:15,5,AIR,7,IRON_BARS,12,CONCRETE:7,100)
RandomBlock(-8,10,-6,CONCRETE:7,60,quark:iron_plate:1,20,STAINED_CLAY:12,15,STAINED_CLAY:15,5,AIR,7,IRON_BARS,12,CONCRETE:7,100)
RandomBlock(-8,10,-5,CONCRETE:7,60,quark:iron_plate:1,20,STAINED_CLAY:12,15,STAINED_CLAY:15,5,AIR,7,IRON_BARS,12,CONCRETE:7,100)
RandomBlock(-8,10,-4,CONCRETE:7,60,quark:iron_plate:1,20,STAINED_CLAY:12,15,STAINED_CLAY:15,5,AIR,7,IRON_BARS,12,CONCRETE:7,100)
RandomBlock(-8,10,-3,CONCRETE:7,60,quark:iron_plate:1,20,STAINED_CLAY:12,15,STAINED_CLAY:15,5,AIR,7,IRON_BARS,12,CONCRETE:7,100)
RandomBlock(-8,10,-2,CONCRETE:7,60,quark:iron_plate:1,20,STAINED_CLAY:12,15,STAINED_CLAY:15,5,AIR,7,IRON_BARS,12,CONCRETE:7,100)
RandomBlock(-8,10,-1,CONCRETE:7,60,quark:iron_plate:1,20,STAINED_CLAY:12,15,STAINED_CLAY:15,5,AIR,7,IRON_BARS,12,CONCRETE:7,100)
RandomBlock(-8,10,0,CONCRETE:7,60,quark:iron_plate:1,20,STAINED_CLAY:12,15,STAINED_CLAY:15,5,AIR,7,IRON_BARS,12,CONCRETE:7,100)
RandomBlock(-8,10,1,STONE:6,80,STONE:6,90,DISPENSER:5,../../../../../Chests/Loot/city_potions.nbt,100)
RandomBlock(-8,10,2,STONE:6,80,STONE:6,90,DISPENSER:5,../../../../../Chests/Loot/city_potions.nbt,100)
RandomBlock(-8,10,3,STONE:6,80,STONE:6,90,DISPENSER:5,../../../../../Chests/Loot/city_potions.nbt,100)
RandomBlock(-8,10,4,CONCRETE:7,60,quark:iron_plate:1,20,STAINED_CLAY:12,15,STAINED_CLAY:15,5,AIR,7,IRON_BARS,12,CONCRETE:7,100)
Block(-8,10,5,AIR:0)
Block(-8,10,6,AIR:0)
Block(-8,10,7,IRON_FENCE:0)
Block(-8,10,8,AIR:0)
RandomBlock(-8,11,-7,CONCRETE:7,60,quark:iron_plate:1,20,STAINED_CLAY:12,15,STAINED_CLAY:15,5,AIR,7,IRON_BARS,12,CONCRETE:7,100)
RandomBlock(-8,11,-6,CONCRETE:7,60,quark:iron_plate:1,20,STAINED_CLAY:12,15,STAINED_CLAY:15,5,AIR,7,IRON_BARS,12,CONCRETE:7,100)
RandomBlock(-8,11,-5,CONCRETE:7,60,quark:iron_plate:1,20,STAINED_CLAY:12,15,STAINED_CLAY:15,5,AIR,7,IRON_BARS,12,CONCRETE:7,100)
RandomBlock(-8,11,-4,CONCRETE:7,60,quark:iron_plate:1,20,STAINED_CLAY:12,15,STAINED_CLAY:15,5,AIR,7,IRON_BARS,12,CONCRETE:7,100)
Block(-8,11,-3,SMOOTH_STAIRS:1)
Block(-8,11,-2,SMOOTH_STAIRS:1)
RandomBlock(-8,11,-1,CONCRETE:7,60,quark:iron_plate:1,20,STAINED_CLAY:12,15,STAINED_CLAY:15,5,AIR,7,IRON_BARS,12,CONCRETE:7,100)
RandomBlock(-8,11,0,CONCRETE:7,60,quark:iron_plate:1,20,STAINED_CLAY:12,15,STAINED_CLAY:15,5,AIR,7,IRON_BARS,12,CONCRETE:7,100)
RandomBlock(-8,11,1,STONE:6,80,STONE:6,90,DISPENSER:5,../../../../../Chests/Loot/city_potions.nbt,100)
RandomBlock(-8,11,2,STONE:6,80,STONE:6,90,DISPENSER:5,../../../../../Chests/Loot/city_potions.nbt,100)
RandomBlock(-8,11,3,STONE:6,80,STONE:6,90,DISPENSER:5,../../../../../Chests/Loot/city_potions.nbt,100)
RandomBlock(-8,11,4,CONCRETE:7,60,quark:iron_plate:1,20,STAINED_CLAY:12,15,STAINED_CLAY:15,5,AIR,7,IRON_BARS,12,CONCRETE:7,100)
Block(-8,11,5,AIR:0)
Block(-8,11,6,AIR:0)
Block(-8,11,7,AIR:0)
Block(-8,11,8,AIR:0)
RandomBlock(-8,12,-7,CONCRETE:7,60,quark:iron_plate:1,20,STAINED_CLAY:12,15,STAINED_CLAY:15,5,AIR,7,IRON_BARS,12,CONCRETE:7,100)
RandomBlock(-8,12,-6,CONCRETE:7,60,quark:iron_plate:1,20,STAINED_CLAY:12,15,STAINED_CLAY:15,5,AIR,7,IRON_BARS,12,CONCRETE:7,100)
RandomBlock(-8,12,-5,CONCRETE:7,60,quark:iron_plate:1,20,STAINED_CLAY:12,15,STAINED_CLAY:15,5,AIR,7,IRON_BARS,12,CONCRETE:7,100)
RandomBlock(-8,12,-4,CONCRETE:7,60,quark:iron_plate:1,20,STAINED_CLAY:12,15,STAINED_CLAY:15,5,AIR,7,IRON_BARS,12,CONCRETE:7,100)
Block(-8,12,-3,AIR:0)
Block(-8,12,-2,AIR:0)
RandomBlock(-8,12,-1,CONCRETE:7,60,quark:iron_plate:1,20,STAINED_CLAY:12,15,STAINED_CLAY:15,5,AIR,7,IRON_BARS,12,CONCRETE:7,100)
RandomBlock(-8,12,0,CONCRETE:7,60,quark:iron_plate:1,20,STAINED_CLAY:12,15,STAINED_CLAY:15,5,AIR,7,IRON_BARS,12,CONCRETE:7,100)
RandomBlock(-8,12,1,STONE:6,80,STONE:6,90,DISPENSER:5,../../../../../Chests/Loot/city_potions.nbt,100)
Block(-8,12,2,DISPENSER:13,../AllScraperData/skyscraper_2x2_04/310-dispenserC16R0.nbt)
RandomBlock(-8,12,3,STONE:6,80,STONE:6,90,DISPENSER:5,../../../../../Chests/Loot/city_potions.nbt,100)
RandomBlock(-8,12,4,CONCRETE:7,60,quark:iron_plate:1,20,STAINED_CLAY:12,15,STAINED_CLAY:15,5,AIR,7,IRON_BARS,12,CONCRETE:7,100)
Block(-8,12,5,AIR:0)
Block(-8,12,6,AIR:0)
Block(-8,12,7,AIR:0)
Block(-8,12,8,AIR:0)
RandomBlock(-8,13,-7,CONCRETE:7,60,quark:iron_plate:1,20,STAINED_CLAY:12,15,STAINED_CLAY:15,5,AIR,7,IRON_BARS,12,CONCRETE:7,100)
RandomBlock(-8,13,-6,CONCRETE:7,60,quark:iron_plate:1,20,STAINED_CLAY:12,15,STAINED_CLAY:15,5,AIR,7,IRON_BARS,12,CONCRETE:7,100)
RandomBlock(-8,13,-5,CONCRETE:7,60,quark:iron_plate:1,20,STAINED_CLAY:12,15,STAINED_CLAY:15,5,AIR,7,IRON_BARS,12,CONCRETE:7,100)
RandomBlock(-8,13,-4,CONCRETE:7,60,quark:iron_plate:1,20,STAINED_CLAY:12,15,STAINED_CLAY:15,5,AIR,7,IRON_BARS,12,CONCRETE:7,100)
Block(-8,13,-3,AIR:0)
Block(-8,13,-2,AIR:0)
RandomBlock(-8,13,-1,CONCRETE:7,60,quark:iron_plate:1,20,STAINED_CLAY:12,15,STAINED_CLAY:15,5,AIR,7,IRON_BARS,12,CONCRETE:7,100)
RandomBlock(-8,13,0,CONCRETE:7,60,quark:iron_plate:1,20,STAINED_CLAY:12,15,STAINED_CLAY:15,5,AIR,7,IRON_BARS,12,CONCRETE:7,100)
RandomBlock(-8,13,1,CONCRETE:7,60,quark:iron_plate:1,20,STAINED_CLAY:12,15,STAINED_CLAY:15,5,AIR,7,IRON_BARS,12,CONCRETE:7,100)
RandomBlock(-8,13,2,CONCRETE:7,60,quark:iron_plate:1,20,STAINED_CLAY:12,15,STAINED_CLAY:15,5,AIR,7,IRON_BARS,12,CONCRETE:7,100)
RandomBlock(-8,13,3,CONCRETE:7,60,quark:iron_plate:1,20,STAINED_CLAY:12,15,STAINED_CLAY:15,5,AIR,7,IRON_BARS,12,CONCRETE:7,100)
RandomBlock(-8,13,4,CONCRETE:7,60,quark:iron_plate:1,20,STAINED_CLAY:12,15,STAINED_CLAY:15,5,AIR,7,IRON_BARS,12,CONCRETE:7,100)
Block(-8,13,5,AIR:0)
Block(-8,13,6,AIR:0)
Block(-8,13,7,AIR:0)
Block(-8,13,8,AIR:0)
RandomBlock(-8,14,-7,CONCRETE:7,60,quark:iron_plate:1,20,STAINED_CLAY:12,15,STAINED_CLAY:15,5,AIR,7,IRON_BARS,12,CONCRETE:7,100)
RandomBlock(-8,14,-6,CONCRETE:7,60,quark:iron_plate:1,20,STAINED_CLAY:12,15,STAINED_CLAY:15,5,AIR,7,IRON_BARS,12,CONCRETE:7,100)
RandomBlock(-8,14,-5,CONCRETE:7,60,quark:iron_plate:1,20,STAINED_CLAY:12,15,STAINED_CLAY:15,5,AIR,7,IRON_BARS,12,CONCRETE:7,100)
RandomBlock(-8,14,-4,CONCRETE:7,60,quark:iron_plate:1,20,STAINED_CLAY:12,15,STAINED_CLAY:15,5,AIR,7,IRON_BARS,12,CONCRETE:7,100)
Block(-8,14,-3,AIR:0)
Block(-8,14,-2,AIR:0)
RandomBlock(-8,14,-1,CONCRETE:7,60,quark:iron_plate:1,20,STAINED_CLAY:12,15,STAINED_CLAY:15,5,AIR,7,IRON_BARS,12,CONCRETE:7,100)
RandomBlock(-8,14,0,CONCRETE:7,60,quark:iron_plate:1,20,STAINED_CLAY:12,15,STAINED_CLAY:15,5,AIR,7,IRON_BARS,12,CONCRETE:7,100)
RandomBlock(-8,14,1,STONE:6,80,STONE:6,90,DISPENSER:5,../../../../../Chests/Loot/city_potions.nbt,100)
RandomBlock(-8,14,2,STONE:6,80,STONE:6,90,DISPENSER:5,../../../../../Chests/Loot/city_potions.nbt,100)
RandomBlock(-8,14,3,STONE:6,80,STONE:6,90,DISPENSER:5,../../../../../Chests/Loot/city_potions.nbt,100)
RandomBlock(-8,14,4,CONCRETE:7,60,quark:iron_plate:1,20,STAINED_CLAY:12,15,STAINED_CLAY:15,5,AIR,7,IRON_BARS,12,CONCRETE:7,100)
Block(-8,14,5,AIR:0)
Block(-8,14,6,STEP:8)
Block(-8,14,7,AIR:0)
Block(-8,14,8,STEP:8)
RandomBlock(-8,15,-7,CONCRETE:7,60,quark:iron_plate:1,20,STAINED_CLAY:12,15,STAINED_CLAY:15,5,AIR,7,IRON_BARS,12,CONCRETE:7,100)
RandomBlock(-8,15,-6,CONCRETE:7,60,quark:iron_plate:1,20,STAINED_CLAY:12,15,STAINED_CLAY:15,5,AIR,7,IRON_BARS,12,CONCRETE:7,100)
RandomBlock(-8,15,-5,CONCRETE:7,60,quark:iron_plate:1,20,STAINED_CLAY:12,15,STAINED_CLAY:15,5,AIR,7,IRON_BARS,12,CONCRETE:7,100)
RandomBlock(-8,15,-4,CONCRETE:7,60,quark:iron_plate:1,20,STAINED_CLAY:12,15,STAINED_CLAY:15,5,AIR,7,IRON_BARS,12,CONCRETE:7,100)
Block(-8,15,-3,SMOOTH_STAIRS:4)
Block(-8,15,-2,SMOOTH_STAIRS:4)
RandomBlock(-8,15,-1,CONCRETE:7,60,quark:iron_plate:1,20,STAINED_CLAY:12,15,STAINED_CLAY:15,5,AIR,7,IRON_BARS,12,CONCRETE:7,100)
RandomBlock(-8,15,0,CONCRETE:7,60,quark:iron_plate:1,20,STAINED_CLAY:12,15,STAINED_CLAY:15,5,AIR,7,IRON_BARS,12,CONCRETE:7,100)
RandomBlock(-8,15,1,STONE:6,80,STONE:6,90,DISPENSER:5,../../../../../Chests/Loot/city_potions.nbt,100)
RandomBlock(-8,15,2,STONE:6,80,STONE:6,90,DISPENSER:5,../../../../../Chests/Loot/city_potions.nbt,100)
RandomBlock(-8,15,3,STONE:6,80,STONE:6,90,DISPENSER:5,../../../../../Chests/Loot/city_potions.nbt,100)
RandomBlock(-8,15,4,CONCRETE:7,60,quark:iron_plate:1,20,STAINED_CLAY:12,15,STAINED_CLAY:15,5,AIR,7,IRON_BARS,12,CONCRETE:7,100)
Block(-8,15,5,AIR:0)
RandomBlock(-8,15,6,CONCRETE:7,60,quark:iron_plate:1,20,STAINED_CLAY:12,15,STAINED_CLAY:15,5,AIR,7,IRON_BARS,12,CONCRETE:7,100)
Block(-8,15,7,AIR:0)
RandomBlock(-8,15,8,CONCRETE:7,60,quark:iron_plate:1,20,STAINED_CLAY:12,15,STAINED_CLAY:15,5,AIR,7,IRON_BARS,12,CONCRETE:7,100)
RandomBlock(-8,16,-7,CONCRETE:7,60,quark:iron_plate:1,20,STAINED_CLAY:12,15,STAINED_CLAY:15,5,AIR,7,IRON_BARS,12,CONCRETE:7,100)
RandomBlock(-8,16,-6,CONCRETE:7,60,quark:iron_plate:1,20,STAINED_CLAY:12,15,STAINED_CLAY:15,5,AIR,7,IRON_BARS,12,CONCRETE:7,100)
RandomBlock(-8,16,-5,CONCRETE:7,60,quark:iron_plate:1,20,STAINED_CLAY:12,15,STAINED_CLAY:15,5,AIR,7,IRON_BARS,12,CONCRETE:7,100)
RandomBlock(-8,16,-4,CONCRETE:7,60,quark:iron_plate:1,20,STAINED_CLAY:12,15,STAINED_CLAY:15,5,AIR,7,IRON_BARS,12,CONCRETE:7,100)
RandomBlock(-8,16,-3,CONCRETE:7,60,quark:iron_plate:1,20,STAINED_CLAY:12,15,STAINED_CLAY:15,5,AIR,7,IRON_BARS,12,CONCRETE:7,100)
RandomBlock(-8,16,-2,CONCRETE:7,60,quark:iron_plate:1,20,STAINED_CLAY:12,15,STAINED_CLAY:15,5,AIR,7,IRON_BARS,12,CONCRETE:7,100)
RandomBlock(-8,16,-1,CONCRETE:7,60,quark:iron_plate:1,20,STAINED_CLAY:12,15,STAINED_CLAY:15,5,AIR,7,IRON_BARS,12,CONCRETE:7,100)
RandomBlock(-8,16,0,CONCRETE:7,60,quark:iron_plate:1,20,STAINED_CLAY:12,15,STAINED_CLAY:15,5,AIR,7,IRON_BARS,12,CONCRETE:7,100)
RandomBlock(-8,16,1,STONE:6,80,STONE:6,90,DISPENSER:5,../../../../../Chests/Loot/city_potions.nbt,100)
RandomBlock(-8,16,2,STONE:6,80,STONE:6,90,DISPENSER:5,../../../../../Chests/Loot/city_potions.nbt,100)
RandomBlock(-8,16,3,STONE:6,80,STONE:6,90,DISPENSER:5,../../../../../Chests/Loot/city_potions.nbt,100)
RandomBlock(-8,16,4,CONCRETE:7,60,quark:iron_plate:1,20,STAINED_CLAY:12,15,STAINED_CLAY:15,5,AIR,7,IRON_BARS,12,CONCRETE:7,100)
Block(-8,16,5,AIR:0)
Block(-8,16,6,AIR:0)
Block(-8,16,7,AIR:0)
Block(-8,16,8,AIR:0)
RandomBlock(-8,17,-7,CONCRETE:7,60,quark:iron_plate:1,20,STAINED_CLAY:12,15,STAINED_CLAY:15,5,AIR,7,IRON_BARS,12,CONCRETE:7,100)
RandomBlock(-8,17,-6,CONCRETE:7,60,quark:iron_plate:1,20,STAINED_CLAY:12,15,STAINED_CLAY:15,5,AIR,7,IRON_BARS,12,CONCRETE:7,100)
RandomBlock(-8,17,-5,CONCRETE:7,60,quark:iron_plate:1,20,STAINED_CLAY:12,15,STAINED_CLAY:15,5,AIR,7,IRON_BARS,12,CONCRETE:7,100)
RandomBlock(-8,17,-4,CONCRETE:7,60,quark:iron_plate:1,20,STAINED_CLAY:12,15,STAINED_CLAY:15,5,AIR,7,IRON_BARS,12,CONCRETE:7,100)
RandomBlock(-8,17,-3,CONCRETE:7,60,quark:iron_plate:1,20,STAINED_CLAY:12,15,STAINED_CLAY:15,5,AIR,7,IRON_BARS,12,CONCRETE:7,100)
RandomBlock(-8,17,-2,CONCRETE:7,60,quark:iron_plate:1,20,STAINED_CLAY:12,15,STAINED_CLAY:15,5,AIR,7,IRON_BARS,12,CONCRETE:7,100)
RandomBlock(-8,17,-1,CONCRETE:7,60,quark:iron_plate:1,20,STAINED_CLAY:12,15,STAINED_CLAY:15,5,AIR,7,IRON_BARS,12,CONCRETE:7,100)
RandomBlock(-8,17,0,CONCRETE:7,60,quark:iron_plate:1,20,STAINED_CLAY:12,15,STAINED_CLAY:15,5,AIR,7,IRON_BARS,12,CONCRETE:7,100)
RandomBlock(-8,17,1,CONCRETE:7,60,quark:iron_plate:1,20,STAINED_CLAY:12,15,STAINED_CLAY:15,5,AIR,7,IRON_BARS,12,CONCRETE:7,100)
RandomBlock(-8,17,2,CONCRETE:7,60,quark:iron_plate:1,20,STAINED_CLAY:12,15,STAINED_CLAY:15,5,AIR,7,IRON_BARS,12,CONCRETE:7,100)
RandomBlock(-8,17,3,CONCRETE:7,60,quark:iron_plate:1,20,STAINED_CLAY:12,15,STAINED_CLAY:15,5,AIR,7,IRON_BARS,12,CONCRETE:7,100)
RandomBlock(-8,17,4,CONCRETE:7,60,quark:iron_plate:1,20,STAINED_CLAY:12,15,STAINED_CLAY:15,5,AIR,7,IRON_BARS,12,CONCRETE:7,100)
RandomBlock(-8,17,5,CONCRETE:7,60,quark:iron_plate:1,20,STAINED_CLAY:12,15,STAINED_CLAY:15,5,AIR,7,IRON_BARS,12,CONCRETE:7,100)
RandomBlock(-8,17,6,CONCRETE:7,60,quark:iron_plate:1,20,STAINED_CLAY:12,15,STAINED_CLAY:15,5,AIR,7,IRON_BARS,12,CONCRETE:7,100)
RandomBlock(-8,17,7,CONCRETE:7,60,quark:iron_plate:1,20,STAINED_CLAY:12,15,STAINED_CLAY:15,5,AIR,7,IRON_BARS,12,CONCRETE:7,100)
RandomBlock(-8,17,8,CONCRETE:7,60,quark:iron_plate:1,20,STAINED_CLAY:12,15,STAINED_CLAY:15,5,AIR,7,IRON_BARS,12,CONCRETE:7,100)
Block(-8,18,-5,CONCRETE:8)
Block(-8,18,-4,CONCRETE:8)
Block(-8,18,-3,CONCRETE:8)
Block(-8,18,-2,CONCRETE:8)
Block(-8,18,-1,CONCRETE:8)
Block(-8,18,0,CONCRETE:15)
Block(-8,18,1,CONCRETE:15)
Block(-8,18,2,CONCRETE:15)
Block(-8,18,3,CONCRETE:15)
Block(-8,18,4,CONCRETE:15)
Block(-8,18,5,CONCRETE:15)
Block(-8,18,6,CONCRETE:15)
Block(-8,18,7,CONCRETE:8)
Block(-8,18,8,CONCRETE:8)
Block(-8,19,-5,STAINED_GLASS:15)
Block(-8,19,0,FENCE:0)
Block(-8,19,1,WOOD_STAIRS:2)
Block(-8,19,2,WOOD_STAIRS:3)
Block(-8,19,3,FENCE:0)
Block(-8,19,4,WOOD_STAIRS:2)
Block(-8,19,5,WOOD_STAIRS:3)
Block(-8,19,6,FENCE:0)
Block(-8,20,-5,STAINED_GLASS:15)
Block(-8,20,0,WOOD_PLATE:0)
Block(-8,20,3,WOOD_PLATE:0)
Block(-8,20,6,WOOD_PLATE:0)
Block(-8,21,-5,STAINED_GLASS:15)
Block(-8,22,-5,STAINED_GLASS:15)
Block(-8,22,-2,LEAVES:4)
Block(-8,23,-5,STAINED_GLASS:15)
Block(-8,24,-5,STAINED_GLASS:15)
Block(-8,25,-5,STAINED_GLASS:15)
Block(-8,26,-5,STAINED_GLASS:15)
Block(-8,27,-5,STAINED_GLASS:15)
Block(-8,28,-5,STAINED_GLASS:15)
Block(-8,29,-5,STAINED_GLASS:15)
Block(-8,30,-5,STAINED_GLASS:15)
Block(-8,31,-5,STAINED_GLASS:15)
Block(-8,32,-5,STAINED_GLASS:15)
RandomBlock(-8,32,4,AIR,90,TRAP_DOOR:7,100)
Block(-8,33,-5,STAINED_GLASS:15)
Block(-8,34,-5,STAINED_GLASS:15)
Block(-8,35,-5,STAINED_GLASS:15)
Block(-8,36,-5,STAINED_GLASS:15)
Block(-8,37,-5,STAINED_GLASS:15)
Block(-8,38,-5,STAINED_GLASS:15)
Block(-8,39,-5,STAINED_GLASS:15)
Block(-8,40,-5,STAINED_GLASS:15)
Block(-8,41,-5,STAINED_GLASS:15)
Block(-8,42,6,STAINED_GLASS:15)
Block(-8,43,6,STAINED_GLASS:15)
Block(-8,44,6,STAINED_GLASS:15)
Block(-8,45,6,STAINED_GLASS:15)
Block(-8,46,6,STAINED_GLASS:15)
Block(-8,47,6,STAINED_GLASS:15)
Block(-8,48,6,STAINED_GLASS:15)
Block(-8,49,6,STAINED_GLASS:15)
Block(-8,50,6,STAINED_GLASS:15)
Block(-8,51,6,STAINED_GLASS:15)
Block(-8,51,7,CONCRETE:8)
Block(-8,51,8,CONCRETE:8)
Block(-8,52,6,STAINED_GLASS:15)
Block(-8,52,7,STAINED_GLASS_PANE:15)
Block(-8,52,8,STAINED_GLASS_PANE:15)
Block(-8,53,6,STAINED_GLASS:15)
Block(-8,54,6,STAINED_GLASS:15)
Block(-8,55,6,STAINED_GLASS:15)
Block(-8,56,6,STAINED_GLASS:15)
Block(-8,57,6,STAINED_GLASS:15)
Block(-8,58,6,STAINED_GLASS:15)
Block(-8,59,6,STAINED_GLASS:15)
Block(-8,60,6,CONCRETE:8)
Block(-8,61,6,CONCRETE:8)
Block(-8,61,7,CONCRETE:8)
Block(-8,61,8,CONCRETE:8)
Block(-8,62,6,CONCRETE:8)
Block(-8,62,7,CONCRETE:8)
Block(-8,62,8,CONCRETE:8)
RandomBlock(-7,0,-7,CONCRETE:7,60,quark:iron_plate:1,20,STAINED_CLAY:12,15,STAINED_CLAY:15,5,AIR,7,IRON_BARS,12,CONCRETE:7,100)
RandomBlock(-7,0,-6,CONCRETE:7,60,quark:iron_plate:1,20,STAINED_CLAY:12,15,STAINED_CLAY:15,5,AIR,7,IRON_BARS,12,CONCRETE:7,100)
RandomBlock(-7,0,-5,CONCRETE:7,60,quark:iron_plate:1,20,STAINED_CLAY:12,15,STAINED_CLAY:15,5,AIR,7,IRON_BARS,12,CONCRETE:7,100)
RandomBlock(-7,0,-4,CONCRETE:7,60,quark:iron_plate:1,20,STAINED_CLAY:12,15,STAINED_CLAY:15,5,AIR,7,IRON_BARS,12,CONCRETE:7,100)
RandomBlock(-7,0,-3,CONCRETE:7,60,quark:iron_plate:1,20,STAINED_CLAY:12,15,STAINED_CLAY:15,5,AIR,7,IRON_BARS,12,CONCRETE:7,100)
RandomBlock(-7,0,-2,CONCRETE:7,60,quark:iron_plate:1,20,STAINED_CLAY:12,15,STAINED_CLAY:15,5,AIR,7,IRON_BARS,12,CONCRETE:7,100)
RandomBlock(-7,0,-1,CONCRETE:7,60,quark:iron_plate:1,20,STAINED_CLAY:12,15,STAINED_CLAY:15,5,AIR,7,IRON_BARS,12,CONCRETE:7,100)
RandomBlock(-7,0,0,CONCRETE:7,60,quark:iron_plate:1,20,STAINED_CLAY:12,15,STAINED_CLAY:15,5,AIR,7,IRON_BARS,12,CONCRETE:7,100)
RandomBlock(-7,0,1,CONCRETE:7,60,quark:iron_plate:1,20,STAINED_CLAY:12,15,STAINED_CLAY:15,5,AIR,7,IRON_BARS,12,CONCRETE:7,100)
RandomBlock(-7,0,2,CONCRETE:7,60,quark:iron_plate:1,20,STAINED_CLAY:12,15,STAINED_CLAY:15,5,AIR,7,IRON_BARS,12,CONCRETE:7,100)
RandomBlock(-7,0,3,CONCRETE:7,60,quark:iron_plate:1,20,STAINED_CLAY:12,15,STAINED_CLAY:15,5,AIR,7,IRON_BARS,12,CONCRETE:7,100)
RandomBlock(-7,0,4,CONCRETE:7,60,quark:iron_plate:1,20,STAINED_CLAY:12,15,STAINED_CLAY:15,5,AIR,7,IRON_BARS,12,CONCRETE:7,100)
RandomBlock(-7,0,5,CONCRETE:7,60,quark:iron_plate:1,20,STAINED_CLAY:12,15,STAINED_CLAY:15,5,AIR,7,IRON_BARS,12,CONCRETE:7,100)
RandomBlock(-7,0,6,CONCRETE:7,60,quark:iron_plate:1,20,STAINED_CLAY:12,15,STAINED_CLAY:15,5,AIR,7,IRON_BARS,12,CONCRETE:7,100)
RandomBlock(-7,0,7,CONCRETE:7,60,quark:iron_plate:1,20,STAINED_CLAY:12,15,STAINED_CLAY:15,5,AIR,7,IRON_BARS,12,CONCRETE:7,100)
RandomBlock(-7,0,8,CONCRETE:7,60,quark:iron_plate:1,20,STAINED_CLAY:12,15,STAINED_CLAY:15,5,AIR,7,IRON_BARS,12,CONCRETE:7,100)
RandomBlock(-7,1,-7,CONCRETE:7,60,quark:iron_plate:1,20,STAINED_CLAY:12,15,STAINED_CLAY:15,5,AIR,7,IRON_BARS,12,CONCRETE:7,100)
RandomBlock(-7,1,-6,CONCRETE:7,60,quark:iron_plate:1,20,STAINED_CLAY:12,15,STAINED_CLAY:15,5,AIR,7,IRON_BARS,12,CONCRETE:7,100)
RandomBlock(-7,1,-5,CONCRETE:7,60,quark:iron_plate:1,20,STAINED_CLAY:12,15,STAINED_CLAY:15,5,AIR,7,IRON_BARS,12,CONCRETE:7,100)
RandomBlock(-7,1,-4,CONCRETE:7,60,quark:iron_plate:1,20,STAINED_CLAY:12,15,STAINED_CLAY:15,5,AIR,7,IRON_BARS,12,CONCRETE:7,100)
RandomBlock(-7,1,-3,CONCRETE:7,60,quark:iron_plate:1,20,STAINED_CLAY:12,15,STAINED_CLAY:15,5,AIR,7,IRON_BARS,12,CONCRETE:7,100)
RandomBlock(-7,1,-2,CONCRETE:7,60,quark:iron_plate:1,20,STAINED_CLAY:12,15,STAINED_CLAY:15,5,AIR,7,IRON_BARS,12,CONCRETE:7,100)
RandomBlock(-7,1,-1,CONCRETE:7,60,quark:iron_plate:1,20,STAINED_CLAY:12,15,STAINED_CLAY:15,5,AIR,7,IRON_BARS,12,CONCRETE:7,100)
RandomBlock(-7,1,0,CONCRETE:7,60,quark:iron_plate:1,20,STAINED_CLAY:12,15,STAINED_CLAY:15,5,AIR,7,IRON_BARS,12,CONCRETE:7,100)
RandomBlock(-7,1,1,CONCRETE:7,60,quark:iron_plate:1,20,STAINED_CLAY:12,15,STAINED_CLAY:15,5,AIR,7,IRON_BARS,12,CONCRETE:7,100)
RandomBlock(-7,1,2,CONCRETE:7,60,quark:iron_plate:1,20,STAINED_CLAY:12,15,STAINED_CLAY:15,5,AIR,7,IRON_BARS,12,CONCRETE:7,100)
Block(-7,1,3,STATIONARY_WATER:0)
Block(-7,1,4,STATIONARY_WATER:0)
RandomBlock(-7,1,5,CONCRETE:7,60,quark:iron_plate:1,20,STAINED_CLAY:12,15,STAINED_CLAY:15,5,AIR,7,IRON_BARS,12,CONCRETE:7,100)
RandomBlock(-7,1,6,CONCRETE:7,60,quark:iron_plate:1,20,STAINED_CLAY:12,15,STAINED_CLAY:15,5,AIR,7,IRON_BARS,12,CONCRETE:7,100)
RandomBlock(-7,1,7,CONCRETE:7,60,quark:iron_plate:1,20,STAINED_CLAY:12,15,STAINED_CLAY:15,5,AIR,7,IRON_BARS,12,CONCRETE:7,100)
RandomBlock(-7,1,8,CONCRETE:7,60,quark:iron_plate:1,20,STAINED_CLAY:12,15,STAINED_CLAY:15,5,AIR,7,IRON_BARS,12,CONCRETE:7,100)
RandomBlock(-7,2,-7,CONCRETE:7,60,quark:iron_plate:1,20,STAINED_CLAY:12,15,STAINED_CLAY:15,5,AIR,7,IRON_BARS,12,CONCRETE:7,100)
RandomBlock(-7,2,-6,CONCRETE:7,60,quark:iron_plate:1,20,STAINED_CLAY:12,15,STAINED_CLAY:15,5,AIR,7,IRON_BARS,12,CONCRETE:7,100)
RandomBlock(-7,2,-5,CONCRETE:7,60,quark:iron_plate:1,20,STAINED_CLAY:12,15,STAINED_CLAY:15,5,AIR,7,IRON_BARS,12,CONCRETE:7,100)
RandomBlock(-7,2,-4,CONCRETE:7,60,quark:iron_plate:1,20,STAINED_CLAY:12,15,STAINED_CLAY:15,5,AIR,7,IRON_BARS,12,CONCRETE:7,100)
RandomBlock(-7,2,-3,CONCRETE:7,60,quark:iron_plate:1,20,STAINED_CLAY:12,15,STAINED_CLAY:15,5,AIR,7,IRON_BARS,12,CONCRETE:7,100)
RandomBlock(-7,2,-2,CONCRETE:7,60,quark:iron_plate:1,20,STAINED_CLAY:12,15,STAINED_CLAY:15,5,AIR,7,IRON_BARS,12,CONCRETE:7,100)
RandomBlock(-7,2,-1,CONCRETE:7,60,quark:iron_plate:1,20,STAINED_CLAY:12,15,STAINED_CLAY:15,5,AIR,7,IRON_BARS,12,CONCRETE:7,100)
RandomBlock(-7,2,0,CONCRETE:7,60,quark:iron_plate:1,20,STAINED_CLAY:12,15,STAINED_CLAY:15,5,AIR,7,IRON_BARS,12,CONCRETE:7,100)
RandomBlock(-7,2,1,CONCRETE:7,60,quark:iron_plate:1,20,STAINED_CLAY:12,15,STAINED_CLAY:15,5,AIR,7,IRON_BARS,12,CONCRETE:7,100)
Block(-7,2,2,SMOOTH_STAIRS:3)
Block(-7,2,3,AIR:0)
Block(-7,2,4,AIR:0)
Block(-7,2,5,SMOOTH_STAIRS:2)
RandomBlock(-7,2,6,CONCRETE:7,60,quark:iron_plate:1,20,STAINED_CLAY:12,15,STAINED_CLAY:15,5,AIR,7,IRON_BARS,12,CONCRETE:7,100)
RandomBlock(-7,2,7,CONCRETE:7,60,quark:iron_plate:1,20,STAINED_CLAY:12,15,STAINED_CLAY:15,5,AIR,7,IRON_BARS,12,CONCRETE:7,100)
RandomBlock(-7,2,8,CONCRETE:7,60,quark:iron_plate:1,20,STAINED_CLAY:12,15,STAINED_CLAY:15,5,AIR,7,IRON_BARS,12,CONCRETE:7,100)
Block(-7,3,-7,AIR:0)
Block(-7,3,-6,AIR:0)
Block(-7,3,-5,AIR:0)
Block(-7,3,-4,AIR:0)
Block(-7,3,-3,AIR:0)
Block(-7,3,-2,AIR:0)
Block(-7,3,-1,AIR:0)
Block(-7,3,0,AIR:0)
Block(-7,3,1,AIR:0)
Block(-7,3,2,AIR:0)
Block(-7,3,3,AIR:0)
Block(-7,3,4,AIR:0)
Block(-7,3,5,AIR:0)
Block(-7,3,6,AIR:0)
Block(-7,3,7,AIR:0)
RandomBlock(-7,3,8,CONCRETE:7,60,quark:iron_plate:1,20,STAINED_CLAY:12,15,STAINED_CLAY:15,5,AIR,7,IRON_BARS,12,CONCRETE:7,100)
Block(-7,4,-7,AIR:0)
Block(-7,4,-6,AIR:0)
Block(-7,4,-5,AIR:0)
Block(-7,4,-4,AIR:0)
Block(-7,4,-3,AIR:0)
Block(-7,4,-2,AIR:0)
Block(-7,4,-1,AIR:0)
Block(-7,4,0,AIR:0)
Block(-7,4,1,AIR:0)
Block(-7,4,2,AIR:0)
Block(-7,4,3,AIR:0)
Block(-7,4,4,AIR:0)
Block(-7,4,5,AIR:0)
Block(-7,4,6,AIR:0)
Block(-7,4,7,AIR:0)
RandomBlock(-7,4,8,CONCRETE:7,60,quark:iron_plate:1,20,STAINED_CLAY:12,15,STAINED_CLAY:15,5,AIR,7,IRON_BARS,12,CONCRETE:7,100)
Block(-7,5,-7,AIR:0)
Block(-7,5,-6,AIR:0)
Block(-7,5,-5,AIR:0)
Block(-7,5,-4,AIR:0)
Block(-7,5,-3,AIR:0)
Block(-7,5,-2,AIR:0)
Block(-7,5,-1,AIR:0)
Block(-7,5,0,AIR:0)
Block(-7,5,1,AIR:0)
Block(-7,5,2,AIR:0)
Block(-7,5,3,AIR:0)
Block(-7,5,4,AIR:0)
Block(-7,5,5,AIR:0)
Block(-7,5,6,CONCRETE:12)
Block(-7,5,7,CONCRETE:4)
RandomBlock(-7,5,8,CONCRETE:7,60,quark:iron_plate:1,20,STAINED_CLAY:12,15,STAINED_CLAY:15,5,AIR,7,IRON_BARS,12,CONCRETE:7,100)
RandomBlock(-7,6,-7,CONCRETE:7,60,quark:iron_plate:1,20,STAINED_CLAY:12,15,STAINED_CLAY:15,5,AIR,7,IRON_BARS,12,CONCRETE:7,100)
Block(-7,6,-6,AIR:0)
Block(-7,6,-5,AIR:0)
Block(-7,6,-4,AIR:0)
Block(-7,6,-3,AIR:0)
Block(-7,6,-2,AIR:0)
Block(-7,6,-1,AIR:0)
Block(-7,6,0,AIR:0)
Block(-7,6,1,AIR:0)
Block(-7,6,2,AIR:0)
Block(-7,6,3,AIR:0)
Block(-7,6,4,AIR:0)
Block(-7,6,5,AIR:0)
Block(-7,6,6,IRON_FENCE:0)
Block(-7,6,7,AIR:0)
RandomBlock(-7,6,8,CONCRETE:7,60,quark:iron_plate:1,20,STAINED_CLAY:12,15,STAINED_CLAY:15,5,AIR,7,IRON_BARS,12,CONCRETE:7,100)
RandomBlock(-7,7,-7,CONCRETE:7,60,quark:iron_plate:1,20,STAINED_CLAY:12,15,STAINED_CLAY:15,5,AIR,7,IRON_BARS,12,CONCRETE:7,100)
RandomBlock(-7,7,-6,CONCRETE:7,60,quark:iron_plate:1,20,STAINED_CLAY:12,15,STAINED_CLAY:15,5,AIR,7,IRON_BARS,12,CONCRETE:7,100)
RandomBlock(-7,7,-5,CONCRETE:7,60,quark:iron_plate:1,20,STAINED_CLAY:12,15,STAINED_CLAY:15,5,AIR,7,IRON_BARS,12,CONCRETE:7,100)
RandomBlock(-7,7,-4,CONCRETE:7,60,quark:iron_plate:1,20,STAINED_CLAY:12,15,STAINED_CLAY:15,5,AIR,7,IRON_BARS,12,CONCRETE:7,100)
RandomBlock(-7,7,-3,CONCRETE:7,60,quark:iron_plate:1,20,STAINED_CLAY:12,15,STAINED_CLAY:15,5,AIR,7,IRON_BARS,12,CONCRETE:7,100)
RandomBlock(-7,7,-2,CONCRETE:7,60,quark:iron_plate:1,20,STAINED_CLAY:12,15,STAINED_CLAY:15,5,AIR,7,IRON_BARS,12,CONCRETE:7,100)
RandomBlock(-7,7,-1,CONCRETE:7,60,quark:iron_plate:1,20,STAINED_CLAY:12,15,STAINED_CLAY:15,5,AIR,7,IRON_BARS,12,CONCRETE:7,100)
RandomBlock(-7,7,0,CONCRETE:7,60,quark:iron_plate:1,20,STAINED_CLAY:12,15,STAINED_CLAY:15,5,AIR,7,IRON_BARS,12,CONCRETE:7,100)
RandomBlock(-7,7,1,CONCRETE:7,60,quark:iron_plate:1,20,STAINED_CLAY:12,15,STAINED_CLAY:15,5,AIR,7,IRON_BARS,12,CONCRETE:7,100)
RandomBlock(-7,7,2,CONCRETE:7,60,quark:iron_plate:1,20,STAINED_CLAY:12,15,STAINED_CLAY:15,5,AIR,7,IRON_BARS,12,CONCRETE:7,100)
RandomBlock(-7,7,3,CONCRETE:7,60,quark:iron_plate:1,20,STAINED_CLAY:12,15,STAINED_CLAY:15,5,AIR,7,IRON_BARS,12,CONCRETE:7,100)
RandomBlock(-7,7,4,CONCRETE:7,60,quark:iron_plate:1,20,STAINED_CLAY:12,15,STAINED_CLAY:15,5,AIR,7,IRON_BARS,12,CONCRETE:7,100)
RandomBlock(-7,7,5,CONCRETE:7,60,quark:iron_plate:1,20,STAINED_CLAY:12,15,STAINED_CLAY:15,5,AIR,7,IRON_BARS,12,CONCRETE:7,100)
RandomBlock(-7,7,6,CONCRETE:7,60,quark:iron_plate:1,20,STAINED_CLAY:12,15,STAINED_CLAY:15,5,AIR,7,IRON_BARS,12,CONCRETE:7,100)
RandomBlock(-7,7,7,CONCRETE:7,60,quark:iron_plate:1,20,STAINED_CLAY:12,15,STAINED_CLAY:15,5,AIR,7,IRON_BARS,12,CONCRETE:7,100)
RandomBlock(-7,7,8,CONCRETE:7,60,quark:iron_plate:1,20,STAINED_CLAY:12,15,STAINED_CLAY:15,5,AIR,7,IRON_BARS,12,CONCRETE:7,100)
RandomBlock(-7,8,-7,CONCRETE:7,60,quark:iron_plate:1,20,STAINED_CLAY:12,15,STAINED_CLAY:15,5,AIR,7,IRON_BARS,12,CONCRETE:7,100)
RandomBlock(-7,8,-6,CONCRETE:7,60,quark:iron_plate:1,20,STAINED_CLAY:12,15,STAINED_CLAY:15,5,AIR,7,IRON_BARS,12,CONCRETE:7,100)
RandomBlock(-7,8,-5,CONCRETE:7,60,quark:iron_plate:1,20,STAINED_CLAY:12,15,STAINED_CLAY:15,5,AIR,7,IRON_BARS,12,CONCRETE:7,100)
RandomBlock(-7,8,-4,CONCRETE:7,60,quark:iron_plate:1,20,STAINED_CLAY:12,15,STAINED_CLAY:15,5,AIR,7,IRON_BARS,12,CONCRETE:7,100)
RandomBlock(-7,8,-3,CONCRETE:7,60,quark:iron_plate:1,20,STAINED_CLAY:12,15,STAINED_CLAY:15,5,AIR,7,IRON_BARS,12,CONCRETE:7,100)
RandomBlock(-7,8,-2,CONCRETE:7,60,quark:iron_plate:1,20,STAINED_CLAY:12,15,STAINED_CLAY:15,5,AIR,7,IRON_BARS,12,CONCRETE:7,100)
RandomBlock(-7,8,-1,CONCRETE:7,60,quark:iron_plate:1,20,STAINED_CLAY:12,15,STAINED_CLAY:15,5,AIR,7,IRON_BARS,12,CONCRETE:7,100)
RandomBlock(-7,8,0,CONCRETE:7,60,quark:iron_plate:1,20,STAINED_CLAY:12,15,STAINED_CLAY:15,5,AIR,7,IRON_BARS,12,CONCRETE:7,100)
RandomBlock(-7,8,1,CONCRETE:7,60,quark:iron_plate:1,20,STAINED_CLAY:12,15,STAINED_CLAY:15,5,AIR,7,IRON_BARS,12,CONCRETE:7,100)
RandomBlock(-7,8,2,CONCRETE:7,60,quark:iron_plate:1,20,STAINED_CLAY:12,15,STAINED_CLAY:15,5,AIR,7,IRON_BARS,12,CONCRETE:7,100)
RandomBlock(-7,8,3,CONCRETE:7,60,quark:iron_plate:1,20,STAINED_CLAY:12,15,STAINED_CLAY:15,5,AIR,7,IRON_BARS,12,CONCRETE:7,100)
RandomBlock(-7,8,4,CONCRETE:7,60,quark:iron_plate:1,20,STAINED_CLAY:12,15,STAINED_CLAY:15,5,AIR,7,IRON_BARS,12,CONCRETE:7,100)
Block(-7,8,5,STEP:0)
Block(-7,8,6,STEP:0)
Block(-7,8,7,STEP:0)
Block(-7,8,8,STEP:0)
RandomBlock(-7,9,-7,CONCRETE:7,60,quark:iron_plate:1,20,STAINED_CLAY:12,15,STAINED_CLAY:15,5,AIR,7,IRON_BARS,12,CONCRETE:7,100)
RandomBlock(-7,9,-6,CONCRETE:7,60,quark:iron_plate:1,20,STAINED_CLAY:12,15,STAINED_CLAY:15,5,AIR,7,IRON_BARS,12,CONCRETE:7,100)
RandomBlock(-7,9,-5,CONCRETE:7,60,quark:iron_plate:1,20,STAINED_CLAY:12,15,STAINED_CLAY:15,5,AIR,7,IRON_BARS,12,CONCRETE:7,100)
RandomBlock(-7,9,-4,CONCRETE:7,60,quark:iron_plate:1,20,STAINED_CLAY:12,15,STAINED_CLAY:15,5,AIR,7,IRON_BARS,12,CONCRETE:7,100)
RandomBlock(-7,9,-3,CONCRETE:7,60,quark:iron_plate:1,20,STAINED_CLAY:12,15,STAINED_CLAY:15,5,AIR,7,IRON_BARS,12,CONCRETE:7,100)
RandomBlock(-7,9,-2,CONCRETE:7,60,quark:iron_plate:1,20,STAINED_CLAY:12,15,STAINED_CLAY:15,5,AIR,7,IRON_BARS,12,CONCRETE:7,100)
RandomBlock(-7,9,-1,CONCRETE:7,60,quark:iron_plate:1,20,STAINED_CLAY:12,15,STAINED_CLAY:15,5,AIR,7,IRON_BARS,12,CONCRETE:7,100)
RandomBlock(-7,9,0,CONCRETE:7,60,quark:iron_plate:1,20,STAINED_CLAY:12,15,STAINED_CLAY:15,5,AIR,7,IRON_BARS,12,CONCRETE:7,100)
RandomBlock(-7,9,1,CONCRETE:7,60,quark:iron_plate:1,20,STAINED_CLAY:12,15,STAINED_CLAY:15,5,AIR,7,IRON_BARS,12,CONCRETE:7,100)
Block(-7,9,2,LEVER:10)
RandomBlock(-7,9,3,CONCRETE:7,60,quark:iron_plate:1,20,STAINED_CLAY:12,15,STAINED_CLAY:15,5,AIR,7,IRON_BARS,12,CONCRETE:7,100)
RandomBlock(-7,9,4,CONCRETE:7,60,quark:iron_plate:1,20,STAINED_CLAY:12,15,STAINED_CLAY:15,5,AIR,7,IRON_BARS,12,CONCRETE:7,100)
Block(-7,9,5,AIR:0)
Block(-7,9,6,AIR:0)
RandomBlock(-7,9,7,AIR,90,IRON_TRAPDOOR:10,100)
RandomBlock(-7,9,8,AIR,90,IRON_TRAPDOOR:10,100)
RandomBlock(-7,10,-7,CONCRETE:7,60,quark:iron_plate:1,20,STAINED_CLAY:12,15,STAINED_CLAY:15,5,AIR,7,IRON_BARS,12,CONCRETE:7,100)
RandomBlock(-7,10,-6,CONCRETE:7,60,quark:iron_plate:1,20,STAINED_CLAY:12,15,STAINED_CLAY:15,5,AIR,7,IRON_BARS,12,CONCRETE:7,100)
RandomBlock(-7,10,-5,CONCRETE:7,60,quark:iron_plate:1,20,STAINED_CLAY:12,15,STAINED_CLAY:15,5,AIR,7,IRON_BARS,12,CONCRETE:7,100)
RandomBlock(-7,10,-4,CONCRETE:7,60,quark:iron_plate:1,20,STAINED_CLAY:12,15,STAINED_CLAY:15,5,AIR,7,IRON_BARS,12,CONCRETE:7,100)
Block(-7,10,-3,SMOOTH_STAIRS:1)
Block(-7,10,-2,SMOOTH_STAIRS:1)
RandomBlock(-7,10,-1,CONCRETE:7,60,quark:iron_plate:1,20,STAINED_CLAY:12,15,STAINED_CLAY:15,5,AIR,7,IRON_BARS,12,CONCRETE:7,100)
RandomBlock(-7,10,0,CONCRETE:7,60,quark:iron_plate:1,20,STAINED_CLAY:12,15,STAINED_CLAY:15,5,AIR,7,IRON_BARS,12,CONCRETE:7,100)
Block(-7,10,1,IRON_FENCE:0)
Block(-7,10,2,IRON_FENCE:0)
Block(-7,10,3,IRON_FENCE:0)
RandomBlock(-7,10,4,CONCRETE:7,60,quark:iron_plate:1,20,STAINED_CLAY:12,15,STAINED_CLAY:15,5,AIR,7,IRON_BARS,12,CONCRETE:7,100)
Block(-7,10,5,AIR:0)
Block(-7,10,6,AIR:0)
Block(-7,10,7,IRON_FENCE:0)
Block(-7,10,8,AIR:0)
RandomBlock(-7,11,-7,CONCRETE:7,60,quark:iron_plate:1,20,STAINED_CLAY:12,15,STAINED_CLAY:15,5,AIR,7,IRON_BARS,12,CONCRETE:7,100)
RandomBlock(-7,11,-6,CONCRETE:7,60,quark:iron_plate:1,20,STAINED_CLAY:12,15,STAINED_CLAY:15,5,AIR,7,IRON_BARS,12,CONCRETE:7,100)
RandomBlock(-7,11,-5,CONCRETE:7,60,quark:iron_plate:1,20,STAINED_CLAY:12,15,STAINED_CLAY:15,5,AIR,7,IRON_BARS,12,CONCRETE:7,100)
RandomBlock(-7,11,-4,CONCRETE:7,60,quark:iron_plate:1,20,STAINED_CLAY:12,15,STAINED_CLAY:15,5,AIR,7,IRON_BARS,12,CONCRETE:7,100)
Block(-7,11,-3,AIR:0)
Block(-7,11,-2,AIR:0)
RandomBlock(-7,11,-1,CONCRETE:7,60,quark:iron_plate:1,20,STAINED_CLAY:12,15,STAINED_CLAY:15,5,AIR,7,IRON_BARS,12,CONCRETE:7,100)
RandomBlock(-7,11,0,CONCRETE:7,60,quark:iron_plate:1,20,STAINED_CLAY:12,15,STAINED_CLAY:15,5,AIR,7,IRON_BARS,12,CONCRETE:7,100)
Block(-7,11,1,IRON_FENCE:0)
Block(-7,11,2,IRON_FENCE:0)
Block(-7,11,3,IRON_FENCE:0)
RandomBlock(-7,11,4,CONCRETE:7,60,quark:iron_plate:1,20,STAINED_CLAY:12,15,STAINED_CLAY:15,5,AIR,7,IRON_BARS,12,CONCRETE:7,100)
Block(-7,11,5,AIR:0)
Block(-7,11,6,AIR:0)
Block(-7,11,7,AIR:0)
Block(-7,11,8,AIR:0)
RandomBlock(-7,12,-7,CONCRETE:7,60,quark:iron_plate:1,20,STAINED_CLAY:12,15,STAINED_CLAY:15,5,AIR,7,IRON_BARS,12,CONCRETE:7,100)
RandomBlock(-7,12,-6,CONCRETE:7,60,quark:iron_plate:1,20,STAINED_CLAY:12,15,STAINED_CLAY:15,5,AIR,7,IRON_BARS,12,CONCRETE:7,100)
RandomBlock(-7,12,-5,CONCRETE:7,60,quark:iron_plate:1,20,STAINED_CLAY:12,15,STAINED_CLAY:15,5,AIR,7,IRON_BARS,12,CONCRETE:7,100)
RandomBlock(-7,12,-4,CONCRETE:7,60,quark:iron_plate:1,20,STAINED_CLAY:12,15,STAINED_CLAY:15,5,AIR,7,IRON_BARS,12,CONCRETE:7,100)
Block(-7,12,-3,AIR:0)
Block(-7,12,-2,AIR:0)
RandomBlock(-7,12,-1,CONCRETE:7,60,quark:iron_plate:1,20,STAINED_CLAY:12,15,STAINED_CLAY:15,5,AIR,7,IRON_BARS,12,CONCRETE:7,100)
RandomBlock(-7,12,0,CONCRETE:7,60,quark:iron_plate:1,20,STAINED_CLAY:12,15,STAINED_CLAY:15,5,AIR,7,IRON_BARS,12,CONCRETE:7,100)
Block(-7,12,1,IRON_FENCE:0)
Block(-7,12,2,IRON_FENCE:0)
Block(-7,12,3,IRON_FENCE:0)
RandomBlock(-7,12,4,CONCRETE:7,60,quark:iron_plate:1,20,STAINED_CLAY:12,15,STAINED_CLAY:15,5,AIR,7,IRON_BARS,12,CONCRETE:7,100)
Block(-7,12,5,AIR:0)
Block(-7,12,6,AIR:0)
Block(-7,12,7,AIR:0)
Block(-7,12,8,AIR:0)
RandomBlock(-7,13,-7,CONCRETE:7,60,quark:iron_plate:1,20,STAINED_CLAY:12,15,STAINED_CLAY:15,5,AIR,7,IRON_BARS,12,CONCRETE:7,100)
RandomBlock(-7,13,-6,CONCRETE:7,60,quark:iron_plate:1,20,STAINED_CLAY:12,15,STAINED_CLAY:15,5,AIR,7,IRON_BARS,12,CONCRETE:7,100)
RandomBlock(-7,13,-5,CONCRETE:7,60,quark:iron_plate:1,20,STAINED_CLAY:12,15,STAINED_CLAY:15,5,AIR,7,IRON_BARS,12,CONCRETE:7,100)
RandomBlock(-7,13,-4,CONCRETE:7,60,quark:iron_plate:1,20,STAINED_CLAY:12,15,STAINED_CLAY:15,5,AIR,7,IRON_BARS,12,CONCRETE:7,100)
Block(-7,13,-3,AIR:0)
Block(-7,13,-2,AIR:0)
RandomBlock(-7,13,-1,CONCRETE:7,60,quark:iron_plate:1,20,STAINED_CLAY:12,15,STAINED_CLAY:15,5,AIR,7,IRON_BARS,12,CONCRETE:7,100)
RandomBlock(-7,13,0,CONCRETE:7,60,quark:iron_plate:1,20,STAINED_CLAY:12,15,STAINED_CLAY:15,5,AIR,7,IRON_BARS,12,CONCRETE:7,100)
RandomBlock(-7,13,1,CONCRETE:7,60,quark:iron_plate:1,20,STAINED_CLAY:12,15,STAINED_CLAY:15,5,AIR,7,IRON_BARS,12,CONCRETE:7,100)
Block(-7,13,2,LEVER:10)
RandomBlock(-7,13,3,CONCRETE:7,60,quark:iron_plate:1,20,STAINED_CLAY:12,15,STAINED_CLAY:15,5,AIR,7,IRON_BARS,12,CONCRETE:7,100)
RandomBlock(-7,13,4,CONCRETE:7,60,quark:iron_plate:1,20,STAINED_CLAY:12,15,STAINED_CLAY:15,5,AIR,7,IRON_BARS,12,CONCRETE:7,100)
Block(-7,13,5,AIR:0)
Block(-7,13,6,AIR:0)
Block(-7,13,7,AIR:0)
Block(-7,13,8,AIR:0)
RandomBlock(-7,14,-7,CONCRETE:7,60,quark:iron_plate:1,20,STAINED_CLAY:12,15,STAINED_CLAY:15,5,AIR,7,IRON_BARS,12,CONCRETE:7,100)
RandomBlock(-7,14,-6,CONCRETE:7,60,quark:iron_plate:1,20,STAINED_CLAY:12,15,STAINED_CLAY:15,5,AIR,7,IRON_BARS,12,CONCRETE:7,100)
RandomBlock(-7,14,-5,CONCRETE:7,60,quark:iron_plate:1,20,STAINED_CLAY:12,15,STAINED_CLAY:15,5,AIR,7,IRON_BARS,12,CONCRETE:7,100)
RandomBlock(-7,14,-4,CONCRETE:7,60,quark:iron_plate:1,20,STAINED_CLAY:12,15,STAINED_CLAY:15,5,AIR,7,IRON_BARS,12,CONCRETE:7,100)
Block(-7,14,-3,SMOOTH_STAIRS:4)
Block(-7,14,-2,SMOOTH_STAIRS:4)
RandomBlock(-7,14,-1,CONCRETE:7,60,quark:iron_plate:1,20,STAINED_CLAY:12,15,STAINED_CLAY:15,5,AIR,7,IRON_BARS,12,CONCRETE:7,100)
RandomBlock(-7,14,0,CONCRETE:7,60,quark:iron_plate:1,20,STAINED_CLAY:12,15,STAINED_CLAY:15,5,AIR,7,IRON_BARS,12,CONCRETE:7,100)
Block(-7,14,1,IRON_FENCE:0)
Block(-7,14,2,IRON_FENCE:0)
Block(-7,14,3,IRON_FENCE:0)
RandomBlock(-7,14,4,CONCRETE:7,60,quark:iron_plate:1,20,STAINED_CLAY:12,15,STAINED_CLAY:15,5,AIR,7,IRON_BARS,12,CONCRETE:7,100)
Block(-7,14,5,AIR:0)
Block(-7,14,6,STEP:8)
Block(-7,14,7,AIR:0)
Block(-7,14,8,STEP:8)
RandomBlock(-7,15,-7,CONCRETE:7,60,quark:iron_plate:1,20,STAINED_CLAY:12,15,STAINED_CLAY:15,5,AIR,7,IRON_BARS,12,CONCRETE:7,100)
RandomBlock(-7,15,-6,CONCRETE:7,60,quark:iron_plate:1,20,STAINED_CLAY:12,15,STAINED_CLAY:15,5,AIR,7,IRON_BARS,12,CONCRETE:7,100)
RandomBlock(-7,15,-5,CONCRETE:7,60,quark:iron_plate:1,20,STAINED_CLAY:12,15,STAINED_CLAY:15,5,AIR,7,IRON_BARS,12,CONCRETE:7,100)
RandomBlock(-7,15,-4,CONCRETE:7,60,quark:iron_plate:1,20,STAINED_CLAY:12,15,STAINED_CLAY:15,5,AIR,7,IRON_BARS,12,CONCRETE:7,100)
RandomBlock(-7,15,-3,CONCRETE:7,60,quark:iron_plate:1,20,STAINED_CLAY:12,15,STAINED_CLAY:15,5,AIR,7,IRON_BARS,12,CONCRETE:7,100)
RandomBlock(-7,15,-2,CONCRETE:7,60,quark:iron_plate:1,20,STAINED_CLAY:12,15,STAINED_CLAY:15,5,AIR,7,IRON_BARS,12,CONCRETE:7,100)
RandomBlock(-7,15,-1,CONCRETE:7,60,quark:iron_plate:1,20,STAINED_CLAY:12,15,STAINED_CLAY:15,5,AIR,7,IRON_BARS,12,CONCRETE:7,100)
RandomBlock(-7,15,0,CONCRETE:7,60,quark:iron_plate:1,20,STAINED_CLAY:12,15,STAINED_CLAY:15,5,AIR,7,IRON_BARS,12,CONCRETE:7,100)
Block(-7,15,1,IRON_FENCE:0)
Block(-7,15,2,IRON_FENCE:0)
Block(-7,15,3,IRON_FENCE:0)
RandomBlock(-7,15,4,CONCRETE:7,60,quark:iron_plate:1,20,STAINED_CLAY:12,15,STAINED_CLAY:15,5,AIR,7,IRON_BARS,12,CONCRETE:7,100)
Block(-7,15,5,AIR:0)
RandomBlock(-7,15,6,CONCRETE:7,60,quark:iron_plate:1,20,STAINED_CLAY:12,15,STAINED_CLAY:15,5,AIR,7,IRON_BARS,12,CONCRETE:7,100)
Block(-7,15,7,AIR:0)
RandomBlock(-7,15,8,CONCRETE:7,60,quark:iron_plate:1,20,STAINED_CLAY:12,15,STAINED_CLAY:15,5,AIR,7,IRON_BARS,12,CONCRETE:7,100)
RandomBlock(-7,16,-7,CONCRETE:7,60,quark:iron_plate:1,20,STAINED_CLAY:12,15,STAINED_CLAY:15,5,AIR,7,IRON_BARS,12,CONCRETE:7,100)
RandomBlock(-7,16,-6,CONCRETE:7,60,quark:iron_plate:1,20,STAINED_CLAY:12,15,STAINED_CLAY:15,5,AIR,7,IRON_BARS,12,CONCRETE:7,100)
RandomBlock(-7,16,-5,CONCRETE:7,60,quark:iron_plate:1,20,STAINED_CLAY:12,15,STAINED_CLAY:15,5,AIR,7,IRON_BARS,12,CONCRETE:7,100)
RandomBlock(-7,16,-4,CONCRETE:7,60,quark:iron_plate:1,20,STAINED_CLAY:12,15,STAINED_CLAY:15,5,AIR,7,IRON_BARS,12,CONCRETE:7,100)
RandomBlock(-7,16,-3,CONCRETE:7,60,quark:iron_plate:1,20,STAINED_CLAY:12,15,STAINED_CLAY:15,5,AIR,7,IRON_BARS,12,CONCRETE:7,100)
RandomBlock(-7,16,-2,CONCRETE:7,60,quark:iron_plate:1,20,STAINED_CLAY:12,15,STAINED_CLAY:15,5,AIR,7,IRON_BARS,12,CONCRETE:7,100)
RandomBlock(-7,16,-1,CONCRETE:7,60,quark:iron_plate:1,20,STAINED_CLAY:12,15,STAINED_CLAY:15,5,AIR,7,IRON_BARS,12,CONCRETE:7,100)
RandomBlock(-7,16,0,CONCRETE:7,60,quark:iron_plate:1,20,STAINED_CLAY:12,15,STAINED_CLAY:15,5,AIR,7,IRON_BARS,12,CONCRETE:7,100)
Block(-7,16,1,IRON_FENCE:0)
Block(-7,16,2,IRON_FENCE:0)
Block(-7,16,3,IRON_FENCE:0)
RandomBlock(-7,16,4,CONCRETE:7,60,quark:iron_plate:1,20,STAINED_CLAY:12,15,STAINED_CLAY:15,5,AIR,7,IRON_BARS,12,CONCRETE:7,100)
Block(-7,16,5,AIR:0)
Block(-7,16,6,AIR:0)
Block(-7,16,7,AIR:0)
Block(-7,16,8,AIR:0)
RandomBlock(-7,17,-7,CONCRETE:7,60,quark:iron_plate:1,20,STAINED_CLAY:12,15,STAINED_CLAY:15,5,AIR,7,IRON_BARS,12,CONCRETE:7,100)
RandomBlock(-7,17,-6,CONCRETE:7,60,quark:iron_plate:1,20,STAINED_CLAY:12,15,STAINED_CLAY:15,5,AIR,7,IRON_BARS,12,CONCRETE:7,100)
RandomBlock(-7,17,-5,CONCRETE:7,60,quark:iron_plate:1,20,STAINED_CLAY:12,15,STAINED_CLAY:15,5,AIR,7,IRON_BARS,12,CONCRETE:7,100)
RandomBlock(-7,17,-4,CONCRETE:7,60,quark:iron_plate:1,20,STAINED_CLAY:12,15,STAINED_CLAY:15,5,AIR,7,IRON_BARS,12,CONCRETE:7,100)
RandomBlock(-7,17,-3,CONCRETE:7,60,quark:iron_plate:1,20,STAINED_CLAY:12,15,STAINED_CLAY:15,5,AIR,7,IRON_BARS,12,CONCRETE:7,100)
RandomBlock(-7,17,-2,CONCRETE:7,60,quark:iron_plate:1,20,STAINED_CLAY:12,15,STAINED_CLAY:15,5,AIR,7,IRON_BARS,12,CONCRETE:7,100)
RandomBlock(-7,17,-1,CONCRETE:7,60,quark:iron_plate:1,20,STAINED_CLAY:12,15,STAINED_CLAY:15,5,AIR,7,IRON_BARS,12,CONCRETE:7,100)
RandomBlock(-7,17,0,CONCRETE:7,60,quark:iron_plate:1,20,STAINED_CLAY:12,15,STAINED_CLAY:15,5,AIR,7,IRON_BARS,12,CONCRETE:7,100)
RandomBlock(-7,17,1,CONCRETE:7,60,quark:iron_plate:1,20,STAINED_CLAY:12,15,STAINED_CLAY:15,5,AIR,7,IRON_BARS,12,CONCRETE:7,100)
RandomBlock(-7,17,2,CONCRETE:7,60,quark:iron_plate:1,20,STAINED_CLAY:12,15,STAINED_CLAY:15,5,AIR,7,IRON_BARS,12,CONCRETE:7,100)
RandomBlock(-7,17,3,CONCRETE:7,60,quark:iron_plate:1,20,STAINED_CLAY:12,15,STAINED_CLAY:15,5,AIR,7,IRON_BARS,12,CONCRETE:7,100)
RandomBlock(-7,17,4,CONCRETE:7,60,quark:iron_plate:1,20,STAINED_CLAY:12,15,STAINED_CLAY:15,5,AIR,7,IRON_BARS,12,CONCRETE:7,100)
RandomBlock(-7,17,5,CONCRETE:7,60,quark:iron_plate:1,20,STAINED_CLAY:12,15,STAINED_CLAY:15,5,AIR,7,IRON_BARS,12,CONCRETE:7,100)
RandomBlock(-7,17,6,CONCRETE:7,60,quark:iron_plate:1,20,STAINED_CLAY:12,15,STAINED_CLAY:15,5,AIR,7,IRON_BARS,12,CONCRETE:7,100)
RandomBlock(-7,17,7,CONCRETE:7,60,quark:iron_plate:1,20,STAINED_CLAY:12,15,STAINED_CLAY:15,5,AIR,7,IRON_BARS,12,CONCRETE:7,100)
RandomBlock(-7,17,8,CONCRETE:7,60,quark:iron_plate:1,20,STAINED_CLAY:12,15,STAINED_CLAY:15,5,AIR,7,IRON_BARS,12,CONCRETE:7,100)
Block(-7,18,-5,CONCRETE:8)
Block(-7,18,-4,CONCRETE:8)
Block(-7,18,-3,CONCRETE:8)
Block(-7,18,-2,CONCRETE:8)
Block(-7,18,-1,CONCRETE:8)
Block(-7,18,0,CONCRETE:15)
Block(-7,18,1,CONCRETE:15)
Block(-7,18,2,CONCRETE:15)
Block(-7,18,3,CONCRETE:15)
Block(-7,18,4,CONCRETE:15)
Block(-7,18,5,CONCRETE:15)
Block(-7,18,6,CONCRETE:15)
Block(-7,18,7,CONCRETE:8)
Block(-7,18,8,CONCRETE:8)
Block(-7,19,-5,STAINED_GLASS:15)
Block(-7,19,-4,CONCRETE:8)
Block(-7,19,-3,STAINED_GLASS_PANE:15)
Block(-7,19,-2,STAINED_GLASS_PANE:15)
Block(-7,19,-1,STAINED_GLASS_PANE:15)
Block(-7,19,0,CONCRETE:8)
Block(-7,19,1,CONCRETE:15)
Block(-7,19,2,CONCRETE:15)
#RandomBlock(-7,19,3,AIR:0,30,CHEST:5,../../../../../Chests/Loot/manhunt_urban_junk.nbt,10,CHEST:5,../../../../../Chests/Loot/manhunt_infected_cache.nbt,5,CHEST:5,../../../../../Chests/Loot/manhunt_urban_junk.nbt,65,CHEST:4,../../../../../Chests/Loot/manhunt_urban_junk.nbt,20,CHEST:4,../../../../../Chests/Loot/manhunt_residential_common.nbt,5,CHEST:4,../../../../../Chests/Loot/manhunt_residential_useful.nbt,3,CHEST:4,../../../../../Chests/Loot/manhunt_human_strategic_cache.nbt,1,CHEST:4,../../../../../Chests/Loot/manhunt_urban_junk.nbt,100)
Block(-7,19,4,CONCRETE:15)
Block(-7,19,5,CONCRETE:15)
Block(-7,19,7,CONCRETE:15)
Block(-7,20,-5,STAINED_GLASS:15)
Block(-7,20,-4,CONCRETE:8)
Block(-7,20,0,CONCRETE:8)
RandomBlock(-7,20,1,AIR,75,AIR:0,100)
Block(-7,20,2,CONCRETE:15)
Block(-7,20,4,CONCRETE:15)
RandomBlock(-7,20,5,AIR,75,AIR:0,100)
Block(-7,20,7,CONCRETE:15)
Block(-7,21,-5,STAINED_GLASS:15)
Block(-7,21,-4,CONCRETE:8)
Block(-7,21,-2,LEAVES:12)
Block(-7,21,0,CONCRETE:8)
Block(-7,21,2,CONCRETE:15)
Block(-7,21,5,CONCRETE:15)
Block(-7,21,8,CONCRETE:15)
Block(-7,22,-5,STAINED_GLASS:15)
Block(-7,22,-4,CONCRETE:8)
Block(-7,22,-3,LEAVES:12)
Block(-7,22,-2,SPRUCE_FENCE:0)
Block(-7,22,-1,LEAVES:4)
Block(-7,22,0,CONCRETE:8)
Block(-7,22,3,CONCRETE:15)
Block(-7,22,5,CONCRETE:15)
Block(-7,22,8,CONCRETE:15)
Block(-7,23,-5,STAINED_GLASS:15)
Block(-7,23,-4,CONCRETE:8)
Block(-7,23,-2,LEAVES:12)
Block(-7,23,0,CONCRETE:8)
Block(-7,23,2,CONCRETE:15)
Block(-7,23,5,CONCRETE:15)
Block(-7,23,8,CONCRETE:15)
Block(-7,24,-5,STAINED_GLASS:15)
Block(-7,24,-4,CONCRETE:8)
Block(-7,24,-1,LEAVES:12)
Block(-7,24,0,CONCRETE:8)
Block(-7,24,1,CONCRETE:15)
Block(-7,24,4,CONCRETE:15)
Block(-7,24,7,CONCRETE:15)
Block(-7,25,-5,STAINED_GLASS:15)
Block(-7,25,-4,CONCRETE:8)
Block(-7,25,0,CONCRETE:8)
Block(-7,25,4,CONCRETE:15)
Block(-7,25,7,CONCRETE:15)
Block(-7,26,-5,STAINED_GLASS:15)
Block(-7,26,-4,CONCRETE:8)
Block(-7,26,0,CONCRETE:8)
Block(-7,26,3,CONCRETE:15)
Block(-7,26,6,CONCRETE:15)
Block(-7,27,-5,STAINED_GLASS:15)
Block(-7,27,-4,CONCRETE:8)
Block(-7,27,-3,CONCRETE:8)
Block(-7,27,-2,CONCRETE:8)
Block(-7,27,-1,CONCRETE:8)
Block(-7,27,0,CONCRETE:8)
Block(-7,27,1,CONCRETE:8)
Block(-7,27,2,CONCRETE:8)
Block(-7,27,3,CONCRETE:8)
Block(-7,27,4,CONCRETE:8)
Block(-7,27,5,CONCRETE:8)
Block(-7,27,6,CONCRETE:8)
Block(-7,27,7,CONCRETE:8)
Block(-7,27,8,CONCRETE:8)
Block(-7,28,-5,STAINED_GLASS:15)
Block(-7,28,-4,CONCRETE:8)
Block(-7,28,-3,STAINED_GLASS_PANE:15)
Block(-7,28,-2,STAINED_GLASS_PANE:15)
Block(-7,28,-1,STAINED_GLASS_PANE:15)
Block(-7,28,0,CONCRETE:8)
Block(-7,28,1,STAINED_GLASS_PANE:15)
Block(-7,28,2,STAINED_GLASS_PANE:15)
Block(-7,28,3,STAINED_GLASS_PANE:15)
Block(-7,28,4,STAINED_GLASS_PANE:15)
Block(-7,28,5,STAINED_GLASS_PANE:15)
Block(-7,28,6,STAINED_GLASS_PANE:15)
Block(-7,28,7,STAINED_GLASS_PANE:15)
Block(-7,28,8,STAINED_GLASS_PANE:15)
Block(-7,29,-5,STAINED_GLASS:15)
Block(-7,29,-4,CONCRETE:8)
Block(-7,29,0,CONCRETE:8)
Block(-7,30,-5,STAINED_GLASS:15)
Block(-7,30,-4,CONCRETE:8)
Block(-7,30,0,CONCRETE:8)
Block(-7,31,-5,STAINED_GLASS:15)
Block(-7,31,-4,CONCRETE:8)
Block(-7,31,0,CONCRETE:8)
Block(-7,32,-5,STAINED_GLASS:15)
Block(-7,32,-4,CONCRETE:8)
Block(-7,32,0,CONCRETE:8)
Block(-7,33,-5,STAINED_GLASS:15)
Block(-7,33,-4,CONCRETE:8)
Block(-7,33,0,CONCRETE:8)
Block(-7,34,-5,STAINED_GLASS:15)
Block(-7,34,-4,CONCRETE:8)
Block(-7,34,0,CONCRETE:8)
Block(-7,35,-5,STAINED_GLASS:15)
Block(-7,35,-4,CONCRETE:8)
Block(-7,35,-3,CONCRETE:8)
Block(-7,35,-2,CONCRETE:8)
Block(-7,35,-1,CONCRETE:8)
Block(-7,35,0,CONCRETE:8)
Block(-7,35,1,CONCRETE:8)
Block(-7,35,2,CONCRETE:8)
Block(-7,35,3,CONCRETE:8)
Block(-7,35,4,CONCRETE:8)
Block(-7,35,5,CONCRETE:8)
Block(-7,35,6,CONCRETE:8)
Block(-7,35,7,CONCRETE:8)
Block(-7,35,8,CONCRETE:8)
Block(-7,36,-5,STAINED_GLASS:15)
Block(-7,36,-4,CONCRETE:8)
Block(-7,36,-3,STAINED_GLASS_PANE:15)
Block(-7,36,-2,STAINED_GLASS_PANE:15)
Block(-7,36,-1,STAINED_GLASS_PANE:15)
Block(-7,36,0,CONCRETE:8)
Block(-7,36,1,STAINED_GLASS_PANE:15)
Block(-7,36,2,STAINED_GLASS_PANE:15)
Block(-7,36,3,STAINED_GLASS_PANE:15)
Block(-7,36,4,STAINED_GLASS_PANE:15)
Block(-7,36,5,STAINED_GLASS_PANE:15)
Block(-7,36,6,STAINED_GLASS_PANE:15)
Block(-7,36,7,STAINED_GLASS_PANE:15)
Block(-7,36,8,STAINED_GLASS_PANE:15)
Block(-7,37,-5,STAINED_GLASS:15)
Block(-7,37,-4,CONCRETE:8)
Block(-7,37,0,CONCRETE:8)
Block(-7,38,-5,STAINED_GLASS:15)
Block(-7,38,-4,CONCRETE:8)
Block(-7,38,0,CONCRETE:8)
Block(-7,39,-5,STAINED_GLASS:15)
Block(-7,39,-4,CONCRETE:8)
Block(-7,39,0,CONCRETE:8)
Block(-7,40,-5,STAINED_GLASS:15)
Block(-7,40,-4,CONCRETE:8)
Block(-7,40,0,CONCRETE:8)
Block(-7,41,-5,STAINED_GLASS:15)
Block(-7,41,-4,CONCRETE:8)
Block(-7,41,0,CONCRETE:8)
Block(-7,42,6,STAINED_GLASS:15)
Block(-7,43,6,STAINED_GLASS:15)
Block(-7,43,7,CONCRETE:8)
Block(-7,43,8,CONCRETE:8)
Block(-7,44,6,STAINED_GLASS:15)
Block(-7,44,7,STAINED_GLASS_PANE:15)
Block(-7,44,8,STAINED_GLASS_PANE:15)
Block(-7,45,6,STAINED_GLASS:15)
Block(-7,46,6,STAINED_GLASS:15)
Block(-7,47,6,STAINED_GLASS:15)
Block(-7,48,6,STAINED_GLASS:15)
Block(-7,49,6,STAINED_GLASS:15)
Block(-7,50,6,STAINED_GLASS:15)
Block(-7,51,6,STAINED_GLASS:15)
Block(-7,51,7,CONCRETE:8)
Block(-7,51,8,CONCRETE:8)
Block(-7,52,6,STAINED_GLASS:15)
Block(-7,53,6,STAINED_GLASS:15)
Block(-7,54,6,STAINED_GLASS:15)
Block(-7,55,6,STAINED_GLASS:15)
Block(-7,56,6,STAINED_GLASS:15)
Block(-7,57,6,STAINED_GLASS:15)
Block(-7,58,6,STAINED_GLASS:15)
Block(-7,59,6,STAINED_GLASS:15)
Block(-7,60,6,STAINED_GLASS:15)
Block(-7,61,6,CONCRETE:8)
Block(-7,62,6,CONCRETE:8)
Block(-7,62,7,CONCRETE:8)
Block(-7,62,8,CONCRETE:8)
Block(-7,63,6,CONCRETE:8)
Block(-7,63,7,CONCRETE:8)
Block(-7,63,8,CONCRETE:8)
RandomBlock(-6,0,-7,CONCRETE:7,60,quark:iron_plate:1,20,STAINED_CLAY:12,15,STAINED_CLAY:15,5,AIR,7,IRON_BARS,12,CONCRETE:7,100)
RandomBlock(-6,0,-6,CONCRETE:7,60,quark:iron_plate:1,20,STAINED_CLAY:12,15,STAINED_CLAY:15,5,AIR,7,IRON_BARS,12,CONCRETE:7,100)
RandomBlock(-6,0,-5,CONCRETE:7,60,quark:iron_plate:1,20,STAINED_CLAY:12,15,STAINED_CLAY:15,5,AIR,7,IRON_BARS,12,CONCRETE:7,100)
RandomBlock(-6,0,-4,CONCRETE:7,60,quark:iron_plate:1,20,STAINED_CLAY:12,15,STAINED_CLAY:15,5,AIR,7,IRON_BARS,12,CONCRETE:7,100)
RandomBlock(-6,0,-3,CONCRETE:7,60,quark:iron_plate:1,20,STAINED_CLAY:12,15,STAINED_CLAY:15,5,AIR,7,IRON_BARS,12,CONCRETE:7,100)
RandomBlock(-6,0,-2,CONCRETE:7,60,quark:iron_plate:1,20,STAINED_CLAY:12,15,STAINED_CLAY:15,5,AIR,7,IRON_BARS,12,CONCRETE:7,100)
RandomBlock(-6,0,-1,CONCRETE:7,60,quark:iron_plate:1,20,STAINED_CLAY:12,15,STAINED_CLAY:15,5,AIR,7,IRON_BARS,12,CONCRETE:7,100)
RandomBlock(-6,0,0,CONCRETE:7,60,quark:iron_plate:1,20,STAINED_CLAY:12,15,STAINED_CLAY:15,5,AIR,7,IRON_BARS,12,CONCRETE:7,100)
RandomBlock(-6,0,1,CONCRETE:7,60,quark:iron_plate:1,20,STAINED_CLAY:12,15,STAINED_CLAY:15,5,AIR,7,IRON_BARS,12,CONCRETE:7,100)
RandomBlock(-6,0,2,CONCRETE:7,60,quark:iron_plate:1,20,STAINED_CLAY:12,15,STAINED_CLAY:15,5,AIR,7,IRON_BARS,12,CONCRETE:7,100)
RandomBlock(-6,0,3,CONCRETE:7,60,quark:iron_plate:1,20,STAINED_CLAY:12,15,STAINED_CLAY:15,5,AIR,7,IRON_BARS,12,CONCRETE:7,100)
RandomBlock(-6,0,4,CONCRETE:7,60,quark:iron_plate:1,20,STAINED_CLAY:12,15,STAINED_CLAY:15,5,AIR,7,IRON_BARS,12,CONCRETE:7,100)
RandomBlock(-6,0,5,CONCRETE:7,60,quark:iron_plate:1,20,STAINED_CLAY:12,15,STAINED_CLAY:15,5,AIR,7,IRON_BARS,12,CONCRETE:7,100)
RandomBlock(-6,0,6,CONCRETE:7,60,quark:iron_plate:1,20,STAINED_CLAY:12,15,STAINED_CLAY:15,5,AIR,7,IRON_BARS,12,CONCRETE:7,100)
RandomBlock(-6,0,7,CONCRETE:7,60,quark:iron_plate:1,20,STAINED_CLAY:12,15,STAINED_CLAY:15,5,AIR,7,IRON_BARS,12,CONCRETE:7,100)
RandomBlock(-6,0,8,CONCRETE:7,60,quark:iron_plate:1,20,STAINED_CLAY:12,15,STAINED_CLAY:15,5,AIR,7,IRON_BARS,12,CONCRETE:7,100)
RandomBlock(-6,1,-7,CONCRETE:7,60,quark:iron_plate:1,20,STAINED_CLAY:12,15,STAINED_CLAY:15,5,AIR,7,IRON_BARS,12,CONCRETE:7,100)
RandomBlock(-6,1,-6,CONCRETE:7,60,quark:iron_plate:1,20,STAINED_CLAY:12,15,STAINED_CLAY:15,5,AIR,7,IRON_BARS,12,CONCRETE:7,100)
RandomBlock(-6,1,-5,CONCRETE:7,60,quark:iron_plate:1,20,STAINED_CLAY:12,15,STAINED_CLAY:15,5,AIR,7,IRON_BARS,12,CONCRETE:7,100)
RandomBlock(-6,1,-4,CONCRETE:7,60,quark:iron_plate:1,20,STAINED_CLAY:12,15,STAINED_CLAY:15,5,AIR,7,IRON_BARS,12,CONCRETE:7,100)
RandomBlock(-6,1,-3,CONCRETE:7,60,quark:iron_plate:1,20,STAINED_CLAY:12,15,STAINED_CLAY:15,5,AIR,7,IRON_BARS,12,CONCRETE:7,100)
RandomBlock(-6,1,-2,CONCRETE:7,60,quark:iron_plate:1,20,STAINED_CLAY:12,15,STAINED_CLAY:15,5,AIR,7,IRON_BARS,12,CONCRETE:7,100)
RandomBlock(-6,1,-1,CONCRETE:7,60,quark:iron_plate:1,20,STAINED_CLAY:12,15,STAINED_CLAY:15,5,AIR,7,IRON_BARS,12,CONCRETE:7,100)
RandomBlock(-6,1,0,CONCRETE:7,60,quark:iron_plate:1,20,STAINED_CLAY:12,15,STAINED_CLAY:15,5,AIR,7,IRON_BARS,12,CONCRETE:7,100)
RandomBlock(-6,1,1,CONCRETE:7,60,quark:iron_plate:1,20,STAINED_CLAY:12,15,STAINED_CLAY:15,5,AIR,7,IRON_BARS,12,CONCRETE:7,100)
RandomBlock(-6,1,2,CONCRETE:7,60,quark:iron_plate:1,20,STAINED_CLAY:12,15,STAINED_CLAY:15,5,AIR,7,IRON_BARS,12,CONCRETE:7,100)
Block(-6,1,3,STATIONARY_WATER:0)
Block(-6,1,4,STATIONARY_WATER:0)
RandomBlock(-6,1,5,CONCRETE:7,60,quark:iron_plate:1,20,STAINED_CLAY:12,15,STAINED_CLAY:15,5,AIR,7,IRON_BARS,12,CONCRETE:7,100)
RandomBlock(-6,1,6,CONCRETE:7,60,quark:iron_plate:1,20,STAINED_CLAY:12,15,STAINED_CLAY:15,5,AIR,7,IRON_BARS,12,CONCRETE:7,100)
RandomBlock(-6,1,7,CONCRETE:7,60,quark:iron_plate:1,20,STAINED_CLAY:12,15,STAINED_CLAY:15,5,AIR,7,IRON_BARS,12,CONCRETE:7,100)
RandomBlock(-6,1,8,CONCRETE:7,60,quark:iron_plate:1,20,STAINED_CLAY:12,15,STAINED_CLAY:15,5,AIR,7,IRON_BARS,12,CONCRETE:7,100)
Block(-6,2,-7,SMOOTH_STAIRS:1)
Block(-6,2,-6,SMOOTH_STAIRS:1)
Block(-6,2,-5,SMOOTH_STAIRS:1)
Block(-6,2,-4,SMOOTH_STAIRS:1)
Block(-6,2,-3,SMOOTH_STAIRS:1)
Block(-6,2,-2,SMOOTH_STAIRS:1)
Block(-6,2,-1,SMOOTH_STAIRS:1)
Block(-6,2,0,SMOOTH_STAIRS:1)
Block(-6,2,1,SMOOTH_STAIRS:1)
Block(-6,2,2,SMOOTH_STAIRS:1)
Block(-6,2,3,AIR:0)
Block(-6,2,4,AIR:0)
Block(-6,2,5,SMOOTH_STAIRS:1)
Block(-6,2,6,SMOOTH_STAIRS:1)
Block(-6,2,7,SMOOTH_STAIRS:1)
Block(-6,2,8,SMOOTH_STAIRS:1)
Block(-6,3,-7,AIR:0)
Block(-6,3,-6,AIR:0)
Block(-6,3,-5,AIR:0)
Block(-6,3,-4,AIR:0)
Block(-6,3,-3,AIR:0)
Block(-6,3,-2,AIR:0)
Block(-6,3,-1,AIR:0)
Block(-6,3,0,AIR:0)
Block(-6,3,1,AIR:0)
Block(-6,3,2,AIR:0)
Block(-6,3,3,AIR:0)
Block(-6,3,4,AIR:0)
Block(-6,3,5,AIR:0)
Block(-6,3,6,AIR:0)
Block(-6,3,7,AIR:0)
Block(-6,3,8,AIR:0)
Block(-6,4,-7,AIR:0)
Block(-6,4,-6,AIR:0)
Block(-6,4,-5,AIR:0)
Block(-6,4,-4,AIR:0)
Block(-6,4,-3,AIR:0)
Block(-6,4,-2,AIR:0)
Block(-6,4,-1,AIR:0)
Block(-6,4,0,AIR:0)
Block(-6,4,1,AIR:0)
Block(-6,4,2,AIR:0)
Block(-6,4,3,AIR:0)
Block(-6,4,4,AIR:0)
Block(-6,4,5,AIR:0)
Block(-6,4,6,AIR:0)
Block(-6,4,7,AIR:0)
Block(-6,4,8,AIR:0)
Block(-6,5,-7,AIR:0)
Block(-6,5,-6,AIR:0)
Block(-6,5,-5,AIR:0)
Block(-6,5,-4,AIR:0)
Block(-6,5,-3,AIR:0)
Block(-6,5,-2,AIR:0)
Block(-6,5,-1,AIR:0)
Block(-6,5,0,AIR:0)
Block(-6,5,1,AIR:0)
Block(-6,5,2,AIR:0)
Block(-6,5,3,AIR:0)
Block(-6,5,4,AIR:0)
Block(-6,5,5,AIR:0)
Block(-6,5,6,CONCRETE:12)
Block(-6,5,7,CONCRETE:4)
Block(-6,5,8,AIR:0)
RandomBlock(-6,6,-7,CONCRETE:7,60,quark:iron_plate:1,20,STAINED_CLAY:12,15,STAINED_CLAY:15,5,AIR,7,IRON_BARS,12,CONCRETE:7,100)
Block(-6,6,-6,AIR:0)
Block(-6,6,-5,AIR:0)
Block(-6,6,-4,AIR:0)
Block(-6,6,-3,AIR:0)
Block(-6,6,-2,AIR:0)
Block(-6,6,-1,AIR:0)
Block(-6,6,0,AIR:0)
Block(-6,6,1,AIR:0)
Block(-6,6,2,AIR:0)
Block(-6,6,3,AIR:0)
Block(-6,6,4,AIR:0)
Block(-6,6,5,AIR:0)
Block(-6,6,6,AIR:0)
Block(-6,6,7,AIR:0)
Block(-6,6,8,AIR:0)
RandomBlock(-6,7,-7,CONCRETE:7,60,quark:iron_plate:1,20,STAINED_CLAY:12,15,STAINED_CLAY:15,5,AIR,7,IRON_BARS,12,CONCRETE:7,100)
RandomBlock(-6,7,-6,CONCRETE:7,60,quark:iron_plate:1,20,STAINED_CLAY:12,15,STAINED_CLAY:15,5,AIR,7,IRON_BARS,12,CONCRETE:7,100)
RandomBlock(-6,7,-5,CONCRETE:7,60,quark:iron_plate:1,20,STAINED_CLAY:12,15,STAINED_CLAY:15,5,AIR,7,IRON_BARS,12,CONCRETE:7,100)
RandomBlock(-6,7,-4,CONCRETE:7,60,quark:iron_plate:1,20,STAINED_CLAY:12,15,STAINED_CLAY:15,5,AIR,7,IRON_BARS,12,CONCRETE:7,100)
RandomBlock(-6,7,-3,CONCRETE:7,60,quark:iron_plate:1,20,STAINED_CLAY:12,15,STAINED_CLAY:15,5,AIR,7,IRON_BARS,12,CONCRETE:7,100)
RandomBlock(-6,7,-2,CONCRETE:7,60,quark:iron_plate:1,20,STAINED_CLAY:12,15,STAINED_CLAY:15,5,AIR,7,IRON_BARS,12,CONCRETE:7,100)
RandomBlock(-6,7,-1,CONCRETE:7,60,quark:iron_plate:1,20,STAINED_CLAY:12,15,STAINED_CLAY:15,5,AIR,7,IRON_BARS,12,CONCRETE:7,100)
RandomBlock(-6,7,0,CONCRETE:7,60,quark:iron_plate:1,20,STAINED_CLAY:12,15,STAINED_CLAY:15,5,AIR,7,IRON_BARS,12,CONCRETE:7,100)
RandomBlock(-6,7,1,CONCRETE:7,60,quark:iron_plate:1,20,STAINED_CLAY:12,15,STAINED_CLAY:15,5,AIR,7,IRON_BARS,12,CONCRETE:7,100)
RandomBlock(-6,7,2,CONCRETE:7,60,quark:iron_plate:1,20,STAINED_CLAY:12,15,STAINED_CLAY:15,5,AIR,7,IRON_BARS,12,CONCRETE:7,100)
RandomBlock(-6,7,3,CONCRETE:7,60,quark:iron_plate:1,20,STAINED_CLAY:12,15,STAINED_CLAY:15,5,AIR,7,IRON_BARS,12,CONCRETE:7,100)
RandomBlock(-6,7,4,CONCRETE:7,60,quark:iron_plate:1,20,STAINED_CLAY:12,15,STAINED_CLAY:15,5,AIR,7,IRON_BARS,12,CONCRETE:7,100)
RandomBlock(-6,7,5,CONCRETE:7,60,quark:iron_plate:1,20,STAINED_CLAY:12,15,STAINED_CLAY:15,5,AIR,7,IRON_BARS,12,CONCRETE:7,100)
RandomBlock(-6,7,6,CONCRETE:7,60,quark:iron_plate:1,20,STAINED_CLAY:12,15,STAINED_CLAY:15,5,AIR,7,IRON_BARS,12,CONCRETE:7,100)
RandomBlock(-6,7,7,CONCRETE:7,60,quark:iron_plate:1,20,STAINED_CLAY:12,15,STAINED_CLAY:15,5,AIR,7,IRON_BARS,12,CONCRETE:7,100)
RandomBlock(-6,7,8,CONCRETE:7,60,quark:iron_plate:1,20,STAINED_CLAY:12,15,STAINED_CLAY:15,5,AIR,7,IRON_BARS,12,CONCRETE:7,100)
RandomBlock(-6,8,-7,CONCRETE:7,60,quark:iron_plate:1,20,STAINED_CLAY:12,15,STAINED_CLAY:15,5,AIR,7,IRON_BARS,12,CONCRETE:7,100)
RandomBlock(-6,8,-6,CONCRETE:7,60,quark:iron_plate:1,20,STAINED_CLAY:12,15,STAINED_CLAY:15,5,AIR,7,IRON_BARS,12,CONCRETE:7,100)
RandomBlock(-6,8,-5,CONCRETE:7,60,quark:iron_plate:1,20,STAINED_CLAY:12,15,STAINED_CLAY:15,5,AIR,7,IRON_BARS,12,CONCRETE:7,100)
RandomBlock(-6,8,-4,CONCRETE:7,60,quark:iron_plate:1,20,STAINED_CLAY:12,15,STAINED_CLAY:15,5,AIR,7,IRON_BARS,12,CONCRETE:7,100)
RandomBlock(-6,8,-3,CONCRETE:7,60,quark:iron_plate:1,20,STAINED_CLAY:12,15,STAINED_CLAY:15,5,AIR,7,IRON_BARS,12,CONCRETE:7,100)
RandomBlock(-6,8,-2,CONCRETE:7,60,quark:iron_plate:1,20,STAINED_CLAY:12,15,STAINED_CLAY:15,5,AIR,7,IRON_BARS,12,CONCRETE:7,100)
RandomBlock(-6,8,-1,CONCRETE:7,60,quark:iron_plate:1,20,STAINED_CLAY:12,15,STAINED_CLAY:15,5,AIR,7,IRON_BARS,12,CONCRETE:7,100)
RandomBlock(-6,8,0,CONCRETE:7,60,quark:iron_plate:1,20,STAINED_CLAY:12,15,STAINED_CLAY:15,5,AIR,7,IRON_BARS,12,CONCRETE:7,100)
RandomBlock(-6,8,1,CONCRETE:7,60,quark:iron_plate:1,20,STAINED_CLAY:12,15,STAINED_CLAY:15,5,AIR,7,IRON_BARS,12,CONCRETE:7,100)
RandomBlock(-6,8,2,CONCRETE:7,60,quark:iron_plate:1,20,STAINED_CLAY:12,15,STAINED_CLAY:15,5,AIR,7,IRON_BARS,12,CONCRETE:7,100)
RandomBlock(-6,8,3,CONCRETE:7,60,quark:iron_plate:1,20,STAINED_CLAY:12,15,STAINED_CLAY:15,5,AIR,7,IRON_BARS,12,CONCRETE:7,100)
RandomBlock(-6,8,4,CONCRETE:7,60,quark:iron_plate:1,20,STAINED_CLAY:12,15,STAINED_CLAY:15,5,AIR,7,IRON_BARS,12,CONCRETE:7,100)
RandomBlock(-6,8,5,CONCRETE:7,60,quark:iron_plate:1,20,STAINED_CLAY:12,15,STAINED_CLAY:15,5,AIR,7,IRON_BARS,12,CONCRETE:7,100)
RandomBlock(-6,8,6,CONCRETE:7,60,quark:iron_plate:1,20,STAINED_CLAY:12,15,STAINED_CLAY:15,5,AIR,7,IRON_BARS,12,CONCRETE:7,100)
RandomBlock(-6,8,7,CONCRETE:7,60,quark:iron_plate:1,20,STAINED_CLAY:12,15,STAINED_CLAY:15,5,AIR,7,IRON_BARS,12,CONCRETE:7,100)
RandomBlock(-6,8,8,CONCRETE:7,60,quark:iron_plate:1,20,STAINED_CLAY:12,15,STAINED_CLAY:15,5,AIR,7,IRON_BARS,12,CONCRETE:7,100)
RandomBlock(-6,9,-7,CONCRETE:7,60,quark:iron_plate:1,20,STAINED_CLAY:12,15,STAINED_CLAY:15,5,AIR,7,IRON_BARS,12,CONCRETE:7,100)
RandomBlock(-6,9,-6,CONCRETE:7,60,quark:iron_plate:1,20,STAINED_CLAY:12,15,STAINED_CLAY:15,5,AIR,7,IRON_BARS,12,CONCRETE:7,100)
RandomBlock(-6,9,-5,CONCRETE:7,60,quark:iron_plate:1,20,STAINED_CLAY:12,15,STAINED_CLAY:15,5,AIR,7,IRON_BARS,12,CONCRETE:7,100)
RandomBlock(-6,9,-4,CONCRETE:7,60,quark:iron_plate:1,20,STAINED_CLAY:12,15,STAINED_CLAY:15,5,AIR,7,IRON_BARS,12,CONCRETE:7,100)
RandomBlock(-6,9,-3,CONCRETE:7,60,quark:iron_plate:1,20,STAINED_CLAY:12,15,STAINED_CLAY:15,5,AIR,7,IRON_BARS,12,CONCRETE:7,100)
RandomBlock(-6,9,-2,CONCRETE:7,60,quark:iron_plate:1,20,STAINED_CLAY:12,15,STAINED_CLAY:15,5,AIR,7,IRON_BARS,12,CONCRETE:7,100)
RandomBlock(-6,9,-1,CONCRETE:7,60,quark:iron_plate:1,20,STAINED_CLAY:12,15,STAINED_CLAY:15,5,AIR,7,IRON_BARS,12,CONCRETE:7,100)
RandomBlock(-6,9,0,CONCRETE:7,60,quark:iron_plate:1,20,STAINED_CLAY:12,15,STAINED_CLAY:15,5,AIR,7,IRON_BARS,12,CONCRETE:7,100)
RandomBlock(-6,9,1,CONCRETE:7,60,quark:iron_plate:1,20,STAINED_CLAY:12,15,STAINED_CLAY:15,5,AIR,7,IRON_BARS,12,CONCRETE:7,100)
RandomBlock(-6,9,2,CONCRETE:7,60,quark:iron_plate:1,20,STAINED_CLAY:12,15,STAINED_CLAY:15,5,AIR,7,IRON_BARS,12,CONCRETE:7,100)
RandomBlock(-6,9,3,CONCRETE:7,60,quark:iron_plate:1,20,STAINED_CLAY:12,15,STAINED_CLAY:15,5,AIR,7,IRON_BARS,12,CONCRETE:7,100)
RandomBlock(-6,9,4,CONCRETE:7,60,quark:iron_plate:1,20,STAINED_CLAY:12,15,STAINED_CLAY:15,5,AIR,7,IRON_BARS,12,CONCRETE:7,100)
RandomBlock(-6,9,5,CONCRETE:7,60,quark:iron_plate:1,20,STAINED_CLAY:12,15,STAINED_CLAY:15,5,AIR,7,IRON_BARS,12,CONCRETE:7,100)
RandomBlock(-6,9,6,CONCRETE:7,60,quark:iron_plate:1,20,STAINED_CLAY:12,15,STAINED_CLAY:15,5,AIR,7,IRON_BARS,12,CONCRETE:7,100)
RandomBlock(-6,9,7,CONCRETE:7,60,quark:iron_plate:1,20,STAINED_CLAY:12,15,STAINED_CLAY:15,5,AIR,7,IRON_BARS,12,CONCRETE:7,100)
RandomBlock(-6,9,8,CONCRETE:7,60,quark:iron_plate:1,20,STAINED_CLAY:12,15,STAINED_CLAY:15,5,AIR,7,IRON_BARS,12,CONCRETE:7,100)
RandomBlock(-6,10,-7,CONCRETE:7,60,quark:iron_plate:1,20,STAINED_CLAY:12,15,STAINED_CLAY:15,5,AIR,7,IRON_BARS,12,CONCRETE:7,100)
RandomBlock(-6,10,-6,CONCRETE:7,60,quark:iron_plate:1,20,STAINED_CLAY:12,15,STAINED_CLAY:15,5,AIR,7,IRON_BARS,12,CONCRETE:7,100)
RandomBlock(-6,10,-5,CONCRETE:7,60,quark:iron_plate:1,20,STAINED_CLAY:12,15,STAINED_CLAY:15,5,AIR,7,IRON_BARS,12,CONCRETE:7,100)
RandomBlock(-6,10,-4,CONCRETE:7,60,quark:iron_plate:1,20,STAINED_CLAY:12,15,STAINED_CLAY:15,5,AIR,7,IRON_BARS,12,CONCRETE:7,100)
Block(-6,10,-3,AIR:0)
Block(-6,10,-2,AIR:0)
RandomBlock(-6,10,-1,CONCRETE:7,60,quark:iron_plate:1,20,STAINED_CLAY:12,15,STAINED_CLAY:15,5,AIR,7,IRON_BARS,12,CONCRETE:7,100)
RandomBlock(-6,10,0,CONCRETE:7,60,quark:iron_plate:1,20,STAINED_CLAY:12,15,STAINED_CLAY:15,5,AIR,7,IRON_BARS,12,CONCRETE:7,100)
Block(-6,10,1,QUARTZ_STAIRS:3)
RandomBlock(-6,10,2,AIR,90,IRON_TRAPDOOR:5,100)
Block(-6,10,3,QUARTZ_STAIRS:2)
RandomBlock(-6,10,4,CONCRETE:7,60,quark:iron_plate:1,20,STAINED_CLAY:12,15,STAINED_CLAY:15,5,AIR,7,IRON_BARS,12,CONCRETE:7,100)
RandomBlock(-6,10,5,CONCRETE:7,60,quark:iron_plate:1,20,STAINED_CLAY:12,15,STAINED_CLAY:15,5,AIR,7,IRON_BARS,12,CONCRETE:7,100)
RandomBlock(-6,10,6,CONCRETE:7,60,quark:iron_plate:1,20,STAINED_CLAY:12,15,STAINED_CLAY:15,5,AIR,7,IRON_BARS,12,CONCRETE:7,100)
RandomBlock(-6,10,7,CONCRETE:7,60,quark:iron_plate:1,20,STAINED_CLAY:12,15,STAINED_CLAY:15,5,AIR,7,IRON_BARS,12,CONCRETE:7,100)
Block(-6,10,8,AIR:0)
RandomBlock(-6,11,-7,CONCRETE:7,60,quark:iron_plate:1,20,STAINED_CLAY:12,15,STAINED_CLAY:15,5,AIR,7,IRON_BARS,12,CONCRETE:7,100)
RandomBlock(-6,11,-6,CONCRETE:7,60,quark:iron_plate:1,20,STAINED_CLAY:12,15,STAINED_CLAY:15,5,AIR,7,IRON_BARS,12,CONCRETE:7,100)
RandomBlock(-6,11,-5,CONCRETE:7,60,quark:iron_plate:1,20,STAINED_CLAY:12,15,STAINED_CLAY:15,5,AIR,7,IRON_BARS,12,CONCRETE:7,100)
RandomBlock(-6,11,-4,CONCRETE:7,60,quark:iron_plate:1,20,STAINED_CLAY:12,15,STAINED_CLAY:15,5,AIR,7,IRON_BARS,12,CONCRETE:7,100)
Block(-6,11,-3,AIR:0)
Block(-6,11,-2,AIR:0)
RandomBlock(-6,11,-1,CONCRETE:7,60,quark:iron_plate:1,20,STAINED_CLAY:12,15,STAINED_CLAY:15,5,AIR,7,IRON_BARS,12,CONCRETE:7,100)
RandomBlock(-6,11,0,CONCRETE:7,60,quark:iron_plate:1,20,STAINED_CLAY:12,15,STAINED_CLAY:15,5,AIR,7,IRON_BARS,12,CONCRETE:7,100)
RandomBlock(-6,11,1,AIR,90,IRON_TRAPDOOR:8,100)
Block(-6,11,2,CONCRETE:14)
RandomBlock(-6,11,3,AIR,90,IRON_TRAPDOOR:1,100)
RandomBlock(-6,11,4,CONCRETE:7,60,quark:iron_plate:1,20,STAINED_CLAY:12,15,STAINED_CLAY:15,5,AIR,7,IRON_BARS,12,CONCRETE:7,100)
RandomBlock(-6,11,5,CONCRETE:7,60,quark:iron_plate:1,20,STAINED_CLAY:12,15,STAINED_CLAY:15,5,AIR,7,IRON_BARS,12,CONCRETE:7,100)
RandomBlock(-6,11,6,CONCRETE:7,60,quark:iron_plate:1,20,STAINED_CLAY:12,15,STAINED_CLAY:15,5,AIR,7,IRON_BARS,12,CONCRETE:7,100)
RandomBlock(-6,11,7,CONCRETE:7,60,quark:iron_plate:1,20,STAINED_CLAY:12,15,STAINED_CLAY:15,5,AIR,7,IRON_BARS,12,CONCRETE:7,100)
Block(-6,11,8,AIR:0)
RandomBlock(-6,12,-7,CONCRETE:7,60,quark:iron_plate:1,20,STAINED_CLAY:12,15,STAINED_CLAY:15,5,AIR,7,IRON_BARS,12,CONCRETE:7,100)
RandomBlock(-6,12,-6,CONCRETE:7,60,quark:iron_plate:1,20,STAINED_CLAY:12,15,STAINED_CLAY:15,5,AIR,7,IRON_BARS,12,CONCRETE:7,100)
RandomBlock(-6,12,-5,CONCRETE:7,60,quark:iron_plate:1,20,STAINED_CLAY:12,15,STAINED_CLAY:15,5,AIR,7,IRON_BARS,12,CONCRETE:7,100)
RandomBlock(-6,12,-4,CONCRETE:7,60,quark:iron_plate:1,20,STAINED_CLAY:12,15,STAINED_CLAY:15,5,AIR,7,IRON_BARS,12,CONCRETE:7,100)
Block(-6,12,-3,AIR:0)
Block(-6,12,-2,AIR:0)
RandomBlock(-6,12,-1,CONCRETE:7,60,quark:iron_plate:1,20,STAINED_CLAY:12,15,STAINED_CLAY:15,5,AIR,7,IRON_BARS,12,CONCRETE:7,100)
RandomBlock(-6,12,0,CONCRETE:7,60,quark:iron_plate:1,20,STAINED_CLAY:12,15,STAINED_CLAY:15,5,AIR,7,IRON_BARS,12,CONCRETE:7,100)
Block(-6,12,1,QUARTZ_STAIRS:7)
RandomBlock(-6,12,2,AIR,90,IRON_TRAPDOOR:4,100)
Block(-6,12,3,QUARTZ_STAIRS:6)
RandomBlock(-6,12,4,CONCRETE:7,60,quark:iron_plate:1,20,STAINED_CLAY:12,15,STAINED_CLAY:15,5,AIR,7,IRON_BARS,12,CONCRETE:7,100)
RandomBlock(-6,12,5,CONCRETE:7,60,quark:iron_plate:1,20,STAINED_CLAY:12,15,STAINED_CLAY:15,5,AIR,7,IRON_BARS,12,CONCRETE:7,100)
RandomBlock(-6,12,6,CONCRETE:7,60,quark:iron_plate:1,20,STAINED_CLAY:12,15,STAINED_CLAY:15,5,AIR,7,IRON_BARS,12,CONCRETE:7,100)
RandomBlock(-6,12,7,CONCRETE:7,60,quark:iron_plate:1,20,STAINED_CLAY:12,15,STAINED_CLAY:15,5,AIR,7,IRON_BARS,12,CONCRETE:7,100)
Block(-6,12,8,AIR:0)
RandomBlock(-6,13,-7,CONCRETE:7,60,quark:iron_plate:1,20,STAINED_CLAY:12,15,STAINED_CLAY:15,5,AIR,7,IRON_BARS,12,CONCRETE:7,100)
RandomBlock(-6,13,-6,CONCRETE:7,60,quark:iron_plate:1,20,STAINED_CLAY:12,15,STAINED_CLAY:15,5,AIR,7,IRON_BARS,12,CONCRETE:7,100)
RandomBlock(-6,13,-5,CONCRETE:7,60,quark:iron_plate:1,20,STAINED_CLAY:12,15,STAINED_CLAY:15,5,AIR,7,IRON_BARS,12,CONCRETE:7,100)
RandomBlock(-6,13,-4,CONCRETE:7,60,quark:iron_plate:1,20,STAINED_CLAY:12,15,STAINED_CLAY:15,5,AIR,7,IRON_BARS,12,CONCRETE:7,100)
Block(-6,13,-3,SMOOTH_STAIRS:4)
Block(-6,13,-2,SMOOTH_STAIRS:4)
RandomBlock(-6,13,-1,CONCRETE:7,60,quark:iron_plate:1,20,STAINED_CLAY:12,15,STAINED_CLAY:15,5,AIR,7,IRON_BARS,12,CONCRETE:7,100)
RandomBlock(-6,13,0,CONCRETE:7,60,quark:iron_plate:1,20,STAINED_CLAY:12,15,STAINED_CLAY:15,5,AIR,7,IRON_BARS,12,CONCRETE:7,100)
RandomBlock(-6,13,1,CONCRETE:7,60,quark:iron_plate:1,20,STAINED_CLAY:12,15,STAINED_CLAY:15,5,AIR,7,IRON_BARS,12,CONCRETE:7,100)
RandomBlock(-6,13,2,CONCRETE:7,60,quark:iron_plate:1,20,STAINED_CLAY:12,15,STAINED_CLAY:15,5,AIR,7,IRON_BARS,12,CONCRETE:7,100)
RandomBlock(-6,13,3,CONCRETE:7,60,quark:iron_plate:1,20,STAINED_CLAY:12,15,STAINED_CLAY:15,5,AIR,7,IRON_BARS,12,CONCRETE:7,100)
RandomBlock(-6,13,4,CONCRETE:7,60,quark:iron_plate:1,20,STAINED_CLAY:12,15,STAINED_CLAY:15,5,AIR,7,IRON_BARS,12,CONCRETE:7,100)
RandomBlock(-6,13,5,CONCRETE:7,60,quark:iron_plate:1,20,STAINED_CLAY:12,15,STAINED_CLAY:15,5,AIR,7,IRON_BARS,12,CONCRETE:7,100)
RandomBlock(-6,13,6,CONCRETE:7,60,quark:iron_plate:1,20,STAINED_CLAY:12,15,STAINED_CLAY:15,5,AIR,7,IRON_BARS,12,CONCRETE:7,100)
RandomBlock(-6,13,7,CONCRETE:7,60,quark:iron_plate:1,20,STAINED_CLAY:12,15,STAINED_CLAY:15,5,AIR,7,IRON_BARS,12,CONCRETE:7,100)
Block(-6,13,8,AIR:0)
RandomBlock(-6,14,-7,CONCRETE:7,60,quark:iron_plate:1,20,STAINED_CLAY:12,15,STAINED_CLAY:15,5,AIR,7,IRON_BARS,12,CONCRETE:7,100)
RandomBlock(-6,14,-6,CONCRETE:7,60,quark:iron_plate:1,20,STAINED_CLAY:12,15,STAINED_CLAY:15,5,AIR,7,IRON_BARS,12,CONCRETE:7,100)
RandomBlock(-6,14,-5,CONCRETE:7,60,quark:iron_plate:1,20,STAINED_CLAY:12,15,STAINED_CLAY:15,5,AIR,7,IRON_BARS,12,CONCRETE:7,100)
RandomBlock(-6,14,-4,CONCRETE:7,60,quark:iron_plate:1,20,STAINED_CLAY:12,15,STAINED_CLAY:15,5,AIR,7,IRON_BARS,12,CONCRETE:7,100)
RandomBlock(-6,14,-3,CONCRETE:7,60,quark:iron_plate:1,20,STAINED_CLAY:12,15,STAINED_CLAY:15,5,AIR,7,IRON_BARS,12,CONCRETE:7,100)
RandomBlock(-6,14,-2,CONCRETE:7,60,quark:iron_plate:1,20,STAINED_CLAY:12,15,STAINED_CLAY:15,5,AIR,7,IRON_BARS,12,CONCRETE:7,100)
RandomBlock(-6,14,-1,CONCRETE:7,60,quark:iron_plate:1,20,STAINED_CLAY:12,15,STAINED_CLAY:15,5,AIR,7,IRON_BARS,12,CONCRETE:7,100)
RandomBlock(-6,14,0,CONCRETE:7,60,quark:iron_plate:1,20,STAINED_CLAY:12,15,STAINED_CLAY:15,5,AIR,7,IRON_BARS,12,CONCRETE:7,100)
Block(-6,14,1,QUARTZ_STAIRS:3)
RandomBlock(-6,14,2,AIR,90,IRON_TRAPDOOR:5,100)
Block(-6,14,3,QUARTZ_STAIRS:2)
RandomBlock(-6,14,4,CONCRETE:7,60,quark:iron_plate:1,20,STAINED_CLAY:12,15,STAINED_CLAY:15,5,AIR,7,IRON_BARS,12,CONCRETE:7,100)
RandomBlock(-6,14,5,CONCRETE:7,60,quark:iron_plate:1,20,STAINED_CLAY:12,15,STAINED_CLAY:15,5,AIR,7,IRON_BARS,12,CONCRETE:7,100)
RandomBlock(-6,14,6,CONCRETE:7,60,quark:iron_plate:1,20,STAINED_CLAY:12,15,STAINED_CLAY:15,5,AIR,7,IRON_BARS,12,CONCRETE:7,100)
RandomBlock(-6,14,7,CONCRETE:7,60,quark:iron_plate:1,20,STAINED_CLAY:12,15,STAINED_CLAY:15,5,AIR,7,IRON_BARS,12,CONCRETE:7,100)
RandomBlock(-6,14,8,CONCRETE:7,60,quark:iron_plate:1,20,STAINED_CLAY:12,15,STAINED_CLAY:15,5,AIR,7,IRON_BARS,12,CONCRETE:7,100)
RandomBlock(-6,15,-7,CONCRETE:7,60,quark:iron_plate:1,20,STAINED_CLAY:12,15,STAINED_CLAY:15,5,AIR,7,IRON_BARS,12,CONCRETE:7,100)
RandomBlock(-6,15,-6,CONCRETE:7,60,quark:iron_plate:1,20,STAINED_CLAY:12,15,STAINED_CLAY:15,5,AIR,7,IRON_BARS,12,CONCRETE:7,100)
RandomBlock(-6,15,-5,CONCRETE:7,60,quark:iron_plate:1,20,STAINED_CLAY:12,15,STAINED_CLAY:15,5,AIR,7,IRON_BARS,12,CONCRETE:7,100)
RandomBlock(-6,15,-4,CONCRETE:7,60,quark:iron_plate:1,20,STAINED_CLAY:12,15,STAINED_CLAY:15,5,AIR,7,IRON_BARS,12,CONCRETE:7,100)
RandomBlock(-6,15,-3,CONCRETE:7,60,quark:iron_plate:1,20,STAINED_CLAY:12,15,STAINED_CLAY:15,5,AIR,7,IRON_BARS,12,CONCRETE:7,100)
RandomBlock(-6,15,-2,CONCRETE:7,60,quark:iron_plate:1,20,STAINED_CLAY:12,15,STAINED_CLAY:15,5,AIR,7,IRON_BARS,12,CONCRETE:7,100)
RandomBlock(-6,15,-1,CONCRETE:7,60,quark:iron_plate:1,20,STAINED_CLAY:12,15,STAINED_CLAY:15,5,AIR,7,IRON_BARS,12,CONCRETE:7,100)
RandomBlock(-6,15,0,CONCRETE:7,60,quark:iron_plate:1,20,STAINED_CLAY:12,15,STAINED_CLAY:15,5,AIR,7,IRON_BARS,12,CONCRETE:7,100)
RandomBlock(-6,15,1,AIR,90,IRON_TRAPDOOR:8,100)
Block(-6,15,2,CONCRETE:14)
RandomBlock(-6,15,3,AIR,90,IRON_TRAPDOOR:1,100)
RandomBlock(-6,15,4,CONCRETE:7,60,quark:iron_plate:1,20,STAINED_CLAY:12,15,STAINED_CLAY:15,5,AIR,7,IRON_BARS,12,CONCRETE:7,100)
RandomBlock(-6,15,5,CONCRETE:7,60,quark:iron_plate:1,20,STAINED_CLAY:12,15,STAINED_CLAY:15,5,AIR,7,IRON_BARS,12,CONCRETE:7,100)
RandomBlock(-6,15,6,CONCRETE:7,60,quark:iron_plate:1,20,STAINED_CLAY:12,15,STAINED_CLAY:15,5,AIR,7,IRON_BARS,12,CONCRETE:7,100)
RandomBlock(-6,15,7,CONCRETE:7,60,quark:iron_plate:1,20,STAINED_CLAY:12,15,STAINED_CLAY:15,5,AIR,7,IRON_BARS,12,CONCRETE:7,100)
RandomBlock(-6,15,8,CONCRETE:7,60,quark:iron_plate:1,20,STAINED_CLAY:12,15,STAINED_CLAY:15,5,AIR,7,IRON_BARS,12,CONCRETE:7,100)
RandomBlock(-6,16,-7,CONCRETE:7,60,quark:iron_plate:1,20,STAINED_CLAY:12,15,STAINED_CLAY:15,5,AIR,7,IRON_BARS,12,CONCRETE:7,100)
RandomBlock(-6,16,-6,CONCRETE:7,60,quark:iron_plate:1,20,STAINED_CLAY:12,15,STAINED_CLAY:15,5,AIR,7,IRON_BARS,12,CONCRETE:7,100)
RandomBlock(-6,16,-5,CONCRETE:7,60,quark:iron_plate:1,20,STAINED_CLAY:12,15,STAINED_CLAY:15,5,AIR,7,IRON_BARS,12,CONCRETE:7,100)
RandomBlock(-6,16,-4,CONCRETE:7,60,quark:iron_plate:1,20,STAINED_CLAY:12,15,STAINED_CLAY:15,5,AIR,7,IRON_BARS,12,CONCRETE:7,100)
RandomBlock(-6,16,-3,CONCRETE:7,60,quark:iron_plate:1,20,STAINED_CLAY:12,15,STAINED_CLAY:15,5,AIR,7,IRON_BARS,12,CONCRETE:7,100)
RandomBlock(-6,16,-2,CONCRETE:7,60,quark:iron_plate:1,20,STAINED_CLAY:12,15,STAINED_CLAY:15,5,AIR,7,IRON_BARS,12,CONCRETE:7,100)
RandomBlock(-6,16,-1,CONCRETE:7,60,quark:iron_plate:1,20,STAINED_CLAY:12,15,STAINED_CLAY:15,5,AIR,7,IRON_BARS,12,CONCRETE:7,100)
RandomBlock(-6,16,0,CONCRETE:7,60,quark:iron_plate:1,20,STAINED_CLAY:12,15,STAINED_CLAY:15,5,AIR,7,IRON_BARS,12,CONCRETE:7,100)
Block(-6,16,1,QUARTZ_STAIRS:7)
RandomBlock(-6,16,2,AIR,90,IRON_TRAPDOOR:4,100)
Block(-6,16,3,QUARTZ_STAIRS:6)
RandomBlock(-6,16,4,CONCRETE:7,60,quark:iron_plate:1,20,STAINED_CLAY:12,15,STAINED_CLAY:15,5,AIR,7,IRON_BARS,12,CONCRETE:7,100)
RandomBlock(-6,16,5,CONCRETE:7,60,quark:iron_plate:1,20,STAINED_CLAY:12,15,STAINED_CLAY:15,5,AIR,7,IRON_BARS,12,CONCRETE:7,100)
RandomBlock(-6,16,6,CONCRETE:7,60,quark:iron_plate:1,20,STAINED_CLAY:12,15,STAINED_CLAY:15,5,AIR,7,IRON_BARS,12,CONCRETE:7,100)
RandomBlock(-6,16,7,CONCRETE:7,60,quark:iron_plate:1,20,STAINED_CLAY:12,15,STAINED_CLAY:15,5,AIR,7,IRON_BARS,12,CONCRETE:7,100)
RandomBlock(-6,16,8,CONCRETE:7,60,quark:iron_plate:1,20,STAINED_CLAY:12,15,STAINED_CLAY:15,5,AIR,7,IRON_BARS,12,CONCRETE:7,100)
RandomBlock(-6,17,-7,CONCRETE:7,60,quark:iron_plate:1,20,STAINED_CLAY:12,15,STAINED_CLAY:15,5,AIR,7,IRON_BARS,12,CONCRETE:7,100)
RandomBlock(-6,17,-6,CONCRETE:7,60,quark:iron_plate:1,20,STAINED_CLAY:12,15,STAINED_CLAY:15,5,AIR,7,IRON_BARS,12,CONCRETE:7,100)
RandomBlock(-6,17,-5,CONCRETE:7,60,quark:iron_plate:1,20,STAINED_CLAY:12,15,STAINED_CLAY:15,5,AIR,7,IRON_BARS,12,CONCRETE:7,100)
RandomBlock(-6,17,-4,CONCRETE:7,60,quark:iron_plate:1,20,STAINED_CLAY:12,15,STAINED_CLAY:15,5,AIR,7,IRON_BARS,12,CONCRETE:7,100)
RandomBlock(-6,17,-3,CONCRETE:7,60,quark:iron_plate:1,20,STAINED_CLAY:12,15,STAINED_CLAY:15,5,AIR,7,IRON_BARS,12,CONCRETE:7,100)
RandomBlock(-6,17,-2,CONCRETE:7,60,quark:iron_plate:1,20,STAINED_CLAY:12,15,STAINED_CLAY:15,5,AIR,7,IRON_BARS,12,CONCRETE:7,100)
RandomBlock(-6,17,-1,CONCRETE:7,60,quark:iron_plate:1,20,STAINED_CLAY:12,15,STAINED_CLAY:15,5,AIR,7,IRON_BARS,12,CONCRETE:7,100)
RandomBlock(-6,17,0,CONCRETE:7,60,quark:iron_plate:1,20,STAINED_CLAY:12,15,STAINED_CLAY:15,5,AIR,7,IRON_BARS,12,CONCRETE:7,100)
RandomBlock(-6,17,1,CONCRETE:7,60,quark:iron_plate:1,20,STAINED_CLAY:12,15,STAINED_CLAY:15,5,AIR,7,IRON_BARS,12,CONCRETE:7,100)
RandomBlock(-6,17,2,CONCRETE:7,60,quark:iron_plate:1,20,STAINED_CLAY:12,15,STAINED_CLAY:15,5,AIR,7,IRON_BARS,12,CONCRETE:7,100)
RandomBlock(-6,17,3,CONCRETE:7,60,quark:iron_plate:1,20,STAINED_CLAY:12,15,STAINED_CLAY:15,5,AIR,7,IRON_BARS,12,CONCRETE:7,100)
RandomBlock(-6,17,4,CONCRETE:7,60,quark:iron_plate:1,20,STAINED_CLAY:12,15,STAINED_CLAY:15,5,AIR,7,IRON_BARS,12,CONCRETE:7,100)
RandomBlock(-6,17,5,CONCRETE:7,60,quark:iron_plate:1,20,STAINED_CLAY:12,15,STAINED_CLAY:15,5,AIR,7,IRON_BARS,12,CONCRETE:7,100)
RandomBlock(-6,17,6,CONCRETE:7,60,quark:iron_plate:1,20,STAINED_CLAY:12,15,STAINED_CLAY:15,5,AIR,7,IRON_BARS,12,CONCRETE:7,100)
RandomBlock(-6,17,7,CONCRETE:7,60,quark:iron_plate:1,20,STAINED_CLAY:12,15,STAINED_CLAY:15,5,AIR,7,IRON_BARS,12,CONCRETE:7,100)
RandomBlock(-6,17,8,CONCRETE:7,60,quark:iron_plate:1,20,STAINED_CLAY:12,15,STAINED_CLAY:15,5,AIR,7,IRON_BARS,12,CONCRETE:7,100)
Block(-6,18,-5,CONCRETE:8)
Block(-6,18,-4,DIRT:2)
Block(-6,18,-3,DIRT:2)
Block(-6,18,-2,DIRT:2)
Block(-6,18,-1,DIRT:2)
Block(-6,18,0,CONCRETE:15)
Block(-6,18,1,CONCRETE:15)
Block(-6,18,2,CONCRETE:15)
Block(-6,18,3,CONCRETE:15)
Block(-6,18,4,CONCRETE:15)
Block(-6,18,5,CONCRETE:15)
Block(-6,18,6,CONCRETE:15)
Block(-6,18,7,CONCRETE:8)
Block(-6,18,8,CONCRETE:8)
Block(-6,19,-5,STAINED_GLASS:15)
Block(-6,19,-4,LONG_GRASS:1)
Block(-6,19,-3,RED_MUSHROOM:0)
Block(-6,19,-2,LONG_GRASS:1)
Block(-6,19,-1,DOUBLE_PLANT:5)
Block(-6,19,0,CONCRETE:8)
Block(-6,19,1,CONCRETE:8)
Block(-6,19,2,CONCRETE:8)
Block(-6,19,3,CONCRETE:8)
Block(-6,19,4,CONCRETE:8)
Block(-6,19,5,CONCRETE:8)
Block(-6,19,6,CONCRETE:8)
Block(-6,19,7,CONCRETE:8)
Block(-6,19,8,CONCRETE:8)
Block(-6,20,-5,STAINED_GLASS:15)
Block(-6,20,-1,DOUBLE_PLANT:10)
Block(-6,20,0,CONCRETE:8)
Block(-6,20,1,CONCRETE:8)
Block(-6,20,2,CONCRETE:8)
Block(-6,20,3,CONCRETE:8)
Block(-6,20,4,CONCRETE:8)
Block(-6,20,5,CONCRETE:8)
Block(-6,20,6,CONCRETE:8)
Block(-6,20,7,CONCRETE:8)
Block(-6,20,8,CONCRETE:8)
Block(-6,21,-5,STAINED_GLASS:15)
Block(-6,21,0,CONCRETE:8)
Block(-6,21,1,CONCRETE:8)
Block(-6,21,2,CONCRETE:8)
Block(-6,21,3,CONCRETE:8)
Block(-6,21,4,CONCRETE:8)
Block(-6,21,5,CONCRETE:8)
Block(-6,21,6,CONCRETE:8)
Block(-6,21,7,CONCRETE:8)
Block(-6,21,8,CONCRETE:8)
Block(-6,22,-5,STAINED_GLASS:15)
Block(-6,22,-2,LOG:5)
Block(-6,22,-1,LEAVES:4)
Block(-6,22,0,CONCRETE:8)
Block(-6,22,1,CONCRETE:8)
Block(-6,22,2,CONCRETE:8)
Block(-6,22,3,CONCRETE:8)
Block(-6,22,4,CONCRETE:8)
Block(-6,22,5,CONCRETE:8)
Block(-6,22,6,CONCRETE:8)
Block(-6,22,7,CONCRETE:8)
Block(-6,22,8,CONCRETE:8)
Block(-6,23,-5,STAINED_GLASS:15)
Block(-6,23,-4,LEAVES:12)
Block(-6,23,-3,LEAVES:12)
Block(-6,23,-2,LEAVES:12)
Block(-6,23,0,CONCRETE:8)
Block(-6,23,1,CONCRETE:8)
Block(-6,23,2,CONCRETE:8)
Block(-6,23,3,CONCRETE:8)
Block(-6,23,4,CONCRETE:8)
Block(-6,23,5,CONCRETE:8)
Block(-6,23,6,CONCRETE:8)
Block(-6,23,7,CONCRETE:8)
Block(-6,23,8,CONCRETE:8)
Block(-6,24,-5,STAINED_GLASS:15)
Block(-6,24,-3,LEAVES:4)
Block(-6,24,-2,LEAVES:12)
Block(-6,24,-1,LEAVES:4)
Block(-6,24,0,CONCRETE:8)
Block(-6,24,1,CONCRETE:8)
Block(-6,24,2,CONCRETE:8)
Block(-6,24,3,CONCRETE:8)
Block(-6,24,4,CONCRETE:8)
Block(-6,24,5,CONCRETE:8)
Block(-6,24,6,CONCRETE:8)
Block(-6,24,7,CONCRETE:8)
Block(-6,24,8,CONCRETE:8)
Block(-6,25,-5,STAINED_GLASS:15)
Block(-6,25,-2,LEAVES:12)
Block(-6,25,0,CONCRETE:8)
Block(-6,25,1,CONCRETE:8)
Block(-6,25,2,CONCRETE:8)
Block(-6,25,3,CONCRETE:8)
Block(-6,25,4,CONCRETE:8)
Block(-6,25,5,CONCRETE:8)
Block(-6,25,6,CONCRETE:8)
Block(-6,25,7,CONCRETE:8)
Block(-6,25,8,CONCRETE:8)
Block(-6,26,-5,STAINED_GLASS:15)
Block(-6,26,0,CONCRETE:8)
Block(-6,26,1,CONCRETE:8)
Block(-6,26,2,CONCRETE:8)
Block(-6,26,3,CONCRETE:8)
Block(-6,26,4,CONCRETE:8)
Block(-6,26,5,CONCRETE:8)
Block(-6,26,6,CONCRETE:8)
Block(-6,26,7,CONCRETE:8)
Block(-6,26,8,CONCRETE:8)
Block(-6,27,-5,STAINED_GLASS:15)
Block(-6,27,-4,CONCRETE:8)
Block(-6,27,-3,CONCRETE:8)
Block(-6,27,-2,CONCRETE:8)
Block(-6,27,-1,CONCRETE:8)
Block(-6,27,0,CONCRETE:8)
Block(-6,27,1,CONCRETE:8)
Block(-6,27,2,CONCRETE:8)
Block(-6,27,3,CONCRETE:8)
Block(-6,27,4,CONCRETE:8)
Block(-6,27,5,CONCRETE:8)
Block(-6,27,6,CONCRETE:8)
Block(-6,27,7,CONCRETE:8)
Block(-6,27,8,CONCRETE:8)
Block(-6,28,-5,STAINED_GLASS:15)
RandomBlock(-6,28,-4,STONE:6,80,STONE:6,90,DISPENSER:3,../../../../../Chests/Loot/city_potions.nbt,100)
Block(-6,28,-3,TRIPWIRE_HOOK:0)
Block(-6,29,-5,STAINED_GLASS:15)
RandomBlock(-6,29,-4,STONE:6,80,STONE:6,90,DISPENSER:3,../../../../../Chests/Loot/city_potions.nbt,100)
RandomBlock(-6,29,-3,AIR,95,WALL_BANNER:3,../AllScraperData/skyscraper_2x2_04/333-bannerC16R0.nbt,100)
Block(-6,30,-5,STAINED_GLASS:15)
RandomBlock(-6,30,-4,AIR,90,IRON_TRAPDOOR:1,100)
Block(-6,31,-5,STAINED_GLASS:15)
Block(-6,32,-5,STAINED_GLASS:15)
Block(-6,33,-5,STAINED_GLASS:15)
Block(-6,34,-5,STAINED_GLASS:15)
Block(-6,35,-5,STAINED_GLASS:15)
Block(-6,35,-4,CONCRETE:8)
Block(-6,35,-3,CONCRETE:8)
Block(-6,35,-2,CONCRETE:8)
Block(-6,35,-1,CONCRETE:8)
Block(-6,35,0,CONCRETE:8)
Block(-6,35,1,CONCRETE:8)
Block(-6,35,2,CONCRETE:8)
Block(-6,35,3,CONCRETE:8)
Block(-6,35,4,CONCRETE:8)
Block(-6,35,5,CONCRETE:8)
Block(-6,35,6,CONCRETE:8)
Block(-6,35,7,CONCRETE:8)
Block(-6,35,8,CONCRETE:8)
Block(-6,36,-5,STAINED_GLASS:15)
RandomBlock(-6,36,-4,STONE:6,80,STONE:6,90,DISPENSER:3,../../../../../Chests/Loot/city_potions.nbt,100)
Block(-6,36,-3,TRIPWIRE_HOOK:0)
Block(-6,37,-5,STAINED_GLASS:15)
RandomBlock(-6,37,-4,STONE:6,80,STONE:6,90,DISPENSER:3,../../../../../Chests/Loot/city_potions.nbt,100)
RandomBlock(-6,37,-3,AIR,95,WALL_BANNER:3,../AllScraperData/skyscraper_2x2_04/336-bannerC16R0.nbt,100)
Block(-6,38,-5,STAINED_GLASS:15)
RandomBlock(-6,38,-4,AIR,90,IRON_TRAPDOOR:1,100)
Block(-6,39,-5,STAINED_GLASS:15)
Block(-6,40,-5,STAINED_GLASS:15)
Block(-6,41,-5,STAINED_GLASS:15)
Block(-6,42,6,STAINED_GLASS:15)
Block(-6,43,6,STAINED_GLASS:15)
Block(-6,43,7,CONCRETE:8)
Block(-6,43,8,CONCRETE:8)
Block(-6,44,6,STAINED_GLASS:15)
Block(-6,45,6,STAINED_GLASS:15)
Block(-6,46,6,STAINED_GLASS:15)
Block(-6,47,6,STAINED_GLASS:15)
Block(-6,48,6,STAINED_GLASS:15)
Block(-6,49,6,STAINED_GLASS:15)
Block(-6,50,6,STAINED_GLASS:15)
Block(-6,50,7,QUARTZ_STAIRS:4)
Block(-6,51,6,STAINED_GLASS:15)
Block(-6,51,7,QUARTZ_STAIRS:1)
Block(-6,51,8,CONCRETE:8)
Block(-6,52,6,STAINED_GLASS:15)
Block(-6,53,6,STAINED_GLASS:15)
Block(-6,54,6,STAINED_GLASS:15)
Block(-6,55,6,STAINED_GLASS:15)
Block(-6,56,6,STAINED_GLASS:15)
Block(-6,57,6,STAINED_GLASS:15)
Block(-6,58,6,STAINED_GLASS:15)
Block(-6,59,6,STAINED_GLASS:15)
Block(-6,60,6,STAINED_GLASS:15)
Block(-6,61,6,STAINED_GLASS:15)
Block(-6,62,6,CONCRETE:8)
Block(-6,63,6,CONCRETE:8)
Block(-6,63,7,CONCRETE:8)
Block(-6,63,8,CONCRETE:8)
Block(-6,64,6,CONCRETE:8)
Block(-6,64,7,CONCRETE:8)
Block(-6,64,8,CONCRETE:8)
RandomBlock(-5,0,-7,CONCRETE:7,60,quark:iron_plate:1,20,STAINED_CLAY:12,15,STAINED_CLAY:15,5,AIR,7,IRON_BARS,12,CONCRETE:7,100)
RandomBlock(-5,0,-6,CONCRETE:7,60,quark:iron_plate:1,20,STAINED_CLAY:12,15,STAINED_CLAY:15,5,AIR,7,IRON_BARS,12,CONCRETE:7,100)
RandomBlock(-5,0,-5,CONCRETE:7,60,quark:iron_plate:1,20,STAINED_CLAY:12,15,STAINED_CLAY:15,5,AIR,7,IRON_BARS,12,CONCRETE:7,100)
RandomBlock(-5,0,-4,CONCRETE:7,60,quark:iron_plate:1,20,STAINED_CLAY:12,15,STAINED_CLAY:15,5,AIR,7,IRON_BARS,12,CONCRETE:7,100)
RandomBlock(-5,0,-3,CONCRETE:7,60,quark:iron_plate:1,20,STAINED_CLAY:12,15,STAINED_CLAY:15,5,AIR,7,IRON_BARS,12,CONCRETE:7,100)
RandomBlock(-5,0,-2,CONCRETE:7,60,quark:iron_plate:1,20,STAINED_CLAY:12,15,STAINED_CLAY:15,5,AIR,7,IRON_BARS,12,CONCRETE:7,100)
RandomBlock(-5,0,-1,CONCRETE:7,60,quark:iron_plate:1,20,STAINED_CLAY:12,15,STAINED_CLAY:15,5,AIR,7,IRON_BARS,12,CONCRETE:7,100)
RandomBlock(-5,0,0,CONCRETE:7,60,quark:iron_plate:1,20,STAINED_CLAY:12,15,STAINED_CLAY:15,5,AIR,7,IRON_BARS,12,CONCRETE:7,100)
RandomBlock(-5,0,1,CONCRETE:7,60,quark:iron_plate:1,20,STAINED_CLAY:12,15,STAINED_CLAY:15,5,AIR,7,IRON_BARS,12,CONCRETE:7,100)
RandomBlock(-5,0,2,CONCRETE:7,60,quark:iron_plate:1,20,STAINED_CLAY:12,15,STAINED_CLAY:15,5,AIR,7,IRON_BARS,12,CONCRETE:7,100)
RandomBlock(-5,0,3,CONCRETE:7,60,quark:iron_plate:1,20,STAINED_CLAY:12,15,STAINED_CLAY:15,5,AIR,7,IRON_BARS,12,CONCRETE:7,100)
RandomBlock(-5,0,4,CONCRETE:7,60,quark:iron_plate:1,20,STAINED_CLAY:12,15,STAINED_CLAY:15,5,AIR,7,IRON_BARS,12,CONCRETE:7,100)
RandomBlock(-5,0,5,CONCRETE:7,60,quark:iron_plate:1,20,STAINED_CLAY:12,15,STAINED_CLAY:15,5,AIR,7,IRON_BARS,12,CONCRETE:7,100)
RandomBlock(-5,0,6,CONCRETE:7,60,quark:iron_plate:1,20,STAINED_CLAY:12,15,STAINED_CLAY:15,5,AIR,7,IRON_BARS,12,CONCRETE:7,100)
RandomBlock(-5,0,7,CONCRETE:7,60,quark:iron_plate:1,20,STAINED_CLAY:12,15,STAINED_CLAY:15,5,AIR,7,IRON_BARS,12,CONCRETE:7,100)
RandomBlock(-5,0,8,CONCRETE:7,60,quark:iron_plate:1,20,STAINED_CLAY:12,15,STAINED_CLAY:15,5,AIR,7,IRON_BARS,12,CONCRETE:7,100)
Block(-5,1,-7,STATIONARY_WATER:0)
Block(-5,1,-6,STATIONARY_WATER:0)
Block(-5,1,-5,STATIONARY_WATER:0)
Block(-5,1,-4,STATIONARY_WATER:0)
Block(-5,1,-3,STATIONARY_WATER:0)
Block(-5,1,-2,STATIONARY_WATER:0)
Block(-5,1,-1,STATIONARY_WATER:0)
Block(-5,1,0,STATIONARY_WATER:0)
Block(-5,1,1,STATIONARY_WATER:0)
Block(-5,1,2,STATIONARY_WATER:0)
Block(-5,1,3,STATIONARY_WATER:0)
Block(-5,1,4,STATIONARY_WATER:0)
Block(-5,1,5,STATIONARY_WATER:0)
Block(-5,1,6,STATIONARY_WATER:0)
Block(-5,1,7,STATIONARY_WATER:0)
Block(-5,1,8,STATIONARY_WATER:0)
Block(-5,2,-7,AIR:0)
Block(-5,2,-6,AIR:0)
Block(-5,2,-5,AIR:0)
Block(-5,2,-4,AIR:0)
Block(-5,2,-3,AIR:0)
Block(-5,2,-2,AIR:0)
Block(-5,2,-1,AIR:0)
Block(-5,2,0,AIR:0)
Block(-5,2,1,AIR:0)
Block(-5,2,2,AIR:0)
Block(-5,2,3,AIR:0)
Block(-5,2,4,AIR:0)
Block(-5,2,5,AIR:0)
Block(-5,2,6,AIR:0)
Block(-5,2,7,AIR:0)
Block(-5,2,8,AIR:0)
Block(-5,3,-7,AIR:0)
Block(-5,3,-6,AIR:0)
Block(-5,3,-5,AIR:0)
Block(-5,3,-4,AIR:0)
Block(-5,3,-3,AIR:0)
Block(-5,3,-2,AIR:0)
Block(-5,3,-1,AIR:0)
Block(-5,3,0,AIR:0)
Block(-5,3,1,AIR:0)
Block(-5,3,2,AIR:0)
Block(-5,3,3,AIR:0)
Block(-5,3,4,AIR:0)
Block(-5,3,5,AIR:0)
Block(-5,3,6,AIR:0)
Block(-5,3,7,AIR:0)
Block(-5,3,8,AIR:0)
Block(-5,4,-7,AIR:0)
Block(-5,4,-6,AIR:0)
Block(-5,4,-5,AIR:0)
Block(-5,4,-4,AIR:0)
Block(-5,4,-3,AIR:0)
Block(-5,4,-2,AIR:0)
Block(-5,4,-1,AIR:0)
Block(-5,4,0,AIR:0)
Block(-5,4,1,AIR:0)
Block(-5,4,2,AIR:0)
Block(-5,4,3,AIR:0)
Block(-5,4,4,AIR:0)
Block(-5,4,5,AIR:0)
Block(-5,4,6,AIR:0)
Block(-5,4,7,AIR:0)
Block(-5,4,8,AIR:0)
Block(-5,5,-7,AIR:0)
Block(-5,5,-6,AIR:0)
Block(-5,5,-5,AIR:0)
Block(-5,5,-4,AIR:0)
Block(-5,5,-3,AIR:0)
Block(-5,5,-2,AIR:0)
Block(-5,5,-1,AIR:0)
Block(-5,5,0,AIR:0)
Block(-5,5,1,AIR:0)
Block(-5,5,2,AIR:0)
Block(-5,5,3,AIR:0)
Block(-5,5,4,AIR:0)
Block(-5,5,5,AIR:0)
Block(-5,5,6,CONCRETE:12)
Block(-5,5,7,CONCRETE:4)
Block(-5,5,8,AIR:0)
RandomBlock(-5,6,-7,CONCRETE:7,60,quark:iron_plate:1,20,STAINED_CLAY:12,15,STAINED_CLAY:15,5,AIR,7,IRON_BARS,12,CONCRETE:7,100)
Block(-5,6,-6,AIR:0)
Block(-5,6,-5,AIR:0)
Block(-5,6,-4,AIR:0)
Block(-5,6,-3,AIR:0)
Block(-5,6,-2,AIR:0)
Block(-5,6,-1,AIR:0)
Block(-5,6,0,AIR:0)
Block(-5,6,1,AIR:0)
Block(-5,6,2,AIR:0)
Block(-5,6,3,AIR:0)
Block(-5,6,4,AIR:0)
Block(-5,6,5,AIR:0)
Block(-5,6,6,AIR:0)
Block(-5,6,7,IRON_FENCE:0)
Block(-5,6,8,AIR:0)
RandomBlock(-5,7,-7,CONCRETE:7,60,quark:iron_plate:1,20,STAINED_CLAY:12,15,STAINED_CLAY:15,5,AIR,7,IRON_BARS,12,CONCRETE:7,100)
RandomBlock(-5,7,-6,CONCRETE:7,60,quark:iron_plate:1,20,STAINED_CLAY:12,15,STAINED_CLAY:15,5,AIR,7,IRON_BARS,12,CONCRETE:7,100)
RandomBlock(-5,7,-5,CONCRETE:7,60,quark:iron_plate:1,20,STAINED_CLAY:12,15,STAINED_CLAY:15,5,AIR,7,IRON_BARS,12,CONCRETE:7,100)
RandomBlock(-5,7,-4,CONCRETE:7,60,quark:iron_plate:1,20,STAINED_CLAY:12,15,STAINED_CLAY:15,5,AIR,7,IRON_BARS,12,CONCRETE:7,100)
RandomBlock(-5,7,-3,CONCRETE:7,60,quark:iron_plate:1,20,STAINED_CLAY:12,15,STAINED_CLAY:15,5,AIR,7,IRON_BARS,12,CONCRETE:7,100)
RandomBlock(-5,7,-2,CONCRETE:7,60,quark:iron_plate:1,20,STAINED_CLAY:12,15,STAINED_CLAY:15,5,AIR,7,IRON_BARS,12,CONCRETE:7,100)
RandomBlock(-5,7,-1,CONCRETE:7,60,quark:iron_plate:1,20,STAINED_CLAY:12,15,STAINED_CLAY:15,5,AIR,7,IRON_BARS,12,CONCRETE:7,100)
RandomBlock(-5,7,0,CONCRETE:7,60,quark:iron_plate:1,20,STAINED_CLAY:12,15,STAINED_CLAY:15,5,AIR,7,IRON_BARS,12,CONCRETE:7,100)
RandomBlock(-5,7,1,CONCRETE:7,60,quark:iron_plate:1,20,STAINED_CLAY:12,15,STAINED_CLAY:15,5,AIR,7,IRON_BARS,12,CONCRETE:7,100)
RandomBlock(-5,7,2,CONCRETE:7,60,quark:iron_plate:1,20,STAINED_CLAY:12,15,STAINED_CLAY:15,5,AIR,7,IRON_BARS,12,CONCRETE:7,100)
RandomBlock(-5,7,3,CONCRETE:7,60,quark:iron_plate:1,20,STAINED_CLAY:12,15,STAINED_CLAY:15,5,AIR,7,IRON_BARS,12,CONCRETE:7,100)
RandomBlock(-5,7,4,CONCRETE:7,60,quark:iron_plate:1,20,STAINED_CLAY:12,15,STAINED_CLAY:15,5,AIR,7,IRON_BARS,12,CONCRETE:7,100)
RandomBlock(-5,7,5,CONCRETE:7,60,quark:iron_plate:1,20,STAINED_CLAY:12,15,STAINED_CLAY:15,5,AIR,7,IRON_BARS,12,CONCRETE:7,100)
RandomBlock(-5,7,6,CONCRETE:7,60,quark:iron_plate:1,20,STAINED_CLAY:12,15,STAINED_CLAY:15,5,AIR,7,IRON_BARS,12,CONCRETE:7,100)
RandomBlock(-5,7,7,CONCRETE:7,60,quark:iron_plate:1,20,STAINED_CLAY:12,15,STAINED_CLAY:15,5,AIR,7,IRON_BARS,12,CONCRETE:7,100)
RandomBlock(-5,7,8,CONCRETE:7,60,quark:iron_plate:1,20,STAINED_CLAY:12,15,STAINED_CLAY:15,5,AIR,7,IRON_BARS,12,CONCRETE:7,100)
RandomBlock(-5,8,-7,CONCRETE:7,60,quark:iron_plate:1,20,STAINED_CLAY:12,15,STAINED_CLAY:15,5,AIR,7,IRON_BARS,12,CONCRETE:7,100)
RandomBlock(-5,8,-6,CONCRETE:7,60,quark:iron_plate:1,20,STAINED_CLAY:12,15,STAINED_CLAY:15,5,AIR,7,IRON_BARS,12,CONCRETE:7,100)
RandomBlock(-5,8,-5,CONCRETE:7,60,quark:iron_plate:1,20,STAINED_CLAY:12,15,STAINED_CLAY:15,5,AIR,7,IRON_BARS,12,CONCRETE:7,100)
RandomBlock(-5,8,-4,CONCRETE:7,60,quark:iron_plate:1,20,STAINED_CLAY:12,15,STAINED_CLAY:15,5,AIR,7,IRON_BARS,12,CONCRETE:7,100)
RandomBlock(-5,8,-3,CONCRETE:7,60,quark:iron_plate:1,20,STAINED_CLAY:12,15,STAINED_CLAY:15,5,AIR,7,IRON_BARS,12,CONCRETE:7,100)
RandomBlock(-5,8,-2,CONCRETE:7,60,quark:iron_plate:1,20,STAINED_CLAY:12,15,STAINED_CLAY:15,5,AIR,7,IRON_BARS,12,CONCRETE:7,100)
RandomBlock(-5,8,-1,CONCRETE:7,60,quark:iron_plate:1,20,STAINED_CLAY:12,15,STAINED_CLAY:15,5,AIR,7,IRON_BARS,12,CONCRETE:7,100)
RandomBlock(-5,8,0,CONCRETE:7,60,quark:iron_plate:1,20,STAINED_CLAY:12,15,STAINED_CLAY:15,5,AIR,7,IRON_BARS,12,CONCRETE:7,100)
RandomBlock(-5,8,1,CONCRETE:7,60,quark:iron_plate:1,20,STAINED_CLAY:12,15,STAINED_CLAY:15,5,AIR,7,IRON_BARS,12,CONCRETE:7,100)
RandomBlock(-5,8,2,CONCRETE:7,60,quark:iron_plate:1,20,STAINED_CLAY:12,15,STAINED_CLAY:15,5,AIR,7,IRON_BARS,12,CONCRETE:7,100)
RandomBlock(-5,8,3,CONCRETE:7,60,quark:iron_plate:1,20,STAINED_CLAY:12,15,STAINED_CLAY:15,5,AIR,7,IRON_BARS,12,CONCRETE:7,100)
RandomBlock(-5,8,4,CONCRETE:7,60,quark:iron_plate:1,20,STAINED_CLAY:12,15,STAINED_CLAY:15,5,AIR,7,IRON_BARS,12,CONCRETE:7,100)
RandomBlock(-5,8,5,CONCRETE:7,60,quark:iron_plate:1,20,STAINED_CLAY:12,15,STAINED_CLAY:15,5,AIR,7,IRON_BARS,12,CONCRETE:7,100)
RandomBlock(-5,8,6,CONCRETE:7,60,quark:iron_plate:1,20,STAINED_CLAY:12,15,STAINED_CLAY:15,5,AIR,7,IRON_BARS,12,CONCRETE:7,100)
RandomBlock(-5,8,7,CONCRETE:7,60,quark:iron_plate:1,20,STAINED_CLAY:12,15,STAINED_CLAY:15,5,AIR,7,IRON_BARS,12,CONCRETE:7,100)
RandomBlock(-5,8,8,CONCRETE:7,60,quark:iron_plate:1,20,STAINED_CLAY:12,15,STAINED_CLAY:15,5,AIR,7,IRON_BARS,12,CONCRETE:7,100)
RandomBlock(-5,9,-7,CONCRETE:7,60,quark:iron_plate:1,20,STAINED_CLAY:12,15,STAINED_CLAY:15,5,AIR,7,IRON_BARS,12,CONCRETE:7,100)
