
#######################################################################
# +-----------------------------------------------------------------+ #
# |                            BO4 object                           | #
# +-----------------------------------------------------------------+ #
#######################################################################

Author: NLBlackEagle

Description: No description given

SettingsMode: WriteDisable


#######################################################################
# +-----------------------------------------------------------------+ #
# |                          Main settings                          | #
# +-----------------------------------------------------------------+ #
#######################################################################

Frequency: 0

SpawnHeight: highestBlock

UseCenterForHighestBlock: true

##############################
# Height Limits for the BO4. #
##############################

MinHeight: 0

MaxHeight: 255

InheritBO3: 

InheritBO3Rotation: NORTH

OverrideChildSettings: true

OverrideParentHeight: false

CanOverride: true

BranchFrequency: 0

BranchFrequencyGroup: 

MustBeBelowOther: false

MustBeInside: 

CannotBeInside: 

ReplacesBO3: L4-M-CrossC0R0, L4-M-CrossC0R1, L4-M-CrossC0R2, L4-M-CrossC0R3, L4-M-CrossC1R0, L4-M-CrossC1R1, L4-M-CrossC1R2, L4-M-CrossC1R3, L4-M-CrossC2R0, L4-M-CrossC2R1, L4-M-CrossC2R2, L4-M-CrossC2R3, L4-M-CrossC3R0, L4-M-CrossC3R1, L4-M-CrossC3R2, L4-M-CrossC3R3, L4-M-Straigth-START_01-C0R0, L4-M-Straigth-START_01-C0R1, L4-M-Straigth-START_01-C1R0, L4-M-Straigth-START_01-C1R1, L4-M-Straigth-START_01-C2R0, L4-M-Straigth-START_01-C2R1, L4-M-Straigth-START_01-C3R0, L4-M-Straigth-START_01-C3R1, L4-M-Straigth-3CC0R0, L4-M-Straigth-3CC0R1, L4-M-Straigth-3CC0R2, L4-M-Straigth-3CC1R0, L4-M-Straigth-3CC1R1, L4-M-Straigth-3CC1R2, L4-M-Straigth-3CC2R0, L4-M-Straigth-3CC2R1, L4-M-Straigth-3CC2R2, L4-M-Straigth-3CC3R0, L4-M-Straigth-3CC3R1, L4-M-Straigth-3CC3R2, L4-M-Cross, skyscraper_2x2_01, skyscraper_2x2_02, skyscraper_2x2_03, skyscraper_2x2_04, skyscraper_2x2_05, skyscraper_3x3_01, skyscraper_3x3_02, skyscraper_3x3_03, L3-M-Straigth-2CC0R0, L3-M-Straigth-2CC0R1, L3-M-Straigth-2CC1R0, L3-M-Straigth-2CC1R1, L3-M-Straigth-2CC2R0, L3-M-Straigth-2CC2R1, L3-M-Straigth-2CC3R0, L3-M-Straigth-2CC3R1, L3-M-Straigth-3CC0R0, L3-M-Straigth-3CC0R1, L3-M-Straigth-3CC0R2, L3-M-Straigth-3CC1R0, L3-M-Straigth-3CC1R1, L3-M-Straigth-3CC1R2, L3-M-Straigth-3CC2R0, L3-M-Straigth-3CC2R1, L3-M-Straigth-3CC2R2, L3-M-Straigth-3CC3R0, L3-M-Straigth-3CC3R1, L3-M-Straigth-3CC3R2

MustBeInsideWorldBorders: true
CanSpawnOnWater: true

SpawnOnWaterOnly: false

SpawnUnderWater: false

SpawnAtWaterLevel: false

HeightOffset: 0

RemoveAir: false

ReplaceAbove: 

ReplaceBelow: 

ReplaceWithBiomeBlocks: true

ReplaceWithSurfaceBlock: GRASS

ReplaceWithGroundBlock: DIRT

ReplaceWithStoneBlock: STONE

SmoothRadius: 0

SmoothHeightOffset: 0

SmoothStartTop: false

SmoothStartWood: false

SmoothingSurfaceBlock: 

SmoothingGroundBlock: 

BO3Group: 

IsSpawnPoint: false

DoReplaceBlocks: true


#######################################################################
# +-----------------------------------------------------------------+ #
# |                              Blocks                             | #
# +-----------------------------------------------------------------+ #
#######################################################################

RandomBlock(-8,0,-7,CONCRETE:7,60,quark:iron_plate:1,20,STAINED_CLAY:12,15,STAINED_CLAY:15,5,AIR,7,IRON_BARS,12,CONCRETE:7,100)
RandomBlock(-8,0,-6,CONCRETE:7,60,quark:iron_plate:1,20,STAINED_CLAY:12,15,STAINED_CLAY:15,5,AIR,7,IRON_BARS,12,CONCRETE:7,100)
RandomBlock(-8,0,-5,CONCRETE:7,60,quark:iron_plate:1,20,STAINED_CLAY:12,15,STAINED_CLAY:15,5,AIR,7,IRON_BARS,12,CONCRETE:7,100)
RandomBlock(-8,0,-4,CONCRETE:7,60,quark:iron_plate:1,20,STAINED_CLAY:12,15,STAINED_CLAY:15,5,AIR,7,IRON_BARS,12,CONCRETE:7,100)
RandomBlock(-8,0,-3,CONCRETE:7,60,quark:iron_plate:1,20,STAINED_CLAY:12,15,STAINED_CLAY:15,5,AIR,7,IRON_BARS,12,CONCRETE:7,100)
RandomBlock(-8,0,-2,CONCRETE:7,60,quark:iron_plate:1,20,STAINED_CLAY:12,15,STAINED_CLAY:15,5,AIR,7,IRON_BARS,12,CONCRETE:7,100)
RandomBlock(-8,0,-1,CONCRETE:7,60,quark:iron_plate:1,20,STAINED_CLAY:12,15,STAINED_CLAY:15,5,AIR,7,IRON_BARS,12,CONCRETE:7,100)
RandomBlock(-8,0,0,CONCRETE:7,60,quark:iron_plate:1,20,STAINED_CLAY:12,15,STAINED_CLAY:15,5,AIR,7,IRON_BARS,12,CONCRETE:7,100)
RandomBlock(-8,0,1,CONCRETE:7,60,quark:iron_plate:1,20,STAINED_CLAY:12,15,STAINED_CLAY:15,5,AIR,7,IRON_BARS,12,CONCRETE:7,100)
RandomBlock(-8,0,2,CONCRETE:7,60,quark:iron_plate:1,20,STAINED_CLAY:12,15,STAINED_CLAY:15,5,AIR,7,IRON_BARS,12,CONCRETE:7,100)
RandomBlock(-8,0,3,CONCRETE:7,60,quark:iron_plate:1,20,STAINED_CLAY:12,15,STAINED_CLAY:15,5,AIR,7,IRON_BARS,12,CONCRETE:7,100)
RandomBlock(-8,0,4,CONCRETE:7,60,quark:iron_plate:1,20,STAINED_CLAY:12,15,STAINED_CLAY:15,5,AIR,7,IRON_BARS,12,CONCRETE:7,100)
RandomBlock(-8,0,5,CONCRETE:7,60,quark:iron_plate:1,20,STAINED_CLAY:12,15,STAINED_CLAY:15,5,AIR,7,IRON_BARS,12,CONCRETE:7,100)
RandomBlock(-8,0,6,CONCRETE:7,60,quark:iron_plate:1,20,STAINED_CLAY:12,15,STAINED_CLAY:15,5,AIR,7,IRON_BARS,12,CONCRETE:7,100)
RandomBlock(-8,0,7,CONCRETE:7,60,quark:iron_plate:1,20,STAINED_CLAY:12,15,STAINED_CLAY:15,5,AIR,7,IRON_BARS,12,CONCRETE:7,100)
RandomBlock(-8,0,8,CONCRETE:7,60,quark:iron_plate:1,20,STAINED_CLAY:12,15,STAINED_CLAY:15,5,AIR,7,IRON_BARS,12,CONCRETE:7,100)
RandomBlock(-8,1,-7,CONCRETE:7,60,quark:iron_plate:1,20,STAINED_CLAY:12,15,STAINED_CLAY:15,5,AIR,7,IRON_BARS,12,CONCRETE:7,100)
RandomBlock(-8,1,-6,CONCRETE:7,60,quark:iron_plate:1,20,STAINED_CLAY:12,15,STAINED_CLAY:15,5,AIR,7,IRON_BARS,12,CONCRETE:7,100)
RandomBlock(-8,1,-5,CONCRETE:7,60,quark:iron_plate:1,20,STAINED_CLAY:12,15,STAINED_CLAY:15,5,AIR,7,IRON_BARS,12,CONCRETE:7,100)
RandomBlock(-8,1,-4,CONCRETE:7,60,quark:iron_plate:1,20,STAINED_CLAY:12,15,STAINED_CLAY:15,5,AIR,7,IRON_BARS,12,CONCRETE:7,100)
RandomBlock(-8,1,-3,CONCRETE:7,60,quark:iron_plate:1,20,STAINED_CLAY:12,15,STAINED_CLAY:15,5,AIR,7,IRON_BARS,12,CONCRETE:7,100)
RandomBlock(-8,1,-2,CONCRETE:7,60,quark:iron_plate:1,20,STAINED_CLAY:12,15,STAINED_CLAY:15,5,AIR,7,IRON_BARS,12,CONCRETE:7,100)
RandomBlock(-8,1,-1,CONCRETE:7,60,quark:iron_plate:1,20,STAINED_CLAY:12,15,STAINED_CLAY:15,5,AIR,7,IRON_BARS,12,CONCRETE:7,100)
RandomBlock(-8,1,0,CONCRETE:7,60,quark:iron_plate:1,20,STAINED_CLAY:12,15,STAINED_CLAY:15,5,AIR,7,IRON_BARS,12,CONCRETE:7,100)
RandomBlock(-8,1,1,CONCRETE:7,60,quark:iron_plate:1,20,STAINED_CLAY:12,15,STAINED_CLAY:15,5,AIR,7,IRON_BARS,12,CONCRETE:7,100)
RandomBlock(-8,1,2,CONCRETE:7,60,quark:iron_plate:1,20,STAINED_CLAY:12,15,STAINED_CLAY:15,5,AIR,7,IRON_BARS,12,CONCRETE:7,100)
RandomBlock(-8,1,3,CONCRETE:7,60,quark:iron_plate:1,20,STAINED_CLAY:12,15,STAINED_CLAY:15,5,AIR,7,IRON_BARS,12,CONCRETE:7,100)
RandomBlock(-8,1,4,CONCRETE:7,60,quark:iron_plate:1,20,STAINED_CLAY:12,15,STAINED_CLAY:15,5,AIR,7,IRON_BARS,12,CONCRETE:7,100)
RandomBlock(-8,1,5,CONCRETE:7,60,quark:iron_plate:1,20,STAINED_CLAY:12,15,STAINED_CLAY:15,5,AIR,7,IRON_BARS,12,CONCRETE:7,100)
RandomBlock(-8,1,6,CONCRETE:7,60,quark:iron_plate:1,20,STAINED_CLAY:12,15,STAINED_CLAY:15,5,AIR,7,IRON_BARS,12,CONCRETE:7,100)
RandomBlock(-8,1,7,CONCRETE:7,60,quark:iron_plate:1,20,STAINED_CLAY:12,15,STAINED_CLAY:15,5,AIR,7,IRON_BARS,12,CONCRETE:7,100)
RandomBlock(-8,1,8,CONCRETE:7,60,quark:iron_plate:1,20,STAINED_CLAY:12,15,STAINED_CLAY:15,5,AIR,7,IRON_BARS,12,CONCRETE:7,100)
RandomBlock(-8,2,-7,CONCRETE:7,60,quark:iron_plate:1,20,STAINED_CLAY:12,15,STAINED_CLAY:15,5,AIR,7,IRON_BARS,12,CONCRETE:7,100)
RandomBlock(-8,2,-6,CONCRETE:7,60,quark:iron_plate:1,20,STAINED_CLAY:12,15,STAINED_CLAY:15,5,AIR,7,IRON_BARS,12,CONCRETE:7,100)
RandomBlock(-8,2,-5,CONCRETE:7,60,quark:iron_plate:1,20,STAINED_CLAY:12,15,STAINED_CLAY:15,5,AIR,7,IRON_BARS,12,CONCRETE:7,100)
RandomBlock(-8,2,-4,CONCRETE:7,60,quark:iron_plate:1,20,STAINED_CLAY:12,15,STAINED_CLAY:15,5,AIR,7,IRON_BARS,12,CONCRETE:7,100)
RandomBlock(-8,2,-3,CONCRETE:7,60,quark:iron_plate:1,20,STAINED_CLAY:12,15,STAINED_CLAY:15,5,AIR,7,IRON_BARS,12,CONCRETE:7,100)
RandomBlock(-8,2,-2,CONCRETE:7,60,quark:iron_plate:1,20,STAINED_CLAY:12,15,STAINED_CLAY:15,5,AIR,7,IRON_BARS,12,CONCRETE:7,100)
RandomBlock(-8,2,-1,CONCRETE:7,60,quark:iron_plate:1,20,STAINED_CLAY:12,15,STAINED_CLAY:15,5,AIR,7,IRON_BARS,12,CONCRETE:7,100)
RandomBlock(-8,2,0,CONCRETE:7,60,quark:iron_plate:1,20,STAINED_CLAY:12,15,STAINED_CLAY:15,5,AIR,7,IRON_BARS,12,CONCRETE:7,100)
RandomBlock(-8,2,1,CONCRETE:7,60,quark:iron_plate:1,20,STAINED_CLAY:12,15,STAINED_CLAY:15,5,AIR,7,IRON_BARS,12,CONCRETE:7,100)
RandomBlock(-8,2,2,CONCRETE:7,60,quark:iron_plate:1,20,STAINED_CLAY:12,15,STAINED_CLAY:15,5,AIR,7,IRON_BARS,12,CONCRETE:7,100)
RandomBlock(-8,2,3,CONCRETE:7,60,quark:iron_plate:1,20,STAINED_CLAY:12,15,STAINED_CLAY:15,5,AIR,7,IRON_BARS,12,CONCRETE:7,100)
RandomBlock(-8,2,4,CONCRETE:7,60,quark:iron_plate:1,20,STAINED_CLAY:12,15,STAINED_CLAY:15,5,AIR,7,IRON_BARS,12,CONCRETE:7,100)
RandomBlock(-8,2,5,CONCRETE:7,60,quark:iron_plate:1,20,STAINED_CLAY:12,15,STAINED_CLAY:15,5,AIR,7,IRON_BARS,12,CONCRETE:7,100)
RandomBlock(-8,2,6,CONCRETE:7,60,quark:iron_plate:1,20,STAINED_CLAY:12,15,STAINED_CLAY:15,5,AIR,7,IRON_BARS,12,CONCRETE:7,100)
RandomBlock(-8,2,7,CONCRETE:7,60,quark:iron_plate:1,20,STAINED_CLAY:12,15,STAINED_CLAY:15,5,AIR,7,IRON_BARS,12,CONCRETE:7,100)
RandomBlock(-8,2,8,CONCRETE:7,60,quark:iron_plate:1,20,STAINED_CLAY:12,15,STAINED_CLAY:15,5,AIR,7,IRON_BARS,12,CONCRETE:7,100)
RandomBlock(-8,3,-7,CONCRETE:7,60,quark:iron_plate:1,20,STAINED_CLAY:12,15,STAINED_CLAY:15,5,AIR,7,IRON_BARS,12,CONCRETE:7,100)
RandomBlock(-8,3,-6,CONCRETE:7,60,quark:iron_plate:1,20,STAINED_CLAY:12,15,STAINED_CLAY:15,5,AIR,7,IRON_BARS,12,CONCRETE:7,100)
RandomBlock(-8,3,-5,CONCRETE:7,60,quark:iron_plate:1,20,STAINED_CLAY:12,15,STAINED_CLAY:15,5,AIR,7,IRON_BARS,12,CONCRETE:7,100)
RandomBlock(-8,3,-4,CONCRETE:7,60,quark:iron_plate:1,20,STAINED_CLAY:12,15,STAINED_CLAY:15,5,AIR,7,IRON_BARS,12,CONCRETE:7,100)
RandomBlock(-8,3,-3,CONCRETE:7,60,quark:iron_plate:1,20,STAINED_CLAY:12,15,STAINED_CLAY:15,5,AIR,7,IRON_BARS,12,CONCRETE:7,100)
RandomBlock(-8,3,-2,CONCRETE:7,60,quark:iron_plate:1,20,STAINED_CLAY:12,15,STAINED_CLAY:15,5,AIR,7,IRON_BARS,12,CONCRETE:7,100)
RandomBlock(-8,3,-1,CONCRETE:7,60,quark:iron_plate:1,20,STAINED_CLAY:12,15,STAINED_CLAY:15,5,AIR,7,IRON_BARS,12,CONCRETE:7,100)
RandomBlock(-8,3,0,CONCRETE:7,60,quark:iron_plate:1,20,STAINED_CLAY:12,15,STAINED_CLAY:15,5,AIR,7,IRON_BARS,12,CONCRETE:7,100)
RandomBlock(-8,3,1,CONCRETE:7,60,quark:iron_plate:1,20,STAINED_CLAY:12,15,STAINED_CLAY:15,5,AIR,7,IRON_BARS,12,CONCRETE:7,100)
RandomBlock(-8,3,2,CONCRETE:7,60,quark:iron_plate:1,20,STAINED_CLAY:12,15,STAINED_CLAY:15,5,AIR,7,IRON_BARS,12,CONCRETE:7,100)
RandomBlock(-8,3,3,CONCRETE:7,60,quark:iron_plate:1,20,STAINED_CLAY:12,15,STAINED_CLAY:15,5,AIR,7,IRON_BARS,12,CONCRETE:7,100)
RandomBlock(-8,3,4,CONCRETE:7,60,quark:iron_plate:1,20,STAINED_CLAY:12,15,STAINED_CLAY:15,5,AIR,7,IRON_BARS,12,CONCRETE:7,100)
RandomBlock(-8,3,5,CONCRETE:7,60,quark:iron_plate:1,20,STAINED_CLAY:12,15,STAINED_CLAY:15,5,AIR,7,IRON_BARS,12,CONCRETE:7,100)
RandomBlock(-8,3,6,CONCRETE:7,60,quark:iron_plate:1,20,STAINED_CLAY:12,15,STAINED_CLAY:15,5,AIR,7,IRON_BARS,12,CONCRETE:7,100)
RandomBlock(-8,3,7,CONCRETE:7,60,quark:iron_plate:1,20,STAINED_CLAY:12,15,STAINED_CLAY:15,5,AIR,7,IRON_BARS,12,CONCRETE:7,100)
RandomBlock(-8,3,8,CONCRETE:7,60,quark:iron_plate:1,20,STAINED_CLAY:12,15,STAINED_CLAY:15,5,AIR,7,IRON_BARS,12,CONCRETE:7,100)
RandomBlock(-8,4,-7,CONCRETE:7,60,quark:iron_plate:1,20,STAINED_CLAY:12,15,STAINED_CLAY:15,5,AIR,7,IRON_BARS,12,CONCRETE:7,100)
RandomBlock(-8,4,-6,CONCRETE:7,60,quark:iron_plate:1,20,STAINED_CLAY:12,15,STAINED_CLAY:15,5,AIR,7,IRON_BARS,12,CONCRETE:7,100)
RandomBlock(-8,4,-5,CONCRETE:7,60,quark:iron_plate:1,20,STAINED_CLAY:12,15,STAINED_CLAY:15,5,AIR,7,IRON_BARS,12,CONCRETE:7,100)
RandomBlock(-8,4,-4,CONCRETE:7,60,quark:iron_plate:1,20,STAINED_CLAY:12,15,STAINED_CLAY:15,5,AIR,7,IRON_BARS,12,CONCRETE:7,100)
RandomBlock(-8,4,-3,CONCRETE:7,60,quark:iron_plate:1,20,STAINED_CLAY:12,15,STAINED_CLAY:15,5,AIR,7,IRON_BARS,12,CONCRETE:7,100)
RandomBlock(-8,4,-2,CONCRETE:7,60,quark:iron_plate:1,20,STAINED_CLAY:12,15,STAINED_CLAY:15,5,AIR,7,IRON_BARS,12,CONCRETE:7,100)
RandomBlock(-8,4,-1,CONCRETE:7,60,quark:iron_plate:1,20,STAINED_CLAY:12,15,STAINED_CLAY:15,5,AIR,7,IRON_BARS,12,CONCRETE:7,100)
RandomBlock(-8,4,0,CONCRETE:7,60,quark:iron_plate:1,20,STAINED_CLAY:12,15,STAINED_CLAY:15,5,AIR,7,IRON_BARS,12,CONCRETE:7,100)
RandomBlock(-8,4,1,CONCRETE:7,60,quark:iron_plate:1,20,STAINED_CLAY:12,15,STAINED_CLAY:15,5,AIR,7,IRON_BARS,12,CONCRETE:7,100)
RandomBlock(-8,4,2,CONCRETE:7,60,quark:iron_plate:1,20,STAINED_CLAY:12,15,STAINED_CLAY:15,5,AIR,7,IRON_BARS,12,CONCRETE:7,100)
RandomBlock(-8,4,3,CONCRETE:7,60,quark:iron_plate:1,20,STAINED_CLAY:12,15,STAINED_CLAY:15,5,AIR,7,IRON_BARS,12,CONCRETE:7,100)
RandomBlock(-8,4,4,CONCRETE:7,60,quark:iron_plate:1,20,STAINED_CLAY:12,15,STAINED_CLAY:15,5,AIR,7,IRON_BARS,12,CONCRETE:7,100)
RandomBlock(-8,4,5,CONCRETE:7,60,quark:iron_plate:1,20,STAINED_CLAY:12,15,STAINED_CLAY:15,5,AIR,7,IRON_BARS,12,CONCRETE:7,100)
RandomBlock(-8,4,6,CONCRETE:7,60,quark:iron_plate:1,20,STAINED_CLAY:12,15,STAINED_CLAY:15,5,AIR,7,IRON_BARS,12,CONCRETE:7,100)
RandomBlock(-8,4,7,CONCRETE:7,60,quark:iron_plate:1,20,STAINED_CLAY:12,15,STAINED_CLAY:15,5,AIR,7,IRON_BARS,12,CONCRETE:7,100)
RandomBlock(-8,4,8,CONCRETE:7,60,quark:iron_plate:1,20,STAINED_CLAY:12,15,STAINED_CLAY:15,5,AIR,7,IRON_BARS,12,CONCRETE:7,100)
RandomBlock(-8,5,-7,CONCRETE:7,60,quark:iron_plate:1,20,STAINED_CLAY:12,15,STAINED_CLAY:15,5,AIR,7,IRON_BARS,12,CONCRETE:7,100)
RandomBlock(-8,5,-6,CONCRETE:7,60,quark:iron_plate:1,20,STAINED_CLAY:12,15,STAINED_CLAY:15,5,AIR,7,IRON_BARS,12,CONCRETE:7,100)
RandomBlock(-8,5,-5,CONCRETE:7,60,quark:iron_plate:1,20,STAINED_CLAY:12,15,STAINED_CLAY:15,5,AIR,7,IRON_BARS,12,CONCRETE:7,100)
RandomBlock(-8,5,-4,CONCRETE:7,60,quark:iron_plate:1,20,STAINED_CLAY:12,15,STAINED_CLAY:15,5,AIR,7,IRON_BARS,12,CONCRETE:7,100)
RandomBlock(-8,5,-3,CONCRETE:7,60,quark:iron_plate:1,20,STAINED_CLAY:12,15,STAINED_CLAY:15,5,AIR,7,IRON_BARS,12,CONCRETE:7,100)
RandomBlock(-8,5,-2,CONCRETE:7,60,quark:iron_plate:1,20,STAINED_CLAY:12,15,STAINED_CLAY:15,5,AIR,7,IRON_BARS,12,CONCRETE:7,100)
RandomBlock(-8,5,-1,CONCRETE:7,60,quark:iron_plate:1,20,STAINED_CLAY:12,15,STAINED_CLAY:15,5,AIR,7,IRON_BARS,12,CONCRETE:7,100)
RandomBlock(-8,5,0,CONCRETE:7,60,quark:iron_plate:1,20,STAINED_CLAY:12,15,STAINED_CLAY:15,5,AIR,7,IRON_BARS,12,CONCRETE:7,100)
RandomBlock(-8,5,1,CONCRETE:7,60,quark:iron_plate:1,20,STAINED_CLAY:12,15,STAINED_CLAY:15,5,AIR,7,IRON_BARS,12,CONCRETE:7,100)
RandomBlock(-8,5,2,CONCRETE:7,60,quark:iron_plate:1,20,STAINED_CLAY:12,15,STAINED_CLAY:15,5,AIR,7,IRON_BARS,12,CONCRETE:7,100)
RandomBlock(-8,5,3,CONCRETE:7,60,quark:iron_plate:1,20,STAINED_CLAY:12,15,STAINED_CLAY:15,5,AIR,7,IRON_BARS,12,CONCRETE:7,100)
RandomBlock(-8,5,4,CONCRETE:7,60,quark:iron_plate:1,20,STAINED_CLAY:12,15,STAINED_CLAY:15,5,AIR,7,IRON_BARS,12,CONCRETE:7,100)
RandomBlock(-8,5,5,CONCRETE:7,60,quark:iron_plate:1,20,STAINED_CLAY:12,15,STAINED_CLAY:15,5,AIR,7,IRON_BARS,12,CONCRETE:7,100)
RandomBlock(-8,5,6,CONCRETE:7,60,quark:iron_plate:1,20,STAINED_CLAY:12,15,STAINED_CLAY:15,5,AIR,7,IRON_BARS,12,CONCRETE:7,100)
RandomBlock(-8,5,7,CONCRETE:7,60,quark:iron_plate:1,20,STAINED_CLAY:12,15,STAINED_CLAY:15,5,AIR,7,IRON_BARS,12,CONCRETE:7,100)
RandomBlock(-8,5,8,CONCRETE:7,60,quark:iron_plate:1,20,STAINED_CLAY:12,15,STAINED_CLAY:15,5,AIR,7,IRON_BARS,12,CONCRETE:7,100)
RandomBlock(-8,6,-7,CONCRETE:7,60,quark:iron_plate:1,20,STAINED_CLAY:12,15,STAINED_CLAY:15,5,AIR,7,IRON_BARS,12,CONCRETE:7,100)
RandomBlock(-8,6,-6,CONCRETE:7,60,quark:iron_plate:1,20,STAINED_CLAY:12,15,STAINED_CLAY:15,5,AIR,7,IRON_BARS,12,CONCRETE:7,100)
RandomBlock(-8,6,-5,CONCRETE:7,60,quark:iron_plate:1,20,STAINED_CLAY:12,15,STAINED_CLAY:15,5,AIR,7,IRON_BARS,12,CONCRETE:7,100)
RandomBlock(-8,6,-4,CONCRETE:7,60,quark:iron_plate:1,20,STAINED_CLAY:12,15,STAINED_CLAY:15,5,AIR,7,IRON_BARS,12,CONCRETE:7,100)
RandomBlock(-8,6,-3,CONCRETE:7,60,quark:iron_plate:1,20,STAINED_CLAY:12,15,STAINED_CLAY:15,5,AIR,7,IRON_BARS,12,CONCRETE:7,100)
RandomBlock(-8,6,-2,CONCRETE:7,60,quark:iron_plate:1,20,STAINED_CLAY:12,15,STAINED_CLAY:15,5,AIR,7,IRON_BARS,12,CONCRETE:7,100)
RandomBlock(-8,6,-1,CONCRETE:7,60,quark:iron_plate:1,20,STAINED_CLAY:12,15,STAINED_CLAY:15,5,AIR,7,IRON_BARS,12,CONCRETE:7,100)
RandomBlock(-8,6,0,CONCRETE:7,60,quark:iron_plate:1,20,STAINED_CLAY:12,15,STAINED_CLAY:15,5,AIR,7,IRON_BARS,12,CONCRETE:7,100)
RandomBlock(-8,6,1,CONCRETE:7,60,quark:iron_plate:1,20,STAINED_CLAY:12,15,STAINED_CLAY:15,5,AIR,7,IRON_BARS,12,CONCRETE:7,100)
RandomBlock(-8,6,2,CONCRETE:7,60,quark:iron_plate:1,20,STAINED_CLAY:12,15,STAINED_CLAY:15,5,AIR,7,IRON_BARS,12,CONCRETE:7,100)
RandomBlock(-8,6,3,CONCRETE:7,60,quark:iron_plate:1,20,STAINED_CLAY:12,15,STAINED_CLAY:15,5,AIR,7,IRON_BARS,12,CONCRETE:7,100)
RandomBlock(-8,6,4,CONCRETE:7,60,quark:iron_plate:1,20,STAINED_CLAY:12,15,STAINED_CLAY:15,5,AIR,7,IRON_BARS,12,CONCRETE:7,100)
RandomBlock(-8,6,5,CONCRETE:7,60,quark:iron_plate:1,20,STAINED_CLAY:12,15,STAINED_CLAY:15,5,AIR,7,IRON_BARS,12,CONCRETE:7,100)
RandomBlock(-8,6,6,CONCRETE:7,60,quark:iron_plate:1,20,STAINED_CLAY:12,15,STAINED_CLAY:15,5,AIR,7,IRON_BARS,12,CONCRETE:7,100)
RandomBlock(-8,6,7,CONCRETE:7,60,quark:iron_plate:1,20,STAINED_CLAY:12,15,STAINED_CLAY:15,5,AIR,7,IRON_BARS,12,CONCRETE:7,100)
RandomBlock(-8,6,8,CONCRETE:7,60,quark:iron_plate:1,20,STAINED_CLAY:12,15,STAINED_CLAY:15,5,AIR,7,IRON_BARS,12,CONCRETE:7,100)
RandomBlock(-8,7,-7,CONCRETE:7,60,quark:iron_plate:1,20,STAINED_CLAY:12,15,STAINED_CLAY:15,5,AIR,7,IRON_BARS,12,CONCRETE:7,100)
RandomBlock(-8,7,-6,CONCRETE:7,60,quark:iron_plate:1,20,STAINED_CLAY:12,15,STAINED_CLAY:15,5,AIR,7,IRON_BARS,12,CONCRETE:7,100)
RandomBlock(-8,7,-5,CONCRETE:7,60,quark:iron_plate:1,20,STAINED_CLAY:12,15,STAINED_CLAY:15,5,AIR,7,IRON_BARS,12,CONCRETE:7,100)
RandomBlock(-8,7,-4,CONCRETE:7,60,quark:iron_plate:1,20,STAINED_CLAY:12,15,STAINED_CLAY:15,5,AIR,7,IRON_BARS,12,CONCRETE:7,100)
RandomBlock(-8,7,-3,CONCRETE:7,60,quark:iron_plate:1,20,STAINED_CLAY:12,15,STAINED_CLAY:15,5,AIR,7,IRON_BARS,12,CONCRETE:7,100)
RandomBlock(-8,7,-2,CONCRETE:7,60,quark:iron_plate:1,20,STAINED_CLAY:12,15,STAINED_CLAY:15,5,AIR,7,IRON_BARS,12,CONCRETE:7,100)
RandomBlock(-8,7,-1,CONCRETE:7,60,quark:iron_plate:1,20,STAINED_CLAY:12,15,STAINED_CLAY:15,5,AIR,7,IRON_BARS,12,CONCRETE:7,100)
RandomBlock(-8,7,0,CONCRETE:7,60,quark:iron_plate:1,20,STAINED_CLAY:12,15,STAINED_CLAY:15,5,AIR,7,IRON_BARS,12,CONCRETE:7,100)
RandomBlock(-8,7,1,CONCRETE:7,60,quark:iron_plate:1,20,STAINED_CLAY:12,15,STAINED_CLAY:15,5,AIR,7,IRON_BARS,12,CONCRETE:7,100)
RandomBlock(-8,7,2,CONCRETE:7,60,quark:iron_plate:1,20,STAINED_CLAY:12,15,STAINED_CLAY:15,5,AIR,7,IRON_BARS,12,CONCRETE:7,100)
RandomBlock(-8,7,3,CONCRETE:7,60,quark:iron_plate:1,20,STAINED_CLAY:12,15,STAINED_CLAY:15,5,AIR,7,IRON_BARS,12,CONCRETE:7,100)
RandomBlock(-8,7,4,CONCRETE:7,60,quark:iron_plate:1,20,STAINED_CLAY:12,15,STAINED_CLAY:15,5,AIR,7,IRON_BARS,12,CONCRETE:7,100)
RandomBlock(-8,7,5,CONCRETE:7,60,quark:iron_plate:1,20,STAINED_CLAY:12,15,STAINED_CLAY:15,5,AIR,7,IRON_BARS,12,CONCRETE:7,100)
RandomBlock(-8,7,6,CONCRETE:7,60,quark:iron_plate:1,20,STAINED_CLAY:12,15,STAINED_CLAY:15,5,AIR,7,IRON_BARS,12,CONCRETE:7,100)
RandomBlock(-8,7,7,CONCRETE:7,60,quark:iron_plate:1,20,STAINED_CLAY:12,15,STAINED_CLAY:15,5,AIR,7,IRON_BARS,12,CONCRETE:7,100)
RandomBlock(-8,7,8,CONCRETE:7,60,quark:iron_plate:1,20,STAINED_CLAY:12,15,STAINED_CLAY:15,5,AIR,7,IRON_BARS,12,CONCRETE:7,100)
RandomBlock(-8,8,-7,CONCRETE:7,60,quark:iron_plate:1,20,STAINED_CLAY:12,15,STAINED_CLAY:15,5,AIR,7,IRON_BARS,12,CONCRETE:7,100)
RandomBlock(-8,8,-6,CONCRETE:7,60,quark:iron_plate:1,20,STAINED_CLAY:12,15,STAINED_CLAY:15,5,AIR,7,IRON_BARS,12,CONCRETE:7,100)
RandomBlock(-8,8,-5,CONCRETE:7,60,quark:iron_plate:1,20,STAINED_CLAY:12,15,STAINED_CLAY:15,5,AIR,7,IRON_BARS,12,CONCRETE:7,100)
RandomBlock(-8,8,-4,CONCRETE:7,60,quark:iron_plate:1,20,STAINED_CLAY:12,15,STAINED_CLAY:15,5,AIR,7,IRON_BARS,12,CONCRETE:7,100)
RandomBlock(-8,8,-3,CONCRETE:7,60,quark:iron_plate:1,20,STAINED_CLAY:12,15,STAINED_CLAY:15,5,AIR,7,IRON_BARS,12,CONCRETE:7,100)
RandomBlock(-8,8,-2,CONCRETE:7,60,quark:iron_plate:1,20,STAINED_CLAY:12,15,STAINED_CLAY:15,5,AIR,7,IRON_BARS,12,CONCRETE:7,100)
RandomBlock(-8,8,-1,CONCRETE:7,60,quark:iron_plate:1,20,STAINED_CLAY:12,15,STAINED_CLAY:15,5,AIR,7,IRON_BARS,12,CONCRETE:7,100)
RandomBlock(-8,8,0,CONCRETE:7,60,quark:iron_plate:1,20,STAINED_CLAY:12,15,STAINED_CLAY:15,5,AIR,7,IRON_BARS,12,CONCRETE:7,100)
RandomBlock(-8,8,1,CONCRETE:7,60,quark:iron_plate:1,20,STAINED_CLAY:12,15,STAINED_CLAY:15,5,AIR,7,IRON_BARS,12,CONCRETE:7,100)
RandomBlock(-8,8,2,CONCRETE:7,60,quark:iron_plate:1,20,STAINED_CLAY:12,15,STAINED_CLAY:15,5,AIR,7,IRON_BARS,12,CONCRETE:7,100)
RandomBlock(-8,8,3,CONCRETE:7,60,quark:iron_plate:1,20,STAINED_CLAY:12,15,STAINED_CLAY:15,5,AIR,7,IRON_BARS,12,CONCRETE:7,100)
RandomBlock(-8,8,4,CONCRETE:7,60,quark:iron_plate:1,20,STAINED_CLAY:12,15,STAINED_CLAY:15,5,AIR,7,IRON_BARS,12,CONCRETE:7,100)
RandomBlock(-8,8,5,CONCRETE:7,60,quark:iron_plate:1,20,STAINED_CLAY:12,15,STAINED_CLAY:15,5,AIR,7,IRON_BARS,12,CONCRETE:7,100)
RandomBlock(-8,8,6,CONCRETE:7,60,quark:iron_plate:1,20,STAINED_CLAY:12,15,STAINED_CLAY:15,5,AIR,7,IRON_BARS,12,CONCRETE:7,100)
RandomBlock(-8,8,7,CONCRETE:7,60,quark:iron_plate:1,20,STAINED_CLAY:12,15,STAINED_CLAY:15,5,AIR,7,IRON_BARS,12,CONCRETE:7,100)
RandomBlock(-8,8,8,CONCRETE:7,60,quark:iron_plate:1,20,STAINED_CLAY:12,15,STAINED_CLAY:15,5,AIR,7,IRON_BARS,12,CONCRETE:7,100)
RandomBlock(-8,9,-7,CONCRETE:7,60,quark:iron_plate:1,20,STAINED_CLAY:12,15,STAINED_CLAY:15,5,AIR,7,IRON_BARS,12,CONCRETE:7,100)
RandomBlock(-8,9,-6,CONCRETE:7,60,quark:iron_plate:1,20,STAINED_CLAY:12,15,STAINED_CLAY:15,5,AIR,7,IRON_BARS,12,CONCRETE:7,100)
RandomBlock(-8,9,-5,CONCRETE:7,60,quark:iron_plate:1,20,STAINED_CLAY:12,15,STAINED_CLAY:15,5,AIR,7,IRON_BARS,12,CONCRETE:7,100)
RandomBlock(-8,9,-4,CONCRETE:7,60,quark:iron_plate:1,20,STAINED_CLAY:12,15,STAINED_CLAY:15,5,AIR,7,IRON_BARS,12,CONCRETE:7,100)
RandomBlock(-8,9,-3,CONCRETE:7,60,quark:iron_plate:1,20,STAINED_CLAY:12,15,STAINED_CLAY:15,5,AIR,7,IRON_BARS,12,CONCRETE:7,100)
RandomBlock(-8,9,-2,CONCRETE:7,60,quark:iron_plate:1,20,STAINED_CLAY:12,15,STAINED_CLAY:15,5,AIR,7,IRON_BARS,12,CONCRETE:7,100)
RandomBlock(-8,9,-1,CONCRETE:7,60,quark:iron_plate:1,20,STAINED_CLAY:12,15,STAINED_CLAY:15,5,AIR,7,IRON_BARS,12,CONCRETE:7,100)
RandomBlock(-8,9,0,CONCRETE:7,60,quark:iron_plate:1,20,STAINED_CLAY:12,15,STAINED_CLAY:15,5,AIR,7,IRON_BARS,12,CONCRETE:7,100)
RandomBlock(-8,9,1,CONCRETE:7,60,quark:iron_plate:1,20,STAINED_CLAY:12,15,STAINED_CLAY:15,5,AIR,7,IRON_BARS,12,CONCRETE:7,100)
RandomBlock(-8,9,2,CONCRETE:7,60,quark:iron_plate:1,20,STAINED_CLAY:12,15,STAINED_CLAY:15,5,AIR,7,IRON_BARS,12,CONCRETE:7,100)
RandomBlock(-8,9,3,CONCRETE:7,60,quark:iron_plate:1,20,STAINED_CLAY:12,15,STAINED_CLAY:15,5,AIR,7,IRON_BARS,12,CONCRETE:7,100)
RandomBlock(-8,9,4,CONCRETE:7,60,quark:iron_plate:1,20,STAINED_CLAY:12,15,STAINED_CLAY:15,5,AIR,7,IRON_BARS,12,CONCRETE:7,100)
RandomBlock(-8,9,5,CONCRETE:7,60,quark:iron_plate:1,20,STAINED_CLAY:12,15,STAINED_CLAY:15,5,AIR,7,IRON_BARS,12,CONCRETE:7,100)
RandomBlock(-8,9,6,CONCRETE:7,60,quark:iron_plate:1,20,STAINED_CLAY:12,15,STAINED_CLAY:15,5,AIR,7,IRON_BARS,12,CONCRETE:7,100)
RandomBlock(-8,9,7,CONCRETE:7,60,quark:iron_plate:1,20,STAINED_CLAY:12,15,STAINED_CLAY:15,5,AIR,7,IRON_BARS,12,CONCRETE:7,100)
RandomBlock(-8,9,8,CONCRETE:7,60,quark:iron_plate:1,20,STAINED_CLAY:12,15,STAINED_CLAY:15,5,AIR,7,IRON_BARS,12,CONCRETE:7,100)
RandomBlock(-8,10,-7,CONCRETE:7,60,quark:iron_plate:1,20,STAINED_CLAY:12,15,STAINED_CLAY:15,5,AIR,7,IRON_BARS,12,CONCRETE:7,100)
RandomBlock(-8,10,-6,CONCRETE:7,60,quark:iron_plate:1,20,STAINED_CLAY:12,15,STAINED_CLAY:15,5,AIR,7,IRON_BARS,12,CONCRETE:7,100)
RandomBlock(-8,10,-5,CONCRETE:7,60,quark:iron_plate:1,20,STAINED_CLAY:12,15,STAINED_CLAY:15,5,AIR,7,IRON_BARS,12,CONCRETE:7,100)
RandomBlock(-8,10,-4,CONCRETE:7,60,quark:iron_plate:1,20,STAINED_CLAY:12,15,STAINED_CLAY:15,5,AIR,7,IRON_BARS,12,CONCRETE:7,100)
RandomBlock(-8,10,-3,CONCRETE:7,60,quark:iron_plate:1,20,STAINED_CLAY:12,15,STAINED_CLAY:15,5,AIR,7,IRON_BARS,12,CONCRETE:7,100)
RandomBlock(-8,10,-2,CONCRETE:7,60,quark:iron_plate:1,20,STAINED_CLAY:12,15,STAINED_CLAY:15,5,AIR,7,IRON_BARS,12,CONCRETE:7,100)
RandomBlock(-8,10,-1,CONCRETE:7,60,quark:iron_plate:1,20,STAINED_CLAY:12,15,STAINED_CLAY:15,5,AIR,7,IRON_BARS,12,CONCRETE:7,100)
RandomBlock(-8,10,0,CONCRETE:7,60,quark:iron_plate:1,20,STAINED_CLAY:12,15,STAINED_CLAY:15,5,AIR,7,IRON_BARS,12,CONCRETE:7,100)
RandomBlock(-8,10,1,CONCRETE:7,60,quark:iron_plate:1,20,STAINED_CLAY:12,15,STAINED_CLAY:15,5,AIR,7,IRON_BARS,12,CONCRETE:7,100)
RandomBlock(-8,10,2,CONCRETE:7,60,quark:iron_plate:1,20,STAINED_CLAY:12,15,STAINED_CLAY:15,5,AIR,7,IRON_BARS,12,CONCRETE:7,100)
RandomBlock(-8,10,3,CONCRETE:7,60,quark:iron_plate:1,20,STAINED_CLAY:12,15,STAINED_CLAY:15,5,AIR,7,IRON_BARS,12,CONCRETE:7,100)
RandomBlock(-8,10,4,CONCRETE:7,60,quark:iron_plate:1,20,STAINED_CLAY:12,15,STAINED_CLAY:15,5,AIR,7,IRON_BARS,12,CONCRETE:7,100)
RandomBlock(-8,10,5,CONCRETE:7,60,quark:iron_plate:1,20,STAINED_CLAY:12,15,STAINED_CLAY:15,5,AIR,7,IRON_BARS,12,CONCRETE:7,100)
RandomBlock(-8,10,6,CONCRETE:7,60,quark:iron_plate:1,20,STAINED_CLAY:12,15,STAINED_CLAY:15,5,AIR,7,IRON_BARS,12,CONCRETE:7,100)
RandomBlock(-8,10,7,CONCRETE:7,60,quark:iron_plate:1,20,STAINED_CLAY:12,15,STAINED_CLAY:15,5,AIR,7,IRON_BARS,12,CONCRETE:7,100)
RandomBlock(-8,10,8,CONCRETE:7,60,quark:iron_plate:1,20,STAINED_CLAY:12,15,STAINED_CLAY:15,5,AIR,7,IRON_BARS,12,CONCRETE:7,100)
RandomBlock(-8,11,-7,CONCRETE:7,60,quark:iron_plate:1,20,STAINED_CLAY:12,15,STAINED_CLAY:15,5,AIR,7,IRON_BARS,12,CONCRETE:7,100)
RandomBlock(-8,11,-6,CONCRETE:7,60,quark:iron_plate:1,20,STAINED_CLAY:12,15,STAINED_CLAY:15,5,AIR,7,IRON_BARS,12,CONCRETE:7,100)
RandomBlock(-8,11,-5,CONCRETE:7,60,quark:iron_plate:1,20,STAINED_CLAY:12,15,STAINED_CLAY:15,5,AIR,7,IRON_BARS,12,CONCRETE:7,100)
RandomBlock(-8,11,-4,CONCRETE:7,60,quark:iron_plate:1,20,STAINED_CLAY:12,15,STAINED_CLAY:15,5,AIR,7,IRON_BARS,12,CONCRETE:7,100)
RandomBlock(-8,11,-3,CONCRETE:7,60,quark:iron_plate:1,20,STAINED_CLAY:12,15,STAINED_CLAY:15,5,AIR,7,IRON_BARS,12,CONCRETE:7,100)
RandomBlock(-8,11,-2,CONCRETE:7,60,quark:iron_plate:1,20,STAINED_CLAY:12,15,STAINED_CLAY:15,5,AIR,7,IRON_BARS,12,CONCRETE:7,100)
RandomBlock(-8,11,-1,CONCRETE:7,60,quark:iron_plate:1,20,STAINED_CLAY:12,15,STAINED_CLAY:15,5,AIR,7,IRON_BARS,12,CONCRETE:7,100)
RandomBlock(-8,11,0,CONCRETE:7,60,quark:iron_plate:1,20,STAINED_CLAY:12,15,STAINED_CLAY:15,5,AIR,7,IRON_BARS,12,CONCRETE:7,100)
RandomBlock(-8,11,1,CONCRETE:7,60,quark:iron_plate:1,20,STAINED_CLAY:12,15,STAINED_CLAY:15,5,AIR,7,IRON_BARS,12,CONCRETE:7,100)
RandomBlock(-8,11,2,CONCRETE:7,60,quark:iron_plate:1,20,STAINED_CLAY:12,15,STAINED_CLAY:15,5,AIR,7,IRON_BARS,12,CONCRETE:7,100)
RandomBlock(-8,11,3,CONCRETE:7,60,quark:iron_plate:1,20,STAINED_CLAY:12,15,STAINED_CLAY:15,5,AIR,7,IRON_BARS,12,CONCRETE:7,100)
RandomBlock(-8,11,4,CONCRETE:7,60,quark:iron_plate:1,20,STAINED_CLAY:12,15,STAINED_CLAY:15,5,AIR,7,IRON_BARS,12,CONCRETE:7,100)
RandomBlock(-8,11,5,CONCRETE:7,60,quark:iron_plate:1,20,STAINED_CLAY:12,15,STAINED_CLAY:15,5,AIR,7,IRON_BARS,12,CONCRETE:7,100)
RandomBlock(-8,11,6,CONCRETE:7,60,quark:iron_plate:1,20,STAINED_CLAY:12,15,STAINED_CLAY:15,5,AIR,7,IRON_BARS,12,CONCRETE:7,100)
RandomBlock(-8,11,7,CONCRETE:7,60,quark:iron_plate:1,20,STAINED_CLAY:12,15,STAINED_CLAY:15,5,AIR,7,IRON_BARS,12,CONCRETE:7,100)
RandomBlock(-8,11,8,CONCRETE:7,60,quark:iron_plate:1,20,STAINED_CLAY:12,15,STAINED_CLAY:15,5,AIR,7,IRON_BARS,12,CONCRETE:7,100)
RandomBlock(-8,12,-7,CONCRETE:7,60,quark:iron_plate:1,20,STAINED_CLAY:12,15,STAINED_CLAY:15,5,AIR,7,IRON_BARS,12,CONCRETE:7,100)
RandomBlock(-8,12,-6,CONCRETE:7,60,quark:iron_plate:1,20,STAINED_CLAY:12,15,STAINED_CLAY:15,5,AIR,7,IRON_BARS,12,CONCRETE:7,100)
RandomBlock(-8,12,-5,CONCRETE:7,60,quark:iron_plate:1,20,STAINED_CLAY:12,15,STAINED_CLAY:15,5,AIR,7,IRON_BARS,12,CONCRETE:7,100)
RandomBlock(-8,12,-4,CONCRETE:7,60,quark:iron_plate:1,20,STAINED_CLAY:12,15,STAINED_CLAY:15,5,AIR,7,IRON_BARS,12,CONCRETE:7,100)
RandomBlock(-8,12,-3,CONCRETE:7,60,quark:iron_plate:1,20,STAINED_CLAY:12,15,STAINED_CLAY:15,5,AIR,7,IRON_BARS,12,CONCRETE:7,100)
RandomBlock(-8,12,-2,CONCRETE:7,60,quark:iron_plate:1,20,STAINED_CLAY:12,15,STAINED_CLAY:15,5,AIR,7,IRON_BARS,12,CONCRETE:7,100)
RandomBlock(-8,12,-1,CONCRETE:7,60,quark:iron_plate:1,20,STAINED_CLAY:12,15,STAINED_CLAY:15,5,AIR,7,IRON_BARS,12,CONCRETE:7,100)
RandomBlock(-8,12,0,CONCRETE:7,60,quark:iron_plate:1,20,STAINED_CLAY:12,15,STAINED_CLAY:15,5,AIR,7,IRON_BARS,12,CONCRETE:7,100)
RandomBlock(-8,12,1,CONCRETE:7,60,quark:iron_plate:1,20,STAINED_CLAY:12,15,STAINED_CLAY:15,5,AIR,7,IRON_BARS,12,CONCRETE:7,100)
RandomBlock(-8,12,2,CONCRETE:7,60,quark:iron_plate:1,20,STAINED_CLAY:12,15,STAINED_CLAY:15,5,AIR,7,IRON_BARS,12,CONCRETE:7,100)
RandomBlock(-8,12,3,CONCRETE:7,60,quark:iron_plate:1,20,STAINED_CLAY:12,15,STAINED_CLAY:15,5,AIR,7,IRON_BARS,12,CONCRETE:7,100)
RandomBlock(-8,12,4,CONCRETE:7,60,quark:iron_plate:1,20,STAINED_CLAY:12,15,STAINED_CLAY:15,5,AIR,7,IRON_BARS,12,CONCRETE:7,100)
RandomBlock(-8,12,5,CONCRETE:7,60,quark:iron_plate:1,20,STAINED_CLAY:12,15,STAINED_CLAY:15,5,AIR,7,IRON_BARS,12,CONCRETE:7,100)
RandomBlock(-8,12,6,CONCRETE:7,60,quark:iron_plate:1,20,STAINED_CLAY:12,15,STAINED_CLAY:15,5,AIR,7,IRON_BARS,12,CONCRETE:7,100)
RandomBlock(-8,12,7,CONCRETE:7,60,quark:iron_plate:1,20,STAINED_CLAY:12,15,STAINED_CLAY:15,5,AIR,7,IRON_BARS,12,CONCRETE:7,100)
RandomBlock(-8,12,8,CONCRETE:7,60,quark:iron_plate:1,20,STAINED_CLAY:12,15,STAINED_CLAY:15,5,AIR,7,IRON_BARS,12,CONCRETE:7,100)
RandomBlock(-8,13,-7,CONCRETE:7,60,quark:iron_plate:1,20,STAINED_CLAY:12,15,STAINED_CLAY:15,5,AIR,7,IRON_BARS,12,CONCRETE:7,100)
RandomBlock(-8,13,-6,CONCRETE:7,60,quark:iron_plate:1,20,STAINED_CLAY:12,15,STAINED_CLAY:15,5,AIR,7,IRON_BARS,12,CONCRETE:7,100)
RandomBlock(-8,13,-5,CONCRETE:7,60,quark:iron_plate:1,20,STAINED_CLAY:12,15,STAINED_CLAY:15,5,AIR,7,IRON_BARS,12,CONCRETE:7,100)
RandomBlock(-8,13,-4,CONCRETE:7,60,quark:iron_plate:1,20,STAINED_CLAY:12,15,STAINED_CLAY:15,5,AIR,7,IRON_BARS,12,CONCRETE:7,100)
RandomBlock(-8,13,-3,CONCRETE:7,60,quark:iron_plate:1,20,STAINED_CLAY:12,15,STAINED_CLAY:15,5,AIR,7,IRON_BARS,12,CONCRETE:7,100)
RandomBlock(-8,13,-2,CONCRETE:7,60,quark:iron_plate:1,20,STAINED_CLAY:12,15,STAINED_CLAY:15,5,AIR,7,IRON_BARS,12,CONCRETE:7,100)
RandomBlock(-8,13,-1,CONCRETE:7,60,quark:iron_plate:1,20,STAINED_CLAY:12,15,STAINED_CLAY:15,5,AIR,7,IRON_BARS,12,CONCRETE:7,100)
RandomBlock(-8,13,0,CONCRETE:7,60,quark:iron_plate:1,20,STAINED_CLAY:12,15,STAINED_CLAY:15,5,AIR,7,IRON_BARS,12,CONCRETE:7,100)
RandomBlock(-8,13,1,CONCRETE:7,60,quark:iron_plate:1,20,STAINED_CLAY:12,15,STAINED_CLAY:15,5,AIR,7,IRON_BARS,12,CONCRETE:7,100)
RandomBlock(-8,13,2,CONCRETE:7,60,quark:iron_plate:1,20,STAINED_CLAY:12,15,STAINED_CLAY:15,5,AIR,7,IRON_BARS,12,CONCRETE:7,100)
RandomBlock(-8,13,3,CONCRETE:7,60,quark:iron_plate:1,20,STAINED_CLAY:12,15,STAINED_CLAY:15,5,AIR,7,IRON_BARS,12,CONCRETE:7,100)
RandomBlock(-8,13,4,CONCRETE:7,60,quark:iron_plate:1,20,STAINED_CLAY:12,15,STAINED_CLAY:15,5,AIR,7,IRON_BARS,12,CONCRETE:7,100)
RandomBlock(-8,13,5,CONCRETE:7,60,quark:iron_plate:1,20,STAINED_CLAY:12,15,STAINED_CLAY:15,5,AIR,7,IRON_BARS,12,CONCRETE:7,100)
RandomBlock(-8,13,6,CONCRETE:7,60,quark:iron_plate:1,20,STAINED_CLAY:12,15,STAINED_CLAY:15,5,AIR,7,IRON_BARS,12,CONCRETE:7,100)
RandomBlock(-8,13,7,CONCRETE:7,60,quark:iron_plate:1,20,STAINED_CLAY:12,15,STAINED_CLAY:15,5,AIR,7,IRON_BARS,12,CONCRETE:7,100)
RandomBlock(-8,13,8,CONCRETE:7,60,quark:iron_plate:1,20,STAINED_CLAY:12,15,STAINED_CLAY:15,5,AIR,7,IRON_BARS,12,CONCRETE:7,100)
RandomBlock(-8,14,-7,CONCRETE:7,60,quark:iron_plate:1,20,STAINED_CLAY:12,15,STAINED_CLAY:15,5,AIR,7,IRON_BARS,12,CONCRETE:7,100)
RandomBlock(-8,14,-6,CONCRETE:7,60,quark:iron_plate:1,20,STAINED_CLAY:12,15,STAINED_CLAY:15,5,AIR,7,IRON_BARS,12,CONCRETE:7,100)
RandomBlock(-8,14,-5,CONCRETE:7,60,quark:iron_plate:1,20,STAINED_CLAY:12,15,STAINED_CLAY:15,5,AIR,7,IRON_BARS,12,CONCRETE:7,100)
RandomBlock(-8,14,-4,CONCRETE:7,60,quark:iron_plate:1,20,STAINED_CLAY:12,15,STAINED_CLAY:15,5,AIR,7,IRON_BARS,12,CONCRETE:7,100)
RandomBlock(-8,14,-3,CONCRETE:7,60,quark:iron_plate:1,20,STAINED_CLAY:12,15,STAINED_CLAY:15,5,AIR,7,IRON_BARS,12,CONCRETE:7,100)
RandomBlock(-8,14,-2,CONCRETE:7,60,quark:iron_plate:1,20,STAINED_CLAY:12,15,STAINED_CLAY:15,5,AIR,7,IRON_BARS,12,CONCRETE:7,100)
RandomBlock(-8,14,-1,CONCRETE:7,60,quark:iron_plate:1,20,STAINED_CLAY:12,15,STAINED_CLAY:15,5,AIR,7,IRON_BARS,12,CONCRETE:7,100)
RandomBlock(-8,14,0,CONCRETE:7,60,quark:iron_plate:1,20,STAINED_CLAY:12,15,STAINED_CLAY:15,5,AIR,7,IRON_BARS,12,CONCRETE:7,100)
RandomBlock(-8,14,1,CONCRETE:7,60,quark:iron_plate:1,20,STAINED_CLAY:12,15,STAINED_CLAY:15,5,AIR,7,IRON_BARS,12,CONCRETE:7,100)
RandomBlock(-8,14,2,CONCRETE:7,60,quark:iron_plate:1,20,STAINED_CLAY:12,15,STAINED_CLAY:15,5,AIR,7,IRON_BARS,12,CONCRETE:7,100)
RandomBlock(-8,14,3,CONCRETE:7,60,quark:iron_plate:1,20,STAINED_CLAY:12,15,STAINED_CLAY:15,5,AIR,7,IRON_BARS,12,CONCRETE:7,100)
RandomBlock(-8,14,4,CONCRETE:7,60,quark:iron_plate:1,20,STAINED_CLAY:12,15,STAINED_CLAY:15,5,AIR,7,IRON_BARS,12,CONCRETE:7,100)
RandomBlock(-8,14,5,CONCRETE:7,60,quark:iron_plate:1,20,STAINED_CLAY:12,15,STAINED_CLAY:15,5,AIR,7,IRON_BARS,12,CONCRETE:7,100)
RandomBlock(-8,14,6,CONCRETE:7,60,quark:iron_plate:1,20,STAINED_CLAY:12,15,STAINED_CLAY:15,5,AIR,7,IRON_BARS,12,CONCRETE:7,100)
RandomBlock(-8,14,7,CONCRETE:7,60,quark:iron_plate:1,20,STAINED_CLAY:12,15,STAINED_CLAY:15,5,AIR,7,IRON_BARS,12,CONCRETE:7,100)
RandomBlock(-8,14,8,CONCRETE:7,60,quark:iron_plate:1,20,STAINED_CLAY:12,15,STAINED_CLAY:15,5,AIR,7,IRON_BARS,12,CONCRETE:7,100)
RandomBlock(-8,15,-7,CONCRETE:7,60,quark:iron_plate:1,20,STAINED_CLAY:12,15,STAINED_CLAY:15,5,AIR,7,IRON_BARS,12,CONCRETE:7,100)
RandomBlock(-8,15,-6,CONCRETE:7,60,quark:iron_plate:1,20,STAINED_CLAY:12,15,STAINED_CLAY:15,5,AIR,7,IRON_BARS,12,CONCRETE:7,100)
RandomBlock(-8,15,-5,CONCRETE:7,60,quark:iron_plate:1,20,STAINED_CLAY:12,15,STAINED_CLAY:15,5,AIR,7,IRON_BARS,12,CONCRETE:7,100)
RandomBlock(-8,15,-4,CONCRETE:7,60,quark:iron_plate:1,20,STAINED_CLAY:12,15,STAINED_CLAY:15,5,AIR,7,IRON_BARS,12,CONCRETE:7,100)
RandomBlock(-8,15,-3,CONCRETE:7,60,quark:iron_plate:1,20,STAINED_CLAY:12,15,STAINED_CLAY:15,5,AIR,7,IRON_BARS,12,CONCRETE:7,100)
RandomBlock(-8,15,-2,CONCRETE:7,60,quark:iron_plate:1,20,STAINED_CLAY:12,15,STAINED_CLAY:15,5,AIR,7,IRON_BARS,12,CONCRETE:7,100)
RandomBlock(-8,15,-1,CONCRETE:7,60,quark:iron_plate:1,20,STAINED_CLAY:12,15,STAINED_CLAY:15,5,AIR,7,IRON_BARS,12,CONCRETE:7,100)
RandomBlock(-8,15,0,CONCRETE:7,60,quark:iron_plate:1,20,STAINED_CLAY:12,15,STAINED_CLAY:15,5,AIR,7,IRON_BARS,12,CONCRETE:7,100)
RandomBlock(-8,15,1,CONCRETE:7,60,quark:iron_plate:1,20,STAINED_CLAY:12,15,STAINED_CLAY:15,5,AIR,7,IRON_BARS,12,CONCRETE:7,100)
RandomBlock(-8,15,2,CONCRETE:7,60,quark:iron_plate:1,20,STAINED_CLAY:12,15,STAINED_CLAY:15,5,AIR,7,IRON_BARS,12,CONCRETE:7,100)
RandomBlock(-8,15,3,CONCRETE:7,60,quark:iron_plate:1,20,STAINED_CLAY:12,15,STAINED_CLAY:15,5,AIR,7,IRON_BARS,12,CONCRETE:7,100)
RandomBlock(-8,15,4,CONCRETE:7,60,quark:iron_plate:1,20,STAINED_CLAY:12,15,STAINED_CLAY:15,5,AIR,7,IRON_BARS,12,CONCRETE:7,100)
RandomBlock(-8,15,5,CONCRETE:7,60,quark:iron_plate:1,20,STAINED_CLAY:12,15,STAINED_CLAY:15,5,AIR,7,IRON_BARS,12,CONCRETE:7,100)
RandomBlock(-8,15,6,CONCRETE:7,60,quark:iron_plate:1,20,STAINED_CLAY:12,15,STAINED_CLAY:15,5,AIR,7,IRON_BARS,12,CONCRETE:7,100)
RandomBlock(-8,15,7,CONCRETE:7,60,quark:iron_plate:1,20,STAINED_CLAY:12,15,STAINED_CLAY:15,5,AIR,7,IRON_BARS,12,CONCRETE:7,100)
RandomBlock(-8,15,8,CONCRETE:7,60,quark:iron_plate:1,20,STAINED_CLAY:12,15,STAINED_CLAY:15,5,AIR,7,IRON_BARS,12,CONCRETE:7,100)
RandomBlock(-8,16,-7,CONCRETE:7,60,quark:iron_plate:1,20,STAINED_CLAY:12,15,STAINED_CLAY:15,5,AIR,7,IRON_BARS,12,CONCRETE:7,100)
RandomBlock(-8,16,-6,CONCRETE:7,60,quark:iron_plate:1,20,STAINED_CLAY:12,15,STAINED_CLAY:15,5,AIR,7,IRON_BARS,12,CONCRETE:7,100)
RandomBlock(-8,16,-5,CONCRETE:7,60,quark:iron_plate:1,20,STAINED_CLAY:12,15,STAINED_CLAY:15,5,AIR,7,IRON_BARS,12,CONCRETE:7,100)
RandomBlock(-8,16,-4,CONCRETE:7,60,quark:iron_plate:1,20,STAINED_CLAY:12,15,STAINED_CLAY:15,5,AIR,7,IRON_BARS,12,CONCRETE:7,100)
RandomBlock(-8,16,-3,CONCRETE:7,60,quark:iron_plate:1,20,STAINED_CLAY:12,15,STAINED_CLAY:15,5,AIR,7,IRON_BARS,12,CONCRETE:7,100)
RandomBlock(-8,16,-2,CONCRETE:7,60,quark:iron_plate:1,20,STAINED_CLAY:12,15,STAINED_CLAY:15,5,AIR,7,IRON_BARS,12,CONCRETE:7,100)
RandomBlock(-8,16,-1,CONCRETE:7,60,quark:iron_plate:1,20,STAINED_CLAY:12,15,STAINED_CLAY:15,5,AIR,7,IRON_BARS,12,CONCRETE:7,100)
RandomBlock(-8,16,0,CONCRETE:7,60,quark:iron_plate:1,20,STAINED_CLAY:12,15,STAINED_CLAY:15,5,AIR,7,IRON_BARS,12,CONCRETE:7,100)
RandomBlock(-8,16,1,CONCRETE:7,60,quark:iron_plate:1,20,STAINED_CLAY:12,15,STAINED_CLAY:15,5,AIR,7,IRON_BARS,12,CONCRETE:7,100)
RandomBlock(-8,16,2,CONCRETE:7,60,quark:iron_plate:1,20,STAINED_CLAY:12,15,STAINED_CLAY:15,5,AIR,7,IRON_BARS,12,CONCRETE:7,100)
RandomBlock(-8,16,3,CONCRETE:7,60,quark:iron_plate:1,20,STAINED_CLAY:12,15,STAINED_CLAY:15,5,AIR,7,IRON_BARS,12,CONCRETE:7,100)
RandomBlock(-8,16,4,CONCRETE:7,60,quark:iron_plate:1,20,STAINED_CLAY:12,15,STAINED_CLAY:15,5,AIR,7,IRON_BARS,12,CONCRETE:7,100)
RandomBlock(-8,16,5,CONCRETE:7,60,quark:iron_plate:1,20,STAINED_CLAY:12,15,STAINED_CLAY:15,5,AIR,7,IRON_BARS,12,CONCRETE:7,100)
RandomBlock(-8,16,6,CONCRETE:7,60,quark:iron_plate:1,20,STAINED_CLAY:12,15,STAINED_CLAY:15,5,AIR,7,IRON_BARS,12,CONCRETE:7,100)
RandomBlock(-8,16,7,CONCRETE:7,60,quark:iron_plate:1,20,STAINED_CLAY:12,15,STAINED_CLAY:15,5,AIR,7,IRON_BARS,12,CONCRETE:7,100)
RandomBlock(-8,16,8,CONCRETE:7,60,quark:iron_plate:1,20,STAINED_CLAY:12,15,STAINED_CLAY:15,5,AIR,7,IRON_BARS,12,CONCRETE:7,100)
RandomBlock(-8,17,-7,CONCRETE:7,60,quark:iron_plate:1,20,STAINED_CLAY:12,15,STAINED_CLAY:15,5,AIR,7,IRON_BARS,12,CONCRETE:7,100)
RandomBlock(-8,17,-6,CONCRETE:7,60,quark:iron_plate:1,20,STAINED_CLAY:12,15,STAINED_CLAY:15,5,AIR,7,IRON_BARS,12,CONCRETE:7,100)
RandomBlock(-8,17,-5,CONCRETE:7,60,quark:iron_plate:1,20,STAINED_CLAY:12,15,STAINED_CLAY:15,5,AIR,7,IRON_BARS,12,CONCRETE:7,100)
RandomBlock(-8,17,-4,CONCRETE:7,60,quark:iron_plate:1,20,STAINED_CLAY:12,15,STAINED_CLAY:15,5,AIR,7,IRON_BARS,12,CONCRETE:7,100)
RandomBlock(-8,17,-3,CONCRETE:7,60,quark:iron_plate:1,20,STAINED_CLAY:12,15,STAINED_CLAY:15,5,AIR,7,IRON_BARS,12,CONCRETE:7,100)
RandomBlock(-8,17,-2,CONCRETE:7,60,quark:iron_plate:1,20,STAINED_CLAY:12,15,STAINED_CLAY:15,5,AIR,7,IRON_BARS,12,CONCRETE:7,100)
RandomBlock(-8,17,-1,CONCRETE:7,60,quark:iron_plate:1,20,STAINED_CLAY:12,15,STAINED_CLAY:15,5,AIR,7,IRON_BARS,12,CONCRETE:7,100)
RandomBlock(-8,17,0,CONCRETE:7,60,quark:iron_plate:1,20,STAINED_CLAY:12,15,STAINED_CLAY:15,5,AIR,7,IRON_BARS,12,CONCRETE:7,100)
RandomBlock(-8,17,1,CONCRETE:7,60,quark:iron_plate:1,20,STAINED_CLAY:12,15,STAINED_CLAY:15,5,AIR,7,IRON_BARS,12,CONCRETE:7,100)
RandomBlock(-8,17,2,CONCRETE:7,60,quark:iron_plate:1,20,STAINED_CLAY:12,15,STAINED_CLAY:15,5,AIR,7,IRON_BARS,12,CONCRETE:7,100)
RandomBlock(-8,17,3,CONCRETE:7,60,quark:iron_plate:1,20,STAINED_CLAY:12,15,STAINED_CLAY:15,5,AIR,7,IRON_BARS,12,CONCRETE:7,100)
RandomBlock(-8,17,4,CONCRETE:7,60,quark:iron_plate:1,20,STAINED_CLAY:12,15,STAINED_CLAY:15,5,AIR,7,IRON_BARS,12,CONCRETE:7,100)
RandomBlock(-8,17,5,CONCRETE:7,60,quark:iron_plate:1,20,STAINED_CLAY:12,15,STAINED_CLAY:15,5,AIR,7,IRON_BARS,12,CONCRETE:7,100)
RandomBlock(-8,17,6,CONCRETE:7,60,quark:iron_plate:1,20,STAINED_CLAY:12,15,STAINED_CLAY:15,5,AIR,7,IRON_BARS,12,CONCRETE:7,100)
RandomBlock(-8,17,7,CONCRETE:7,60,quark:iron_plate:1,20,STAINED_CLAY:12,15,STAINED_CLAY:15,5,AIR,7,IRON_BARS,12,CONCRETE:7,100)
RandomBlock(-8,17,8,CONCRETE:7,60,quark:iron_plate:1,20,STAINED_CLAY:12,15,STAINED_CLAY:15,5,AIR,7,IRON_BARS,12,CONCRETE:7,100)
Block(-8,18,-7,CONCRETE:8)
Block(-8,18,-6,STAINED_GLASS_PANE:15)
Block(-8,18,-5,STAINED_GLASS_PANE:15)
Block(-8,18,-4,STAINED_GLASS_PANE:15)
Block(-8,18,-3,STAINED_GLASS_PANE:15)
Block(-8,18,-2,STAINED_GLASS_PANE:15)
Block(-8,18,-1,STAINED_GLASS_PANE:15)
Block(-8,18,2,STAINED_GLASS_PANE:15)
Block(-8,18,3,STAINED_GLASS_PANE:15)
Block(-8,18,4,STAINED_GLASS_PANE:15)
Block(-8,18,5,STAINED_GLASS_PANE:15)
Block(-8,18,6,STAINED_GLASS_PANE:15)
Block(-8,18,7,STAINED_GLASS_PANE:15)
Block(-8,18,8,CONCRETE:8)
Block(-8,19,-7,CONCRETE:8)
Block(-8,19,8,CONCRETE:8)
Block(-8,20,-7,CONCRETE:8)
Block(-8,20,8,CONCRETE:8)
Block(-8,21,-7,CONCRETE:8)
Block(-8,21,8,CONCRETE:8)
Block(-8,22,-7,CONCRETE:8)
Block(-8,22,8,CONCRETE:8)
Block(-8,23,-7,CONCRETE:8)
Block(-8,23,8,CONCRETE:8)
Block(-8,24,-7,CONCRETE:8)
Block(-8,24,8,CONCRETE:8)
Block(-8,25,-7,CONCRETE:8)
Block(-8,25,8,CONCRETE:8)
Block(-8,26,-7,CONCRETE:8)
Block(-8,26,8,CONCRETE:8)
Block(-8,27,-7,CONCRETE:8)
Block(-8,27,8,CONCRETE:8)
Block(-8,28,-7,CONCRETE:8)
Block(-8,28,8,CONCRETE:8)
Block(-8,29,-7,CONCRETE:8)
Block(-8,29,8,CONCRETE:8)
Block(-8,30,-7,CONCRETE:8)
Block(-8,30,8,CONCRETE:8)
Block(-8,31,-7,CONCRETE:8)
Block(-8,31,8,CONCRETE:8)
Block(-8,32,-7,CONCRETE:8)
Block(-8,32,8,CONCRETE:8)
Block(-8,33,-7,CONCRETE:8)
Block(-8,33,8,CONCRETE:8)
Block(-8,34,-7,CONCRETE:8)
Block(-8,34,8,CONCRETE:8)
Block(-8,35,-7,CONCRETE:8)
Block(-8,35,8,CONCRETE:8)
Block(-8,36,-7,CONCRETE:8)
Block(-8,36,8,CONCRETE:8)
Block(-8,37,-7,CONCRETE:8)
Block(-8,37,8,CONCRETE:8)
Block(-8,38,-7,CONCRETE:8)
Block(-8,38,8,CONCRETE:8)
Block(-8,39,-7,CONCRETE:8)
Block(-8,39,8,CONCRETE:8)
Block(-8,40,-7,CONCRETE:8)
Block(-8,40,8,CONCRETE:8)
Block(-8,41,-7,CONCRETE:8)
Block(-8,41,8,CONCRETE:8)
Block(-8,42,-7,CONCRETE:8)
Block(-8,42,8,CONCRETE:8)
Block(-8,43,-7,CONCRETE:8)
Block(-8,43,8,CONCRETE:8)
Block(-8,44,-7,CONCRETE:8)
Block(-8,44,8,CONCRETE:8)
Block(-8,45,-7,CONCRETE:8)
Block(-8,45,8,CONCRETE:8)
Block(-8,46,-7,CONCRETE:8)
Block(-8,46,8,CONCRETE:8)
Block(-8,47,-7,CONCRETE:8)
Block(-8,47,8,CONCRETE:8)
Block(-8,48,-7,CONCRETE:8)
Block(-8,48,8,CONCRETE:8)
Block(-8,49,-7,CONCRETE:8)
Block(-8,49,8,CONCRETE:8)
Block(-8,50,-7,CONCRETE:8)
Block(-8,50,8,CONCRETE:8)
Block(-8,51,-7,CONCRETE:8)
Block(-8,51,8,CONCRETE:8)
Block(-8,52,-7,STEP:0)
Block(-8,52,8,STEP:0)
RandomBlock(-7,0,-7,CONCRETE:7,60,quark:iron_plate:1,20,STAINED_CLAY:12,15,STAINED_CLAY:15,5,AIR,7,IRON_BARS,12,CONCRETE:7,100)
RandomBlock(-7,0,-6,CONCRETE:7,60,quark:iron_plate:1,20,STAINED_CLAY:12,15,STAINED_CLAY:15,5,AIR,7,IRON_BARS,12,CONCRETE:7,100)
RandomBlock(-7,0,-5,CONCRETE:7,60,quark:iron_plate:1,20,STAINED_CLAY:12,15,STAINED_CLAY:15,5,AIR,7,IRON_BARS,12,CONCRETE:7,100)
RandomBlock(-7,0,-4,CONCRETE:7,60,quark:iron_plate:1,20,STAINED_CLAY:12,15,STAINED_CLAY:15,5,AIR,7,IRON_BARS,12,CONCRETE:7,100)
RandomBlock(-7,0,-3,CONCRETE:7,60,quark:iron_plate:1,20,STAINED_CLAY:12,15,STAINED_CLAY:15,5,AIR,7,IRON_BARS,12,CONCRETE:7,100)
RandomBlock(-7,0,-2,CONCRETE:7,60,quark:iron_plate:1,20,STAINED_CLAY:12,15,STAINED_CLAY:15,5,AIR,7,IRON_BARS,12,CONCRETE:7,100)
RandomBlock(-7,0,-1,CONCRETE:7,60,quark:iron_plate:1,20,STAINED_CLAY:12,15,STAINED_CLAY:15,5,AIR,7,IRON_BARS,12,CONCRETE:7,100)
RandomBlock(-7,0,0,CONCRETE:7,60,quark:iron_plate:1,20,STAINED_CLAY:12,15,STAINED_CLAY:15,5,AIR,7,IRON_BARS,12,CONCRETE:7,100)
RandomBlock(-7,0,1,CONCRETE:7,60,quark:iron_plate:1,20,STAINED_CLAY:12,15,STAINED_CLAY:15,5,AIR,7,IRON_BARS,12,CONCRETE:7,100)
RandomBlock(-7,0,2,CONCRETE:7,60,quark:iron_plate:1,20,STAINED_CLAY:12,15,STAINED_CLAY:15,5,AIR,7,IRON_BARS,12,CONCRETE:7,100)
RandomBlock(-7,0,3,CONCRETE:7,60,quark:iron_plate:1,20,STAINED_CLAY:12,15,STAINED_CLAY:15,5,AIR,7,IRON_BARS,12,CONCRETE:7,100)
RandomBlock(-7,0,4,CONCRETE:7,60,quark:iron_plate:1,20,STAINED_CLAY:12,15,STAINED_CLAY:15,5,AIR,7,IRON_BARS,12,CONCRETE:7,100)
RandomBlock(-7,0,5,CONCRETE:7,60,quark:iron_plate:1,20,STAINED_CLAY:12,15,STAINED_CLAY:15,5,AIR,7,IRON_BARS,12,CONCRETE:7,100)
RandomBlock(-7,0,6,CONCRETE:7,60,quark:iron_plate:1,20,STAINED_CLAY:12,15,STAINED_CLAY:15,5,AIR,7,IRON_BARS,12,CONCRETE:7,100)
RandomBlock(-7,0,7,CONCRETE:7,60,quark:iron_plate:1,20,STAINED_CLAY:12,15,STAINED_CLAY:15,5,AIR,7,IRON_BARS,12,CONCRETE:7,100)
RandomBlock(-7,0,8,CONCRETE:7,60,quark:iron_plate:1,20,STAINED_CLAY:12,15,STAINED_CLAY:15,5,AIR,7,IRON_BARS,12,CONCRETE:7,100)
RandomBlock(-7,1,-7,CONCRETE:7,60,quark:iron_plate:1,20,STAINED_CLAY:12,15,STAINED_CLAY:15,5,AIR,7,IRON_BARS,12,CONCRETE:7,100)
RandomBlock(-7,1,-6,CONCRETE:7,60,quark:iron_plate:1,20,STAINED_CLAY:12,15,STAINED_CLAY:15,5,AIR,7,IRON_BARS,12,CONCRETE:7,100)
RandomBlock(-7,1,-5,CONCRETE:7,60,quark:iron_plate:1,20,STAINED_CLAY:12,15,STAINED_CLAY:15,5,AIR,7,IRON_BARS,12,CONCRETE:7,100)
RandomBlock(-7,1,-4,CONCRETE:7,60,quark:iron_plate:1,20,STAINED_CLAY:12,15,STAINED_CLAY:15,5,AIR,7,IRON_BARS,12,CONCRETE:7,100)
RandomBlock(-7,1,-3,CONCRETE:7,60,quark:iron_plate:1,20,STAINED_CLAY:12,15,STAINED_CLAY:15,5,AIR,7,IRON_BARS,12,CONCRETE:7,100)
RandomBlock(-7,1,-2,CONCRETE:7,60,quark:iron_plate:1,20,STAINED_CLAY:12,15,STAINED_CLAY:15,5,AIR,7,IRON_BARS,12,CONCRETE:7,100)
RandomBlock(-7,1,-1,CONCRETE:7,60,quark:iron_plate:1,20,STAINED_CLAY:12,15,STAINED_CLAY:15,5,AIR,7,IRON_BARS,12,CONCRETE:7,100)
RandomBlock(-7,1,0,CONCRETE:7,60,quark:iron_plate:1,20,STAINED_CLAY:12,15,STAINED_CLAY:15,5,AIR,7,IRON_BARS,12,CONCRETE:7,100)
RandomBlock(-7,1,1,CONCRETE:7,60,quark:iron_plate:1,20,STAINED_CLAY:12,15,STAINED_CLAY:15,5,AIR,7,IRON_BARS,12,CONCRETE:7,100)
RandomBlock(-7,1,2,CONCRETE:7,60,quark:iron_plate:1,20,STAINED_CLAY:12,15,STAINED_CLAY:15,5,AIR,7,IRON_BARS,12,CONCRETE:7,100)
RandomBlock(-7,1,3,CONCRETE:7,60,quark:iron_plate:1,20,STAINED_CLAY:12,15,STAINED_CLAY:15,5,AIR,7,IRON_BARS,12,CONCRETE:7,100)
RandomBlock(-7,1,4,CONCRETE:7,60,quark:iron_plate:1,20,STAINED_CLAY:12,15,STAINED_CLAY:15,5,AIR,7,IRON_BARS,12,CONCRETE:7,100)
RandomBlock(-7,1,5,CONCRETE:7,60,quark:iron_plate:1,20,STAINED_CLAY:12,15,STAINED_CLAY:15,5,AIR,7,IRON_BARS,12,CONCRETE:7,100)
RandomBlock(-7,1,6,CONCRETE:7,60,quark:iron_plate:1,20,STAINED_CLAY:12,15,STAINED_CLAY:15,5,AIR,7,IRON_BARS,12,CONCRETE:7,100)
RandomBlock(-7,1,7,CONCRETE:7,60,quark:iron_plate:1,20,STAINED_CLAY:12,15,STAINED_CLAY:15,5,AIR,7,IRON_BARS,12,CONCRETE:7,100)
RandomBlock(-7,1,8,CONCRETE:7,60,quark:iron_plate:1,20,STAINED_CLAY:12,15,STAINED_CLAY:15,5,AIR,7,IRON_BARS,12,CONCRETE:7,100)
RandomBlock(-7,2,-7,CONCRETE:7,60,quark:iron_plate:1,20,STAINED_CLAY:12,15,STAINED_CLAY:15,5,AIR,7,IRON_BARS,12,CONCRETE:7,100)
RandomBlock(-7,2,-6,CONCRETE:7,60,quark:iron_plate:1,20,STAINED_CLAY:12,15,STAINED_CLAY:15,5,AIR,7,IRON_BARS,12,CONCRETE:7,100)
RandomBlock(-7,2,-5,CONCRETE:7,60,quark:iron_plate:1,20,STAINED_CLAY:12,15,STAINED_CLAY:15,5,AIR,7,IRON_BARS,12,CONCRETE:7,100)
RandomBlock(-7,2,-4,CONCRETE:7,60,quark:iron_plate:1,20,STAINED_CLAY:12,15,STAINED_CLAY:15,5,AIR,7,IRON_BARS,12,CONCRETE:7,100)
RandomBlock(-7,2,-3,CONCRETE:7,60,quark:iron_plate:1,20,STAINED_CLAY:12,15,STAINED_CLAY:15,5,AIR,7,IRON_BARS,12,CONCRETE:7,100)
RandomBlock(-7,2,-2,CONCRETE:7,60,quark:iron_plate:1,20,STAINED_CLAY:12,15,STAINED_CLAY:15,5,AIR,7,IRON_BARS,12,CONCRETE:7,100)
RandomBlock(-7,2,-1,CONCRETE:7,60,quark:iron_plate:1,20,STAINED_CLAY:12,15,STAINED_CLAY:15,5,AIR,7,IRON_BARS,12,CONCRETE:7,100)
RandomBlock(-7,2,0,CONCRETE:7,60,quark:iron_plate:1,20,STAINED_CLAY:12,15,STAINED_CLAY:15,5,AIR,7,IRON_BARS,12,CONCRETE:7,100)
RandomBlock(-7,2,1,CONCRETE:7,60,quark:iron_plate:1,20,STAINED_CLAY:12,15,STAINED_CLAY:15,5,AIR,7,IRON_BARS,12,CONCRETE:7,100)
RandomBlock(-7,2,2,CONCRETE:7,60,quark:iron_plate:1,20,STAINED_CLAY:12,15,STAINED_CLAY:15,5,AIR,7,IRON_BARS,12,CONCRETE:7,100)
RandomBlock(-7,2,3,CONCRETE:7,60,quark:iron_plate:1,20,STAINED_CLAY:12,15,STAINED_CLAY:15,5,AIR,7,IRON_BARS,12,CONCRETE:7,100)
RandomBlock(-7,2,4,CONCRETE:7,60,quark:iron_plate:1,20,STAINED_CLAY:12,15,STAINED_CLAY:15,5,AIR,7,IRON_BARS,12,CONCRETE:7,100)
RandomBlock(-7,2,5,CONCRETE:7,60,quark:iron_plate:1,20,STAINED_CLAY:12,15,STAINED_CLAY:15,5,AIR,7,IRON_BARS,12,CONCRETE:7,100)
RandomBlock(-7,2,6,CONCRETE:7,60,quark:iron_plate:1,20,STAINED_CLAY:12,15,STAINED_CLAY:15,5,AIR,7,IRON_BARS,12,CONCRETE:7,100)
RandomBlock(-7,2,7,CONCRETE:7,60,quark:iron_plate:1,20,STAINED_CLAY:12,15,STAINED_CLAY:15,5,AIR,7,IRON_BARS,12,CONCRETE:7,100)
RandomBlock(-7,2,8,CONCRETE:7,60,quark:iron_plate:1,20,STAINED_CLAY:12,15,STAINED_CLAY:15,5,AIR,7,IRON_BARS,12,CONCRETE:7,100)
RandomBlock(-7,3,-7,CONCRETE:7,60,quark:iron_plate:1,20,STAINED_CLAY:12,15,STAINED_CLAY:15,5,AIR,7,IRON_BARS,12,CONCRETE:7,100)
RandomBlock(-7,3,-6,CONCRETE:7,60,quark:iron_plate:1,20,STAINED_CLAY:12,15,STAINED_CLAY:15,5,AIR,7,IRON_BARS,12,CONCRETE:7,100)
RandomBlock(-7,3,-5,CONCRETE:7,60,quark:iron_plate:1,20,STAINED_CLAY:12,15,STAINED_CLAY:15,5,AIR,7,IRON_BARS,12,CONCRETE:7,100)
RandomBlock(-7,3,-4,CONCRETE:7,60,quark:iron_plate:1,20,STAINED_CLAY:12,15,STAINED_CLAY:15,5,AIR,7,IRON_BARS,12,CONCRETE:7,100)
RandomBlock(-7,3,-3,CONCRETE:7,60,quark:iron_plate:1,20,STAINED_CLAY:12,15,STAINED_CLAY:15,5,AIR,7,IRON_BARS,12,CONCRETE:7,100)
RandomBlock(-7,3,-2,CONCRETE:7,60,quark:iron_plate:1,20,STAINED_CLAY:12,15,STAINED_CLAY:15,5,AIR,7,IRON_BARS,12,CONCRETE:7,100)
RandomBlock(-7,3,-1,CONCRETE:7,60,quark:iron_plate:1,20,STAINED_CLAY:12,15,STAINED_CLAY:15,5,AIR,7,IRON_BARS,12,CONCRETE:7,100)
RandomBlock(-7,3,0,CONCRETE:7,60,quark:iron_plate:1,20,STAINED_CLAY:12,15,STAINED_CLAY:15,5,AIR,7,IRON_BARS,12,CONCRETE:7,100)
RandomBlock(-7,3,1,CONCRETE:7,60,quark:iron_plate:1,20,STAINED_CLAY:12,15,STAINED_CLAY:15,5,AIR,7,IRON_BARS,12,CONCRETE:7,100)
RandomBlock(-7,3,2,CONCRETE:7,60,quark:iron_plate:1,20,STAINED_CLAY:12,15,STAINED_CLAY:15,5,AIR,7,IRON_BARS,12,CONCRETE:7,100)
RandomBlock(-7,3,3,CONCRETE:7,60,quark:iron_plate:1,20,STAINED_CLAY:12,15,STAINED_CLAY:15,5,AIR,7,IRON_BARS,12,CONCRETE:7,100)
RandomBlock(-7,3,4,CONCRETE:7,60,quark:iron_plate:1,20,STAINED_CLAY:12,15,STAINED_CLAY:15,5,AIR,7,IRON_BARS,12,CONCRETE:7,100)
RandomBlock(-7,3,5,CONCRETE:7,60,quark:iron_plate:1,20,STAINED_CLAY:12,15,STAINED_CLAY:15,5,AIR,7,IRON_BARS,12,CONCRETE:7,100)
RandomBlock(-7,3,6,CONCRETE:7,60,quark:iron_plate:1,20,STAINED_CLAY:12,15,STAINED_CLAY:15,5,AIR,7,IRON_BARS,12,CONCRETE:7,100)
RandomBlock(-7,3,7,CONCRETE:7,60,quark:iron_plate:1,20,STAINED_CLAY:12,15,STAINED_CLAY:15,5,AIR,7,IRON_BARS,12,CONCRETE:7,100)
RandomBlock(-7,3,8,CONCRETE:7,60,quark:iron_plate:1,20,STAINED_CLAY:12,15,STAINED_CLAY:15,5,AIR,7,IRON_BARS,12,CONCRETE:7,100)
RandomBlock(-7,4,-7,CONCRETE:7,60,quark:iron_plate:1,20,STAINED_CLAY:12,15,STAINED_CLAY:15,5,AIR,7,IRON_BARS,12,CONCRETE:7,100)
RandomBlock(-7,4,-6,CONCRETE:7,60,quark:iron_plate:1,20,STAINED_CLAY:12,15,STAINED_CLAY:15,5,AIR,7,IRON_BARS,12,CONCRETE:7,100)
RandomBlock(-7,4,-5,CONCRETE:7,60,quark:iron_plate:1,20,STAINED_CLAY:12,15,STAINED_CLAY:15,5,AIR,7,IRON_BARS,12,CONCRETE:7,100)
RandomBlock(-7,4,-4,CONCRETE:7,60,quark:iron_plate:1,20,STAINED_CLAY:12,15,STAINED_CLAY:15,5,AIR,7,IRON_BARS,12,CONCRETE:7,100)
RandomBlock(-7,4,-3,CONCRETE:7,60,quark:iron_plate:1,20,STAINED_CLAY:12,15,STAINED_CLAY:15,5,AIR,7,IRON_BARS,12,CONCRETE:7,100)
RandomBlock(-7,4,-2,CONCRETE:7,60,quark:iron_plate:1,20,STAINED_CLAY:12,15,STAINED_CLAY:15,5,AIR,7,IRON_BARS,12,CONCRETE:7,100)
RandomBlock(-7,4,-1,CONCRETE:7,60,quark:iron_plate:1,20,STAINED_CLAY:12,15,STAINED_CLAY:15,5,AIR,7,IRON_BARS,12,CONCRETE:7,100)
RandomBlock(-7,4,0,CONCRETE:7,60,quark:iron_plate:1,20,STAINED_CLAY:12,15,STAINED_CLAY:15,5,AIR,7,IRON_BARS,12,CONCRETE:7,100)
RandomBlock(-7,4,1,CONCRETE:7,60,quark:iron_plate:1,20,STAINED_CLAY:12,15,STAINED_CLAY:15,5,AIR,7,IRON_BARS,12,CONCRETE:7,100)
RandomBlock(-7,4,2,CONCRETE:7,60,quark:iron_plate:1,20,STAINED_CLAY:12,15,STAINED_CLAY:15,5,AIR,7,IRON_BARS,12,CONCRETE:7,100)
RandomBlock(-7,4,3,CONCRETE:7,60,quark:iron_plate:1,20,STAINED_CLAY:12,15,STAINED_CLAY:15,5,AIR,7,IRON_BARS,12,CONCRETE:7,100)
RandomBlock(-7,4,4,CONCRETE:7,60,quark:iron_plate:1,20,STAINED_CLAY:12,15,STAINED_CLAY:15,5,AIR,7,IRON_BARS,12,CONCRETE:7,100)
RandomBlock(-7,4,5,CONCRETE:7,60,quark:iron_plate:1,20,STAINED_CLAY:12,15,STAINED_CLAY:15,5,AIR,7,IRON_BARS,12,CONCRETE:7,100)
RandomBlock(-7,4,6,CONCRETE:7,60,quark:iron_plate:1,20,STAINED_CLAY:12,15,STAINED_CLAY:15,5,AIR,7,IRON_BARS,12,CONCRETE:7,100)
RandomBlock(-7,4,7,CONCRETE:7,60,quark:iron_plate:1,20,STAINED_CLAY:12,15,STAINED_CLAY:15,5,AIR,7,IRON_BARS,12,CONCRETE:7,100)
RandomBlock(-7,4,8,CONCRETE:7,60,quark:iron_plate:1,20,STAINED_CLAY:12,15,STAINED_CLAY:15,5,AIR,7,IRON_BARS,12,CONCRETE:7,100)
RandomBlock(-7,5,-7,CONCRETE:7,60,quark:iron_plate:1,20,STAINED_CLAY:12,15,STAINED_CLAY:15,5,AIR,7,IRON_BARS,12,CONCRETE:7,100)
RandomBlock(-7,5,-6,CONCRETE:7,60,quark:iron_plate:1,20,STAINED_CLAY:12,15,STAINED_CLAY:15,5,AIR,7,IRON_BARS,12,CONCRETE:7,100)
RandomBlock(-7,5,-5,CONCRETE:7,60,quark:iron_plate:1,20,STAINED_CLAY:12,15,STAINED_CLAY:15,5,AIR,7,IRON_BARS,12,CONCRETE:7,100)
RandomBlock(-7,5,-4,CONCRETE:7,60,quark:iron_plate:1,20,STAINED_CLAY:12,15,STAINED_CLAY:15,5,AIR,7,IRON_BARS,12,CONCRETE:7,100)
RandomBlock(-7,5,-3,CONCRETE:7,60,quark:iron_plate:1,20,STAINED_CLAY:12,15,STAINED_CLAY:15,5,AIR,7,IRON_BARS,12,CONCRETE:7,100)
RandomBlock(-7,5,-2,CONCRETE:7,60,quark:iron_plate:1,20,STAINED_CLAY:12,15,STAINED_CLAY:15,5,AIR,7,IRON_BARS,12,CONCRETE:7,100)
RandomBlock(-7,5,-1,CONCRETE:7,60,quark:iron_plate:1,20,STAINED_CLAY:12,15,STAINED_CLAY:15,5,AIR,7,IRON_BARS,12,CONCRETE:7,100)
RandomBlock(-7,5,0,CONCRETE:7,60,quark:iron_plate:1,20,STAINED_CLAY:12,15,STAINED_CLAY:15,5,AIR,7,IRON_BARS,12,CONCRETE:7,100)
RandomBlock(-7,5,1,CONCRETE:7,60,quark:iron_plate:1,20,STAINED_CLAY:12,15,STAINED_CLAY:15,5,AIR,7,IRON_BARS,12,CONCRETE:7,100)
RandomBlock(-7,5,2,CONCRETE:7,60,quark:iron_plate:1,20,STAINED_CLAY:12,15,STAINED_CLAY:15,5,AIR,7,IRON_BARS,12,CONCRETE:7,100)
RandomBlock(-7,5,3,CONCRETE:7,60,quark:iron_plate:1,20,STAINED_CLAY:12,15,STAINED_CLAY:15,5,AIR,7,IRON_BARS,12,CONCRETE:7,100)
RandomBlock(-7,5,4,CONCRETE:7,60,quark:iron_plate:1,20,STAINED_CLAY:12,15,STAINED_CLAY:15,5,AIR,7,IRON_BARS,12,CONCRETE:7,100)
RandomBlock(-7,5,5,CONCRETE:7,60,quark:iron_plate:1,20,STAINED_CLAY:12,15,STAINED_CLAY:15,5,AIR,7,IRON_BARS,12,CONCRETE:7,100)
RandomBlock(-7,5,6,CONCRETE:7,60,quark:iron_plate:1,20,STAINED_CLAY:12,15,STAINED_CLAY:15,5,AIR,7,IRON_BARS,12,CONCRETE:7,100)
RandomBlock(-7,5,7,CONCRETE:7,60,quark:iron_plate:1,20,STAINED_CLAY:12,15,STAINED_CLAY:15,5,AIR,7,IRON_BARS,12,CONCRETE:7,100)
RandomBlock(-7,5,8,CONCRETE:7,60,quark:iron_plate:1,20,STAINED_CLAY:12,15,STAINED_CLAY:15,5,AIR,7,IRON_BARS,12,CONCRETE:7,100)
RandomBlock(-7,6,-7,CONCRETE:7,60,quark:iron_plate:1,20,STAINED_CLAY:12,15,STAINED_CLAY:15,5,AIR,7,IRON_BARS,12,CONCRETE:7,100)
RandomBlock(-7,6,-6,CONCRETE:7,60,quark:iron_plate:1,20,STAINED_CLAY:12,15,STAINED_CLAY:15,5,AIR,7,IRON_BARS,12,CONCRETE:7,100)
RandomBlock(-7,6,-5,CONCRETE:7,60,quark:iron_plate:1,20,STAINED_CLAY:12,15,STAINED_CLAY:15,5,AIR,7,IRON_BARS,12,CONCRETE:7,100)
RandomBlock(-7,6,-4,CONCRETE:7,60,quark:iron_plate:1,20,STAINED_CLAY:12,15,STAINED_CLAY:15,5,AIR,7,IRON_BARS,12,CONCRETE:7,100)
RandomBlock(-7,6,-3,CONCRETE:7,60,quark:iron_plate:1,20,STAINED_CLAY:12,15,STAINED_CLAY:15,5,AIR,7,IRON_BARS,12,CONCRETE:7,100)
RandomBlock(-7,6,-2,CONCRETE:7,60,quark:iron_plate:1,20,STAINED_CLAY:12,15,STAINED_CLAY:15,5,AIR,7,IRON_BARS,12,CONCRETE:7,100)
RandomBlock(-7,6,-1,CONCRETE:7,60,quark:iron_plate:1,20,STAINED_CLAY:12,15,STAINED_CLAY:15,5,AIR,7,IRON_BARS,12,CONCRETE:7,100)
RandomBlock(-7,6,0,CONCRETE:7,60,quark:iron_plate:1,20,STAINED_CLAY:12,15,STAINED_CLAY:15,5,AIR,7,IRON_BARS,12,CONCRETE:7,100)
RandomBlock(-7,6,1,CONCRETE:7,60,quark:iron_plate:1,20,STAINED_CLAY:12,15,STAINED_CLAY:15,5,AIR,7,IRON_BARS,12,CONCRETE:7,100)
RandomBlock(-7,6,2,CONCRETE:7,60,quark:iron_plate:1,20,STAINED_CLAY:12,15,STAINED_CLAY:15,5,AIR,7,IRON_BARS,12,CONCRETE:7,100)
RandomBlock(-7,6,3,CONCRETE:7,60,quark:iron_plate:1,20,STAINED_CLAY:12,15,STAINED_CLAY:15,5,AIR,7,IRON_BARS,12,CONCRETE:7,100)
RandomBlock(-7,6,4,CONCRETE:7,60,quark:iron_plate:1,20,STAINED_CLAY:12,15,STAINED_CLAY:15,5,AIR,7,IRON_BARS,12,CONCRETE:7,100)
RandomBlock(-7,6,5,CONCRETE:7,60,quark:iron_plate:1,20,STAINED_CLAY:12,15,STAINED_CLAY:15,5,AIR,7,IRON_BARS,12,CONCRETE:7,100)
RandomBlock(-7,6,6,CONCRETE:7,60,quark:iron_plate:1,20,STAINED_CLAY:12,15,STAINED_CLAY:15,5,AIR,7,IRON_BARS,12,CONCRETE:7,100)
RandomBlock(-7,6,7,CONCRETE:7,60,quark:iron_plate:1,20,STAINED_CLAY:12,15,STAINED_CLAY:15,5,AIR,7,IRON_BARS,12,CONCRETE:7,100)
RandomBlock(-7,6,8,CONCRETE:7,60,quark:iron_plate:1,20,STAINED_CLAY:12,15,STAINED_CLAY:15,5,AIR,7,IRON_BARS,12,CONCRETE:7,100)
RandomBlock(-7,7,-7,CONCRETE:7,60,quark:iron_plate:1,20,STAINED_CLAY:12,15,STAINED_CLAY:15,5,AIR,7,IRON_BARS,12,CONCRETE:7,100)
RandomBlock(-7,7,-6,CONCRETE:7,60,quark:iron_plate:1,20,STAINED_CLAY:12,15,STAINED_CLAY:15,5,AIR,7,IRON_BARS,12,CONCRETE:7,100)
RandomBlock(-7,7,-5,CONCRETE:7,60,quark:iron_plate:1,20,STAINED_CLAY:12,15,STAINED_CLAY:15,5,AIR,7,IRON_BARS,12,CONCRETE:7,100)
RandomBlock(-7,7,-4,CONCRETE:7,60,quark:iron_plate:1,20,STAINED_CLAY:12,15,STAINED_CLAY:15,5,AIR,7,IRON_BARS,12,CONCRETE:7,100)
RandomBlock(-7,7,-3,CONCRETE:7,60,quark:iron_plate:1,20,STAINED_CLAY:12,15,STAINED_CLAY:15,5,AIR,7,IRON_BARS,12,CONCRETE:7,100)
RandomBlock(-7,7,-2,CONCRETE:7,60,quark:iron_plate:1,20,STAINED_CLAY:12,15,STAINED_CLAY:15,5,AIR,7,IRON_BARS,12,CONCRETE:7,100)
RandomBlock(-7,7,-1,CONCRETE:7,60,quark:iron_plate:1,20,STAINED_CLAY:12,15,STAINED_CLAY:15,5,AIR,7,IRON_BARS,12,CONCRETE:7,100)
RandomBlock(-7,7,0,CONCRETE:7,60,quark:iron_plate:1,20,STAINED_CLAY:12,15,STAINED_CLAY:15,5,AIR,7,IRON_BARS,12,CONCRETE:7,100)
RandomBlock(-7,7,1,CONCRETE:7,60,quark:iron_plate:1,20,STAINED_CLAY:12,15,STAINED_CLAY:15,5,AIR,7,IRON_BARS,12,CONCRETE:7,100)
RandomBlock(-7,7,2,CONCRETE:7,60,quark:iron_plate:1,20,STAINED_CLAY:12,15,STAINED_CLAY:15,5,AIR,7,IRON_BARS,12,CONCRETE:7,100)
RandomBlock(-7,7,3,CONCRETE:7,60,quark:iron_plate:1,20,STAINED_CLAY:12,15,STAINED_CLAY:15,5,AIR,7,IRON_BARS,12,CONCRETE:7,100)
RandomBlock(-7,7,4,CONCRETE:7,60,quark:iron_plate:1,20,STAINED_CLAY:12,15,STAINED_CLAY:15,5,AIR,7,IRON_BARS,12,CONCRETE:7,100)
RandomBlock(-7,7,5,CONCRETE:7,60,quark:iron_plate:1,20,STAINED_CLAY:12,15,STAINED_CLAY:15,5,AIR,7,IRON_BARS,12,CONCRETE:7,100)
RandomBlock(-7,7,6,CONCRETE:7,60,quark:iron_plate:1,20,STAINED_CLAY:12,15,STAINED_CLAY:15,5,AIR,7,IRON_BARS,12,CONCRETE:7,100)
RandomBlock(-7,7,7,CONCRETE:7,60,quark:iron_plate:1,20,STAINED_CLAY:12,15,STAINED_CLAY:15,5,AIR,7,IRON_BARS,12,CONCRETE:7,100)
RandomBlock(-7,7,8,CONCRETE:7,60,quark:iron_plate:1,20,STAINED_CLAY:12,15,STAINED_CLAY:15,5,AIR,7,IRON_BARS,12,CONCRETE:7,100)
RandomBlock(-7,8,-7,CONCRETE:7,60,quark:iron_plate:1,20,STAINED_CLAY:12,15,STAINED_CLAY:15,5,AIR,7,IRON_BARS,12,CONCRETE:7,100)
RandomBlock(-7,8,-6,CONCRETE:7,60,quark:iron_plate:1,20,STAINED_CLAY:12,15,STAINED_CLAY:15,5,AIR,7,IRON_BARS,12,CONCRETE:7,100)
RandomBlock(-7,8,-5,CONCRETE:7,60,quark:iron_plate:1,20,STAINED_CLAY:12,15,STAINED_CLAY:15,5,AIR,7,IRON_BARS,12,CONCRETE:7,100)
RandomBlock(-7,8,-4,CONCRETE:7,60,quark:iron_plate:1,20,STAINED_CLAY:12,15,STAINED_CLAY:15,5,AIR,7,IRON_BARS,12,CONCRETE:7,100)
RandomBlock(-7,8,-3,CONCRETE:7,60,quark:iron_plate:1,20,STAINED_CLAY:12,15,STAINED_CLAY:15,5,AIR,7,IRON_BARS,12,CONCRETE:7,100)
RandomBlock(-7,8,-2,CONCRETE:7,60,quark:iron_plate:1,20,STAINED_CLAY:12,15,STAINED_CLAY:15,5,AIR,7,IRON_BARS,12,CONCRETE:7,100)
RandomBlock(-7,8,-1,CONCRETE:7,60,quark:iron_plate:1,20,STAINED_CLAY:12,15,STAINED_CLAY:15,5,AIR,7,IRON_BARS,12,CONCRETE:7,100)
RandomBlock(-7,8,0,CONCRETE:7,60,quark:iron_plate:1,20,STAINED_CLAY:12,15,STAINED_CLAY:15,5,AIR,7,IRON_BARS,12,CONCRETE:7,100)
RandomBlock(-7,8,1,CONCRETE:7,60,quark:iron_plate:1,20,STAINED_CLAY:12,15,STAINED_CLAY:15,5,AIR,7,IRON_BARS,12,CONCRETE:7,100)
RandomBlock(-7,8,2,CONCRETE:7,60,quark:iron_plate:1,20,STAINED_CLAY:12,15,STAINED_CLAY:15,5,AIR,7,IRON_BARS,12,CONCRETE:7,100)
RandomBlock(-7,8,3,CONCRETE:7,60,quark:iron_plate:1,20,STAINED_CLAY:12,15,STAINED_CLAY:15,5,AIR,7,IRON_BARS,12,CONCRETE:7,100)
RandomBlock(-7,8,4,CONCRETE:7,60,quark:iron_plate:1,20,STAINED_CLAY:12,15,STAINED_CLAY:15,5,AIR,7,IRON_BARS,12,CONCRETE:7,100)
RandomBlock(-7,8,5,CONCRETE:7,60,quark:iron_plate:1,20,STAINED_CLAY:12,15,STAINED_CLAY:15,5,AIR,7,IRON_BARS,12,CONCRETE:7,100)
RandomBlock(-7,8,6,CONCRETE:7,60,quark:iron_plate:1,20,STAINED_CLAY:12,15,STAINED_CLAY:15,5,AIR,7,IRON_BARS,12,CONCRETE:7,100)
RandomBlock(-7,8,7,CONCRETE:7,60,quark:iron_plate:1,20,STAINED_CLAY:12,15,STAINED_CLAY:15,5,AIR,7,IRON_BARS,12,CONCRETE:7,100)
RandomBlock(-7,8,8,CONCRETE:7,60,quark:iron_plate:1,20,STAINED_CLAY:12,15,STAINED_CLAY:15,5,AIR,7,IRON_BARS,12,CONCRETE:7,100)
Block(-7,9,-7,CONCRETE:8)
Block(-7,9,-6,CONCRETE:8)
Block(-7,9,-5,CONCRETE:8)
Block(-7,9,-4,CONCRETE:8)
Block(-7,9,-3,CONCRETE:8)
Block(-7,9,-2,CONCRETE:8)
Block(-7,9,-1,CONCRETE:8)
Block(-7,9,0,CONCRETE:8)
Block(-7,9,1,CONCRETE:8)
Block(-7,9,2,CONCRETE:8)
Block(-7,9,3,CONCRETE:8)
Block(-7,9,4,CONCRETE:8)
Block(-7,9,5,CONCRETE:8)
Block(-7,9,6,CONCRETE:8)
Block(-7,9,7,CONCRETE:8)
Block(-7,9,8,CONCRETE:8)
Block(-7,10,-7,CONCRETE:8)
Block(-7,10,-6,CONCRETE:8)
Block(-7,10,-5,CONCRETE:8)
Block(-7,10,-4,CONCRETE:8)
Block(-7,10,-3,CONCRETE:8)
Block(-7,10,-2,CONCRETE:8)
Block(-7,10,-1,CONCRETE:8)
Block(-7,10,0,CONCRETE:8)
Block(-7,10,1,CONCRETE:8)
Block(-7,10,2,CONCRETE:8)
Block(-7,10,3,CONCRETE:8)
Block(-7,10,4,CONCRETE:8)
Block(-7,10,5,CONCRETE:8)
Block(-7,10,6,CONCRETE:8)
Block(-7,10,7,CONCRETE:8)
Block(-7,10,8,CONCRETE:8)
Block(-7,11,-7,CONCRETE:8)
Block(-7,11,-6,CONCRETE:8)
Block(-7,11,-5,CONCRETE:8)
Block(-7,11,-4,CONCRETE:8)
Block(-7,11,-3,CONCRETE:8)
Block(-7,11,-2,CONCRETE:8)
Block(-7,11,-1,CONCRETE:8)
Block(-7,11,0,CONCRETE:8)
Block(-7,11,1,CONCRETE:8)
Block(-7,11,2,CONCRETE:8)
Block(-7,11,3,CONCRETE:8)
Block(-7,11,4,CONCRETE:8)
Block(-7,11,5,CONCRETE:8)
Block(-7,11,6,CONCRETE:8)
Block(-7,11,7,CONCRETE:8)
Block(-7,11,8,CONCRETE:8)
Block(-7,12,-7,CONCRETE:8)
Block(-7,12,-6,STATIONARY_WATER:0)
Block(-7,12,-5,STATIONARY_WATER:0)
Block(-7,12,-4,STATIONARY_WATER:0)
Block(-7,12,-3,STATIONARY_WATER:0)
Block(-7,12,-2,STATIONARY_WATER:0)
Block(-7,12,-1,STATIONARY_WATER:0)
Block(-7,12,0,STATIONARY_WATER:0)
Block(-7,12,1,STATIONARY_WATER:0)
Block(-7,12,2,STATIONARY_WATER:0)
Block(-7,12,3,STATIONARY_WATER:0)
Block(-7,12,4,STATIONARY_WATER:0)
Block(-7,12,5,STATIONARY_WATER:0)
Block(-7,12,6,STATIONARY_WATER:0)
Block(-7,12,7,STATIONARY_WATER:0)
Block(-7,12,8,CONCRETE:8)
Block(-7,13,-7,CONCRETE:8)
Block(-7,13,-6,AIR:0)
Block(-7,13,-5,AIR:0)
Block(-7,13,-4,AIR:0)
Block(-7,13,-3,AIR:0)
Block(-7,13,-2,AIR:0)
Block(-7,13,-1,AIR:0)
Block(-7,13,0,AIR:0)
Block(-7,13,1,AIR:0)
Block(-7,13,2,AIR:0)
Block(-7,13,3,AIR:0)
Block(-7,13,4,AIR:0)
Block(-7,13,5,AIR:0)
Block(-7,13,6,AIR:0)
Block(-7,13,7,AIR:0)
Block(-7,13,8,CONCRETE:8)
Block(-7,14,-7,CONCRETE:8)
Block(-7,14,-6,AIR:0)
Block(-7,14,-5,AIR:0)
Block(-7,14,-4,AIR:0)
Block(-7,14,-3,AIR:0)
Block(-7,14,-2,AIR:0)
Block(-7,14,-1,AIR:0)
Block(-7,14,0,AIR:0)
Block(-7,14,1,AIR:0)
Block(-7,14,2,AIR:0)
Block(-7,14,3,AIR:0)
Block(-7,14,4,AIR:0)
Block(-7,14,5,AIR:0)
Block(-7,14,6,AIR:0)
Block(-7,14,7,AIR:0)
Block(-7,14,8,CONCRETE:8)
Block(-7,15,-7,CONCRETE:8)
Block(-7,15,-6,AIR:0)
Block(-7,15,-5,AIR:0)
Block(-7,15,-4,AIR:0)
Block(-7,15,-3,AIR:0)
Block(-7,15,-2,AIR:0)
Block(-7,15,-1,AIR:0)
Block(-7,15,0,AIR:0)
Block(-7,15,1,AIR:0)
Block(-7,15,2,AIR:0)
Block(-7,15,3,AIR:0)
Block(-7,15,4,AIR:0)
Block(-7,15,5,AIR:0)
Block(-7,15,6,AIR:0)
Block(-7,15,7,AIR:0)
Block(-7,15,8,CONCRETE:8)
Block(-7,16,-7,CONCRETE:8)
Block(-7,16,-6,AIR:0)
Block(-7,16,-5,AIR:0)
Block(-7,16,-4,AIR:0)
Block(-7,16,-3,AIR:0)
Block(-7,16,-2,AIR:0)
Block(-7,16,-1,AIR:0)
Block(-7,16,0,AIR:0)
Block(-7,16,1,AIR:0)
Block(-7,16,2,AIR:0)
Block(-7,16,3,AIR:0)
Block(-7,16,4,AIR:0)
Block(-7,16,5,AIR:0)
Block(-7,16,6,AIR:0)
Block(-7,16,7,AIR:0)
Block(-7,16,8,CONCRETE:8)
Block(-7,17,-7,CONCRETE:8)
Block(-7,17,-6,AIR:0)
Block(-7,17,-5,AIR:0)
Block(-7,17,-4,AIR:0)
Block(-7,17,-3,AIR:0)
Block(-7,17,-2,AIR:0)
Block(-7,17,-1,STAINED_GLASS:15)
Block(-7,17,0,CONCRETE:8)
Block(-7,17,1,CONCRETE:8)
Block(-7,17,2,STAINED_GLASS:15)
Block(-7,17,3,AIR:0)
Block(-7,17,4,AIR:0)
Block(-7,17,5,AIR:0)
Block(-7,17,6,AIR:0)
Block(-7,17,7,AIR:0)
Block(-7,17,8,CONCRETE:8)
Block(-7,18,-7,CONCRETE:8)
Block(-7,18,-1,STAINED_GLASS_PANE:15)
Block(-7,18,2,STAINED_GLASS_PANE:15)
Block(-7,18,8,CONCRETE:8)
Block(-7,19,-7,CONCRETE:8)
Block(-7,19,8,CONCRETE:8)
Block(-7,20,-7,CONCRETE:8)
Block(-7,20,8,CONCRETE:8)
Block(-7,21,-7,CONCRETE:8)
Block(-7,21,8,CONCRETE:8)
Block(-7,22,-7,CONCRETE:8)
Block(-7,22,8,CONCRETE:8)
Block(-7,23,-7,CONCRETE:8)
Block(-7,23,8,CONCRETE:8)
Block(-7,24,-7,CONCRETE:8)
Block(-7,24,8,CONCRETE:8)
Block(-7,25,-7,CONCRETE:8)
Block(-7,25,8,CONCRETE:8)
Block(-7,26,-7,CONCRETE:8)
Block(-7,26,8,CONCRETE:8)
Block(-7,27,-7,CONCRETE:8)
Block(-7,27,8,CONCRETE:8)
Block(-7,28,-7,CONCRETE:8)
Block(-7,28,8,CONCRETE:8)
Block(-7,29,-7,CONCRETE:8)
Block(-7,29,8,CONCRETE:8)
Block(-7,30,-7,CONCRETE:8)
Block(-7,30,8,CONCRETE:8)
Block(-7,31,-7,CONCRETE:8)
Block(-7,31,8,CONCRETE:8)
Block(-7,32,-7,CONCRETE:8)
Block(-7,32,8,CONCRETE:8)
Block(-7,33,-7,CONCRETE:8)
Block(-7,33,8,CONCRETE:8)
Block(-7,34,-7,CONCRETE:8)
Block(-7,34,8,CONCRETE:8)
Block(-7,35,-7,CONCRETE:8)
Block(-7,35,8,CONCRETE:8)
Block(-7,36,-7,CONCRETE:8)
Block(-7,36,8,CONCRETE:8)
Block(-7,37,-7,CONCRETE:8)
Block(-7,37,8,CONCRETE:8)
Block(-7,38,-7,CONCRETE:8)
Block(-7,38,8,CONCRETE:8)
Block(-7,39,-7,CONCRETE:8)
Block(-7,39,8,CONCRETE:8)
Block(-7,40,-7,CONCRETE:8)
Block(-7,40,8,CONCRETE:8)
Block(-7,41,-7,CONCRETE:8)
Block(-7,41,8,CONCRETE:8)
Block(-7,42,-7,CONCRETE:8)
Block(-7,42,8,CONCRETE:8)
Block(-7,43,-7,CONCRETE:8)
Block(-7,43,8,CONCRETE:8)
Block(-7,44,-7,CONCRETE:8)
Block(-7,44,8,CONCRETE:8)
Block(-7,45,-7,CONCRETE:8)
Block(-7,45,8,CONCRETE:8)
Block(-7,46,-7,CONCRETE:8)
Block(-7,46,8,CONCRETE:8)
Block(-7,47,-7,CONCRETE:8)
Block(-7,47,8,CONCRETE:8)
Block(-7,48,-7,CONCRETE:8)
Block(-7,48,8,CONCRETE:8)
Block(-7,49,-7,CONCRETE:8)
Block(-7,49,8,CONCRETE:8)
Block(-7,50,-7,CONCRETE:8)
Block(-7,50,8,CONCRETE:8)
Block(-7,51,-7,CONCRETE:8)
Block(-7,51,8,CONCRETE:8)
Block(-7,52,-7,STEP:0)
Block(-7,52,8,STEP:0)
RandomBlock(-6,0,-7,CONCRETE:7,60,quark:iron_plate:1,20,STAINED_CLAY:12,15,STAINED_CLAY:15,5,AIR,7,IRON_BARS,12,CONCRETE:7,100)
RandomBlock(-6,0,-6,CONCRETE:7,60,quark:iron_plate:1,20,STAINED_CLAY:12,15,STAINED_CLAY:15,5,AIR,7,IRON_BARS,12,CONCRETE:7,100)
RandomBlock(-6,0,-5,CONCRETE:7,60,quark:iron_plate:1,20,STAINED_CLAY:12,15,STAINED_CLAY:15,5,AIR,7,IRON_BARS,12,CONCRETE:7,100)
RandomBlock(-6,0,-4,CONCRETE:7,60,quark:iron_plate:1,20,STAINED_CLAY:12,15,STAINED_CLAY:15,5,AIR,7,IRON_BARS,12,CONCRETE:7,100)
RandomBlock(-6,0,-3,CONCRETE:7,60,quark:iron_plate:1,20,STAINED_CLAY:12,15,STAINED_CLAY:15,5,AIR,7,IRON_BARS,12,CONCRETE:7,100)
RandomBlock(-6,0,-2,CONCRETE:7,60,quark:iron_plate:1,20,STAINED_CLAY:12,15,STAINED_CLAY:15,5,AIR,7,IRON_BARS,12,CONCRETE:7,100)
RandomBlock(-6,0,-1,CONCRETE:7,60,quark:iron_plate:1,20,STAINED_CLAY:12,15,STAINED_CLAY:15,5,AIR,7,IRON_BARS,12,CONCRETE:7,100)
RandomBlock(-6,0,0,CONCRETE:7,60,quark:iron_plate:1,20,STAINED_CLAY:12,15,STAINED_CLAY:15,5,AIR,7,IRON_BARS,12,CONCRETE:7,100)
RandomBlock(-6,0,1,CONCRETE:7,60,quark:iron_plate:1,20,STAINED_CLAY:12,15,STAINED_CLAY:15,5,AIR,7,IRON_BARS,12,CONCRETE:7,100)
RandomBlock(-6,0,2,CONCRETE:7,60,quark:iron_plate:1,20,STAINED_CLAY:12,15,STAINED_CLAY:15,5,AIR,7,IRON_BARS,12,CONCRETE:7,100)
RandomBlock(-6,0,3,CONCRETE:7,60,quark:iron_plate:1,20,STAINED_CLAY:12,15,STAINED_CLAY:15,5,AIR,7,IRON_BARS,12,CONCRETE:7,100)
RandomBlock(-6,0,4,CONCRETE:7,60,quark:iron_plate:1,20,STAINED_CLAY:12,15,STAINED_CLAY:15,5,AIR,7,IRON_BARS,12,CONCRETE:7,100)
RandomBlock(-6,0,5,CONCRETE:7,60,quark:iron_plate:1,20,STAINED_CLAY:12,15,STAINED_CLAY:15,5,AIR,7,IRON_BARS,12,CONCRETE:7,100)
RandomBlock(-6,0,6,CONCRETE:7,60,quark:iron_plate:1,20,STAINED_CLAY:12,15,STAINED_CLAY:15,5,AIR,7,IRON_BARS,12,CONCRETE:7,100)
RandomBlock(-6,0,7,CONCRETE:7,60,quark:iron_plate:1,20,STAINED_CLAY:12,15,STAINED_CLAY:15,5,AIR,7,IRON_BARS,12,CONCRETE:7,100)
RandomBlock(-6,0,8,CONCRETE:7,60,quark:iron_plate:1,20,STAINED_CLAY:12,15,STAINED_CLAY:15,5,AIR,7,IRON_BARS,12,CONCRETE:7,100)
RandomBlock(-6,1,-7,CONCRETE:7,60,quark:iron_plate:1,20,STAINED_CLAY:12,15,STAINED_CLAY:15,5,AIR,7,IRON_BARS,12,CONCRETE:7,100)
RandomBlock(-6,1,-6,CONCRETE:7,60,quark:iron_plate:1,20,STAINED_CLAY:12,15,STAINED_CLAY:15,5,AIR,7,IRON_BARS,12,CONCRETE:7,100)
RandomBlock(-6,1,-5,CONCRETE:7,60,quark:iron_plate:1,20,STAINED_CLAY:12,15,STAINED_CLAY:15,5,AIR,7,IRON_BARS,12,CONCRETE:7,100)
RandomBlock(-6,1,-4,CONCRETE:7,60,quark:iron_plate:1,20,STAINED_CLAY:12,15,STAINED_CLAY:15,5,AIR,7,IRON_BARS,12,CONCRETE:7,100)
RandomBlock(-6,1,-3,CONCRETE:7,60,quark:iron_plate:1,20,STAINED_CLAY:12,15,STAINED_CLAY:15,5,AIR,7,IRON_BARS,12,CONCRETE:7,100)
RandomBlock(-6,1,-2,CONCRETE:7,60,quark:iron_plate:1,20,STAINED_CLAY:12,15,STAINED_CLAY:15,5,AIR,7,IRON_BARS,12,CONCRETE:7,100)
RandomBlock(-6,1,-1,CONCRETE:7,60,quark:iron_plate:1,20,STAINED_CLAY:12,15,STAINED_CLAY:15,5,AIR,7,IRON_BARS,12,CONCRETE:7,100)
RandomBlock(-6,1,0,CONCRETE:7,60,quark:iron_plate:1,20,STAINED_CLAY:12,15,STAINED_CLAY:15,5,AIR,7,IRON_BARS,12,CONCRETE:7,100)
RandomBlock(-6,1,1,CONCRETE:7,60,quark:iron_plate:1,20,STAINED_CLAY:12,15,STAINED_CLAY:15,5,AIR,7,IRON_BARS,12,CONCRETE:7,100)
RandomBlock(-6,1,2,CONCRETE:7,60,quark:iron_plate:1,20,STAINED_CLAY:12,15,STAINED_CLAY:15,5,AIR,7,IRON_BARS,12,CONCRETE:7,100)
RandomBlock(-6,1,3,CONCRETE:7,60,quark:iron_plate:1,20,STAINED_CLAY:12,15,STAINED_CLAY:15,5,AIR,7,IRON_BARS,12,CONCRETE:7,100)
RandomBlock(-6,1,4,CONCRETE:7,60,quark:iron_plate:1,20,STAINED_CLAY:12,15,STAINED_CLAY:15,5,AIR,7,IRON_BARS,12,CONCRETE:7,100)
RandomBlock(-6,1,5,CONCRETE:7,60,quark:iron_plate:1,20,STAINED_CLAY:12,15,STAINED_CLAY:15,5,AIR,7,IRON_BARS,12,CONCRETE:7,100)
RandomBlock(-6,1,6,CONCRETE:7,60,quark:iron_plate:1,20,STAINED_CLAY:12,15,STAINED_CLAY:15,5,AIR,7,IRON_BARS,12,CONCRETE:7,100)
RandomBlock(-6,1,7,CONCRETE:7,60,quark:iron_plate:1,20,STAINED_CLAY:12,15,STAINED_CLAY:15,5,AIR,7,IRON_BARS,12,CONCRETE:7,100)
RandomBlock(-6,1,8,CONCRETE:7,60,quark:iron_plate:1,20,STAINED_CLAY:12,15,STAINED_CLAY:15,5,AIR,7,IRON_BARS,12,CONCRETE:7,100)
RandomBlock(-6,2,-7,CONCRETE:7,60,quark:iron_plate:1,20,STAINED_CLAY:12,15,STAINED_CLAY:15,5,AIR,7,IRON_BARS,12,CONCRETE:7,100)
RandomBlock(-6,2,-6,CONCRETE:7,60,quark:iron_plate:1,20,STAINED_CLAY:12,15,STAINED_CLAY:15,5,AIR,7,IRON_BARS,12,CONCRETE:7,100)
RandomBlock(-6,2,-5,CONCRETE:7,60,quark:iron_plate:1,20,STAINED_CLAY:12,15,STAINED_CLAY:15,5,AIR,7,IRON_BARS,12,CONCRETE:7,100)
RandomBlock(-6,2,-4,CONCRETE:7,60,quark:iron_plate:1,20,STAINED_CLAY:12,15,STAINED_CLAY:15,5,AIR,7,IRON_BARS,12,CONCRETE:7,100)
RandomBlock(-6,2,-3,CONCRETE:7,60,quark:iron_plate:1,20,STAINED_CLAY:12,15,STAINED_CLAY:15,5,AIR,7,IRON_BARS,12,CONCRETE:7,100)
RandomBlock(-6,2,-2,CONCRETE:7,60,quark:iron_plate:1,20,STAINED_CLAY:12,15,STAINED_CLAY:15,5,AIR,7,IRON_BARS,12,CONCRETE:7,100)
RandomBlock(-6,2,-1,CONCRETE:7,60,quark:iron_plate:1,20,STAINED_CLAY:12,15,STAINED_CLAY:15,5,AIR,7,IRON_BARS,12,CONCRETE:7,100)
RandomBlock(-6,2,0,CONCRETE:7,60,quark:iron_plate:1,20,STAINED_CLAY:12,15,STAINED_CLAY:15,5,AIR,7,IRON_BARS,12,CONCRETE:7,100)
RandomBlock(-6,2,1,CONCRETE:7,60,quark:iron_plate:1,20,STAINED_CLAY:12,15,STAINED_CLAY:15,5,AIR,7,IRON_BARS,12,CONCRETE:7,100)
RandomBlock(-6,2,2,CONCRETE:7,60,quark:iron_plate:1,20,STAINED_CLAY:12,15,STAINED_CLAY:15,5,AIR,7,IRON_BARS,12,CONCRETE:7,100)
RandomBlock(-6,2,3,CONCRETE:7,60,quark:iron_plate:1,20,STAINED_CLAY:12,15,STAINED_CLAY:15,5,AIR,7,IRON_BARS,12,CONCRETE:7,100)
RandomBlock(-6,2,4,CONCRETE:7,60,quark:iron_plate:1,20,STAINED_CLAY:12,15,STAINED_CLAY:15,5,AIR,7,IRON_BARS,12,CONCRETE:7,100)
RandomBlock(-6,2,5,CONCRETE:7,60,quark:iron_plate:1,20,STAINED_CLAY:12,15,STAINED_CLAY:15,5,AIR,7,IRON_BARS,12,CONCRETE:7,100)
RandomBlock(-6,2,6,CONCRETE:7,60,quark:iron_plate:1,20,STAINED_CLAY:12,15,STAINED_CLAY:15,5,AIR,7,IRON_BARS,12,CONCRETE:7,100)
RandomBlock(-6,2,7,CONCRETE:7,60,quark:iron_plate:1,20,STAINED_CLAY:12,15,STAINED_CLAY:15,5,AIR,7,IRON_BARS,12,CONCRETE:7,100)
RandomBlock(-6,2,8,CONCRETE:7,60,quark:iron_plate:1,20,STAINED_CLAY:12,15,STAINED_CLAY:15,5,AIR,7,IRON_BARS,12,CONCRETE:7,100)
RandomBlock(-6,3,-7,CONCRETE:7,60,quark:iron_plate:1,20,STAINED_CLAY:12,15,STAINED_CLAY:15,5,AIR,7,IRON_BARS,12,CONCRETE:7,100)
RandomBlock(-6,3,-6,CONCRETE:7,60,quark:iron_plate:1,20,STAINED_CLAY:12,15,STAINED_CLAY:15,5,AIR,7,IRON_BARS,12,CONCRETE:7,100)
RandomBlock(-6,3,-5,CONCRETE:7,60,quark:iron_plate:1,20,STAINED_CLAY:12,15,STAINED_CLAY:15,5,AIR,7,IRON_BARS,12,CONCRETE:7,100)
RandomBlock(-6,3,-4,CONCRETE:7,60,quark:iron_plate:1,20,STAINED_CLAY:12,15,STAINED_CLAY:15,5,AIR,7,IRON_BARS,12,CONCRETE:7,100)
RandomBlock(-6,3,-3,CONCRETE:7,60,quark:iron_plate:1,20,STAINED_CLAY:12,15,STAINED_CLAY:15,5,AIR,7,IRON_BARS,12,CONCRETE:7,100)
RandomBlock(-6,3,-2,CONCRETE:7,60,quark:iron_plate:1,20,STAINED_CLAY:12,15,STAINED_CLAY:15,5,AIR,7,IRON_BARS,12,CONCRETE:7,100)
RandomBlock(-6,3,-1,CONCRETE:7,60,quark:iron_plate:1,20,STAINED_CLAY:12,15,STAINED_CLAY:15,5,AIR,7,IRON_BARS,12,CONCRETE:7,100)
RandomBlock(-6,3,0,CONCRETE:7,60,quark:iron_plate:1,20,STAINED_CLAY:12,15,STAINED_CLAY:15,5,AIR,7,IRON_BARS,12,CONCRETE:7,100)
RandomBlock(-6,3,1,CONCRETE:7,60,quark:iron_plate:1,20,STAINED_CLAY:12,15,STAINED_CLAY:15,5,AIR,7,IRON_BARS,12,CONCRETE:7,100)
RandomBlock(-6,3,2,CONCRETE:7,60,quark:iron_plate:1,20,STAINED_CLAY:12,15,STAINED_CLAY:15,5,AIR,7,IRON_BARS,12,CONCRETE:7,100)
RandomBlock(-6,3,3,CONCRETE:7,60,quark:iron_plate:1,20,STAINED_CLAY:12,15,STAINED_CLAY:15,5,AIR,7,IRON_BARS,12,CONCRETE:7,100)
RandomBlock(-6,3,4,CONCRETE:7,60,quark:iron_plate:1,20,STAINED_CLAY:12,15,STAINED_CLAY:15,5,AIR,7,IRON_BARS,12,CONCRETE:7,100)
RandomBlock(-6,3,5,CONCRETE:7,60,quark:iron_plate:1,20,STAINED_CLAY:12,15,STAINED_CLAY:15,5,AIR,7,IRON_BARS,12,CONCRETE:7,100)
RandomBlock(-6,3,6,CONCRETE:7,60,quark:iron_plate:1,20,STAINED_CLAY:12,15,STAINED_CLAY:15,5,AIR,7,IRON_BARS,12,CONCRETE:7,100)
RandomBlock(-6,3,7,CONCRETE:7,60,quark:iron_plate:1,20,STAINED_CLAY:12,15,STAINED_CLAY:15,5,AIR,7,IRON_BARS,12,CONCRETE:7,100)
RandomBlock(-6,3,8,CONCRETE:7,60,quark:iron_plate:1,20,STAINED_CLAY:12,15,STAINED_CLAY:15,5,AIR,7,IRON_BARS,12,CONCRETE:7,100)
RandomBlock(-6,4,-7,CONCRETE:7,60,quark:iron_plate:1,20,STAINED_CLAY:12,15,STAINED_CLAY:15,5,AIR,7,IRON_BARS,12,CONCRETE:7,100)
RandomBlock(-6,4,-6,CONCRETE:7,60,quark:iron_plate:1,20,STAINED_CLAY:12,15,STAINED_CLAY:15,5,AIR,7,IRON_BARS,12,CONCRETE:7,100)
RandomBlock(-6,4,-5,CONCRETE:7,60,quark:iron_plate:1,20,STAINED_CLAY:12,15,STAINED_CLAY:15,5,AIR,7,IRON_BARS,12,CONCRETE:7,100)
RandomBlock(-6,4,-4,CONCRETE:7,60,quark:iron_plate:1,20,STAINED_CLAY:12,15,STAINED_CLAY:15,5,AIR,7,IRON_BARS,12,CONCRETE:7,100)
RandomBlock(-6,4,-3,CONCRETE:7,60,quark:iron_plate:1,20,STAINED_CLAY:12,15,STAINED_CLAY:15,5,AIR,7,IRON_BARS,12,CONCRETE:7,100)
RandomBlock(-6,4,-2,CONCRETE:7,60,quark:iron_plate:1,20,STAINED_CLAY:12,15,STAINED_CLAY:15,5,AIR,7,IRON_BARS,12,CONCRETE:7,100)
RandomBlock(-6,4,-1,CONCRETE:7,60,quark:iron_plate:1,20,STAINED_CLAY:12,15,STAINED_CLAY:15,5,AIR,7,IRON_BARS,12,CONCRETE:7,100)
RandomBlock(-6,4,0,CONCRETE:7,60,quark:iron_plate:1,20,STAINED_CLAY:12,15,STAINED_CLAY:15,5,AIR,7,IRON_BARS,12,CONCRETE:7,100)
RandomBlock(-6,4,1,CONCRETE:7,60,quark:iron_plate:1,20,STAINED_CLAY:12,15,STAINED_CLAY:15,5,AIR,7,IRON_BARS,12,CONCRETE:7,100)
RandomBlock(-6,4,2,CONCRETE:7,60,quark:iron_plate:1,20,STAINED_CLAY:12,15,STAINED_CLAY:15,5,AIR,7,IRON_BARS,12,CONCRETE:7,100)
RandomBlock(-6,4,3,CONCRETE:7,60,quark:iron_plate:1,20,STAINED_CLAY:12,15,STAINED_CLAY:15,5,AIR,7,IRON_BARS,12,CONCRETE:7,100)
RandomBlock(-6,4,4,CONCRETE:7,60,quark:iron_plate:1,20,STAINED_CLAY:12,15,STAINED_CLAY:15,5,AIR,7,IRON_BARS,12,CONCRETE:7,100)
RandomBlock(-6,4,5,CONCRETE:7,60,quark:iron_plate:1,20,STAINED_CLAY:12,15,STAINED_CLAY:15,5,AIR,7,IRON_BARS,12,CONCRETE:7,100)
RandomBlock(-6,4,6,CONCRETE:7,60,quark:iron_plate:1,20,STAINED_CLAY:12,15,STAINED_CLAY:15,5,AIR,7,IRON_BARS,12,CONCRETE:7,100)
RandomBlock(-6,4,7,CONCRETE:7,60,quark:iron_plate:1,20,STAINED_CLAY:12,15,STAINED_CLAY:15,5,AIR,7,IRON_BARS,12,CONCRETE:7,100)
RandomBlock(-6,4,8,CONCRETE:7,60,quark:iron_plate:1,20,STAINED_CLAY:12,15,STAINED_CLAY:15,5,AIR,7,IRON_BARS,12,CONCRETE:7,100)
RandomBlock(-6,5,-7,CONCRETE:7,60,quark:iron_plate:1,20,STAINED_CLAY:12,15,STAINED_CLAY:15,5,AIR,7,IRON_BARS,12,CONCRETE:7,100)
RandomBlock(-6,5,-6,CONCRETE:7,60,quark:iron_plate:1,20,STAINED_CLAY:12,15,STAINED_CLAY:15,5,AIR,7,IRON_BARS,12,CONCRETE:7,100)
RandomBlock(-6,5,-5,CONCRETE:7,60,quark:iron_plate:1,20,STAINED_CLAY:12,15,STAINED_CLAY:15,5,AIR,7,IRON_BARS,12,CONCRETE:7,100)
RandomBlock(-6,5,-4,CONCRETE:7,60,quark:iron_plate:1,20,STAINED_CLAY:12,15,STAINED_CLAY:15,5,AIR,7,IRON_BARS,12,CONCRETE:7,100)
RandomBlock(-6,5,-3,CONCRETE:7,60,quark:iron_plate:1,20,STAINED_CLAY:12,15,STAINED_CLAY:15,5,AIR,7,IRON_BARS,12,CONCRETE:7,100)
RandomBlock(-6,5,-2,CONCRETE:7,60,quark:iron_plate:1,20,STAINED_CLAY:12,15,STAINED_CLAY:15,5,AIR,7,IRON_BARS,12,CONCRETE:7,100)
RandomBlock(-6,5,-1,CONCRETE:7,60,quark:iron_plate:1,20,STAINED_CLAY:12,15,STAINED_CLAY:15,5,AIR,7,IRON_BARS,12,CONCRETE:7,100)
RandomBlock(-6,5,0,CONCRETE:7,60,quark:iron_plate:1,20,STAINED_CLAY:12,15,STAINED_CLAY:15,5,AIR,7,IRON_BARS,12,CONCRETE:7,100)
RandomBlock(-6,5,1,CONCRETE:7,60,quark:iron_plate:1,20,STAINED_CLAY:12,15,STAINED_CLAY:15,5,AIR,7,IRON_BARS,12,CONCRETE:7,100)
RandomBlock(-6,5,2,CONCRETE:7,60,quark:iron_plate:1,20,STAINED_CLAY:12,15,STAINED_CLAY:15,5,AIR,7,IRON_BARS,12,CONCRETE:7,100)
RandomBlock(-6,5,3,CONCRETE:7,60,quark:iron_plate:1,20,STAINED_CLAY:12,15,STAINED_CLAY:15,5,AIR,7,IRON_BARS,12,CONCRETE:7,100)
RandomBlock(-6,5,4,CONCRETE:7,60,quark:iron_plate:1,20,STAINED_CLAY:12,15,STAINED_CLAY:15,5,AIR,7,IRON_BARS,12,CONCRETE:7,100)
RandomBlock(-6,5,5,CONCRETE:7,60,quark:iron_plate:1,20,STAINED_CLAY:12,15,STAINED_CLAY:15,5,AIR,7,IRON_BARS,12,CONCRETE:7,100)
RandomBlock(-6,5,6,CONCRETE:7,60,quark:iron_plate:1,20,STAINED_CLAY:12,15,STAINED_CLAY:15,5,AIR,7,IRON_BARS,12,CONCRETE:7,100)
RandomBlock(-6,5,7,CONCRETE:7,60,quark:iron_plate:1,20,STAINED_CLAY:12,15,STAINED_CLAY:15,5,AIR,7,IRON_BARS,12,CONCRETE:7,100)
RandomBlock(-6,5,8,CONCRETE:7,60,quark:iron_plate:1,20,STAINED_CLAY:12,15,STAINED_CLAY:15,5,AIR,7,IRON_BARS,12,CONCRETE:7,100)
RandomBlock(-6,6,-7,CONCRETE:7,60,quark:iron_plate:1,20,STAINED_CLAY:12,15,STAINED_CLAY:15,5,AIR,7,IRON_BARS,12,CONCRETE:7,100)
RandomBlock(-6,6,-6,CONCRETE:7,60,quark:iron_plate:1,20,STAINED_CLAY:12,15,STAINED_CLAY:15,5,AIR,7,IRON_BARS,12,CONCRETE:7,100)
RandomBlock(-6,6,-5,CONCRETE:7,60,quark:iron_plate:1,20,STAINED_CLAY:12,15,STAINED_CLAY:15,5,AIR,7,IRON_BARS,12,CONCRETE:7,100)
RandomBlock(-6,6,-4,CONCRETE:7,60,quark:iron_plate:1,20,STAINED_CLAY:12,15,STAINED_CLAY:15,5,AIR,7,IRON_BARS,12,CONCRETE:7,100)
RandomBlock(-6,6,-3,CONCRETE:7,60,quark:iron_plate:1,20,STAINED_CLAY:12,15,STAINED_CLAY:15,5,AIR,7,IRON_BARS,12,CONCRETE:7,100)
RandomBlock(-6,6,-2,CONCRETE:7,60,quark:iron_plate:1,20,STAINED_CLAY:12,15,STAINED_CLAY:15,5,AIR,7,IRON_BARS,12,CONCRETE:7,100)
RandomBlock(-6,6,-1,CONCRETE:7,60,quark:iron_plate:1,20,STAINED_CLAY:12,15,STAINED_CLAY:15,5,AIR,7,IRON_BARS,12,CONCRETE:7,100)
RandomBlock(-6,6,0,CONCRETE:7,60,quark:iron_plate:1,20,STAINED_CLAY:12,15,STAINED_CLAY:15,5,AIR,7,IRON_BARS,12,CONCRETE:7,100)
RandomBlock(-6,6,1,CONCRETE:7,60,quark:iron_plate:1,20,STAINED_CLAY:12,15,STAINED_CLAY:15,5,AIR,7,IRON_BARS,12,CONCRETE:7,100)
RandomBlock(-6,6,2,CONCRETE:7,60,quark:iron_plate:1,20,STAINED_CLAY:12,15,STAINED_CLAY:15,5,AIR,7,IRON_BARS,12,CONCRETE:7,100)
RandomBlock(-6,6,3,CONCRETE:7,60,quark:iron_plate:1,20,STAINED_CLAY:12,15,STAINED_CLAY:15,5,AIR,7,IRON_BARS,12,CONCRETE:7,100)
RandomBlock(-6,6,4,CONCRETE:7,60,quark:iron_plate:1,20,STAINED_CLAY:12,15,STAINED_CLAY:15,5,AIR,7,IRON_BARS,12,CONCRETE:7,100)
RandomBlock(-6,6,5,CONCRETE:7,60,quark:iron_plate:1,20,STAINED_CLAY:12,15,STAINED_CLAY:15,5,AIR,7,IRON_BARS,12,CONCRETE:7,100)
RandomBlock(-6,6,6,CONCRETE:7,60,quark:iron_plate:1,20,STAINED_CLAY:12,15,STAINED_CLAY:15,5,AIR,7,IRON_BARS,12,CONCRETE:7,100)
RandomBlock(-6,6,7,CONCRETE:7,60,quark:iron_plate:1,20,STAINED_CLAY:12,15,STAINED_CLAY:15,5,AIR,7,IRON_BARS,12,CONCRETE:7,100)
RandomBlock(-6,6,8,CONCRETE:7,60,quark:iron_plate:1,20,STAINED_CLAY:12,15,STAINED_CLAY:15,5,AIR,7,IRON_BARS,12,CONCRETE:7,100)
RandomBlock(-6,7,-7,CONCRETE:7,60,quark:iron_plate:1,20,STAINED_CLAY:12,15,STAINED_CLAY:15,5,AIR,7,IRON_BARS,12,CONCRETE:7,100)
RandomBlock(-6,7,-6,CONCRETE:7,60,quark:iron_plate:1,20,STAINED_CLAY:12,15,STAINED_CLAY:15,5,AIR,7,IRON_BARS,12,CONCRETE:7,100)
RandomBlock(-6,7,-5,CONCRETE:7,60,quark:iron_plate:1,20,STAINED_CLAY:12,15,STAINED_CLAY:15,5,AIR,7,IRON_BARS,12,CONCRETE:7,100)
RandomBlock(-6,7,-4,CONCRETE:7,60,quark:iron_plate:1,20,STAINED_CLAY:12,15,STAINED_CLAY:15,5,AIR,7,IRON_BARS,12,CONCRETE:7,100)
RandomBlock(-6,7,-3,CONCRETE:7,60,quark:iron_plate:1,20,STAINED_CLAY:12,15,STAINED_CLAY:15,5,AIR,7,IRON_BARS,12,CONCRETE:7,100)
RandomBlock(-6,7,-2,CONCRETE:7,60,quark:iron_plate:1,20,STAINED_CLAY:12,15,STAINED_CLAY:15,5,AIR,7,IRON_BARS,12,CONCRETE:7,100)
RandomBlock(-6,7,-1,CONCRETE:7,60,quark:iron_plate:1,20,STAINED_CLAY:12,15,STAINED_CLAY:15,5,AIR,7,IRON_BARS,12,CONCRETE:7,100)
RandomBlock(-6,7,0,CONCRETE:7,60,quark:iron_plate:1,20,STAINED_CLAY:12,15,STAINED_CLAY:15,5,AIR,7,IRON_BARS,12,CONCRETE:7,100)
RandomBlock(-6,7,1,CONCRETE:7,60,quark:iron_plate:1,20,STAINED_CLAY:12,15,STAINED_CLAY:15,5,AIR,7,IRON_BARS,12,CONCRETE:7,100)
RandomBlock(-6,7,2,CONCRETE:7,60,quark:iron_plate:1,20,STAINED_CLAY:12,15,STAINED_CLAY:15,5,AIR,7,IRON_BARS,12,CONCRETE:7,100)
RandomBlock(-6,7,3,CONCRETE:7,60,quark:iron_plate:1,20,STAINED_CLAY:12,15,STAINED_CLAY:15,5,AIR,7,IRON_BARS,12,CONCRETE:7,100)
RandomBlock(-6,7,4,CONCRETE:7,60,quark:iron_plate:1,20,STAINED_CLAY:12,15,STAINED_CLAY:15,5,AIR,7,IRON_BARS,12,CONCRETE:7,100)
RandomBlock(-6,7,5,CONCRETE:7,60,quark:iron_plate:1,20,STAINED_CLAY:12,15,STAINED_CLAY:15,5,AIR,7,IRON_BARS,12,CONCRETE:7,100)
RandomBlock(-6,7,6,CONCRETE:7,60,quark:iron_plate:1,20,STAINED_CLAY:12,15,STAINED_CLAY:15,5,AIR,7,IRON_BARS,12,CONCRETE:7,100)
RandomBlock(-6,7,7,CONCRETE:7,60,quark:iron_plate:1,20,STAINED_CLAY:12,15,STAINED_CLAY:15,5,AIR,7,IRON_BARS,12,CONCRETE:7,100)
RandomBlock(-6,7,8,CONCRETE:7,60,quark:iron_plate:1,20,STAINED_CLAY:12,15,STAINED_CLAY:15,5,AIR,7,IRON_BARS,12,CONCRETE:7,100)
RandomBlock(-6,8,-7,CONCRETE:7,60,quark:iron_plate:1,20,STAINED_CLAY:12,15,STAINED_CLAY:15,5,AIR,7,IRON_BARS,12,CONCRETE:7,100)
RandomBlock(-6,8,-6,CONCRETE:7,60,quark:iron_plate:1,20,STAINED_CLAY:12,15,STAINED_CLAY:15,5,AIR,7,IRON_BARS,12,CONCRETE:7,100)
RandomBlock(-6,8,-5,CONCRETE:7,60,quark:iron_plate:1,20,STAINED_CLAY:12,15,STAINED_CLAY:15,5,AIR,7,IRON_BARS,12,CONCRETE:7,100)
RandomBlock(-6,8,-4,CONCRETE:7,60,quark:iron_plate:1,20,STAINED_CLAY:12,15,STAINED_CLAY:15,5,AIR,7,IRON_BARS,12,CONCRETE:7,100)
RandomBlock(-6,8,-3,CONCRETE:7,60,quark:iron_plate:1,20,STAINED_CLAY:12,15,STAINED_CLAY:15,5,AIR,7,IRON_BARS,12,CONCRETE:7,100)
RandomBlock(-6,8,-2,CONCRETE:7,60,quark:iron_plate:1,20,STAINED_CLAY:12,15,STAINED_CLAY:15,5,AIR,7,IRON_BARS,12,CONCRETE:7,100)
RandomBlock(-6,8,-1,CONCRETE:7,60,quark:iron_plate:1,20,STAINED_CLAY:12,15,STAINED_CLAY:15,5,AIR,7,IRON_BARS,12,CONCRETE:7,100)
RandomBlock(-6,8,0,CONCRETE:7,60,quark:iron_plate:1,20,STAINED_CLAY:12,15,STAINED_CLAY:15,5,AIR,7,IRON_BARS,12,CONCRETE:7,100)
RandomBlock(-6,8,1,CONCRETE:7,60,quark:iron_plate:1,20,STAINED_CLAY:12,15,STAINED_CLAY:15,5,AIR,7,IRON_BARS,12,CONCRETE:7,100)
RandomBlock(-6,8,2,CONCRETE:7,60,quark:iron_plate:1,20,STAINED_CLAY:12,15,STAINED_CLAY:15,5,AIR,7,IRON_BARS,12,CONCRETE:7,100)
RandomBlock(-6,8,3,CONCRETE:7,60,quark:iron_plate:1,20,STAINED_CLAY:12,15,STAINED_CLAY:15,5,AIR,7,IRON_BARS,12,CONCRETE:7,100)
RandomBlock(-6,8,4,CONCRETE:7,60,quark:iron_plate:1,20,STAINED_CLAY:12,15,STAINED_CLAY:15,5,AIR,7,IRON_BARS,12,CONCRETE:7,100)
RandomBlock(-6,8,5,CONCRETE:7,60,quark:iron_plate:1,20,STAINED_CLAY:12,15,STAINED_CLAY:15,5,AIR,7,IRON_BARS,12,CONCRETE:7,100)
RandomBlock(-6,8,6,CONCRETE:7,60,quark:iron_plate:1,20,STAINED_CLAY:12,15,STAINED_CLAY:15,5,AIR,7,IRON_BARS,12,CONCRETE:7,100)
RandomBlock(-6,8,7,CONCRETE:7,60,quark:iron_plate:1,20,STAINED_CLAY:12,15,STAINED_CLAY:15,5,AIR,7,IRON_BARS,12,CONCRETE:7,100)
RandomBlock(-6,8,8,CONCRETE:7,60,quark:iron_plate:1,20,STAINED_CLAY:12,15,STAINED_CLAY:15,5,AIR,7,IRON_BARS,12,CONCRETE:7,100)
Block(-6,9,-7,CONCRETE:8)
Block(-6,9,-6,CONCRETE:8)
Block(-6,9,-5,CONCRETE:8)
Block(-6,9,-4,CONCRETE:8)
Block(-6,9,-3,CONCRETE:8)
Block(-6,9,-2,CONCRETE:8)
Block(-6,9,-1,CONCRETE:8)
Block(-6,9,0,CONCRETE:8)
Block(-6,9,1,CONCRETE:8)
Block(-6,9,2,CONCRETE:8)
Block(-6,9,3,CONCRETE:8)
Block(-6,9,4,CONCRETE:8)
Block(-6,9,5,CONCRETE:8)
Block(-6,9,6,CONCRETE:8)
Block(-6,9,7,CONCRETE:8)
Block(-6,9,8,CONCRETE:8)
Block(-6,10,-7,STAINED_GLASS:15)
Block(-6,10,-6,STAINED_GLASS:15)
Block(-6,10,-5,STAINED_GLASS:15)
Block(-6,10,-4,STAINED_GLASS:15)
Block(-6,10,-3,STAINED_GLASS:15)
Block(-6,10,-2,STAINED_GLASS:15)
Block(-6,10,-1,STAINED_GLASS:15)
Block(-6,10,0,STAINED_GLASS:15)
Block(-6,10,1,STAINED_GLASS:15)
Block(-6,10,2,STAINED_GLASS:15)
Block(-6,10,3,STAINED_GLASS:15)
Block(-6,10,4,STAINED_GLASS:15)
Block(-6,10,5,STAINED_GLASS:15)
Block(-6,10,6,STAINED_GLASS:15)
Block(-6,10,7,STAINED_GLASS:15)
Block(-6,10,8,STAINED_GLASS:15)
Block(-6,11,-7,STATIONARY_WATER:0)
Block(-6,11,-6,STATIONARY_WATER:0)
Block(-6,11,-5,STATIONARY_WATER:0)
Block(-6,11,-4,STATIONARY_WATER:0)
Block(-6,11,-3,STATIONARY_WATER:0)
Block(-6,11,-2,STATIONARY_WATER:0)
Block(-6,11,-1,STATIONARY_WATER:0)
Block(-6,11,0,STATIONARY_WATER:0)
Block(-6,11,1,STATIONARY_WATER:0)
Block(-6,11,2,STATIONARY_WATER:0)
Block(-6,11,3,STATIONARY_WATER:0)
Block(-6,11,4,STATIONARY_WATER:0)
Block(-6,11,5,STATIONARY_WATER:0)
Block(-6,11,6,STATIONARY_WATER:0)
Block(-6,11,7,STATIONARY_WATER:0)
Block(-6,11,8,STATIONARY_WATER:0)
Block(-6,12,-7,STATIONARY_WATER:0)
Block(-6,12,-6,STATIONARY_WATER:0)
Block(-6,12,-5,STATIONARY_WATER:0)
Block(-6,12,-4,STATIONARY_WATER:0)
Block(-6,12,-3,STATIONARY_WATER:0)
Block(-6,12,-2,STATIONARY_WATER:0)
Block(-6,12,-1,STATIONARY_WATER:0)
Block(-6,12,0,STATIONARY_WATER:0)
Block(-6,12,1,STATIONARY_WATER:0)
Block(-6,12,2,STATIONARY_WATER:0)
Block(-6,12,3,STATIONARY_WATER:0)
Block(-6,12,4,STATIONARY_WATER:0)
Block(-6,12,5,STATIONARY_WATER:0)
Block(-6,12,6,STATIONARY_WATER:0)
Block(-6,12,7,STATIONARY_WATER:0)
Block(-6,12,8,STATIONARY_WATER:0)
Block(-6,13,-7,AIR:0)
Block(-6,13,-6,AIR:0)
Block(-6,13,-5,AIR:0)
Block(-6,13,-4,AIR:0)
Block(-6,13,-3,AIR:0)
Block(-6,13,-2,AIR:0)
Block(-6,13,-1,AIR:0)
Block(-6,13,0,AIR:0)
Block(-6,13,1,AIR:0)
Block(-6,13,2,AIR:0)
Block(-6,13,3,AIR:0)
Block(-6,13,4,AIR:0)
Block(-6,13,5,AIR:0)
Block(-6,13,6,AIR:0)
Block(-6,13,7,AIR:0)
Block(-6,13,8,AIR:0)
Block(-6,14,-7,AIR:0)
Block(-6,14,-6,AIR:0)
Block(-6,14,-5,AIR:0)
Block(-6,14,-4,AIR:0)
Block(-6,14,-3,AIR:0)
Block(-6,14,-2,AIR:0)
Block(-6,14,-1,AIR:0)
Block(-6,14,0,AIR:0)
Block(-6,14,1,AIR:0)
Block(-6,14,2,AIR:0)
Block(-6,14,3,AIR:0)
Block(-6,14,4,AIR:0)
Block(-6,14,5,AIR:0)
Block(-6,14,6,AIR:0)
Block(-6,14,7,AIR:0)
Block(-6,14,8,AIR:0)
Block(-6,15,-7,AIR:0)
Block(-6,15,-6,AIR:0)
Block(-6,15,-5,AIR:0)
Block(-6,15,-4,AIR:0)
Block(-6,15,-3,AIR:0)
Block(-6,15,-2,AIR:0)
Block(-6,15,-1,AIR:0)
Block(-6,15,0,AIR:0)
Block(-6,15,1,AIR:0)
Block(-6,15,2,AIR:0)
Block(-6,15,3,AIR:0)
Block(-6,15,4,AIR:0)
Block(-6,15,5,AIR:0)
Block(-6,15,6,AIR:0)
Block(-6,15,7,AIR:0)
Block(-6,15,8,AIR:0)
Block(-6,16,-7,AIR:0)
Block(-6,16,-6,AIR:0)
Block(-6,16,-5,AIR:0)
Block(-6,16,-4,AIR:0)
Block(-6,16,-3,AIR:0)
Block(-6,16,-2,AIR:0)
Block(-6,16,-1,AIR:0)
Block(-6,16,0,AIR:0)
Block(-6,16,1,AIR:0)
Block(-6,16,2,AIR:0)
Block(-6,16,3,AIR:0)
Block(-6,16,4,AIR:0)
Block(-6,16,5,AIR:0)
Block(-6,16,6,AIR:0)
Block(-6,16,7,AIR:0)
Block(-6,16,8,AIR:0)
Block(-6,17,-7,AIR:0)
Block(-6,17,-6,AIR:0)
Block(-6,17,-5,AIR:0)
Block(-6,17,-4,AIR:0)
Block(-6,17,-3,AIR:0)
Block(-6,17,-2,AIR:0)
Block(-6,17,-1,STAINED_GLASS:15)
Block(-6,17,0,CONCRETE:8)
Block(-6,17,1,CONCRETE:8)
Block(-6,17,2,STAINED_GLASS:15)
Block(-6,17,3,AIR:0)
Block(-6,17,4,AIR:0)
Block(-6,17,5,AIR:0)
Block(-6,17,6,AIR:0)
Block(-6,17,7,AIR:0)
Block(-6,17,8,AIR:0)
Block(-6,18,-1,STAINED_GLASS_PANE:15)
Block(-6,18,2,STAINED_GLASS_PANE:15)
RandomBlock(-5,0,-7,CONCRETE:7,60,quark:iron_plate:1,20,STAINED_CLAY:12,15,STAINED_CLAY:15,5,AIR,7,IRON_BARS,12,CONCRETE:7,100)
RandomBlock(-5,0,-6,CONCRETE:7,60,quark:iron_plate:1,20,STAINED_CLAY:12,15,STAINED_CLAY:15,5,AIR,7,IRON_BARS,12,CONCRETE:7,100)
RandomBlock(-5,0,-5,CONCRETE:7,60,quark:iron_plate:1,20,STAINED_CLAY:12,15,STAINED_CLAY:15,5,AIR,7,IRON_BARS,12,CONCRETE:7,100)
RandomBlock(-5,0,-4,CONCRETE:7,60,quark:iron_plate:1,20,STAINED_CLAY:12,15,STAINED_CLAY:15,5,AIR,7,IRON_BARS,12,CONCRETE:7,100)
RandomBlock(-5,0,-3,CONCRETE:7,60,quark:iron_plate:1,20,STAINED_CLAY:12,15,STAINED_CLAY:15,5,AIR,7,IRON_BARS,12,CONCRETE:7,100)
RandomBlock(-5,0,-2,CONCRETE:7,60,quark:iron_plate:1,20,STAINED_CLAY:12,15,STAINED_CLAY:15,5,AIR,7,IRON_BARS,12,CONCRETE:7,100)
RandomBlock(-5,0,-1,CONCRETE:7,60,quark:iron_plate:1,20,STAINED_CLAY:12,15,STAINED_CLAY:15,5,AIR,7,IRON_BARS,12,CONCRETE:7,100)
RandomBlock(-5,0,0,CONCRETE:7,60,quark:iron_plate:1,20,STAINED_CLAY:12,15,STAINED_CLAY:15,5,AIR,7,IRON_BARS,12,CONCRETE:7,100)
RandomBlock(-5,0,1,CONCRETE:7,60,quark:iron_plate:1,20,STAINED_CLAY:12,15,STAINED_CLAY:15,5,AIR,7,IRON_BARS,12,CONCRETE:7,100)
RandomBlock(-5,0,2,CONCRETE:7,60,quark:iron_plate:1,20,STAINED_CLAY:12,15,STAINED_CLAY:15,5,AIR,7,IRON_BARS,12,CONCRETE:7,100)
RandomBlock(-5,0,3,CONCRETE:7,60,quark:iron_plate:1,20,STAINED_CLAY:12,15,STAINED_CLAY:15,5,AIR,7,IRON_BARS,12,CONCRETE:7,100)
RandomBlock(-5,0,4,CONCRETE:7,60,quark:iron_plate:1,20,STAINED_CLAY:12,15,STAINED_CLAY:15,5,AIR,7,IRON_BARS,12,CONCRETE:7,100)
RandomBlock(-5,0,5,CONCRETE:7,60,quark:iron_plate:1,20,STAINED_CLAY:12,15,STAINED_CLAY:15,5,AIR,7,IRON_BARS,12,CONCRETE:7,100)
RandomBlock(-5,0,6,CONCRETE:7,60,quark:iron_plate:1,20,STAINED_CLAY:12,15,STAINED_CLAY:15,5,AIR,7,IRON_BARS,12,CONCRETE:7,100)
RandomBlock(-5,0,7,CONCRETE:7,60,quark:iron_plate:1,20,STAINED_CLAY:12,15,STAINED_CLAY:15,5,AIR,7,IRON_BARS,12,CONCRETE:7,100)
RandomBlock(-5,0,8,CONCRETE:7,60,quark:iron_plate:1,20,STAINED_CLAY:12,15,STAINED_CLAY:15,5,AIR,7,IRON_BARS,12,CONCRETE:7,100)
RandomBlock(-5,1,-7,CONCRETE:7,60,quark:iron_plate:1,20,STAINED_CLAY:12,15,STAINED_CLAY:15,5,AIR,7,IRON_BARS,12,CONCRETE:7,100)
RandomBlock(-5,1,-6,CONCRETE:7,60,quark:iron_plate:1,20,STAINED_CLAY:12,15,STAINED_CLAY:15,5,AIR,7,IRON_BARS,12,CONCRETE:7,100)
RandomBlock(-5,1,-5,CONCRETE:7,60,quark:iron_plate:1,20,STAINED_CLAY:12,15,STAINED_CLAY:15,5,AIR,7,IRON_BARS,12,CONCRETE:7,100)
RandomBlock(-5,1,-4,CONCRETE:7,60,quark:iron_plate:1,20,STAINED_CLAY:12,15,STAINED_CLAY:15,5,AIR,7,IRON_BARS,12,CONCRETE:7,100)
RandomBlock(-5,1,-3,CONCRETE:7,60,quark:iron_plate:1,20,STAINED_CLAY:12,15,STAINED_CLAY:15,5,AIR,7,IRON_BARS,12,CONCRETE:7,100)
RandomBlock(-5,1,-2,CONCRETE:7,60,quark:iron_plate:1,20,STAINED_CLAY:12,15,STAINED_CLAY:15,5,AIR,7,IRON_BARS,12,CONCRETE:7,100)
RandomBlock(-5,1,-1,CONCRETE:7,60,quark:iron_plate:1,20,STAINED_CLAY:12,15,STAINED_CLAY:15,5,AIR,7,IRON_BARS,12,CONCRETE:7,100)
RandomBlock(-5,1,0,CONCRETE:7,60,quark:iron_plate:1,20,STAINED_CLAY:12,15,STAINED_CLAY:15,5,AIR,7,IRON_BARS,12,CONCRETE:7,100)
RandomBlock(-5,1,1,CONCRETE:7,60,quark:iron_plate:1,20,STAINED_CLAY:12,15,STAINED_CLAY:15,5,AIR,7,IRON_BARS,12,CONCRETE:7,100)
RandomBlock(-5,1,2,CONCRETE:7,60,quark:iron_plate:1,20,STAINED_CLAY:12,15,STAINED_CLAY:15,5,AIR,7,IRON_BARS,12,CONCRETE:7,100)
RandomBlock(-5,1,3,CONCRETE:7,60,quark:iron_plate:1,20,STAINED_CLAY:12,15,STAINED_CLAY:15,5,AIR,7,IRON_BARS,12,CONCRETE:7,100)
RandomBlock(-5,1,4,CONCRETE:7,60,quark:iron_plate:1,20,STAINED_CLAY:12,15,STAINED_CLAY:15,5,AIR,7,IRON_BARS,12,CONCRETE:7,100)
RandomBlock(-5,1,5,CONCRETE:7,60,quark:iron_plate:1,20,STAINED_CLAY:12,15,STAINED_CLAY:15,5,AIR,7,IRON_BARS,12,CONCRETE:7,100)
RandomBlock(-5,1,6,CONCRETE:7,60,quark:iron_plate:1,20,STAINED_CLAY:12,15,STAINED_CLAY:15,5,AIR,7,IRON_BARS,12,CONCRETE:7,100)
RandomBlock(-5,1,7,CONCRETE:7,60,quark:iron_plate:1,20,STAINED_CLAY:12,15,STAINED_CLAY:15,5,AIR,7,IRON_BARS,12,CONCRETE:7,100)
RandomBlock(-5,1,8,CONCRETE:7,60,quark:iron_plate:1,20,STAINED_CLAY:12,15,STAINED_CLAY:15,5,AIR,7,IRON_BARS,12,CONCRETE:7,100)
RandomBlock(-5,2,-7,CONCRETE:7,60,quark:iron_plate:1,20,STAINED_CLAY:12,15,STAINED_CLAY:15,5,AIR,7,IRON_BARS,12,CONCRETE:7,100)
RandomBlock(-5,2,-6,CONCRETE:7,60,quark:iron_plate:1,20,STAINED_CLAY:12,15,STAINED_CLAY:15,5,AIR,7,IRON_BARS,12,CONCRETE:7,100)
RandomBlock(-5,2,-5,CONCRETE:7,60,quark:iron_plate:1,20,STAINED_CLAY:12,15,STAINED_CLAY:15,5,AIR,7,IRON_BARS,12,CONCRETE:7,100)
RandomBlock(-5,2,-4,CONCRETE:7,60,quark:iron_plate:1,20,STAINED_CLAY:12,15,STAINED_CLAY:15,5,AIR,7,IRON_BARS,12,CONCRETE:7,100)
RandomBlock(-5,2,-3,CONCRETE:7,60,quark:iron_plate:1,20,STAINED_CLAY:12,15,STAINED_CLAY:15,5,AIR,7,IRON_BARS,12,CONCRETE:7,100)
RandomBlock(-5,2,-2,CONCRETE:7,60,quark:iron_plate:1,20,STAINED_CLAY:12,15,STAINED_CLAY:15,5,AIR,7,IRON_BARS,12,CONCRETE:7,100)
RandomBlock(-5,2,-1,CONCRETE:7,60,quark:iron_plate:1,20,STAINED_CLAY:12,15,STAINED_CLAY:15,5,AIR,7,IRON_BARS,12,CONCRETE:7,100)
RandomBlock(-5,2,0,CONCRETE:7,60,quark:iron_plate:1,20,STAINED_CLAY:12,15,STAINED_CLAY:15,5,AIR,7,IRON_BARS,12,CONCRETE:7,100)
RandomBlock(-5,2,1,CONCRETE:7,60,quark:iron_plate:1,20,STAINED_CLAY:12,15,STAINED_CLAY:15,5,AIR,7,IRON_BARS,12,CONCRETE:7,100)
RandomBlock(-5,2,2,CONCRETE:7,60,quark:iron_plate:1,20,STAINED_CLAY:12,15,STAINED_CLAY:15,5,AIR,7,IRON_BARS,12,CONCRETE:7,100)
RandomBlock(-5,2,3,CONCRETE:7,60,quark:iron_plate:1,20,STAINED_CLAY:12,15,STAINED_CLAY:15,5,AIR,7,IRON_BARS,12,CONCRETE:7,100)
RandomBlock(-5,2,4,CONCRETE:7,60,quark:iron_plate:1,20,STAINED_CLAY:12,15,STAINED_CLAY:15,5,AIR,7,IRON_BARS,12,CONCRETE:7,100)
RandomBlock(-5,2,5,CONCRETE:7,60,quark:iron_plate:1,20,STAINED_CLAY:12,15,STAINED_CLAY:15,5,AIR,7,IRON_BARS,12,CONCRETE:7,100)
RandomBlock(-5,2,6,CONCRETE:7,60,quark:iron_plate:1,20,STAINED_CLAY:12,15,STAINED_CLAY:15,5,AIR,7,IRON_BARS,12,CONCRETE:7,100)
RandomBlock(-5,2,7,CONCRETE:7,60,quark:iron_plate:1,20,STAINED_CLAY:12,15,STAINED_CLAY:15,5,AIR,7,IRON_BARS,12,CONCRETE:7,100)
RandomBlock(-5,2,8,CONCRETE:7,60,quark:iron_plate:1,20,STAINED_CLAY:12,15,STAINED_CLAY:15,5,AIR,7,IRON_BARS,12,CONCRETE:7,100)
RandomBlock(-5,3,-7,CONCRETE:7,60,quark:iron_plate:1,20,STAINED_CLAY:12,15,STAINED_CLAY:15,5,AIR,7,IRON_BARS,12,CONCRETE:7,100)
RandomBlock(-5,3,-6,CONCRETE:7,60,quark:iron_plate:1,20,STAINED_CLAY:12,15,STAINED_CLAY:15,5,AIR,7,IRON_BARS,12,CONCRETE:7,100)
RandomBlock(-5,3,-5,CONCRETE:7,60,quark:iron_plate:1,20,STAINED_CLAY:12,15,STAINED_CLAY:15,5,AIR,7,IRON_BARS,12,CONCRETE:7,100)
RandomBlock(-5,3,-4,CONCRETE:7,60,quark:iron_plate:1,20,STAINED_CLAY:12,15,STAINED_CLAY:15,5,AIR,7,IRON_BARS,12,CONCRETE:7,100)
RandomBlock(-5,3,-3,CONCRETE:7,60,quark:iron_plate:1,20,STAINED_CLAY:12,15,STAINED_CLAY:15,5,AIR,7,IRON_BARS,12,CONCRETE:7,100)
RandomBlock(-5,3,-2,CONCRETE:7,60,quark:iron_plate:1,20,STAINED_CLAY:12,15,STAINED_CLAY:15,5,AIR,7,IRON_BARS,12,CONCRETE:7,100)
RandomBlock(-5,3,-1,CONCRETE:7,60,quark:iron_plate:1,20,STAINED_CLAY:12,15,STAINED_CLAY:15,5,AIR,7,IRON_BARS,12,CONCRETE:7,100)
RandomBlock(-5,3,0,CONCRETE:7,60,quark:iron_plate:1,20,STAINED_CLAY:12,15,STAINED_CLAY:15,5,AIR,7,IRON_BARS,12,CONCRETE:7,100)
RandomBlock(-5,3,1,CONCRETE:7,60,quark:iron_plate:1,20,STAINED_CLAY:12,15,STAINED_CLAY:15,5,AIR,7,IRON_BARS,12,CONCRETE:7,100)
RandomBlock(-5,3,2,CONCRETE:7,60,quark:iron_plate:1,20,STAINED_CLAY:12,15,STAINED_CLAY:15,5,AIR,7,IRON_BARS,12,CONCRETE:7,100)
RandomBlock(-5,3,3,CONCRETE:7,60,quark:iron_plate:1,20,STAINED_CLAY:12,15,STAINED_CLAY:15,5,AIR,7,IRON_BARS,12,CONCRETE:7,100)
RandomBlock(-5,3,4,CONCRETE:7,60,quark:iron_plate:1,20,STAINED_CLAY:12,15,STAINED_CLAY:15,5,AIR,7,IRON_BARS,12,CONCRETE:7,100)
RandomBlock(-5,3,5,CONCRETE:7,60,quark:iron_plate:1,20,STAINED_CLAY:12,15,STAINED_CLAY:15,5,AIR,7,IRON_BARS,12,CONCRETE:7,100)
RandomBlock(-5,3,6,CONCRETE:7,60,quark:iron_plate:1,20,STAINED_CLAY:12,15,STAINED_CLAY:15,5,AIR,7,IRON_BARS,12,CONCRETE:7,100)
Block(-5,3,7,SMOOTH_STAIRS:1)
Block(-5,3,8,SMOOTH_STAIRS:1)
RandomBlock(-5,4,-7,CONCRETE:7,60,quark:iron_plate:1,20,STAINED_CLAY:12,15,STAINED_CLAY:15,5,AIR,7,IRON_BARS,12,CONCRETE:7,100)
RandomBlock(-5,4,-6,CONCRETE:7,60,quark:iron_plate:1,20,STAINED_CLAY:12,15,STAINED_CLAY:15,5,AIR,7,IRON_BARS,12,CONCRETE:7,100)
RandomBlock(-5,4,-5,CONCRETE:7,60,quark:iron_plate:1,20,STAINED_CLAY:12,15,STAINED_CLAY:15,5,AIR,7,IRON_BARS,12,CONCRETE:7,100)
RandomBlock(-5,4,-4,CONCRETE:7,60,quark:iron_plate:1,20,STAINED_CLAY:12,15,STAINED_CLAY:15,5,AIR,7,IRON_BARS,12,CONCRETE:7,100)
RandomBlock(-5,4,-3,CONCRETE:7,60,quark:iron_plate:1,20,STAINED_CLAY:12,15,STAINED_CLAY:15,5,AIR,7,IRON_BARS,12,CONCRETE:7,100)
RandomBlock(-5,4,-2,CONCRETE:7,60,quark:iron_plate:1,20,STAINED_CLAY:12,15,STAINED_CLAY:15,5,AIR,7,IRON_BARS,12,CONCRETE:7,100)
RandomBlock(-5,4,-1,CONCRETE:7,60,quark:iron_plate:1,20,STAINED_CLAY:12,15,STAINED_CLAY:15,5,AIR,7,IRON_BARS,12,CONCRETE:7,100)
RandomBlock(-5,4,0,CONCRETE:7,60,quark:iron_plate:1,20,STAINED_CLAY:12,15,STAINED_CLAY:15,5,AIR,7,IRON_BARS,12,CONCRETE:7,100)
RandomBlock(-5,4,1,CONCRETE:7,60,quark:iron_plate:1,20,STAINED_CLAY:12,15,STAINED_CLAY:15,5,AIR,7,IRON_BARS,12,CONCRETE:7,100)
RandomBlock(-5,4,2,CONCRETE:7,60,quark:iron_plate:1,20,STAINED_CLAY:12,15,STAINED_CLAY:15,5,AIR,7,IRON_BARS,12,CONCRETE:7,100)
RandomBlock(-5,4,3,CONCRETE:7,60,quark:iron_plate:1,20,STAINED_CLAY:12,15,STAINED_CLAY:15,5,AIR,7,IRON_BARS,12,CONCRETE:7,100)
RandomBlock(-5,4,4,CONCRETE:7,60,quark:iron_plate:1,20,STAINED_CLAY:12,15,STAINED_CLAY:15,5,AIR,7,IRON_BARS,12,CONCRETE:7,100)
RandomBlock(-5,4,5,CONCRETE:7,60,quark:iron_plate:1,20,STAINED_CLAY:12,15,STAINED_CLAY:15,5,AIR,7,IRON_BARS,12,CONCRETE:7,100)
RandomBlock(-5,4,6,CONCRETE:7,60,quark:iron_plate:1,20,STAINED_CLAY:12,15,STAINED_CLAY:15,5,AIR,7,IRON_BARS,12,CONCRETE:7,100)
Block(-5,4,7,COBBLE_WALL:0)
Block(-5,4,8,COBBLE_WALL:0)
RandomBlock(-5,5,-7,CONCRETE:7,60,quark:iron_plate:1,20,STAINED_CLAY:12,15,STAINED_CLAY:15,5,AIR,7,IRON_BARS,12,CONCRETE:7,100)
RandomBlock(-5,5,-6,CONCRETE:7,60,quark:iron_plate:1,20,STAINED_CLAY:12,15,STAINED_CLAY:15,5,AIR,7,IRON_BARS,12,CONCRETE:7,100)
RandomBlock(-5,5,-5,CONCRETE:7,60,quark:iron_plate:1,20,STAINED_CLAY:12,15,STAINED_CLAY:15,5,AIR,7,IRON_BARS,12,CONCRETE:7,100)
RandomBlock(-5,5,-4,CONCRETE:7,60,quark:iron_plate:1,20,STAINED_CLAY:12,15,STAINED_CLAY:15,5,AIR,7,IRON_BARS,12,CONCRETE:7,100)
RandomBlock(-5,5,-3,CONCRETE:7,60,quark:iron_plate:1,20,STAINED_CLAY:12,15,STAINED_CLAY:15,5,AIR,7,IRON_BARS,12,CONCRETE:7,100)
RandomBlock(-5,5,-2,CONCRETE:7,60,quark:iron_plate:1,20,STAINED_CLAY:12,15,STAINED_CLAY:15,5,AIR,7,IRON_BARS,12,CONCRETE:7,100)
RandomBlock(-5,5,-1,CONCRETE:7,60,quark:iron_plate:1,20,STAINED_CLAY:12,15,STAINED_CLAY:15,5,AIR,7,IRON_BARS,12,CONCRETE:7,100)
RandomBlock(-5,5,0,CONCRETE:7,60,quark:iron_plate:1,20,STAINED_CLAY:12,15,STAINED_CLAY:15,5,AIR,7,IRON_BARS,12,CONCRETE:7,100)
RandomBlock(-5,5,1,CONCRETE:7,60,quark:iron_plate:1,20,STAINED_CLAY:12,15,STAINED_CLAY:15,5,AIR,7,IRON_BARS,12,CONCRETE:7,100)
RandomBlock(-5,5,2,CONCRETE:7,60,quark:iron_plate:1,20,STAINED_CLAY:12,15,STAINED_CLAY:15,5,AIR,7,IRON_BARS,12,CONCRETE:7,100)
RandomBlock(-5,5,3,CONCRETE:7,60,quark:iron_plate:1,20,STAINED_CLAY:12,15,STAINED_CLAY:15,5,AIR,7,IRON_BARS,12,CONCRETE:7,100)
RandomBlock(-5,5,4,CONCRETE:7,60,quark:iron_plate:1,20,STAINED_CLAY:12,15,STAINED_CLAY:15,5,AIR,7,IRON_BARS,12,CONCRETE:7,100)
