
#######################################################################
# +-----------------------------------------------------------------+ #
# |                            BO4 object                           | #
# +-----------------------------------------------------------------+ #
#######################################################################

Author: NLBlackEagle

Description: No description given

SettingsMode: WriteDisable


#######################################################################
# +-----------------------------------------------------------------+ #
# |                          Main settings                          | #
# +-----------------------------------------------------------------+ #
#######################################################################

Frequency: 0

SpawnHeight: highestBlock

UseCenterForHighestBlock: true

##############################
# Height Limits for the BO4. #
##############################

MinHeight: 0

MaxHeight: 255

InheritBO3: 

InheritBO3Rotation: NORTH

OverrideChildSettings: true

OverrideParentHeight: false

CanOverride: true

BranchFrequency: 0

BranchFrequencyGroup: 

MustBeBelowOther: false

MustBeInside: 

CannotBeInside: 

ReplacesBO3: L4-M-CrossC0R0, L4-M-CrossC0R1, L4-M-CrossC0R2, L4-M-CrossC0R3, L4-M-CrossC1R0, L4-M-CrossC1R1, L4-M-CrossC1R2, L4-M-CrossC1R3, L4-M-CrossC2R0, L4-M-CrossC2R1, L4-M-CrossC2R2, L4-M-CrossC2R3, L4-M-CrossC3R0, L4-M-CrossC3R1, L4-M-CrossC3R2, L4-M-CrossC3R3, L4-M-Straigth-START_01-C0R0, L4-M-Straigth-START_01-C0R1, L4-M-Straigth-START_01-C1R0, L4-M-Straigth-START_01-C1R1, L4-M-Straigth-START_01-C2R0, L4-M-Straigth-START_01-C2R1, L4-M-Straigth-START_01-C3R0, L4-M-Straigth-START_01-C3R1, L4-M-Straigth-3CC0R0, L4-M-Straigth-3CC0R1, L4-M-Straigth-3CC0R2, L4-M-Straigth-3CC1R0, L4-M-Straigth-3CC1R1, L4-M-Straigth-3CC1R2, L4-M-Straigth-3CC2R0, L4-M-Straigth-3CC2R1, L4-M-Straigth-3CC2R2, L4-M-Straigth-3CC3R0, L4-M-Straigth-3CC3R1, L4-M-Straigth-3CC3R2, L4-M-Cross, skyscraper_2x2_01, skyscraper_2x2_02, skyscraper_2x2_03, skyscraper_2x2_04, skyscraper_2x2_05, skyscraper_3x3_01, skyscraper_3x3_02, skyscraper_3x3_03, L3-M-Straigth-2CC0R0, L3-M-Straigth-2CC0R1, L3-M-Straigth-2CC1R0, L3-M-Straigth-2CC1R1, L3-M-Straigth-2CC2R0, L3-M-Straigth-2CC2R1, L3-M-Straigth-2CC3R0, L3-M-Straigth-2CC3R1, L3-M-Straigth-3CC0R0, L3-M-Straigth-3CC0R1, L3-M-Straigth-3CC0R2, L3-M-Straigth-3CC1R0, L3-M-Straigth-3CC1R1, L3-M-Straigth-3CC1R2, L3-M-Straigth-3CC2R0, L3-M-Straigth-3CC2R1, L3-M-Straigth-3CC2R2, L3-M-Straigth-3CC3R0, L3-M-Straigth-3CC3R1, L3-M-Straigth-3CC3R2L4-M-CrossC0R0, L4-M-CrossC0R1, L4-M-CrossC0R2, L4-M-CrossC0R3, L4-M-CrossC1R0, L4-M-CrossC1R1, L4-M-CrossC1R2, L4-M-CrossC1R3, L4-M-CrossC2R0, L4-M-CrossC2R1, L4-M-CrossC2R2, L4-M-CrossC2R3, L4-M-CrossC3R0, L4-M-CrossC3R1, L4-M-CrossC3R2, L4-M-CrossC3R3, L4-M-Straigth-START_01-C0R0, L4-M-Straigth-START_01-C0R1, L4-M-Straigth-START_01-C1R0, L4-M-Straigth-START_01-C1R1, L4-M-Straigth-START_01-C2R0, L4-M-Straigth-START_01-C2R1, L4-M-Straigth-START_01-C3R0, L4-M-Straigth-START_01-C3R1, L4-M-Straigth-3CC0R0, L4-M-Straigth-3CC0R1, L4-M-Straigth-3CC0R2, L4-M-Straigth-3CC1R0, L4-M-Straigth-3CC1R1, L4-M-Straigth-3CC1R2, L4-M-Straigth-3CC2R0, L4-M-Straigth-3CC2R1, L4-M-Straigth-3CC2R2, L4-M-Straigth-3CC3R0, L4-M-Straigth-3CC3R1, L4-M-Straigth-3CC3R2, L4-M-Cross, skyscraper_2x2_01, skyscraper_2x2_02, skyscraper_2x2_03, skyscraper_2x2_04, skyscraper_2x2_05, skyscraper_3x3_01, skyscraper_3x3_02, skyscraper_3x3_03

MustBeInsideWorldBorders: true
CanSpawnOnWater: true

SpawnOnWaterOnly: false

SpawnUnderWater: false

SpawnAtWaterLevel: false

HeightOffset: 0

RemoveAir: false

ReplaceAbove: 

ReplaceBelow: 

ReplaceWithBiomeBlocks: true

ReplaceWithSurfaceBlock: GRASS

ReplaceWithGroundBlock: DIRT

ReplaceWithStoneBlock: STONE

SmoothRadius: 0

SmoothHeightOffset: 0

SmoothStartTop: false

SmoothStartWood: false

SmoothingSurfaceBlock: 

SmoothingGroundBlock: 

BO3Group: 

IsSpawnPoint: false

DoReplaceBlocks: true


#######################################################################
# +-----------------------------------------------------------------+ #
# |                              Blocks                             | #
# +-----------------------------------------------------------------+ #
#######################################################################

RandomBlock(-8,0,-7,CONCRETE:7,60,quark:iron_plate:1,20,STAINED_CLAY:12,15,STAINED_CLAY:15,5,AIR,7,IRON_BARS,12,CONCRETE:7,100)
RandomBlock(-8,0,-6,CONCRETE:7,60,quark:iron_plate:1,20,STAINED_CLAY:12,15,STAINED_CLAY:15,5,AIR,7,IRON_BARS,12,CONCRETE:7,100)
RandomBlock(-8,0,-5,CONCRETE:7,60,quark:iron_plate:1,20,STAINED_CLAY:12,15,STAINED_CLAY:15,5,AIR,7,IRON_BARS,12,CONCRETE:7,100)
RandomBlock(-8,0,-4,CONCRETE:7,60,quark:iron_plate:1,20,STAINED_CLAY:12,15,STAINED_CLAY:15,5,AIR,7,IRON_BARS,12,CONCRETE:7,100)
RandomBlock(-8,0,-3,CONCRETE:7,60,quark:iron_plate:1,20,STAINED_CLAY:12,15,STAINED_CLAY:15,5,AIR,7,IRON_BARS,12,CONCRETE:7,100)
RandomBlock(-8,0,-2,CONCRETE:7,60,quark:iron_plate:1,20,STAINED_CLAY:12,15,STAINED_CLAY:15,5,AIR,7,IRON_BARS,12,CONCRETE:7,100)
RandomBlock(-8,0,-1,CONCRETE:7,60,quark:iron_plate:1,20,STAINED_CLAY:12,15,STAINED_CLAY:15,5,AIR,7,IRON_BARS,12,CONCRETE:7,100)
RandomBlock(-8,0,0,CONCRETE:7,60,quark:iron_plate:1,20,STAINED_CLAY:12,15,STAINED_CLAY:15,5,AIR,7,IRON_BARS,12,CONCRETE:7,100)
RandomBlock(-8,0,1,CONCRETE:7,60,quark:iron_plate:1,20,STAINED_CLAY:12,15,STAINED_CLAY:15,5,AIR,7,IRON_BARS,12,CONCRETE:7,100)
RandomBlock(-8,0,2,CONCRETE:7,60,quark:iron_plate:1,20,STAINED_CLAY:12,15,STAINED_CLAY:15,5,AIR,7,IRON_BARS,12,CONCRETE:7,100)
RandomBlock(-8,0,3,CONCRETE:7,60,quark:iron_plate:1,20,STAINED_CLAY:12,15,STAINED_CLAY:15,5,AIR,7,IRON_BARS,12,CONCRETE:7,100)
RandomBlock(-8,0,4,CONCRETE:7,60,quark:iron_plate:1,20,STAINED_CLAY:12,15,STAINED_CLAY:15,5,AIR,7,IRON_BARS,12,CONCRETE:7,100)
RandomBlock(-8,0,5,CONCRETE:7,60,quark:iron_plate:1,20,STAINED_CLAY:12,15,STAINED_CLAY:15,5,AIR,7,IRON_BARS,12,CONCRETE:7,100)
RandomBlock(-8,0,6,CONCRETE:7,60,quark:iron_plate:1,20,STAINED_CLAY:12,15,STAINED_CLAY:15,5,AIR,7,IRON_BARS,12,CONCRETE:7,100)
RandomBlock(-8,0,7,CONCRETE:7,60,quark:iron_plate:1,20,STAINED_CLAY:12,15,STAINED_CLAY:15,5,AIR,7,IRON_BARS,12,CONCRETE:7,100)
RandomBlock(-8,0,8,CONCRETE:7,60,quark:iron_plate:1,20,STAINED_CLAY:12,15,STAINED_CLAY:15,5,AIR,7,IRON_BARS,12,CONCRETE:7,100)
RandomBlock(-8,1,-7,CONCRETE:7,60,quark:iron_plate:1,20,STAINED_CLAY:12,15,STAINED_CLAY:15,5,AIR,7,IRON_BARS,12,CONCRETE:7,100)
RandomBlock(-8,1,-6,CONCRETE:7,60,quark:iron_plate:1,20,STAINED_CLAY:12,15,STAINED_CLAY:15,5,AIR,7,IRON_BARS,12,CONCRETE:7,100)
RandomBlock(-8,1,-5,CONCRETE:7,60,quark:iron_plate:1,20,STAINED_CLAY:12,15,STAINED_CLAY:15,5,AIR,7,IRON_BARS,12,CONCRETE:7,100)
RandomBlock(-8,1,-4,CONCRETE:7,60,quark:iron_plate:1,20,STAINED_CLAY:12,15,STAINED_CLAY:15,5,AIR,7,IRON_BARS,12,CONCRETE:7,100)
Block(-8,1,-3,STATIONARY_WATER:0)
Block(-8,1,-2,STATIONARY_WATER:0)
RandomBlock(-8,1,-1,CONCRETE:7,60,quark:iron_plate:1,20,STAINED_CLAY:12,15,STAINED_CLAY:15,5,AIR,7,IRON_BARS,12,CONCRETE:7,100)
RandomBlock(-8,1,0,CONCRETE:7,60,quark:iron_plate:1,20,STAINED_CLAY:12,15,STAINED_CLAY:15,5,AIR,7,IRON_BARS,12,CONCRETE:7,100)
RandomBlock(-8,1,1,CONCRETE:7,60,quark:iron_plate:1,20,STAINED_CLAY:12,15,STAINED_CLAY:15,5,AIR,7,IRON_BARS,12,CONCRETE:7,100)
RandomBlock(-8,1,2,CONCRETE:7,60,quark:iron_plate:1,20,STAINED_CLAY:12,15,STAINED_CLAY:15,5,AIR,7,IRON_BARS,12,CONCRETE:7,100)
RandomBlock(-8,1,3,CONCRETE:7,60,quark:iron_plate:1,20,STAINED_CLAY:12,15,STAINED_CLAY:15,5,AIR,7,IRON_BARS,12,CONCRETE:7,100)
RandomBlock(-8,1,4,CONCRETE:7,60,quark:iron_plate:1,20,STAINED_CLAY:12,15,STAINED_CLAY:15,5,AIR,7,IRON_BARS,12,CONCRETE:7,100)
RandomBlock(-8,1,5,CONCRETE:7,60,quark:iron_plate:1,20,STAINED_CLAY:12,15,STAINED_CLAY:15,5,AIR,7,IRON_BARS,12,CONCRETE:7,100)
RandomBlock(-8,1,6,CONCRETE:7,60,quark:iron_plate:1,20,STAINED_CLAY:12,15,STAINED_CLAY:15,5,AIR,7,IRON_BARS,12,CONCRETE:7,100)
RandomBlock(-8,1,7,CONCRETE:7,60,quark:iron_plate:1,20,STAINED_CLAY:12,15,STAINED_CLAY:15,5,AIR,7,IRON_BARS,12,CONCRETE:7,100)
RandomBlock(-8,1,8,CONCRETE:7,60,quark:iron_plate:1,20,STAINED_CLAY:12,15,STAINED_CLAY:15,5,AIR,7,IRON_BARS,12,CONCRETE:7,100)
RandomBlock(-8,2,-7,CONCRETE:7,60,quark:iron_plate:1,20,STAINED_CLAY:12,15,STAINED_CLAY:15,5,AIR,7,IRON_BARS,12,CONCRETE:7,100)
RandomBlock(-8,2,-6,CONCRETE:7,60,quark:iron_plate:1,20,STAINED_CLAY:12,15,STAINED_CLAY:15,5,AIR,7,IRON_BARS,12,CONCRETE:7,100)
RandomBlock(-8,2,-5,CONCRETE:7,60,quark:iron_plate:1,20,STAINED_CLAY:12,15,STAINED_CLAY:15,5,AIR,7,IRON_BARS,12,CONCRETE:7,100)
Block(-8,2,-4,SMOOTH_STAIRS:3)
Block(-8,2,-3,AIR:0)
Block(-8,2,-2,AIR:0)
Block(-8,2,-1,SMOOTH_STAIRS:2)
RandomBlock(-8,2,0,CONCRETE:7,60,quark:iron_plate:1,20,STAINED_CLAY:12,15,STAINED_CLAY:15,5,AIR,7,IRON_BARS,12,CONCRETE:7,100)
RandomBlock(-8,2,1,CONCRETE:7,60,quark:iron_plate:1,20,STAINED_CLAY:12,15,STAINED_CLAY:15,5,AIR,7,IRON_BARS,12,CONCRETE:7,100)
RandomBlock(-8,2,2,CONCRETE:7,60,quark:iron_plate:1,20,STAINED_CLAY:12,15,STAINED_CLAY:15,5,AIR,7,IRON_BARS,12,CONCRETE:7,100)
RandomBlock(-8,2,3,CONCRETE:7,60,quark:iron_plate:1,20,STAINED_CLAY:12,15,STAINED_CLAY:15,5,AIR,7,IRON_BARS,12,CONCRETE:7,100)
RandomBlock(-8,2,4,CONCRETE:7,60,quark:iron_plate:1,20,STAINED_CLAY:12,15,STAINED_CLAY:15,5,AIR,7,IRON_BARS,12,CONCRETE:7,100)
RandomBlock(-8,2,5,CONCRETE:7,60,quark:iron_plate:1,20,STAINED_CLAY:12,15,STAINED_CLAY:15,5,AIR,7,IRON_BARS,12,CONCRETE:7,100)
RandomBlock(-8,2,6,CONCRETE:7,60,quark:iron_plate:1,20,STAINED_CLAY:12,15,STAINED_CLAY:15,5,AIR,7,IRON_BARS,12,CONCRETE:7,100)
RandomBlock(-8,2,7,CONCRETE:7,60,quark:iron_plate:1,20,STAINED_CLAY:12,15,STAINED_CLAY:15,5,AIR,7,IRON_BARS,12,CONCRETE:7,100)
RandomBlock(-8,2,8,CONCRETE:7,60,quark:iron_plate:1,20,STAINED_CLAY:12,15,STAINED_CLAY:15,5,AIR,7,IRON_BARS,12,CONCRETE:7,100)
RandomBlock(-8,3,-7,CONCRETE:7,60,quark:iron_plate:1,20,STAINED_CLAY:12,15,STAINED_CLAY:15,5,AIR,7,IRON_BARS,12,CONCRETE:7,100)
Block(-8,3,-6,AIR:0)
Block(-8,3,-5,AIR:0)
Block(-8,3,-4,AIR:0)
Block(-8,3,-3,AIR:0)
Block(-8,3,-2,AIR:0)
Block(-8,3,-1,AIR:0)
Block(-8,3,0,AIR:0)
Block(-8,3,1,AIR:0)
Block(-8,3,2,AIR:0)
Block(-8,3,3,AIR:0)
Block(-8,3,4,AIR:0)
Block(-8,3,5,AIR:0)
Block(-8,3,6,AIR:0)
Block(-8,3,7,AIR:0)
Block(-8,3,8,AIR:0)
RandomBlock(-8,4,-7,CONCRETE:7,60,quark:iron_plate:1,20,STAINED_CLAY:12,15,STAINED_CLAY:15,5,AIR,7,IRON_BARS,12,CONCRETE:7,100)
Block(-8,4,-6,AIR:0)
Block(-8,4,-5,AIR:0)
Block(-8,4,-4,AIR:0)
Block(-8,4,-3,AIR:0)
Block(-8,4,-2,AIR:0)
Block(-8,4,-1,AIR:0)
Block(-8,4,0,AIR:0)
Block(-8,4,1,AIR:0)
Block(-8,4,2,AIR:0)
Block(-8,4,3,AIR:0)
Block(-8,4,4,AIR:0)
Block(-8,4,5,AIR:0)
Block(-8,4,6,AIR:0)
Block(-8,4,7,AIR:0)
Block(-8,4,8,AIR:0)
RandomBlock(-8,5,-7,CONCRETE:7,60,quark:iron_plate:1,20,STAINED_CLAY:12,15,STAINED_CLAY:15,5,AIR,7,IRON_BARS,12,CONCRETE:7,100)
Block(-8,5,-6,CONCRETE:4)
Block(-8,5,-5,CONCRETE:12)
Block(-8,5,-4,AIR:0)
Block(-8,5,-3,AIR:0)
Block(-8,5,-2,AIR:0)
Block(-8,5,-1,AIR:0)
Block(-8,5,0,AIR:0)
Block(-8,5,1,AIR:0)
Block(-8,5,2,AIR:0)
Block(-8,5,3,AIR:0)
Block(-8,5,4,AIR:0)
Block(-8,5,5,AIR:0)
Block(-8,5,6,AIR:0)
Block(-8,5,7,AIR:0)
Block(-8,5,8,AIR:0)
RandomBlock(-8,6,-7,CONCRETE:7,60,quark:iron_plate:1,20,STAINED_CLAY:12,15,STAINED_CLAY:15,5,AIR,7,IRON_BARS,12,CONCRETE:7,100)
Block(-8,6,-6,AIR:0)
Block(-8,6,-5,AIR:0)
Block(-8,6,-4,AIR:0)
Block(-8,6,-3,AIR:0)
Block(-8,6,-2,AIR:0)
Block(-8,6,-1,AIR:0)
Block(-8,6,0,AIR:0)
Block(-8,6,1,AIR:0)
Block(-8,6,2,AIR:0)
Block(-8,6,3,AIR:0)
Block(-8,6,4,AIR:0)
Block(-8,6,5,AIR:0)
Block(-8,6,6,AIR:0)
Block(-8,6,7,AIR:0)
RandomBlock(-8,6,8,CONCRETE:7,60,quark:iron_plate:1,20,STAINED_CLAY:12,15,STAINED_CLAY:15,5,AIR,7,IRON_BARS,12,CONCRETE:7,100)
RandomBlock(-8,7,-7,CONCRETE:7,60,quark:iron_plate:1,20,STAINED_CLAY:12,15,STAINED_CLAY:15,5,AIR,7,IRON_BARS,12,CONCRETE:7,100)
RandomBlock(-8,7,-6,CONCRETE:7,60,quark:iron_plate:1,20,STAINED_CLAY:12,15,STAINED_CLAY:15,5,AIR,7,IRON_BARS,12,CONCRETE:7,100)
RandomBlock(-8,7,-5,CONCRETE:7,60,quark:iron_plate:1,20,STAINED_CLAY:12,15,STAINED_CLAY:15,5,AIR,7,IRON_BARS,12,CONCRETE:7,100)
RandomBlock(-8,7,-4,CONCRETE:7,60,quark:iron_plate:1,20,STAINED_CLAY:12,15,STAINED_CLAY:15,5,AIR,7,IRON_BARS,12,CONCRETE:7,100)
RandomBlock(-8,7,-3,CONCRETE:7,60,quark:iron_plate:1,20,STAINED_CLAY:12,15,STAINED_CLAY:15,5,AIR,7,IRON_BARS,12,CONCRETE:7,100)
RandomBlock(-8,7,-2,CONCRETE:7,60,quark:iron_plate:1,20,STAINED_CLAY:12,15,STAINED_CLAY:15,5,AIR,7,IRON_BARS,12,CONCRETE:7,100)
RandomBlock(-8,7,-1,CONCRETE:7,60,quark:iron_plate:1,20,STAINED_CLAY:12,15,STAINED_CLAY:15,5,AIR,7,IRON_BARS,12,CONCRETE:7,100)
RandomBlock(-8,7,0,CONCRETE:7,60,quark:iron_plate:1,20,STAINED_CLAY:12,15,STAINED_CLAY:15,5,AIR,7,IRON_BARS,12,CONCRETE:7,100)
RandomBlock(-8,7,1,CONCRETE:7,60,quark:iron_plate:1,20,STAINED_CLAY:12,15,STAINED_CLAY:15,5,AIR,7,IRON_BARS,12,CONCRETE:7,100)
RandomBlock(-8,7,2,CONCRETE:7,60,quark:iron_plate:1,20,STAINED_CLAY:12,15,STAINED_CLAY:15,5,AIR,7,IRON_BARS,12,CONCRETE:7,100)
RandomBlock(-8,7,3,CONCRETE:7,60,quark:iron_plate:1,20,STAINED_CLAY:12,15,STAINED_CLAY:15,5,AIR,7,IRON_BARS,12,CONCRETE:7,100)
RandomBlock(-8,7,4,CONCRETE:7,60,quark:iron_plate:1,20,STAINED_CLAY:12,15,STAINED_CLAY:15,5,AIR,7,IRON_BARS,12,CONCRETE:7,100)
RandomBlock(-8,7,5,CONCRETE:7,60,quark:iron_plate:1,20,STAINED_CLAY:12,15,STAINED_CLAY:15,5,AIR,7,IRON_BARS,12,CONCRETE:7,100)
RandomBlock(-8,7,6,CONCRETE:7,60,quark:iron_plate:1,20,STAINED_CLAY:12,15,STAINED_CLAY:15,5,AIR,7,IRON_BARS,12,CONCRETE:7,100)
RandomBlock(-8,7,7,CONCRETE:7,60,quark:iron_plate:1,20,STAINED_CLAY:12,15,STAINED_CLAY:15,5,AIR,7,IRON_BARS,12,CONCRETE:7,100)
RandomBlock(-8,7,8,CONCRETE:7,60,quark:iron_plate:1,20,STAINED_CLAY:12,15,STAINED_CLAY:15,5,AIR,7,IRON_BARS,12,CONCRETE:7,100)
Block(-8,8,-7,AIR:0)
Block(-8,8,-6,IRON_FENCE:0)
Block(-8,8,-5,AIR:0)
Block(-8,8,-4,AIR:0)
#RandomBlock(-8,8,-3,AIR:0,30,CHEST:5,../../../../../Chests/Loot/manhunt_urban_junk.nbt,10,CHEST:5,../../../../../Chests/Loot/manhunt_infected_cache.nbt,5,CHEST:5,../../../../../Chests/Loot/manhunt_urban_junk.nbt,65,CHEST:2,../../../../../Chests/Loot/manhunt_urban_junk.nbt,20,CHEST:2,../../../../../Chests/Loot/manhunt_residential_common.nbt,5,CHEST:2,../../../../../Chests/Loot/manhunt_residential_useful.nbt,3,CHEST:2,../../../../../Chests/Loot/manhunt_human_strategic_cache.nbt,1,CHEST:2,../../../../../Chests/Loot/manhunt_urban_junk.nbt,100)
RandomBlock(-8,8,-2,CONCRETE:7,60,quark:iron_plate:1,20,STAINED_CLAY:12,15,STAINED_CLAY:15,5,AIR,7,IRON_BARS,12,CONCRETE:7,100)
RandomBlock(-8,8,-1,CONCRETE:7,60,quark:iron_plate:1,20,STAINED_CLAY:12,15,STAINED_CLAY:15,5,AIR,7,IRON_BARS,12,CONCRETE:7,100)
RandomBlock(-8,8,0,CONCRETE:7,60,quark:iron_plate:1,20,STAINED_CLAY:12,15,STAINED_CLAY:15,5,AIR,7,IRON_BARS,12,CONCRETE:7,100)
RandomBlock(-8,8,1,CONCRETE:7,60,quark:iron_plate:1,20,STAINED_CLAY:12,15,STAINED_CLAY:15,5,AIR,7,IRON_BARS,12,CONCRETE:7,100)
RandomBlock(-8,8,2,CONCRETE:7,60,quark:iron_plate:1,20,STAINED_CLAY:12,15,STAINED_CLAY:15,5,AIR,7,IRON_BARS,12,CONCRETE:7,100)
RandomBlock(-8,8,3,CONCRETE:7,60,quark:iron_plate:1,20,STAINED_CLAY:12,15,STAINED_CLAY:15,5,AIR,7,IRON_BARS,12,CONCRETE:7,100)
RandomBlock(-8,8,4,CONCRETE:7,60,quark:iron_plate:1,20,STAINED_CLAY:12,15,STAINED_CLAY:15,5,AIR,7,IRON_BARS,12,CONCRETE:7,100)
RandomBlock(-8,8,5,CONCRETE:7,60,quark:iron_plate:1,20,STAINED_CLAY:12,15,STAINED_CLAY:15,5,AIR,7,IRON_BARS,12,CONCRETE:7,100)
RandomBlock(-8,8,6,CONCRETE:7,60,quark:iron_plate:1,20,STAINED_CLAY:12,15,STAINED_CLAY:15,5,AIR,7,IRON_BARS,12,CONCRETE:7,100)
RandomBlock(-8,8,7,CONCRETE:7,60,quark:iron_plate:1,20,STAINED_CLAY:12,15,STAINED_CLAY:15,5,AIR,7,IRON_BARS,12,CONCRETE:7,100)
RandomBlock(-8,8,8,CONCRETE:7,60,quark:iron_plate:1,20,STAINED_CLAY:12,15,STAINED_CLAY:15,5,AIR,7,IRON_BARS,12,CONCRETE:7,100)
Block(-8,9,-7,AIR:0)
Block(-8,9,-6,CONCRETE:14)
Block(-8,9,-5,AIR:0)
Block(-8,9,-4,AIR:0)
Block(-8,9,-3,AIR:0)
RandomBlock(-8,9,-2,CONCRETE:7,60,quark:iron_plate:1,20,STAINED_CLAY:12,15,STAINED_CLAY:15,5,AIR,7,IRON_BARS,12,CONCRETE:7,100)
RandomBlock(-8,9,-1,CONCRETE:7,60,quark:iron_plate:1,20,STAINED_CLAY:12,15,STAINED_CLAY:15,5,AIR,7,IRON_BARS,12,CONCRETE:7,100)
RandomBlock(-8,9,0,CONCRETE:7,60,quark:iron_plate:1,20,STAINED_CLAY:12,15,STAINED_CLAY:15,5,AIR,7,IRON_BARS,12,CONCRETE:7,100)
RandomBlock(-8,9,1,CONCRETE:7,60,quark:iron_plate:1,20,STAINED_CLAY:12,15,STAINED_CLAY:15,5,AIR,7,IRON_BARS,12,CONCRETE:7,100)
RandomBlock(-8,9,2,CONCRETE:7,60,quark:iron_plate:1,20,STAINED_CLAY:12,15,STAINED_CLAY:15,5,AIR,7,IRON_BARS,12,CONCRETE:7,100)
RandomBlock(-8,9,3,CONCRETE:7,60,quark:iron_plate:1,20,STAINED_CLAY:12,15,STAINED_CLAY:15,5,AIR,7,IRON_BARS,12,CONCRETE:7,100)
RandomBlock(-8,9,4,CONCRETE:7,60,quark:iron_plate:1,20,STAINED_CLAY:12,15,STAINED_CLAY:15,5,AIR,7,IRON_BARS,12,CONCRETE:7,100)
RandomBlock(-8,9,5,CONCRETE:7,60,quark:iron_plate:1,20,STAINED_CLAY:12,15,STAINED_CLAY:15,5,AIR,7,IRON_BARS,12,CONCRETE:7,100)
RandomBlock(-8,9,6,CONCRETE:7,60,quark:iron_plate:1,20,STAINED_CLAY:12,15,STAINED_CLAY:15,5,AIR,7,IRON_BARS,12,CONCRETE:7,100)
RandomBlock(-8,9,7,CONCRETE:7,60,quark:iron_plate:1,20,STAINED_CLAY:12,15,STAINED_CLAY:15,5,AIR,7,IRON_BARS,12,CONCRETE:7,100)
RandomBlock(-8,9,8,CONCRETE:7,60,quark:iron_plate:1,20,STAINED_CLAY:12,15,STAINED_CLAY:15,5,AIR,7,IRON_BARS,12,CONCRETE:7,100)
Block(-8,10,-7,AIR:0)
Block(-8,10,-6,CONCRETE:14)
Block(-8,10,-5,AIR:0)
Block(-8,10,-4,AIR:0)
Block(-8,10,-3,AIR:0)
RandomBlock(-8,10,-2,CONCRETE:7,60,quark:iron_plate:1,20,STAINED_CLAY:12,15,STAINED_CLAY:15,5,AIR,7,IRON_BARS,12,CONCRETE:7,100)
RandomBlock(-8,10,-1,CONCRETE:7,60,quark:iron_plate:1,20,STAINED_CLAY:12,15,STAINED_CLAY:15,5,AIR,7,IRON_BARS,12,CONCRETE:7,100)
RandomBlock(-8,10,0,CONCRETE:7,60,quark:iron_plate:1,20,STAINED_CLAY:12,15,STAINED_CLAY:15,5,AIR,7,IRON_BARS,12,CONCRETE:7,100)
RandomBlock(-8,10,1,CONCRETE:7,60,quark:iron_plate:1,20,STAINED_CLAY:12,15,STAINED_CLAY:15,5,AIR,7,IRON_BARS,12,CONCRETE:7,100)
RandomBlock(-8,10,2,CONCRETE:7,60,quark:iron_plate:1,20,STAINED_CLAY:12,15,STAINED_CLAY:15,5,AIR,7,IRON_BARS,12,CONCRETE:7,100)
RandomBlock(-8,10,3,CONCRETE:7,60,quark:iron_plate:1,20,STAINED_CLAY:12,15,STAINED_CLAY:15,5,AIR,7,IRON_BARS,12,CONCRETE:7,100)
RandomBlock(-8,10,4,CONCRETE:7,60,quark:iron_plate:1,20,STAINED_CLAY:12,15,STAINED_CLAY:15,5,AIR,7,IRON_BARS,12,CONCRETE:7,100)
RandomBlock(-8,10,5,CONCRETE:7,60,quark:iron_plate:1,20,STAINED_CLAY:12,15,STAINED_CLAY:15,5,AIR,7,IRON_BARS,12,CONCRETE:7,100)
RandomBlock(-8,10,6,CONCRETE:7,60,quark:iron_plate:1,20,STAINED_CLAY:12,15,STAINED_CLAY:15,5,AIR,7,IRON_BARS,12,CONCRETE:7,100)
RandomBlock(-8,10,7,CONCRETE:7,60,quark:iron_plate:1,20,STAINED_CLAY:12,15,STAINED_CLAY:15,5,AIR,7,IRON_BARS,12,CONCRETE:7,100)
RandomBlock(-8,10,8,CONCRETE:7,60,quark:iron_plate:1,20,STAINED_CLAY:12,15,STAINED_CLAY:15,5,AIR,7,IRON_BARS,12,CONCRETE:7,100)
Block(-8,11,-7,AIR:0)
Block(-8,11,-6,CONCRETE:14)
Block(-8,11,-5,AIR:0)
Block(-8,11,-4,AIR:0)
Block(-8,11,-3,AIR:0)
Block(-8,11,-2,STEP:7)
Block(-8,11,-1,STEP:7)
Block(-8,11,0,CONCRETE:12)
Block(-8,11,1,STEP:7)
Block(-8,11,2,CONCRETE:4)
Block(-8,11,3,STEP:7)
Block(-8,11,4,STEP:7)
RandomBlock(-8,11,5,CONCRETE:7,60,quark:iron_plate:1,20,STAINED_CLAY:12,15,STAINED_CLAY:15,5,AIR,7,IRON_BARS,12,CONCRETE:7,100)
RandomBlock(-8,11,6,CONCRETE:7,60,quark:iron_plate:1,20,STAINED_CLAY:12,15,STAINED_CLAY:15,5,AIR,7,IRON_BARS,12,CONCRETE:7,100)
RandomBlock(-8,11,7,CONCRETE:7,60,quark:iron_plate:1,20,STAINED_CLAY:12,15,STAINED_CLAY:15,5,AIR,7,IRON_BARS,12,CONCRETE:7,100)
RandomBlock(-8,11,8,CONCRETE:7,60,quark:iron_plate:1,20,STAINED_CLAY:12,15,STAINED_CLAY:15,5,AIR,7,IRON_BARS,12,CONCRETE:7,100)
Block(-8,12,-7,AIR:0)
Block(-8,12,-6,IRON_FENCE:0)
Block(-8,12,-5,AIR:0)
Block(-8,12,-4,AIR:0)
Block(-8,12,-3,AIR:0)
Block(-8,12,-2,AIR:0)
Block(-8,12,-1,AIR:0)
Block(-8,12,0,AIR:0)
Block(-8,12,1,AIR:0)
Block(-8,12,2,AIR:0)
Block(-8,12,3,AIR:0)
Block(-8,12,4,AIR:0)
RandomBlock(-8,12,5,CONCRETE:7,60,quark:iron_plate:1,20,STAINED_CLAY:12,15,STAINED_CLAY:15,5,AIR,7,IRON_BARS,12,CONCRETE:7,100)
RandomBlock(-8,12,6,CONCRETE:7,60,quark:iron_plate:1,20,STAINED_CLAY:12,15,STAINED_CLAY:15,5,AIR,7,IRON_BARS,12,CONCRETE:7,100)
RandomBlock(-8,12,7,CONCRETE:7,60,quark:iron_plate:1,20,STAINED_CLAY:12,15,STAINED_CLAY:15,5,AIR,7,IRON_BARS,12,CONCRETE:7,100)
RandomBlock(-8,12,8,CONCRETE:7,60,quark:iron_plate:1,20,STAINED_CLAY:12,15,STAINED_CLAY:15,5,AIR,7,IRON_BARS,12,CONCRETE:7,100)
Block(-8,13,-7,CONCRETE:8)
Block(-8,13,-6,CONCRETE:8)
Block(-8,13,-5,CONCRETE:8)
Block(-8,13,-4,CONCRETE:8)
Block(-8,13,-3,CONCRETE:8)
Block(-8,13,-2,CONCRETE:8)
Block(-8,13,-1,CONCRETE:8)
Block(-8,13,0,CONCRETE:8)
Block(-8,13,1,CONCRETE:8)
Block(-8,13,2,CONCRETE:8)
Block(-8,13,3,CONCRETE:8)
Block(-8,13,4,CONCRETE:8)
Block(-8,13,5,CONCRETE:8)
Block(-8,13,6,CONCRETE:8)
Block(-8,13,7,CONCRETE:8)
Block(-8,13,8,CONCRETE:8)
Block(-8,14,-7,CONCRETE:8)
Block(-8,14,-6,CONCRETE:8)
Block(-8,14,-5,CONCRETE:8)
Block(-8,14,-4,CONCRETE:8)
Block(-8,14,-3,CONCRETE:8)
Block(-8,14,-2,CONCRETE:8)
Block(-8,14,-1,CONCRETE:8)
Block(-8,14,0,AIR:0)
Block(-8,14,1,AIR:0)
Block(-8,14,2,AIR:0)
Block(-8,14,3,QUARTZ_STAIRS:3)
Block(-8,14,4,CONCRETE:8)
Block(-8,14,5,CONCRETE:8)
Block(-8,14,6,CONCRETE:8)
Block(-8,14,7,CONCRETE:8)
Block(-8,14,8,STEP:15)
RandomBlock(-8,15,-7,CONCRETE:7,60,quark:iron_plate:1,20,STAINED_CLAY:12,15,STAINED_CLAY:15,5,AIR,7,IRON_BARS,12,CONCRETE:7,100)
RandomBlock(-8,15,-6,CONCRETE:7,60,quark:iron_plate:1,20,STAINED_CLAY:12,15,STAINED_CLAY:15,5,AIR,7,IRON_BARS,12,CONCRETE:7,100)
RandomBlock(-8,15,-5,CONCRETE:7,60,quark:iron_plate:1,20,STAINED_CLAY:12,15,STAINED_CLAY:15,5,AIR,7,IRON_BARS,12,CONCRETE:7,100)
RandomBlock(-8,15,-4,CONCRETE:7,60,quark:iron_plate:1,20,STAINED_CLAY:12,15,STAINED_CLAY:15,5,AIR,7,IRON_BARS,12,CONCRETE:7,100)
RandomBlock(-8,15,-3,CONCRETE:7,60,quark:iron_plate:1,20,STAINED_CLAY:12,15,STAINED_CLAY:15,5,AIR,7,IRON_BARS,12,CONCRETE:7,100)
RandomBlock(-8,15,-2,CONCRETE:7,60,quark:iron_plate:1,20,STAINED_CLAY:12,15,STAINED_CLAY:15,5,AIR,7,IRON_BARS,12,CONCRETE:7,100)
RandomBlock(-8,15,-1,CONCRETE:7,60,quark:iron_plate:1,20,STAINED_CLAY:12,15,STAINED_CLAY:15,5,AIR,7,IRON_BARS,12,CONCRETE:7,100)
Block(-8,15,0,AIR:0)
Block(-8,15,1,AIR:0)
Block(-8,15,2,AIR:0)
Block(-8,15,3,AIR:0)
RandomBlock(-8,15,4,CONCRETE:7,60,quark:iron_plate:1,20,STAINED_CLAY:12,15,STAINED_CLAY:15,5,AIR,7,IRON_BARS,12,CONCRETE:7,100)
RandomBlock(-8,15,5,CONCRETE:7,60,quark:iron_plate:1,20,STAINED_CLAY:12,15,STAINED_CLAY:15,5,AIR,7,IRON_BARS,12,CONCRETE:7,100)
Block(-8,15,6,CONCRETE:8)
RandomBlock(-8,15,7,CONCRETE:7,60,quark:iron_plate:1,20,STAINED_CLAY:12,15,STAINED_CLAY:15,5,AIR,7,IRON_BARS,12,CONCRETE:7,100)
RandomBlock(-8,15,8,AIR,90,IRON_TRAPDOOR:9,100)
RandomBlock(-8,16,-7,CONCRETE:7,60,quark:iron_plate:1,20,STAINED_CLAY:12,15,STAINED_CLAY:15,5,AIR,7,IRON_BARS,12,CONCRETE:7,100)
RandomBlock(-8,16,-6,CONCRETE:7,60,quark:iron_plate:1,20,STAINED_CLAY:12,15,STAINED_CLAY:15,5,AIR,7,IRON_BARS,12,CONCRETE:7,100)
RandomBlock(-8,16,-5,CONCRETE:7,60,quark:iron_plate:1,20,STAINED_CLAY:12,15,STAINED_CLAY:15,5,AIR,7,IRON_BARS,12,CONCRETE:7,100)
RandomBlock(-8,16,-4,CONCRETE:7,60,quark:iron_plate:1,20,STAINED_CLAY:12,15,STAINED_CLAY:15,5,AIR,7,IRON_BARS,12,CONCRETE:7,100)
RandomBlock(-8,16,-3,CONCRETE:7,60,quark:iron_plate:1,20,STAINED_CLAY:12,15,STAINED_CLAY:15,5,AIR,7,IRON_BARS,12,CONCRETE:7,100)
RandomBlock(-8,16,-2,CONCRETE:7,60,quark:iron_plate:1,20,STAINED_CLAY:12,15,STAINED_CLAY:15,5,AIR,7,IRON_BARS,12,CONCRETE:7,100)
RandomBlock(-8,16,-1,CONCRETE:7,60,quark:iron_plate:1,20,STAINED_CLAY:12,15,STAINED_CLAY:15,5,AIR,7,IRON_BARS,12,CONCRETE:7,100)
Block(-8,16,0,STEP:15)
Block(-8,16,1,STEP:15)
Block(-8,16,2,STEP:15)
Block(-8,16,3,STEP:15)
RandomBlock(-8,16,4,CONCRETE:7,60,quark:iron_plate:1,20,STAINED_CLAY:12,15,STAINED_CLAY:15,5,AIR,7,IRON_BARS,12,CONCRETE:7,100)
RandomBlock(-8,16,5,CONCRETE:7,60,quark:iron_plate:1,20,STAINED_CLAY:12,15,STAINED_CLAY:15,5,AIR,7,IRON_BARS,12,CONCRETE:7,100)
Block(-8,16,6,CONCRETE:8)
RandomBlock(-8,16,7,CONCRETE:7,60,quark:iron_plate:1,20,STAINED_CLAY:12,15,STAINED_CLAY:15,5,AIR,7,IRON_BARS,12,CONCRETE:7,100)
Block(-8,16,8,AIR:0)
RandomBlock(-8,17,-7,CONCRETE:7,60,quark:iron_plate:1,20,STAINED_CLAY:12,15,STAINED_CLAY:15,5,AIR,7,IRON_BARS,12,CONCRETE:7,100)
RandomBlock(-8,17,-6,CONCRETE:7,60,quark:iron_plate:1,20,STAINED_CLAY:12,15,STAINED_CLAY:15,5,AIR,7,IRON_BARS,12,CONCRETE:7,100)
RandomBlock(-8,17,-5,CONCRETE:7,60,quark:iron_plate:1,20,STAINED_CLAY:12,15,STAINED_CLAY:15,5,AIR,7,IRON_BARS,12,CONCRETE:7,100)
RandomBlock(-8,17,-4,CONCRETE:7,60,quark:iron_plate:1,20,STAINED_CLAY:12,15,STAINED_CLAY:15,5,AIR,7,IRON_BARS,12,CONCRETE:7,100)
RandomBlock(-8,17,-3,CONCRETE:7,60,quark:iron_plate:1,20,STAINED_CLAY:12,15,STAINED_CLAY:15,5,AIR,7,IRON_BARS,12,CONCRETE:7,100)
RandomBlock(-8,17,-2,CONCRETE:7,60,quark:iron_plate:1,20,STAINED_CLAY:12,15,STAINED_CLAY:15,5,AIR,7,IRON_BARS,12,CONCRETE:7,100)
RandomBlock(-8,17,-1,CONCRETE:7,60,quark:iron_plate:1,20,STAINED_CLAY:12,15,STAINED_CLAY:15,5,AIR,7,IRON_BARS,12,CONCRETE:7,100)
RandomBlock(-8,17,0,CONCRETE:7,60,quark:iron_plate:1,20,STAINED_CLAY:12,15,STAINED_CLAY:15,5,AIR,7,IRON_BARS,12,CONCRETE:7,100)
RandomBlock(-8,17,1,CONCRETE:7,60,quark:iron_plate:1,20,STAINED_CLAY:12,15,STAINED_CLAY:15,5,AIR,7,IRON_BARS,12,CONCRETE:7,100)
RandomBlock(-8,17,2,CONCRETE:7,60,quark:iron_plate:1,20,STAINED_CLAY:12,15,STAINED_CLAY:15,5,AIR,7,IRON_BARS,12,CONCRETE:7,100)
RandomBlock(-8,17,3,CONCRETE:7,60,quark:iron_plate:1,20,STAINED_CLAY:12,15,STAINED_CLAY:15,5,AIR,7,IRON_BARS,12,CONCRETE:7,100)
RandomBlock(-8,17,4,CONCRETE:7,60,quark:iron_plate:1,20,STAINED_CLAY:12,15,STAINED_CLAY:15,5,AIR,7,IRON_BARS,12,CONCRETE:7,100)
RandomBlock(-8,17,5,CONCRETE:7,60,quark:iron_plate:1,20,STAINED_CLAY:12,15,STAINED_CLAY:15,5,AIR,7,IRON_BARS,12,CONCRETE:7,100)
RandomBlock(-8,17,6,CONCRETE:7,60,quark:iron_plate:1,20,STAINED_CLAY:12,15,STAINED_CLAY:15,5,AIR,7,IRON_BARS,12,CONCRETE:7,100)
RandomBlock(-8,17,7,CONCRETE:7,60,quark:iron_plate:1,20,STAINED_CLAY:12,15,STAINED_CLAY:15,5,AIR,7,IRON_BARS,12,CONCRETE:7,100)
RandomBlock(-8,17,8,CONCRETE:7,60,quark:iron_plate:1,20,STAINED_CLAY:12,15,STAINED_CLAY:15,5,AIR,7,IRON_BARS,12,CONCRETE:7,100)
Block(-8,18,0,CARPET:8)
Block(-8,18,1,CARPET:8)
Block(-8,18,2,CARPET:8)
RandomBlock(-8,21,-2,AIR,90,TRAP_DOOR:7,100)
RandomBlock(-8,21,6,AIR,90,TRAP_DOOR:7,100)
Block(-8,25,-7,CONCRETE:15)
Block(-8,25,-6,CONCRETE:15)
Block(-8,25,-5,CONCRETE:15)
Block(-8,25,-4,CONCRETE:15)
Block(-8,25,-3,CONCRETE:15)
Block(-8,25,-2,CONCRETE:15)
Block(-8,25,-1,CONCRETE:15)
Block(-8,25,0,CONCRETE:15)
Block(-8,25,1,CONCRETE:15)
Block(-8,25,2,CONCRETE:15)
Block(-8,25,3,CONCRETE:15)
Block(-8,25,4,CONCRETE:15)
Block(-8,25,5,CONCRETE:15)
Block(-8,25,6,CONCRETE:15)
Block(-8,25,7,CONCRETE:15)
Block(-8,25,8,CONCRETE:15)
Block(-8,26,-6,CARPET:13)
Block(-8,26,-4,CONCRETE:0)
Block(-8,26,-3,BOOKSHELF:0)
Block(-8,26,-2,BOOKSHELF:0)
Block(-8,26,-1,BOOKSHELF:0)
Block(-8,26,0,BOOKSHELF:0)
Block(-8,26,1,CONCRETE:0)
Block(-8,26,2,BOOKSHELF:0)
Block(-8,26,3,BOOKSHELF:0)
#RandomBlock(-8,26,4,AIR:0,30,CHEST:5,../../../../../Chests/Loot/manhunt_urban_junk.nbt,10,CHEST:5,../../../../../Chests/Loot/manhunt_infected_cache.nbt,5,CHEST:5,../../../../../Chests/Loot/manhunt_urban_junk.nbt,65,CHEST:4,../../../../../Chests/Loot/manhunt_urban_junk.nbt,20,CHEST:4,../../../../../Chests/Loot/manhunt_residential_common.nbt,5,CHEST:4,../../../../../Chests/Loot/manhunt_residential_useful.nbt,3,CHEST:4,../../../../../Chests/Loot/manhunt_human_strategic_cache.nbt,1,CHEST:4,../../../../../Chests/Loot/manhunt_urban_junk.nbt,100)
Block(-8,26,5,BOOKSHELF:0)
Block(-8,26,6,CONCRETE:0)
Block(-8,26,8,CARPET:13)
Block(-8,27,-4,CONCRETE:0)
RandomBlock(-8,27,-3,AIR,90,TRAP_DOOR:1,100)
RandomBlock(-8,27,-2,AIR,90,TRAP_DOOR:1,100)
RandomBlock(-8,27,-1,AIR,90,TRAP_DOOR:1,100)
RandomBlock(-8,27,0,AIR,90,TRAP_DOOR:2,100)
Block(-8,27,1,CONCRETE:0)
RandomBlock(-8,27,2,AIR,90,TRAP_DOOR:1,100)
RandomBlock(-8,27,3,AIR,90,TRAP_DOOR:1,100)
RandomBlock(-8,27,4,AIR,90,TRAP_DOOR:2,100)
RandomBlock(-8,27,5,AIR,90,TRAP_DOOR:2,100)
Block(-8,27,6,CONCRETE:0)
Block(-8,28,-4,CONCRETE:0)
Block(-8,28,1,CONCRETE:0)
Block(-8,28,6,CONCRETE:0)
Block(-8,29,-7,CONCRETE:15)
Block(-8,29,-6,CONCRETE:15)
Block(-8,29,-5,CONCRETE:15)
Block(-8,29,-4,CONCRETE:15)
Block(-8,29,-3,CONCRETE:15)
Block(-8,29,-2,CONCRETE:15)
Block(-8,29,-1,CONCRETE:15)
Block(-8,29,0,CONCRETE:15)
Block(-8,29,1,CONCRETE:15)
Block(-8,29,2,CONCRETE:15)
Block(-8,29,3,CONCRETE:15)
Block(-8,29,4,CONCRETE:15)
Block(-8,29,5,CONCRETE:15)
Block(-8,29,6,CONCRETE:15)
Block(-8,29,7,CONCRETE:15)
Block(-8,29,8,CONCRETE:15)
RandomBlock(-8,30,-7,AIR,90,AIR:0,100)
Block(-8,30,-2,DOUBLE_STEP:7)
Block(-8,30,-1,BIRCH_WOOD_STAIRS:2)
Block(-8,30,0,BIRCH_DOOR:1)
Block(-8,30,4,SPRUCE_DOOR:1)
Block(-8,31,-2,CARPET:8)
RandomBlock(-8,31,-1,AIR,95,WALL_BANNER:2,../AllScraperData/skyscraper_3x3_03/302-bannerC16R16.nbt,100)
Block(-8,31,0,BIRCH_DOOR:11)
Block(-8,31,4,SPRUCE_DOOR:10)
RandomBlock(-8,32,4,CONCRETE:7,60,quark:iron_plate:1,20,STAINED_CLAY:12,15,STAINED_CLAY:15,5,AIR,7,IRON_BARS,12,CONCRETE:7,100)
Block(-8,33,-7,CONCRETE:15)
Block(-8,33,-6,CONCRETE:15)
Block(-8,33,-5,CONCRETE:15)
Block(-8,33,-4,CONCRETE:15)
Block(-8,33,-3,CONCRETE:15)
Block(-8,33,-2,CONCRETE:15)
Block(-8,33,-1,CONCRETE:15)
Block(-8,33,0,CONCRETE:15)
Block(-8,33,1,CONCRETE:15)
Block(-8,33,2,CONCRETE:15)
Block(-8,33,3,CONCRETE:15)
Block(-8,33,4,CONCRETE:15)
Block(-8,33,5,CONCRETE:15)
Block(-8,33,6,CONCRETE:15)
Block(-8,33,7,CONCRETE:15)
Block(-8,33,8,CONCRETE:15)
Block(-8,34,-1,CARPET:11)
Block(-8,34,0,CARPET:0)
Block(-8,34,1,CARPET:11)
Block(-8,34,2,CARPET:0)
Block(-8,34,3,CARPET:11)
Block(-8,37,-7,CONCRETE:15)
Block(-8,37,-6,CONCRETE:15)
Block(-8,37,-5,CONCRETE:15)
Block(-8,37,-4,CONCRETE:15)
Block(-8,37,-3,CONCRETE:15)
Block(-8,37,-2,CONCRETE:15)
Block(-8,37,-1,CONCRETE:15)
Block(-8,37,0,CONCRETE:15)
Block(-8,37,1,CONCRETE:15)
Block(-8,37,2,CONCRETE:15)
Block(-8,37,3,CONCRETE:15)
Block(-8,37,4,CONCRETE:15)
Block(-8,37,5,CONCRETE:15)
Block(-8,37,6,CONCRETE:15)
Block(-8,37,7,CONCRETE:15)
Block(-8,37,8,CONCRETE:15)
Block(-8,38,-1,CARPET:0)
Block(-8,38,0,CARPET:5)
Block(-8,38,1,CARPET:0)
Block(-8,38,2,CARPET:5)
Block(-8,38,3,CARPET:0)
Block(-8,41,-7,CONCRETE:15)
Block(-8,41,-6,CONCRETE:15)
Block(-8,41,-5,CONCRETE:15)
Block(-8,41,-4,CONCRETE:15)
Block(-8,41,-3,CONCRETE:15)
Block(-8,41,-2,CONCRETE:15)
Block(-8,41,-1,CONCRETE:15)
Block(-8,41,0,CONCRETE:15)
Block(-8,41,1,CONCRETE:15)
Block(-8,41,2,CONCRETE:15)
Block(-8,41,3,CONCRETE:15)
Block(-8,41,4,CONCRETE:15)
Block(-8,41,5,CONCRETE:15)
Block(-8,41,6,CONCRETE:15)
Block(-8,41,7,CONCRETE:15)
Block(-8,41,8,CONCRETE:15)
Block(-8,42,-1,CARPET:11)
Block(-8,42,0,CARPET:0)
Block(-8,42,1,CARPET:11)
Block(-8,42,2,CARPET:0)
Block(-8,42,3,CARPET:11)
Block(-8,45,-7,CONCRETE:15)
Block(-8,45,-6,CONCRETE:15)
Block(-8,45,-5,CONCRETE:15)
Block(-8,45,-4,CONCRETE:15)
Block(-8,45,-3,CONCRETE:15)
Block(-8,45,-2,CONCRETE:15)
Block(-8,45,-1,CONCRETE:15)
Block(-8,45,0,CONCRETE:15)
Block(-8,45,1,CONCRETE:15)
Block(-8,45,2,CONCRETE:15)
Block(-8,45,3,CONCRETE:15)
Block(-8,45,4,CONCRETE:15)
Block(-8,45,5,CONCRETE:15)
Block(-8,45,6,CONCRETE:15)
Block(-8,45,7,CONCRETE:15)
Block(-8,45,8,CONCRETE:15)
Block(-8,46,-1,CARPET:0)
Block(-8,46,0,CARPET:5)
Block(-8,46,1,CARPET:0)
Block(-8,46,2,CARPET:5)
Block(-8,46,3,CARPET:0)
Block(-8,49,-7,CONCRETE:15)
Block(-8,49,-6,CONCRETE:15)
Block(-8,49,-5,CONCRETE:15)
Block(-8,49,-4,CONCRETE:15)
Block(-8,49,-3,CONCRETE:15)
Block(-8,49,-2,CONCRETE:15)
Block(-8,49,-1,CONCRETE:15)
Block(-8,49,0,CONCRETE:15)
Block(-8,49,1,CONCRETE:15)
Block(-8,49,2,CONCRETE:15)
Block(-8,49,3,CONCRETE:15)
Block(-8,49,4,CONCRETE:15)
Block(-8,49,5,CONCRETE:15)
Block(-8,49,6,CONCRETE:15)
Block(-8,49,7,CONCRETE:15)
Block(-8,49,8,CONCRETE:15)
RandomBlock(-8,50,-7,AIR,90,AIR:0,100)
Block(-8,50,-2,DOUBLE_STEP:7)
Block(-8,50,-1,BIRCH_WOOD_STAIRS:2)
Block(-8,50,0,BIRCH_DOOR:1)
Block(-8,50,4,SPRUCE_DOOR:1)
Block(-8,51,-2,CARPET:8)
RandomBlock(-8,51,-1,AIR,95,WALL_BANNER:2,../AllScraperData/skyscraper_3x3_03/310-bannerC16R16.nbt,100)
Block(-8,51,0,BIRCH_DOOR:11)
Block(-8,51,4,SPRUCE_DOOR:10)
RandomBlock(-8,52,4,CONCRETE:7,60,quark:iron_plate:1,20,STAINED_CLAY:12,15,STAINED_CLAY:15,5,AIR,7,IRON_BARS,12,CONCRETE:7,100)
Block(-8,53,-7,CONCRETE:15)
Block(-8,53,-6,CONCRETE:15)
Block(-8,53,-5,CONCRETE:15)
Block(-8,53,-4,CONCRETE:15)
Block(-8,53,-3,CONCRETE:15)
Block(-8,53,-2,CONCRETE:15)
Block(-8,53,-1,CONCRETE:15)
Block(-8,53,0,CONCRETE:15)
Block(-8,53,1,CONCRETE:15)
Block(-8,53,2,CONCRETE:15)
Block(-8,53,3,CONCRETE:15)
Block(-8,53,4,CONCRETE:15)
Block(-8,53,5,CONCRETE:15)
Block(-8,53,6,CONCRETE:15)
Block(-8,53,7,CONCRETE:15)
Block(-8,53,8,CONCRETE:15)
Block(-8,54,-1,CARPET:11)
Block(-8,54,0,CARPET:0)
Block(-8,54,1,CARPET:11)
Block(-8,54,2,CARPET:0)
Block(-8,54,3,CARPET:11)
Block(-8,57,-7,CONCRETE:15)
Block(-8,57,-6,CONCRETE:15)
Block(-8,57,-5,CONCRETE:15)
Block(-8,57,-4,CONCRETE:15)
Block(-8,57,-3,CONCRETE:15)
Block(-8,57,-2,CONCRETE:15)
Block(-8,57,-1,CONCRETE:15)
Block(-8,57,0,CONCRETE:15)
Block(-8,57,1,CONCRETE:15)
Block(-8,57,2,CONCRETE:15)
Block(-8,57,3,CONCRETE:15)
Block(-8,57,4,CONCRETE:15)
Block(-8,57,5,CONCRETE:15)
Block(-8,57,6,CONCRETE:15)
Block(-8,57,7,CONCRETE:15)
Block(-8,57,8,CONCRETE:15)
Block(-8,58,-1,CARPET:0)
Block(-8,58,0,CARPET:5)
Block(-8,58,1,CARPET:0)
Block(-8,58,2,CARPET:5)
Block(-8,58,3,CARPET:0)
Block(-8,61,-7,CONCRETE:15)
Block(-8,61,-6,CONCRETE:15)
Block(-8,61,-5,CONCRETE:15)
Block(-8,61,-4,CONCRETE:15)
Block(-8,61,-3,CONCRETE:15)
Block(-8,61,-2,CONCRETE:15)
Block(-8,61,-1,CONCRETE:15)
Block(-8,61,0,CONCRETE:15)
Block(-8,61,1,CONCRETE:15)
Block(-8,61,2,CONCRETE:15)
Block(-8,61,3,CONCRETE:15)
Block(-8,61,4,CONCRETE:15)
Block(-8,61,5,CONCRETE:15)
Block(-8,61,6,CONCRETE:15)
Block(-8,61,7,CONCRETE:15)
Block(-8,61,8,CONCRETE:15)
Block(-8,62,-1,CARPET:11)
Block(-8,62,0,CARPET:0)
Block(-8,62,1,CARPET:11)
Block(-8,62,2,CARPET:0)
Block(-8,62,3,CARPET:11)
Block(-8,65,-7,CONCRETE:15)
Block(-8,65,-6,CONCRETE:15)
Block(-8,65,-5,CONCRETE:15)
Block(-8,65,-4,CONCRETE:15)
Block(-8,65,-3,CONCRETE:15)
Block(-8,65,-2,CONCRETE:15)
Block(-8,65,-1,CONCRETE:15)
Block(-8,65,0,CONCRETE:15)
Block(-8,65,1,CONCRETE:15)
Block(-8,65,2,CONCRETE:15)
Block(-8,65,3,CONCRETE:15)
Block(-8,65,4,CONCRETE:15)
Block(-8,65,5,CONCRETE:15)
Block(-8,65,6,CONCRETE:15)
Block(-8,65,7,CONCRETE:15)
Block(-8,65,8,CONCRETE:15)
Block(-8,66,-1,CARPET:0)
Block(-8,66,0,CARPET:5)
Block(-8,66,1,CARPET:0)
Block(-8,66,2,CARPET:5)
Block(-8,66,3,CARPET:0)
Block(-8,69,-7,CONCRETE:15)
Block(-8,69,-6,CONCRETE:15)
Block(-8,69,-5,CONCRETE:15)
Block(-8,69,-4,CONCRETE:15)
Block(-8,69,-3,CONCRETE:15)
Block(-8,69,-2,CONCRETE:15)
Block(-8,69,-1,CONCRETE:15)
Block(-8,69,0,CONCRETE:15)
Block(-8,69,1,CONCRETE:15)
Block(-8,69,2,CONCRETE:15)
Block(-8,69,3,CONCRETE:15)
Block(-8,69,4,CONCRETE:15)
Block(-8,69,5,CONCRETE:15)
Block(-8,69,6,CONCRETE:15)
Block(-8,69,7,CONCRETE:15)
Block(-8,69,8,CONCRETE:15)
RandomBlock(-7,0,-7,CONCRETE:7,60,quark:iron_plate:1,20,STAINED_CLAY:12,15,STAINED_CLAY:15,5,AIR,7,IRON_BARS,12,CONCRETE:7,100)
RandomBlock(-7,0,-6,CONCRETE:7,60,quark:iron_plate:1,20,STAINED_CLAY:12,15,STAINED_CLAY:15,5,AIR,7,IRON_BARS,12,CONCRETE:7,100)
RandomBlock(-7,0,-5,CONCRETE:7,60,quark:iron_plate:1,20,STAINED_CLAY:12,15,STAINED_CLAY:15,5,AIR,7,IRON_BARS,12,CONCRETE:7,100)
RandomBlock(-7,0,-4,CONCRETE:7,60,quark:iron_plate:1,20,STAINED_CLAY:12,15,STAINED_CLAY:15,5,AIR,7,IRON_BARS,12,CONCRETE:7,100)
RandomBlock(-7,0,-3,CONCRETE:7,60,quark:iron_plate:1,20,STAINED_CLAY:12,15,STAINED_CLAY:15,5,AIR,7,IRON_BARS,12,CONCRETE:7,100)
RandomBlock(-7,0,-2,CONCRETE:7,60,quark:iron_plate:1,20,STAINED_CLAY:12,15,STAINED_CLAY:15,5,AIR,7,IRON_BARS,12,CONCRETE:7,100)
RandomBlock(-7,0,-1,CONCRETE:7,60,quark:iron_plate:1,20,STAINED_CLAY:12,15,STAINED_CLAY:15,5,AIR,7,IRON_BARS,12,CONCRETE:7,100)
RandomBlock(-7,0,0,CONCRETE:7,60,quark:iron_plate:1,20,STAINED_CLAY:12,15,STAINED_CLAY:15,5,AIR,7,IRON_BARS,12,CONCRETE:7,100)
RandomBlock(-7,0,1,CONCRETE:7,60,quark:iron_plate:1,20,STAINED_CLAY:12,15,STAINED_CLAY:15,5,AIR,7,IRON_BARS,12,CONCRETE:7,100)
RandomBlock(-7,0,2,CONCRETE:7,60,quark:iron_plate:1,20,STAINED_CLAY:12,15,STAINED_CLAY:15,5,AIR,7,IRON_BARS,12,CONCRETE:7,100)
RandomBlock(-7,0,3,CONCRETE:7,60,quark:iron_plate:1,20,STAINED_CLAY:12,15,STAINED_CLAY:15,5,AIR,7,IRON_BARS,12,CONCRETE:7,100)
RandomBlock(-7,0,4,CONCRETE:7,60,quark:iron_plate:1,20,STAINED_CLAY:12,15,STAINED_CLAY:15,5,AIR,7,IRON_BARS,12,CONCRETE:7,100)
RandomBlock(-7,0,5,CONCRETE:7,60,quark:iron_plate:1,20,STAINED_CLAY:12,15,STAINED_CLAY:15,5,AIR,7,IRON_BARS,12,CONCRETE:7,100)
RandomBlock(-7,0,6,CONCRETE:7,60,quark:iron_plate:1,20,STAINED_CLAY:12,15,STAINED_CLAY:15,5,AIR,7,IRON_BARS,12,CONCRETE:7,100)
RandomBlock(-7,0,7,CONCRETE:7,60,quark:iron_plate:1,20,STAINED_CLAY:12,15,STAINED_CLAY:15,5,AIR,7,IRON_BARS,12,CONCRETE:7,100)
RandomBlock(-7,0,8,CONCRETE:7,60,quark:iron_plate:1,20,STAINED_CLAY:12,15,STAINED_CLAY:15,5,AIR,7,IRON_BARS,12,CONCRETE:7,100)
RandomBlock(-7,1,-7,CONCRETE:7,60,quark:iron_plate:1,20,STAINED_CLAY:12,15,STAINED_CLAY:15,5,AIR,7,IRON_BARS,12,CONCRETE:7,100)
RandomBlock(-7,1,-6,CONCRETE:7,60,quark:iron_plate:1,20,STAINED_CLAY:12,15,STAINED_CLAY:15,5,AIR,7,IRON_BARS,12,CONCRETE:7,100)
RandomBlock(-7,1,-5,CONCRETE:7,60,quark:iron_plate:1,20,STAINED_CLAY:12,15,STAINED_CLAY:15,5,AIR,7,IRON_BARS,12,CONCRETE:7,100)
RandomBlock(-7,1,-4,CONCRETE:7,60,quark:iron_plate:1,20,STAINED_CLAY:12,15,STAINED_CLAY:15,5,AIR,7,IRON_BARS,12,CONCRETE:7,100)
Block(-7,1,-3,STATIONARY_WATER:0)
Block(-7,1,-2,STATIONARY_WATER:0)
RandomBlock(-7,1,-1,CONCRETE:7,60,quark:iron_plate:1,20,STAINED_CLAY:12,15,STAINED_CLAY:15,5,AIR,7,IRON_BARS,12,CONCRETE:7,100)
RandomBlock(-7,1,0,CONCRETE:7,60,quark:iron_plate:1,20,STAINED_CLAY:12,15,STAINED_CLAY:15,5,AIR,7,IRON_BARS,12,CONCRETE:7,100)
RandomBlock(-7,1,1,CONCRETE:7,60,quark:iron_plate:1,20,STAINED_CLAY:12,15,STAINED_CLAY:15,5,AIR,7,IRON_BARS,12,CONCRETE:7,100)
RandomBlock(-7,1,2,CONCRETE:7,60,quark:iron_plate:1,20,STAINED_CLAY:12,15,STAINED_CLAY:15,5,AIR,7,IRON_BARS,12,CONCRETE:7,100)
RandomBlock(-7,1,3,CONCRETE:7,60,quark:iron_plate:1,20,STAINED_CLAY:12,15,STAINED_CLAY:15,5,AIR,7,IRON_BARS,12,CONCRETE:7,100)
RandomBlock(-7,1,4,CONCRETE:7,60,quark:iron_plate:1,20,STAINED_CLAY:12,15,STAINED_CLAY:15,5,AIR,7,IRON_BARS,12,CONCRETE:7,100)
RandomBlock(-7,1,5,CONCRETE:7,60,quark:iron_plate:1,20,STAINED_CLAY:12,15,STAINED_CLAY:15,5,AIR,7,IRON_BARS,12,CONCRETE:7,100)
RandomBlock(-7,1,6,CONCRETE:7,60,quark:iron_plate:1,20,STAINED_CLAY:12,15,STAINED_CLAY:15,5,AIR,7,IRON_BARS,12,CONCRETE:7,100)
RandomBlock(-7,1,7,CONCRETE:7,60,quark:iron_plate:1,20,STAINED_CLAY:12,15,STAINED_CLAY:15,5,AIR,7,IRON_BARS,12,CONCRETE:7,100)
RandomBlock(-7,1,8,CONCRETE:7,60,quark:iron_plate:1,20,STAINED_CLAY:12,15,STAINED_CLAY:15,5,AIR,7,IRON_BARS,12,CONCRETE:7,100)
RandomBlock(-7,2,-7,CONCRETE:7,60,quark:iron_plate:1,20,STAINED_CLAY:12,15,STAINED_CLAY:15,5,AIR,7,IRON_BARS,12,CONCRETE:7,100)
RandomBlock(-7,2,-6,CONCRETE:7,60,quark:iron_plate:1,20,STAINED_CLAY:12,15,STAINED_CLAY:15,5,AIR,7,IRON_BARS,12,CONCRETE:7,100)
RandomBlock(-7,2,-5,CONCRETE:7,60,quark:iron_plate:1,20,STAINED_CLAY:12,15,STAINED_CLAY:15,5,AIR,7,IRON_BARS,12,CONCRETE:7,100)
Block(-7,2,-4,SMOOTH_STAIRS:3)
Block(-7,2,-3,AIR:0)
Block(-7,2,-2,AIR:0)
Block(-7,2,-1,SMOOTH_STAIRS:2)
RandomBlock(-7,2,0,CONCRETE:7,60,quark:iron_plate:1,20,STAINED_CLAY:12,15,STAINED_CLAY:15,5,AIR,7,IRON_BARS,12,CONCRETE:7,100)
RandomBlock(-7,2,1,CONCRETE:7,60,quark:iron_plate:1,20,STAINED_CLAY:12,15,STAINED_CLAY:15,5,AIR,7,IRON_BARS,12,CONCRETE:7,100)
RandomBlock(-7,2,2,CONCRETE:7,60,quark:iron_plate:1,20,STAINED_CLAY:12,15,STAINED_CLAY:15,5,AIR,7,IRON_BARS,12,CONCRETE:7,100)
RandomBlock(-7,2,3,CONCRETE:7,60,quark:iron_plate:1,20,STAINED_CLAY:12,15,STAINED_CLAY:15,5,AIR,7,IRON_BARS,12,CONCRETE:7,100)
RandomBlock(-7,2,4,CONCRETE:7,60,quark:iron_plate:1,20,STAINED_CLAY:12,15,STAINED_CLAY:15,5,AIR,7,IRON_BARS,12,CONCRETE:7,100)
RandomBlock(-7,2,5,CONCRETE:7,60,quark:iron_plate:1,20,STAINED_CLAY:12,15,STAINED_CLAY:15,5,AIR,7,IRON_BARS,12,CONCRETE:7,100)
RandomBlock(-7,2,6,CONCRETE:7,60,quark:iron_plate:1,20,STAINED_CLAY:12,15,STAINED_CLAY:15,5,AIR,7,IRON_BARS,12,CONCRETE:7,100)
RandomBlock(-7,2,7,CONCRETE:7,60,quark:iron_plate:1,20,STAINED_CLAY:12,15,STAINED_CLAY:15,5,AIR,7,IRON_BARS,12,CONCRETE:7,100)
RandomBlock(-7,2,8,CONCRETE:7,60,quark:iron_plate:1,20,STAINED_CLAY:12,15,STAINED_CLAY:15,5,AIR,7,IRON_BARS,12,CONCRETE:7,100)
Block(-7,3,-7,AIR:0)
Block(-7,3,-6,AIR:0)
Block(-7,3,-5,AIR:0)
Block(-7,3,-4,AIR:0)
Block(-7,3,-3,AIR:0)
Block(-7,3,-2,AIR:0)
Block(-7,3,-1,AIR:0)
Block(-7,3,0,AIR:0)
RandomBlock(-7,3,1,CONCRETE:7,60,quark:iron_plate:1,20,STAINED_CLAY:12,15,STAINED_CLAY:15,5,AIR,7,IRON_BARS,12,CONCRETE:7,100)
RandomBlock(-7,3,2,CONCRETE:7,60,quark:iron_plate:1,20,STAINED_CLAY:12,15,STAINED_CLAY:15,5,AIR,7,IRON_BARS,12,CONCRETE:7,100)
Block(-7,3,3,AIR:0)
Block(-7,3,4,LADDER:2)
RandomBlock(-7,3,5,CONCRETE:7,60,quark:iron_plate:1,20,STAINED_CLAY:12,15,STAINED_CLAY:15,5,AIR,7,IRON_BARS,12,CONCRETE:7,100)
RandomBlock(-7,3,6,CONCRETE:7,60,quark:iron_plate:1,20,STAINED_CLAY:12,15,STAINED_CLAY:15,5,AIR,7,IRON_BARS,12,CONCRETE:7,100)
Block(-7,3,7,AIR:0)
RandomBlock(-7,3,8,CONCRETE:7,60,quark:iron_plate:1,20,STAINED_CLAY:12,15,STAINED_CLAY:15,5,AIR,7,IRON_BARS,12,CONCRETE:7,100)
Block(-7,4,-7,AIR:0)
Block(-7,4,-6,AIR:0)
Block(-7,4,-5,AIR:0)
Block(-7,4,-4,AIR:0)
Block(-7,4,-3,AIR:0)
Block(-7,4,-2,AIR:0)
Block(-7,4,-1,AIR:0)
Block(-7,4,0,AIR:0)
RandomBlock(-7,4,1,CONCRETE:7,60,quark:iron_plate:1,20,STAINED_CLAY:12,15,STAINED_CLAY:15,5,AIR,7,IRON_BARS,12,CONCRETE:7,100)
RandomBlock(-7,4,2,CONCRETE:7,60,quark:iron_plate:1,20,STAINED_CLAY:12,15,STAINED_CLAY:15,5,AIR,7,IRON_BARS,12,CONCRETE:7,100)
Block(-7,4,3,AIR:0)
Block(-7,4,4,LADDER:2)
RandomBlock(-7,4,5,CONCRETE:7,60,quark:iron_plate:1,20,STAINED_CLAY:12,15,STAINED_CLAY:15,5,AIR,7,IRON_BARS,12,CONCRETE:7,100)
RandomBlock(-7,4,6,CONCRETE:7,60,quark:iron_plate:1,20,STAINED_CLAY:12,15,STAINED_CLAY:15,5,AIR,7,IRON_BARS,12,CONCRETE:7,100)
Block(-7,4,7,AIR:0)
RandomBlock(-7,4,8,CONCRETE:7,60,quark:iron_plate:1,20,STAINED_CLAY:12,15,STAINED_CLAY:15,5,AIR,7,IRON_BARS,12,CONCRETE:7,100)
Block(-7,5,-7,AIR:0)
Block(-7,5,-6,CONCRETE:4)
Block(-7,5,-5,CONCRETE:12)
Block(-7,5,-4,AIR:0)
Block(-7,5,-3,AIR:0)
Block(-7,5,-2,AIR:0)
Block(-7,5,-1,AIR:0)
Block(-7,5,0,AIR:0)
RandomBlock(-7,5,1,CONCRETE:7,60,quark:iron_plate:1,20,STAINED_CLAY:12,15,STAINED_CLAY:15,5,AIR,7,IRON_BARS,12,CONCRETE:7,100)
RandomBlock(-7,5,2,CONCRETE:7,60,quark:iron_plate:1,20,STAINED_CLAY:12,15,STAINED_CLAY:15,5,AIR,7,IRON_BARS,12,CONCRETE:7,100)
Block(-7,5,3,AIR:0)
Block(-7,5,4,LADDER:2)
RandomBlock(-7,5,5,CONCRETE:7,60,quark:iron_plate:1,20,STAINED_CLAY:12,15,STAINED_CLAY:15,5,AIR,7,IRON_BARS,12,CONCRETE:7,100)
RandomBlock(-7,5,6,CONCRETE:7,60,quark:iron_plate:1,20,STAINED_CLAY:12,15,STAINED_CLAY:15,5,AIR,7,IRON_BARS,12,CONCRETE:7,100)
Block(-7,5,7,AIR:0)
RandomBlock(-7,5,8,CONCRETE:7,60,quark:iron_plate:1,20,STAINED_CLAY:12,15,STAINED_CLAY:15,5,AIR,7,IRON_BARS,12,CONCRETE:7,100)
Block(-7,6,-7,AIR:0)
Block(-7,6,-6,AIR:0)
Block(-7,6,-5,AIR:0)
Block(-7,6,-4,AIR:0)
Block(-7,6,-3,AIR:0)
Block(-7,6,-2,AIR:0)
Block(-7,6,-1,AIR:0)
Block(-7,6,0,AIR:0)
RandomBlock(-7,6,1,CONCRETE:7,60,quark:iron_plate:1,20,STAINED_CLAY:12,15,STAINED_CLAY:15,5,AIR,7,IRON_BARS,12,CONCRETE:7,100)
RandomBlock(-7,6,2,CONCRETE:7,60,quark:iron_plate:1,20,STAINED_CLAY:12,15,STAINED_CLAY:15,5,AIR,7,IRON_BARS,12,CONCRETE:7,100)
Block(-7,6,3,AIR:0)
Block(-7,6,4,LADDER:2)
RandomBlock(-7,6,5,CONCRETE:7,60,quark:iron_plate:1,20,STAINED_CLAY:12,15,STAINED_CLAY:15,5,AIR,7,IRON_BARS,12,CONCRETE:7,100)
RandomBlock(-7,6,6,CONCRETE:7,60,quark:iron_plate:1,20,STAINED_CLAY:12,15,STAINED_CLAY:15,5,AIR,7,IRON_BARS,12,CONCRETE:7,100)
Block(-7,6,7,AIR:0)
RandomBlock(-7,6,8,CONCRETE:7,60,quark:iron_plate:1,20,STAINED_CLAY:12,15,STAINED_CLAY:15,5,AIR,7,IRON_BARS,12,CONCRETE:7,100)
RandomBlock(-7,7,-7,CONCRETE:7,60,quark:iron_plate:1,20,STAINED_CLAY:12,15,STAINED_CLAY:15,5,AIR,7,IRON_BARS,12,CONCRETE:7,100)
RandomBlock(-7,7,-6,CONCRETE:7,60,quark:iron_plate:1,20,STAINED_CLAY:12,15,STAINED_CLAY:15,5,AIR,7,IRON_BARS,12,CONCRETE:7,100)
RandomBlock(-7,7,-5,CONCRETE:7,60,quark:iron_plate:1,20,STAINED_CLAY:12,15,STAINED_CLAY:15,5,AIR,7,IRON_BARS,12,CONCRETE:7,100)
RandomBlock(-7,7,-4,CONCRETE:7,60,quark:iron_plate:1,20,STAINED_CLAY:12,15,STAINED_CLAY:15,5,AIR,7,IRON_BARS,12,CONCRETE:7,100)
RandomBlock(-7,7,-3,CONCRETE:7,60,quark:iron_plate:1,20,STAINED_CLAY:12,15,STAINED_CLAY:15,5,AIR,7,IRON_BARS,12,CONCRETE:7,100)
RandomBlock(-7,7,-2,CONCRETE:7,60,quark:iron_plate:1,20,STAINED_CLAY:12,15,STAINED_CLAY:15,5,AIR,7,IRON_BARS,12,CONCRETE:7,100)
RandomBlock(-7,7,-1,CONCRETE:7,60,quark:iron_plate:1,20,STAINED_CLAY:12,15,STAINED_CLAY:15,5,AIR,7,IRON_BARS,12,CONCRETE:7,100)
RandomBlock(-7,7,0,CONCRETE:7,60,quark:iron_plate:1,20,STAINED_CLAY:12,15,STAINED_CLAY:15,5,AIR,7,IRON_BARS,12,CONCRETE:7,100)
RandomBlock(-7,7,1,CONCRETE:7,60,quark:iron_plate:1,20,STAINED_CLAY:12,15,STAINED_CLAY:15,5,AIR,7,IRON_BARS,12,CONCRETE:7,100)
RandomBlock(-7,7,2,CONCRETE:7,60,quark:iron_plate:1,20,STAINED_CLAY:12,15,STAINED_CLAY:15,5,AIR,7,IRON_BARS,12,CONCRETE:7,100)
RandomBlock(-7,7,3,CONCRETE:7,60,quark:iron_plate:1,20,STAINED_CLAY:12,15,STAINED_CLAY:15,5,AIR,7,IRON_BARS,12,CONCRETE:7,100)
Block(-7,7,4,LADDER:2)
RandomBlock(-7,7,5,CONCRETE:7,60,quark:iron_plate:1,20,STAINED_CLAY:12,15,STAINED_CLAY:15,5,AIR,7,IRON_BARS,12,CONCRETE:7,100)
RandomBlock(-7,7,6,CONCRETE:7,60,quark:iron_plate:1,20,STAINED_CLAY:12,15,STAINED_CLAY:15,5,AIR,7,IRON_BARS,12,CONCRETE:7,100)
RandomBlock(-7,7,7,CONCRETE:7,60,quark:iron_plate:1,20,STAINED_CLAY:12,15,STAINED_CLAY:15,5,AIR,7,IRON_BARS,12,CONCRETE:7,100)
RandomBlock(-7,7,8,CONCRETE:7,60,quark:iron_plate:1,20,STAINED_CLAY:12,15,STAINED_CLAY:15,5,AIR,7,IRON_BARS,12,CONCRETE:7,100)
Block(-7,8,-7,AIR:0)
Block(-7,8,-6,AIR:0)
Block(-7,8,-5,AIR:0)
Block(-7,8,-4,AIR:0)
Block(-7,8,-3,AIR:0)
Block(-7,8,-2,IRON_FENCE:0)
Block(-7,8,-1,AIR:0)
Block(-7,8,0,AIR:0)
Block(-7,8,1,AIR:0)
Block(-7,8,2,AIR:0)
Block(-7,8,3,AIR:0)
RandomBlock(-7,8,4,AIR,90,TRAP_DOOR:0,100)
RandomBlock(-7,8,5,CONCRETE:7,60,quark:iron_plate:1,20,STAINED_CLAY:12,15,STAINED_CLAY:15,5,AIR,7,IRON_BARS,12,CONCRETE:7,100)
RandomBlock(-7,8,6,CONCRETE:7,60,quark:iron_plate:1,20,STAINED_CLAY:12,15,STAINED_CLAY:15,5,AIR,7,IRON_BARS,12,CONCRETE:7,100)
RandomBlock(-7,8,7,CONCRETE:7,60,quark:iron_plate:1,20,STAINED_CLAY:12,15,STAINED_CLAY:15,5,AIR,7,IRON_BARS,12,CONCRETE:7,100)
RandomBlock(-7,8,8,CONCRETE:7,60,quark:iron_plate:1,20,STAINED_CLAY:12,15,STAINED_CLAY:15,5,AIR,7,IRON_BARS,12,CONCRETE:7,100)
Block(-7,9,-7,AIR:0)
Block(-7,9,-6,AIR:0)
Block(-7,9,-5,AIR:0)
Block(-7,9,-4,AIR:0)
Block(-7,9,-3,AIR:0)
Block(-7,9,-2,IRON_FENCE:0)
Block(-7,9,-1,AIR:0)
Block(-7,9,0,AIR:0)
Block(-7,9,1,AIR:0)
Block(-7,9,2,AIR:0)
Block(-7,9,3,AIR:0)
Block(-7,9,4,AIR:0)
RandomBlock(-7,9,5,CONCRETE:7,60,quark:iron_plate:1,20,STAINED_CLAY:12,15,STAINED_CLAY:15,5,AIR,7,IRON_BARS,12,CONCRETE:7,100)
RandomBlock(-7,9,6,CONCRETE:7,60,quark:iron_plate:1,20,STAINED_CLAY:12,15,STAINED_CLAY:15,5,AIR,7,IRON_BARS,12,CONCRETE:7,100)
RandomBlock(-7,9,7,CONCRETE:7,60,quark:iron_plate:1,20,STAINED_CLAY:12,15,STAINED_CLAY:15,5,AIR,7,IRON_BARS,12,CONCRETE:7,100)
RandomBlock(-7,9,8,CONCRETE:7,60,quark:iron_plate:1,20,STAINED_CLAY:12,15,STAINED_CLAY:15,5,AIR,7,IRON_BARS,12,CONCRETE:7,100)
Block(-7,10,-7,AIR:0)
Block(-7,10,-6,AIR:0)
Block(-7,10,-5,AIR:0)
Block(-7,10,-4,AIR:0)
Block(-7,10,-3,AIR:0)
Block(-7,10,-2,IRON_FENCE:0)
Block(-7,10,-1,AIR:0)
Block(-7,10,0,AIR:0)
Block(-7,10,1,AIR:0)
Block(-7,10,2,AIR:0)
Block(-7,10,3,AIR:0)
Block(-7,10,4,AIR:0)
RandomBlock(-7,10,5,CONCRETE:7,60,quark:iron_plate:1,20,STAINED_CLAY:12,15,STAINED_CLAY:15,5,AIR,7,IRON_BARS,12,CONCRETE:7,100)
RandomBlock(-7,10,6,CONCRETE:7,60,quark:iron_plate:1,20,STAINED_CLAY:12,15,STAINED_CLAY:15,5,AIR,7,IRON_BARS,12,CONCRETE:7,100)
RandomBlock(-7,10,7,CONCRETE:7,60,quark:iron_plate:1,20,STAINED_CLAY:12,15,STAINED_CLAY:15,5,AIR,7,IRON_BARS,12,CONCRETE:7,100)
RandomBlock(-7,10,8,CONCRETE:7,60,quark:iron_plate:1,20,STAINED_CLAY:12,15,STAINED_CLAY:15,5,AIR,7,IRON_BARS,12,CONCRETE:7,100)
Block(-7,11,-7,AIR:0)
Block(-7,11,-6,CONCRETE:14)
Block(-7,11,-5,AIR:0)
Block(-7,11,-4,AIR:0)
Block(-7,11,-3,AIR:0)
Block(-7,11,-2,AIR:0)
Block(-7,11,-1,AIR:0)
Block(-7,11,0,CONCRETE:12)
Block(-7,11,1,AIR:0)
Block(-7,11,2,CONCRETE:4)
Block(-7,11,3,AIR:0)
Block(-7,11,4,AIR:0)
RandomBlock(-7,11,5,CONCRETE:7,60,quark:iron_plate:1,20,STAINED_CLAY:12,15,STAINED_CLAY:15,5,AIR,7,IRON_BARS,12,CONCRETE:7,100)
RandomBlock(-7,11,6,CONCRETE:7,60,quark:iron_plate:1,20,STAINED_CLAY:12,15,STAINED_CLAY:15,5,AIR,7,IRON_BARS,12,CONCRETE:7,100)
RandomBlock(-7,11,7,CONCRETE:7,60,quark:iron_plate:1,20,STAINED_CLAY:12,15,STAINED_CLAY:15,5,AIR,7,IRON_BARS,12,CONCRETE:7,100)
RandomBlock(-7,11,8,CONCRETE:7,60,quark:iron_plate:1,20,STAINED_CLAY:12,15,STAINED_CLAY:15,5,AIR,7,IRON_BARS,12,CONCRETE:7,100)
Block(-7,12,-7,AIR:0)
Block(-7,12,-6,AIR:0)
Block(-7,12,-5,AIR:0)
Block(-7,12,-4,AIR:0)
Block(-7,12,-3,AIR:0)
Block(-7,12,-2,AIR:0)
Block(-7,12,-1,AIR:0)
Block(-7,12,0,AIR:0)
Block(-7,12,1,AIR:0)
Block(-7,12,2,AIR:0)
Block(-7,12,3,AIR:0)
Block(-7,12,4,AIR:0)
RandomBlock(-7,12,5,CONCRETE:7,60,quark:iron_plate:1,20,STAINED_CLAY:12,15,STAINED_CLAY:15,5,AIR,7,IRON_BARS,12,CONCRETE:7,100)
RandomBlock(-7,12,6,CONCRETE:7,60,quark:iron_plate:1,20,STAINED_CLAY:12,15,STAINED_CLAY:15,5,AIR,7,IRON_BARS,12,CONCRETE:7,100)
RandomBlock(-7,12,7,CONCRETE:7,60,quark:iron_plate:1,20,STAINED_CLAY:12,15,STAINED_CLAY:15,5,AIR,7,IRON_BARS,12,CONCRETE:7,100)
RandomBlock(-7,12,8,CONCRETE:7,60,quark:iron_plate:1,20,STAINED_CLAY:12,15,STAINED_CLAY:15,5,AIR,7,IRON_BARS,12,CONCRETE:7,100)
Block(-7,13,-7,CONCRETE:8)
Block(-7,13,-6,CONCRETE:8)
Block(-7,13,-5,CONCRETE:8)
Block(-7,13,-4,CONCRETE:8)
Block(-7,13,-3,CONCRETE:8)
Block(-7,13,-2,CONCRETE:8)
Block(-7,13,-1,CONCRETE:8)
Block(-7,13,0,CONCRETE:8)
Block(-7,13,1,CONCRETE:8)
Block(-7,13,2,CONCRETE:8)
Block(-7,13,3,CONCRETE:8)
Block(-7,13,4,CONCRETE:8)
Block(-7,13,5,CONCRETE:8)
Block(-7,13,6,CONCRETE:8)
Block(-7,13,7,CONCRETE:8)
Block(-7,13,8,CONCRETE:8)
Block(-7,14,-7,CONCRETE:8)
Block(-7,14,-6,STEP:0)
RandomBlock(-7,14,-5,STONE:6,80,STONE:6,90,STONEBRICK:0,100)
Block(-7,14,-4,CONCRETE:8)
RandomBlock(-7,14,-3,STONE:6,80,STONE:6,90,STONEBRICK:0,100)
Block(-7,14,-2,STEP:0)
Block(-7,14,-1,CONCRETE:8)
Block(-7,14,0,AIR:0)
Block(-7,14,1,AIR:0)
Block(-7,14,2,AIR:0)
Block(-7,14,3,QUARTZ_STAIRS:3)
Block(-7,14,4,CONCRETE:8)
Block(-7,14,5,CONCRETE:8)
Block(-7,14,6,CONCRETE:8)
Block(-7,14,7,CONCRETE:8)
Block(-7,14,8,STEP:15)
RandomBlock(-7,15,-7,CONCRETE:7,60,quark:iron_plate:1,20,STAINED_CLAY:12,15,STAINED_CLAY:15,5,AIR,7,IRON_BARS,12,CONCRETE:7,100)
Block(-7,15,-6,AIR:0)
RandomBlock(-7,15,-5,AIR,90,TRAP_DOOR:4,100)
RandomBlock(-7,15,-4,CONCRETE:7,60,quark:iron_plate:1,20,STAINED_CLAY:12,15,STAINED_CLAY:15,5,AIR,7,IRON_BARS,12,CONCRETE:7,100)
RandomBlock(-7,15,-3,AIR,90,TRAP_DOOR:5,100)
Block(-7,15,-2,AIR:0)
RandomBlock(-7,15,-1,CONCRETE:7,60,quark:iron_plate:1,20,STAINED_CLAY:12,15,STAINED_CLAY:15,5,AIR,7,IRON_BARS,12,CONCRETE:7,100)
Block(-7,15,0,AIR:0)
Block(-7,15,1,AIR:0)
Block(-7,15,2,AIR:0)
Block(-7,15,3,TRIPWIRE_HOOK:2)
RandomBlock(-7,15,4,CONCRETE:7,60,quark:iron_plate:1,20,STAINED_CLAY:12,15,STAINED_CLAY:15,5,AIR,7,IRON_BARS,12,CONCRETE:7,100)
RandomBlock(-7,15,5,CONCRETE:7,60,quark:iron_plate:1,20,STAINED_CLAY:12,15,STAINED_CLAY:15,5,AIR,7,IRON_BARS,12,CONCRETE:7,100)
Block(-7,15,6,CONCRETE:8)
RandomBlock(-7,15,7,CONCRETE:7,60,quark:iron_plate:1,20,STAINED_CLAY:12,15,STAINED_CLAY:15,5,AIR,7,IRON_BARS,12,CONCRETE:7,100)
RandomBlock(-7,15,8,AIR,90,IRON_TRAPDOOR:9,100)
RandomBlock(-7,16,-7,CONCRETE:7,60,quark:iron_plate:1,20,STAINED_CLAY:12,15,STAINED_CLAY:15,5,AIR,7,IRON_BARS,12,CONCRETE:7,100)
Block(-7,16,-6,AIR:0)
Block(-7,16,-5,AIR:0)
RandomBlock(-7,16,-4,CONCRETE:7,60,quark:iron_plate:1,20,STAINED_CLAY:12,15,STAINED_CLAY:15,5,AIR,7,IRON_BARS,12,CONCRETE:7,100)
Block(-7,16,-3,AIR:0)
Block(-7,16,-2,AIR:0)
RandomBlock(-7,16,-1,CONCRETE:7,60,quark:iron_plate:1,20,STAINED_CLAY:12,15,STAINED_CLAY:15,5,AIR,7,IRON_BARS,12,CONCRETE:7,100)
Block(-7,16,0,AIR:0)
Block(-7,16,1,AIR:0)
Block(-7,16,2,AIR:0)
Block(-7,16,3,AIR:0)
RandomBlock(-7,16,4,CONCRETE:7,60,quark:iron_plate:1,20,STAINED_CLAY:12,15,STAINED_CLAY:15,5,AIR,7,IRON_BARS,12,CONCRETE:7,100)
RandomBlock(-7,16,5,CONCRETE:7,60,quark:iron_plate:1,20,STAINED_CLAY:12,15,STAINED_CLAY:15,5,AIR,7,IRON_BARS,12,CONCRETE:7,100)
Block(-7,16,6,CONCRETE:8)
RandomBlock(-7,16,7,CONCRETE:7,60,quark:iron_plate:1,20,STAINED_CLAY:12,15,STAINED_CLAY:15,5,AIR,7,IRON_BARS,12,CONCRETE:7,100)
Block(-7,16,8,AIR:0)
RandomBlock(-7,17,-7,CONCRETE:7,60,quark:iron_plate:1,20,STAINED_CLAY:12,15,STAINED_CLAY:15,5,AIR,7,IRON_BARS,12,CONCRETE:7,100)
RandomBlock(-7,17,-6,CONCRETE:7,60,quark:iron_plate:1,20,STAINED_CLAY:12,15,STAINED_CLAY:15,5,AIR,7,IRON_BARS,12,CONCRETE:7,100)
RandomBlock(-7,17,-5,CONCRETE:7,60,quark:iron_plate:1,20,STAINED_CLAY:12,15,STAINED_CLAY:15,5,AIR,7,IRON_BARS,12,CONCRETE:7,100)
RandomBlock(-7,17,-4,CONCRETE:7,60,quark:iron_plate:1,20,STAINED_CLAY:12,15,STAINED_CLAY:15,5,AIR,7,IRON_BARS,12,CONCRETE:7,100)
RandomBlock(-7,17,-3,CONCRETE:7,60,quark:iron_plate:1,20,STAINED_CLAY:12,15,STAINED_CLAY:15,5,AIR,7,IRON_BARS,12,CONCRETE:7,100)
RandomBlock(-7,17,-2,CONCRETE:7,60,quark:iron_plate:1,20,STAINED_CLAY:12,15,STAINED_CLAY:15,5,AIR,7,IRON_BARS,12,CONCRETE:7,100)
RandomBlock(-7,17,-1,CONCRETE:7,60,quark:iron_plate:1,20,STAINED_CLAY:12,15,STAINED_CLAY:15,5,AIR,7,IRON_BARS,12,CONCRETE:7,100)
RandomBlock(-7,17,0,CONCRETE:7,60,quark:iron_plate:1,20,STAINED_CLAY:12,15,STAINED_CLAY:15,5,AIR,7,IRON_BARS,12,CONCRETE:7,100)
RandomBlock(-7,17,1,CONCRETE:7,60,quark:iron_plate:1,20,STAINED_CLAY:12,15,STAINED_CLAY:15,5,AIR,7,IRON_BARS,12,CONCRETE:7,100)
RandomBlock(-7,17,2,CONCRETE:7,60,quark:iron_plate:1,20,STAINED_CLAY:12,15,STAINED_CLAY:15,5,AIR,7,IRON_BARS,12,CONCRETE:7,100)
RandomBlock(-7,17,3,CONCRETE:7,60,quark:iron_plate:1,20,STAINED_CLAY:12,15,STAINED_CLAY:15,5,AIR,7,IRON_BARS,12,CONCRETE:7,100)
RandomBlock(-7,17,4,CONCRETE:7,60,quark:iron_plate:1,20,STAINED_CLAY:12,15,STAINED_CLAY:15,5,AIR,7,IRON_BARS,12,CONCRETE:7,100)
RandomBlock(-7,17,5,CONCRETE:7,60,quark:iron_plate:1,20,STAINED_CLAY:12,15,STAINED_CLAY:15,5,AIR,7,IRON_BARS,12,CONCRETE:7,100)
RandomBlock(-7,17,6,CONCRETE:7,60,quark:iron_plate:1,20,STAINED_CLAY:12,15,STAINED_CLAY:15,5,AIR,7,IRON_BARS,12,CONCRETE:7,100)
RandomBlock(-7,17,7,CONCRETE:7,60,quark:iron_plate:1,20,STAINED_CLAY:12,15,STAINED_CLAY:15,5,AIR,7,IRON_BARS,12,CONCRETE:7,100)
RandomBlock(-7,17,8,CONCRETE:7,60,quark:iron_plate:1,20,STAINED_CLAY:12,15,STAINED_CLAY:15,5,AIR,7,IRON_BARS,12,CONCRETE:7,100)
Block(-7,18,0,CARPET:8)
Block(-7,18,1,CARPET:8)
Block(-7,18,2,CARPET:8)
Block(-7,23,-6,CONCRETE:0)
Block(-7,23,2,CONCRETE:0)
Block(-7,24,-6,CONCRETE:0)
Block(-7,24,-4,minecraft:black_glazed_terracotta)
Block(-7,24,-2,CONCRETE:15)
Block(-7,24,0,CONCRETE:0)
Block(-7,24,2,CONCRETE:0)
Block(-7,24,4,minecraft:black_glazed_terracotta)
Block(-7,24,6,CONCRETE:0)
Block(-7,24,8,CONCRETE:15)
Block(-7,25,-7,CONCRETE:15)
Block(-7,25,-6,CONCRETE:15)
Block(-7,25,-5,CONCRETE:15)
Block(-7,25,-4,CONCRETE:15)
Block(-7,25,-3,CONCRETE:15)
Block(-7,25,-2,CONCRETE:15)
Block(-7,25,-1,CONCRETE:15)
Block(-7,25,0,CONCRETE:15)
Block(-7,25,1,CONCRETE:15)
Block(-7,25,2,CONCRETE:15)
Block(-7,25,3,CONCRETE:15)
Block(-7,25,4,CONCRETE:15)
Block(-7,25,5,CONCRETE:15)
Block(-7,25,6,CONCRETE:15)
Block(-7,25,7,CONCRETE:15)
Block(-7,25,8,CONCRETE:15)
Block(-7,26,-6,CARPET:13)
Block(-7,26,-4,CONCRETE:0)
Block(-7,26,-3,CONCRETE:0)
Block(-7,26,-2,CONCRETE:0)
Block(-7,26,-1,CONCRETE:0)
Block(-7,26,0,CONCRETE:0)
Block(-7,26,1,CONCRETE:0)
Block(-7,26,2,CONCRETE:0)
Block(-7,26,3,CONCRETE:0)
Block(-7,26,4,CONCRETE:0)
Block(-7,26,5,CONCRETE:0)
Block(-7,26,6,CONCRETE:0)
Block(-7,26,8,CARPET:13)
Block(-7,27,-4,CONCRETE:0)
Block(-7,27,-3,STAINED_GLASS_PANE:15)
Block(-7,27,-2,STAINED_GLASS_PANE:15)
Block(-7,27,-1,STAINED_GLASS_PANE:15)
Block(-7,27,0,STAINED_GLASS_PANE:15)
Block(-7,27,1,CONCRETE:0)
Block(-7,27,2,STAINED_GLASS_PANE:15)
Block(-7,27,3,STAINED_GLASS_PANE:15)
Block(-7,27,4,STAINED_GLASS_PANE:15)
Block(-7,27,5,STAINED_GLASS_PANE:15)
Block(-7,27,6,CONCRETE:0)
Block(-7,28,-4,CONCRETE:0)
Block(-7,28,-3,CONCRETE:0)
Block(-7,28,-2,CONCRETE:0)
Block(-7,28,-1,CONCRETE:0)
Block(-7,28,0,CONCRETE:0)
Block(-7,28,1,CONCRETE:0)
Block(-7,28,2,CONCRETE:0)
Block(-7,28,3,CONCRETE:0)
Block(-7,28,4,CONCRETE:0)
Block(-7,28,5,CONCRETE:0)
Block(-7,28,6,CONCRETE:0)
Block(-7,29,-7,CONCRETE:15)
Block(-7,29,-6,CONCRETE:15)
Block(-7,29,-5,CONCRETE:15)
Block(-7,29,-4,CONCRETE:15)
Block(-7,29,-3,CONCRETE:15)
Block(-7,29,-2,CONCRETE:15)
Block(-7,29,-1,CONCRETE:15)
Block(-7,29,0,CONCRETE:15)
Block(-7,29,1,CONCRETE:15)
Block(-7,29,2,CONCRETE:15)
Block(-7,29,3,CONCRETE:15)
Block(-7,29,4,CONCRETE:15)
Block(-7,29,5,CONCRETE:15)
Block(-7,29,6,CONCRETE:15)
Block(-7,29,7,CONCRETE:15)
Block(-7,29,8,CONCRETE:15)
Block(-7,30,-7,BIRCH_WOOD_STAIRS:2)
Block(-7,30,-6,BIRCH_DOOR:1)
RandomBlock(-7,30,-4,AIR,90,AIR:0,100)
Block(-7,30,-2,STEP:15)
RandomBlock(-7,30,-1,AIR,90,AIR:0,100)
RandomBlock(-7,30,4,CONCRETE:7,60,quark:iron_plate:1,20,STAINED_CLAY:12,15,STAINED_CLAY:15,5,AIR,7,IRON_BARS,12,CONCRETE:7,100)
RandomBlock(-7,30,5,AIR,90,TRAP_DOOR:6,100)
Block(-7,30,7,BIRCH_DOOR:3)
Block(-7,30,8,WOOD_STEP:2)
RandomBlock(-7,31,-7,AIR,95,WALL_BANNER:2,../AllScraperData/skyscraper_3x3_03/331-bannerC16R16.nbt,100)
Block(-7,31,-6,BIRCH_DOOR:11)
RandomBlock(-7,31,4,CONCRETE:7,60,quark:iron_plate:1,20,STAINED_CLAY:12,15,STAINED_CLAY:15,5,AIR,7,IRON_BARS,12,CONCRETE:7,100)
Block(-7,31,7,BIRCH_DOOR:10)
RandomBlock(-7,31,8,AIR,95,WALL_BANNER:3,../AllScraperData/skyscraper_3x3_03/332-bannerC16R16.nbt,100)
RandomBlock(-7,32,4,CONCRETE:7,60,quark:iron_plate:1,20,STAINED_CLAY:12,15,STAINED_CLAY:15,5,AIR,7,IRON_BARS,12,CONCRETE:7,100)
Block(-7,33,-7,CONCRETE:15)
Block(-7,33,-6,CONCRETE:15)
Block(-7,33,-5,CONCRETE:15)
Block(-7,33,-4,CONCRETE:15)
Block(-7,33,-3,CONCRETE:15)
Block(-7,33,-2,CONCRETE:15)
Block(-7,33,-1,CONCRETE:15)
Block(-7,33,0,CONCRETE:15)
Block(-7,33,1,CONCRETE:15)
Block(-7,33,2,CONCRETE:15)
Block(-7,33,3,CONCRETE:15)
Block(-7,33,4,CONCRETE:15)
Block(-7,33,5,CONCRETE:15)
Block(-7,33,6,CONCRETE:15)
Block(-7,33,7,CONCRETE:15)
Block(-7,33,8,CONCRETE:15)
Block(-7,34,-1,CARPET:0)
Block(-7,34,0,CARPET:11)
Block(-7,34,1,CARPET:0)
Block(-7,34,2,CARPET:11)
Block(-7,34,3,CARPET:0)
Block(-7,37,-7,CONCRETE:15)
Block(-7,37,-6,CONCRETE:15)
Block(-7,37,-5,CONCRETE:15)
Block(-7,37,-4,CONCRETE:15)
Block(-7,37,-3,CONCRETE:15)
Block(-7,37,-2,CONCRETE:15)
Block(-7,37,-1,CONCRETE:15)
Block(-7,37,0,CONCRETE:15)
Block(-7,37,1,CONCRETE:15)
Block(-7,37,2,CONCRETE:15)
Block(-7,37,3,CONCRETE:15)
Block(-7,37,4,CONCRETE:15)
Block(-7,37,5,CONCRETE:15)
Block(-7,37,6,CONCRETE:15)
Block(-7,37,7,CONCRETE:15)
Block(-7,37,8,CONCRETE:15)
Block(-7,38,-1,CARPET:5)
Block(-7,38,0,CARPET:0)
Block(-7,38,1,CARPET:5)
Block(-7,38,2,CARPET:0)
Block(-7,38,3,CARPET:5)
Block(-7,41,-7,CONCRETE:15)
Block(-7,41,-6,CONCRETE:15)
Block(-7,41,-5,CONCRETE:15)
Block(-7,41,-4,CONCRETE:15)
Block(-7,41,-3,CONCRETE:15)
Block(-7,41,-2,CONCRETE:15)
Block(-7,41,-1,CONCRETE:15)
Block(-7,41,0,CONCRETE:15)
Block(-7,41,1,CONCRETE:15)
Block(-7,41,2,CONCRETE:15)
Block(-7,41,3,CONCRETE:15)
Block(-7,41,4,CONCRETE:15)
Block(-7,41,5,CONCRETE:15)
Block(-7,41,6,CONCRETE:15)
Block(-7,41,7,CONCRETE:15)
Block(-7,41,8,CONCRETE:15)
Block(-7,42,-1,CARPET:0)
Block(-7,42,0,CARPET:11)
Block(-7,42,1,CARPET:0)
Block(-7,42,2,CARPET:11)
Block(-7,42,3,CARPET:0)
Block(-7,45,-7,CONCRETE:15)
Block(-7,45,-6,CONCRETE:15)
Block(-7,45,-5,CONCRETE:15)
Block(-7,45,-4,CONCRETE:15)
Block(-7,45,-3,CONCRETE:15)
Block(-7,45,-2,CONCRETE:15)
Block(-7,45,-1,CONCRETE:15)
Block(-7,45,0,CONCRETE:15)
Block(-7,45,1,CONCRETE:15)
Block(-7,45,2,CONCRETE:15)
Block(-7,45,3,CONCRETE:15)
Block(-7,45,4,CONCRETE:15)
Block(-7,45,5,CONCRETE:15)
Block(-7,45,6,CONCRETE:15)
Block(-7,45,7,CONCRETE:15)
Block(-7,45,8,CONCRETE:15)
Block(-7,46,-1,CARPET:5)
Block(-7,46,0,CARPET:0)
Block(-7,46,1,CARPET:5)
Block(-7,46,2,CARPET:0)
Block(-7,46,3,CARPET:5)
Block(-7,49,-7,CONCRETE:15)
Block(-7,49,-6,CONCRETE:15)
Block(-7,49,-5,CONCRETE:15)
Block(-7,49,-4,CONCRETE:15)
Block(-7,49,-3,CONCRETE:15)
Block(-7,49,-2,CONCRETE:15)
Block(-7,49,-1,CONCRETE:15)
Block(-7,49,0,CONCRETE:15)
Block(-7,49,1,CONCRETE:15)
Block(-7,49,2,CONCRETE:15)
Block(-7,49,3,CONCRETE:15)
Block(-7,49,4,CONCRETE:15)
Block(-7,49,5,CONCRETE:15)
Block(-7,49,6,CONCRETE:15)
Block(-7,49,7,CONCRETE:15)
Block(-7,49,8,CONCRETE:15)
Block(-7,50,-7,BIRCH_WOOD_STAIRS:2)
Block(-7,50,-6,BIRCH_DOOR:1)
RandomBlock(-7,50,-4,AIR,90,AIR:0,100)
Block(-7,50,-2,STEP:15)
RandomBlock(-7,50,-1,AIR,90,AIR:0,100)
RandomBlock(-7,50,4,CONCRETE:7,60,quark:iron_plate:1,20,STAINED_CLAY:12,15,STAINED_CLAY:15,5,AIR,7,IRON_BARS,12,CONCRETE:7,100)
RandomBlock(-7,50,5,AIR,90,TRAP_DOOR:6,100)
Block(-7,50,7,BIRCH_DOOR:3)
Block(-7,50,8,WOOD_STEP:2)
RandomBlock(-7,51,-7,AIR,95,WALL_BANNER:2,../AllScraperData/skyscraper_3x3_03/338-bannerC16R16.nbt,100)
Block(-7,51,-6,BIRCH_DOOR:11)
RandomBlock(-7,51,4,CONCRETE:7,60,quark:iron_plate:1,20,STAINED_CLAY:12,15,STAINED_CLAY:15,5,AIR,7,IRON_BARS,12,CONCRETE:7,100)
Block(-7,51,7,BIRCH_DOOR:10)
RandomBlock(-7,51,8,AIR,95,WALL_BANNER:3,../AllScraperData/skyscraper_3x3_03/339-bannerC16R16.nbt,100)
RandomBlock(-7,52,4,CONCRETE:7,60,quark:iron_plate:1,20,STAINED_CLAY:12,15,STAINED_CLAY:15,5,AIR,7,IRON_BARS,12,CONCRETE:7,100)
Block(-7,53,-7,CONCRETE:15)
Block(-7,53,-6,CONCRETE:15)
Block(-7,53,-5,CONCRETE:15)
Block(-7,53,-4,CONCRETE:15)
Block(-7,53,-3,CONCRETE:15)
Block(-7,53,-2,CONCRETE:15)
Block(-7,53,-1,CONCRETE:15)
Block(-7,53,0,CONCRETE:15)
Block(-7,53,1,CONCRETE:15)
Block(-7,53,2,CONCRETE:15)
Block(-7,53,3,CONCRETE:15)
Block(-7,53,4,CONCRETE:15)
Block(-7,53,5,CONCRETE:15)
Block(-7,53,6,CONCRETE:15)
Block(-7,53,7,CONCRETE:15)
Block(-7,53,8,CONCRETE:15)
Block(-7,54,-1,CARPET:0)
Block(-7,54,0,CARPET:11)
Block(-7,54,1,CARPET:0)
Block(-7,54,2,CARPET:11)
Block(-7,54,3,CARPET:0)
Block(-7,57,-7,CONCRETE:15)
Block(-7,57,-6,CONCRETE:15)
Block(-7,57,-5,CONCRETE:15)
Block(-7,57,-4,CONCRETE:15)
Block(-7,57,-3,CONCRETE:15)
Block(-7,57,-2,CONCRETE:15)
Block(-7,57,-1,CONCRETE:15)
Block(-7,57,0,CONCRETE:15)
Block(-7,57,1,CONCRETE:15)
Block(-7,57,2,CONCRETE:15)
Block(-7,57,3,CONCRETE:15)
Block(-7,57,4,CONCRETE:15)
Block(-7,57,5,CONCRETE:15)
Block(-7,57,6,CONCRETE:15)
Block(-7,57,7,CONCRETE:15)
Block(-7,57,8,CONCRETE:15)
Block(-7,58,-1,CARPET:5)
Block(-7,58,0,CARPET:0)
Block(-7,58,1,CARPET:5)
Block(-7,58,2,CARPET:0)
Block(-7,58,3,CARPET:5)
Block(-7,61,-7,CONCRETE:15)
Block(-7,61,-6,CONCRETE:15)
Block(-7,61,-5,CONCRETE:15)
Block(-7,61,-4,CONCRETE:15)
Block(-7,61,-3,CONCRETE:15)
Block(-7,61,-2,CONCRETE:15)
Block(-7,61,-1,CONCRETE:15)
Block(-7,61,0,CONCRETE:15)
Block(-7,61,1,CONCRETE:15)
Block(-7,61,2,CONCRETE:15)
Block(-7,61,3,CONCRETE:15)
Block(-7,61,4,CONCRETE:15)
Block(-7,61,5,CONCRETE:15)
Block(-7,61,6,CONCRETE:15)
Block(-7,61,7,CONCRETE:15)
Block(-7,61,8,CONCRETE:15)
Block(-7,62,-1,CARPET:0)
Block(-7,62,0,CARPET:11)
Block(-7,62,1,CARPET:0)
Block(-7,62,2,CARPET:11)
Block(-7,62,3,CARPET:0)
Block(-7,65,-7,CONCRETE:15)
Block(-7,65,-6,CONCRETE:15)
Block(-7,65,-5,CONCRETE:15)
Block(-7,65,-4,CONCRETE:15)
Block(-7,65,-3,CONCRETE:15)
Block(-7,65,-2,CONCRETE:15)
Block(-7,65,-1,CONCRETE:15)
Block(-7,65,0,CONCRETE:15)
Block(-7,65,1,CONCRETE:15)
Block(-7,65,2,CONCRETE:15)
Block(-7,65,3,CONCRETE:15)
Block(-7,65,4,CONCRETE:15)
Block(-7,65,5,CONCRETE:15)
Block(-7,65,6,CONCRETE:15)
Block(-7,65,7,CONCRETE:15)
Block(-7,65,8,CONCRETE:15)
Block(-7,66,-1,CARPET:5)
Block(-7,66,0,CARPET:0)
Block(-7,66,1,CARPET:5)
Block(-7,66,2,CARPET:0)
Block(-7,66,3,CARPET:5)
Block(-7,69,-7,CONCRETE:15)
Block(-7,69,-6,CONCRETE:15)
Block(-7,69,-5,CONCRETE:15)
Block(-7,69,-4,CONCRETE:15)
Block(-7,69,-3,CONCRETE:15)
Block(-7,69,-2,CONCRETE:15)
Block(-7,69,-1,CONCRETE:15)
Block(-7,69,0,CONCRETE:15)
Block(-7,69,1,CONCRETE:15)
Block(-7,69,2,CONCRETE:15)
Block(-7,69,3,CONCRETE:15)
Block(-7,69,4,CONCRETE:15)
Block(-7,69,5,CONCRETE:15)
Block(-7,69,6,CONCRETE:15)
Block(-7,69,7,CONCRETE:15)
Block(-7,69,8,CONCRETE:15)
RandomBlock(-6,0,-7,CONCRETE:7,60,quark:iron_plate:1,20,STAINED_CLAY:12,15,STAINED_CLAY:15,5,AIR,7,IRON_BARS,12,CONCRETE:7,100)
RandomBlock(-6,0,-6,CONCRETE:7,60,quark:iron_plate:1,20,STAINED_CLAY:12,15,STAINED_CLAY:15,5,AIR,7,IRON_BARS,12,CONCRETE:7,100)
RandomBlock(-6,0,-5,CONCRETE:7,60,quark:iron_plate:1,20,STAINED_CLAY:12,15,STAINED_CLAY:15,5,AIR,7,IRON_BARS,12,CONCRETE:7,100)
RandomBlock(-6,0,-4,CONCRETE:7,60,quark:iron_plate:1,20,STAINED_CLAY:12,15,STAINED_CLAY:15,5,AIR,7,IRON_BARS,12,CONCRETE:7,100)
RandomBlock(-6,0,-3,CONCRETE:7,60,quark:iron_plate:1,20,STAINED_CLAY:12,15,STAINED_CLAY:15,5,AIR,7,IRON_BARS,12,CONCRETE:7,100)
RandomBlock(-6,0,-2,CONCRETE:7,60,quark:iron_plate:1,20,STAINED_CLAY:12,15,STAINED_CLAY:15,5,AIR,7,IRON_BARS,12,CONCRETE:7,100)
RandomBlock(-6,0,-1,CONCRETE:7,60,quark:iron_plate:1,20,STAINED_CLAY:12,15,STAINED_CLAY:15,5,AIR,7,IRON_BARS,12,CONCRETE:7,100)
RandomBlock(-6,0,0,CONCRETE:7,60,quark:iron_plate:1,20,STAINED_CLAY:12,15,STAINED_CLAY:15,5,AIR,7,IRON_BARS,12,CONCRETE:7,100)
RandomBlock(-6,0,1,CONCRETE:7,60,quark:iron_plate:1,20,STAINED_CLAY:12,15,STAINED_CLAY:15,5,AIR,7,IRON_BARS,12,CONCRETE:7,100)
RandomBlock(-6,0,2,CONCRETE:7,60,quark:iron_plate:1,20,STAINED_CLAY:12,15,STAINED_CLAY:15,5,AIR,7,IRON_BARS,12,CONCRETE:7,100)
RandomBlock(-6,0,3,CONCRETE:7,60,quark:iron_plate:1,20,STAINED_CLAY:12,15,STAINED_CLAY:15,5,AIR,7,IRON_BARS,12,CONCRETE:7,100)
RandomBlock(-6,0,4,CONCRETE:7,60,quark:iron_plate:1,20,STAINED_CLAY:12,15,STAINED_CLAY:15,5,AIR,7,IRON_BARS,12,CONCRETE:7,100)
RandomBlock(-6,0,5,CONCRETE:7,60,quark:iron_plate:1,20,STAINED_CLAY:12,15,STAINED_CLAY:15,5,AIR,7,IRON_BARS,12,CONCRETE:7,100)
RandomBlock(-6,0,6,CONCRETE:7,60,quark:iron_plate:1,20,STAINED_CLAY:12,15,STAINED_CLAY:15,5,AIR,7,IRON_BARS,12,CONCRETE:7,100)
RandomBlock(-6,0,7,CONCRETE:7,60,quark:iron_plate:1,20,STAINED_CLAY:12,15,STAINED_CLAY:15,5,AIR,7,IRON_BARS,12,CONCRETE:7,100)
RandomBlock(-6,0,8,CONCRETE:7,60,quark:iron_plate:1,20,STAINED_CLAY:12,15,STAINED_CLAY:15,5,AIR,7,IRON_BARS,12,CONCRETE:7,100)
RandomBlock(-6,1,-7,CONCRETE:7,60,quark:iron_plate:1,20,STAINED_CLAY:12,15,STAINED_CLAY:15,5,AIR,7,IRON_BARS,12,CONCRETE:7,100)
RandomBlock(-6,1,-6,CONCRETE:7,60,quark:iron_plate:1,20,STAINED_CLAY:12,15,STAINED_CLAY:15,5,AIR,7,IRON_BARS,12,CONCRETE:7,100)
RandomBlock(-6,1,-5,CONCRETE:7,60,quark:iron_plate:1,20,STAINED_CLAY:12,15,STAINED_CLAY:15,5,AIR,7,IRON_BARS,12,CONCRETE:7,100)
RandomBlock(-6,1,-4,CONCRETE:7,60,quark:iron_plate:1,20,STAINED_CLAY:12,15,STAINED_CLAY:15,5,AIR,7,IRON_BARS,12,CONCRETE:7,100)
Block(-6,1,-3,STATIONARY_WATER:0)
Block(-6,1,-2,STATIONARY_WATER:0)
RandomBlock(-6,1,-1,CONCRETE:7,60,quark:iron_plate:1,20,STAINED_CLAY:12,15,STAINED_CLAY:15,5,AIR,7,IRON_BARS,12,CONCRETE:7,100)
RandomBlock(-6,1,0,CONCRETE:7,60,quark:iron_plate:1,20,STAINED_CLAY:12,15,STAINED_CLAY:15,5,AIR,7,IRON_BARS,12,CONCRETE:7,100)
RandomBlock(-6,1,1,CONCRETE:7,60,quark:iron_plate:1,20,STAINED_CLAY:12,15,STAINED_CLAY:15,5,AIR,7,IRON_BARS,12,CONCRETE:7,100)
RandomBlock(-6,1,2,CONCRETE:7,60,quark:iron_plate:1,20,STAINED_CLAY:12,15,STAINED_CLAY:15,5,AIR,7,IRON_BARS,12,CONCRETE:7,100)
RandomBlock(-6,1,3,CONCRETE:7,60,quark:iron_plate:1,20,STAINED_CLAY:12,15,STAINED_CLAY:15,5,AIR,7,IRON_BARS,12,CONCRETE:7,100)
RandomBlock(-6,1,4,CONCRETE:7,60,quark:iron_plate:1,20,STAINED_CLAY:12,15,STAINED_CLAY:15,5,AIR,7,IRON_BARS,12,CONCRETE:7,100)
RandomBlock(-6,1,5,CONCRETE:7,60,quark:iron_plate:1,20,STAINED_CLAY:12,15,STAINED_CLAY:15,5,AIR,7,IRON_BARS,12,CONCRETE:7,100)
RandomBlock(-6,1,6,CONCRETE:7,60,quark:iron_plate:1,20,STAINED_CLAY:12,15,STAINED_CLAY:15,5,AIR,7,IRON_BARS,12,CONCRETE:7,100)
RandomBlock(-6,1,7,CONCRETE:7,60,quark:iron_plate:1,20,STAINED_CLAY:12,15,STAINED_CLAY:15,5,AIR,7,IRON_BARS,12,CONCRETE:7,100)
RandomBlock(-6,1,8,CONCRETE:7,60,quark:iron_plate:1,20,STAINED_CLAY:12,15,STAINED_CLAY:15,5,AIR,7,IRON_BARS,12,CONCRETE:7,100)
RandomBlock(-6,2,-7,CONCRETE:7,60,quark:iron_plate:1,20,STAINED_CLAY:12,15,STAINED_CLAY:15,5,AIR,7,IRON_BARS,12,CONCRETE:7,100)
RandomBlock(-6,2,-6,CONCRETE:7,60,quark:iron_plate:1,20,STAINED_CLAY:12,15,STAINED_CLAY:15,5,AIR,7,IRON_BARS,12,CONCRETE:7,100)
RandomBlock(-6,2,-5,CONCRETE:7,60,quark:iron_plate:1,20,STAINED_CLAY:12,15,STAINED_CLAY:15,5,AIR,7,IRON_BARS,12,CONCRETE:7,100)
Block(-6,2,-4,SMOOTH_STAIRS:3)
Block(-6,2,-3,AIR:0)
Block(-6,2,-2,AIR:0)
Block(-6,2,-1,SMOOTH_STAIRS:2)
RandomBlock(-6,2,0,CONCRETE:7,60,quark:iron_plate:1,20,STAINED_CLAY:12,15,STAINED_CLAY:15,5,AIR,7,IRON_BARS,12,CONCRETE:7,100)
RandomBlock(-6,2,1,CONCRETE:7,60,quark:iron_plate:1,20,STAINED_CLAY:12,15,STAINED_CLAY:15,5,AIR,7,IRON_BARS,12,CONCRETE:7,100)
RandomBlock(-6,2,2,CONCRETE:7,60,quark:iron_plate:1,20,STAINED_CLAY:12,15,STAINED_CLAY:15,5,AIR,7,IRON_BARS,12,CONCRETE:7,100)
RandomBlock(-6,2,3,CONCRETE:7,60,quark:iron_plate:1,20,STAINED_CLAY:12,15,STAINED_CLAY:15,5,AIR,7,IRON_BARS,12,CONCRETE:7,100)
RandomBlock(-6,2,4,CONCRETE:7,60,quark:iron_plate:1,20,STAINED_CLAY:12,15,STAINED_CLAY:15,5,AIR,7,IRON_BARS,12,CONCRETE:7,100)
RandomBlock(-6,2,5,CONCRETE:7,60,quark:iron_plate:1,20,STAINED_CLAY:12,15,STAINED_CLAY:15,5,AIR,7,IRON_BARS,12,CONCRETE:7,100)
RandomBlock(-6,2,6,CONCRETE:7,60,quark:iron_plate:1,20,STAINED_CLAY:12,15,STAINED_CLAY:15,5,AIR,7,IRON_BARS,12,CONCRETE:7,100)
RandomBlock(-6,2,7,CONCRETE:7,60,quark:iron_plate:1,20,STAINED_CLAY:12,15,STAINED_CLAY:15,5,AIR,7,IRON_BARS,12,CONCRETE:7,100)
RandomBlock(-6,2,8,CONCRETE:7,60,quark:iron_plate:1,20,STAINED_CLAY:12,15,STAINED_CLAY:15,5,AIR,7,IRON_BARS,12,CONCRETE:7,100)
Block(-6,3,-7,AIR:0)
Block(-6,3,-6,AIR:0)
Block(-6,3,-5,AIR:0)
Block(-6,3,-4,AIR:0)
Block(-6,3,-3,AIR:0)
Block(-6,3,-2,AIR:0)
Block(-6,3,-1,AIR:0)
Block(-6,3,0,AIR:0)
RandomBlock(-6,3,1,CONCRETE:7,60,quark:iron_plate:1,20,STAINED_CLAY:12,15,STAINED_CLAY:15,5,AIR,7,IRON_BARS,12,CONCRETE:7,100)
RandomBlock(-6,3,2,CONCRETE:7,60,quark:iron_plate:1,20,STAINED_CLAY:12,15,STAINED_CLAY:15,5,AIR,7,IRON_BARS,12,CONCRETE:7,100)
Block(-6,3,3,AIR:0)
Block(-6,3,4,AIR:0)
RandomBlock(-6,3,5,CONCRETE:7,60,quark:iron_plate:1,20,STAINED_CLAY:12,15,STAINED_CLAY:15,5,AIR,7,IRON_BARS,12,CONCRETE:7,100)
RandomBlock(-6,3,6,CONCRETE:7,60,quark:iron_plate:1,20,STAINED_CLAY:12,15,STAINED_CLAY:15,5,AIR,7,IRON_BARS,12,CONCRETE:7,100)
Block(-6,3,7,AIR:0)
RandomBlock(-6,3,8,CONCRETE:7,60,quark:iron_plate:1,20,STAINED_CLAY:12,15,STAINED_CLAY:15,5,AIR,7,IRON_BARS,12,CONCRETE:7,100)
Block(-6,4,-7,AIR:0)
Block(-6,4,-6,AIR:0)
Block(-6,4,-5,AIR:0)
Block(-6,4,-4,AIR:0)
Block(-6,4,-3,AIR:0)
Block(-6,4,-2,AIR:0)
Block(-6,4,-1,AIR:0)
Block(-6,4,0,AIR:0)
RandomBlock(-6,4,1,CONCRETE:7,60,quark:iron_plate:1,20,STAINED_CLAY:12,15,STAINED_CLAY:15,5,AIR,7,IRON_BARS,12,CONCRETE:7,100)
RandomBlock(-6,4,2,CONCRETE:7,60,quark:iron_plate:1,20,STAINED_CLAY:12,15,STAINED_CLAY:15,5,AIR,7,IRON_BARS,12,CONCRETE:7,100)
Block(-6,4,3,AIR:0)
Block(-6,4,4,AIR:0)
RandomBlock(-6,4,5,CONCRETE:7,60,quark:iron_plate:1,20,STAINED_CLAY:12,15,STAINED_CLAY:15,5,AIR,7,IRON_BARS,12,CONCRETE:7,100)
RandomBlock(-6,4,6,CONCRETE:7,60,quark:iron_plate:1,20,STAINED_CLAY:12,15,STAINED_CLAY:15,5,AIR,7,IRON_BARS,12,CONCRETE:7,100)
Block(-6,4,7,AIR:0)
RandomBlock(-6,4,8,CONCRETE:7,60,quark:iron_plate:1,20,STAINED_CLAY:12,15,STAINED_CLAY:15,5,AIR,7,IRON_BARS,12,CONCRETE:7,100)
Block(-6,5,-7,AIR:0)
Block(-6,5,-6,CONCRETE:4)
Block(-6,5,-5,CONCRETE:12)
Block(-6,5,-4,CONCRETE:12)
Block(-6,5,-3,CONCRETE:12)
Block(-6,5,-2,CONCRETE:12)
Block(-6,5,-1,CONCRETE:12)
Block(-6,5,0,CONCRETE:12)
RandomBlock(-6,5,1,CONCRETE:7,60,quark:iron_plate:1,20,STAINED_CLAY:12,15,STAINED_CLAY:15,5,AIR,7,IRON_BARS,12,CONCRETE:7,100)
RandomBlock(-6,5,2,CONCRETE:7,60,quark:iron_plate:1,20,STAINED_CLAY:12,15,STAINED_CLAY:15,5,AIR,7,IRON_BARS,12,CONCRETE:7,100)
Block(-6,5,3,AIR:0)
Block(-6,5,4,AIR:0)
RandomBlock(-6,5,5,CONCRETE:7,60,quark:iron_plate:1,20,STAINED_CLAY:12,15,STAINED_CLAY:15,5,AIR,7,IRON_BARS,12,CONCRETE:7,100)
RandomBlock(-6,5,6,CONCRETE:7,60,quark:iron_plate:1,20,STAINED_CLAY:12,15,STAINED_CLAY:15,5,AIR,7,IRON_BARS,12,CONCRETE:7,100)
Block(-6,5,7,AIR:0)
RandomBlock(-6,5,8,CONCRETE:7,60,quark:iron_plate:1,20,STAINED_CLAY:12,15,STAINED_CLAY:15,5,AIR,7,IRON_BARS,12,CONCRETE:7,100)
Block(-6,6,-7,AIR:0)
Block(-6,6,-6,IRON_FENCE:0)
Block(-6,6,-5,AIR:0)
Block(-6,6,-4,AIR:0)
Block(-6,6,-3,AIR:0)
Block(-6,6,-2,IRON_FENCE:0)
Block(-6,6,-1,AIR:0)
Block(-6,6,0,CONCRETE:12)
RandomBlock(-6,6,1,CONCRETE:7,60,quark:iron_plate:1,20,STAINED_CLAY:12,15,STAINED_CLAY:15,5,AIR,7,IRON_BARS,12,CONCRETE:7,100)
RandomBlock(-6,6,2,CONCRETE:7,60,quark:iron_plate:1,20,STAINED_CLAY:12,15,STAINED_CLAY:15,5,AIR,7,IRON_BARS,12,CONCRETE:7,100)
Block(-6,6,3,AIR:0)
Block(-6,6,4,AIR:0)
RandomBlock(-6,6,5,CONCRETE:7,60,quark:iron_plate:1,20,STAINED_CLAY:12,15,STAINED_CLAY:15,5,AIR,7,IRON_BARS,12,CONCRETE:7,100)
RandomBlock(-6,6,6,CONCRETE:7,60,quark:iron_plate:1,20,STAINED_CLAY:12,15,STAINED_CLAY:15,5,AIR,7,IRON_BARS,12,CONCRETE:7,100)
Block(-6,6,7,AIR:0)
RandomBlock(-6,6,8,CONCRETE:7,60,quark:iron_plate:1,20,STAINED_CLAY:12,15,STAINED_CLAY:15,5,AIR,7,IRON_BARS,12,CONCRETE:7,100)
RandomBlock(-6,7,-7,CONCRETE:7,60,quark:iron_plate:1,20,STAINED_CLAY:12,15,STAINED_CLAY:15,5,AIR,7,IRON_BARS,12,CONCRETE:7,100)
RandomBlock(-6,7,-6,CONCRETE:7,60,quark:iron_plate:1,20,STAINED_CLAY:12,15,STAINED_CLAY:15,5,AIR,7,IRON_BARS,12,CONCRETE:7,100)
RandomBlock(-6,7,-5,CONCRETE:7,60,quark:iron_plate:1,20,STAINED_CLAY:12,15,STAINED_CLAY:15,5,AIR,7,IRON_BARS,12,CONCRETE:7,100)
RandomBlock(-6,7,-4,CONCRETE:7,60,quark:iron_plate:1,20,STAINED_CLAY:12,15,STAINED_CLAY:15,5,AIR,7,IRON_BARS,12,CONCRETE:7,100)
RandomBlock(-6,7,-3,CONCRETE:7,60,quark:iron_plate:1,20,STAINED_CLAY:12,15,STAINED_CLAY:15,5,AIR,7,IRON_BARS,12,CONCRETE:7,100)
RandomBlock(-6,7,-2,CONCRETE:7,60,quark:iron_plate:1,20,STAINED_CLAY:12,15,STAINED_CLAY:15,5,AIR,7,IRON_BARS,12,CONCRETE:7,100)
RandomBlock(-6,7,-1,CONCRETE:7,60,quark:iron_plate:1,20,STAINED_CLAY:12,15,STAINED_CLAY:15,5,AIR,7,IRON_BARS,12,CONCRETE:7,100)
Block(-6,7,0,CONCRETE:12)
RandomBlock(-6,7,1,CONCRETE:7,60,quark:iron_plate:1,20,STAINED_CLAY:12,15,STAINED_CLAY:15,5,AIR,7,IRON_BARS,12,CONCRETE:7,100)
RandomBlock(-6,7,2,CONCRETE:7,60,quark:iron_plate:1,20,STAINED_CLAY:12,15,STAINED_CLAY:15,5,AIR,7,IRON_BARS,12,CONCRETE:7,100)
RandomBlock(-6,7,3,CONCRETE:7,60,quark:iron_plate:1,20,STAINED_CLAY:12,15,STAINED_CLAY:15,5,AIR,7,IRON_BARS,12,CONCRETE:7,100)
RandomBlock(-6,7,4,CONCRETE:7,60,quark:iron_plate:1,20,STAINED_CLAY:12,15,STAINED_CLAY:15,5,AIR,7,IRON_BARS,12,CONCRETE:7,100)
RandomBlock(-6,7,5,CONCRETE:7,60,quark:iron_plate:1,20,STAINED_CLAY:12,15,STAINED_CLAY:15,5,AIR,7,IRON_BARS,12,CONCRETE:7,100)
RandomBlock(-6,7,6,CONCRETE:7,60,quark:iron_plate:1,20,STAINED_CLAY:12,15,STAINED_CLAY:15,5,AIR,7,IRON_BARS,12,CONCRETE:7,100)
RandomBlock(-6,7,7,CONCRETE:7,60,quark:iron_plate:1,20,STAINED_CLAY:12,15,STAINED_CLAY:15,5,AIR,7,IRON_BARS,12,CONCRETE:7,100)
RandomBlock(-6,7,8,CONCRETE:7,60,quark:iron_plate:1,20,STAINED_CLAY:12,15,STAINED_CLAY:15,5,AIR,7,IRON_BARS,12,CONCRETE:7,100)
Block(-6,8,-7,IRON_FENCE:0)
Block(-6,8,-6,IRON_FENCE:0)
RandomBlock(-6,8,-5,CONCRETE:7,60,quark:iron_plate:1,20,STAINED_CLAY:12,15,STAINED_CLAY:15,5,AIR,7,IRON_BARS,12,CONCRETE:7,100)
Block(-6,8,-4,IRON_DOOR_BLOCK:1)
RandomBlock(-6,8,-3,CONCRETE:7,60,quark:iron_plate:1,20,STAINED_CLAY:12,15,STAINED_CLAY:15,5,AIR,7,IRON_BARS,12,CONCRETE:7,100)
RandomBlock(-6,8,-2,CONCRETE:7,60,quark:iron_plate:1,20,STAINED_CLAY:12,15,STAINED_CLAY:15,5,AIR,7,IRON_BARS,12,CONCRETE:7,100)
Block(-6,8,-1,AIR:0)
Block(-6,8,0,CONCRETE:12)
Block(-6,8,1,AIR:0)
Block(-6,8,2,AIR:0)
Block(-6,8,3,AIR:0)
Block(-6,8,4,AIR:0)
Block(-6,8,5,AIR:0)
Block(-6,8,6,AIR:0)
RandomBlock(-6,8,7,CONCRETE:7,60,quark:iron_plate:1,20,STAINED_CLAY:12,15,STAINED_CLAY:15,5,AIR,7,IRON_BARS,12,CONCRETE:7,100)
RandomBlock(-6,8,8,CONCRETE:7,60,quark:iron_plate:1,20,STAINED_CLAY:12,15,STAINED_CLAY:15,5,AIR,7,IRON_BARS,12,CONCRETE:7,100)
Block(-6,9,-7,IRON_FENCE:0)
Block(-6,9,-6,IRON_FENCE:0)
RandomBlock(-6,9,-5,CONCRETE:7,60,quark:iron_plate:1,20,STAINED_CLAY:12,15,STAINED_CLAY:15,5,AIR,7,IRON_BARS,12,CONCRETE:7,100)
Block(-6,9,-4,IRON_DOOR_BLOCK:11)
RandomBlock(-6,9,-3,CONCRETE:7,60,quark:iron_plate:1,20,STAINED_CLAY:12,15,STAINED_CLAY:15,5,AIR,7,IRON_BARS,12,CONCRETE:7,100)
RandomBlock(-6,9,-2,CONCRETE:7,60,quark:iron_plate:1,20,STAINED_CLAY:12,15,STAINED_CLAY:15,5,AIR,7,IRON_BARS,12,CONCRETE:7,100)
Block(-6,9,-1,AIR:0)
Block(-6,9,0,CONCRETE:12)
Block(-6,9,1,AIR:0)
Block(-6,9,2,AIR:0)
Block(-6,9,3,AIR:0)
Block(-6,9,4,AIR:0)
Block(-6,9,5,AIR:0)
Block(-6,9,6,AIR:0)
RandomBlock(-6,9,7,CONCRETE:7,60,quark:iron_plate:1,20,STAINED_CLAY:12,15,STAINED_CLAY:15,5,AIR,7,IRON_BARS,12,CONCRETE:7,100)
RandomBlock(-6,9,8,CONCRETE:7,60,quark:iron_plate:1,20,STAINED_CLAY:12,15,STAINED_CLAY:15,5,AIR,7,IRON_BARS,12,CONCRETE:7,100)
Block(-6,10,-7,IRON_FENCE:0)
Block(-6,10,-6,IRON_FENCE:0)
RandomBlock(-6,10,-5,CONCRETE:7,60,quark:iron_plate:1,20,STAINED_CLAY:12,15,STAINED_CLAY:15,5,AIR,7,IRON_BARS,12,CONCRETE:7,100)
RandomBlock(-6,10,-4,CONCRETE:7,60,quark:iron_plate:1,20,STAINED_CLAY:12,15,STAINED_CLAY:15,5,AIR,7,IRON_BARS,12,CONCRETE:7,100)
RandomBlock(-6,10,-3,CONCRETE:7,60,quark:iron_plate:1,20,STAINED_CLAY:12,15,STAINED_CLAY:15,5,AIR,7,IRON_BARS,12,CONCRETE:7,100)
RandomBlock(-6,10,-2,CONCRETE:7,60,quark:iron_plate:1,20,STAINED_CLAY:12,15,STAINED_CLAY:15,5,AIR,7,IRON_BARS,12,CONCRETE:7,100)
Block(-6,10,-1,AIR:0)
Block(-6,10,0,CONCRETE:12)
Block(-6,10,1,AIR:0)
Block(-6,10,2,AIR:0)
Block(-6,10,3,AIR:0)
Block(-6,10,4,AIR:0)
Block(-6,10,5,AIR:0)
Block(-6,10,6,AIR:0)
RandomBlock(-6,10,7,CONCRETE:7,60,quark:iron_plate:1,20,STAINED_CLAY:12,15,STAINED_CLAY:15,5,AIR,7,IRON_BARS,12,CONCRETE:7,100)
RandomBlock(-6,10,8,CONCRETE:7,60,quark:iron_plate:1,20,STAINED_CLAY:12,15,STAINED_CLAY:15,5,AIR,7,IRON_BARS,12,CONCRETE:7,100)
Block(-6,11,-7,AIR:0)
Block(-6,11,-6,CONCRETE:14)
RandomBlock(-6,11,-5,CONCRETE:7,60,quark:iron_plate:1,20,STAINED_CLAY:12,15,STAINED_CLAY:15,5,AIR,7,IRON_BARS,12,CONCRETE:7,100)
Block(-6,11,-4,AIR:0)
RandomBlock(-6,11,-3,CONCRETE:7,60,quark:iron_plate:1,20,STAINED_CLAY:12,15,STAINED_CLAY:15,5,AIR,7,IRON_BARS,12,CONCRETE:7,100)
RandomBlock(-6,11,-2,CONCRETE:7,60,quark:iron_plate:1,20,STAINED_CLAY:12,15,STAINED_CLAY:15,5,AIR,7,IRON_BARS,12,CONCRETE:7,100)
Block(-6,11,-1,AIR:0)
Block(-6,11,0,CONCRETE:12)
Block(-6,11,1,AIR:0)
Block(-6,11,2,CONCRETE:4)
Block(-6,11,3,AIR:0)
Block(-6,11,4,AIR:0)
Block(-6,11,5,AIR:0)
Block(-6,11,6,AIR:0)
RandomBlock(-6,11,7,CONCRETE:7,60,quark:iron_plate:1,20,STAINED_CLAY:12,15,STAINED_CLAY:15,5,AIR,7,IRON_BARS,12,CONCRETE:7,100)
RandomBlock(-6,11,8,CONCRETE:7,60,quark:iron_plate:1,20,STAINED_CLAY:12,15,STAINED_CLAY:15,5,AIR,7,IRON_BARS,12,CONCRETE:7,100)
Block(-6,12,-7,AIR:0)
Block(-6,12,-6,AIR:0)
RandomBlock(-6,12,-5,CONCRETE:7,60,quark:iron_plate:1,20,STAINED_CLAY:12,15,STAINED_CLAY:15,5,AIR,7,IRON_BARS,12,CONCRETE:7,100)
Block(-6,12,-4,AIR:0)
RandomBlock(-6,12,-3,CONCRETE:7,60,quark:iron_plate:1,20,STAINED_CLAY:12,15,STAINED_CLAY:15,5,AIR,7,IRON_BARS,12,CONCRETE:7,100)
RandomBlock(-6,12,-2,CONCRETE:7,60,quark:iron_plate:1,20,STAINED_CLAY:12,15,STAINED_CLAY:15,5,AIR,7,IRON_BARS,12,CONCRETE:7,100)
Block(-6,12,-1,AIR:0)
Block(-6,12,0,IRON_FENCE:0)
Block(-6,12,1,AIR:0)
Block(-6,12,2,IRON_FENCE:0)
Block(-6,12,3,AIR:0)
Block(-6,12,4,AIR:0)
Block(-6,12,5,AIR:0)
Block(-6,12,6,AIR:0)
RandomBlock(-6,12,7,CONCRETE:7,60,quark:iron_plate:1,20,STAINED_CLAY:12,15,STAINED_CLAY:15,5,AIR,7,IRON_BARS,12,CONCRETE:7,100)
RandomBlock(-6,12,8,CONCRETE:7,60,quark:iron_plate:1,20,STAINED_CLAY:12,15,STAINED_CLAY:15,5,AIR,7,IRON_BARS,12,CONCRETE:7,100)
Block(-6,13,-7,CONCRETE:8)
Block(-6,13,-6,CONCRETE:8)
Block(-6,13,-5,CONCRETE:8)
Block(-6,13,-4,CONCRETE:8)
Block(-6,13,-3,CONCRETE:8)
Block(-6,13,-2,CONCRETE:8)
Block(-6,13,-1,CONCRETE:8)
Block(-6,13,0,CONCRETE:8)
Block(-6,13,1,CONCRETE:8)
Block(-6,13,2,CONCRETE:8)
Block(-6,13,3,CONCRETE:8)
Block(-6,13,4,CONCRETE:8)
Block(-6,13,5,CONCRETE:8)
Block(-6,13,6,CONCRETE:8)
Block(-6,13,7,CONCRETE:8)
Block(-6,13,8,CONCRETE:8)
Block(-6,14,-7,SPRUCE_DOOR:3)
Block(-6,14,-6,AIR:0)
RandomBlock(-6,14,-5,STONE:6,85,CAULDRON:3,100)
Block(-6,14,-4,CONCRETE:8)
Block(-6,14,-3,AIR:0)
Block(-6,14,-2,AIR:0)
Block(-6,14,-1,SPRUCE_DOOR:1)
Block(-6,14,0,AIR:0)
Block(-6,14,1,AIR:0)
Block(-6,14,2,AIR:0)
Block(-6,14,3,QUARTZ_STAIRS:3)
Block(-6,14,4,CONCRETE:8)
Block(-6,14,5,CONCRETE:8)
Block(-6,14,6,CONCRETE:8)
Block(-6,14,7,CONCRETE:8)
Block(-6,14,8,QUARTZ_STAIRS:4)
Block(-6,15,-7,SPRUCE_DOOR:11)
Block(-6,15,-6,AIR:0)
Block(-6,15,-5,TRIPWIRE_HOOK:2)
RandomBlock(-6,15,-4,CONCRETE:7,60,quark:iron_plate:1,20,STAINED_CLAY:12,15,STAINED_CLAY:15,5,AIR,7,IRON_BARS,12,CONCRETE:7,100)
Block(-6,15,-3,AIR:0)
Block(-6,15,-2,AIR:0)
Block(-6,15,-1,SPRUCE_DOOR:11)
Block(-6,15,0,AIR:0)
Block(-6,15,1,AIR:0)
Block(-6,15,2,AIR:0)
Block(-6,15,3,AIR:0)
RandomBlock(-6,15,4,CONCRETE:7,60,quark:iron_plate:1,20,STAINED_CLAY:12,15,STAINED_CLAY:15,5,AIR,7,IRON_BARS,12,CONCRETE:7,100)
RandomBlock(-6,15,5,CONCRETE:7,60,quark:iron_plate:1,20,STAINED_CLAY:12,15,STAINED_CLAY:15,5,AIR,7,IRON_BARS,12,CONCRETE:7,100)
Block(-6,15,6,CONCRETE:8)
RandomBlock(-6,15,7,CONCRETE:7,60,quark:iron_plate:1,20,STAINED_CLAY:12,15,STAINED_CLAY:15,5,AIR,7,IRON_BARS,12,CONCRETE:7,100)
RandomBlock(-6,15,8,AIR,90,IRON_TRAPDOOR:9,100)
RandomBlock(-6,16,-7,AIR,90,TRAP_DOOR:12,100)
Block(-6,16,-6,AIR:0)
Block(-6,16,-5,AIR:0)
RandomBlock(-6,16,-4,CONCRETE:7,60,quark:iron_plate:1,20,STAINED_CLAY:12,15,STAINED_CLAY:15,5,AIR,7,IRON_BARS,12,CONCRETE:7,100)
Block(-6,16,-3,AIR:0)
Block(-6,16,-2,AIR:0)
RandomBlock(-6,16,-1,AIR,90,TRAP_DOOR:13,100)
Block(-6,16,0,AIR:0)
Block(-6,16,1,AIR:0)
Block(-6,16,2,AIR:0)
Block(-6,16,3,AIR:0)
RandomBlock(-6,16,4,CONCRETE:7,60,quark:iron_plate:1,20,STAINED_CLAY:12,15,STAINED_CLAY:15,5,AIR,7,IRON_BARS,12,CONCRETE:7,100)
RandomBlock(-6,16,5,CONCRETE:7,60,quark:iron_plate:1,20,STAINED_CLAY:12,15,STAINED_CLAY:15,5,AIR,7,IRON_BARS,12,CONCRETE:7,100)
Block(-6,16,6,CONCRETE:8)
RandomBlock(-6,16,7,CONCRETE:7,60,quark:iron_plate:1,20,STAINED_CLAY:12,15,STAINED_CLAY:15,5,AIR,7,IRON_BARS,12,CONCRETE:7,100)
Block(-6,16,8,AIR:0)
RandomBlock(-6,17,-7,CONCRETE:7,60,quark:iron_plate:1,20,STAINED_CLAY:12,15,STAINED_CLAY:15,5,AIR,7,IRON_BARS,12,CONCRETE:7,100)
RandomBlock(-6,17,-6,CONCRETE:7,60,quark:iron_plate:1,20,STAINED_CLAY:12,15,STAINED_CLAY:15,5,AIR,7,IRON_BARS,12,CONCRETE:7,100)
RandomBlock(-6,17,-5,CONCRETE:7,60,quark:iron_plate:1,20,STAINED_CLAY:12,15,STAINED_CLAY:15,5,AIR,7,IRON_BARS,12,CONCRETE:7,100)
RandomBlock(-6,17,-4,CONCRETE:7,60,quark:iron_plate:1,20,STAINED_CLAY:12,15,STAINED_CLAY:15,5,AIR,7,IRON_BARS,12,CONCRETE:7,100)
RandomBlock(-6,17,-3,CONCRETE:7,60,quark:iron_plate:1,20,STAINED_CLAY:12,15,STAINED_CLAY:15,5,AIR,7,IRON_BARS,12,CONCRETE:7,100)
RandomBlock(-6,17,-2,CONCRETE:7,60,quark:iron_plate:1,20,STAINED_CLAY:12,15,STAINED_CLAY:15,5,AIR,7,IRON_BARS,12,CONCRETE:7,100)
RandomBlock(-6,17,-1,CONCRETE:7,60,quark:iron_plate:1,20,STAINED_CLAY:12,15,STAINED_CLAY:15,5,AIR,7,IRON_BARS,12,CONCRETE:7,100)
RandomBlock(-6,17,0,CONCRETE:7,60,quark:iron_plate:1,20,STAINED_CLAY:12,15,STAINED_CLAY:15,5,AIR,7,IRON_BARS,12,CONCRETE:7,100)
RandomBlock(-6,17,1,CONCRETE:7,60,quark:iron_plate:1,20,STAINED_CLAY:12,15,STAINED_CLAY:15,5,AIR,7,IRON_BARS,12,CONCRETE:7,100)
RandomBlock(-6,17,2,CONCRETE:7,60,quark:iron_plate:1,20,STAINED_CLAY:12,15,STAINED_CLAY:15,5,AIR,7,IRON_BARS,12,CONCRETE:7,100)
RandomBlock(-6,17,3,CONCRETE:7,60,quark:iron_plate:1,20,STAINED_CLAY:12,15,STAINED_CLAY:15,5,AIR,7,IRON_BARS,12,CONCRETE:7,100)
RandomBlock(-6,17,4,CONCRETE:7,60,quark:iron_plate:1,20,STAINED_CLAY:12,15,STAINED_CLAY:15,5,AIR,7,IRON_BARS,12,CONCRETE:7,100)
RandomBlock(-6,17,5,CONCRETE:7,60,quark:iron_plate:1,20,STAINED_CLAY:12,15,STAINED_CLAY:15,5,AIR,7,IRON_BARS,12,CONCRETE:7,100)
RandomBlock(-6,17,6,CONCRETE:7,60,quark:iron_plate:1,20,STAINED_CLAY:12,15,STAINED_CLAY:15,5,AIR,7,IRON_BARS,12,CONCRETE:7,100)
RandomBlock(-6,17,7,CONCRETE:7,60,quark:iron_plate:1,20,STAINED_CLAY:12,15,STAINED_CLAY:15,5,AIR,7,IRON_BARS,12,CONCRETE:7,100)
RandomBlock(-6,17,8,CONCRETE:7,60,quark:iron_plate:1,20,STAINED_CLAY:12,15,STAINED_CLAY:15,5,AIR,7,IRON_BARS,12,CONCRETE:7,100)
RandomBlock(-6,18,-2,AIR,90,TRAP_DOOR:14,100)
Block(-6,18,0,CARPET:8)
Block(-6,18,1,CARPET:8)
Block(-6,18,2,CARPET:8)
RandomBlock(-6,18,4,AIR,90,TRAP_DOOR:14,100)
RandomBlock(-6,21,-6,AIR,90,TRAP_DOOR:6,100)
Block(-6,25,-7,CONCRETE:15)
Block(-6,25,-6,CONCRETE:15)
Block(-6,25,-5,CONCRETE:15)
Block(-6,25,-4,CONCRETE:15)
Block(-6,25,-3,CONCRETE:15)
Block(-6,25,-2,CONCRETE:15)
Block(-6,25,-1,CONCRETE:15)
Block(-6,25,0,CONCRETE:15)
Block(-6,25,1,CONCRETE:15)
Block(-6,25,2,CONCRETE:15)
Block(-6,25,3,CONCRETE:15)
Block(-6,25,4,CONCRETE:15)
Block(-6,25,5,CONCRETE:15)
Block(-6,25,6,CONCRETE:15)
Block(-6,25,7,CONCRETE:15)
Block(-6,25,8,CONCRETE:15)
Block(-6,26,-6,CARPET:13)
Block(-6,26,8,CARPET:13)
Block(-6,29,-7,CONCRETE:15)
Block(-6,29,-6,CONCRETE:15)
Block(-6,29,-5,CONCRETE:15)
Block(-6,29,-4,CONCRETE:15)
Block(-6,29,-3,CONCRETE:15)
Block(-6,29,-2,CONCRETE:15)
Block(-6,29,-1,CONCRETE:15)
Block(-6,29,0,CONCRETE:15)
Block(-6,29,1,CONCRETE:15)
Block(-6,29,2,CONCRETE:15)
Block(-6,29,3,CONCRETE:15)
Block(-6,29,4,CONCRETE:15)
Block(-6,29,5,CONCRETE:15)
Block(-6,29,6,CONCRETE:15)
Block(-6,29,7,CONCRETE:15)
Block(-6,29,8,CONCRETE:15)
RandomBlock(-6,30,-7,AIR,90,AIR:0,100)
Block(-6,30,-5,BIRCH_DOOR:3)
Block(-6,30,-4,BIRCH_WOOD_STAIRS:3)
Block(-6,30,-3,DOUBLE_STEP:7)
Block(-6,30,-2,DOUBLE_STEP:7)
Block(-6,30,1,QUARTZ_STAIRS:4)
Block(-6,30,2,QUARTZ_STAIRS:4)
RandomBlock(-6,30,3,AIR,90,TRAP_DOOR:9,100)
RandomBlock(-6,30,4,CONCRETE:7,60,quark:iron_plate:1,20,STAINED_CLAY:12,15,STAINED_CLAY:15,5,AIR,7,IRON_BARS,12,CONCRETE:7,100)
Block(-6,30,5,WOOD_STEP:2)
Block(-6,31,-5,BIRCH_DOOR:11)
RandomBlock(-6,31,-4,AIR,95,WALL_BANNER:3,../AllScraperData/skyscraper_3x3_03/350-bannerC16R16.nbt,100)
Block(-6,31,-3,CARPET:8)
RandomBlock(-6,31,1,AIR,75,AIR:0,100)
Block(-6,31,4,STAINED_GLASS_PANE:10)
RandomBlock(-6,32,4,CONCRETE:7,60,quark:iron_plate:1,20,STAINED_CLAY:12,15,STAINED_CLAY:15,5,AIR,7,IRON_BARS,12,CONCRETE:7,100)
Block(-6,33,-7,CONCRETE:15)
Block(-6,33,-6,CONCRETE:15)
Block(-6,33,-5,CONCRETE:15)
Block(-6,33,-4,CONCRETE:15)
Block(-6,33,-3,CONCRETE:15)
Block(-6,33,-2,CONCRETE:15)
Block(-6,33,-1,CONCRETE:15)
Block(-6,33,0,CONCRETE:15)
Block(-6,33,1,CONCRETE:15)
Block(-6,33,2,CONCRETE:15)
Block(-6,33,3,CONCRETE:15)
Block(-6,33,4,CONCRETE:15)
Block(-6,33,5,CONCRETE:15)
Block(-6,33,6,CONCRETE:15)
Block(-6,33,7,CONCRETE:15)
Block(-6,33,8,CONCRETE:15)
Block(-6,34,-1,CARPET:0)
Block(-6,34,0,CARPET:11)
Block(-6,34,1,CARPET:0)
Block(-6,34,2,CARPET:11)
Block(-6,34,3,CARPET:0)
Block(-6,37,-7,CONCRETE:15)
Block(-6,37,-6,CONCRETE:15)
Block(-6,37,-5,CONCRETE:15)
Block(-6,37,-4,CONCRETE:15)
Block(-6,37,-3,CONCRETE:15)
Block(-6,37,-2,CONCRETE:15)
Block(-6,37,-1,CONCRETE:15)
Block(-6,37,0,CONCRETE:15)
Block(-6,37,1,CONCRETE:15)
Block(-6,37,2,CONCRETE:15)
Block(-6,37,3,CONCRETE:15)
Block(-6,37,4,CONCRETE:15)
Block(-6,37,5,CONCRETE:15)
Block(-6,37,6,CONCRETE:15)
Block(-6,37,7,CONCRETE:15)
Block(-6,37,8,CONCRETE:15)
Block(-6,38,-1,CARPET:0)
Block(-6,38,0,CARPET:5)
Block(-6,38,1,CARPET:0)
Block(-6,38,2,CARPET:5)
Block(-6,38,3,CARPET:0)
Block(-6,41,-7,CONCRETE:15)
Block(-6,41,-6,CONCRETE:15)
Block(-6,41,-5,CONCRETE:15)
Block(-6,41,-4,CONCRETE:15)
Block(-6,41,-3,CONCRETE:15)
Block(-6,41,-2,CONCRETE:15)
Block(-6,41,-1,CONCRETE:15)
Block(-6,41,0,CONCRETE:15)
Block(-6,41,1,CONCRETE:15)
Block(-6,41,2,CONCRETE:15)
Block(-6,41,3,CONCRETE:15)
Block(-6,41,4,CONCRETE:15)
Block(-6,41,5,CONCRETE:15)
Block(-6,41,6,CONCRETE:15)
Block(-6,41,7,CONCRETE:15)
Block(-6,41,8,CONCRETE:15)
Block(-6,42,-1,CARPET:0)
Block(-6,42,0,CARPET:11)
Block(-6,42,1,CARPET:0)
Block(-6,42,2,CARPET:11)
Block(-6,42,3,CARPET:0)
Block(-6,45,-7,CONCRETE:15)
Block(-6,45,-6,CONCRETE:15)
Block(-6,45,-5,CONCRETE:15)
Block(-6,45,-4,CONCRETE:15)
Block(-6,45,-3,CONCRETE:15)
Block(-6,45,-2,CONCRETE:15)
Block(-6,45,-1,CONCRETE:15)
Block(-6,45,0,CONCRETE:15)
Block(-6,45,1,CONCRETE:15)
Block(-6,45,2,CONCRETE:15)
Block(-6,45,3,CONCRETE:15)
Block(-6,45,4,CONCRETE:15)
Block(-6,45,5,CONCRETE:15)
Block(-6,45,6,CONCRETE:15)
Block(-6,45,7,CONCRETE:15)
Block(-6,45,8,CONCRETE:15)
Block(-6,46,-1,CARPET:0)
Block(-6,46,0,CARPET:5)
Block(-6,46,1,CARPET:0)
Block(-6,46,2,CARPET:5)
Block(-6,46,3,CARPET:0)
Block(-6,49,-7,CONCRETE:15)
Block(-6,49,-6,CONCRETE:15)
Block(-6,49,-5,CONCRETE:15)
Block(-6,49,-4,CONCRETE:15)
Block(-6,49,-3,CONCRETE:15)
Block(-6,49,-2,CONCRETE:15)
Block(-6,49,-1,CONCRETE:15)
Block(-6,49,0,CONCRETE:15)
Block(-6,49,1,CONCRETE:15)
Block(-6,49,2,CONCRETE:15)
Block(-6,49,3,CONCRETE:15)
Block(-6,49,4,CONCRETE:15)
Block(-6,49,5,CONCRETE:15)
Block(-6,49,6,CONCRETE:15)
Block(-6,49,7,CONCRETE:15)
Block(-6,49,8,CONCRETE:15)
RandomBlock(-6,50,-7,AIR,90,AIR:0,100)
Block(-6,50,-5,BIRCH_DOOR:3)
Block(-6,50,-4,BIRCH_WOOD_STAIRS:3)
Block(-6,50,-3,DOUBLE_STEP:7)
Block(-6,50,-2,DOUBLE_STEP:7)
Block(-6,50,1,QUARTZ_STAIRS:4)
Block(-6,50,2,QUARTZ_STAIRS:4)
RandomBlock(-6,50,3,AIR,90,TRAP_DOOR:9,100)
RandomBlock(-6,50,4,CONCRETE:7,60,quark:iron_plate:1,20,STAINED_CLAY:12,15,STAINED_CLAY:15,5,AIR,7,IRON_BARS,12,CONCRETE:7,100)
Block(-6,50,5,WOOD_STEP:2)
Block(-6,51,-5,BIRCH_DOOR:11)
RandomBlock(-6,51,-4,AIR,95,WALL_BANNER:3,../AllScraperData/skyscraper_3x3_03/360-bannerC16R16.nbt,100)
Block(-6,51,-3,CARPET:8)
RandomBlock(-6,51,1,AIR,75,AIR:0,100)
Block(-6,51,4,STAINED_GLASS_PANE:10)
RandomBlock(-6,52,4,CONCRETE:7,60,quark:iron_plate:1,20,STAINED_CLAY:12,15,STAINED_CLAY:15,5,AIR,7,IRON_BARS,12,CONCRETE:7,100)
Block(-6,53,-7,CONCRETE:15)
Block(-6,53,-6,CONCRETE:15)
Block(-6,53,-5,CONCRETE:15)
Block(-6,53,-4,CONCRETE:15)
Block(-6,53,-3,CONCRETE:15)
Block(-6,53,-2,CONCRETE:15)
Block(-6,53,-1,CONCRETE:15)
Block(-6,53,0,CONCRETE:15)
Block(-6,53,1,CONCRETE:15)
Block(-6,53,2,CONCRETE:15)
Block(-6,53,3,CONCRETE:15)
Block(-6,53,4,CONCRETE:15)
Block(-6,53,5,CONCRETE:15)
Block(-6,53,6,CONCRETE:15)
Block(-6,53,7,CONCRETE:15)
Block(-6,53,8,CONCRETE:15)
Block(-6,54,-1,CARPET:0)
Block(-6,54,0,CARPET:11)
Block(-6,54,1,CARPET:0)
Block(-6,54,2,CARPET:11)
Block(-6,54,3,CARPET:0)
Block(-6,57,-7,CONCRETE:15)
Block(-6,57,-6,CONCRETE:15)
Block(-6,57,-5,CONCRETE:15)
Block(-6,57,-4,CONCRETE:15)
Block(-6,57,-3,CONCRETE:15)
Block(-6,57,-2,CONCRETE:15)
Block(-6,57,-1,CONCRETE:15)
Block(-6,57,0,CONCRETE:15)
Block(-6,57,1,CONCRETE:15)
Block(-6,57,2,CONCRETE:15)
Block(-6,57,3,CONCRETE:15)
Block(-6,57,4,CONCRETE:15)
Block(-6,57,5,CONCRETE:15)
Block(-6,57,6,CONCRETE:15)
Block(-6,57,7,CONCRETE:15)
Block(-6,57,8,CONCRETE:15)
Block(-6,58,-1,CARPET:0)
Block(-6,58,0,CARPET:5)
Block(-6,58,1,CARPET:0)
Block(-6,58,2,CARPET:5)
Block(-6,58,3,CARPET:0)
Block(-6,61,-7,CONCRETE:15)
Block(-6,61,-6,CONCRETE:15)
Block(-6,61,-5,CONCRETE:15)
Block(-6,61,-4,CONCRETE:15)
Block(-6,61,-3,CONCRETE:15)
Block(-6,61,-2,CONCRETE:15)
Block(-6,61,-1,CONCRETE:15)
Block(-6,61,0,CONCRETE:15)
Block(-6,61,1,CONCRETE:15)
Block(-6,61,2,CONCRETE:15)
Block(-6,61,3,CONCRETE:15)
Block(-6,61,4,CONCRETE:15)
Block(-6,61,5,CONCRETE:15)
Block(-6,61,6,CONCRETE:15)
Block(-6,61,7,CONCRETE:15)
Block(-6,61,8,CONCRETE:15)
Block(-6,62,-1,CARPET:0)
Block(-6,62,0,CARPET:11)
Block(-6,62,1,CARPET:0)
Block(-6,62,2,CARPET:11)
Block(-6,62,3,CARPET:0)
Block(-6,65,-7,CONCRETE:15)
Block(-6,65,-6,CONCRETE:15)
Block(-6,65,-5,CONCRETE:15)
Block(-6,65,-4,CONCRETE:15)
Block(-6,65,-3,CONCRETE:15)
Block(-6,65,-2,CONCRETE:15)
Block(-6,65,-1,CONCRETE:15)
Block(-6,65,0,CONCRETE:15)
Block(-6,65,1,CONCRETE:15)
Block(-6,65,2,CONCRETE:15)
Block(-6,65,3,CONCRETE:15)
Block(-6,65,4,CONCRETE:15)
Block(-6,65,5,CONCRETE:15)
Block(-6,65,6,CONCRETE:15)
Block(-6,65,7,CONCRETE:15)
Block(-6,65,8,CONCRETE:15)
Block(-6,66,-1,CARPET:0)
Block(-6,66,0,CARPET:5)
Block(-6,66,1,CARPET:0)
Block(-6,66,2,CARPET:5)
Block(-6,66,3,CARPET:0)
Block(-6,69,-7,CONCRETE:15)
Block(-6,69,-6,CONCRETE:15)
Block(-6,69,-5,CONCRETE:15)
Block(-6,69,-4,CONCRETE:15)
Block(-6,69,-3,CONCRETE:15)
Block(-6,69,-2,CONCRETE:15)
Block(-6,69,-1,CONCRETE:15)
Block(-6,69,0,CONCRETE:15)
Block(-6,69,1,CONCRETE:15)
Block(-6,69,2,CONCRETE:15)
Block(-6,69,3,CONCRETE:15)
Block(-6,69,4,CONCRETE:15)
Block(-6,69,5,CONCRETE:15)
Block(-6,69,6,CONCRETE:15)
Block(-6,69,7,CONCRETE:15)
Block(-6,69,8,CONCRETE:15)
RandomBlock(-5,0,-7,CONCRETE:7,60,quark:iron_plate:1,20,STAINED_CLAY:12,15,STAINED_CLAY:15,5,AIR,7,IRON_BARS,12,CONCRETE:7,100)
RandomBlock(-5,0,-6,CONCRETE:7,60,quark:iron_plate:1,20,STAINED_CLAY:12,15,STAINED_CLAY:15,5,AIR,7,IRON_BARS,12,CONCRETE:7,100)
RandomBlock(-5,0,-5,CONCRETE:7,60,quark:iron_plate:1,20,STAINED_CLAY:12,15,STAINED_CLAY:15,5,AIR,7,IRON_BARS,12,CONCRETE:7,100)
RandomBlock(-5,0,-4,CONCRETE:7,60,quark:iron_plate:1,20,STAINED_CLAY:12,15,STAINED_CLAY:15,5,AIR,7,IRON_BARS,12,CONCRETE:7,100)
RandomBlock(-5,0,-3,CONCRETE:7,60,quark:iron_plate:1,20,STAINED_CLAY:12,15,STAINED_CLAY:15,5,AIR,7,IRON_BARS,12,CONCRETE:7,100)
RandomBlock(-5,0,-2,CONCRETE:7,60,quark:iron_plate:1,20,STAINED_CLAY:12,15,STAINED_CLAY:15,5,AIR,7,IRON_BARS,12,CONCRETE:7,100)
RandomBlock(-5,0,-1,CONCRETE:7,60,quark:iron_plate:1,20,STAINED_CLAY:12,15,STAINED_CLAY:15,5,AIR,7,IRON_BARS,12,CONCRETE:7,100)
RandomBlock(-5,0,0,CONCRETE:7,60,quark:iron_plate:1,20,STAINED_CLAY:12,15,STAINED_CLAY:15,5,AIR,7,IRON_BARS,12,CONCRETE:7,100)
RandomBlock(-5,0,1,CONCRETE:7,60,quark:iron_plate:1,20,STAINED_CLAY:12,15,STAINED_CLAY:15,5,AIR,7,IRON_BARS,12,CONCRETE:7,100)
RandomBlock(-5,0,2,CONCRETE:7,60,quark:iron_plate:1,20,STAINED_CLAY:12,15,STAINED_CLAY:15,5,AIR,7,IRON_BARS,12,CONCRETE:7,100)
RandomBlock(-5,0,3,CONCRETE:7,60,quark:iron_plate:1,20,STAINED_CLAY:12,15,STAINED_CLAY:15,5,AIR,7,IRON_BARS,12,CONCRETE:7,100)
RandomBlock(-5,0,4,CONCRETE:7,60,quark:iron_plate:1,20,STAINED_CLAY:12,15,STAINED_CLAY:15,5,AIR,7,IRON_BARS,12,CONCRETE:7,100)
RandomBlock(-5,0,5,CONCRETE:7,60,quark:iron_plate:1,20,STAINED_CLAY:12,15,STAINED_CLAY:15,5,AIR,7,IRON_BARS,12,CONCRETE:7,100)
RandomBlock(-5,0,6,CONCRETE:7,60,quark:iron_plate:1,20,STAINED_CLAY:12,15,STAINED_CLAY:15,5,AIR,7,IRON_BARS,12,CONCRETE:7,100)
RandomBlock(-5,0,7,CONCRETE:7,60,quark:iron_plate:1,20,STAINED_CLAY:12,15,STAINED_CLAY:15,5,AIR,7,IRON_BARS,12,CONCRETE:7,100)
RandomBlock(-5,0,8,CONCRETE:7,60,quark:iron_plate:1,20,STAINED_CLAY:12,15,STAINED_CLAY:15,5,AIR,7,IRON_BARS,12,CONCRETE:7,100)
RandomBlock(-5,1,-7,CONCRETE:7,60,quark:iron_plate:1,20,STAINED_CLAY:12,15,STAINED_CLAY:15,5,AIR,7,IRON_BARS,12,CONCRETE:7,100)
RandomBlock(-5,1,-6,CONCRETE:7,60,quark:iron_plate:1,20,STAINED_CLAY:12,15,STAINED_CLAY:15,5,AIR,7,IRON_BARS,12,CONCRETE:7,100)
RandomBlock(-5,1,-5,CONCRETE:7,60,quark:iron_plate:1,20,STAINED_CLAY:12,15,STAINED_CLAY:15,5,AIR,7,IRON_BARS,12,CONCRETE:7,100)
RandomBlock(-5,1,-4,CONCRETE:7,60,quark:iron_plate:1,20,STAINED_CLAY:12,15,STAINED_CLAY:15,5,AIR,7,IRON_BARS,12,CONCRETE:7,100)
Block(-5,1,-3,STATIONARY_WATER:0)
Block(-5,1,-2,STATIONARY_WATER:0)
RandomBlock(-5,1,-1,CONCRETE:7,60,quark:iron_plate:1,20,STAINED_CLAY:12,15,STAINED_CLAY:15,5,AIR,7,IRON_BARS,12,CONCRETE:7,100)
RandomBlock(-5,1,0,CONCRETE:7,60,quark:iron_plate:1,20,STAINED_CLAY:12,15,STAINED_CLAY:15,5,AIR,7,IRON_BARS,12,CONCRETE:7,100)
RandomBlock(-5,1,1,CONCRETE:7,60,quark:iron_plate:1,20,STAINED_CLAY:12,15,STAINED_CLAY:15,5,AIR,7,IRON_BARS,12,CONCRETE:7,100)
RandomBlock(-5,1,2,CONCRETE:7,60,quark:iron_plate:1,20,STAINED_CLAY:12,15,STAINED_CLAY:15,5,AIR,7,IRON_BARS,12,CONCRETE:7,100)
RandomBlock(-5,1,3,CONCRETE:7,60,quark:iron_plate:1,20,STAINED_CLAY:12,15,STAINED_CLAY:15,5,AIR,7,IRON_BARS,12,CONCRETE:7,100)
RandomBlock(-5,1,4,CONCRETE:7,60,quark:iron_plate:1,20,STAINED_CLAY:12,15,STAINED_CLAY:15,5,AIR,7,IRON_BARS,12,CONCRETE:7,100)
RandomBlock(-5,1,5,CONCRETE:7,60,quark:iron_plate:1,20,STAINED_CLAY:12,15,STAINED_CLAY:15,5,AIR,7,IRON_BARS,12,CONCRETE:7,100)
RandomBlock(-5,1,6,CONCRETE:7,60,quark:iron_plate:1,20,STAINED_CLAY:12,15,STAINED_CLAY:15,5,AIR,7,IRON_BARS,12,CONCRETE:7,100)
RandomBlock(-5,1,7,CONCRETE:7,60,quark:iron_plate:1,20,STAINED_CLAY:12,15,STAINED_CLAY:15,5,AIR,7,IRON_BARS,12,CONCRETE:7,100)
RandomBlock(-5,1,8,CONCRETE:7,60,quark:iron_plate:1,20,STAINED_CLAY:12,15,STAINED_CLAY:15,5,AIR,7,IRON_BARS,12,CONCRETE:7,100)
RandomBlock(-5,2,-7,CONCRETE:7,60,quark:iron_plate:1,20,STAINED_CLAY:12,15,STAINED_CLAY:15,5,AIR,7,IRON_BARS,12,CONCRETE:7,100)
RandomBlock(-5,2,-6,CONCRETE:7,60,quark:iron_plate:1,20,STAINED_CLAY:12,15,STAINED_CLAY:15,5,AIR,7,IRON_BARS,12,CONCRETE:7,100)
RandomBlock(-5,2,-5,CONCRETE:7,60,quark:iron_plate:1,20,STAINED_CLAY:12,15,STAINED_CLAY:15,5,AIR,7,IRON_BARS,12,CONCRETE:7,100)
Block(-5,2,-4,SMOOTH_STAIRS:3)
Block(-5,2,-3,AIR:0)
Block(-5,2,-2,AIR:0)
Block(-5,2,-1,SMOOTH_STAIRS:2)
RandomBlock(-5,2,0,CONCRETE:7,60,quark:iron_plate:1,20,STAINED_CLAY:12,15,STAINED_CLAY:15,5,AIR,7,IRON_BARS,12,CONCRETE:7,100)
RandomBlock(-5,2,1,CONCRETE:7,60,quark:iron_plate:1,20,STAINED_CLAY:12,15,STAINED_CLAY:15,5,AIR,7,IRON_BARS,12,CONCRETE:7,100)
RandomBlock(-5,2,2,CONCRETE:7,60,quark:iron_plate:1,20,STAINED_CLAY:12,15,STAINED_CLAY:15,5,AIR,7,IRON_BARS,12,CONCRETE:7,100)
RandomBlock(-5,2,3,CONCRETE:7,60,quark:iron_plate:1,20,STAINED_CLAY:12,15,STAINED_CLAY:15,5,AIR,7,IRON_BARS,12,CONCRETE:7,100)
RandomBlock(-5,2,4,CONCRETE:7,60,quark:iron_plate:1,20,STAINED_CLAY:12,15,STAINED_CLAY:15,5,AIR,7,IRON_BARS,12,CONCRETE:7,100)
RandomBlock(-5,2,5,CONCRETE:7,60,quark:iron_plate:1,20,STAINED_CLAY:12,15,STAINED_CLAY:15,5,AIR,7,IRON_BARS,12,CONCRETE:7,100)
RandomBlock(-5,2,6,CONCRETE:7,60,quark:iron_plate:1,20,STAINED_CLAY:12,15,STAINED_CLAY:15,5,AIR,7,IRON_BARS,12,CONCRETE:7,100)
RandomBlock(-5,2,7,CONCRETE:7,60,quark:iron_plate:1,20,STAINED_CLAY:12,15,STAINED_CLAY:15,5,AIR,7,IRON_BARS,12,CONCRETE:7,100)
RandomBlock(-5,2,8,CONCRETE:7,60,quark:iron_plate:1,20,STAINED_CLAY:12,15,STAINED_CLAY:15,5,AIR,7,IRON_BARS,12,CONCRETE:7,100)
RandomBlock(-5,3,-7,CONCRETE:7,60,quark:iron_plate:1,20,STAINED_CLAY:12,15,STAINED_CLAY:15,5,AIR,7,IRON_BARS,12,CONCRETE:7,100)
Block(-5,3,-6,AIR:0)
Block(-5,3,-5,AIR:0)
Block(-5,3,-4,AIR:0)
Block(-5,3,-3,AIR:0)
Block(-5,3,-2,AIR:0)
Block(-5,3,-1,AIR:0)
Block(-5,3,0,AIR:0)
Block(-5,3,1,AIR:0)
Block(-5,3,2,AIR:0)
Block(-5,3,3,AIR:0)
Block(-5,3,4,AIR:0)
Block(-5,3,5,AIR:0)
Block(-5,3,6,AIR:0)
Block(-5,3,7,AIR:0)
RandomBlock(-5,3,8,CONCRETE:7,60,quark:iron_plate:1,20,STAINED_CLAY:12,15,STAINED_CLAY:15,5,AIR,7,IRON_BARS,12,CONCRETE:7,100)
RandomBlock(-5,4,-7,CONCRETE:7,60,quark:iron_plate:1,20,STAINED_CLAY:12,15,STAINED_CLAY:15,5,AIR,7,IRON_BARS,12,CONCRETE:7,100)
Block(-5,4,-6,AIR:0)
Block(-5,4,-5,AIR:0)
Block(-5,4,-4,AIR:0)
Block(-5,4,-3,AIR:0)
Block(-5,4,-2,AIR:0)
Block(-5,4,-1,AIR:0)
Block(-5,4,0,AIR:0)
Block(-5,4,1,AIR:0)
Block(-5,4,2,AIR:0)
Block(-5,4,3,AIR:0)
Block(-5,4,4,AIR:0)
Block(-5,4,5,AIR:0)
Block(-5,4,6,AIR:0)
Block(-5,4,7,AIR:0)
RandomBlock(-5,4,8,CONCRETE:7,60,quark:iron_plate:1,20,STAINED_CLAY:12,15,STAINED_CLAY:15,5,AIR,7,IRON_BARS,12,CONCRETE:7,100)
RandomBlock(-5,5,-7,CONCRETE:7,60,quark:iron_plate:1,20,STAINED_CLAY:12,15,STAINED_CLAY:15,5,AIR,7,IRON_BARS,12,CONCRETE:7,100)
Block(-5,5,-6,CONCRETE:4)
Block(-5,5,-5,CONCRETE:12)
Block(-5,5,-4,AIR:0)
Block(-5,5,-3,AIR:0)
Block(-5,5,-2,AIR:0)
Block(-5,5,-1,AIR:0)
Block(-5,5,0,AIR:0)
Block(-5,5,1,AIR:0)
Block(-5,5,2,AIR:0)
Block(-5,5,3,AIR:0)
Block(-5,5,4,AIR:0)
Block(-5,5,5,AIR:0)
Block(-5,5,6,AIR:0)
Block(-5,5,7,AIR:0)
RandomBlock(-5,5,8,CONCRETE:7,60,quark:iron_plate:1,20,STAINED_CLAY:12,15,STAINED_CLAY:15,5,AIR,7,IRON_BARS,12,CONCRETE:7,100)
RandomBlock(-5,6,-7,CONCRETE:7,60,quark:iron_plate:1,20,STAINED_CLAY:12,15,STAINED_CLAY:15,5,AIR,7,IRON_BARS,12,CONCRETE:7,100)
Block(-5,6,-6,AIR:0)
Block(-5,6,-5,AIR:0)
Block(-5,6,-4,AIR:0)
Block(-5,6,-3,AIR:0)
Block(-5,6,-2,AIR:0)
Block(-5,6,-1,AIR:0)
Block(-5,6,0,AIR:0)
Block(-5,6,1,AIR:0)
Block(-5,6,2,AIR:0)
Block(-5,6,3,AIR:0)
Block(-5,6,4,AIR:0)
Block(-5,6,5,AIR:0)
Block(-5,6,6,AIR:0)
Block(-5,6,7,AIR:0)
