
#######################################################################
# +-----------------------------------------------------------------+ #
# |                            BO4 object                           | #
# +-----------------------------------------------------------------+ #
#######################################################################

Author: NLBlackEagle

Description: No description given

SettingsMode: WriteWithoutComments


#######################################################################
# +-----------------------------------------------------------------+ #
# |                          Main settings                          | #
# +-----------------------------------------------------------------+ #
#######################################################################

FixedRotation: 

Frequency: 0

SpawnHeight: highestBlock

UseCenterForHighestBlock: true

##############################
# Height Limits for the BO4. #
##############################

MinHeight: 0

MaxHeight: 255

InheritBO3: 

InheritBO3Rotation: NORTH

OverrideChildSettings: true

OverrideParentHeight: false

CanOverride: false

BranchFrequency: 0

BranchFrequencyGroup: 

MustBeBelowOther: false

MustBeInside: 

CannotBeInside: 

ReplacesBO3: 

MustBeInsideWorldBorders: true
CanSpawnOnWater: true

SpawnOnWaterOnly: false

SpawnUnderWater: false

SpawnAtWaterLevel: false

HeightOffset: 0

RemoveAir: false

ReplaceAbove: 

ReplaceBelow: 

ReplaceWithBiomeBlocks: true

ReplaceWithSurfaceBlock: GRASS

ReplaceWithGroundBlock: DIRT

ReplaceWithStoneBlock: STONE

SmoothRadius: 0

SmoothHeightOffset: 0

SmoothStartTop: false

SmoothStartWood: false

SmoothingSurfaceBlock: 

SmoothingGroundBlock: 

BO3Group: 

IsSpawnPoint: false

DoReplaceBlocks: true


#######################################################################
# +-----------------------------------------------------------------+ #
# |                              Blocks                             | #
# +-----------------------------------------------------------------+ #
#######################################################################

Block(-7,0,-6,minecraft:concrete:0)
Block(-7,0,-5,minecraft:concrete:0)
Block(-7,0,-4,minecraft:concrete:0)
Block(-7,0,-3,minecraft:concrete:0)
Block(-7,0,-2,minecraft:concrete:0)
Block(-7,0,-1,minecraft:concrete:0)
Block(-7,0,0,minecraft:concrete:0)
Block(-7,0,1,minecraft:concrete:0)
Block(-7,0,2,minecraft:concrete:0)
Block(-7,0,3,minecraft:concrete:0)
Block(-7,0,4,minecraft:concrete:0)
Block(-7,0,5,minecraft:concrete:0)
Block(-7,0,6,minecraft:concrete:0)
Block(-7,0,7,minecraft:concrete:0)
Block(-7,0,8,minecraft:concrete:0)
Block(-7,0,9,minecraft:concrete:0)
Block(-7,1,-6,minecraft:concrete:0)
Block(-7,1,-5,minecraft:concrete:0)
Block(-7,1,-4,minecraft:concrete:0)
Block(-7,1,-3,minecraft:concrete:0)
Block(-7,1,-2,minecraft:concrete:0)
Block(-7,1,-1,minecraft:concrete:0)
Block(-7,1,0,minecraft:concrete:0)
Block(-7,1,1,minecraft:concrete:0)
Block(-7,1,2,minecraft:concrete:0)
Block(-7,1,3,minecraft:concrete:0)
Block(-7,1,4,minecraft:concrete:0)
Block(-7,1,5,minecraft:concrete:0)
Block(-7,1,6,minecraft:concrete:0)
Block(-7,1,7,minecraft:concrete:0)
Block(-7,1,8,minecraft:concrete:0)
Block(-7,1,9,minecraft:concrete:0)
Block(-7,2,-6,minecraft:concrete:0)
Block(-7,2,-5,minecraft:concrete:0)
Block(-7,2,-4,minecraft:concrete:0)
Block(-7,2,-3,minecraft:concrete:0)
Block(-7,2,-2,minecraft:concrete:0)
Block(-7,2,-1,minecraft:concrete:0)
Block(-7,2,0,minecraft:concrete:0)
Block(-7,2,1,minecraft:concrete:0)
Block(-7,2,2,minecraft:concrete:0)
Block(-7,2,3,minecraft:concrete:0)
Block(-7,2,4,minecraft:concrete:0)
Block(-7,2,5,minecraft:concrete:0)
Block(-7,2,6,minecraft:concrete:0)
Block(-7,2,7,minecraft:concrete:0)
Block(-7,2,8,minecraft:concrete:0)
Block(-7,2,9,minecraft:concrete:0)
Block(-7,3,-6,minecraft:concrete:0)
Block(-7,3,-5,minecraft:concrete:0)
Block(-7,3,-4,minecraft:concrete:0)
Block(-7,3,-3,minecraft:concrete:0)
Block(-7,3,-2,minecraft:concrete:0)
Block(-7,3,-1,minecraft:concrete:0)
Block(-7,3,0,minecraft:concrete:0)
Block(-7,3,1,minecraft:concrete:0)
Block(-7,3,2,minecraft:concrete:0)
Block(-7,3,3,minecraft:concrete:0)
Block(-7,3,4,minecraft:concrete:0)
Block(-7,3,5,minecraft:concrete:0)
Block(-7,3,6,minecraft:concrete:0)
Block(-7,3,7,minecraft:concrete:0)
Block(-7,3,8,minecraft:concrete:0)
Block(-7,3,9,minecraft:concrete:0)
Block(-7,4,-6,minecraft:concrete:0)
Block(-7,4,-5,minecraft:concrete:0)
Block(-7,4,-4,minecraft:concrete:0)
Block(-7,4,-3,minecraft:concrete:0)
Block(-7,4,-2,minecraft:concrete:0)
Block(-7,4,-1,minecraft:concrete:0)
Block(-7,4,0,minecraft:concrete:0)
Block(-7,4,1,minecraft:concrete:0)
Block(-7,4,2,minecraft:concrete:0)
Block(-7,4,3,minecraft:concrete:0)
Block(-7,4,4,minecraft:concrete:0)
Block(-7,4,5,minecraft:concrete:0)
Block(-7,4,6,minecraft:concrete:0)
Block(-7,4,7,minecraft:concrete:0)
Block(-7,4,8,minecraft:concrete:0)
Block(-7,4,9,minecraft:concrete:0)
Block(-7,5,-6,minecraft:concrete:0)
Block(-7,5,-5,minecraft:concrete:0)
Block(-7,5,-4,minecraft:concrete:0)
Block(-7,5,-3,minecraft:concrete:0)
Block(-7,5,-2,minecraft:concrete:0)
Block(-7,5,-1,minecraft:concrete:0)
Block(-7,5,0,minecraft:concrete:0)
Block(-7,5,1,minecraft:concrete:0)
Block(-7,5,2,minecraft:concrete:0)
Block(-7,5,3,minecraft:concrete:0)
Block(-7,5,4,minecraft:concrete:0)
Block(-7,5,5,minecraft:concrete:0)
Block(-7,5,6,minecraft:concrete:0)
Block(-7,5,7,minecraft:concrete:0)
Block(-7,5,8,minecraft:concrete:0)
Block(-7,5,9,minecraft:concrete:0)
Block(-7,6,-6,minecraft:concrete:0)
Block(-7,6,-5,minecraft:concrete:0)
Block(-7,6,-4,minecraft:concrete:0)
Block(-7,6,-3,minecraft:concrete:0)
Block(-7,6,-2,minecraft:concrete:0)
Block(-7,6,-1,minecraft:concrete:0)
Block(-7,6,0,minecraft:concrete:0)
Block(-7,6,1,minecraft:concrete:0)
Block(-7,6,2,minecraft:concrete:0)
Block(-7,6,3,minecraft:concrete:0)
Block(-7,6,4,minecraft:concrete:0)
Block(-7,6,5,minecraft:concrete:0)
Block(-7,6,6,minecraft:concrete:0)
Block(-7,6,7,minecraft:concrete:0)
Block(-7,6,8,minecraft:concrete:0)
Block(-7,6,9,minecraft:concrete:0)
Block(-7,7,-6,minecraft:concrete:0)
Block(-7,7,-5,minecraft:concrete:0)
Block(-7,7,-4,minecraft:concrete:0)
Block(-7,7,-3,minecraft:concrete:0)
Block(-7,7,-2,minecraft:concrete:0)
Block(-7,7,-1,minecraft:concrete:0)
Block(-7,7,0,minecraft:concrete:0)
Block(-7,7,1,minecraft:concrete:0)
Block(-7,7,2,minecraft:concrete:0)
Block(-7,7,3,minecraft:concrete:0)
Block(-7,7,4,minecraft:concrete:0)
Block(-7,7,5,minecraft:concrete:0)
Block(-7,7,6,minecraft:concrete:0)
Block(-7,7,7,minecraft:concrete:0)
Block(-7,7,8,minecraft:concrete:0)
Block(-7,7,9,minecraft:concrete:0)
Block(-7,8,-6,minecraft:concrete:0)
Block(-7,8,-5,minecraft:concrete:0)
Block(-7,8,-4,minecraft:concrete:0)
Block(-7,8,-3,minecraft:concrete:0)
Block(-7,8,-2,minecraft:concrete:0)
Block(-7,8,-1,minecraft:concrete:0)
Block(-7,8,0,minecraft:concrete:0)
Block(-7,8,1,minecraft:concrete:0)
Block(-7,8,2,minecraft:concrete:0)
Block(-7,8,3,minecraft:concrete:0)
Block(-7,8,4,minecraft:concrete:0)
Block(-7,8,5,minecraft:concrete:0)
Block(-7,8,6,minecraft:concrete:0)
Block(-7,8,7,minecraft:concrete:0)
Block(-7,8,8,minecraft:concrete:0)
Block(-7,8,9,minecraft:concrete:0)
Block(-7,9,-6,minecraft:concrete:0)
Block(-7,9,-5,minecraft:concrete:0)
Block(-7,9,-4,minecraft:concrete:0)
Block(-7,9,-3,minecraft:concrete:0)
Block(-7,9,-2,minecraft:concrete:0)
Block(-7,9,-1,minecraft:concrete:0)
Block(-7,9,0,minecraft:concrete:0)
Block(-7,9,1,minecraft:concrete:0)
Block(-7,9,2,minecraft:concrete:0)
Block(-7,9,3,minecraft:concrete:0)
Block(-7,9,4,minecraft:concrete:0)
Block(-7,9,5,minecraft:concrete:0)
Block(-7,9,6,minecraft:concrete:0)
Block(-7,9,7,minecraft:concrete:0)
Block(-7,9,8,minecraft:concrete:0)
Block(-7,9,9,minecraft:concrete:0)
Block(-7,10,-6,minecraft:concrete:0)
Block(-7,10,-5,minecraft:concrete:0)
Block(-7,10,-4,minecraft:concrete:0)
Block(-7,10,-3,minecraft:concrete:0)
Block(-7,10,-2,minecraft:concrete:0)
Block(-7,10,-1,minecraft:concrete:0)
Block(-7,10,0,minecraft:concrete:0)
Block(-7,10,1,minecraft:concrete:0)
Block(-7,10,2,minecraft:concrete:0)
Block(-7,10,3,minecraft:concrete:0)
Block(-7,10,4,minecraft:concrete:0)
Block(-7,10,5,minecraft:concrete:0)
Block(-7,10,6,minecraft:concrete:0)
Block(-7,10,7,minecraft:concrete:0)
Block(-7,10,8,minecraft:concrete:0)
Block(-7,10,9,minecraft:concrete:0)
Block(-7,11,-6,minecraft:concrete:0)
Block(-7,11,-5,minecraft:concrete:0)
Block(-7,11,-4,minecraft:concrete:0)
Block(-7,11,-3,minecraft:concrete:0)
Block(-7,11,-2,minecraft:concrete:0)
Block(-7,11,-1,minecraft:concrete:0)
Block(-7,11,0,minecraft:concrete:0)
Block(-7,11,1,minecraft:concrete:0)
Block(-7,11,2,minecraft:concrete:0)
Block(-7,11,3,minecraft:concrete:0)
Block(-7,11,4,minecraft:concrete:0)
Block(-7,11,5,minecraft:concrete:0)
Block(-7,11,6,minecraft:concrete:0)
Block(-7,11,7,minecraft:concrete:0)
Block(-7,11,8,minecraft:concrete:0)
Block(-7,11,9,minecraft:concrete:0)
Block(-7,12,-6,minecraft:concrete:0)
Block(-7,12,-5,minecraft:concrete:0)
Block(-7,12,-4,minecraft:concrete:0)
Block(-7,12,-3,minecraft:concrete:0)
Block(-7,12,-2,minecraft:concrete:0)
Block(-7,12,-1,minecraft:concrete:0)
Block(-7,12,0,minecraft:concrete:0)
Block(-7,12,1,minecraft:concrete:0)
Block(-7,12,2,minecraft:concrete:0)
Block(-7,12,3,minecraft:concrete:0)
Block(-7,12,4,minecraft:concrete:0)
Block(-7,12,5,minecraft:concrete:0)
Block(-7,12,6,minecraft:concrete:0)
Block(-7,12,7,minecraft:concrete:0)
Block(-7,12,8,minecraft:concrete:0)
Block(-7,12,9,minecraft:concrete:0)
Block(-7,13,-6,minecraft:concrete:0)
Block(-7,13,-5,minecraft:concrete:0)
Block(-7,13,-4,minecraft:concrete:0)
Block(-7,13,-3,minecraft:concrete:0)
Block(-7,13,-2,minecraft:concrete:0)
Block(-7,13,-1,minecraft:concrete:0)
Block(-7,13,0,minecraft:concrete:0)
Block(-7,13,1,minecraft:concrete:0)
Block(-7,13,2,minecraft:concrete:0)
Block(-7,13,3,minecraft:concrete:0)
Block(-7,13,4,minecraft:concrete:0)
Block(-7,13,5,minecraft:concrete:0)
Block(-7,13,6,minecraft:concrete:0)
Block(-7,13,7,minecraft:concrete:0)
Block(-7,13,8,minecraft:concrete:0)
Block(-7,13,9,minecraft:concrete:0)
Block(-7,14,-6,minecraft:concrete:0)
Block(-7,14,-5,minecraft:concrete:0)
Block(-7,14,-4,minecraft:concrete:0)
Block(-7,14,-3,minecraft:concrete:0)
Block(-7,14,-2,minecraft:concrete:0)
Block(-7,14,-1,minecraft:concrete:0)
Block(-7,14,0,minecraft:concrete:0)
Block(-7,14,1,minecraft:concrete:0)
Block(-7,14,2,minecraft:concrete:0)
Block(-7,14,3,minecraft:concrete:0)
Block(-7,14,4,minecraft:concrete:0)
Block(-7,14,5,minecraft:concrete:0)
Block(-7,14,6,minecraft:concrete:0)
Block(-7,14,7,minecraft:concrete:0)
Block(-7,14,8,minecraft:concrete:0)
Block(-7,14,9,minecraft:concrete:0)
Block(-7,15,-6,minecraft:concrete:0)
Block(-7,15,-5,minecraft:concrete:0)
Block(-7,15,-4,minecraft:concrete:0)
Block(-7,15,-3,minecraft:concrete:0)
Block(-7,15,-2,minecraft:concrete:0)
Block(-7,15,-1,minecraft:concrete:0)
Block(-7,15,0,minecraft:concrete:0)
Block(-7,15,1,minecraft:concrete:0)
Block(-7,15,2,minecraft:concrete:0)
Block(-7,15,3,minecraft:concrete:0)
Block(-7,15,4,minecraft:concrete:0)
Block(-7,15,5,minecraft:concrete:0)
Block(-7,15,6,minecraft:concrete:0)
Block(-7,15,7,minecraft:concrete:0)
Block(-7,15,8,minecraft:concrete:0)
Block(-7,15,9,minecraft:concrete:0)
Block(-7,16,-6,minecraft:concrete:0)
Block(-7,16,-5,minecraft:concrete:0)
Block(-7,16,-4,minecraft:concrete:0)
Block(-7,16,-3,minecraft:concrete:0)
Block(-7,16,-2,minecraft:concrete:0)
Block(-7,16,-1,minecraft:concrete:0)
Block(-7,16,0,minecraft:concrete:0)
Block(-7,16,1,minecraft:concrete:0)
Block(-7,16,2,minecraft:concrete:0)
Block(-7,16,3,minecraft:concrete:0)
Block(-7,16,4,minecraft:concrete:0)
Block(-7,16,5,minecraft:concrete:0)
Block(-7,16,6,minecraft:concrete:0)
Block(-7,16,7,minecraft:concrete:0)
Block(-7,16,8,minecraft:concrete:0)
Block(-7,16,9,minecraft:concrete:0)
Block(-7,17,-6,minecraft:concrete:0)
Block(-7,17,-5,minecraft:concrete:0)
Block(-7,17,-4,minecraft:concrete:0)
Block(-7,17,-3,minecraft:concrete:0)
Block(-7,17,-2,minecraft:concrete:0)
Block(-7,17,-1,minecraft:concrete:0)
Block(-7,17,0,minecraft:concrete:0)
Block(-7,17,1,minecraft:concrete:0)
Block(-7,17,2,minecraft:concrete:0)
Block(-7,17,3,minecraft:concrete:0)
Block(-7,17,4,minecraft:concrete:0)
Block(-7,17,5,minecraft:concrete:0)
Block(-7,17,6,minecraft:concrete:0)
Block(-7,17,7,minecraft:concrete:0)
Block(-7,17,8,minecraft:concrete:0)
Block(-7,17,9,minecraft:concrete:0)
Block(-7,18,-6,minecraft:concrete:0)
Block(-7,18,-5,minecraft:concrete:0)
Block(-7,18,-4,minecraft:concrete:0)
Block(-7,18,-3,minecraft:concrete:0)
Block(-7,18,-2,minecraft:concrete:0)
Block(-7,18,-1,minecraft:concrete:0)
Block(-7,18,0,minecraft:concrete:0)
Block(-7,18,1,minecraft:concrete:0)
Block(-7,18,2,minecraft:concrete:0)
Block(-7,18,3,minecraft:concrete:0)
Block(-7,18,4,minecraft:concrete:0)
Block(-7,18,5,minecraft:concrete:0)
Block(-7,18,6,minecraft:concrete:0)
Block(-7,18,7,minecraft:concrete:0)
Block(-7,18,8,minecraft:concrete:0)
Block(-7,18,9,minecraft:concrete:0)
Block(-7,19,-6,minecraft:concrete:0)
Block(-7,19,-5,minecraft:concrete:0)
Block(-7,19,-4,minecraft:concrete:0)
Block(-7,19,-3,minecraft:concrete:0)
Block(-7,19,-2,minecraft:concrete:0)
Block(-7,19,-1,minecraft:concrete:0)
Block(-7,19,0,minecraft:concrete:0)
Block(-7,19,1,minecraft:concrete:0)
Block(-7,19,2,minecraft:concrete:0)
Block(-7,19,3,minecraft:concrete:0)
Block(-7,19,4,minecraft:concrete:0)
Block(-7,19,5,minecraft:concrete:0)
Block(-7,19,6,minecraft:concrete:0)
Block(-7,19,7,minecraft:concrete:0)
Block(-7,19,8,minecraft:concrete:0)
Block(-7,19,9,minecraft:concrete:0)
Block(-7,20,-6,minecraft:concrete:0)
Block(-7,20,-5,minecraft:concrete:0)
Block(-7,20,-4,minecraft:concrete:0)
Block(-7,20,-3,minecraft:concrete:0)
Block(-7,20,-2,minecraft:concrete:0)
Block(-7,20,-1,minecraft:concrete:0)
Block(-7,20,0,minecraft:concrete:0)
Block(-7,20,1,minecraft:concrete:0)
Block(-7,20,2,minecraft:concrete:0)
Block(-7,20,3,minecraft:concrete:0)
Block(-7,20,4,minecraft:concrete:0)
Block(-7,20,5,minecraft:concrete:0)
Block(-7,20,6,minecraft:concrete:0)
Block(-7,20,7,minecraft:concrete:0)
Block(-7,20,8,minecraft:concrete:0)
Block(-7,20,9,minecraft:concrete:0)
Block(-7,21,-6,minecraft:concrete:0)
Block(-7,21,-5,minecraft:concrete:0)
Block(-7,21,-4,minecraft:concrete:0)
Block(-7,21,-3,minecraft:concrete:0)
Block(-7,21,-2,minecraft:concrete:0)
Block(-7,21,-1,minecraft:concrete:0)
Block(-7,21,0,minecraft:concrete:0)
Block(-7,21,1,minecraft:concrete:0)
Block(-7,21,2,minecraft:concrete:0)
Block(-7,21,3,minecraft:concrete:0)
Block(-7,21,4,minecraft:concrete:0)
Block(-7,21,5,minecraft:concrete:0)
Block(-7,21,6,minecraft:concrete:0)
Block(-7,21,7,minecraft:concrete:0)
Block(-7,21,8,minecraft:concrete:0)
Block(-7,21,9,minecraft:concrete:0)
Block(-7,22,-6,minecraft:concrete:0)
Block(-7,22,-5,minecraft:concrete:0)
Block(-7,22,-4,minecraft:concrete:0)
Block(-7,22,-3,minecraft:concrete:0)
Block(-7,22,-2,minecraft:concrete:0)
Block(-7,22,-1,minecraft:concrete:0)
Block(-7,22,0,minecraft:concrete:0)
Block(-7,22,1,minecraft:concrete:0)
Block(-7,22,2,minecraft:concrete:0)
Block(-7,22,3,minecraft:concrete:0)
Block(-7,22,4,minecraft:concrete:0)
Block(-7,22,5,minecraft:concrete:0)
Block(-7,22,6,minecraft:concrete:0)
Block(-7,22,7,minecraft:concrete:0)
Block(-7,22,8,minecraft:concrete:0)
Block(-7,22,9,minecraft:concrete:0)
Block(-7,23,-6,minecraft:concrete:0)
Block(-7,23,-5,minecraft:concrete:0)
Block(-7,23,-4,minecraft:concrete:0)
Block(-7,23,-3,minecraft:concrete:0)
Block(-7,23,-2,minecraft:concrete:0)
Block(-7,23,-1,minecraft:concrete:0)
Block(-7,23,0,minecraft:concrete:0)
Block(-7,23,1,minecraft:concrete:0)
Block(-7,23,2,minecraft:concrete:0)
Block(-7,23,3,minecraft:concrete:0)
Block(-7,23,4,minecraft:concrete:0)
Block(-7,23,5,minecraft:concrete:0)
Block(-7,23,6,minecraft:concrete:0)
Block(-7,23,7,minecraft:concrete:0)
Block(-7,23,8,minecraft:concrete:0)
Block(-7,23,9,minecraft:concrete:0)
Block(-7,24,-6,minecraft:concrete:0)
Block(-7,24,-5,minecraft:concrete:0)
Block(-7,24,-4,minecraft:concrete:0)
Block(-7,24,-3,minecraft:concrete:0)
Block(-7,24,-2,minecraft:concrete:0)
Block(-7,24,-1,minecraft:concrete:0)
Block(-7,24,0,minecraft:concrete:0)
Block(-7,24,1,minecraft:concrete:0)
Block(-7,24,2,minecraft:concrete:0)
Block(-7,24,3,minecraft:concrete:0)
Block(-7,24,4,minecraft:concrete:0)
Block(-7,24,5,minecraft:concrete:0)
Block(-7,24,6,minecraft:concrete:0)
Block(-7,24,7,minecraft:concrete:0)
Block(-7,24,8,minecraft:concrete:0)
Block(-7,24,9,minecraft:concrete:0)
Block(-7,25,-6,minecraft:concrete:0)
Block(-7,25,-5,minecraft:concrete:0)
Block(-7,25,-4,minecraft:concrete:0)
Block(-7,25,-3,minecraft:concrete:0)
Block(-7,25,-2,minecraft:concrete:0)
Block(-7,25,-1,minecraft:concrete:0)
Block(-7,25,0,minecraft:concrete:0)
Block(-7,25,1,minecraft:concrete:0)
Block(-7,25,2,minecraft:concrete:0)
Block(-7,25,3,minecraft:concrete:0)
Block(-7,25,4,minecraft:concrete:0)
Block(-7,25,5,minecraft:concrete:0)
Block(-7,25,6,minecraft:concrete:0)
Block(-7,25,7,minecraft:concrete:0)
Block(-7,25,8,minecraft:concrete:0)
Block(-7,25,9,minecraft:concrete:0)
Block(-7,26,-6,minecraft:concrete:0)
Block(-7,26,-5,minecraft:concrete:0)
Block(-7,26,-4,minecraft:concrete:0)
Block(-7,26,-3,minecraft:concrete:0)
Block(-7,26,-2,minecraft:concrete:0)
Block(-7,26,-1,minecraft:concrete:0)
Block(-7,26,0,minecraft:concrete:0)
Block(-7,26,1,minecraft:concrete:0)
Block(-7,26,2,minecraft:concrete:0)
Block(-7,26,3,minecraft:concrete:0)
Block(-7,26,4,minecraft:concrete:0)
Block(-7,26,5,minecraft:concrete:0)
Block(-7,26,6,minecraft:concrete:0)
Block(-7,26,7,minecraft:concrete:0)
Block(-7,26,8,minecraft:concrete:0)
Block(-7,26,9,minecraft:concrete:0)
Block(-7,27,-6,minecraft:concrete:0)
Block(-7,27,-5,minecraft:concrete:0)
Block(-7,27,-4,minecraft:concrete:0)
Block(-7,27,-3,minecraft:concrete:0)
Block(-7,27,-2,minecraft:concrete:0)
Block(-7,27,-1,minecraft:concrete:0)
Block(-7,27,0,minecraft:concrete:0)
Block(-7,27,1,minecraft:concrete:0)
Block(-7,27,2,minecraft:concrete:0)
Block(-7,27,3,minecraft:concrete:0)
Block(-7,27,4,minecraft:concrete:0)
Block(-7,27,5,minecraft:concrete:0)
Block(-7,27,6,minecraft:concrete:0)
Block(-7,27,7,minecraft:concrete:0)
Block(-7,27,8,minecraft:concrete:0)
Block(-7,27,9,minecraft:concrete:0)
Block(-7,28,-6,minecraft:concrete:0)
Block(-7,28,-5,minecraft:concrete:0)
Block(-7,28,-4,minecraft:concrete:0)
Block(-7,28,-3,minecraft:concrete:0)
Block(-7,28,-2,minecraft:concrete:0)
Block(-7,28,-1,minecraft:concrete:0)
Block(-7,28,0,minecraft:concrete:0)
Block(-7,28,1,minecraft:concrete:0)
Block(-7,28,2,minecraft:concrete:0)
Block(-7,28,3,minecraft:concrete:0)
Block(-7,28,4,minecraft:concrete:0)
Block(-7,28,5,minecraft:concrete:0)
Block(-7,28,6,minecraft:concrete:0)
Block(-7,28,7,minecraft:concrete:0)
Block(-7,28,8,minecraft:concrete:0)
Block(-7,28,9,minecraft:concrete:0)
Block(-7,29,-6,minecraft:concrete:0)
Block(-7,29,-5,minecraft:concrete:0)
Block(-7,29,-4,minecraft:concrete:0)
Block(-7,29,-3,minecraft:concrete:0)
Block(-7,29,-2,minecraft:concrete:0)
Block(-7,29,-1,minecraft:concrete:0)
Block(-7,29,0,minecraft:concrete:0)
Block(-7,29,1,minecraft:concrete:0)
Block(-7,29,2,minecraft:concrete:0)
Block(-7,29,3,minecraft:concrete:0)
Block(-7,29,4,minecraft:concrete:0)
Block(-7,29,5,minecraft:concrete:0)
Block(-7,29,6,minecraft:concrete:0)
Block(-7,29,7,minecraft:concrete:0)
Block(-7,29,8,minecraft:concrete:0)
Block(-7,29,9,minecraft:concrete:0)
Block(-7,30,-6,minecraft:concrete:0)
Block(-7,30,-5,minecraft:concrete:0)
Block(-7,30,-4,minecraft:concrete:0)
Block(-7,30,-3,minecraft:concrete:0)
Block(-7,30,-2,minecraft:concrete:0)
Block(-7,30,-1,minecraft:concrete:0)
Block(-7,30,0,minecraft:concrete:0)
Block(-7,30,1,minecraft:concrete:0)
Block(-7,30,2,minecraft:concrete:0)
Block(-7,30,3,minecraft:concrete:0)
Block(-7,31,-6,minecraft:concrete:0)
Block(-7,31,-5,minecraft:concrete:0)
Block(-7,31,-4,minecraft:concrete:0)
Block(-7,31,-3,minecraft:concrete:0)
Block(-7,31,-2,minecraft:concrete:0)
Block(-7,31,-1,minecraft:concrete:0)
Block(-7,31,0,minecraft:concrete:0)
Block(-7,31,1,minecraft:concrete:0)
Block(-7,31,2,minecraft:concrete:0)
Block(-7,31,3,minecraft:concrete:0)
Block(-7,32,-6,minecraft:concrete:0)
Block(-7,32,-5,minecraft:concrete:0)
Block(-7,32,-4,minecraft:concrete:0)
Block(-7,32,-3,minecraft:concrete:0)
Block(-7,32,-2,minecraft:concrete:0)
Block(-7,32,-1,minecraft:concrete:0)
Block(-7,32,0,minecraft:concrete:0)
Block(-7,32,1,minecraft:concrete:0)
Block(-7,32,2,minecraft:concrete:0)
Block(-7,32,3,minecraft:concrete:0)
Block(-7,33,-6,minecraft:concrete:0)
Block(-7,33,-5,minecraft:concrete:0)
Block(-7,33,-4,minecraft:concrete:0)
Block(-7,33,-3,minecraft:concrete:0)
Block(-7,33,-2,minecraft:concrete:0)
Block(-7,33,-1,minecraft:concrete:0)
Block(-7,33,0,minecraft:concrete:0)
Block(-7,33,1,minecraft:concrete:0)
Block(-7,33,2,minecraft:concrete:0)
Block(-7,33,3,minecraft:concrete:0)
Block(-6,0,-6,minecraft:concrete:0)
Block(-6,0,-5,minecraft:concrete:0)
Block(-6,0,-4,minecraft:concrete:0)
Block(-6,0,-3,minecraft:concrete:0)
Block(-6,0,-2,minecraft:concrete:0)
Block(-6,0,-1,minecraft:concrete:0)
Block(-6,0,0,minecraft:concrete:0)
Block(-6,0,1,minecraft:concrete:0)
Block(-6,0,2,minecraft:concrete:0)
Block(-6,0,3,minecraft:concrete:0)
Block(-6,0,4,minecraft:concrete:0)
Block(-6,0,5,minecraft:concrete:0)
Block(-6,0,6,minecraft:concrete:0)
Block(-6,0,7,minecraft:concrete:0)
Block(-6,0,8,minecraft:concrete:0)
Block(-6,0,9,minecraft:concrete:0)
Block(-6,1,-6,minecraft:concrete:0)
Block(-6,1,-5,minecraft:concrete:0)
Block(-6,1,-4,minecraft:concrete:0)
Block(-6,1,-3,minecraft:concrete:0)
Block(-6,1,-2,minecraft:concrete:0)
Block(-6,1,-1,STATIONARY_WATER:0)
Block(-6,1,0,STATIONARY_WATER:0)
Block(-6,1,1,STATIONARY_WATER:0)
Block(-6,1,2,STATIONARY_WATER:0)
Block(-6,1,3,STATIONARY_WATER:0)
Block(-6,1,4,STATIONARY_WATER:0)
Block(-6,1,5,STATIONARY_WATER:0)
Block(-6,1,6,STATIONARY_WATER:0)
Block(-6,1,7,STATIONARY_WATER:0)
Block(-6,1,8,STATIONARY_WATER:0)
Block(-6,1,9,minecraft:concrete:0)
Block(-6,2,-6,minecraft:concrete:0)
Block(-6,2,-5,minecraft:iron_block:1)
Block(-6,2,-4,minecraft:stonebrick:0)
Block(-6,2,-3,AIR:0)
Block(-6,2,-2,minecraft:stone_brick_stairs:2)
Block(-6,2,-1,minecraft:stone_brick_stairs:7)
Block(-6,2,0,minecraft:iron_block:1)
Block(-6,2,1,minecraft:iron_block:1)
Block(-6,2,2,minecraft:iron_block:1)
Block(-6,2,3,minecraft:iron_block:1)
Block(-6,2,4,minecraft:iron_block:1)
Block(-6,2,5,minecraft:iron_block:1)
Block(-6,2,6,minecraft:iron_block:1)
Block(-6,2,7,minecraft:iron_block:1)
Block(-6,2,8,minecraft:iron_block:1)
Block(-6,2,9,minecraft:concrete:0)
Block(-6,3,-6,minecraft:concrete:0)
Block(-6,3,-5,minecraft:stonebrick:3)
Block(-6,3,-4,AIR:0)
Block(-6,3,-3,AIR:0)
Block(-6,3,-2,AIR:0)
Block(-6,3,-1,AIR:0)
Block(-6,3,0,minecraft:tallgrass:0)
Block(-6,3,1,AIR:0)
Block(-6,3,2,AIR:0)
Block(-6,3,3,AIR:0)
Block(-6,3,4,AIR:0)
Block(-6,3,5,AIR:0)
Block(-6,3,6,AIR:0)
Block(-6,3,7,minecraft:tallgrass:0)
Block(-6,3,8,AIR:0)
Block(-6,3,9,minecraft:concrete:0)
Block(-6,4,-6,minecraft:concrete:0)
Block(-6,4,-5,WEB:0)
Block(-6,4,-4,AIR:0)
Block(-6,4,-3,AIR:0)
Block(-6,4,-2,AIR:0)
Block(-6,4,-1,AIR:0)
Block(-6,4,0,AIR:0)
Block(-6,4,1,AIR:0)
Block(-6,4,2,AIR:0)
Block(-6,4,3,AIR:0)
Block(-6,4,4,AIR:0)
Block(-6,4,5,AIR:0)
Block(-6,4,6,AIR:0)
Block(-6,4,7,AIR:0)
Block(-6,4,8,AIR:0)
Block(-6,4,9,minecraft:concrete:0)
Block(-6,5,-6,minecraft:concrete:0)
Block(-6,5,-5,minecraft:concrete:0)
Block(-6,5,-4,minecraft:concrete:0)
Block(-6,5,-3,minecraft:concrete:0)
Block(-6,5,-2,minecraft:concrete:0)
Block(-6,5,-1,minecraft:concrete:0)
Block(-6,5,0,minecraft:concrete:0)
Block(-6,5,1,minecraft:concrete:0)
Block(-6,5,2,minecraft:concrete:0)
Block(-6,5,3,minecraft:concrete:0)
Block(-6,5,4,minecraft:concrete:0)
Block(-6,5,5,minecraft:concrete:0)
Block(-6,5,6,minecraft:concrete:0)
Block(-6,5,7,minecraft:concrete:0)
Block(-6,5,8,minecraft:concrete:0)
Block(-6,5,9,minecraft:concrete:0)
Block(-6,6,-6,minecraft:concrete:0)
Block(-6,6,-5,minecraft:planks:8,../../../Chests/Loot/manhunt_vagrant_scrap.nbt)
Block(-6,6,-4,minecraft:stone_brick_stairs:7)
Block(-6,6,-3,minecraft:iron_block:1)
Block(-6,6,-2,minecraft:iron_block:1)
Block(-6,6,-1,minecraft:stone_brick_stairs:6)
Block(-6,6,0,AIR:0)
Block(-6,6,1,minecraft:stone:0)
Block(-6,6,2,minecraft:stone_brick_stairs:2)
Block(-6,6,3,quark:grate:0)
Block(-6,6,4,quark:grate:0)
Block(-6,6,5,minecraft:iron_block:0)
Block(-6,6,6,quark:grate:0)
Block(-6,6,7,quark:grate:0)
Block(-6,6,8,quark:grate:0)
Block(-6,6,9,minecraft:concrete:0)
Block(-6,7,-6,minecraft:concrete:0)
Block(-6,7,-5,minecraft:planks:8,../../../Chests/Loot/manhunt_vagrant_scrap.nbt)
Block(-6,7,-4,minecraft:planks:8,../../../Chests/Loot/manhunt_vagrant_scrap.nbt)
Block(-6,7,-3,minecraft:planks:0,../../../Chests/Loot/manhunt_vagrant_scrap.nbt)
Block(-6,7,-2,minecraft:stonebrick:5)
Block(-6,7,-1,minecraft:stonebrick:5)
Block(-6,7,0,AIR:0)
Block(-6,7,1,AIR:0)
Block(-6,7,2,AIR:0)
Block(-6,7,3,AIR:0)
Block(-6,7,4,AIR:0)
Block(-6,7,5,AIR:0)
Block(-6,7,6,AIR:0)
Block(-6,7,7,AIR:0)
Block(-6,7,8,WEB:0)
Block(-6,7,9,minecraft:concrete:0)
Block(-6,8,-6,minecraft:concrete:0)
Block(-6,8,-5,minecraft:planks:8,../../../Chests/Loot/manhunt_vagrant_scrap.nbt)
Block(-6,8,-4,minecraft:planks:8,../../../Chests/Loot/manhunt_vagrant_scrap.nbt)
Block(-6,8,-3,minecraft:planks:0,../../../Chests/Loot/manhunt_vagrant_scrap.nbt)
Block(-6,8,-2,minecraft:stonebrick:5)
Block(-6,8,-1,minecraft:stonebrick:5)
Block(-6,8,0,AIR:0)
Block(-6,8,1,AIR:0)
Block(-6,8,2,AIR:0)
Block(-6,8,3,AIR:0)
Block(-6,8,4,AIR:0)
Block(-6,8,5,minecraft:iron_block:1)
Block(-6,8,6,AIR:0)
Block(-6,8,7,AIR:0)
Block(-6,8,8,AIR:0)
Block(-6,8,9,minecraft:concrete:0)
Block(-6,9,-6,minecraft:concrete:0)
Block(-6,9,-5,minecraft:concrete:0)
Block(-6,9,-4,minecraft:concrete:0)
Block(-6,9,-3,minecraft:concrete:0)
Block(-6,9,-2,minecraft:concrete:0)
Block(-6,9,-1,minecraft:concrete:0)
Block(-6,9,0,minecraft:concrete:0)
Block(-6,9,1,minecraft:concrete:0)
Block(-6,9,2,minecraft:concrete:0)
Block(-6,9,3,minecraft:concrete:0)
Block(-6,9,4,minecraft:concrete:0)
Block(-6,9,5,minecraft:concrete:0)
Block(-6,9,6,minecraft:concrete:0)
Block(-6,9,7,minecraft:concrete:0)
Block(-6,9,8,minecraft:concrete:0)
Block(-6,9,9,minecraft:concrete:0)
Block(-6,10,-6,minecraft:concrete:0)
Block(-6,10,-5,minecraft:concrete:0)
Block(-6,10,-4,minecraft:planks:0)
RandomBlock(-6,10,-3,minecraft:planks:5,5,minecraft:planks:1,../../../Chests/Loot/manhunt_vagrant_scrap.nbt,100)
Block(-6,10,-2,minecraft:bookshelf:0)
Block(-6,10,-1,minecraft:concrete:0)
RandomBlock(-6,10,0,minecraft:planks:5,5,minecraft:planks:5,../../../Chests/Loot/manhunt_vagrant_scrap.nbt,100)
RandomBlock(-6,10,1,minecraft:planks:5,5,minecraft:planks:5,../../../Chests/Loot/manhunt_vagrant_scrap.nbt,100)
Block(-6,10,2,minecraft:planks:0,../../../Chests/Loot/manhunt_vagrant_scrap.nbt)
Block(-6,10,3,minecraft:concrete:0)
Block(-6,10,4,minecraft:planks:0)
Block(-6,10,5,minecraft:concrete:0)
Block(-6,10,6,minecraft:iron_block:0)
Block(-6,10,7,minecraft:iron_block:0)
Block(-6,10,8,minecraft:concrete:0)
Block(-6,10,9,minecraft:concrete:0)
Block(-6,11,-6,minecraft:concrete:0)
Block(-6,11,-5,minecraft:concrete:0)
RandomBlock(-6,11,-4,minecraft:planks:5,5,minecraft:planks:1,../../../Chests/Loot/manhunt_vagrant_scrap.nbt,100)
Block(-6,11,-3,CHEST:5,../../../Chests/Loot/manhunt_military_common.nbt)
Block(-6,11,-2,minecraft:bookshelf:0)
Block(-6,11,-1,minecraft:concrete:0)
RandomBlock(-6,11,0,minecraft:planks:5,5,minecraft:planks:5,../../../Chests/Loot/manhunt_vagrant_scrap.nbt,100)
Block(-6,11,1,minecraft:planks:15)
Block(-6,11,2,minecraft:planks:1)
Block(-6,11,3,minecraft:concrete:0)
Block(-6,11,4,minecraft:planks:15)
Block(-6,11,5,minecraft:concrete:0)
Block(-6,11,6,minecraft:iron_block:0)
Block(-6,11,7,minecraft:iron_block:0)
Block(-6,11,8,minecraft:concrete:0)
Block(-6,11,9,minecraft:concrete:0)
Block(-6,12,-6,minecraft:concrete:0)
Block(-6,12,-5,minecraft:concrete:0)
Block(-6,12,-4,AIR:0)
Block(-6,12,-3,AIR:0)
Block(-6,12,-2,AIR:0)
Block(-6,12,-1,minecraft:concrete:0)
Block(-6,12,0,minecraft:planks:8,../../../Chests/Loot/manhunt_vagrant_scrap.nbt)
Block(-6,12,1,AIR:0)
Block(-6,12,2,AIR:0)
Block(-6,12,3,minecraft:concrete:0)
Block(-6,12,4,minecraft:planks:15)
Block(-6,12,5,minecraft:concrete:0)
Block(-6,12,6,minecraft:iron_block:0)
Block(-6,12,7,minecraft:iron_block:0)
Block(-6,12,8,minecraft:concrete:0)
Block(-6,12,9,minecraft:concrete:0)
Block(-6,13,-6,minecraft:concrete:0)
Block(-6,13,-5,minecraft:concrete:0)
Block(-6,13,-4,minecraft:concrete:0)
Block(-6,13,-3,minecraft:concrete:0)
Block(-6,13,-2,minecraft:concrete:0)
Block(-6,13,-1,minecraft:concrete:0)
Block(-6,13,0,minecraft:concrete:0)
Block(-6,13,1,minecraft:concrete:0)
Block(-6,13,2,minecraft:concrete:0)
Block(-6,13,3,minecraft:concrete:0)
Block(-6,13,4,minecraft:concrete:0)
Block(-6,13,5,minecraft:concrete:0)
Block(-6,13,6,minecraft:concrete:0)
Block(-6,13,7,minecraft:concrete:0)
Block(-6,13,8,minecraft:concrete:0)
Block(-6,13,9,minecraft:concrete:0)
Block(-6,14,-6,minecraft:concrete:0)
Block(-6,14,-5,minecraft:planks:0)
Block(-6,14,-4,minecraft:stonebrick:0)
Block(-6,14,-3,minecraft:concrete:0)
Block(-6,14,-2,minecraft:stonebrick:8)
Block(-6,14,-1,minecraft:planks:0,../../../Chests/Loot/manhunt_vagrant_scrap.nbt)
Block(-6,14,0,minecraft:furnace:5)
Block(-6,14,1,minecraft:planks:0,../../../Chests/Loot/manhunt_vagrant_scrap.nbt)
Block(-6,14,2,minecraft:planks:5)
Block(-6,14,3,minecraft:stonebrick:0)
Block(-6,14,4,minecraft:concrete:0)
Block(-6,14,5,minecraft:stonebrick:0)
Block(-6,14,6,minecraft:oak_stairs:1)
Block(-6,14,7,minecraft:oak_stairs:1)
Block(-6,14,8,minecraft:oak_stairs:5)
Block(-6,14,9,minecraft:concrete:0)
Block(-6,15,-6,minecraft:concrete:0)
Block(-6,15,-5,minecraft:planks:0)
Block(-6,15,-4,AIR:0)
Block(-6,15,-3,minecraft:concrete:0)
Block(-6,15,-2,minecraft:bookshelf:0)
Block(-6,15,-1,AIR:0)
Block(-6,15,0,quark:grate:0)
Block(-6,15,1,minecraft:bookshelf:0)
Block(-6,15,2,minecraft:stonebrick:5)
Block(-6,15,3,minecraft:stonebrick:0)
Block(-6,15,4,minecraft:concrete:0)
Block(-6,15,5,AIR:0)
Block(-6,15,6,AIR:0)
Block(-6,15,7,AIR:0)
Block(-6,15,8,AIR:0)
Block(-6,15,9,minecraft:concrete:0)
Block(-6,16,-6,minecraft:concrete:0)
Block(-6,16,-5,minecraft:planks:0)
Block(-6,16,-4,WEB:0)
Block(-6,16,-3,minecraft:concrete:0)
Block(-6,16,-2,minecraft:planks:8,../../../Chests/Loot/manhunt_vagrant_scrap.nbt)
Block(-6,16,-1,minecraft:planks:0,../../../Chests/Loot/manhunt_vagrant_scrap.nbt)
Block(-6,16,0,minecraft:stone_brick_stairs:1)
Block(-6,16,1,minecraft:planks:8,../../../Chests/Loot/manhunt_vagrant_scrap.nbt)
Block(-6,16,2,minecraft:planks:0,../../../Chests/Loot/manhunt_vagrant_scrap.nbt)
Block(-6,16,3,minecraft:stonebrick:3)
Block(-6,16,4,minecraft:concrete:0)
Block(-6,16,5,AIR:0)
Block(-6,16,6,AIR:0)
Block(-6,16,7,AIR:0)
Block(-6,16,8,AIR:0)
Block(-6,16,9,minecraft:concrete:0)
Block(-6,17,-6,minecraft:concrete:0)
Block(-6,17,-5,minecraft:concrete:0)
Block(-6,17,-4,minecraft:concrete:0)
Block(-6,17,-3,minecraft:concrete:0)
Block(-6,17,-2,minecraft:concrete:0)
Block(-6,17,-1,minecraft:concrete:0)
Block(-6,17,0,minecraft:concrete:0)
Block(-6,17,1,minecraft:concrete:0)
Block(-6,17,2,minecraft:concrete:0)
Block(-6,17,3,minecraft:concrete:0)
Block(-6,17,4,minecraft:concrete:0)
Block(-6,17,5,minecraft:concrete:0)
Block(-6,17,6,minecraft:concrete:0)
Block(-6,17,7,minecraft:concrete:0)
Block(-6,17,8,minecraft:concrete:0)
Block(-6,17,9,minecraft:concrete:0)
Block(-6,18,-6,minecraft:concrete:0)
Block(-6,18,-5,minecraft:planks:8,../../../Chests/Loot/manhunt_vagrant_scrap.nbt)
Block(-6,18,-4,minecraft:planks:0,../../../Chests/Loot/manhunt_vagrant_scrap.nbt)
Block(-6,18,-3,minecraft:concrete:0)
Block(-6,18,-2,minecraft:stonebrick:8)
Block(-6,18,-1,minecraft:planks:0,../../../Chests/Loot/manhunt_vagrant_scrap.nbt)
Block(-6,18,0,minecraft:furnace:5)
Block(-6,18,1,minecraft:planks:8,../../../Chests/Loot/manhunt_vagrant_scrap.nbt)
Block(-6,18,2,minecraft:planks:5)
Block(-6,18,3,minecraft:stonebrick:0)
Block(-6,18,4,minecraft:concrete:0)
Block(-6,18,5,AIR:0)
Block(-6,18,6,minecraft:oak_stairs:1)
Block(-6,18,7,minecraft:oak_stairs:1)
Block(-6,18,8,minecraft:oak_stairs:5)
Block(-6,18,9,minecraft:concrete:0)
Block(-6,19,-6,minecraft:concrete:0)
Block(-6,19,-5,minecraft:glowstone)
Block(-6,19,-4,minecraft:planks:15)
Block(-6,19,-3,minecraft:concrete:0)
Block(-6,19,-2,minecraft:bookshelf:0)
Block(-6,19,-1,AIR:0)
Block(-6,19,0,quark:grate:0)
Block(-6,19,1,minecraft:bookshelf:0)
Block(-6,19,2,minecraft:stonebrick:5)
Block(-6,19,3,minecraft:stonebrick:0)
Block(-6,19,4,minecraft:concrete:0)
Block(-6,19,5,AIR:0)
Block(-6,19,6,AIR:0)
Block(-6,19,7,AIR:0)
Block(-6,19,8,AIR:0)
Block(-6,19,9,minecraft:concrete:0)
Block(-6,20,-6,minecraft:concrete:0)
Block(-6,20,-5,WEB:0)
Block(-6,20,-4,minecraft:planks:15)
Block(-6,20,-3,minecraft:concrete:0)
Block(-6,20,-2,minecraft:planks:8,../../../Chests/Loot/manhunt_vagrant_scrap.nbt)
Block(-6,20,-1,minecraft:planks:8,../../../Chests/Loot/manhunt_vagrant_scrap.nbt)
Block(-6,20,0,minecraft:stone_brick_stairs:1)
Block(-6,20,1,minecraft:planks:8,../../../Chests/Loot/manhunt_vagrant_scrap.nbt)
Block(-6,20,2,minecraft:planks:8,../../../Chests/Loot/manhunt_vagrant_scrap.nbt)
Block(-6,20,3,minecraft:stonebrick)
Block(-6,20,4,minecraft:concrete:0)
Block(-6,20,5,WEB:0)
Block(-6,20,6,AIR:0)
Block(-6,20,7,AIR:0)
Block(-6,20,8,AIR:0)
Block(-6,20,9,minecraft:concrete:0)
Block(-6,21,-6,minecraft:concrete:0)
Block(-6,21,-5,minecraft:concrete:0)
Block(-6,21,-4,minecraft:concrete:0)
Block(-6,21,-3,minecraft:concrete:0)
Block(-6,21,-2,minecraft:concrete:0)
Block(-6,21,-1,minecraft:concrete:0)
Block(-6,21,0,minecraft:concrete:0)
Block(-6,21,1,minecraft:concrete:0)
Block(-6,21,2,minecraft:concrete:0)
Block(-6,21,3,minecraft:concrete:0)
Block(-6,21,4,minecraft:concrete:0)
Block(-6,21,5,minecraft:concrete:0)
Block(-6,21,6,minecraft:concrete:0)
Block(-6,21,7,minecraft:concrete:0)
Block(-6,21,8,minecraft:concrete:0)
Block(-6,21,9,minecraft:concrete:0)
Block(-6,22,-6,minecraft:concrete:0)
Block(-6,22,-5,minecraft:planks:8,../../../Chests/Loot/manhunt_vagrant_scrap.nbt)
Block(-6,22,-4,minecraft:planks:0,../../../Chests/Loot/manhunt_vagrant_scrap.nbt)
Block(-6,22,-3,minecraft:concrete:0)
Block(-6,22,-2,minecraft:stonebrick:8)
Block(-6,22,-1,minecraft:planks:0,../../../Chests/Loot/manhunt_vagrant_scrap.nbt)
Block(-6,22,0,minecraft:furnace:5)
Block(-6,22,1,minecraft:planks:8,../../../Chests/Loot/manhunt_vagrant_scrap.nbt)
Block(-6,22,2,minecraft:planks:5)
Block(-6,22,3,minecraft:stonebrick:0)
Block(-6,22,4,minecraft:concrete:0)
Block(-6,22,5,AIR:0)
Block(-6,22,6,minecraft:oak_stairs:1)
Block(-6,22,7,minecraft:oak_stairs:1)
Block(-6,22,8,minecraft:oak_stairs:5)
Block(-6,22,9,minecraft:concrete:0)
Block(-6,23,-6,minecraft:concrete:0)
Block(-6,23,-5,minecraft:planks:15)
Block(-6,23,-4,minecraft:planks:15)
Block(-6,23,-3,minecraft:concrete:0)
Block(-6,23,-2,minecraft:bookshelf:0)
Block(-6,23,-1,AIR:0)
Block(-6,23,0,quark:grate:0)
Block(-6,23,1,minecraft:bookshelf:0)
Block(-6,23,2,minecraft:stonebrick:5)
Block(-6,23,3,minecraft:stonebrick:0)
Block(-6,23,4,minecraft:concrete:0)
Block(-6,23,5,AIR:0)
Block(-6,23,6,AIR:0)
Block(-6,23,7,AIR:0)
Block(-6,23,8,AIR:0)
Block(-6,23,9,minecraft:concrete:0)
Block(-6,24,-6,minecraft:concrete:0)
Block(-6,24,-5,minecraft:planks:15)
Block(-6,24,-4,minecraft:planks:15)
Block(-6,24,-3,minecraft:concrete:0)
Block(-6,24,-2,minecraft:planks:8,../../../Chests/Loot/manhunt_vagrant_scrap.nbt)
Block(-6,24,-1,minecraft:planks:8,../../../Chests/Loot/manhunt_vagrant_scrap.nbt)
Block(-6,24,0,minecraft:stone_brick_stairs:1)
Block(-6,24,1,minecraft:planks:8,../../../Chests/Loot/manhunt_vagrant_scrap.nbt)
Block(-6,24,2,minecraft:planks:8,../../../Chests/Loot/manhunt_vagrant_scrap.nbt)
Block(-6,24,3,minecraft:stonebrick:5)
Block(-6,24,4,minecraft:concrete:0)
Block(-6,24,5,AIR:0)
Block(-6,24,6,AIR:0)
Block(-6,24,7,AIR:0)
Block(-6,24,8,WEB:0)
Block(-6,24,9,minecraft:concrete:0)
Block(-6,25,-6,minecraft:concrete:0)
Block(-6,25,-5,minecraft:concrete:0)
Block(-6,25,-4,minecraft:concrete:0)
Block(-6,25,-3,minecraft:concrete:0)
Block(-6,25,-2,minecraft:concrete:0)
Block(-6,25,-1,minecraft:concrete:0)
Block(-6,25,0,minecraft:concrete:0)
Block(-6,25,1,minecraft:concrete:0)
Block(-6,25,2,minecraft:concrete:0)
Block(-6,25,3,minecraft:concrete:0)
Block(-6,25,4,minecraft:concrete:0)
Block(-6,25,5,minecraft:concrete:0)
Block(-6,25,6,minecraft:concrete:0)
Block(-6,25,7,minecraft:concrete:0)
Block(-6,25,8,minecraft:concrete:0)
Block(-6,25,9,minecraft:concrete:0)
Block(-6,26,-6,minecraft:concrete:0)
Block(-6,26,-5,minecraft:planks:8,../../../Chests/Loot/manhunt_vagrant_scrap.nbt)
Block(-6,26,-4,minecraft:planks:0,../../../Chests/Loot/manhunt_vagrant_scrap.nbt)
Block(-6,26,-3,minecraft:concrete:0)
Block(-6,26,-2,minecraft:stonebrick:8)
Block(-6,26,-1,minecraft:planks:0,../../../Chests/Loot/manhunt_vagrant_scrap.nbt)
Block(-6,26,0,minecraft:furnace:5)
Block(-6,26,1,minecraft:planks:8,../../../Chests/Loot/manhunt_vagrant_scrap.nbt)
Block(-6,26,2,minecraft:planks:5)
Block(-6,26,3,minecraft:stonebrick:0)
Block(-6,26,4,minecraft:concrete:0)
Block(-6,26,5,WEB:0)
Block(-6,26,6,minecraft:oak_stairs:1)
Block(-6,26,7,minecraft:oak_stairs:1)
Block(-6,26,8,minecraft:oak_stairs:5)
Block(-6,26,9,minecraft:concrete:0)
Block(-6,27,-6,minecraft:concrete:0)
Block(-6,27,-5,minecraft:planks:15)
Block(-6,27,-4,minecraft:planks:15)
Block(-6,27,-3,minecraft:concrete:0)
Block(-6,27,-2,minecraft:bookshelf:0)
Block(-6,27,-1,minecraft:stonebrick:3)
Block(-6,27,0,quark:grate:0)
Block(-6,27,1,minecraft:bookshelf:0)
Block(-6,27,2,minecraft:stonebrick:5)
Block(-6,27,3,minecraft:stonebrick:0)
Block(-6,27,4,minecraft:concrete:0)
Block(-6,27,5,AIR:0)
Block(-6,27,6,AIR:0)
Block(-6,27,7,AIR:0)
Block(-6,27,8,AIR:0)
Block(-6,27,9,minecraft:concrete:0)
Block(-6,28,-6,minecraft:concrete:0)
Block(-6,28,-5,minecraft:planks:15)
Block(-6,28,-4,minecraft:planks:15)
Block(-6,28,-3,minecraft:concrete:0)
Block(-6,28,-2,minecraft:planks:8,../../../Chests/Loot/manhunt_vagrant_scrap.nbt)
Block(-6,28,-1,minecraft:planks:8,../../../Chests/Loot/manhunt_vagrant_scrap.nbt)
Block(-6,28,0,minecraft:stone_brick_stairs:1)
Block(-6,28,1,minecraft:planks:8,../../../Chests/Loot/manhunt_vagrant_scrap.nbt)
Block(-6,28,2,minecraft:planks:8,../../../Chests/Loot/manhunt_vagrant_scrap.nbt)
Block(-6,28,3,minecraft:stonebrick:5)
Block(-6,28,4,minecraft:concrete:0)
Block(-6,28,5,AIR:0)
Block(-6,28,6,AIR:0)
Block(-6,28,7,AIR:0)
Block(-6,28,8,WEB:0)
Block(-6,28,9,minecraft:concrete:0)
Block(-6,29,-6,minecraft:concrete:0)
Block(-6,29,-5,minecraft:concrete:0)
Block(-6,29,-4,minecraft:concrete:0)
Block(-6,29,-3,minecraft:concrete:0)
Block(-6,29,-2,minecraft:concrete:0)
Block(-6,29,-1,minecraft:concrete:0)
Block(-6,29,0,minecraft:concrete:0)
Block(-6,29,1,minecraft:concrete:0)
Block(-6,29,2,minecraft:concrete:0)
Block(-6,29,3,minecraft:concrete:0)
Block(-6,29,4,minecraft:concrete:0)
Block(-6,29,5,minecraft:concrete:0)
Block(-6,29,6,minecraft:concrete:0)
Block(-6,29,7,minecraft:concrete:0)
Block(-6,29,8,minecraft:concrete:0)
Block(-6,29,9,minecraft:concrete:0)
Block(-6,30,-6,minecraft:concrete:0)
Block(-6,30,-5,minecraft:planks:0)
Block(-6,30,-4,minecraft:planks:0)
RandomBlock(-6,30,-3,minecraft:planks:5,5,minecraft:planks:5,../../../Chests/Loot/manhunt_vagrant_scrap.nbt,100)
Block(-6,30,-2,minecraft:planks:0,../../../Chests/Loot/manhunt_vagrant_scrap.nbt)
Block(-6,30,-1,minecraft:planks:1)
Block(-6,30,0,minecraft:planks:0)
RandomBlock(-6,30,1,minecraft:planks:5,5,minecraft:planks:5,../../../Chests/Loot/manhunt_vagrant_scrap.nbt,100)
Block(-6,30,2,minecraft:planks:0)
Block(-6,30,3,minecraft:concrete:0)
Block(-6,31,-6,minecraft:concrete:0)
Block(-6,31,-5,minecraft:planks:0)
Block(-6,31,-4,minecraft:oak_stairs:1)
Block(-6,31,-3,minecraft:planks:8,../../../Chests/Loot/manhunt_vagrant_scrap.nbt)
Block(-6,31,-2,minecraft:planks:0,../../../Chests/Loot/manhunt_vagrant_scrap.nbt)
Block(-6,31,-1,minecraft:planks:5)
Block(-6,31,0,minecraft:oak_stairs:5)
Block(-6,31,1,minecraft:planks:5)
Block(-6,31,2,minecraft:planks:0)
Block(-6,31,3,minecraft:concrete:0)
Block(-6,32,-6,minecraft:concrete:0)
RandomBlock(-6,32,-5,minecraft:planks:5,5,minecraft:planks:1,../../../Chests/Loot/manhunt_vagrant_scrap.nbt,100)
Block(-6,32,-4,AIR:0)
Block(-6,32,-3,AIR:0)
Block(-6,32,-2,AIR:0)
Block(-6,32,-1,AIR:0)
Block(-6,32,0,AIR:0)
Block(-6,32,1,AIR:0)
RandomBlock(-6,32,2,minecraft:planks:5,5,minecraft:planks:1,../../../Chests/Loot/manhunt_vagrant_scrap.nbt,100)
Block(-6,32,3,minecraft:concrete:0)
Block(-6,33,-6,minecraft:concrete:0)
Block(-6,33,-5,minecraft:concrete:0)
Block(-6,33,-4,minecraft:concrete:0)
Block(-6,33,-3,minecraft:concrete:0)
Block(-6,33,-2,minecraft:concrete:0)
Block(-6,33,-1,minecraft:concrete:0)
Block(-6,33,0,minecraft:concrete:0)
Block(-6,33,1,minecraft:concrete:0)
Block(-6,33,2,minecraft:concrete:0)
Block(-6,33,3,minecraft:concrete:0)
Block(-5,0,-6,minecraft:concrete:0)
Block(-5,0,-5,minecraft:concrete:0)
Block(-5,0,-4,minecraft:concrete:0)
Block(-5,0,-3,minecraft:concrete:0)
Block(-5,0,-2,minecraft:concrete:0)
Block(-5,0,-1,minecraft:concrete:0)
Block(-5,0,0,minecraft:concrete:0)
Block(-5,0,1,minecraft:concrete:0)
Block(-5,0,2,minecraft:concrete:0)
Block(-5,0,3,minecraft:concrete:0)
Block(-5,0,4,minecraft:concrete:0)
Block(-5,0,5,minecraft:concrete:0)
Block(-5,0,6,minecraft:concrete:0)
Block(-5,0,7,minecraft:concrete:0)
Block(-5,0,8,minecraft:concrete:0)
Block(-5,0,9,minecraft:concrete:0)
Block(-5,1,-6,minecraft:concrete:0)
Block(-5,1,-5,minecraft:concrete:0)
Block(-5,1,-4,minecraft:concrete:0)
Block(-5,1,-3,minecraft:concrete:0)
Block(-5,1,-2,minecraft:concrete:0)
Block(-5,1,-1,STATIONARY_WATER:0)
Block(-5,1,0,STATIONARY_WATER:0)
Block(-5,1,1,STATIONARY_WATER:0)
Block(-5,1,2,STATIONARY_WATER:0)
Block(-5,1,3,STATIONARY_WATER:0)
Block(-5,1,4,STATIONARY_WATER:0)
Block(-5,1,5,STATIONARY_WATER:0)
Block(-5,1,6,STATIONARY_WATER:0)
Block(-5,1,7,STATIONARY_WATER:0)
Block(-5,1,8,STATIONARY_WATER:0)
Block(-5,1,9,minecraft:concrete:0)
Block(-5,2,-6,minecraft:concrete:0)
Block(-5,2,-5,minecraft:iron_block:1)
Block(-5,2,-4,AIR:0)
Block(-5,2,-3,AIR:0)
Block(-5,2,-2,minecraft:iron_bars:0)
Block(-5,2,-1,AIR:0)
Block(-5,2,0,AIR:0)
Block(-5,2,1,AIR:0)
Block(-5,2,2,AIR:0)
Block(-5,2,3,AIR:0)
Block(-5,2,4,AIR:0)
Block(-5,2,5,AIR:0)
Block(-5,2,6,AIR:0)
Block(-5,2,7,AIR:0)
Block(-5,2,8,minecraft:iron_block:1)
Block(-5,2,9,minecraft:concrete:0)
Block(-5,3,-6,minecraft:concrete:0)
Block(-5,3,-5,minecraft:stonebrick:3)
Block(-5,3,-4,AIR:0)
Block(-5,3,-3,AIR:0)
Block(-5,3,-2,minecraft:iron_bars:0)
Block(-5,3,-1,AIR:0)
Block(-5,3,0,AIR:0)
Block(-5,3,1,AIR:0)
Block(-5,3,2,AIR:0)
Block(-5,3,3,AIR:0)
Block(-5,3,4,AIR:0)
Block(-5,3,5,AIR:0)
Block(-5,3,6,AIR:0)
Block(-5,3,7,AIR:0)
Block(-5,3,8,AIR:0)
Block(-5,3,9,minecraft:concrete:0)
Block(-5,4,-6,minecraft:concrete:0)
Block(-5,4,-5,AIR:0)
Block(-5,4,-4,AIR:0)
Block(-5,4,-3,AIR:0)
Block(-5,4,-2,minecraft:iron_bars:0)
Block(-5,4,-1,AIR:0)
Block(-5,4,0,AIR:0)
Block(-5,4,1,AIR:0)
Block(-5,4,2,AIR:0)
Block(-5,4,3,AIR:0)
Block(-5,4,4,AIR:0)
Block(-5,4,5,AIR:0)
Block(-5,4,6,AIR:0)
Block(-5,4,7,AIR:0)
Block(-5,4,8,AIR:0)
Block(-5,4,9,minecraft:concrete:0)
Block(-5,5,-6,minecraft:concrete:0)
Block(-5,5,-5,minecraft:concrete:0)
Block(-5,5,-4,minecraft:concrete:0)
Block(-5,5,-3,minecraft:concrete:0)
Block(-5,5,-2,minecraft:concrete:0)
Block(-5,5,-1,minecraft:concrete:0)
Block(-5,5,0,minecraft:concrete:0)
Block(-5,5,1,minecraft:concrete:0)
Block(-5,5,2,minecraft:concrete:0)
Block(-5,5,3,minecraft:concrete:0)
Block(-5,5,4,minecraft:concrete:0)
Block(-5,5,5,minecraft:concrete:0)
Block(-5,5,6,minecraft:concrete:0)
Block(-5,5,7,minecraft:concrete:0)
Block(-5,5,8,minecraft:concrete:0)
Block(-5,5,9,minecraft:concrete:0)
Block(-5,6,-6,minecraft:concrete:0)
Block(-5,6,-5,minecraft:tallgrass:0)
Block(-5,6,-4,AIR:0)
Block(-5,6,-3,minecraft:stone:0)
Block(-5,6,-2,AIR:0)
Block(-5,6,-1,AIR:0)
Block(-5,6,0,minecraft:stonebrick:0)
Block(-5,6,1,AIR:0)
Block(-5,6,2,minecraft:stone_brick_stairs:2)
Block(-5,6,3,quark:grate:0)
Block(-5,6,4,quark:grate:0)
Block(-5,6,5,minecraft:iron_block:0)
Block(-5,6,6,quark:grate:0)
Block(-5,6,7,quark:grate:0)
Block(-5,6,8,quark:grate:0)
Block(-5,6,9,minecraft:concrete:0)
Block(-5,7,-6,minecraft:concrete:0)
Block(-5,7,-5,AIR:0)
Block(-5,7,-4,AIR:0)
Block(-5,7,-3,AIR:0)
Block(-5,7,-2,AIR:0)
Block(-5,7,-1,AIR:0)
Block(-5,7,0,AIR:0)
Block(-5,7,1,AIR:0)
Block(-5,7,2,AIR:0)
Block(-5,7,3,AIR:0)
Block(-5,7,4,AIR:0)
Block(-5,7,5,minecraft:tallgrass:0)
Block(-5,7,6,AIR:0)
Block(-5,7,7,AIR:0)
Block(-5,7,8,AIR:0)
Block(-5,7,9,minecraft:concrete:0)
Block(-5,8,-6,minecraft:concrete:0)
Block(-5,8,-5,AIR:0)
Block(-5,8,-4,AIR:0)
Block(-5,8,-3,AIR:0)
Block(-5,8,-2,AIR:0)
Block(-5,8,-1,AIR:0)
Block(-5,8,0,AIR:0)
Block(-5,8,1,AIR:0)
Block(-5,8,2,AIR:0)
Block(-5,8,3,AIR:0)
Block(-5,8,4,AIR:0)
Block(-5,8,5,minecraft:iron_block:1)
Block(-5,8,6,AIR:0)
Block(-5,8,7,AIR:0)
Block(-5,8,8,AIR:0)
Block(-5,8,9,minecraft:concrete:0)
Block(-5,9,-6,minecraft:concrete:0)
Block(-5,9,-5,minecraft:concrete:0)
Block(-5,9,-4,minecraft:concrete:0)
Block(-5,9,-3,minecraft:concrete:0)
Block(-5,9,-2,minecraft:concrete:0)
Block(-5,9,-1,minecraft:concrete:0)
Block(-5,9,0,minecraft:concrete:0)
Block(-5,9,1,minecraft:concrete:0)
Block(-5,9,2,minecraft:concrete:0)
Block(-5,9,3,minecraft:concrete:0)
Block(-5,9,4,minecraft:concrete:0)
Block(-5,9,5,minecraft:concrete:0)
Block(-5,9,6,minecraft:concrete:0)
Block(-5,9,7,minecraft:concrete:0)
Block(-5,9,8,minecraft:concrete:0)
Block(-5,9,9,minecraft:concrete:0)
Block(-5,10,-6,minecraft:concrete:0)
RandomBlock(-5,10,-5,minecraft:planks:5,5,minecraft:planks:1,../../../Chests/Loot/manhunt_vagrant_scrap.nbt,100)
Block(-5,10,-4,minecraft:stonebrick:0)
Block(-5,10,-3,AIR:0)
Block(-5,10,-2,minecraft:stonebrick:0)
Block(-5,10,-1,AIR:0)
Block(-5,10,0,minecraft:stonebrick:0)
Block(-5,10,1,AIR:0)
Block(-5,10,2,minecraft:tallgrass:3)
Block(-5,10,3,minecraft:stonebrick:0)
Block(-5,10,4,AIR:0)
Block(-5,10,5,minecraft:stonebrick:3)
Block(-5,10,6,minecraft:iron_block:0)
Block(-5,10,7,minecraft:water:0)
Block(-5,10,8,minecraft:water:0)
Block(-5,10,9,minecraft:concrete:0)
Block(-5,11,-6,minecraft:concrete:0)
Block(-5,11,-5,minecraft:planks:3)
Block(-5,11,-4,AIR:0)
Block(-5,11,-3,AIR:0)
Block(-5,11,-2,AIR:0)
Block(-5,11,-1,AIR:0)
Block(-5,11,0,AIR:0)
Block(-5,11,1,AIR:0)
Block(-5,11,2,AIR:0)
Block(-5,11,3,AIR:0)
Block(-5,11,4,AIR:0)
Block(-5,11,5,AIR:0)
Block(-5,11,6,quark:framed_glass:0)
Block(-5,11,7,minecraft:water:0)
Block(-5,11,8,minecraft:water:0)
Block(-5,11,9,minecraft:concrete:0)
Block(-5,12,-6,minecraft:concrete:0)
Block(-5,12,-5,minecraft:planks:3)
Block(-5,12,-4,AIR:0)
Block(-5,12,-3,AIR:0)
Block(-5,12,-2,AIR:0)
Block(-5,12,-1,AIR:0)
Block(-5,12,0,AIR:0)
Block(-5,12,1,AIR:0)
Block(-5,12,2,AIR:0)
Block(-5,12,3,AIR:0)
Block(-5,12,4,AIR:0)
Block(-5,12,5,AIR:0)
Block(-5,12,6,minecraft:iron_block:0)
Block(-5,12,7,minecraft:water:0)
Block(-5,12,8,minecraft:water:0)
Block(-5,12,9,minecraft:concrete:0)
Block(-5,13,-6,minecraft:concrete:0)
Block(-5,13,-5,minecraft:concrete:0)
Block(-5,13,-4,minecraft:concrete:0)
Block(-5,13,-3,minecraft:concrete:0)
Block(-5,13,-2,minecraft:concrete:0)
Block(-5,13,-1,minecraft:concrete:0)
Block(-5,13,0,minecraft:concrete:0)
Block(-5,13,1,minecraft:concrete:0)
Block(-5,13,2,minecraft:concrete:0)
Block(-5,13,3,minecraft:concrete:0)
Block(-5,13,4,minecraft:concrete:0)
Block(-5,13,5,minecraft:concrete:0)
Block(-5,13,6,minecraft:concrete:0)
Block(-5,13,7,minecraft:concrete:0)
Block(-5,13,8,minecraft:concrete:0)
Block(-5,13,9,minecraft:concrete:0)
Block(-5,14,-6,minecraft:concrete:0)
Block(-5,14,-5,minecraft:planks:2,../../../Chests/Loot/manhunt_vagrant_scrap.nbt)
Block(-5,14,-4,AIR:0)
Block(-5,14,-3,CARPET:4)
Block(-5,14,-2,CARPET:15)
Block(-5,14,-1,CARPET:15)
Block(-5,14,0,CARPET:15)
Block(-5,14,1,CARPET:15)
Block(-5,14,2,CARPET:4)
Block(-5,14,3,minecraft:stone:0)
Block(-5,14,4,AIR:0)
Block(-5,14,5,AIR:0)
Block(-5,14,6,minecraft:planks:5)
Block(-5,14,7,minecraft:planks:5)
Block(-5,14,8,minecraft:planks:5)
Block(-5,14,9,minecraft:concrete:0)
Block(-5,15,-6,minecraft:concrete:0)
Block(-5,15,-5,minecraft:netherrack:0)
Block(-5,15,-4,AIR:0)
Block(-5,15,-3,AIR:0)
Block(-5,15,-2,AIR:0)
Block(-5,15,-1,AIR:0)
Block(-5,15,0,AIR:0)
Block(-5,15,1,AIR:0)
Block(-5,15,2,AIR:0)
Block(-5,15,3,AIR:0)
Block(-5,15,4,AIR:0)
Block(-5,15,5,AIR:0)
Block(-5,15,6,AIR:0)
Block(-5,15,7,AIR:0)
Block(-5,15,8,minecraft:glowstone)
Block(-5,15,9,minecraft:concrete:0)
Block(-5,16,-6,minecraft:concrete:0)
Block(-5,16,-5,minecraft:tallgrass:8)
Block(-5,16,-4,AIR:0)
Block(-5,16,-3,STEP:8)
Block(-5,16,-2,STEP:8)
Block(-5,16,-1,STEP:8)
Block(-5,16,0,STEP:8)
Block(-5,16,1,STEP:8)
Block(-5,16,2,STEP:8)
Block(-5,16,3,STEP:8)
Block(-5,16,4,STEP:8)
Block(-5,16,5,STEP:8)
Block(-5,16,6,STEP:8)
Block(-5,16,7,AIR:0)
Block(-5,16,8,minecraft:stonebrick)
Block(-5,16,9,minecraft:concrete:0)
Block(-5,17,-6,minecraft:concrete:0)
Block(-5,17,-5,minecraft:concrete:0)
Block(-5,17,-4,minecraft:concrete:0)
Block(-5,17,-3,minecraft:concrete:0)
Block(-5,17,-2,minecraft:concrete:0)
Block(-5,17,-1,minecraft:concrete:0)
Block(-5,17,0,minecraft:concrete:0)
Block(-5,17,1,minecraft:concrete:0)
Block(-5,17,2,minecraft:concrete:0)
Block(-5,17,3,minecraft:concrete:0)
Block(-5,17,4,minecraft:concrete:0)
Block(-5,17,5,minecraft:concrete:0)
Block(-5,17,6,minecraft:concrete:0)
Block(-5,17,7,minecraft:concrete:0)
Block(-5,17,8,minecraft:concrete:0)
Block(-5,17,9,minecraft:concrete:0)
Block(-5,18,-6,minecraft:concrete:0)
Block(-5,18,-5,minecraft:stone:0)
Block(-5,18,-4,AIR:0)
Block(-5,18,-3,minecraft:stonebrick:0)
Block(-5,18,-2,AIR:0)
Block(-5,18,-1,AIR:0)
Block(-5,18,0,AIR:0)
Block(-5,18,1,AIR:0)
Block(-5,18,2,AIR:0)
Block(-5,18,3,minecraft:stone:0)
Block(-5,18,4,minecraft:tallgrass:0)
Block(-5,18,5,minecraft:stonebrick:0)
Block(-5,18,6,minecraft:planks:5)
Block(-5,18,7,minecraft:planks:5)
Block(-5,18,8,minecraft:planks:5)
Block(-5,18,9,minecraft:concrete:0)
Block(-5,19,-6,minecraft:concrete:0)
Block(-5,19,-5,AIR:0)
Block(-5,19,-4,AIR:0)
Block(-5,19,-3,AIR:0)
Block(-5,19,-2,AIR:0)
Block(-5,19,-1,AIR:0)
Block(-5,19,0,AIR:0)
Block(-5,19,1,AIR:0)
Block(-5,19,2,AIR:0)
Block(-5,19,3,AIR:0)
Block(-5,19,4,AIR:0)
Block(-5,19,5,AIR:0)
Block(-5,19,6,AIR:0)
Block(-5,19,7,minecraft:stonebrick)
Block(-5,19,8,AIR:0)
Block(-5,19,9,minecraft:concrete:0)
Block(-5,20,-6,minecraft:concrete:0)
Block(-5,20,-5,AIR:0)
Block(-5,20,-4,STEP:8)
Block(-5,20,-3,STEP:8)
Block(-5,20,-2,STEP:8)
Block(-5,20,-1,STEP:8)
Block(-5,20,0,STEP:8)
Block(-5,20,1,STEP:8)
Block(-5,20,2,STEP:8)
Block(-5,20,3,STEP:8)
Block(-5,20,4,STEP:8)
Block(-5,20,5,STEP:8)
Block(-5,20,6,STEP:8)
Block(-5,20,7,AIR:0)
Block(-5,20,8,minecraft:stonebrick)
Block(-5,20,9,minecraft:concrete:0)
Block(-5,21,-6,minecraft:concrete:0)
Block(-5,21,-5,minecraft:concrete:0)
Block(-5,21,-4,minecraft:concrete:0)
Block(-5,21,-3,minecraft:concrete:0)
Block(-5,21,-2,minecraft:concrete:0)
Block(-5,21,-1,minecraft:concrete:0)
Block(-5,21,0,minecraft:concrete:0)
Block(-5,21,1,minecraft:concrete:0)
Block(-5,21,2,minecraft:concrete:0)
Block(-5,21,3,minecraft:concrete:0)
Block(-5,21,4,minecraft:concrete:0)
Block(-5,21,5,minecraft:concrete:0)
Block(-5,21,6,minecraft:concrete:0)
Block(-5,21,7,minecraft:concrete:0)
Block(-5,21,8,minecraft:concrete:0)
Block(-5,21,9,minecraft:concrete:0)
Block(-5,22,-6,minecraft:concrete:0)
Block(-5,22,-5,AIR:0)
Block(-5,22,-4,minecraft:stonebrick:0)
Block(-5,22,-3,minecraft:stone:0)
Block(-5,22,-2,AIR:0)
Block(-5,22,-1,AIR:0)
Block(-5,22,0,minecraft:tallgrass:0)
Block(-5,22,1,AIR:0)
Block(-5,22,2,AIR:0)
Block(-5,22,3,minecraft:tallgrass:0)
Block(-5,22,4,minecraft:stone:0)
Block(-5,22,5,AIR:0)
Block(-5,22,6,minecraft:planks:5)
Block(-5,22,7,minecraft:planks:5)
Block(-5,22,8,minecraft:planks:5)
Block(-5,22,9,minecraft:concrete:0)
Block(-5,23,-6,minecraft:concrete:0)
Block(-5,23,-5,AIR:0)
Block(-5,23,-4,AIR:0)
Block(-5,23,-3,AIR:0)
Block(-5,23,-2,AIR:0)
Block(-5,23,-1,AIR:0)
Block(-5,23,0,AIR:0)
Block(-5,23,1,AIR:0)
Block(-5,23,2,AIR:0)
Block(-5,23,3,AIR:0)
Block(-5,23,4,AIR:0)
Block(-5,23,5,AIR:0)
Block(-5,23,6,minecraft:stonebrick)
Block(-5,23,7,AIR:0)
Block(-5,23,8,minecraft:stonebrick:5)
Block(-5,23,9,minecraft:concrete:0)
Block(-5,24,-6,minecraft:concrete:0)
Block(-5,24,-5,WEB:0)
Block(-5,24,-4,STEP:8)
Block(-5,24,-3,STEP:8)
Block(-5,24,-2,STEP:8)
Block(-5,24,-1,STEP:8)
Block(-5,24,0,STEP:8)
Block(-5,24,1,STEP:8)
Block(-5,24,2,STEP:8)
Block(-5,24,3,STEP:8)
Block(-5,24,4,STEP:8)
Block(-5,24,5,STEP:8)
Block(-5,24,6,STEP:8)
Block(-5,24,7,AIR:0)
Block(-5,24,8,minecraft:stonebrick)
Block(-5,24,9,minecraft:concrete:0)
Block(-5,25,-6,minecraft:concrete:0)
Block(-5,25,-5,minecraft:concrete:0)
Block(-5,25,-4,minecraft:concrete:0)
Block(-5,25,-3,minecraft:concrete:0)
Block(-5,25,-2,minecraft:concrete:0)
Block(-5,25,-1,minecraft:concrete:0)
Block(-5,25,0,minecraft:concrete:0)
Block(-5,25,1,minecraft:concrete:0)
Block(-5,25,2,minecraft:concrete:0)
Block(-5,25,3,minecraft:concrete:0)
Block(-5,25,4,minecraft:concrete:0)
Block(-5,25,5,minecraft:concrete:0)
Block(-5,25,6,minecraft:concrete:0)
Block(-5,25,7,minecraft:concrete:0)
Block(-5,25,8,minecraft:concrete:0)
Block(-5,25,9,minecraft:concrete:0)
Block(-5,26,-6,minecraft:concrete:0)
Block(-5,26,-5,AIR:0)
Block(-5,26,-4,minecraft:stone:0)
Block(-5,26,-3,AIR:0)
Block(-5,26,-2,AIR:0)
Block(-5,26,-1,minecraft:tallgrass:0)
Block(-5,26,0,minecraft:stonebrick:0)
Block(-5,26,1,AIR:0)
Block(-5,26,2,AIR:0)
Block(-5,26,3,minecraft:stone:0)
Block(-5,26,4,minecraft:stonebrick:0)
Block(-5,26,5,AIR:0)
Block(-5,26,6,minecraft:planks:5)
Block(-5,26,7,minecraft:planks:5)
Block(-5,26,8,minecraft:planks:5)
Block(-5,26,9,minecraft:concrete:0)
Block(-5,27,-6,minecraft:concrete:0)
Block(-5,27,-5,AIR:0)
Block(-5,27,-4,AIR:0)
Block(-5,27,-3,AIR:0)
Block(-5,27,-2,AIR:0)
Block(-5,27,-1,AIR:0)
Block(-5,27,0,AIR:0)
Block(-5,27,1,AIR:0)
Block(-5,27,2,AIR:0)
Block(-5,27,3,AIR:0)
Block(-5,27,4,AIR:0)
Block(-5,27,5,AIR:0)
Block(-5,27,6,minecraft:stonebrick)
Block(-5,27,7,AIR:0)
Block(-5,27,8,minecraft:stonebrick:5)
Block(-5,27,9,minecraft:concrete:0)
Block(-5,28,-6,minecraft:concrete:0)
Block(-5,28,-5,WEB:0)
Block(-5,28,-4,STEP:8)
Block(-5,28,-3,STEP:8)
Block(-5,28,-2,STEP:8)
Block(-5,28,-1,STEP:8)
Block(-5,28,0,STEP:8)
Block(-5,28,1,STEP:8)
Block(-5,28,2,STEP:8)
Block(-5,28,3,STEP:8)
Block(-5,28,4,STEP:8)
Block(-5,28,5,STEP:8)
Block(-5,28,6,STEP:8)
Block(-5,28,7,AIR:0)
Block(-5,28,8,minecraft:stonebrick)
Block(-5,28,9,minecraft:concrete:0)
Block(-5,29,-6,minecraft:concrete:0)
Block(-5,29,-5,minecraft:concrete:0)
Block(-5,29,-4,minecraft:concrete:0)
Block(-5,29,-3,minecraft:concrete:0)
Block(-5,29,-2,minecraft:concrete:0)
Block(-5,29,-1,minecraft:concrete:0)
Block(-5,29,0,minecraft:concrete:0)
Block(-5,29,1,minecraft:concrete:0)
Block(-5,29,2,minecraft:concrete:0)
Block(-5,29,3,minecraft:concrete:0)
Block(-5,29,4,minecraft:concrete:0)
Block(-5,29,5,minecraft:concrete:0)
Block(-5,29,6,minecraft:concrete:0)
Block(-5,29,7,minecraft:concrete:0)
Block(-5,29,8,minecraft:concrete:0)
Block(-5,29,9,minecraft:concrete:0)
Block(-5,30,-6,minecraft:concrete:0)
RandomBlock(-5,30,-5,minecraft:planks:5,5,minecraft:planks:5,../../../Chests/Loot/manhunt_vagrant_scrap.nbt,100)
Block(-5,30,-4,AIR:0)
Block(-5,30,-3,AIR:0)
Block(-5,30,-2,minecraft:stone:0)
Block(-5,30,-1,AIR:0)
Block(-5,30,0,minecraft:stonebrick:0)
Block(-5,30,1,minecraft:stone:0)
Block(-5,30,2,minecraft:planks:0)
Block(-5,30,3,minecraft:concrete:0)
Block(-5,30,6,minecraft:concrete:0)
Block(-5,30,7,minecraft:concrete:0)
Block(-5,31,-6,minecraft:concrete:0)
Block(-5,31,-5,minecraft:planks:1)
Block(-5,31,-4,AIR:0)
Block(-5,31,-3,AIR:0)
Block(-5,31,-2,AIR:0)
Block(-5,31,-1,AIR:0)
Block(-5,31,0,AIR:0)
Block(-5,31,1,AIR:0)
Block(-5,31,2,minecraft:planks:5)
Block(-5,31,3,minecraft:concrete:0)
Block(-5,31,6,minecraft:concrete:0)
Block(-5,31,7,minecraft:concrete:0)
Block(-5,32,-6,minecraft:concrete:0)
Block(-5,32,-5,WEB:0)
Block(-5,32,-4,AIR:0)
Block(-5,32,-3,AIR:0)
Block(-5,32,-2,AIR:0)
Block(-5,32,-1,AIR:0)
Block(-5,32,0,AIR:0)
Block(-5,32,1,AIR:0)
Block(-5,32,2,WEB:0)
Block(-5,32,3,minecraft:concrete:0)
Block(-5,32,6,minecraft:concrete:0)
Block(-5,32,7,minecraft:concrete:0)
Block(-5,33,-6,minecraft:concrete:0)
Block(-5,33,-5,minecraft:concrete:0)
Block(-5,33,-4,minecraft:concrete:0)
Block(-5,33,-3,minecraft:concrete:0)
Block(-5,33,-2,minecraft:concrete:0)
Block(-5,33,-1,minecraft:concrete:0)
Block(-5,33,0,minecraft:concrete:0)
Block(-5,33,1,minecraft:concrete:0)
Block(-5,33,2,minecraft:concrete:0)
Block(-5,33,3,minecraft:concrete:0)
Block(-5,33,6,minecraft:concrete:0)
Block(-5,33,7,minecraft:concrete:0)
Block(-5,34,-5,minecraft:concrete:0)
Block(-5,34,-4,minecraft:concrete:0)
Block(-5,34,-1,minecraft:concrete:0)
Block(-5,34,0,minecraft:concrete:0)
Block(-5,34,6,minecraft:concrete:0)
Block(-5,34,7,minecraft:concrete:0)
Block(-5,35,-5,minecraft:concrete:0)
Block(-5,35,-4,minecraft:concrete:0)
Block(-5,35,-1,minecraft:concrete:0)
Block(-5,35,0,minecraft:concrete:0)
Block(-5,35,6,minecraft:concrete:0)
Block(-5,35,7,minecraft:concrete:0)
Block(-5,36,-5,minecraft:concrete:0)
Block(-5,36,-4,minecraft:concrete:0)
Block(-5,36,-1,minecraft:concrete:0)
Block(-5,36,0,minecraft:concrete:0)
Block(-5,36,6,minecraft:concrete:0)
Block(-5,36,7,minecraft:concrete:0)
Block(-5,37,-5,minecraft:concrete:0)
Block(-5,37,-4,minecraft:concrete:0)
Block(-5,37,-1,minecraft:concrete:0)
Block(-5,37,0,minecraft:concrete:0)
Block(-5,37,6,minecraft:concrete:0)
Block(-5,37,7,minecraft:concrete:0)
Block(-5,38,-5,minecraft:concrete:0)
Block(-5,38,-4,minecraft:concrete:0)
Block(-5,38,-1,minecraft:concrete:0)
Block(-5,38,0,minecraft:concrete:0)
Block(-5,38,6,minecraft:concrete:0)
Block(-5,38,7,minecraft:concrete:0)
Block(-5,39,-5,minecraft:concrete:0)
Block(-5,39,-4,minecraft:concrete:0)
Block(-5,39,-1,minecraft:concrete:0)
Block(-5,39,0,minecraft:concrete:0)
Block(-5,39,6,minecraft:concrete:0)
Block(-5,39,7,minecraft:concrete:0)
Block(-5,40,-5,minecraft:concrete:0)
Block(-5,40,-4,minecraft:concrete:0)
Block(-5,40,-1,minecraft:concrete:0)
Block(-5,40,0,minecraft:concrete:0)
Block(-5,40,6,minecraft:concrete:0)
Block(-5,40,7,minecraft:concrete:0)
Block(-5,41,-5,minecraft:concrete:0)
Block(-5,41,-4,minecraft:concrete:0)
Block(-5,41,-1,minecraft:concrete:0)
Block(-5,41,0,minecraft:concrete:0)
Block(-5,41,6,minecraft:concrete:0)
Block(-5,41,7,minecraft:concrete:0)
Block(-5,42,-5,minecraft:concrete:0)
Block(-5,42,-4,minecraft:concrete:0)
Block(-5,42,-1,minecraft:concrete:0)
Block(-5,42,0,minecraft:concrete:0)
Block(-5,42,6,minecraft:concrete:0)
Block(-5,42,7,minecraft:concrete:0)
Block(-5,43,-5,minecraft:concrete:0)
Block(-5,43,-4,minecraft:concrete:0)
Block(-5,43,-1,minecraft:concrete:0)
Block(-5,43,0,minecraft:concrete:0)
Block(-5,43,6,minecraft:concrete:0)
Block(-5,43,7,minecraft:concrete:0)
Block(-4,0,-6,minecraft:concrete:0)
Block(-4,0,-5,minecraft:concrete:0)
Block(-4,0,-4,minecraft:concrete:0)
Block(-4,0,-3,minecraft:concrete:0)
Block(-4,0,-2,minecraft:concrete:0)
Block(-4,0,-1,minecraft:concrete:0)
Block(-4,0,0,minecraft:concrete:0)
Block(-4,0,1,minecraft:concrete:0)
Block(-4,0,2,minecraft:concrete:0)
Block(-4,0,3,minecraft:concrete:0)
Block(-4,0,4,minecraft:concrete:0)
Block(-4,0,5,minecraft:concrete:0)
Block(-4,0,6,minecraft:concrete:0)
Block(-4,0,7,minecraft:concrete:0)
Block(-4,0,8,minecraft:concrete:0)
Block(-4,0,9,minecraft:concrete:0)
Block(-4,1,-6,minecraft:concrete:0)
Block(-4,1,-5,minecraft:concrete:0)
Block(-4,1,-4,minecraft:concrete:0)
Block(-4,1,-3,minecraft:concrete:0)
Block(-4,1,-2,minecraft:concrete:0)
Block(-4,1,-1,STATIONARY_WATER:0)
Block(-4,1,0,STATIONARY_WATER:0)
Block(-4,1,1,STATIONARY_WATER:0)
Block(-4,1,2,STATIONARY_WATER:0)
Block(-4,1,3,STATIONARY_WATER:0)
Block(-4,1,4,STATIONARY_WATER:0)
Block(-4,1,5,STATIONARY_WATER:0)
Block(-4,1,6,STATIONARY_WATER:0)
Block(-4,1,7,STATIONARY_WATER:0)
Block(-4,1,8,STATIONARY_WATER:0)
Block(-4,1,9,minecraft:concrete:0)
Block(-4,2,-6,minecraft:concrete:0)
Block(-4,2,-5,minecraft:iron_block:1)
Block(-4,2,-4,AIR:0)
Block(-4,2,-3,minecraft:tallgrass:0)
Block(-4,2,-2,minecraft:iron_bars:0)
Block(-4,2,-1,AIR:0)
Block(-4,2,0,AIR:0)
Block(-4,2,1,AIR:0)
Block(-4,2,2,AIR:0)
Block(-4,2,3,AIR:0)
Block(-4,2,4,AIR:0)
Block(-4,2,5,AIR:0)
Block(-4,2,6,AIR:0)
Block(-4,2,7,AIR:0)
Block(-4,2,8,minecraft:iron_block:1)
Block(-4,2,9,minecraft:concrete:0)
Block(-4,3,-6,minecraft:concrete:0)
Block(-4,3,-5,minecraft:stonebrick:3)
Block(-4,3,-4,AIR:0)
Block(-4,3,-3,AIR:0)
Block(-4,3,-2,minecraft:iron_bars:0)
Block(-4,3,-1,AIR:0)
Block(-4,3,0,AIR:0)
Block(-4,3,1,AIR:0)
Block(-4,3,2,AIR:0)
Block(-4,3,3,AIR:0)
Block(-4,3,4,AIR:0)
Block(-4,3,5,AIR:0)
Block(-4,3,6,AIR:0)
Block(-4,3,7,AIR:0)
Block(-4,3,8,AIR:0)
Block(-4,3,9,minecraft:concrete:0)
Block(-4,4,-6,minecraft:concrete:0)
Block(-4,4,-5,AIR:0)
Block(-4,4,-4,AIR:0)
Block(-4,4,-3,AIR:0)
Block(-4,4,-2,minecraft:iron_bars:0)
Block(-4,4,-1,AIR:0)
Block(-4,4,0,AIR:0)
Block(-4,4,1,AIR:0)
Block(-4,4,2,AIR:0)
Block(-4,4,3,AIR:0)
Block(-4,4,4,AIR:0)
Block(-4,4,5,AIR:0)
Block(-4,4,6,AIR:0)
Block(-4,4,7,AIR:0)
Block(-4,4,8,AIR:0)
Block(-4,4,9,minecraft:concrete:0)
Block(-4,5,-6,minecraft:concrete:0)
Block(-4,5,-5,minecraft:concrete:0)
Block(-4,5,-4,minecraft:concrete:0)
Block(-4,5,-3,minecraft:concrete:0)
Block(-4,5,-2,minecraft:concrete:0)
Block(-4,5,-1,minecraft:concrete:0)
Block(-4,5,0,minecraft:concrete:0)
Block(-4,5,1,minecraft:concrete:0)
Block(-4,5,2,minecraft:concrete:0)
Block(-4,5,3,minecraft:concrete:0)
Block(-4,5,4,minecraft:concrete:0)
Block(-4,5,5,minecraft:concrete:0)
Block(-4,5,6,minecraft:concrete:0)
Block(-4,5,7,minecraft:concrete:0)
Block(-4,5,8,minecraft:concrete:0)
Block(-4,5,9,minecraft:concrete:0)
Block(-4,6,-6,minecraft:concrete:0)
Block(-4,6,-5,AIR:0)
Block(-4,6,-4,AIR:0)
Block(-4,6,-3,minecraft:stonebrick:0)
Block(-4,6,-2,AIR:0)
Block(-4,6,-1,minecraft:stone:0)
Block(-4,6,0,AIR:0)
Block(-4,6,1,AIR:0)
Block(-4,6,2,minecraft:concrete:0)
Block(-4,6,3,minecraft:concrete:0)
Block(-4,6,4,minecraft:concrete:0)
Block(-4,6,5,minecraft:concrete:0)
Block(-4,6,6,minecraft:concrete:0)
Block(-4,6,7,minecraft:concrete:0)
Block(-4,6,8,minecraft:concrete:0)
Block(-4,6,9,minecraft:concrete:0)
Block(-4,7,-6,minecraft:concrete:0)
Block(-4,7,-5,AIR:0)
Block(-4,7,-4,AIR:0)
Block(-4,7,-3,AIR:0)
Block(-4,7,-2,AIR:0)
Block(-4,7,-1,AIR:0)
Block(-4,7,0,AIR:0)
Block(-4,7,1,AIR:0)
Block(-4,7,2,minecraft:stonebrick:1)
Block(-4,7,3,AIR:0)
Block(-4,7,4,minecraft:stonebrick:1)
Block(-4,7,5,minecraft:stonebrick:1)
Block(-4,7,6,minecraft:stonebrick:1)
Block(-4,7,7,AIR:0)
Block(-4,7,8,minecraft:stonebrick:1)
Block(-4,7,9,minecraft:concrete:0)
Block(-4,8,-6,minecraft:concrete:0)
Block(-4,8,-5,WEB:0)
Block(-4,8,-4,AIR:0)
Block(-4,8,-3,AIR:0)
Block(-4,8,-2,AIR:0)
Block(-4,8,-1,AIR:0)
Block(-4,8,0,AIR:0)
Block(-4,8,1,AIR:0)
Block(-4,8,2,minecraft:stonebrick:1)
Block(-4,8,3,AIR:0)
Block(-4,8,4,minecraft:stone_brick_stairs:0)
Block(-4,8,5,minecraft:iron_block:0)
Block(-4,8,6,minecraft:stone_brick_stairs:0)
Block(-4,8,7,AIR:0)
Block(-4,8,8,minecraft:stonebrick:1)
Block(-4,8,9,minecraft:concrete:0)
Block(-4,9,-6,minecraft:concrete:0)
Block(-4,9,-5,minecraft:concrete:0)
Block(-4,9,-4,minecraft:concrete:0)
Block(-4,9,-3,minecraft:concrete:0)
Block(-4,9,-2,minecraft:concrete:0)
Block(-4,9,-1,minecraft:concrete:0)
Block(-4,9,0,minecraft:concrete:0)
Block(-4,9,1,minecraft:concrete:0)
Block(-4,9,2,minecraft:concrete:0)
Block(-4,9,3,minecraft:concrete:0)
Block(-4,9,4,minecraft:concrete:0)
Block(-4,9,5,minecraft:concrete:0)
Block(-4,9,6,minecraft:concrete:0)
Block(-4,9,7,minecraft:concrete:0)
Block(-4,9,8,minecraft:concrete:0)
Block(-4,9,9,minecraft:concrete:0)
Block(-4,10,-6,minecraft:concrete:0)
Block(-4,10,-5,minecraft:planks:10,../../../Chests/Loot/manhunt_vagrant_scrap.nbt)
Block(-4,10,-4,AIR:0)
Block(-4,10,-3,minecraft:stonebrick:0)
Block(-4,10,-2,AIR:0)
Block(-4,10,-1,AIR:0)
Block(-4,10,0,minecraft:stonebrick:0)
Block(-4,10,1,minecraft:planks:5)
Block(-4,10,2,minecraft:stone:0)
RandomBlock(-4,10,3,minecraft:planks:5,5,minecraft:planks:1,../../../Chests/Loot/manhunt_vagrant_scrap.nbt,100)
Block(-4,10,4,AIR:0)
Block(-4,10,5,minecraft:stonebrick:3)
Block(-4,10,6,minecraft:iron_block:0)
Block(-4,10,7,minecraft:water:0)
Block(-4,10,8,minecraft:water:0)
Block(-4,10,9,minecraft:concrete:0)
Block(-4,11,-6,minecraft:concrete:0)
Block(-4,11,-5,minecraft:planks:1)
Block(-4,11,-4,AIR:0)
Block(-4,11,-3,AIR:0)
Block(-4,11,-2,AIR:0)
Block(-4,11,-1,AIR:0)
Block(-4,11,0,AIR:0)
Block(-4,11,1,CHEST:2,../../../Chests/Loot/manhunt_military_common.nbt)
Block(-4,11,2,AIR:0)
Block(-4,11,3,minecraft:planks:7)
Block(-4,11,4,AIR:0)
Block(-4,11,5,AIR:0)
Block(-4,11,6,quark:framed_glass:0)
Block(-4,11,7,minecraft:water:0)
Block(-4,11,8,minecraft:water:0)
Block(-4,11,9,minecraft:concrete:0)
Block(-4,12,-6,minecraft:concrete:0)
Block(-4,12,-5,AIR:0)
Block(-4,12,-4,AIR:0)
Block(-4,12,-3,AIR:0)
Block(-4,12,-2,AIR:0)
Block(-4,12,-1,AIR:0)
Block(-4,12,0,AIR:0)
Block(-4,12,1,AIR:0)
Block(-4,12,2,AIR:0)
Block(-4,12,3,AIR:0)
Block(-4,12,4,AIR:0)
Block(-4,12,5,AIR:0)
Block(-4,12,6,minecraft:iron_block:0)
Block(-4,12,7,minecraft:water:0)
Block(-4,12,8,minecraft:water:0)
Block(-4,12,9,minecraft:concrete:0)
Block(-4,13,-6,minecraft:concrete:0)
Block(-4,13,-5,minecraft:concrete:0)
Block(-4,13,-4,minecraft:concrete:0)
Block(-4,13,-3,minecraft:concrete:0)
Block(-4,13,-2,minecraft:concrete:0)
Block(-4,13,-1,minecraft:concrete:0)
Block(-4,13,0,minecraft:concrete:0)
Block(-4,13,1,minecraft:concrete:0)
Block(-4,13,2,minecraft:concrete:0)
Block(-4,13,3,minecraft:concrete:0)
Block(-4,13,4,minecraft:concrete:0)
Block(-4,13,5,minecraft:concrete:0)
Block(-4,13,6,minecraft:concrete:0)
Block(-4,13,7,minecraft:concrete:0)
Block(-4,13,8,minecraft:concrete:0)
Block(-4,13,9,minecraft:concrete:0)
Block(-4,14,-6,minecraft:concrete:0)
Block(-4,14,-5,minecraft:planks:0)
Block(-4,14,-4,minecraft:stone:0)
Block(-4,14,-3,CARPET:4)
Block(-4,14,-2,CARPET:15)
Block(-4,14,-1,CARPET:15)
Block(-4,14,0,CARPET:15)
Block(-4,14,1,CARPET:15)
Block(-4,14,2,CARPET:4)
Block(-4,14,3,minecraft:planks:7)
Block(-4,14,4,minecraft:planks:7)
Block(-4,14,5,minecraft:stone:0)
Block(-4,14,6,minecraft:oak_stairs:5)
Block(-4,14,7,minecraft:oak_stairs:1)
Block(-4,14,8,minecraft:oak_stairs:1)
Block(-4,14,9,minecraft:concrete:0)
Block(-4,15,-6,minecraft:concrete:0)
Block(-4,15,-5,minecraft:planks:0)
Block(-4,15,-4,AIR:0)
Block(-4,15,-3,AIR:0)
Block(-4,15,-2,AIR:0)
Block(-4,15,-1,AIR:0)
Block(-4,15,0,AIR:0)
Block(-4,15,1,AIR:0)
Block(-4,15,2,AIR:0)
Block(-4,15,3,minecraft:planks:7)
Block(-4,15,4,minecraft:planks:7)
Block(-4,15,5,AIR:0)
Block(-4,15,6,AIR:0)
Block(-4,15,7,AIR:0)
Block(-4,15,8,AIR:0)
Block(-4,15,9,minecraft:concrete:0)
Block(-4,16,-6,minecraft:concrete:0)
Block(-4,16,-5,minecraft:planks:0)
Block(-4,16,-4,STEP:8)
Block(-4,16,-3,AIR:0)
Block(-4,16,-2,minecraft:stonebrick)
Block(-4,16,-1,AIR:0)
Block(-4,16,0,AIR:0)
Block(-4,16,1,AIR:0)
Block(-4,16,2,AIR:0)
Block(-4,16,3,minecraft:planks:7)
Block(-4,16,4,minecraft:planks:7)
Block(-4,16,5,minecraft:stonebrick)
Block(-4,16,6,STEP:8)
Block(-4,16,7,AIR:0)
Block(-4,16,8,WEB:0)
Block(-4,16,9,minecraft:concrete:0)
Block(-4,17,-6,minecraft:concrete:0)
Block(-4,17,-5,minecraft:concrete:0)
Block(-4,17,-4,minecraft:concrete:0)
Block(-4,17,-3,minecraft:concrete:0)
Block(-4,17,-2,minecraft:concrete:0)
Block(-4,17,-1,minecraft:concrete:0)
Block(-4,17,0,minecraft:concrete:0)
Block(-4,17,1,minecraft:concrete:0)
Block(-4,17,2,minecraft:concrete:0)
Block(-4,17,3,minecraft:concrete:0)
Block(-4,17,4,minecraft:concrete:0)
Block(-4,17,5,minecraft:concrete:0)
Block(-4,17,6,minecraft:concrete:0)
Block(-4,17,7,minecraft:concrete:0)
Block(-4,17,8,minecraft:concrete:0)
Block(-4,17,9,minecraft:concrete:0)
Block(-4,18,-6,minecraft:concrete:0)
Block(-4,18,-5,minecraft:planks:3)
Block(-4,18,-4,AIR:0)
Block(-4,18,-3,AIR:0)
Block(-4,18,-2,minecraft:tallgrass:3)
Block(-4,18,-1,AIR:0)
Block(-4,18,0,AIR:0)
Block(-4,18,1,minecraft:stonebrick:0)
Block(-4,18,2,minecraft:stonebrick:1)
Block(-4,18,3,minecraft:planks:7)
Block(-4,18,4,minecraft:planks:7)
Block(-4,18,5,AIR:0)
Block(-4,18,6,minecraft:oak_stairs:5)
Block(-4,18,7,minecraft:oak_stairs:1)
Block(-4,18,8,minecraft:oak_stairs:1)
Block(-4,18,9,minecraft:concrete:0)
Block(-4,19,-6,minecraft:concrete:0)
Block(-4,19,-5,minecraft:planks:3)
Block(-4,19,-4,AIR:0)
Block(-4,19,-3,AIR:0)
Block(-4,19,-2,AIR:0)
Block(-4,19,-1,AIR:0)
Block(-4,19,0,AIR:0)
Block(-4,19,1,AIR:0)
Block(-4,19,2,AIR:0)
Block(-4,19,3,minecraft:planks:7)
Block(-4,19,4,minecraft:planks:7)
Block(-4,19,5,AIR:0)
Block(-4,19,6,AIR:0)
Block(-4,19,7,AIR:0)
Block(-4,19,8,AIR:0)
Block(-4,19,9,minecraft:concrete:0)
Block(-4,20,-6,minecraft:concrete:0)
Block(-4,20,-5,minecraft:planks:3)
Block(-4,20,-4,STEP:8)
Block(-4,20,-3,AIR:0)
Block(-4,20,-2,minecraft:stonebrick)
Block(-4,20,-1,AIR:0)
Block(-4,20,0,AIR:0)
Block(-4,20,1,AIR:0)
Block(-4,20,2,AIR:0)
Block(-4,20,3,minecraft:planks:7)
Block(-4,20,4,minecraft:planks:7)
Block(-4,20,5,AIR:0)
Block(-4,20,6,STEP:8)
Block(-4,20,7,AIR:0)
Block(-4,20,8,WEB:0)
Block(-4,20,9,minecraft:concrete:0)
Block(-4,21,-6,minecraft:concrete:0)
Block(-4,21,-5,minecraft:concrete:0)
Block(-4,21,-4,minecraft:concrete:0)
Block(-4,21,-3,minecraft:concrete:0)
Block(-4,21,-2,minecraft:concrete:0)
Block(-4,21,-1,minecraft:concrete:0)
Block(-4,21,0,minecraft:concrete:0)
Block(-4,21,1,minecraft:concrete:0)
Block(-4,21,2,minecraft:concrete:0)
Block(-4,21,3,minecraft:concrete:0)
Block(-4,21,4,minecraft:concrete:0)
Block(-4,21,5,minecraft:concrete:0)
Block(-4,21,6,minecraft:concrete:0)
Block(-4,21,7,minecraft:concrete:0)
Block(-4,21,8,minecraft:concrete:0)
Block(-4,21,9,minecraft:concrete:0)
Block(-4,22,-6,minecraft:concrete:0)
Block(-4,22,-5,minecraft:planks:3)
Block(-4,22,-4,AIR:0)
Block(-4,22,-3,AIR:0)
Block(-4,22,-2,minecraft:stonebrick:0)
Block(-4,22,-1,AIR:0)
Block(-4,22,0,AIR:0)
Block(-4,22,1,minecraft:stone:0)
Block(-4,22,2,minecraft:oak_stairs:5)
Block(-4,22,3,minecraft:planks:7)
Block(-4,22,4,minecraft:planks:7)
Block(-4,22,5,WEB:0)
Block(-4,22,6,minecraft:oak_stairs:5)
Block(-4,22,7,minecraft:oak_stairs:1)
Block(-4,22,8,minecraft:oak_stairs:1)
Block(-4,22,9,minecraft:concrete:0)
Block(-4,23,-6,minecraft:concrete:0)
Block(-4,23,-5,minecraft:planks:3)
Block(-4,23,-4,AIR:0)
Block(-4,23,-3,AIR:0)
Block(-4,23,-2,AIR:0)
Block(-4,23,-1,AIR:0)
Block(-4,23,0,AIR:0)
Block(-4,23,1,AIR:0)
Block(-4,23,2,AIR:0)
Block(-4,23,3,minecraft:planks:7)
Block(-4,23,4,minecraft:planks:7)
Block(-4,23,5,AIR:0)
Block(-4,23,6,AIR:0)
Block(-4,23,7,AIR:0)
Block(-4,23,8,AIR:0)
Block(-4,23,9,minecraft:concrete:0)
Block(-4,24,-6,minecraft:concrete:0)
Block(-4,24,-5,minecraft:planks:3)
Block(-4,24,-4,STEP:8)
Block(-4,24,-3,AIR:0)
Block(-4,24,-2,minecraft:stonebrick)
Block(-4,24,-1,AIR:0)
Block(-4,24,0,AIR:0)
Block(-4,24,1,AIR:0)
Block(-4,24,2,AIR:0)
Block(-4,24,3,minecraft:planks:7)
Block(-4,24,4,minecraft:planks:7)
Block(-4,24,5,AIR:0)
Block(-4,24,6,STEP:8)
Block(-4,24,7,AIR:0)
Block(-4,24,8,AIR:0)
Block(-4,24,9,minecraft:concrete:0)
Block(-4,25,-6,minecraft:concrete:0)
Block(-4,25,-5,minecraft:concrete:0)
Block(-4,25,-4,minecraft:concrete:0)
Block(-4,25,-3,minecraft:concrete:0)
Block(-4,25,-2,minecraft:concrete:0)
Block(-4,25,-1,minecraft:concrete:0)
Block(-4,25,0,minecraft:concrete:0)
Block(-4,25,1,minecraft:concrete:0)
Block(-4,25,2,minecraft:concrete:0)
Block(-4,25,3,minecraft:concrete:0)
Block(-4,25,4,minecraft:concrete:0)
Block(-4,25,5,minecraft:concrete:0)
Block(-4,25,6,minecraft:concrete:0)
Block(-4,25,7,minecraft:concrete:0)
Block(-4,25,8,minecraft:concrete:0)
Block(-4,25,9,minecraft:concrete:0)
Block(-4,26,-6,minecraft:concrete:0)
Block(-4,26,-5,minecraft:planks:3)
Block(-4,26,-4,AIR:0)
Block(-4,26,-3,minecraft:stonebrick:0)
Block(-4,26,-2,minecraft:stone:0)
Block(-4,26,-1,AIR:0)
Block(-4,26,0,AIR:0)
Block(-4,26,1,minecraft:stone:0)
Block(-4,26,2,minecraft:stonebrick:1)
Block(-4,26,3,minecraft:planks:7)
Block(-4,26,4,minecraft:planks:7)
Block(-4,26,5,minecraft:stone:0)
Block(-4,26,6,minecraft:oak_stairs:5)
Block(-4,26,7,minecraft:oak_stairs:1)
Block(-4,26,8,minecraft:oak_stairs:1)
Block(-4,26,9,minecraft:concrete:0)
Block(-4,27,-6,minecraft:concrete:0)
Block(-4,27,-5,minecraft:planks:3)
Block(-4,27,-4,AIR:0)
Block(-4,27,-3,AIR:0)
Block(-4,27,-2,AIR:0)
Block(-4,27,-1,AIR:0)
Block(-4,27,0,AIR:0)
Block(-4,27,1,AIR:0)
Block(-4,27,2,AIR:0)
Block(-4,27,3,minecraft:planks:7)
Block(-4,27,4,minecraft:planks:7)
Block(-4,27,5,AIR:0)
Block(-4,27,6,AIR:0)
Block(-4,27,7,AIR:0)
Block(-4,27,8,AIR:0)
Block(-4,27,9,minecraft:concrete:0)
Block(-4,28,-6,minecraft:concrete:0)
Block(-4,28,-5,minecraft:planks:3)
Block(-4,28,-4,STEP:8)
Block(-4,28,-3,AIR:0)
Block(-4,28,-2,AIR:0)
Block(-4,28,-1,AIR:0)
Block(-4,28,0,AIR:0)
Block(-4,28,1,AIR:0)
Block(-4,28,2,AIR:0)
Block(-4,28,3,minecraft:planks:7)
Block(-4,28,4,minecraft:planks:7)
Block(-4,28,5,AIR:0)
Block(-4,28,6,STEP:8)
Block(-4,28,7,AIR:0)
Block(-4,28,8,AIR:0)
Block(-4,28,9,minecraft:concrete:0)
Block(-4,29,-6,minecraft:concrete:0)
Block(-4,29,-5,minecraft:concrete:0)
Block(-4,29,-4,minecraft:concrete:0)
Block(-4,29,-3,minecraft:concrete:0)
Block(-4,29,-2,minecraft:concrete:0)
Block(-4,29,-1,minecraft:concrete:0)
Block(-4,29,0,minecraft:concrete:0)
Block(-4,29,1,minecraft:concrete:0)
Block(-4,29,2,minecraft:concrete:0)
Block(-4,29,3,minecraft:concrete:0)
Block(-4,29,4,minecraft:concrete:0)
Block(-4,29,5,minecraft:concrete:0)
Block(-4,29,6,minecraft:concrete:0)
Block(-4,29,7,minecraft:concrete:0)
Block(-4,29,8,minecraft:concrete:0)
Block(-4,29,9,minecraft:concrete:0)
Block(-4,30,-6,minecraft:concrete:0)
Block(-4,30,-5,minecraft:planks:5)
Block(-4,30,-4,AIR:0)
Block(-4,30,-3,minecraft:stonebrick:0)
Block(-4,30,-2,AIR:0)
Block(-4,30,-1,minecraft:tallgrass:0)
Block(-4,30,0,AIR:0)
Block(-4,30,1,AIR:0)
Block(-4,30,2,minecraft:planks:5)
Block(-4,30,3,minecraft:concrete:0)
Block(-4,30,6,minecraft:concrete:0)
Block(-4,30,7,minecraft:concrete:0)
Block(-4,31,-6,minecraft:concrete:0)
Block(-4,31,-5,minecraft:planks:5)
Block(-4,31,-4,AIR:0)
Block(-4,31,-3,AIR:0)
Block(-4,31,-2,AIR:0)
Block(-4,31,-1,AIR:0)
Block(-4,31,0,AIR:0)
Block(-4,31,1,AIR:0)
Block(-4,31,2,minecraft:stonebrick:1)
Block(-4,31,3,minecraft:concrete:0)
Block(-4,31,6,minecraft:concrete:0)
Block(-4,31,7,minecraft:concrete:0)
Block(-4,32,-6,minecraft:concrete:0)
Block(-4,32,-5,minecraft:planks:2,../../../Chests/Loot/manhunt_vagrant_scrap.nbt)
Block(-4,32,-4,AIR:0)
Block(-4,32,-3,AIR:0)
Block(-4,32,-2,AIR:0)
Block(-4,32,-1,AIR:0)
Block(-4,32,0,AIR:0)
Block(-4,32,1,AIR:0)
Block(-4,32,2,AIR:0)
Block(-4,32,3,minecraft:concrete:0)
Block(-4,32,6,minecraft:concrete:0)
Block(-4,32,7,minecraft:concrete:0)
Block(-4,33,-6,minecraft:concrete:0)
Block(-4,33,-5,minecraft:concrete:0)
Block(-4,33,-4,minecraft:concrete:0)
Block(-4,33,-3,minecraft:concrete:0)
Block(-4,33,-2,minecraft:concrete:0)
Block(-4,33,-1,minecraft:concrete:0)
Block(-4,33,0,minecraft:concrete:0)
Block(-4,33,1,minecraft:concrete:0)
Block(-4,33,2,minecraft:concrete:0)
Block(-4,33,3,minecraft:concrete:0)
Block(-4,33,6,minecraft:concrete:0)
Block(-4,33,7,minecraft:concrete:0)
Block(-4,34,-5,minecraft:concrete:0)
Block(-4,34,-4,minecraft:concrete:0)
Block(-4,34,-1,minecraft:concrete:0)
Block(-4,34,0,minecraft:concrete:0)
Block(-4,34,6,minecraft:concrete:0)
Block(-4,34,7,minecraft:concrete:0)
Block(-4,35,-5,minecraft:concrete:0)
Block(-4,35,-4,minecraft:concrete:0)
Block(-4,35,-1,minecraft:concrete:0)
Block(-4,35,0,minecraft:concrete:0)
Block(-4,35,6,minecraft:concrete:0)
Block(-4,35,7,minecraft:concrete:0)
Block(-4,36,-5,minecraft:concrete:0)
Block(-4,36,-4,minecraft:concrete:0)
Block(-4,36,-1,minecraft:concrete:0)
Block(-4,36,0,minecraft:concrete:0)
Block(-4,36,6,minecraft:concrete:0)
Block(-4,36,7,minecraft:concrete:0)
Block(-4,37,-5,minecraft:concrete:0)
Block(-4,37,-4,minecraft:concrete:0)
Block(-4,37,-1,minecraft:concrete:0)
Block(-4,37,0,minecraft:concrete:0)
Block(-4,37,6,minecraft:concrete:0)
Block(-4,37,7,minecraft:concrete:0)
Block(-4,38,-6,minecraft:concrete:0)
Block(-4,38,-5,minecraft:concrete:0)
Block(-4,38,-4,minecraft:concrete:0)
Block(-4,38,-3,minecraft:concrete:0)
Block(-4,38,-2,minecraft:concrete:0)
Block(-4,38,-1,minecraft:concrete:0)
Block(-4,38,0,minecraft:concrete:0)
Block(-4,38,1,minecraft:concrete:0)
Block(-4,38,2,minecraft:concrete:0)
Block(-4,38,3,minecraft:concrete:0)
Block(-4,38,4,minecraft:concrete:0)
Block(-4,38,5,minecraft:concrete:0)
Block(-4,38,6,minecraft:concrete:0)
Block(-4,38,7,minecraft:concrete:0)
Block(-4,39,-6,minecraft:concrete:0)
Block(-4,39,-5,minecraft:concrete:0)
Block(-4,39,-4,minecraft:concrete:0)
Block(-4,39,-3,minecraft:concrete:0)
Block(-4,39,-2,minecraft:concrete:0)
Block(-4,39,-1,minecraft:concrete:0)
Block(-4,39,0,minecraft:concrete:0)
Block(-4,39,1,minecraft:concrete:0)
Block(-4,39,2,minecraft:stone_brick_stairs:0)
Block(-4,39,3,minecraft:concrete:0)
Block(-4,39,4,minecraft:concrete:0)
Block(-4,39,5,minecraft:concrete:0)
Block(-4,39,6,minecraft:concrete:0)
Block(-4,39,7,minecraft:concrete:0)
Block(-4,40,-6,minecraft:concrete:0)
Block(-4,40,-5,minecraft:concrete:0)
Block(-4,40,-4,minecraft:concrete:0)
Block(-4,40,-3,minecraft:stone_brick_stairs:0)
Block(-4,40,-2,minecraft:concrete:0)
Block(-4,40,-1,minecraft:concrete:0)
Block(-4,40,0,minecraft:concrete:0)
Block(-4,40,1,minecraft:concrete:0)
Block(-4,40,2,minecraft:stone_brick_stairs:4)
Block(-4,40,3,minecraft:stone_brick_stairs:4)
Block(-4,40,4,minecraft:stone_brick_stairs:4)
Block(-4,40,5,minecraft:concrete:0)
Block(-4,40,6,minecraft:concrete:0)
Block(-4,40,7,minecraft:concrete:0)
Block(-4,41,-6,minecraft:concrete:0)
Block(-4,41,-5,minecraft:concrete:0)
Block(-4,41,-4,minecraft:concrete:0)
Block(-4,41,-3,minecraft:stone_brick_stairs:4)
Block(-4,41,-2,minecraft:stone_brick_stairs:0)
Block(-4,41,-1,minecraft:concrete:0)
Block(-4,41,0,minecraft:concrete:0)
Block(-4,41,1,minecraft:concrete:0)
Block(-4,41,2,minecraft:concrete:0)
Block(-4,41,3,minecraft:stone_brick_stairs:0)
Block(-4,41,4,minecraft:concrete:0)
Block(-4,41,5,minecraft:concrete:0)
Block(-4,41,6,minecraft:concrete:0)
Block(-4,41,7,minecraft:concrete:0)
Block(-4,42,-6,minecraft:concrete:0)
Block(-4,42,-5,minecraft:concrete:0)
Block(-4,42,-4,minecraft:concrete:0)
Block(-4,42,-3,AIR:0)
Block(-4,42,-2,AIR:0)
Block(-4,42,-1,minecraft:concrete:0)
Block(-4,42,0,minecraft:concrete:0)
Block(-4,42,1,minecraft:concrete:0)
Block(-4,42,2,minecraft:concrete:0)
Block(-4,42,3,AIR:0)
Block(-4,42,4,minecraft:concrete:0)
Block(-4,42,5,minecraft:concrete:0)
Block(-4,42,6,minecraft:concrete:0)
Block(-4,42,7,minecraft:concrete:0)
Block(-4,43,-5,minecraft:concrete:0)
Block(-4,43,-4,minecraft:concrete:0)
Block(-4,43,-1,minecraft:concrete:0)
Block(-4,43,0,minecraft:concrete:0)
Block(-4,43,6,minecraft:concrete:0)
Block(-4,43,7,minecraft:concrete:0)
Block(-3,0,-6,minecraft:concrete:0)
Block(-3,0,-5,minecraft:concrete:0)
Block(-3,0,-4,minecraft:concrete:0)
Block(-3,0,-3,minecraft:concrete:0)
Block(-3,0,-2,minecraft:concrete:0)
Block(-3,0,-1,minecraft:concrete:0)
Block(-3,0,0,minecraft:concrete:0)
Block(-3,0,1,minecraft:concrete:0)
Block(-3,0,2,minecraft:concrete:0)
Block(-3,0,3,minecraft:concrete:0)
Block(-3,0,4,minecraft:concrete:0)
Block(-3,0,5,minecraft:concrete:0)
Block(-3,0,6,minecraft:concrete:0)
Block(-3,0,7,minecraft:concrete:0)
Block(-3,0,8,minecraft:concrete:0)
Block(-3,0,9,minecraft:concrete:0)
Block(-3,1,-6,minecraft:concrete:0)
Block(-3,1,-5,minecraft:concrete:0)
Block(-3,1,-4,minecraft:concrete:0)
Block(-3,1,-3,minecraft:concrete:0)
Block(-3,1,-2,minecraft:concrete:0)
Block(-3,1,-1,STATIONARY_WATER:0)
Block(-3,1,0,STATIONARY_WATER:0)
Block(-3,1,1,minecraft:concrete:0)
Block(-3,1,2,minecraft:concrete:0)
Block(-3,1,3,STATIONARY_WATER:0)
Block(-3,1,4,STATIONARY_WATER:0)
Block(-3,1,5,STATIONARY_WATER:0)
Block(-3,1,6,minecraft:concrete:0)
Block(-3,1,7,minecraft:concrete:0)
Block(-3,1,8,STATIONARY_WATER:0)
Block(-3,1,9,minecraft:concrete:0)
Block(-3,2,-6,minecraft:concrete:0)
Block(-3,2,-5,minecraft:concrete:0)
Block(-3,2,-4,minecraft:iron_door:0)
Block(-3,2,-3,minecraft:concrete:0)
Block(-3,2,-2,minecraft:concrete:0)
Block(-3,2,-1,AIR:0)
Block(-3,2,0,AIR:0)
Block(-3,2,1,minecraft:concrete:0)
Block(-3,2,2,minecraft:concrete:0)
Block(-3,2,3,AIR:0)
Block(-3,2,4,AIR:0)
Block(-3,2,5,AIR:0)
Block(-3,2,6,minecraft:concrete:0)
Block(-3,2,7,minecraft:concrete:0)
Block(-3,2,8,minecraft:iron_block:1)
Block(-3,2,9,minecraft:concrete:0)
Block(-3,3,-6,minecraft:concrete:0)
Block(-3,3,-5,minecraft:concrete:0)
Block(-3,3,-4,minecraft:iron_door:9)
Block(-3,3,-3,minecraft:concrete:0)
Block(-3,3,-2,minecraft:concrete:0)
Block(-3,3,-1,AIR:0)
Block(-3,3,0,AIR:0)
Block(-3,3,1,minecraft:concrete:0)
Block(-3,3,2,minecraft:concrete:0)
Block(-3,3,3,AIR:0)
Block(-3,3,4,AIR:0)
Block(-3,3,5,AIR:0)
Block(-3,3,6,minecraft:concrete:0)
Block(-3,3,7,minecraft:concrete:0)
Block(-3,3,8,AIR:0)
Block(-3,3,9,minecraft:concrete:0)
Block(-3,4,-6,minecraft:concrete:0)
Block(-3,4,-5,minecraft:concrete:0)
Block(-3,4,-4,minecraft:concrete:0)
Block(-3,4,-3,minecraft:concrete:0)
Block(-3,4,-2,minecraft:concrete:0)
Block(-3,4,-1,AIR:0)
Block(-3,4,0,AIR:0)
Block(-3,4,1,minecraft:concrete:0)
Block(-3,4,2,minecraft:concrete:0)
Block(-3,4,3,AIR:0)
Block(-3,4,4,AIR:0)
Block(-3,4,5,AIR:0)
Block(-3,4,6,minecraft:concrete:0)
Block(-3,4,7,minecraft:concrete:0)
Block(-3,4,8,AIR:0)
Block(-3,4,9,minecraft:concrete:0)
Block(-3,5,-6,minecraft:concrete:0)
Block(-3,5,-5,minecraft:concrete:0)
Block(-3,5,-4,minecraft:concrete:0)
Block(-3,5,-3,minecraft:concrete:0)
Block(-3,5,-2,minecraft:concrete:0)
Block(-3,5,-1,minecraft:concrete:0)
Block(-3,5,0,minecraft:concrete:0)
Block(-3,5,1,minecraft:concrete:0)
Block(-3,5,2,minecraft:concrete:0)
Block(-3,5,3,minecraft:concrete:0)
Block(-3,5,4,minecraft:concrete:0)
Block(-3,5,5,minecraft:concrete:0)
Block(-3,5,6,minecraft:concrete:0)
Block(-3,5,7,minecraft:concrete:0)
Block(-3,5,8,minecraft:concrete:0)
Block(-3,5,9,minecraft:concrete:0)
Block(-3,6,-6,minecraft:concrete:0)
Block(-3,6,-5,minecraft:concrete:0)
Block(-3,6,-4,minecraft:iron_door:0)
Block(-3,6,-3,minecraft:concrete:0)
Block(-3,6,-2,minecraft:concrete:0)
Block(-3,6,-1,AIR:0)
Block(-3,6,0,AIR:0)
Block(-3,6,1,minecraft:iron_block:0)
Block(-3,6,2,minecraft:concrete:0)
Block(-3,6,3,minecraft:concrete:0)
Block(-3,6,4,minecraft:concrete:0)
Block(-3,6,5,minecraft:concrete:0)
Block(-3,6,6,minecraft:concrete:0)
Block(-3,6,7,minecraft:concrete:0)
Block(-3,6,8,minecraft:concrete:0)
Block(-3,6,9,minecraft:concrete:0)
Block(-3,7,-6,minecraft:concrete:0)
Block(-3,7,-5,minecraft:concrete:0)
Block(-3,7,-4,minecraft:iron_door:9)
Block(-3,7,-3,minecraft:concrete:0)
Block(-3,7,-2,minecraft:concrete:0)
Block(-3,7,-1,AIR:0)
Block(-3,7,0,AIR:0)
Block(-3,7,1,minecraft:stone_brick_stairs:2)
Block(-3,7,2,minecraft:iron_block)
Block(-3,7,3,minecraft:iron_block:0)
Block(-3,7,4,minecraft:iron_block:0)
Block(-3,7,5,minecraft:iron_block:0)
Block(-3,7,6,minecraft:iron_block:0)
Block(-3,7,7,minecraft:iron_block:0)
Block(-3,7,8,minecraft:stonebrick:1)
Block(-3,7,9,minecraft:concrete:0)
Block(-3,8,-6,minecraft:concrete:0)
Block(-3,8,-5,minecraft:concrete:0)
Block(-3,8,-4,minecraft:concrete:0)
Block(-3,8,-3,minecraft:concrete:0)
Block(-3,8,-2,minecraft:concrete:0)
Block(-3,8,-1,AIR:0)
Block(-3,8,0,AIR:0)
Block(-3,8,1,minecraft:stone_brick_stairs:6)
Block(-3,8,2,minecraft:stonebrick:1)
Block(-3,8,3,AIR:0)
Block(-3,8,4,minecraft:stonebrick:1)
Block(-3,8,5,minecraft:stonebrick:1)
Block(-3,8,6,minecraft:stonebrick:1)
Block(-3,8,7,AIR:0)
Block(-3,8,8,minecraft:stonebrick:1)
Block(-3,8,9,minecraft:concrete:0)
Block(-3,9,-6,minecraft:concrete:0)
Block(-3,9,-5,minecraft:concrete:0)
Block(-3,9,-4,minecraft:concrete:0)
Block(-3,9,-3,minecraft:concrete:0)
Block(-3,9,-2,minecraft:concrete:0)
Block(-3,9,-1,minecraft:concrete:0)
Block(-3,9,0,minecraft:concrete:0)
Block(-3,9,1,minecraft:concrete:0)
Block(-3,9,2,minecraft:concrete:0)
Block(-3,9,3,minecraft:concrete:0)
Block(-3,9,4,minecraft:concrete:0)
Block(-3,9,5,minecraft:concrete:0)
Block(-3,9,6,minecraft:concrete:0)
Block(-3,9,7,minecraft:concrete:0)
Block(-3,9,8,minecraft:concrete:0)
Block(-3,9,9,minecraft:concrete:0)
Block(-3,10,-6,minecraft:concrete:0)
Block(-3,10,-5,minecraft:concrete:0)
Block(-3,10,-4,minecraft:iron_door:0)
Block(-3,10,-3,minecraft:concrete:0)
Block(-3,10,-2,minecraft:concrete:0)
Block(-3,10,-1,minecraft:concrete:0)
Block(-3,10,0,AIR:0)
Block(-3,10,1,minecraft:planks:5)
Block(-3,10,2,AIR:0)
Block(-3,10,3,minecraft:planks:5)
Block(-3,10,4,AIR:0)
Block(-3,10,5,minecraft:tallgrass:3)
Block(-3,10,6,minecraft:iron_block:0)
Block(-3,10,7,minecraft:water:0)
Block(-3,10,8,minecraft:water:0)
Block(-3,10,9,minecraft:concrete:0)
Block(-3,11,-6,minecraft:concrete:0)
Block(-3,11,-5,minecraft:concrete:0)
Block(-3,11,-4,minecraft:iron_door:8)
Block(-3,11,-3,minecraft:concrete:0)
Block(-3,11,-2,minecraft:concrete:0)
Block(-3,11,-1,minecraft:concrete:0)
Block(-3,11,0,AIR:0)
Block(-3,11,1,CHEST:2,../../../Chests/Loot/manhunt_military_common.nbt)
Block(-3,11,2,AIR:0)
Block(-3,11,3,minecraft:planks:10,../../../Chests/Loot/manhunt_vagrant_scrap.nbt)
Block(-3,11,4,AIR:0)
Block(-3,11,5,AIR:0)
Block(-3,11,6,quark:framed_glass:0)
Block(-3,11,7,minecraft:water:0)
Block(-3,11,8,minecraft:water:0)
Block(-3,11,9,minecraft:concrete:0)
Block(-3,12,-6,minecraft:concrete:0)
Block(-3,12,-5,minecraft:concrete:0)
Block(-3,12,-4,minecraft:concrete:0)
Block(-3,12,-3,minecraft:concrete:0)
Block(-3,12,-2,minecraft:concrete:0)
Block(-3,12,-1,minecraft:concrete:0)
Block(-3,12,0,AIR:0)
Block(-3,12,1,AIR:0)
Block(-3,12,2,AIR:0)
Block(-3,12,3,AIR:0)
Block(-3,12,4,AIR:0)
Block(-3,12,5,AIR:0)
Block(-3,12,6,minecraft:iron_block:0)
Block(-3,12,7,minecraft:water:0)
Block(-3,12,8,minecraft:water:0)
Block(-3,12,9,minecraft:concrete:0)
Block(-3,13,-6,minecraft:concrete:0)
Block(-3,13,-5,minecraft:concrete:0)
Block(-3,13,-4,minecraft:concrete:0)
Block(-3,13,-3,minecraft:concrete:0)
Block(-3,13,-2,minecraft:concrete:0)
Block(-3,13,-1,minecraft:concrete:0)
Block(-3,13,0,minecraft:concrete:0)
Block(-3,13,1,minecraft:concrete:0)
Block(-3,13,2,minecraft:concrete:0)
Block(-3,13,3,minecraft:concrete:0)
Block(-3,13,4,minecraft:concrete:0)
Block(-3,13,5,minecraft:concrete:0)
Block(-3,13,6,minecraft:concrete:0)
Block(-3,13,7,minecraft:concrete:0)
Block(-3,13,8,minecraft:concrete:0)
Block(-3,13,9,minecraft:concrete:0)
Block(-3,14,-6,minecraft:concrete:0)
Block(-3,14,-5,minecraft:concrete:0)
Block(-3,14,-4,minecraft:iron_door:0)
Block(-3,14,-3,minecraft:concrete:0)
Block(-3,14,-2,minecraft:concrete:0)
Block(-3,14,-1,minecraft:concrete:0)
Block(-3,14,0,AIR:0)
Block(-3,14,1,minecraft:stonebrick:0)
Block(-3,14,2,minecraft:concrete:0)
Block(-3,14,3,minecraft:concrete:0)
Block(-3,14,4,minecraft:concrete:0)
Block(-3,14,5,minecraft:concrete:0)
Block(-3,14,6,minecraft:concrete:0)
Block(-3,14,7,minecraft:concrete:0)
Block(-3,14,8,minecraft:concrete:0)
Block(-3,14,9,minecraft:concrete:0)
Block(-3,15,-6,minecraft:concrete:0)
Block(-3,15,-5,minecraft:concrete:0)
Block(-3,15,-4,minecraft:iron_door:8)
Block(-3,15,-3,minecraft:concrete:0)
Block(-3,15,-2,minecraft:concrete:0)
Block(-3,15,-1,minecraft:concrete:0)
Block(-3,15,0,AIR:0)
Block(-3,15,1,AIR:0)
Block(-3,15,2,minecraft:concrete:0)
Block(-3,15,3,minecraft:concrete:0)
Block(-3,15,4,minecraft:concrete:0)
Block(-3,15,5,minecraft:concrete:0)
Block(-3,15,6,minecraft:concrete:0)
Block(-3,15,7,minecraft:concrete:0)
Block(-3,15,8,minecraft:concrete:0)
Block(-3,15,9,minecraft:concrete:0)
Block(-3,16,-6,minecraft:concrete:0)
Block(-3,16,-5,minecraft:concrete:0)
Block(-3,16,-4,quark:sturdy_stone:0)
Block(-3,16,-3,minecraft:concrete:0)
Block(-3,16,-2,minecraft:concrete:0)
Block(-3,16,-1,minecraft:concrete:0)
Block(-3,16,0,minecraft:concrete:0)
Block(-3,16,1,minecraft:concrete:0)
Block(-3,16,2,minecraft:concrete:0)
Block(-3,16,3,minecraft:concrete:0)
Block(-3,16,4,minecraft:concrete:0)
Block(-3,16,5,minecraft:concrete:0)
Block(-3,16,6,minecraft:concrete:0)
Block(-3,16,7,minecraft:concrete:0)
Block(-3,16,8,minecraft:concrete:0)
Block(-3,16,9,minecraft:concrete:0)
Block(-3,17,-6,minecraft:concrete:0)
Block(-3,17,-5,minecraft:concrete:0)
Block(-3,17,-4,minecraft:concrete:0)
Block(-3,17,-3,minecraft:concrete:0)
Block(-3,17,-2,minecraft:concrete:0)
Block(-3,17,-1,minecraft:concrete:0)
Block(-3,17,0,minecraft:concrete:0)
Block(-3,17,1,minecraft:concrete:0)
Block(-3,17,2,minecraft:concrete:0)
Block(-3,17,3,minecraft:concrete:0)
Block(-3,17,4,minecraft:concrete:0)
Block(-3,17,5,minecraft:concrete:0)
Block(-3,17,6,minecraft:concrete:0)
Block(-3,17,7,minecraft:concrete:0)
Block(-3,17,8,minecraft:concrete:0)
Block(-3,17,9,minecraft:concrete:0)
Block(-3,18,-6,minecraft:concrete:0)
Block(-3,18,-5,minecraft:concrete:0)
Block(-3,18,-4,minecraft:iron_door:0)
Block(-3,18,-3,minecraft:concrete:0)
Block(-3,18,-2,minecraft:concrete:0)
Block(-3,18,-1,minecraft:concrete:0)
Block(-3,18,0,minecraft:stonebrick:0)
Block(-3,18,1,AIR:0)
Block(-3,18,2,minecraft:concrete:0)
Block(-3,18,3,minecraft:concrete:0)
Block(-3,18,4,minecraft:concrete:0)
Block(-3,18,5,minecraft:concrete:0)
Block(-3,18,6,minecraft:concrete:0)
Block(-3,18,7,minecraft:concrete:0)
Block(-3,18,8,minecraft:concrete:0)
Block(-3,18,9,minecraft:concrete:0)
Block(-3,19,-6,minecraft:concrete:0)
Block(-3,19,-5,minecraft:concrete:0)
Block(-3,19,-4,minecraft:iron_door:9)
Block(-3,19,-3,minecraft:concrete:0)
Block(-3,19,-2,minecraft:concrete:0)
Block(-3,19,-1,minecraft:concrete:0)
Block(-3,19,0,AIR:0)
Block(-3,19,1,AIR:0)
Block(-3,19,2,minecraft:concrete:0)
Block(-3,19,3,minecraft:concrete:0)
Block(-3,19,4,minecraft:concrete:0)
Block(-3,19,5,minecraft:concrete:0)
Block(-3,19,6,minecraft:concrete:0)
Block(-3,19,7,minecraft:concrete:0)
Block(-3,19,8,minecraft:concrete:0)
Block(-3,19,9,minecraft:concrete:0)
Block(-3,20,-6,minecraft:concrete:0)
Block(-3,20,-5,minecraft:concrete:0)
Block(-3,20,-4,quark:sturdy_stone:0)
Block(-3,20,-3,minecraft:concrete:0)
Block(-3,20,-2,minecraft:concrete:0)
Block(-3,20,-1,minecraft:concrete:0)
Block(-3,20,0,minecraft:concrete:0)
Block(-3,20,1,minecraft:concrete:0)
Block(-3,20,2,minecraft:concrete:0)
Block(-3,20,3,minecraft:concrete:0)
Block(-3,20,4,minecraft:concrete:0)
Block(-3,20,5,minecraft:concrete:0)
Block(-3,20,6,minecraft:concrete:0)
Block(-3,20,7,minecraft:concrete:0)
Block(-3,20,8,minecraft:concrete:0)
Block(-3,20,9,minecraft:concrete:0)
Block(-3,21,-6,minecraft:concrete:0)
Block(-3,21,-5,minecraft:concrete:0)
Block(-3,21,-4,minecraft:concrete:0)
Block(-3,21,-3,minecraft:concrete:0)
Block(-3,21,-2,minecraft:concrete:0)
Block(-3,21,-1,minecraft:concrete:0)
Block(-3,21,0,minecraft:concrete:0)
Block(-3,21,1,minecraft:concrete:0)
Block(-3,21,2,minecraft:concrete:0)
Block(-3,21,3,minecraft:concrete:0)
Block(-3,21,4,minecraft:concrete:0)
Block(-3,21,5,minecraft:concrete:0)
Block(-3,21,6,minecraft:concrete:0)
Block(-3,21,7,minecraft:concrete:0)
Block(-3,21,8,minecraft:concrete:0)
Block(-3,21,9,minecraft:concrete:0)
Block(-3,22,-6,minecraft:concrete:0)
Block(-3,22,-5,minecraft:concrete:0)
Block(-3,22,-4,minecraft:iron_door:0)
Block(-3,22,-3,minecraft:concrete:0)
Block(-3,22,-2,minecraft:concrete:0)
Block(-3,22,-1,minecraft:concrete:0)
Block(-3,22,0,AIR:0)
Block(-3,22,1,minecraft:stone:0)
Block(-3,22,2,minecraft:concrete:0)
Block(-3,22,3,minecraft:concrete:0)
Block(-3,22,4,minecraft:concrete:0)
Block(-3,22,5,minecraft:concrete:0)
Block(-3,22,6,minecraft:concrete:0)
Block(-3,22,7,minecraft:concrete:0)
Block(-3,22,8,minecraft:concrete:0)
Block(-3,22,9,minecraft:concrete:0)
Block(-3,23,-6,minecraft:concrete:0)
Block(-3,23,-5,minecraft:concrete:0)
Block(-3,23,-4,minecraft:iron_door:9)
Block(-3,23,-3,minecraft:concrete:0)
Block(-3,23,-2,minecraft:concrete:0)
Block(-3,23,-1,minecraft:concrete:0)
Block(-3,23,0,AIR:0)
Block(-3,23,1,AIR:0)
Block(-3,23,2,minecraft:concrete:0)
Block(-3,23,3,minecraft:concrete:0)
Block(-3,23,4,minecraft:concrete:0)
Block(-3,23,5,minecraft:concrete:0)
Block(-3,23,6,minecraft:concrete:0)
Block(-3,23,7,minecraft:concrete:0)
Block(-3,23,8,minecraft:concrete:0)
Block(-3,23,9,minecraft:concrete:0)
Block(-3,24,-6,minecraft:concrete:0)
Block(-3,24,-5,minecraft:concrete:0)
Block(-3,24,-4,quark:sturdy_stone:0)
Block(-3,24,-3,minecraft:concrete:0)
Block(-3,24,-2,minecraft:concrete:0)
Block(-3,24,-1,minecraft:concrete:0)
Block(-3,24,0,minecraft:concrete:0)
Block(-3,24,1,minecraft:concrete:0)
Block(-3,24,2,minecraft:concrete:0)
Block(-3,24,3,minecraft:concrete:0)
Block(-3,24,4,minecraft:concrete:0)
Block(-3,24,5,minecraft:concrete:0)
Block(-3,24,6,minecraft:concrete:0)
Block(-3,24,7,minecraft:concrete:0)
Block(-3,24,8,minecraft:concrete:0)
Block(-3,24,9,minecraft:concrete:0)
Block(-3,25,-6,minecraft:concrete:0)
Block(-3,25,-5,minecraft:concrete:0)
Block(-3,25,-4,minecraft:concrete:0)
Block(-3,25,-3,minecraft:concrete:0)
Block(-3,25,-2,minecraft:concrete:0)
Block(-3,25,-1,minecraft:concrete:0)
Block(-3,25,0,minecraft:concrete:0)
Block(-3,25,1,minecraft:concrete:0)
Block(-3,25,2,minecraft:concrete:0)
Block(-3,25,3,minecraft:concrete:0)
Block(-3,25,4,minecraft:concrete:0)
Block(-3,25,5,minecraft:concrete:0)
Block(-3,25,6,minecraft:concrete:0)
Block(-3,25,7,minecraft:concrete:0)
Block(-3,25,8,minecraft:concrete:0)
Block(-3,25,9,minecraft:concrete:0)
Block(-3,26,-6,minecraft:concrete:0)
Block(-3,26,-5,minecraft:concrete:0)
Block(-3,26,-4,minecraft:iron_door:0)
Block(-3,26,-3,minecraft:concrete:0)
Block(-3,26,-2,minecraft:concrete:0)
Block(-3,26,-1,minecraft:concrete:0)
Block(-3,26,0,AIR:0)
Block(-3,26,1,AIR:0)
Block(-3,26,2,minecraft:concrete:0)
Block(-3,26,3,minecraft:concrete:0)
Block(-3,26,4,minecraft:concrete:0)
Block(-3,26,5,minecraft:concrete:0)
Block(-3,26,6,minecraft:concrete:0)
Block(-3,26,7,minecraft:concrete:0)
Block(-3,26,8,minecraft:concrete:0)
Block(-3,26,9,minecraft:concrete:0)
Block(-3,27,-6,minecraft:concrete:0)
Block(-3,27,-5,minecraft:concrete:0)
Block(-3,27,-4,minecraft:iron_door:9)
Block(-3,27,-3,minecraft:concrete:0)
Block(-3,27,-2,minecraft:concrete:0)
Block(-3,27,-1,minecraft:concrete:0)
Block(-3,27,0,AIR:0)
Block(-3,27,1,AIR:0)
Block(-3,27,2,minecraft:concrete:0)
Block(-3,27,3,minecraft:concrete:0)
Block(-3,27,4,minecraft:concrete:0)
Block(-3,27,5,minecraft:concrete:0)
Block(-3,27,6,minecraft:concrete:0)
Block(-3,27,7,minecraft:concrete:0)
Block(-3,27,8,minecraft:concrete:0)
Block(-3,27,9,minecraft:concrete:0)
Block(-3,28,-6,minecraft:concrete:0)
Block(-3,28,-5,minecraft:concrete:0)
Block(-3,28,-4,quark:sturdy_stone:0)
Block(-3,28,-3,minecraft:concrete:0)
Block(-3,28,-2,minecraft:concrete:0)
Block(-3,28,-1,minecraft:concrete:0)
Block(-3,28,0,minecraft:concrete:0)
Block(-3,28,1,minecraft:concrete:0)
Block(-3,28,2,minecraft:concrete:0)
Block(-3,28,3,minecraft:concrete:0)
Block(-3,28,4,minecraft:concrete:0)
Block(-3,28,5,minecraft:concrete:0)
Block(-3,28,6,minecraft:concrete:0)
Block(-3,28,7,minecraft:concrete:0)
Block(-3,28,8,minecraft:concrete:0)
Block(-3,28,9,minecraft:concrete:0)
Block(-3,29,-6,minecraft:concrete:0)
Block(-3,29,-5,minecraft:concrete:0)
Block(-3,29,-4,minecraft:concrete:0)
Block(-3,29,-3,minecraft:concrete:0)
Block(-3,29,-2,minecraft:concrete:0)
Block(-3,29,-1,minecraft:concrete:0)
Block(-3,29,0,minecraft:concrete:0)
Block(-3,29,1,minecraft:concrete:0)
Block(-3,29,2,minecraft:concrete:0)
Block(-3,29,3,minecraft:concrete:0)
Block(-3,29,4,minecraft:concrete:0)
Block(-3,29,5,minecraft:concrete:0)
Block(-3,29,6,minecraft:concrete:0)
Block(-3,29,7,minecraft:concrete:0)
Block(-3,29,8,minecraft:concrete:0)
Block(-3,29,9,minecraft:concrete:0)
Block(-3,30,-6,minecraft:concrete:0)
Block(-3,30,-5,minecraft:concrete:0)
Block(-3,30,-4,minecraft:iron_door:0)
Block(-3,30,-3,minecraft:concrete:0)
Block(-3,30,-2,minecraft:concrete:0)
Block(-3,30,-1,minecraft:concrete:0)
Block(-3,30,0,minecraft:iron_door:4)
Block(-3,30,1,minecraft:concrete:0)
Block(-3,30,2,minecraft:concrete:0)
Block(-3,30,3,minecraft:concrete:0)
Block(-3,31,-6,minecraft:concrete:0)
Block(-3,31,-5,minecraft:concrete:0)
Block(-3,31,-4,minecraft:iron_door:9)
Block(-3,31,-3,minecraft:concrete:0)
Block(-3,31,-2,minecraft:concrete:0)
Block(-3,31,-1,minecraft:concrete:0)
Block(-3,31,0,minecraft:iron_door:9)
Block(-3,31,1,minecraft:concrete:0)
Block(-3,31,2,minecraft:concrete:0)
Block(-3,31,3,minecraft:concrete:0)
Block(-3,32,-6,minecraft:concrete:0)
Block(-3,32,-5,minecraft:concrete:0)
Block(-3,32,-4,minecraft:concrete:0)
Block(-3,32,-3,minecraft:concrete:0)
Block(-3,32,-2,minecraft:concrete:0)
Block(-3,32,-1,minecraft:concrete:0)
Block(-3,32,0,minecraft:concrete:0)
Block(-3,32,1,minecraft:concrete:0)
Block(-3,32,2,minecraft:concrete:0)
Block(-3,32,3,minecraft:concrete:0)
Block(-3,33,-6,minecraft:concrete:0)
Block(-3,33,-5,minecraft:concrete:0)
Block(-3,33,-4,minecraft:concrete:0)
Block(-3,33,-3,minecraft:concrete:0)
Block(-3,33,-2,minecraft:concrete:0)
Block(-3,33,-1,minecraft:concrete:0)
Block(-3,33,0,minecraft:concrete:0)
Block(-3,33,1,minecraft:concrete:0)
Block(-3,33,2,minecraft:concrete:0)
Block(-3,33,3,minecraft:concrete:0)
Block(-3,34,-6,minecraft:concrete:0)
Block(-3,34,-5,minecraft:concrete:0)
Block(-3,34,-4,minecraft:concrete:0)
Block(-3,34,-3,minecraft:concrete:0)
Block(-3,34,-2,minecraft:concrete:0)
Block(-3,35,-6,minecraft:concrete:0)
Block(-3,35,-5,minecraft:concrete:0)
Block(-3,35,-4,minecraft:concrete:0)
Block(-3,35,-3,minecraft:concrete:0)
Block(-3,35,-2,minecraft:concrete:0)
Block(-3,36,-6,minecraft:concrete:0)
Block(-3,36,-5,minecraft:concrete:0)
Block(-3,36,-4,minecraft:concrete:0)
Block(-3,36,-3,minecraft:concrete:0)
Block(-3,36,-2,minecraft:concrete:0)
Block(-3,37,-6,minecraft:concrete:0)
Block(-3,37,-5,minecraft:concrete:0)
Block(-3,37,-4,minecraft:concrete:0)
Block(-3,37,-3,minecraft:concrete:0)
Block(-3,37,-2,minecraft:concrete:0)
Block(-3,38,-6,minecraft:concrete:0)
Block(-3,38,-5,minecraft:concrete:0)
Block(-3,38,-4,minecraft:concrete:0)
Block(-3,38,-3,minecraft:concrete:0)
Block(-3,38,-2,minecraft:concrete:0)
Block(-3,38,-1,minecraft:concrete:0)
Block(-3,38,0,minecraft:concrete:0)
Block(-3,38,1,minecraft:concrete:0)
Block(-3,38,2,minecraft:concrete:0)
Block(-3,38,3,minecraft:concrete:0)
Block(-3,38,4,minecraft:concrete:0)
Block(-3,38,5,minecraft:concrete:0)
Block(-3,38,6,minecraft:concrete:0)
Block(-3,38,7,minecraft:concrete:0)
Block(-3,39,-6,minecraft:concrete:0)
Block(-3,39,-5,minecraft:concrete:0)
Block(-3,39,-4,minecraft:concrete:0)
Block(-3,39,-3,minecraft:concrete:0)
Block(-3,39,-2,minecraft:concrete:0)
Block(-3,39,-1,minecraft:concrete:0)
Block(-3,39,0,minecraft:concrete:0)
Block(-3,39,1,minecraft:concrete:0)
Block(-3,39,2,minecraft:concrete:0)
Block(-3,39,3,minecraft:concrete:0)
Block(-3,39,4,minecraft:concrete:0)
Block(-3,39,5,minecraft:concrete:0)
Block(-3,39,6,minecraft:concrete:0)
Block(-3,39,7,minecraft:concrete:0)
Block(-3,40,-6,minecraft:concrete:0)
Block(-3,40,-5,minecraft:concrete:0)
Block(-3,40,-4,minecraft:concrete:0)
Block(-3,40,-3,minecraft:concrete:0)
Block(-3,40,-2,minecraft:stonebrick)
Block(-3,40,-1,minecraft:concrete:0)
Block(-3,40,0,minecraft:concrete:0)
Block(-3,40,1,minecraft:concrete:0)
Block(-3,40,2,minecraft:concrete:0)
Block(-3,40,3,minecraft:stonebrick:5)
Block(-3,40,4,minecraft:concrete:0)
Block(-3,40,5,minecraft:concrete:0)
Block(-3,40,6,minecraft:concrete:0)
Block(-3,40,7,minecraft:concrete:0)
Block(-3,41,-6,minecraft:concrete:0)
Block(-3,41,-5,minecraft:concrete:0)
Block(-3,41,-4,minecraft:concrete:0)
Block(-3,41,-3,minecraft:concrete:0)
Block(-3,41,-2,minecraft:concrete:0)
Block(-3,41,-1,minecraft:concrete:0)
Block(-3,41,0,minecraft:concrete:0)
Block(-3,41,1,minecraft:concrete:0)
Block(-3,41,2,minecraft:concrete:0)
Block(-3,41,3,minecraft:concrete:0)
Block(-3,41,4,minecraft:concrete:0)
Block(-3,41,5,minecraft:concrete:0)
Block(-3,41,6,minecraft:concrete:0)
Block(-3,41,7,minecraft:concrete:0)
Block(-3,42,-6,minecraft:concrete:0)
Block(-3,42,-5,minecraft:concrete:0)
Block(-3,42,-4,minecraft:concrete:0)
Block(-3,42,-3,minecraft:stone_brick_stairs:2)
Block(-3,42,-2,minecraft:concrete:0)
Block(-3,42,-1,minecraft:concrete:0)
Block(-3,42,0,minecraft:concrete:0)
Block(-3,42,1,minecraft:concrete:0)
Block(-3,42,2,minecraft:concrete:0)
