
#######################################################################
# +-----------------------------------------------------------------+ #
# |                            BO4 object                           | #
# +-----------------------------------------------------------------+ #
#######################################################################

# This is the config file of a custom object.
# If you add this object correctly to your BiomeConfigs, it will spawn in the world.

# This is the creator of this BO4 object
Author: NLBlackEagle

# A short description of this BO4 object
Description: No description given

# The settings mode, WriteAll, WriteWithoutComments or WriteDisable. See WorldConfig.
SettingsMode: WriteAll


#######################################################################
# +-----------------------------------------------------------------+ #
# |                          Main settings                          | #
# +-----------------------------------------------------------------+ #
#######################################################################

# If this BO4 should spawn with a fixed rotation, set it here.
# For example: NORTH, EAST, SOUTH or WEST. Empty by default
FixedRotation: 

# This BO4 can only spawn at least Frequency chunks distance away from any other BO4 with the exact same name.
# You can use this to make this BO4 spawn in groups or make sure that this BO4 only spawns once every X chunks.
Frequency: 0

# The spawn height of the BO4: randomY, highestBlock or highestSolidBlock.
SpawnHeight: highestBlock

# When set to true, uses the center of the structure (determined by minimum structure size) when checking the highestBlock to spawn at.
UseCenterForHighestBlock: true

##############################
# Height Limits for the BO4. #
##############################

# When in randomY mode used as the minimum Y or in atMinY mode as the actual Y to spawn this BO4 at.
MinHeight: 0

# When in randomY mode used as the maximum Y to spawn this BO4 at.
MaxHeight: 255

# Copies the blocks and branches of an existing BO4 into this BO4. You can still add blocks and branches in this BO4, they will be added on top of the inherited blocks and branches.
InheritBO3: 

# Rotates the inheritedBO3's resources (blocks, spawners, checks etc) and branches, defaults to NORTH (no rotation).
InheritBO3Rotation: NORTH

# Defaults to true, if true and this is the starting BO4 for this branching structure then this BO4's smoothing and height settings are used for all children (branches).
OverrideChildSettings: true

# Defaults to false, if true then this branch uses it's own height settings (SpawnHeight, minHeight, maxHeight, spawnAtWaterLevel) instead of those defined in the starting BO4 for this branching structure.
OverrideParentHeight: false

# If this is set to true then this BO4 can spawn on top of or inside an existing BO4. If this is set to false then this BO4 will use a bounding box to detect collisions with other BO4's, if a collision is detected then this BO4 won't spawn and the current branch is rolled back.
CanOverride: false

# This branch can only spawn at least branchFrequency chunks (x,z) distance away from any other branch with the exact same name.
BranchFrequency: 0

# Define groups that this branch belongs to along with a minimum (x,z) range in chunks that this branch must have between it and any other members of this group if it is to be allowed to spawn. Syntax is "GroupName:Frequency, GoupName2:Frequency2" etc so for example a branch that belongs to 3 groups: "BranchFrequencyGroup: Ships:10, Vehicles:5, FloatingThings:3".
BranchFrequencyGroup: 

# If this is set to true then this BO4 can only spawn underneath an existing BO4. Used to make sure that dungeons only appear underneath buildings.
MustBeBelowOther: false

# Used with CanOverride: true. A comma-seperated list of BO4s, this BO4's bounding box must collide with one of the BO4's in the list or this BO4 fails to spawn and the current branch is rolled back. AND/OR is supported, comma is OR, space is AND, f.e: branch1, branch2 branch3, branch 4.
MustBeInside: 

# Used with CanOverride: true. A comma-seperated list of BO4s, this BO4's bounding box cannot collide with any of the BO4's in the list or this BO4 fails to spawn and the current branch is rolled back.
CannotBeInside: 

# Used with CanOverride: true. A comma-seperated list of BO4s, if this BO4's bounding box collides with any of the BO4's in the list then those BO4's won't spawn any blocks. This does not remove or roll back any BO4's.
ReplacesBO3: 

# If this is set to true then this BO4 can only spawn inside world borders. Used to make sure that dungeons only appear inside the world borders.
MustBeInsideWorldBorders: true
# Defaults to true. Set to false if the BO4 is not allowed to spawn on a water block
CanSpawnOnWater: true

# Defaults to false. Set to true if the BO4 is allowed to spawn only on a water block
SpawnOnWaterOnly: false

# Defaults to false. Set to true if the BO4 and its smoothing area should ignore water when looking for the highest block to spawn on. Defaults to false (things spawn on top of water)
SpawnUnderWater: false

# Defaults to false. Set to true if the BO4 should spawn at water level
SpawnAtWaterLevel: false

# Spawns the BO4 at a Y offset of this value. Handy when using highestBlock for lowering BO4s into the surrounding terrain when there are layers of ground included in the BO4, also handy when using SpawnAtWaterLevel to lower objects like ships into the water.
HeightOffset: 0

# If set to true removes all AIR blocks from the BO4 so that it can be flooded or buried.
RemoveAir: false

# Replaces all the non-air blocks that are above this BO4 or its smoothing area with the given block material (should be WATER or AIR or NONE), also applies to smoothing areas although OTG intentionally leaves some of the terrain above them intact. WATER can be used in combination with SpawnUnderWater to fill any air blocks underneath waterlevel with water (and any above waterlevel with air).
ReplaceAbove: 

# Replaces all air blocks underneath the BO4 (but not its smoothing area) with the specified material until a solid block is found.
ReplaceBelow: 

# Defaults to true. If set to true then every block in the BO4 of the materials defined in ReplaceWithGroundBlock or ReplaceWithSurfaceBlock will be replaced by the GroundBlock or SurfaceBlock materials configured for the biome the block is spawned in.
ReplaceWithBiomeBlocks: true

# Defaults to GRASS, Replaces all the blocks of the given material in the BO4 with the SurfaceBlock configured for the biome it spawns in.
ReplaceWithSurfaceBlock: GRASS

# Defaults to DIRT, Replaces all the blocks of the given material in the BO4 with the GroundBlock configured for the biome it spawns in.
ReplaceWithGroundBlock: DIRT

# Defaults to STONE, Replaces all the blocks of the given material in the BO4 with the StoneBlock configured for the biome it spawns in.
ReplaceWithStoneBlock: STONE

# Makes the terrain around the BO4 slope evenly towards the edges of the BO4. The given value is the distance in blocks around the BO4 from where the slope should start and can be any positive number.
SmoothRadius: 0

# Moves the smoothing area up or down relative to the BO4 (at the points where the smoothing area is connected to the BO4). Handy when using SmoothStartTop: false and the BO4 has some layers of ground included, in that case we can set the HeightOffset to a negative value to lower the BO4 into the ground and we can set the SmoothHeightOffset to a positive value to move the smoothing area starting height up.
SmoothHeightOffset: 0

# Should the smoothing area be attached at the bottom or the top of the edges of the BO4? Defaults to false (bottom). Using this setting can make things slower so try to avoid using it and use SmoothHeightOffset instead if for instance you have a BO4 with some ground layers included. The only reason you should need to use this setting is if you have a BO4 with edges that have an irregular height (like some hills).
SmoothStartTop: false

# Should the smoothing area attach itself to "log" block or ignore them? Defaults to false (ignore logs).
SmoothStartWood: false

# The block used for smoothing area surface blocks, defaults to biome SurfaceBlock.
SmoothingSurfaceBlock: 

# The block used for smoothing area ground blocks, defaults to biome GroundBlock.
SmoothingGroundBlock: 

# Define groups that this BO4 belongs to along with a minimum range in chunks that this BO4 must have between it and any other members of this group if it is to be allowed to spawn. Syntax is "GroupName:Frequency, GoupName2:Frequency2" etc so for example a BO4 that belongs to 3 groups: "BO4Group: Ships:10, Vehicles:5, FloatingThings:3".
BO3Group: 

# Defaults to false. Set to true if this BO4 should spawn at the player spawn point. When the server starts the spawn point is determined and the BO4's for the biome it is in are loaded, one of these BO4s that has IsSpawnPoint set to true (if any) is selected randomly and is spawned at the spawn point regardless of its rarity (so even Rarity:0, IsSpawnPoint: true BO4's can get spawned as the spawn point!).
IsSpawnPoint: false

# Defaults to true. Set to false to make the BO4 ignore any ReplacedBlocks settings in Biome Configs.
DoReplaceBlocks: true


#######################################################################
# +-----------------------------------------------------------------+ #
# |                              Blocks                             | #
# +-----------------------------------------------------------------+ #
#######################################################################

# All the blocks used in the BO4 are listed here. Possible blocks:
# Block(x,y,z,id[.data][,nbtfile.nbt)
# RandomBlock(x,y,z,id[:data][,nbtfile.nbt],chance[,id[:data][,nbtfile.nbt],chance[,...]])
#  So RandomBlock(0,0,0,CHEST,chest.nbt,50,CHEST,anotherchest.nbt,100) will spawn a chest at
#  the BO4 origin, and give it a 50% chance to have the contents of chest.nbt, or, if that
#  fails, a 100% percent chance to have the contents of anotherchest.nbt.
# MinecraftObject(x,y,z,name) (TODO: This may not work anymore and needs to be tested.
#  Spawns an object in the Mojang NBT structure format. For example, 
#  MinecraftObject(0,0,0,minecraft:igloo/igloo_bottom)
#  spawns the bottom part of an igloo.
Block(-7,0,-6,minecraft:concrete:0)
Block(-7,0,-5,minecraft:concrete:0)
Block(-7,0,8,minecraft:concrete:0)
Block(-7,0,9,minecraft:concrete:0)
Block(-7,1,-6,minecraft:concrete:0)
Block(-7,1,-5,minecraft:concrete:0)
Block(-7,1,8,minecraft:concrete:0)
Block(-7,1,9,minecraft:concrete:0)
Block(-7,2,-6,minecraft:concrete:0)
Block(-7,2,-5,minecraft:concrete:0)
Block(-7,2,8,minecraft:concrete:0)
Block(-7,2,9,minecraft:concrete:0)
Block(-7,3,-6,minecraft:concrete:0)
Block(-7,3,-5,minecraft:concrete:0)
Block(-7,3,8,minecraft:concrete:0)
Block(-7,3,9,minecraft:concrete:0)
Block(-7,4,-6,minecraft:concrete:0)
Block(-7,4,-5,minecraft:concrete:0)
Block(-7,4,-4,minecraft:concrete:0)
Block(-7,4,-3,minecraft:concrete:0)
Block(-7,4,-2,minecraft:concrete:0)
Block(-7,4,-1,minecraft:concrete:0)
Block(-7,4,0,minecraft:concrete:0)
Block(-7,4,1,minecraft:concrete:0)
Block(-7,4,2,minecraft:concrete:0)
Block(-7,4,8,minecraft:concrete:0)
Block(-7,4,9,minecraft:concrete:0)
Block(-7,5,-6,minecraft:concrete:0)
Block(-7,5,-5,minecraft:concrete:0)
Block(-7,5,-4,minecraft:concrete:0)
Block(-7,5,-3,minecraft:concrete:0)
Block(-7,5,-2,minecraft:concrete:0)
Block(-7,5,-1,minecraft:concrete:0)
Block(-7,5,0,minecraft:concrete:0)
Block(-7,5,1,minecraft:concrete:0)
Block(-7,5,2,minecraft:concrete:0)
Block(-7,5,3,minecraft:concrete:0)
Block(-7,5,4,minecraft:concrete:0)
Block(-7,5,5,minecraft:concrete:0)
Block(-7,5,6,minecraft:concrete:0)
Block(-7,5,7,minecraft:concrete:0)
Block(-7,5,8,minecraft:concrete:0)
Block(-7,5,9,minecraft:concrete:0)
Block(-7,6,-6,minecraft:concrete:0)
Block(-7,6,-5,minecraft:concrete:0)
Block(-7,6,-4,minecraft:concrete:0)
Block(-7,6,-3,minecraft:concrete:0)
Block(-7,6,-2,minecraft:concrete:0)
Block(-7,6,-1,minecraft:concrete:0)
Block(-7,6,0,minecraft:concrete:0)
Block(-7,6,1,minecraft:concrete:0)
Block(-7,6,2,minecraft:concrete:0)
Block(-7,6,3,minecraft:concrete:0)
Block(-7,6,4,minecraft:concrete:0)
Block(-7,6,5,minecraft:concrete:0)
Block(-7,6,6,minecraft:concrete:0)
Block(-7,6,7,minecraft:concrete:0)
Block(-7,6,8,minecraft:concrete:0)
Block(-7,6,9,minecraft:concrete:0)
Block(-7,7,-6,minecraft:concrete:0)
Block(-7,7,-5,minecraft:concrete:0)
Block(-7,7,-4,minecraft:concrete:0)
Block(-7,7,-3,minecraft:concrete:0)
Block(-7,7,-2,minecraft:concrete:0)
Block(-7,7,-1,minecraft:concrete:0)
Block(-7,7,0,minecraft:concrete:0)
Block(-7,7,1,minecraft:concrete:0)
Block(-7,7,2,minecraft:concrete:0)
Block(-7,7,3,minecraft:concrete:0)
Block(-7,7,4,minecraft:concrete:0)
Block(-7,7,5,minecraft:concrete:0)
Block(-7,7,6,minecraft:concrete:0)
Block(-7,7,7,minecraft:concrete:0)
Block(-7,7,8,minecraft:concrete:0)
Block(-7,7,9,minecraft:concrete:0)
Block(-7,8,-6,minecraft:concrete:0)
Block(-7,8,-5,minecraft:concrete:0)
Block(-7,8,-4,minecraft:concrete:0)
Block(-7,8,-3,minecraft:concrete:0)
Block(-7,8,-2,minecraft:concrete:0)
Block(-7,8,-1,minecraft:concrete:0)
Block(-7,8,0,minecraft:concrete:0)
Block(-7,8,1,minecraft:concrete:0)
Block(-7,8,2,minecraft:concrete:0)
Block(-7,8,3,minecraft:concrete:0)
Block(-7,8,4,minecraft:concrete:0)
Block(-7,8,5,minecraft:concrete:0)
Block(-7,8,6,minecraft:concrete:0)
Block(-7,8,7,minecraft:concrete:0)
Block(-7,8,8,minecraft:concrete:0)
Block(-7,8,9,minecraft:concrete:0)
Block(-7,9,-6,minecraft:concrete:0)
Block(-7,9,-5,minecraft:concrete:0)
Block(-7,9,-4,minecraft:concrete:0)
Block(-7,9,-3,minecraft:concrete:0)
Block(-7,9,-2,minecraft:concrete:0)
Block(-7,9,-1,minecraft:concrete:0)
Block(-7,9,0,minecraft:concrete:0)
Block(-7,9,1,minecraft:concrete:0)
Block(-7,9,2,minecraft:concrete:0)
Block(-7,9,3,minecraft:concrete:0)
Block(-7,9,4,minecraft:concrete:0)
Block(-7,9,5,minecraft:concrete:0)
Block(-7,9,6,minecraft:concrete:0)
Block(-7,9,7,minecraft:concrete:0)
Block(-7,9,8,minecraft:concrete:0)
Block(-7,9,9,minecraft:concrete:0)
Block(-7,10,-6,minecraft:concrete:0)
Block(-7,10,-5,minecraft:concrete:0)
Block(-7,10,-4,minecraft:concrete:0)
Block(-7,10,-3,minecraft:concrete:0)
Block(-7,10,-2,minecraft:concrete:0)
Block(-7,10,-1,minecraft:concrete:0)
Block(-7,10,0,minecraft:concrete:0)
Block(-7,10,1,minecraft:concrete:0)
Block(-7,10,2,minecraft:concrete:0)
Block(-7,10,3,minecraft:concrete:0)
Block(-7,10,4,minecraft:concrete:0)
Block(-7,10,5,minecraft:concrete:0)
Block(-7,10,6,minecraft:concrete:0)
Block(-7,10,7,minecraft:concrete:0)
Block(-7,10,8,minecraft:concrete:0)
Block(-7,10,9,minecraft:concrete:0)
Block(-7,11,-6,minecraft:concrete:0)
Block(-7,11,-5,minecraft:concrete:0)
Block(-7,11,-4,minecraft:concrete:0)
Block(-7,11,-3,minecraft:concrete:0)
Block(-7,11,-2,minecraft:concrete:0)
Block(-7,11,-1,minecraft:concrete:0)
Block(-7,11,0,minecraft:concrete:0)
Block(-7,11,1,minecraft:concrete:0)
Block(-7,11,2,minecraft:concrete:0)
Block(-7,11,3,minecraft:concrete:0)
Block(-7,11,4,minecraft:concrete:0)
Block(-7,11,5,minecraft:concrete:0)
Block(-7,11,6,minecraft:concrete:0)
Block(-7,11,7,minecraft:concrete:0)
Block(-7,11,8,minecraft:concrete:0)
Block(-7,11,9,minecraft:concrete:0)
Block(-7,12,-6,minecraft:concrete:0)
Block(-7,12,-5,minecraft:concrete:0)
Block(-7,12,-4,minecraft:concrete:0)
Block(-7,12,-3,minecraft:concrete:0)
Block(-7,12,-2,minecraft:concrete:0)
Block(-7,12,-1,minecraft:concrete:0)
Block(-7,12,0,minecraft:concrete:0)
Block(-7,12,1,minecraft:concrete:0)
Block(-7,12,2,minecraft:concrete:0)
Block(-7,12,3,minecraft:concrete:0)
Block(-7,12,4,minecraft:concrete:0)
Block(-7,12,5,minecraft:concrete:0)
Block(-7,12,6,minecraft:concrete:0)
Block(-7,12,7,minecraft:concrete:0)
Block(-7,12,8,minecraft:concrete:0)
Block(-7,12,9,minecraft:concrete:0)
Block(-7,13,-6,minecraft:concrete:0)
Block(-7,13,-5,minecraft:concrete:0)
Block(-7,13,-4,minecraft:concrete:0)
Block(-7,13,-3,minecraft:concrete:0)
Block(-7,13,-2,minecraft:concrete:0)
Block(-7,13,-1,minecraft:concrete:0)
Block(-7,13,0,minecraft:concrete:0)
Block(-7,13,1,minecraft:concrete:0)
Block(-7,13,2,minecraft:concrete:0)
Block(-7,13,3,minecraft:concrete:0)
Block(-7,13,4,minecraft:concrete:0)
Block(-7,13,5,minecraft:concrete:0)
Block(-7,13,6,minecraft:concrete:0)
Block(-7,13,7,minecraft:concrete:0)
Block(-7,13,8,minecraft:concrete:0)
Block(-7,13,9,minecraft:concrete:0)
Block(-7,14,-6,minecraft:concrete:0)
Block(-7,14,-5,minecraft:concrete:0)
Block(-7,14,-4,minecraft:concrete:0)
Block(-7,14,-3,minecraft:concrete:0)
Block(-7,14,-2,minecraft:concrete:0)
Block(-7,14,-1,minecraft:concrete:0)
Block(-7,14,0,minecraft:concrete:0)
Block(-7,14,1,minecraft:concrete:0)
Block(-7,14,2,minecraft:concrete:0)
Block(-7,14,3,minecraft:concrete:0)
Block(-7,14,4,minecraft:concrete:0)
Block(-7,14,5,minecraft:concrete:0)
Block(-7,14,6,minecraft:concrete:0)
Block(-7,14,7,minecraft:concrete:0)
Block(-7,14,8,minecraft:concrete:0)
Block(-7,14,9,minecraft:concrete:0)
Block(-7,15,-6,minecraft:concrete:0)
Block(-7,15,-5,minecraft:concrete:0)
Block(-7,15,-4,minecraft:concrete:0)
Block(-7,15,-3,minecraft:concrete:0)
Block(-7,15,-2,minecraft:concrete:0)
Block(-7,15,-1,minecraft:concrete:0)
Block(-7,15,0,minecraft:concrete:0)
Block(-7,15,1,minecraft:concrete:0)
Block(-7,15,2,minecraft:concrete:0)
Block(-7,15,3,minecraft:concrete:0)
Block(-7,15,4,minecraft:concrete:0)
Block(-7,15,5,minecraft:concrete:0)
Block(-7,15,6,minecraft:concrete:0)
Block(-7,15,7,minecraft:concrete:0)
Block(-7,15,8,minecraft:concrete:0)
Block(-7,15,9,minecraft:concrete:0)
Block(-7,16,-6,minecraft:concrete:0)
Block(-7,16,-5,minecraft:concrete:0)
Block(-7,16,-4,minecraft:concrete:0)
Block(-7,16,-3,minecraft:concrete:0)
Block(-7,16,-2,minecraft:concrete:0)
Block(-7,16,-1,minecraft:concrete:0)
Block(-7,16,0,minecraft:concrete:0)
Block(-7,16,1,minecraft:concrete:0)
Block(-7,16,2,minecraft:concrete:0)
Block(-7,16,3,minecraft:concrete:0)
Block(-7,16,4,minecraft:concrete:0)
Block(-7,16,5,minecraft:concrete:0)
Block(-7,16,6,minecraft:concrete:0)
Block(-7,16,7,minecraft:concrete:0)
Block(-7,16,8,minecraft:concrete:0)
Block(-7,16,9,minecraft:concrete:0)
Block(-7,17,-6,minecraft:concrete:0)
Block(-7,17,-5,minecraft:concrete:0)
Block(-7,17,-4,minecraft:concrete:0)
Block(-7,17,-3,minecraft:concrete:0)
Block(-7,17,-2,minecraft:concrete:0)
Block(-7,17,-1,minecraft:concrete:0)
Block(-7,17,0,minecraft:concrete:0)
Block(-7,17,1,minecraft:concrete:0)
Block(-7,17,2,minecraft:concrete:0)
Block(-7,17,3,minecraft:concrete:0)
Block(-7,17,4,minecraft:concrete:0)
Block(-7,17,5,minecraft:concrete:0)
Block(-7,17,6,minecraft:concrete:0)
Block(-7,17,7,minecraft:concrete:0)
Block(-7,17,8,minecraft:concrete:0)
Block(-7,17,9,minecraft:concrete:0)
Block(-7,18,-6,minecraft:concrete:0)
Block(-7,18,-5,minecraft:concrete:0)
Block(-7,18,-4,minecraft:concrete:0)
Block(-7,18,-3,minecraft:concrete:0)
Block(-7,18,-2,minecraft:concrete:0)
Block(-7,18,-1,minecraft:concrete:0)
Block(-7,18,0,minecraft:concrete:0)
Block(-7,18,1,minecraft:concrete:0)
Block(-7,18,2,minecraft:concrete:0)
Block(-7,18,3,minecraft:concrete:0)
Block(-7,18,4,minecraft:concrete:0)
Block(-7,18,5,minecraft:concrete:0)
Block(-7,18,6,minecraft:concrete:0)
Block(-7,18,7,minecraft:concrete:0)
Block(-7,18,8,minecraft:concrete:0)
Block(-7,18,9,minecraft:concrete:0)
Block(-7,19,-6,minecraft:concrete:0)
Block(-7,19,-5,minecraft:concrete:0)
Block(-7,19,-4,minecraft:concrete:0)
Block(-7,19,-3,minecraft:concrete:0)
Block(-7,19,-2,minecraft:concrete:0)
Block(-7,19,-1,minecraft:concrete:0)
Block(-7,19,0,minecraft:concrete:0)
Block(-7,19,1,minecraft:concrete:0)
Block(-7,19,2,minecraft:concrete:0)
Block(-7,19,3,minecraft:concrete:0)
Block(-7,19,4,minecraft:concrete:0)
Block(-7,19,5,minecraft:concrete:0)
Block(-7,19,6,minecraft:concrete:0)
Block(-7,19,7,minecraft:concrete:0)
Block(-7,19,8,minecraft:concrete:0)
Block(-7,19,9,minecraft:concrete:0)
Block(-7,20,-6,minecraft:concrete:0)
Block(-7,20,1,minecraft:concrete:0)
Block(-7,20,5,minecraft:concrete:0)
Block(-7,20,6,minecraft:concrete:0)
Block(-7,20,7,minecraft:concrete:0)
Block(-7,20,8,minecraft:concrete:0)
Block(-7,20,9,minecraft:concrete:0)
Block(-7,21,-6,minecraft:concrete:0)
Block(-7,21,1,minecraft:concrete:0)
Block(-7,21,5,minecraft:concrete:0)
Block(-7,21,6,minecraft:concrete:0)
Block(-7,21,7,minecraft:concrete:0)
Block(-7,21,8,minecraft:concrete:0)
Block(-7,21,9,minecraft:concrete:0)
Block(-7,22,-6,minecraft:concrete:0)
Block(-7,22,1,minecraft:concrete:0)
Block(-7,22,5,minecraft:concrete:0)
Block(-7,22,6,minecraft:concrete:0)
Block(-7,22,7,minecraft:concrete:0)
Block(-7,22,8,minecraft:concrete:0)
Block(-7,22,9,minecraft:concrete:0)
Block(-7,23,-6,minecraft:concrete:0)
Block(-7,23,1,minecraft:concrete:0)
Block(-7,23,5,minecraft:concrete:0)
Block(-7,23,6,minecraft:concrete:0)
Block(-7,23,7,minecraft:concrete:0)
Block(-7,23,8,minecraft:concrete:0)
Block(-7,23,9,minecraft:concrete:0)
Block(-7,24,-6,minecraft:concrete:0)
Block(-7,24,1,minecraft:concrete:0)
Block(-7,25,-6,minecraft:concrete:0)
Block(-7,25,1,minecraft:concrete:0)
Block(-7,26,-6,minecraft:concrete:0)
Block(-7,26,1,minecraft:concrete:0)
Block(-7,27,-6,minecraft:concrete:0)
Block(-7,27,1,minecraft:concrete:0)
Block(-7,28,-6,minecraft:concrete:0)
Block(-7,28,-5,minecraft:concrete:0)
Block(-7,28,-4,minecraft:concrete:0)
Block(-7,28,-3,minecraft:concrete:0)
Block(-7,28,-2,minecraft:concrete:0)
Block(-7,28,-1,minecraft:concrete:0)
Block(-7,28,0,minecraft:concrete:0)
Block(-7,28,1,minecraft:concrete:0)
Block(-7,29,-6,minecraft:concrete:0)
Block(-7,29,-5,minecraft:concrete:0)
Block(-7,29,-4,minecraft:concrete:0)
Block(-7,29,-3,minecraft:concrete:0)
Block(-7,29,-2,minecraft:concrete:0)
Block(-7,29,-1,minecraft:stone_brick_stairs:0)
Block(-7,29,0,minecraft:stone_brick_stairs:0)
Block(-7,29,1,minecraft:stone_brick_stairs:3)
Block(-7,30,-6,minecraft:concrete:0)
Block(-7,30,-5,minecraft:concrete:0)
Block(-7,30,-4,minecraft:concrete:0)
Block(-7,30,-3,minecraft:stone_brick_stairs:0)
Block(-7,30,-2,minecraft:stone_brick_stairs:0)
Block(-7,30,-1,minecraft:concrete:0)
Block(-7,30,0,minecraft:concrete:0)
Block(-7,30,1,minecraft:concrete:0)
Block(-7,31,-6,minecraft:concrete:0)
Block(-7,31,-5,minecraft:stone_brick_stairs:4)
Block(-7,31,-4,minecraft:concrete:0)
Block(-7,31,-3,minecraft:concrete:0)
Block(-7,31,-2,minecraft:concrete:0)
Block(-7,31,-1,minecraft:concrete:0)
Block(-7,31,0,minecraft:concrete:0)
Block(-7,31,1,minecraft:concrete:0)
Block(-7,32,-2,minecraft:concrete:0)
Block(-6,0,-6,minecraft:concrete:0)
Block(-6,0,-5,minecraft:concrete:0)
Block(-6,0,8,minecraft:concrete:0)
Block(-6,0,9,minecraft:concrete:0)
Block(-6,1,-6,minecraft:concrete:0)
Block(-6,1,-5,minecraft:concrete:0)
Block(-6,1,8,minecraft:concrete:0)
Block(-6,1,9,minecraft:concrete:0)
Block(-6,2,-6,minecraft:concrete:0)
Block(-6,2,-5,minecraft:concrete:0)
Block(-6,2,8,minecraft:concrete:0)
Block(-6,2,9,minecraft:concrete:0)
Block(-6,3,-6,minecraft:concrete:0)
Block(-6,3,-5,minecraft:concrete:0)
Block(-6,3,8,minecraft:concrete:0)
Block(-6,3,9,minecraft:concrete:0)
Block(-6,4,-6,minecraft:concrete:0)
Block(-6,4,-5,minecraft:concrete:0)
Block(-6,4,-4,minecraft:concrete:0)
Block(-6,4,-3,minecraft:concrete:0)
Block(-6,4,-2,minecraft:concrete:0)
Block(-6,4,-1,minecraft:concrete:0)
Block(-6,4,0,minecraft:concrete:0)
Block(-6,4,1,minecraft:concrete:0)
Block(-6,4,2,minecraft:concrete:0)
Block(-6,4,8,minecraft:concrete:0)
Block(-6,4,9,minecraft:concrete:0)
Block(-6,5,-6,minecraft:concrete:0)
Block(-6,5,-5,minecraft:stonebrick:0)
Block(-6,5,-4,minecraft:stonebrick:0)
Block(-6,5,-3,minecraft:stonebrick:0)
Block(-6,5,-2,minecraft:stonebrick:0)
Block(-6,5,-1,minecraft:stonebrick:0)
Block(-6,5,0,minecraft:stonebrick:0)
Block(-6,5,1,minecraft:stonebrick:0)
Block(-6,5,2,minecraft:concrete:0)
Block(-6,5,3,minecraft:concrete:0)
Block(-6,5,4,minecraft:concrete:0)
Block(-6,5,5,minecraft:concrete:0)
Block(-6,5,6,minecraft:concrete:0)
Block(-6,5,7,minecraft:concrete:0)
Block(-6,5,8,minecraft:concrete:0)
Block(-6,5,9,minecraft:concrete:0)
Block(-6,6,-6,minecraft:concrete:0)
Block(-6,6,-5,minecraft:stonebrick:0)
Block(-6,6,-4,minecraft:stonebrick:0)
Block(-6,6,-3,minecraft:stonebrick:0)
Block(-6,6,-2,minecraft:stonebrick:0)
Block(-6,6,-1,minecraft:stonebrick:0)
Block(-6,6,0,minecraft:stonebrick:0)
Block(-6,6,1,minecraft:stonebrick:0)
Block(-6,6,2,minecraft:stonebrick:0)
Block(-6,6,3,AIR:0)
Block(-6,6,4,minecraft:stonebrick:0)
Block(-6,6,5,AIR:0)
Block(-6,6,6,AIR:0)
Block(-6,6,7,minecraft:concrete:0)
Block(-6,6,8,AIR:0)
Block(-6,6,9,minecraft:concrete:0)
Block(-6,7,-6,minecraft:concrete:0)
Block(-6,7,-5,minecraft:stonebrick:0)
Block(-6,7,-4,minecraft:stonebrick:0)
Block(-6,7,-3,minecraft:stonebrick:0)
Block(-6,7,-2,minecraft:stonebrick:0)
Block(-6,7,-1,minecraft:stonebrick)
Block(-6,7,0,minecraft:stonebrick:0)
Block(-6,7,1,minecraft:stonebrick:0)
Block(-6,7,2,minecraft:stonebrick:0)
Block(-6,7,3,AIR:0)
Block(-6,7,4,AIR:0)
Block(-6,7,5,AIR:0)
Block(-6,7,6,AIR:0)
Block(-6,7,7,minecraft:concrete:0)
Block(-6,7,8,AIR:0)
Block(-6,7,9,minecraft:concrete:0)
Block(-6,8,-6,minecraft:concrete:0)
Block(-6,8,-5,minecraft:stonebrick:0)
Block(-6,8,-4,minecraft:stonebrick:0)
Block(-6,8,-3,minecraft:stonebrick:0)
Block(-6,8,-2,minecraft:stonebrick:0)
Block(-6,8,-1,minecraft:stonebrick:0)
Block(-6,8,0,minecraft:stonebrick:0)
Block(-6,8,1,minecraft:stonebrick:0)
Block(-6,8,2,minecraft:stonebrick:0)
Block(-6,8,3,AIR:0)
Block(-6,8,4,AIR:0)
Block(-6,8,5,AIR:0)
Block(-6,8,6,AIR:0)
Block(-6,8,7,minecraft:concrete:0)
Block(-6,8,8,AIR:0)
Block(-6,8,9,minecraft:concrete:0)
Block(-6,9,-6,minecraft:concrete:0)
Block(-6,9,-5,minecraft:stonebrick:0)
Block(-6,9,-4,minecraft:stonebrick:0)
Block(-6,9,-3,minecraft:stonebrick:0)
Block(-6,9,-2,minecraft:stonebrick:0)
Block(-6,9,-1,minecraft:stonebrick:0)
Block(-6,9,0,minecraft:stonebrick:0)
Block(-6,9,1,minecraft:stonebrick:0)
Block(-6,9,2,minecraft:stonebrick:0)
Block(-6,9,3,AIR:0)
Block(-6,9,4,AIR:0)
Block(-6,9,5,AIR:0)
Block(-6,9,6,AIR:0)
Block(-6,9,7,quark:framed_glass:0)
Block(-6,9,8,AIR:0)
Block(-6,9,9,minecraft:concrete:0)
Block(-6,10,-6,minecraft:concrete:0)
Block(-6,10,-5,AIR:0)
Block(-6,10,-4,AIR:0)
Block(-6,10,-3,AIR:0)
Block(-6,10,-2,AIR:0)
Block(-6,10,-1,AIR:0)
Block(-6,10,0,AIR:0)
Block(-6,10,1,AIR:0)
Block(-6,10,2,minecraft:stonebrick:0)
Block(-6,10,3,AIR:0)
Block(-6,10,4,AIR:0)
Block(-6,10,5,AIR:0)
Block(-6,10,6,WEB:0)
Block(-6,10,7,quark:framed_glass:0)
Block(-6,10,8,minecraft:glowstone)
Block(-6,10,9,minecraft:concrete:0)
Block(-6,11,-6,minecraft:concrete:0)
Block(-6,11,-5,minecraft:concrete:0)
Block(-6,11,-4,minecraft:concrete:0)
Block(-6,11,-3,minecraft:concrete:0)
Block(-6,11,-2,minecraft:concrete:0)
Block(-6,11,-1,minecraft:concrete:0)
Block(-6,11,0,minecraft:concrete:0)
Block(-6,11,1,minecraft:concrete:0)
Block(-6,11,2,minecraft:concrete:0)
Block(-6,11,3,minecraft:concrete:0)
Block(-6,11,4,minecraft:concrete:0)
Block(-6,11,5,minecraft:concrete:0)
Block(-6,11,6,minecraft:concrete:0)
Block(-6,11,7,minecraft:concrete:0)
Block(-6,11,8,minecraft:concrete:0)
Block(-6,11,9,minecraft:concrete:0)
Block(-6,12,-6,minecraft:concrete:0)
Block(-6,12,-5,AIR:0)
Block(-6,12,-4,minecraft:glowstone:0)
Block(-6,12,-3,AIR:0)
Block(-6,12,-2,minecraft:concrete:0)
Block(-6,12,-1,minecraft:concrete:0)
Block(-6,12,0,minecraft:concrete:0)
Block(-6,12,1,minecraft:concrete:0)
Block(-6,12,2,minecraft:concrete:0)
Block(-6,12,3,BED_BLOCK:10,f_bunker_mid_nuclear/3-bed.nbt)
Block(-6,12,4,BED_BLOCK:2,f_bunker_mid_nuclear/4-bed.nbt)
Block(-6,12,5,minecraft:stone:0)
Block(-6,12,6,minecraft:glowstone:0)
Block(-6,12,7,minecraft:stonebrick:0)
Block(-6,12,8,minecraft:stonebrick)
Block(-6,12,9,minecraft:concrete:0)
Block(-6,13,-6,minecraft:concrete:0)
Block(-6,13,-5,AIR:0)
Block(-6,13,-4,AIR:0)
Block(-6,13,-3,AIR:0)
Block(-6,13,-2,minecraft:concrete:0)
Block(-6,13,-1,AIR:0)
Block(-6,13,0,AIR:0)
Block(-6,13,1,AIR:0)
Block(-6,13,2,minecraft:concrete:0)
Block(-6,13,3,AIR:0)
Block(-6,13,4,AIR:0)
Block(-6,13,5,AIR:0)
Block(-6,13,6,AIR:0)
Block(-6,13,7,AIR:0)
Block(-6,13,8,minecraft:stonebrick)
Block(-6,13,9,minecraft:concrete:0)
Block(-6,14,-6,minecraft:concrete:0)
Block(-6,14,-5,AIR:0)
Block(-6,14,-4,AIR:0)
Block(-6,14,-3,AIR:0)
Block(-6,14,-2,minecraft:concrete:0)
Block(-6,14,-1,minecraft:planks:0)
RandomBlock(-6,14,0,minecraft:planks:5,5,minecraft:planks:5,../../../Chests/Loot/manhunt_vagrant_scrap.nbt,100)
RandomBlock(-6,14,1,minecraft:planks:5,5,minecraft:planks:5,../../../Chests/Loot/manhunt_vagrant_scrap.nbt,100)
Block(-6,14,2,minecraft:concrete:0)
Block(-6,14,3,AIR:0)
Block(-6,14,4,AIR:0)
Block(-6,14,5,AIR:0)
Block(-6,14,6,AIR:0)
Block(-6,14,7,AIR:0)
Block(-6,14,8,minecraft:glowstone)
Block(-6,14,9,minecraft:concrete:0)
Block(-6,15,-6,minecraft:concrete:0)
Block(-6,15,-5,minecraft:concrete:0)
Block(-6,15,-4,minecraft:concrete:0)
Block(-6,15,-3,minecraft:concrete:0)
Block(-6,15,-2,minecraft:concrete:0)
Block(-6,15,-1,minecraft:concrete:0)
Block(-6,15,0,minecraft:concrete:0)
Block(-6,15,1,minecraft:concrete:0)
Block(-6,15,2,minecraft:concrete:0)
Block(-6,15,3,minecraft:concrete:0)
Block(-6,15,4,minecraft:concrete:0)
Block(-6,15,5,minecraft:concrete:0)
Block(-6,15,6,minecraft:concrete:0)
Block(-6,15,7,minecraft:concrete:0)
Block(-6,15,8,minecraft:concrete:0)
Block(-6,15,9,minecraft:concrete:0)
Block(-6,16,-6,minecraft:concrete:0)
Block(-6,16,-5,minecraft:planks:5)
Block(-6,16,-4,minecraft:stonebrick:3)
Block(-6,16,-3,minecraft:stonebrick:3)
Block(-6,16,-2,minecraft:planks:8,../../../Chests/Loot/manhunt_vagrant_scrap.nbt)
Block(-6,16,-1,minecraft:stonebrick:3)
Block(-6,16,0,minecraft:stonebrick:3)
Block(-6,16,1,AIR:0)
Block(-6,16,2,AIR:0)
Block(-6,16,3,AIR:0)
Block(-6,16,4,minecraft:iron_door:5)
Block(-6,16,5,AIR:0)
Block(-6,16,6,minecraft:stonebrick:0)
Block(-6,16,7,AIR:0)
Block(-6,16,8,minecraft:bone_block:0)
Block(-6,16,9,minecraft:concrete:0)
Block(-6,17,-6,minecraft:concrete:0)
Block(-6,17,-5,minecraft:stonebrick:12)
Block(-6,17,-4,AIR:0)
Block(-6,17,-3,AIR:0)
Block(-6,17,-2,AIR:0)
Block(-6,17,-1,AIR:0)
Block(-6,17,0,AIR:0)
Block(-6,17,1,AIR:0)
Block(-6,17,2,AIR:0)
Block(-6,17,3,AIR:0)
Block(-6,17,4,minecraft:iron_door:9)
Block(-6,17,5,AIR:0)
Block(-6,17,6,AIR:0)
Block(-6,17,7,AIR:0)
Block(-6,17,8,AIR:0)
Block(-6,17,9,minecraft:concrete:0)
Block(-6,18,-6,minecraft:concrete:0)
Block(-6,18,-5,AIR:0)
Block(-6,18,-4,AIR:0)
Block(-6,18,-3,AIR:0)
Block(-6,18,-2,AIR:0)
Block(-6,18,-1,AIR:0)
Block(-6,18,0,AIR:0)
Block(-6,18,1,AIR:0)
Block(-6,18,2,AIR:0)
Block(-6,18,3,WEB:0)
Block(-6,18,4,minecraft:concrete:0)
Block(-6,18,5,AIR:0)
Block(-6,18,6,AIR:0)
Block(-6,18,7,minecraft:glowstone)
Block(-6,18,8,WEB:0)
Block(-6,18,9,minecraft:concrete:0)
Block(-6,19,-6,minecraft:concrete:0)
Block(-6,19,-5,minecraft:concrete:0)
Block(-6,19,-4,minecraft:concrete:0)
Block(-6,19,-3,minecraft:concrete:0)
Block(-6,19,-2,minecraft:concrete:0)
Block(-6,19,-1,minecraft:concrete:0)
Block(-6,19,0,minecraft:concrete:0)
Block(-6,19,1,minecraft:concrete:0)
Block(-6,19,2,minecraft:concrete:0)
Block(-6,19,3,minecraft:concrete:0)
Block(-6,19,4,minecraft:concrete:0)
Block(-6,19,5,minecraft:concrete:0)
Block(-6,19,6,minecraft:concrete:0)
Block(-6,19,7,minecraft:concrete:0)
Block(-6,19,8,minecraft:concrete:0)
Block(-6,19,9,minecraft:concrete:0)
Block(-6,20,-5,minecraft:concrete:0)
Block(-6,20,-4,minecraft:concrete:0)
Block(-6,20,-3,minecraft:concrete:0)
Block(-6,20,-2,minecraft:concrete:0)
Block(-6,20,-1,minecraft:concrete:0)
Block(-6,20,0,minecraft:concrete:0)
Block(-6,20,1,minecraft:concrete:0)
Block(-6,20,2,minecraft:concrete:0)
Block(-6,20,3,minecraft:concrete:0)
Block(-6,20,4,minecraft:concrete:0)
Block(-6,20,5,minecraft:concrete:0)
Block(-6,20,6,minecraft:glowstone:0)
Block(-6,20,7,minecraft:stonebrick:0)
Block(-6,20,8,minecraft:stone:0)
Block(-6,20,9,minecraft:concrete:0)
Block(-6,21,-5,minecraft:concrete:0)
Block(-6,21,-4,minecraft:concrete:0)
Block(-6,21,-3,minecraft:concrete:0)
Block(-6,21,-2,minecraft:concrete:0)
Block(-6,21,-1,minecraft:concrete:0)
Block(-6,21,0,minecraft:concrete:0)
Block(-6,21,1,minecraft:concrete:0)
Block(-6,21,2,minecraft:concrete:0)
Block(-6,21,3,minecraft:concrete:0)
Block(-6,21,4,minecraft:concrete:0)
Block(-6,21,5,minecraft:concrete:0)
Block(-6,21,6,AIR:0)
Block(-6,21,7,AIR:0)
Block(-6,21,8,AIR:0)
Block(-6,21,9,minecraft:concrete:0)
Block(-6,22,-5,minecraft:concrete:0)
Block(-6,22,-4,minecraft:concrete:0)
Block(-6,22,-3,minecraft:concrete:0)
Block(-6,22,-2,minecraft:concrete:0)
Block(-6,22,-1,minecraft:concrete:0)
Block(-6,22,0,minecraft:concrete:0)
Block(-6,22,1,minecraft:concrete:0)
Block(-6,22,2,minecraft:concrete:0)
Block(-6,22,3,minecraft:concrete:0)
Block(-6,22,4,minecraft:concrete:0)
Block(-6,22,5,minecraft:concrete:0)
Block(-6,22,6,WEB:0)
Block(-6,22,7,AIR:0)
Block(-6,22,8,WEB:0)
Block(-6,22,9,minecraft:concrete:0)
Block(-6,23,-5,minecraft:concrete:0)
Block(-6,23,-4,minecraft:concrete:0)
Block(-6,23,-3,minecraft:concrete:0)
Block(-6,23,-2,minecraft:concrete:0)
Block(-6,23,-1,minecraft:concrete:0)
Block(-6,23,0,minecraft:concrete:0)
Block(-6,23,1,minecraft:concrete:0)
Block(-6,23,2,minecraft:concrete:0)
Block(-6,23,3,minecraft:concrete:0)
Block(-6,23,4,minecraft:concrete:0)
Block(-6,23,5,minecraft:concrete:0)
Block(-6,23,6,minecraft:concrete:0)
Block(-6,23,7,minecraft:concrete:0)
Block(-6,23,8,minecraft:concrete:0)
Block(-6,23,9,minecraft:concrete:0)
Block(-6,24,-5,minecraft:concrete:0)
Block(-6,24,-4,minecraft:concrete:0)
Block(-6,24,-3,minecraft:concrete:0)
Block(-6,24,-2,minecraft:concrete:0)
Block(-6,24,-1,minecraft:concrete:0)
Block(-6,24,0,minecraft:concrete:0)
Block(-6,24,1,minecraft:concrete:0)
Block(-6,24,2,minecraft:concrete:0)
Block(-6,24,3,minecraft:concrete:0)
Block(-6,24,4,minecraft:concrete:0)
Block(-6,24,5,minecraft:concrete:0)
Block(-6,24,6,minecraft:concrete:0)
Block(-6,25,-5,minecraft:concrete:0)
Block(-6,25,-4,minecraft:concrete:0)
Block(-6,25,-3,minecraft:concrete:0)
Block(-6,25,-2,minecraft:concrete:0)
Block(-6,25,-1,minecraft:concrete:0)
Block(-6,25,0,minecraft:concrete:0)
Block(-6,25,1,minecraft:concrete:0)
Block(-6,25,2,minecraft:concrete:0)
Block(-6,25,3,minecraft:concrete:0)
Block(-6,25,4,minecraft:concrete:0)
Block(-6,26,-5,minecraft:concrete:0)
Block(-6,26,-4,minecraft:concrete:0)
Block(-6,26,-3,minecraft:concrete:0)
Block(-6,26,-2,minecraft:concrete:0)
Block(-6,26,-1,minecraft:concrete:0)
Block(-6,26,0,minecraft:concrete:0)
Block(-6,26,1,minecraft:concrete:0)
Block(-6,26,2,minecraft:concrete:0)
Block(-6,26,3,minecraft:concrete:0)
Block(-6,26,4,minecraft:concrete:0)
Block(-6,27,-5,minecraft:concrete:0)
Block(-6,27,-4,minecraft:concrete:0)
Block(-6,27,-3,minecraft:concrete:0)
Block(-6,27,-2,minecraft:concrete:0)
Block(-6,27,-1,minecraft:concrete:0)
Block(-6,27,0,minecraft:concrete:0)
Block(-6,27,1,minecraft:concrete:0)
Block(-6,27,2,minecraft:concrete:0)
Block(-6,28,-6,minecraft:concrete:0)
Block(-6,28,-5,minecraft:concrete:0)
Block(-6,28,-4,minecraft:concrete:0)
Block(-6,28,-3,minecraft:concrete:0)
Block(-6,28,-2,minecraft:concrete:0)
Block(-6,28,-1,minecraft:concrete:0)
Block(-6,28,0,minecraft:concrete:0)
Block(-6,29,-6,minecraft:concrete:0)
Block(-6,29,-5,AIR:0)
Block(-6,29,-4,minecraft:stone:0)
Block(-6,29,-3,minecraft:stonebrick:0)
Block(-6,29,-2,WEB:0)
Block(-6,29,-1,minecraft:concrete:0)
Block(-6,29,0,minecraft:concrete:0)
Block(-6,29,1,minecraft:stone_brick_stairs:3)
Block(-6,30,-6,minecraft:stone_brick_stairs:2)
Block(-6,30,-5,WEB:0)
Block(-6,30,-4,AIR:0)
Block(-6,30,-3,AIR:0)
Block(-6,30,-2,AIR:0)
Block(-6,30,-1,minecraft:concrete:0)
Block(-6,30,0,minecraft:concrete:0)
Block(-6,30,1,minecraft:concrete:0)
Block(-6,31,-6,minecraft:concrete:0)
Block(-6,31,-5,minecraft:concrete:0)
Block(-6,31,-4,minecraft:stone_brick_stairs:0)
Block(-6,31,-3,minecraft:stone_brick_stairs:0)
Block(-6,31,-2,minecraft:stone_brick_stairs:2)
Block(-6,31,-1,quark:sturdy_stone:0)
Block(-6,31,0,quark:sturdy_stone:0)
Block(-6,31,1,minecraft:stone_brick_stairs:3)
Block(-6,32,-1,IRON_TRAPDOOR:1)
Block(-6,32,0,IRON_TRAPDOOR:1)
Block(-5,4,-6,minecraft:concrete:0)
Block(-5,4,-5,minecraft:concrete:0)
Block(-5,4,-4,minecraft:concrete:0)
Block(-5,4,-3,minecraft:concrete:0)
Block(-5,4,-2,minecraft:concrete:0)
Block(-5,4,-1,minecraft:concrete:0)
Block(-5,4,0,minecraft:concrete:0)
Block(-5,4,1,minecraft:concrete:0)
Block(-5,4,2,minecraft:concrete:0)
Block(-5,5,-6,minecraft:concrete:0)
Block(-5,5,-5,minecraft:stonebrick:0)
Block(-5,5,-4,minecraft:stonebrick:0)
Block(-5,5,-3,minecraft:stonebrick:0)
Block(-5,5,-2,minecraft:stonebrick:0)
Block(-5,5,-1,minecraft:stonebrick:0)
Block(-5,5,0,minecraft:stonebrick:0)
Block(-5,5,1,minecraft:stonebrick:0)
Block(-5,5,2,minecraft:stonebrick:0)
Block(-5,5,3,minecraft:concrete:0)
Block(-5,5,4,minecraft:concrete:0)
Block(-5,5,5,minecraft:concrete:0)
Block(-5,5,6,minecraft:concrete:0)
Block(-5,5,7,minecraft:concrete:0)
Block(-5,5,8,minecraft:concrete:0)
Block(-5,5,9,minecraft:concrete:0)
Block(-5,6,-6,minecraft:concrete:0)
Block(-5,6,-5,minecraft:stonebrick:0)
Block(-5,6,-4,minecraft:iron_block:1)
Block(-5,6,-3,minecraft:stone:0)
Block(-5,6,-2,minecraft:stonebrick:0)
Block(-5,6,-1,AIR:0)
Block(-5,6,0,AIR:0)
Block(-5,6,1,AIR:0)
Block(-5,6,2,minecraft:iron_door:3)
Block(-5,6,3,AIR:0)
Block(-5,6,4,AIR:0)
Block(-5,6,5,AIR:0)
Block(-5,6,6,AIR:0)
Block(-5,6,7,minecraft:iron_door:1)
Block(-5,6,8,AIR:0)
Block(-5,6,9,minecraft:concrete:0)
Block(-5,7,-6,minecraft:concrete:0)
Block(-5,7,-5,minecraft:stonebrick:0)
Block(-5,7,-4,AIR:0)
Block(-5,7,-3,AIR:0)
Block(-5,7,-2,AIR:0)
Block(-5,7,-1,AIR:0)
Block(-5,7,0,AIR:0)
Block(-5,7,1,AIR:0)
Block(-5,7,2,minecraft:iron_door:8)
Block(-5,7,3,AIR:0)
Block(-5,7,4,AIR:0)
Block(-5,7,5,AIR:0)
Block(-5,7,6,AIR:0)
Block(-5,7,7,minecraft:iron_door:8)
Block(-5,7,8,AIR:0)
Block(-5,7,9,minecraft:concrete:0)
Block(-5,8,-6,minecraft:concrete:0)
Block(-5,8,-5,minecraft:stonebrick:0)
Block(-5,8,-4,AIR:0)
Block(-5,8,-3,AIR:0)
Block(-5,8,-2,AIR:0)
Block(-5,8,-1,AIR:0)
Block(-5,8,0,AIR:0)
Block(-5,8,1,quark:iron_button:4)
Block(-5,8,2,minecraft:stonebrick:0)
Block(-5,8,3,quark:iron_button:3)
Block(-5,8,4,AIR:0)
Block(-5,8,5,AIR:0)
Block(-5,8,6,AIR:0)
Block(-5,8,7,minecraft:concrete:0)
Block(-5,8,8,AIR:0)
Block(-5,8,9,minecraft:concrete:0)
Block(-5,9,-6,minecraft:concrete:0)
Block(-5,9,-5,minecraft:stonebrick:0)
Block(-5,9,-4,minecraft:stonebrick:1)
Block(-5,9,-3,minecraft:stonebrick:1)
Block(-5,9,-2,minecraft:stonebrick:1)
Block(-5,9,-1,minecraft:stonebrick:1)
Block(-5,9,0,minecraft:stonebrick:1)
Block(-5,9,1,minecraft:stonebrick:1)
Block(-5,9,2,minecraft:stonebrick:0)
Block(-5,9,3,WALL_SIGN:3,f_bunker_mid_nuclear/17-sign.nbt)
Block(-5,9,4,AIR:0)
Block(-5,9,5,AIR:0)
Block(-5,9,6,AIR:0)
Block(-5,9,7,quark:framed_glass:0)
Block(-5,9,8,AIR:0)
Block(-5,9,9,minecraft:concrete:0)
Block(-5,10,-6,minecraft:concrete:0)
Block(-5,10,-5,minecraft:stonebrick:0)
Block(-5,10,-4,minecraft:stonebrick:0)
Block(-5,10,-3,minecraft:stonebrick:0)
Block(-5,10,-2,minecraft:stonebrick:0)
Block(-5,10,-1,minecraft:stonebrick:0)
Block(-5,10,0,minecraft:stonebrick:0)
Block(-5,10,1,minecraft:stonebrick:0)
Block(-5,10,2,minecraft:stonebrick:0)
Block(-5,10,3,AIR:0)
Block(-5,10,4,AIR:0)
Block(-5,10,5,AIR:0)
Block(-5,10,6,AIR:0)
Block(-5,10,7,quark:framed_glass:0)
Block(-5,10,8,AIR:0)
Block(-5,10,9,minecraft:concrete:0)
Block(-5,11,-6,minecraft:concrete:0)
Block(-5,11,-5,minecraft:concrete:0)
Block(-5,11,-4,minecraft:concrete:0)
Block(-5,11,-3,minecraft:concrete:0)
Block(-5,11,-2,minecraft:concrete:0)
Block(-5,11,-1,minecraft:concrete:0)
Block(-5,11,0,minecraft:concrete:0)
Block(-5,11,1,minecraft:concrete:0)
Block(-5,11,2,minecraft:concrete:0)
Block(-5,11,3,minecraft:concrete:0)
Block(-5,11,4,minecraft:concrete:0)
Block(-5,11,5,minecraft:concrete:0)
Block(-5,11,6,minecraft:concrete:0)
Block(-5,11,7,minecraft:concrete:0)
Block(-5,11,8,minecraft:concrete:0)
Block(-5,11,9,minecraft:concrete:0)
Block(-5,12,-6,minecraft:concrete:0)
Block(-5,12,-5,minecraft:stonebrick:14)
Block(-5,12,-4,minecraft:stonebrick:14)
Block(-5,12,-3,minecraft:stonebrick:14)
Block(-5,12,-2,minecraft:concrete:0)
Block(-5,12,-1,minecraft:concrete:0)
Block(-5,12,0,minecraft:concrete:0)
Block(-5,12,1,minecraft:concrete:0)
Block(-5,12,2,minecraft:concrete:0)
Block(-5,12,3,quark:paper_wall_big:0)
Block(-5,12,4,quark:paper_wall_big:0)
Block(-5,12,5,quark:paper_wall_big:0)
Block(-5,12,6,minecraft:glowstone:0)
Block(-5,12,7,minecraft:glowstone:0)
Block(-5,12,8,minecraft:planks,../../../Chests/Loot/manhunt_vagrant_scrap.nbt)
Block(-5,12,9,minecraft:concrete:0)
Block(-5,13,-6,minecraft:concrete:0)
Block(-5,13,-5,minecraft:glowstone:0)
Block(-5,13,-4,AIR:0)
Block(-5,13,-3,minecraft:grass:0)
Block(-5,13,-2,minecraft:iron_door:3)
Block(-5,13,-1,AIR:0)
RandomBlock(-5,13,0,minecraft:planks:5,5,minecraft:planks:5,../../../Chests/Loot/manhunt_vagrant_scrap.nbt,100)
RandomBlock(-5,13,1,minecraft:planks:5,5,minecraft:planks:5,../../../Chests/Loot/manhunt_vagrant_scrap.nbt,100)
Block(-5,13,2,minecraft:concrete:0)
Block(-5,13,3,quark:paper_wall_big:0)
Block(-5,13,4,quark:paper_wall_big:0)
Block(-5,13,5,quark:paper_wall_big:0)
Block(-5,13,6,AIR:0)
Block(-5,13,7,AIR:0)
Block(-5,13,8,minecraft:bookshelf:0)
Block(-5,13,9,minecraft:concrete:0)
Block(-5,14,-6,minecraft:concrete:0)
Block(-5,14,-5,AIR:0)
Block(-5,14,-4,AIR:0)
Block(-5,14,-3,AIR:0)
Block(-5,14,-2,minecraft:iron_door:8)
Block(-5,14,-1,AIR:0)
Block(-5,14,0,minecraft:stonebrick:5)
RandomBlock(-5,14,1,minecraft:planks:5,5,minecraft:planks:5,../../../Chests/Loot/manhunt_vagrant_scrap.nbt,100)
Block(-5,14,2,minecraft:concrete:0)
Block(-5,14,3,AIR:0)
Block(-5,14,4,AIR:0)
Block(-5,14,5,AIR:0)
Block(-5,14,6,AIR:0)
Block(-5,14,7,AIR:0)
Block(-5,14,8,minecraft:planks,../../../Chests/Loot/manhunt_vagrant_scrap.nbt)
Block(-5,14,9,minecraft:concrete:0)
Block(-5,15,-6,minecraft:concrete:0)
Block(-5,15,-5,minecraft:concrete:0)
Block(-5,15,-4,minecraft:concrete:0)
Block(-5,15,-3,minecraft:concrete:0)
Block(-5,15,-2,minecraft:concrete:0)
Block(-5,15,-1,minecraft:concrete:0)
Block(-5,15,0,minecraft:concrete:0)
Block(-5,15,1,minecraft:concrete:0)
Block(-5,15,2,minecraft:concrete:0)
Block(-5,15,3,minecraft:concrete:0)
Block(-5,15,4,minecraft:concrete:0)
Block(-5,15,5,minecraft:concrete:0)
Block(-5,15,6,minecraft:concrete:0)
Block(-5,15,7,minecraft:concrete:0)
Block(-5,15,8,minecraft:concrete:0)
Block(-5,15,9,minecraft:concrete:0)
Block(-5,16,-6,minecraft:concrete:0)
Block(-5,16,-5,minecraft:planks:5)
Block(-5,16,-4,minecraft:stonebrick:0)
Block(-5,16,-3,AIR:0)
Block(-5,16,-2,minecraft:stone:0)
Block(-5,16,-1,AIR:0)
Block(-5,16,0,AIR:0)
Block(-5,16,1,minecraft:stone:0)
Block(-5,16,2,minecraft:stone:0)
Block(-5,16,3,minecraft:stone:0)
Block(-5,16,4,minecraft:concrete:0)
Block(-5,16,5,minecraft:oak_stairs:5)
Block(-5,16,6,AIR:0)
Block(-5,16,7,AIR:0)
Block(-5,16,8,minecraft:oak_stairs:5)
Block(-5,16,9,minecraft:concrete:0)
Block(-5,17,-6,minecraft:concrete:0)
Block(-5,17,-5,AIR:0)
Block(-5,17,-4,quark:grate:0)
Block(-5,17,-3,AIR:0)
Block(-5,17,-2,AIR:0)
Block(-5,17,-1,AIR:0)
Block(-5,17,0,AIR:0)
Block(-5,17,1,AIR:0)
Block(-5,17,2,AIR:0)
Block(-5,17,3,AIR:0)
Block(-5,17,4,minecraft:concrete:0)
Block(-5,17,5,AIR:0)
Block(-5,17,6,AIR:0)
Block(-5,17,7,AIR:0)
Block(-5,17,8,AIR:0)
Block(-5,17,9,minecraft:concrete:0)
Block(-5,18,-6,minecraft:concrete:0)
Block(-5,18,-5,AIR:0)
Block(-5,18,-4,DISPENSER:0,f_bunker_mid_nuclear/28-dispenser.nbt)
Block(-5,18,-3,STEP:8)
Block(-5,18,-2,STEP:8)
Block(-5,18,-1,STEP:8)
Block(-5,18,0,STEP:8)
Block(-5,18,1,STEP:8)
Block(-5,18,2,STEP:8)
Block(-5,18,3,STEP:8)
Block(-5,18,4,minecraft:concrete:0)
Block(-5,18,5,STEP:8)
Block(-5,18,6,STEP:8)
Block(-5,18,7,AIR:0)
Block(-5,18,8,AIR:0)
Block(-5,18,9,minecraft:concrete:0)
Block(-5,19,-6,minecraft:concrete:0)
Block(-5,19,-5,minecraft:concrete:0)
Block(-5,19,-4,minecraft:concrete:0)
Block(-5,19,-3,minecraft:concrete:0)
Block(-5,19,-2,minecraft:concrete:0)
Block(-5,19,-1,minecraft:concrete:0)
Block(-5,19,0,minecraft:concrete:0)
Block(-5,19,1,minecraft:concrete:0)
Block(-5,19,2,minecraft:concrete:0)
Block(-5,19,3,minecraft:concrete:0)
Block(-5,19,4,minecraft:concrete:0)
Block(-5,19,5,minecraft:concrete:0)
Block(-5,19,6,minecraft:concrete:0)
Block(-5,19,7,minecraft:concrete:0)
Block(-5,19,8,minecraft:concrete:0)
Block(-5,19,9,minecraft:concrete:0)
Block(-5,20,-5,minecraft:concrete:0)
Block(-5,20,-4,minecraft:concrete:0)
Block(-5,20,-3,minecraft:concrete:0)
Block(-5,20,-2,minecraft:concrete:0)
Block(-5,20,-1,minecraft:concrete:0)
Block(-5,20,0,minecraft:concrete:0)
Block(-5,20,1,minecraft:concrete:0)
Block(-5,20,2,minecraft:concrete:0)
Block(-5,20,3,minecraft:concrete:0)
Block(-5,20,4,minecraft:stone_brick_stairs:3)
Block(-5,20,5,AIR:0)
Block(-5,20,6,minecraft:glowstone:0)
Block(-5,20,7,minecraft:glowstone:0)
Block(-5,20,8,minecraft:stonebrick:0)
Block(-5,20,9,minecraft:concrete:0)
Block(-5,21,-5,minecraft:concrete:0)
Block(-5,21,-4,minecraft:concrete:0)
Block(-5,21,-3,minecraft:concrete:0)
Block(-5,21,-2,minecraft:concrete:0)
Block(-5,21,-1,minecraft:concrete:0)
Block(-5,21,0,minecraft:concrete:0)
Block(-5,21,1,minecraft:concrete:0)
Block(-5,21,2,minecraft:concrete:0)
Block(-5,21,3,minecraft:stone_brick_stairs:3)
Block(-5,21,4,AIR:0)
Block(-5,21,5,AIR:0)
Block(-5,21,6,AIR:0)
Block(-5,21,7,AIR:0)
Block(-5,21,8,AIR:0)
Block(-5,21,9,minecraft:concrete:0)
Block(-5,22,-5,minecraft:concrete:0)
Block(-5,22,-4,minecraft:concrete:0)
Block(-5,22,-3,minecraft:concrete:0)
Block(-5,22,-2,minecraft:concrete:0)
Block(-5,22,-1,minecraft:concrete:0)
Block(-5,22,0,minecraft:concrete:0)
Block(-5,22,1,minecraft:concrete:0)
Block(-5,22,2,minecraft:stone_brick_stairs:3)
Block(-5,22,3,AIR:0)
Block(-5,22,4,AIR:0)
Block(-5,22,5,AIR:0)
Block(-5,22,6,AIR:0)
Block(-5,22,7,AIR:0)
Block(-5,22,8,AIR:0)
Block(-5,22,9,minecraft:concrete:0)
Block(-5,23,-5,minecraft:concrete:0)
Block(-5,23,-4,minecraft:concrete:0)
Block(-5,23,-3,minecraft:concrete:0)
Block(-5,23,-2,minecraft:concrete:0)
Block(-5,23,-1,minecraft:concrete:0)
Block(-5,23,0,minecraft:concrete:0)
Block(-5,23,1,minecraft:stone_brick_stairs:3)
Block(-5,23,2,AIR:0)
Block(-5,23,3,AIR:0)
Block(-5,23,4,AIR:0)
Block(-5,23,5,minecraft:stone_brick_stairs:6)
Block(-5,23,6,minecraft:concrete:0)
Block(-5,23,7,minecraft:concrete:0)
Block(-5,23,8,minecraft:concrete:0)
Block(-5,23,9,minecraft:concrete:0)
Block(-5,24,-5,minecraft:concrete:0)
Block(-5,24,-4,minecraft:concrete:0)
Block(-5,24,-3,minecraft:concrete:0)
Block(-5,24,-2,minecraft:concrete:0)
Block(-5,24,-1,minecraft:concrete:0)
Block(-5,24,0,minecraft:stone_brick_stairs:3)
Block(-5,24,1,AIR:0)
Block(-5,24,2,AIR:0)
Block(-5,24,3,AIR:0)
Block(-5,24,4,minecraft:stone_brick_stairs:6)
Block(-5,24,5,minecraft:concrete:0)
Block(-5,24,6,minecraft:concrete:0)
Block(-5,25,-5,minecraft:concrete:0)
Block(-5,25,-4,minecraft:concrete:0)
Block(-5,25,-3,minecraft:concrete:0)
Block(-5,25,-2,minecraft:concrete:0)
Block(-5,25,-1,minecraft:stone_brick_stairs:3)
Block(-5,25,0,AIR:0)
Block(-5,25,1,AIR:0)
Block(-5,25,2,AIR:0)
Block(-5,25,3,minecraft:stone_brick_stairs:6)
Block(-5,25,4,minecraft:concrete:0)
Block(-5,26,-5,minecraft:concrete:0)
Block(-5,26,-4,minecraft:concrete:0)
Block(-5,26,-3,minecraft:concrete:0)
Block(-5,26,-2,minecraft:stone_brick_stairs:3)
Block(-5,26,-1,AIR:0)
Block(-5,26,0,AIR:0)
Block(-5,26,1,AIR:0)
Block(-5,26,2,minecraft:stone_brick_stairs:6)
Block(-5,26,3,minecraft:concrete:0)
Block(-5,26,4,minecraft:concrete:0)
Block(-5,27,-5,minecraft:concrete:0)
Block(-5,27,-4,minecraft:concrete:0)
Block(-5,27,-3,minecraft:stone_brick_stairs:3)
Block(-5,27,-2,AIR:0)
Block(-5,27,-1,AIR:0)
Block(-5,27,0,AIR:0)
Block(-5,27,1,minecraft:stone_brick_stairs:6)
Block(-5,27,2,minecraft:concrete:0)
Block(-5,28,-6,minecraft:concrete:0)
Block(-5,28,-5,minecraft:concrete:0)
Block(-5,28,-4,minecraft:stone_brick_stairs:3)
Block(-5,28,-3,AIR:0)
Block(-5,28,-2,AIR:0)
Block(-5,28,-1,AIR:0)
Block(-5,28,0,minecraft:stone_brick_stairs:6)
Block(-5,29,-6,minecraft:concrete:0)
Block(-5,29,-5,AIR:0)
Block(-5,29,-4,AIR:0)
Block(-5,29,-3,AIR:0)
Block(-5,29,-2,AIR:0)
Block(-5,29,-1,minecraft:stone_brick_stairs:6)
Block(-5,29,0,minecraft:concrete:0)
Block(-5,29,1,minecraft:concrete:0)
Block(-5,30,-6,minecraft:concrete:0)
Block(-5,30,-5,AIR:0)
Block(-5,30,-4,AIR:0)
Block(-5,30,-3,AIR:0)
Block(-5,30,-2,AIR:0)
Block(-5,30,-1,minecraft:concrete:0)
Block(-5,30,0,minecraft:concrete:0)
Block(-5,30,1,minecraft:concrete:0)
Block(-5,31,-6,minecraft:concrete:0)
Block(-5,31,-5,minecraft:stone_brick_stairs:2)
Block(-5,31,-4,minecraft:concrete:0)
Block(-5,31,-3,minecraft:concrete:1)
Block(-5,31,-2,minecraft:concrete:0)
Block(-5,31,-1,quark:sturdy_stone:0)
Block(-5,31,0,quark:sturdy_stone:0)
Block(-5,31,1,minecraft:stone_brick_stairs:3)
Block(-5,32,-3,minecraft:concrete:0)
Block(-5,32,-2,minecraft:concrete:0)
Block(-5,32,-1,IRON_TRAPDOOR:1)
Block(-5,32,0,IRON_TRAPDOOR:2)
Block(-4,4,-6,minecraft:concrete:0)
Block(-4,4,-5,minecraft:concrete:0)
Block(-4,4,-4,minecraft:concrete:0)
Block(-4,4,-3,minecraft:concrete:0)
Block(-4,4,-2,minecraft:concrete:0)
Block(-4,4,-1,minecraft:concrete:0)
Block(-4,4,0,minecraft:concrete:0)
Block(-4,4,1,minecraft:concrete:0)
Block(-4,4,2,minecraft:concrete:0)
Block(-4,5,-6,minecraft:concrete:0)
Block(-4,5,-5,minecraft:stonebrick:0)
Block(-4,5,-4,minecraft:stonebrick:0)
Block(-4,5,-3,minecraft:stonebrick:0)
Block(-4,5,-2,minecraft:stonebrick:0)
Block(-4,5,-1,minecraft:stonebrick:0)
Block(-4,5,0,minecraft:stonebrick:0)
Block(-4,5,1,minecraft:stonebrick:0)
Block(-4,5,2,minecraft:concrete:0)
Block(-4,5,3,minecraft:concrete:0)
Block(-4,5,4,minecraft:concrete:0)
Block(-4,5,5,minecraft:concrete:0)
Block(-4,5,6,minecraft:concrete:0)
Block(-4,5,7,minecraft:concrete:0)
Block(-4,5,8,minecraft:concrete:0)
Block(-4,5,9,minecraft:concrete:0)
Block(-4,6,-6,minecraft:concrete:0)
Block(-4,6,-5,minecraft:stonebrick:0)
Block(-4,6,-4,minecraft:iron_block:1)
Block(-4,6,-3,AIR:0)
Block(-4,6,-2,AIR:0)
Block(-4,6,-1,AIR:0)
Block(-4,6,0,minecraft:stonebrick:0)
Block(-4,6,1,AIR:0)
Block(-4,6,2,minecraft:stonebrick:0)
Block(-4,6,3,AIR:0)
Block(-4,6,4,minecraft:stone:0)
Block(-4,6,5,AIR:0)
Block(-4,6,6,minecraft:stonebrick:0)
Block(-4,6,7,minecraft:concrete:0)
Block(-4,6,8,minecraft:stone_brick_stairs:0)
Block(-4,6,9,minecraft:concrete:0)
Block(-4,7,-6,minecraft:concrete:0)
Block(-4,7,-5,minecraft:stonebrick:0)
Block(-4,7,-4,minecraft:stonebrick)
Block(-4,7,-3,AIR:0)
Block(-4,7,-2,AIR:0)
Block(-4,7,-1,AIR:0)
Block(-4,7,0,AIR:0)
Block(-4,7,1,minecraft:stonebrick)
Block(-4,7,2,minecraft:stonebrick:0)
Block(-4,7,3,AIR:0)
Block(-4,7,4,AIR:0)
Block(-4,7,5,AIR:0)
Block(-4,7,6,AIR:0)
Block(-4,7,7,minecraft:concrete:0)
Block(-4,7,8,AIR:0)
Block(-4,7,9,minecraft:concrete:0)
Block(-4,8,-6,minecraft:concrete:0)
Block(-4,8,-5,minecraft:stonebrick:0)
Block(-4,8,-4,AIR:0)
Block(-4,8,-3,AIR:0)
Block(-4,8,-2,AIR:0)
Block(-4,8,-1,AIR:0)
Block(-4,8,0,AIR:0)
Block(-4,8,1,AIR:0)
Block(-4,8,2,minecraft:stonebrick:0)
Block(-4,8,3,AIR:0)
Block(-4,8,4,AIR:0)
Block(-4,8,5,AIR:0)
Block(-4,8,6,AIR:0)
Block(-4,8,7,minecraft:concrete:0)
Block(-4,8,8,AIR:0)
Block(-4,8,9,minecraft:concrete:0)
Block(-4,9,-6,minecraft:concrete:0)
Block(-4,9,-5,minecraft:stonebrick:0)
Block(-4,9,-4,AIR:0)
Block(-4,9,-3,AIR:0)
Block(-4,9,-2,AIR:0)
Block(-4,9,-1,AIR:0)
Block(-4,9,0,AIR:0)
Block(-4,9,1,minecraft:stonebrick:1)
Block(-4,9,2,minecraft:stonebrick:0)
Block(-4,9,3,AIR:0)
Block(-4,9,4,AIR:0)
Block(-4,9,5,AIR:0)
Block(-4,9,6,AIR:0)
Block(-4,9,7,quark:framed_glass:0)
Block(-4,9,8,AIR:0)
Block(-4,9,9,minecraft:concrete:0)
Block(-4,10,-6,minecraft:concrete:0)
Block(-4,10,-5,minecraft:stonebrick:0)
Block(-4,10,-4,minecraft:stonebrick:0)
Block(-4,10,-3,minecraft:stonebrick:0)
Block(-4,10,-2,minecraft:stonebrick:0)
Block(-4,10,-1,minecraft:stonebrick:0)
Block(-4,10,0,minecraft:stonebrick:0)
Block(-4,10,1,minecraft:stonebrick:0)
Block(-4,10,2,minecraft:stonebrick:0)
Block(-4,10,3,WEB:0)
Block(-4,10,4,AIR:0)
Block(-4,10,5,AIR:0)
Block(-4,10,6,AIR:0)
Block(-4,10,7,quark:framed_glass:0)
Block(-4,10,8,AIR:0)
Block(-4,10,9,minecraft:concrete:0)
Block(-4,11,-6,minecraft:concrete:0)
Block(-4,11,-5,minecraft:concrete:0)
Block(-4,11,-4,minecraft:concrete:0)
Block(-4,11,-3,minecraft:concrete:0)
Block(-4,11,-2,minecraft:concrete:0)
Block(-4,11,-1,minecraft:concrete:0)
Block(-4,11,0,minecraft:concrete:0)
Block(-4,11,1,minecraft:concrete:0)
Block(-4,11,2,minecraft:concrete:0)
Block(-4,11,3,minecraft:concrete:0)
Block(-4,11,4,minecraft:concrete:0)
Block(-4,11,5,minecraft:concrete:0)
Block(-4,11,6,minecraft:concrete:0)
Block(-4,11,7,minecraft:concrete:0)
Block(-4,11,8,minecraft:concrete:0)
Block(-4,11,9,minecraft:concrete:0)
Block(-4,12,-6,minecraft:concrete:0)
Block(-4,12,-5,minecraft:dirt:0)
Block(-4,12,-4,minecraft:stonebrick:14)
Block(-4,12,-3,minecraft:stonebrick:14)
Block(-4,12,-2,minecraft:concrete:0)
Block(-4,12,-1,minecraft:concrete:0)
Block(-4,12,0,minecraft:concrete:0)
Block(-4,12,1,minecraft:concrete:0)
Block(-4,12,2,minecraft:concrete:0)
Block(-4,12,3,BED_BLOCK:10,f_bunker_mid_nuclear/31-bed.nbt)
Block(-4,12,4,BED_BLOCK:2,f_bunker_mid_nuclear/32-bed.nbt)
Block(-4,12,5,minecraft:stonebrick:0)
Block(-4,12,6,minecraft:glowstone:0)
Block(-4,12,7,minecraft:stonebrick:0)
Block(-4,12,8,CAULDRON:0)
Block(-4,12,9,minecraft:concrete:0)
Block(-4,13,-6,minecraft:concrete:0)
Block(-4,13,-5,WEB:0)
Block(-4,13,-4,minecraft:glowstone:0)
Block(-4,13,-3,minecraft:glowstone:0)
Block(-4,13,-2,minecraft:concrete:0)
Block(-4,13,-1,minecraft:stone:0)
RandomBlock(-4,13,0,minecraft:planks:5,5,minecraft:planks:5,../../../Chests/Loot/manhunt_vagrant_scrap.nbt,100)
RandomBlock(-4,13,1,minecraft:planks:5,5,minecraft:planks:5,../../../Chests/Loot/manhunt_vagrant_scrap.nbt,100)
Block(-4,13,2,minecraft:concrete:0)
Block(-4,13,3,AIR:0)
Block(-4,13,4,AIR:0)
Block(-4,13,5,AIR:0)
Block(-4,13,6,AIR:0)
Block(-4,13,7,AIR:0)
Block(-4,13,8,minecraft:bookshelf:0)
Block(-4,13,9,minecraft:concrete:0)
Block(-4,14,-6,minecraft:concrete:0)
Block(-4,14,-5,AIR:0)
Block(-4,14,-4,AIR:0)
Block(-4,14,-3,AIR:0)
Block(-4,14,-2,minecraft:concrete:0)
Block(-4,14,-1,AIR:0)
Block(-4,14,0,minecraft:stonebrick)
Block(-4,14,1,minecraft:planks:0)
Block(-4,14,2,minecraft:concrete:0)
Block(-4,14,3,AIR:0)
Block(-4,14,4,AIR:0)
Block(-4,14,5,AIR:0)
Block(-4,14,6,AIR:0)
Block(-4,14,7,AIR:0)
Block(-4,14,8,minecraft:planks:3,../../../Chests/Loot/manhunt_vagrant_scrap.nbt)
Block(-4,14,9,minecraft:concrete:0)
Block(-4,15,-6,minecraft:concrete:0)
Block(-4,15,-5,minecraft:concrete:0)
Block(-4,15,-4,minecraft:concrete:0)
Block(-4,15,-3,minecraft:concrete:0)
Block(-4,15,-2,minecraft:concrete:0)
Block(-4,15,-1,minecraft:concrete:0)
Block(-4,15,0,minecraft:concrete:0)
Block(-4,15,1,minecraft:concrete:0)
Block(-4,15,2,minecraft:concrete:0)
Block(-4,15,3,minecraft:concrete:0)
Block(-4,15,4,minecraft:concrete:0)
Block(-4,15,5,minecraft:concrete:0)
Block(-4,15,6,minecraft:concrete:0)
Block(-4,15,7,minecraft:concrete:0)
Block(-4,15,8,minecraft:concrete:0)
Block(-4,15,9,minecraft:concrete:0)
Block(-4,16,-6,minecraft:concrete:0)
Block(-4,16,-5,minecraft:planks:5)
Block(-4,16,-4,AIR:0)
Block(-4,16,-3,minecraft:planks:4)
Block(-4,16,-2,AIR:0)
Block(-4,16,-1,minecraft:stonebrick:3)
Block(-4,16,0,minecraft:stonebrick:3)
Block(-4,16,1,AIR:0)
Block(-4,16,2,AIR:0)
Block(-4,16,3,AIR:0)
Block(-4,16,4,minecraft:concrete:0)
Block(-4,16,5,minecraft:planks:1)
Block(-4,16,6,minecraft:stone:0)
Block(-4,16,7,minecraft:planks:5)
Block(-4,16,8,minecraft:planks:5)
Block(-4,16,9,minecraft:concrete:0)
Block(-4,17,-6,minecraft:concrete:0)
Block(-4,17,-5,minecraft:glowstone)
Block(-4,17,-4,AIR:0)
Block(-4,17,-3,minecraft:planks:4)
Block(-4,17,-2,AIR:0)
Block(-4,17,-1,AIR:0)
Block(-4,17,0,AIR:0)
Block(-4,17,1,AIR:0)
Block(-4,17,2,AIR:0)
Block(-4,17,3,AIR:0)
Block(-4,17,4,minecraft:concrete:0)
Block(-4,17,5,minecraft:stonebrick:3)
Block(-4,17,6,AIR:0)
Block(-4,17,7,minecraft:stonebrick)
Block(-4,17,8,AIR:0)
Block(-4,17,9,minecraft:concrete:0)
Block(-4,18,-6,minecraft:concrete:0)
Block(-4,18,-5,WEB:0)
Block(-4,18,-4,AIR:0)
Block(-4,18,-3,AIR:0)
Block(-4,18,-2,AIR:0)
Block(-4,18,-1,AIR:0)
Block(-4,18,0,AIR:0)
Block(-4,18,1,AIR:0)
Block(-4,18,2,AIR:0)
Block(-4,18,3,AIR:0)
Block(-4,18,4,minecraft:concrete:0)
Block(-4,18,5,minecraft:stonebrick)
Block(-4,18,6,STEP:8)
Block(-4,18,7,AIR:0)
Block(-4,18,8,minecraft:stonebrick)
Block(-4,18,9,minecraft:concrete:0)
Block(-4,19,-6,minecraft:concrete:0)
Block(-4,19,-5,minecraft:concrete:0)
Block(-4,19,-4,minecraft:concrete:0)
Block(-4,19,-3,minecraft:concrete:0)
Block(-4,19,-2,minecraft:concrete:0)
Block(-4,19,-1,minecraft:concrete:0)
Block(-4,19,0,minecraft:concrete:0)
Block(-4,19,1,minecraft:concrete:0)
Block(-4,19,2,minecraft:concrete:0)
Block(-4,19,3,minecraft:concrete:0)
Block(-4,19,4,minecraft:concrete:0)
Block(-4,19,5,minecraft:concrete:0)
Block(-4,19,6,minecraft:concrete:0)
Block(-4,19,7,minecraft:concrete:0)
Block(-4,19,8,minecraft:concrete:0)
Block(-4,19,9,minecraft:concrete:0)
Block(-4,20,-6,minecraft:concrete:0)
Block(-4,20,-5,minecraft:concrete:0)
Block(-4,20,-4,minecraft:concrete:0)
Block(-4,20,-3,minecraft:concrete:0)
Block(-4,20,-2,minecraft:concrete:0)
Block(-4,20,-1,minecraft:concrete:0)
Block(-4,20,0,minecraft:concrete:0)
Block(-4,20,1,minecraft:concrete:0)
Block(-4,20,2,minecraft:concrete:0)
Block(-4,20,3,minecraft:concrete:0)
Block(-4,20,4,minecraft:concrete:0)
Block(-4,20,5,minecraft:concrete:0)
Block(-4,20,6,minecraft:glowstone:0)
Block(-4,20,7,minecraft:glowstone:0)
Block(-4,20,8,minecraft:stone:0)
Block(-4,20,9,minecraft:concrete:0)
Block(-4,21,-6,minecraft:concrete:0)
Block(-4,21,-5,minecraft:concrete:0)
Block(-4,21,-4,minecraft:concrete:0)
Block(-4,21,-3,minecraft:concrete:0)
Block(-4,21,-2,minecraft:concrete:0)
Block(-4,21,-1,minecraft:concrete:0)
Block(-4,21,0,minecraft:concrete:0)
Block(-4,21,1,minecraft:concrete:0)
Block(-4,21,2,minecraft:concrete:0)
Block(-4,21,3,minecraft:concrete:0)
Block(-4,21,4,minecraft:concrete:0)
Block(-4,21,5,minecraft:concrete:0)
Block(-4,21,6,AIR:0)
Block(-4,21,7,AIR:0)
Block(-4,21,8,quark:iron_button:2)
Block(-4,21,9,minecraft:concrete:0)
Block(-4,22,-6,minecraft:concrete:0)
Block(-4,22,-5,minecraft:concrete:0)
Block(-4,22,-4,minecraft:concrete:0)
Block(-4,22,-3,minecraft:concrete:0)
Block(-4,22,-2,minecraft:concrete:0)
Block(-4,22,-1,minecraft:concrete:0)
Block(-4,22,0,minecraft:concrete:0)
Block(-4,22,1,minecraft:concrete:0)
Block(-4,22,2,minecraft:concrete:0)
Block(-4,22,3,minecraft:concrete:0)
Block(-4,22,4,minecraft:concrete:0)
Block(-4,22,5,minecraft:concrete:0)
Block(-4,22,6,AIR:0)
Block(-4,22,7,AIR:0)
Block(-4,22,8,AIR:0)
Block(-4,22,9,minecraft:concrete:0)
Block(-4,23,-6,minecraft:concrete:0)
Block(-4,23,-5,minecraft:concrete:0)
Block(-4,23,-4,minecraft:concrete:0)
Block(-4,23,-3,minecraft:concrete:0)
Block(-4,23,-2,minecraft:concrete:0)
Block(-4,23,-1,minecraft:concrete:0)
Block(-4,23,0,minecraft:concrete:0)
Block(-4,23,1,minecraft:concrete:0)
Block(-4,23,2,minecraft:concrete:0)
Block(-4,23,3,minecraft:concrete:0)
Block(-4,23,4,minecraft:concrete:0)
Block(-4,23,5,minecraft:concrete:0)
Block(-4,23,6,minecraft:concrete:0)
Block(-4,23,7,minecraft:concrete:0)
Block(-4,23,8,minecraft:concrete:0)
Block(-4,23,9,minecraft:concrete:0)
Block(-4,24,-5,minecraft:concrete:0)
Block(-4,24,-4,minecraft:concrete:0)
Block(-4,24,-3,minecraft:concrete:0)
Block(-4,24,-2,minecraft:concrete:0)
Block(-4,24,-1,minecraft:concrete:0)
Block(-4,24,0,minecraft:concrete:0)
Block(-4,24,1,minecraft:concrete:0)
Block(-4,24,2,minecraft:concrete:0)
Block(-4,24,3,minecraft:concrete:0)
Block(-4,24,4,minecraft:concrete:0)
Block(-4,24,5,minecraft:concrete:0)
Block(-4,24,6,minecraft:concrete:0)
Block(-4,25,-5,minecraft:concrete:0)
Block(-4,25,-4,minecraft:concrete:0)
Block(-4,25,-3,minecraft:concrete:0)
Block(-4,25,-2,minecraft:concrete:0)
Block(-4,25,-1,minecraft:concrete:0)
Block(-4,25,0,minecraft:concrete:0)
Block(-4,25,1,minecraft:concrete:0)
Block(-4,25,2,minecraft:concrete:0)
Block(-4,25,3,minecraft:concrete:0)
Block(-4,25,4,minecraft:concrete:0)
Block(-4,26,-5,minecraft:concrete:0)
Block(-4,26,-4,minecraft:concrete:0)
Block(-4,26,-3,minecraft:concrete:0)
Block(-4,26,-2,minecraft:concrete:0)
Block(-4,26,-1,minecraft:concrete:0)
Block(-4,26,0,minecraft:concrete:0)
Block(-4,26,1,minecraft:concrete:0)
Block(-4,26,2,minecraft:concrete:0)
Block(-4,26,3,minecraft:concrete:0)
Block(-4,26,4,minecraft:concrete:0)
Block(-4,27,-5,minecraft:concrete:0)
Block(-4,27,-4,minecraft:concrete:0)
Block(-4,27,-3,minecraft:concrete:0)
Block(-4,27,-2,minecraft:concrete:0)
Block(-4,27,-1,minecraft:concrete:0)
Block(-4,27,0,minecraft:concrete:0)
Block(-4,27,1,minecraft:concrete:0)
Block(-4,27,2,minecraft:concrete:0)
Block(-4,28,-6,minecraft:concrete:0)
Block(-4,28,-5,minecraft:concrete:0)
Block(-4,28,-4,minecraft:concrete:0)
Block(-4,28,-3,minecraft:concrete:0)
Block(-4,28,-2,minecraft:concrete:0)
Block(-4,28,-1,minecraft:concrete:0)
Block(-4,28,0,minecraft:concrete:0)
Block(-4,29,-6,minecraft:concrete:0)
Block(-4,29,-5,minecraft:stonebrick:0)
Block(-4,29,-4,AIR:0)
Block(-4,29,-3,AIR:0)
Block(-4,29,-2,minecraft:bone_block:0)
Block(-4,29,-1,minecraft:concrete:0)
Block(-4,29,0,minecraft:concrete:0)
Block(-4,29,1,minecraft:concrete:0)
Block(-4,30,-6,minecraft:stone_brick_stairs:2)
Block(-4,30,-5,quark:iron_button:2)
Block(-4,30,-4,AIR:0)
Block(-4,30,-3,AIR:0)
Block(-4,30,-2,AIR:0)
Block(-4,30,-1,minecraft:concrete:0)
Block(-4,30,0,minecraft:concrete:0)
Block(-4,30,1,minecraft:concrete:0)
Block(-4,31,-6,minecraft:concrete:0)
Block(-4,31,-5,minecraft:stone_brick_stairs:2)
Block(-4,31,-4,minecraft:stone_brick_stairs:1)
Block(-4,31,-3,minecraft:concrete:0)
Block(-4,31,-2,minecraft:concrete:1)
Block(-4,31,-1,quark:sturdy_stone:0)
Block(-4,31,0,quark:sturdy_stone:0)
Block(-4,31,1,minecraft:concrete:0)
Block(-4,32,-1,IRON_TRAPDOOR:3)
Block(-4,32,0,IRON_TRAPDOOR:1)
Block(-3,4,-6,minecraft:concrete:0)
Block(-3,4,-5,minecraft:concrete:0)
Block(-3,4,-4,minecraft:concrete:0)
Block(-3,4,-3,minecraft:concrete:0)
Block(-3,4,-2,minecraft:concrete:0)
Block(-3,4,-1,minecraft:concrete:0)
Block(-3,4,0,minecraft:concrete:0)
Block(-3,4,1,minecraft:concrete:0)
Block(-3,4,2,minecraft:concrete:0)
Block(-3,5,-6,minecraft:concrete:0)
Block(-3,5,-5,minecraft:stonebrick:0)
Block(-3,5,-4,minecraft:stonebrick:0)
Block(-3,5,-3,minecraft:stonebrick:0)
Block(-3,5,-2,minecraft:stonebrick:0)
Block(-3,5,-1,minecraft:stonebrick:0)
Block(-3,5,0,minecraft:stonebrick:0)
Block(-3,5,1,minecraft:stonebrick:0)
Block(-3,5,2,minecraft:concrete:0)
Block(-3,5,3,minecraft:concrete:0)
Block(-3,5,4,minecraft:concrete:0)
Block(-3,5,5,minecraft:concrete:0)
Block(-3,5,6,minecraft:concrete:0)
Block(-3,5,7,minecraft:concrete:0)
Block(-3,5,8,minecraft:concrete:0)
Block(-3,5,9,minecraft:concrete:0)
Block(-3,6,-6,minecraft:concrete:0)
Block(-3,6,-5,minecraft:stonebrick:0)
Block(-3,6,-4,minecraft:stonebrick:1)
Block(-3,6,-3,minecraft:bone_block:0)
Block(-3,6,-2,AIR:0)
Block(-3,6,-1,AIR:0)
Block(-3,6,0,AIR:0)
Block(-3,6,1,AIR:0)
Block(-3,6,2,minecraft:stonebrick:0)
Block(-3,6,3,minecraft:concrete:0)
Block(-3,6,4,AIR:0)
Block(-3,6,5,AIR:0)
Block(-3,6,6,AIR:0)
Block(-3,6,7,minecraft:concrete:0)
Block(-3,6,8,minecraft:concrete:0)
Block(-3,6,9,minecraft:concrete:0)
Block(-3,7,-6,minecraft:concrete:0)
Block(-3,7,-5,minecraft:stonebrick:0)
Block(-3,7,-4,minecraft:stonebrick:1)
Block(-3,7,-3,AIR:0)
Block(-3,7,-2,AIR:0)
Block(-3,7,-1,AIR:0)
Block(-3,7,0,AIR:0)
Block(-3,7,1,minecraft:stonebrick)
Block(-3,7,2,minecraft:stonebrick:0)
Block(-3,7,3,minecraft:concrete:0)
Block(-3,7,4,AIR:0)
Block(-3,7,5,AIR:0)
Block(-3,7,6,AIR:0)
Block(-3,7,7,minecraft:concrete:0)
Block(-3,7,8,minecraft:stone_brick_stairs:0)
Block(-3,7,9,minecraft:concrete:0)
Block(-3,8,-6,minecraft:concrete:0)
Block(-3,8,-5,minecraft:stonebrick:0)
Block(-3,8,-4,minecraft:stonebrick:1)
Block(-3,8,-3,AIR:0)
Block(-3,8,-2,AIR:0)
Block(-3,8,-1,AIR:0)
Block(-3,8,0,AIR:0)
Block(-3,8,1,AIR:0)
Block(-3,8,2,minecraft:stonebrick:0)
Block(-3,8,3,minecraft:concrete:0)
Block(-3,8,4,minecraft:iron_bars:0)
Block(-3,8,5,minecraft:iron_bars:0)
Block(-3,8,6,minecraft:iron_bars:0)
Block(-3,8,7,minecraft:concrete:0)
Block(-3,8,8,AIR:0)
Block(-3,8,9,minecraft:concrete:0)
Block(-3,9,-6,minecraft:concrete:0)
Block(-3,9,-5,minecraft:stonebrick:0)
Block(-3,9,-4,minecraft:stonebrick:1)
Block(-3,9,-3,AIR:0)
Block(-3,9,-2,AIR:0)
Block(-3,9,-1,AIR:0)
Block(-3,9,0,AIR:0)
Block(-3,9,1,minecraft:stonebrick:1)
Block(-3,9,2,minecraft:concrete:0)
Block(-3,9,3,minecraft:concrete:0)
Block(-3,9,4,AIR:0)
Block(-3,9,5,AIR:0)
Block(-3,9,6,AIR:0)
Block(-3,9,7,quark:framed_glass:0)
Block(-3,9,8,AIR:0)
Block(-3,9,9,minecraft:concrete:0)
Block(-3,10,-6,minecraft:concrete:0)
Block(-3,10,-5,minecraft:stonebrick:0)
Block(-3,10,-4,minecraft:stonebrick:0)
Block(-3,10,-3,minecraft:stonebrick:0)
Block(-3,10,-2,minecraft:stonebrick:0)
Block(-3,10,-1,minecraft:stonebrick:0)
Block(-3,10,0,minecraft:stonebrick:0)
Block(-3,10,1,minecraft:stonebrick:0)
Block(-3,10,2,minecraft:concrete:0)
Block(-3,10,3,minecraft:concrete:0)
Block(-3,10,4,AIR:0)
Block(-3,10,5,AIR:0)
Block(-3,10,6,AIR:0)
Block(-3,10,7,quark:framed_glass:0)
Block(-3,10,8,AIR:0)
Block(-3,10,9,minecraft:concrete:0)
Block(-3,11,-6,minecraft:concrete:0)
Block(-3,11,-5,minecraft:concrete:0)
Block(-3,11,-4,minecraft:concrete:0)
Block(-3,11,-3,minecraft:concrete:0)
Block(-3,11,-2,minecraft:concrete:0)
Block(-3,11,-1,minecraft:concrete:0)
Block(-3,11,0,minecraft:concrete:0)
Block(-3,11,1,minecraft:concrete:0)
Block(-3,11,2,minecraft:concrete:0)
Block(-3,11,3,minecraft:concrete:0)
Block(-3,11,4,minecraft:concrete:0)
Block(-3,11,5,minecraft:concrete:0)
Block(-3,11,6,minecraft:concrete:0)
Block(-3,11,7,minecraft:concrete:0)
Block(-3,11,8,minecraft:concrete:0)
Block(-3,11,9,minecraft:concrete:0)
Block(-3,12,-6,minecraft:concrete:0)
Block(-3,12,-5,minecraft:dirt:0)
Block(-3,12,-4,STATIONARY_WATER:0)
Block(-3,12,-3,minecraft:dirt:0)
Block(-3,12,-2,minecraft:concrete:0)
Block(-3,12,-1,minecraft:concrete:0)
Block(-3,12,0,minecraft:concrete:0)
Block(-3,12,1,minecraft:concrete:0)
Block(-3,12,2,minecraft:concrete:0)
Block(-3,12,3,quark:paper_wall_big:0)
Block(-3,12,4,quark:paper_wall_big:0)
Block(-3,12,5,quark:paper_wall_big:0)
Block(-3,12,6,minecraft:glowstone:0)
Block(-3,12,7,minecraft:bone_block:0)
Block(-3,12,8,CAULDRON:0)
Block(-3,12,9,minecraft:concrete:0)
Block(-3,13,-6,minecraft:concrete:0)
Block(-3,13,-5,minecraft:leaves:5)
Block(-3,13,-4,AIR:0)
Block(-3,13,-3,minecraft:tallgrass:13)
Block(-3,13,-2,minecraft:concrete:0)
Block(-3,13,-1,AIR:0)
Block(-3,13,0,minecraft:stone:0)
RandomBlock(-3,13,1,minecraft:planks:5,5,minecraft:planks:5,../../../Chests/Loot/manhunt_vagrant_scrap.nbt,100)
Block(-3,13,2,minecraft:concrete:0)
Block(-3,13,3,quark:paper_wall_big:0)
Block(-3,13,4,quark:paper_wall_big:0)
Block(-3,13,5,quark:paper_wall_big:0)
Block(-3,13,6,AIR:0)
Block(-3,13,7,AIR:0)
Block(-3,13,8,minecraft:bookshelf:0)
Block(-3,13,9,minecraft:concrete:0)
Block(-3,14,-6,minecraft:concrete:0)
Block(-3,14,-5,AIR:0)
Block(-3,14,-4,AIR:0)
Block(-3,14,-3,AIR:0)
Block(-3,14,-2,minecraft:concrete:0)
Block(-3,14,-1,AIR:0)
Block(-3,14,0,AIR:0)
Block(-3,14,1,minecraft:glowstone)
Block(-3,14,2,minecraft:concrete:0)
Block(-3,14,3,AIR:0)
Block(-3,14,4,AIR:0)
Block(-3,14,5,AIR:0)
Block(-3,14,6,AIR:0)
Block(-3,14,7,AIR:0)
Block(-3,14,8,minecraft:planks:3,../../../Chests/Loot/manhunt_vagrant_scrap.nbt)
Block(-3,14,9,minecraft:concrete:0)
Block(-3,15,-6,minecraft:concrete:0)
Block(-3,15,-5,minecraft:concrete:0)
Block(-3,15,-4,minecraft:concrete:0)
Block(-3,15,-3,minecraft:concrete:0)
Block(-3,15,-2,minecraft:concrete:0)
Block(-3,15,-1,minecraft:concrete:0)
Block(-3,15,0,minecraft:concrete:0)
Block(-3,15,1,minecraft:concrete:0)
Block(-3,15,2,minecraft:concrete:0)
Block(-3,15,3,minecraft:concrete:0)
Block(-3,15,4,minecraft:concrete:0)
Block(-3,15,5,minecraft:concrete:0)
Block(-3,15,6,minecraft:concrete:0)
Block(-3,15,7,minecraft:concrete:0)
Block(-3,15,8,minecraft:concrete:0)
Block(-3,15,9,minecraft:concrete:0)
Block(-3,16,-6,minecraft:concrete:0)
Block(-3,16,-5,minecraft:concrete:0)
Block(-3,16,-4,minecraft:iron_door:4)
Block(-3,16,-3,minecraft:concrete:0)
Block(-3,16,-2,minecraft:iron_door:0)
Block(-3,16,-1,minecraft:concrete:0)
Block(-3,16,0,minecraft:concrete:0)
Block(-3,16,1,minecraft:iron_door:2)
Block(-3,16,2,minecraft:concrete:0)
Block(-3,16,3,minecraft:iron_door:6)
Block(-3,16,4,minecraft:concrete:0)
Block(-3,16,5,AIR:0)
Block(-3,16,6,AIR:0)
Block(-3,16,7,AIR:0)
Block(-3,16,8,minecraft:oak_stairs:5)
Block(-3,16,9,minecraft:concrete:0)
Block(-3,17,-6,minecraft:concrete:0)
Block(-3,17,-5,minecraft:concrete:0)
Block(-3,17,-4,minecraft:iron_door:9)
Block(-3,17,-3,minecraft:concrete:0)
Block(-3,17,-2,minecraft:iron_door:8)
Block(-3,17,-1,minecraft:concrete:0)
Block(-3,17,0,minecraft:concrete:0)
Block(-3,17,1,minecraft:iron_door:8)
Block(-3,17,2,minecraft:concrete:0)
Block(-3,17,3,minecraft:iron_door:9)
Block(-3,17,4,minecraft:concrete:0)
Block(-3,17,5,AIR:0)
Block(-3,17,6,AIR:0)
Block(-3,17,7,AIR:0)
Block(-3,17,8,AIR:0)
Block(-3,17,9,minecraft:concrete:0)
Block(-3,18,-6,minecraft:concrete:0)
Block(-3,18,-5,minecraft:concrete:0)
Block(-3,18,-4,minecraft:concrete:0)
Block(-3,18,-3,minecraft:concrete:0)
Block(-3,18,-2,minecraft:concrete:0)
Block(-3,18,-1,minecraft:concrete:0)
Block(-3,18,0,minecraft:concrete:0)
Block(-3,18,1,minecraft:stonebrick:5)
Block(-3,18,2,minecraft:concrete:0)
Block(-3,18,3,minecraft:stonebrick:5)
Block(-3,18,4,minecraft:concrete:0)
Block(-3,18,5,AIR:0)
Block(-3,18,6,STEP:8)
Block(-3,18,7,AIR:0)
Block(-3,18,8,AIR:0)
Block(-3,18,9,minecraft:concrete:0)
Block(-3,19,-6,minecraft:concrete:0)
Block(-3,19,-5,minecraft:concrete:0)
Block(-3,19,-4,minecraft:concrete:0)
Block(-3,19,-3,minecraft:concrete:0)
Block(-3,19,-2,minecraft:concrete:0)
Block(-3,19,-1,minecraft:concrete:0)
Block(-3,19,0,minecraft:concrete:0)
Block(-3,19,1,minecraft:concrete:0)
Block(-3,19,2,minecraft:concrete:0)
Block(-3,19,3,minecraft:concrete:0)
Block(-3,19,4,minecraft:concrete:0)
Block(-3,19,5,minecraft:concrete:0)
Block(-3,19,6,minecraft:concrete:0)
Block(-3,19,7,minecraft:concrete:0)
Block(-3,19,8,minecraft:concrete:0)
Block(-3,19,9,minecraft:concrete:0)
Block(-3,20,-6,minecraft:concrete:0)
Block(-3,20,-5,AIR:0)
Block(-3,20,-4,AIR:0)
Block(-3,20,-3,AIR:0)
Block(-3,20,-2,minecraft:iron_bars:0)
Block(-3,20,-1,WEB:0)
Block(-3,20,0,AIR:0)
Block(-3,20,1,minecraft:stonebrick:0)
Block(-3,20,2,minecraft:concrete:0)
Block(-3,20,3,minecraft:concrete:0)
Block(-3,20,4,minecraft:concrete:0)
Block(-3,20,5,minecraft:iron_block:0)
Block(-3,20,6,minecraft:iron_block:0)
Block(-3,20,7,minecraft:iron_door:0)
Block(-3,20,8,minecraft:iron_block:0)
Block(-3,20,9,minecraft:iron_block:0)
Block(-3,21,-6,minecraft:concrete:0)
Block(-3,21,-5,AIR:0)
Block(-3,21,-4,AIR:0)
Block(-3,21,-3,AIR:0)
Block(-3,21,-2,AIR:0)
Block(-3,21,-1,AIR:0)
Block(-3,21,0,WEB:0)
Block(-3,21,1,AIR:0)
Block(-3,21,2,minecraft:concrete:0)
Block(-3,21,3,minecraft:concrete:0)
Block(-3,21,4,minecraft:concrete:0)
Block(-3,21,5,minecraft:iron_block:0)
Block(-3,21,6,minecraft:iron_block:0)
Block(-3,21,7,minecraft:iron_door:9)
Block(-3,21,8,minecraft:iron_block:0)
Block(-3,21,9,minecraft:iron_block:0)
Block(-3,22,-6,minecraft:concrete:0)
Block(-3,22,-5,AIR:0)
Block(-3,22,-4,AIR:0)
Block(-3,22,-3,AIR:0)
Block(-3,22,-2,minecraft:iron_bars:0)
Block(-3,22,-1,AIR:0)
Block(-3,22,0,AIR:0)
Block(-3,22,1,WEB:0)
Block(-3,22,2,minecraft:concrete:0)
Block(-3,22,3,minecraft:concrete:0)
Block(-3,22,4,minecraft:concrete:0)
Block(-3,22,5,minecraft:iron_block:0)
Block(-3,22,6,minecraft:iron_block:0)
Block(-3,22,7,minecraft:iron_block:0)
Block(-3,22,8,minecraft:iron_block:0)
Block(-3,22,9,minecraft:iron_block:0)
Block(-3,23,-6,minecraft:concrete:0)
Block(-3,23,-5,minecraft:concrete:0)
Block(-3,23,-4,minecraft:concrete:0)
Block(-3,23,-3,minecraft:concrete:0)
Block(-3,23,-2,minecraft:concrete:0)
Block(-3,23,-1,minecraft:concrete:0)
Block(-3,23,0,minecraft:concrete:0)
Block(-3,23,1,minecraft:concrete:0)
Block(-3,23,2,minecraft:concrete:0)
Block(-3,23,3,minecraft:concrete:0)
Block(-3,23,4,minecraft:concrete:0)
Block(-3,23,5,minecraft:concrete:0)
Block(-3,23,6,minecraft:concrete:0)
Block(-3,23,7,minecraft:concrete:0)
Block(-3,23,8,minecraft:concrete:0)
Block(-3,23,9,minecraft:concrete:0)
Block(-3,28,-6,minecraft:concrete:0)
Block(-3,28,-5,minecraft:concrete:0)
Block(-3,28,-4,minecraft:concrete:0)
Block(-3,28,-3,minecraft:concrete:0)
Block(-3,28,-2,minecraft:concrete:0)
Block(-3,29,-6,minecraft:concrete:0)
Block(-3,29,-5,minecraft:concrete:0)
Block(-3,29,-4,IRON_DOOR_BLOCK:2)
Block(-3,29,-3,minecraft:concrete:0)
Block(-3,29,-2,minecraft:concrete:0)
Block(-3,29,-1,minecraft:concrete:0)
Block(-3,29,0,minecraft:concrete:0)
Block(-3,29,1,minecraft:concrete:0)
Block(-3,30,-6,minecraft:concrete:0)
Block(-3,30,-5,minecraft:concrete:0)
Block(-3,30,-4,IRON_DOOR_BLOCK:9)
Block(-3,30,-3,minecraft:concrete:0)
Block(-3,30,-2,minecraft:concrete:0)
Block(-3,30,-1,minecraft:concrete:0)
Block(-3,30,0,minecraft:concrete:0)
Block(-3,30,1,minecraft:concrete:0)
Block(-3,31,-6,minecraft:concrete:0)
Block(-3,31,-5,minecraft:concrete:0)
Block(-3,31,-4,minecraft:stone_brick_stairs:2)
Block(-3,31,-3,minecraft:concrete:0)
Block(-3,31,-2,minecraft:concrete:0)
Block(-3,31,-1,minecraft:concrete:0)
Block(-3,31,0,minecraft:concrete:0)
Block(-3,31,1,minecraft:concrete:0)
Block(-2,4,-6,minecraft:concrete:0)
Block(-2,4,-5,minecraft:concrete:0)
Block(-2,4,-4,minecraft:concrete:0)
Block(-2,4,-3,minecraft:concrete:0)
Block(-2,4,-2,minecraft:concrete:0)
Block(-2,4,-1,minecraft:concrete:0)
Block(-2,4,0,minecraft:concrete:0)
Block(-2,4,1,minecraft:concrete:0)
Block(-2,4,2,minecraft:concrete:0)
Block(-2,5,-6,minecraft:concrete:0)
Block(-2,5,-5,minecraft:stonebrick:0)
Block(-2,5,-4,minecraft:stonebrick:0)
Block(-2,5,-3,minecraft:stonebrick:0)
Block(-2,5,-2,minecraft:stonebrick:0)
Block(-2,5,-1,minecraft:stonebrick:0)
Block(-2,5,0,minecraft:stonebrick:0)
Block(-2,5,1,minecraft:stonebrick:0)
Block(-2,5,2,minecraft:concrete:0)
Block(-2,5,3,minecraft:concrete:0)
Block(-2,5,4,minecraft:concrete:0)
Block(-2,5,5,minecraft:concrete:0)
Block(-2,5,6,minecraft:concrete:0)
Block(-2,5,7,minecraft:concrete:0)
Block(-2,5,8,minecraft:concrete:0)
Block(-2,5,9,minecraft:concrete:0)
Block(-2,6,-6,minecraft:concrete:0)
Block(-2,6,-5,minecraft:stonebrick:0)
Block(-2,6,-4,minecraft:stone:0)
Block(-2,6,-3,AIR:0)
Block(-2,6,-2,minecraft:stonebrick:0)
Block(-2,6,-1,AIR:0)
Block(-2,6,0,minecraft:stone:0)
Block(-2,6,1,AIR:0)
Block(-2,6,2,minecraft:stonebrick:0)
Block(-2,6,3,WEB:0)
Block(-2,6,4,AIR:0)
Block(-2,6,5,AIR:0)
Block(-2,6,6,AIR:0)
Block(-2,6,7,CONCRETE:15)
Block(-2,6,8,minecraft:concrete:0)
Block(-2,6,9,minecraft:concrete:0)
Block(-2,7,-6,minecraft:concrete:0)
Block(-2,7,-5,minecraft:stonebrick)
Block(-2,7,-4,minecraft:stonebrick:3)
Block(-2,7,-3,AIR:0)
Block(-2,7,-2,AIR:0)
Block(-2,7,-1,AIR:0)
Block(-2,7,0,AIR:0)
Block(-2,7,1,AIR:0)
Block(-2,7,2,minecraft:iron_block:0)
Block(-2,7,3,AIR:0)
Block(-2,7,4,AIR:0)
Block(-2,7,5,AIR:0)
Block(-2,7,6,AIR:0)
Block(-2,7,7,OBSERVER:3)
Block(-2,7,8,OBSERVER:2)
Block(-2,7,9,minecraft:concrete:0)
Block(-2,8,-6,minecraft:concrete:0)
Block(-2,8,-5,minecraft:stonebrick)
Block(-2,8,-4,minecraft:stonebrick:3)
Block(-2,8,-3,AIR:0)
Block(-2,8,-2,AIR:0)
Block(-2,8,-1,AIR:0)
Block(-2,8,0,AIR:0)
Block(-2,8,1,AIR:0)
Block(-2,8,2,minecraft:stonebrick:0)
Block(-2,8,3,minecraft:concrete:0)
Block(-2,8,4,minecraft:concrete:0)
Block(-2,8,5,minecraft:concrete:0)
Block(-2,8,6,minecraft:concrete:0)
Block(-2,8,7,minecraft:concrete:0)
Block(-2,8,8,minecraft:stone_brick_stairs:0)
Block(-2,8,9,minecraft:concrete:0)
Block(-2,9,-6,minecraft:concrete:0)
Block(-2,9,-5,minecraft:stonebrick:0)
Block(-2,9,-4,minecraft:stone:0)
Block(-2,9,-3,AIR:0)
Block(-2,9,-2,AIR:0)
Block(-2,9,-1,AIR:0)
Block(-2,9,0,AIR:0)
Block(-2,9,1,minecraft:stonebrick:1)
Block(-2,9,2,minecraft:concrete:0)
Block(-2,9,3,quark:framed_glass:0)
Block(-2,9,4,quark:framed_glass:0)
Block(-2,9,5,quark:framed_glass:0)
Block(-2,9,6,quark:framed_glass:0)
Block(-2,9,7,quark:framed_glass:0)
Block(-2,9,8,AIR:0)
Block(-2,9,9,minecraft:concrete:0)
Block(-2,10,-6,minecraft:concrete:0)
Block(-2,10,-5,minecraft:stonebrick:0)
Block(-2,10,-4,minecraft:stonebrick:0)
Block(-2,10,-3,minecraft:stonebrick:0)
Block(-2,10,-2,minecraft:stonebrick:0)
Block(-2,10,-1,minecraft:stonebrick:0)
Block(-2,10,0,minecraft:stonebrick:0)
Block(-2,10,1,minecraft:stonebrick:0)
Block(-2,10,2,minecraft:concrete:0)
Block(-2,10,3,quark:framed_glass:0)
Block(-2,10,4,quark:framed_glass:0)
Block(-2,10,5,quark:framed_glass:0)
Block(-2,10,6,quark:framed_glass:0)
Block(-2,10,7,quark:framed_glass:0)
Block(-2,10,8,AIR:0)
Block(-2,10,9,minecraft:concrete:0)
Block(-2,11,-6,minecraft:concrete:0)
Block(-2,11,-5,minecraft:concrete:0)
Block(-2,11,-4,minecraft:concrete:0)
Block(-2,11,-3,minecraft:concrete:0)
Block(-2,11,-2,minecraft:concrete:0)
Block(-2,11,-1,minecraft:concrete:0)
Block(-2,11,0,minecraft:concrete:0)
Block(-2,11,1,minecraft:concrete:0)
Block(-2,11,2,minecraft:concrete:0)
Block(-2,11,3,minecraft:concrete:0)
Block(-2,11,4,minecraft:concrete:0)
Block(-2,11,5,minecraft:concrete:0)
Block(-2,11,6,minecraft:concrete:0)
Block(-2,11,7,minecraft:concrete:0)
Block(-2,11,8,minecraft:concrete:0)
Block(-2,11,9,minecraft:concrete:0)
Block(-2,12,-6,minecraft:concrete:0)
Block(-2,12,-5,minecraft:stonebrick:14)
Block(-2,12,-4,STATIONARY_WATER:0)
Block(-2,12,-3,minecraft:stonebrick:14)
Block(-2,12,-2,minecraft:concrete:0)
Block(-2,12,-1,minecraft:concrete:0)
Block(-2,12,0,minecraft:concrete:0)
Block(-2,12,1,minecraft:concrete:0)
Block(-2,12,2,minecraft:concrete:0)
Block(-2,12,3,BED_BLOCK:10,f_bunker_mid_nuclear/65-bed.nbt)
Block(-2,12,4,BED_BLOCK:2,f_bunker_mid_nuclear/66-bed.nbt)
Block(-2,12,5,AIR:0)
Block(-2,12,6,minecraft:stone:0)
Block(-2,12,7,AIR:0)
Block(-2,12,8,minecraft:stonebrick:3)
Block(-2,12,9,minecraft:concrete:0)
Block(-2,13,-6,minecraft:concrete:0)
Block(-2,13,-5,minecraft:grass:0)
Block(-2,13,-4,AIR:0)
Block(-2,13,-3,minecraft:glowstone:0)
Block(-2,13,-2,minecraft:concrete:0)
Block(-2,13,-1,AIR:0)
Block(-2,13,0,minecraft:planks:0)
RandomBlock(-2,13,1,minecraft:planks:5,5,minecraft:planks:5,../../../Chests/Loot/manhunt_vagrant_scrap.nbt,100)
Block(-2,13,2,minecraft:concrete:0)
Block(-2,13,3,AIR:0)
Block(-2,13,4,AIR:0)
Block(-2,13,5,AIR:0)
Block(-2,13,6,AIR:0)
Block(-2,13,7,AIR:0)
Block(-2,13,8,AIR:0)
Block(-2,13,9,minecraft:concrete:0)
Block(-2,14,-6,minecraft:concrete:0)
Block(-2,14,-5,AIR:0)
Block(-2,14,-4,AIR:0)
Block(-2,14,-3,AIR:0)
Block(-2,14,-2,minecraft:concrete:0)
Block(-2,14,-1,AIR:0)
Block(-2,14,0,WEB:0)
RandomBlock(-2,14,1,minecraft:planks:5,5,minecraft:planks:5,../../../Chests/Loot/manhunt_vagrant_scrap.nbt,100)
Block(-2,14,2,minecraft:concrete:0)
Block(-2,14,3,AIR:0)
Block(-2,14,4,AIR:0)
Block(-2,14,5,AIR:0)
Block(-2,14,6,AIR:0)
Block(-2,14,7,AIR:0)
Block(-2,14,8,minecraft:planks:3,../../../Chests/Loot/manhunt_vagrant_scrap.nbt)
Block(-2,14,9,minecraft:concrete:0)
Block(-2,15,-6,minecraft:concrete:0)
Block(-2,15,-5,minecraft:concrete:0)
Block(-2,15,-4,minecraft:concrete:0)
Block(-2,15,-3,minecraft:concrete:0)
Block(-2,15,-2,minecraft:concrete:0)
Block(-2,15,-1,minecraft:concrete:0)
Block(-2,15,0,minecraft:concrete:0)
Block(-2,15,1,minecraft:concrete:0)
Block(-2,15,2,minecraft:concrete:0)
Block(-2,15,3,minecraft:concrete:0)
Block(-2,15,4,minecraft:concrete:0)
Block(-2,15,5,minecraft:concrete:0)
Block(-2,15,6,minecraft:concrete:0)
Block(-2,15,7,minecraft:concrete:0)
Block(-2,15,8,minecraft:concrete:0)
Block(-2,15,9,minecraft:concrete:0)
Block(-2,16,-6,minecraft:concrete:0)
Block(-2,16,-5,BED_BLOCK:3,f_bunker_mid_nuclear/71-bed.nbt)
Block(-2,16,-4,AIR:0)
Block(-2,16,-3,BED_BLOCK:3,f_bunker_mid_nuclear/72-bed.nbt)
Block(-2,16,-2,AIR:0)
Block(-2,16,-1,BED_BLOCK:3,f_bunker_mid_nuclear/73-bed.nbt)
Block(-2,16,0,minecraft:concrete:0)
Block(-2,16,1,AIR:0)
Block(-2,16,2,minecraft:concrete:0)
Block(-2,16,3,AIR:0)
Block(-2,16,4,minecraft:concrete:0)
Block(-2,16,5,minecraft:oak_stairs:1)
Block(-2,16,6,minecraft:stonebrick:0)
Block(-2,16,7,AIR:0)
Block(-2,16,8,minecraft:oak_stairs:5)
Block(-2,16,9,minecraft:concrete:0)
Block(-2,17,-6,minecraft:concrete:0)
Block(-2,17,-5,BED_BLOCK:3,f_bunker_mid_nuclear/76-bed.nbt)
Block(-2,17,-4,AIR:0)
Block(-2,17,-3,BED_BLOCK:3,f_bunker_mid_nuclear/77-bed.nbt)
Block(-2,17,-2,AIR:0)
Block(-2,17,-1,BED_BLOCK:3,f_bunker_mid_nuclear/78-bed.nbt)
Block(-2,17,0,minecraft:concrete:0)
Block(-2,17,1,AIR:0)
Block(-2,17,2,minecraft:concrete:0)
Block(-2,17,3,AIR:0)
Block(-2,17,4,minecraft:concrete:0)
Block(-2,17,5,AIR:0)
Block(-2,17,6,AIR:0)
Block(-2,17,7,AIR:0)
Block(-2,17,8,AIR:0)
Block(-2,17,9,minecraft:concrete:0)
Block(-2,18,-6,minecraft:concrete:0)
Block(-2,18,-5,AIR:0)
Block(-2,18,-4,AIR:0)
Block(-2,18,-3,AIR:0)
Block(-2,18,-2,AIR:0)
Block(-2,18,-1,AIR:0)
Block(-2,18,0,minecraft:concrete:0)
Block(-2,18,1,AIR:0)
Block(-2,18,2,minecraft:concrete:0)
Block(-2,18,3,AIR:0)
Block(-2,18,4,minecraft:concrete:0)
Block(-2,18,5,AIR:0)
Block(-2,18,6,STEP:8)
Block(-2,18,7,AIR:0)
Block(-2,18,8,AIR:0)
Block(-2,18,9,minecraft:concrete:0)
Block(-2,19,-6,minecraft:concrete:0)
Block(-2,19,-5,minecraft:concrete:0)
Block(-2,19,-4,minecraft:concrete:0)
Block(-2,19,-3,minecraft:concrete:0)
Block(-2,19,-2,minecraft:concrete:0)
Block(-2,19,-1,minecraft:concrete:0)
Block(-2,19,0,minecraft:concrete:0)
Block(-2,19,1,minecraft:concrete:0)
Block(-2,19,2,minecraft:concrete:0)
Block(-2,19,3,minecraft:stone_brick_stairs:5)
Block(-2,19,4,minecraft:concrete:0)
Block(-2,19,5,minecraft:concrete:0)
Block(-2,19,6,minecraft:concrete:0)
Block(-2,19,7,minecraft:concrete:0)
Block(-2,19,8,minecraft:concrete:0)
Block(-2,19,9,minecraft:concrete:0)
Block(-2,20,-6,minecraft:concrete:0)
Block(-2,20,-5,quark:iron_plate_slab:8)
Block(-2,20,-4,minecraft:stone_brick_stairs:6)
Block(-2,20,-3,minecraft:stone_brick_stairs:7)
Block(-2,20,-2,minecraft:iron_bars:0)
Block(-2,20,-1,minecraft:stonebrick:0)
Block(-2,20,0,minecraft:stonebrick:0)
Block(-2,20,1,minecraft:concrete:0)
Block(-2,20,2,minecraft:concrete:0)
Block(-2,20,3,minecraft:concrete:0)
Block(-2,20,4,minecraft:concrete:0)
Block(-2,20,5,minecraft:iron_block:0)
Block(-2,20,6,AIR:0)
Block(-2,20,7,AIR:0)
Block(-2,20,8,AIR:0)
Block(-2,20,9,minecraft:iron_block:0)
Block(-2,21,-6,minecraft:concrete:0)
Block(-2,21,-5,quark:iron_plate:0)
Block(-2,21,-4,quark:iron_plate:0)
Block(-2,21,-3,minecraft:stonebrick)
Block(-2,21,-2,AIR:0)
Block(-2,21,-1,AIR:0)
Block(-2,21,0,AIR:0)
Block(-2,21,1,minecraft:concrete:0)
Block(-2,21,2,minecraft:concrete:0)
Block(-2,21,3,minecraft:concrete:0)
Block(-2,21,4,minecraft:concrete:0)
Block(-2,21,5,minecraft:iron_block:0)
Block(-2,21,6,AIR:0)
Block(-2,21,7,AIR:0)
Block(-2,21,8,quark:iron_button:1)
Block(-2,21,9,minecraft:iron_block:0)
Block(-2,22,-6,minecraft:concrete:0)
Block(-2,22,-5,AIR:0)
Block(-2,22,-4,AIR:0)
Block(-2,22,-3,IRON_TRAPDOOR:1)
Block(-2,22,-2,minecraft:iron_bars:0)
Block(-2,22,-1,AIR:0)
Block(-2,22,0,AIR:0)
Block(-2,22,1,minecraft:concrete:0)
Block(-2,22,2,minecraft:concrete:0)
Block(-2,22,3,minecraft:concrete:0)
Block(-2,22,4,minecraft:concrete:0)
Block(-2,22,5,minecraft:iron_block:0)
Block(-2,22,6,AIR:0)
Block(-2,22,7,AIR:0)
Block(-2,22,8,AIR:0)
Block(-2,22,9,minecraft:iron_block:0)
Block(-2,23,-6,minecraft:concrete:0)
Block(-2,23,-5,minecraft:concrete:0)
Block(-2,23,-4,minecraft:concrete:0)
Block(-2,23,-3,minecraft:concrete:0)
Block(-2,23,-2,minecraft:concrete:0)
Block(-2,23,-1,minecraft:concrete:0)
Block(-2,23,0,minecraft:concrete:0)
Block(-2,23,1,minecraft:concrete:0)
Block(-2,23,2,minecraft:concrete:0)
Block(-2,23,3,minecraft:concrete:0)
Block(-2,23,4,minecraft:concrete:0)
Block(-2,23,5,minecraft:concrete:0)
Block(-2,23,6,minecraft:concrete:0)
Block(-2,23,7,minecraft:concrete:0)
Block(-2,23,8,minecraft:concrete:0)
Block(-2,23,9,minecraft:concrete:0)
Block(-2,24,-6,minecraft:concrete:0)
Block(-2,24,-2,minecraft:concrete:0)
Block(-2,25,-6,minecraft:concrete:0)
Block(-2,25,-2,minecraft:concrete:0)
Block(-2,26,-6,minecraft:concrete:0)
Block(-2,26,-2,minecraft:concrete:0)
Block(-2,27,-6,minecraft:concrete:0)
Block(-2,27,-2,minecraft:concrete:0)
Block(-2,28,-6,minecraft:concrete:0)
Block(-2,28,-5,minecraft:concrete:0)
Block(-2,28,-4,minecraft:concrete:0)
Block(-2,28,-3,minecraft:concrete:0)
Block(-2,28,-2,minecraft:concrete:0)
Block(-2,29,-6,minecraft:concrete:0)
Block(-2,29,-2,minecraft:concrete:0)
Block(-2,30,-6,minecraft:concrete:0)
Block(-2,30,-5,quark:iron_button:1)
Block(-2,30,-3,minecraft:stonebrick:5)
Block(-2,30,-2,minecraft:concrete:0)
Block(-2,31,-6,minecraft:concrete:0)
Block(-2,31,-5,minecraft:concrete:0)
Block(-2,31,-4,minecraft:concrete:0)
Block(-2,31,-3,minecraft:concrete:0)
Block(-2,31,-2,minecraft:concrete:0)
Block(-1,4,-6,minecraft:concrete:0)
Block(-1,4,-5,minecraft:concrete:0)
Block(-1,4,-4,minecraft:concrete:0)
Block(-1,4,-3,minecraft:concrete:0)
Block(-1,4,-2,minecraft:concrete:0)
Block(-1,4,-1,minecraft:concrete:0)
Block(-1,4,0,minecraft:concrete:0)
Block(-1,4,1,minecraft:concrete:0)
Block(-1,4,2,minecraft:concrete:0)
Block(-1,5,-6,minecraft:concrete:0)
Block(-1,5,-5,minecraft:stonebrick:0)
Block(-1,5,-4,minecraft:stonebrick:0)
Block(-1,5,-3,minecraft:stonebrick:0)
Block(-1,5,-2,minecraft:stonebrick:0)
Block(-1,5,-1,minecraft:stonebrick:0)
Block(-1,5,0,minecraft:stonebrick:0)
Block(-1,5,1,minecraft:stonebrick:0)
Block(-1,5,2,minecraft:concrete:0)
Block(-1,5,3,minecraft:concrete:0)
Block(-1,5,4,minecraft:concrete:0)
Block(-1,5,5,minecraft:concrete:0)
Block(-1,5,6,minecraft:concrete:0)
Block(-1,5,7,minecraft:concrete:0)
Block(-1,5,8,minecraft:concrete:0)
Block(-1,5,9,minecraft:concrete:0)
Block(-1,6,-6,minecraft:concrete:0)
Block(-1,6,-5,minecraft:stonebrick:0)
Block(-1,6,-4,minecraft:stone:0)
Block(-1,6,-3,AIR:0)
Block(-1,6,-2,minecraft:stone:0)
Block(-1,6,-1,dregorarl_srpmanhunt:encounter_marker:10)
Block(-1,6,0,AIR:0)
Block(-1,6,1,minecraft:stone:0)
Block(-1,6,2,minecraft:stonebrick:0)
Block(-1,6,3,AIR:0)
Block(-1,6,4,minecraft:stonebrick:0)
Block(-1,6,5,AIR:0)
Block(-1,6,6,minecraft:stone:0)
Block(-1,6,7,OBSERVER:3)
Block(-1,6,8,OBSERVER:2)
Block(-1,6,9,minecraft:concrete:0)
Block(-1,7,-6,minecraft:concrete:0)
Block(-1,7,-5,minecraft:stonebrick)
Block(-1,7,-4,minecraft:stonebrick:3)
Block(-1,7,-3,AIR:0)
Block(-1,7,-2,AIR:0)
Block(-1,7,-1,AIR:0)
Block(-1,7,0,AIR:0)
Block(-1,7,1,AIR:0)
Block(-1,7,2,minecraft:iron_block:0)
Block(-1,7,3,AIR:0)
Block(-1,7,4,AIR:0)
Block(-1,7,5,AIR:0)
Block(-1,7,6,AIR:0)
Block(-1,7,7,minecraft:stonebrick)
Block(-1,7,8,minecraft:concrete:0)
Block(-1,7,9,minecraft:concrete:0)
Block(-1,8,-6,minecraft:concrete:0)
Block(-1,8,-5,minecraft:stonebrick)
Block(-1,8,-4,minecraft:stonebrick:3)
Block(-1,8,-3,AIR:0)
Block(-1,8,-2,AIR:0)
Block(-1,8,-1,AIR:0)
Block(-1,8,0,AIR:0)
Block(-1,8,1,AIR:0)
Block(-1,8,2,minecraft:stonebrick:0)
Block(-1,8,3,minecraft:concrete:0)
Block(-1,8,4,minecraft:concrete:0)
Block(-1,8,5,minecraft:concrete:0)
Block(-1,8,6,minecraft:concrete:0)
Block(-1,8,7,minecraft:concrete:0)
Block(-1,8,8,minecraft:concrete:0)
Block(-1,8,9,minecraft:concrete:0)
Block(-1,9,-6,minecraft:concrete:0)
Block(-1,9,-5,minecraft:stonebrick:0)
Block(-1,9,-4,minecraft:stone:0)
Block(-1,9,-3,AIR:0)
Block(-1,9,-2,AIR:0)
Block(-1,9,-1,AIR:0)
Block(-1,9,0,AIR:0)
Block(-1,9,1,minecraft:stonebrick:1)
Block(-1,9,2,minecraft:concrete:0)
Block(-1,9,3,AIR:0)
Block(-1,9,4,AIR:0)
Block(-1,9,5,minecraft:stone:0)
Block(-1,9,6,AIR:0)
Block(-1,9,7,AIR:0)
Block(-1,9,8,AIR:0)
Block(-1,9,9,minecraft:concrete:0)
Block(-1,10,-6,minecraft:concrete:0)
Block(-1,10,-5,minecraft:stonebrick:0)
Block(-1,10,-4,minecraft:stonebrick:0)
Block(-1,10,-3,minecraft:stonebrick:0)
Block(-1,10,-2,minecraft:stonebrick:0)
Block(-1,10,-1,minecraft:stonebrick:0)
Block(-1,10,0,minecraft:stonebrick:0)
Block(-1,10,1,minecraft:stonebrick:0)
Block(-1,10,2,minecraft:concrete:0)
Block(-1,10,3,AIR:0)
Block(-1,10,4,AIR:0)
Block(-1,10,5,AIR:0)
Block(-1,10,6,AIR:0)
Block(-1,10,7,AIR:0)
Block(-1,10,8,AIR:0)
Block(-1,10,9,minecraft:concrete:0)
Block(-1,11,-6,minecraft:concrete:0)
Block(-1,11,-5,minecraft:concrete:0)
Block(-1,11,-4,minecraft:concrete:0)
Block(-1,11,-3,minecraft:concrete:0)
Block(-1,11,-2,minecraft:concrete:0)
Block(-1,11,-1,minecraft:concrete:0)
Block(-1,11,0,minecraft:concrete:0)
Block(-1,11,1,minecraft:concrete:0)
Block(-1,11,2,minecraft:concrete:0)
Block(-1,11,3,minecraft:stone_brick_stairs:5)
Block(-1,11,4,minecraft:concrete:0)
Block(-1,11,5,minecraft:concrete:0)
Block(-1,11,6,minecraft:concrete:0)
Block(-1,11,7,minecraft:concrete:0)
Block(-1,11,8,minecraft:concrete:0)
Block(-1,11,9,minecraft:concrete:0)
Block(-1,12,-6,minecraft:concrete:0)
Block(-1,12,-5,minecraft:stonebrick:14)
Block(-1,12,-4,minecraft:stonebrick:14)
Block(-1,12,-3,minecraft:stonebrick:14)
Block(-1,12,-2,minecraft:concrete:0)
Block(-1,12,-1,minecraft:concrete:0)
Block(-1,12,0,minecraft:concrete:0)
Block(-1,12,1,minecraft:concrete:0)
Block(-1,12,2,minecraft:concrete:0)
Block(-1,12,3,minecraft:concrete:0)
Block(-1,12,4,minecraft:concrete:0)
Block(-1,12,5,minecraft:concrete:0)
Block(-1,12,6,minecraft:glass:0)
Block(-1,12,7,minecraft:glass:0)
Block(-1,12,8,minecraft:concrete:0)
Block(-1,12,9,minecraft:concrete:0)
Block(-1,13,-6,minecraft:concrete:0)
Block(-1,13,-5,AIR:0)
Block(-1,13,-4,AIR:0)
Block(-1,13,-3,AIR:0)
Block(-1,13,-2,minecraft:concrete:0)
Block(-1,13,-1,minecraft:iron_door:0)
Block(-1,13,0,minecraft:concrete:0)
Block(-1,13,1,minecraft:concrete:0)
Block(-1,13,2,minecraft:concrete:0)
Block(-1,13,3,minecraft:concrete:0)
Block(-1,13,4,minecraft:concrete:0)
Block(-1,13,5,minecraft:concrete:0)
Block(-1,13,6,minecraft:glass:8)
Block(-1,13,7,minecraft:glass:9)
Block(-1,13,8,minecraft:concrete:0)
Block(-1,13,9,minecraft:concrete:0)
Block(-1,14,-6,minecraft:concrete:0)
Block(-1,14,-5,AIR:0)
Block(-1,14,-4,AIR:0)
Block(-1,14,-3,AIR:0)
Block(-1,14,-2,minecraft:concrete:0)
Block(-1,14,-1,minecraft:iron_door:9)
Block(-1,14,0,minecraft:concrete:0)
Block(-1,14,1,minecraft:concrete:0)
Block(-1,14,2,minecraft:concrete:0)
Block(-1,14,3,minecraft:concrete:0)
Block(-1,14,4,minecraft:concrete:0)
Block(-1,14,5,minecraft:concrete:0)
Block(-1,14,6,minecraft:concrete:0)
Block(-1,14,7,minecraft:concrete:0)
Block(-1,14,8,minecraft:concrete:0)
Block(-1,14,9,minecraft:concrete:0)
Block(-1,15,-6,minecraft:concrete:0)
Block(-1,15,-5,minecraft:concrete:0)
Block(-1,15,-4,minecraft:concrete:0)
Block(-1,15,-3,minecraft:concrete:0)
Block(-1,15,-2,minecraft:concrete:0)
Block(-1,15,-1,minecraft:concrete:0)
Block(-1,15,0,minecraft:concrete:0)
Block(-1,15,1,minecraft:stone_brick_stairs:1)
Block(-1,15,2,minecraft:concrete:0)
Block(-1,15,3,minecraft:concrete:0)
Block(-1,15,4,minecraft:concrete:0)
Block(-1,15,5,minecraft:concrete:0)
Block(-1,15,6,minecraft:concrete:0)
Block(-1,15,7,minecraft:concrete:0)
Block(-1,15,8,minecraft:concrete:0)
Block(-1,15,9,minecraft:concrete:0)
Block(-1,16,-6,minecraft:concrete:0)
Block(-1,16,-5,BED_BLOCK:11,f_bunker_mid_nuclear/86-bed.nbt)
Block(-1,16,-4,minecraft:stonebrick:0)
Block(-1,16,-3,BED_BLOCK:11,f_bunker_mid_nuclear/87-bed.nbt)
Block(-1,16,-2,AIR:0)
Block(-1,16,-1,BED_BLOCK:11,f_bunker_mid_nuclear/88-bed.nbt)
Block(-1,16,0,minecraft:concrete:0)
Block(-1,16,1,AIR:0)
Block(-1,16,2,minecraft:concrete:0)
Block(-1,16,3,minecraft:stone_brick_stairs:0)
Block(-1,16,4,minecraft:concrete:0)
Block(-1,16,5,minecraft:planks:5)
Block(-1,16,6,AIR:0)
Block(-1,16,7,minecraft:planks:1)
Block(-1,16,8,minecraft:planks:1)
Block(-1,16,9,minecraft:concrete:0)
Block(-1,17,-6,minecraft:concrete:0)
Block(-1,17,-5,BED_BLOCK:11,f_bunker_mid_nuclear/92-bed.nbt)
Block(-1,17,-4,AIR:0)
Block(-1,17,-3,BED_BLOCK:11,f_bunker_mid_nuclear/93-bed.nbt)
Block(-1,17,-2,AIR:0)
Block(-1,17,-1,BED_BLOCK:11,f_bunker_mid_nuclear/94-bed.nbt)
Block(-1,17,0,minecraft:concrete:0)
Block(-1,17,1,AIR:0)
Block(-1,17,2,minecraft:concrete:0)
Block(-1,17,3,AIR:0)
Block(-1,17,4,minecraft:concrete:0)
Block(-1,17,5,AIR:0)
Block(-1,17,6,AIR:0)
Block(-1,17,7,minecraft:stonebrick:4)
Block(-1,17,8,minecraft:stonebrick:4)
Block(-1,17,9,minecraft:concrete:0)
Block(-1,18,-6,minecraft:concrete:0)
Block(-1,18,-5,AIR:0)
Block(-1,18,-4,AIR:0)
Block(-1,18,-3,AIR:0)
Block(-1,18,-2,AIR:0)
Block(-1,18,-1,AIR:0)
Block(-1,18,0,minecraft:concrete:0)
Block(-1,18,1,AIR:0)
Block(-1,18,2,minecraft:concrete:0)
Block(-1,18,3,AIR:0)
Block(-1,18,4,minecraft:concrete:0)
Block(-1,18,5,minecraft:stonebrick)
Block(-1,18,6,STEP:8)
Block(-1,18,7,AIR:0)
Block(-1,18,8,minecraft:stonebrick)
Block(-1,18,9,minecraft:concrete:0)
Block(-1,19,-6,minecraft:concrete:0)
Block(-1,19,-5,minecraft:concrete:0)
Block(-1,19,-4,minecraft:concrete:0)
Block(-1,19,-3,minecraft:concrete:0)
Block(-1,19,-2,minecraft:concrete:0)
Block(-1,19,-1,minecraft:concrete:0)
Block(-1,19,0,minecraft:concrete:0)
Block(-1,19,1,minecraft:concrete:0)
Block(-1,19,2,minecraft:concrete:0)
Block(-1,19,3,AIR:0)
Block(-1,19,4,minecraft:concrete:0)
Block(-1,19,5,minecraft:concrete:0)
Block(-1,19,6,minecraft:concrete:0)
Block(-1,19,7,minecraft:concrete:0)
Block(-1,19,8,minecraft:concrete:0)
Block(-1,19,9,minecraft:concrete:0)
Block(-1,20,-6,minecraft:concrete:0)
Block(-1,20,-5,AIR:0)
Block(-1,20,-4,AIR:0)
Block(-1,20,-3,AIR:0)
Block(-1,20,-2,minecraft:iron_bars:0)
Block(-1,20,-1,minecraft:stone:0)
Block(-1,20,0,quark:iron_button:4)
Block(-1,20,1,CONCRETE:15)
Block(-1,20,2,minecraft:concrete:0)
Block(-1,20,3,minecraft:stone_brick_stairs:5)
Block(-1,20,4,minecraft:concrete:0)
Block(-1,20,5,minecraft:iron_block:0)
Block(-1,20,6,AIR:0)
Block(-1,20,7,AIR:0)
Block(-1,20,8,AIR:0)
Block(-1,20,9,minecraft:iron_block:0)
Block(-1,21,-6,minecraft:concrete:0)
Block(-1,21,-5,AIR:0)
Block(-1,21,-4,AIR:0)
Block(-1,21,-3,AIR:0)
Block(-1,21,-2,AIR:0)
Block(-1,21,-1,AIR:0)
Block(-1,21,0,quark:iron_button:4)
Block(-1,21,1,CONCRETE:15)
Block(-1,21,2,minecraft:concrete:0)
Block(-1,21,3,minecraft:concrete:0)
Block(-1,21,4,minecraft:concrete:0)
Block(-1,21,5,minecraft:iron_block:0)
Block(-1,21,6,AIR:0)
Block(-1,21,7,AIR:0)
Block(-1,21,8,AIR:0)
Block(-1,21,9,minecraft:iron_block:0)
Block(-1,22,-6,minecraft:concrete:0)
Block(-1,22,-5,AIR:0)
Block(-1,22,-4,AIR:0)
Block(-1,22,-3,AIR:0)
Block(-1,22,-2,minecraft:iron_bars:0)
Block(-1,22,-1,AIR:0)
Block(-1,22,0,minecraft:glowstone:4)
Block(-1,22,1,CONCRETE:15)
Block(-1,22,2,minecraft:concrete:0)
Block(-1,22,3,minecraft:concrete:0)
Block(-1,22,4,minecraft:concrete:0)
Block(-1,22,5,minecraft:iron_block:0)
Block(-1,22,6,AIR:0)
Block(-1,22,7,AIR:0)
Block(-1,22,8,AIR:0)
Block(-1,22,9,minecraft:iron_block:0)
Block(-1,23,-6,minecraft:concrete:0)
Block(-1,23,-5,minecraft:concrete:0)
Block(-1,23,-4,minecraft:concrete:0)
Block(-1,23,-3,minecraft:concrete:0)
Block(-1,23,-2,minecraft:concrete:0)
Block(-1,23,-1,minecraft:concrete:0)
Block(-1,23,0,minecraft:concrete:0)
Block(-1,23,1,minecraft:concrete:0)
Block(-1,23,2,minecraft:concrete:0)
Block(-1,23,3,minecraft:concrete:0)
Block(-1,23,4,minecraft:concrete:0)
Block(-1,23,5,minecraft:concrete:0)
Block(-1,23,6,minecraft:concrete:0)
Block(-1,23,7,minecraft:concrete:0)
Block(-1,23,8,minecraft:concrete:0)
Block(-1,23,9,minecraft:concrete:0)
Block(0,0,-6,minecraft:concrete:0)
Block(0,0,-5,minecraft:concrete:0)
Block(0,0,-4,minecraft:concrete:0)
Block(0,0,-3,minecraft:concrete:0)
Block(0,0,-2,minecraft:concrete:0)
Block(0,0,-1,minecraft:concrete:0)
Block(0,0,0,minecraft:concrete:0)
Block(0,0,1,minecraft:concrete:0)
Block(0,0,2,minecraft:concrete:0)
Block(0,1,-6,minecraft:concrete:0)
Block(0,1,-5,minecraft:concrete:0)
Block(0,1,-4,minecraft:concrete:0)
Block(0,1,-3,minecraft:concrete:0)
Block(0,1,-2,minecraft:concrete:0)
Block(0,1,-1,minecraft:concrete:0)
Block(0,1,0,minecraft:concrete:0)
Block(0,1,1,minecraft:concrete:0)
Block(0,1,2,minecraft:concrete:0)
Block(0,2,-6,minecraft:concrete:0)
Block(0,2,-5,minecraft:concrete:0)
Block(0,2,-4,minecraft:concrete:0)
Block(0,2,-3,minecraft:concrete:0)
Block(0,2,-2,minecraft:concrete:0)
Block(0,2,-1,minecraft:concrete:0)
Block(0,2,0,minecraft:concrete:0)
Block(0,2,1,minecraft:concrete:0)
Block(0,2,2,minecraft:concrete:0)
Block(0,3,-6,minecraft:concrete:0)
Block(0,3,-5,minecraft:concrete:0)
Block(0,3,-4,minecraft:concrete:0)
Block(0,3,-3,minecraft:concrete:0)
Block(0,3,-2,minecraft:concrete:0)
Block(0,3,-1,minecraft:concrete:0)
Block(0,3,0,minecraft:concrete:0)
Block(0,3,1,minecraft:concrete:0)
Block(0,3,2,minecraft:concrete:0)
Block(0,4,-6,minecraft:concrete:0)
Block(0,4,-5,minecraft:concrete:0)
Block(0,4,-4,minecraft:concrete:0)
Block(0,4,-3,minecraft:concrete:0)
Block(0,4,-2,minecraft:concrete:0)
Block(0,4,-1,minecraft:concrete:0)
Block(0,4,0,minecraft:concrete:0)
Block(0,4,1,minecraft:concrete:0)
Block(0,4,2,minecraft:concrete:0)
Block(0,5,-6,minecraft:concrete:0)
Block(0,5,-5,minecraft:stonebrick:0)
Block(0,5,-4,minecraft:stonebrick:0)
Block(0,5,-3,minecraft:stonebrick:0)
Block(0,5,-2,minecraft:stonebrick:0)
Block(0,5,-1,minecraft:stonebrick:0)
Block(0,5,0,minecraft:stonebrick:0)
Block(0,5,1,minecraft:stonebrick:0)
Block(0,5,2,minecraft:concrete:0)
Block(0,5,3,minecraft:concrete:0)
Block(0,5,4,minecraft:concrete:0)
Block(0,5,5,minecraft:concrete:0)
Block(0,5,6,minecraft:concrete:0)
Block(0,5,7,minecraft:concrete:0)
Block(0,5,8,minecraft:concrete:0)
Block(0,5,9,minecraft:concrete:0)
Block(0,6,-6,minecraft:concrete:0)
Block(0,6,-5,minecraft:stonebrick:0)
Block(0,6,-4,minecraft:stonebrick:1)
Block(0,6,-3,minecraft:stone:0)
Block(0,6,-2,AIR:0)
Block(0,6,-1,AIR:0)
Block(0,6,0,dregorarl_srpmanhunt:encounter_marker:13)
Block(0,6,1,minecraft:stone:0)
Block(0,6,2,minecraft:stonebrick:0)
Block(0,6,3,WEB:0)
Block(0,6,4,AIR:0)
Block(0,6,5,AIR:0)
Block(0,6,6,AIR:0)
Block(0,6,7,minecraft:concrete:0)
Block(0,6,8,minecraft:concrete:0)
Block(0,6,9,minecraft:concrete:0)
Block(0,7,-6,minecraft:concrete:0)
Block(0,7,-5,minecraft:stonebrick)
Block(0,7,-4,minecraft:stonebrick:1)
Block(0,7,-3,AIR:0)
Block(0,7,-2,AIR:0)
Block(0,7,-1,AIR:0)
Block(0,7,0,AIR:0)
Block(0,7,1,AIR:0)
Block(0,7,2,minecraft:iron_block:0)
Block(0,7,3,WEB:0)
Block(0,7,4,AIR:0)
Block(0,7,5,AIR:0)
Block(0,7,6,AIR:0)
Block(0,7,7,minecraft:concrete:0)
Block(0,7,8,minecraft:concrete:0)
Block(0,7,9,minecraft:concrete:0)
Block(0,8,-6,minecraft:concrete:0)
Block(0,8,-5,minecraft:stonebrick:1)
Block(0,8,-4,minecraft:stonebrick:1)
Block(0,8,-3,AIR:0)
Block(0,8,-2,quark:iron_button:2)
Block(0,8,-1,AIR:0)
Block(0,8,0,minecraft:glowstone:2)
Block(0,8,1,AIR:0)
Block(0,8,2,minecraft:stonebrick:0)
Block(0,8,3,minecraft:concrete:0)
Block(0,8,4,minecraft:concrete:0)
Block(0,8,5,minecraft:concrete:0)
Block(0,8,6,minecraft:concrete:0)
Block(0,8,7,minecraft:concrete:0)
Block(0,8,8,minecraft:concrete:0)
Block(0,8,9,minecraft:concrete:0)
Block(0,9,-6,minecraft:concrete:0)
Block(0,9,-5,minecraft:stonebrick:0)
Block(0,9,-4,minecraft:stonebrick:1)
Block(0,9,-3,AIR:0)
Block(0,9,-2,WALL_SIGN:4,f_bunker_mid_nuclear/100-sign.nbt)
Block(0,9,-1,AIR:0)
Block(0,9,0,WALL_SIGN:4,f_bunker_mid_nuclear/101-sign.nbt)
Block(0,9,1,minecraft:stonebrick:1)
Block(0,9,2,minecraft:concrete:0)
Block(0,9,3,AIR:0)
Block(0,9,4,AIR:0)
Block(0,9,5,WEB:0)
Block(0,9,6,AIR:0)
Block(0,9,7,minecraft:stonebrick:0)
Block(0,9,8,AIR:0)
Block(0,9,9,minecraft:concrete:0)
Block(0,10,-6,minecraft:concrete:0)
Block(0,10,-5,minecraft:stonebrick:0)
Block(0,10,-4,minecraft:stonebrick:0)
Block(0,10,-3,minecraft:stonebrick:0)
Block(0,10,-2,minecraft:stonebrick:0)
Block(0,10,-1,minecraft:stonebrick:0)
Block(0,10,0,minecraft:stonebrick:0)
Block(0,10,1,minecraft:stonebrick:0)
Block(0,10,2,minecraft:concrete:0)
Block(0,10,3,AIR:0)
Block(0,10,4,AIR:0)
Block(0,10,5,AIR:0)
Block(0,10,6,AIR:0)
Block(0,10,7,AIR:0)
Block(0,10,8,WEB:0)
Block(0,10,9,minecraft:concrete:0)
Block(0,11,-6,minecraft:concrete:0)
Block(0,11,-5,minecraft:concrete:0)
Block(0,11,-4,minecraft:concrete:0)
Block(0,11,-3,minecraft:concrete:0)
Block(0,11,-2,minecraft:concrete:0)
Block(0,11,-1,minecraft:concrete:0)
Block(0,11,0,minecraft:concrete:0)
Block(0,11,1,minecraft:concrete:0)
Block(0,11,2,minecraft:concrete:0)
Block(0,11,3,AIR:0)
Block(0,11,4,minecraft:concrete:0)
Block(0,11,5,minecraft:concrete:0)
Block(0,11,6,minecraft:concrete:0)
Block(0,11,7,minecraft:concrete:0)
Block(0,11,8,minecraft:concrete:0)
Block(0,11,9,minecraft:concrete:0)
