
#######################################################################
# +-----------------------------------------------------------------+ #
# |                            BO4 object                           | #
# +-----------------------------------------------------------------+ #
#######################################################################

# This is the config file of a custom object.
# If you add this object correctly to your BiomeConfigs, it will spawn in the world.

# This is the creator of this BO4 object
Author: NLBlackEagle

# A short description of this BO4 object
Description: No description given

# The settings mode, WriteAll, WriteWithoutComments or WriteDisable. See WorldConfig.
SettingsMode: WriteAll


#######################################################################
# +-----------------------------------------------------------------+ #
# |                          Main settings                          | #
# +-----------------------------------------------------------------+ #
#######################################################################

# If this BO4 should spawn with a fixed rotation, set it here.
# For example: NORTH, EAST, SOUTH or WEST. Empty by default
FixedRotation: 

# This BO4 can only spawn at least Frequency chunks distance away from any other BO4 with the exact same name.
# You can use this to make this BO4 spawn in groups or make sure that this BO4 only spawns once every X chunks.
Frequency: 0

# The spawn height of the BO4: randomY, highestBlock or highestSolidBlock.
SpawnHeight: highestBlock

# When set to true, uses the center of the structure (determined by minimum structure size) when checking the highestBlock to spawn at.
UseCenterForHighestBlock: true

##############################
# Height Limits for the BO4. #
##############################

# When in randomY mode used as the minimum Y or in atMinY mode as the actual Y to spawn this BO4 at.
MinHeight: 0

# When in randomY mode used as the maximum Y to spawn this BO4 at.
MaxHeight: 255

# Copies the blocks and branches of an existing BO4 into this BO4. You can still add blocks and branches in this BO4, they will be added on top of the inherited blocks and branches.
InheritBO3: 

# Rotates the inheritedBO3's resources (blocks, spawners, checks etc) and branches, defaults to NORTH (no rotation).
InheritBO3Rotation: NORTH

# Defaults to true, if true and this is the starting BO4 for this branching structure then this BO4's smoothing and height settings are used for all children (branches).
OverrideChildSettings: true

# Defaults to false, if true then this branch uses it's own height settings (SpawnHeight, minHeight, maxHeight, spawnAtWaterLevel) instead of those defined in the starting BO4 for this branching structure.
OverrideParentHeight: false

# If this is set to true then this BO4 can spawn on top of or inside an existing BO4. If this is set to false then this BO4 will use a bounding box to detect collisions with other BO4's, if a collision is detected then this BO4 won't spawn and the current branch is rolled back.
CanOverride: false

# This branch can only spawn at least branchFrequency chunks (x,z) distance away from any other branch with the exact same name.
BranchFrequency: 0

# Define groups that this branch belongs to along with a minimum (x,z) range in chunks that this branch must have between it and any other members of this group if it is to be allowed to spawn. Syntax is "GroupName:Frequency, GoupName2:Frequency2" etc so for example a branch that belongs to 3 groups: "BranchFrequencyGroup: Ships:10, Vehicles:5, FloatingThings:3".
BranchFrequencyGroup: 

# If this is set to true then this BO4 can only spawn underneath an existing BO4. Used to make sure that dungeons only appear underneath buildings.
MustBeBelowOther: false

# Used with CanOverride: true. A comma-seperated list of BO4s, this BO4's bounding box must collide with one of the BO4's in the list or this BO4 fails to spawn and the current branch is rolled back. AND/OR is supported, comma is OR, space is AND, f.e: branch1, branch2 branch3, branch 4.
MustBeInside: 

# Used with CanOverride: true. A comma-seperated list of BO4s, this BO4's bounding box cannot collide with any of the BO4's in the list or this BO4 fails to spawn and the current branch is rolled back.
CannotBeInside: 

# Used with CanOverride: true. A comma-seperated list of BO4s, if this BO4's bounding box collides with any of the BO4's in the list then those BO4's won't spawn any blocks. This does not remove or roll back any BO4's.
ReplacesBO3: 

# If this is set to true then this BO4 can only spawn inside world borders. Used to make sure that dungeons only appear inside the world borders.
MustBeInsideWorldBorders: true

# Defaults to true. Set to false if the BO4 is not allowed to spawn on a water block
CanSpawnOnWater: true

# Defaults to false. Set to true if the BO4 is allowed to spawn only on a water block
SpawnOnWaterOnly: false

# Defaults to false. Set to true if the BO4 and its smoothing area should ignore water when looking for the highest block to spawn on. Defaults to false (things spawn on top of water)
SpawnUnderWater: false

# Defaults to false. Set to true if the BO4 should spawn at water level
SpawnAtWaterLevel: false

# Spawns the BO4 at a Y offset of this value. Handy when using highestBlock for lowering BO4s into the surrounding terrain when there are layers of ground included in the BO4, also handy when using SpawnAtWaterLevel to lower objects like ships into the water.
HeightOffset: 0

# If set to true removes all AIR blocks from the BO4 so that it can be flooded or buried.
RemoveAir: false

# Replaces all the non-air blocks that are above this BO4 or its smoothing area with the given block material (should be WATER or AIR or NONE), also applies to smoothing areas although OTG intentionally leaves some of the terrain above them intact. WATER can be used in combination with SpawnUnderWater to fill any air blocks underneath waterlevel with water (and any above waterlevel with air).
ReplaceAbove: 

# Replaces all air blocks underneath the BO4 (but not its smoothing area) with the specified material until a solid block is found.
ReplaceBelow: 

# Defaults to true. If set to true then every block in the BO4 of the materials defined in ReplaceWithGroundBlock or ReplaceWithSurfaceBlock will be replaced by the GroundBlock or SurfaceBlock materials configured for the biome the block is spawned in.
ReplaceWithBiomeBlocks: true

# Defaults to GRASS, Replaces all the blocks of the given material in the BO4 with the SurfaceBlock configured for the biome it spawns in.
ReplaceWithSurfaceBlock: GRASS

# Defaults to DIRT, Replaces all the blocks of the given material in the BO4 with the GroundBlock configured for the biome it spawns in.
ReplaceWithGroundBlock: DIRT

# Defaults to STONE, Replaces all the blocks of the given material in the BO4 with the StoneBlock configured for the biome it spawns in.
ReplaceWithStoneBlock: STONE

# Makes the terrain around the BO4 slope evenly towards the edges of the BO4. The given value is the distance in blocks around the BO4 from where the slope should start and can be any positive number.
SmoothRadius: 0

# Moves the smoothing area up or down relative to the BO4 (at the points where the smoothing area is connected to the BO4). Handy when using SmoothStartTop: false and the BO4 has some layers of ground included, in that case we can set the HeightOffset to a negative value to lower the BO4 into the ground and we can set the SmoothHeightOffset to a positive value to move the smoothing area starting height up.
SmoothHeightOffset: 0

# Should the smoothing area be attached at the bottom or the top of the edges of the BO4? Defaults to false (bottom). Using this setting can make things slower so try to avoid using it and use SmoothHeightOffset instead if for instance you have a BO4 with some ground layers included. The only reason you should need to use this setting is if you have a BO4 with edges that have an irregular height (like some hills).
SmoothStartTop: false

# Should the smoothing area attach itself to "log" block or ignore them? Defaults to false (ignore logs).
SmoothStartWood: false

# The block used for smoothing area surface blocks, defaults to biome SurfaceBlock.
SmoothingSurfaceBlock: 

# The block used for smoothing area ground blocks, defaults to biome GroundBlock.
SmoothingGroundBlock: 

# Define groups that this BO4 belongs to along with a minimum range in chunks that this BO4 must have between it and any other members of this group if it is to be allowed to spawn. Syntax is "GroupName:Frequency, GoupName2:Frequency2" etc so for example a BO4 that belongs to 3 groups: "BO4Group: Ships:10, Vehicles:5, FloatingThings:3".
BO3Group: 

# Defaults to false. Set to true if this BO4 should spawn at the player spawn point. When the server starts the spawn point is determined and the BO4's for the biome it is in are loaded, one of these BO4s that has IsSpawnPoint set to true (if any) is selected randomly and is spawned at the spawn point regardless of its rarity (so even Rarity:0, IsSpawnPoint: true BO4's can get spawned as the spawn point!).
IsSpawnPoint: false

# Defaults to true. Set to false to make the BO4 ignore any ReplacedBlocks settings in Biome Configs.
DoReplaceBlocks: true


#######################################################################
# +-----------------------------------------------------------------+ #
# |                              Blocks                             | #
# +-----------------------------------------------------------------+ #
#######################################################################

# All the blocks used in the BO4 are listed here. Possible blocks:
# Block(x,y,z,id[.data][,nbtfile.nbt)
# RandomBlock(x,y,z,id[:data][,nbtfile.nbt],chance[,id[:data][,nbtfile.nbt],chance[,...]])
#  So RandomBlock(0,0,0,CHEST,chest.nbt,50,CHEST,anotherchest.nbt,100) will spawn a chest at
#  the BO4 origin, and give it a 50% chance to have the contents of chest.nbt, or, if that
#  fails, a 100% percent chance to have the contents of anotherchest.nbt.
# MinecraftObject(x,y,z,name) (TODO: This may not work anymore and needs to be tested.
#  Spawns an object in the Mojang NBT structure format. For example, 
#  MinecraftObject(0,0,0,minecraft:igloo/igloo_bottom)
#  spawns the bottom part of an igloo.
Block(-7,0,-6,CONCRETE:0)
Block(-7,0,-5,CONCRETE:0)
Block(-7,0,-4,CONCRETE:0)
Block(-7,0,-3,CONCRETE:0)
Block(-7,0,-2,CONCRETE:0)
Block(-7,0,-1,CONCRETE:0)
Block(-7,0,0,CONCRETE:0)
Block(-7,0,1,CONCRETE:0)
Block(-7,0,2,CONCRETE:0)
Block(-7,0,3,CONCRETE:0)
Block(-7,0,4,CONCRETE:0)
Block(-7,0,5,CONCRETE:0)
Block(-7,0,6,CONCRETE:0)
Block(-7,0,7,CONCRETE:0)
Block(-7,0,8,CONCRETE:0)
Block(-7,0,9,CONCRETE:0)
Block(-7,1,-6,CONCRETE:0)
Block(-7,1,-5,CONCRETE:0)
Block(-7,1,-4,CONCRETE:0)
Block(-7,1,-3,CONCRETE:0)
Block(-7,1,-2,CONCRETE:0)
Block(-7,1,-1,CONCRETE:0)
Block(-7,1,0,CONCRETE:0)
Block(-7,1,1,CONCRETE:0)
Block(-7,1,2,CONCRETE:0)
Block(-7,1,3,CONCRETE:0)
Block(-7,1,4,CONCRETE:0)
Block(-7,1,5,CONCRETE:0)
Block(-7,1,6,CONCRETE:0)
Block(-7,1,7,CONCRETE:0)
Block(-7,1,8,CONCRETE:0)
Block(-7,1,9,CONCRETE:0)
Block(-7,2,-6,CONCRETE:0)
Block(-7,2,-5,CONCRETE:0)
Block(-7,2,-4,CONCRETE:0)
Block(-7,2,-3,CONCRETE:0)
Block(-7,2,-2,CONCRETE:0)
Block(-7,2,-1,CONCRETE:0)
Block(-7,2,0,CONCRETE:0)
Block(-7,2,1,CONCRETE:0)
Block(-7,2,2,CONCRETE:0)
Block(-7,2,3,CONCRETE:0)
Block(-7,2,4,CONCRETE:0)
Block(-7,2,5,CONCRETE:0)
Block(-7,2,6,CONCRETE:0)
Block(-7,2,7,CONCRETE:0)
Block(-7,2,8,CONCRETE:0)
Block(-7,2,9,CONCRETE:0)
Block(-7,3,-6,CONCRETE:0)
Block(-7,3,-5,CONCRETE:0)
Block(-7,3,-4,CONCRETE:0)
Block(-7,3,-3,CONCRETE:0)
Block(-7,3,-2,CONCRETE:0)
Block(-7,3,-1,CONCRETE:0)
Block(-7,3,0,CONCRETE:0)
Block(-7,3,1,CONCRETE:0)
Block(-7,3,2,CONCRETE:0)
Block(-7,3,3,CONCRETE:0)
Block(-7,3,4,CONCRETE:0)
Block(-7,3,5,CONCRETE:0)
Block(-7,3,6,CONCRETE:0)
Block(-7,3,7,CONCRETE:0)
Block(-7,3,8,CONCRETE:0)
Block(-7,3,9,CONCRETE:0)
Block(-7,4,-6,CONCRETE:0)
Block(-7,4,-5,CONCRETE:0)
Block(-7,4,-4,CONCRETE:0)
Block(-7,4,-3,CONCRETE:0)
Block(-7,4,-2,CONCRETE:0)
Block(-7,4,-1,CONCRETE:0)
Block(-7,4,0,CONCRETE:0)
Block(-7,4,1,CONCRETE:0)
Block(-7,4,2,CONCRETE:0)
Block(-7,4,3,CONCRETE:0)
Block(-7,4,4,CONCRETE:0)
Block(-7,4,5,CONCRETE:0)
Block(-7,4,6,CONCRETE:0)
Block(-7,4,7,CONCRETE:0)
Block(-7,4,8,CONCRETE:0)
Block(-7,4,9,CONCRETE:0)
Block(-7,5,-6,CONCRETE:0)
Block(-7,5,-5,CONCRETE:0)
Block(-7,5,-4,CONCRETE:0)
Block(-7,5,-3,CONCRETE:0)
Block(-7,5,-2,CONCRETE:0)
Block(-7,5,-1,CONCRETE:0)
Block(-7,5,0,CONCRETE:0)
Block(-7,5,1,CONCRETE:0)
Block(-7,5,2,CONCRETE:0)
Block(-7,5,3,CONCRETE:0)
Block(-7,5,4,CONCRETE:0)
Block(-7,5,5,CONCRETE:0)
Block(-7,5,6,CONCRETE:0)
Block(-7,5,7,CONCRETE:0)
Block(-7,5,8,CONCRETE:0)
Block(-7,5,9,CONCRETE:0)
Block(-7,6,-6,CONCRETE:0)
Block(-7,6,-5,CONCRETE:0)
Block(-7,6,-4,CONCRETE:0)
Block(-7,6,-3,CONCRETE:0)
Block(-7,6,-2,CONCRETE:0)
Block(-7,6,-1,CONCRETE:0)
Block(-7,6,0,CONCRETE:0)
Block(-7,6,1,CONCRETE:0)
Block(-7,6,2,CONCRETE:0)
Block(-7,6,3,CONCRETE:0)
Block(-7,6,4,CONCRETE:0)
Block(-7,6,5,CONCRETE:0)
Block(-7,6,6,CONCRETE:0)
Block(-7,6,7,CONCRETE:0)
Block(-7,6,8,CONCRETE:0)
Block(-7,6,9,CONCRETE:0)
Block(-7,7,-6,CONCRETE:0)
Block(-7,7,-5,CONCRETE:0)
Block(-7,7,-4,CONCRETE:0)
Block(-7,7,-3,CONCRETE:0)
Block(-7,7,-2,CONCRETE:0)
Block(-7,7,-1,CONCRETE:0)
Block(-7,7,0,CONCRETE:0)
Block(-7,7,1,CONCRETE:0)
Block(-7,7,2,CONCRETE:0)
Block(-7,7,3,CONCRETE:0)
Block(-7,7,4,CONCRETE:0)
Block(-7,7,5,CONCRETE:0)
Block(-7,7,6,CONCRETE:0)
Block(-7,7,7,CONCRETE:0)
Block(-7,7,8,CONCRETE:0)
Block(-7,7,9,CONCRETE:0)
Block(-7,8,-2,CONCRETE:0)
Block(-7,8,5,CONCRETE:0)
Block(-7,8,8,CONCRETE:0)
Block(-7,9,-2,CONCRETE:0)
Block(-7,9,5,CONCRETE:0)
Block(-7,9,8,CONCRETE:0)
Block(-7,10,-2,CONCRETE:0)
Block(-7,10,5,CONCRETE:0)
Block(-7,10,8,CONCRETE:0)
Block(-7,11,-2,CONCRETE:0)
Block(-7,11,5,CONCRETE:0)
Block(-7,11,8,CONCRETE:0)
Block(-7,12,-2,CONCRETE:0)
Block(-7,12,5,CONCRETE:0)
Block(-7,12,8,CONCRETE:0)
Block(-7,13,-2,CONCRETE:0)
Block(-7,13,5,CONCRETE:0)
Block(-7,13,8,CONCRETE:0)
Block(-7,14,-2,CONCRETE:0)
Block(-7,14,5,CONCRETE:0)
Block(-7,14,8,CONCRETE:0)
Block(-7,15,-2,CONCRETE:0)
Block(-7,15,5,CONCRETE:0)
Block(-7,15,8,CONCRETE:0)
Block(-7,16,-2,CONCRETE:0)
Block(-7,16,-1,CONCRETE:0)
Block(-7,16,0,CONCRETE:0)
Block(-7,16,1,CONCRETE:0)
Block(-7,16,2,CONCRETE:0)
Block(-7,16,3,CONCRETE:0)
Block(-7,16,4,CONCRETE:0)
Block(-7,16,5,CONCRETE:0)
Block(-7,16,8,CONCRETE:0)
Block(-7,17,-2,CONCRETE:0)
Block(-7,17,-1,CONCRETE:0)
Block(-7,17,0,CONCRETE:0)
Block(-7,17,1,CONCRETE:0)
Block(-7,17,2,CONCRETE:0)
Block(-7,17,3,CONCRETE:0)
Block(-7,17,4,CONCRETE:0)
Block(-7,17,5,CONCRETE:0)
Block(-7,17,8,CONCRETE:0)
Block(-7,18,-2,CONCRETE:0)
Block(-7,18,-1,CONCRETE:0)
Block(-7,18,0,CONCRETE:0)
Block(-7,18,1,CONCRETE:0)
Block(-7,18,2,CONCRETE:0)
Block(-7,18,3,CONCRETE:0)
Block(-7,18,4,CONCRETE:0)
Block(-7,18,5,CONCRETE:0)
Block(-7,18,6,CONCRETE:0)
Block(-7,18,7,CONCRETE:0)
Block(-7,18,8,CONCRETE:0)
Block(-7,19,-2,CONCRETE:0)
Block(-7,19,-1,CONCRETE:0)
Block(-7,19,0,CONCRETE:0)
Block(-7,19,1,CONCRETE:0)
Block(-7,19,2,CONCRETE:0)
Block(-7,19,3,CONCRETE:0)
Block(-7,19,4,CONCRETE:0)
Block(-7,19,5,CONCRETE:0)
Block(-7,19,6,CONCRETE:0)
Block(-7,19,7,CONCRETE:0)
Block(-7,19,8,CONCRETE:0)
Block(-7,20,-2,CONCRETE:0)
Block(-7,20,-1,CONCRETE:0)
Block(-7,20,0,CONCRETE:0)
Block(-7,20,1,CONCRETE:0)
Block(-7,20,2,CONCRETE:0)
Block(-7,20,3,CONCRETE:0)
Block(-7,20,4,CONCRETE:0)
Block(-7,20,5,CONCRETE:0)
Block(-7,20,6,CONCRETE:0)
Block(-7,20,7,CONCRETE:0)
Block(-7,20,8,CONCRETE:0)
Block(-7,21,-2,CONCRETE:0)
Block(-7,21,-1,CONCRETE:0)
Block(-7,21,0,CONCRETE:0)
Block(-7,21,1,CONCRETE:0)
Block(-7,21,2,CONCRETE:0)
Block(-7,21,3,CONCRETE:0)
Block(-7,21,4,CONCRETE:0)
Block(-7,21,5,CONCRETE:0)
Block(-7,21,6,CONCRETE:0)
Block(-7,21,7,CONCRETE:0)
Block(-7,21,8,CONCRETE:0)
Block(-7,22,-2,CONCRETE:0)
Block(-7,22,-1,CONCRETE:0)
Block(-7,22,0,CONCRETE:0)
Block(-7,22,1,CONCRETE:0)
Block(-7,22,2,CONCRETE:0)
Block(-7,22,3,CONCRETE:0)
Block(-7,22,4,CONCRETE:0)
Block(-7,22,5,CONCRETE:0)
Block(-6,0,-6,CONCRETE:0)
Block(-6,0,-5,CONCRETE:0)
Block(-6,0,-4,CONCRETE:0)
Block(-6,0,-3,CONCRETE:0)
Block(-6,0,-2,CONCRETE:0)
Block(-6,0,-1,CONCRETE:0)
Block(-6,0,0,CONCRETE:0)
Block(-6,0,1,CONCRETE:0)
Block(-6,0,2,CONCRETE:0)
Block(-6,0,3,CONCRETE:0)
Block(-6,0,4,CONCRETE:0)
Block(-6,0,5,CONCRETE:0)
Block(-6,0,6,CONCRETE:0)
Block(-6,0,7,CONCRETE:0)
Block(-6,0,8,CONCRETE:0)
Block(-6,0,9,CONCRETE:0)
Block(-6,1,-6,CONCRETE:0)
Block(-6,1,-5,CONCRETE:0)
Block(-6,1,-4,CONCRETE:0)
Block(-6,1,-3,CONCRETE:0)
Block(-6,1,-2,CONCRETE:0)
Block(-6,1,-1,CONCRETE:0)
Block(-6,1,0,CONCRETE:0)
Block(-6,1,1,CONCRETE:0)
Block(-6,1,2,CONCRETE:0)
Block(-6,1,3,CONCRETE:0)
Block(-6,1,4,CONCRETE:0)
Block(-6,1,5,CONCRETE:0)
Block(-6,1,6,CONCRETE:0)
Block(-6,1,7,CONCRETE:0)
Block(-6,1,8,CONCRETE:0)
Block(-6,1,9,CONCRETE:0)
Block(-6,2,-6,CONCRETE:0)
Block(-6,2,-5,CONCRETE:0)
Block(-6,2,-4,CONCRETE:0)
Block(-6,2,-3,CONCRETE:0)
Block(-6,2,-2,CONCRETE:0)
Block(-6,2,-1,CONCRETE:0)
Block(-6,2,0,CONCRETE:0)
Block(-6,2,1,CONCRETE:0)
Block(-6,2,2,CONCRETE:0)
Block(-6,2,3,CONCRETE:0)
Block(-6,2,4,CONCRETE:0)
Block(-6,2,5,CONCRETE:0)
Block(-6,2,6,CONCRETE:0)
Block(-6,2,7,CONCRETE:0)
Block(-6,2,8,CONCRETE:0)
Block(-6,2,9,CONCRETE:0)
Block(-6,3,-6,CONCRETE:0)
RandomBlock(-6,3,-5,WOOD:5,5,WOOD:5,../../../Chests/Loot/manhunt_vagrant_scrap.nbt,100)
RandomBlock(-6,3,-4,WOOD:5,5,WOOD:5,../../../Chests/Loot/manhunt_vagrant_scrap.nbt,100)
Block(-6,3,-3,AIR:0)
Block(-6,3,-2,AIR:0)
Block(-6,3,-1,WOOD:0)
Block(-6,3,0,WOOD:0)
Block(-6,3,1,AIR:0)
Block(-6,3,2,AIR:0)
Block(-6,3,3,AIR:0)
Block(-6,3,4,AIR:0)
Block(-6,3,5,AIR:0)
Block(-6,3,6,AIR:0)
RandomBlock(-6,3,7,WOOD:5,5,WOOD:5,../../../Chests/Loot/manhunt_vagrant_scrap.nbt,100)
RandomBlock(-6,3,8,WOOD:5,5,WOOD:5,../../../Chests/Loot/manhunt_vagrant_scrap.nbt,100)
Block(-6,3,9,CONCRETE:0)
Block(-6,4,-6,CONCRETE:0)
RandomBlock(-6,4,-5,WOOD:5,5,WOOD:5,../../../Chests/Loot/manhunt_vagrant_scrap.nbt,100)
Block(-6,4,-4,CHEST:5,../../../Chests/Loot/manhunt_military_common.nbt)
Block(-6,4,-3,AIR:0)
Block(-6,4,-2,AIR:0)
Block(-6,4,-1,WOOD:0)
Block(-6,4,0,WOOD:0)
Block(-6,4,1,AIR:0)
Block(-6,4,2,AIR:0)
Block(-6,4,3,AIR:0)
Block(-6,4,4,AIR:0)
Block(-6,4,5,AIR:0)
Block(-6,4,6,AIR:0)
Block(-6,4,7,AIR:0)
RandomBlock(-6,4,8,WOOD:5,5,WOOD:5,../../../Chests/Loot/manhunt_vagrant_scrap.nbt,100)
Block(-6,4,9,CONCRETE:0)
Block(-6,5,-6,CONCRETE:0)
RandomBlock(-6,5,-5,WOOD:5,5,WOOD:5,../../../Chests/Loot/manhunt_vagrant_scrap.nbt,100)
Block(-6,5,-4,AIR:0)
Block(-6,5,-3,WEB:0)
Block(-6,5,-2,AIR:0)
Block(-6,5,-1,AIR:0)
Block(-6,5,0,AIR:0)
Block(-6,5,1,AIR:0)
Block(-6,5,2,AIR:0)
Block(-6,5,3,AIR:0)
Block(-6,5,4,AIR:0)
Block(-6,5,5,AIR:0)
Block(-6,5,6,AIR:0)
Block(-6,5,7,AIR:0)
Block(-6,5,8,AIR:0)
Block(-6,5,9,CONCRETE:0)
Block(-6,6,-6,CONCRETE:0)
Block(-6,6,-5,AIR:0)
Block(-6,6,-4,WEB:0)
Block(-6,6,-3,WEB:0)
Block(-6,6,-2,AIR:0)
Block(-6,6,-1,AIR:0)
Block(-6,6,0,AIR:0)
Block(-6,6,1,AIR:0)
Block(-6,6,2,AIR:0)
Block(-6,6,3,AIR:0)
Block(-6,6,4,STEP:8)
Block(-6,6,5,AIR:0)
Block(-6,6,6,AIR:0)
Block(-6,6,7,AIR:0)
Block(-6,6,8,AIR:0)
Block(-6,6,9,CONCRETE:0)
Block(-6,7,-6,CONCRETE:0)
Block(-6,7,-5,CONCRETE:0)
Block(-6,7,-4,CONCRETE:0)
Block(-6,7,-3,CONCRETE:0)
Block(-6,7,-2,CONCRETE:0)
Block(-6,7,-1,CONCRETE:0)
Block(-6,7,0,CONCRETE:0)
Block(-6,7,1,CONCRETE:0)
Block(-6,7,2,CONCRETE:0)
Block(-6,7,3,CONCRETE:0)
Block(-6,7,4,CONCRETE:0)
Block(-6,7,5,CONCRETE:0)
Block(-6,7,6,CONCRETE:0)
Block(-6,7,7,CONCRETE:0)
Block(-6,7,8,CONCRETE:0)
Block(-6,7,9,CONCRETE:0)
Block(-6,8,-5,CONCRETE:0)
Block(-6,9,-5,CONCRETE:0)
Block(-6,10,-5,CONCRETE:0)
Block(-6,11,-5,CONCRETE:0)
Block(-6,12,-5,CONCRETE:0)
Block(-6,13,-5,CONCRETE:0)
Block(-6,14,-5,CONCRETE:0)
Block(-6,15,-5,CONCRETE:0)
Block(-6,16,-5,CONCRETE:0)
Block(-6,16,-2,CONCRETE:0)
Block(-6,16,-1,CONCRETE:0)
Block(-6,16,0,CONCRETE:0)
Block(-6,16,1,CONCRETE:0)
Block(-6,16,2,CONCRETE:0)
Block(-6,16,3,CONCRETE:0)
Block(-6,16,4,CONCRETE:0)
Block(-6,16,5,CONCRETE:0)
Block(-6,17,-5,CONCRETE:0)
Block(-6,17,-2,CONCRETE:0)
Block(-6,17,-1,CONCRETE:0)
Block(-6,17,0,CONCRETE:0)
Block(-6,17,1,DROPPER:1,f_bunker_storage/13-dropper.nbt)
Block(-6,17,2,DROPPER:1,f_bunker_storage/14-dropper.nbt)
Block(-6,17,3,CONCRETE:0)
Block(-6,17,4,CONCRETE:0)
Block(-6,17,5,CONCRETE:0)
Block(-6,18,-5,CONCRETE:0)
Block(-6,18,-4,CONCRETE:0)
Block(-6,18,-3,CONCRETE:0)
Block(-6,18,-2,CONCRETE:0)
Block(-6,18,-1,CONCRETE:0)
Block(-6,18,0,CONCRETE:0)
Block(-6,18,1,quark:grate:0)
Block(-6,18,2,quark:grate:0)
Block(-6,18,3,CONCRETE:0)
Block(-6,18,4,CONCRETE:0)
Block(-6,18,5,CONCRETE:0)
Block(-6,18,6,CONCRETE:0)
Block(-6,18,7,CONCRETE:0)
Block(-6,18,8,CONCRETE:0)
Block(-6,19,-5,CONCRETE:0)
Block(-6,19,-4,CONCRETE:0)
Block(-6,19,-3,CONCRETE:0)
Block(-6,19,-2,CONCRETE:0)
Block(-6,19,-1,WEB:0)
Block(-6,19,0,AIR:0)
Block(-6,19,1,AIR:0)
Block(-6,19,2,AIR:0)
Block(-6,19,3,SMOOTH_BRICK:0)
Block(-6,19,4,AIR:0)
Block(-6,19,5,CONCRETE:0)
Block(-6,19,6,CONCRETE:0)
Block(-6,19,7,CONCRETE:0)
Block(-6,19,8,CONCRETE:0)
Block(-6,20,-5,CONCRETE:0)
Block(-6,20,-4,CONCRETE:0)
Block(-6,20,-3,CONCRETE:0)
Block(-6,20,-2,CONCRETE:0)
Block(-6,20,-1,AIR:0)
Block(-6,20,0,AIR:0)
Block(-6,20,1,AIR:0)
Block(-6,20,2,AIR:0)
Block(-6,20,3,AIR:0)
Block(-6,20,4,WEB:0)
Block(-6,20,5,CONCRETE:0)
Block(-6,20,6,CONCRETE:0)
Block(-6,20,7,CONCRETE:0)
Block(-6,20,8,CONCRETE:0)
Block(-6,21,-5,CONCRETE:0)
Block(-6,21,-4,CONCRETE:0)
Block(-6,21,-3,CONCRETE:0)
Block(-6,21,-2,CONCRETE:0)
Block(-6,21,-1,STEP:8)
Block(-6,21,0,STEP:8)
Block(-6,21,1,quark:grate:0)
Block(-6,21,2,quark:grate:0)
Block(-6,21,3,STEP:8)
Block(-6,21,4,STEP:8)
Block(-6,21,5,CONCRETE:0)
Block(-6,21,6,CONCRETE:0)
Block(-6,21,7,CONCRETE:0)
Block(-6,21,8,CONCRETE:0)
Block(-6,22,-2,CONCRETE:0)
Block(-6,22,-1,CONCRETE:0)
Block(-6,22,0,CONCRETE:0)
Block(-6,22,1,CONCRETE:0)
Block(-6,22,2,CONCRETE:0)
Block(-6,22,3,CONCRETE:0)
Block(-6,22,4,CONCRETE:0)
Block(-6,22,5,CONCRETE:0)
Block(-5,0,-6,CONCRETE:0)
Block(-5,0,-5,CONCRETE:0)
Block(-5,0,-4,CONCRETE:0)
Block(-5,0,-3,CONCRETE:0)
Block(-5,0,-2,CONCRETE:0)
Block(-5,0,-1,CONCRETE:0)
Block(-5,0,0,CONCRETE:0)
Block(-5,0,1,CONCRETE:0)
Block(-5,0,2,CONCRETE:0)
Block(-5,0,3,CONCRETE:0)
Block(-5,0,4,CONCRETE:0)
Block(-5,0,5,CONCRETE:0)
Block(-5,0,6,CONCRETE:0)
Block(-5,0,7,CONCRETE:0)
Block(-5,0,8,CONCRETE:0)
Block(-5,0,9,CONCRETE:0)
Block(-5,1,-6,CONCRETE:0)
Block(-5,1,-5,CONCRETE:0)
Block(-5,1,-4,CONCRETE:0)
Block(-5,1,-3,CONCRETE:0)
Block(-5,1,-2,CONCRETE:0)
Block(-5,1,-1,CONCRETE:0)
Block(-5,1,0,CONCRETE:0)
Block(-5,1,1,CONCRETE:0)
Block(-5,1,2,CONCRETE:0)
Block(-5,1,3,CONCRETE:0)
Block(-5,1,4,CONCRETE:0)
Block(-5,1,5,CONCRETE:0)
Block(-5,1,6,CONCRETE:0)
Block(-5,1,7,CONCRETE:0)
Block(-5,1,8,CONCRETE:0)
Block(-5,1,9,CONCRETE:0)
Block(-5,2,-6,CONCRETE:0)
Block(-5,2,-5,CONCRETE:0)
Block(-5,2,-4,CONCRETE:0)
Block(-5,2,-3,CONCRETE:0)
Block(-5,2,-2,CONCRETE:0)
Block(-5,2,-1,CONCRETE:0)
Block(-5,2,0,CONCRETE:0)
Block(-5,2,1,CONCRETE:0)
Block(-5,2,2,CONCRETE:0)
Block(-5,2,3,CONCRETE:0)
Block(-5,2,4,CONCRETE:0)
Block(-5,2,5,CONCRETE:0)
Block(-5,2,6,CONCRETE:0)
Block(-5,2,7,CONCRETE:0)
Block(-5,2,8,CONCRETE:0)
Block(-5,2,9,CONCRETE:0)
Block(-5,3,-6,CONCRETE:0)
RandomBlock(-5,3,-5,WOOD:5,5,WOOD:5,../../../Chests/Loot/manhunt_vagrant_scrap.nbt,100)
Block(-5,3,-4,SMOOTH_BRICK:3)
Block(-5,3,-3,AIR:0)
Block(-5,3,-2,CONCRETE:4)
Block(-5,3,-1,AIR:0)
Block(-5,3,0,SMOOTH_BRICK:0)
Block(-5,3,1,SMOOTH_BRICK:0)
Block(-5,3,2,CONCRETE:4)
RandomBlock(-5,3,3,WOOD:5,5,WOOD:5,../../../Chests/Loot/manhunt_vagrant_scrap.nbt,100)
Block(-5,3,4,AIR:0)
RandomBlock(-5,3,5,WOOD:5,5,WOOD:5,../../../Chests/Loot/manhunt_vagrant_scrap.nbt,100)
Block(-5,3,6,CONCRETE:4)
Block(-5,3,7,SKULL:1,f_bunker_storage/19-skull.nbt)
RandomBlock(-5,3,8,WOOD:5,5,WOOD:5,../../../Chests/Loot/manhunt_vagrant_scrap.nbt,100)
Block(-5,3,9,CONCRETE:0)
Block(-5,4,-6,CONCRETE:0)
RandomBlock(-5,4,-5,WOOD:5,5,WOOD:5,../../../Chests/Loot/manhunt_vagrant_scrap.nbt,100)
Block(-5,4,-4,AIR:0)
Block(-5,4,-3,AIR:0)
Block(-5,4,-2,CONCRETE:0)
Block(-5,4,-1,AIR:0)
Block(-5,4,0,AIR:0)
Block(-5,4,1,AIR:0)
Block(-5,4,2,CONCRETE:0)
RandomBlock(-5,4,3,WOOD:5,5,WOOD:5,../../../Chests/Loot/manhunt_vagrant_scrap.nbt,100)
Block(-5,4,4,AIR:0)
Block(-5,4,5,WEB:0)
Block(-5,4,6,CONCRETE:0)
Block(-5,4,7,AIR:0)
Block(-5,4,8,AIR:0)
Block(-5,4,9,CONCRETE:0)
Block(-5,5,-6,CONCRETE:0)
Block(-5,5,-5,AIR:0)
Block(-5,5,-4,AIR:0)
Block(-5,5,-3,AIR:0)
Block(-5,5,-2,CONCRETE:0)
Block(-5,5,-1,AIR:0)
Block(-5,5,0,AIR:0)
Block(-5,5,1,AIR:0)
Block(-5,5,2,CONCRETE:0)
Block(-5,5,3,AIR:0)
Block(-5,5,4,WEB:0)
Block(-5,5,5,AIR:0)
Block(-5,5,6,CONCRETE:0)
Block(-5,5,7,AIR:0)
Block(-5,5,8,AIR:0)
Block(-5,5,9,CONCRETE:0)
Block(-5,6,-6,CONCRETE:0)
Block(-5,6,-5,AIR:0)
Block(-5,6,-4,AIR:0)
Block(-5,6,-3,AIR:0)
Block(-5,6,-2,CONCRETE:0)
Block(-5,6,-1,AIR:0)
Block(-5,6,0,AIR:0)
Block(-5,6,1,AIR:0)
Block(-5,6,2,CONCRETE:0)
Block(-5,6,3,WEB:0)
Block(-5,6,4,STEP:8)
Block(-5,6,5,WEB:0)
Block(-5,6,6,CONCRETE:0)
Block(-5,6,7,AIR:0)
Block(-5,6,8,AIR:0)
Block(-5,6,9,CONCRETE:0)
Block(-5,7,-6,CONCRETE:0)
Block(-5,7,-5,CONCRETE:0)
Block(-5,7,-4,CONCRETE:0)
Block(-5,7,-3,CONCRETE:0)
Block(-5,7,-2,CONCRETE:0)
Block(-5,7,-1,CONCRETE:0)
Block(-5,7,0,CONCRETE:0)
Block(-5,7,1,CONCRETE:0)
Block(-5,7,2,CONCRETE:0)
Block(-5,7,3,CONCRETE:0)
Block(-5,7,4,CONCRETE:0)
Block(-5,7,5,CONCRETE:0)
Block(-5,7,6,CONCRETE:0)
Block(-5,7,7,CONCRETE:0)
Block(-5,7,8,CONCRETE:0)
Block(-5,7,9,CONCRETE:0)
Block(-5,16,-2,CONCRETE:0)
Block(-5,16,-1,CONCRETE:0)
Block(-5,16,0,CONCRETE:0)
Block(-5,16,1,CONCRETE:0)
Block(-5,16,2,CONCRETE:0)
Block(-5,16,3,CONCRETE:0)
Block(-5,16,4,CONCRETE:0)
Block(-5,16,5,CONCRETE:0)
Block(-5,17,-2,CONCRETE:0)
Block(-5,17,-1,quark:lit_lamp:0)
Block(-5,17,0,CONCRETE:0)
Block(-5,17,1,DROPPER:1,f_bunker_storage/23-dropper.nbt)
Block(-5,17,2,DROPPER:1,f_bunker_storage/24-dropper.nbt)
Block(-5,17,3,CONCRETE:0)
Block(-5,17,4,quark:lit_lamp:0)
Block(-5,17,5,CONCRETE:0)
Block(-5,18,-5,CONCRETE:0)
Block(-5,18,-4,CONCRETE:0)
Block(-5,18,-3,CONCRETE:0)
Block(-5,18,-2,CONCRETE:0)
Block(-5,18,-1,quark:grate:0)
Block(-5,18,0,CONCRETE:0)
Block(-5,18,1,quark:grate:0)
Block(-5,18,2,quark:grate:0)
Block(-5,18,3,CONCRETE:0)
Block(-5,18,4,quark:grate:0)
Block(-5,18,5,CONCRETE:0)
Block(-5,18,6,CONCRETE:0)
Block(-5,18,7,CONCRETE:0)
Block(-5,18,8,CONCRETE:0)
Block(-5,19,-5,CONCRETE:0)
Block(-5,19,-4,CONCRETE:0)
Block(-5,19,-3,CONCRETE:0)
Block(-5,19,-2,CONCRETE:0)
Block(-5,19,-1,AIR:0)
Block(-5,19,0,AIR:0)
Block(-5,19,1,AIR:0)
Block(-5,19,2,AIR:0)
Block(-5,19,3,AIR:0)
Block(-5,19,4,AIR:0)
Block(-5,19,5,CONCRETE:0)
Block(-5,19,6,CONCRETE:0)
Block(-5,19,7,CONCRETE:0)
Block(-5,19,8,CONCRETE:0)
Block(-5,20,-5,CONCRETE:0)
Block(-5,20,-4,REDSTONE_WIRE:0)
Block(-5,20,-3,REDSTONE_WIRE:0)
Block(-5,20,-2,IRON_BLOCK:0)
Block(-5,20,-1,quark:iron_button:3)
Block(-5,20,0,AIR:0)
Block(-5,20,1,AIR:0)
Block(-5,20,2,AIR:0)
Block(-5,20,3,AIR:0)
Block(-5,20,4,quark:iron_button:4)
Block(-5,20,5,IRON_BLOCK:0)
Block(-5,20,6,REDSTONE_WIRE:0)
Block(-5,20,7,REDSTONE_WIRE:0)
Block(-5,20,8,CONCRETE:0)
Block(-5,21,-5,CONCRETE:0)
Block(-5,21,-4,CONCRETE:0)
Block(-5,21,-3,CONCRETE:0)
Block(-5,21,-2,CONCRETE:0)
Block(-5,21,-1,STEP:8)
Block(-5,21,0,STEP:8)
Block(-5,21,1,quark:grate:0)
Block(-5,21,2,quark:grate:0)
Block(-5,21,3,STEP:8)
Block(-5,21,4,STEP:8)
Block(-5,21,5,CONCRETE:0)
Block(-5,21,6,CONCRETE:0)
Block(-5,21,7,CONCRETE:0)
Block(-5,21,8,CONCRETE:0)
Block(-5,22,-2,CONCRETE:0)
Block(-5,22,-1,CONCRETE:0)
Block(-5,22,0,CONCRETE:0)
Block(-5,22,1,CONCRETE:0)
Block(-5,22,2,CONCRETE:0)
Block(-5,22,3,CONCRETE:0)
Block(-5,22,4,CONCRETE:0)
Block(-5,22,5,CONCRETE:0)
Block(-4,0,-6,CONCRETE:0)
Block(-4,0,-5,CONCRETE:0)
Block(-4,0,-4,CONCRETE:0)
Block(-4,0,-3,CONCRETE:0)
Block(-4,0,-2,CONCRETE:0)
Block(-4,0,-1,CONCRETE:0)
Block(-4,0,0,CONCRETE:0)
Block(-4,0,1,CONCRETE:0)
Block(-4,0,2,CONCRETE:0)
Block(-4,0,3,CONCRETE:0)
Block(-4,0,4,CONCRETE:0)
Block(-4,0,5,CONCRETE:0)
Block(-4,0,6,CONCRETE:0)
Block(-4,0,7,CONCRETE:0)
Block(-4,0,8,CONCRETE:0)
Block(-4,0,9,CONCRETE:0)
Block(-4,1,-6,CONCRETE:0)
Block(-4,1,-5,CONCRETE:0)
Block(-4,1,-4,CONCRETE:0)
Block(-4,1,-3,CONCRETE:0)
Block(-4,1,-2,CONCRETE:0)
Block(-4,1,-1,CONCRETE:0)
Block(-4,1,0,CONCRETE:0)
Block(-4,1,1,CONCRETE:0)
Block(-4,1,2,CONCRETE:0)
Block(-4,1,3,CONCRETE:0)
Block(-4,1,4,CONCRETE:0)
Block(-4,1,5,CONCRETE:0)
Block(-4,1,6,CONCRETE:0)
Block(-4,1,7,CONCRETE:0)
Block(-4,1,8,CONCRETE:0)
Block(-4,1,9,CONCRETE:0)
Block(-4,2,-6,CONCRETE:0)
Block(-4,2,-5,CONCRETE:0)
Block(-4,2,-4,CONCRETE:0)
Block(-4,2,-3,CONCRETE:0)
Block(-4,2,-2,CONCRETE:0)
Block(-4,2,-1,CONCRETE:0)
Block(-4,2,0,CONCRETE:0)
Block(-4,2,1,CONCRETE:0)
Block(-4,2,2,CONCRETE:0)
Block(-4,2,3,CONCRETE:0)
Block(-4,2,4,CONCRETE:0)
Block(-4,2,5,CONCRETE:0)
Block(-4,2,6,CONCRETE:0)
Block(-4,2,7,CONCRETE:0)
Block(-4,2,8,CONCRETE:0)
Block(-4,2,9,CONCRETE:0)
Block(-4,3,-6,CONCRETE:0)
RandomBlock(-4,3,-5,WOOD:5,5,WOOD:5,../../../Chests/Loot/manhunt_vagrant_scrap.nbt,100)
Block(-4,3,-4,AIR:0)
Block(-4,3,-3,AIR:0)
Block(-4,3,-2,SMOOTH_BRICK:0)
Block(-4,3,-1,AIR:0)
Block(-4,3,0,AIR:0)
Block(-4,3,1,SMOOTH_BRICK:0)
Block(-4,3,2,AIR:0)
Block(-4,3,3,AIR:0)
Block(-4,3,4,AIR:0)
Block(-4,3,5,SMOOTH_BRICK:0)
Block(-4,3,6,BONE_BLOCK:4)
Block(-4,3,7,AIR:0)
Block(-4,3,8,BONE_BLOCK:0)
Block(-4,3,9,CONCRETE:0)
Block(-4,4,-6,CONCRETE:0)
Block(-4,4,-5,AIR:0)
Block(-4,4,-4,AIR:0)
Block(-4,4,-3,AIR:0)
Block(-4,4,-2,AIR:0)
Block(-4,4,-1,AIR:0)
Block(-4,4,0,AIR:0)
Block(-4,4,1,AIR:0)
Block(-4,4,2,AIR:0)
Block(-4,4,3,AIR:0)
Block(-4,4,4,AIR:0)
Block(-4,4,5,AIR:0)
Block(-4,4,6,AIR:0)
Block(-4,4,7,AIR:0)
Block(-4,4,8,SMOOTH_BRICK)
Block(-4,4,9,CONCRETE:0)
Block(-4,5,-6,CONCRETE:0)
Block(-4,5,-5,AIR:0)
Block(-4,5,-4,AIR:0)
Block(-4,5,-3,AIR:0)
Block(-4,5,-2,AIR:0)
Block(-4,5,-1,AIR:0)
Block(-4,5,0,AIR:0)
Block(-4,5,1,AIR:0)
Block(-4,5,2,AIR:0)
Block(-4,5,3,AIR:0)
Block(-4,5,4,AIR:0)
Block(-4,5,5,AIR:0)
Block(-4,5,6,AIR:0)
Block(-4,5,7,AIR:0)
Block(-4,5,8,AIR:0)
Block(-4,5,9,CONCRETE:0)
Block(-4,6,-6,CONCRETE:0)
Block(-4,6,-5,WEB:0)
Block(-4,6,-4,AIR:0)
Block(-4,6,-3,AIR:0)
Block(-4,6,-2,AIR:0)
Block(-4,6,-1,AIR:0)
Block(-4,6,0,AIR:0)
Block(-4,6,1,AIR:0)
Block(-4,6,2,AIR:0)
Block(-4,6,3,AIR:0)
Block(-4,6,4,STEP:8)
Block(-4,6,5,AIR:0)
Block(-4,6,6,AIR:0)
Block(-4,6,7,AIR:0)
Block(-4,6,8,AIR:0)
Block(-4,6,9,CONCRETE:0)
Block(-4,7,-6,CONCRETE:0)
Block(-4,7,-5,CONCRETE:0)
Block(-4,7,-4,CONCRETE:0)
Block(-4,7,-3,CONCRETE:0)
Block(-4,7,-2,CONCRETE:0)
Block(-4,7,-1,CONCRETE:0)
Block(-4,7,0,CONCRETE:0)
Block(-4,7,1,CONCRETE:0)
Block(-4,7,2,CONCRETE:0)
Block(-4,7,3,CONCRETE:0)
Block(-4,7,4,CONCRETE:0)
Block(-4,7,5,CONCRETE:0)
Block(-4,7,6,CONCRETE:0)
Block(-4,7,7,CONCRETE:0)
Block(-4,7,8,CONCRETE:0)
Block(-4,7,9,CONCRETE:0)
Block(-4,8,-2,CONCRETE:0)
Block(-4,9,-2,CONCRETE:0)
Block(-4,10,-2,CONCRETE:0)
Block(-4,11,-2,CONCRETE:0)
Block(-4,12,-2,CONCRETE:0)
Block(-4,13,-2,CONCRETE:0)
Block(-4,14,-2,CONCRETE:0)
Block(-4,15,-2,CONCRETE:0)
Block(-4,16,-2,CONCRETE:0)
Block(-4,16,-1,CONCRETE:0)
Block(-4,16,0,CONCRETE:0)
Block(-4,16,1,CONCRETE:0)
Block(-4,16,2,CONCRETE:0)
Block(-4,16,3,CONCRETE:0)
Block(-4,16,4,CONCRETE:0)
Block(-4,16,5,CONCRETE:0)
Block(-4,17,-2,CONCRETE:0)
Block(-4,17,-1,CONCRETE:0)
Block(-4,17,0,CONCRETE:0)
Block(-4,17,1,DROPPER:1,f_bunker_storage/27-dropper.nbt)
Block(-4,17,2,DROPPER:1,f_bunker_storage/28-dropper.nbt)
Block(-4,17,3,CONCRETE:0)
Block(-4,17,4,CONCRETE:0)
Block(-4,17,5,CONCRETE:0)
Block(-4,18,-5,CONCRETE:0)
Block(-4,18,-4,CONCRETE:0)
Block(-4,18,-3,CONCRETE:0)
Block(-4,18,-2,CONCRETE:0)
Block(-4,18,-1,CONCRETE:0)
Block(-4,18,0,CONCRETE:0)
Block(-4,18,1,quark:grate:0)
Block(-4,18,2,quark:grate:0)
Block(-4,18,3,CONCRETE:0)
Block(-4,18,4,CONCRETE:0)
Block(-4,18,5,CONCRETE:0)
Block(-4,18,6,CONCRETE:0)
Block(-4,18,7,CONCRETE:0)
Block(-4,18,8,CONCRETE:0)
Block(-4,19,-5,CONCRETE:0)
Block(-4,19,-4,CONCRETE:0)
Block(-4,19,-3,CONCRETE:0)
Block(-4,19,-2,CONCRETE:0)
Block(-4,19,-1,AIR:0)
Block(-4,19,0,SMOOTH_BRICK:0)
Block(-4,19,1,AIR:0)
Block(-4,19,2,AIR:0)
Block(-4,19,3,AIR:0)
Block(-4,19,4,AIR:0)
Block(-4,19,5,CONCRETE:0)
Block(-4,19,6,CONCRETE:0)
Block(-4,19,7,CONCRETE:0)
Block(-4,19,8,CONCRETE:0)
Block(-4,20,-5,CONCRETE:0)
Block(-4,20,-4,REDSTONE_WIRE:0)
Block(-4,20,-3,CONCRETE:0)
Block(-4,20,-2,CONCRETE:0)
Block(-4,20,-1,AIR:0)
Block(-4,20,0,AIR:0)
Block(-4,20,1,AIR:0)
Block(-4,20,2,AIR:0)
Block(-4,20,3,AIR:0)
Block(-4,20,4,AIR:0)
Block(-4,20,5,CONCRETE:0)
Block(-4,20,6,CONCRETE:0)
Block(-4,20,7,REDSTONE_WIRE:0)
Block(-4,20,8,CONCRETE:0)
Block(-4,21,-5,CONCRETE:0)
Block(-4,21,-4,CONCRETE:0)
Block(-4,21,-3,CONCRETE:0)
Block(-4,21,-2,CONCRETE:0)
Block(-4,21,-1,STEP:8)
Block(-4,21,0,STEP:8)
Block(-4,21,1,quark:grate:0)
Block(-4,21,2,quark:grate:0)
Block(-4,21,3,STEP:8)
Block(-4,21,4,STEP:8)
Block(-4,21,5,CONCRETE:0)
Block(-4,21,6,CONCRETE:0)
Block(-4,21,7,CONCRETE:0)
Block(-4,21,8,CONCRETE:0)
Block(-4,22,-2,CONCRETE:0)
Block(-4,22,-1,CONCRETE:0)
Block(-4,22,0,CONCRETE:0)
Block(-4,22,1,CONCRETE:0)
Block(-4,22,2,CONCRETE:0)
Block(-4,22,3,CONCRETE:0)
Block(-4,22,4,CONCRETE:0)
Block(-4,22,5,CONCRETE:0)
Block(-3,0,-6,CONCRETE:0)
Block(-3,0,-5,CONCRETE:0)
Block(-3,0,-4,CONCRETE:0)
Block(-3,0,-3,CONCRETE:0)
Block(-3,0,-2,CONCRETE:0)
Block(-3,0,-1,CONCRETE:0)
Block(-3,0,0,CONCRETE:0)
Block(-3,0,1,CONCRETE:0)
Block(-3,0,2,CONCRETE:0)
Block(-3,0,3,CONCRETE:0)
Block(-3,0,4,CONCRETE:0)
Block(-3,0,5,CONCRETE:0)
Block(-3,0,6,CONCRETE:0)
Block(-3,0,7,CONCRETE:0)
Block(-3,0,8,CONCRETE:0)
Block(-3,0,9,CONCRETE:0)
Block(-3,1,-6,CONCRETE:0)
Block(-3,1,-5,CONCRETE:0)
Block(-3,1,-4,quark:lit_lamp:0)
Block(-3,1,-3,CONCRETE:0)
Block(-3,1,-2,CONCRETE:0)
Block(-3,1,-1,CONCRETE:0)
Block(-3,1,0,quark:lit_lamp:0)
Block(-3,1,1,CONCRETE:0)
Block(-3,1,2,CONCRETE:0)
Block(-3,1,3,CONCRETE:0)
Block(-3,1,4,quark:lit_lamp:0)
Block(-3,1,5,CONCRETE:0)
Block(-3,1,6,CONCRETE:0)
Block(-3,1,7,CONCRETE:0)
Block(-3,1,8,CONCRETE:0)
Block(-3,1,9,CONCRETE:0)
Block(-3,2,-6,CONCRETE:0)
Block(-3,2,-5,CONCRETE:0)
Block(-3,2,-4,quark:grate:0)
Block(-3,2,-3,CONCRETE:0)
Block(-3,2,-2,CONCRETE:0)
Block(-3,2,-1,CONCRETE:0)
Block(-3,2,0,quark:grate:0)
Block(-3,2,1,CONCRETE:0)
Block(-3,2,2,CONCRETE:0)
Block(-3,2,3,CONCRETE:0)
Block(-3,2,4,quark:grate:0)
Block(-3,2,5,CONCRETE:0)
Block(-3,2,6,CONCRETE:0)
Block(-3,2,7,CONCRETE:0)
Block(-3,2,8,CONCRETE:0)
Block(-3,2,9,CONCRETE:0)
Block(-3,3,-6,CONCRETE:0)
Block(-3,3,-5,AIR:0)
Block(-3,3,-4,AIR:0)
Block(-3,3,-3,AIR:0)
Block(-3,3,-2,AIR:0)
Block(-3,3,-1,AIR:0)
Block(-3,3,0,AIR:0)
Block(-3,3,1,AIR:0)
Block(-3,3,2,AIR:0)
Block(-3,3,3,AIR:0)
Block(-3,3,4,AIR:0)
Block(-3,3,5,AIR:0)
Block(-3,3,6,CARPET:0)
Block(-3,3,7,AIR:0)
Block(-3,3,8,WOOD:1)
Block(-3,3,9,CONCRETE:0)
Block(-3,4,-6,CONCRETE:0)
Block(-3,4,-5,AIR:0)
Block(-3,4,-4,AIR:0)
Block(-3,4,-3,AIR:0)
Block(-3,4,-2,AIR:0)
Block(-3,4,-1,AIR:0)
Block(-3,4,0,AIR:0)
Block(-3,4,1,AIR:0)
Block(-3,4,2,AIR:0)
Block(-3,4,3,AIR:0)
Block(-3,4,4,AIR:0)
Block(-3,4,5,AIR:0)
Block(-3,4,6,AIR:0)
Block(-3,4,7,AIR:0)
Block(-3,4,8,SMOOTH_BRICK)
Block(-3,4,9,CONCRETE:0)
Block(-3,5,-6,CONCRETE:0)
Block(-3,5,-5,WEB:0)
Block(-3,5,-4,AIR:0)
Block(-3,5,-3,AIR:0)
Block(-3,5,-2,AIR:0)
Block(-3,5,-1,AIR:0)
Block(-3,5,0,AIR:0)
Block(-3,5,1,AIR:0)
Block(-3,5,2,AIR:0)
Block(-3,5,3,AIR:0)
Block(-3,5,4,quark:grate:0)
Block(-3,5,5,AIR:0)
Block(-3,5,6,AIR:0)
Block(-3,5,7,AIR:0)
Block(-3,5,8,AIR:0)
Block(-3,5,9,CONCRETE:0)
Block(-3,6,-6,CONCRETE:0)
Block(-3,6,-5,WEB:0)
Block(-3,6,-4,AIR:0)
Block(-3,6,-3,AIR:0)
Block(-3,6,-2,AIR:0)
Block(-3,6,-1,AIR:0)
Block(-3,6,0,AIR:0)
Block(-3,6,1,AIR:0)
Block(-3,6,2,AIR:0)
Block(-3,6,3,AIR:0)
Block(-3,6,4,DROPPER:0,f_bunker_storage/31-dropper.nbt)
Block(-3,6,5,AIR:0)
Block(-3,6,6,AIR:0)
Block(-3,6,7,AIR:0)
Block(-3,6,8,AIR:0)
Block(-3,6,9,CONCRETE:0)
Block(-3,7,-6,CONCRETE:0)
Block(-3,7,-5,CONCRETE:0)
Block(-3,7,-4,CONCRETE:0)
Block(-3,7,-3,CONCRETE:0)
Block(-3,7,-2,CONCRETE:0)
Block(-3,7,-1,CONCRETE:0)
Block(-3,7,0,CONCRETE:0)
Block(-3,7,1,CONCRETE:0)
Block(-3,7,2,CONCRETE:0)
Block(-3,7,3,CONCRETE:0)
Block(-3,7,4,CONCRETE:0)
Block(-3,7,5,CONCRETE:0)
Block(-3,7,6,CONCRETE:0)
Block(-3,7,7,CONCRETE:0)
Block(-3,7,8,CONCRETE:0)
Block(-3,7,9,CONCRETE:0)
Block(-3,17,-1,CONCRETE:0)
Block(-3,17,0,CONCRETE:0)
Block(-3,17,1,CONCRETE:0)
Block(-3,17,2,CONCRETE:0)
Block(-3,17,3,CONCRETE:0)
Block(-3,17,4,CONCRETE:0)
Block(-3,18,-5,CONCRETE:0)
Block(-3,18,-4,CONCRETE:0)
Block(-3,18,-3,CONCRETE:0)
Block(-3,18,-2,CONCRETE:0)
Block(-3,18,-1,CONCRETE:0)
Block(-3,18,0,CONCRETE:0)
Block(-3,18,1,CONCRETE:0)
Block(-3,18,2,CONCRETE:0)
Block(-3,18,3,CONCRETE:0)
Block(-3,18,4,CONCRETE:0)
Block(-3,18,5,CONCRETE:0)
Block(-3,18,6,CONCRETE:0)
Block(-3,18,7,CONCRETE:0)
Block(-3,18,8,CONCRETE:0)
Block(-3,19,-5,CONCRETE:0)
Block(-3,19,-4,CONCRETE:0)
Block(-3,19,-3,CONCRETE:0)
Block(-3,19,-2,CONCRETE:0)
Block(-3,19,-1,CONCRETE:0)
Block(-3,19,0,AIR:0)
Block(-3,19,1,CONCRETE:0)
Block(-3,19,2,CONCRETE:0)
Block(-3,19,3,AIR:0)
Block(-3,19,4,CONCRETE:0)
Block(-3,19,5,CONCRETE:0)
Block(-3,19,6,CONCRETE:0)
Block(-3,19,7,CONCRETE:0)
Block(-3,19,8,CONCRETE:0)
Block(-3,20,-5,CONCRETE:0)
Block(-3,20,-4,REDSTONE_WIRE:0)
Block(-3,20,-3,CONCRETE:0)
Block(-3,20,-2,CONCRETE:0)
Block(-3,20,-1,CONCRETE:0)
Block(-3,20,0,AIR:0)
Block(-3,20,1,CONCRETE:0)
Block(-3,20,2,CONCRETE:0)
Block(-3,20,3,AIR:0)
Block(-3,20,4,CONCRETE:0)
Block(-3,20,5,CONCRETE:0)
Block(-3,20,6,CONCRETE:0)
Block(-3,20,7,REDSTONE_WIRE:0)
Block(-3,20,8,CONCRETE:0)
Block(-3,21,-5,CONCRETE:0)
Block(-3,21,-4,CONCRETE:0)
Block(-3,21,-3,CONCRETE:0)
Block(-3,21,-2,CONCRETE:0)
Block(-3,21,-1,CONCRETE:0)
Block(-3,21,0,CONCRETE:0)
Block(-3,21,1,CONCRETE:0)
Block(-3,21,2,CONCRETE:0)
Block(-3,21,3,CONCRETE:0)
Block(-3,21,4,CONCRETE:0)
Block(-3,21,5,CONCRETE:0)
Block(-3,21,6,CONCRETE:0)
Block(-3,21,7,CONCRETE:0)
Block(-3,21,8,CONCRETE:0)
Block(-3,22,-2,CONCRETE:0)
Block(-3,22,-1,CONCRETE:0)
Block(-3,22,0,CONCRETE:0)
Block(-3,22,1,CONCRETE:0)
Block(-3,22,2,CONCRETE:0)
Block(-3,22,3,CONCRETE:0)
Block(-3,22,4,CONCRETE:0)
Block(-3,22,5,CONCRETE:0)
Block(-2,0,-6,CONCRETE:0)
Block(-2,0,-5,CONCRETE:0)
Block(-2,0,-4,CONCRETE:0)
Block(-2,0,-3,CONCRETE:0)
Block(-2,0,-2,CONCRETE:0)
Block(-2,0,-1,CONCRETE:0)
Block(-2,0,0,CONCRETE:0)
Block(-2,0,1,CONCRETE:0)
Block(-2,0,2,CONCRETE:0)
Block(-2,0,3,CONCRETE:0)
Block(-2,0,4,CONCRETE:0)
Block(-2,0,5,CONCRETE:0)
Block(-2,0,6,CONCRETE:0)
Block(-2,0,7,CONCRETE:0)
Block(-2,0,8,CONCRETE:0)
Block(-2,0,9,CONCRETE:0)
Block(-2,1,-6,CONCRETE:0)
Block(-2,1,-5,CONCRETE:0)
Block(-2,1,-4,CONCRETE:0)
Block(-2,1,-3,CONCRETE:0)
Block(-2,1,-2,CONCRETE:0)
Block(-2,1,-1,CONCRETE:0)
Block(-2,1,0,CONCRETE:0)
Block(-2,1,1,CONCRETE:0)
Block(-2,1,2,CONCRETE:0)
Block(-2,1,3,CONCRETE:0)
Block(-2,1,4,CONCRETE:0)
Block(-2,1,5,CONCRETE:0)
Block(-2,1,6,CONCRETE:0)
Block(-2,1,7,CONCRETE:0)
Block(-2,1,8,CONCRETE:0)
Block(-2,1,9,CONCRETE:0)
Block(-2,2,-6,CONCRETE:0)
Block(-2,2,-5,CONCRETE:0)
Block(-2,2,-4,CONCRETE:0)
Block(-2,2,-3,CONCRETE:0)
Block(-2,2,-2,CONCRETE:0)
Block(-2,2,-1,CONCRETE:0)
Block(-2,2,0,CONCRETE:0)
Block(-2,2,1,CONCRETE:0)
Block(-2,2,2,CONCRETE:0)
Block(-2,2,3,CONCRETE:0)
Block(-2,2,4,CONCRETE:0)
Block(-2,2,5,CONCRETE:0)
Block(-2,2,6,CONCRETE:0)
Block(-2,2,7,CONCRETE:0)
Block(-2,2,8,CONCRETE:0)
Block(-2,2,9,CONCRETE:0)
Block(-2,3,-6,CONCRETE:0)
Block(-2,3,-5,AIR:0)
Block(-2,3,-4,SMOOTH_BRICK:0)
Block(-2,3,-3,AIR:0)
RandomBlock(-2,3,-2,WOOD:5,5,WOOD:5,../../../Chests/Loot/manhunt_vagrant_scrap.nbt,100)
Block(-2,3,-1,AIR:0)
Block(-2,3,0,AIR:0)
Block(-2,3,1,SMOOTH_BRICK:3)
Block(-2,3,2,AIR:0)
Block(-2,3,3,AIR:0)
Block(-2,3,4,AIR:0)
RandomBlock(-2,3,5,WOOD:5,5,WOOD:5,../../../Chests/Loot/manhunt_vagrant_scrap.nbt,100)
Block(-2,3,6,CARPET:0)
Block(-2,3,7,BONE_BLOCK:4)
Block(-2,3,8,WOOD:1)
Block(-2,3,9,CONCRETE:0)
Block(-2,4,-6,CONCRETE:0)
Block(-2,4,-5,AIR:0)
Block(-2,4,-4,AIR:0)
Block(-2,4,-3,AIR:0)
RandomBlock(-2,4,-2,WOOD:5,5,WOOD:5,../../../Chests/Loot/manhunt_vagrant_scrap.nbt,100)
Block(-2,4,-1,AIR:0)
Block(-2,4,0,AIR:0)
Block(-2,4,1,AIR:0)
Block(-2,4,2,AIR:0)
Block(-2,4,3,AIR:0)
Block(-2,4,4,AIR:0)
RandomBlock(-2,4,5,WOOD:5,5,WOOD:5,../../../Chests/Loot/manhunt_vagrant_scrap.nbt,100)
Block(-2,4,6,AIR:0)
Block(-2,4,7,AIR:0)
Block(-2,4,8,AIR:0)
Block(-2,4,9,CONCRETE:0)
Block(-2,5,-6,CONCRETE:0)
Block(-2,5,-5,AIR:0)
Block(-2,5,-4,AIR:0)
Block(-2,5,-3,AIR:0)
Block(-2,5,-2,AIR:0)
Block(-2,5,-1,AIR:0)
Block(-2,5,0,AIR:0)
Block(-2,5,1,AIR:0)
Block(-2,5,2,AIR:0)
Block(-2,5,3,AIR:0)
Block(-2,5,4,AIR:0)
Block(-2,5,5,AIR:0)
Block(-2,5,6,AIR:0)
Block(-2,5,7,AIR:0)
Block(-2,5,8,AIR:0)
Block(-2,5,9,CONCRETE:0)
Block(-2,6,-6,CONCRETE:0)
Block(-2,6,-5,WEB:0)
Block(-2,6,-4,AIR:0)
Block(-2,6,-3,AIR:0)
Block(-2,6,-2,AIR:0)
Block(-2,6,-1,AIR:0)
Block(-2,6,0,AIR:0)
Block(-2,6,1,AIR:0)
Block(-2,6,2,AIR:0)
Block(-2,6,3,AIR:0)
Block(-2,6,4,STEP:8)
Block(-2,6,5,AIR:0)
Block(-2,6,6,AIR:0)
Block(-2,6,7,AIR:0)
Block(-2,6,8,AIR:0)
Block(-2,6,9,CONCRETE:0)
Block(-2,7,-6,CONCRETE:0)
Block(-2,7,-5,CONCRETE:0)
Block(-2,7,-4,CONCRETE:0)
Block(-2,7,-3,CONCRETE:0)
Block(-2,7,-2,CONCRETE:0)
Block(-2,7,-1,CONCRETE:0)
Block(-2,7,0,CONCRETE:0)
Block(-2,7,1,CONCRETE:0)
Block(-2,7,2,CONCRETE:0)
Block(-2,7,3,CONCRETE:0)
Block(-2,7,4,CONCRETE:0)
Block(-2,7,5,CONCRETE:0)
Block(-2,7,6,CONCRETE:0)
Block(-2,7,7,CONCRETE:0)
Block(-2,7,8,CONCRETE:0)
Block(-2,7,9,CONCRETE:0)
Block(-2,17,-1,CONCRETE:0)
Block(-2,17,0,CONCRETE:0)
Block(-2,17,1,CONCRETE:0)
Block(-2,17,2,CONCRETE:0)
Block(-2,17,3,CONCRETE:0)
Block(-2,17,4,CONCRETE:0)
Block(-2,18,-5,CONCRETE:0)
Block(-2,18,-4,CONCRETE:0)
Block(-2,18,-3,CONCRETE:0)
Block(-2,18,-2,CONCRETE:0)
Block(-2,18,-1,CONCRETE:0)
Block(-2,18,0,CONCRETE:0)
Block(-2,18,1,CONCRETE:0)
Block(-2,18,2,IRON_BLOCK:0)
Block(-2,18,3,IRON_BLOCK:0)
Block(-2,18,4,IRON_BLOCK:0)
Block(-2,18,5,CONCRETE:0)
Block(-2,18,6,CONCRETE:0)
Block(-2,18,7,CONCRETE:0)
Block(-2,18,8,CONCRETE:0)
Block(-2,19,-5,CONCRETE:0)
Block(-2,19,-4,CONCRETE:0)
Block(-2,19,-3,CONCRETE:0)
Block(-2,19,-2,PISTON_STICKY_BASE:11)
Block(-2,19,-1,PISTON_MOVING_PIECE:11)
Block(-2,19,0,IRON_BLOCK:0)
Block(-2,19,1,IRON_BLOCK:0)
Block(-2,19,2,IRON_BLOCK:0)
Block(-2,19,3,IRON_BLOCK:0)
Block(-2,19,4,PISTON_MOVING_PIECE:10)
Block(-2,19,5,PISTON_STICKY_BASE:10)
Block(-2,19,6,CONCRETE:0)
Block(-2,19,7,CONCRETE:0)
Block(-2,19,8,CONCRETE:0)
Block(-2,20,-5,CONCRETE:0)
Block(-2,20,-4,CONCRETE:0)
Block(-2,20,-3,REDSTONE_TORCH_ON:3)
Block(-2,20,-2,PISTON_STICKY_BASE:11)
Block(-2,20,-1,PISTON_MOVING_PIECE:11)
Block(-2,20,0,IRON_BLOCK:0)
Block(-2,20,1,IRON_BLOCK:0)
Block(-2,20,2,IRON_BLOCK:0)
Block(-2,20,3,IRON_BLOCK:0)
Block(-2,20,4,PISTON_MOVING_PIECE:10)
Block(-2,20,5,PISTON_STICKY_BASE:10)
Block(-2,20,6,REDSTONE_TORCH_ON:4)
Block(-2,20,7,CONCRETE:0)
Block(-2,20,8,CONCRETE:0)
Block(-2,21,-5,CONCRETE:0)
Block(-2,21,-4,CONCRETE:0)
Block(-2,21,-3,CONCRETE:0)
Block(-2,21,-2,CONCRETE:0)
Block(-2,21,-1,IRON_BLOCK:0)
Block(-2,21,0,IRON_BLOCK:0)
Block(-2,21,1,IRON_BLOCK:0)
Block(-2,21,2,IRON_BLOCK:0)
Block(-2,21,3,IRON_BLOCK:0)
Block(-2,21,4,IRON_BLOCK:0)
Block(-2,21,5,CONCRETE:0)
Block(-2,21,6,CONCRETE:0)
Block(-2,21,7,CONCRETE:0)
Block(-2,21,8,CONCRETE:0)
Block(-1,0,-6,CONCRETE:0)
Block(-1,0,-5,CONCRETE:0)
Block(-1,0,-4,CONCRETE:0)
Block(-1,0,-3,CONCRETE:0)
Block(-1,0,-2,CONCRETE:0)
Block(-1,0,-1,CONCRETE:0)
Block(-1,0,0,CONCRETE:0)
Block(-1,0,1,CONCRETE:0)
Block(-1,0,2,CONCRETE:0)
Block(-1,0,3,CONCRETE:0)
Block(-1,0,4,CONCRETE:0)
Block(-1,0,5,CONCRETE:0)
Block(-1,0,6,CONCRETE:0)
Block(-1,0,7,CONCRETE:0)
Block(-1,0,8,CONCRETE:0)
Block(-1,0,9,CONCRETE:0)
Block(-1,1,-6,CONCRETE:0)
Block(-1,1,-5,CONCRETE:0)
Block(-1,1,-4,CONCRETE:0)
Block(-1,1,-3,CONCRETE:0)
Block(-1,1,-2,CONCRETE:0)
Block(-1,1,-1,CONCRETE:0)
Block(-1,1,0,CONCRETE:0)
Block(-1,1,1,CONCRETE:0)
Block(-1,1,2,CONCRETE:0)
Block(-1,1,3,CONCRETE:0)
Block(-1,1,4,CONCRETE:0)
Block(-1,1,5,CONCRETE:0)
Block(-1,1,6,CONCRETE:0)
Block(-1,1,7,CONCRETE:0)
Block(-1,1,8,CONCRETE:0)
Block(-1,1,9,CONCRETE:0)
Block(-1,2,-6,CONCRETE:0)
Block(-1,2,-5,CONCRETE:0)
Block(-1,2,-4,CONCRETE:0)
Block(-1,2,-3,CONCRETE:0)
Block(-1,2,-2,CONCRETE:0)
Block(-1,2,-1,CONCRETE:0)
Block(-1,2,0,CONCRETE:0)
Block(-1,2,1,CONCRETE:0)
Block(-1,2,2,CONCRETE:0)
Block(-1,2,3,CONCRETE:0)
Block(-1,2,4,CONCRETE:0)
Block(-1,2,5,CONCRETE:0)
Block(-1,2,6,CONCRETE:0)
Block(-1,2,7,CONCRETE:0)
Block(-1,2,8,CONCRETE:0)
Block(-1,2,9,CONCRETE:0)
Block(-1,3,-6,CONCRETE:0)
Block(-1,3,-5,WOOD:1)
Block(-1,3,-4,WEB:0)
Block(-1,3,-3,AIR:0)
Block(-1,3,-2,CONCRETE:4)
Block(-1,3,-1,AIR:0)
Block(-1,3,0,SMOOTH_BRICK:0)
Block(-1,3,1,dregorarl_srpmanhunt:encounter_marker:12)
Block(-1,3,2,CONCRETE:4)
Block(-1,3,3,WOOD:1)
Block(-1,3,4,AIR:0)
RandomBlock(-1,3,5,WOOD:5,5,WOOD:5,../../../Chests/Loot/manhunt_vagrant_scrap.nbt,100)
Block(-1,3,6,CONCRETE:4)
RandomBlock(-1,3,7,WOOD:5,5,WOOD:5,../../../Chests/Loot/manhunt_vagrant_scrap.nbt,100)
RandomBlock(-1,3,8,WOOD:5,5,WOOD:5,../../../Chests/Loot/manhunt_vagrant_scrap.nbt,100)
Block(-1,3,9,CONCRETE:0)
Block(-1,4,-6,CONCRETE:0)
Block(-1,4,-5,AIR:0)
Block(-1,4,-4,AIR:0)
Block(-1,4,-3,WEB:0)
Block(-1,4,-2,CONCRETE:0)
Block(-1,4,-1,AIR:0)
Block(-1,4,0,AIR:0)
Block(-1,4,1,AIR:0)
Block(-1,4,2,CONCRETE:0)
Block(-1,4,3,AIR:0)
Block(-1,4,4,AIR:0)
RandomBlock(-1,4,5,WOOD:5,5,WOOD:5,../../../Chests/Loot/manhunt_vagrant_scrap.nbt,100)
Block(-1,4,6,CONCRETE:0)
Block(-1,4,7,WEB:0)
Block(-1,4,8,AIR:0)
Block(-1,4,9,CONCRETE:0)
Block(-1,5,-6,CONCRETE:0)
Block(-1,5,-5,AIR:0)
Block(-1,5,-4,AIR:0)
Block(-1,5,-3,AIR:0)
Block(-1,5,-2,CONCRETE:0)
Block(-1,5,-1,AIR:0)
Block(-1,5,0,AIR:0)
Block(-1,5,1,AIR:0)
Block(-1,5,2,CONCRETE:0)
Block(-1,5,3,AIR:0)
Block(-1,5,4,AIR:0)
Block(-1,5,5,AIR:0)
Block(-1,5,6,CONCRETE:0)
Block(-1,5,7,AIR:0)
Block(-1,5,8,WEB:0)
Block(-1,5,9,CONCRETE:0)
Block(-1,6,-6,CONCRETE:0)
Block(-1,6,-5,WEB:0)
Block(-1,6,-4,AIR:0)
Block(-1,6,-3,AIR:0)
Block(-1,6,-2,CONCRETE:0)
Block(-1,6,-1,AIR:0)
Block(-1,6,0,AIR:0)
Block(-1,6,1,WEB:0)
Block(-1,6,2,CONCRETE:0)
Block(-1,6,3,AIR:0)
Block(-1,6,4,STEP:8)
Block(-1,6,5,AIR:0)
Block(-1,6,6,CONCRETE:0)
Block(-1,6,7,AIR:0)
Block(-1,6,8,AIR:0)
Block(-1,6,9,CONCRETE:0)
Block(-1,7,-6,CONCRETE:0)
Block(-1,7,-5,CONCRETE:0)
Block(-1,7,-4,CONCRETE:0)
Block(-1,7,-3,CONCRETE:0)
Block(-1,7,-2,CONCRETE:0)
Block(-1,7,-1,CONCRETE:0)
Block(-1,7,0,CONCRETE:0)
Block(-1,7,1,CONCRETE:0)
Block(-1,7,2,CONCRETE:0)
Block(-1,7,3,CONCRETE:0)
Block(-1,7,4,CONCRETE:0)
Block(-1,7,5,CONCRETE:0)
Block(-1,7,6,CONCRETE:0)
Block(-1,7,7,CONCRETE:0)
Block(-1,7,8,CONCRETE:0)
Block(-1,7,9,CONCRETE:0)
Block(-1,17,-1,CONCRETE:0)
Block(-1,17,0,CONCRETE:0)
Block(-1,17,1,CONCRETE:0)
Block(-1,17,2,CONCRETE:0)
Block(-1,17,3,CONCRETE:0)
Block(-1,17,4,CONCRETE:0)
Block(-1,18,-5,CONCRETE:0)
Block(-1,18,-4,CONCRETE:0)
Block(-1,18,-3,CONCRETE:0)
Block(-1,18,-2,CONCRETE:0)
Block(-1,18,-1,CONCRETE:0)
Block(-1,18,0,CONCRETE:0)
Block(-1,18,1,CONCRETE:0)
Block(-1,18,2,CONCRETE:0)
Block(-1,18,3,IRON_BLOCK:0)
Block(-1,18,4,CONCRETE:0)
Block(-1,18,5,CONCRETE:0)
Block(-1,18,6,CONCRETE:0)
Block(-1,18,7,CONCRETE:0)
Block(-1,18,8,CONCRETE:0)
Block(-1,19,-5,CONCRETE:0)
Block(-1,19,-4,CONCRETE:0)
Block(-1,19,-3,CONCRETE:0)
Block(-1,19,-2,CONCRETE:0)
Block(-1,19,-1,CONCRETE:0)
Block(-1,19,0,AIR:0)
Block(-1,19,1,CONCRETE:0)
Block(-1,19,2,IRON_BLOCK:0)
Block(-1,19,3,AIR:0)
Block(-1,19,4,IRON_BLOCK:0)
Block(-1,19,5,CONCRETE:0)
Block(-1,19,6,CONCRETE:0)
Block(-1,19,7,CONCRETE:0)
Block(-1,19,8,CONCRETE:0)
Block(-1,20,-5,CONCRETE:0)
Block(-1,20,-4,REDSTONE_WIRE:0)
Block(-1,20,-3,CONCRETE:0)
Block(-1,20,-2,CONCRETE:0)
Block(-1,20,-1,CONCRETE:0)
Block(-1,20,0,AIR:0)
Block(-1,20,1,CONCRETE:0)
Block(-1,20,2,IRON_BLOCK:0)
Block(-1,20,3,AIR:0)
Block(-1,20,4,IRON_BLOCK:0)
Block(-1,20,5,CONCRETE:0)
Block(-1,20,6,CONCRETE:0)
Block(-1,20,7,REDSTONE_WIRE:0)
Block(-1,20,8,CONCRETE:0)
Block(-1,21,-5,CONCRETE:0)
Block(-1,21,-4,CONCRETE:0)
Block(-1,21,-3,CONCRETE:0)
Block(-1,21,-2,CONCRETE:0)
Block(-1,21,-1,CONCRETE:0)
Block(-1,21,0,CONCRETE:0)
Block(-1,21,1,CONCRETE:0)
Block(-1,21,2,IRON_BLOCK:0)
Block(-1,21,3,AIR:0)
Block(-1,21,4,IRON_BLOCK:0)
Block(-1,21,5,CONCRETE:0)
Block(-1,21,6,CONCRETE:0)
Block(-1,21,7,CONCRETE:0)
Block(-1,21,8,CONCRETE:0)
Block(-1,22,1,CONCRETE:0)
Block(-1,22,2,IRON_BLOCK:0)
Block(-1,22,3,IRON_BLOCK:0)
Block(-1,22,4,IRON_BLOCK:0)
Block(-1,22,5,CONCRETE:0)
Block(-1,23,2,CONCRETE:0)
Block(-1,23,3,CONCRETE:0)
Block(-1,23,4,CONCRETE:0)
Block(-1,24,1,CONCRETE:0)
Block(-1,24,2,CONCRETE:0)
Block(-1,24,3,CONCRETE:0)
Block(-1,24,4,CONCRETE:0)
Block(-1,24,5,CONCRETE:0)
Block(-1,25,1,CONCRETE:0)
Block(-1,25,2,CONCRETE:0)
Block(-1,25,3,CONCRETE:0)
Block(-1,25,4,CONCRETE:0)
Block(-1,25,5,CONCRETE:0)
Block(-1,26,1,CONCRETE:0)
Block(-1,26,2,CONCRETE:0)
Block(-1,26,3,SMOOTH_STAIRS:0)
Block(-1,26,4,SMOOTH_STAIRS:0)
Block(-1,26,5,CONCRETE:0)
Block(0,0,-6,CONCRETE:0)
Block(0,0,-5,CONCRETE:0)
Block(0,0,-4,CONCRETE:0)
Block(0,0,-3,CONCRETE:0)
Block(0,0,-2,CONCRETE:0)
Block(0,0,-1,CONCRETE:0)
Block(0,0,0,CONCRETE:0)
Block(0,0,1,CONCRETE:0)
Block(0,0,2,CONCRETE:0)
Block(0,0,3,CONCRETE:0)
Block(0,0,4,CONCRETE:0)
Block(0,0,5,CONCRETE:0)
Block(0,0,6,CONCRETE:0)
Block(0,0,7,CONCRETE:0)
Block(0,0,8,CONCRETE:0)
Block(0,0,9,CONCRETE:0)
Block(0,1,-6,CONCRETE:0)
Block(0,1,-5,CONCRETE:0)
Block(0,1,-4,CONCRETE:0)
Block(0,1,-3,CONCRETE:0)
Block(0,1,-2,CONCRETE:0)
Block(0,1,-1,CONCRETE:0)
Block(0,1,0,CONCRETE:0)
Block(0,1,1,CONCRETE:0)
Block(0,1,2,CONCRETE:0)
Block(0,1,3,CONCRETE:0)
Block(0,1,4,CONCRETE:0)
Block(0,1,5,CONCRETE:0)
Block(0,1,6,CONCRETE:0)
Block(0,1,7,CONCRETE:0)
Block(0,1,8,CONCRETE:0)
Block(0,1,9,CONCRETE:0)
Block(0,2,-6,CONCRETE:0)
Block(0,2,-5,CONCRETE:0)
Block(0,2,-4,CONCRETE:0)
Block(0,2,-3,CONCRETE:0)
Block(0,2,-2,CONCRETE:0)
Block(0,2,-1,CONCRETE:0)
Block(0,2,0,CONCRETE:0)
Block(0,2,1,CONCRETE:0)
Block(0,2,2,CONCRETE:0)
Block(0,2,3,CONCRETE:0)
Block(0,2,4,CONCRETE:0)
Block(0,2,5,CONCRETE:0)
Block(0,2,6,CONCRETE:0)
Block(0,2,7,CONCRETE:0)
Block(0,2,8,CONCRETE:0)
Block(0,2,9,CONCRETE:0)
Block(0,3,-6,CONCRETE:0)
Block(0,3,-5,WOOD:1)
Block(0,3,-4,AIR:0)
Block(0,3,-3,AIR:0)
Block(0,3,-2,AIR:0)
Block(0,3,-1,dregorarl_srpmanhunt:encounter_marker)
Block(0,3,0,AIR:0)
Block(0,3,1,dregorarl_srpmanhunt:encounter_marker:13)
Block(0,3,2,WOOD:1)
Block(0,3,3,WOOD:1)
Block(0,3,4,AIR:0)
Block(0,3,5,AIR:0)
Block(0,3,6,AIR:0)
Block(0,3,7,AIR:0)
RandomBlock(0,3,8,WOOD:5,5,WOOD:5,../../../Chests/Loot/manhunt_vagrant_scrap.nbt,100)
Block(0,3,9,CONCRETE:0)
Block(0,4,-6,CONCRETE:0)
Block(0,4,-5,AIR:0)
Block(0,4,-4,AIR:0)
Block(0,4,-3,AIR:0)
Block(0,4,-2,AIR:0)
Block(0,4,-1,AIR:0)
Block(0,4,0,AIR:0)
Block(0,4,1,AIR:0)
Block(0,4,2,WEB:0)
Block(0,4,3,AIR:0)
Block(0,4,4,AIR:0)
Block(0,4,5,AIR:0)
Block(0,4,6,AIR:0)
Block(0,4,7,AIR:0)
RandomBlock(0,4,8,WOOD:5,5,WOOD:5,../../../Chests/Loot/manhunt_vagrant_scrap.nbt,100)
Block(0,4,9,CONCRETE:0)
Block(0,5,-6,CONCRETE:0)
Block(0,5,-5,AIR:0)
Block(0,5,-4,AIR:0)
Block(0,5,-3,AIR:0)
Block(0,5,-2,AIR:0)
Block(0,5,-1,AIR:0)
Block(0,5,0,AIR:0)
Block(0,5,1,AIR:0)
Block(0,5,2,AIR:0)
Block(0,5,3,AIR:0)
Block(0,5,4,AIR:0)
Block(0,5,5,AIR:0)
Block(0,5,6,AIR:0)
Block(0,5,7,AIR:0)
Block(0,5,8,AIR:0)
Block(0,5,9,CONCRETE:0)
Block(0,6,-6,CONCRETE:0)
Block(0,6,-5,AIR:0)
Block(0,6,-4,AIR:0)
Block(0,6,-3,AIR:0)
Block(0,6,-2,AIR:0)
Block(0,6,-1,AIR:0)
Block(0,6,0,WEB:0)
Block(0,6,1,WEB:0)
Block(0,6,2,AIR:0)
Block(0,6,3,AIR:0)
Block(0,6,4,STEP:8)
Block(0,6,5,AIR:0)
Block(0,6,6,AIR:0)
Block(0,6,7,AIR:0)
Block(0,6,8,AIR:0)
Block(0,6,9,CONCRETE:0)
Block(0,7,-6,CONCRETE:0)
Block(0,7,-5,CONCRETE:0)
Block(0,7,-4,CONCRETE:0)
Block(0,7,-3,CONCRETE:0)
Block(0,7,-2,CONCRETE:0)
Block(0,7,-1,CONCRETE:0)
Block(0,7,0,CONCRETE:0)
Block(0,7,1,CONCRETE:0)
Block(0,7,2,CONCRETE:0)
Block(0,7,3,CONCRETE:0)
Block(0,7,4,CONCRETE:0)
Block(0,7,5,CONCRETE:0)
Block(0,7,6,CONCRETE:0)
Block(0,7,7,CONCRETE:0)
Block(0,7,8,CONCRETE:0)
Block(0,7,9,CONCRETE:0)
Block(0,17,-1,CONCRETE:0)
Block(0,17,0,CONCRETE:0)
Block(0,17,1,CONCRETE:0)
Block(0,17,2,CONCRETE:0)
Block(0,17,3,CONCRETE:0)
Block(0,17,4,CONCRETE:0)
Block(0,18,-5,CONCRETE:0)
Block(0,18,-4,CONCRETE:0)
Block(0,18,-3,CONCRETE:0)
Block(0,18,-2,CONCRETE:0)
Block(0,18,-1,CONCRETE:0)
Block(0,18,0,CONCRETE:0)
Block(0,18,1,CONCRETE:0)
Block(0,18,2,CONCRETE:0)
Block(0,18,3,CONCRETE:0)
Block(0,18,4,CONCRETE:0)
Block(0,18,5,CONCRETE:0)
Block(0,18,6,CONCRETE:0)
Block(0,18,7,CONCRETE:0)
Block(0,18,8,CONCRETE:0)
Block(0,19,-5,CONCRETE:0)
Block(0,19,-4,CONCRETE:0)
Block(0,19,-3,CONCRETE:0)
Block(0,19,-2,CONCRETE:0)
Block(0,19,-1,SMOOTH_BRICK:0)
Block(0,19,0,AIR:0)
Block(0,19,1,AIR:0)
Block(0,19,2,CONCRETE:0)
Block(0,19,3,AIR:0)
Block(0,19,4,CONCRETE:0)
Block(0,19,5,CONCRETE:0)
Block(0,19,6,CONCRETE:0)
Block(0,19,7,CONCRETE:0)
Block(0,19,8,CONCRETE:0)
Block(0,20,-5,CONCRETE:0)
Block(0,20,-4,REDSTONE_WIRE:0)
Block(0,20,-3,CONCRETE:0)
Block(0,20,-2,CONCRETE:0)
Block(0,20,-1,SMOOTH_BRICK)
Block(0,20,0,AIR:0)
Block(0,20,1,SMOOTH_BRICK)
Block(0,20,2,CONCRETE:0)
Block(0,20,3,quark:iron_button:4)
Block(0,20,4,CONCRETE:0)
Block(0,20,5,REDSTONE_WIRE:0)
Block(0,20,6,REDSTONE_WIRE:0)
Block(0,20,7,REDSTONE_WIRE:0)
Block(0,20,8,CONCRETE:0)
Block(0,21,-5,CONCRETE:0)
Block(0,21,-4,CONCRETE:0)
Block(0,21,-3,CONCRETE:0)
Block(0,21,-2,CONCRETE:0)
Block(0,21,-1,CONCRETE:0)
Block(0,21,0,CONCRETE:0)
Block(0,21,1,CONCRETE:0)
Block(0,21,2,STEP:0)
Block(0,21,3,AIR:0)
Block(0,21,4,STEP:0)
Block(0,21,5,CONCRETE:0)
Block(0,21,6,CONCRETE:0)
Block(0,21,7,CONCRETE:0)
Block(0,21,8,CONCRETE:0)
Block(0,22,1,CONCRETE:0)
Block(0,22,2,AIR:0)
Block(0,22,3,AIR:0)
Block(0,22,4,AIR:0)
Block(0,22,5,CONCRETE:0)
Block(0,23,1,CONCRETE:0)
Block(0,23,2,WEB:0)
Block(0,23,3,AIR:0)
Block(0,23,4,AIR:0)
Block(0,23,5,CONCRETE:0)
Block(0,24,1,CONCRETE:0)
Block(0,24,2,AIR:0)
Block(0,24,3,AIR:0)
Block(0,24,4,WEB:0)
Block(0,24,5,SMOOTH_STAIRS:3)
Block(0,25,1,CONCRETE:0)
Block(0,25,2,AIR:0)
Block(0,25,3,WEB:0)
Block(0,25,4,WEB:0)
Block(0,25,5,SMOOTH_STAIRS:7)
Block(0,26,1,SMOOTH_STAIRS:2)
Block(0,26,2,CONCRETE:0)
Block(0,26,3,CONCRETE:0)
Block(0,26,4,CONCRETE:0)
Block(0,26,5,CONCRETE:0)
Block(0,27,3,CONCRETE:0)
Block(1,0,-6,CONCRETE:0)
Block(1,0,-5,CONCRETE:0)
Block(1,0,-4,CONCRETE:0)
Block(1,0,-3,CONCRETE:0)
Block(1,0,-2,CONCRETE:0)
Block(1,0,-1,CONCRETE:0)
Block(1,0,0,CONCRETE:0)
Block(1,0,1,CONCRETE:0)
Block(1,0,2,CONCRETE:0)
Block(1,0,3,CONCRETE:0)
Block(1,0,4,CONCRETE:0)
Block(1,0,5,CONCRETE:0)
Block(1,0,6,CONCRETE:0)
Block(1,0,7,CONCRETE:0)
Block(1,0,8,CONCRETE:0)
Block(1,0,9,CONCRETE:0)
Block(1,1,-6,CONCRETE:0)
Block(1,1,-5,CONCRETE:0)
Block(1,1,-4,quark:lit_lamp:0)
Block(1,1,-3,CONCRETE:0)
Block(1,1,-2,CONCRETE:0)
Block(1,1,-1,CONCRETE:0)
Block(1,1,0,quark:lit_lamp:0)
Block(1,1,1,CONCRETE:0)
Block(1,1,2,CONCRETE:0)
Block(1,1,3,CONCRETE:0)
Block(1,1,4,quark:lit_lamp:0)
Block(1,1,5,CONCRETE:0)
Block(1,1,6,CONCRETE:0)
Block(1,1,7,CONCRETE:0)
Block(1,1,8,CONCRETE:0)
Block(1,1,9,CONCRETE:0)
Block(1,2,-6,CONCRETE:0)
Block(1,2,-5,CONCRETE:0)
Block(1,2,-4,quark:grate:0)
Block(1,2,-3,CONCRETE:0)
Block(1,2,-2,CONCRETE:0)
Block(1,2,-1,CONCRETE:0)
Block(1,2,0,quark:grate:0)
Block(1,2,1,CONCRETE:0)
Block(1,2,2,CONCRETE:0)
Block(1,2,3,CONCRETE:0)
Block(1,2,4,quark:grate:0)
Block(1,2,5,CONCRETE:0)
Block(1,2,6,CONCRETE:0)
Block(1,2,7,CONCRETE:0)
Block(1,2,8,CONCRETE:0)
Block(1,2,9,CONCRETE:0)
Block(1,3,-6,CONCRETE:0)
Block(1,3,-5,WOOD:1)
Block(1,3,-4,AIR:0)
Block(1,3,-3,AIR:0)
Block(1,3,-2,AIR:0)
Block(1,3,-1,AIR:0)
Block(1,3,0,AIR:0)
Block(1,3,1,AIR:0)
Block(1,3,2,AIR:0)
Block(1,3,3,AIR:0)
Block(1,3,4,AIR:0)
Block(1,3,5,SMOOTH_BRICK:0)
Block(1,3,6,SMOOTH_BRICK:0)
Block(1,3,7,AIR:0)
RandomBlock(1,3,8,WOOD:5,5,WOOD:5,../../../Chests/Loot/manhunt_vagrant_scrap.nbt,100)
Block(1,3,9,CONCRETE:0)
Block(1,4,-6,CONCRETE:0)
Block(1,4,-5,AIR:0)
Block(1,4,-4,AIR:0)
Block(1,4,-3,AIR:0)
Block(1,4,-2,AIR:0)
Block(1,4,-1,AIR:0)
Block(1,4,0,AIR:0)
Block(1,4,1,AIR:0)
Block(1,4,2,AIR:0)
Block(1,4,3,AIR:0)
Block(1,4,4,AIR:0)
Block(1,4,5,AIR:0)
Block(1,4,6,AIR:0)
Block(1,4,7,AIR:0)
Block(1,4,8,AIR:0)
Block(1,4,9,CONCRETE:0)
Block(1,5,-6,CONCRETE:0)
Block(1,5,-5,AIR:0)
Block(1,5,-4,AIR:0)
Block(1,5,-3,AIR:0)
Block(1,5,-2,AIR:0)
Block(1,5,-1,AIR:0)
Block(1,5,0,quark:grate:0)
Block(1,5,1,AIR:0)
Block(1,5,2,WEB:0)
Block(1,5,3,AIR:0)
Block(1,5,4,AIR:0)
Block(1,5,5,AIR:0)
Block(1,5,6,AIR:0)
Block(1,5,7,AIR:0)
Block(1,5,8,AIR:0)
Block(1,5,9,CONCRETE:0)
Block(1,6,-6,CONCRETE:0)
Block(1,6,-5,STEP:8)
Block(1,6,-4,STEP:8)
Block(1,6,-3,STEP:8)
Block(1,6,-2,STEP:8)
Block(1,6,-1,STEP:8)
Block(1,6,0,DROPPER:0,f_bunker_storage/53-dropper.nbt)
Block(1,6,1,STEP:8)
Block(1,6,2,STEP:8)
Block(1,6,3,STEP:8)
Block(1,6,4,STEP:8)
Block(1,6,5,AIR:0)
Block(1,6,6,AIR:0)
Block(1,6,7,AIR:0)
Block(1,6,8,AIR:0)
Block(1,6,9,CONCRETE:0)
Block(1,7,-6,CONCRETE:0)
Block(1,7,-5,CONCRETE:0)
Block(1,7,-4,CONCRETE:0)
Block(1,7,-3,CONCRETE:0)
Block(1,7,-2,CONCRETE:0)
Block(1,7,-1,CONCRETE:0)
Block(1,7,0,CONCRETE:0)
Block(1,7,1,CONCRETE:0)
Block(1,7,2,CONCRETE:0)
Block(1,7,3,CONCRETE:0)
Block(1,7,4,CONCRETE:0)
Block(1,7,5,CONCRETE:0)
Block(1,7,6,CONCRETE:0)
Block(1,7,7,CONCRETE:0)
Block(1,7,8,CONCRETE:0)
Block(1,7,9,CONCRETE:0)
Block(1,8,8,CONCRETE:0)
Block(1,9,8,CONCRETE:0)
Block(1,10,8,CONCRETE:0)
Block(1,11,8,CONCRETE:0)
Block(1,12,8,CONCRETE:0)
Block(1,13,8,CONCRETE:0)
Block(1,14,8,CONCRETE:0)
Block(1,15,8,CONCRETE:0)
Block(1,16,8,CONCRETE:0)
Block(1,17,-1,CONCRETE:0)
Block(1,17,0,CONCRETE:0)
Block(1,17,1,CONCRETE:0)
Block(1,17,2,CONCRETE:0)
Block(1,17,3,CONCRETE:0)
Block(1,17,4,CONCRETE:0)
Block(1,17,8,CONCRETE:0)
Block(1,18,-5,CONCRETE:0)
Block(1,18,-4,CONCRETE:0)
Block(1,18,-3,CONCRETE:0)
Block(1,18,-2,CONCRETE:0)
Block(1,18,-1,IRON_FENCE:0)
Block(1,18,0,SMOOTH_STAIRS:1)
Block(1,18,1,IRON_FENCE:0)
Block(1,18,2,CONCRETE:0)
Block(1,18,3,CONCRETE:0)
Block(1,18,4,CONCRETE:0)
Block(1,18,5,CONCRETE:0)
Block(1,18,6,CONCRETE:0)
Block(1,18,7,CONCRETE:0)
Block(1,18,8,CONCRETE:0)
Block(1,19,-5,CONCRETE:0)
Block(1,19,-4,CONCRETE:0)
Block(1,19,-3,CONCRETE:0)
Block(1,19,-2,CONCRETE:0)
Block(1,19,-1,IRON_FENCE:0)
Block(1,19,0,AIR:0)
Block(1,19,1,IRON_FENCE:0)
Block(1,19,2,CONCRETE:0)
Block(1,19,3,SMOOTH_STAIRS:0)
Block(1,19,4,CONCRETE:0)
Block(1,19,5,CONCRETE:0)
Block(1,19,6,CONCRETE:0)
Block(1,19,7,CONCRETE:0)
Block(1,19,8,CONCRETE:0)
Block(1,20,-5,CONCRETE:0)
Block(1,20,-4,REDSTONE_WIRE:0)
Block(1,20,-3,REDSTONE_WIRE:0)
Block(1,20,-2,IRON_BLOCK:0)
Block(1,20,-1,quark:iron_button:3)
Block(1,20,0,AIR:0)
Block(1,20,1,AIR:0)
Block(1,20,2,CONCRETE:0)
Block(1,20,3,AIR:0)
Block(1,20,4,CONCRETE:0)
Block(1,20,5,CONCRETE:0)
Block(1,20,6,CONCRETE:0)
Block(1,20,7,CONCRETE:0)
Block(1,20,8,CONCRETE:0)
Block(1,21,-5,CONCRETE:0)
Block(1,21,-4,CONCRETE:0)
Block(1,21,-3,CONCRETE:0)
Block(1,21,-2,CONCRETE:0)
Block(1,21,-1,CONCRETE:0)
Block(1,21,0,CONCRETE:0)
Block(1,21,1,CONCRETE:0)
Block(1,21,2,STEP:0)
Block(1,21,3,AIR:0)
Block(1,21,4,STEP:0)
Block(1,21,5,CONCRETE:0)
Block(1,21,6,CONCRETE:0)
Block(1,21,7,CONCRETE:0)
Block(1,21,8,CONCRETE:0)
Block(1,22,1,CONCRETE:0)
Block(1,22,2,AIR:0)
Block(1,22,3,AIR:0)
Block(1,22,4,AIR:0)
Block(1,22,5,CONCRETE:0)
Block(1,23,1,CONCRETE:0)
Block(1,23,2,AIR:0)
Block(1,23,3,AIR:0)
Block(1,23,4,AIR:0)
Block(1,23,5,CONCRETE:0)
Block(1,24,1,CONCRETE:0)
Block(1,24,2,AIR:0)
Block(1,24,3,AIR:0)
Block(1,24,4,AIR:0)
Block(1,24,5,CONCRETE:0)
Block(1,25,1,CONCRETE:0)
Block(1,25,2,AIR:0)
Block(1,25,3,AIR:0)
Block(1,25,4,WEB:0)
Block(1,25,5,SMOOTH_STAIRS:7)
Block(1,26,1,SMOOTH_STAIRS:2)
Block(1,26,2,CONCRETE:0)
Block(1,26,3,CONCRETE:0)
Block(1,26,4,CONCRETE:0)
Block(1,26,5,CONCRETE:0)
Block(1,27,3,CONCRETE:0)
Block(1,27,4,CONCRETE:0)
Block(2,0,-6,CONCRETE:0)
Block(2,0,-5,CONCRETE:0)
Block(2,0,-4,CONCRETE:0)
Block(2,0,-3,CONCRETE:0)
Block(2,0,-2,CONCRETE:0)
Block(2,0,-1,CONCRETE:0)
Block(2,0,0,CONCRETE:0)
Block(2,0,1,CONCRETE:0)
Block(2,0,2,CONCRETE:0)
Block(2,0,3,CONCRETE:0)
Block(2,0,4,CONCRETE:0)
Block(2,0,5,CONCRETE:0)
Block(2,0,6,CONCRETE:0)
Block(2,0,7,CONCRETE:0)
Block(2,0,8,CONCRETE:0)
Block(2,0,9,CONCRETE:0)
Block(2,1,-6,CONCRETE:0)
Block(2,1,-5,CONCRETE:0)
Block(2,1,-4,CONCRETE:0)
Block(2,1,-3,CONCRETE:0)
Block(2,1,-2,CONCRETE:0)
Block(2,1,-1,CONCRETE:0)
Block(2,1,0,CONCRETE:0)
Block(2,1,1,CONCRETE:0)
Block(2,1,2,CONCRETE:0)
Block(2,1,3,CONCRETE:0)
Block(2,1,4,CONCRETE:0)
Block(2,1,5,CONCRETE:0)
Block(2,1,6,CONCRETE:0)
Block(2,1,7,CONCRETE:0)
Block(2,1,8,CONCRETE:0)
Block(2,1,9,CONCRETE:0)
Block(2,2,-6,CONCRETE:0)
Block(2,2,-5,CONCRETE:0)
Block(2,2,-4,CONCRETE:0)
Block(2,2,-3,CONCRETE:0)
Block(2,2,-2,CONCRETE:0)
Block(2,2,-1,CONCRETE:0)
Block(2,2,0,CONCRETE:0)
Block(2,2,1,CONCRETE:0)
Block(2,2,2,CONCRETE:0)
Block(2,2,3,CONCRETE:0)
Block(2,2,4,CONCRETE:0)
Block(2,2,5,CONCRETE:0)
Block(2,2,6,CONCRETE:0)
Block(2,2,7,CONCRETE:0)
Block(2,2,8,CONCRETE:0)
Block(2,2,9,CONCRETE:0)
Block(2,3,-6,CONCRETE:0)
Block(2,3,-5,AIR:0)
Block(2,3,-4,AIR:0)
Block(2,3,-3,AIR:0)
Block(2,3,-2,AIR:0)
Block(2,3,-1,AIR:0)
Block(2,3,0,AIR:0)
Block(2,3,1,AIR:0)
Block(2,3,2,AIR:0)
Block(2,3,3,AIR:0)
Block(2,3,4,AIR:0)
Block(2,3,5,AIR:0)
Block(2,3,6,AIR:0)
Block(2,3,7,AIR:0)
Block(2,3,8,AIR:0)
Block(2,3,9,CONCRETE:0)
Block(2,4,-6,CONCRETE:0)
Block(2,4,-5,AIR:0)
Block(2,4,-4,AIR:0)
Block(2,4,-3,AIR:0)
Block(2,4,-2,AIR:0)
Block(2,4,-1,AIR:0)
Block(2,4,0,AIR:0)
Block(2,4,1,AIR:0)
Block(2,4,2,AIR:0)
Block(2,4,3,AIR:0)
Block(2,4,4,AIR:0)
Block(2,4,5,AIR:0)
Block(2,4,6,AIR:0)
Block(2,4,7,AIR:0)
Block(2,4,8,AIR:0)
Block(2,4,9,CONCRETE:0)
Block(2,5,-6,CONCRETE:0)
Block(2,5,-5,WEB:0)
Block(2,5,-4,AIR:0)
Block(2,5,-3,AIR:0)
Block(2,5,-2,AIR:0)
Block(2,5,-1,AIR:0)
Block(2,5,0,AIR:0)
Block(2,5,1,AIR:0)
Block(2,5,2,AIR:0)
Block(2,5,3,AIR:0)
Block(2,5,4,AIR:0)
Block(2,5,5,AIR:0)
Block(2,5,6,AIR:0)
Block(2,5,7,AIR:0)
Block(2,5,8,AIR:0)
Block(2,5,9,CONCRETE:0)
Block(2,6,-6,CONCRETE:0)
Block(2,6,-5,WEB:0)
Block(2,6,-4,AIR:0)
Block(2,6,-3,AIR:0)
Block(2,6,-2,AIR:0)
Block(2,6,-1,AIR:0)
Block(2,6,0,AIR:0)
Block(2,6,1,AIR:0)
Block(2,6,2,WEB:0)
Block(2,6,3,AIR:0)
Block(2,6,4,AIR:0)
Block(2,6,5,AIR:0)
Block(2,6,6,AIR:0)
Block(2,6,7,AIR:0)
Block(2,6,8,AIR:0)
Block(2,6,9,CONCRETE:0)
Block(2,7,-6,CONCRETE:0)
Block(2,7,-5,CONCRETE:0)
Block(2,7,-4,CONCRETE:0)
Block(2,7,-3,CONCRETE:0)
Block(2,7,-2,CONCRETE:0)
Block(2,7,-1,CONCRETE:0)
Block(2,7,0,CONCRETE:0)
Block(2,7,1,CONCRETE:0)
Block(2,7,2,CONCRETE:0)
Block(2,7,3,CONCRETE:0)
Block(2,7,4,CONCRETE:0)
Block(2,7,5,CONCRETE:0)
Block(2,7,6,CONCRETE:0)
Block(2,7,7,CONCRETE:0)
Block(2,7,8,CONCRETE:0)
Block(2,7,9,CONCRETE:0)
Block(2,8,-6,CONCRETE:0)
Block(2,8,1,CONCRETE:0)
Block(2,9,-6,CONCRETE:0)
Block(2,9,1,CONCRETE:0)
Block(2,10,-6,CONCRETE:0)
Block(2,10,1,CONCRETE:0)
Block(2,11,-6,CONCRETE:0)
Block(2,11,1,CONCRETE:0)
Block(2,12,-6,CONCRETE:0)
Block(2,12,1,CONCRETE:0)
Block(2,13,-6,CONCRETE:0)
Block(2,13,1,CONCRETE:0)
Block(2,14,-6,CONCRETE:0)
Block(2,14,1,CONCRETE:0)
Block(2,15,-6,CONCRETE:0)
Block(2,15,-1,CONCRETE:0)
Block(2,15,0,CONCRETE:0)
Block(2,15,1,CONCRETE:0)
Block(2,16,-6,CONCRETE:0)
Block(2,16,-1,CONCRETE:0)
Block(2,16,0,CONCRETE:0)
Block(2,16,1,CONCRETE:0)
Block(2,17,-6,CONCRETE:0)
Block(2,17,-5,CONCRETE:0)
Block(2,17,-4,CONCRETE:0)
Block(2,17,-3,CONCRETE:0)
Block(2,17,-2,CONCRETE:0)
Block(2,17,-1,CONCRETE:0)
Block(2,17,0,CONCRETE:0)
Block(2,17,1,CONCRETE:0)
Block(2,17,2,CONCRETE:0)
Block(2,17,3,CONCRETE:0)
Block(2,17,4,CONCRETE:0)
Block(2,18,-6,CONCRETE:0)
Block(2,18,-5,CONCRETE:0)
Block(2,18,-4,STONE:0)
Block(2,18,-3,CONCRETE:0)
Block(2,18,-2,CONCRETE:0)
Block(2,18,-1,WEB:0)
Block(2,18,0,SMOOTH_BRICK:0)
Block(2,18,1,AIR:0)
Block(2,18,2,CONCRETE:0)
Block(2,18,3,CONCRETE:0)
Block(2,18,4,CONCRETE:0)
Block(2,19,-6,CONCRETE:0)
Block(2,19,-5,CONCRETE:0)
Block(2,19,-4,SMOOTH_BRICK)
Block(2,19,-3,CONCRETE:0)
Block(2,19,-2,CONCRETE:0)
Block(2,19,-1,AIR:0)
Block(2,19,0,AIR:0)
Block(2,19,1,AIR:0)
Block(2,19,2,CONCRETE:0)
Block(2,19,3,CONCRETE:0)
Block(2,19,4,CONCRETE:0)
Block(2,20,-6,CONCRETE:0)
Block(2,20,-5,CONCRETE:0)
Block(2,20,-4,STONE:0)
Block(2,20,-3,CONCRETE:0)
Block(2,20,-2,CONCRETE:0)
Block(2,20,-1,AIR:0)
Block(2,20,0,AIR:0)
Block(2,20,1,AIR:0)
Block(2,20,2,CONCRETE:0)
Block(2,20,3,SMOOTH_STAIRS:0)
Block(2,20,4,CONCRETE:0)
Block(2,20,5,CONCRETE:0)
Block(2,21,-6,CONCRETE:0)
Block(2,21,-5,CONCRETE:0)
Block(2,21,-4,CONCRETE:0)
Block(2,21,-3,CONCRETE:0)
Block(2,21,-2,CONCRETE:0)
Block(2,21,-1,CONCRETE:0)
Block(2,21,0,CONCRETE:0)
Block(2,21,1,CONCRETE:0)
Block(2,21,2,STEP:0)
Block(2,21,3,AIR:0)
Block(2,21,4,STEP:0)
Block(2,21,5,CONCRETE:0)
Block(2,22,1,CONCRETE:0)
Block(2,22,2,AIR:0)
Block(2,22,3,AIR:0)
Block(2,22,4,AIR:0)
Block(2,22,5,CONCRETE:0)
Block(2,23,1,CONCRETE:0)
Block(2,23,2,AIR:0)
Block(2,23,3,AIR:0)
Block(2,23,4,AIR:0)
Block(2,23,5,CONCRETE:0)
Block(2,24,1,CONCRETE:0)
Block(2,24,2,AIR:0)
Block(2,24,3,AIR:0)
Block(2,24,4,AIR:0)
Block(2,24,5,CONCRETE:0)
Block(2,25,1,CONCRETE:0)
Block(2,25,2,AIR:0)
Block(2,25,3,AIR:0)
Block(2,25,4,AIR:0)
Block(2,25,5,SMOOTH_STAIRS:3)
Block(2,26,1,CONCRETE:0)
Block(2,26,2,CONCRETE:0)
Block(2,26,3,CONCRETE:0)
Block(2,26,4,CONCRETE:0)
Block(2,26,5,CONCRETE:0)
Block(2,27,1,CONCRETE:0)
Block(3,0,-6,CONCRETE:0)
Block(3,0,-5,CONCRETE:0)
Block(3,0,-4,CONCRETE:0)
Block(3,0,-3,CONCRETE:0)
Block(3,0,-2,CONCRETE:0)
Block(3,0,-1,CONCRETE:0)
Block(3,0,0,CONCRETE:0)
Block(3,0,1,CONCRETE:0)
Block(3,0,2,CONCRETE:0)
Block(3,0,3,CONCRETE:0)
Block(3,0,4,CONCRETE:0)
Block(3,0,5,CONCRETE:0)
Block(3,0,6,CONCRETE:0)
Block(3,0,7,CONCRETE:0)
Block(3,0,8,CONCRETE:0)
Block(3,0,9,CONCRETE:0)
Block(3,1,-6,CONCRETE:0)
Block(3,1,-5,CONCRETE:0)
Block(3,1,-4,CONCRETE:0)
Block(3,1,-3,CONCRETE:0)
Block(3,1,-2,CONCRETE:0)
Block(3,1,-1,CONCRETE:0)
Block(3,1,0,CONCRETE:0)
Block(3,1,1,CONCRETE:0)
Block(3,1,2,CONCRETE:0)
Block(3,1,3,CONCRETE:0)
Block(3,1,4,CONCRETE:0)
Block(3,1,5,CONCRETE:0)
Block(3,1,6,CONCRETE:0)
Block(3,1,7,CONCRETE:0)
Block(3,1,8,CONCRETE:0)
Block(3,1,9,CONCRETE:0)
Block(3,2,-6,CONCRETE:0)
Block(3,2,-5,CONCRETE:0)
Block(3,2,-4,CONCRETE:0)
Block(3,2,-3,CONCRETE:0)
Block(3,2,-2,CONCRETE:0)
Block(3,2,-1,CONCRETE:0)
Block(3,2,0,CONCRETE:0)
Block(3,2,1,CONCRETE:0)
Block(3,2,2,CONCRETE:0)
Block(3,2,3,CONCRETE:0)
Block(3,2,4,CONCRETE:0)
Block(3,2,5,CONCRETE:0)
Block(3,2,6,CONCRETE:0)
Block(3,2,7,CONCRETE:0)
Block(3,2,8,CONCRETE:0)
Block(3,2,9,CONCRETE:0)
Block(3,3,-6,CONCRETE:0)
RandomBlock(3,3,-5,WOOD:5,5,WOOD:5,../../../Chests/Loot/manhunt_vagrant_scrap.nbt,100)
RandomBlock(3,3,-4,WOOD:5,5,WOOD:5,../../../Chests/Loot/manhunt_vagrant_scrap.nbt,100)
RandomBlock(3,3,-3,WOOD:5,5,WOOD:5,../../../Chests/Loot/manhunt_vagrant_scrap.nbt,100)
Block(3,3,-2,AIR:0)
RandomBlock(3,3,-1,WOOD:5,5,WOOD:5,../../../Chests/Loot/manhunt_vagrant_scrap.nbt,100)
RandomBlock(3,3,0,WOOD:5,5,WOOD:5,../../../Chests/Loot/manhunt_vagrant_scrap.nbt,100)
Block(3,3,1,AIR:0)
Block(3,3,2,CONCRETE:4)
Block(3,3,3,AIR:0)
Block(3,3,4,SMOOTH_BRICK:0)
Block(3,3,5,WOOD:1)
Block(3,3,6,CONCRETE:4)
Block(3,3,7,AIR:0)
Block(3,3,8,WOOD)
Block(3,3,9,CONCRETE:0)
Block(3,4,-6,CONCRETE:0)
RandomBlock(3,4,-5,WOOD:5,5,WOOD:5,../../../Chests/Loot/manhunt_vagrant_scrap.nbt,100)
Block(3,4,-4,AIR:0)
Block(3,4,-3,AIR:0)
Block(3,4,-2,AIR:0)
RandomBlock(3,4,-1,WOOD:5,5,WOOD:5,../../../Chests/Loot/manhunt_vagrant_scrap.nbt,100)
Block(3,4,0,AIR:0)
Block(3,4,1,AIR:0)
Block(3,4,2,CONCRETE:0)
Block(3,4,3,AIR:0)
Block(3,4,4,AIR:0)
Block(3,4,5,SMOOTH_BRICK)
Block(3,4,6,CONCRETE:0)
Block(3,4,7,AIR:0)
Block(3,4,8,WOOD)
Block(3,4,9,CONCRETE:0)
Block(3,5,-6,CONCRETE:0)
Block(3,5,-5,WEB:0)
Block(3,5,-4,AIR:0)
Block(3,5,-3,AIR:0)
Block(3,5,-2,AIR:0)
Block(3,5,-1,AIR:0)
Block(3,5,0,AIR:0)
Block(3,5,1,AIR:0)
Block(3,5,2,CONCRETE:0)
Block(3,5,3,AIR:0)
Block(3,5,4,AIR:0)
Block(3,5,5,AIR:0)
Block(3,5,6,CONCRETE:0)
Block(3,5,7,AIR:0)
Block(3,5,8,AIR:0)
Block(3,5,9,CONCRETE:0)
Block(3,6,-6,CONCRETE:0)
Block(3,6,-5,WEB:0)
Block(3,6,-4,WEB:0)
Block(3,6,-3,AIR:0)
Block(3,6,-2,AIR:0)
Block(3,6,-1,AIR:0)
Block(3,6,0,AIR:0)
Block(3,6,1,AIR:0)
Block(3,6,2,CONCRETE:0)
Block(3,6,3,AIR:0)
Block(3,6,4,AIR:0)
Block(3,6,5,AIR:0)
Block(3,6,6,CONCRETE:0)
Block(3,6,7,AIR:0)
Block(3,6,8,AIR:0)
Block(3,6,9,CONCRETE:0)
Block(3,7,-6,CONCRETE:0)
Block(3,7,-5,CONCRETE:0)
Block(3,7,-4,CONCRETE:0)
Block(3,7,-3,CONCRETE:0)
Block(3,7,-2,CONCRETE:0)
Block(3,7,-1,CONCRETE:0)
Block(3,7,0,CONCRETE:0)
Block(3,7,1,CONCRETE:0)
Block(3,7,2,CONCRETE:0)
Block(3,7,3,CONCRETE:0)
Block(3,7,4,CONCRETE:0)
Block(3,7,5,CONCRETE:0)
Block(3,7,6,CONCRETE:0)
Block(3,7,7,CONCRETE:0)
Block(3,7,8,CONCRETE:0)
Block(3,7,9,CONCRETE:0)
Block(3,15,-1,CONCRETE:0)
Block(3,15,0,CONCRETE:0)
Block(3,15,1,CONCRETE:0)
Block(3,16,-1,CONCRETE:0)
Block(3,16,0,quark:lit_lamp:0)
Block(3,16,1,CONCRETE:0)
Block(3,17,-6,CONCRETE:0)
Block(3,17,-5,CONCRETE:0)
Block(3,17,-4,CONCRETE:0)
Block(3,17,-3,CONCRETE:0)
Block(3,17,-2,CONCRETE:0)
Block(3,17,-1,CONCRETE:0)
Block(3,17,0,quark:grate:0)
Block(3,17,1,CONCRETE:0)
Block(3,17,2,CONCRETE:0)
Block(3,17,3,CONCRETE:0)
Block(3,17,4,CONCRETE:0)
Block(3,18,-6,CONCRETE:0)
Block(3,18,-5,AIR:0)
Block(3,18,-4,AIR:0)
Block(3,18,-3,AIR:0)
Block(3,18,-2,AIR:0)
Block(3,18,-1,AIR:0)
Block(3,18,0,AIR:0)
Block(3,18,1,AIR:0)
Block(3,18,2,CONCRETE:15)
Block(3,18,3,CONCRETE:0)
Block(3,18,4,CONCRETE:0)
Block(3,19,-6,CONCRETE:0)
Block(3,19,-5,AIR:0)
Block(3,19,-4,AIR:0)
Block(3,19,-3,AIR:0)
Block(3,19,-2,AIR:0)
Block(3,19,-1,AIR:0)
Block(3,19,0,AIR:0)
Block(3,19,1,AIR:0)
Block(3,19,2,CONCRETE:15)
Block(3,19,3,CONCRETE:0)
Block(3,19,4,CONCRETE:0)
Block(3,20,-6,CONCRETE:0)
Block(3,20,-5,WEB:0)
Block(3,20,-4,STEP:8)
Block(3,20,-3,AIR:0)
Block(3,20,-2,AIR:0)
Block(3,20,-1,AIR:0)
Block(3,20,0,AIR:0)
Block(3,20,1,AIR:0)
Block(3,20,2,CONCRETE:15)
Block(3,20,3,CONCRETE:0)
Block(3,20,4,CONCRETE:0)
Block(3,20,5,CONCRETE:0)
Block(3,21,-6,CONCRETE:0)
Block(3,21,-5,CONCRETE:0)
Block(3,21,-4,CONCRETE:0)
Block(3,21,-3,CONCRETE:0)
Block(3,21,-2,CONCRETE:0)
Block(3,21,-1,CONCRETE:0)
Block(3,21,0,CONCRETE:0)
Block(3,21,1,CONCRETE:0)
Block(3,21,2,STEP:0)
Block(3,21,3,SMOOTH_STAIRS:0)
Block(3,21,4,STEP:0)
Block(3,21,5,CONCRETE:0)
Block(3,22,1,CONCRETE:0)
Block(3,22,2,AIR:0)
Block(3,22,3,AIR:0)
Block(3,22,4,AIR:0)
Block(3,22,5,CONCRETE:0)
Block(3,23,1,CONCRETE:0)
Block(3,23,2,AIR:0)
Block(3,23,3,AIR:0)
Block(3,23,4,AIR:0)
Block(3,23,5,CONCRETE:0)
Block(3,24,1,CONCRETE:0)
Block(3,24,2,AIR:0)
Block(3,24,3,AIR:0)
Block(3,24,4,AIR:0)
Block(3,24,5,CONCRETE:0)
Block(3,25,1,CONCRETE:0)
Block(3,25,2,AIR:0)
Block(3,25,3,AIR:0)
Block(3,25,4,WEB:0)
Block(3,25,5,CONCRETE:0)
Block(3,26,1,CONCRETE:0)
Block(3,26,2,CONCRETE:0)
Block(3,26,3,CONCRETE:0)
Block(3,26,4,CONCRETE:0)
Block(3,26,5,SMOOTH_STAIRS:3)
Block(4,0,-6,CONCRETE:0)
Block(4,0,-5,CONCRETE:0)
Block(4,0,-4,CONCRETE:0)
Block(4,0,-3,CONCRETE:0)
Block(4,0,-2,CONCRETE:0)
Block(4,0,-1,CONCRETE:0)
Block(4,0,0,CONCRETE:0)
Block(4,0,1,CONCRETE:0)
Block(4,0,2,CONCRETE:0)
Block(4,0,3,CONCRETE:0)
Block(4,0,4,CONCRETE:0)
Block(4,0,5,CONCRETE:0)
Block(4,0,6,CONCRETE:0)
Block(4,0,7,CONCRETE:0)
Block(4,0,8,CONCRETE:0)
Block(4,0,9,CONCRETE:0)
Block(4,1,-6,CONCRETE:0)
Block(4,1,-5,CONCRETE:0)
Block(4,1,-4,CONCRETE:0)
Block(4,1,-3,CONCRETE:0)
Block(4,1,-2,CONCRETE:0)
Block(4,1,-1,CONCRETE:0)
Block(4,1,0,CONCRETE:0)
Block(4,1,1,CONCRETE:0)
Block(4,1,2,CONCRETE:0)
Block(4,1,3,CONCRETE:0)
Block(4,1,4,CONCRETE:0)
Block(4,1,5,CONCRETE:0)
Block(4,1,6,CONCRETE:0)
Block(4,1,7,CONCRETE:0)
Block(4,1,8,CONCRETE:0)
Block(4,1,9,CONCRETE:0)
Block(4,2,-6,CONCRETE:0)
Block(4,2,-5,CONCRETE:0)
Block(4,2,-4,CONCRETE:0)
Block(4,2,-3,CONCRETE:0)
Block(4,2,-2,CONCRETE:0)
Block(4,2,-1,CONCRETE:0)
Block(4,2,0,CONCRETE:0)
Block(4,2,1,CONCRETE:0)
Block(4,2,2,CONCRETE:0)
Block(4,2,3,CONCRETE:0)
Block(4,2,4,CONCRETE:0)
Block(4,2,5,CONCRETE:0)
Block(4,2,6,CONCRETE:0)
Block(4,2,7,CONCRETE:0)
Block(4,2,8,CONCRETE:0)
Block(4,2,9,CONCRETE:0)
Block(4,3,-6,CONCRETE:0)
Block(4,3,-5,CONCRETE:0)
Block(4,3,-4,CONCRETE:0)
Block(4,3,-3,CONCRETE:0)
Block(4,3,-2,CONCRETE:0)
Block(4,3,-1,CONCRETE:0)
Block(4,3,0,AIR:0)
Block(4,3,1,AIR:0)
Block(4,3,2,AIR:0)
Block(4,3,3,AIR:0)
Block(4,3,4,AIR:0)
Block(4,3,5,AIR:0)
Block(4,3,6,WEB:0)
Block(4,3,7,AIR:0)
Block(4,3,8,AIR:0)
Block(4,3,9,CONCRETE:0)
Block(4,4,-6,CONCRETE:0)
Block(4,4,-5,CONCRETE:0)
Block(4,4,-4,CONCRETE:0)
Block(4,4,-3,CONCRETE:0)
Block(4,4,-2,CONCRETE:0)
Block(4,4,-1,CONCRETE:0)
Block(4,4,0,AIR:0)
Block(4,4,1,AIR:0)
Block(4,4,2,AIR:0)
Block(4,4,3,AIR:0)
Block(4,4,4,AIR:0)
Block(4,4,5,AIR:0)
Block(4,4,6,AIR:0)
Block(4,4,7,AIR:0)
Block(4,4,8,AIR:0)
Block(4,4,9,CONCRETE:0)
Block(4,5,-6,CONCRETE:0)
Block(4,5,-5,CONCRETE:0)
Block(4,5,-4,CONCRETE:0)
Block(4,5,-3,CONCRETE:0)
Block(4,5,-2,CONCRETE:0)
Block(4,5,-1,CONCRETE:0)
Block(4,5,0,AIR:0)
Block(4,5,1,AIR:0)
Block(4,5,2,WEB:0)
Block(4,5,3,AIR:0)
Block(4,5,4,AIR:0)
Block(4,5,5,AIR:0)
Block(4,5,6,AIR:0)
Block(4,5,7,AIR:0)
Block(4,5,8,AIR:0)
Block(4,5,9,CONCRETE:0)
Block(4,6,-6,CONCRETE:0)
Block(4,6,-5,CONCRETE:0)
Block(4,6,-4,CONCRETE:0)
Block(4,6,-3,CONCRETE:0)
Block(4,6,-2,CONCRETE:0)
Block(4,6,-1,CONCRETE:0)
Block(4,6,0,AIR:0)
Block(4,6,1,AIR:0)
Block(4,6,2,WEB:0)
Block(4,6,3,AIR:0)
Block(4,6,4,AIR:0)
Block(4,6,5,AIR:0)
Block(4,6,6,AIR:0)
Block(4,6,7,AIR:0)
Block(4,6,8,AIR:0)
Block(4,6,9,CONCRETE:0)
Block(4,7,-6,CONCRETE:0)
Block(4,7,-5,CONCRETE:0)
Block(4,7,-4,CONCRETE:0)
Block(4,7,-3,CONCRETE:0)
Block(4,7,-2,CONCRETE:0)
Block(4,7,-1,CONCRETE:0)
Block(4,7,0,CONCRETE:0)
Block(4,7,1,CONCRETE:0)
Block(4,7,2,CONCRETE:0)
Block(4,7,3,CONCRETE:0)
Block(4,7,4,CONCRETE:0)
Block(4,7,5,CONCRETE:0)
Block(4,7,6,CONCRETE:0)
Block(4,7,7,CONCRETE:0)
Block(4,7,8,CONCRETE:0)
Block(4,7,9,CONCRETE:0)
Block(4,8,-6,CONCRETE:0)
Block(4,8,-5,CONCRETE:0)
Block(4,8,-4,CONCRETE:0)
Block(4,8,-3,CONCRETE:0)
Block(4,8,-2,CONCRETE:0)
Block(4,8,-1,CONCRETE:0)
Block(4,9,-6,CONCRETE:0)
Block(4,9,-5,CONCRETE:0)
Block(4,9,-4,CONCRETE:0)
Block(4,9,-3,CONCRETE:0)
Block(4,9,-2,CONCRETE:0)
Block(4,9,-1,CONCRETE:0)
Block(4,10,-6,CONCRETE:0)
Block(4,10,-5,CONCRETE:0)
Block(4,10,-4,CONCRETE:0)
Block(4,10,-3,CONCRETE:0)
Block(4,10,-2,CONCRETE:0)
Block(4,10,-1,CONCRETE:0)
Block(4,11,-6,CONCRETE:0)
Block(4,11,-5,CONCRETE:0)
Block(4,11,-4,CONCRETE:0)
Block(4,11,-3,CONCRETE:0)
Block(4,11,-2,CONCRETE:0)
Block(4,11,-1,CONCRETE:0)
Block(4,12,-6,CONCRETE:0)
Block(4,12,-5,CONCRETE:0)
Block(4,12,-4,CONCRETE:0)
Block(4,12,-3,CONCRETE:0)
Block(4,12,-2,CONCRETE:0)
Block(4,12,-1,CONCRETE:0)
Block(4,13,-6,CONCRETE:0)
Block(4,13,-5,CONCRETE:0)
Block(4,13,-4,CONCRETE:0)
Block(4,13,-3,CONCRETE:0)
Block(4,13,-2,CONCRETE:0)
Block(4,13,-1,CONCRETE:0)
Block(4,14,-6,CONCRETE:0)
Block(4,14,-5,CONCRETE:0)
Block(4,14,-4,CONCRETE:0)
Block(4,14,-3,CONCRETE:0)
Block(4,14,-2,CONCRETE:0)
Block(4,14,-1,CONCRETE:0)
Block(4,15,-6,CONCRETE:0)
Block(4,15,-5,CONCRETE:0)
Block(4,15,-4,CONCRETE:0)
Block(4,15,-3,CONCRETE:0)
Block(4,15,-2,CONCRETE:0)
Block(4,15,-1,CONCRETE:0)
Block(4,15,0,CONCRETE:0)
Block(4,15,1,CONCRETE:0)
Block(4,16,-6,CONCRETE:0)
Block(4,16,-5,CONCRETE:0)
Block(4,16,-4,CONCRETE:0)
Block(4,16,-3,CONCRETE:0)
Block(4,16,-2,CONCRETE:0)
Block(4,16,-1,CONCRETE:0)
Block(4,16,0,CONCRETE:0)
Block(4,16,1,CONCRETE:0)
Block(4,17,-6,CONCRETE:0)
Block(4,17,-5,CONCRETE:0)
Block(4,17,-4,CONCRETE:0)
Block(4,17,-3,CONCRETE:0)
Block(4,17,-2,CONCRETE:0)
Block(4,17,-1,CONCRETE:0)
Block(4,17,0,CONCRETE:0)
Block(4,17,1,CONCRETE:0)
Block(4,17,2,CONCRETE:0)
Block(4,17,3,CONCRETE:0)
Block(4,17,4,CONCRETE:0)
Block(4,18,-6,CONCRETE:0)
Block(4,18,-5,IRON_FENCE:0)
Block(4,18,-4,IRON_FENCE:0)
Block(4,18,-3,IRON_FENCE:0)
Block(4,18,-2,IRON_FENCE:0)
Block(4,18,-1,SMOOTH_BRICK:0)
Block(4,18,0,AIR:0)
Block(4,18,1,AIR:0)
Block(4,18,2,SMOOTH_STAIRS:1)
Block(4,18,3,quark:basalt_wall:0)
Block(4,18,4,CONCRETE:0)
Block(4,19,-6,CONCRETE:0)
Block(4,19,-5,IRON_FENCE:0)
Block(4,19,-4,IRON_FENCE:0)
Block(4,19,-3,IRON_FENCE:0)
Block(4,19,-2,IRON_FENCE:0)
Block(4,19,-1,AIR:0)
Block(4,19,0,AIR:0)
Block(4,19,1,AIR:0)
Block(4,19,2,SMOOTH_STAIRS:5)
Block(4,19,3,quark:basalt_wall:0)
Block(4,19,4,CONCRETE:0)
Block(4,20,-6,CONCRETE:0)
Block(4,20,-5,AIR:0)
Block(4,20,-4,STEP:8)
Block(4,20,-3,AIR:0)
Block(4,20,-2,AIR:0)
Block(4,20,-1,AIR:0)
Block(4,20,0,AIR:0)
Block(4,20,1,AIR:0)
Block(4,20,2,DROPPER:4,f_bunker_storage/66-dropper.nbt)
Block(4,20,3,CONCRETE:0)
Block(4,20,4,CONCRETE:0)
Block(4,20,5,CONCRETE:0)
Block(4,21,-6,CONCRETE:0)
Block(4,21,-5,CONCRETE:0)
Block(4,21,-4,CONCRETE:0)
Block(4,21,-3,CONCRETE:0)
Block(4,21,-2,CONCRETE:0)
Block(4,21,-1,CONCRETE:0)
Block(4,21,0,CONCRETE:0)
Block(4,21,1,CONCRETE:0)
Block(4,21,2,STEP:0)
Block(4,21,3,CONCRETE:0)
Block(4,21,4,STEP:0)
Block(4,21,5,CONCRETE:0)
Block(4,22,1,CONCRETE:0)
Block(4,22,2,AIR:0)
Block(4,22,3,SMOOTH_STAIRS:0)
Block(4,22,4,AIR:0)
Block(4,22,5,CONCRETE:0)
Block(4,23,1,CONCRETE:0)
Block(4,23,2,AIR:0)
Block(4,23,3,AIR:0)
Block(4,23,4,AIR:0)
Block(4,23,5,CONCRETE:0)
Block(4,24,1,CONCRETE:0)
Block(4,24,2,AIR:0)
Block(4,24,3,AIR:0)
Block(4,24,4,AIR:0)
Block(4,24,5,CONCRETE:0)
Block(4,25,1,CONCRETE:0)
Block(4,25,2,AIR:0)
Block(4,25,3,AIR:0)
Block(4,25,4,AIR:0)
Block(4,25,5,CONCRETE:0)
Block(4,26,1,CONCRETE:0)
Block(4,26,2,CONCRETE:0)
Block(4,26,3,CONCRETE:0)
Block(4,26,4,CONCRETE:0)
Block(4,26,5,SMOOTH_STAIRS:3)
Block(4,27,3,CONCRETE:0)
Block(4,27,4,CONCRETE:0)
Block(5,0,-6,CONCRETE:0)
Block(5,0,-5,CONCRETE:0)
Block(5,0,-4,CONCRETE:0)
Block(5,0,-3,CONCRETE:0)
Block(5,0,-2,CONCRETE:0)
Block(5,0,-1,CONCRETE:0)
Block(5,0,0,CONCRETE:0)
Block(5,0,1,CONCRETE:0)
Block(5,0,2,CONCRETE:0)
Block(5,0,3,CONCRETE:0)
Block(5,0,4,CONCRETE:0)
Block(5,0,5,CONCRETE:0)
Block(5,0,6,CONCRETE:0)
Block(5,0,7,CONCRETE:0)
Block(5,0,8,CONCRETE:0)
Block(5,0,9,CONCRETE:0)
Block(5,1,-6,CONCRETE:0)
Block(5,1,-5,CONCRETE:0)
Block(5,1,-4,CONCRETE:0)
Block(5,1,-3,CONCRETE:0)
Block(5,1,-2,CONCRETE:0)
Block(5,1,-1,CONCRETE:0)
Block(5,1,0,CONCRETE:0)
Block(5,1,1,CONCRETE:0)
Block(5,1,2,CONCRETE:0)
Block(5,1,3,CONCRETE:0)
Block(5,1,4,quark:lit_lamp:0)
Block(5,1,5,CONCRETE:0)
Block(5,1,6,CONCRETE:0)
Block(5,1,7,CONCRETE:0)
Block(5,1,8,CONCRETE:0)
Block(5,1,9,CONCRETE:0)
Block(5,2,-6,CONCRETE:0)
Block(5,2,-5,CONCRETE:0)
Block(5,2,-4,CONCRETE:0)
Block(5,2,-3,CONCRETE:0)
Block(5,2,-2,CONCRETE:0)
Block(5,2,-1,CONCRETE:0)
Block(5,2,0,CONCRETE:0)
Block(5,2,1,CONCRETE:0)
Block(5,2,2,CONCRETE:0)
Block(5,2,3,CONCRETE:0)
Block(5,2,4,quark:grate:0)
Block(5,2,5,CONCRETE:0)
Block(5,2,6,CONCRETE:0)
Block(5,2,7,CONCRETE:0)
Block(5,2,8,CONCRETE:0)
Block(5,2,9,CONCRETE:0)
Block(5,3,-6,CONCRETE:0)
Block(5,3,-5,IRON_BLOCK:0)
Block(5,3,-4,IRON_BLOCK:0)
Block(5,3,-3,AIR:0)
Block(5,3,-2,AIR:0)
Block(5,3,-1,AIR:0)
Block(5,3,0,AIR:0)
Block(5,3,1,AIR:0)
Block(5,3,2,SMOOTH_BRICK:0)
Block(5,3,3,AIR:0)
Block(5,3,4,AIR:0)
Block(5,3,5,AIR:0)
Block(5,3,6,SMOOTH_BRICK:0)
Block(5,3,7,AIR:0)
RandomBlock(5,3,8,WOOD:5,5,WOOD:5,../../../Chests/Loot/manhunt_vagrant_scrap.nbt,100)
Block(5,3,9,CONCRETE:0)
Block(5,4,-6,CONCRETE:0)
Block(5,4,-5,SMOOTH_BRICK:0)
Block(5,4,-4,AIR:0)
Block(5,4,-3,AIR:0)
Block(5,4,-2,AIR:0)
Block(5,4,-1,AIR:0)
Block(5,4,0,AIR:0)
Block(5,4,1,AIR:0)
Block(5,4,2,AIR:0)
Block(5,4,3,AIR:0)
Block(5,4,4,AIR:0)
Block(5,4,5,AIR:0)
Block(5,4,6,AIR:0)
Block(5,4,7,AIR:0)
Block(5,4,8,CHEST:2,../../../Chests/Loot/manhunt_military_common.nbt)
Block(5,4,9,CONCRETE:0)
Block(5,5,-6,CONCRETE:0)
Block(5,5,-5,AIR:0)
Block(5,5,-4,AIR:0)
Block(5,5,-3,AIR:0)
Block(5,5,-2,AIR:0)
Block(5,5,-1,AIR:0)
Block(5,5,0,AIR:0)
Block(5,5,1,AIR:0)
Block(5,5,2,AIR:0)
Block(5,5,3,AIR:0)
Block(5,5,4,AIR:0)
Block(5,5,5,AIR:0)
Block(5,5,6,AIR:0)
Block(5,5,7,AIR:0)
Block(5,5,8,AIR:0)
Block(5,5,9,CONCRETE:0)
Block(5,6,-6,CONCRETE:0)
Block(5,6,-5,AIR:0)
Block(5,6,-4,AIR:0)
Block(5,6,-3,IRON_BLOCK:0)
Block(5,6,-2,CONCRETE:0)
Block(5,6,-1,AIR:0)
Block(5,6,0,AIR:0)
Block(5,6,1,AIR:0)
Block(5,6,2,WEB:0)
Block(5,6,3,AIR:0)
Block(5,6,4,AIR:0)
Block(5,6,5,AIR:0)
Block(5,6,6,AIR:0)
Block(5,6,7,AIR:0)
Block(5,6,8,AIR:0)
Block(5,6,9,CONCRETE:0)
Block(5,7,-6,CONCRETE:0)
Block(5,7,-5,IRON_BLOCK:0)
Block(5,7,-4,IRON_BLOCK:0)
Block(5,7,-3,SMOOTH_BRICK:0)
Block(5,7,-2,CONCRETE:0)
Block(5,7,-1,CONCRETE:0)
Block(5,7,0,CONCRETE:0)
Block(5,7,1,CONCRETE:0)
Block(5,7,2,CONCRETE:0)
Block(5,7,3,CONCRETE:0)
Block(5,7,4,CONCRETE:0)
Block(5,7,5,CONCRETE:0)
Block(5,7,6,CONCRETE:0)
Block(5,7,7,CONCRETE:0)
Block(5,7,8,CONCRETE:0)
Block(5,7,9,CONCRETE:0)
Block(5,8,-6,CONCRETE:0)
Block(5,8,-5,AIR:0)
Block(5,8,-4,AIR:0)
Block(5,8,-3,AIR:0)
Block(5,8,-2,CONCRETE:0)
Block(5,8,-1,CONCRETE:0)
Block(5,9,-6,CONCRETE:0)
Block(5,9,-5,AIR:0)
Block(5,9,-4,AIR:0)
Block(5,9,-3,AIR:0)
Block(5,9,-2,CONCRETE:0)
Block(5,9,-1,CONCRETE:0)
Block(5,10,-6,CONCRETE:0)
Block(5,10,-5,AIR:0)
Block(5,10,-4,AIR:0)
Block(5,10,-3,IRON_BLOCK:0)
Block(5,10,-2,CONCRETE:0)
Block(5,10,-1,CONCRETE:0)
Block(5,11,-6,CONCRETE:0)
Block(5,11,-5,IRON_BLOCK:0)
Block(5,11,-4,IRON_BLOCK:0)
Block(5,11,-3,SMOOTH_BRICK:0)
Block(5,11,-2,CONCRETE:0)
Block(5,11,-1,CONCRETE:0)
Block(5,12,-6,CONCRETE:0)
Block(5,12,-5,AIR:0)
Block(5,12,-4,AIR:0)
Block(5,12,-3,AIR:0)
Block(5,12,-2,CONCRETE:0)
Block(5,12,-1,CONCRETE:0)
Block(5,13,-6,CONCRETE:0)
Block(5,13,-5,AIR:0)
Block(5,13,-4,AIR:0)
Block(5,13,-3,AIR:0)
Block(5,13,-2,CONCRETE:0)
Block(5,13,-1,CONCRETE:0)
Block(5,14,-6,CONCRETE:0)
Block(5,14,-5,AIR:0)
Block(5,14,-4,AIR:0)
Block(5,14,-3,IRON_BLOCK:0)
Block(5,14,-2,CONCRETE:0)
Block(5,14,-1,CONCRETE:0)
Block(5,15,-6,CONCRETE:0)
Block(5,15,-5,IRON_BLOCK:0)
Block(5,15,-4,IRON_BLOCK:0)
Block(5,15,-3,AIR:0)
Block(5,15,-2,CONCRETE:0)
Block(5,15,-1,CONCRETE:0)
Block(5,15,0,CONCRETE:0)
Block(5,15,1,CONCRETE:0)
Block(5,16,-6,CONCRETE:0)
Block(5,16,-5,AIR:0)
Block(5,16,-4,AIR:0)
Block(5,16,-3,AIR:0)
Block(5,16,-2,CONCRETE:0)
Block(5,16,-1,CONCRETE:0)
Block(5,16,0,CONCRETE:0)
Block(5,16,1,CONCRETE:0)
Block(5,17,-6,CONCRETE:0)
Block(5,17,-5,AIR:0)
Block(5,17,-4,AIR:0)
Block(5,17,-3,AIR:0)
Block(5,17,-2,CONCRETE:0)
Block(5,17,-1,CONCRETE:0)
Block(5,17,0,CONCRETE:0)
Block(5,17,1,CONCRETE:0)
Block(5,17,2,CONCRETE:0)
Block(5,17,3,CONCRETE:0)
Block(5,17,4,CONCRETE:0)
Block(5,18,-6,CONCRETE:0)
Block(5,18,-5,AIR:0)
Block(5,18,-4,AIR:0)
Block(5,18,-3,AIR:0)
Block(5,18,-2,IRON_FENCE:0)
Block(5,18,-1,AIR:0)
Block(5,18,0,AIR:0)
Block(5,18,1,AIR:0)
Block(5,18,2,SMOOTH_STAIRS:0)
Block(5,18,3,quark:basalt_wall:0)
Block(5,18,4,CONCRETE:0)
Block(5,19,-6,CONCRETE:0)
Block(5,19,-5,AIR:0)
Block(5,19,-4,AIR:0)
Block(5,19,-3,AIR:0)
Block(5,19,-2,IRON_FENCE:0)
Block(5,19,-1,AIR:0)
Block(5,19,0,AIR:0)
Block(5,19,1,AIR:0)
Block(5,19,2,SMOOTH_STAIRS:4)
Block(5,19,3,quark:basalt_wall:0)
Block(5,19,4,CONCRETE:0)
Block(5,20,-6,CONCRETE:0)
Block(5,20,-5,AIR:0)
Block(5,20,-4,STEP:8)
Block(5,20,-3,AIR:0)
Block(5,20,-2,AIR:0)
Block(5,20,-1,AIR:0)
Block(5,20,0,AIR:0)
Block(5,20,1,LEVER:4)
Block(5,20,2,DROPPER:4,f_bunker_storage/69-dropper.nbt)
Block(5,20,3,CONCRETE:0)
Block(5,20,4,CONCRETE:0)
Block(5,20,5,CONCRETE:0)
Block(5,21,-6,CONCRETE:0)
Block(5,21,-5,CONCRETE:0)
Block(5,21,-4,CONCRETE:0)
Block(5,21,-3,CONCRETE:0)
Block(5,21,-2,CONCRETE:0)
Block(5,21,-1,CONCRETE:0)
Block(5,21,0,CONCRETE:0)
Block(5,21,1,CONCRETE:0)
Block(5,21,2,IRON_BLOCK:0)
Block(5,21,3,CONCRETE:0)
Block(5,21,4,IRON_BLOCK:0)
Block(5,21,5,CONCRETE:0)
Block(5,22,1,CONCRETE:0)
Block(5,22,2,IRON_BLOCK:0)
Block(5,22,3,CONCRETE:0)
Block(5,22,4,IRON_BLOCK:0)
Block(5,22,5,CONCRETE:0)
Block(5,23,1,CONCRETE:0)
Block(5,23,2,IRON_BLOCK:0)
Block(5,23,3,SMOOTH_STAIRS:0)
Block(5,23,4,IRON_BLOCK:0)
Block(5,23,5,CONCRETE:0)
Block(5,24,1,CONCRETE:0)
Block(5,24,2,IRON_BLOCK:0)
Block(5,24,3,AIR:0)
Block(5,24,4,IRON_BLOCK:0)
Block(5,24,5,CONCRETE:0)
Block(5,25,1,CONCRETE:0)
Block(5,25,2,IRON_BLOCK:0)
Block(5,25,3,quark:iron_button:4)
Block(5,25,4,IRON_BLOCK:0)
Block(5,25,5,CONCRETE:0)
Block(5,26,1,CONCRETE:0)
Block(5,26,2,IRON_BLOCK:0)
Block(5,26,3,IRON_BLOCK:0)
Block(5,26,4,IRON_BLOCK:0)
Block(5,26,5,CONCRETE:0)
Block(5,27,2,CONCRETE:0)
Block(5,27,3,CONCRETE:0)
Block(5,27,4,CONCRETE:0)
Block(6,0,-6,CONCRETE:0)
Block(6,0,-5,CONCRETE:0)
Block(6,0,-4,CONCRETE:0)
Block(6,0,-3,CONCRETE:0)
Block(6,0,-2,CONCRETE:0)
Block(6,0,-1,CONCRETE:0)
Block(6,0,0,CONCRETE:0)
Block(6,0,1,CONCRETE:0)
Block(6,0,2,CONCRETE:0)
Block(6,0,3,CONCRETE:0)
Block(6,0,4,CONCRETE:0)
Block(6,0,5,CONCRETE:0)
Block(6,0,6,CONCRETE:0)
Block(6,0,7,CONCRETE:0)
Block(6,0,8,CONCRETE:0)
Block(6,0,9,CONCRETE:0)
Block(6,1,-6,CONCRETE:0)
Block(6,1,-5,CONCRETE:0)
Block(6,1,-4,CONCRETE:0)
Block(6,1,-3,CONCRETE:0)
Block(6,1,-2,CONCRETE:0)
Block(6,1,-1,CONCRETE:0)
Block(6,1,0,CONCRETE:0)
Block(6,1,1,CONCRETE:0)
Block(6,1,2,CONCRETE:0)
Block(6,1,3,CONCRETE:0)
Block(6,1,4,CONCRETE:0)
Block(6,1,5,CONCRETE:0)
Block(6,1,6,CONCRETE:0)
Block(6,1,7,CONCRETE:0)
Block(6,1,8,CONCRETE:0)
Block(6,1,9,CONCRETE:0)
Block(6,2,-6,CONCRETE:0)
Block(6,2,-5,CONCRETE:0)
Block(6,2,-4,CONCRETE:0)
Block(6,2,-3,CONCRETE:0)
Block(6,2,-2,CONCRETE:0)
Block(6,2,-1,CONCRETE:0)
Block(6,2,0,CONCRETE:0)
Block(6,2,1,CONCRETE:0)
Block(6,2,2,CONCRETE:0)
Block(6,2,3,CONCRETE:0)
Block(6,2,4,CONCRETE:0)
Block(6,2,5,CONCRETE:0)
Block(6,2,6,CONCRETE:0)
Block(6,2,7,CONCRETE:0)
Block(6,2,8,CONCRETE:0)
Block(6,2,9,CONCRETE:0)
Block(6,3,-6,CONCRETE:0)
Block(6,3,-5,AIR:0)
Block(6,3,-4,CONCRETE:0)
Block(6,3,-3,AIR:0)
Block(6,3,-2,AIR:0)
Block(6,3,-1,SMOOTH_BRICK:0)
Block(6,3,0,AIR:0)
Block(6,3,1,AIR:0)
Block(6,3,2,AIR:0)
Block(6,3,3,AIR:0)
Block(6,3,4,AIR:0)
Block(6,3,5,AIR:0)
Block(6,3,6,AIR:0)
Block(6,3,7,AIR:0)
RandomBlock(6,3,8,WOOD:5,5,WOOD:5,../../../Chests/Loot/manhunt_vagrant_scrap.nbt,100)
Block(6,3,9,CONCRETE:0)
Block(6,4,-6,CONCRETE:0)
Block(6,4,-5,IRON_BLOCK:0)
Block(6,4,-4,CONCRETE:0)
Block(6,4,-3,AIR:0)
Block(6,4,-2,AIR:0)
Block(6,4,-1,AIR:0)
Block(6,4,0,AIR:0)
Block(6,4,1,AIR:0)
Block(6,4,2,AIR:0)
Block(6,4,3,AIR:0)
Block(6,4,4,AIR:0)
Block(6,4,5,AIR:0)
Block(6,4,6,AIR:0)
Block(6,4,7,AIR:0)
RandomBlock(6,4,8,WOOD:5,5,WOOD:5,../../../Chests/Loot/manhunt_vagrant_scrap.nbt,100)
Block(6,4,9,CONCRETE:0)
Block(6,5,-6,CONCRETE:0)
Block(6,5,-5,AIR:0)
Block(6,5,-4,CONCRETE:0)
Block(6,5,-3,AIR:0)
Block(6,5,-2,AIR:0)
Block(6,5,-1,AIR:0)
Block(6,5,0,AIR:0)
Block(6,5,1,AIR:0)
Block(6,5,2,AIR:0)
Block(6,5,3,AIR:0)
Block(6,5,4,AIR:0)
Block(6,5,5,AIR:0)
Block(6,5,6,AIR:0)
Block(6,5,7,AIR:0)
Block(6,5,8,WEB:0)
Block(6,5,9,CONCRETE:0)
Block(6,6,-6,CONCRETE:0)
Block(6,6,-5,AIR:0)
Block(6,6,-4,CONCRETE:0)
Block(6,6,-3,IRON_BLOCK:0)
Block(6,6,-2,CONCRETE:0)
Block(6,6,-1,AIR:0)
Block(6,6,0,AIR:0)
Block(6,6,1,AIR:0)
Block(6,6,2,AIR:0)
Block(6,6,3,AIR:0)
Block(6,6,4,AIR:0)
Block(6,6,5,AIR:0)
Block(6,6,6,AIR:0)
Block(6,6,7,AIR:0)
Block(6,6,8,AIR:0)
Block(6,6,9,CONCRETE:0)
Block(6,7,-6,CONCRETE:0)
Block(6,7,-5,AIR:0)
Block(6,7,-4,CONCRETE:0)
Block(6,7,-3,AIR:0)
Block(6,7,-2,CONCRETE:0)
Block(6,7,-1,CONCRETE:0)
Block(6,7,0,CONCRETE:0)
Block(6,7,1,CONCRETE:0)
Block(6,7,2,CONCRETE:0)
Block(6,7,3,CONCRETE:0)
Block(6,7,4,CONCRETE:0)
Block(6,7,5,CONCRETE:0)
Block(6,7,6,CONCRETE:0)
Block(6,7,7,CONCRETE:0)
Block(6,7,8,CONCRETE:0)
Block(6,7,9,CONCRETE:0)
Block(6,8,-6,CONCRETE:0)
Block(6,8,-5,IRON_BLOCK:0)
Block(6,8,-4,CONCRETE:0)
Block(6,8,-3,AIR:0)
Block(6,8,-2,GLOWSTONE:0)
Block(6,8,-1,CONCRETE:0)
Block(6,8,5,CONCRETE:0)
Block(6,9,-6,CONCRETE:0)
Block(6,9,-5,AIR:0)
Block(6,9,-4,CONCRETE:0)
Block(6,9,-3,AIR:0)
Block(6,9,-2,CONCRETE:0)
Block(6,9,-1,CONCRETE:0)
Block(6,9,5,CONCRETE:0)
Block(6,10,-6,CONCRETE:0)
Block(6,10,-5,AIR:0)
Block(6,10,-4,CONCRETE:0)
Block(6,10,-3,IRON_BLOCK:0)
Block(6,10,-2,CONCRETE:0)
Block(6,10,-1,CONCRETE:0)
Block(6,10,5,CONCRETE:0)
Block(6,11,-6,CONCRETE:0)
Block(6,11,-5,AIR:0)
Block(6,11,-4,CONCRETE:0)
Block(6,11,-3,AIR:0)
Block(6,11,-2,CONCRETE:0)
Block(6,11,-1,CONCRETE:0)
Block(6,11,5,CONCRETE:0)
Block(6,12,-6,CONCRETE:0)
Block(6,12,-5,IRON_BLOCK:0)
Block(6,12,-4,CONCRETE:0)
Block(6,12,-3,AIR:0)
Block(6,12,-2,GLOWSTONE:0)
Block(6,12,-1,CONCRETE:0)
Block(6,12,5,CONCRETE:0)
Block(6,13,-6,CONCRETE:0)
Block(6,13,-5,AIR:0)
Block(6,13,-4,CONCRETE:0)
Block(6,13,-3,AIR:0)
Block(6,13,-2,CONCRETE:0)
Block(6,13,-1,CONCRETE:0)
Block(6,13,5,CONCRETE:0)
Block(6,14,-6,CONCRETE:0)
Block(6,14,-5,AIR:0)
Block(6,14,-4,CONCRETE:0)
Block(6,14,-3,IRON_BLOCK:0)
Block(6,14,-2,CONCRETE:0)
Block(6,14,-1,CONCRETE:0)
Block(6,14,5,CONCRETE:0)
Block(6,15,-6,CONCRETE:0)
Block(6,15,-5,AIR:0)
Block(6,15,-4,CONCRETE:0)
Block(6,15,-3,AIR:0)
Block(6,15,-2,CONCRETE:0)
Block(6,15,-1,CONCRETE:0)
Block(6,15,0,CONCRETE:0)
Block(6,15,1,CONCRETE:0)
Block(6,15,5,CONCRETE:0)
Block(6,16,-6,CONCRETE:0)
Block(6,16,-5,IRON_BLOCK:0)
Block(6,16,-4,CONCRETE:0)
Block(6,16,-3,AIR:0)
Block(6,16,-2,GLOWSTONE:0)
Block(6,16,-1,CONCRETE:0)
Block(6,16,0,quark:lit_lamp:0)
Block(6,16,1,CONCRETE:0)
Block(6,16,5,CONCRETE:0)
Block(6,17,-6,CONCRETE:0)
Block(6,17,-5,AIR:0)
Block(6,17,-4,CONCRETE:0)
Block(6,17,-3,IRON_BLOCK:0)
Block(6,17,-2,CONCRETE:0)
Block(6,17,-1,CONCRETE:0)
Block(6,17,0,quark:grate:0)
Block(6,17,1,CONCRETE:0)
Block(6,17,2,CONCRETE:0)
Block(6,17,3,CONCRETE:0)
Block(6,17,4,CONCRETE:0)
Block(6,17,5,CONCRETE:0)
Block(6,18,-6,CONCRETE:0)
Block(6,18,-5,AIR:0)
Block(6,18,-4,IRON_FENCE:0)
Block(6,18,-3,IRON_FENCE:0)
Block(6,18,-2,IRON_FENCE:0)
Block(6,18,-1,AIR:0)
Block(6,18,0,AIR:0)
Block(6,18,1,WEB:0)
Block(6,18,2,OBSERVER:3)
Block(6,18,3,CONCRETE:0)
Block(6,18,4,CONCRETE:0)
Block(6,18,5,CONCRETE:0)
Block(6,19,-6,CONCRETE:0)
Block(6,19,-5,AIR:0)
Block(6,19,-4,IRON_FENCE:0)
Block(6,19,-3,IRON_FENCE:0)
Block(6,19,-2,IRON_FENCE:0)
Block(6,19,-1,AIR:0)
Block(6,19,0,AIR:0)
Block(6,19,1,AIR:0)
Block(6,19,2,OBSERVER:3)
Block(6,19,3,CONCRETE:0)
Block(6,19,4,CONCRETE:0)
Block(6,19,5,CONCRETE:0)
Block(6,20,-6,CONCRETE:0)
Block(6,20,-5,WEB:0)
Block(6,20,-4,STEP:8)
Block(6,20,-3,AIR:0)
Block(6,20,-2,AIR:0)
Block(6,20,-1,AIR:0)
Block(6,20,0,AIR:0)
Block(6,20,1,LEVER:4)
Block(6,20,2,DROPPER:4,f_bunker_storage/72-dropper.nbt)
Block(6,20,3,CONCRETE:0)
Block(6,20,4,CONCRETE:0)
Block(6,20,5,CONCRETE:0)
Block(6,21,-6,CONCRETE:0)
Block(6,21,-5,CONCRETE:0)
Block(6,21,-4,CONCRETE:0)
Block(6,21,-3,CONCRETE:0)
Block(6,21,-2,CONCRETE:0)
Block(6,21,-1,CONCRETE:0)
Block(6,21,0,CONCRETE:0)
Block(6,21,1,CONCRETE:0)
Block(6,21,2,CONCRETE:0)
Block(6,21,3,CONCRETE:0)
Block(6,21,4,CONCRETE:0)
Block(6,21,5,CONCRETE:0)
Block(6,22,1,CONCRETE:0)
Block(6,22,2,CONCRETE:0)
Block(6,22,3,CONCRETE:0)
Block(6,22,4,CONCRETE:0)
Block(6,22,5,CONCRETE:0)
Block(6,23,1,CONCRETE:0)
Block(6,23,2,CONCRETE:0)
Block(6,23,3,CONCRETE:0)
Block(6,23,4,CONCRETE:0)
Block(6,23,5,CONCRETE:0)
Block(6,24,1,CONCRETE:0)
Block(6,24,2,AIR:0)
Block(6,24,3,IRON_DOOR_BLOCK:0)
Block(6,24,4,AIR:0)
Block(6,24,5,CONCRETE:0)
Block(6,25,1,CONCRETE:0)
Block(6,25,2,SMOOTH_BRICK:0)
Block(6,25,3,IRON_DOOR_BLOCK:8)
Block(6,25,4,quark:iron_button:1)
Block(6,25,5,CONCRETE:0)
Block(6,26,1,CONCRETE:0)
Block(6,26,2,CONCRETE:0)
Block(6,26,3,CONCRETE:0)
Block(6,26,4,CONCRETE:0)
Block(6,26,5,CONCRETE:0)
Block(6,27,2,CONCRETE:0)
Block(7,0,-6,CONCRETE:0)
Block(7,0,-5,CONCRETE:0)
Block(7,0,-4,CONCRETE:0)
Block(7,0,-3,CONCRETE:0)
Block(7,0,-2,CONCRETE:0)
Block(7,0,-1,CONCRETE:0)
Block(7,0,0,CONCRETE:0)
Block(7,0,1,CONCRETE:0)
Block(7,0,2,CONCRETE:0)
Block(7,0,3,CONCRETE:0)
Block(7,0,4,CONCRETE:0)
Block(7,0,5,CONCRETE:0)
Block(7,0,6,CONCRETE:0)
Block(7,0,7,CONCRETE:0)
Block(7,0,8,CONCRETE:0)
Block(7,0,9,CONCRETE:0)
Block(7,1,-6,CONCRETE:0)
Block(7,1,-5,CONCRETE:0)
Block(7,1,-4,CONCRETE:0)
Block(7,1,-3,CONCRETE:0)
Block(7,1,-2,CONCRETE:0)
Block(7,1,-1,CONCRETE:0)
Block(7,1,0,CONCRETE:0)
Block(7,1,1,CONCRETE:0)
Block(7,1,2,CONCRETE:0)
Block(7,1,3,CONCRETE:0)
Block(7,1,4,CONCRETE:0)
Block(7,1,5,CONCRETE:0)
Block(7,1,6,CONCRETE:0)
Block(7,1,7,CONCRETE:0)
Block(7,1,8,CONCRETE:0)
Block(7,1,9,CONCRETE:0)
Block(7,2,-6,CONCRETE:0)
Block(7,2,-5,CONCRETE:0)
Block(7,2,-4,CONCRETE:0)
Block(7,2,-3,CONCRETE:0)
Block(7,2,-2,CONCRETE:0)
Block(7,2,-1,CONCRETE:0)
Block(7,2,0,CONCRETE:0)
Block(7,2,1,CONCRETE:0)
Block(7,2,2,CONCRETE:0)
Block(7,2,3,CONCRETE:0)
Block(7,2,4,CONCRETE:0)
Block(7,2,5,CONCRETE:0)
Block(7,2,6,CONCRETE:0)
Block(7,2,7,CONCRETE:0)
Block(7,2,8,CONCRETE:0)
Block(7,2,9,CONCRETE:0)
Block(7,3,-6,CONCRETE:0)
Block(7,3,-5,WEB:0)
Block(7,3,-4,AIR:0)
Block(7,3,-3,AIR:0)
Block(7,3,-2,AIR:0)
Block(7,3,-1,WOOD:1)
Block(7,3,0,WOOD:1)
Block(7,3,1,AIR:0)
Block(7,3,2,CONCRETE:0)
RandomBlock(7,3,3,WOOD:5,5,WOOD:5,../../../Chests/Loot/manhunt_vagrant_scrap.nbt,100)
RandomBlock(7,3,4,WOOD:5,5,WOOD:5,../../../Chests/Loot/manhunt_vagrant_scrap.nbt,100)
Block(7,3,5,WEB:0)
Block(7,3,6,CONCRETE:0)
RandomBlock(7,3,7,WOOD:5,5,WOOD:5,../../../Chests/Loot/manhunt_vagrant_scrap.nbt,100)
RandomBlock(7,3,8,WOOD:5,5,WOOD:5,../../../Chests/Loot/manhunt_vagrant_scrap.nbt,100)
Block(7,3,9,CONCRETE:0)
Block(7,4,-6,CONCRETE:0)
Block(7,4,-5,IRON_BLOCK:0)
Block(7,4,-4,AIR:0)
Block(7,4,-3,AIR:0)
Block(7,4,-2,AIR:0)
Block(7,4,-1,SMOOTH_BRICK)
Block(7,4,0,SMOOTH_BRICK:0)
Block(7,4,1,AIR:0)
Block(7,4,2,CONCRETE:0)
RandomBlock(7,4,3,WOOD:5,5,WOOD:5,../../../Chests/Loot/manhunt_vagrant_scrap.nbt,100)
Block(7,4,4,WEB:0)
Block(7,4,5,AIR:0)
Block(7,4,6,CONCRETE:0)
Block(7,4,7,AIR:0)
RandomBlock(7,4,8,WOOD:5,5,WOOD:5,../../../Chests/Loot/manhunt_vagrant_scrap.nbt,100)
Block(7,4,9,CONCRETE:0)
Block(7,5,-6,CONCRETE:0)
Block(7,5,-5,AIR:0)
Block(7,5,-4,IRON_BLOCK:0)
Block(7,5,-3,IRON_BLOCK:0)
Block(7,5,-2,AIR:0)
Block(7,5,-1,AIR:0)
Block(7,5,0,AIR:0)
Block(7,5,1,AIR:0)
Block(7,5,2,CONCRETE:0)
Block(7,5,3,AIR:0)
Block(7,5,4,AIR:0)
Block(7,5,5,AIR:0)
Block(7,5,6,CONCRETE:0)
Block(7,5,7,AIR:0)
RandomBlock(7,5,8,WOOD:5,5,WOOD:5,../../../Chests/Loot/manhunt_vagrant_scrap.nbt,100)
Block(7,5,9,CONCRETE:0)
Block(7,6,-6,CONCRETE:0)
Block(7,6,-5,AIR:0)
Block(7,6,-4,AIR:0)
Block(7,6,-3,AIR:0)
Block(7,6,-2,CONCRETE:0)
Block(7,6,-1,AIR:0)
Block(7,6,0,AIR:0)
Block(7,6,1,AIR:0)
Block(7,6,2,CONCRETE:0)
Block(7,6,3,AIR:0)
Block(7,6,4,AIR:0)
Block(7,6,5,AIR:0)
Block(7,6,6,CONCRETE:0)
Block(7,6,7,AIR:0)
Block(7,6,8,WEB:0)
Block(7,6,9,CONCRETE:0)
Block(7,7,-6,CONCRETE:0)
Block(7,7,-5,AIR:0)
Block(7,7,-4,AIR:0)
Block(7,7,-3,AIR:0)
Block(7,7,-2,CONCRETE:0)
Block(7,7,-1,CONCRETE:0)
Block(7,7,0,CONCRETE:0)
Block(7,7,1,CONCRETE:0)
Block(7,7,2,CONCRETE:0)
Block(7,7,3,CONCRETE:0)
Block(7,7,4,CONCRETE:0)
Block(7,7,5,CONCRETE:0)
Block(7,7,6,CONCRETE:0)
Block(7,7,7,CONCRETE:0)
Block(7,7,8,CONCRETE:0)
Block(7,7,9,CONCRETE:0)
Block(7,8,-6,CONCRETE:0)
Block(7,8,-5,IRON_BLOCK:0)
Block(7,8,-4,AIR:0)
Block(7,8,-3,AIR:0)
Block(7,8,-2,CONCRETE:0)
Block(7,8,-1,CONCRETE:0)
Block(7,9,-6,CONCRETE:0)
Block(7,9,-5,SMOOTH_BRICK:0)
Block(7,9,-4,IRON_BLOCK:0)
Block(7,9,-3,IRON_BLOCK:0)
Block(7,9,-2,CONCRETE:0)
Block(7,9,-1,CONCRETE:0)
Block(7,10,-6,CONCRETE:0)
Block(7,10,-5,AIR:0)
Block(7,10,-4,AIR:0)
Block(7,10,-3,AIR:0)
Block(7,10,-2,CONCRETE:0)
Block(7,10,-1,CONCRETE:0)
Block(7,11,-6,CONCRETE:0)
Block(7,11,-5,AIR:0)
Block(7,11,-4,AIR:0)
Block(7,11,-3,AIR:0)
Block(7,11,-2,CONCRETE:0)
Block(7,11,-1,CONCRETE:0)
Block(7,12,-6,CONCRETE:0)
Block(7,12,-5,IRON_BLOCK:0)
Block(7,12,-4,AIR:0)
Block(7,12,-3,AIR:0)
Block(7,12,-2,CONCRETE:0)
Block(7,12,-1,CONCRETE:0)
Block(7,13,-6,CONCRETE:0)
Block(7,13,-5,AIR:0)
Block(7,13,-4,IRON_BLOCK:0)
Block(7,13,-3,IRON_BLOCK:0)
Block(7,13,-2,CONCRETE:0)
Block(7,13,-1,CONCRETE:0)
Block(7,14,-6,CONCRETE:0)
Block(7,14,-5,AIR:0)
Block(7,14,-4,AIR:0)
Block(7,14,-3,AIR:0)
Block(7,14,-2,CONCRETE:0)
Block(7,14,-1,CONCRETE:0)
Block(7,15,-6,CONCRETE:0)
Block(7,15,-5,AIR:0)
Block(7,15,-4,AIR:0)
Block(7,15,-3,AIR:0)
Block(7,15,-2,CONCRETE:0)
Block(7,15,-1,CONCRETE:0)
Block(7,15,0,CONCRETE:0)
Block(7,15,1,CONCRETE:0)
Block(7,16,-6,CONCRETE:0)
Block(7,16,-5,IRON_BLOCK:0)
Block(7,16,-4,AIR:0)
Block(7,16,-3,AIR:0)
Block(7,16,-2,CONCRETE:0)
Block(7,16,-1,CONCRETE:0)
Block(7,16,0,CONCRETE:0)
Block(7,16,1,CONCRETE:0)
Block(7,17,-6,CONCRETE:0)
Block(7,17,-5,AIR:0)
Block(7,17,-4,IRON_BLOCK:0)
Block(7,17,-3,IRON_BLOCK:0)
Block(7,17,-2,CONCRETE:0)
Block(7,17,-1,CONCRETE:0)
Block(7,17,0,CONCRETE:0)
Block(7,17,1,CONCRETE:0)
Block(7,17,2,CONCRETE:0)
Block(7,17,3,CONCRETE:0)
Block(7,18,-6,CONCRETE:0)
Block(7,18,-5,AIR:0)
Block(7,18,-4,AIR:0)
Block(7,18,-3,AIR:0)
Block(7,18,-2,AIR:0)
Block(7,18,-1,AIR:0)
Block(7,18,0,SMOOTH_BRICK:0)
Block(7,18,1,STONE:0)
Block(7,18,2,CONCRETE:0)
Block(7,18,3,CONCRETE:0)
Block(7,19,-6,CONCRETE:0)
Block(7,19,-5,AIR:0)
Block(7,19,-4,AIR:0)
Block(7,19,-3,AIR:0)
Block(7,19,-2,AIR:0)
Block(7,19,-1,SMOOTH_BRICK:0)
Block(7,19,0,AIR:0)
Block(7,19,1,STONE:0)
Block(7,19,2,CONCRETE:0)
Block(7,19,3,CONCRETE:0)
Block(7,20,-6,CONCRETE:0)
Block(7,20,-5,WEB:0)
Block(7,20,-4,STEP:8)
Block(7,20,-3,STEP:8)
Block(7,20,-2,STEP:8)
Block(7,20,-1,STEP:8)
Block(7,20,0,STEP:8)
Block(7,20,1,STONE:0)
Block(7,20,2,CONCRETE:0)
Block(7,20,3,CONCRETE:0)
Block(7,21,-6,CONCRETE:0)
Block(7,21,-5,CONCRETE:0)
Block(7,21,-4,CONCRETE:0)
Block(7,21,-3,CONCRETE:0)
Block(7,21,-2,CONCRETE:0)
Block(7,21,-1,CONCRETE:0)
Block(7,21,0,CONCRETE:0)
Block(7,21,1,CONCRETE:0)
Block(7,21,2,CONCRETE:0)
Block(7,21,3,CONCRETE:0)
Block(8,0,-6,CONCRETE:0)
Block(8,0,-5,CONCRETE:0)
Block(8,0,-4,CONCRETE:0)
Block(8,0,-3,CONCRETE:0)
Block(8,0,-2,CONCRETE:0)
Block(8,0,-1,CONCRETE:0)
Block(8,0,0,CONCRETE:0)
Block(8,0,1,CONCRETE:0)
Block(8,0,2,CONCRETE:0)
Block(8,0,3,CONCRETE:0)
Block(8,0,4,CONCRETE:0)
Block(8,0,5,CONCRETE:0)
