
#######################################################################
# +-----------------------------------------------------------------+ #
# |                            BO4 object                           | #
# +-----------------------------------------------------------------+ #
#######################################################################

# This is the config file of a custom object.
# If you add this object correctly to your BiomeConfigs, it will spawn in the world.

# This is the creator of this BO4 object
Author: NLBlackEagle

# A short description of this BO4 object
Description: No description given

# The settings mode, WriteAll, WriteWithoutComments or WriteDisable. See WorldConfig.
SettingsMode: WriteAll


#######################################################################
# +-----------------------------------------------------------------+ #
# |                          Main settings                          | #
# +-----------------------------------------------------------------+ #
#######################################################################

# If this BO4 should spawn with a fixed rotation, set it here.
# For example: NORTH, EAST, SOUTH or WEST. Empty by default
FixedRotation: 

# This BO4 can only spawn at least Frequency chunks distance away from any other BO4 with the exact same name.
# You can use this to make this BO4 spawn in groups or make sure that this BO4 only spawns once every X chunks.
Frequency: 0

# The spawn height of the BO4: randomY, highestBlock or highestSolidBlock.
SpawnHeight: highestBlock

# When set to true, uses the center of the structure (determined by minimum structure size) when checking the highestBlock to spawn at.
UseCenterForHighestBlock: true

##############################
# Height Limits for the BO4. #
##############################

# When in randomY mode used as the minimum Y or in atMinY mode as the actual Y to spawn this BO4 at.
MinHeight: 0

# When in randomY mode used as the maximum Y to spawn this BO4 at.
MaxHeight: 255

# Copies the blocks and branches of an existing BO4 into this BO4. You can still add blocks and branches in this BO4, they will be added on top of the inherited blocks and branches.
InheritBO3: 

# Rotates the inheritedBO3's resources (blocks, spawners, checks etc) and branches, defaults to NORTH (no rotation).
InheritBO3Rotation: NORTH

# Defaults to true, if true and this is the starting BO4 for this branching structure then this BO4's smoothing and height settings are used for all children (branches).
OverrideChildSettings: true

# Defaults to false, if true then this branch uses it's own height settings (SpawnHeight, minHeight, maxHeight, spawnAtWaterLevel) instead of those defined in the starting BO4 for this branching structure.
OverrideParentHeight: false

# If this is set to true then this BO4 can spawn on top of or inside an existing BO4. If this is set to false then this BO4 will use a bounding box to detect collisions with other BO4's, if a collision is detected then this BO4 won't spawn and the current branch is rolled back.
CanOverride: false

# This branch can only spawn at least branchFrequency chunks (x,z) distance away from any other branch with the exact same name.
BranchFrequency: 0

# Define groups that this branch belongs to along with a minimum (x,z) range in chunks that this branch must have between it and any other members of this group if it is to be allowed to spawn. Syntax is "GroupName:Frequency, GoupName2:Frequency2" etc so for example a branch that belongs to 3 groups: "BranchFrequencyGroup: Ships:10, Vehicles:5, FloatingThings:3".
BranchFrequencyGroup: 

# If this is set to true then this BO4 can only spawn underneath an existing BO4. Used to make sure that dungeons only appear underneath buildings.
MustBeBelowOther: false

# Used with CanOverride: true. A comma-seperated list of BO4s, this BO4's bounding box must collide with one of the BO4's in the list or this BO4 fails to spawn and the current branch is rolled back. AND/OR is supported, comma is OR, space is AND, f.e: branch1, branch2 branch3, branch 4.
MustBeInside: 

# Used with CanOverride: true. A comma-seperated list of BO4s, this BO4's bounding box cannot collide with any of the BO4's in the list or this BO4 fails to spawn and the current branch is rolled back.
CannotBeInside: 

# Used with CanOverride: true. A comma-seperated list of BO4s, if this BO4's bounding box collides with any of the BO4's in the list then those BO4's won't spawn any blocks. This does not remove or roll back any BO4's.
ReplacesBO3: 

# If this is set to true then this BO4 can only spawn inside world borders. Used to make sure that dungeons only appear inside the world borders.
MustBeInsideWorldBorders: true
# Defaults to true. Set to false if the BO4 is not allowed to spawn on a water block
CanSpawnOnWater: true

# Defaults to false. Set to true if the BO4 is allowed to spawn only on a water block
SpawnOnWaterOnly: false

# Defaults to false. Set to true if the BO4 and its smoothing area should ignore water when looking for the highest block to spawn on. Defaults to false (things spawn on top of water)
SpawnUnderWater: false

# Defaults to false. Set to true if the BO4 should spawn at water level
SpawnAtWaterLevel: false

# Spawns the BO4 at a Y offset of this value. Handy when using highestBlock for lowering BO4s into the surrounding terrain when there are layers of ground included in the BO4, also handy when using SpawnAtWaterLevel to lower objects like ships into the water.
HeightOffset: 0

# If set to true removes all AIR blocks from the BO4 so that it can be flooded or buried.
RemoveAir: false

# Replaces all the non-air blocks that are above this BO4 or its smoothing area with the given block material (should be WATER or AIR or NONE), also applies to smoothing areas although OTG intentionally leaves some of the terrain above them intact. WATER can be used in combination with SpawnUnderWater to fill any air blocks underneath waterlevel with water (and any above waterlevel with air).
ReplaceAbove: 

# Replaces all air blocks underneath the BO4 (but not its smoothing area) with the specified material until a solid block is found.
ReplaceBelow: 

# Defaults to true. If set to true then every block in the BO4 of the materials defined in ReplaceWithGroundBlock or ReplaceWithSurfaceBlock will be replaced by the GroundBlock or SurfaceBlock materials configured for the biome the block is spawned in.
ReplaceWithBiomeBlocks: true

# Defaults to GRASS, Replaces all the blocks of the given material in the BO4 with the SurfaceBlock configured for the biome it spawns in.
ReplaceWithSurfaceBlock: GRASS

# Defaults to DIRT, Replaces all the blocks of the given material in the BO4 with the GroundBlock configured for the biome it spawns in.
ReplaceWithGroundBlock: DIRT

# Defaults to STONE, Replaces all the blocks of the given material in the BO4 with the StoneBlock configured for the biome it spawns in.
ReplaceWithStoneBlock: STONE

# Makes the terrain around the BO4 slope evenly towards the edges of the BO4. The given value is the distance in blocks around the BO4 from where the slope should start and can be any positive number.
SmoothRadius: 0

# Moves the smoothing area up or down relative to the BO4 (at the points where the smoothing area is connected to the BO4). Handy when using SmoothStartTop: false and the BO4 has some layers of ground included, in that case we can set the HeightOffset to a negative value to lower the BO4 into the ground and we can set the SmoothHeightOffset to a positive value to move the smoothing area starting height up.
SmoothHeightOffset: 0

# Should the smoothing area be attached at the bottom or the top of the edges of the BO4? Defaults to false (bottom). Using this setting can make things slower so try to avoid using it and use SmoothHeightOffset instead if for instance you have a BO4 with some ground layers included. The only reason you should need to use this setting is if you have a BO4 with edges that have an irregular height (like some hills).
SmoothStartTop: false

# Should the smoothing area attach itself to "log" block or ignore them? Defaults to false (ignore logs).
SmoothStartWood: false

# The block used for smoothing area surface blocks, defaults to biome SurfaceBlock.
SmoothingSurfaceBlock: 

# The block used for smoothing area ground blocks, defaults to biome GroundBlock.
SmoothingGroundBlock: 

# Define groups that this BO4 belongs to along with a minimum range in chunks that this BO4 must have between it and any other members of this group if it is to be allowed to spawn. Syntax is "GroupName:Frequency, GoupName2:Frequency2" etc so for example a BO4 that belongs to 3 groups: "BO4Group: Ships:10, Vehicles:5, FloatingThings:3".
BO3Group: 

# Defaults to false. Set to true if this BO4 should spawn at the player spawn point. When the server starts the spawn point is determined and the BO4's for the biome it is in are loaded, one of these BO4s that has IsSpawnPoint set to true (if any) is selected randomly and is spawned at the spawn point regardless of its rarity (so even Rarity:0, IsSpawnPoint: true BO4's can get spawned as the spawn point!).
IsSpawnPoint: false

# Defaults to true. Set to false to make the BO4 ignore any ReplacedBlocks settings in Biome Configs.
DoReplaceBlocks: true


#######################################################################
# +-----------------------------------------------------------------+ #
# |                              Blocks                             | #
# +-----------------------------------------------------------------+ #
#######################################################################

# All the blocks used in the BO4 are listed here. Possible blocks:
# Block(x,y,z,id[.data][,nbtfile.nbt)
# RandomBlock(x,y,z,id[:data][,nbtfile.nbt],chance[,id[:data][,nbtfile.nbt],chance[,...]])
#  So RandomBlock(0,0,0,CHEST,chest.nbt,50,CHEST,anotherchest.nbt,100) will spawn a chest at
#  the BO4 origin, and give it a 50% chance to have the contents of chest.nbt, or, if that
#  fails, a 100% percent chance to have the contents of anotherchest.nbt.
# MinecraftObject(x,y,z,name) (TODO: This may not work anymore and needs to be tested.
#  Spawns an object in the Mojang NBT structure format. For example, 
#  MinecraftObject(0,0,0,minecraft:igloo/igloo_bottom)
#  spawns the bottom part of an igloo.
Block(-7,0,-5,minecraft:concrete:0)
Block(-7,0,-4,minecraft:concrete:0)
Block(-7,0,-3,minecraft:concrete:0)
Block(-7,0,-2,minecraft:concrete:0)
Block(-7,0,-1,minecraft:concrete:0)
Block(-7,0,0,minecraft:concrete:0)
Block(-7,0,1,minecraft:concrete:0)
Block(-7,0,2,minecraft:concrete:0)
Block(-7,0,3,minecraft:concrete:0)
Block(-7,1,-5,minecraft:concrete:0)
Block(-7,1,-4,minecraft:concrete:0)
Block(-7,1,-3,minecraft:concrete:0)
Block(-7,1,-2,minecraft:concrete:0)
Block(-7,1,-1,minecraft:concrete:0)
Block(-7,1,0,minecraft:concrete:0)
Block(-7,1,1,minecraft:concrete:0)
Block(-7,1,2,minecraft:concrete:0)
Block(-7,1,3,minecraft:concrete:0)
Block(-7,2,-5,minecraft:concrete:0)
Block(-7,2,-4,minecraft:concrete:0)
Block(-7,2,-3,minecraft:concrete:0)
Block(-7,2,-2,minecraft:concrete:0)
Block(-7,2,-1,minecraft:concrete:0)
Block(-7,2,0,minecraft:concrete:0)
Block(-7,2,1,minecraft:concrete:0)
Block(-7,2,2,minecraft:concrete:0)
Block(-7,2,3,minecraft:concrete:0)
Block(-7,3,-5,minecraft:concrete:0)
Block(-7,3,-4,minecraft:concrete:0)
Block(-7,3,-3,minecraft:concrete:0)
Block(-7,3,-2,minecraft:concrete:0)
Block(-7,3,-1,minecraft:concrete:0)
Block(-7,3,0,minecraft:concrete:0)
Block(-7,3,1,minecraft:concrete:0)
Block(-7,3,2,minecraft:concrete:0)
Block(-7,3,3,minecraft:concrete:0)
Block(-7,4,-5,minecraft:concrete:0)
Block(-7,4,-4,minecraft:concrete:0)
Block(-7,4,-3,minecraft:concrete:0)
Block(-7,4,-2,minecraft:concrete:0)
Block(-7,4,-1,minecraft:concrete:0)
Block(-7,4,0,minecraft:concrete:0)
Block(-7,4,1,minecraft:concrete:0)
Block(-7,4,2,minecraft:concrete:0)
Block(-7,4,3,minecraft:concrete:0)
Block(-7,5,-5,minecraft:concrete:0)
Block(-7,5,-4,minecraft:concrete:0)
Block(-7,5,-3,minecraft:concrete:0)
Block(-7,6,-5,minecraft:concrete:0)
Block(-7,6,-4,minecraft:concrete:0)
Block(-7,6,-3,minecraft:concrete:0)
Block(-7,7,-5,minecraft:concrete:0)
Block(-7,7,-4,minecraft:concrete:0)
Block(-7,7,-3,minecraft:concrete:0)
Block(-6,0,-5,minecraft:concrete:0)
Block(-6,0,-4,minecraft:concrete:0)
Block(-6,0,-3,minecraft:concrete:0)
Block(-6,0,-2,minecraft:concrete:0)
Block(-6,0,-1,minecraft:concrete:0)
Block(-6,0,0,minecraft:concrete:0)
Block(-6,0,1,minecraft:concrete:0)
Block(-6,0,2,minecraft:concrete:0)
Block(-6,0,3,minecraft:concrete:0)
Block(-6,1,-5,minecraft:concrete:0)
Block(-6,1,-4,quark:iron_ladder:3)
Block(-6,1,-3,minecraft:glass:3)
Block(-6,1,-2,AIR:0)
Block(-6,1,-1,minecraft:concrete:0)
Block(-6,1,0,minecraft:planks:8,../../../Chests/Loot/manhunt_vagrant_scrap.nbt)
Block(-6,1,1,minecraft:log:6)
Block(-6,1,2,minecraft:dark_oak_stairs:2)
Block(-6,1,3,minecraft:concrete:0)
Block(-6,2,-5,minecraft:concrete:0)
Block(-6,2,-4,quark:iron_ladder:3)
Block(-6,2,-3,minecraft:glass:8)
Block(-6,2,-2,IRON_TRAPDOOR:11)
Block(-6,2,-1,minecraft:concrete:0)
Block(-6,2,0,minecraft:planks:8,../../../Chests/Loot/manhunt_vagrant_scrap.nbt)
Block(-6,2,1,AIR:0)
Block(-6,2,2,minecraft:bookshelf:0)
Block(-6,2,3,minecraft:concrete:0)
Block(-6,3,-5,minecraft:concrete:0)
Block(-6,3,-4,quark:iron_ladder:3)
Block(-6,3,-3,AIR:0)
Block(-6,3,-2,minecraft:stonebrick:1)
Block(-6,3,-1,minecraft:concrete:0)
Block(-6,3,0,minecraft:planks:8,../../../Chests/Loot/manhunt_vagrant_scrap.nbt)
Block(-6,3,1,minecraft:planks:0,../../../Chests/Loot/manhunt_vagrant_scrap.nbt)
Block(-6,3,2,minecraft:planks:0,../../../Chests/Loot/manhunt_vagrant_scrap.nbt)
Block(-6,3,3,minecraft:concrete:0)
Block(-6,4,-5,minecraft:concrete:0)
Block(-6,4,-4,minecraft:trapdoor:0)
Block(-6,4,-3,minecraft:concrete:0)
Block(-6,4,-2,minecraft:concrete:0)
Block(-6,4,-1,minecraft:concrete:0)
Block(-6,4,0,minecraft:concrete:0)
Block(-6,4,1,minecraft:concrete:0)
Block(-6,4,2,minecraft:concrete:0)
Block(-6,4,3,minecraft:concrete:0)
Block(-6,5,-5,minecraft:concrete:0)
Block(-6,5,-4,quark:iron_ladder:3)
Block(-6,5,-3,minecraft:concrete:0)
Block(-6,6,-5,minecraft:concrete:0)
Block(-6,6,-4,quark:iron_ladder:3)
Block(-6,6,-3,minecraft:concrete:0)
Block(-6,7,-5,minecraft:concrete:0)
Block(-6,7,-4,minecraft:trapdoor:8)
Block(-6,7,-3,minecraft:concrete:0)
Block(-5,0,-5,minecraft:concrete:0)
Block(-5,0,-4,minecraft:concrete:0)
Block(-5,0,-3,minecraft:concrete:0)
Block(-5,0,-2,minecraft:concrete:0)
Block(-5,0,-1,minecraft:concrete:0)
Block(-5,0,0,minecraft:concrete:0)
Block(-5,0,1,minecraft:concrete:0)
Block(-5,0,2,minecraft:concrete:0)
Block(-5,0,3,minecraft:concrete:0)
Block(-5,1,-5,minecraft:concrete:0)
Block(-5,1,-4,DISPENSER:1,f_bunker_small_05/7-dispenser.nbt)
Block(-5,1,-3,AIR:0)
Block(-5,1,-2,minecraft:glass:0)
Block(-5,1,-1,minecraft:concrete:0)
Block(-5,1,0,CARPET:7)
Block(-5,1,1,minecraft:log:6)
Block(-5,1,2,minecraft:dark_oak_stairs:2)
Block(-5,1,3,minecraft:concrete:0)
Block(-5,2,-5,minecraft:concrete:0)
Block(-5,2,-4,minecraft:trapdoor:1)
Block(-5,2,-3,AIR:0)
Block(-5,2,-2,minecraft:glass:9)
Block(-5,2,-1,minecraft:concrete:0)
Block(-5,2,0,minecraft:bookshelf:0)
Block(-5,2,1,AIR:0)
Block(-5,2,2,minecraft:bookshelf:0)
Block(-5,2,3,minecraft:concrete:0)
Block(-5,3,-5,minecraft:concrete:0)
Block(-5,3,-4,quark:iron_button:0)
Block(-5,3,-3,AIR:0)
Block(-5,3,-2,AIR:0)
Block(-5,3,-1,minecraft:concrete:0)
Block(-5,3,0,minecraft:bookshelf:0)
Block(-5,3,1,AIR:0)
Block(-5,3,2,AIR:0)
Block(-5,3,3,minecraft:concrete:0)
Block(-5,4,-5,minecraft:concrete:0)
Block(-5,4,-4,minecraft:concrete:0)
Block(-5,4,-3,minecraft:concrete:0)
Block(-5,4,-2,minecraft:concrete:0)
Block(-5,4,-1,minecraft:concrete:0)
Block(-5,4,0,minecraft:concrete:0)
Block(-5,4,1,minecraft:concrete:0)
Block(-5,4,2,minecraft:concrete:0)
Block(-5,4,3,minecraft:concrete:0)
Block(-5,5,-5,minecraft:concrete:0)
Block(-5,5,-4,minecraft:concrete:0)
Block(-5,5,-3,minecraft:concrete:0)
Block(-5,6,-5,minecraft:concrete:0)
Block(-5,6,-4,minecraft:concrete:0)
Block(-5,6,-3,minecraft:concrete:0)
Block(-5,7,-5,minecraft:concrete:0)
Block(-5,7,-4,minecraft:concrete:0)
Block(-5,7,-3,minecraft:concrete:0)
Block(-4,0,-5,minecraft:concrete:0)
Block(-4,0,-4,minecraft:concrete:0)
Block(-4,0,-3,minecraft:concrete:0)
Block(-4,0,-2,minecraft:concrete:0)
Block(-4,0,-1,minecraft:concrete:0)
Block(-4,0,0,minecraft:concrete:0)
Block(-4,0,1,minecraft:concrete:0)
Block(-4,0,2,minecraft:concrete:0)
Block(-4,0,3,minecraft:concrete:0)
Block(-4,1,-5,minecraft:concrete:0)
Block(-4,1,-4,minecraft:planks:8,../../../Chests/Loot/manhunt_vagrant_scrap.nbt)
Block(-4,1,-3,DARK_OAK_DOOR:0)
Block(-4,1,-2,minecraft:planks:15)
Block(-4,1,-1,minecraft:concrete:0)
Block(-4,1,0,CARPET:7)
Block(-4,1,1,CARPET:7)
Block(-4,1,2,minecraft:planks,../../../Chests/Loot/manhunt_vagrant_scrap.nbt)
Block(-4,1,3,minecraft:concrete:0)
Block(-4,2,-5,minecraft:concrete:0)
Block(-4,2,-4,minecraft:planks:8,../../../Chests/Loot/manhunt_vagrant_scrap.nbt)
Block(-4,2,-3,DARK_OAK_DOOR:8)
Block(-4,2,-2,minecraft:planks:15)
Block(-4,2,-1,minecraft:concrete:0)
Block(-4,2,0,minecraft:bookshelf:0)
Block(-4,2,1,AIR:0)
Block(-4,2,2,minecraft:planks:11,../../../Chests/Loot/manhunt_vagrant_scrap.nbt)
Block(-4,2,3,minecraft:concrete:0)
Block(-4,3,-5,minecraft:concrete:0)
Block(-4,3,-4,minecraft:planks:8,../../../Chests/Loot/manhunt_vagrant_scrap.nbt)
Block(-4,3,-3,minecraft:planks:15)
Block(-4,3,-2,minecraft:planks:15)
Block(-4,3,-1,minecraft:concrete:0)
Block(-4,3,0,minecraft:bookshelf:0)
Block(-4,3,1,AIR:0)
Block(-4,3,2,minecraft:planks,../../../Chests/Loot/manhunt_vagrant_scrap.nbt)
Block(-4,3,3,minecraft:concrete:0)
Block(-4,4,-5,minecraft:concrete:0)
Block(-4,4,-4,minecraft:concrete:0)
Block(-4,4,-3,minecraft:concrete:0)
Block(-4,4,-2,minecraft:concrete:0)
Block(-4,4,-1,minecraft:concrete:0)
Block(-4,4,0,minecraft:concrete:0)
Block(-4,4,1,minecraft:concrete:0)
Block(-4,4,2,minecraft:concrete:0)
Block(-4,4,3,minecraft:concrete:0)
Block(-3,0,-5,minecraft:concrete:0)
Block(-3,0,-4,minecraft:concrete:0)
Block(-3,0,-3,minecraft:concrete:0)
Block(-3,0,-2,minecraft:concrete:0)
Block(-3,0,-1,minecraft:concrete:0)
Block(-3,0,0,minecraft:concrete:0)
Block(-3,0,1,minecraft:concrete:0)
Block(-3,0,2,minecraft:concrete:0)
Block(-3,0,3,minecraft:concrete:0)
Block(-3,1,-5,minecraft:concrete:0)
Block(-3,1,-4,STANDING_BANNER:0,f_bunker_small_05/23-banner.nbt)
Block(-3,1,-3,AIR:0)
Block(-3,1,-2,minecraft:bookshelf:0)
Block(-3,1,-1,minecraft:concrete:0)
Block(-3,1,0,minecraft:planks:8,../../../Chests/Loot/manhunt_vagrant_scrap.nbt)
Block(-3,1,1,DARK_OAK_DOOR:0)
Block(-3,1,2,minecraft:planks:0,../../../Chests/Loot/manhunt_vagrant_scrap.nbt)
Block(-3,1,3,minecraft:concrete:0)
Block(-3,2,-5,minecraft:concrete:0)
Block(-3,2,-4,IRON_TRAPDOOR:1)
Block(-3,2,-3,AIR:0)
Block(-3,2,-2,minecraft:bookshelf:0)
Block(-3,2,-1,minecraft:concrete:0)
Block(-3,2,0,minecraft:planks:8,../../../Chests/Loot/manhunt_vagrant_scrap.nbt)
Block(-3,2,1,DARK_OAK_DOOR:9)
Block(-3,2,2,minecraft:planks:0,../../../Chests/Loot/manhunt_vagrant_scrap.nbt)
Block(-3,2,3,minecraft:concrete:0)
Block(-3,3,-5,minecraft:concrete:0)
Block(-3,3,-4,minecraft:stonebrick:3)
Block(-3,3,-3,AIR:0)
Block(-3,3,-2,minecraft:bookshelf:0)
Block(-3,3,-1,minecraft:concrete:0)
Block(-3,3,0,minecraft:planks:8,../../../Chests/Loot/manhunt_vagrant_scrap.nbt)
Block(-3,3,1,minecraft:planks:8,../../../Chests/Loot/manhunt_vagrant_scrap.nbt)
Block(-3,3,2,minecraft:planks:0,../../../Chests/Loot/manhunt_vagrant_scrap.nbt)
Block(-3,3,3,minecraft:concrete:0)
Block(-3,4,-5,minecraft:concrete:0)
Block(-3,4,-4,minecraft:concrete:0)
Block(-3,4,-3,minecraft:concrete:0)
Block(-3,4,-2,minecraft:concrete:0)
Block(-3,4,-1,minecraft:concrete:0)
Block(-3,4,0,minecraft:concrete:0)
Block(-3,4,1,minecraft:concrete:0)
Block(-3,4,2,minecraft:concrete:0)
Block(-3,4,3,minecraft:concrete:0)
Block(-2,0,-5,minecraft:concrete:0)
Block(-2,0,-4,minecraft:concrete:0)
Block(-2,0,-3,minecraft:concrete:0)
Block(-2,0,-2,minecraft:concrete:0)
Block(-2,0,-1,minecraft:concrete:0)
Block(-2,0,0,minecraft:concrete:0)
Block(-2,0,1,minecraft:concrete:0)
Block(-2,0,2,minecraft:concrete:0)
Block(-2,0,3,minecraft:concrete:0)
Block(-2,1,-5,minecraft:concrete:0)
Block(-2,1,-4,STANDING_BANNER:0,f_bunker_small_05/35-banner.nbt)
Block(-2,1,-3,minecraft:oak_stairs:5)
Block(-2,1,-2,dregorarl_srpmanhunt:encounter_marker:10)
Block(-2,1,-1,AIR:0)
Block(-2,1,0,dregorarl_srpmanhunt:encounter_marker:13)
Block(-2,1,1,AIR:0)
Block(-2,1,2,minecraft:bookshelf:0)
Block(-2,1,3,minecraft:concrete:0)
Block(-2,2,-5,minecraft:concrete:0)
Block(-2,2,-4,IRON_TRAPDOOR:1)
Block(-2,2,-3,AIR:0)
Block(-2,2,-2,AIR:0)
Block(-2,2,-1,AIR:0)
Block(-2,2,0,AIR:0)
Block(-2,2,1,AIR:0)
Block(-2,2,2,minecraft:bookshelf:0)
Block(-2,2,3,minecraft:concrete:0)
Block(-2,3,-5,minecraft:concrete:0)
Block(-2,3,-4,minecraft:stonebrick:3)
Block(-2,3,-3,AIR:0)
Block(-2,3,-2,minecraft:bookshelf:0)
Block(-2,3,-1,minecraft:concrete:0)
Block(-2,3,0,AIR:0)
Block(-2,3,1,AIR:0)
Block(-2,3,2,minecraft:bookshelf:0)
Block(-2,3,3,minecraft:concrete:0)
Block(-2,4,-5,minecraft:concrete:0)
Block(-2,4,-4,minecraft:concrete:0)
Block(-2,4,-3,minecraft:concrete:0)
Block(-2,4,-2,minecraft:concrete:0)
Block(-2,4,-1,minecraft:concrete:0)
Block(-2,4,0,minecraft:concrete:0)
Block(-2,4,1,minecraft:concrete:0)
Block(-2,4,2,minecraft:concrete:0)
Block(-2,4,3,minecraft:concrete:0)
Block(-1,0,-5,minecraft:concrete:0)
Block(-1,0,-4,minecraft:concrete:0)
Block(-1,0,-3,minecraft:concrete:0)
Block(-1,0,-2,minecraft:concrete:0)
Block(-1,0,-1,minecraft:concrete:0)
Block(-1,0,0,minecraft:concrete:0)
Block(-1,0,1,minecraft:concrete:0)
Block(-1,0,2,minecraft:concrete:0)
Block(-1,0,3,minecraft:concrete:0)
Block(-1,1,-5,minecraft:concrete:0)
Block(-1,1,-4,minecraft:planks:15)
Block(-1,1,-3,AIR:0)
Block(-1,1,-2,minecraft:bookshelf:0)
Block(-1,1,-1,minecraft:concrete:0)
Block(-1,1,0,minecraft:log:6)
Block(-1,1,1,CARPET:7)
Block(-1,1,2,minecraft:stonebrick)
Block(-1,1,3,minecraft:concrete:0)
Block(-1,2,-5,minecraft:concrete:0)
Block(-1,2,-4,minecraft:planks:15)
Block(-1,2,-3,AIR:0)
Block(-1,2,-2,minecraft:bookshelf:0)
Block(-1,2,-1,minecraft:concrete:0)
Block(-1,2,0,WALL_BANNER:3,f_bunker_small_05/47-banner.nbt)
Block(-1,2,1,AIR:0)
Block(-1,2,2,AIR:0)
Block(-1,2,3,minecraft:concrete:0)
Block(-1,3,-5,minecraft:concrete:0)
Block(-1,3,-4,minecraft:planks:15)
Block(-1,3,-3,AIR:0)
Block(-1,3,-2,minecraft:bookshelf:0)
Block(-1,3,-1,minecraft:concrete:0)
Block(-1,3,0,minecraft:planks:10,../../../Chests/Loot/manhunt_vagrant_scrap.nbt)
Block(-1,3,1,AIR:0)
Block(-1,3,2,minecraft:bookshelf:0)
Block(-1,3,3,minecraft:concrete:0)
Block(-1,4,-5,minecraft:concrete:0)
Block(-1,4,-4,minecraft:concrete:0)
Block(-1,4,-3,minecraft:concrete:0)
Block(-1,4,-2,minecraft:concrete:0)
Block(-1,4,-1,minecraft:concrete:0)
Block(-1,4,0,minecraft:concrete:0)
Block(-1,4,1,minecraft:concrete:0)
Block(-1,4,2,minecraft:concrete:0)
Block(-1,4,3,minecraft:concrete:0)
Block(0,0,-5,minecraft:concrete:0)
Block(0,0,-4,minecraft:concrete:0)
Block(0,0,-3,minecraft:concrete:0)
Block(0,0,-2,minecraft:concrete:0)
Block(0,0,-1,minecraft:concrete:0)
Block(0,0,0,minecraft:concrete:0)
Block(0,0,1,minecraft:concrete:0)
Block(0,0,2,minecraft:concrete:0)
Block(0,0,3,minecraft:concrete:0)
Block(0,1,-5,minecraft:concrete:0)
Block(0,1,-4,minecraft:planks:5)
Block(0,1,-3,AIR:0)
Block(0,1,-2,minecraft:stonebrick)
Block(0,1,-1,minecraft:concrete:0)
Block(0,1,0,minecraft:log:6)
Block(0,1,1,CARPET:7)
Block(0,1,2,minecraft:stonebrick)
Block(0,1,3,minecraft:concrete:0)
Block(0,2,-5,minecraft:concrete:0)
Block(0,2,-4,minecraft:stonebrick)
Block(0,2,-3,AIR:0)
Block(0,2,-2,minecraft:stonebrick)
Block(0,2,-1,minecraft:concrete:0)
Block(0,2,0,WALL_BANNER:3,f_bunker_small_05/57-banner.nbt)
Block(0,2,1,AIR:0)
Block(0,2,2,AIR:0)
Block(0,2,3,minecraft:concrete:0)
Block(0,3,-5,minecraft:concrete:0)
Block(0,3,-4,minecraft:planks:2,../../../Chests/Loot/manhunt_vagrant_scrap.nbt)
Block(0,3,-3,AIR:0)
Block(0,3,-2,minecraft:planks:3,../../../Chests/Loot/manhunt_vagrant_scrap.nbt)
Block(0,3,-1,minecraft:concrete:0)
Block(0,3,0,minecraft:planks:10,../../../Chests/Loot/manhunt_vagrant_scrap.nbt)
Block(0,3,1,AIR:0)
Block(0,3,2,minecraft:bookshelf:0)
Block(0,3,3,minecraft:concrete:0)
Block(0,4,-5,minecraft:concrete:0)
Block(0,4,-4,minecraft:concrete:0)
Block(0,4,-3,minecraft:concrete:0)
Block(0,4,-2,minecraft:concrete:0)
Block(0,4,-1,minecraft:concrete:0)
Block(0,4,0,minecraft:concrete:0)
Block(0,4,1,minecraft:concrete:0)
Block(0,4,2,minecraft:concrete:0)
Block(0,4,3,minecraft:concrete:0)
Block(1,0,-5,minecraft:concrete:0)
Block(1,0,-4,minecraft:concrete:0)
Block(1,0,-3,minecraft:concrete:0)
Block(1,0,-2,minecraft:concrete:0)
Block(1,0,-1,minecraft:concrete:0)
Block(1,0,0,minecraft:concrete:0)
Block(1,0,1,minecraft:concrete:0)
Block(1,0,2,minecraft:concrete:0)
Block(1,0,3,minecraft:concrete:0)
Block(1,1,-5,minecraft:concrete:0)
Block(1,1,-4,minecraft:planks:2,../../../Chests/Loot/manhunt_vagrant_scrap.nbt)
Block(1,1,-3,AIR:0)
Block(1,1,-2,minecraft:planks,../../../Chests/Loot/manhunt_vagrant_scrap.nbt)
Block(1,1,-1,minecraft:concrete:0)
Block(1,1,0,minecraft:planks:6,../../../Chests/Loot/manhunt_vagrant_scrap.nbt)
Block(1,1,1,DARK_OAK_DOOR:2)
Block(1,1,2,minecraft:planks,../../../Chests/Loot/manhunt_vagrant_scrap.nbt)
Block(1,1,3,minecraft:concrete:0)
Block(1,2,-5,minecraft:concrete:0)
Block(1,2,-4,minecraft:bookshelf:0)
Block(1,2,-3,AIR:0)
Block(1,2,-2,minecraft:bookshelf:0)
Block(1,2,-1,minecraft:concrete:0)
Block(1,2,0,minecraft:planks:14,../../../Chests/Loot/manhunt_vagrant_scrap.nbt)
Block(1,2,1,DARK_OAK_DOOR:8)
Block(1,2,2,minecraft:planks:11,../../../Chests/Loot/manhunt_vagrant_scrap.nbt)
Block(1,2,3,minecraft:concrete:0)
Block(1,3,-5,minecraft:concrete:0)
Block(1,3,-4,minecraft:planks:2,../../../Chests/Loot/manhunt_vagrant_scrap.nbt)
Block(1,3,-3,AIR:0)
Block(1,3,-2,minecraft:bookshelf:0)
Block(1,3,-1,minecraft:concrete:0)
Block(1,3,0,minecraft:stonebrick:4)
Block(1,3,1,minecraft:planks:1,../../../Chests/Loot/manhunt_vagrant_scrap.nbt)
Block(1,3,2,minecraft:stonebrick)
Block(1,3,3,minecraft:concrete:0)
Block(1,4,-5,minecraft:concrete:0)
Block(1,4,-4,minecraft:concrete:0)
Block(1,4,-3,minecraft:concrete:0)
Block(1,4,-2,minecraft:concrete:0)
Block(1,4,-1,minecraft:concrete:0)
Block(1,4,0,minecraft:concrete:0)
Block(1,4,1,minecraft:concrete:0)
Block(1,4,2,minecraft:concrete:0)
Block(1,4,3,minecraft:concrete:0)
Block(2,0,-5,minecraft:concrete:0)
Block(2,0,-4,minecraft:concrete:0)
Block(2,0,-3,minecraft:concrete:0)
Block(2,0,-2,minecraft:concrete:0)
Block(2,0,-1,minecraft:concrete:0)
Block(2,0,0,minecraft:concrete:0)
Block(2,0,1,minecraft:concrete:0)
Block(2,0,2,minecraft:concrete:0)
Block(2,0,3,minecraft:concrete:0)
Block(2,1,-5,minecraft:concrete:0)
Block(2,1,-4,minecraft:planks:10,../../../Chests/Loot/manhunt_vagrant_scrap.nbt)
Block(2,1,-3,AIR:0)
Block(2,1,-2,minecraft:furnace)
Block(2,1,-1,minecraft:concrete:0)
Block(2,1,0,minecraft:trapdoor:1)
Block(2,1,1,AIR:0)
Block(2,1,2,minecraft:trapdoor:0)
Block(2,1,3,minecraft:concrete:0)
Block(2,2,-5,minecraft:concrete:0)
Block(2,2,-4,minecraft:bookshelf:0)
Block(2,2,-3,AIR:0)
Block(2,2,-2,quark:grate:0)
Block(2,2,-1,minecraft:concrete:0)
Block(2,2,0,minecraft:trapdoor:1)
Block(2,2,1,AIR:0)
Block(2,2,2,minecraft:trapdoor:0)
Block(2,2,3,minecraft:concrete:0)
Block(2,3,-5,minecraft:concrete:0)
Block(2,3,-4,minecraft:planks:10,../../../Chests/Loot/manhunt_vagrant_scrap.nbt)
Block(2,3,-3,AIR:0)
Block(2,3,-2,minecraft:iron_block:0)
Block(2,3,-1,minecraft:concrete:0)
Block(2,3,0,minecraft:trapdoor:1)
Block(2,3,1,AIR:0)
Block(2,3,2,minecraft:trapdoor:3)
Block(2,3,3,minecraft:concrete:0)
Block(2,4,-5,minecraft:concrete:0)
Block(2,4,-4,minecraft:concrete:0)
Block(2,4,-3,minecraft:concrete:0)
Block(2,4,-2,minecraft:concrete:0)
Block(2,4,-1,minecraft:concrete:0)
Block(2,4,0,minecraft:concrete:0)
Block(2,4,1,minecraft:concrete:0)
Block(2,4,2,minecraft:concrete:0)
Block(2,4,3,minecraft:concrete:0)
Block(3,0,-5,minecraft:concrete:0)
Block(3,0,-4,minecraft:concrete:0)
Block(3,0,-3,minecraft:concrete:0)
Block(3,0,-2,minecraft:concrete:0)
Block(3,0,-1,minecraft:concrete:0)
Block(3,0,0,minecraft:concrete:0)
Block(3,0,1,minecraft:concrete:0)
Block(3,0,2,minecraft:concrete:0)
Block(3,0,3,minecraft:concrete:0)
Block(3,1,-5,minecraft:concrete:0)
Block(3,1,-4,minecraft:stonebrick)
Block(3,1,-3,AIR:0)
Block(3,1,-2,minecraft:planks)
Block(3,1,-1,minecraft:concrete:0)
Block(3,1,0,minecraft:trapdoor:1)
Block(3,1,1,quark:iron_ladder:4)
Block(3,1,2,minecraft:trapdoor:0)
Block(3,1,3,minecraft:concrete:0)
Block(3,2,-5,minecraft:concrete:0)
Block(3,2,-4,minecraft:stonebrick:3)
Block(3,2,-3,AIR:0)
Block(3,2,-2,minecraft:stonebrick)
Block(3,2,-1,minecraft:concrete:0)
Block(3,2,0,minecraft:trapdoor:1)
Block(3,2,1,quark:iron_ladder:4)
Block(3,2,2,minecraft:trapdoor:0)
Block(3,2,3,minecraft:concrete:0)
Block(3,3,-5,minecraft:concrete:0)
Block(3,3,-4,minecraft:planks:10,../../../Chests/Loot/manhunt_vagrant_scrap.nbt)
Block(3,3,-3,quark:iron_button:2)
Block(3,3,-2,minecraft:iron_block:0)
Block(3,3,-1,minecraft:concrete:0)
Block(3,3,0,minecraft:trapdoor:1)
Block(3,3,1,quark:iron_ladder:4)
Block(3,3,2,minecraft:trapdoor:0)
Block(3,3,3,minecraft:concrete:0)
Block(3,4,-5,minecraft:concrete:0)
Block(3,4,-4,minecraft:concrete:0)
Block(3,4,-3,minecraft:concrete:0)
Block(3,4,-2,minecraft:concrete:0)
Block(3,4,-1,minecraft:concrete:0)
Block(3,4,0,minecraft:concrete:0)
Block(3,4,1,minecraft:concrete:0)
Block(3,4,2,minecraft:concrete:0)
Block(3,4,3,minecraft:concrete:0)
Block(3,8,-6,minecraft:concrete:0)
Block(3,8,-5,minecraft:concrete:0)
Block(3,8,-4,minecraft:concrete:0)
Block(3,8,-3,minecraft:concrete:0)
Block(3,8,-2,minecraft:concrete:0)
Block(3,9,-6,minecraft:concrete:0)
Block(3,9,-5,AIR:0)
Block(3,9,-4,AIR:0)
Block(3,9,-3,AIR:0)
Block(3,9,-2,minecraft:concrete:0)
Block(3,10,-6,minecraft:concrete:0)
Block(3,10,-5,AIR:0)
Block(3,10,-4,quark:iron_button:2)
Block(3,10,-3,minecraft:stonebrick:5)
Block(3,10,-2,minecraft:concrete:0)
Block(3,11,-6,minecraft:concrete:0)
Block(3,11,-5,minecraft:concrete:0)
Block(3,11,-4,minecraft:concrete:0)
Block(3,11,-3,minecraft:concrete:0)
Block(3,11,-2,minecraft:concrete:0)
Block(4,0,-6,minecraft:concrete:0)
Block(4,0,-5,minecraft:concrete:0)
Block(4,0,-4,minecraft:concrete:0)
Block(4,0,-3,minecraft:concrete:0)
Block(4,0,-2,minecraft:concrete:0)
Block(4,0,-1,minecraft:concrete:0)
Block(4,0,0,minecraft:concrete:0)
Block(4,0,1,minecraft:concrete:0)
Block(4,0,2,minecraft:concrete:0)
Block(4,0,3,minecraft:concrete:0)
Block(4,1,-6,minecraft:concrete:0)
Block(4,1,-5,minecraft:concrete:0)
Block(4,1,-4,minecraft:concrete:0)
Block(4,1,-3,minecraft:iron_door:2)
Block(4,1,-2,minecraft:concrete:0)
Block(4,1,-1,minecraft:concrete:0)
Block(4,1,0,minecraft:concrete:0)
Block(4,1,1,minecraft:concrete:0)
Block(4,1,2,minecraft:concrete:0)
Block(4,1,3,minecraft:concrete:0)
Block(4,2,-6,minecraft:concrete:0)
Block(4,2,-5,minecraft:concrete:0)
Block(4,2,-4,minecraft:concrete:0)
Block(4,2,-3,minecraft:iron_door:9)
Block(4,2,-2,minecraft:concrete:0)
Block(4,2,-1,minecraft:concrete:0)
Block(4,2,0,minecraft:concrete:0)
Block(4,2,1,minecraft:concrete:0)
Block(4,2,2,minecraft:concrete:0)
Block(4,2,3,minecraft:concrete:0)
Block(4,3,-6,minecraft:concrete:0)
Block(4,3,-5,minecraft:concrete:0)
Block(4,3,-4,minecraft:concrete:0)
Block(4,3,-3,minecraft:concrete:0)
Block(4,3,-2,minecraft:concrete:0)
Block(4,3,-1,minecraft:concrete:0)
Block(4,3,0,minecraft:concrete:0)
Block(4,3,1,minecraft:concrete:0)
Block(4,3,2,minecraft:concrete:0)
Block(4,3,3,minecraft:concrete:0)
Block(4,4,-6,minecraft:concrete:0)
Block(4,4,-5,minecraft:concrete:0)
Block(4,4,-4,minecraft:concrete:0)
Block(4,4,-3,minecraft:concrete:0)
Block(4,4,-2,minecraft:concrete:0)
Block(4,4,-1,minecraft:concrete:0)
Block(4,4,0,minecraft:concrete:0)
Block(4,4,1,minecraft:concrete:0)
Block(4,4,2,minecraft:concrete:0)
Block(4,4,3,minecraft:concrete:0)
Block(4,5,-6,minecraft:concrete:0)
Block(4,5,-5,minecraft:concrete:0)
Block(4,5,-4,minecraft:concrete:0)
Block(4,5,-3,minecraft:concrete:0)
Block(4,5,-2,minecraft:concrete:0)
Block(4,6,-6,minecraft:concrete:0)
Block(4,6,-5,minecraft:concrete:0)
Block(4,6,-4,minecraft:concrete:0)
Block(4,6,-3,minecraft:concrete:0)
Block(4,6,-2,minecraft:concrete:0)
Block(4,7,-6,minecraft:concrete:0)
Block(4,7,-5,minecraft:concrete:0)
Block(4,7,-4,minecraft:concrete:0)
Block(4,7,-3,minecraft:concrete:0)
Block(4,7,-2,minecraft:concrete:0)
Block(4,8,-6,minecraft:concrete:0)
Block(4,8,-5,minecraft:concrete:0)
Block(4,8,-4,minecraft:concrete:0)
Block(4,8,-3,minecraft:concrete:0)
Block(4,8,-2,minecraft:concrete:0)
Block(4,9,-6,minecraft:concrete:0)
Block(4,9,-5,IRON_DOOR_BLOCK:0)
Block(4,9,-4,minecraft:concrete:0)
Block(4,9,-3,minecraft:concrete:0)
Block(4,9,-2,minecraft:concrete:0)
Block(4,10,-6,minecraft:stone_brick_stairs:2)
Block(4,10,-5,IRON_DOOR_BLOCK:8)
Block(4,10,-4,minecraft:concrete:0)
Block(4,10,-3,minecraft:concrete:0)
Block(4,10,-2,minecraft:concrete:0)
Block(4,11,-6,minecraft:concrete:0)
Block(4,11,-5,minecraft:concrete:0)
Block(4,11,-4,minecraft:concrete:0)
Block(4,11,-3,minecraft:concrete:0)
Block(4,11,-2,minecraft:concrete:0)
Block(5,0,-6,minecraft:concrete:0)
Block(5,0,-5,minecraft:concrete:0)
Block(5,0,-4,minecraft:concrete:0)
Block(5,0,-3,minecraft:concrete:0)
Block(5,0,-2,minecraft:concrete:0)
Block(5,0,-1,minecraft:concrete:0)
Block(5,1,-6,minecraft:concrete:0)
Block(5,1,-5,minecraft:concrete:0)
Block(5,1,-4,minecraft:concrete:0)
Block(5,1,-3,AIR:0)
Block(5,1,-2,minecraft:concrete:0)
Block(5,1,-1,minecraft:concrete:0)
Block(5,2,-6,minecraft:concrete:0)
Block(5,2,-5,minecraft:concrete:0)
Block(5,2,-4,minecraft:concrete:0)
Block(5,2,-3,AIR:0)
Block(5,2,-2,minecraft:concrete:0)
Block(5,2,-1,minecraft:concrete:0)
Block(5,3,-6,minecraft:concrete:0)
Block(5,3,-5,minecraft:concrete:0)
Block(5,3,-4,minecraft:concrete:0)
Block(5,3,-3,quark:iron_button:1)
Block(5,3,-2,minecraft:concrete:0)
Block(5,3,-1,minecraft:concrete:0)
Block(5,4,-6,minecraft:concrete:0)
Block(5,4,-5,AIR:0)
Block(5,4,-4,minecraft:stone_brick_stairs:2)
Block(5,4,-3,minecraft:concrete:0)
Block(5,4,-2,minecraft:concrete:0)
Block(5,5,-6,minecraft:concrete:0)
Block(5,5,-5,AIR:0)
Block(5,5,-4,AIR:0)
Block(5,5,-3,AIR:0)
Block(5,5,-2,minecraft:concrete:0)
Block(5,6,-6,minecraft:concrete:0)
Block(5,6,-5,AIR:0)
Block(5,6,-4,AIR:0)
Block(5,6,-3,AIR:0)
Block(5,6,-2,minecraft:concrete:0)
Block(5,7,-6,minecraft:concrete:0)
Block(5,7,-5,minecraft:concrete:0)
Block(5,7,-4,minecraft:stone_brick_stairs:7)
Block(5,7,-3,AIR:0)
Block(5,7,-2,minecraft:concrete:0)
Block(5,8,-6,minecraft:concrete:0)
Block(5,8,-5,minecraft:stone_brick_stairs:1)
Block(5,8,-4,minecraft:concrete:0)
Block(5,8,-3,minecraft:concrete:0)
Block(5,8,-2,minecraft:concrete:0)
Block(5,9,-6,minecraft:concrete:0)
Block(5,9,-5,AIR:0)
Block(5,9,-4,minecraft:concrete:0)
Block(5,9,-3,minecraft:concrete:0)
Block(5,9,-2,minecraft:stone_brick_stairs:3)
Block(5,10,-6,minecraft:stone_brick_stairs:2)
Block(5,10,-5,quark:iron_button:0)
Block(5,10,-4,minecraft:concrete:0)
Block(5,10,-3,minecraft:concrete:0)
Block(5,10,-2,minecraft:stone_brick_stairs:7)
Block(5,11,-6,minecraft:stone_brick_stairs:6)
Block(5,11,-5,minecraft:concrete:0)
Block(5,11,-4,minecraft:concrete:0)
Block(5,11,-3,minecraft:concrete:0)
Block(5,11,-2,minecraft:concrete:0)
Block(6,0,-6,minecraft:concrete:0)
Block(6,0,-5,minecraft:concrete:0)
Block(6,0,-4,minecraft:concrete:0)
Block(6,0,-3,minecraft:concrete:0)
Block(6,0,-2,minecraft:concrete:0)
Block(6,0,-1,minecraft:concrete:0)
Block(6,1,-6,minecraft:concrete:0)
Block(6,1,-5,minecraft:concrete:0)
Block(6,1,-4,minecraft:concrete:0)
Block(6,1,-3,minecraft:stone_brick_stairs:0)
Block(6,1,-2,minecraft:concrete:0)
Block(6,1,-1,minecraft:concrete:0)
Block(6,2,-6,minecraft:concrete:0)
Block(6,2,-5,minecraft:concrete:0)
Block(6,2,-4,minecraft:concrete:0)
Block(6,2,-3,AIR:0)
Block(6,2,-2,minecraft:concrete:0)
Block(6,2,-1,minecraft:concrete:0)
Block(6,3,-6,minecraft:concrete:0)
Block(6,3,-5,minecraft:stone_brick_stairs:1)
Block(6,3,-4,minecraft:concrete:0)
Block(6,3,-3,AIR:0)
Block(6,3,-2,minecraft:concrete:0)
Block(6,3,-1,minecraft:concrete:0)
Block(6,4,-6,minecraft:concrete:0)
Block(6,4,-5,AIR:0)
Block(6,4,-4,minecraft:concrete:0)
Block(6,4,-3,minecraft:stone_brick_stairs:5)
Block(6,4,-2,minecraft:concrete:0)
Block(6,5,-6,minecraft:concrete:0)
Block(6,5,-5,AIR:0)
Block(6,5,-4,minecraft:concrete:0)
Block(6,5,-3,minecraft:stone_brick_stairs:0)
Block(6,5,-2,minecraft:concrete:0)
Block(6,6,-6,minecraft:concrete:0)
Block(6,6,-5,minecraft:stone_brick_stairs:4)
Block(6,6,-4,minecraft:concrete:0)
Block(6,6,-3,AIR:0)
Block(6,6,-2,minecraft:concrete:0)
Block(6,7,-6,minecraft:concrete:0)
Block(6,7,-5,minecraft:stone_brick_stairs:1)
Block(6,7,-4,minecraft:concrete:0)
Block(6,7,-3,AIR:0)
Block(6,7,-2,minecraft:concrete:0)
Block(6,8,-6,minecraft:concrete:0)
Block(6,8,-5,AIR:0)
Block(6,8,-4,minecraft:concrete:0)
Block(6,8,-3,minecraft:stone_brick_stairs:5)
Block(6,8,-2,minecraft:concrete:0)
Block(6,9,-6,minecraft:concrete:0)
Block(6,9,-5,AIR:0)
Block(6,9,-4,minecraft:concrete:0)
Block(6,9,-3,minecraft:concrete:0)
Block(6,9,-2,minecraft:concrete:0)
Block(6,10,-6,minecraft:concrete:0)
Block(6,10,-5,AIR:0)
Block(6,10,-4,minecraft:concrete:0)
Block(6,10,-3,minecraft:concrete:0)
Block(6,10,-2,minecraft:concrete:0)
Block(6,11,-6,minecraft:concrete:0)
Block(6,11,-5,minecraft:concrete:0)
Block(6,11,-4,minecraft:concrete:0)
Block(6,11,-3,minecraft:concrete:0)
Block(6,11,-2,minecraft:concrete:0)
Block(7,0,-6,minecraft:concrete:0)
Block(7,0,-5,minecraft:concrete:0)
Block(7,0,-4,minecraft:concrete:0)
Block(7,0,-3,minecraft:concrete:0)
Block(7,0,-2,minecraft:concrete:0)
Block(7,1,-6,minecraft:concrete:0)
Block(7,1,-5,minecraft:concrete:0)
Block(7,1,-4,minecraft:concrete:0)
Block(7,1,-3,minecraft:concrete:0)
Block(7,1,-2,minecraft:concrete:0)
Block(7,2,-6,minecraft:concrete:0)
Block(7,2,-5,minecraft:concrete:0)
Block(7,2,-4,minecraft:stone_brick_stairs:3)
Block(7,2,-3,AIR:0)
Block(7,2,-2,minecraft:concrete:0)
Block(7,3,-6,minecraft:concrete:0)
Block(7,3,-5,AIR:0)
Block(7,3,-4,AIR:0)
Block(7,3,-3,AIR:0)
Block(7,3,-2,minecraft:concrete:0)
Block(7,4,-6,minecraft:concrete:0)
Block(7,4,-5,AIR:0)
Block(7,4,-4,AIR:0)
Block(7,4,-3,AIR:0)
Block(7,4,-2,minecraft:concrete:0)
Block(7,5,-6,minecraft:concrete:0)
Block(7,5,-5,AIR:0)
Block(7,5,-4,minecraft:stone_brick_stairs:6)
Block(7,5,-3,minecraft:concrete:0)
Block(7,5,-2,minecraft:concrete:0)
Block(7,6,-6,minecraft:concrete:0)
Block(7,6,-5,minecraft:concrete:0)
Block(7,6,-4,minecraft:stone_brick_stairs:3)
Block(7,6,-3,AIR:0)
Block(7,6,-2,minecraft:concrete:0)
Block(7,7,-6,minecraft:concrete:0)
Block(7,7,-5,AIR:0)
Block(7,7,-4,AIR:0)
Block(7,7,-3,AIR:0)
Block(7,7,-2,minecraft:concrete:0)
Block(7,8,-6,minecraft:concrete:0)
Block(7,8,-5,AIR:0)
Block(7,8,-4,AIR:0)
Block(7,8,-3,AIR:0)
Block(7,8,-2,minecraft:concrete:0)
Block(7,9,-6,minecraft:concrete:0)
Block(7,9,-5,AIR:0)
Block(7,9,-4,AIR:0)
Block(7,9,-3,AIR:0)
Block(7,9,-2,minecraft:concrete:0)
Block(7,10,-6,minecraft:concrete:0)
Block(7,10,-5,AIR:0)
Block(7,10,-4,AIR:0)
Block(7,10,-3,AIR:0)
Block(7,10,-2,minecraft:stone_brick_stairs:7)
Block(7,11,-6,minecraft:concrete:0)
Block(7,11,-5,minecraft:concrete:0)
Block(7,11,-4,minecraft:concrete:0)
Block(7,11,-3,minecraft:concrete:0)
Block(7,11,-2,minecraft:concrete:0)
Block(8,0,-6,minecraft:concrete:0)
Block(8,0,-5,minecraft:concrete:0)
Block(8,0,-4,minecraft:concrete:0)
Block(8,0,-3,minecraft:concrete:0)
Block(8,0,-2,minecraft:concrete:0)
Block(8,1,-6,minecraft:concrete:0)
Block(8,1,-5,minecraft:concrete:0)
Block(8,1,-4,minecraft:concrete:0)
Block(8,1,-3,minecraft:concrete:0)
Block(8,1,-2,minecraft:concrete:0)
Block(8,2,-6,minecraft:concrete:0)
Block(8,2,-5,minecraft:concrete:0)
Block(8,2,-4,minecraft:concrete:0)
Block(8,2,-3,minecraft:concrete:0)
Block(8,2,-2,minecraft:concrete:0)
Block(8,3,-6,minecraft:concrete:0)
Block(8,3,-5,minecraft:concrete:0)
Block(8,3,-4,minecraft:concrete:0)
Block(8,3,-3,minecraft:concrete:0)
Block(8,3,-2,minecraft:concrete:0)
Block(8,4,-6,minecraft:concrete:0)
Block(8,4,-5,minecraft:concrete:0)
Block(8,4,-4,minecraft:concrete:0)
Block(8,4,-3,minecraft:concrete:0)
Block(8,4,-2,minecraft:concrete:0)
Block(8,5,-6,minecraft:concrete:0)
Block(8,5,-5,minecraft:concrete:0)
Block(8,5,-4,minecraft:concrete:0)
Block(8,5,-3,minecraft:concrete:0)
Block(8,5,-2,minecraft:concrete:0)
Block(8,6,-6,minecraft:concrete:0)
Block(8,6,-5,minecraft:concrete:0)
Block(8,6,-4,minecraft:concrete:0)
Block(8,6,-3,minecraft:concrete:0)
Block(8,6,-2,minecraft:concrete:0)
Block(8,7,-6,minecraft:concrete:0)
Block(8,7,-5,minecraft:concrete:0)
Block(8,7,-4,minecraft:concrete:0)
Block(8,7,-3,minecraft:concrete:0)
Block(8,7,-2,minecraft:concrete:0)
Block(8,8,-6,minecraft:concrete:0)
Block(8,8,-5,minecraft:concrete:0)
Block(8,8,-4,minecraft:concrete:0)
Block(8,8,-3,minecraft:concrete:0)
Block(8,8,-2,minecraft:concrete:0)
Block(8,9,-6,minecraft:concrete:0)
Block(8,9,-5,minecraft:concrete:0)
Block(8,9,-4,minecraft:concrete:0)
Block(8,9,-3,minecraft:concrete:0)
Block(8,9,-2,minecraft:concrete:0)
Block(8,10,-6,minecraft:concrete:0)
Block(8,10,-5,minecraft:concrete:0)
Block(8,10,-4,minecraft:concrete:0)
Block(8,10,-3,minecraft:concrete:0)
Block(8,10,-2,minecraft:concrete:0)
Block(8,11,-6,minecraft:stone_brick_stairs:1)
Block(8,11,-5,minecraft:concrete:0)
Block(8,11,-4,minecraft:concrete:0)
Block(8,11,-3,minecraft:concrete:0)
Block(8,11,-2,minecraft:concrete:0)

#######################################################################
# +-----------------------------------------------------------------+ #
# |                             Branches                            | #
# +-----------------------------------------------------------------+ #
#######################################################################

# Branches are child-BO4's that spawn if this BO4 is configured to spawn as a
# CustomStructure resource in a biome config. Branches can have branches,
# making complex structures possible. See the wiki for more details.

# Regular Branches spawn each branch with an independent chance of spawning.
# Branch(x,y,z,isRequiredBranch,branchName,rotation,chance,branchDepth[,anotherBranchName,rotation,chance,branchDepth[,...]][IndividualChance])
# branchName - name of the object to spawn.
# rotation - NORTH, SOUTH, EAST or WEST.
# IndividualChance - The chance each branch has to spawn, assumed to be 100 when left blank
# isRequiredBranch - If this is set to true then at least one of the branches in this BO4 must spawn at these x,y,z coordinates. If no branch can spawn there then this BO4 fails to spawn and its branch is rolled back.
# isRequiredBranch:true branches must spawn or the current branch is rolled back entirely. This is useful for grouping BO4's that must spawn together, for instance a single room made of multiple BO4's/branches.
# If all parts of the room are connected together via isRequiredBranch:true branches then either the entire room will spawns or no part of it will spawn.
# *Note: When isRequiredBranch:true only one BO4 can be added per Branch() and it will automatically have a rarity of 100.0.
# isRequiredBranch:false branches are used to make optional parts of structures, for instance the middle section of a tunnel that has a beginning, middle and end BO4/branch and can have a variable length by repeating the middle BO4/branch.
# By making the start and end branches isRequiredBranch:true and the middle branch isRequiredbranch:false you can make it so that either:
# A. A tunnel spawns with at least a beginning and end branch
# B. A tunnel spawns with a beginning and end branch and as many middle branches as will fit in the available space.
# C. No tunnel spawns at all because there wasn't enough space to spawn at least a beginning and end branch.
# branchDepth - When creating a chain of branches that contains optional (isRequiredBranch:false) branches branch depth is configured for the first BO4 in the chain to determine the maximum length of the chain.
# branchDepth - 1 is inherited by each isRequiredBranch:false branch in the chain. When branchDepth is zero isRequiredBranch:false branches cannot spawn and the chain ends. In the case of the tunnel this means the last middle branch would be
# rolled back and an IsRequiredBranch:true end branch could be spawned in its place to make sure the tunnel has a proper ending.
# Instead of inheriting branchDepth - 1 from the parent branchDepth can be overridden by child branches if it is set higher than 0 (the default value).
# isRequiredBranch:true branches do inherit branchDepth and pass it on to their own branches, however they cannot be prevented from spawning by it and also don't subtract 1 from branchDepth when inheriting it.

# Weighted Branches spawn branches with a dependent chance of spawning.
# WeightedBranch(x,y,z,isRequiredBranch,branchName,rotation,chance,branchDepth[,anotherBranchName,rotation,chance,branchDepth[,...]][MaxChanceOutOf])
# *Note: isRequiredBranch must be set to false. It is not possible to use isRequiredBranch:true with WeightedBranch() since isRequired:true branches must spawn and automatically have a rarity of 100.0.
# MaxChanceOutOf - The chance all branches have to spawn out of, assumed to be 100 when left blank

#######################################################################
# +-----------------------------------------------------------------+ #
# |                             Entities                            | #
# +-----------------------------------------------------------------+ #
#######################################################################

# Forge only (this may have changed, check for updates).
# An EntityFunction spawns an entity instead of a block. The entity is spawned only once when the BO4 is spawned.
# Entities are persistent by default so they don't de-spawn when no player is near, they are only unloaded.
# Usage: Entity(x,y,z,entityName,groupSize,NameTagOrNBTFileName) or Entity(x,y,z,mobName,groupSize)
# Use /otg entities to get a list of entities that can be used as entityName, this includes entities added by other mods and non-living entities.
# NameTagOrNBTFileName can be either a nametag for the mob or an .txt file with nbt data (such as myentityinfo.txt).
# In the text file you can use the same mob spawning parameters used with the /summon command to equip the
# entity and give it custom attributes etc. You can copy the DATA part of a summon command including surrounding 
# curly braces to a .txt file, for instance for: "/summon Skeleton x y z {DATA}"

#######################################################################
# +-----------------------------------------------------------------+ #
# |                            Particles                            | #
# +-----------------------------------------------------------------+ #
#######################################################################

# Forge only (this may have changed, check for updates).
# Creates an invisible particle spawner at the given location that spawns particles every x milliseconds.
# Usage: Particle(x,y,z,particleName,interval,velocityX,velocityY,velocityZ)
# velocityX, velocityY and velocityZ are optional.
# Only vanilla particle names can be used, for 1.11.2 these are;
# explode, largeexplode, hugeexplosion, fireworksSpark, bubble, splash, wake, suspended
# depthsuspend, crit, magicCrit, smoke, largesmoke, spell, instantSpell, mobSpell
# mobSpellAmbient, witchMagic, dripWater, dripLava, angryVillager, happyVillager
# townaura, note, portal, enchantmenttable, flame, lava, footstep, cloud, reddust
# snowballpoof,  snowshovel, slime, heart, barrier, iconcrack, blockcrack, blockdust
# droplet, take, mobappearance, dragonbreath, endRod, damageIndicator, sweepAttack
# fallingdust, totem, spit.
# Use /otg particles (forge only) to show a list of particles.
# velocityX,velocityY,velocityZ - Spawn the enemy with the given velocity. If this is not filled in then a small random velocity is applied.

#######################################################################
# +-----------------------------------------------------------------+ #
# |                             Spawners                            | #
# +-----------------------------------------------------------------+ #
#######################################################################

# Forge only (this may have changed, check for updates).
# Creates an invisible entity spawner at the given location that spawns entities every x seconds.
# Entities can only spawn if their spawn requirements are met (zombies/skeletons only spawn in the dark etc). Max entity count for the server is ignored, each spawner has its own maxCount setting.
# Usage: Spawner(x,y,z,entityName,nbtFileName,groupSize,interval,spawnChance,maxCount,despawnTime,velocityX,velocityY,velocityZ,yaw,pitch)
# nbtFileName, despawnTime, velocityX, velocityY, velocityZ, yaw and pitch are optional
# Example Spawner(0, 0, 0, Villager, 1, 5, 100, 5) or Spawner(0, 0, 0, Villager, villager1.txt, 1, 5, 100, 5) or Spawner(0, 0, 0, Villager, 1, 5, 100, 5, 30, 1, 1, 1, 0, 0)
# entityName - Name of the entity to spawn, use /otg entities to get a list of entities that can be used as entityName, this includes entities added by other mods and non-living entities.
# nbtFileName - A .txt file with nbt data (such as myentityinfo.txt).
# In the text file you can use the same mob spawning parameters used with the /summon command to equip the
# entity and give it custom attributes etc. You can copy the DATA part of a summon command including surrounding 
# curly braces to a .txt file, for instance for: "/summon Skeleton x y z {DATA}"
# groupSize - Number of entities that should spawn for each successful spawn attempt.
# interval - Time in seconds between each spawn attempt.
# spawnChance - For each spawn attempt, the chance between 0-100 that the spawn attempt will succeed.
# maxCount - The maximum amount of this kind of entity that can exist within 32 blocks. If there are already maxCount or more entities of this type in a 32 radius this spawner will not spawn anything.
# despawnTime - After despawnTime seconds, if there is no player within 32 blocks of the entity it will despawn..
# velocityX,velocityY,velocityZ,yaw,pitch - Spawn the enemy with the given velocity and angle, handy for making traps and launchers (shooting arrows and fireballs etc).

#######################################################################
# +-----------------------------------------------------------------+ #
# |                             ModData                             | #
# +-----------------------------------------------------------------+ #
#######################################################################

# Forge only.
# Use the ModData() tag to include data that other mods can use
# Mod makers can use ModData and the /otg GetModData command to test IMC communications between OTG
# and their mod.
# Normal users can use it to spawn some mobs and blocks on command.
# ModData(x,y,z,"ModName", "MyModDataAsText"
# Example: ModData(x,y,z,MyCystomNPCMod,SpawnBobHere/WithAPotato/And50Health)
# Try not to use exotic/reserved characters, like brackets and comma's etc, this stuff isn't fool-proof.
# Also, use this only to store IDs/object names etc for your mod, DO NOT include things like character dialogue,
# messages on signs, loot lists etc in this file. As much as possible just store id's/names here and store all the data related to those id's/names in your own mod.
# OTG has some built in ModData commands for basic mob and block spawning.
# These are mostly just a demonstration for mod makers to show how ModData.
# can be used by other mods.
# For mob spawning in OTG use: ModData(x,y,z,OTG,mob/MobType/Count/Persistent/Name)
# mob: Makes OTG recognise this as a mob spawning command.
# MobType: Lower-case, no spaces. Any vanilla mob like dragon, skeleton, wither, villager etc
# Count: The number of mobs to spawn
# Persistent (true/false): Should the mobs never de-spawn? If set to true the mob will get a
# name-tag ingame so you can recognise it.
# Name: A name-tag for the monster/npc.
# Example: ModData(0,0,0,OTG,villager/1/true/Bob)
# To spawn blocks using ModData use: ModData(x,y,z,OTG,block/material)
# block: Makes OTG recognise this as a block spawning command.
# material: id or text, custom blocks can be added using ModName:MaterialName.
# To send all ModData within a radius in chunks around the player to the specified mod
# use this console command: /otg GetModData ModName Radius
# ModName: name of the mod, for OTG commands use OTG 
# Radius (optional): Radius in chunks around the player.
