
#######################################################################
# +-----------------------------------------------------------------+ #
# |                            BO4 object                           | #
# +-----------------------------------------------------------------+ #
#######################################################################

# This is the config file of a custom object.
# If you add this object correctly to your BiomeConfigs, it will spawn in the world.

# This is the creator of this BO4 object
Author: NLBlackEagle

# A short description of this BO4 object
Description: No description given

# The settings mode, WriteAll, WriteWithoutComments or WriteDisable. See WorldConfig.
SettingsMode: WriteAll


#######################################################################
# +-----------------------------------------------------------------+ #
# |                          Main settings                          | #
# +-----------------------------------------------------------------+ #
#######################################################################

# If this BO4 should spawn with a fixed rotation, set it here.
# For example: NORTH, EAST, SOUTH or WEST. Empty by default
FixedRotation: 

# This BO4 can only spawn at least Frequency chunks distance away from any other BO4 with the exact same name.
# You can use this to make this BO4 spawn in groups or make sure that this BO4 only spawns once every X chunks.
Frequency: 0

# The spawn height of the BO4: randomY, highestBlock or highestSolidBlock.
SpawnHeight: highestBlock

# When set to true, uses the center of the structure (determined by minimum structure size) when checking the highestBlock to spawn at.
UseCenterForHighestBlock: true

##############################
# Height Limits for the BO4. #
##############################

# When in randomY mode used as the minimum Y or in atMinY mode as the actual Y to spawn this BO4 at.
MinHeight: 0

# When in randomY mode used as the maximum Y to spawn this BO4 at.
MaxHeight: 255

# Copies the blocks and branches of an existing BO4 into this BO4. You can still add blocks and branches in this BO4, they will be added on top of the inherited blocks and branches.
InheritBO3: 

# Rotates the inheritedBO3's resources (blocks, spawners, checks etc) and branches, defaults to NORTH (no rotation).
InheritBO3Rotation: NORTH

# Defaults to true, if true and this is the starting BO4 for this branching structure then this BO4's smoothing and height settings are used for all children (branches).
OverrideChildSettings: true

# Defaults to false, if true then this branch uses it's own height settings (SpawnHeight, minHeight, maxHeight, spawnAtWaterLevel) instead of those defined in the starting BO4 for this branching structure.
OverrideParentHeight: false

# If this is set to true then this BO4 can spawn on top of or inside an existing BO4. If this is set to false then this BO4 will use a bounding box to detect collisions with other BO4's, if a collision is detected then this BO4 won't spawn and the current branch is rolled back.
CanOverride: false

# This branch can only spawn at least branchFrequency chunks (x,z) distance away from any other branch with the exact same name.
BranchFrequency: 0

# Define groups that this branch belongs to along with a minimum (x,z) range in chunks that this branch must have between it and any other members of this group if it is to be allowed to spawn. Syntax is "GroupName:Frequency, GoupName2:Frequency2" etc so for example a branch that belongs to 3 groups: "BranchFrequencyGroup: Ships:10, Vehicles:5, FloatingThings:3".
BranchFrequencyGroup: 

# If this is set to true then this BO4 can only spawn underneath an existing BO4. Used to make sure that dungeons only appear underneath buildings.
MustBeBelowOther: false

# Used with CanOverride: true. A comma-seperated list of BO4s, this BO4's bounding box must collide with one of the BO4's in the list or this BO4 fails to spawn and the current branch is rolled back. AND/OR is supported, comma is OR, space is AND, f.e: branch1, branch2 branch3, branch 4.
MustBeInside: 

# Used with CanOverride: true. A comma-seperated list of BO4s, this BO4's bounding box cannot collide with any of the BO4's in the list or this BO4 fails to spawn and the current branch is rolled back.
CannotBeInside: 

# Used with CanOverride: true. A comma-seperated list of BO4s, if this BO4's bounding box collides with any of the BO4's in the list then those BO4's won't spawn any blocks. This does not remove or roll back any BO4's.
ReplacesBO3: 

# If this is set to true then this BO4 can only spawn inside world borders. Used to make sure that dungeons only appear inside the world borders.
MustBeInsideWorldBorders: true

# Defaults to true. Set to false if the BO4 is not allowed to spawn on a water block
CanSpawnOnWater: true

# Defaults to false. Set to true if the BO4 is allowed to spawn only on a water block
SpawnOnWaterOnly: false

# Defaults to false. Set to true if the BO4 and its smoothing area should ignore water when looking for the highest block to spawn on. Defaults to false (things spawn on top of water)
SpawnUnderWater: false

# Defaults to false. Set to true if the BO4 should spawn at water level
SpawnAtWaterLevel: false

# Spawns the BO4 at a Y offset of this value. Handy when using highestBlock for lowering BO4s into the surrounding terrain when there are layers of ground included in the BO4, also handy when using SpawnAtWaterLevel to lower objects like ships into the water.
HeightOffset: 0

# If set to true removes all AIR blocks from the BO4 so that it can be flooded or buried.
RemoveAir: false

# Replaces all the non-air blocks that are above this BO4 or its smoothing area with the given block material (should be WATER or AIR or NONE), also applies to smoothing areas although OTG intentionally leaves some of the terrain above them intact. WATER can be used in combination with SpawnUnderWater to fill any air blocks underneath waterlevel with water (and any above waterlevel with air).
ReplaceAbove: 

# Replaces all air blocks underneath the BO4 (but not its smoothing area) with the specified material until a solid block is found.
ReplaceBelow: 

# Defaults to true. If set to true then every block in the BO4 of the materials defined in ReplaceWithGroundBlock or ReplaceWithSurfaceBlock will be replaced by the GroundBlock or SurfaceBlock materials configured for the biome the block is spawned in.
ReplaceWithBiomeBlocks: true

# Defaults to GRASS, Replaces all the blocks of the given material in the BO4 with the SurfaceBlock configured for the biome it spawns in.
ReplaceWithSurfaceBlock: GRASS

# Defaults to DIRT, Replaces all the blocks of the given material in the BO4 with the GroundBlock configured for the biome it spawns in.
ReplaceWithGroundBlock: DIRT

# Defaults to STONE, Replaces all the blocks of the given material in the BO4 with the StoneBlock configured for the biome it spawns in.
ReplaceWithStoneBlock: STONE

# Makes the terrain around the BO4 slope evenly towards the edges of the BO4. The given value is the distance in blocks around the BO4 from where the slope should start and can be any positive number.
SmoothRadius: 0

# Moves the smoothing area up or down relative to the BO4 (at the points where the smoothing area is connected to the BO4). Handy when using SmoothStartTop: false and the BO4 has some layers of ground included, in that case we can set the HeightOffset to a negative value to lower the BO4 into the ground and we can set the SmoothHeightOffset to a positive value to move the smoothing area starting height up.
SmoothHeightOffset: 0

# Should the smoothing area be attached at the bottom or the top of the edges of the BO4? Defaults to false (bottom). Using this setting can make things slower so try to avoid using it and use SmoothHeightOffset instead if for instance you have a BO4 with some ground layers included. The only reason you should need to use this setting is if you have a BO4 with edges that have an irregular height (like some hills).
SmoothStartTop: false

# Should the smoothing area attach itself to "log" block or ignore them? Defaults to false (ignore logs).
SmoothStartWood: false

# The block used for smoothing area surface blocks, defaults to biome SurfaceBlock.
SmoothingSurfaceBlock: 

# The block used for smoothing area ground blocks, defaults to biome GroundBlock.
SmoothingGroundBlock: 

# Define groups that this BO4 belongs to along with a minimum range in chunks that this BO4 must have between it and any other members of this group if it is to be allowed to spawn. Syntax is "GroupName:Frequency, GoupName2:Frequency2" etc so for example a BO4 that belongs to 3 groups: "BO4Group: Ships:10, Vehicles:5, FloatingThings:3".
BO3Group: 

# Defaults to false. Set to true if this BO4 should spawn at the player spawn point. When the server starts the spawn point is determined and the BO4's for the biome it is in are loaded, one of these BO4s that has IsSpawnPoint set to true (if any) is selected randomly and is spawned at the spawn point regardless of its rarity (so even Rarity:0, IsSpawnPoint: true BO4's can get spawned as the spawn point!).
IsSpawnPoint: false

# Defaults to true. Set to false to make the BO4 ignore any ReplacedBlocks settings in Biome Configs.
DoReplaceBlocks: true


#######################################################################
# +-----------------------------------------------------------------+ #
# |                              Blocks                             | #
# +-----------------------------------------------------------------+ #
#######################################################################

# All the blocks used in the BO4 are listed here. Possible blocks:
# Block(x,y,z,id[.data][,nbtfile.nbt)
# RandomBlock(x,y,z,id[:data][,nbtfile.nbt],chance[,id[:data][,nbtfile.nbt],chance[,...]])
#  So RandomBlock(0,0,0,CHEST,chest.nbt,50,CHEST,anotherchest.nbt,100) will spawn a chest at
#  the BO4 origin, and give it a 50% chance to have the contents of chest.nbt, or, if that
#  fails, a 100% percent chance to have the contents of anotherchest.nbt.
# MinecraftObject(x,y,z,name) (TODO: This may not work anymore and needs to be tested.
#  Spawns an object in the Mojang NBT structure format. For example, 
#  MinecraftObject(0,0,0,minecraft:igloo/igloo_bottom)
#  spawns the bottom part of an igloo.
Block(-6,0,-5,CONCRETE:0)
Block(-6,0,-4,CONCRETE:0)
Block(-6,0,-3,CONCRETE:0)
Block(-6,0,7,CONCRETE:0)
Block(-6,0,8,CONCRETE:0)
Block(-6,0,9,CONCRETE:0)
Block(-6,1,-5,CONCRETE:0)
Block(-6,1,-4,CONCRETE:0)
Block(-6,1,-3,CONCRETE:0)
Block(-6,1,7,CONCRETE:0)
Block(-6,1,8,CONCRETE:0)
Block(-6,1,9,CONCRETE:0)
Block(-6,2,-5,CONCRETE:0)
Block(-6,2,-4,CONCRETE:0)
Block(-6,2,-3,CONCRETE:0)
Block(-6,2,7,CONCRETE:0)
Block(-6,2,8,CONCRETE:0)
Block(-6,2,9,CONCRETE:0)
Block(-6,3,-5,CONCRETE:0)
Block(-6,3,-4,CONCRETE:0)
Block(-6,3,-3,CONCRETE:0)
Block(-6,3,7,CONCRETE:0)
Block(-6,3,8,CONCRETE:0)
Block(-6,3,9,CONCRETE:0)
Block(-6,4,-5,CONCRETE:0)
Block(-6,4,-4,CONCRETE:0)
Block(-6,4,-3,CONCRETE:0)
Block(-6,4,7,CONCRETE:0)
Block(-6,4,8,CONCRETE:0)
Block(-6,4,9,CONCRETE:0)
Block(-6,5,-5,CONCRETE:0)
Block(-6,5,-4,SMOOTH_STAIRS:0)
Block(-6,5,-3,CONCRETE:0)
Block(-6,5,7,CONCRETE:0)
Block(-6,5,8,SMOOTH_STAIRS:0)
Block(-6,5,9,CONCRETE:0)
Block(-5,0,-5,CONCRETE:0)
Block(-5,0,-4,CONCRETE:0)
Block(-5,0,-3,CONCRETE:0)
Block(-5,0,7,CONCRETE:0)
Block(-5,0,8,CONCRETE:0)
Block(-5,0,9,CONCRETE:0)
Block(-5,1,-5,CONCRETE:0)
Block(-5,1,-4,CONCRETE:0)
Block(-5,1,-3,CONCRETE:0)
Block(-5,1,7,CONCRETE:0)
Block(-5,1,8,CONCRETE:0)
Block(-5,1,9,CONCRETE:0)
Block(-5,2,-5,CONCRETE:0)
Block(-5,2,-4,CONCRETE:0)
Block(-5,2,-3,CONCRETE:0)
Block(-5,2,7,CONCRETE:0)
Block(-5,2,8,CONCRETE:0)
Block(-5,2,9,CONCRETE:0)
Block(-5,3,-5,CONCRETE:0)
Block(-5,3,-4,CONCRETE:0)
Block(-5,3,-3,CONCRETE:0)
Block(-5,3,7,CONCRETE:0)
Block(-5,3,8,CONCRETE:0)
Block(-5,3,9,CONCRETE:0)
Block(-5,4,-5,CONCRETE:0)
Block(-5,4,-4,CONCRETE:0)
Block(-5,4,-3,CONCRETE:0)
Block(-5,4,7,CONCRETE:0)
Block(-5,4,8,CONCRETE:0)
Block(-5,4,9,CONCRETE:0)
Block(-5,5,-5,SMOOTH_STAIRS:2)
Block(-5,5,-4,CONCRETE:0)
Block(-5,5,-3,SMOOTH_STAIRS:3)
Block(-5,5,7,SMOOTH_STAIRS:2)
Block(-5,5,8,CONCRETE:0)
Block(-5,5,9,SMOOTH_STAIRS:3)
Block(-5,6,-4,CONCRETE:0)
Block(-5,6,-3,CONCRETE:0)
Block(-5,6,-2,CONCRETE:0)
Block(-5,6,-1,CONCRETE:0)
Block(-5,6,0,CONCRETE:0)
Block(-5,6,1,CONCRETE:0)
Block(-5,6,2,CONCRETE:0)
Block(-5,6,3,CONCRETE:0)
Block(-5,6,4,CONCRETE:0)
Block(-5,6,5,CONCRETE:0)
Block(-5,6,6,CONCRETE:0)
Block(-5,6,7,CONCRETE:0)
Block(-5,6,8,CONCRETE:0)
Block(-5,7,-4,CONCRETE:0)
Block(-5,7,8,CONCRETE:0)
Block(-5,8,-4,CONCRETE:0)
Block(-5,8,-3,SMOOTH_BRICK:0)
Block(-5,8,7,SMOOTH_BRICK:0)
Block(-5,8,8,CONCRETE:0)
Block(-5,9,-4,CONCRETE:0)
Block(-5,9,-3,CONCRETE:0)
Block(-5,9,-2,SMOOTH_BRICK:0)
Block(-5,9,6,SMOOTH_BRICK:0)
Block(-5,9,7,CONCRETE:0)
Block(-5,9,8,CONCRETE:0)
Block(-5,10,-4,CONCRETE:0)
Block(-5,10,-3,CONCRETE:7)
Block(-5,10,-2,CONCRETE:0)
Block(-5,10,-1,SMOOTH_BRICK:0)
Block(-5,10,5,SMOOTH_BRICK:0)
Block(-5,10,6,CONCRETE:0)
Block(-5,10,7,CONCRETE:7)
Block(-5,10,8,CONCRETE:0)
Block(-5,11,-4,CONCRETE:0)
Block(-5,11,-2,CONCRETE:7)
Block(-5,11,-1,CONCRETE:0)
Block(-5,11,0,SMOOTH_BRICK:0)
Block(-5,11,4,SMOOTH_BRICK:0)
Block(-5,11,5,CONCRETE:0)
Block(-5,11,6,CONCRETE:7)
Block(-5,11,8,CONCRETE:0)
Block(-5,12,-4,CONCRETE:0)
Block(-5,12,-1,CONCRETE:7)
Block(-5,12,0,CONCRETE:0)
Block(-5,12,1,SMOOTH_BRICK:0)
Block(-5,12,3,SMOOTH_BRICK:0)
Block(-5,12,4,CONCRETE:0)
Block(-5,12,5,CONCRETE:7)
Block(-5,12,8,CONCRETE:0)
Block(-5,13,-4,CONCRETE:0)
Block(-5,13,0,CONCRETE:7)
Block(-5,13,1,CONCRETE:0)
Block(-5,13,2,SMOOTH_BRICK:0)
Block(-5,13,3,CONCRETE:0)
Block(-5,13,4,CONCRETE:7)
Block(-5,13,8,CONCRETE:0)
Block(-5,14,-4,CONCRETE:0)
Block(-5,14,1,IRON_FENCE)
Block(-5,14,2,CONCRETE:0)
Block(-5,14,3,IRON_FENCE)
Block(-5,14,8,CONCRETE:0)
Block(-5,15,-4,CONCRETE:0)
Block(-5,15,0,SMOOTH_BRICK:0)
Block(-5,15,1,CONCRETE:0)
Block(-5,15,2,CONCRETE:7)
Block(-5,15,3,CONCRETE:0)
Block(-5,15,4,SMOOTH_BRICK:0)
Block(-5,15,8,CONCRETE:0)
Block(-5,16,-4,CONCRETE:0)
Block(-5,16,-1,SMOOTH_BRICK:0)
Block(-5,16,0,CONCRETE:0)
Block(-5,16,1,CONCRETE:7)
Block(-5,16,3,CONCRETE:7)
Block(-5,16,4,CONCRETE:0)
Block(-5,16,5,SMOOTH_BRICK:0)
Block(-5,16,8,CONCRETE:0)
Block(-5,17,-4,CONCRETE:0)
Block(-5,17,-2,SMOOTH_BRICK:0)
Block(-5,17,-1,CONCRETE:0)
Block(-5,17,0,CONCRETE:7)
Block(-5,17,4,CONCRETE:7)
Block(-5,17,5,CONCRETE:0)
Block(-5,17,6,SMOOTH_BRICK:0)
Block(-5,17,8,CONCRETE:0)
Block(-5,18,-4,CONCRETE:0)
Block(-5,18,-3,SMOOTH_BRICK:0)
Block(-5,18,-2,CONCRETE:0)
Block(-5,18,-1,CONCRETE:7)
Block(-5,18,5,CONCRETE:7)
Block(-5,18,6,CONCRETE:0)
Block(-5,18,7,SMOOTH_BRICK:0)
Block(-5,18,8,CONCRETE:0)
Block(-5,19,-4,CONCRETE:0)
Block(-5,19,-3,CONCRETE:0)
Block(-5,19,-2,CONCRETE:7)
Block(-5,19,6,CONCRETE:7)
Block(-5,19,7,CONCRETE:0)
Block(-5,19,8,CONCRETE:0)
Block(-5,20,-4,CONCRETE:0)
Block(-5,20,-3,CONCRETE:7)
Block(-5,20,7,CONCRETE:7)
Block(-5,20,8,CONCRETE:0)
Block(-5,21,-4,IRON_FENCE)
Block(-5,21,8,IRON_FENCE)
Block(-5,22,-4,IRON_FENCE)
Block(-5,22,8,IRON_FENCE)
Block(-5,23,-4,IRON_FENCE)
Block(-5,23,8,IRON_FENCE)
Block(-4,0,-5,CONCRETE:0)
Block(-4,0,-4,CONCRETE:0)
Block(-4,0,-3,CONCRETE:0)
Block(-4,0,7,CONCRETE:0)
Block(-4,0,8,CONCRETE:0)
Block(-4,0,9,CONCRETE:0)
Block(-4,1,-5,CONCRETE:0)
Block(-4,1,-4,CONCRETE:0)
Block(-4,1,-3,CONCRETE:0)
Block(-4,1,7,CONCRETE:0)
Block(-4,1,8,CONCRETE:0)
Block(-4,1,9,CONCRETE:0)
Block(-4,2,-5,CONCRETE:0)
Block(-4,2,-4,CONCRETE:0)
Block(-4,2,-3,CONCRETE:0)
Block(-4,2,7,CONCRETE:0)
Block(-4,2,8,CONCRETE:0)
Block(-4,2,9,CONCRETE:0)
Block(-4,3,-5,CONCRETE:0)
Block(-4,3,-4,CONCRETE:0)
Block(-4,3,-3,CONCRETE:0)
Block(-4,3,7,CONCRETE:0)
Block(-4,3,8,CONCRETE:0)
Block(-4,3,9,CONCRETE:0)
Block(-4,4,-5,CONCRETE:0)
Block(-4,4,-4,CONCRETE:0)
Block(-4,4,-3,CONCRETE:0)
Block(-4,4,7,CONCRETE:0)
Block(-4,4,8,CONCRETE:0)
Block(-4,4,9,CONCRETE:0)
Block(-4,5,-5,CONCRETE:0)
Block(-4,5,-4,SMOOTH_STAIRS:1)
Block(-4,5,-3,CONCRETE:0)
Block(-4,5,7,CONCRETE:0)
Block(-4,5,8,SMOOTH_STAIRS:1)
Block(-4,5,9,CONCRETE:0)
Block(-4,6,-4,CONCRETE:0)
Block(-4,6,8,CONCRETE:0)
Block(-4,8,-4,SMOOTH_BRICK:0)
Block(-4,8,8,SMOOTH_BRICK:0)
Block(-4,9,-4,CONCRETE:0)
Block(-4,9,8,CONCRETE:0)
Block(-4,10,-4,CONCRETE:7)
Block(-4,10,8,CONCRETE:7)
Block(-4,18,-4,SMOOTH_BRICK:0)
Block(-4,18,-3,IRON_FENCE)
Block(-4,18,-2,IRON_FENCE)
Block(-4,18,-1,IRON_FENCE)
Block(-4,18,0,IRON_FENCE)
Block(-4,18,1,IRON_FENCE)
Block(-4,18,2,IRON_FENCE)
Block(-4,18,3,IRON_FENCE)
Block(-4,18,4,IRON_FENCE)
Block(-4,18,5,IRON_FENCE)
Block(-4,18,6,IRON_FENCE)
Block(-4,18,7,IRON_FENCE)
Block(-4,18,8,SMOOTH_BRICK:0)
Block(-4,19,-4,CONCRETE:0)
Block(-4,19,-3,CONCRETE:0)
Block(-4,19,-2,CONCRETE:0)
Block(-4,19,-1,CONCRETE:0)
Block(-4,19,0,CONCRETE:0)
Block(-4,19,1,CONCRETE:0)
Block(-4,19,2,CONCRETE:0)
Block(-4,19,3,CONCRETE:0)
Block(-4,19,4,CONCRETE:0)
Block(-4,19,5,CONCRETE:0)
Block(-4,19,6,CONCRETE:0)
Block(-4,19,7,CONCRETE:0)
Block(-4,19,8,CONCRETE:0)
Block(-4,20,-4,CONCRETE:7)
Block(-4,20,-3,CONCRETE:0)
Block(-4,20,-2,SMOOTH_BRICK:0)
Block(-4,20,-1,IRON_FENCE)
Block(-4,20,0,IRON_FENCE)
Block(-4,20,1,IRON_FENCE)
Block(-4,20,2,IRON_FENCE)
Block(-4,20,3,IRON_FENCE)
Block(-4,20,4,IRON_FENCE)
Block(-4,20,5,IRON_FENCE)
Block(-4,20,6,SMOOTH_BRICK:0)
Block(-4,20,7,CONCRETE:0)
Block(-4,20,8,CONCRETE:7)
Block(-4,21,-3,CONCRETE:0)
Block(-4,21,-2,CONCRETE:0)
Block(-4,21,-1,SMOOTH_BRICK:0)
Block(-4,21,5,SMOOTH_BRICK:0)
Block(-4,21,6,CONCRETE:0)
Block(-4,21,7,CONCRETE:0)
Block(-4,22,-3,CONCRETE:0)
Block(-4,22,-2,CONCRETE:7)
Block(-4,22,-1,CONCRETE:0)
Block(-4,22,0,SMOOTH_BRICK:0)
Block(-4,22,4,SMOOTH_BRICK:0)
Block(-4,22,5,CONCRETE:0)
Block(-4,22,6,CONCRETE:7)
Block(-4,22,7,CONCRETE:0)
Block(-4,23,-3,CONCRETE:0)
Block(-4,23,-1,CONCRETE:7)
Block(-4,23,0,CONCRETE:0)
Block(-4,23,1,SMOOTH_BRICK:0)
Block(-4,23,3,SMOOTH_BRICK:0)
Block(-4,23,4,CONCRETE:0)
Block(-4,23,5,CONCRETE:7)
Block(-4,23,7,CONCRETE:0)
Block(-4,24,-3,CONCRETE:0)
Block(-4,24,0,CONCRETE:7)
Block(-4,24,1,CONCRETE:0)
Block(-4,24,2,SMOOTH_BRICK:0)
Block(-4,24,3,CONCRETE:0)
Block(-4,24,4,CONCRETE:7)
Block(-4,24,7,CONCRETE:0)
Block(-4,25,-3,CONCRETE:0)
Block(-4,25,1,CONCRETE:7)
Block(-4,25,2,CONCRETE:0)
Block(-4,25,3,CONCRETE:7)
Block(-4,25,7,CONCRETE:0)
Block(-4,26,-3,CONCRETE:7)
Block(-4,26,-2,CONCRETE:7)
Block(-4,26,-1,SMOOTH_BRICK:0)
Block(-4,26,2,IRON_FENCE)
Block(-4,26,5,SMOOTH_BRICK:0)
Block(-4,26,6,CONCRETE:7)
Block(-4,26,7,CONCRETE:7)
Block(-4,27,-3,CONCRETE:7)
Block(-4,27,0,CONCRETE:7)
Block(-4,27,1,SMOOTH_BRICK:0)
Block(-4,27,3,SMOOTH_BRICK:0)
Block(-4,27,4,CONCRETE:7)
Block(-4,27,7,CONCRETE:7)
Block(-4,28,-3,CONCRETE:7)
Block(-4,28,1,SMOOTH_BRICK:0)
Block(-4,28,2,CONCRETE:7)
Block(-4,28,3,SMOOTH_BRICK:0)
Block(-4,28,7,CONCRETE:7)
Block(-4,29,-3,CONCRETE:7)
Block(-4,29,-1,SMOOTH_BRICK:0)
Block(-4,29,0,CONCRETE:7)
Block(-4,29,4,CONCRETE:7)
Block(-4,29,5,SMOOTH_BRICK:0)
Block(-4,29,7,CONCRETE:7)
Block(-4,30,-3,CONCRETE:7)
Block(-4,30,-2,SMOOTH_BRICK:0)
Block(-4,30,-1,SMOOTH_BRICK:0)
Block(-4,30,0,SMOOTH_BRICK:0)
Block(-4,30,1,SMOOTH_BRICK:0)
Block(-4,30,2,SMOOTH_BRICK:0)
Block(-4,30,3,SMOOTH_BRICK:0)
Block(-4,30,4,SMOOTH_BRICK:0)
Block(-4,30,5,SMOOTH_BRICK:0)
Block(-4,30,6,SMOOTH_BRICK:0)
Block(-4,30,7,CONCRETE:7)
Block(-4,31,-3,IRON_FENCE)
Block(-4,31,-2,SMOOTH_STAIRS:0)
Block(-4,31,-1,IRON_FENCE)
Block(-4,31,0,IRON_FENCE)
Block(-4,31,1,IRON_FENCE)
Block(-4,31,2,IRON_FENCE)
Block(-4,31,3,IRON_FENCE)
Block(-4,31,4,IRON_FENCE)
Block(-4,31,5,IRON_FENCE)
Block(-4,31,6,SMOOTH_STAIRS:0)
Block(-4,31,7,IRON_FENCE)
Block(-4,32,-3,IRON_FENCE)
Block(-4,32,7,IRON_FENCE)
Block(-4,33,-3,IRON_FENCE)
Block(-4,33,7,IRON_FENCE)
Block(-3,6,-4,CONCRETE:0)
Block(-3,6,8,CONCRETE:0)
Block(-3,9,-4,SMOOTH_BRICK:0)
Block(-3,9,8,SMOOTH_BRICK:0)
Block(-3,10,-4,CONCRETE:0)
Block(-3,10,8,CONCRETE:0)
Block(-3,11,-4,CONCRETE:7)
Block(-3,11,8,CONCRETE:7)
Block(-3,17,-4,SMOOTH_BRICK:0)
Block(-3,17,8,SMOOTH_BRICK:0)
Block(-3,18,-4,CONCRETE:0)
Block(-3,18,-3,IRON_FENCE)
Block(-3,18,7,IRON_FENCE)
Block(-3,18,8,CONCRETE:0)
Block(-3,19,-4,CONCRETE:7)
Block(-3,19,-3,CONCRETE:0)
Block(-3,19,7,CONCRETE:0)
Block(-3,19,8,CONCRETE:7)
Block(-3,20,-3,SMOOTH_BRICK:0)
Block(-3,20,7,SMOOTH_BRICK:0)
Block(-3,21,-3,CONCRETE:0)
Block(-3,21,7,CONCRETE:0)
Block(-3,22,-3,CONCRETE:7)
Block(-3,22,7,CONCRETE:7)
Block(-3,24,0,SMOOTH_BRICK:0)
Block(-3,24,2,SMOOTH_BRICK:0)
Block(-3,24,4,SMOOTH_BRICK:0)
Block(-3,25,-2,CONCRETE:0)
Block(-3,25,-1,CONCRETE:0)
Block(-3,25,0,CONCRETE:0)
Block(-3,25,1,CONCRETE:0)
Block(-3,25,2,CONCRETE:0)
Block(-3,25,3,CONCRETE:0)
Block(-3,25,4,CONCRETE:0)
Block(-3,25,5,CONCRETE:0)
Block(-3,25,6,CONCRETE:0)
Block(-3,26,-3,CONCRETE:7)
Block(-3,26,-2,IRON_FENCE)
Block(-3,26,-1,IRON_FENCE)
Block(-3,26,0,IRON_FENCE)
Block(-3,26,1,IRON_FENCE)
Block(-3,26,2,IRON_FENCE)
Block(-3,26,3,IRON_FENCE)
Block(-3,26,4,IRON_FENCE)
Block(-3,26,5,IRON_FENCE)
Block(-3,26,6,IRON_FENCE)
Block(-3,26,7,CONCRETE:7)
Block(-3,30,-3,SMOOTH_BRICK:0)
Block(-3,30,-2,SMOOTH_BRICK:0)
Block(-3,30,6,SMOOTH_BRICK:0)
Block(-3,30,7,SMOOTH_BRICK:0)
Block(-3,31,-3,SMOOTH_STAIRS:2)
Block(-3,31,-2,CONCRETE:7)
Block(-3,31,-1,CONCRETE:7)
Block(-3,31,0,SMOOTH_BRICK:0)
Block(-3,31,4,SMOOTH_BRICK:0)
Block(-3,31,5,CONCRETE:7)
Block(-3,31,6,CONCRETE:7)
Block(-3,31,7,SMOOTH_STAIRS:3)
Block(-3,32,-2,CONCRETE:7)
Block(-3,32,1,CONCRETE:7)
Block(-3,32,2,SMOOTH_BRICK:0)
Block(-3,32,3,CONCRETE:7)
Block(-3,32,6,CONCRETE:7)
Block(-3,33,-2,CONCRETE:7)
Block(-3,33,1,SMOOTH_BRICK:0)
Block(-3,33,2,CONCRETE:7)
Block(-3,33,3,SMOOTH_BRICK:0)
Block(-3,33,6,CONCRETE:7)
Block(-3,34,-2,CONCRETE:7)
Block(-3,34,-1,SMOOTH_BRICK:0)
Block(-3,34,0,CONCRETE:7)
Block(-3,34,4,CONCRETE:7)
Block(-3,34,5,SMOOTH_BRICK:0)
Block(-3,34,6,CONCRETE:7)
Block(-3,35,-2,CONCRETE:7)
Block(-3,35,-1,CONCRETE:7)
Block(-3,35,0,CONCRETE:7)
Block(-3,35,1,CONCRETE:7)
Block(-3,35,2,CONCRETE:7)
Block(-3,35,3,CONCRETE:7)
Block(-3,35,4,CONCRETE:7)
Block(-3,35,5,CONCRETE:7)
Block(-3,35,6,CONCRETE:7)
Block(-3,36,-2,CONCRETE:7)
Block(-3,36,-1,CONCRETE:7)
Block(-3,36,0,SMOOTH_BRICK:0)
Block(-3,36,4,SMOOTH_BRICK:0)
Block(-3,36,5,CONCRETE:7)
Block(-3,36,6,CONCRETE:7)
Block(-3,37,-2,CONCRETE:7)
Block(-3,37,1,CONCRETE:7)
Block(-3,37,2,SMOOTH_BRICK:0)
Block(-3,37,3,CONCRETE:7)
Block(-3,37,6,CONCRETE:7)
Block(-3,38,-2,CONCRETE:7)
Block(-3,38,0,SMOOTH_BRICK:0)
Block(-3,38,1,CONCRETE:7)
Block(-3,38,3,CONCRETE:7)
Block(-3,38,4,SMOOTH_BRICK:0)
Block(-3,38,6,CONCRETE:7)
Block(-3,39,-2,CONCRETE:7)
Block(-3,39,-1,SMOOTH_BRICK:0)
Block(-3,39,0,SMOOTH_BRICK:0)
Block(-3,39,1,SMOOTH_BRICK:0)
Block(-3,39,2,SMOOTH_BRICK:0)
Block(-3,39,3,SMOOTH_BRICK:0)
Block(-3,39,4,SMOOTH_BRICK:0)
Block(-3,39,5,SMOOTH_BRICK:0)
Block(-3,39,6,CONCRETE:7)
Block(-3,40,-2,IRON_FENCE)
Block(-3,40,-1,SMOOTH_STAIRS:0)
Block(-3,40,0,IRON_FENCE)
Block(-3,40,1,IRON_FENCE)
Block(-3,40,2,IRON_FENCE)
Block(-3,40,3,IRON_FENCE)
Block(-3,40,4,IRON_FENCE)
Block(-3,40,5,SMOOTH_STAIRS:0)
Block(-3,40,6,IRON_FENCE)
Block(-3,41,-2,IRON_FENCE)
Block(-3,41,6,IRON_FENCE)
Block(-2,6,-4,CONCRETE:0)
Block(-2,6,8,CONCRETE:0)
Block(-2,10,-4,SMOOTH_BRICK:0)
Block(-2,10,8,SMOOTH_BRICK:0)
Block(-2,11,-4,CONCRETE:0)
Block(-2,11,8,CONCRETE:0)
Block(-2,12,-4,CONCRETE:7)
Block(-2,12,8,CONCRETE:7)
Block(-2,16,-4,SMOOTH_BRICK:0)
Block(-2,16,8,SMOOTH_BRICK:0)
Block(-2,17,-4,CONCRETE:0)
Block(-2,17,8,CONCRETE:0)
Block(-2,18,-4,CONCRETE:7)
Block(-2,18,-3,IRON_FENCE)
Block(-2,18,7,IRON_FENCE)
Block(-2,18,8,CONCRETE:7)
Block(-2,19,-3,CONCRETE:0)
Block(-2,19,7,CONCRETE:0)
Block(-2,20,-3,IRON_FENCE)
Block(-2,20,7,IRON_FENCE)
Block(-2,21,-3,SMOOTH_BRICK:0)
Block(-2,21,7,SMOOTH_BRICK:0)
Block(-2,22,-3,CONCRETE:0)
Block(-2,22,7,CONCRETE:0)
Block(-2,23,-3,CONCRETE:7)
Block(-2,23,7,CONCRETE:7)
Block(-2,25,-2,CONCRETE:0)
Block(-2,25,6,CONCRETE:0)
Block(-2,26,-3,SMOOTH_BRICK:0)
Block(-2,26,-2,IRON_FENCE)
Block(-2,26,6,IRON_FENCE)
Block(-2,26,7,SMOOTH_BRICK:0)
Block(-2,29,-3,SMOOTH_BRICK:0)
Block(-2,29,7,SMOOTH_BRICK:0)
Block(-2,30,-3,SMOOTH_BRICK:0)
Block(-2,30,7,SMOOTH_BRICK:0)
Block(-2,31,-3,IRON_FENCE)
Block(-2,31,-2,CONCRETE:7)
Block(-2,31,6,CONCRETE:7)
Block(-2,31,7,IRON_FENCE)
Block(-2,34,-2,SMOOTH_BRICK:0)
Block(-2,34,6,SMOOTH_BRICK:0)
Block(-2,35,-2,CONCRETE:7)
Block(-2,35,6,CONCRETE:7)
Block(-2,36,-2,CONCRETE:7)
Block(-2,36,6,CONCRETE:7)
Block(-2,39,-2,SMOOTH_BRICK:0)
Block(-2,39,-1,CONCRETE:0)
Block(-2,39,0,CONCRETE:0)
Block(-2,39,1,CONCRETE:0)
Block(-2,39,2,CONCRETE:0)
Block(-2,39,3,CONCRETE:0)
Block(-2,39,4,CONCRETE:0)
Block(-2,39,5,CONCRETE:0)
Block(-2,39,6,SMOOTH_BRICK:0)
Block(-2,40,-2,SMOOTH_STAIRS:2)
Block(-2,40,-1,CONCRETE:0)
Block(-2,40,0,SMOOTH_BRICK:0)
Block(-2,40,1,IRON_FENCE)
Block(-2,40,2,CONCRETE:7)
Block(-2,40,3,IRON_FENCE)
Block(-2,40,4,SMOOTH_BRICK:0)
Block(-2,40,5,CONCRETE:0)
Block(-2,40,6,SMOOTH_STAIRS:3)
Block(-2,41,-1,CONCRETE:0)
Block(-2,41,0,CONCRETE:0)
Block(-2,41,1,SMOOTH_BRICK:0)
Block(-2,41,3,SMOOTH_BRICK:0)
Block(-2,41,4,CONCRETE:0)
Block(-2,41,5,CONCRETE:0)
Block(-2,42,-1,CONCRETE:0)
Block(-2,42,0,CONCRETE:7)
Block(-2,42,1,CONCRETE:0)
Block(-2,42,2,SMOOTH_BRICK:0)
Block(-2,42,3,CONCRETE:0)
Block(-2,42,4,CONCRETE:7)
Block(-2,42,5,CONCRETE:0)
Block(-2,43,-1,CONCRETE:0)
Block(-2,43,1,IRON_FENCE)
Block(-2,43,2,CONCRETE:0)
Block(-2,43,3,IRON_FENCE)
Block(-2,43,5,CONCRETE:0)
Block(-2,44,-1,CONCRETE:0)
Block(-2,44,0,SMOOTH_BRICK:0)
Block(-2,44,1,CONCRETE:0)
Block(-2,44,2,CONCRETE:7)
Block(-2,44,3,CONCRETE:0)
Block(-2,44,4,SMOOTH_BRICK:0)
Block(-2,44,5,CONCRETE:0)
Block(-2,45,-1,CONCRETE:0)
Block(-2,45,0,CONCRETE:0)
Block(-2,45,1,IRON_FENCE)
Block(-2,45,3,IRON_FENCE)
Block(-2,45,4,CONCRETE:0)
Block(-2,45,5,CONCRETE:0)
Block(-2,46,-1,CONCRETE:0)
Block(-2,46,0,CONCRETE:7)
Block(-2,46,1,CONCRETE:0)
Block(-2,46,2,SMOOTH_BRICK:0)
Block(-2,46,3,CONCRETE:0)
Block(-2,46,4,CONCRETE:7)
Block(-2,46,5,CONCRETE:0)
Block(-2,47,-1,CONCRETE:0)
Block(-2,47,1,IRON_FENCE)
Block(-2,47,2,CONCRETE:0)
Block(-2,47,3,IRON_FENCE)
Block(-2,47,5,CONCRETE:0)
Block(-2,48,-1,CONCRETE:0)
Block(-2,48,0,SMOOTH_BRICK:0)
Block(-2,48,1,CONCRETE:0)
Block(-2,48,2,CONCRETE:7)
Block(-2,48,3,CONCRETE:0)
Block(-2,48,4,SMOOTH_BRICK:0)
Block(-2,48,5,CONCRETE:0)
Block(-2,49,-1,CONCRETE:0)
Block(-2,49,0,CONCRETE:0)
Block(-2,49,1,CONCRETE:7)
Block(-2,49,3,CONCRETE:7)
Block(-2,49,4,CONCRETE:0)
Block(-2,49,5,CONCRETE:0)
Block(-2,50,-1,IRON_FENCE)
Block(-2,50,0,CONCRETE:7)
Block(-2,50,4,CONCRETE:7)
Block(-2,50,5,IRON_FENCE)
Block(-2,51,-1,IRON_FENCE)
Block(-2,51,5,IRON_FENCE)
Block(-1,6,-4,CONCRETE:0)
Block(-1,6,8,CONCRETE:0)
Block(-1,11,-4,SMOOTH_BRICK:0)
Block(-1,11,8,SMOOTH_BRICK:0)
Block(-1,12,-4,CONCRETE:0)
Block(-1,12,8,CONCRETE:0)
Block(-1,13,-4,CONCRETE:7)
Block(-1,13,8,CONCRETE:7)
Block(-1,15,-4,SMOOTH_BRICK:0)
Block(-1,15,8,SMOOTH_BRICK:0)
Block(-1,16,-4,CONCRETE:0)
Block(-1,16,8,CONCRETE:0)
Block(-1,17,-4,CONCRETE:7)
Block(-1,17,8,CONCRETE:7)
Block(-1,18,-3,IRON_FENCE)
Block(-1,18,7,IRON_FENCE)
Block(-1,19,-3,CONCRETE:0)
Block(-1,19,7,CONCRETE:0)
Block(-1,20,-3,IRON_FENCE)
Block(-1,20,7,IRON_FENCE)
Block(-1,22,-3,SMOOTH_BRICK:0)
Block(-1,22,7,SMOOTH_BRICK:0)
Block(-1,23,-3,CONCRETE:0)
Block(-1,23,7,CONCRETE:0)
Block(-1,24,-3,CONCRETE:7)
Block(-1,24,-2,SMOOTH_BRICK:0)
Block(-1,24,6,SMOOTH_BRICK:0)
Block(-1,24,7,CONCRETE:7)
Block(-1,25,-2,CONCRETE:0)
Block(-1,25,6,CONCRETE:0)
Block(-1,26,-2,IRON_FENCE)
Block(-1,26,6,IRON_FENCE)
Block(-1,27,-3,CONCRETE:7)
Block(-1,27,7,CONCRETE:7)
Block(-1,29,-3,CONCRETE:7)
Block(-1,29,7,CONCRETE:7)
Block(-1,30,-3,SMOOTH_BRICK:0)
Block(-1,30,7,SMOOTH_BRICK:0)
Block(-1,31,-3,IRON_FENCE)
Block(-1,31,-2,SMOOTH_BRICK:0)
Block(-1,31,6,SMOOTH_BRICK:0)
Block(-1,31,7,IRON_FENCE)
Block(-1,34,-2,CONCRETE:7)
Block(-1,34,6,CONCRETE:7)
Block(-1,35,-2,CONCRETE:7)
Block(-1,35,6,CONCRETE:7)
Block(-1,36,-2,SMOOTH_BRICK:0)
Block(-1,36,6,SMOOTH_BRICK:0)
Block(-1,38,-2,SMOOTH_BRICK:0)
Block(-1,38,6,SMOOTH_BRICK:0)
Block(-1,39,-2,SMOOTH_BRICK:0)
Block(-1,39,-1,CONCRETE:0)
Block(-1,39,5,CONCRETE:0)
Block(-1,39,6,SMOOTH_BRICK:0)
Block(-1,40,-2,IRON_FENCE)
Block(-1,40,-1,SMOOTH_BRICK:0)
Block(-1,40,5,SMOOTH_BRICK:0)
Block(-1,40,6,IRON_FENCE)
Block(-1,41,-1,CONCRETE:0)
Block(-1,41,5,CONCRETE:0)
Block(-1,42,-1,CONCRETE:7)
Block(-1,42,5,CONCRETE:7)
Block(-1,44,-1,SMOOTH_BRICK:0)
Block(-1,44,5,SMOOTH_BRICK:0)
Block(-1,45,-1,CONCRETE:0)
Block(-1,45,5,CONCRETE:0)
Block(-1,46,-1,CONCRETE:7)
Block(-1,46,5,CONCRETE:7)
Block(-1,48,-1,SMOOTH_BRICK:0)
Block(-1,48,5,SMOOTH_BRICK:0)
Block(-1,49,-1,CONCRETE:0)
Block(-1,49,0,CONCRETE:0)
Block(-1,49,1,CONCRETE:0)
Block(-1,49,2,CONCRETE:0)
Block(-1,49,3,CONCRETE:0)
Block(-1,49,4,CONCRETE:0)
Block(-1,49,5,CONCRETE:0)
Block(-1,50,-1,CONCRETE:7)
Block(-1,50,0,CONCRETE:7)
Block(-1,50,1,SMOOTH_BRICK:0)
Block(-1,50,2,SMOOTH_BRICK:0)
Block(-1,50,3,SMOOTH_BRICK:0)
Block(-1,50,4,CONCRETE:7)
Block(-1,50,5,CONCRETE:7)
Block(-1,51,0,CONCRETE:7)
Block(-1,51,1,SMOOTH_STAIRS:7)
Block(-1,51,3,SMOOTH_STAIRS:6)
Block(-1,51,4,CONCRETE:7)
Block(-1,52,0,CONCRETE:7)
Block(-1,52,2,CONCRETE:7)
Block(-1,52,4,CONCRETE:7)
Block(-1,53,0,CONCRETE:7)
Block(-1,53,1,SMOOTH_STAIRS:3)
Block(-1,53,3,SMOOTH_STAIRS:2)
Block(-1,53,4,CONCRETE:7)
Block(-1,54,0,CONCRETE:7)
Block(-1,54,1,SMOOTH_STAIRS:7)
Block(-1,54,3,SMOOTH_STAIRS:6)
Block(-1,54,4,CONCRETE:7)
Block(-1,55,0,CONCRETE:7)
Block(-1,55,2,CONCRETE:7)
Block(-1,55,4,CONCRETE:7)
Block(-1,56,0,CONCRETE:7)
Block(-1,56,1,SMOOTH_STAIRS:3)
Block(-1,56,3,SMOOTH_STAIRS:2)
Block(-1,56,4,CONCRETE:7)
Block(-1,57,0,CONCRETE:7)
Block(-1,57,1,SMOOTH_STAIRS:7)
Block(-1,57,3,SMOOTH_STAIRS:6)
Block(-1,57,4,CONCRETE:7)
Block(-1,58,0,CONCRETE:7)
Block(-1,58,2,CONCRETE:7)
Block(-1,58,4,CONCRETE:7)
Block(-1,59,0,CONCRETE:7)
Block(-1,59,1,SMOOTH_STAIRS:3)
Block(-1,59,3,SMOOTH_STAIRS:2)
Block(-1,59,4,CONCRETE:7)
Block(-1,60,0,IRON_FENCE)
Block(-1,60,4,IRON_FENCE)
Block(-1,61,0,IRON_FENCE)
Block(-1,61,4,IRON_FENCE)
Block(0,0,0,CONCRETE:0)
Block(0,0,4,CONCRETE:0)
Block(0,1,0,CONCRETE:0)
Block(0,1,4,CONCRETE:0)
Block(0,2,0,CONCRETE:0)
Block(0,2,4,CONCRETE:0)
Block(0,3,0,CONCRETE:0)
Block(0,3,4,CONCRETE:0)
Block(0,4,0,CONCRETE:0)
Block(0,4,1,CONCRETE:0)
Block(0,4,2,CONCRETE:0)
Block(0,4,3,CONCRETE:0)
Block(0,4,4,CONCRETE:0)
Block(0,5,0,CONCRETE:0)
Block(0,5,1,CONCRETE:0)
Block(0,5,2,CONCRETE:0)
Block(0,5,3,CONCRETE:0)
Block(0,5,4,CONCRETE:0)
Block(0,6,-4,CONCRETE:0)
Block(0,6,0,CONCRETE:0)
Block(0,6,1,CONCRETE:0)
Block(0,6,2,CONCRETE:0)
Block(0,6,3,CONCRETE:0)
Block(0,6,4,CONCRETE:0)
Block(0,6,8,CONCRETE:0)
Block(0,7,1,IRON_FENCE)
Block(0,7,2,IRON_FENCE)
Block(0,7,3,IRON_FENCE)
Block(0,8,1,IRON_FENCE)
Block(0,8,2,IRON_FENCE)
Block(0,8,3,IRON_FENCE)
Block(0,9,1,IRON_FENCE)
Block(0,9,2,IRON_FENCE)
Block(0,9,3,IRON_FENCE)
Block(0,9,4,IRON_FENCE)
Block(0,10,1,IRON_FENCE)
Block(0,10,2,IRON_FENCE)
Block(0,10,3,IRON_FENCE)
Block(0,10,4,IRON_FENCE)
Block(0,11,1,IRON_FENCE)
Block(0,11,2,IRON_FENCE)
Block(0,11,3,IRON_FENCE)
Block(0,11,4,IRON_FENCE)
Block(0,12,-4,SMOOTH_BRICK:0)
Block(0,12,1,IRON_FENCE)
Block(0,12,2,IRON_FENCE)
Block(0,12,3,IRON_FENCE)
Block(0,12,4,IRON_FENCE)
Block(0,12,8,SMOOTH_BRICK:0)
Block(0,13,-4,CONCRETE:0)
Block(0,13,1,IRON_FENCE)
Block(0,13,2,IRON_FENCE)
Block(0,13,3,IRON_FENCE)
Block(0,13,4,IRON_FENCE)
Block(0,13,8,CONCRETE:0)
Block(0,14,-4,IRON_FENCE)
Block(0,14,1,IRON_FENCE)
Block(0,14,2,IRON_FENCE)
Block(0,14,3,IRON_FENCE)
Block(0,14,4,IRON_FENCE)
Block(0,14,8,IRON_FENCE)
Block(0,15,-4,CONCRETE:0)
Block(0,15,1,IRON_FENCE)
Block(0,15,2,IRON_FENCE)
Block(0,15,3,IRON_FENCE)
Block(0,15,4,IRON_FENCE)
Block(0,15,8,CONCRETE:0)
Block(0,16,-4,CONCRETE:7)
Block(0,16,1,IRON_FENCE)
Block(0,16,2,IRON_FENCE)
Block(0,16,3,IRON_FENCE)
Block(0,16,4,IRON_FENCE)
Block(0,16,8,CONCRETE:7)
Block(0,17,1,IRON_FENCE)
Block(0,17,2,IRON_FENCE)
Block(0,17,3,IRON_FENCE)
Block(0,17,4,IRON_FENCE)
Block(0,18,-3,IRON_FENCE)
Block(0,18,1,IRON_FENCE)
Block(0,18,2,IRON_FENCE)
Block(0,18,3,IRON_FENCE)
Block(0,18,4,IRON_FENCE)
Block(0,18,7,IRON_FENCE)
Block(0,19,-3,CONCRETE:0)
Block(0,19,1,IRON_FENCE)
Block(0,19,2,IRON_FENCE)
Block(0,19,3,IRON_FENCE)
Block(0,19,4,IRON_FENCE)
Block(0,19,7,CONCRETE:0)
Block(0,20,-3,IRON_FENCE)
Block(0,20,1,IRON_FENCE)
Block(0,20,2,IRON_FENCE)
Block(0,20,3,IRON_FENCE)
Block(0,20,4,IRON_FENCE)
Block(0,20,7,IRON_FENCE)
Block(0,21,1,IRON_FENCE)
Block(0,21,2,IRON_FENCE)
Block(0,21,3,IRON_FENCE)
Block(0,21,4,IRON_FENCE)
Block(0,22,1,IRON_FENCE)
Block(0,22,2,IRON_FENCE)
Block(0,22,3,IRON_FENCE)
Block(0,22,4,IRON_FENCE)
Block(0,23,-3,SMOOTH_BRICK:0)
Block(0,23,1,IRON_FENCE)
Block(0,23,2,IRON_FENCE)
Block(0,23,3,IRON_FENCE)
Block(0,23,4,IRON_FENCE)
Block(0,23,7,SMOOTH_BRICK:0)
Block(0,24,-3,CONCRETE:0)
Block(0,24,1,IRON_FENCE)
Block(0,24,2,IRON_FENCE)
Block(0,24,3,IRON_FENCE)
Block(0,24,4,IRON_FENCE)
Block(0,24,7,CONCRETE:0)
Block(0,25,-3,CONCRETE:7)
Block(0,25,-2,CONCRETE:0)
Block(0,25,1,IRON_FENCE)
Block(0,25,2,IRON_FENCE)
Block(0,25,3,IRON_FENCE)
Block(0,25,4,IRON_FENCE)
Block(0,25,6,CONCRETE:0)
Block(0,25,7,CONCRETE:7)
Block(0,26,-2,IRON_FENCE)
Block(0,26,1,IRON_FENCE)
Block(0,26,2,IRON_FENCE)
Block(0,26,3,IRON_FENCE)
Block(0,26,4,IRON_FENCE)
Block(0,26,6,IRON_FENCE)
Block(0,27,-3,SMOOTH_BRICK:0)
Block(0,27,1,IRON_FENCE)
Block(0,27,2,IRON_FENCE)
Block(0,27,3,IRON_FENCE)
Block(0,27,4,IRON_FENCE)
Block(0,27,7,SMOOTH_BRICK:0)
Block(0,28,-3,SMOOTH_BRICK:0)
Block(0,28,1,IRON_FENCE)
Block(0,28,2,IRON_FENCE)
Block(0,28,3,IRON_FENCE)
Block(0,28,4,IRON_FENCE)
Block(0,28,7,SMOOTH_BRICK:0)
Block(0,29,1,IRON_FENCE)
Block(0,29,2,IRON_FENCE)
Block(0,29,3,IRON_FENCE)
Block(0,29,4,IRON_FENCE)
Block(0,30,-3,SMOOTH_BRICK:0)
Block(0,30,1,IRON_FENCE)
Block(0,30,2,IRON_FENCE)
Block(0,30,3,IRON_FENCE)
Block(0,30,4,IRON_FENCE)
Block(0,30,7,SMOOTH_BRICK:0)
Block(0,31,-3,IRON_FENCE)
Block(0,31,1,IRON_FENCE)
Block(0,31,2,IRON_FENCE)
Block(0,31,3,IRON_FENCE)
Block(0,31,4,IRON_FENCE)
Block(0,31,7,IRON_FENCE)
Block(0,32,-2,CONCRETE:7)
Block(0,32,1,IRON_FENCE)
Block(0,32,2,IRON_FENCE)
Block(0,32,3,IRON_FENCE)
Block(0,32,4,IRON_FENCE)
Block(0,32,6,CONCRETE:7)
Block(0,33,-2,SMOOTH_BRICK:0)
Block(0,33,1,IRON_FENCE)
Block(0,33,2,IRON_FENCE)
Block(0,33,3,IRON_FENCE)
Block(0,33,4,IRON_FENCE)
Block(0,33,6,SMOOTH_BRICK:0)
Block(0,34,1,IRON_FENCE)
Block(0,34,2,IRON_FENCE)
Block(0,34,3,IRON_FENCE)
Block(0,34,4,IRON_FENCE)
Block(0,35,-2,CONCRETE:7)
Block(0,35,1,IRON_FENCE)
Block(0,35,2,IRON_FENCE)
Block(0,35,3,IRON_FENCE)
Block(0,35,4,IRON_FENCE)
Block(0,35,6,CONCRETE:7)
Block(0,36,1,IRON_FENCE)
Block(0,36,2,IRON_FENCE)
Block(0,36,3,IRON_FENCE)
Block(0,36,4,IRON_FENCE)
Block(0,37,-2,CONCRETE:7)
Block(0,37,1,IRON_FENCE)
Block(0,37,2,IRON_FENCE)
Block(0,37,3,IRON_FENCE)
Block(0,37,4,IRON_FENCE)
Block(0,37,6,CONCRETE:7)
Block(0,38,-2,CONCRETE:7)
Block(0,38,1,IRON_FENCE)
Block(0,38,2,IRON_FENCE)
Block(0,38,3,IRON_FENCE)
Block(0,38,4,IRON_FENCE)
Block(0,38,6,CONCRETE:7)
Block(0,39,-2,SMOOTH_BRICK:0)
Block(0,39,-1,CONCRETE:0)
Block(0,39,1,IRON_FENCE)
Block(0,39,2,IRON_FENCE)
Block(0,39,3,IRON_FENCE)
Block(0,39,4,IRON_FENCE)
Block(0,39,5,CONCRETE:0)
Block(0,39,6,SMOOTH_BRICK:0)
Block(0,40,-2,IRON_FENCE)
Block(0,40,-1,IRON_FENCE)
Block(0,40,1,IRON_FENCE)
Block(0,40,2,IRON_FENCE)
Block(0,40,3,IRON_FENCE)
Block(0,40,4,IRON_FENCE)
Block(0,40,5,IRON_FENCE)
Block(0,40,6,IRON_FENCE)
Block(0,41,-1,SMOOTH_BRICK:0)
Block(0,41,1,IRON_FENCE)
Block(0,41,2,IRON_FENCE)
Block(0,41,3,IRON_FENCE)
Block(0,41,4,IRON_FENCE)
Block(0,41,5,SMOOTH_BRICK:0)
Block(0,42,-1,CONCRETE:0)
Block(0,42,1,IRON_FENCE)
Block(0,42,2,IRON_FENCE)
Block(0,42,3,IRON_FENCE)
Block(0,42,4,IRON_FENCE)
Block(0,42,5,CONCRETE:0)
Block(0,43,-1,IRON_FENCE)
Block(0,43,1,IRON_FENCE)
Block(0,43,2,IRON_FENCE)
Block(0,43,3,IRON_FENCE)
Block(0,43,4,IRON_FENCE)
Block(0,43,5,IRON_FENCE)
Block(0,44,-1,CONCRETE:0)
Block(0,44,1,IRON_FENCE)
Block(0,44,2,IRON_FENCE)
Block(0,44,3,IRON_FENCE)
Block(0,44,4,IRON_FENCE)
Block(0,44,5,CONCRETE:0)
Block(0,45,-1,IRON_FENCE)
Block(0,45,1,IRON_FENCE)
Block(0,45,2,IRON_FENCE)
Block(0,45,3,IRON_FENCE)
Block(0,45,4,IRON_FENCE)
Block(0,45,5,IRON_FENCE)
Block(0,46,-1,CONCRETE:0)
Block(0,46,1,IRON_FENCE)
Block(0,46,2,IRON_FENCE)
Block(0,46,3,IRON_FENCE)
Block(0,46,4,IRON_FENCE)
Block(0,46,5,CONCRETE:0)
Block(0,47,-1,IRON_FENCE)
Block(0,47,1,IRON_FENCE)
Block(0,47,2,IRON_FENCE)
Block(0,47,3,IRON_FENCE)
Block(0,47,4,IRON_FENCE)
Block(0,47,5,IRON_FENCE)
Block(0,48,-1,CONCRETE:0)
Block(0,48,1,IRON_FENCE)
Block(0,48,2,IRON_FENCE)
Block(0,48,3,IRON_FENCE)
Block(0,48,4,IRON_FENCE)
Block(0,48,5,CONCRETE:0)
Block(0,49,-1,CONCRETE:7)
Block(0,49,0,CONCRETE:0)
Block(0,49,1,IRON_FENCE)
Block(0,49,2,IRON_FENCE)
Block(0,49,3,IRON_FENCE)
Block(0,49,4,CONCRETE:0)
Block(0,49,5,CONCRETE:7)
Block(0,50,0,SMOOTH_BRICK:0)
Block(0,50,1,IRON_TRAPDOOR:9)
Block(0,50,2,IRON_TRAPDOOR:9)
Block(0,50,3,IRON_TRAPDOOR:9)
Block(0,50,4,SMOOTH_BRICK:0)
Block(0,51,0,SMOOTH_STAIRS:5)
Block(0,51,4,SMOOTH_STAIRS:5)
Block(0,53,0,SMOOTH_STAIRS:1)
Block(0,53,4,SMOOTH_STAIRS:1)
Block(0,54,0,SMOOTH_STAIRS:5)
Block(0,54,4,SMOOTH_STAIRS:5)
Block(0,56,0,SMOOTH_STAIRS:1)
Block(0,56,4,SMOOTH_STAIRS:1)
Block(0,57,0,SMOOTH_STAIRS:5)
Block(0,57,4,SMOOTH_STAIRS:5)
Block(0,59,0,SMOOTH_STAIRS:1)
Block(0,59,1,SMOOTH_BRICK:0)
Block(0,59,2,SMOOTH_BRICK:0)
Block(0,59,3,SMOOTH_BRICK:0)
Block(0,59,4,SMOOTH_STAIRS:1)
Block(0,60,1,CONCRETE:7)
Block(0,60,2,dregorarl_srpmanhunt:encounter_marker:13)
Block(0,60,3,CONCRETE:7)
Block(0,61,1,CONCRETE:7)
Block(0,61,2,SMOOTH_STAIRS:6)
Block(0,61,3,CONCRETE:7)
Block(0,62,1,CONCRETE:7)
Block(0,62,2,SMOOTH_STAIRS:7)
Block(0,62,3,CONCRETE:7)
Block(0,63,1,CONCRETE:7)
Block(0,63,2,SMOOTH_STAIRS:6)
Block(0,63,3,CONCRETE:7)
Block(0,64,1,CONCRETE:0)
Block(0,64,3,CONCRETE:0)
Block(0,65,1,CONCRETE:0)
Block(0,65,2,CONCRETE:0)
Block(0,65,3,CONCRETE:0)
Block(0,66,1,CONCRETE:0)
Block(0,66,3,CONCRETE:0)
Block(0,67,1,CONCRETE:0)
Block(0,67,2,CONCRETE:0)
Block(0,67,3,CONCRETE:0)
Block(0,68,1,CONCRETE:7)
Block(0,68,2,SMOOTH_STAIRS:0)
Block(0,68,3,CONCRETE:7)
Block(0,69,1,IRON_FENCE)
Block(0,69,2,IRON_FENCE)
Block(0,70,2,IRON_FENCE)
Block(0,70,3,IRON_FENCE)
Block(0,71,1,IRON_FENCE)
Block(0,71,2,IRON_FENCE)
Block(0,72,2,IRON_FENCE)
Block(0,72,3,IRON_FENCE)
Block(0,73,2,IRON_FENCE)
Block(0,74,1,IRON_FENCE)
Block(0,74,2,IRON_FENCE)
Block(0,75,2,IRON_FENCE)
Block(0,75,3,IRON_FENCE)
Block(0,76,2,IRON_FENCE)
Block(0,77,2,IRON_FENCE)
Block(0,78,2,IRON_FENCE)
Block(0,79,2,IRON_FENCE)
Block(1,4,0,CONCRETE:0)
Block(1,4,1,CONCRETE:0)
Block(1,4,2,CONCRETE:0)
Block(1,4,3,CONCRETE:0)
Block(1,4,4,CONCRETE:0)
Block(1,5,0,CONCRETE:0)
Block(1,5,1,CONCRETE:0)
Block(1,5,2,CONCRETE:0)
Block(1,5,3,CONCRETE:0)
Block(1,5,4,CONCRETE:0)
Block(1,6,-4,CONCRETE:0)
Block(1,6,0,CONCRETE:0)
Block(1,6,1,CONCRETE:0)
Block(1,6,2,CONCRETE:7)
Block(1,6,3,CONCRETE:0)
Block(1,6,4,CONCRETE:0)
Block(1,6,8,CONCRETE:0)
Block(1,7,1,IRON_FENCE)
Block(1,7,2,CONCRETE:7)
Block(1,8,1,IRON_FENCE)
Block(1,8,2,CONCRETE:7)
Block(1,8,3,quark:iron_ladder:3)
Block(1,9,1,IRON_FENCE)
Block(1,9,2,CONCRETE:7)
Block(1,9,3,quark:iron_ladder:3)
Block(1,9,4,IRON_FENCE)
Block(1,10,1,IRON_FENCE)
Block(1,10,2,CONCRETE:7)
Block(1,10,3,quark:iron_ladder:3)
Block(1,10,4,IRON_FENCE)
Block(1,11,1,IRON_FENCE)
Block(1,11,2,CONCRETE:7)
Block(1,11,3,quark:iron_ladder:3)
Block(1,11,4,IRON_FENCE)
Block(1,12,1,IRON_FENCE)
Block(1,12,2,CONCRETE:7)
Block(1,12,3,quark:iron_ladder:3)
Block(1,12,4,IRON_FENCE)
Block(1,13,-4,SMOOTH_BRICK:0)
Block(1,13,1,IRON_FENCE)
Block(1,13,2,CONCRETE:7)
Block(1,13,3,quark:iron_ladder:3)
Block(1,13,4,IRON_FENCE)
Block(1,13,8,SMOOTH_BRICK:0)
Block(1,14,-4,CONCRETE:0)
Block(1,14,1,IRON_FENCE)
Block(1,14,2,CONCRETE:7)
Block(1,14,3,quark:iron_ladder:3)
Block(1,14,4,IRON_FENCE)
Block(1,14,8,CONCRETE:0)
Block(1,15,-4,CONCRETE:7)
Block(1,15,1,IRON_FENCE)
Block(1,15,2,CONCRETE:7)
Block(1,15,3,quark:iron_ladder:3)
Block(1,15,4,IRON_FENCE)
Block(1,15,8,CONCRETE:7)
Block(1,16,1,IRON_FENCE)
Block(1,16,2,CONCRETE:7)
Block(1,16,3,quark:iron_ladder:3)
Block(1,16,4,IRON_FENCE)
Block(1,17,1,IRON_FENCE)
Block(1,17,2,CONCRETE:7)
Block(1,17,3,quark:iron_ladder:3)
Block(1,17,4,IRON_FENCE)
Block(1,18,-3,IRON_FENCE)
Block(1,18,1,IRON_FENCE)
Block(1,18,2,CONCRETE:7)
Block(1,18,3,quark:iron_ladder:3)
Block(1,18,4,IRON_FENCE)
Block(1,18,7,IRON_FENCE)
Block(1,19,-3,CONCRETE:0)
Block(1,19,1,IRON_FENCE)
Block(1,19,2,CONCRETE:7)
Block(1,19,3,quark:iron_ladder:3)
Block(1,19,4,IRON_FENCE)
Block(1,19,7,CONCRETE:0)
Block(1,20,-3,IRON_FENCE)
Block(1,20,1,IRON_FENCE)
Block(1,20,2,CONCRETE:7)
Block(1,20,3,quark:iron_ladder:3)
Block(1,20,4,IRON_FENCE)
Block(1,20,7,IRON_FENCE)
Block(1,21,1,IRON_FENCE)
Block(1,21,2,CONCRETE:7)
Block(1,21,3,quark:iron_ladder:3)
Block(1,21,4,IRON_FENCE)
Block(1,22,1,IRON_FENCE)
Block(1,22,2,CONCRETE:7)
Block(1,22,3,quark:iron_ladder:3)
Block(1,22,4,IRON_FENCE)
Block(1,23,1,IRON_FENCE)
Block(1,23,2,CONCRETE:7)
Block(1,23,3,quark:iron_ladder:3)
Block(1,23,4,IRON_FENCE)
Block(1,24,-3,SMOOTH_BRICK:0)
Block(1,24,-2,SMOOTH_BRICK:0)
Block(1,24,1,IRON_FENCE)
Block(1,24,2,CONCRETE:7)
Block(1,24,3,quark:iron_ladder:3)
Block(1,24,4,IRON_FENCE)
Block(1,24,6,SMOOTH_BRICK:0)
Block(1,24,7,SMOOTH_BRICK:0)
Block(1,25,-3,CONCRETE:0)
Block(1,25,-2,CONCRETE:0)
Block(1,25,1,IRON_FENCE)
Block(1,25,2,CONCRETE:7)
Block(1,25,3,quark:iron_ladder:3)
Block(1,25,4,IRON_FENCE)
Block(1,25,6,CONCRETE:0)
Block(1,25,7,CONCRETE:0)
Block(1,26,-3,IRON_FENCE)
Block(1,26,-2,IRON_FENCE)
Block(1,26,1,IRON_FENCE)
Block(1,26,2,CONCRETE:7)
Block(1,26,3,quark:iron_ladder:3)
Block(1,26,4,IRON_FENCE)
Block(1,26,6,IRON_FENCE)
Block(1,26,7,IRON_FENCE)
Block(1,27,1,IRON_FENCE)
Block(1,27,2,CONCRETE:7)
Block(1,27,3,quark:iron_ladder:3)
Block(1,27,4,IRON_FENCE)
Block(1,28,-3,CONCRETE:7)
Block(1,28,1,IRON_FENCE)
Block(1,28,2,CONCRETE:7)
Block(1,28,3,quark:iron_ladder:3)
Block(1,28,4,IRON_FENCE)
Block(1,28,7,CONCRETE:7)
Block(1,29,1,IRON_FENCE)
Block(1,29,2,CONCRETE:7)
Block(1,29,3,quark:iron_ladder:3)
Block(1,29,4,IRON_FENCE)
Block(1,30,-3,SMOOTH_BRICK:0)
Block(1,30,1,IRON_FENCE)
Block(1,30,2,CONCRETE:7)
Block(1,30,3,quark:iron_ladder:3)
Block(1,30,4,IRON_FENCE)
Block(1,30,7,SMOOTH_BRICK:0)
Block(1,31,-3,IRON_FENCE)
Block(1,31,1,IRON_FENCE)
Block(1,31,2,CONCRETE:7)
Block(1,31,3,quark:iron_ladder:3)
Block(1,31,4,IRON_FENCE)
Block(1,31,7,IRON_FENCE)
Block(1,32,-2,SMOOTH_BRICK:0)
Block(1,32,1,IRON_FENCE)
Block(1,32,2,CONCRETE:7)
Block(1,32,3,quark:iron_ladder:3)
Block(1,32,4,IRON_FENCE)
Block(1,32,6,SMOOTH_BRICK:0)
Block(1,33,-2,CONCRETE:7)
Block(1,33,1,IRON_FENCE)
Block(1,33,2,CONCRETE:7)
Block(1,33,3,quark:iron_ladder:3)
Block(1,33,4,IRON_FENCE)
Block(1,33,6,CONCRETE:7)
Block(1,34,1,IRON_FENCE)
Block(1,34,2,CONCRETE:7)
Block(1,34,3,quark:iron_ladder:3)
Block(1,34,4,IRON_FENCE)
Block(1,35,-2,CONCRETE:7)
Block(1,35,1,IRON_FENCE)
Block(1,35,2,CONCRETE:7)
Block(1,35,3,quark:iron_ladder:3)
Block(1,35,4,IRON_FENCE)
Block(1,35,6,CONCRETE:7)
Block(1,36,1,IRON_FENCE)
Block(1,36,2,CONCRETE:7)
Block(1,36,3,quark:iron_ladder:3)
Block(1,36,4,IRON_FENCE)
Block(1,37,-2,SMOOTH_BRICK:0)
Block(1,37,1,IRON_FENCE)
Block(1,37,2,CONCRETE:7)
Block(1,37,3,quark:iron_ladder:3)
Block(1,37,4,IRON_FENCE)
Block(1,37,6,SMOOTH_BRICK:0)
Block(1,38,1,IRON_FENCE)
Block(1,38,2,CONCRETE:7)
Block(1,38,3,quark:iron_ladder:3)
Block(1,38,4,IRON_FENCE)
Block(1,39,-2,SMOOTH_BRICK:0)
Block(1,39,-1,CONCRETE:0)
Block(1,39,1,IRON_FENCE)
Block(1,39,2,CONCRETE:7)
Block(1,39,3,quark:iron_ladder:3)
Block(1,39,4,IRON_FENCE)
Block(1,39,5,CONCRETE:0)
Block(1,39,6,SMOOTH_BRICK:0)
Block(1,40,-2,IRON_FENCE)
Block(1,40,-1,CONCRETE:7)
Block(1,40,1,IRON_FENCE)
Block(1,40,2,CONCRETE:7)
Block(1,40,3,quark:iron_ladder:3)
Block(1,40,4,IRON_FENCE)
Block(1,40,5,CONCRETE:7)
Block(1,40,6,IRON_FENCE)
Block(1,41,1,IRON_FENCE)
Block(1,41,2,CONCRETE:7)
Block(1,41,3,quark:iron_ladder:3)
Block(1,41,4,IRON_FENCE)
Block(1,42,-1,SMOOTH_BRICK:0)
Block(1,42,1,IRON_FENCE)
Block(1,42,2,CONCRETE:7)
Block(1,42,3,quark:iron_ladder:3)
Block(1,42,4,IRON_FENCE)
Block(1,42,5,SMOOTH_BRICK:0)
Block(1,43,-1,CONCRETE:0)
Block(1,43,1,IRON_FENCE)
Block(1,43,2,CONCRETE:7)
Block(1,43,3,quark:iron_ladder:3)
Block(1,43,4,IRON_FENCE)
Block(1,43,5,CONCRETE:0)
Block(1,44,-1,CONCRETE:7)
Block(1,44,1,IRON_FENCE)
Block(1,44,2,CONCRETE:7)
Block(1,44,3,quark:iron_ladder:3)
Block(1,44,4,IRON_FENCE)
Block(1,44,5,CONCRETE:7)
Block(1,45,1,IRON_FENCE)
Block(1,45,2,CONCRETE:7)
Block(1,45,3,quark:iron_ladder:3)
Block(1,45,4,IRON_FENCE)
Block(1,46,-1,SMOOTH_BRICK:0)
Block(1,46,1,IRON_FENCE)
Block(1,46,2,CONCRETE:7)
Block(1,46,3,quark:iron_ladder:3)
Block(1,46,4,IRON_FENCE)
Block(1,46,5,SMOOTH_BRICK:0)
Block(1,47,-1,CONCRETE:0)
Block(1,47,1,IRON_FENCE)
Block(1,47,2,CONCRETE:7)
Block(1,47,3,quark:iron_ladder:3)
Block(1,47,4,IRON_FENCE)
Block(1,47,5,CONCRETE:0)
Block(1,48,-1,CONCRETE:7)
Block(1,48,1,IRON_FENCE)
Block(1,48,2,CONCRETE:7)
Block(1,48,3,quark:iron_ladder:3)
Block(1,48,4,IRON_FENCE)
Block(1,48,5,CONCRETE:7)
Block(1,49,0,CONCRETE:0)
Block(1,49,1,IRON_FENCE)
Block(1,49,2,CONCRETE:7)
Block(1,49,3,quark:iron_ladder:3)
Block(1,49,4,CONCRETE:0)
Block(1,50,0,SMOOTH_BRICK:0)
Block(1,50,1,IRON_TRAPDOOR:9)
Block(1,50,2,CONCRETE:7)
Block(1,50,3,quark:iron_ladder:3)
Block(1,50,4,SMOOTH_BRICK:0)
Block(1,52,0,CONCRETE:7)
Block(1,52,4,CONCRETE:7)
Block(1,55,0,CONCRETE:7)
Block(1,55,4,CONCRETE:7)
Block(1,58,0,CONCRETE:7)
Block(1,58,4,CONCRETE:7)
Block(1,59,1,SMOOTH_BRICK:0)
Block(1,59,3,SMOOTH_BRICK:0)
Block(1,60,1,SMOOTH_STAIRS:4)
Block(1,60,3,SMOOTH_STAIRS:5)
Block(1,61,1,SMOOTH_STAIRS:5)
Block(1,61,3,SMOOTH_STAIRS:4)
Block(1,62,1,SMOOTH_STAIRS:4)
Block(1,62,3,SMOOTH_STAIRS:5)
Block(1,63,1,SMOOTH_STAIRS:5)
Block(1,63,3,SMOOTH_STAIRS:4)
Block(1,65,1,CONCRETE:0)
Block(1,65,3,CONCRETE:0)
Block(1,67,1,CONCRETE:0)
Block(1,67,3,CONCRETE:0)
Block(1,68,1,SMOOTH_STAIRS:2)
Block(1,68,2,CONCRETE:0)
Block(1,68,3,SMOOTH_STAIRS:3)
Block(1,69,1,IRON_FENCE)
Block(1,69,2,CONCRETE:0)
Block(1,69,3,IRON_FENCE)
Block(1,70,1,IRON_FENCE)
Block(1,70,2,CONCRETE:0)
Block(1,70,3,IRON_FENCE)
Block(1,71,1,IRON_FENCE)
Block(1,71,2,CONCRETE:7)
Block(1,71,3,IRON_FENCE)
Block(1,72,1,IRON_FENCE)
Block(1,72,2,CONCRETE:7)
Block(1,72,3,IRON_FENCE)
Block(1,73,1,IRON_FENCE)
Block(1,73,2,CONCRETE:7)
Block(1,73,3,IRON_FENCE)
Block(1,74,1,IRON_FENCE)
Block(1,74,2,CONCRETE:7)
Block(1,74,3,IRON_FENCE)
Block(1,75,1,IRON_FENCE)
Block(1,75,2,CONCRETE:7)
Block(1,75,3,IRON_FENCE)
Block(1,76,1,IRON_FENCE)
Block(1,76,2,CONCRETE:7)
Block(1,76,3,IRON_FENCE)
Block(1,77,1,IRON_FENCE)
Block(1,77,2,IRON_FENCE)
Block(1,77,3,IRON_FENCE)
Block(1,78,2,IRON_FENCE)
Block(1,78,3,IRON_FENCE)
Block(1,79,2,IRON_FENCE)
Block(1,79,3,IRON_FENCE)
Block(1,80,2,IRON_FENCE)
Block(1,80,3,IRON_FENCE)
Block(1,81,2,IRON_FENCE)
Block(1,82,2,IRON_FENCE)
Block(1,83,2,IRON_FENCE)
Block(1,84,2,IRON_FENCE)
Block(2,0,0,CONCRETE:0)
Block(2,0,4,CONCRETE:0)
Block(2,1,0,CONCRETE:0)
Block(2,1,4,CONCRETE:0)
Block(2,2,0,CONCRETE:0)
Block(2,2,4,CONCRETE:0)
Block(2,3,0,CONCRETE:0)
Block(2,3,4,CONCRETE:0)
Block(2,4,0,CONCRETE:0)
Block(2,4,1,CONCRETE:0)
Block(2,4,2,CONCRETE:0)
Block(2,4,3,CONCRETE:0)
Block(2,4,4,CONCRETE:0)
Block(2,5,0,CONCRETE:0)
Block(2,5,1,CONCRETE:0)
Block(2,5,2,CONCRETE:0)
Block(2,5,3,CONCRETE:0)
Block(2,5,4,CONCRETE:0)
Block(2,6,-4,CONCRETE:0)
Block(2,6,0,CONCRETE:0)
Block(2,6,1,CONCRETE:0)
Block(2,6,2,CONCRETE:0)
Block(2,6,3,CONCRETE:0)
Block(2,6,4,CONCRETE:0)
Block(2,6,8,CONCRETE:0)
Block(2,7,1,IRON_FENCE)
Block(2,7,2,IRON_FENCE)
Block(2,7,3,IRON_FENCE)
Block(2,8,1,IRON_FENCE)
Block(2,8,2,IRON_FENCE)
Block(2,8,3,IRON_FENCE)
Block(2,9,1,IRON_FENCE)
Block(2,9,2,IRON_FENCE)
Block(2,9,3,IRON_FENCE)
Block(2,9,4,IRON_FENCE)
Block(2,10,1,IRON_FENCE)
Block(2,10,2,IRON_FENCE)
Block(2,10,3,IRON_FENCE)
Block(2,10,4,IRON_FENCE)
Block(2,11,1,IRON_FENCE)
Block(2,11,2,IRON_FENCE)
Block(2,11,3,IRON_FENCE)
Block(2,11,4,IRON_FENCE)
Block(2,12,-4,SMOOTH_BRICK:0)
Block(2,12,1,IRON_FENCE)
Block(2,12,2,IRON_FENCE)
Block(2,12,3,IRON_FENCE)
Block(2,12,4,IRON_FENCE)
Block(2,12,8,SMOOTH_BRICK:0)
Block(2,13,-4,CONCRETE:0)
Block(2,13,1,IRON_FENCE)
Block(2,13,2,IRON_FENCE)
Block(2,13,3,IRON_FENCE)
Block(2,13,4,IRON_FENCE)
Block(2,13,8,CONCRETE:0)
Block(2,14,-4,IRON_FENCE)
Block(2,14,1,IRON_FENCE)
Block(2,14,2,IRON_FENCE)
Block(2,14,3,IRON_FENCE)
Block(2,14,4,IRON_FENCE)
Block(2,14,8,IRON_FENCE)
Block(2,15,-4,CONCRETE:0)
Block(2,15,1,IRON_FENCE)
Block(2,15,2,IRON_FENCE)
Block(2,15,3,IRON_FENCE)
Block(2,15,4,IRON_FENCE)
Block(2,15,8,CONCRETE:0)
Block(2,16,-4,CONCRETE:7)
Block(2,16,1,IRON_FENCE)
Block(2,16,2,IRON_FENCE)
Block(2,16,3,IRON_FENCE)
Block(2,16,4,IRON_FENCE)
Block(2,16,8,CONCRETE:7)
Block(2,17,1,IRON_FENCE)
Block(2,17,2,IRON_FENCE)
Block(2,17,3,IRON_FENCE)
Block(2,17,4,IRON_FENCE)
Block(2,18,-3,IRON_FENCE)
Block(2,18,1,IRON_FENCE)
Block(2,18,2,IRON_FENCE)
Block(2,18,3,IRON_FENCE)
Block(2,18,4,IRON_FENCE)
Block(2,18,7,IRON_FENCE)
Block(2,19,-3,CONCRETE:0)
Block(2,19,1,IRON_FENCE)
Block(2,19,2,IRON_FENCE)
Block(2,19,3,IRON_FENCE)
Block(2,19,4,IRON_FENCE)
Block(2,19,7,CONCRETE:0)
Block(2,20,-3,IRON_FENCE)
Block(2,20,1,IRON_FENCE)
Block(2,20,2,IRON_FENCE)
Block(2,20,3,IRON_FENCE)
Block(2,20,4,IRON_FENCE)
Block(2,20,7,IRON_FENCE)
Block(2,21,1,IRON_FENCE)
Block(2,21,2,IRON_FENCE)
Block(2,21,3,IRON_FENCE)
Block(2,21,4,IRON_FENCE)
Block(2,22,1,IRON_FENCE)
Block(2,22,2,IRON_FENCE)
Block(2,22,3,IRON_FENCE)
Block(2,22,4,IRON_FENCE)
Block(2,23,-3,SMOOTH_BRICK:0)
Block(2,23,1,IRON_FENCE)
Block(2,23,2,IRON_FENCE)
Block(2,23,3,IRON_FENCE)
Block(2,23,4,IRON_FENCE)
Block(2,23,7,SMOOTH_BRICK:0)
Block(2,24,-3,CONCRETE:0)
Block(2,24,1,IRON_FENCE)
Block(2,24,2,IRON_FENCE)
Block(2,24,3,IRON_FENCE)
Block(2,24,4,IRON_FENCE)
Block(2,24,7,CONCRETE:0)
Block(2,25,-3,CONCRETE:7)
Block(2,25,-2,CONCRETE:0)
Block(2,25,1,IRON_FENCE)
Block(2,25,2,IRON_FENCE)
Block(2,25,3,IRON_FENCE)
Block(2,25,4,IRON_FENCE)
Block(2,25,6,CONCRETE:0)
Block(2,25,7,CONCRETE:7)
Block(2,26,-2,IRON_FENCE)
Block(2,26,1,IRON_FENCE)
Block(2,26,2,IRON_FENCE)
Block(2,26,3,IRON_FENCE)
Block(2,26,4,IRON_FENCE)
Block(2,26,6,IRON_FENCE)
Block(2,27,-3,SMOOTH_BRICK:0)
Block(2,27,1,IRON_FENCE)
Block(2,27,2,IRON_FENCE)
Block(2,27,3,IRON_FENCE)
Block(2,27,4,IRON_FENCE)
Block(2,27,7,SMOOTH_BRICK:0)
Block(2,28,-3,SMOOTH_BRICK:0)
Block(2,28,1,IRON_FENCE)
Block(2,28,2,IRON_FENCE)
Block(2,28,3,IRON_FENCE)
Block(2,28,4,IRON_FENCE)
Block(2,28,7,SMOOTH_BRICK:0)
Block(2,29,1,IRON_FENCE)
Block(2,29,2,IRON_FENCE)
Block(2,29,3,IRON_FENCE)
Block(2,29,4,IRON_FENCE)
Block(2,30,-3,SMOOTH_BRICK:0)
Block(2,30,1,IRON_FENCE)
Block(2,30,2,IRON_FENCE)
Block(2,30,3,IRON_FENCE)
Block(2,30,4,IRON_FENCE)
Block(2,30,7,SMOOTH_BRICK:0)
Block(2,31,-3,IRON_FENCE)
Block(2,31,1,IRON_FENCE)
Block(2,31,2,IRON_FENCE)
Block(2,31,3,IRON_FENCE)
Block(2,31,4,IRON_FENCE)
Block(2,31,7,IRON_FENCE)
Block(2,32,-2,CONCRETE:7)
Block(2,32,1,IRON_FENCE)
Block(2,32,2,IRON_FENCE)
Block(2,32,3,IRON_FENCE)
Block(2,32,4,IRON_FENCE)
Block(2,32,6,CONCRETE:7)
Block(2,33,-2,SMOOTH_BRICK:0)
Block(2,33,1,IRON_FENCE)
Block(2,33,2,IRON_FENCE)
Block(2,33,3,IRON_FENCE)
Block(2,33,4,IRON_FENCE)
Block(2,33,6,SMOOTH_BRICK:0)
Block(2,34,1,IRON_FENCE)
Block(2,34,2,IRON_FENCE)
Block(2,34,3,IRON_FENCE)
Block(2,34,4,IRON_FENCE)
Block(2,35,-2,CONCRETE:7)
Block(2,35,1,IRON_FENCE)
Block(2,35,2,IRON_FENCE)
Block(2,35,3,IRON_FENCE)
Block(2,35,4,IRON_FENCE)
Block(2,35,6,CONCRETE:7)
Block(2,36,1,IRON_FENCE)
Block(2,36,2,IRON_FENCE)
Block(2,36,3,IRON_FENCE)
Block(2,36,4,IRON_FENCE)
Block(2,37,-2,CONCRETE:7)
Block(2,37,1,IRON_FENCE)
Block(2,37,2,IRON_FENCE)
Block(2,37,3,IRON_FENCE)
Block(2,37,4,IRON_FENCE)
Block(2,37,6,CONCRETE:7)
Block(2,38,-2,CONCRETE:7)
Block(2,38,1,IRON_FENCE)
Block(2,38,2,IRON_FENCE)
Block(2,38,3,IRON_FENCE)
Block(2,38,4,IRON_FENCE)
Block(2,38,6,CONCRETE:7)
Block(2,39,-2,SMOOTH_BRICK:0)
Block(2,39,-1,CONCRETE:0)
Block(2,39,1,IRON_FENCE)
Block(2,39,2,IRON_FENCE)
Block(2,39,3,IRON_FENCE)
Block(2,39,4,IRON_FENCE)
Block(2,39,5,CONCRETE:0)
Block(2,39,6,SMOOTH_BRICK:0)
Block(2,40,-2,IRON_FENCE)
Block(2,40,-1,IRON_FENCE)
Block(2,40,1,IRON_FENCE)
Block(2,40,2,IRON_FENCE)
Block(2,40,3,IRON_FENCE)
Block(2,40,4,IRON_FENCE)
Block(2,40,5,IRON_FENCE)
Block(2,40,6,IRON_FENCE)
Block(2,41,-1,SMOOTH_BRICK:0)
Block(2,41,1,IRON_FENCE)
Block(2,41,2,IRON_FENCE)
Block(2,41,3,IRON_FENCE)
Block(2,41,4,IRON_FENCE)
Block(2,41,5,SMOOTH_BRICK:0)
Block(2,42,-1,CONCRETE:0)
Block(2,42,1,IRON_FENCE)
Block(2,42,2,IRON_FENCE)
Block(2,42,3,IRON_FENCE)
Block(2,42,4,IRON_FENCE)
Block(2,42,5,CONCRETE:0)
Block(2,43,-1,IRON_FENCE)
Block(2,43,1,IRON_FENCE)
Block(2,43,2,IRON_FENCE)
Block(2,43,3,IRON_FENCE)
Block(2,43,4,IRON_FENCE)
Block(2,43,5,IRON_FENCE)
Block(2,44,-1,CONCRETE:0)
Block(2,44,1,IRON_FENCE)
Block(2,44,2,IRON_FENCE)
Block(2,44,3,IRON_FENCE)
Block(2,44,4,IRON_FENCE)
Block(2,44,5,CONCRETE:0)
Block(2,45,-1,IRON_FENCE)
Block(2,45,1,IRON_FENCE)
Block(2,45,2,IRON_FENCE)
Block(2,45,3,IRON_FENCE)
Block(2,45,4,IRON_FENCE)
Block(2,45,5,IRON_FENCE)
Block(2,46,-1,CONCRETE:0)
Block(2,46,1,IRON_FENCE)
Block(2,46,2,IRON_FENCE)
Block(2,46,3,IRON_FENCE)
Block(2,46,4,IRON_FENCE)
Block(2,46,5,CONCRETE:0)
Block(2,47,-1,IRON_FENCE)
Block(2,47,1,IRON_FENCE)
Block(2,47,2,IRON_FENCE)
Block(2,47,3,IRON_FENCE)
Block(2,47,4,IRON_FENCE)
Block(2,47,5,IRON_FENCE)
Block(2,48,-1,CONCRETE:0)
Block(2,48,1,IRON_FENCE)
Block(2,48,2,IRON_FENCE)
Block(2,48,3,IRON_FENCE)
Block(2,48,4,IRON_FENCE)
Block(2,48,5,CONCRETE:0)
Block(2,49,-1,CONCRETE:7)
Block(2,49,0,CONCRETE:0)
Block(2,49,1,IRON_FENCE)
Block(2,49,2,IRON_FENCE)
Block(2,49,3,IRON_FENCE)
Block(2,49,4,CONCRETE:0)
Block(2,49,5,CONCRETE:7)
Block(2,50,0,SMOOTH_BRICK:0)
Block(2,50,1,IRON_TRAPDOOR:10)
Block(2,50,2,IRON_TRAPDOOR:9)
Block(2,50,3,IRON_TRAPDOOR:9)
Block(2,50,4,SMOOTH_BRICK:0)
Block(2,51,0,SMOOTH_STAIRS:4)
Block(2,51,4,SMOOTH_STAIRS:4)
Block(2,53,0,SMOOTH_STAIRS:0)
Block(2,53,4,SMOOTH_STAIRS:0)
Block(2,54,0,SMOOTH_STAIRS:4)
Block(2,54,4,SMOOTH_STAIRS:4)
Block(2,56,0,SMOOTH_STAIRS:0)
Block(2,56,4,SMOOTH_STAIRS:0)
Block(2,57,0,SMOOTH_STAIRS:4)
Block(2,57,4,SMOOTH_STAIRS:4)
Block(2,59,0,SMOOTH_STAIRS:0)
Block(2,59,1,SMOOTH_BRICK:0)
Block(2,59,2,SMOOTH_BRICK:0)
Block(2,59,3,SMOOTH_BRICK:0)
Block(2,59,4,SMOOTH_STAIRS:0)
Block(2,60,1,CONCRETE:7)
Block(2,60,2,SMOOTH_STAIRS:6)
Block(2,60,3,CONCRETE:7)
Block(2,61,1,CONCRETE:7)
Block(2,61,2,SMOOTH_STAIRS:7)
Block(2,61,3,CONCRETE:7)
Block(2,62,1,CONCRETE:7)
Block(2,62,2,SMOOTH_STAIRS:6)
Block(2,62,3,CONCRETE:7)
Block(2,63,1,CONCRETE:7)
Block(2,63,2,SMOOTH_STAIRS:7)
Block(2,63,3,CONCRETE:7)
Block(2,64,1,CONCRETE:0)
Block(2,64,3,CONCRETE:0)
Block(2,65,1,CONCRETE:0)
Block(2,65,2,CONCRETE:0)
Block(2,65,3,CONCRETE:0)
Block(2,66,1,CONCRETE:0)
Block(2,66,3,CONCRETE:0)
Block(2,67,1,CONCRETE:0)
Block(2,67,2,CONCRETE:0)
Block(2,67,3,CONCRETE:0)
Block(2,68,1,CONCRETE:7)
Block(2,68,2,SMOOTH_STAIRS:1)
Block(2,68,3,CONCRETE:7)
Block(2,69,2,IRON_FENCE)
Block(2,70,2,IRON_FENCE)
Block(2,71,2,IRON_FENCE)
Block(2,71,3,IRON_FENCE)
Block(2,72,1,IRON_FENCE)
Block(2,72,2,IRON_FENCE)
Block(2,73,2,IRON_FENCE)
Block(2,73,3,IRON_FENCE)
Block(2,74,2,IRON_FENCE)
Block(2,75,1,IRON_FENCE)
Block(2,75,2,IRON_FENCE)
Block(2,76,2,IRON_FENCE)
Block(2,77,2,IRON_FENCE)
Block(2,78,2,IRON_FENCE)
Block(3,6,-4,CONCRETE:0)
Block(3,6,8,CONCRETE:0)
Block(3,11,-4,SMOOTH_BRICK:0)
Block(3,11,8,SMOOTH_BRICK:0)
Block(3,12,-4,CONCRETE:0)
Block(3,12,8,CONCRETE:0)
Block(3,13,-4,CONCRETE:7)
Block(3,13,8,CONCRETE:7)
Block(3,15,-4,SMOOTH_BRICK:0)
Block(3,15,8,SMOOTH_BRICK:0)
Block(3,16,-4,CONCRETE:0)
Block(3,16,8,CONCRETE:0)
Block(3,17,-4,CONCRETE:7)
Block(3,17,8,CONCRETE:7)
Block(3,18,-3,IRON_FENCE)
Block(3,18,7,IRON_FENCE)
Block(3,19,-3,CONCRETE:0)
Block(3,19,7,CONCRETE:0)
Block(3,20,-3,IRON_FENCE)
Block(3,20,7,IRON_FENCE)
Block(3,22,-3,SMOOTH_BRICK:0)
Block(3,22,7,SMOOTH_BRICK:0)
Block(3,23,-3,CONCRETE:0)
Block(3,23,7,CONCRETE:0)
Block(3,24,-3,CONCRETE:7)
Block(3,24,-2,SMOOTH_BRICK:0)
Block(3,24,6,SMOOTH_BRICK:0)
Block(3,24,7,CONCRETE:7)
Block(3,25,-2,CONCRETE:0)
Block(3,25,6,CONCRETE:0)
Block(3,26,-2,IRON_FENCE)
Block(3,26,6,IRON_FENCE)
Block(3,27,-3,CONCRETE:7)
Block(3,27,7,CONCRETE:7)
Block(3,29,-3,CONCRETE:7)
Block(3,29,7,CONCRETE:7)
Block(3,30,-3,SMOOTH_BRICK:0)
Block(3,30,7,SMOOTH_BRICK:0)
Block(3,31,-3,IRON_FENCE)
Block(3,31,-2,SMOOTH_BRICK:0)
Block(3,31,6,SMOOTH_BRICK:0)
Block(3,31,7,IRON_FENCE)
Block(3,34,-2,CONCRETE:7)
Block(3,34,6,CONCRETE:7)
Block(3,35,-2,CONCRETE:7)
Block(3,35,6,CONCRETE:7)
Block(3,36,-2,SMOOTH_BRICK:0)
Block(3,36,6,SMOOTH_BRICK:0)
Block(3,38,-2,SMOOTH_BRICK:0)
Block(3,38,6,SMOOTH_BRICK:0)
Block(3,39,-2,SMOOTH_BRICK:0)
Block(3,39,-1,CONCRETE:0)
Block(3,39,5,CONCRETE:0)
Block(3,39,6,SMOOTH_BRICK:0)
Block(3,40,-2,IRON_FENCE)
Block(3,40,-1,SMOOTH_BRICK:0)
Block(3,40,5,SMOOTH_BRICK:0)
Block(3,40,6,IRON_FENCE)
Block(3,41,-1,CONCRETE:0)
Block(3,41,5,CONCRETE:0)
Block(3,42,-1,CONCRETE:7)
Block(3,42,5,CONCRETE:7)
Block(3,44,-1,SMOOTH_BRICK:0)
Block(3,44,5,SMOOTH_BRICK:0)
Block(3,45,-1,CONCRETE:0)
Block(3,45,5,CONCRETE:0)
Block(3,46,-1,CONCRETE:7)
Block(3,46,5,CONCRETE:7)
Block(3,48,-1,SMOOTH_BRICK:0)
Block(3,48,5,SMOOTH_BRICK:0)
Block(3,49,-1,CONCRETE:0)
Block(3,49,0,CONCRETE:0)
Block(3,49,1,CONCRETE:0)
Block(3,49,2,CONCRETE:0)
Block(3,49,3,CONCRETE:0)
Block(3,49,4,CONCRETE:0)
Block(3,49,5,CONCRETE:0)
Block(3,50,-1,CONCRETE:7)
Block(3,50,0,CONCRETE:7)
Block(3,50,1,SMOOTH_BRICK:0)
Block(3,50,2,SMOOTH_BRICK:0)
Block(3,50,3,SMOOTH_BRICK:0)
Block(3,50,4,CONCRETE:7)
Block(3,50,5,CONCRETE:7)
Block(3,51,0,CONCRETE:7)
Block(3,51,1,SMOOTH_STAIRS:7)
Block(3,51,3,SMOOTH_STAIRS:6)
Block(3,51,4,CONCRETE:7)
Block(3,52,0,CONCRETE:7)
Block(3,52,2,CONCRETE:7)
Block(3,52,4,CONCRETE:7)
Block(3,53,0,CONCRETE:7)
Block(3,53,1,SMOOTH_STAIRS:3)
Block(3,53,3,SMOOTH_STAIRS:2)
Block(3,53,4,CONCRETE:7)
Block(3,54,0,CONCRETE:7)
Block(3,54,1,SMOOTH_STAIRS:7)
Block(3,54,3,SMOOTH_STAIRS:6)
Block(3,54,4,CONCRETE:7)
Block(3,55,0,CONCRETE:7)
Block(3,55,2,CONCRETE:7)
Block(3,55,4,CONCRETE:7)
Block(3,56,0,CONCRETE:7)
Block(3,56,1,SMOOTH_STAIRS:3)
Block(3,56,3,SMOOTH_STAIRS:2)
Block(3,56,4,CONCRETE:7)
Block(3,57,0,CONCRETE:7)
Block(3,57,1,SMOOTH_STAIRS:7)
Block(3,57,3,SMOOTH_STAIRS:6)
Block(3,57,4,CONCRETE:7)
Block(3,58,0,CONCRETE:7)
Block(3,58,2,CONCRETE:7)
Block(3,58,4,CONCRETE:7)
Block(3,59,0,CONCRETE:7)
Block(3,59,1,SMOOTH_STAIRS:3)
Block(3,59,3,SMOOTH_STAIRS:2)
Block(3,59,4,CONCRETE:7)
Block(3,60,0,IRON_FENCE)
Block(3,60,4,IRON_FENCE)
Block(3,61,0,IRON_FENCE)
Block(3,61,4,IRON_FENCE)
Block(4,6,-4,CONCRETE:0)
Block(4,6,8,CONCRETE:0)
Block(4,10,-4,SMOOTH_BRICK:0)
Block(4,10,8,SMOOTH_BRICK:0)
Block(4,11,-4,CONCRETE:0)
Block(4,11,8,CONCRETE:0)
Block(4,12,-4,CONCRETE:7)
Block(4,12,8,CONCRETE:7)
Block(4,16,-4,SMOOTH_BRICK:0)
Block(4,16,8,SMOOTH_BRICK:0)
Block(4,17,-4,CONCRETE:0)
Block(4,17,8,CONCRETE:0)
Block(4,18,-4,CONCRETE:7)
Block(4,18,-3,IRON_FENCE)
Block(4,18,7,IRON_FENCE)
Block(4,18,8,CONCRETE:7)
Block(4,19,-3,CONCRETE:0)
Block(4,19,7,CONCRETE:0)
Block(4,20,-3,IRON_FENCE)
Block(4,20,7,IRON_FENCE)
Block(4,21,-3,SMOOTH_BRICK:0)
Block(4,21,7,SMOOTH_BRICK:0)
Block(4,22,-3,CONCRETE:0)
Block(4,22,7,CONCRETE:0)
Block(4,23,-3,CONCRETE:7)
Block(4,23,7,CONCRETE:7)
Block(4,25,-2,CONCRETE:0)
Block(4,25,6,CONCRETE:0)
Block(4,26,-3,SMOOTH_BRICK:0)
Block(4,26,-2,IRON_FENCE)
Block(4,26,6,IRON_FENCE)
Block(4,26,7,SMOOTH_BRICK:0)
Block(4,29,-3,SMOOTH_BRICK:0)
Block(4,29,7,SMOOTH_BRICK:0)
Block(4,30,-3,SMOOTH_BRICK:0)
Block(4,30,7,SMOOTH_BRICK:0)
Block(4,31,-3,IRON_FENCE)
Block(4,31,-2,CONCRETE:7)
Block(4,31,6,CONCRETE:7)
Block(4,31,7,IRON_FENCE)
Block(4,34,-2,SMOOTH_BRICK:0)
Block(4,34,6,SMOOTH_BRICK:0)
Block(4,35,-2,CONCRETE:7)
Block(4,35,6,CONCRETE:7)
Block(4,36,-2,CONCRETE:7)
Block(4,36,6,CONCRETE:7)
Block(4,39,-2,SMOOTH_BRICK:0)
Block(4,39,-1,CONCRETE:0)
Block(4,39,0,CONCRETE:0)
Block(4,39,1,CONCRETE:0)
Block(4,39,2,CONCRETE:0)
Block(4,39,3,CONCRETE:0)
Block(4,39,4,CONCRETE:0)
Block(4,39,5,CONCRETE:0)
Block(4,39,6,SMOOTH_BRICK:0)
Block(4,40,-2,SMOOTH_STAIRS:2)
Block(4,40,-1,CONCRETE:0)
Block(4,40,0,SMOOTH_BRICK:0)
Block(4,40,1,IRON_FENCE)
Block(4,40,2,CONCRETE:7)
Block(4,40,3,IRON_FENCE)
Block(4,40,4,SMOOTH_BRICK:0)
Block(4,40,5,CONCRETE:0)
Block(4,40,6,SMOOTH_STAIRS:3)
Block(4,41,-1,CONCRETE:0)
Block(4,41,0,CONCRETE:0)
Block(4,41,1,SMOOTH_BRICK:0)
Block(4,41,3,SMOOTH_BRICK:0)
Block(4,41,4,CONCRETE:0)
Block(4,41,5,CONCRETE:0)
Block(4,42,-1,CONCRETE:0)
Block(4,42,0,CONCRETE:7)
Block(4,42,1,CONCRETE:0)
Block(4,42,2,SMOOTH_BRICK:0)
Block(4,42,3,CONCRETE:0)
Block(4,42,4,CONCRETE:7)
Block(4,42,5,CONCRETE:0)
Block(4,43,-1,CONCRETE:0)
Block(4,43,1,IRON_FENCE)
Block(4,43,2,CONCRETE:0)
Block(4,43,3,IRON_FENCE)
Block(4,43,5,CONCRETE:0)
Block(4,44,-1,CONCRETE:0)
Block(4,44,0,SMOOTH_BRICK:0)
Block(4,44,1,CONCRETE:0)
Block(4,44,2,CONCRETE:7)
Block(4,44,3,CONCRETE:0)
Block(4,44,4,SMOOTH_BRICK:0)
Block(4,44,5,CONCRETE:0)
Block(4,45,-1,CONCRETE:0)
Block(4,45,0,CONCRETE:0)
Block(4,45,1,IRON_FENCE)
Block(4,45,3,IRON_FENCE)
Block(4,45,4,CONCRETE:0)
Block(4,45,5,CONCRETE:0)
Block(4,46,-1,CONCRETE:0)
Block(4,46,0,CONCRETE:7)
Block(4,46,1,CONCRETE:0)
Block(4,46,2,SMOOTH_BRICK:0)
Block(4,46,3,CONCRETE:0)
Block(4,46,4,CONCRETE:7)
Block(4,46,5,CONCRETE:0)
Block(4,47,-1,CONCRETE:0)
Block(4,47,1,IRON_FENCE)
Block(4,47,2,CONCRETE:0)
Block(4,47,3,IRON_FENCE)
Block(4,47,5,CONCRETE:0)
Block(4,48,-1,CONCRETE:0)
Block(4,48,0,SMOOTH_BRICK:0)
Block(4,48,1,CONCRETE:0)
Block(4,48,2,CONCRETE:7)
Block(4,48,3,CONCRETE:0)
Block(4,48,4,SMOOTH_BRICK:0)
Block(4,48,5,CONCRETE:0)
Block(4,49,-1,CONCRETE:0)
Block(4,49,0,CONCRETE:0)
Block(4,49,1,CONCRETE:7)
Block(4,49,3,CONCRETE:7)
Block(4,49,4,CONCRETE:0)
Block(4,49,5,CONCRETE:0)
Block(4,50,-1,IRON_FENCE)
Block(4,50,0,CONCRETE:7)
Block(4,50,4,CONCRETE:7)
Block(4,50,5,IRON_FENCE)
Block(4,51,-1,IRON_FENCE)
Block(4,51,5,IRON_FENCE)
Block(5,6,-4,CONCRETE:0)
Block(5,6,8,CONCRETE:0)
Block(5,9,-4,SMOOTH_BRICK:0)
Block(5,9,8,SMOOTH_BRICK:0)
Block(5,10,-4,CONCRETE:0)
Block(5,10,8,CONCRETE:0)
Block(5,11,-4,CONCRETE:7)
Block(5,11,8,CONCRETE:7)
Block(5,17,-4,SMOOTH_BRICK:0)
Block(5,17,8,SMOOTH_BRICK:0)
Block(5,18,-4,CONCRETE:0)
Block(5,18,-3,IRON_FENCE)
Block(5,18,7,IRON_FENCE)
Block(5,18,8,CONCRETE:0)
Block(5,19,-4,CONCRETE:7)
Block(5,19,-3,CONCRETE:0)
Block(5,19,7,CONCRETE:0)
Block(5,19,8,CONCRETE:7)
Block(5,20,-3,SMOOTH_BRICK:0)
Block(5,20,7,SMOOTH_BRICK:0)
Block(5,21,-3,CONCRETE:0)
Block(5,21,7,CONCRETE:0)
Block(5,22,-3,CONCRETE:7)
Block(5,22,7,CONCRETE:7)
Block(5,24,0,SMOOTH_BRICK:0)
Block(5,24,2,SMOOTH_BRICK:0)
Block(5,24,4,SMOOTH_BRICK:0)
Block(5,25,-2,CONCRETE:0)
Block(5,25,-1,CONCRETE:0)
Block(5,25,0,CONCRETE:0)
Block(5,25,1,CONCRETE:0)
Block(5,25,2,CONCRETE:0)
Block(5,25,3,CONCRETE:0)
Block(5,25,4,CONCRETE:0)
Block(5,25,5,CONCRETE:0)
Block(5,25,6,CONCRETE:0)
Block(5,26,-3,CONCRETE:7)
Block(5,26,-2,IRON_FENCE)
Block(5,26,-1,IRON_FENCE)
Block(5,26,0,IRON_FENCE)
Block(5,26,1,IRON_FENCE)
Block(5,26,2,IRON_FENCE)
Block(5,26,3,IRON_FENCE)
Block(5,26,4,IRON_FENCE)
Block(5,26,5,IRON_FENCE)
Block(5,26,6,IRON_FENCE)
Block(5,26,7,CONCRETE:7)
Block(5,30,-3,SMOOTH_BRICK:0)
Block(5,30,-2,SMOOTH_BRICK:0)
Block(5,30,6,SMOOTH_BRICK:0)
Block(5,30,7,SMOOTH_BRICK:0)
Block(5,31,-3,SMOOTH_STAIRS:2)
Block(5,31,-2,CONCRETE:7)
Block(5,31,-1,CONCRETE:7)
Block(5,31,0,SMOOTH_BRICK:0)
Block(5,31,4,SMOOTH_BRICK:0)
Block(5,31,5,CONCRETE:7)
Block(5,31,6,CONCRETE:7)
Block(5,31,7,SMOOTH_STAIRS:3)
Block(5,32,-2,CONCRETE:7)
Block(5,32,1,CONCRETE:7)
Block(5,32,2,SMOOTH_BRICK:0)
Block(5,32,3,CONCRETE:7)
Block(5,32,6,CONCRETE:7)
Block(5,33,-2,CONCRETE:7)
Block(5,33,1,SMOOTH_BRICK:0)
Block(5,33,2,CONCRETE:7)
Block(5,33,3,SMOOTH_BRICK:0)
Block(5,33,6,CONCRETE:7)
Block(5,34,-2,CONCRETE:7)
Block(5,34,-1,SMOOTH_BRICK:0)
Block(5,34,0,CONCRETE:7)
Block(5,34,4,CONCRETE:7)
Block(5,34,5,SMOOTH_BRICK:0)
Block(5,34,6,CONCRETE:7)
Block(5,35,-2,CONCRETE:7)
Block(5,35,-1,CONCRETE:7)
Block(5,35,0,CONCRETE:7)
Block(5,35,1,CONCRETE:7)
Block(5,35,2,CONCRETE:7)
Block(5,35,3,CONCRETE:7)
Block(5,35,4,CONCRETE:7)
Block(5,35,5,CONCRETE:7)
Block(5,35,6,CONCRETE:7)
Block(5,36,-2,CONCRETE:7)
Block(5,36,-1,CONCRETE:7)
Block(5,36,0,SMOOTH_BRICK:0)
Block(5,36,4,SMOOTH_BRICK:0)
Block(5,36,5,CONCRETE:7)
Block(5,36,6,CONCRETE:7)
Block(5,37,-2,CONCRETE:7)
Block(5,37,1,CONCRETE:7)
Block(5,37,2,SMOOTH_BRICK:0)
Block(5,37,3,CONCRETE:7)
Block(5,37,6,CONCRETE:7)
Block(5,38,-2,CONCRETE:7)
Block(5,38,0,SMOOTH_BRICK:0)
Block(5,38,1,CONCRETE:7)
Block(5,38,3,CONCRETE:7)
Block(5,38,4,SMOOTH_BRICK:0)
Block(5,38,6,CONCRETE:7)
Block(5,39,-2,CONCRETE:7)
Block(5,39,-1,SMOOTH_BRICK:0)
Block(5,39,0,SMOOTH_BRICK:0)
Block(5,39,1,SMOOTH_BRICK:0)
Block(5,39,2,SMOOTH_BRICK:0)
Block(5,39,3,SMOOTH_BRICK:0)
Block(5,39,4,SMOOTH_BRICK:0)
Block(5,39,5,SMOOTH_BRICK:0)
Block(5,39,6,CONCRETE:7)
Block(5,40,-2,IRON_FENCE)
Block(5,40,-1,SMOOTH_STAIRS:1)
Block(5,40,0,IRON_FENCE)
Block(5,40,1,IRON_FENCE)
Block(5,40,2,IRON_FENCE)
Block(5,40,3,IRON_FENCE)
Block(5,40,4,IRON_FENCE)
Block(5,40,5,SMOOTH_STAIRS:1)
Block(5,40,6,IRON_FENCE)
Block(5,41,-2,IRON_FENCE)
Block(5,41,6,IRON_FENCE)
Block(6,0,-5,CONCRETE:0)
Block(6,0,-4,CONCRETE:0)
Block(6,0,-3,CONCRETE:0)
Block(6,0,7,CONCRETE:0)
Block(6,0,8,CONCRETE:0)
Block(6,0,9,CONCRETE:0)
Block(6,1,-5,CONCRETE:0)
Block(6,1,-4,CONCRETE:0)
Block(6,1,-3,CONCRETE:0)
Block(6,1,7,CONCRETE:0)
Block(6,1,8,CONCRETE:0)
Block(6,1,9,CONCRETE:0)
Block(6,2,-5,CONCRETE:0)
Block(6,2,-4,CONCRETE:0)
Block(6,2,-3,CONCRETE:0)
Block(6,2,7,CONCRETE:0)
Block(6,2,8,CONCRETE:0)
Block(6,2,9,CONCRETE:0)
Block(6,3,-5,CONCRETE:0)
Block(6,3,-4,CONCRETE:0)
Block(6,3,-3,CONCRETE:0)
Block(6,3,7,CONCRETE:0)
Block(6,3,8,CONCRETE:0)
Block(6,3,9,CONCRETE:0)
Block(6,4,-5,CONCRETE:0)
Block(6,4,-4,CONCRETE:0)
Block(6,4,-3,CONCRETE:0)
Block(6,4,7,CONCRETE:0)
Block(6,4,8,CONCRETE:0)
Block(6,4,9,CONCRETE:0)
Block(6,5,-5,CONCRETE:0)
Block(6,5,-4,SMOOTH_STAIRS:0)
Block(6,5,-3,CONCRETE:0)
Block(6,5,7,CONCRETE:0)
Block(6,5,8,SMOOTH_STAIRS:0)
Block(6,5,9,CONCRETE:0)
Block(6,6,-4,CONCRETE:0)
Block(6,6,8,CONCRETE:0)
Block(6,8,-4,SMOOTH_BRICK:0)
Block(6,8,8,SMOOTH_BRICK:0)
Block(6,9,-4,CONCRETE:0)
Block(6,9,8,CONCRETE:0)
Block(6,10,-4,CONCRETE:7)
Block(6,10,8,CONCRETE:7)
Block(6,18,-4,SMOOTH_BRICK:0)
Block(6,18,-3,IRON_FENCE)
Block(6,18,-2,IRON_FENCE)
Block(6,18,-1,IRON_FENCE)
Block(6,18,0,IRON_FENCE)
Block(6,18,1,IRON_FENCE)
Block(6,18,2,IRON_FENCE)
Block(6,18,3,IRON_FENCE)
Block(6,18,4,IRON_FENCE)
Block(6,18,5,IRON_FENCE)
Block(6,18,6,IRON_FENCE)
Block(6,18,7,IRON_FENCE)
Block(6,18,8,SMOOTH_BRICK:0)
Block(6,19,-4,CONCRETE:0)
Block(6,19,-3,CONCRETE:0)
Block(6,19,-2,CONCRETE:0)
Block(6,19,-1,CONCRETE:0)
Block(6,19,0,CONCRETE:0)
Block(6,19,1,CONCRETE:0)
Block(6,19,2,CONCRETE:0)
Block(6,19,3,CONCRETE:0)
Block(6,19,4,CONCRETE:0)
Block(6,19,5,CONCRETE:0)
Block(6,19,6,CONCRETE:0)
Block(6,19,7,CONCRETE:0)
Block(6,19,8,CONCRETE:0)
Block(6,20,-4,CONCRETE:7)
Block(6,20,-3,CONCRETE:0)
Block(6,20,-2,SMOOTH_BRICK:0)
Block(6,20,-1,IRON_FENCE)
Block(6,20,0,IRON_FENCE)
Block(6,20,1,IRON_FENCE)
Block(6,20,2,IRON_FENCE)
Block(6,20,3,IRON_FENCE)
Block(6,20,4,IRON_FENCE)
Block(6,20,5,IRON_FENCE)
Block(6,20,6,SMOOTH_BRICK:0)
Block(6,20,7,CONCRETE:0)
Block(6,20,8,CONCRETE:7)
Block(6,21,-3,CONCRETE:0)
Block(6,21,-2,CONCRETE:0)
Block(6,21,-1,SMOOTH_BRICK:0)
Block(6,21,5,SMOOTH_BRICK:0)
Block(6,21,6,CONCRETE:0)
Block(6,21,7,CONCRETE:0)
Block(6,22,-3,CONCRETE:0)
Block(6,22,-2,CONCRETE:7)
Block(6,22,-1,CONCRETE:0)
Block(6,22,0,SMOOTH_BRICK:0)
Block(6,22,4,SMOOTH_BRICK:0)
Block(6,22,5,CONCRETE:0)
Block(6,22,6,CONCRETE:7)
Block(6,22,7,CONCRETE:0)
Block(6,23,-3,CONCRETE:0)
Block(6,23,-1,CONCRETE:7)
Block(6,23,0,CONCRETE:0)
Block(6,23,1,SMOOTH_BRICK:0)
Block(6,23,3,SMOOTH_BRICK:0)
Block(6,23,4,CONCRETE:0)
Block(6,23,5,CONCRETE:7)
Block(6,23,7,CONCRETE:0)
Block(6,24,-3,CONCRETE:0)
Block(6,24,0,CONCRETE:7)
Block(6,24,1,CONCRETE:0)
Block(6,24,2,SMOOTH_BRICK:0)
Block(6,24,3,CONCRETE:0)
Block(6,24,4,CONCRETE:7)
Block(6,24,7,CONCRETE:0)
Block(6,25,-3,CONCRETE:0)
Block(6,25,1,CONCRETE:7)
Block(6,25,2,CONCRETE:0)
Block(6,25,3,CONCRETE:7)
Block(6,25,7,CONCRETE:0)
Block(6,26,-3,CONCRETE:7)
Block(6,26,-2,CONCRETE:7)
Block(6,26,-1,SMOOTH_BRICK:0)
Block(6,26,2,IRON_FENCE)
Block(6,26,5,SMOOTH_BRICK:0)
Block(6,26,6,CONCRETE:7)
Block(6,26,7,CONCRETE:7)
Block(6,27,-3,CONCRETE:7)
Block(6,27,0,CONCRETE:7)
Block(6,27,1,SMOOTH_BRICK:0)
Block(6,27,3,SMOOTH_BRICK:0)
Block(6,27,4,CONCRETE:7)
Block(6,27,7,CONCRETE:7)
Block(6,28,-3,CONCRETE:7)
Block(6,28,1,SMOOTH_BRICK:0)
Block(6,28,2,CONCRETE:7)
Block(6,28,3,SMOOTH_BRICK:0)
Block(6,28,7,CONCRETE:7)
Block(6,29,-3,CONCRETE:7)
Block(6,29,-1,SMOOTH_BRICK:0)
Block(6,29,0,CONCRETE:7)
Block(6,29,4,CONCRETE:7)
Block(6,29,5,SMOOTH_BRICK:0)
Block(6,29,7,CONCRETE:7)
Block(6,30,-3,CONCRETE:7)
Block(6,30,-2,SMOOTH_BRICK:0)
Block(6,30,-1,SMOOTH_BRICK:0)
Block(6,30,0,SMOOTH_BRICK:0)
Block(6,30,1,SMOOTH_BRICK:0)
Block(6,30,2,SMOOTH_BRICK:0)
Block(6,30,3,SMOOTH_BRICK:0)
Block(6,30,4,SMOOTH_BRICK:0)
Block(6,30,5,SMOOTH_BRICK:0)
Block(6,30,6,SMOOTH_BRICK:0)
Block(6,30,7,CONCRETE:7)
Block(6,31,-3,IRON_FENCE)
Block(6,31,-2,SMOOTH_STAIRS:1)
Block(6,31,-1,IRON_FENCE)
Block(6,31,0,IRON_FENCE)
Block(6,31,1,IRON_FENCE)
Block(6,31,2,IRON_FENCE)
Block(6,31,3,IRON_FENCE)
Block(6,31,4,IRON_FENCE)
Block(6,31,5,IRON_FENCE)
Block(6,31,6,SMOOTH_STAIRS:1)
Block(6,31,7,IRON_FENCE)
Block(6,32,-3,IRON_FENCE)
Block(6,32,7,IRON_FENCE)
Block(6,33,-3,IRON_FENCE)
Block(6,33,7,IRON_FENCE)
Block(7,0,-5,CONCRETE:0)
Block(7,0,-4,CONCRETE:0)
Block(7,0,-3,CONCRETE:0)
Block(7,0,7,CONCRETE:0)
Block(7,0,8,CONCRETE:0)
Block(7,0,9,CONCRETE:0)
Block(7,1,-5,CONCRETE:0)
Block(7,1,-4,CONCRETE:0)
Block(7,1,-3,CONCRETE:0)
Block(7,1,7,CONCRETE:0)
Block(7,1,8,CONCRETE:0)
Block(7,1,9,CONCRETE:0)
Block(7,2,-5,CONCRETE:0)
Block(7,2,-4,CONCRETE:0)
Block(7,2,-3,CONCRETE:0)
Block(7,2,7,CONCRETE:0)
Block(7,2,8,CONCRETE:0)
Block(7,2,9,CONCRETE:0)
Block(7,3,-5,CONCRETE:0)
Block(7,3,-4,CONCRETE:0)
Block(7,3,-3,CONCRETE:0)
Block(7,3,7,CONCRETE:0)
Block(7,3,8,CONCRETE:0)
Block(7,3,9,CONCRETE:0)
Block(7,4,-5,CONCRETE:0)
Block(7,4,-4,CONCRETE:0)
Block(7,4,-3,CONCRETE:0)
Block(7,4,7,CONCRETE:0)
Block(7,4,8,CONCRETE:0)
Block(7,4,9,CONCRETE:0)
Block(7,5,-5,SMOOTH_STAIRS:2)
Block(7,5,-4,CONCRETE:0)
Block(7,5,-3,SMOOTH_STAIRS:3)
Block(7,5,7,SMOOTH_STAIRS:2)
Block(7,5,8,CONCRETE:0)
Block(7,5,9,SMOOTH_STAIRS:3)
Block(7,6,-4,CONCRETE:0)
Block(7,6,-3,CONCRETE:0)
Block(7,6,-2,CONCRETE:0)
Block(7,6,-1,CONCRETE:0)
Block(7,6,0,CONCRETE:0)
Block(7,6,1,CONCRETE:0)
Block(7,6,2,CONCRETE:0)
Block(7,6,3,CONCRETE:0)
Block(7,6,4,CONCRETE:0)
Block(7,6,5,CONCRETE:0)
Block(7,6,6,CONCRETE:0)
Block(7,6,7,CONCRETE:0)
Block(7,6,8,CONCRETE:0)
Block(7,7,-4,CONCRETE:0)
Block(7,7,8,CONCRETE:0)
Block(7,8,-4,CONCRETE:0)
Block(7,8,-3,SMOOTH_BRICK:0)
Block(7,8,7,SMOOTH_BRICK:0)
Block(7,8,8,CONCRETE:0)
Block(7,9,-4,CONCRETE:0)
Block(7,9,-3,CONCRETE:0)
Block(7,9,-2,SMOOTH_BRICK:0)
Block(7,9,6,SMOOTH_BRICK:0)
Block(7,9,7,CONCRETE:0)
Block(7,9,8,CONCRETE:0)
Block(7,10,-4,CONCRETE:0)
Block(7,10,-3,CONCRETE:7)
Block(7,10,-2,CONCRETE:0)
Block(7,10,-1,SMOOTH_BRICK:0)
Block(7,10,5,SMOOTH_BRICK:0)
Block(7,10,6,CONCRETE:0)
Block(7,10,7,CONCRETE:7)
Block(7,10,8,CONCRETE:0)
Block(7,11,-4,CONCRETE:0)
Block(7,11,-2,CONCRETE:7)
Block(7,11,-1,CONCRETE:0)
Block(7,11,0,SMOOTH_BRICK:0)
Block(7,11,4,SMOOTH_BRICK:0)
Block(7,11,5,CONCRETE:0)
Block(7,11,6,CONCRETE:7)
Block(7,11,8,CONCRETE:0)
Block(7,12,-4,CONCRETE:0)
Block(7,12,-1,CONCRETE:7)
Block(7,12,0,CONCRETE:0)
Block(7,12,1,SMOOTH_BRICK:0)
Block(7,12,3,SMOOTH_BRICK:0)
Block(7,12,4,CONCRETE:0)
Block(7,12,5,CONCRETE:7)
Block(7,12,8,CONCRETE:0)
Block(7,13,-4,CONCRETE:0)
Block(7,13,0,CONCRETE:7)
Block(7,13,1,CONCRETE:0)
Block(7,13,2,SMOOTH_BRICK:0)
Block(7,13,3,CONCRETE:0)
Block(7,13,4,CONCRETE:7)
Block(7,13,8,CONCRETE:0)
Block(7,14,-4,CONCRETE:0)
Block(7,14,1,IRON_FENCE)
Block(7,14,2,CONCRETE:0)
Block(7,14,3,IRON_FENCE)
Block(7,14,8,CONCRETE:0)
Block(7,15,-4,CONCRETE:0)
Block(7,15,0,SMOOTH_BRICK:0)
Block(7,15,1,CONCRETE:0)
Block(7,15,2,CONCRETE:7)
Block(7,15,3,CONCRETE:0)
Block(7,15,4,SMOOTH_BRICK:0)
Block(7,15,8,CONCRETE:0)
Block(7,16,-4,CONCRETE:0)
Block(7,16,-1,SMOOTH_BRICK:0)
Block(7,16,0,CONCRETE:0)
Block(7,16,1,CONCRETE:7)
Block(7,16,3,CONCRETE:7)
Block(7,16,4,CONCRETE:0)
Block(7,16,5,SMOOTH_BRICK:0)
Block(7,16,8,CONCRETE:0)
Block(7,17,-4,CONCRETE:0)
Block(7,17,-2,SMOOTH_BRICK:0)
Block(7,17,-1,CONCRETE:0)
Block(7,17,0,CONCRETE:7)
Block(7,17,4,CONCRETE:7)
Block(7,17,5,CONCRETE:0)
Block(7,17,6,SMOOTH_BRICK:0)
Block(7,17,8,CONCRETE:0)
Block(7,18,-4,CONCRETE:0)
Block(7,18,-3,SMOOTH_BRICK:0)
Block(7,18,-2,CONCRETE:0)
Block(7,18,-1,CONCRETE:7)
Block(7,18,5,CONCRETE:7)
Block(7,18,6,CONCRETE:0)
Block(7,18,7,SMOOTH_BRICK:0)
Block(7,18,8,CONCRETE:0)
Block(7,19,-4,CONCRETE:0)
Block(7,19,-3,CONCRETE:0)
Block(7,19,-2,CONCRETE:7)
Block(7,19,6,CONCRETE:7)
Block(7,19,7,CONCRETE:0)
Block(7,19,8,CONCRETE:0)
Block(7,20,-4,CONCRETE:0)
Block(7,20,-3,CONCRETE:7)
Block(7,20,7,CONCRETE:7)
Block(7,20,8,CONCRETE:0)
Block(7,21,-4,IRON_FENCE)
Block(7,21,8,IRON_FENCE)
Block(7,22,-4,IRON_FENCE)
Block(7,22,8,IRON_FENCE)
Block(7,23,-4,IRON_FENCE)
Block(7,23,8,IRON_FENCE)
Block(8,0,-5,CONCRETE:0)
Block(8,0,-4,CONCRETE:0)
Block(8,0,-3,CONCRETE:0)
Block(8,0,7,CONCRETE:0)
Block(8,0,8,CONCRETE:0)
Block(8,0,9,CONCRETE:0)
Block(8,1,-5,CONCRETE:0)
Block(8,1,-4,CONCRETE:0)
Block(8,1,-3,CONCRETE:0)
Block(8,1,7,CONCRETE:0)
Block(8,1,8,CONCRETE:0)
Block(8,1,9,CONCRETE:0)
Block(8,2,-5,CONCRETE:0)
Block(8,2,-4,CONCRETE:0)
Block(8,2,-3,CONCRETE:0)
Block(8,2,7,CONCRETE:0)
Block(8,2,8,CONCRETE:0)
Block(8,2,9,CONCRETE:0)
Block(8,3,-5,CONCRETE:0)
Block(8,3,-4,CONCRETE:0)
Block(8,3,-3,CONCRETE:0)
Block(8,3,7,CONCRETE:0)
Block(8,3,8,CONCRETE:0)
Block(8,3,9,CONCRETE:0)
Block(8,4,-5,CONCRETE:0)
Block(8,4,-4,CONCRETE:0)
Block(8,4,-3,CONCRETE:0)
Block(8,4,7,CONCRETE:0)
Block(8,4,8,CONCRETE:0)
Block(8,4,9,CONCRETE:0)
Block(8,5,-5,CONCRETE:0)
Block(8,5,-4,SMOOTH_STAIRS:1)
Block(8,5,-3,CONCRETE:0)
Block(8,5,7,CONCRETE:0)
Block(8,5,8,SMOOTH_STAIRS:1)
Block(8,5,9,CONCRETE:0)

#######################################################################
# +-----------------------------------------------------------------+ #
# |                             Branches                            | #
# +-----------------------------------------------------------------+ #
#######################################################################

# Branches are child-BO4's that spawn if this BO4 is configured to spawn as a
# CustomStructure resource in a biome config. Branches can have branches,
# making complex structures possible. See the wiki for more details.

# Regular Branches spawn each branch with an independent chance of spawning.
# Branch(x,y,z,isRequiredBranch,branchName,rotation,chance,branchDepth[,anotherBranchName,rotation,chance,branchDepth[,...]][IndividualChance])
# branchName - name of the object to spawn.
# rotation - NORTH, SOUTH, EAST or WEST.
# IndividualChance - The chance each branch has to spawn, assumed to be 100 when left blank
# isRequiredBranch - If this is set to true then at least one of the branches in this BO4 must spawn at these x,y,z coordinates. If no branch can spawn there then this BO4 fails to spawn and its branch is rolled back.
# isRequiredBranch:true branches must spawn or the current branch is rolled back entirely. This is useful for grouping BO4's that must spawn together, for instance a single room made of multiple BO4's/branches.
# If all parts of the room are connected together via isRequiredBranch:true branches then either the entire room will spawns or no part of it will spawn.
# *Note: When isRequiredBranch:true only one BO4 can be added per Branch() and it will automatically have a rarity of 100.0.
# isRequiredBranch:false branches are used to make optional parts of structures, for instance the middle section of a tunnel that has a beginning, middle and end BO4/branch and can have a variable length by repeating the middle BO4/branch.
# By making the start and end branches isRequiredBranch:true and the middle branch isRequiredbranch:false you can make it so that either:
# A. A tunnel spawns with at least a beginning and end branch
# B. A tunnel spawns with a beginning and end branch and as many middle branches as will fit in the available space.
# C. No tunnel spawns at all because there wasn't enough space to spawn at least a beginning and end branch.
# branchDepth - When creating a chain of branches that contains optional (isRequiredBranch:false) branches branch depth is configured for the first BO4 in the chain to determine the maximum length of the chain.
# branchDepth - 1 is inherited by each isRequiredBranch:false branch in the chain. When branchDepth is zero isRequiredBranch:false branches cannot spawn and the chain ends. In the case of the tunnel this means the last middle branch would be
# rolled back and an IsRequiredBranch:true end branch could be spawned in its place to make sure the tunnel has a proper ending.
# Instead of inheriting branchDepth - 1 from the parent branchDepth can be overridden by child branches if it is set higher than 0 (the default value).
# isRequiredBranch:true branches do inherit branchDepth and pass it on to their own branches, however they cannot be prevented from spawning by it and also don't subtract 1 from branchDepth when inheriting it.

# Weighted Branches spawn branches with a dependent chance of spawning.
# WeightedBranch(x,y,z,isRequiredBranch,branchName,rotation,chance,branchDepth[,anotherBranchName,rotation,chance,branchDepth[,...]][MaxChanceOutOf])
# *Note: isRequiredBranch must be set to false. It is not possible to use isRequiredBranch:true with WeightedBranch() since isRequired:true branches must spawn and automatically have a rarity of 100.0.
# MaxChanceOutOf - The chance all branches have to spawn out of, assumed to be 100 when left blank

#######################################################################
# +-----------------------------------------------------------------+ #
# |                             Entities                            | #
# +-----------------------------------------------------------------+ #
#######################################################################

# Forge only (this may have changed, check for updates).
# An EntityFunction spawns an entity instead of a block. The entity is spawned only once when the BO4 is spawned.
# Entities are persistent by default so they don't de-spawn when no player is near, they are only unloaded.
# Usage: Entity(x,y,z,entityName,groupSize,NameTagOrNBTFileName) or Entity(x,y,z,mobName,groupSize)
# Use /otg entities to get a list of entities that can be used as entityName, this includes entities added by other mods and non-living entities.
# NameTagOrNBTFileName can be either a nametag for the mob or an .txt file with nbt data (such as myentityinfo.txt).
# In the text file you can use the same mob spawning parameters used with the /summon command to equip the
# entity and give it custom attributes etc. You can copy the DATA part of a summon command including surrounding 
# curly braces to a .txt file, for instance for: "/summon Skeleton x y z {DATA}"

#######################################################################
# +-----------------------------------------------------------------+ #
# |                            Particles                            | #
# +-----------------------------------------------------------------+ #
#######################################################################

# Forge only (this may have changed, check for updates).
# Creates an invisible particle spawner at the given location that spawns particles every x milliseconds.
# Usage: Particle(x,y,z,particleName,interval,velocityX,velocityY,velocityZ)
# velocityX, velocityY and velocityZ are optional.
# Only vanilla particle names can be used, for 1.11.2 these are;
# explode, largeexplode, hugeexplosion, fireworksSpark, bubble, splash, wake, suspended
# depthsuspend, crit, magicCrit, smoke, largesmoke, spell, instantSpell, mobSpell
# mobSpellAmbient, witchMagic, dripWater, dripLava, angryVillager, happyVillager
# townaura, note, portal, enchantmenttable, flame, lava, footstep, cloud, reddust
# snowballpoof,  snowshovel, slime, heart, barrier, iconcrack, blockcrack, blockdust
# droplet, take, mobappearance, dragonbreath, endRod, damageIndicator, sweepAttack
# fallingdust, totem, spit.
# Use /otg particles (forge only) to show a list of particles.
# velocityX,velocityY,velocityZ - Spawn the enemy with the given velocity. If this is not filled in then a small random velocity is applied.

#######################################################################
# +-----------------------------------------------------------------+ #
# |                             Spawners                            | #
# +-----------------------------------------------------------------+ #
#######################################################################

# Forge only (this may have changed, check for updates).
# Creates an invisible entity spawner at the given location that spawns entities every x seconds.
# Entities can only spawn if their spawn requirements are met (zombies/skeletons only spawn in the dark etc). Max entity count for the server is ignored, each spawner has its own maxCount setting.
# Usage: Spawner(x,y,z,entityName,nbtFileName,groupSize,interval,spawnChance,maxCount,despawnTime,velocityX,velocityY,velocityZ,yaw,pitch)
# nbtFileName, despawnTime, velocityX, velocityY, velocityZ, yaw and pitch are optional
# Example Spawner(0, 0, 0, Villager, 1, 5, 100, 5) or Spawner(0, 0, 0, Villager, villager1.txt, 1, 5, 100, 5) or Spawner(0, 0, 0, Villager, 1, 5, 100, 5, 30, 1, 1, 1, 0, 0)
# entityName - Name of the entity to spawn, use /otg entities to get a list of entities that can be used as entityName, this includes entities added by other mods and non-living entities.
# nbtFileName - A .txt file with nbt data (such as myentityinfo.txt).
# In the text file you can use the same mob spawning parameters used with the /summon command to equip the
# entity and give it custom attributes etc. You can copy the DATA part of a summon command including surrounding 
# curly braces to a .txt file, for instance for: "/summon Skeleton x y z {DATA}"
# groupSize - Number of entities that should spawn for each successful spawn attempt.
# interval - Time in seconds between each spawn attempt.
# spawnChance - For each spawn attempt, the chance between 0-100 that the spawn attempt will succeed.
# maxCount - The maximum amount of this kind of entity that can exist within 32 blocks. If there are already maxCount or more entities of this type in a 32 radius this spawner will not spawn anything.
# despawnTime - After despawnTime seconds, if there is no player within 32 blocks of the entity it will despawn..
# velocityX,velocityY,velocityZ,yaw,pitch - Spawn the enemy with the given velocity and angle, handy for making traps and launchers (shooting arrows and fireballs etc).

#######################################################################
# +-----------------------------------------------------------------+ #
# |                             ModData                             | #
# +-----------------------------------------------------------------+ #
#######################################################################

# Forge only.
# Use the ModData() tag to include data that other mods can use
# Mod makers can use ModData and the /otg GetModData command to test IMC communications between OTG
# and their mod.
# Normal users can use it to spawn some mobs and blocks on command.
# ModData(x,y,z,"ModName", "MyModDataAsText"
# Example: ModData(x,y,z,MyCystomNPCMod,SpawnBobHere/WithAPotato/And50Health)
# Try not to use exotic/reserved characters, like brackets and comma's etc, this stuff isn't fool-proof.
# Also, use this only to store IDs/object names etc for your mod, DO NOT include things like character dialogue,
# messages on signs, loot lists etc in this file. As much as possible just store id's/names here and store all the data related to those id's/names in your own mod.
# OTG has some built in ModData commands for basic mob and block spawning.
# These are mostly just a demonstration for mod makers to show how ModData.
# can be used by other mods.
# For mob spawning in OTG use: ModData(x,y,z,OTG,mob/MobType/Count/Persistent/Name)
# mob: Makes OTG recognise this as a mob spawning command.
# MobType: Lower-case, no spaces. Any vanilla mob like dragon, skeleton, wither, villager etc
# Count: The number of mobs to spawn
# Persistent (true/false): Should the mobs never de-spawn? If set to true the mob will get a
# name-tag ingame so you can recognise it.
# Name: A name-tag for the monster/npc.
# Example: ModData(0,0,0,OTG,villager/1/true/Bob)
# To spawn blocks using ModData use: ModData(x,y,z,OTG,block/material)
# block: Makes OTG recognise this as a block spawning command.
# material: id or text, custom blocks can be added using ModName:MaterialName.
# To send all ModData within a radius in chunks around the player to the specified mod
# use this console command: /otg GetModData ModName Radius
# ModName: name of the mod, for OTG commands use OTG 
# Radius (optional): Radius in chunks around the player.
