
#######################################################################
# +-----------------------------------------------------------------+ #
# |                            BO4 object                           | #
# +-----------------------------------------------------------------+ #
#######################################################################

Author: NLBlackEagle

Description: No description given

SettingsMode: WriteWithoutComments


#######################################################################
# +-----------------------------------------------------------------+ #
# |                          Main settings                          | #
# +-----------------------------------------------------------------+ #
#######################################################################

FixedRotation: 

Frequency: 0

SpawnHeight: highestBlock

UseCenterForHighestBlock: true

##############################
# Height Limits for the BO4. #
##############################

MinHeight: 0

MaxHeight: 255

InheritBO3: 

InheritBO3Rotation: NORTH

OverrideChildSettings: true

OverrideParentHeight: false

CanOverride: false

BranchFrequency: 0

BranchFrequencyGroup: 

MustBeBelowOther: false

MustBeInside: 

CannotBeInside: 

ReplacesBO3: 

MustBeInsideWorldBorders: true

CanSpawnOnWater: true

SpawnOnWaterOnly: false

SpawnUnderWater: false

SpawnAtWaterLevel: false

HeightOffset: 0

RemoveAir: false

ReplaceAbove: 

ReplaceBelow: 

ReplaceWithBiomeBlocks: true

ReplaceWithSurfaceBlock: GRASS

ReplaceWithGroundBlock: DIRT

ReplaceWithStoneBlock: STONE

SmoothRadius: 0

SmoothHeightOffset: 0

SmoothStartTop: false

SmoothStartWood: false

SmoothingSurfaceBlock: 

SmoothingGroundBlock: 

BO3Group: 

IsSpawnPoint: false

DoReplaceBlocks: true


#######################################################################
# +-----------------------------------------------------------------+ #
# |                              Blocks                             | #
# +-----------------------------------------------------------------+ #
#######################################################################

Block(-7,0,-1,CONCRETE)
Block(-7,0,0,CONCRETE)
Block(-7,0,1,CONCRETE)
Block(-7,0,2,CONCRETE)
Block(-7,0,3,CONCRETE)
Block(-7,0,4,CONCRETE)
Block(-7,0,9,CONCRETE)
Block(-7,1,-1,CONCRETE)
Block(-7,1,0,CONCRETE)
Block(-7,1,1,CONCRETE)
Block(-7,1,2,CONCRETE)
Block(-7,1,3,CONCRETE)
Block(-7,1,4,CONCRETE)
Block(-7,1,9,CONCRETE)
Block(-7,2,-1,CONCRETE)
Block(-7,2,0,CONCRETE)
Block(-7,2,1,CONCRETE)
Block(-7,2,2,CONCRETE)
Block(-7,2,3,CONCRETE)
Block(-7,2,4,CONCRETE)
Block(-7,2,9,CONCRETE)
Block(-7,3,-1,CONCRETE)
Block(-7,3,0,CONCRETE)
Block(-7,3,1,CONCRETE)
Block(-7,3,2,CONCRETE)
Block(-7,3,3,CONCRETE)
Block(-7,3,4,CONCRETE)
Block(-7,3,9,CONCRETE)
Block(-7,4,-1,CONCRETE)
Block(-7,4,0,CONCRETE)
Block(-7,4,1,CONCRETE)
Block(-7,4,2,CONCRETE)
Block(-7,4,3,CONCRETE)
Block(-7,4,4,CONCRETE)
Block(-7,4,9,CONCRETE)
Block(-7,5,-1,CONCRETE)
Block(-7,5,0,CONCRETE)
Block(-7,5,1,CONCRETE)
Block(-7,5,2,CONCRETE)
Block(-7,5,3,CONCRETE)
Block(-7,5,4,CONCRETE)
Block(-7,5,9,CONCRETE)
Block(-7,6,-1,CONCRETE)
Block(-7,6,0,CONCRETE)
Block(-7,6,1,CONCRETE)
Block(-7,6,2,CONCRETE)
Block(-7,6,3,CONCRETE)
Block(-7,6,4,CONCRETE)
Block(-7,6,9,CONCRETE)
Block(-7,7,-1,CONCRETE)
Block(-7,7,0,CONCRETE)
Block(-7,7,1,CONCRETE)
Block(-7,7,2,CONCRETE)
Block(-7,7,3,CONCRETE)
Block(-7,7,4,CONCRETE)
Block(-7,7,9,CONCRETE)
Block(-7,8,-1,CONCRETE)
Block(-7,8,0,CONCRETE)
Block(-7,8,1,CONCRETE)
Block(-7,8,2,CONCRETE)
Block(-7,8,3,CONCRETE)
Block(-7,8,4,CONCRETE)
Block(-7,8,9,CONCRETE)
Block(-7,9,-1,CONCRETE)
Block(-7,9,0,CONCRETE)
Block(-7,9,1,CONCRETE)
Block(-7,9,2,CONCRETE)
Block(-7,9,3,CONCRETE)
Block(-7,9,4,CONCRETE)
Block(-7,9,9,CONCRETE)
Block(-7,10,-1,CONCRETE)
Block(-7,10,0,CONCRETE)
Block(-7,10,1,CONCRETE)
Block(-7,10,2,CONCRETE)
Block(-7,10,3,CONCRETE)
Block(-7,10,4,CONCRETE)
Block(-7,10,9,CONCRETE)
Block(-7,11,-1,CONCRETE)
Block(-7,11,0,CONCRETE)
Block(-7,11,1,CONCRETE)
Block(-7,11,2,CONCRETE)
Block(-7,11,3,CONCRETE)
Block(-7,11,4,CONCRETE)
Block(-7,11,9,CONCRETE)
Block(-7,12,-1,CONCRETE)
Block(-7,12,0,CONCRETE)
Block(-7,12,1,CONCRETE)
Block(-7,12,2,CONCRETE)
Block(-7,12,3,CONCRETE)
Block(-7,12,4,CONCRETE)
Block(-7,12,9,CONCRETE)
Block(-7,13,-1,CONCRETE)
Block(-7,13,0,CONCRETE)
Block(-7,13,1,CONCRETE)
Block(-7,13,2,CONCRETE)
Block(-7,13,3,CONCRETE)
Block(-7,13,4,CONCRETE)
Block(-7,13,9,CONCRETE)
Block(-7,14,-1,CONCRETE)
Block(-7,14,0,CONCRETE)
Block(-7,14,1,CONCRETE)
Block(-7,14,2,CONCRETE)
Block(-7,14,3,CONCRETE)
Block(-7,14,4,CONCRETE)
Block(-7,14,9,CONCRETE)
Block(-7,15,-1,CONCRETE)
Block(-7,15,0,CONCRETE)
Block(-7,15,1,CONCRETE)
Block(-7,15,2,CONCRETE)
Block(-7,15,3,CONCRETE)
Block(-7,15,4,CONCRETE)
Block(-7,15,9,CONCRETE)
Block(-7,16,-1,CONCRETE)
Block(-7,16,0,CONCRETE)
Block(-7,16,1,CONCRETE)
Block(-7,16,2,CONCRETE)
Block(-7,16,3,CONCRETE)
Block(-7,16,4,CONCRETE)
Block(-7,16,9,CONCRETE)
Block(-7,17,-1,CONCRETE)
Block(-7,17,0,CONCRETE)
Block(-7,17,1,CONCRETE)
Block(-7,17,2,CONCRETE)
Block(-7,17,3,CONCRETE)
Block(-7,17,4,CONCRETE)
Block(-7,17,9,CONCRETE)
Block(-7,18,-1,CONCRETE)
Block(-7,18,0,CONCRETE)
Block(-7,18,1,CONCRETE)
Block(-7,18,2,CONCRETE)
Block(-7,18,3,CONCRETE)
Block(-7,18,4,CONCRETE)
Block(-7,18,9,CONCRETE)
Block(-7,19,-1,CONCRETE)
Block(-7,19,0,CONCRETE)
Block(-7,19,1,CONCRETE)
Block(-7,19,2,CONCRETE)
Block(-7,19,3,CONCRETE)
Block(-7,19,4,CONCRETE)
Block(-7,19,9,CONCRETE)
Block(-7,20,-1,CONCRETE)
Block(-7,20,0,CONCRETE)
Block(-7,20,1,CONCRETE)
Block(-7,20,2,CONCRETE)
Block(-7,20,3,CONCRETE)
Block(-7,20,4,CONCRETE)
Block(-7,20,9,CONCRETE)
Block(-7,21,-1,CONCRETE)
Block(-7,21,0,CONCRETE)
Block(-7,21,1,CONCRETE)
Block(-7,21,2,CONCRETE)
Block(-7,21,3,CONCRETE)
Block(-7,21,4,CONCRETE)
Block(-7,21,9,CONCRETE)
Block(-7,22,-1,CONCRETE)
Block(-7,22,0,CONCRETE)
Block(-7,22,1,CONCRETE)
Block(-7,22,2,CONCRETE)
Block(-7,22,3,CONCRETE)
Block(-7,22,4,CONCRETE)
Block(-7,22,9,CONCRETE)
Block(-7,23,-1,CONCRETE)
Block(-7,23,0,CONCRETE)
Block(-7,23,1,CONCRETE)
Block(-7,23,2,CONCRETE)
Block(-7,23,3,CONCRETE)
Block(-7,23,4,CONCRETE)
Block(-7,23,9,CONCRETE)
Block(-7,24,-1,CONCRETE)
Block(-7,24,0,CONCRETE)
Block(-7,24,1,CONCRETE)
Block(-7,24,2,CONCRETE)
Block(-7,24,3,CONCRETE)
Block(-7,24,4,CONCRETE)
Block(-7,24,9,CONCRETE)
Block(-7,25,-1,CONCRETE)
Block(-7,25,0,CONCRETE)
Block(-7,25,1,CONCRETE)
Block(-7,25,2,CONCRETE)
Block(-7,25,3,CONCRETE)
Block(-7,25,4,CONCRETE)
Block(-7,25,5,CONCRETE)
Block(-7,25,6,CONCRETE)
Block(-7,25,7,CONCRETE)
Block(-7,25,8,CONCRETE)
Block(-7,25,9,CONCRETE)
Block(-7,26,-1,CONCRETE)
Block(-7,26,0,CONCRETE)
Block(-7,26,1,CONCRETE)
Block(-7,26,2,CONCRETE)
Block(-7,26,3,CONCRETE)
Block(-7,26,4,CONCRETE)
Block(-7,26,5,CONCRETE)
Block(-7,26,6,CONCRETE)
Block(-7,26,7,CONCRETE)
Block(-7,26,8,CONCRETE)
Block(-7,26,9,CONCRETE)
Block(-7,27,-1,CONCRETE)
Block(-7,27,0,CONCRETE)
Block(-7,27,1,CONCRETE)
Block(-7,27,2,CONCRETE)
Block(-7,27,3,CONCRETE)
Block(-7,27,4,CONCRETE)
Block(-7,27,5,CONCRETE)
Block(-7,27,6,CONCRETE)
Block(-7,27,7,CONCRETE)
Block(-7,27,8,CONCRETE)
Block(-7,27,9,CONCRETE)
Block(-7,28,-1,CONCRETE)
Block(-7,28,0,CONCRETE)
Block(-7,28,1,CONCRETE)
Block(-7,28,2,CONCRETE)
Block(-7,28,3,CONCRETE)
Block(-7,28,4,CONCRETE)
Block(-7,28,5,CONCRETE)
Block(-7,28,6,CONCRETE)
Block(-7,28,7,CONCRETE)
Block(-7,28,8,CONCRETE)
Block(-7,28,9,CONCRETE)
Block(-7,29,-1,CONCRETE)
Block(-7,29,0,CONCRETE)
Block(-7,29,1,CONCRETE)
Block(-7,29,2,CONCRETE)
Block(-7,29,3,CONCRETE)
Block(-7,29,4,CONCRETE)
Block(-7,29,9,CONCRETE)
Block(-7,30,-1,CONCRETE)
Block(-7,30,0,CONCRETE)
Block(-7,30,1,CONCRETE)
Block(-7,30,2,CONCRETE)
Block(-7,30,3,CONCRETE)
Block(-7,30,4,CONCRETE)
Block(-7,30,9,CONCRETE)
Block(-7,31,-1,CONCRETE)
Block(-7,31,0,CONCRETE)
Block(-7,31,1,CONCRETE)
Block(-7,31,2,CONCRETE)
Block(-7,31,3,CONCRETE)
Block(-7,31,4,CONCRETE)
Block(-7,31,9,CONCRETE)
Block(-7,32,-1,CONCRETE)
Block(-7,32,0,CONCRETE)
Block(-7,32,1,CONCRETE)
Block(-7,32,2,CONCRETE)
Block(-7,32,3,CONCRETE)
Block(-7,32,4,CONCRETE)
Block(-7,32,9,CONCRETE)
Block(-7,33,-1,CONCRETE)
Block(-7,33,0,CONCRETE)
Block(-7,33,1,CONCRETE)
Block(-7,33,2,CONCRETE)
Block(-7,33,3,CONCRETE)
Block(-7,33,4,CONCRETE)
Block(-7,33,9,CONCRETE)
Block(-7,34,-1,CONCRETE)
Block(-7,34,0,CONCRETE)
Block(-7,34,1,CONCRETE)
Block(-7,34,2,CONCRETE)
Block(-7,34,3,CONCRETE)
Block(-7,34,4,CONCRETE)
Block(-7,34,9,CONCRETE)
Block(-7,35,-1,CONCRETE)
Block(-7,35,0,CONCRETE)
Block(-7,35,1,CONCRETE)
Block(-7,35,2,CONCRETE)
Block(-7,35,3,CONCRETE)
Block(-7,35,4,CONCRETE)
Block(-7,35,9,CONCRETE)
Block(-7,36,-1,CONCRETE)
Block(-7,36,0,CONCRETE)
Block(-7,36,1,CONCRETE)
Block(-7,36,2,CONCRETE)
Block(-7,36,3,CONCRETE)
Block(-7,36,4,CONCRETE)
Block(-7,36,9,CONCRETE)
Block(-7,37,-1,CONCRETE)
Block(-7,37,0,CONCRETE)
Block(-7,37,1,CONCRETE)
Block(-7,37,2,CONCRETE)
Block(-7,37,3,CONCRETE)
Block(-7,37,4,CONCRETE)
Block(-7,37,9,CONCRETE)
Block(-7,38,-1,CONCRETE)
Block(-7,38,0,CONCRETE)
Block(-7,38,1,CONCRETE)
Block(-7,38,2,CONCRETE)
Block(-7,38,3,CONCRETE)
Block(-7,38,4,CONCRETE)
Block(-7,38,9,CONCRETE)
Block(-7,39,-1,CONCRETE)
Block(-7,39,0,CONCRETE)
Block(-7,39,1,CONCRETE)
Block(-7,39,2,CONCRETE)
Block(-7,39,3,CONCRETE)
Block(-7,39,4,CONCRETE)
Block(-7,39,9,CONCRETE)
Block(-7,40,-1,CONCRETE)
Block(-7,40,0,CONCRETE)
Block(-7,40,1,CONCRETE)
Block(-7,40,2,CONCRETE)
Block(-7,40,3,CONCRETE)
Block(-7,40,4,CONCRETE)
Block(-7,40,9,CONCRETE)
Block(-7,41,-1,CONCRETE)
Block(-7,41,0,CONCRETE)
Block(-7,41,1,CONCRETE)
Block(-7,41,2,CONCRETE)
Block(-7,41,3,CONCRETE)
Block(-7,41,4,CONCRETE)
Block(-7,41,9,CONCRETE)
Block(-7,42,-1,CONCRETE)
Block(-7,42,0,CONCRETE)
Block(-7,42,1,CONCRETE)
Block(-7,42,2,CONCRETE)
Block(-7,42,3,CONCRETE)
Block(-7,42,4,CONCRETE)
Block(-7,42,9,CONCRETE)
Block(-7,43,-1,CONCRETE)
Block(-7,43,0,CONCRETE)
Block(-7,43,1,CONCRETE)
Block(-7,43,2,CONCRETE)
Block(-7,43,3,CONCRETE)
Block(-7,43,4,CONCRETE)
Block(-7,43,9,CONCRETE)
Block(-7,44,-1,CONCRETE)
Block(-7,44,0,CONCRETE)
Block(-7,44,1,CONCRETE)
Block(-7,44,2,CONCRETE)
Block(-7,44,3,CONCRETE)
Block(-7,44,4,CONCRETE)
Block(-7,44,9,CONCRETE)
Block(-7,45,-1,CONCRETE)
Block(-7,45,0,CONCRETE)
Block(-7,45,1,CONCRETE)
Block(-7,45,2,CONCRETE)
Block(-7,45,3,CONCRETE)
Block(-7,45,4,CONCRETE)
Block(-7,45,9,CONCRETE)
Block(-7,46,-1,CONCRETE)
Block(-7,46,0,CONCRETE)
Block(-7,46,1,CONCRETE)
Block(-7,46,2,CONCRETE)
Block(-7,46,3,CONCRETE)
Block(-7,46,4,CONCRETE)
Block(-7,46,9,CONCRETE)
Block(-7,47,-1,CONCRETE)
Block(-7,47,0,CONCRETE)
Block(-7,47,1,CONCRETE)
Block(-7,47,2,CONCRETE)
Block(-7,47,3,CONCRETE)
Block(-7,47,4,CONCRETE)
Block(-7,47,9,CONCRETE)
Block(-7,48,-1,CONCRETE)
Block(-7,48,0,CONCRETE)
Block(-7,48,1,CONCRETE)
Block(-7,48,2,CONCRETE)
Block(-7,48,3,CONCRETE)
Block(-7,48,4,CONCRETE)
Block(-7,48,9,CONCRETE)
Block(-7,49,-1,CONCRETE)
Block(-7,49,0,CONCRETE)
Block(-7,49,1,CONCRETE)
Block(-7,49,2,CONCRETE)
Block(-7,49,3,CONCRETE)
Block(-7,49,4,CONCRETE)
Block(-7,49,9,CONCRETE)
Block(-7,50,-1,CONCRETE)
Block(-7,50,0,CONCRETE)
Block(-7,50,1,CONCRETE)
Block(-7,50,2,CONCRETE)
Block(-7,50,3,CONCRETE)
Block(-7,50,4,CONCRETE)
Block(-7,50,9,CONCRETE)
Block(-7,51,-1,CONCRETE)
Block(-7,51,0,CONCRETE)
Block(-7,51,1,CONCRETE)
Block(-7,51,2,CONCRETE)
Block(-7,51,3,CONCRETE)
Block(-7,51,4,CONCRETE)
Block(-7,51,9,CONCRETE)
Block(-7,52,-1,CONCRETE)
Block(-7,52,0,CONCRETE)
Block(-7,52,1,CONCRETE)
Block(-7,52,2,CONCRETE)
Block(-7,52,3,CONCRETE)
Block(-7,52,4,CONCRETE)
Block(-7,52,9,CONCRETE)
Block(-7,53,-1,CONCRETE)
Block(-7,53,0,CONCRETE)
Block(-7,53,1,CONCRETE)
Block(-7,53,2,CONCRETE)
Block(-7,53,3,CONCRETE)
Block(-7,53,4,CONCRETE)
Block(-7,53,9,CONCRETE)
Block(-7,54,-1,CONCRETE)
Block(-7,54,0,CONCRETE)
Block(-7,54,1,CONCRETE)
Block(-7,54,2,CONCRETE)
Block(-7,54,3,CONCRETE)
Block(-7,54,4,CONCRETE)
Block(-7,54,9,CONCRETE)
Block(-7,55,-6,CONCRETE)
Block(-7,55,-5,CONCRETE)
Block(-7,55,-4,CONCRETE)
Block(-7,55,-3,CONCRETE)
Block(-7,55,-2,CONCRETE)
Block(-7,55,-1,CONCRETE)
Block(-7,55,0,CONCRETE)
Block(-7,55,1,CONCRETE)
Block(-7,55,2,CONCRETE)
Block(-7,55,3,CONCRETE)
Block(-7,55,4,CONCRETE)
Block(-7,55,5,CONCRETE)
Block(-7,55,6,CONCRETE)
Block(-7,55,7,CONCRETE)
Block(-7,55,8,CONCRETE)
Block(-7,55,9,CONCRETE)
Block(-7,56,-6,CONCRETE)
Block(-7,56,-5,CONCRETE)
Block(-7,56,-4,CONCRETE)
Block(-7,56,-3,CONCRETE)
Block(-7,56,-2,CONCRETE)
Block(-7,56,-1,CONCRETE)
Block(-7,56,0,CONCRETE)
Block(-7,56,1,CONCRETE)
Block(-7,56,2,CONCRETE)
Block(-7,56,3,CONCRETE)
Block(-7,56,4,CONCRETE)
Block(-7,56,5,CONCRETE)
Block(-7,56,6,CONCRETE)
Block(-7,56,7,CONCRETE)
Block(-7,56,8,CONCRETE)
Block(-7,56,9,CONCRETE)
Block(-7,57,-6,CONCRETE)
Block(-7,57,-5,CONCRETE)
Block(-7,57,-4,CONCRETE)
Block(-7,57,-3,CONCRETE)
Block(-7,57,-2,CONCRETE)
Block(-7,57,-1,CONCRETE)
Block(-7,57,0,CONCRETE)
Block(-7,57,1,CONCRETE)
Block(-7,57,2,CONCRETE)
Block(-7,57,3,CONCRETE)
Block(-7,57,4,CONCRETE)
Block(-7,57,5,CONCRETE)
Block(-7,57,6,CONCRETE)
Block(-7,57,7,CONCRETE)
Block(-7,57,8,CONCRETE)
Block(-7,57,9,CONCRETE)
Block(-7,58,-6,CONCRETE)
Block(-7,58,-5,CONCRETE)
Block(-7,58,-4,CONCRETE)
Block(-7,58,-3,CONCRETE)
Block(-7,58,-2,CONCRETE)
Block(-7,58,-1,CONCRETE)
Block(-7,58,0,CONCRETE)
Block(-7,58,1,CONCRETE)
Block(-7,58,2,CONCRETE)
Block(-7,58,3,CONCRETE)
Block(-7,58,4,CONCRETE)
Block(-7,58,5,CONCRETE)
Block(-7,58,6,CONCRETE)
Block(-7,58,7,CONCRETE)
Block(-7,58,8,CONCRETE)
Block(-7,58,9,CONCRETE)
Block(-7,59,-6,CONCRETE)
Block(-7,59,-5,CONCRETE)
Block(-7,59,-4,CONCRETE)
Block(-7,59,-3,CONCRETE)
Block(-7,59,-2,CONCRETE)
Block(-7,59,-1,CONCRETE)
Block(-7,59,0,CONCRETE)
Block(-7,59,1,CONCRETE)
Block(-7,59,2,CONCRETE)
Block(-7,59,3,CONCRETE)
Block(-7,59,4,CONCRETE)
Block(-7,59,5,CONCRETE)
Block(-7,59,6,CONCRETE)
Block(-7,59,7,CONCRETE)
Block(-7,59,8,CONCRETE)
Block(-7,59,9,CONCRETE)
Block(-7,60,-6,CONCRETE)
Block(-7,60,-5,CONCRETE)
Block(-7,60,-4,CONCRETE)
Block(-7,60,-3,CONCRETE)
Block(-7,60,-2,CONCRETE)
Block(-7,60,-1,CONCRETE)
Block(-7,60,0,CONCRETE)
Block(-7,60,1,CONCRETE)
Block(-7,60,2,CONCRETE)
Block(-7,60,3,CONCRETE)
Block(-7,60,4,CONCRETE)
Block(-7,60,5,CONCRETE)
Block(-7,60,6,CONCRETE)
Block(-7,60,7,CONCRETE)
Block(-7,60,8,CONCRETE)
Block(-7,60,9,CONCRETE)
Block(-7,61,-6,CONCRETE)
Block(-7,61,-5,CONCRETE)
Block(-7,61,-4,CONCRETE)
Block(-7,61,7,CONCRETE)
Block(-7,61,8,CONCRETE)
Block(-7,61,9,SMOOTH_STAIRS:0)
Block(-6,0,-5,CONCRETE)
Block(-6,0,-2,CONCRETE)
Block(-6,0,-1,CONCRETE)
Block(-6,0,0,CONCRETE)
Block(-6,0,1,CONCRETE)
Block(-6,0,2,CONCRETE)
Block(-6,0,3,CONCRETE)
Block(-6,0,4,CONCRETE)
Block(-6,0,5,CONCRETE)
Block(-6,1,-5,CONCRETE)
Block(-6,1,-2,CONCRETE)
Block(-6,1,-1,CONCRETE)
Block(-6,1,0,CONCRETE)
Block(-6,1,1,CONCRETE)
Block(-6,1,2,CONCRETE)
Block(-6,1,3,CONCRETE)
Block(-6,1,4,CONCRETE)
Block(-6,1,5,CONCRETE)
Block(-6,2,-5,CONCRETE)
Block(-6,2,-2,CONCRETE)
Block(-6,2,-1,CONCRETE)
Block(-6,2,0,CONCRETE)
Block(-6,2,1,CONCRETE)
Block(-6,2,2,CONCRETE)
Block(-6,2,3,CONCRETE)
Block(-6,2,4,CONCRETE)
Block(-6,2,5,CONCRETE)
Block(-6,3,-5,CONCRETE)
Block(-6,3,-2,CONCRETE)
Block(-6,3,-1,CONCRETE)
Block(-6,3,0,CONCRETE)
Block(-6,3,1,CONCRETE)
Block(-6,3,2,CONCRETE)
Block(-6,3,3,CONCRETE)
Block(-6,3,4,CONCRETE)
Block(-6,3,5,CONCRETE)
Block(-6,4,-5,CONCRETE)
Block(-6,4,-2,CONCRETE)
Block(-6,4,-1,CONCRETE)
Block(-6,4,0,CONCRETE)
Block(-6,4,1,CONCRETE)
Block(-6,4,2,CONCRETE)
Block(-6,4,3,CONCRETE)
Block(-6,4,4,CONCRETE)
Block(-6,4,5,CONCRETE)
Block(-6,5,-5,CONCRETE)
Block(-6,5,-2,CONCRETE)
Block(-6,5,-1,CONCRETE)
Block(-6,5,0,CONCRETE)
Block(-6,5,1,CONCRETE)
Block(-6,5,2,CONCRETE)
Block(-6,5,3,CONCRETE)
Block(-6,5,4,CONCRETE)
Block(-6,5,5,CONCRETE)
Block(-6,6,-5,CONCRETE)
Block(-6,6,-2,CONCRETE)
Block(-6,6,-1,CONCRETE)
Block(-6,6,0,CONCRETE)
Block(-6,6,1,CONCRETE)
Block(-6,6,2,CONCRETE)
Block(-6,6,3,CONCRETE)
Block(-6,6,4,CONCRETE)
Block(-6,6,5,CONCRETE)
Block(-6,7,-5,CONCRETE)
Block(-6,7,-2,CONCRETE)
Block(-6,7,-1,CONCRETE)
Block(-6,7,0,CONCRETE)
Block(-6,7,1,CONCRETE)
Block(-6,7,2,CONCRETE)
Block(-6,7,3,CONCRETE)
Block(-6,7,4,CONCRETE)
Block(-6,7,5,CONCRETE)
Block(-6,7,6,CONCRETE)
Block(-6,7,7,CONCRETE)
Block(-6,7,8,CONCRETE)
Block(-6,7,9,CONCRETE)
Block(-6,8,-5,CONCRETE)
Block(-6,8,-2,CONCRETE)
Block(-6,8,-1,CONCRETE)
Block(-6,8,0,CONCRETE)
Block(-6,8,1,CONCRETE)
Block(-6,8,2,CONCRETE)
Block(-6,8,3,CONCRETE)
Block(-6,8,4,CONCRETE)
Block(-6,8,5,CONCRETE)
Block(-6,8,6,CONCRETE)
Block(-6,8,7,CONCRETE)
Block(-6,8,8,CONCRETE)
Block(-6,8,9,CONCRETE)
Block(-6,9,-5,CONCRETE)
Block(-6,9,-2,CONCRETE)
Block(-6,9,-1,CONCRETE)
Block(-6,9,0,CONCRETE)
Block(-6,9,1,CONCRETE)
Block(-6,9,2,CONCRETE)
Block(-6,9,3,CONCRETE)
Block(-6,9,4,CONCRETE)
Block(-6,9,5,CONCRETE)
Block(-6,9,6,CONCRETE)
Block(-6,9,7,CONCRETE)
Block(-6,9,8,CONCRETE)
Block(-6,9,9,CONCRETE)
Block(-6,10,-5,CONCRETE)
Block(-6,10,-2,CONCRETE)
Block(-6,10,-1,CONCRETE)
Block(-6,10,0,CONCRETE)
Block(-6,10,1,CONCRETE)
Block(-6,10,2,CONCRETE)
Block(-6,10,3,CONCRETE)
Block(-6,10,4,CONCRETE)
Block(-6,10,5,CONCRETE)
Block(-6,10,6,CONCRETE)
Block(-6,10,7,CONCRETE)
Block(-6,10,8,CONCRETE)
Block(-6,10,9,CONCRETE)
Block(-6,11,-5,CONCRETE)
Block(-6,11,-2,CONCRETE)
Block(-6,11,-1,AIR:0)
Block(-6,11,0,STONE)
Block(-6,11,1,SMOOTH_STAIRS:2)
Block(-6,11,2,CONCRETE)
Block(-6,11,3,CONCRETE)
Block(-6,11,4,CONCRETE)
Block(-6,11,5,CONCRETE)
Block(-6,11,6,CONCRETE)
Block(-6,11,7,CONCRETE)
Block(-6,11,8,CONCRETE)
Block(-6,11,9,CONCRETE)
Block(-6,12,-5,CONCRETE)
Block(-6,12,-2,CONCRETE)
Block(-6,12,-1,AIR:0)
Block(-6,12,0,AIR:0)
Block(-6,12,1,AIR:0)
Block(-6,12,2,SMOOTH_STAIRS:2)
Block(-6,12,3,CONCRETE)
Block(-6,12,4,CONCRETE)
Block(-6,12,5,CONCRETE)
Block(-6,12,6,CONCRETE)
Block(-6,12,7,CONCRETE)
Block(-6,12,8,CONCRETE)
Block(-6,12,9,CONCRETE)
Block(-6,13,-5,CONCRETE)
Block(-6,13,-2,CONCRETE)
Block(-6,13,-1,AIR:0)
Block(-6,13,0,AIR:0)
Block(-6,13,1,AIR:0)
Block(-6,13,2,AIR:0)
Block(-6,13,3,SMOOTH_STAIRS:2)
Block(-6,13,4,CONCRETE)
Block(-6,13,5,CONCRETE)
Block(-6,14,-5,CONCRETE)
Block(-6,14,-2,CONCRETE)
Block(-6,14,-1,AIR:0)
Block(-6,14,0,AIR:0)
Block(-6,14,1,AIR:0)
Block(-6,14,2,AIR:0)
Block(-6,14,3,AIR:0)
Block(-6,14,4,AIR:0)
Block(-6,14,5,CONCRETE)
Block(-6,15,-5,CONCRETE)
Block(-6,15,-2,CONCRETE)
Block(-6,15,-1,WEB:0)
Block(-6,15,0,AIR:0)
Block(-6,15,1,AIR:0)
Block(-6,15,2,AIR:0)
Block(-6,15,3,AIR:0)
Block(-6,15,4,AIR:0)
Block(-6,15,5,CONCRETE)
Block(-6,16,-5,CONCRETE)
Block(-6,16,-2,CONCRETE)
Block(-6,16,-1,CONCRETE)
Block(-6,16,0,CONCRETE)
Block(-6,16,1,CONCRETE)
Block(-6,16,2,CONCRETE)
Block(-6,16,3,CONCRETE)
Block(-6,16,4,CONCRETE)
Block(-6,16,5,CONCRETE)
Block(-6,17,-5,CONCRETE)
Block(-6,17,-2,CONCRETE)
Block(-6,17,-1,CONCRETE)
Block(-6,17,0,AIR:0)
Block(-6,17,1,SMOOTH_STAIRS:2)
Block(-6,17,2,CONCRETE)
Block(-6,17,3,CONCRETE)
Block(-6,17,4,CONCRETE)
Block(-6,17,5,CONCRETE)
Block(-6,18,-5,CONCRETE)
Block(-6,18,-2,CONCRETE)
Block(-6,18,-1,CONCRETE)
Block(-6,18,0,AIR:0)
Block(-6,18,1,AIR:0)
Block(-6,18,2,SMOOTH_STAIRS:2)
Block(-6,18,3,CONCRETE)
Block(-6,18,4,CONCRETE)
Block(-6,18,5,CONCRETE)
Block(-6,19,-5,CONCRETE)
Block(-6,19,-2,CONCRETE)
Block(-6,19,-1,CONCRETE)
Block(-6,19,0,AIR:0)
Block(-6,19,1,AIR:0)
Block(-6,19,2,AIR:0)
Block(-6,19,3,SMOOTH_STAIRS:2)
Block(-6,19,4,CONCRETE)
Block(-6,19,5,CONCRETE)
Block(-6,20,-5,CONCRETE)
Block(-6,20,-2,CONCRETE)
Block(-6,20,-1,CONCRETE)
Block(-6,20,0,AIR:0)
Block(-6,20,1,AIR:0)
Block(-6,20,2,AIR:0)
Block(-6,20,3,AIR:0)
Block(-6,20,4,LONG_GRASS)
Block(-6,20,5,CONCRETE)
Block(-6,21,-5,CONCRETE)
Block(-6,21,-2,CONCRETE)
Block(-6,21,-1,CONCRETE)
Block(-6,21,0,AIR:0)
Block(-6,21,1,AIR:0)
Block(-6,21,2,AIR:0)
Block(-6,21,3,AIR:0)
Block(-6,21,4,AIR:0)
Block(-6,21,5,CONCRETE)
Block(-6,22,-5,CONCRETE)
Block(-6,22,-2,CONCRETE)
Block(-6,22,-1,CONCRETE)
Block(-6,22,0,CONCRETE)
Block(-6,22,1,CONCRETE)
Block(-6,22,2,CONCRETE)
Block(-6,22,3,CONCRETE)
Block(-6,22,4,CONCRETE)
Block(-6,22,5,CONCRETE)
Block(-6,23,-5,CONCRETE)
Block(-6,23,-2,CONCRETE)
Block(-6,23,-1,LONG_GRASS)
Block(-6,23,0,SMOOTH_BRICK)
Block(-6,23,1,SMOOTH_STAIRS:2)
Block(-6,23,2,CONCRETE)
Block(-6,23,3,CONCRETE)
Block(-6,23,4,CONCRETE)
Block(-6,23,5,CONCRETE)
Block(-6,24,-5,CONCRETE)
Block(-6,24,-2,CONCRETE)
Block(-6,24,-1,AIR:0)
Block(-6,24,0,AIR:0)
Block(-6,24,1,AIR:0)
Block(-6,24,2,SMOOTH_STAIRS:2)
Block(-6,24,3,CONCRETE)
Block(-6,24,4,CONCRETE)
Block(-6,24,5,CONCRETE)
Block(-6,25,-5,CONCRETE)
Block(-6,25,-2,CONCRETE)
Block(-6,25,-1,AIR:0)
Block(-6,25,0,AIR:0)
Block(-6,25,1,AIR:0)
Block(-6,25,2,AIR:0)
Block(-6,25,3,SMOOTH_STAIRS:2)
Block(-6,25,4,CONCRETE)
Block(-6,25,5,CONCRETE)
Block(-6,25,6,CONCRETE)
Block(-6,25,7,CONCRETE)
Block(-6,25,8,CONCRETE)
Block(-6,25,9,CONCRETE)
Block(-6,26,-5,CONCRETE)
Block(-6,26,-2,CONCRETE)
Block(-6,26,-1,AIR:0)
Block(-6,26,0,AIR:0)
Block(-6,26,1,AIR:0)
Block(-6,26,2,AIR:0)
Block(-6,26,3,AIR:0)
Block(-6,26,4,AIR:0)
Block(-6,26,5,SMOOTH_BRICK)
Block(-6,26,6,AIR:0)
Block(-6,26,7,AIR:0)
Block(-6,26,8,AIR:0)
Block(-6,26,9,CONCRETE)
Block(-6,27,-5,CONCRETE)
Block(-6,27,-2,CONCRETE)
Block(-6,27,-1,AIR:0)
Block(-6,27,0,AIR:0)
Block(-6,27,1,AIR:0)
Block(-6,27,2,AIR:0)
Block(-6,27,3,AIR:0)
Block(-6,27,4,AIR:0)
Block(-6,27,5,AIR:0)
Block(-6,27,6,AIR:0)
Block(-6,27,7,AIR:0)
Block(-6,27,8,AIR:0)
Block(-6,27,9,CONCRETE)
Block(-6,28,-5,CONCRETE)
Block(-6,28,-2,CONCRETE)
Block(-6,28,-1,CONCRETE)
Block(-6,28,0,CONCRETE)
Block(-6,28,1,CONCRETE)
Block(-6,28,2,CONCRETE)
Block(-6,28,3,CONCRETE)
Block(-6,28,4,CONCRETE)
Block(-6,28,5,CONCRETE)
Block(-6,28,6,CONCRETE)
Block(-6,28,7,CONCRETE)
Block(-6,28,8,CONCRETE)
Block(-6,28,9,CONCRETE)
Block(-6,29,-5,CONCRETE)
Block(-6,29,-2,CONCRETE)
Block(-6,29,-1,CONCRETE)
Block(-6,29,0,STONE)
Block(-6,29,1,SMOOTH_STAIRS:2)
Block(-6,29,2,CONCRETE)
Block(-6,29,3,CONCRETE)
Block(-6,29,4,CONCRETE)
Block(-6,29,5,CONCRETE)
Block(-6,30,-5,CONCRETE)
Block(-6,30,-2,CONCRETE)
Block(-6,30,-1,CONCRETE)
Block(-6,30,0,AIR:0)
Block(-6,30,1,AIR:0)
Block(-6,30,2,SMOOTH_STAIRS:2)
Block(-6,30,3,CONCRETE)
Block(-6,30,4,CONCRETE)
Block(-6,30,5,CONCRETE)
Block(-6,31,-5,CONCRETE)
Block(-6,31,-2,CONCRETE)
Block(-6,31,-1,CONCRETE)
Block(-6,31,0,AIR:0)
Block(-6,31,1,AIR:0)
Block(-6,31,2,AIR:0)
Block(-6,31,3,SMOOTH_STAIRS:2)
Block(-6,31,4,CONCRETE)
Block(-6,31,5,CONCRETE)
Block(-6,32,-5,CONCRETE)
Block(-6,32,-2,CONCRETE)
Block(-6,32,-1,CONCRETE)
Block(-6,32,0,AIR:0)
Block(-6,32,1,AIR:0)
Block(-6,32,2,AIR:0)
Block(-6,32,3,AIR:0)
Block(-6,32,4,SMOOTH_BRICK)
Block(-6,32,5,CONCRETE)
Block(-6,33,-5,CONCRETE)
Block(-6,33,-2,CONCRETE)
Block(-6,33,-1,CONCRETE)
Block(-6,33,0,AIR:0)
Block(-6,33,1,AIR:0)
Block(-6,33,2,AIR:0)
Block(-6,33,3,AIR:0)
Block(-6,33,4,AIR:0)
Block(-6,33,5,CONCRETE)
Block(-6,34,-5,CONCRETE)
Block(-6,34,-2,CONCRETE)
Block(-6,34,-1,CONCRETE)
Block(-6,34,0,CONCRETE)
Block(-6,34,1,CONCRETE)
Block(-6,34,2,CONCRETE)
Block(-6,34,3,CONCRETE)
Block(-6,34,4,CONCRETE)
Block(-6,34,5,CONCRETE)
Block(-6,35,-5,CONCRETE)
Block(-6,35,-2,CONCRETE)
Block(-6,35,-1,LONG_GRASS)
Block(-6,35,0,AIR:0)
Block(-6,35,1,SMOOTH_STAIRS:2)
Block(-6,35,2,CONCRETE)
Block(-6,35,3,CONCRETE)
Block(-6,35,4,CONCRETE)
Block(-6,35,5,CONCRETE)
Block(-6,36,-5,CONCRETE)
Block(-6,36,-2,CONCRETE)
Block(-6,36,-1,AIR:0)
Block(-6,36,0,AIR:0)
Block(-6,36,1,AIR:0)
Block(-6,36,2,SMOOTH_STAIRS:2)
Block(-6,36,3,CONCRETE)
Block(-6,36,4,CONCRETE)
Block(-6,36,5,CONCRETE)
Block(-6,37,-5,CONCRETE)
Block(-6,37,-2,CONCRETE)
Block(-6,37,-1,AIR:0)
Block(-6,37,0,AIR:0)
Block(-6,37,1,AIR:0)
Block(-6,37,2,AIR:0)
Block(-6,37,3,SMOOTH_STAIRS:2)
Block(-6,37,4,CONCRETE)
Block(-6,37,5,CONCRETE)
Block(-6,38,-5,CONCRETE)
Block(-6,38,-2,CONCRETE)
Block(-6,38,-1,AIR:0)
Block(-6,38,0,AIR:0)
Block(-6,38,1,AIR:0)
Block(-6,38,2,AIR:0)
Block(-6,38,3,AIR:0)
Block(-6,38,4,SMOOTH_BRICK)
Block(-6,38,5,CONCRETE)
Block(-6,39,-5,CONCRETE)
Block(-6,39,-2,CONCRETE)
Block(-6,39,-1,WEB:0)
Block(-6,39,0,AIR:0)
Block(-6,39,1,AIR:0)
Block(-6,39,2,AIR:0)
Block(-6,39,3,AIR:0)
Block(-6,39,4,AIR:0)
Block(-6,39,5,CONCRETE)
Block(-6,40,-5,CONCRETE)
Block(-6,40,-2,CONCRETE)
Block(-6,40,-1,CONCRETE)
Block(-6,40,0,CONCRETE)
Block(-6,40,1,CONCRETE)
Block(-6,40,2,CONCRETE)
Block(-6,40,3,CONCRETE)
Block(-6,40,4,CONCRETE)
Block(-6,40,5,CONCRETE)
Block(-6,41,-5,CONCRETE)
Block(-6,41,-2,CONCRETE)
Block(-6,41,-1,CONCRETE)
Block(-6,41,0,LONG_GRASS)
Block(-6,41,1,SMOOTH_STAIRS:2)
Block(-6,41,2,CONCRETE)
Block(-6,41,3,CONCRETE)
Block(-6,41,4,CONCRETE)
Block(-6,41,5,CONCRETE)
Block(-6,42,-5,CONCRETE)
Block(-6,42,-2,CONCRETE)
Block(-6,42,-1,CONCRETE)
Block(-6,42,0,AIR:0)
Block(-6,42,1,AIR:0)
Block(-6,42,2,SMOOTH_STAIRS:2)
Block(-6,42,3,CONCRETE)
Block(-6,42,4,CONCRETE)
Block(-6,42,5,CONCRETE)
Block(-6,43,-5,CONCRETE)
Block(-6,43,-4,CONCRETE)
Block(-6,43,-3,CONCRETE)
Block(-6,43,-2,CONCRETE)
Block(-6,43,-1,CONCRETE)
Block(-6,43,0,AIR:0)
Block(-6,43,1,AIR:0)
Block(-6,43,2,AIR:0)
Block(-6,43,3,SMOOTH_STAIRS:2)
Block(-6,43,4,CONCRETE)
Block(-6,43,5,CONCRETE)
Block(-6,44,-5,CONCRETE)
Block(-6,44,-4,CONCRETE)
Block(-6,44,-3,CONCRETE)
Block(-6,44,-2,CONCRETE)
Block(-6,44,-1,CONCRETE)
Block(-6,44,0,AIR:0)
Block(-6,44,1,AIR:0)
Block(-6,44,2,AIR:0)
Block(-6,44,3,AIR:0)
Block(-6,44,4,STONE)
Block(-6,44,5,CONCRETE)
Block(-6,45,-5,CONCRETE)
Block(-6,45,-4,CONCRETE)
Block(-6,45,-3,CONCRETE)
Block(-6,45,-2,CONCRETE)
Block(-6,45,-1,CONCRETE)
Block(-6,45,0,AIR:0)
Block(-6,45,1,AIR:0)
Block(-6,45,2,AIR:0)
Block(-6,45,3,AIR:0)
Block(-6,45,4,AIR:0)
Block(-6,45,5,CONCRETE)
Block(-6,46,-5,CONCRETE)
Block(-6,46,-4,CONCRETE)
Block(-6,46,-3,CONCRETE)
Block(-6,46,-2,CONCRETE)
Block(-6,46,-1,CONCRETE)
Block(-6,46,0,CONCRETE)
Block(-6,46,1,CONCRETE)
Block(-6,46,2,CONCRETE)
Block(-6,46,3,CONCRETE)
Block(-6,46,4,CONCRETE)
Block(-6,46,5,CONCRETE)
Block(-6,47,-5,CONCRETE)
Block(-6,47,-4,CONCRETE)
Block(-6,47,-3,CONCRETE)
Block(-6,47,-2,CONCRETE)
Block(-6,47,-1,CONCRETE)
Block(-6,47,0,STONE)
Block(-6,47,1,SMOOTH_STAIRS:2)
Block(-6,47,2,CONCRETE)
Block(-6,47,3,CONCRETE)
Block(-6,47,4,CONCRETE)
Block(-6,47,5,CONCRETE)
Block(-6,48,-5,CONCRETE)
Block(-6,48,-4,CONCRETE)
Block(-6,48,-3,CONCRETE)
Block(-6,48,-2,CONCRETE)
Block(-6,48,-1,CONCRETE)
Block(-6,48,0,AIR:0)
Block(-6,48,1,AIR:0)
Block(-6,48,2,SMOOTH_STAIRS:2)
Block(-6,48,3,CONCRETE)
Block(-6,48,4,CONCRETE)
Block(-6,48,5,CONCRETE)
Block(-6,49,-5,CONCRETE)
Block(-6,49,-2,CONCRETE)
Block(-6,49,-1,CONCRETE)
Block(-6,49,0,AIR:0)
Block(-6,49,1,AIR:0)
Block(-6,49,2,AIR:0)
Block(-6,49,3,SMOOTH_STAIRS:2)
Block(-6,49,4,CONCRETE)
Block(-6,49,5,CONCRETE)
Block(-6,50,-5,CONCRETE)
Block(-6,50,-2,CONCRETE)
Block(-6,50,-1,CONCRETE)
Block(-6,50,0,AIR:0)
Block(-6,50,1,AIR:0)
Block(-6,50,2,AIR:0)
Block(-6,50,3,AIR:0)
Block(-6,50,4,LONG_GRASS)
Block(-6,50,5,CONCRETE)
Block(-6,51,-5,CONCRETE)
Block(-6,51,-2,CONCRETE)
Block(-6,51,-1,CONCRETE)
Block(-6,51,0,WEB:0)
Block(-6,51,1,AIR:0)
Block(-6,51,2,AIR:0)
Block(-6,51,3,AIR:0)
Block(-6,51,4,AIR:0)
Block(-6,51,5,CONCRETE)
Block(-6,52,-5,CONCRETE)
Block(-6,52,-2,CONCRETE)
Block(-6,52,-1,CONCRETE)
Block(-6,52,0,CONCRETE)
Block(-6,52,1,CONCRETE)
Block(-6,52,2,CONCRETE)
Block(-6,52,3,CONCRETE)
Block(-6,52,4,CONCRETE)
Block(-6,52,5,CONCRETE)
Block(-6,53,-5,CONCRETE)
Block(-6,53,-2,CONCRETE)
Block(-6,53,-1,CONCRETE)
Block(-6,53,0,AIR:0)
Block(-6,53,1,SMOOTH_STAIRS:2)
Block(-6,53,2,CONCRETE)
Block(-6,53,3,CONCRETE)
Block(-6,53,4,CONCRETE)
Block(-6,53,5,CONCRETE)
Block(-6,54,-5,CONCRETE)
Block(-6,54,-2,CONCRETE)
Block(-6,54,-1,CONCRETE)
Block(-6,54,0,AIR:0)
Block(-6,54,1,AIR:0)
Block(-6,54,2,SMOOTH_STAIRS:2)
Block(-6,54,3,CONCRETE)
Block(-6,54,4,CONCRETE)
Block(-6,54,5,CONCRETE)
Block(-6,55,-6,CONCRETE)
Block(-6,55,-5,CONCRETE)
Block(-6,55,-4,CONCRETE)
Block(-6,55,-3,CONCRETE)
Block(-6,55,-2,CONCRETE)
Block(-6,55,-1,CONCRETE)
Block(-6,55,0,AIR:0)
Block(-6,55,1,AIR:0)
Block(-6,55,2,AIR:0)
Block(-6,55,3,SMOOTH_STAIRS:2)
Block(-6,55,4,CONCRETE)
Block(-6,55,5,CONCRETE)
Block(-6,55,6,CONCRETE)
Block(-6,55,7,CONCRETE)
Block(-6,55,8,CONCRETE)
Block(-6,55,9,CONCRETE)
Block(-6,56,-6,CONCRETE)
Block(-6,56,-5,quark:iron_ladder:5)
Block(-6,56,-4,CONCRETE)
Block(-6,56,-3,CONCRETE)
Block(-6,56,-2,CONCRETE)
Block(-6,56,-1,CONCRETE)
Block(-6,56,0,AIR:0)
Block(-6,56,1,AIR:0)
Block(-6,56,2,AIR:0)
Block(-6,56,3,AIR:0)
Block(-6,56,4,CONCRETE)
Block(-6,56,5,STONE)
Block(-6,56,6,BONE_BLOCK)
Block(-6,56,7,CONCRETE)
Block(-6,56,8,quark:iron_ladder:5)
Block(-6,56,9,CONCRETE)
Block(-6,57,-6,CONCRETE)
Block(-6,57,-5,quark:iron_ladder:5)
Block(-6,57,-4,CONCRETE)
Block(-6,57,-3,CONCRETE)
Block(-6,57,-2,SMOOTH_BRICK)
Block(-6,57,-1,CONCRETE)
Block(-6,57,0,AIR:0)
Block(-6,57,1,AIR:0)
Block(-6,57,2,AIR:0)
Block(-6,57,3,AIR:0)
Block(-6,57,4,CONCRETE)
Block(-6,57,5,AIR:0)
Block(-6,57,6,AIR:0)
Block(-6,57,7,CONCRETE)
Block(-6,57,8,quark:iron_ladder:5)
Block(-6,57,9,CONCRETE)
Block(-6,58,-6,CONCRETE)
Block(-6,58,-5,quark:iron_ladder:5)
Block(-6,58,-4,CONCRETE)
Block(-6,58,-3,CONCRETE)
Block(-6,58,-2,CONCRETE)
Block(-6,58,-1,CONCRETE)
Block(-6,58,0,AIR:0)
Block(-6,58,1,AIR:0)
Block(-6,58,2,AIR:0)
Block(-6,58,3,WEB:0)
Block(-6,58,4,CONCRETE)
Block(-6,58,5,AIR:0)
Block(-6,58,6,WEB:0)
Block(-6,58,7,CONCRETE)
Block(-6,58,8,quark:iron_ladder:5)
Block(-6,58,9,CONCRETE)
Block(-6,59,-6,CONCRETE)
Block(-6,59,-5,quark:iron_ladder:5)
Block(-6,59,-4,CONCRETE)
Block(-6,59,-3,CONCRETE)
Block(-6,59,-2,CONCRETE)
Block(-6,59,-1,CONCRETE)
Block(-6,59,0,CONCRETE)
Block(-6,59,1,CONCRETE)
Block(-6,59,2,CONCRETE)
Block(-6,59,3,CONCRETE)
Block(-6,59,4,CONCRETE)
Block(-6,59,5,CONCRETE)
Block(-6,59,6,CONCRETE)
Block(-6,59,7,CONCRETE)
Block(-6,59,8,quark:iron_ladder:5)
Block(-6,59,9,CONCRETE)
Block(-6,60,-6,CONCRETE)
Block(-6,60,-5,quark:iron_ladder:5)
Block(-6,60,-4,CONCRETE)
Block(-6,60,-3,CONCRETE)
Block(-6,60,-2,CONCRETE)
Block(-6,60,-1,CONCRETE)
Block(-6,60,0,SMOOTH_BRICK:1)
Block(-6,60,1,CONCRETE)
Block(-6,60,2,CONCRETE)
Block(-6,60,3,SMOOTH_BRICK:1)
Block(-6,60,4,CONCRETE)
Block(-6,60,5,CONCRETE)
Block(-6,60,6,CONCRETE)
Block(-6,60,7,CONCRETE)
Block(-6,60,8,quark:iron_ladder:5)
Block(-6,60,9,CONCRETE)
Block(-6,61,-6,CONCRETE)
Block(-6,61,-5,quark:iron_ladder:5)
Block(-6,61,-4,SMOOTH_STAIRS:0)
Block(-6,61,0,CONCRETE)
Block(-6,61,1,SMOOTH_STAIRS:0)
Block(-6,61,2,CONCRETE)
Block(-6,61,3,CONCRETE)
Block(-6,61,7,CONCRETE)
Block(-6,61,8,quark:iron_ladder:5)
Block(-6,61,9,CONCRETE)
Block(-6,62,-6,quark:iron_button:5)
Block(-6,62,-5,TRAP_DOOR:1)
Block(-6,62,7,quark:iron_button:5)
Block(-6,62,8,TRAP_DOOR:1)
Block(-5,0,-3,CONCRETE)
Block(-5,0,-2,CONCRETE)
Block(-5,0,-1,CONCRETE)
Block(-5,0,0,CONCRETE)
Block(-5,0,1,CONCRETE)
Block(-5,0,2,CONCRETE)
Block(-5,0,3,CONCRETE)
Block(-5,0,4,CONCRETE)
Block(-5,0,5,CONCRETE)
Block(-5,0,6,CONCRETE)
Block(-5,1,-3,CONCRETE)
Block(-5,1,-2,CONCRETE)
Block(-5,1,-1,CONCRETE)
Block(-5,1,0,CONCRETE)
Block(-5,1,1,CONCRETE)
Block(-5,1,2,CONCRETE)
Block(-5,1,3,CONCRETE)
Block(-5,1,4,CONCRETE)
Block(-5,1,5,CONCRETE)
Block(-5,1,6,CONCRETE)
Block(-5,2,-3,CONCRETE)
Block(-5,2,-2,CONCRETE)
Block(-5,2,-1,CONCRETE)
Block(-5,2,0,CONCRETE)
Block(-5,2,1,CONCRETE)
Block(-5,2,2,CONCRETE)
Block(-5,2,3,CONCRETE)
Block(-5,2,4,CONCRETE)
Block(-5,2,5,CONCRETE)
Block(-5,2,6,CONCRETE)
Block(-5,3,-3,CONCRETE)
Block(-5,3,-2,CONCRETE)
Block(-5,3,-1,CONCRETE)
Block(-5,3,0,CONCRETE)
Block(-5,3,1,CONCRETE)
Block(-5,3,2,CONCRETE)
Block(-5,3,3,CONCRETE)
Block(-5,3,4,CONCRETE)
Block(-5,3,5,CONCRETE)
Block(-5,3,6,CONCRETE)
Block(-5,4,-3,CONCRETE)
Block(-5,4,-2,CONCRETE)
Block(-5,4,-1,CONCRETE)
Block(-5,4,0,CONCRETE)
Block(-5,4,1,CONCRETE)
Block(-5,4,2,CONCRETE)
Block(-5,4,3,CONCRETE)
Block(-5,4,4,CONCRETE)
Block(-5,4,5,CONCRETE)
Block(-5,4,6,CONCRETE)
Block(-5,5,-3,CONCRETE)
Block(-5,5,-2,CONCRETE)
Block(-5,5,-1,CONCRETE)
Block(-5,5,0,CONCRETE)
Block(-5,5,1,CONCRETE)
Block(-5,5,2,CONCRETE)
Block(-5,5,3,CONCRETE)
Block(-5,5,4,CONCRETE)
Block(-5,5,5,CONCRETE)
Block(-5,5,6,CONCRETE)
Block(-5,6,-3,CONCRETE)
Block(-5,6,-2,CONCRETE)
Block(-5,6,-1,CONCRETE)
Block(-5,6,0,CONCRETE)
Block(-5,6,1,CONCRETE)
Block(-5,6,2,CONCRETE)
Block(-5,6,3,CONCRETE)
Block(-5,6,4,CONCRETE)
Block(-5,6,5,CONCRETE)
Block(-5,6,6,CONCRETE)
Block(-5,7,-3,CONCRETE)
Block(-5,7,-2,CONCRETE)
Block(-5,7,-1,CONCRETE)
Block(-5,7,0,CONCRETE)
Block(-5,7,1,CONCRETE)
Block(-5,7,2,CONCRETE)
Block(-5,7,3,CONCRETE)
Block(-5,7,4,CONCRETE)
Block(-5,7,5,CONCRETE)
Block(-5,7,6,CONCRETE)
Block(-5,7,7,CONCRETE)
Block(-5,7,8,CONCRETE)
Block(-5,7,9,CONCRETE)
Block(-5,8,-3,CONCRETE)
Block(-5,8,-2,CONCRETE)
Block(-5,8,-1,CONCRETE)
Block(-5,8,0,CONCRETE)
Block(-5,8,1,CONCRETE)
Block(-5,8,2,CONCRETE)
Block(-5,8,3,CONCRETE)
Block(-5,8,4,CONCRETE)
Block(-5,8,5,WOOD:0,../../../Chests/Loot/manhunt_vagrant_scrap.nbt)
Block(-5,8,6,WOOD:0,../../../Chests/Loot/manhunt_vagrant_scrap.nbt)
Block(-5,8,7,WOOD:5)
Block(-5,8,8,ANVIL:1)
Block(-5,8,9,CONCRETE)
Block(-5,9,-3,CONCRETE)
Block(-5,9,-2,CONCRETE)
Block(-5,9,-1,CONCRETE)
Block(-5,9,0,CONCRETE)
Block(-5,9,1,CONCRETE)
Block(-5,9,2,CONCRETE)
Block(-5,9,3,CONCRETE)
Block(-5,9,4,CONCRETE)
Block(-5,9,5,WOOD:0,../../../Chests/Loot/manhunt_vagrant_scrap.nbt)
Block(-5,9,6,WOOD:0,../../../Chests/Loot/manhunt_vagrant_scrap.nbt)
Block(-5,9,7,SMOOTH_BRICK:0)
Block(-5,9,8,SMOOTH_BRICK:0)
Block(-5,9,9,CONCRETE)
Block(-5,10,-3,CONCRETE)
Block(-5,10,-2,CONCRETE)
Block(-5,10,-1,CONCRETE)
Block(-5,10,0,CONCRETE)
Block(-5,10,1,CONCRETE)
Block(-5,10,2,CONCRETE)
Block(-5,10,3,CONCRETE)
Block(-5,10,4,CONCRETE)
Block(-5,10,5,AIR:0)
Block(-5,10,6,AIR:0)
Block(-5,10,7,AIR:0)
Block(-5,10,8,AIR:0)
Block(-5,10,9,CONCRETE)
Block(-5,11,-3,CONCRETE)
Block(-5,11,-2,CONCRETE)
Block(-5,11,-1,SMOOTH_BRICK)
Block(-5,11,0,CONCRETE)
Block(-5,11,1,CONCRETE)
Block(-5,11,2,CONCRETE)
Block(-5,11,3,CONCRETE)
Block(-5,11,4,CONCRETE)
Block(-5,11,5,AIR:0)
Block(-5,11,6,AIR:0)
Block(-5,11,7,AIR:0)
Block(-5,11,8,WEB:0)
Block(-5,11,9,CONCRETE)
Block(-5,12,-3,CONCRETE)
Block(-5,12,-2,CONCRETE)
Block(-5,12,-1,AIR:0)
Block(-5,12,0,CONCRETE)
Block(-5,12,1,CONCRETE)
Block(-5,12,2,CONCRETE)
Block(-5,12,3,CONCRETE)
Block(-5,12,4,CONCRETE)
Block(-5,12,5,CONCRETE)
Block(-5,12,6,CONCRETE)
Block(-5,12,7,CONCRETE)
Block(-5,12,8,CONCRETE)
Block(-5,12,9,CONCRETE)
Block(-5,13,-3,CONCRETE)
Block(-5,13,-2,CONCRETE)
Block(-5,13,-1,CONCRETE)
Block(-5,13,0,CONCRETE)
Block(-5,13,1,CONCRETE)
Block(-5,13,2,CONCRETE)
Block(-5,13,3,CONCRETE)
Block(-5,13,4,CONCRETE)
Block(-5,13,5,CONCRETE)
Block(-5,13,6,CONCRETE)
Block(-5,13,7,CONCRETE)
Block(-5,13,8,CONCRETE)
Block(-5,13,9,CONCRETE)
Block(-5,14,-3,CONCRETE)
Block(-5,14,-2,CONCRETE)
Block(-5,14,-1,CONCRETE)
Block(-5,14,0,CONCRETE)
Block(-5,14,1,CONCRETE)
Block(-5,14,2,CONCRETE)
Block(-5,14,3,CONCRETE)
Block(-5,14,4,STONE)
Block(-5,14,5,CONCRETE)
Block(-5,14,6,CONCRETE)
Block(-5,15,-3,CONCRETE)
Block(-5,15,-2,CONCRETE)
Block(-5,15,-1,CONCRETE)
Block(-5,15,0,CONCRETE)
Block(-5,15,1,CONCRETE)
Block(-5,15,2,CONCRETE)
Block(-5,15,3,CONCRETE)
Block(-5,15,4,AIR:0)
Block(-5,15,5,CONCRETE)
Block(-5,15,6,CONCRETE)
Block(-5,16,-3,CONCRETE)
Block(-5,16,-2,CONCRETE)
Block(-5,16,-1,CONCRETE)
Block(-5,16,0,CONCRETE)
Block(-5,16,1,CONCRETE)
Block(-5,16,2,CONCRETE)
Block(-5,16,3,CONCRETE)
Block(-5,16,4,CONCRETE)
Block(-5,16,5,CONCRETE)
Block(-5,16,6,CONCRETE)
Block(-5,17,-3,CONCRETE)
Block(-5,17,-2,CONCRETE)
Block(-5,17,-1,CONCRETE)
Block(-5,17,0,LONG_GRASS)
Block(-5,17,1,CONCRETE)
Block(-5,17,2,CONCRETE)
Block(-5,17,3,CONCRETE)
Block(-5,17,4,CONCRETE)
Block(-5,17,5,CONCRETE)
Block(-5,17,6,CONCRETE)
Block(-5,18,-3,CONCRETE)
Block(-5,18,-2,CONCRETE)
Block(-5,18,-1,CONCRETE)
Block(-5,18,0,AIR:0)
Block(-5,18,1,CONCRETE)
Block(-5,18,2,CONCRETE)
Block(-5,18,3,CONCRETE)
Block(-5,18,4,CONCRETE)
Block(-5,18,5,CONCRETE)
Block(-5,18,6,CONCRETE)
Block(-5,19,-3,CONCRETE)
Block(-5,19,-2,CONCRETE)
Block(-5,19,-1,CONCRETE)
Block(-5,19,0,CONCRETE)
Block(-5,19,1,CONCRETE)
Block(-5,19,2,CONCRETE)
Block(-5,19,3,CONCRETE)
Block(-5,19,4,CONCRETE)
Block(-5,19,5,CONCRETE)
Block(-5,19,6,CONCRETE)
Block(-5,20,-3,CONCRETE)
Block(-5,20,-2,CONCRETE)
Block(-5,20,-1,CONCRETE)
Block(-5,20,0,CONCRETE)
Block(-5,20,1,CONCRETE)
Block(-5,20,2,CONCRETE)
Block(-5,20,3,CONCRETE)
Block(-5,20,4,AIR:0)
Block(-5,20,5,CONCRETE)
Block(-5,20,6,CONCRETE)
Block(-5,21,-3,CONCRETE)
Block(-5,21,-2,CONCRETE)
Block(-5,21,-1,CONCRETE)
Block(-5,21,0,CONCRETE)
Block(-5,21,1,CONCRETE)
Block(-5,21,2,CONCRETE)
Block(-5,21,3,CONCRETE)
Block(-5,21,4,AIR:0)
Block(-5,21,5,CONCRETE)
Block(-5,21,6,CONCRETE)
Block(-5,22,-3,CONCRETE)
Block(-5,22,-2,CONCRETE)
Block(-5,22,-1,CONCRETE)
Block(-5,22,0,CONCRETE)
Block(-5,22,1,CONCRETE)
Block(-5,22,2,CONCRETE)
Block(-5,22,3,CONCRETE)
Block(-5,22,4,CONCRETE)
Block(-5,22,5,CONCRETE)
Block(-5,22,6,CONCRETE)
Block(-5,23,-3,CONCRETE)
Block(-5,23,-2,CONCRETE)
Block(-5,23,-1,STONE)
Block(-5,23,0,CONCRETE)
Block(-5,23,1,CONCRETE)
Block(-5,23,2,CONCRETE)
Block(-5,23,3,CONCRETE)
Block(-5,23,4,CONCRETE)
Block(-5,23,5,CONCRETE)
Block(-5,23,6,CONCRETE)
Block(-5,24,-3,CONCRETE)
Block(-5,24,-2,CONCRETE)
Block(-5,24,-1,AIR:0)
Block(-5,24,0,CONCRETE)
Block(-5,24,1,CONCRETE)
Block(-5,24,2,CONCRETE)
Block(-5,24,3,CONCRETE)
Block(-5,24,4,CONCRETE)
Block(-5,24,5,CONCRETE)
Block(-5,24,6,CONCRETE)
Block(-5,25,-3,CONCRETE)
Block(-5,25,-2,CONCRETE)
Block(-5,25,-1,CONCRETE)
Block(-5,25,0,CONCRETE)
Block(-5,25,1,CONCRETE)
Block(-5,25,2,CONCRETE)
Block(-5,25,3,CONCRETE)
Block(-5,25,4,CONCRETE)
Block(-5,25,5,CONCRETE)
Block(-5,25,6,CONCRETE)
Block(-5,25,7,CONCRETE)
Block(-5,25,8,CONCRETE)
Block(-5,25,9,CONCRETE)
Block(-5,26,-3,CONCRETE)
Block(-5,26,-2,CONCRETE)
Block(-5,26,-1,CONCRETE)
Block(-5,26,0,CONCRETE)
Block(-5,26,1,CONCRETE)
Block(-5,26,2,CONCRETE)
Block(-5,26,3,CONCRETE)
Block(-5,26,4,LONG_GRASS)
Block(-5,26,5,CONCRETE)
Block(-5,26,6,WEB:0)
Block(-5,26,7,SMOOTH_BRICK)
Block(-5,26,8,AIR:0)
Block(-5,26,9,CONCRETE)
Block(-5,27,-3,CONCRETE)
Block(-5,27,-2,CONCRETE)
Block(-5,27,-1,CONCRETE)
Block(-5,27,0,CONCRETE)
Block(-5,27,1,CONCRETE)
Block(-5,27,2,CONCRETE)
Block(-5,27,3,CONCRETE)
Block(-5,27,4,AIR:0)
Block(-5,27,5,CONCRETE)
Block(-5,27,6,quark:iron_button:2)
Block(-5,27,7,AIR:0)
Block(-5,27,8,AIR:0)
Block(-5,27,9,CONCRETE)
Block(-5,28,-3,CONCRETE)
Block(-5,28,-2,CONCRETE)
Block(-5,28,-1,CONCRETE)
Block(-5,28,0,CONCRETE)
Block(-5,28,1,CONCRETE)
Block(-5,28,2,CONCRETE)
Block(-5,28,3,CONCRETE)
Block(-5,28,4,CONCRETE)
Block(-5,28,5,CONCRETE)
Block(-5,28,6,CONCRETE)
Block(-5,28,7,CONCRETE)
Block(-5,28,8,CONCRETE)
Block(-5,28,9,CONCRETE)
Block(-5,29,-3,CONCRETE)
Block(-5,29,-2,CONCRETE)
Block(-5,29,-1,CONCRETE)
Block(-5,29,0,AIR:0)
Block(-5,29,1,CONCRETE)
Block(-5,29,2,CONCRETE)
Block(-5,29,3,CONCRETE)
Block(-5,29,4,CONCRETE)
Block(-5,29,5,CONCRETE)
Block(-5,29,6,CONCRETE)
Block(-5,30,-3,CONCRETE)
Block(-5,30,-2,CONCRETE)
Block(-5,30,-1,CONCRETE)
Block(-5,30,0,AIR:0)
Block(-5,30,1,CONCRETE)
Block(-5,30,2,CONCRETE)
Block(-5,30,3,CONCRETE)
Block(-5,30,4,CONCRETE)
Block(-5,30,5,CONCRETE)
Block(-5,30,6,CONCRETE)
Block(-5,31,-3,CONCRETE)
Block(-5,31,-2,CONCRETE)
Block(-5,31,-1,CONCRETE)
Block(-5,31,0,CONCRETE)
Block(-5,31,1,CONCRETE)
Block(-5,31,2,CONCRETE)
Block(-5,31,3,CONCRETE)
Block(-5,31,4,CONCRETE)
Block(-5,31,5,CONCRETE)
Block(-5,31,6,CONCRETE)
Block(-5,32,-3,CONCRETE)
Block(-5,32,-2,CONCRETE)
Block(-5,32,-1,CONCRETE)
Block(-5,32,0,CONCRETE)
Block(-5,32,1,CONCRETE)
Block(-5,32,2,CONCRETE)
Block(-5,32,3,CONCRETE)
Block(-5,32,4,AIR:0)
Block(-5,32,5,CONCRETE)
Block(-5,32,6,CONCRETE)
Block(-5,33,-3,CONCRETE)
Block(-5,33,-2,CONCRETE)
Block(-5,33,-1,CONCRETE)
Block(-5,33,0,CONCRETE)
Block(-5,33,1,CONCRETE)
Block(-5,33,2,CONCRETE)
Block(-5,33,3,CONCRETE)
Block(-5,33,4,AIR:0)
Block(-5,33,5,CONCRETE)
Block(-5,33,6,CONCRETE)
Block(-5,34,-3,CONCRETE)
Block(-5,34,-2,CONCRETE)
Block(-5,34,-1,CONCRETE)
Block(-5,34,0,CONCRETE)
Block(-5,34,1,CONCRETE)
Block(-5,34,2,CONCRETE)
Block(-5,34,3,CONCRETE)
Block(-5,34,4,CONCRETE)
Block(-5,34,5,CONCRETE)
Block(-5,34,6,CONCRETE)
Block(-5,35,-3,CONCRETE)
Block(-5,35,-2,CONCRETE)
Block(-5,35,-1,AIR:0)
Block(-5,35,0,CONCRETE)
Block(-5,35,1,CONCRETE)
Block(-5,35,2,CONCRETE)
Block(-5,35,3,CONCRETE)
Block(-5,35,4,CONCRETE)
Block(-5,35,5,CONCRETE)
Block(-5,35,6,CONCRETE)
Block(-5,36,-3,CONCRETE)
Block(-5,36,-2,CONCRETE)
Block(-5,36,-1,AIR:0)
Block(-5,36,0,CONCRETE)
Block(-5,36,1,CONCRETE)
Block(-5,36,2,CONCRETE)
Block(-5,36,3,CONCRETE)
Block(-5,36,4,CONCRETE)
Block(-5,36,5,CONCRETE)
Block(-5,36,6,CONCRETE)
Block(-5,37,-3,CONCRETE)
Block(-5,37,-2,CONCRETE)
Block(-5,37,-1,CONCRETE)
Block(-5,37,0,CONCRETE)
Block(-5,37,1,CONCRETE)
Block(-5,37,2,CONCRETE)
Block(-5,37,3,CONCRETE)
Block(-5,37,4,CONCRETE)
Block(-5,37,5,CONCRETE)
Block(-5,37,6,CONCRETE)
Block(-5,38,-3,CONCRETE)
Block(-5,38,-2,CONCRETE)
Block(-5,38,-1,CONCRETE)
Block(-5,38,0,CONCRETE)
Block(-5,38,1,CONCRETE)
Block(-5,38,2,CONCRETE)
Block(-5,38,3,CONCRETE)
Block(-5,38,4,AIR:0)
Block(-5,38,5,CONCRETE)
Block(-5,38,6,CONCRETE)
Block(-5,39,-3,CONCRETE)
Block(-5,39,-2,CONCRETE)
Block(-5,39,-1,CONCRETE)
Block(-5,39,0,CONCRETE)
Block(-5,39,1,CONCRETE)
Block(-5,39,2,CONCRETE)
Block(-5,39,3,CONCRETE)
Block(-5,39,4,AIR:0)
Block(-5,39,5,CONCRETE)
Block(-5,39,6,CONCRETE)
Block(-5,40,-3,CONCRETE)
Block(-5,40,-2,CONCRETE)
Block(-5,40,-1,CONCRETE)
Block(-5,40,0,CONCRETE)
Block(-5,40,1,CONCRETE)
Block(-5,40,2,CONCRETE)
Block(-5,40,3,CONCRETE)
Block(-5,40,4,CONCRETE)
Block(-5,40,5,CONCRETE)
Block(-5,40,6,CONCRETE)
Block(-5,41,-3,CONCRETE)
Block(-5,41,-2,CONCRETE)
Block(-5,41,-1,CONCRETE)
Block(-5,41,0,STONE)
Block(-5,41,1,CONCRETE)
Block(-5,41,2,CONCRETE)
Block(-5,41,3,CONCRETE)
Block(-5,41,4,CONCRETE)
Block(-5,41,5,CONCRETE)
Block(-5,41,6,CONCRETE)
Block(-5,42,-3,CONCRETE)
Block(-5,42,-2,CONCRETE)
Block(-5,42,-1,CONCRETE)
Block(-5,42,0,AIR:0)
Block(-5,42,1,CONCRETE)
Block(-5,42,2,CONCRETE)
Block(-5,42,3,CONCRETE)
Block(-5,42,4,CONCRETE)
Block(-5,42,5,CONCRETE)
Block(-5,42,6,CONCRETE)
Block(-5,43,-5,CONCRETE)
Block(-5,43,-4,CONCRETE)
Block(-5,43,-3,CONCRETE)
Block(-5,43,-2,CONCRETE)
Block(-5,43,-1,CONCRETE)
Block(-5,43,0,CONCRETE)
Block(-5,43,1,CONCRETE)
Block(-5,43,2,CONCRETE)
Block(-5,43,3,CONCRETE)
Block(-5,43,4,CONCRETE)
Block(-5,43,5,CONCRETE)
Block(-5,43,6,CONCRETE)
Block(-5,44,-5,CONCRETE)
Block(-5,44,-4,STONE)
Block(-5,44,-3,AIR:0)
Block(-5,44,-2,DISPENSER:1,f_bunker_silo/9-dispenser.nbt)
Block(-5,44,-1,CONCRETE)
Block(-5,44,0,CONCRETE)
Block(-5,44,1,CONCRETE)
Block(-5,44,2,CONCRETE)
Block(-5,44,3,CONCRETE)
Block(-5,44,4,AIR:0)
Block(-5,44,5,CONCRETE)
Block(-5,44,6,CONCRETE)
Block(-5,45,-5,CONCRETE)
Block(-5,45,-4,quark:iron_button:3)
Block(-5,45,-3,BOOKSHELF:0)
Block(-5,45,-2,TRAP_DOOR:7)
Block(-5,45,-1,CONCRETE)
Block(-5,45,0,CONCRETE)
Block(-5,45,1,CONCRETE)
Block(-5,45,2,CONCRETE)
Block(-5,45,3,CONCRETE)
Block(-5,45,4,AIR:0)
Block(-5,45,5,CONCRETE)
Block(-5,45,6,CONCRETE)
Block(-5,46,-5,CONCRETE)
Block(-5,46,-4,IRON_TRAPDOOR:9)
Block(-5,46,-3,AIR:0)
Block(-5,46,-2,AIR:0)
Block(-5,46,-1,CONCRETE)
Block(-5,46,0,CONCRETE)
Block(-5,46,1,CONCRETE)
Block(-5,46,2,CONCRETE)
Block(-5,46,3,CONCRETE)
Block(-5,46,4,CONCRETE)
Block(-5,46,5,CONCRETE)
Block(-5,46,6,CONCRETE)
Block(-5,47,-5,CONCRETE)
Block(-5,47,-4,SMOOTH_BRICK:1)
Block(-5,47,-3,AIR:0)
Block(-5,47,-2,WEB:0)
Block(-5,47,-1,CONCRETE)
Block(-5,47,0,AIR:0)
Block(-5,47,1,CONCRETE)
Block(-5,47,2,CONCRETE)
Block(-5,47,3,CONCRETE)
Block(-5,47,4,CONCRETE)
Block(-5,47,5,CONCRETE)
Block(-5,47,6,CONCRETE)
Block(-5,48,-5,CONCRETE)
Block(-5,48,-4,CONCRETE)
Block(-5,48,-3,CONCRETE)
Block(-5,48,-2,CONCRETE)
Block(-5,48,-1,CONCRETE)
Block(-5,48,0,AIR:0)
Block(-5,48,1,CONCRETE)
Block(-5,48,2,CONCRETE)
Block(-5,48,3,CONCRETE)
Block(-5,48,4,CONCRETE)
Block(-5,48,5,CONCRETE)
Block(-5,48,6,CONCRETE)
Block(-5,49,-3,CONCRETE)
Block(-5,49,-2,CONCRETE)
Block(-5,49,-1,CONCRETE)
Block(-5,49,0,CONCRETE)
Block(-5,49,1,CONCRETE)
Block(-5,49,2,CONCRETE)
Block(-5,49,3,CONCRETE)
Block(-5,49,4,CONCRETE)
Block(-5,49,5,CONCRETE)
Block(-5,49,6,CONCRETE)
Block(-5,50,-3,CONCRETE)
Block(-5,50,-2,quark:stonebrick_wall)
Block(-5,50,-1,CONCRETE)
Block(-5,50,0,CONCRETE)
Block(-5,50,1,CONCRETE)
Block(-5,50,2,CONCRETE)
Block(-5,50,3,CONCRETE)
Block(-5,50,4,AIR:0)
Block(-5,50,5,CONCRETE)
Block(-5,50,6,CONCRETE)
Block(-5,51,-3,CONCRETE)
Block(-5,51,-2,quark:stonebrick_wall)
Block(-5,51,-1,CONCRETE)
Block(-5,51,0,CONCRETE)
Block(-5,51,1,CONCRETE)
Block(-5,51,2,CONCRETE)
Block(-5,51,3,CONCRETE)
Block(-5,51,4,AIR:0)
Block(-5,51,5,CONCRETE)
Block(-5,51,6,CONCRETE)
Block(-5,52,-3,CONCRETE)
Block(-5,52,-2,quark:stonebrick_wall)
Block(-5,52,-1,CONCRETE)
Block(-5,52,0,CONCRETE)
Block(-5,52,1,CONCRETE)
Block(-5,52,2,CONCRETE)
Block(-5,52,3,CONCRETE)
Block(-5,52,4,CONCRETE)
Block(-5,52,5,CONCRETE)
Block(-5,52,6,CONCRETE)
Block(-5,53,-3,CONCRETE)
Block(-5,53,-2,quark:stonebrick_wall)
Block(-5,53,-1,CONCRETE)
Block(-5,53,0,AIR:0)
Block(-5,53,1,CONCRETE)
Block(-5,53,2,CONCRETE)
Block(-5,53,3,CONCRETE)
Block(-5,53,4,CONCRETE)
Block(-5,53,5,CONCRETE)
Block(-5,53,6,CONCRETE)
Block(-5,54,-3,CONCRETE)
Block(-5,54,-2,CONCRETE)
Block(-5,54,-1,CONCRETE)
Block(-5,54,0,AIR:0)
Block(-5,54,1,CONCRETE)
Block(-5,54,2,CONCRETE)
Block(-5,54,3,CONCRETE)
Block(-5,54,4,CONCRETE)
Block(-5,54,5,CONCRETE)
Block(-5,54,6,CONCRETE)
Block(-5,55,-6,CONCRETE)
Block(-5,55,-5,CONCRETE)
Block(-5,55,-4,CONCRETE)
Block(-5,55,-3,CONCRETE)
Block(-5,55,-2,CONCRETE)
Block(-5,55,-1,CONCRETE)
Block(-5,55,0,CONCRETE)
Block(-5,55,1,CONCRETE)
Block(-5,55,2,CONCRETE)
Block(-5,55,3,CONCRETE)
Block(-5,55,4,CONCRETE)
Block(-5,55,5,CONCRETE)
Block(-5,55,6,CONCRETE)
Block(-5,55,7,CONCRETE)
Block(-5,55,8,CONCRETE)
Block(-5,55,9,CONCRETE)
Block(-5,56,-6,CONCRETE)
Block(-5,56,-5,AIR:0)
Block(-5,56,-4,CONCRETE)
Block(-5,56,-3,IRON_BLOCK:0)
Block(-5,56,-2,IRON_BLOCK:0)
Block(-5,56,-1,CONCRETE)
Block(-5,56,0,IRON_FENCE:0)
Block(-5,56,1,IRON_FENCE:0)
Block(-5,56,2,IRON_FENCE:0)
Block(-5,56,3,AIR:0)
Block(-5,56,4,CONCRETE)
Block(-5,56,5,AIR:0)
Block(-5,56,6,AIR:0)
Block(-5,56,7,CONCRETE)
Block(-5,56,8,AIR:0)
Block(-5,56,9,CONCRETE)
Block(-5,57,-6,CONCRETE)
Block(-5,57,-5,AIR:0)
Block(-5,57,-4,CONCRETE)
Block(-5,57,-3,SMOOTH_BRICK)
Block(-5,57,-2,AIR:0)
Block(-5,57,-1,CONCRETE)
Block(-5,57,0,IRON_FENCE:0)
Block(-5,57,1,IRON_FENCE:0)
Block(-5,57,2,IRON_FENCE:0)
Block(-5,57,3,AIR:0)
Block(-5,57,4,CONCRETE)
Block(-5,57,5,AIR:0)
Block(-5,57,6,AIR:0)
Block(-5,57,7,CONCRETE)
Block(-5,57,8,AIR:0)
Block(-5,57,9,CONCRETE)
Block(-5,58,-6,CONCRETE)
Block(-5,58,-5,CONCRETE)
Block(-5,58,-4,CONCRETE)
Block(-5,58,-3,SMOOTH_BRICK:0)
Block(-5,58,-2,SMOOTH_BRICK:0)
Block(-5,58,-1,CONCRETE)
Block(-5,58,0,AIR:0)
Block(-5,58,1,AIR:0)
Block(-5,58,2,AIR:0)
Block(-5,58,3,AIR:0)
Block(-5,58,4,CONCRETE)
Block(-5,58,5,AIR:0)
Block(-5,58,6,AIR:0)
Block(-5,58,7,CONCRETE)
Block(-5,58,8,CONCRETE)
Block(-5,58,9,CONCRETE)
Block(-5,59,-6,CONCRETE)
Block(-5,59,-5,CONCRETE)
Block(-5,59,-4,CONCRETE)
Block(-5,59,-3,CONCRETE)
Block(-5,59,-2,CONCRETE)
Block(-5,59,-1,CONCRETE)
Block(-5,59,0,CONCRETE)
Block(-5,59,1,CONCRETE)
Block(-5,59,2,CONCRETE)
Block(-5,59,3,CONCRETE)
Block(-5,59,4,CONCRETE)
Block(-5,59,5,CONCRETE)
Block(-5,59,6,CONCRETE)
Block(-5,59,7,CONCRETE)
Block(-5,59,8,CONCRETE)
Block(-5,59,9,CONCRETE)
Block(-5,60,-6,CONCRETE)
Block(-5,60,-5,SMOOTH_BRICK)
Block(-5,60,-4,CONCRETE)
Block(-5,60,-3,CONCRETE)
Block(-5,60,-2,SMOOTH_BRICK:1)
Block(-5,60,-1,SMOOTH_BRICK:1)
Block(-5,60,0,SMOOTH_BRICK:1)
Block(-5,60,1,CONCRETE)
Block(-5,60,2,CONCRETE)
Block(-5,60,3,SMOOTH_BRICK:1)
Block(-5,60,4,SMOOTH_BRICK:1)
Block(-5,60,5,SMOOTH_BRICK:1)
Block(-5,60,6,CONCRETE)
Block(-5,60,7,CONCRETE)
Block(-5,60,8,SMOOTH_BRICK)
Block(-5,60,9,CONCRETE)
Block(-5,61,-6,CONCRETE)
Block(-5,61,-5,CONCRETE)
Block(-5,61,-4,SMOOTH_STAIRS:0)
Block(-5,61,-2,CONCRETE)
Block(-5,61,-1,SMOOTH_STAIRS:0)
Block(-5,61,0,CONCRETE)
Block(-5,61,1,CONCRETE)
Block(-5,61,2,CONCRETE)
Block(-5,61,3,CONCRETE)
Block(-5,61,4,CONCRETE)
Block(-5,61,5,SMOOTH_STAIRS:0)
Block(-5,61,7,CONCRETE)
Block(-5,61,8,CONCRETE)
Block(-5,61,9,SMOOTH_STAIRS:0)
Block(-5,62,0,IRON_BLOCK)
Block(-5,62,1,IRON_BLOCK)
Block(-5,62,2,IRON_BLOCK)
Block(-5,62,3,IRON_BLOCK)
Block(-5,62,7,CONCRETE)
Block(-4,0,-4,CONCRETE)
Block(-4,0,-3,CONCRETE)
Block(-4,0,-2,CONCRETE)
Block(-4,0,-1,CONCRETE)
Block(-4,0,0,CONCRETE)
Block(-4,0,1,CONCRETE)
Block(-4,0,2,CONCRETE)
Block(-4,0,3,CONCRETE)
Block(-4,0,4,CONCRETE)
Block(-4,0,5,CONCRETE)
Block(-4,0,6,CONCRETE)
Block(-4,0,7,CONCRETE)
Block(-4,1,-4,CONCRETE)
Block(-4,1,-3,CONCRETE)
Block(-4,1,-2,CONCRETE)
Block(-4,1,-1,CONCRETE)
Block(-4,1,0,CONCRETE)
Block(-4,1,1,CONCRETE)
Block(-4,1,2,CONCRETE)
Block(-4,1,3,CONCRETE)
Block(-4,1,4,CONCRETE)
Block(-4,1,5,CONCRETE)
Block(-4,1,6,CONCRETE)
Block(-4,1,7,CONCRETE)
Block(-4,2,-4,CONCRETE)
Block(-4,2,-3,CONCRETE)
Block(-4,2,-2,CONCRETE)
Block(-4,2,-1,CONCRETE)
Block(-4,2,0,CONCRETE)
Block(-4,2,1,CONCRETE)
Block(-4,2,2,CONCRETE)
Block(-4,2,3,CONCRETE)
Block(-4,2,4,CONCRETE)
Block(-4,2,5,CONCRETE)
Block(-4,2,6,CONCRETE)
Block(-4,2,7,CONCRETE)
Block(-4,3,-4,CONCRETE)
Block(-4,3,-3,CONCRETE)
Block(-4,3,-2,CONCRETE)
Block(-4,3,-1,CONCRETE)
Block(-4,3,0,CONCRETE)
Block(-4,3,1,CONCRETE)
Block(-4,3,2,CONCRETE)
Block(-4,3,3,CONCRETE)
Block(-4,3,4,CONCRETE)
Block(-4,3,5,CONCRETE)
Block(-4,3,6,CONCRETE)
Block(-4,3,7,CONCRETE)
Block(-4,4,-4,CONCRETE)
Block(-4,4,-3,CONCRETE)
Block(-4,4,-2,CONCRETE)
Block(-4,4,-1,CONCRETE)
Block(-4,4,0,CONCRETE)
Block(-4,4,1,CONCRETE)
Block(-4,4,2,CONCRETE)
Block(-4,4,3,CONCRETE)
Block(-4,4,4,CONCRETE)
Block(-4,4,5,CONCRETE)
Block(-4,4,6,CONCRETE)
Block(-4,4,7,CONCRETE)
Block(-4,5,-4,CONCRETE)
Block(-4,5,-3,CONCRETE)
Block(-4,5,-2,CONCRETE)
Block(-4,5,-1,CONCRETE)
Block(-4,5,0,CONCRETE)
Block(-4,5,1,CONCRETE)
Block(-4,5,2,CONCRETE)
Block(-4,5,3,CONCRETE)
Block(-4,5,4,CONCRETE)
Block(-4,5,5,CONCRETE)
Block(-4,5,6,CONCRETE)
Block(-4,5,7,CONCRETE)
Block(-4,6,-4,CONCRETE)
Block(-4,6,-3,CONCRETE)
Block(-4,6,-2,CONCRETE)
Block(-4,6,-1,CONCRETE)
Block(-4,6,0,CONCRETE)
Block(-4,6,1,CONCRETE)
Block(-4,6,2,CONCRETE)
Block(-4,6,3,CONCRETE)
Block(-4,6,4,CONCRETE)
Block(-4,6,5,CONCRETE)
Block(-4,6,6,CONCRETE)
Block(-4,6,7,CONCRETE)
Block(-4,7,-4,CONCRETE)
Block(-4,7,-3,CONCRETE)
Block(-4,7,-2,CONCRETE)
Block(-4,7,-1,CONCRETE)
Block(-4,7,0,CONCRETE)
Block(-4,7,1,CONCRETE)
Block(-4,7,2,CONCRETE)
Block(-4,7,3,CONCRETE)
Block(-4,7,4,CONCRETE)
Block(-4,7,5,CONCRETE)
Block(-4,7,6,CONCRETE)
Block(-4,7,7,CONCRETE)
Block(-4,7,8,CONCRETE)
Block(-4,7,9,CONCRETE)
Block(-4,8,-4,CONCRETE)
Block(-4,8,-3,CONCRETE)
Block(-4,8,-2,CONCRETE)
Block(-4,8,-1,CONCRETE)
Block(-4,8,0,CONCRETE)
Block(-4,8,1,CONCRETE)
Block(-4,8,2,SMOOTH_STAIRS:0)
Block(-4,8,3,AIR:0)
Block(-4,8,4,SMOOTH_BRICK)
Block(-4,8,5,AIR:0)
Block(-4,8,6,AIR:0)
Block(-4,8,7,AIR:0)
Block(-4,8,8,AIR:0)
Block(-4,8,9,CONCRETE)
Block(-4,9,-4,CONCRETE)
Block(-4,9,-3,CONCRETE)
Block(-4,9,-2,CONCRETE)
Block(-4,9,-1,CONCRETE)
Block(-4,9,0,CONCRETE)
Block(-4,9,1,SMOOTH_STAIRS:0)
Block(-4,9,2,AIR:0)
Block(-4,9,3,AIR:0)
Block(-4,9,4,AIR:0)
Block(-4,9,5,AIR:0)
Block(-4,9,6,AIR:0)
Block(-4,9,7,AIR:0)
Block(-4,9,8,AIR:0)
Block(-4,9,9,CONCRETE)
Block(-4,10,-4,CONCRETE)
Block(-4,10,-3,CONCRETE)
Block(-4,10,-2,CONCRETE)
Block(-4,10,-1,CONCRETE)
Block(-4,10,0,SMOOTH_STAIRS:0)
Block(-4,10,1,AIR:0)
Block(-4,10,2,AIR:0)
Block(-4,10,3,AIR:0)
Block(-4,10,4,AIR:0)
Block(-4,10,5,AIR:0)
Block(-4,10,6,AIR:0)
Block(-4,10,7,AIR:0)
Block(-4,10,8,AIR:0)
Block(-4,10,9,CONCRETE)
Block(-4,11,-4,CONCRETE)
Block(-4,11,-3,CONCRETE)
Block(-4,11,-2,CONCRETE)
Block(-4,11,-1,STONE)
Block(-4,11,0,AIR:0)
Block(-4,11,1,AIR:0)
Block(-4,11,2,AIR:0)
Block(-4,11,3,AIR:0)
Block(-4,11,4,AIR:0)
Block(-4,11,5,AIR:0)
Block(-4,11,6,AIR:0)
Block(-4,11,7,AIR:0)
Block(-4,11,8,AIR:0)
Block(-4,11,9,CONCRETE)
Block(-4,12,-4,CONCRETE)
Block(-4,12,-3,CONCRETE)
Block(-4,12,-2,CONCRETE)
Block(-4,12,-1,AIR:0)
Block(-4,12,0,AIR:0)
Block(-4,12,1,AIR:0)
Block(-4,12,2,AIR:0)
Block(-4,12,3,AIR:0)
Block(-4,12,4,AIR:0)
Block(-4,12,5,AIR:0)
Block(-4,12,6,AIR:0)
Block(-4,12,7,AIR:0)
Block(-4,12,8,WEB:0)
Block(-4,12,9,CONCRETE)
Block(-4,13,-4,CONCRETE)
Block(-4,13,-3,CONCRETE)
Block(-4,13,-2,CONCRETE)
Block(-4,13,-1,CONCRETE)
Block(-4,13,0,CONCRETE)
Block(-4,13,1,CONCRETE)
Block(-4,13,2,CONCRETE)
Block(-4,13,3,CONCRETE)
Block(-4,13,4,CONCRETE)
Block(-4,13,5,CONCRETE)
Block(-4,13,6,CONCRETE)
Block(-4,13,7,CONCRETE)
Block(-4,13,8,CONCRETE)
Block(-4,13,9,CONCRETE)
Block(-4,14,-4,CONCRETE)
Block(-4,14,-3,CONCRETE)
Block(-4,14,-2,CONCRETE)
Block(-4,14,-1,CONCRETE)
Block(-4,14,0,CONCRETE)
Block(-4,14,1,CONCRETE)
Block(-4,14,2,CONCRETE)
Block(-4,14,3,SMOOTH_STAIRS:0)
Block(-4,14,4,LONG_GRASS)
Block(-4,14,5,AIR:0)
Block(-4,14,6,AIR:0)
Block(-4,14,7,CONCRETE)
Block(-4,15,-4,CONCRETE)
Block(-4,15,-3,CONCRETE)
Block(-4,15,-2,CONCRETE)
Block(-4,15,-1,CONCRETE)
Block(-4,15,0,CONCRETE)
Block(-4,15,1,CONCRETE)
Block(-4,15,2,SMOOTH_STAIRS:0)
Block(-4,15,3,AIR:0)
Block(-4,15,4,AIR:0)
Block(-4,15,5,AIR:0)
Block(-4,15,6,AIR:0)
Block(-4,15,7,CONCRETE)
Block(-4,16,-4,CONCRETE)
Block(-4,16,-3,CONCRETE)
Block(-4,16,-2,CONCRETE)
Block(-4,16,-1,CONCRETE)
Block(-4,16,0,CONCRETE)
Block(-4,16,1,SMOOTH_STAIRS:0)
Block(-4,16,2,AIR:0)
Block(-4,16,3,AIR:0)
Block(-4,16,4,AIR:0)
Block(-4,16,5,AIR:0)
Block(-4,16,6,AIR:0)
Block(-4,16,7,CONCRETE)
Block(-4,17,-4,CONCRETE)
Block(-4,17,-3,CONCRETE)
Block(-4,17,-2,CONCRETE)
Block(-4,17,-1,CONCRETE)
Block(-4,17,0,AIR:0)
Block(-4,17,1,AIR:0)
Block(-4,17,2,AIR:0)
Block(-4,17,3,AIR:0)
Block(-4,17,4,AIR:0)
Block(-4,17,5,AIR:0)
Block(-4,17,6,WEB:0)
Block(-4,17,7,CONCRETE)
Block(-4,18,-4,CONCRETE)
Block(-4,18,-3,CONCRETE)
Block(-4,18,-2,CONCRETE)
Block(-4,18,-1,CONCRETE)
Block(-4,18,0,AIR:0)
Block(-4,18,1,AIR:0)
Block(-4,18,2,AIR:0)
Block(-4,18,3,AIR:0)
Block(-4,18,4,AIR:0)
Block(-4,18,5,AIR:0)
Block(-4,18,6,GLOWSTONE)
Block(-4,18,7,CONCRETE)
Block(-4,19,-4,CONCRETE)
Block(-4,19,-3,CONCRETE)
Block(-4,19,-2,CONCRETE)
Block(-4,19,-1,CONCRETE)
Block(-4,19,0,CONCRETE)
Block(-4,19,1,CONCRETE)
Block(-4,19,2,CONCRETE)
Block(-4,19,3,CONCRETE)
Block(-4,19,4,CONCRETE)
Block(-4,19,5,CONCRETE)
Block(-4,19,6,CONCRETE)
Block(-4,19,7,CONCRETE)
Block(-4,20,-4,CONCRETE)
Block(-4,20,-3,CONCRETE)
Block(-4,20,-2,CONCRETE)
Block(-4,20,-1,CONCRETE)
Block(-4,20,0,CONCRETE)
Block(-4,20,1,CONCRETE)
Block(-4,20,2,SMOOTH_STAIRS:0)
Block(-4,20,3,LONG_GRASS)
Block(-4,20,4,STONE)
Block(-4,20,5,AIR:0)
Block(-4,20,6,STONE)
Block(-4,20,7,CONCRETE)
Block(-4,21,-4,CONCRETE)
Block(-4,21,-3,CONCRETE)
Block(-4,21,-2,CONCRETE)
Block(-4,21,-1,CONCRETE)
Block(-4,21,0,CONCRETE)
Block(-4,21,1,SMOOTH_STAIRS:0)
Block(-4,21,2,AIR:0)
Block(-4,21,3,AIR:0)
Block(-4,21,4,AIR:0)
Block(-4,21,5,AIR:0)
Block(-4,21,6,AIR:0)
Block(-4,21,7,CONCRETE)
Block(-4,22,-4,CONCRETE)
Block(-4,22,-3,CONCRETE)
Block(-4,22,-2,CONCRETE)
Block(-4,22,-1,CONCRETE)
Block(-4,22,0,SMOOTH_STAIRS:0)
Block(-4,22,1,AIR:0)
Block(-4,22,2,AIR:0)
Block(-4,22,3,AIR:0)
Block(-4,22,4,AIR:0)
Block(-4,22,5,AIR:0)
Block(-4,22,6,AIR:0)
Block(-4,22,7,CONCRETE)
Block(-4,23,-4,CONCRETE)
Block(-4,23,-3,CONCRETE)
Block(-4,23,-2,CONCRETE)
Block(-4,23,-1,AIR:0)
Block(-4,23,0,AIR:0)
Block(-4,23,1,AIR:0)
Block(-4,23,2,AIR:0)
Block(-4,23,3,AIR:0)
Block(-4,23,4,AIR:0)
Block(-4,23,5,AIR:0)
Block(-4,23,6,AIR:0)
Block(-4,23,7,CONCRETE)
Block(-4,24,-4,CONCRETE)
Block(-4,24,-3,CONCRETE)
Block(-4,24,-2,CONCRETE)
Block(-4,24,-1,AIR:0)
Block(-4,24,0,AIR:0)
Block(-4,24,1,AIR:0)
Block(-4,24,2,AIR:0)
Block(-4,24,3,AIR:0)
Block(-4,24,4,AIR:0)
Block(-4,24,5,AIR:0)
Block(-4,24,6,WEB:0)
Block(-4,24,7,CONCRETE)
Block(-4,25,-4,CONCRETE)
Block(-4,25,-3,CONCRETE)
Block(-4,25,-2,CONCRETE)
Block(-4,25,-1,CONCRETE)
Block(-4,25,0,CONCRETE)
Block(-4,25,1,CONCRETE)
Block(-4,25,2,CONCRETE)
Block(-4,25,3,CONCRETE)
Block(-4,25,4,CONCRETE)
Block(-4,25,5,CONCRETE)
Block(-4,25,6,CONCRETE)
Block(-4,25,7,CONCRETE)
Block(-4,25,8,CONCRETE)
Block(-4,25,9,CONCRETE)
Block(-4,26,-4,CONCRETE)
Block(-4,26,-3,WEB:0)
Block(-4,26,-2,LONG_GRASS)
Block(-4,26,-1,CONCRETE)
Block(-4,26,0,CONCRETE)
Block(-4,26,1,CONCRETE)
Block(-4,26,2,CONCRETE)
Block(-4,26,3,SMOOTH_STAIRS:0)
Block(-4,26,4,SMOOTH_BRICK)
Block(-4,26,5,CONCRETE)
Block(-4,26,6,CONCRETE)
Block(-4,26,7,CONCRETE)
Block(-4,26,8,AIR:0)
Block(-4,26,9,CONCRETE)
Block(-4,27,-4,CONCRETE)
Block(-4,27,-3,AIR:0)
Block(-4,27,-2,AIR:0)
Block(-4,27,-1,CONCRETE)
Block(-4,27,0,CONCRETE)
Block(-4,27,1,CONCRETE)
Block(-4,27,2,SMOOTH_STAIRS:0)
Block(-4,27,3,AIR:0)
Block(-4,27,4,AIR:0)
Block(-4,27,5,CONCRETE)
Block(-4,27,6,OBSERVER:4)
Block(-4,27,7,CONCRETE)
Block(-4,27,8,AIR:0)
Block(-4,27,9,CONCRETE)
Block(-4,28,-4,CONCRETE)
Block(-4,28,-3,AIR:0)
Block(-4,28,-2,AIR:0)
Block(-4,28,-1,CONCRETE)
Block(-4,28,0,CONCRETE)
Block(-4,28,1,SMOOTH_STAIRS:0)
Block(-4,28,2,AIR:0)
Block(-4,28,3,AIR:0)
Block(-4,28,4,AIR:0)
Block(-4,28,5,CONCRETE)
Block(-4,28,6,CONCRETE)
Block(-4,28,7,CONCRETE)
Block(-4,28,8,CONCRETE)
Block(-4,28,9,CONCRETE)
Block(-4,29,-4,CONCRETE)
Block(-4,29,-3,AIR:0)
Block(-4,29,-2,AIR:0)
Block(-4,29,-1,CONCRETE)
Block(-4,29,0,LONG_GRASS)
Block(-4,29,1,AIR:0)
Block(-4,29,2,AIR:0)
Block(-4,29,3,AIR:0)
Block(-4,29,4,AIR:0)
Block(-4,29,5,CONCRETE)
Block(-4,29,6,CONCRETE)
Block(-4,29,7,CONCRETE)
Block(-4,30,-4,CONCRETE)
Block(-4,30,-3,AIR:0)
Block(-4,30,-2,AIR:0)
Block(-4,30,-1,CONCRETE)
Block(-4,30,0,AIR:0)
Block(-4,30,1,AIR:0)
Block(-4,30,2,AIR:0)
Block(-4,30,3,AIR:0)
Block(-4,30,4,WEB:0)
Block(-4,30,5,CONCRETE)
Block(-4,30,6,CONCRETE)
Block(-4,30,7,CONCRETE)
Block(-4,31,-4,CONCRETE)
Block(-4,31,-3,CONCRETE)
Block(-4,31,-2,CONCRETE)
Block(-4,31,-1,CONCRETE)
Block(-4,31,0,CONCRETE)
Block(-4,31,1,CONCRETE)
Block(-4,31,2,CONCRETE)
Block(-4,31,3,CONCRETE)
Block(-4,31,4,CONCRETE)
Block(-4,31,5,CONCRETE)
Block(-4,31,6,CONCRETE)
Block(-4,31,7,CONCRETE)
Block(-4,32,-4,CONCRETE)
Block(-4,32,-3,CONCRETE)
Block(-4,32,-2,CONCRETE)
Block(-4,32,-1,CONCRETE)
Block(-4,32,0,CONCRETE)
Block(-4,32,1,CONCRETE)
Block(-4,32,2,SMOOTH_STAIRS:0)
Block(-4,32,3,AIR:0)
Block(-4,32,4,SMOOTH_BRICK)
Block(-4,32,5,LONG_GRASS)
Block(-4,32,6,SMOOTH_BRICK)
Block(-4,32,7,CONCRETE)
Block(-4,33,-4,CONCRETE)
Block(-4,33,-3,CONCRETE)
Block(-4,33,-2,CONCRETE)
Block(-4,33,-1,CONCRETE)
Block(-4,33,0,CONCRETE)
Block(-4,33,1,SMOOTH_STAIRS:0)
Block(-4,33,2,AIR:0)
Block(-4,33,3,AIR:0)
Block(-4,33,4,AIR:0)
Block(-4,33,5,AIR:0)
Block(-4,33,6,AIR:0)
Block(-4,33,7,CONCRETE)
Block(-4,34,-4,CONCRETE)
Block(-4,34,-3,CONCRETE)
Block(-4,34,-2,CONCRETE)
Block(-4,34,-1,CONCRETE)
Block(-4,34,0,SMOOTH_STAIRS:0)
Block(-4,34,1,AIR:0)
Block(-4,34,2,AIR:0)
Block(-4,34,3,AIR:0)
Block(-4,34,4,AIR:0)
Block(-4,34,5,AIR:0)
Block(-4,34,6,AIR:0)
Block(-4,34,7,CONCRETE)
Block(-4,35,-4,CONCRETE)
Block(-4,35,-3,CONCRETE)
Block(-4,35,-2,CONCRETE)
Block(-4,35,-1,SMOOTH_BRICK)
Block(-4,35,0,AIR:0)
Block(-4,35,1,AIR:0)
Block(-4,35,2,AIR:0)
Block(-4,35,3,AIR:0)
Block(-4,35,4,AIR:0)
Block(-4,35,5,AIR:0)
Block(-4,35,6,WEB:0)
Block(-4,35,7,CONCRETE)
Block(-4,36,-4,CONCRETE)
Block(-4,36,-3,CONCRETE)
Block(-4,36,-2,CONCRETE)
Block(-4,36,-1,AIR:0)
Block(-4,36,0,AIR:0)
Block(-4,36,1,AIR:0)
Block(-4,36,2,AIR:0)
Block(-4,36,3,AIR:0)
Block(-4,36,4,AIR:0)
Block(-4,36,5,AIR:0)
Block(-4,36,6,WEB:0)
Block(-4,36,7,CONCRETE)
Block(-4,37,-6,CONCRETE)
Block(-4,37,-5,CONCRETE)
Block(-4,37,-4,CONCRETE)
Block(-4,37,-3,CONCRETE)
Block(-4,37,-2,CONCRETE)
Block(-4,37,-1,CONCRETE)
Block(-4,37,0,CONCRETE)
Block(-4,37,1,CONCRETE)
Block(-4,37,2,CONCRETE)
Block(-4,37,3,CONCRETE)
Block(-4,37,4,CONCRETE)
Block(-4,37,5,CONCRETE)
Block(-4,37,6,CONCRETE)
Block(-4,37,7,CONCRETE)
Block(-4,38,-6,CONCRETE)
Block(-4,38,-5,CONCRETE)
Block(-4,38,-4,CONCRETE)
Block(-4,38,-3,CONCRETE)
Block(-4,38,-2,CONCRETE)
Block(-4,38,-1,CONCRETE)
Block(-4,38,0,CONCRETE)
Block(-4,38,1,CONCRETE)
Block(-4,38,2,CONCRETE)
Block(-4,38,3,SMOOTH_STAIRS:0)
Block(-4,38,4,STONE)
Block(-4,38,5,SMOOTH_BRICK)
Block(-4,38,6,STONE)
Block(-4,38,7,CONCRETE)
Block(-4,39,-6,CONCRETE)
Block(-4,39,-5,CONCRETE)
Block(-4,39,-4,CONCRETE)
Block(-4,39,-3,CONCRETE)
Block(-4,39,-2,CONCRETE)
Block(-4,39,-1,CONCRETE)
Block(-4,39,0,CONCRETE)
Block(-4,39,1,CONCRETE)
Block(-4,39,2,SMOOTH_STAIRS:0)
Block(-4,39,3,AIR:0)
Block(-4,39,4,AIR:0)
Block(-4,39,5,AIR:0)
Block(-4,39,6,AIR:0)
Block(-4,39,7,CONCRETE)
Block(-4,40,-6,CONCRETE)
Block(-4,40,-5,CONCRETE)
Block(-4,40,-4,CONCRETE)
Block(-4,40,-3,CONCRETE)
Block(-4,40,-2,CONCRETE)
Block(-4,40,-1,CONCRETE)
Block(-4,40,0,CONCRETE)
Block(-4,40,1,SMOOTH_STAIRS:0)
Block(-4,40,2,AIR:0)
Block(-4,40,3,AIR:0)
Block(-4,40,4,AIR:0)
Block(-4,40,5,AIR:0)
Block(-4,40,6,AIR:0)
Block(-4,40,7,CONCRETE)
Block(-4,41,-6,CONCRETE)
Block(-4,41,-5,CONCRETE)
Block(-4,41,-4,CONCRETE)
Block(-4,41,-3,CONCRETE)
Block(-4,41,-2,CONCRETE)
Block(-4,41,-1,CONCRETE)
Block(-4,41,0,AIR:0)
Block(-4,41,1,AIR:0)
Block(-4,41,2,AIR:0)
Block(-4,41,3,AIR:0)
Block(-4,41,4,AIR:0)
Block(-4,41,5,AIR:0)
Block(-4,41,6,WEB:0)
Block(-4,41,7,CONCRETE)
Block(-4,42,-6,CONCRETE)
Block(-4,42,-5,CONCRETE)
Block(-4,42,-4,CONCRETE)
Block(-4,42,-3,CONCRETE)
Block(-4,42,-2,CONCRETE)
Block(-4,42,-1,CONCRETE)
Block(-4,42,0,AIR:0)
Block(-4,42,1,AIR:0)
Block(-4,42,2,AIR:0)
Block(-4,42,3,AIR:0)
Block(-4,42,4,AIR:0)
Block(-4,42,5,AIR:0)
Block(-4,42,6,GLOWSTONE)
Block(-4,42,7,CONCRETE)
Block(-4,43,-6,CONCRETE)
Block(-4,43,-5,CONCRETE)
Block(-4,43,-4,CONCRETE)
Block(-4,43,-3,CONCRETE)
Block(-4,43,-2,CONCRETE)
Block(-4,43,-1,CONCRETE)
Block(-4,43,0,CONCRETE)
Block(-4,43,1,CONCRETE)
Block(-4,43,2,CONCRETE)
Block(-4,43,3,CONCRETE)
Block(-4,43,4,CONCRETE)
Block(-4,43,5,CONCRETE)
Block(-4,43,6,CONCRETE)
Block(-4,43,7,CONCRETE)
Block(-4,44,-5,CONCRETE)
Block(-4,44,-4,STAINED_GLASS_PANE:0)
Block(-4,44,-3,STONE)
Block(-4,44,-2,AIR:0)
Block(-4,44,-1,CONCRETE)
Block(-4,44,0,CONCRETE)
Block(-4,44,1,CONCRETE)
Block(-4,44,2,CONCRETE)
Block(-4,44,3,SMOOTH_STAIRS:0)
Block(-4,44,4,LONG_GRASS)
Block(-4,44,5,LONG_GRASS:0)
Block(-4,44,6,SMOOTH_BRICK)
Block(-4,44,7,CONCRETE)
Block(-4,45,-5,CONCRETE)
Block(-4,45,-4,STAINED_GLASS_PANE:0)
Block(-4,45,-3,AIR:0)
Block(-4,45,-2,AIR:0)
Block(-4,45,-1,CONCRETE)
Block(-4,45,0,CONCRETE)
Block(-4,45,1,CONCRETE)
Block(-4,45,2,SMOOTH_STAIRS:0)
Block(-4,45,3,AIR:0)
Block(-4,45,4,AIR:0)
Block(-4,45,5,AIR:0)
Block(-4,45,6,AIR:0)
Block(-4,45,7,CONCRETE)
Block(-4,46,-5,CONCRETE)
Block(-4,46,-4,STAINED_GLASS_PANE:0)
Block(-4,46,-3,AIR:0)
Block(-4,46,-2,AIR:0)
Block(-4,46,-1,CONCRETE)
Block(-4,46,0,CONCRETE)
Block(-4,46,1,SMOOTH_STAIRS:0)
Block(-4,46,2,AIR:0)
Block(-4,46,3,AIR:0)
Block(-4,46,4,AIR:0)
Block(-4,46,5,AIR:0)
Block(-4,46,6,AIR:0)
Block(-4,46,7,CONCRETE)
Block(-4,47,-5,CONCRETE)
Block(-4,47,-4,STAINED_GLASS_PANE:0)
Block(-4,47,-3,AIR:0)
Block(-4,47,-2,AIR:0)
Block(-4,47,-1,CONCRETE)
Block(-4,47,0,LONG_GRASS)
Block(-4,47,1,AIR:0)
Block(-4,47,2,AIR:0)
Block(-4,47,3,AIR:0)
Block(-4,47,4,AIR:0)
Block(-4,47,5,AIR:0)
Block(-4,47,6,WEB:0)
Block(-4,47,7,CONCRETE)
Block(-4,48,-5,CONCRETE)
Block(-4,48,-4,CONCRETE)
Block(-4,48,-3,CONCRETE)
Block(-4,48,-2,CONCRETE)
Block(-4,48,-1,CONCRETE)
Block(-4,48,0,AIR:0)
Block(-4,48,1,AIR:0)
Block(-4,48,2,AIR:0)
Block(-4,48,3,AIR:0)
Block(-4,48,4,AIR:0)
Block(-4,48,5,AIR:0)
Block(-4,48,6,WEB:0)
Block(-4,48,7,CONCRETE)
Block(-4,49,-4,CONCRETE)
Block(-4,49,-3,CONCRETE)
Block(-4,49,-2,CONCRETE)
Block(-4,49,-1,CONCRETE)
Block(-4,49,0,CONCRETE)
Block(-4,49,1,CONCRETE)
Block(-4,49,2,CONCRETE)
Block(-4,49,3,CONCRETE)
Block(-4,49,4,CONCRETE)
Block(-4,49,5,CONCRETE)
Block(-4,49,6,CONCRETE)
Block(-4,49,7,CONCRETE)
Block(-4,50,-4,CONCRETE)
Block(-4,50,-3,quark:basalt_speleothem:2)
Block(-4,50,-2,STONE)
Block(-4,50,-1,CONCRETE)
Block(-4,50,0,CONCRETE)
Block(-4,50,1,CONCRETE)
Block(-4,50,2,CONCRETE)
Block(-4,50,3,SMOOTH_STAIRS:0)
Block(-4,50,4,STONE)
Block(-4,50,5,AIR:0)
Block(-4,50,6,AIR:0)
Block(-4,50,7,CONCRETE)
Block(-4,51,-4,CONCRETE)
Block(-4,51,-3,IRON_BLOCK)
Block(-4,51,-2,STONE)
Block(-4,51,-1,CONCRETE)
Block(-4,51,0,CONCRETE)
Block(-4,51,1,CONCRETE)
Block(-4,51,2,SMOOTH_STAIRS:0)
Block(-4,51,3,AIR:0)
Block(-4,51,4,AIR:0)
Block(-4,51,5,AIR:0)
Block(-4,51,6,AIR:0)
Block(-4,51,7,CONCRETE)
Block(-4,52,-4,CONCRETE)
Block(-4,52,-3,IRON_BLOCK)
Block(-4,52,-2,STONE)
Block(-4,52,-1,CONCRETE)
Block(-4,52,0,CONCRETE)
Block(-4,52,1,SMOOTH_STAIRS:0)
Block(-4,52,2,AIR:0)
Block(-4,52,3,AIR:0)
Block(-4,52,4,AIR:0)
Block(-4,52,5,AIR:0)
Block(-4,52,6,AIR:0)
Block(-4,52,7,CONCRETE)
Block(-4,53,-4,CONCRETE)
Block(-4,53,-3,quark:basalt_speleothem:2)
Block(-4,53,-2,STONE)
Block(-4,53,-1,CONCRETE)
Block(-4,53,0,AIR:0)
Block(-4,53,1,AIR:0)
Block(-4,53,2,AIR:0)
Block(-4,53,3,AIR:0)
Block(-4,53,4,AIR:0)
Block(-4,53,5,AIR:0)
Block(-4,53,6,AIR:0)
Block(-4,53,7,CONCRETE)
Block(-4,54,-4,CONCRETE)
Block(-4,54,-3,CONCRETE)
Block(-4,54,-2,CONCRETE)
Block(-4,54,-1,CONCRETE)
Block(-4,54,0,AIR:0)
Block(-4,54,1,AIR:0)
Block(-4,54,2,AIR:0)
Block(-4,54,3,AIR:0)
Block(-4,54,4,AIR:0)
Block(-4,54,5,AIR:0)
Block(-4,54,6,WEB:0)
Block(-4,54,7,CONCRETE)
Block(-4,55,-6,CONCRETE)
Block(-4,55,-5,CONCRETE)
Block(-4,55,-4,CONCRETE)
Block(-4,55,-3,CONCRETE)
Block(-4,55,-2,CONCRETE)
Block(-4,55,-1,CONCRETE)
Block(-4,55,0,CONCRETE)
Block(-4,55,1,CONCRETE)
Block(-4,55,2,CONCRETE)
Block(-4,55,3,CONCRETE)
Block(-4,55,4,CONCRETE)
Block(-4,55,5,CONCRETE)
Block(-4,55,6,CONCRETE)
Block(-4,55,7,CONCRETE)
Block(-4,55,8,CONCRETE)
Block(-4,55,9,CONCRETE)
Block(-4,56,-6,CONCRETE)
Block(-4,56,-5,AIR:0)
Block(-4,56,-4,CONCRETE)
Block(-4,56,-3,STONE)
Block(-4,56,-2,AIR:0)
Block(-4,56,-1,IRON_DOOR_BLOCK:1)
Block(-4,56,0,STONE)
Block(-4,56,1,AIR:0)
Block(-4,56,2,AIR:0)
Block(-4,56,3,STONE)
Block(-4,56,4,IRON_DOOR_BLOCK)
Block(-4,56,5,AIR:0)
Block(-4,56,6,AIR:0)
Block(-4,56,7,CONCRETE)
Block(-4,56,8,AIR:0)
Block(-4,56,9,CONCRETE)
Block(-4,57,-6,CONCRETE)
Block(-4,57,-5,AIR:0)
Block(-4,57,-4,CONCRETE)
Block(-4,57,-3,AIR:0)
Block(-4,57,-2,AIR:0)
Block(-4,57,-1,IRON_DOOR_BLOCK:9)
Block(-4,57,0,AIR:0)
Block(-4,57,1,AIR:0)
Block(-4,57,2,AIR:0)
Block(-4,57,3,AIR:0)
Block(-4,57,4,IRON_DOOR_BLOCK:9)
Block(-4,57,5,AIR:0)
Block(-4,57,6,AIR:0)
Block(-4,57,7,CONCRETE)
Block(-4,57,8,AIR:0)
Block(-4,57,9,CONCRETE)
Block(-4,58,-6,CONCRETE)
Block(-4,58,-5,CONCRETE)
Block(-4,58,-4,CONCRETE)
Block(-4,58,-3,AIR:0)
Block(-4,58,-2,quark:iron_button)
Block(-4,58,-1,CONCRETE)
Block(-4,58,0,quark:iron_button:3)
Block(-4,58,1,AIR:0)
Block(-4,58,2,AIR:0)
Block(-4,58,3,quark:iron_button)
Block(-4,58,4,CONCRETE)
Block(-4,58,5,quark:iron_button:3)
Block(-4,58,6,AIR:0)
Block(-4,58,7,CONCRETE)
Block(-4,58,8,CONCRETE)
Block(-4,58,9,CONCRETE)
Block(-4,59,-4,CONCRETE)
Block(-4,59,-3,CONCRETE)
Block(-4,59,-2,CONCRETE)
Block(-4,59,-1,CONCRETE)
Block(-4,59,0,CONCRETE)
Block(-4,59,1,CONCRETE)
Block(-4,59,2,CONCRETE)
Block(-4,59,3,CONCRETE)
Block(-4,59,4,CONCRETE)
Block(-4,59,5,CONCRETE)
Block(-4,59,6,CONCRETE)
Block(-4,59,7,CONCRETE)
Block(-4,60,-4,CONCRETE)
Block(-4,60,-3,SMOOTH_BRICK:1)
Block(-4,60,-2,SMOOTH_BRICK:1)
Block(-4,60,-1,SMOOTH_BRICK:1)
Block(-4,60,0,SMOOTH_BRICK:1)
Block(-4,60,1,CONCRETE)
Block(-4,60,2,CONCRETE)
Block(-4,60,3,SMOOTH_BRICK:1)
Block(-4,60,4,SMOOTH_BRICK:1)
Block(-4,60,5,SMOOTH_BRICK:1)
Block(-4,60,6,SMOOTH_BRICK:1)
Block(-4,60,7,CONCRETE)
Block(-4,61,-3,CONCRETE)
Block(-4,61,-2,CONCRETE)
Block(-4,61,-1,CONCRETE)
Block(-4,61,0,CONCRETE)
Block(-4,61,1,CONCRETE)
Block(-4,61,2,CONCRETE)
Block(-4,61,3,CONCRETE)
Block(-4,61,4,CONCRETE)
Block(-4,61,5,CONCRETE)
Block(-4,61,6,SMOOTH_STAIRS:0)
Block(-4,62,-1,IRON_BLOCK)
Block(-4,62,0,CONCRETE)
Block(-4,62,1,SMOOTH_STAIRS:0)
Block(-4,62,2,CONCRETE)
Block(-4,62,3,CONCRETE)
Block(-4,62,4,IRON_BLOCK)
Block(-3,0,-5,CONCRETE)
Block(-3,0,-4,CONCRETE)
Block(-3,0,-3,CONCRETE)
Block(-3,0,-2,CONCRETE)
Block(-3,0,-1,CONCRETE)
Block(-3,0,0,CONCRETE)
Block(-3,0,1,CONCRETE)
Block(-3,0,2,CONCRETE)
Block(-3,0,3,CONCRETE)
Block(-3,0,4,CONCRETE)
Block(-3,0,5,CONCRETE)
Block(-3,0,6,CONCRETE)
Block(-3,0,7,CONCRETE)
Block(-3,0,8,CONCRETE)
Block(-3,1,-5,CONCRETE)
Block(-3,1,-4,CONCRETE)
Block(-3,1,-3,CONCRETE)
Block(-3,1,-2,CONCRETE)
Block(-3,1,-1,CONCRETE)
Block(-3,1,0,CONCRETE)
Block(-3,1,1,CONCRETE)
Block(-3,1,2,CONCRETE)
Block(-3,1,3,CONCRETE)
Block(-3,1,4,CONCRETE)
Block(-3,1,5,CONCRETE)
Block(-3,1,6,CONCRETE)
Block(-3,1,7,CONCRETE)
Block(-3,1,8,CONCRETE)
Block(-3,2,-5,CONCRETE)
Block(-3,2,-4,CONCRETE)
Block(-3,2,-3,CONCRETE)
Block(-3,2,-2,CONCRETE)
Block(-3,2,-1,CONCRETE)
Block(-3,2,0,CONCRETE)
Block(-3,2,1,CONCRETE)
Block(-3,2,2,CONCRETE)
Block(-3,2,3,CONCRETE)
Block(-3,2,4,CONCRETE)
Block(-3,2,5,CONCRETE)
Block(-3,2,6,CONCRETE)
Block(-3,2,7,CONCRETE)
Block(-3,2,8,CONCRETE)
Block(-3,3,-5,CONCRETE)
Block(-3,3,-4,CONCRETE)
Block(-3,3,-3,CONCRETE)
Block(-3,3,-2,CONCRETE)
Block(-3,3,-1,CONCRETE)
Block(-3,3,0,CONCRETE)
Block(-3,3,1,CONCRETE)
Block(-3,3,2,CONCRETE)
Block(-3,3,3,CONCRETE)
Block(-3,3,4,CONCRETE)
Block(-3,3,5,CONCRETE)
Block(-3,3,6,CONCRETE)
Block(-3,3,7,CONCRETE)
Block(-3,3,8,CONCRETE)
Block(-3,4,-5,CONCRETE)
Block(-3,4,-4,CONCRETE)
Block(-3,4,-3,CONCRETE)
Block(-3,4,-2,CONCRETE)
Block(-3,4,-1,CONCRETE)
Block(-3,4,0,CONCRETE)
Block(-3,4,1,CONCRETE)
Block(-3,4,2,CONCRETE)
Block(-3,4,3,CONCRETE)
Block(-3,4,4,CONCRETE)
Block(-3,4,5,CONCRETE)
Block(-3,4,6,CONCRETE)
Block(-3,4,7,CONCRETE)
Block(-3,4,8,CONCRETE)
Block(-3,5,-5,CONCRETE)
Block(-3,5,-4,CONCRETE)
Block(-3,5,-3,CONCRETE)
Block(-3,5,-2,CONCRETE)
Block(-3,5,-1,CONCRETE)
Block(-3,5,0,CONCRETE)
Block(-3,5,1,CONCRETE)
Block(-3,5,2,CONCRETE)
Block(-3,5,3,CONCRETE)
Block(-3,5,4,CONCRETE)
Block(-3,5,5,CONCRETE)
Block(-3,5,6,CONCRETE)
Block(-3,5,7,CONCRETE)
Block(-3,5,8,CONCRETE)
Block(-3,6,-5,CONCRETE)
Block(-3,6,-4,CONCRETE)
Block(-3,6,-3,CONCRETE)
Block(-3,6,-2,CONCRETE)
Block(-3,6,-1,CONCRETE)
Block(-3,6,0,CONCRETE)
Block(-3,6,1,CONCRETE)
Block(-3,6,2,CONCRETE)
Block(-3,6,3,CONCRETE)
Block(-3,6,4,CONCRETE)
Block(-3,6,5,CONCRETE)
Block(-3,6,6,CONCRETE)
Block(-3,6,7,CONCRETE)
Block(-3,6,8,CONCRETE)
Block(-3,7,-5,CONCRETE)
Block(-3,7,-4,CONCRETE)
Block(-3,7,-3,CONCRETE)
Block(-3,7,-2,CONCRETE)
Block(-3,7,-1,CONCRETE)
Block(-3,7,0,CONCRETE)
Block(-3,7,1,CONCRETE)
Block(-3,7,2,CONCRETE)
Block(-3,7,3,CONCRETE)
Block(-3,7,4,CONCRETE)
Block(-3,7,5,CONCRETE)
Block(-3,7,6,CONCRETE)
Block(-3,7,7,CONCRETE)
Block(-3,7,8,CONCRETE)
Block(-3,7,9,CONCRETE)
Block(-3,8,-5,CONCRETE)
Block(-3,8,-4,CONCRETE)
Block(-3,8,-3,CONCRETE)
Block(-3,8,-2,CONCRETE)
Block(-3,8,-1,CONCRETE)
Block(-3,8,0,CONCRETE)
Block(-3,8,1,CONCRETE)
Block(-3,8,2,CONCRETE)
Block(-3,8,3,CONCRETE)
Block(-3,8,4,AIR:0)
Block(-3,8,5,AIR:0)
Block(-3,8,6,LONG_GRASS)
Block(-3,8,7,SMOOTH_BRICK)
Block(-3,8,8,AIR:0)
Block(-3,8,9,CONCRETE)
Block(-3,9,-5,CONCRETE)
Block(-3,9,-4,CONCRETE)
Block(-3,9,-3,CONCRETE)
Block(-3,9,-2,CONCRETE)
Block(-3,9,-1,CONCRETE)
Block(-3,9,0,CONCRETE)
Block(-3,9,1,CONCRETE)
Block(-3,9,2,CONCRETE)
Block(-3,9,3,CONCRETE)
Block(-3,9,4,AIR:0)
Block(-3,9,5,AIR:0)
Block(-3,9,6,AIR:0)
Block(-3,9,7,AIR:0)
Block(-3,9,8,AIR:0)
Block(-3,9,9,CONCRETE)
Block(-3,10,-5,CONCRETE)
Block(-3,10,-4,CONCRETE)
Block(-3,10,-3,CONCRETE)
Block(-3,10,-2,CONCRETE)
Block(-3,10,-1,CONCRETE)
Block(-3,10,0,CONCRETE)
Block(-3,10,1,CONCRETE)
Block(-3,10,2,CONCRETE)
Block(-3,10,3,CONCRETE)
Block(-3,10,4,AIR:0)
Block(-3,10,5,AIR:0)
Block(-3,10,6,AIR:0)
Block(-3,10,7,AIR:0)
Block(-3,10,8,AIR:0)
Block(-3,10,9,CONCRETE)
Block(-3,11,-5,CONCRETE)
Block(-3,11,-4,CONCRETE)
Block(-3,11,-3,CONCRETE)
Block(-3,11,-2,CONCRETE)
Block(-3,11,-1,CONCRETE)
Block(-3,11,0,CONCRETE)
Block(-3,11,1,CONCRETE)
Block(-3,11,2,CONCRETE)
Block(-3,11,3,CONCRETE)
Block(-3,11,4,AIR:0)
Block(-3,11,5,AIR:0)
Block(-3,11,6,AIR:0)
Block(-3,11,7,AIR:0)
Block(-3,11,8,AIR:0)
Block(-3,11,9,CONCRETE)
Block(-3,12,-5,CONCRETE)
Block(-3,12,-4,CONCRETE)
Block(-3,12,-3,CONCRETE)
Block(-3,12,-2,CONCRETE)
Block(-3,12,-1,CONCRETE)
Block(-3,12,0,CONCRETE)
Block(-3,12,1,CONCRETE)
Block(-3,12,2,CONCRETE)
Block(-3,12,3,CONCRETE)
Block(-3,12,4,AIR:0)
Block(-3,12,5,AIR:0)
Block(-3,12,6,AIR:0)
Block(-3,12,7,AIR:0)
Block(-3,12,8,AIR:0)
Block(-3,12,9,CONCRETE)
Block(-3,13,-5,CONCRETE)
Block(-3,13,-4,CONCRETE)
Block(-3,13,-3,CONCRETE)
Block(-3,13,-2,CONCRETE)
Block(-3,13,-1,CONCRETE)
Block(-3,13,0,CONCRETE)
Block(-3,13,1,CONCRETE)
Block(-3,13,2,CONCRETE)
Block(-3,13,3,CONCRETE)
Block(-3,13,4,CONCRETE)
Block(-3,13,5,CONCRETE)
Block(-3,13,6,CONCRETE)
Block(-3,13,7,CONCRETE)
Block(-3,13,8,CONCRETE)
Block(-3,13,9,CONCRETE)
Block(-3,14,-5,CONCRETE)
Block(-3,14,-4,CONCRETE)
Block(-3,14,-3,CONCRETE)
Block(-3,14,-2,CONCRETE)
Block(-3,14,-1,CONCRETE)
Block(-3,14,0,CONCRETE)
Block(-3,14,1,CONCRETE)
Block(-3,14,2,CONCRETE)
Block(-3,14,3,CONCRETE)
Block(-3,14,4,CONCRETE)
Block(-3,14,5,CONCRETE)
Block(-3,14,6,LONG_GRASS)
Block(-3,14,7,CONCRETE)
Block(-3,14,8,CONCRETE)
Block(-3,15,-5,CONCRETE)
Block(-3,15,-4,CONCRETE)
Block(-3,15,-3,CONCRETE)
Block(-3,15,-2,CONCRETE)
Block(-3,15,-1,CONCRETE)
Block(-3,15,0,CONCRETE)
Block(-3,15,1,CONCRETE)
Block(-3,15,2,CONCRETE)
Block(-3,15,3,CONCRETE)
Block(-3,15,4,CONCRETE)
Block(-3,15,5,CONCRETE)
Block(-3,15,6,AIR:0)
Block(-3,15,7,CONCRETE)
Block(-3,15,8,CONCRETE)
Block(-3,16,-5,CONCRETE)
Block(-3,16,-4,CONCRETE)
Block(-3,16,-3,CONCRETE)
Block(-3,16,-2,CONCRETE)
Block(-3,16,-1,CONCRETE)
Block(-3,16,0,CONCRETE)
Block(-3,16,1,CONCRETE)
Block(-3,16,2,CONCRETE)
Block(-3,16,3,CONCRETE)
Block(-3,16,4,CONCRETE)
Block(-3,16,5,CONCRETE)
Block(-3,16,6,CONCRETE)
Block(-3,16,7,CONCRETE)
Block(-3,16,8,CONCRETE)
Block(-3,17,-5,CONCRETE)
Block(-3,17,-4,CONCRETE)
Block(-3,17,-3,CONCRETE)
Block(-3,17,-2,CONCRETE)
Block(-3,17,-1,CONCRETE)
Block(-3,17,0,CONCRETE)
Block(-3,17,1,CONCRETE)
Block(-3,17,2,CONCRETE)
Block(-3,17,3,CONCRETE)
Block(-3,17,4,CONCRETE)
Block(-3,17,5,CONCRETE)
Block(-3,17,6,CONCRETE)
Block(-3,17,7,CONCRETE)
Block(-3,17,8,CONCRETE)
Block(-3,18,-5,CONCRETE)
Block(-3,18,-4,CONCRETE)
Block(-3,18,-3,CONCRETE)
Block(-3,18,-2,CONCRETE)
Block(-3,18,-1,CONCRETE)
Block(-3,18,0,CONCRETE)
Block(-3,18,1,CONCRETE)
Block(-3,18,2,CONCRETE)
Block(-3,18,3,CONCRETE)
Block(-3,18,4,CONCRETE)
Block(-3,18,5,CONCRETE)
Block(-3,18,6,CONCRETE)
Block(-3,18,7,CONCRETE)
Block(-3,18,8,CONCRETE)
Block(-3,19,-5,CONCRETE)
Block(-3,19,-4,CONCRETE)
Block(-3,19,-3,CONCRETE)
Block(-3,19,-2,CONCRETE)
Block(-3,19,-1,CONCRETE)
Block(-3,19,0,CONCRETE)
Block(-3,19,1,CONCRETE)
Block(-3,19,2,CONCRETE)
Block(-3,19,3,CONCRETE)
Block(-3,19,4,CONCRETE)
Block(-3,19,5,CONCRETE)
Block(-3,19,6,CONCRETE)
Block(-3,19,7,CONCRETE)
Block(-3,19,8,CONCRETE)
Block(-3,20,-5,CONCRETE)
Block(-3,20,-4,CONCRETE)
Block(-3,20,-3,CONCRETE)
Block(-3,20,-2,CONCRETE)
Block(-3,20,-1,CONCRETE)
Block(-3,20,0,CONCRETE)
Block(-3,20,1,CONCRETE)
Block(-3,20,2,CONCRETE)
Block(-3,20,3,CONCRETE)
Block(-3,20,4,CONCRETE)
Block(-3,20,5,CONCRETE)
Block(-3,20,6,IRON_DOOR_BLOCK:6)
Block(-3,20,7,CONCRETE)
Block(-3,20,8,CONCRETE)
Block(-3,21,-5,CONCRETE)
Block(-3,21,-4,CONCRETE)
Block(-3,21,-3,CONCRETE)
Block(-3,21,-2,CONCRETE)
Block(-3,21,-1,CONCRETE)
Block(-3,21,0,CONCRETE)
Block(-3,21,1,CONCRETE)
Block(-3,21,2,CONCRETE)
Block(-3,21,3,CONCRETE)
Block(-3,21,4,CONCRETE)
Block(-3,21,5,CONCRETE)
Block(-3,21,6,IRON_DOOR_BLOCK:8)
Block(-3,21,7,CONCRETE)
Block(-3,21,8,CONCRETE)
Block(-3,22,-5,CONCRETE)
Block(-3,22,-4,CONCRETE)
Block(-3,22,-3,CONCRETE)
Block(-3,22,-2,CONCRETE)
Block(-3,22,-1,CONCRETE)
Block(-3,22,0,CONCRETE)
Block(-3,22,1,CONCRETE)
Block(-3,22,2,CONCRETE)
Block(-3,22,3,CONCRETE)
Block(-3,22,4,CONCRETE)
Block(-3,22,5,CONCRETE)
Block(-3,22,6,CONCRETE)
Block(-3,22,7,CONCRETE)
Block(-3,22,8,CONCRETE)
Block(-3,23,-5,CONCRETE)
Block(-3,23,-4,CONCRETE)
Block(-3,23,-3,CONCRETE)
Block(-3,23,-2,CONCRETE)
Block(-3,23,-1,CONCRETE)
Block(-3,23,0,CONCRETE)
Block(-3,23,1,CONCRETE)
Block(-3,23,2,CONCRETE)
Block(-3,23,3,CONCRETE)
Block(-3,23,4,CONCRETE)
Block(-3,23,5,CONCRETE)
Block(-3,23,6,CONCRETE)
Block(-3,23,7,CONCRETE)
Block(-3,23,8,CONCRETE)
Block(-3,24,-5,CONCRETE)
Block(-3,24,-4,CONCRETE)
Block(-3,24,-3,CONCRETE)
Block(-3,24,-2,CONCRETE)
Block(-3,24,-1,CONCRETE)
Block(-3,24,0,CONCRETE)
Block(-3,24,1,CONCRETE)
Block(-3,24,2,CONCRETE)
Block(-3,24,3,CONCRETE)
Block(-3,24,4,CONCRETE)
Block(-3,24,5,CONCRETE)
Block(-3,24,6,CONCRETE)
Block(-3,24,7,CONCRETE)
Block(-3,24,8,CONCRETE)
Block(-3,25,-5,CONCRETE)
Block(-3,25,-4,CONCRETE)
Block(-3,25,-3,CONCRETE)
Block(-3,25,-2,CONCRETE)
Block(-3,25,-1,CONCRETE)
Block(-3,25,0,CONCRETE)
Block(-3,25,1,CONCRETE)
Block(-3,25,2,CONCRETE)
Block(-3,25,3,CONCRETE)
Block(-3,25,4,CONCRETE)
Block(-3,25,5,CONCRETE)
Block(-3,25,6,CONCRETE)
Block(-3,25,7,CONCRETE)
Block(-3,25,8,CONCRETE)
Block(-3,25,9,CONCRETE)
Block(-3,26,-5,CONCRETE)
Block(-3,26,-4,AIR:0)
Block(-3,26,-3,SMOOTH_BRICK)
Block(-3,26,-2,AIR:0)
Block(-3,26,-1,AIR:0)
Block(-3,26,0,CONCRETE)
Block(-3,26,1,CONCRETE)
Block(-3,26,2,CONCRETE)
Block(-3,26,3,CONCRETE)
Block(-3,26,4,CONCRETE)
Block(-3,26,5,CONCRETE)
Block(-3,26,6,PISTON_STICKY_BASE:3)
Block(-3,26,7,AIR:0)
Block(-3,26,8,IRON_BLOCK)
Block(-3,26,9,CONCRETE)
Block(-3,27,-5,CONCRETE)
Block(-3,27,-4,AIR:0)
Block(-3,27,-3,AIR:0)
Block(-3,27,-2,AIR:0)
Block(-3,27,-1,AIR:0)
Block(-3,27,0,CONCRETE)
Block(-3,27,1,CONCRETE)
Block(-3,27,2,CONCRETE)
Block(-3,27,3,CONCRETE)
Block(-3,27,4,CONCRETE)
Block(-3,27,5,CONCRETE)
Block(-3,27,6,PISTON_STICKY_BASE:3)
Block(-3,27,7,AIR:0)
Block(-3,27,8,IRON_BLOCK)
Block(-3,27,9,CONCRETE)
Block(-3,28,-5,CONCRETE)
Block(-3,28,-4,AIR:0)
Block(-3,28,-3,AIR:0)
Block(-3,28,-2,AIR:0)
Block(-3,28,-1,AIR:0)
Block(-3,28,0,CONCRETE)
Block(-3,28,1,CONCRETE)
Block(-3,28,2,CONCRETE)
Block(-3,28,3,CONCRETE)
Block(-3,28,4,CONCRETE)
Block(-3,28,5,CONCRETE)
Block(-3,28,6,CONCRETE)
Block(-3,28,7,CONCRETE)
Block(-3,28,8,CONCRETE)
Block(-3,28,9,CONCRETE)
Block(-3,29,-5,CONCRETE)
Block(-3,29,-4,AIR:0)
Block(-3,29,-3,AIR:0)
Block(-3,29,-2,AIR:0)
Block(-3,29,-1,AIR:0)
Block(-3,29,0,CONCRETE)
Block(-3,29,1,CONCRETE)
Block(-3,29,2,CONCRETE)
Block(-3,29,3,CONCRETE)
Block(-3,29,4,CONCRETE)
Block(-3,29,5,CONCRETE)
Block(-3,29,6,CONCRETE)
Block(-3,29,7,CONCRETE)
Block(-3,29,8,CONCRETE)
Block(-3,30,-5,CONCRETE)
Block(-3,30,-4,WEB:0)
Block(-3,30,-3,AIR:0)
Block(-3,30,-2,AIR:0)
Block(-3,30,-1,AIR:0)
Block(-3,30,0,CONCRETE)
Block(-3,30,1,CONCRETE)
Block(-3,30,2,CONCRETE)
Block(-3,30,3,CONCRETE)
Block(-3,30,4,CONCRETE)
Block(-3,30,5,CONCRETE)
Block(-3,30,6,CONCRETE)
Block(-3,30,7,CONCRETE)
Block(-3,30,8,CONCRETE)
Block(-3,31,-5,CONCRETE)
Block(-3,31,-4,CONCRETE)
Block(-3,31,-3,CONCRETE)
Block(-3,31,-2,CONCRETE)
Block(-3,31,-1,CONCRETE)
Block(-3,31,0,CONCRETE)
Block(-3,31,1,CONCRETE)
Block(-3,31,2,CONCRETE)
Block(-3,31,3,CONCRETE)
Block(-3,31,4,CONCRETE)
Block(-3,31,5,CONCRETE)
Block(-3,31,6,CONCRETE)
Block(-3,31,7,CONCRETE)
Block(-3,31,8,CONCRETE)
Block(-3,32,-5,CONCRETE)
Block(-3,32,-4,CONCRETE)
Block(-3,32,-3,CONCRETE)
Block(-3,32,-2,CONCRETE)
Block(-3,32,-1,CONCRETE)
Block(-3,32,0,CONCRETE)
Block(-3,32,1,CONCRETE)
Block(-3,32,2,CONCRETE)
Block(-3,32,3,CONCRETE)
Block(-3,32,4,CONCRETE)
Block(-3,32,5,CONCRETE)
Block(-3,32,6,CONCRETE)
Block(-3,32,7,CONCRETE)
Block(-3,32,8,CONCRETE)
Block(-3,33,-5,CONCRETE)
Block(-3,33,-4,CONCRETE)
Block(-3,33,-3,CONCRETE)
Block(-3,33,-2,CONCRETE)
Block(-3,33,-1,CONCRETE)
Block(-3,33,0,CONCRETE)
Block(-3,33,1,CONCRETE)
Block(-3,33,2,CONCRETE)
Block(-3,33,3,CONCRETE)
Block(-3,33,4,CONCRETE)
Block(-3,33,5,CONCRETE)
Block(-3,33,6,CONCRETE)
Block(-3,33,7,CONCRETE)
Block(-3,33,8,CONCRETE)
Block(-3,34,-5,CONCRETE)
Block(-3,34,-4,CONCRETE)
Block(-3,34,-3,CONCRETE)
Block(-3,34,-2,CONCRETE)
Block(-3,34,-1,CONCRETE)
Block(-3,34,0,CONCRETE)
Block(-3,34,1,CONCRETE)
Block(-3,34,2,CONCRETE)
Block(-3,34,3,CONCRETE)
Block(-3,34,4,CONCRETE)
Block(-3,34,5,CONCRETE)
Block(-3,34,6,CONCRETE)
Block(-3,34,7,CONCRETE)
Block(-3,34,8,CONCRETE)
Block(-3,35,-5,CONCRETE)
Block(-3,35,-4,CONCRETE)
Block(-3,35,-3,CONCRETE)
Block(-3,35,-2,CONCRETE)
Block(-3,35,-1,CONCRETE)
Block(-3,35,0,CONCRETE)
Block(-3,35,1,CONCRETE)
Block(-3,35,2,CONCRETE)
Block(-3,35,3,CONCRETE)
Block(-3,35,4,CONCRETE)
Block(-3,35,5,CONCRETE)
Block(-3,35,6,CONCRETE)
Block(-3,35,7,CONCRETE)
Block(-3,35,8,CONCRETE)
Block(-3,36,-5,CONCRETE)
Block(-3,36,-4,CONCRETE)
Block(-3,36,-3,CONCRETE)
Block(-3,36,-2,CONCRETE)
Block(-3,36,-1,CONCRETE)
Block(-3,36,0,CONCRETE)
Block(-3,36,1,CONCRETE)
Block(-3,36,2,CONCRETE)
Block(-3,36,3,CONCRETE)
Block(-3,36,4,CONCRETE)
Block(-3,36,5,CONCRETE)
Block(-3,36,6,CONCRETE)
Block(-3,36,7,CONCRETE)
Block(-3,36,8,CONCRETE)
Block(-3,37,-6,CONCRETE)
Block(-3,37,-5,CONCRETE)
Block(-3,37,-4,CONCRETE)
Block(-3,37,-3,CONCRETE)
Block(-3,37,-2,CONCRETE)
Block(-3,37,-1,CONCRETE)
Block(-3,37,0,CONCRETE)
Block(-3,37,1,CONCRETE)
Block(-3,37,2,CONCRETE)
Block(-3,37,3,CONCRETE)
Block(-3,37,4,CONCRETE)
Block(-3,37,5,CONCRETE)
Block(-3,37,6,CONCRETE)
Block(-3,37,7,CONCRETE)
Block(-3,37,8,CONCRETE)
Block(-3,38,-6,CONCRETE)
Block(-3,38,-5,WOOD)
Block(-3,38,-4,WOOD)
Block(-3,38,-3,WOOD)
Block(-3,38,-2,CONCRETE)
Block(-3,38,-1,CONCRETE)
Block(-3,38,0,CONCRETE)
Block(-3,38,1,CONCRETE)
Block(-3,38,2,CONCRETE)
Block(-3,38,3,CONCRETE)
Block(-3,38,4,CONCRETE)
Block(-3,38,5,CONCRETE)
Block(-3,38,6,AIR:0)
Block(-3,38,7,CONCRETE)
Block(-3,38,8,CONCRETE)
Block(-3,39,-6,CONCRETE)
Block(-3,39,-5,WOOD)
Block(-3,39,-4,STONE)
Block(-3,39,-3,WOOD)
Block(-3,39,-2,CONCRETE)
Block(-3,39,-1,CONCRETE)
Block(-3,39,0,CONCRETE)
Block(-3,39,1,CONCRETE)
Block(-3,39,2,CONCRETE)
Block(-3,39,3,CONCRETE)
Block(-3,39,4,CONCRETE)
Block(-3,39,5,CONCRETE)
Block(-3,39,6,AIR:0)
Block(-3,39,7,CONCRETE)
Block(-3,39,8,CONCRETE)
Block(-3,40,-6,CONCRETE)
Block(-3,40,-5,WOOD)
Block(-3,40,-4,AIR:0)
Block(-3,40,-3,WOOD)
Block(-3,40,-2,CONCRETE)
Block(-3,40,-1,CONCRETE)
Block(-3,40,0,CONCRETE)
Block(-3,40,1,CONCRETE)
Block(-3,40,2,CONCRETE)
Block(-3,40,3,CONCRETE)
Block(-3,40,4,CONCRETE)
Block(-3,40,5,CONCRETE)
Block(-3,40,6,CONCRETE)
Block(-3,40,7,CONCRETE)
Block(-3,40,8,CONCRETE)
Block(-3,41,-6,CONCRETE)
Block(-3,41,-5,AIR:0)
Block(-3,41,-4,AIR:0)
Block(-3,41,-3,AIR:0)
Block(-3,41,-2,CONCRETE)
Block(-3,41,-1,CONCRETE)
Block(-3,41,0,CONCRETE)
Block(-3,41,1,CONCRETE)
Block(-3,41,2,CONCRETE)
Block(-3,41,3,CONCRETE)
Block(-3,41,4,CONCRETE)
Block(-3,41,5,CONCRETE)
Block(-3,41,6,CONCRETE)
Block(-3,41,7,CONCRETE)
Block(-3,41,8,CONCRETE)
Block(-3,42,-6,CONCRETE)
Block(-3,42,-5,AIR:0)
Block(-3,42,-4,AIR:0)
Block(-3,42,-3,WEB:0)
Block(-3,42,-2,CONCRETE)
Block(-3,42,-1,CONCRETE)
Block(-3,42,0,CONCRETE)
Block(-3,42,1,CONCRETE)
Block(-3,42,2,CONCRETE)
Block(-3,42,3,CONCRETE)
Block(-3,42,4,CONCRETE)
Block(-3,42,5,CONCRETE)
Block(-3,42,6,CONCRETE)
Block(-3,42,7,CONCRETE)
Block(-3,42,8,CONCRETE)
Block(-3,43,-6,CONCRETE)
Block(-3,43,-5,CONCRETE)
Block(-3,43,-4,CONCRETE)
Block(-3,43,-3,CONCRETE)
Block(-3,43,-2,CONCRETE)
Block(-3,43,-1,CONCRETE)
Block(-3,43,0,CONCRETE)
Block(-3,43,1,LEVER:10)
Block(-3,43,2,LEVER:10)
Block(-3,43,3,CONCRETE)
Block(-3,43,4,CONCRETE)
Block(-3,43,5,CONCRETE)
Block(-3,43,6,CONCRETE)
Block(-3,43,7,CONCRETE)
Block(-3,43,8,CONCRETE)
Block(-3,44,-5,CONCRETE)
Block(-3,44,-4,LONG_GRASS:0)
Block(-3,44,-3,AIR:0)
Block(-3,44,-2,SMOOTH_BRICK:0)
Block(-3,44,-1,CONCRETE)
Block(-3,44,0,CONCRETE)
Block(-3,44,1,LEVER:10)
Block(-3,44,2,LEVER:10)
Block(-3,44,3,CONCRETE)
Block(-3,44,4,CONCRETE)
Block(-3,44,5,CONCRETE)
Block(-3,44,6,AIR:0)
Block(-3,44,7,CONCRETE)
Block(-3,44,8,CONCRETE)
Block(-3,45,-5,CONCRETE)
Block(-3,45,-4,AIR:0)
Block(-3,45,-3,AIR:0)
Block(-3,45,-2,AIR:0)
Block(-3,45,-1,CONCRETE)
Block(-3,45,0,CONCRETE)
Block(-3,45,1,CONCRETE)
Block(-3,45,2,CONCRETE)
Block(-3,45,3,CONCRETE)
Block(-3,45,4,CONCRETE)
Block(-3,45,5,CONCRETE)
Block(-3,45,6,AIR:0)
Block(-3,45,7,CONCRETE)
Block(-3,45,8,CONCRETE)
Block(-3,46,-5,CONCRETE)
Block(-3,46,-4,AIR:0)
Block(-3,46,-3,AIR:0)
Block(-3,46,-2,AIR:0)
Block(-3,46,-1,CONCRETE)
Block(-3,46,0,CONCRETE)
Block(-3,46,1,CONCRETE)
Block(-3,46,2,CONCRETE)
Block(-3,46,3,CONCRETE)
Block(-3,46,4,CONCRETE)
Block(-3,46,5,CONCRETE)
Block(-3,46,6,CONCRETE)
Block(-3,46,7,CONCRETE)
Block(-3,46,8,CONCRETE)
Block(-3,47,-5,CONCRETE)
Block(-3,47,-4,AIR:0)
Block(-3,47,-3,AIR:0)
Block(-3,47,-2,AIR:0)
Block(-3,47,-1,CONCRETE)
Block(-3,47,0,CONCRETE)
Block(-3,47,1,CONCRETE)
Block(-3,47,2,CONCRETE)
Block(-3,47,3,CONCRETE)
Block(-3,47,4,CONCRETE)
Block(-3,47,5,CONCRETE)
Block(-3,47,6,CONCRETE)
Block(-3,47,7,CONCRETE)
Block(-3,47,8,CONCRETE)
Block(-3,48,-5,CONCRETE)
Block(-3,48,-4,CONCRETE)
Block(-3,48,-3,CONCRETE)
Block(-3,48,-2,CONCRETE)
Block(-3,48,-1,CONCRETE)
Block(-3,48,0,CONCRETE)
Block(-3,48,1,CONCRETE)
Block(-3,48,2,CONCRETE)
Block(-3,48,3,CONCRETE)
Block(-3,48,4,CONCRETE)
Block(-3,48,5,CONCRETE)
Block(-3,48,6,CONCRETE)
Block(-3,48,7,CONCRETE)
Block(-3,48,8,CONCRETE)
Block(-3,49,-5,CONCRETE)
Block(-3,49,-4,CONCRETE)
Block(-3,49,-3,CONCRETE)
Block(-3,49,-2,CONCRETE)
Block(-3,49,-1,CONCRETE)
Block(-3,49,0,CONCRETE)
Block(-3,49,1,SMOOTH_BRICK)
Block(-3,49,2,LEVER:10)
Block(-3,49,3,CONCRETE)
Block(-3,49,4,CONCRETE)
Block(-3,49,5,CONCRETE)
Block(-3,49,6,CONCRETE)
Block(-3,49,7,CONCRETE)
Block(-3,49,8,CONCRETE)
Block(-3,50,-5,CONCRETE)
Block(-3,50,-4,WOOD:5)
Block(-3,50,-3,WOOD:5)
Block(-3,50,-2,WOOD:5)
Block(-3,50,-1,quark:stonebrick_wall)
Block(-3,50,0,CONCRETE)
Block(-3,50,1,CONCRETE)
Block(-3,50,2,CONCRETE)
Block(-3,50,3,CONCRETE)
Block(-3,50,4,CONCRETE)
Block(-3,50,5,CONCRETE)
Block(-3,50,6,IRON_DOOR_BLOCK:6)
Block(-3,50,7,CONCRETE)
Block(-3,50,8,CONCRETE)
Block(-3,51,-5,CONCRETE)
Block(-3,51,-4,AIR:0)
Block(-3,51,-3,SMOOTH_BRICK)
Block(-3,51,-2,AIR:0)
Block(-3,51,-1,quark:stonebrick_wall)
Block(-3,51,0,CONCRETE)
Block(-3,51,1,CONCRETE)
Block(-3,51,2,CONCRETE)
Block(-3,51,3,CONCRETE)
Block(-3,51,4,CONCRETE)
Block(-3,51,5,CONCRETE)
Block(-3,51,6,IRON_DOOR_BLOCK:9)
Block(-3,51,7,CONCRETE)
Block(-3,51,8,CONCRETE)
Block(-3,52,-5,CONCRETE)
Block(-3,52,-4,AIR:0)
Block(-3,52,-3,AIR:0)
Block(-3,52,-2,AIR:0)
Block(-3,52,-1,quark:stonebrick_wall)
Block(-3,52,0,CONCRETE)
Block(-3,52,1,CONCRETE)
Block(-3,52,2,CONCRETE)
Block(-3,52,3,CONCRETE)
Block(-3,52,4,CONCRETE)
Block(-3,52,5,CONCRETE)
Block(-3,52,6,CONCRETE)
Block(-3,52,7,CONCRETE)
Block(-3,52,8,CONCRETE)
Block(-3,53,-5,CONCRETE)
Block(-3,53,-4,WEB:0)
Block(-3,53,-3,AIR:0)
Block(-3,53,-2,AIR:0)
Block(-3,53,-1,quark:stonebrick_wall)
Block(-3,53,0,CONCRETE)
Block(-3,53,1,CONCRETE)
Block(-3,53,2,CONCRETE)
Block(-3,53,3,CONCRETE)
Block(-3,53,4,CONCRETE)
Block(-3,53,5,CONCRETE)
Block(-3,53,6,CONCRETE)
Block(-3,53,7,CONCRETE)
Block(-3,53,8,CONCRETE)
Block(-3,54,-5,CONCRETE)
Block(-3,54,-4,CONCRETE)
Block(-3,54,-3,CONCRETE)
Block(-3,54,-2,CONCRETE)
Block(-3,54,-1,CONCRETE)
Block(-3,54,0,CONCRETE)
Block(-3,54,1,CONCRETE)
Block(-3,54,2,CONCRETE)
Block(-3,54,3,CONCRETE)
Block(-3,54,4,CONCRETE)
Block(-3,54,5,CONCRETE)
Block(-3,54,6,CONCRETE)
Block(-3,54,7,CONCRETE)
Block(-3,54,8,CONCRETE)
Block(-3,55,-6,CONCRETE)
Block(-3,55,-5,CONCRETE)
Block(-3,55,-4,CONCRETE)
Block(-3,55,-3,CONCRETE)
Block(-3,55,-2,CONCRETE)
Block(-3,55,-1,CONCRETE)
Block(-3,55,0,CONCRETE)
Block(-3,55,1,CONCRETE)
Block(-3,55,2,CONCRETE)
Block(-3,55,3,CONCRETE)
Block(-3,55,4,CONCRETE)
Block(-3,55,5,CONCRETE)
Block(-3,55,6,CONCRETE)
Block(-3,55,7,CONCRETE)
Block(-3,55,8,CONCRETE)
Block(-3,55,9,CONCRETE)
Block(-3,56,-6,CONCRETE)
Block(-3,56,-5,AIR:0)
Block(-3,56,-4,IRON_DOOR_BLOCK)
Block(-3,56,-3,AIR:0)
Block(-3,56,-2,AIR:0)
Block(-3,56,-1,CONCRETE)
Block(-3,56,0,CONCRETE)
Block(-3,56,1,CONCRETE)
Block(-3,56,2,CONCRETE)
Block(-3,56,3,CONCRETE)
Block(-3,56,4,CONCRETE)
Block(-3,56,5,AIR:0)
Block(-3,56,6,STONE)
Block(-3,56,7,IRON_DOOR_BLOCK:1)
Block(-3,56,8,AIR:0)
Block(-3,56,9,CONCRETE)
Block(-3,57,-6,CONCRETE)
Block(-3,57,-5,quark:iron_button:2)
Block(-3,57,-4,IRON_DOOR_BLOCK:9)
Block(-3,57,-3,AIR:0)
Block(-3,57,-2,AIR:0)
Block(-3,57,-1,CONCRETE)
Block(-3,57,0,CONCRETE)
Block(-3,57,1,CONCRETE)
Block(-3,57,2,CONCRETE)
Block(-3,57,3,CONCRETE)
Block(-3,57,4,CONCRETE)
Block(-3,57,5,AIR:0)
Block(-3,57,6,AIR:0)
Block(-3,57,7,IRON_DOOR_BLOCK:9)
Block(-3,57,8,quark:iron_button:2)
Block(-3,57,9,CONCRETE)
Block(-3,58,-6,CONCRETE)
Block(-3,58,-5,CONCRETE)
Block(-3,58,-4,CONCRETE)
Block(-3,58,-3,quark:iron_button:3)
Block(-3,58,-2,AIR:0)
Block(-3,58,-1,CONCRETE)
Block(-3,58,0,CONCRETE)
Block(-3,58,1,CONCRETE)
Block(-3,58,2,CONCRETE)
Block(-3,58,3,CONCRETE)
Block(-3,58,4,CONCRETE)
Block(-3,58,5,AIR:0)
Block(-3,58,6,quark:iron_button)
Block(-3,58,7,CONCRETE)
Block(-3,58,8,CONCRETE)
Block(-3,58,9,CONCRETE)
Block(-3,59,-5,CONCRETE)
Block(-3,59,-4,CONCRETE)
Block(-3,59,-3,CONCRETE)
Block(-3,59,-2,CONCRETE)
Block(-3,59,-1,CONCRETE)
Block(-3,59,0,CONCRETE)
Block(-3,59,1,CONCRETE)
Block(-3,59,2,CONCRETE)
Block(-3,59,3,CONCRETE)
Block(-3,59,4,CONCRETE)
Block(-3,59,5,CONCRETE)
Block(-3,59,6,CONCRETE)
Block(-3,59,7,CONCRETE)
Block(-3,59,8,CONCRETE)
Block(-3,60,-5,CONCRETE)
Block(-3,60,-4,SMOOTH_BRICK:1)
Block(-3,60,-3,SMOOTH_BRICK:1)
Block(-3,60,-2,SMOOTH_BRICK:1)
Block(-3,60,-1,SMOOTH_BRICK:1)
Block(-3,60,0,CONCRETE)
Block(-3,60,1,CONCRETE)
Block(-3,60,2,CONCRETE)
Block(-3,60,3,CONCRETE)
Block(-3,60,4,SMOOTH_BRICK:1)
Block(-3,60,5,SMOOTH_BRICK:1)
Block(-3,60,6,SMOOTH_BRICK:1)
Block(-3,60,7,SMOOTH_BRICK:1)
Block(-3,60,8,CONCRETE)
Block(-3,61,-4,CONCRETE)
Block(-3,61,-3,SMOOTH_STAIRS:2)
Block(-3,61,-2,CONCRETE)
Block(-3,61,-1,CONCRETE)
Block(-3,61,0,CONCRETE)
Block(-3,61,1,CONCRETE)
Block(-3,61,2,CONCRETE)
Block(-3,61,3,CONCRETE)
Block(-3,61,4,CONCRETE)
Block(-3,61,5,CONCRETE)
Block(-3,61,6,CONCRETE)
Block(-3,61,7,CONCRETE)
Block(-3,62,-2,IRON_BLOCK)
Block(-3,62,-1,SMOOTH_STAIRS:0)
Block(-3,62,0,CONCRETE)
Block(-3,62,1,CONCRETE)
Block(-3,62,2,CONCRETE)
Block(-3,62,3,CONCRETE)
Block(-3,62,4,CONCRETE)
Block(-3,62,5,IRON_BLOCK)
Block(-2,0,-5,CONCRETE)
Block(-2,0,-4,CONCRETE)
Block(-2,0,-3,CONCRETE)
Block(-2,0,-2,CONCRETE)
Block(-2,0,-1,CONCRETE)
Block(-2,0,0,CONCRETE)
Block(-2,0,1,CONCRETE)
Block(-2,0,2,CONCRETE)
Block(-2,0,3,CONCRETE)
Block(-2,0,4,CONCRETE)
Block(-2,0,5,CONCRETE)
Block(-2,0,6,CONCRETE)
Block(-2,0,7,CONCRETE)
Block(-2,0,8,CONCRETE)
Block(-2,1,-5,CONCRETE)
Block(-2,1,-4,CONCRETE)
Block(-2,1,-3,CONCRETE)
Block(-2,1,-2,CONCRETE)
Block(-2,1,-1,CONCRETE)
Block(-2,1,0,CONCRETE)
Block(-2,1,1,CONCRETE)
Block(-2,1,2,CONCRETE)
Block(-2,1,3,CONCRETE)
Block(-2,1,4,CONCRETE)
Block(-2,1,5,CONCRETE)
Block(-2,1,6,CONCRETE)
Block(-2,1,7,CONCRETE)
Block(-2,1,8,CONCRETE)
Block(-2,2,-5,CONCRETE)
Block(-2,2,-4,CONCRETE)
Block(-2,2,-3,CONCRETE)
Block(-2,2,-2,CONCRETE)
Block(-2,2,-1,CONCRETE)
Block(-2,2,0,CONCRETE)
Block(-2,2,1,CONCRETE)
Block(-2,2,2,CONCRETE)
Block(-2,2,3,CONCRETE)
Block(-2,2,4,CONCRETE)
Block(-2,2,5,CONCRETE)
Block(-2,2,6,CONCRETE)
Block(-2,2,7,CONCRETE)
Block(-2,2,8,CONCRETE)
Block(-2,3,-5,CONCRETE)
Block(-2,3,-4,CONCRETE)
Block(-2,3,-3,CONCRETE)
Block(-2,3,-2,CONCRETE)
Block(-2,3,-1,CONCRETE)
Block(-2,3,0,CONCRETE)
Block(-2,3,1,CONCRETE)
Block(-2,3,2,CONCRETE)
Block(-2,3,3,CONCRETE)
Block(-2,3,4,CONCRETE)
Block(-2,3,5,CONCRETE)
Block(-2,3,6,CONCRETE)
Block(-2,3,7,CONCRETE)
Block(-2,3,8,CONCRETE)
Block(-2,4,-5,CONCRETE)
Block(-2,4,-4,CONCRETE)
Block(-2,4,-3,CONCRETE)
Block(-2,4,-2,CONCRETE)
Block(-2,4,-1,CONCRETE)
Block(-2,4,0,CONCRETE)
Block(-2,4,1,CONCRETE)
Block(-2,4,2,CONCRETE)
Block(-2,4,3,CONCRETE)
Block(-2,4,4,CONCRETE)
Block(-2,4,5,CONCRETE)
Block(-2,4,6,CONCRETE)
Block(-2,4,7,CONCRETE)
Block(-2,4,8,CONCRETE)
Block(-2,5,-5,CONCRETE)
Block(-2,5,-4,CONCRETE)
Block(-2,5,-3,CONCRETE)
Block(-2,5,-2,CONCRETE)
Block(-2,5,-1,CONCRETE)
Block(-2,5,0,CONCRETE)
Block(-2,5,1,CONCRETE)
Block(-2,5,2,CONCRETE)
Block(-2,5,3,CONCRETE)
Block(-2,5,4,CONCRETE)
Block(-2,5,5,CONCRETE)
Block(-2,5,6,CONCRETE)
Block(-2,5,7,CONCRETE)
Block(-2,5,8,CONCRETE)
Block(-2,6,-5,CONCRETE)
Block(-2,6,-4,CONCRETE)
Block(-2,6,-3,CONCRETE)
Block(-2,6,-2,CONCRETE)
Block(-2,6,-1,CONCRETE)
Block(-2,6,0,CONCRETE)
Block(-2,6,1,CONCRETE)
Block(-2,6,2,CONCRETE)
Block(-2,6,3,CONCRETE)
Block(-2,6,4,CONCRETE)
Block(-2,6,5,CONCRETE)
Block(-2,6,6,CONCRETE)
Block(-2,6,7,CONCRETE)
Block(-2,6,8,CONCRETE)
Block(-2,7,-5,CONCRETE)
Block(-2,7,-4,CONCRETE)
Block(-2,7,-3,CONCRETE)
Block(-2,7,-2,CONCRETE)
Block(-2,7,-1,CONCRETE)
Block(-2,7,0,CONCRETE)
Block(-2,7,1,CONCRETE)
Block(-2,7,2,CONCRETE)
Block(-2,7,3,CONCRETE)
Block(-2,7,4,CONCRETE)
Block(-2,7,5,CONCRETE)
Block(-2,7,6,CONCRETE)
Block(-2,7,7,CONCRETE)
Block(-2,7,8,CONCRETE)
Block(-2,7,9,CONCRETE)
Block(-2,8,-5,CONCRETE)
Block(-2,8,-4,CONCRETE)
Block(-2,8,-3,CONCRETE)
Block(-2,8,-2,CONCRETE)
Block(-2,8,-1,SMOOTH_STAIRS:0)
Block(-2,8,0,AIR:0)
Block(-2,8,1,STONE)
Block(-2,8,2,IRON_DOOR_BLOCK:7)
Block(-2,8,3,AIR:0)
Block(-2,8,4,AIR:0)
Block(-2,8,5,STONE)
Block(-2,8,6,AIR:0)
Block(-2,8,7,AIR:0)
Block(-2,8,8,AIR:0)
Block(-2,8,9,CONCRETE)
Block(-2,9,-5,CONCRETE)
Block(-2,9,-4,SMOOTH_BRICK:1)
Block(-2,9,-3,AIR:0)
Block(-2,9,-2,STONE)
Block(-2,9,-1,AIR:0)
Block(-2,9,0,AIR:0)
Block(-2,9,1,AIR:0)
Block(-2,9,2,IRON_DOOR_BLOCK:8)
Block(-2,9,3,AIR:0)
Block(-2,9,4,AIR:0)
Block(-2,9,5,AIR:0)
Block(-2,9,6,AIR:0)
Block(-2,9,7,AIR:0)
Block(-2,9,8,AIR:0)
Block(-2,9,9,CONCRETE)
Block(-2,10,-5,CONCRETE)
Block(-2,10,-4,SMOOTH_BRICK:3)
Block(-2,10,-3,AIR:0)
Block(-2,10,-2,AIR:0)
Block(-2,10,-1,AIR:0)
Block(-2,10,0,AIR:0)
Block(-2,10,1,AIR:0)
Block(-2,10,2,CONCRETE)
Block(-2,10,3,SMOOTH_BRICK:0)
Block(-2,10,4,AIR:0)
Block(-2,10,5,AIR:0)
Block(-2,10,6,AIR:0)
Block(-2,10,7,AIR:0)
Block(-2,10,8,AIR:0)
Block(-2,10,9,CONCRETE)
Block(-2,11,-5,CONCRETE)
Block(-2,11,-4,IRON_BLOCK)
Block(-2,11,-3,AIR:0)
Block(-2,11,-2,AIR:0)
Block(-2,11,-1,AIR:0)
Block(-2,11,0,AIR:0)
Block(-2,11,1,AIR:0)
Block(-2,11,2,CONCRETE)
Block(-2,11,3,AIR:0)
Block(-2,11,4,AIR:0)
Block(-2,11,5,AIR:0)
Block(-2,11,6,AIR:0)
Block(-2,11,7,AIR:0)
Block(-2,11,8,AIR:0)
Block(-2,11,9,CONCRETE)
Block(-2,12,-5,CONCRETE)
Block(-2,12,-4,IRON_BLOCK:0)
Block(-2,12,-3,WEB:0)
Block(-2,12,-2,AIR:0)
Block(-2,12,-1,AIR:0)
Block(-2,12,0,AIR:0)
Block(-2,12,1,AIR:0)
Block(-2,12,2,CONCRETE)
Block(-2,12,3,AIR:0)
Block(-2,12,4,AIR:0)
Block(-2,12,5,AIR:0)
Block(-2,12,6,AIR:0)
Block(-2,12,7,AIR:0)
Block(-2,12,8,AIR:0)
Block(-2,12,9,CONCRETE)
Block(-2,13,-5,CONCRETE)
Block(-2,13,-4,CONCRETE)
Block(-2,13,-3,CONCRETE)
Block(-2,13,-2,CONCRETE)
Block(-2,13,-1,CONCRETE)
Block(-2,13,0,CONCRETE)
Block(-2,13,1,CONCRETE)
Block(-2,13,2,CONCRETE)
Block(-2,13,3,CONCRETE)
Block(-2,13,4,CONCRETE)
Block(-2,13,5,CONCRETE)
Block(-2,13,6,CONCRETE)
Block(-2,13,7,CONCRETE)
Block(-2,13,8,CONCRETE)
Block(-2,13,9,CONCRETE)
Block(-2,14,-5,CONCRETE)
Block(-2,14,-4,WOOD:0,../../../Chests/Loot/manhunt_vagrant_scrap.nbt)
Block(-2,14,-3,WOOD_STAIRS:5)
Block(-2,14,-2,WOOD:0,../../../Chests/Loot/manhunt_vagrant_scrap.nbt)
Block(-2,14,-1,WOOD:5)
Block(-2,14,0,WOOD)
Block(-2,14,1,WOOD:5)
Block(-2,14,2,WOOD:1)
Block(-2,14,3,CONCRETE)
Block(-2,14,4,WOOD)
Block(-2,14,5,SMOOTH_BRICK)
Block(-2,14,6,AIR:0)
Block(-2,14,7,WOOD)
Block(-2,14,8,CONCRETE)
Block(-2,15,-5,CONCRETE)
Block(-2,15,-4,WOOD:5)
Block(-2,15,-3,WOOD:5)
RandomBlock(-2,15,-2,WOOD:5,5,WOOD:5,../../../Chests/Loot/manhunt_vagrant_scrap.nbt,100)
Block(-2,15,-1,BOOKSHELF:0)
Block(-2,15,0,WOOD:0,../../../Chests/Loot/manhunt_vagrant_scrap.nbt)
Block(-2,15,1,WOOD:5)
RandomBlock(-2,15,2,WOOD:5,5,WOOD:5,../../../Chests/Loot/manhunt_vagrant_scrap.nbt,100)
Block(-2,15,3,CONCRETE)
Block(-2,15,4,LONG_GRASS)
Block(-2,15,5,AIR:0)
Block(-2,15,6,AIR:0)
Block(-2,15,7,WOOD)
Block(-2,15,8,CONCRETE)
Block(-2,16,-5,CONCRETE)
Block(-2,16,-4,WOOD:0,../../../Chests/Loot/manhunt_vagrant_scrap.nbt)
Block(-2,16,-3,AIR:0)
Block(-2,16,-2,SMOOTH_BRICK:1)
Block(-2,16,-1,AIR:0)
Block(-2,16,0,WOOD_STAIRS:1)
Block(-2,16,1,WOOD:0,../../../Chests/Loot/manhunt_vagrant_scrap.nbt)
Block(-2,16,2,WOOD)
Block(-2,16,3,CONCRETE)
Block(-2,16,4,AIR:0)
Block(-2,16,5,AIR:0)
Block(-2,16,6,AIR:0)
Block(-2,16,7,AIR:0)
Block(-2,16,8,CONCRETE)
Block(-2,17,-5,CONCRETE)
Block(-2,17,-4,AIR:0)
Block(-2,17,-3,AIR:0)
Block(-2,17,-2,AIR:0)
Block(-2,17,-1,AIR:0)
Block(-2,17,0,AIR:0)
Block(-2,17,1,AIR:0)
Block(-2,17,2,AIR:0)
Block(-2,17,3,CONCRETE)
Block(-2,17,4,WEB:0)
Block(-2,17,5,AIR:0)
Block(-2,17,6,AIR:0)
Block(-2,17,7,AIR:0)
Block(-2,17,8,CONCRETE)
Block(-2,18,-5,CONCRETE)
Block(-2,18,-4,WEB:0)
Block(-2,18,-3,CONCRETE)
Block(-2,18,-2,AIR:0)
Block(-2,18,-1,CONCRETE)
Block(-2,18,0,AIR:0)
Block(-2,18,1,CONCRETE)
Block(-2,18,2,AIR:0)
Block(-2,18,3,CONCRETE)
Block(-2,18,4,CONCRETE)
Block(-2,18,5,CONCRETE)
Block(-2,18,6,CONCRETE)
Block(-2,18,7,CONCRETE)
Block(-2,18,8,CONCRETE)
Block(-2,19,-5,CONCRETE)
Block(-2,19,-4,CONCRETE)
Block(-2,19,-3,CONCRETE)
Block(-2,19,-2,CONCRETE)
Block(-2,19,-1,CONCRETE)
Block(-2,19,0,CONCRETE)
Block(-2,19,1,CONCRETE)
Block(-2,19,2,CONCRETE)
Block(-2,19,3,CONCRETE)
Block(-2,19,4,CONCRETE)
Block(-2,19,5,CONCRETE)
Block(-2,19,6,CONCRETE)
Block(-2,19,7,CONCRETE)
Block(-2,19,8,CONCRETE)
Block(-2,20,-5,CONCRETE)
Block(-2,20,-4,SMOOTH_BRICK)
Block(-2,20,-3,WOOD,../../../Chests/Loot/manhunt_vagrant_scrap.nbt)
Block(-2,20,-2,AIR:0)
Block(-2,20,-1,WOOD:0)
Block(-2,20,0,WOOD:0)
Block(-2,20,1,WOOD:0)
Block(-2,20,2,CONCRETE)
Block(-2,20,3,WOOD:0,../../../Chests/Loot/manhunt_vagrant_scrap.nbt)
Block(-2,20,4,WOOD:0,../../../Chests/Loot/manhunt_vagrant_scrap.nbt)
Block(-2,20,5,WOOD:0)
Block(-2,20,6,AIR:0)
Block(-2,20,7,WOOD:0)
Block(-2,20,8,CONCRETE)
Block(-2,21,-5,CONCRETE)
Block(-2,21,-4,AIR:0)
Block(-2,21,-3,quark:dark_oak_trapdoor:11)
Block(-2,21,-2,AIR:0)
