
#######################################################################
# +-----------------------------------------------------------------+ #
# |                            BO4 object                           | #
# +-----------------------------------------------------------------+ #
#######################################################################

Author: NLBlackEagle

Description: No description given

SettingsMode: WriteWithoutComments


#######################################################################
# +-----------------------------------------------------------------+ #
# |                          Main settings                          | #
# +-----------------------------------------------------------------+ #
#######################################################################

FixedRotation: 

Frequency: 0

SpawnHeight: highestBlock

UseCenterForHighestBlock: true

##############################
# Height Limits for the BO4. #
##############################

MinHeight: 0

MaxHeight: 255

InheritBO3: 

InheritBO3Rotation: NORTH

OverrideChildSettings: true

OverrideParentHeight: false

CanOverride: true

BranchFrequency: 0

BranchFrequencyGroup: 

MustBeBelowOther: false

MustBeInside: 

CannotBeInside: 

ReplacesBO3: 

MustBeInsideWorldBorders: true
CanSpawnOnWater: true

SpawnOnWaterOnly: false

SpawnUnderWater: false

SpawnAtWaterLevel: false

HeightOffset: 0

RemoveAir: true

ReplaceAbove: 

ReplaceBelow: 

ReplaceWithBiomeBlocks: false

ReplaceWithSurfaceBlock: GRASS

ReplaceWithGroundBlock: DIRT

ReplaceWithStoneBlock: STONE

SmoothRadius: 0

SmoothHeightOffset: 0

SmoothStartTop: false

SmoothStartWood: false

SmoothingSurfaceBlock: 

SmoothingGroundBlock: 

BO3Group: 

IsSpawnPoint: false

DoReplaceBlocks: true


#######################################################################
# +-----------------------------------------------------------------+ #
# |                              Blocks                             | #
# +-----------------------------------------------------------------+ #
#######################################################################

Block(0,13,-7,minecraft:iron_bars)
Block(1,0,-6,quark:limestone:1)
Block(1,0,-5,quark:limestone:1)
Block(1,0,-4,quark:limestone:1)
Block(1,1,-6,quark:limestone:1)
Block(1,1,-5,quark:limestone:1)
Block(1,1,-4,quark:limestone:1)
Block(1,2,-6,quark:limestone:1)
Block(1,2,-5,quark:limestone:1)
Block(1,2,-4,quark:limestone:1)
Block(1,3,-6,quark:limestone:1)
Block(1,3,-5,quark:limestone:1)
Block(1,3,-4,quark:limestone:1)
Block(1,4,-6,quark:limestone:1)
Block(1,4,-5,quark:limestone:1)
Block(1,4,-4,quark:limestone:1)
Block(1,5,-6,quark:limestone:1)
Block(1,5,-5,quark:limestone:1)
Block(1,5,-4,quark:limestone:1)
Block(1,6,-6,quark:limestone:1)
Block(1,6,-5,quark:limestone:1)
Block(1,6,-4,quark:limestone:1)
Block(1,7,-6,quark:limestone:1)
Block(1,7,-5,quark:limestone:1)
Block(1,7,-4,quark:limestone:1)
Block(1,8,-6,quark:limestone:1)
Block(1,8,-5,quark:limestone:1)
Block(1,8,-4,quark:limestone:1)
Block(1,9,-6,quark:limestone:1)
Block(1,9,-5,quark:limestone:1)
Block(1,9,-4,quark:limestone:1)
Block(1,12,-7,minecraft:iron_bars)
Block(1,12,-6,minecraft:iron_bars)
Block(1,13,-7,minecraft:iron_bars)
Block(1,15,-7,minecraft:iron_bars)
Block(1,17,-7,minecraft:iron_bars)
Block(2,0,-6,quark:limestone:1)
Block(2,0,-5,quark:limestone:1)
Block(2,0,-4,quark:limestone:1)
Block(2,1,-6,quark:limestone:1)
Block(2,1,-5,quark:limestone:1)
Block(2,1,-4,quark:limestone:1)
Block(2,2,-6,quark:limestone:1)
Block(2,2,-5,quark:limestone:1)
Block(2,2,-4,quark:limestone:1)
Block(2,3,-6,quark:limestone:1)
Block(2,3,-5,quark:limestone:1)
Block(2,3,-4,quark:limestone:1)
Block(2,4,-6,quark:limestone:1)
Block(2,4,-5,quark:limestone:1)
Block(2,4,-4,quark:limestone:1)
Block(2,5,-6,quark:limestone:1)
Block(2,5,-5,quark:limestone:1)
Block(2,5,-4,quark:limestone:1)
Block(2,6,-6,quark:limestone:1)
Block(2,6,-5,quark:limestone:1)
Block(2,6,-4,quark:limestone:1)
Block(2,7,-6,quark:limestone:1)
Block(2,7,-5,quark:limestone:1)
Block(2,7,-4,quark:limestone:1)
Block(2,8,-6,quark:limestone:1)
Block(2,8,-5,quark:limestone:1)
Block(2,8,-4,quark:limestone:1)
Block(2,9,-6,quark:limestone:1)
Block(2,9,-5,quark:limestone:1)
Block(2,9,-4,quark:limestone:1)
Block(2,10,-6,minecraft:iron_bars)
Block(2,10,-5,minecraft:iron_bars)
Block(2,11,-6,minecraft:iron_bars)
Block(2,11,-5,minecraft:iron_bars)
Block(2,12,-7,minecraft:iron_bars)
Block(2,12,-6,minecraft:iron_bars)
Block(2,12,-5,minecraft:iron_bars)
Block(2,13,-6,minecraft:iron_bars)
Block(2,13,-5,minecraft:iron_bars)
Block(2,14,-6,minecraft:iron_bars)
Block(2,14,-5,minecraft:iron_bars)
Block(2,15,-7,minecraft:iron_bars)
Block(2,15,-6,minecraft:iron_bars)
Block(2,16,-7,minecraft:iron_bars)
Block(2,16,-6,minecraft:iron_bars)
Block(2,17,-7,minecraft:iron_bars)
Block(2,17,-6,minecraft:iron_bars)
Block(2,18,-7,minecraft:iron_bars)
Block(2,18,-6,minecraft:iron_bars)
Block(2,19,-7,minecraft:iron_bars)
Block(2,19,-6,minecraft:iron_bars)
Block(2,20,-7,minecraft:iron_bars)
Block(2,21,-7,minecraft:iron_bars)
Block(2,22,-7,minecraft:iron_bars)
Block(2,23,-7,minecraft:iron_bars)
Block(2,24,-7,minecraft:iron_bars)
Block(2,25,-7,minecraft:iron_bars)
Block(2,26,-7,minecraft:iron_bars)
Block(2,29,-7,minecraft:iron_bars)
Block(3,0,-6,quark:limestone:1)
Block(3,0,-5,quark:limestone:1)
Block(3,0,-4,quark:limestone:1)
Block(3,1,-6,quark:limestone:1)
Block(3,1,-5,quark:limestone:1)
Block(3,1,-4,quark:limestone:1)
Block(3,2,-6,quark:limestone:1)
Block(3,2,-5,quark:limestone:1)
Block(3,2,-4,quark:limestone:1)
Block(3,3,-6,quark:limestone:1)
Block(3,3,-5,quark:limestone:1)
Block(3,3,-4,quark:limestone:1)
Block(3,4,-6,quark:limestone:1)
Block(3,4,-5,quark:limestone:1)
Block(3,4,-4,quark:limestone:1)
Block(3,5,-6,quark:limestone:1)
Block(3,5,-5,quark:limestone:1)
Block(3,5,-4,quark:limestone:1)
Block(3,6,-6,quark:limestone:1)
Block(3,6,-5,quark:limestone:1)
Block(3,6,-4,quark:limestone:1)
Block(3,7,-6,quark:limestone:1)
Block(3,7,-5,quark:limestone:1)
Block(3,7,-4,quark:limestone:1)
Block(3,8,-6,quark:limestone:1)
Block(3,8,-5,quark:limestone:1)
Block(3,8,-4,quark:limestone:1)
Block(3,9,-6,quark:limestone:1)
Block(3,9,-5,quark:limestone:1)
Block(3,9,-4,quark:limestone:1)
Block(3,10,-6,minecraft:iron_bars)
Block(3,10,-5,minecraft:iron_bars)
Block(3,11,-6,minecraft:iron_bars)
Block(3,11,-5,minecraft:iron_bars)
Block(3,12,-7,minecraft:iron_bars)
Block(3,12,-6,minecraft:iron_bars)
Block(3,12,-5,minecraft:iron_bars)
Block(3,13,-6,minecraft:iron_bars)
Block(3,13,-5,minecraft:iron_bars)
Block(3,14,-6,minecraft:iron_bars)
Block(3,14,-5,minecraft:iron_bars)
Block(3,15,-7,minecraft:iron_bars)
Block(3,15,-6,minecraft:iron_bars)
Block(3,16,-7,minecraft:iron_bars)
Block(3,16,-6,minecraft:iron_bars)
Block(3,17,-7,minecraft:iron_bars)
Block(3,17,-6,minecraft:iron_bars)
Block(3,18,-7,minecraft:iron_bars)
Block(3,18,-6,minecraft:iron_bars)
Block(3,19,-7,minecraft:iron_bars)
Block(3,19,-6,minecraft:iron_bars)
Block(3,20,-7,minecraft:iron_bars)
Block(3,21,-7,minecraft:iron_bars)
Block(3,22,-7,minecraft:iron_bars)
Block(3,23,-7,minecraft:iron_bars)
Block(3,24,-7,minecraft:iron_bars)
Block(3,25,-7,minecraft:iron_bars)
Block(3,26,-7,minecraft:iron_bars)
Block(3,27,-7,minecraft:iron_bars)
Block(3,27,-6,minecraft:iron_bars)
Block(3,28,-7,minecraft:iron_bars)
Block(3,28,-6,minecraft:iron_bars)
Block(3,29,-7,minecraft:iron_bars)
Block(3,29,-6,minecraft:iron_bars)
Block(3,30,-7,minecraft:iron_bars)
Block(3,30,-6,minecraft:iron_bars)
Block(4,12,-7,minecraft:iron_bars)
Block(4,12,-6,minecraft:iron_bars)
Block(4,13,-7,minecraft:iron_bars)
Block(4,15,-7,minecraft:iron_bars)
Block(4,17,-7,minecraft:iron_bars)
Block(4,27,-7,minecraft:iron_bars)
Block(4,27,-6,minecraft:iron_bars)
Block(4,28,-7,minecraft:iron_bars)
Block(4,28,-6,minecraft:iron_bars)
Block(4,29,-7,minecraft:iron_bars)
Block(4,29,-6,minecraft:iron_bars)
Block(4,30,-7,minecraft:iron_bars)
Block(4,30,-6,minecraft:iron_bars)
Block(4,30,-5,minecraft:iron_bars)
Block(4,31,-6,minecraft:iron_bars)
Block(4,31,-5,minecraft:iron_bars)
Block(5,13,-7,minecraft:iron_bars)
Block(5,27,-7,minecraft:iron_bars)
Block(5,30,-7,minecraft:iron_bars)
Block(5,30,-6,minecraft:iron_bars)
Block(5,30,-5,minecraft:iron_bars)
Block(5,31,-6,minecraft:iron_bars)
Block(5,31,-5,minecraft:iron_bars)
Block(5,32,-5,minecraft:iron_bars)
Block(5,32,-4,minecraft:iron_bars)
Block(5,33,-5,minecraft:iron_bars)
Block(5,33,-4,minecraft:iron_bars)
Block(6,30,-7,minecraft:iron_bars)
Block(6,30,-6,minecraft:iron_bars)
Block(6,32,-5,minecraft:iron_bars)
Block(6,32,-4,minecraft:iron_bars)
Block(6,33,-5,minecraft:iron_bars)
Block(6,33,-4,minecraft:iron_bars)
Block(6,34,-6,minecraft:iron_bars)
Block(6,34,-5,minecraft:iron_bars)
Block(6,35,-6,minecraft:iron_bars)
Block(6,35,-5,minecraft:iron_bars)
Block(6,40,-7,minecraft:iron_bars)
Block(6,42,-7,minecraft:iron_bars)
Block(6,43,-7,minecraft:iron_bars)
Block(6,44,-7,minecraft:iron_bars)
Block(7,30,-7,minecraft:iron_bars)
Block(7,34,-7,minecraft:iron_bars)
Block(7,34,-6,minecraft:iron_bars)
Block(7,34,-5,minecraft:iron_bars)
Block(7,35,-6,minecraft:iron_bars)
Block(7,35,-5,minecraft:iron_bars)
Block(7,36,-5,minecraft:iron_bars)
Block(7,36,-4,minecraft:iron_bars)
Block(7,37,-5,minecraft:iron_bars)
Block(7,37,-4,minecraft:iron_bars)
Block(7,40,-7,minecraft:iron_bars)
Block(7,40,-6,minecraft:iron_bars)
Block(7,41,-7,minecraft:iron_bars)
Block(7,41,-6,minecraft:iron_bars)
Block(7,42,-7,minecraft:iron_bars)
Block(7,43,-7,minecraft:iron_bars)
Block(7,43,-6,minecraft:iron_bars)
Block(7,44,-7,minecraft:iron_bars)
Block(7,45,-7,minecraft:iron_bars)
Block(7,45,-6,minecraft:iron_bars)

#######################################################################
# +-----------------------------------------------------------------+ #
# |                             Branches                            | #
# +-----------------------------------------------------------------+ #
#######################################################################


#######################################################################
# +-----------------------------------------------------------------+ #
# |                             Entities                            | #
# +-----------------------------------------------------------------+ #
#######################################################################


#######################################################################
# +-----------------------------------------------------------------+ #
# |                            Particles                            | #
# +-----------------------------------------------------------------+ #
#######################################################################


#######################################################################
# +-----------------------------------------------------------------+ #
# |                             Spawners                            | #
# +-----------------------------------------------------------------+ #
#######################################################################


#######################################################################
# +-----------------------------------------------------------------+ #
# |                             ModData                             | #
# +-----------------------------------------------------------------+ #
#######################################################################

