
#######################################################################
# +-----------------------------------------------------------------+ #
# |                            BO4 object                           | #
# +-----------------------------------------------------------------+ #
#######################################################################

Author: NLBlackEagle

Description: No description given

SettingsMode: WriteWithoutComments


#######################################################################
# +-----------------------------------------------------------------+ #
# |                          Main settings                          | #
# +-----------------------------------------------------------------+ #
#######################################################################

FixedRotation: 

Frequency: 0

SpawnHeight: highestBlock

UseCenterForHighestBlock: true

##############################
# Height Limits for the BO4. #
##############################

MinHeight: 0

MaxHeight: 255

InheritBO3: 

InheritBO3Rotation: NORTH

OverrideChildSettings: true

OverrideParentHeight: false

CanOverride: true

BranchFrequency: 0

BranchFrequencyGroup: 

MustBeBelowOther: false

MustBeInside: 

CannotBeInside: 

ReplacesBO3: 

MustBeInsideWorldBorders: true
CanSpawnOnWater: true

SpawnOnWaterOnly: false

SpawnUnderWater: false

SpawnAtWaterLevel: false

HeightOffset: 0

RemoveAir: true

ReplaceAbove: 

ReplaceBelow: 

ReplaceWithBiomeBlocks: false

ReplaceWithSurfaceBlock: GRASS

ReplaceWithGroundBlock: DIRT

ReplaceWithStoneBlock: STONE

SmoothRadius: 0

SmoothHeightOffset: 0

SmoothStartTop: false

SmoothStartWood: false

SmoothingSurfaceBlock: 

SmoothingGroundBlock: 

BO3Group: 

IsSpawnPoint: false

DoReplaceBlocks: true


#######################################################################
# +-----------------------------------------------------------------+ #
# |                              Blocks                             | #
# +-----------------------------------------------------------------+ #
#######################################################################

Block(-8,35,-5,quark:basalt_wall:0)
Block(-8,36,-5,quark:basalt_wall:0)
Block(-8,37,-5,quark:basalt_wall:0)
Block(-8,38,-6,IRON_FENCE:0)
Block(-8,38,-5,IRON_FENCE:0)
Block(-8,39,-6,quark:basalt_wall:0)
Block(-8,39,-5,quark:basalt_wall:0)
Block(-8,40,-6,minecraft:iron_bars)
Block(-8,40,-5,minecraft:iron_bars)
Block(-7,37,-6,quark:basalt_wall:0)
Block(-7,37,-5,quark:basalt_wall:0)
Block(-7,38,-6,IRON_FENCE:0)
Block(-7,38,-5,IRON_FENCE:0)
Block(-7,39,-6,quark:basalt_wall:0)
Block(-7,39,-5,quark:basalt_wall:0)
Block(-7,40,-6,minecraft:iron_bars)
Block(-7,40,-5,minecraft:iron_bars)
Block(-7,40,-4,minecraft:iron_bars)
Block(-7,41,-5,minecraft:iron_bars)
Block(-7,41,-4,minecraft:iron_bars)
Block(-6,40,-5,minecraft:iron_bars)
Block(-6,40,-4,minecraft:iron_bars)
Block(-6,40,-3,minecraft:iron_bars)
Block(-6,41,-5,minecraft:iron_bars)
Block(-6,41,-4,minecraft:iron_bars)
Block(-6,42,-4,minecraft:iron_bars)
Block(-6,42,-3,minecraft:iron_bars)
Block(-5,0,4,quark:limestone:1)
Block(-5,0,5,quark:limestone:1)
Block(-5,0,6,quark:limestone:1)
Block(-5,1,4,quark:limestone:1)
Block(-5,1,5,quark:limestone:1)
Block(-5,1,6,quark:limestone:1)
Block(-5,2,4,quark:limestone:1)
Block(-5,2,5,quark:limestone:1)
Block(-5,2,6,quark:limestone:1)
Block(-5,3,4,quark:limestone:1)
Block(-5,3,5,quark:limestone:1)
Block(-5,3,6,quark:limestone:1)
Block(-5,4,4,quark:limestone:1)
Block(-5,4,5,quark:limestone:1)
Block(-5,4,6,quark:limestone:1)
Block(-5,5,4,quark:limestone:1)
Block(-5,5,5,quark:limestone:1)
Block(-5,5,6,quark:limestone:1)
Block(-5,6,4,quark:limestone:1)
Block(-5,6,5,quark:limestone:1)
Block(-5,6,6,quark:limestone:1)
Block(-5,7,4,quark:limestone:1)
Block(-5,7,5,quark:limestone:1)
Block(-5,7,6,quark:limestone:1)
Block(-5,8,4,quark:limestone:1)
Block(-5,8,5,quark:limestone:1)
Block(-5,8,6,quark:limestone:1)
Block(-5,9,4,quark:limestone:1)
Block(-5,9,5,quark:limestone:1)
Block(-5,9,6,quark:limestone:1)
Block(-5,32,1,minecraft:iron_bars)
Block(-5,32,2,minecraft:iron_bars)
Block(-5,33,1,minecraft:iron_bars)
Block(-5,33,2,minecraft:iron_bars)
Block(-5,36,-1,minecraft:iron_bars)
Block(-5,36,0,minecraft:iron_bars)
Block(-5,37,-1,minecraft:iron_bars)
Block(-5,37,0,minecraft:iron_bars)
Block(-5,40,-4,minecraft:iron_bars)
Block(-5,40,-3,minecraft:iron_bars)
Block(-5,40,-2,minecraft:iron_bars)
Block(-5,42,-4,minecraft:iron_bars)
Block(-5,42,-3,minecraft:iron_bars)
Block(-5,43,-3,minecraft:iron_bars)
Block(-5,43,-2,minecraft:iron_bars)
Block(-4,0,4,quark:limestone:1)
Block(-4,0,5,quark:limestone:1)
Block(-4,0,6,quark:limestone:1)
Block(-4,1,4,quark:limestone:1)
Block(-4,1,5,quark:limestone:1)
Block(-4,1,6,quark:limestone:1)
Block(-4,2,4,quark:limestone:1)
Block(-4,2,5,quark:limestone:1)
Block(-4,2,6,quark:limestone:1)
Block(-4,3,4,quark:limestone:1)
Block(-4,3,5,quark:limestone:1)
Block(-4,3,6,quark:limestone:1)
Block(-4,4,4,quark:limestone:1)
Block(-4,4,5,quark:limestone:1)
Block(-4,4,6,quark:limestone:1)
Block(-4,5,4,quark:limestone:1)
Block(-4,5,5,quark:limestone:1)
Block(-4,5,6,quark:limestone:1)
Block(-4,6,4,quark:limestone:1)
Block(-4,6,5,quark:limestone:1)
Block(-4,6,6,quark:limestone:1)
Block(-4,7,4,quark:limestone:1)
Block(-4,7,5,quark:limestone:1)
Block(-4,7,6,quark:limestone:1)
Block(-4,8,4,quark:limestone:1)
Block(-4,8,5,quark:limestone:1)
Block(-4,8,6,quark:limestone:1)
Block(-4,9,4,quark:limestone:1)
Block(-4,9,5,quark:limestone:1)
Block(-4,9,6,quark:limestone:1)
Block(-4,10,4,minecraft:iron_bars)
Block(-4,10,5,minecraft:iron_bars)
Block(-4,11,4,minecraft:iron_bars)
Block(-4,11,5,minecraft:iron_bars)
Block(-4,12,4,minecraft:iron_bars)
Block(-4,12,5,minecraft:iron_bars)
Block(-4,13,4,minecraft:iron_bars)
Block(-4,13,5,minecraft:iron_bars)
Block(-4,14,4,minecraft:iron_bars)
Block(-4,14,5,minecraft:iron_bars)
Block(-4,30,2,minecraft:iron_bars)
Block(-4,30,3,minecraft:iron_bars)
Block(-4,31,2,minecraft:iron_bars)
Block(-4,31,3,minecraft:iron_bars)
Block(-4,32,1,minecraft:iron_bars)
Block(-4,32,2,minecraft:iron_bars)
Block(-4,33,1,minecraft:iron_bars)
Block(-4,33,2,minecraft:iron_bars)
Block(-4,34,0,minecraft:iron_bars)
Block(-4,34,1,minecraft:iron_bars)
Block(-4,35,0,minecraft:iron_bars)
Block(-4,35,1,minecraft:iron_bars)
Block(-4,36,-1,minecraft:iron_bars)
Block(-4,36,0,minecraft:iron_bars)
Block(-4,37,-1,minecraft:iron_bars)
Block(-4,37,0,minecraft:iron_bars)
Block(-4,38,-2,minecraft:iron_bars)
Block(-4,38,-1,minecraft:iron_bars)
Block(-4,39,-2,minecraft:iron_bars)
Block(-4,39,-1,minecraft:iron_bars)
Block(-4,40,-3,minecraft:iron_bars)
Block(-4,40,-2,minecraft:iron_bars)
Block(-4,40,-1,minecraft:iron_bars)
Block(-4,41,-2,minecraft:iron_bars)
Block(-4,41,-1,minecraft:iron_bars)
Block(-4,42,-2,minecraft:iron_bars)
Block(-4,42,-1,minecraft:iron_bars)
Block(-4,43,-3,minecraft:iron_bars)
Block(-4,43,-2,minecraft:iron_bars)
Block(-4,43,-1,minecraft:iron_bars)
Block(-4,44,-2,minecraft:iron_bars)
Block(-4,44,-1,minecraft:iron_bars)
Block(-4,45,-2,minecraft:iron_bars)
Block(-4,45,-1,minecraft:iron_bars)
Block(-4,46,-2,minecraft:iron_bars)
Block(-4,46,-1,minecraft:iron_bars)
Block(-3,0,4,quark:limestone:1)
Block(-3,0,5,quark:limestone:1)
Block(-3,0,6,quark:limestone:1)
Block(-3,1,4,quark:limestone:1)
Block(-3,1,5,quark:limestone:1)
Block(-3,1,6,quark:limestone:1)
Block(-3,2,4,quark:limestone:1)
Block(-3,2,5,quark:limestone:1)
Block(-3,2,6,quark:limestone:1)
Block(-3,3,4,quark:limestone:1)
Block(-3,3,5,quark:limestone:1)
Block(-3,3,6,quark:limestone:1)
Block(-3,4,4,quark:limestone:1)
Block(-3,4,5,quark:limestone:1)
Block(-3,4,6,quark:limestone:1)
Block(-3,5,4,quark:limestone:1)
Block(-3,5,5,quark:limestone:1)
Block(-3,5,6,quark:limestone:1)
Block(-3,6,4,quark:limestone:1)
Block(-3,6,5,quark:limestone:1)
Block(-3,6,6,quark:limestone:1)
Block(-3,7,4,quark:limestone:1)
Block(-3,7,5,quark:limestone:1)
Block(-3,7,6,quark:limestone:1)
Block(-3,8,4,quark:limestone:1)
Block(-3,8,5,quark:limestone:1)
Block(-3,8,6,quark:limestone:1)
Block(-3,9,4,quark:limestone:1)
Block(-3,9,5,quark:limestone:1)
Block(-3,9,6,quark:limestone:1)
Block(-3,10,4,minecraft:iron_bars)
Block(-3,10,5,minecraft:iron_bars)
Block(-3,11,4,minecraft:iron_bars)
Block(-3,11,5,minecraft:iron_bars)
Block(-3,12,3,minecraft:iron_bars)
Block(-3,12,4,minecraft:iron_bars)
Block(-3,12,5,minecraft:iron_bars)
Block(-3,12,6,minecraft:iron_bars)
Block(-3,13,4,minecraft:iron_bars)
Block(-3,13,5,minecraft:iron_bars)
Block(-3,14,4,minecraft:iron_bars)
Block(-3,14,5,minecraft:iron_bars)
Block(-3,15,4,minecraft:iron_bars)
Block(-3,15,5,minecraft:iron_bars)
Block(-3,16,4,minecraft:iron_bars)
Block(-3,16,5,minecraft:iron_bars)
Block(-3,17,4,minecraft:iron_bars)
Block(-3,17,5,minecraft:iron_bars)
Block(-3,18,4,minecraft:iron_bars)
Block(-3,18,5,minecraft:iron_bars)
Block(-3,19,4,minecraft:iron_bars)
Block(-3,19,5,minecraft:iron_bars)
Block(-3,27,3,minecraft:iron_bars)
Block(-3,27,4,minecraft:iron_bars)
Block(-3,28,3,minecraft:iron_bars)
Block(-3,28,4,minecraft:iron_bars)
Block(-3,29,3,minecraft:iron_bars)
Block(-3,29,4,minecraft:iron_bars)
Block(-3,30,1,minecraft:iron_bars)
Block(-3,30,2,minecraft:iron_bars)
Block(-3,30,3,minecraft:iron_bars)
Block(-3,30,4,minecraft:iron_bars)
Block(-3,31,2,minecraft:iron_bars)
Block(-3,31,3,minecraft:iron_bars)
Block(-3,34,-1,minecraft:iron_bars)
Block(-3,34,0,minecraft:iron_bars)
Block(-3,34,1,minecraft:iron_bars)
Block(-3,35,0,minecraft:iron_bars)
Block(-3,35,1,minecraft:iron_bars)
Block(-3,36,-3,minecraft:iron_bars)
Block(-3,36,-2,minecraft:iron_bars)
Block(-3,37,-3,minecraft:iron_bars)
Block(-3,37,-2,minecraft:iron_bars)
Block(-3,38,-2,minecraft:iron_bars)
Block(-3,38,-1,minecraft:iron_bars)
Block(-3,39,-2,minecraft:iron_bars)
Block(-3,39,-1,minecraft:iron_bars)
Block(-3,40,-2,minecraft:iron_bars)
Block(-3,40,-1,minecraft:iron_bars)
Block(-3,40,0,minecraft:iron_bars)
Block(-3,41,-2,minecraft:iron_bars)
Block(-3,41,-1,minecraft:iron_bars)
Block(-3,41,0,minecraft:iron_bars)
Block(-3,42,-2,minecraft:iron_bars)
Block(-3,42,-1,minecraft:iron_bars)
Block(-3,43,-2,minecraft:iron_bars)
Block(-3,43,-1,minecraft:iron_bars)
Block(-3,43,0,minecraft:iron_bars)
Block(-3,44,-2,minecraft:iron_bars)
Block(-3,44,-1,minecraft:iron_bars)
Block(-3,45,-2,minecraft:iron_bars)
Block(-3,45,-1,minecraft:iron_bars)
Block(-3,45,0,minecraft:iron_bars)
Block(-3,46,-2,minecraft:iron_bars)
Block(-3,46,-1,minecraft:iron_bars)
Block(-2,12,3,minecraft:iron_bars)
Block(-2,12,4,minecraft:iron_bars)
Block(-2,12,5,minecraft:iron_bars)
Block(-2,12,6,minecraft:iron_bars)
Block(-2,13,2,minecraft:iron_bars)
Block(-2,13,3,minecraft:iron_bars)
Block(-2,13,6,minecraft:iron_bars)
Block(-2,13,7,minecraft:iron_bars)
Block(-2,15,3,minecraft:iron_bars)
Block(-2,15,4,minecraft:iron_bars)
Block(-2,15,5,minecraft:iron_bars)
Block(-2,15,6,minecraft:iron_bars)
Block(-2,16,4,minecraft:iron_bars)
Block(-2,16,5,minecraft:iron_bars)
Block(-2,17,3,minecraft:iron_bars)
Block(-2,17,4,minecraft:iron_bars)
Block(-2,17,5,minecraft:iron_bars)
Block(-2,17,6,minecraft:iron_bars)
Block(-2,18,4,minecraft:iron_bars)
Block(-2,18,5,minecraft:iron_bars)
Block(-2,19,4,minecraft:iron_bars)
Block(-2,19,5,minecraft:iron_bars)
Block(-2,20,4,minecraft:iron_bars)
Block(-2,20,5,minecraft:iron_bars)
Block(-2,21,4,minecraft:iron_bars)
Block(-2,21,5,minecraft:iron_bars)
Block(-2,22,4,minecraft:iron_bars)
Block(-2,22,5,minecraft:iron_bars)
Block(-2,23,4,minecraft:iron_bars)
Block(-2,23,5,minecraft:iron_bars)
Block(-2,24,4,minecraft:iron_bars)
Block(-2,24,5,minecraft:iron_bars)
Block(-2,25,4,minecraft:iron_bars)
Block(-2,25,5,minecraft:iron_bars)
Block(-2,26,4,minecraft:iron_bars)
Block(-2,26,5,minecraft:iron_bars)
Block(-2,27,2,minecraft:iron_bars)
Block(-2,27,3,minecraft:iron_bars)
Block(-2,27,4,minecraft:iron_bars)
Block(-2,28,3,minecraft:iron_bars)
Block(-2,28,4,minecraft:iron_bars)
Block(-2,29,3,minecraft:iron_bars)
Block(-2,29,4,minecraft:iron_bars)
Block(-2,29,5,minecraft:iron_bars)
Block(-2,30,0,minecraft:iron_bars)
Block(-2,30,1,minecraft:iron_bars)
Block(-2,30,2,minecraft:iron_bars)
Block(-2,30,3,minecraft:iron_bars)
Block(-2,30,4,minecraft:iron_bars)
Block(-2,34,-2,minecraft:iron_bars)
Block(-2,34,-1,minecraft:iron_bars)
Block(-2,34,0,minecraft:iron_bars)
Block(-2,35,-2,minecraft:iron_bars)
Block(-2,35,-1,minecraft:iron_bars)
Block(-2,36,-3,minecraft:iron_bars)
Block(-2,36,-2,minecraft:iron_bars)
Block(-2,37,-3,minecraft:iron_bars)
Block(-2,37,-2,minecraft:iron_bars)
Block(-2,40,-1,minecraft:iron_bars)
Block(-2,40,0,minecraft:iron_bars)
Block(-2,40,1,minecraft:iron_bars)
Block(-2,41,-1,minecraft:iron_bars)
Block(-2,41,0,minecraft:iron_bars)
Block(-2,42,0,minecraft:iron_bars)
Block(-2,42,1,minecraft:iron_bars)
Block(-2,43,-1,minecraft:iron_bars)
Block(-2,43,0,minecraft:iron_bars)
Block(-2,43,1,minecraft:iron_bars)
Block(-2,44,0,minecraft:iron_bars)
Block(-2,44,1,minecraft:iron_bars)
Block(-2,45,-1,minecraft:iron_bars)
Block(-2,45,0,minecraft:iron_bars)
Block(-1,13,2,minecraft:iron_bars)
Block(-1,13,3,minecraft:iron_bars)
Block(-1,13,6,minecraft:iron_bars)
Block(-1,13,7,minecraft:iron_bars)
Block(-1,14,1,minecraft:iron_bars)
Block(-1,14,2,minecraft:iron_bars)
Block(-1,14,7,minecraft:iron_bars)
Block(-1,14,8,minecraft:iron_bars)
Block(-1,15,2,minecraft:iron_bars)
Block(-1,15,3,minecraft:iron_bars)
Block(-1,15,4,minecraft:iron_bars)
Block(-1,15,5,minecraft:iron_bars)
Block(-1,15,6,minecraft:iron_bars)
Block(-1,15,7,minecraft:iron_bars)
Block(-1,17,3,minecraft:iron_bars)
Block(-1,17,4,minecraft:iron_bars)
Block(-1,17,5,minecraft:iron_bars)
Block(-1,17,6,minecraft:iron_bars)
Block(-1,18,2,minecraft:iron_bars)
Block(-1,18,3,minecraft:iron_bars)
Block(-1,18,6,minecraft:iron_bars)
Block(-1,18,7,minecraft:iron_bars)
Block(-1,19,2,minecraft:iron_bars)
Block(-1,19,3,minecraft:iron_bars)
Block(-1,19,6,minecraft:iron_bars)
Block(-1,19,7,minecraft:iron_bars)
Block(-1,20,3,minecraft:iron_bars)
Block(-1,20,4,minecraft:iron_bars)
Block(-1,20,5,minecraft:iron_bars)
Block(-1,20,6,minecraft:iron_bars)
Block(-1,21,4,minecraft:iron_bars)
Block(-1,21,5,minecraft:iron_bars)
Block(-1,22,3,minecraft:iron_bars)
Block(-1,22,4,minecraft:iron_bars)
Block(-1,22,5,minecraft:iron_bars)
Block(-1,22,6,minecraft:iron_bars)
Block(-1,23,4,minecraft:iron_bars)
Block(-1,23,5,minecraft:iron_bars)
Block(-1,24,3,minecraft:iron_bars)
Block(-1,24,4,minecraft:iron_bars)
Block(-1,24,5,minecraft:iron_bars)
Block(-1,24,6,minecraft:iron_bars)
Block(-1,25,3,minecraft:iron_bars)
Block(-1,25,4,minecraft:iron_bars)
Block(-1,25,5,minecraft:iron_bars)
Block(-1,25,6,minecraft:iron_bars)
Block(-1,26,4,minecraft:iron_bars)
Block(-1,26,5,minecraft:iron_bars)
Block(-1,27,1,minecraft:iron_bars)
Block(-1,27,2,minecraft:iron_bars)
Block(-1,27,3,minecraft:iron_bars)
Block(-1,28,5,minecraft:iron_bars)
Block(-1,28,6,minecraft:iron_bars)
Block(-1,29,4,minecraft:iron_bars)
Block(-1,29,5,minecraft:iron_bars)
Block(-1,30,-1,minecraft:iron_bars)
Block(-1,30,0,minecraft:iron_bars)
Block(-1,30,1,minecraft:iron_bars)
Block(-1,32,-3,minecraft:iron_bars)
Block(-1,32,-2,minecraft:iron_bars)
Block(-1,33,-3,minecraft:iron_bars)
Block(-1,33,-2,minecraft:iron_bars)
Block(-1,34,-2,minecraft:iron_bars)
Block(-1,34,-1,minecraft:iron_bars)
Block(-1,35,-2,minecraft:iron_bars)
Block(-1,35,-1,minecraft:iron_bars)
Block(-1,40,0,minecraft:iron_bars)
Block(-1,40,1,minecraft:iron_bars)
Block(-1,40,2,minecraft:iron_bars)
Block(-1,41,1,minecraft:iron_bars)
Block(-1,41,2,minecraft:iron_bars)
Block(-1,42,0,minecraft:iron_bars)
Block(-1,42,1,minecraft:iron_bars)
Block(-1,43,0,minecraft:iron_bars)
Block(-1,43,1,minecraft:iron_bars)
Block(-1,43,2,minecraft:iron_bars)
Block(-1,44,0,minecraft:iron_bars)
Block(-1,44,1,minecraft:iron_bars)
Block(0,13,0,minecraft:iron_bars)
Block(0,13,1,minecraft:iron_bars)
Block(0,13,8,minecraft:iron_bars)
Block(0,14,1,minecraft:iron_bars)
Block(0,14,2,minecraft:iron_bars)
Block(0,14,7,minecraft:iron_bars)
Block(0,14,8,minecraft:iron_bars)
Block(0,15,1,minecraft:iron_bars)
Block(0,15,2,minecraft:iron_bars)
Block(0,15,3,minecraft:iron_bars)
Block(0,15,6,minecraft:iron_bars)
Block(0,15,7,minecraft:iron_bars)
Block(0,15,8,minecraft:iron_bars)
Block(0,18,1,minecraft:iron_bars)
Block(0,18,2,minecraft:iron_bars)
Block(0,18,3,minecraft:iron_bars)
Block(0,18,6,minecraft:iron_bars)
Block(0,18,7,minecraft:iron_bars)
Block(0,18,8,minecraft:iron_bars)
Block(0,19,1,minecraft:iron_bars)
Block(0,19,2,minecraft:iron_bars)
Block(0,19,3,minecraft:iron_bars)
Block(0,19,6,minecraft:iron_bars)
Block(0,19,7,minecraft:iron_bars)
Block(0,19,8,minecraft:iron_bars)
Block(0,20,2,minecraft:iron_bars)
Block(0,20,3,minecraft:iron_bars)
Block(0,20,4,minecraft:iron_bars)
Block(0,20,5,minecraft:iron_bars)
Block(0,20,6,minecraft:iron_bars)
Block(0,20,7,minecraft:iron_bars)
Block(0,22,3,minecraft:iron_bars)
Block(0,22,4,minecraft:iron_bars)
Block(0,22,5,minecraft:iron_bars)
Block(0,22,6,minecraft:iron_bars)
Block(0,23,2,minecraft:iron_bars)
Block(0,23,3,minecraft:iron_bars)
Block(0,23,6,minecraft:iron_bars)
Block(0,23,7,minecraft:iron_bars)
Block(0,24,2,minecraft:iron_bars)
Block(0,24,3,minecraft:iron_bars)
Block(0,24,4,minecraft:iron_bars)
Block(0,24,5,minecraft:iron_bars)
Block(0,24,6,minecraft:iron_bars)
Block(0,24,7,minecraft:iron_bars)
Block(0,25,2,minecraft:iron_bars)
Block(0,25,3,minecraft:iron_bars)
Block(0,25,4,minecraft:iron_bars)
Block(0,25,5,minecraft:iron_bars)
Block(0,25,6,minecraft:iron_bars)
Block(0,25,7,minecraft:iron_bars)
Block(0,26,6,minecraft:iron_bars)
Block(0,26,7,minecraft:iron_bars)
Block(0,27,0,minecraft:iron_bars)
Block(0,27,1,minecraft:iron_bars)
Block(0,27,2,minecraft:iron_bars)
Block(0,27,6,minecraft:iron_bars)
Block(0,27,7,minecraft:iron_bars)
Block(0,28,5,minecraft:iron_bars)
Block(0,28,6,minecraft:iron_bars)
Block(0,30,-2,minecraft:iron_bars)
Block(0,30,-1,minecraft:iron_bars)
Block(0,30,0,minecraft:iron_bars)
Block(0,31,-2,minecraft:iron_bars)
Block(0,31,-1,minecraft:iron_bars)
Block(0,32,-3,minecraft:iron_bars)
Block(0,32,-2,minecraft:iron_bars)
Block(0,33,-3,minecraft:iron_bars)
Block(0,33,-2,minecraft:iron_bars)
Block(0,39,2,minecraft:iron_bars)
Block(0,39,3,minecraft:iron_bars)
Block(0,40,1,minecraft:iron_bars)
Block(0,40,2,minecraft:iron_bars)
Block(0,40,3,minecraft:iron_bars)
Block(0,41,1,minecraft:iron_bars)
Block(0,41,2,minecraft:iron_bars)
Block(0,42,2,minecraft:iron_bars)
Block(0,42,3,minecraft:iron_bars)
Block(0,43,1,minecraft:iron_bars)
Block(0,43,2,minecraft:iron_bars)
Block(0,43,3,minecraft:iron_bars)
Block(1,0,-2,quark:limestone:1)
Block(1,0,-1,quark:limestone:1)
Block(1,0,0,quark:limestone:1)
Block(1,1,-2,quark:limestone:1)
Block(1,1,-1,quark:limestone:1)
Block(1,1,0,quark:limestone:1)
Block(1,2,-2,quark:limestone:1)
Block(1,2,-1,quark:limestone:1)
Block(1,2,0,quark:limestone:1)
Block(1,3,-2,quark:limestone:1)
Block(1,3,-1,quark:limestone:1)
Block(1,3,0,quark:limestone:1)
Block(1,4,-2,quark:limestone:1)
Block(1,4,-1,quark:limestone:1)
Block(1,4,0,quark:limestone:1)
Block(1,5,-2,quark:limestone:1)
Block(1,5,-1,quark:limestone:1)
Block(1,5,0,quark:limestone:1)
Block(1,6,-2,quark:limestone:1)
Block(1,6,-1,quark:limestone:1)
Block(1,6,0,quark:limestone:1)
Block(1,7,-2,quark:limestone:1)
Block(1,7,-1,quark:limestone:1)
Block(1,7,0,quark:limestone:1)
Block(1,8,-2,quark:limestone:1)
Block(1,8,-1,quark:limestone:1)
Block(1,8,0,quark:limestone:1)
Block(1,9,-2,quark:limestone:1)
Block(1,9,-1,quark:limestone:1)
Block(1,9,0,quark:limestone:1)
Block(1,12,-1,minecraft:iron_bars)
Block(1,12,0,minecraft:iron_bars)
Block(1,13,0,minecraft:iron_bars)
Block(1,13,1,minecraft:iron_bars)
Block(1,13,8,minecraft:iron_bars)
Block(1,15,0,minecraft:iron_bars)
Block(1,15,1,minecraft:iron_bars)
Block(1,15,2,minecraft:iron_bars)
Block(1,15,7,minecraft:iron_bars)
Block(1,15,8,minecraft:iron_bars)
Block(1,17,0,minecraft:iron_bars)
Block(1,17,1,minecraft:iron_bars)
Block(1,17,8,minecraft:iron_bars)
Block(1,18,1,minecraft:iron_bars)
Block(1,18,2,minecraft:iron_bars)
Block(1,18,7,minecraft:iron_bars)
Block(1,18,8,minecraft:iron_bars)
Block(1,19,1,minecraft:iron_bars)
Block(1,19,2,minecraft:iron_bars)
Block(1,19,7,minecraft:iron_bars)
Block(1,19,8,minecraft:iron_bars)
Block(1,20,1,minecraft:iron_bars)
Block(1,20,2,minecraft:iron_bars)
Block(1,20,3,minecraft:iron_bars)
Block(1,20,6,minecraft:iron_bars)
Block(1,20,7,minecraft:iron_bars)
Block(1,20,8,minecraft:iron_bars)
Block(1,22,1,minecraft:iron_bars)
Block(1,22,2,minecraft:iron_bars)
Block(1,22,7,minecraft:iron_bars)
Block(1,22,8,minecraft:iron_bars)
Block(1,23,2,minecraft:iron_bars)
Block(1,23,3,minecraft:iron_bars)
Block(1,23,6,minecraft:iron_bars)
Block(1,23,7,minecraft:iron_bars)
Block(1,24,1,minecraft:iron_bars)
Block(1,24,2,minecraft:iron_bars)
Block(1,24,3,minecraft:iron_bars)
Block(1,24,6,minecraft:iron_bars)
Block(1,24,7,minecraft:iron_bars)
Block(1,24,8,minecraft:iron_bars)
Block(1,25,1,minecraft:iron_bars)
Block(1,25,2,minecraft:iron_bars)
Block(1,25,3,minecraft:iron_bars)
Block(1,25,6,minecraft:iron_bars)
Block(1,25,7,minecraft:iron_bars)
Block(1,25,8,minecraft:iron_bars)
Block(1,26,6,minecraft:iron_bars)
Block(1,26,7,minecraft:iron_bars)
Block(1,27,-1,minecraft:iron_bars)
Block(1,27,0,minecraft:iron_bars)
Block(1,27,1,minecraft:iron_bars)
Block(1,27,6,minecraft:iron_bars)
Block(1,27,7,minecraft:iron_bars)
Block(1,28,-1,minecraft:iron_bars)
Block(1,28,0,minecraft:iron_bars)
Block(1,28,7,minecraft:iron_bars)
Block(1,28,8,minecraft:iron_bars)
Block(1,29,-1,minecraft:iron_bars)
Block(1,29,0,minecraft:iron_bars)
Block(1,30,-2,minecraft:iron_bars)
Block(1,30,-1,minecraft:iron_bars)
Block(1,30,0,minecraft:iron_bars)
Block(1,31,-2,minecraft:iron_bars)
Block(1,31,-1,minecraft:iron_bars)
Block(1,38,3,minecraft:iron_bars)
Block(1,38,4,minecraft:iron_bars)
Block(1,39,2,minecraft:iron_bars)
Block(1,39,3,minecraft:iron_bars)
Block(1,40,2,minecraft:iron_bars)
Block(1,40,3,minecraft:iron_bars)
Block(1,40,4,minecraft:iron_bars)
Block(1,41,3,minecraft:iron_bars)
Block(1,41,4,minecraft:iron_bars)
Block(1,42,2,minecraft:iron_bars)
Block(1,42,3,minecraft:iron_bars)
Block(1,43,2,minecraft:iron_bars)
Block(1,43,3,minecraft:iron_bars)
Block(1,43,4,minecraft:iron_bars)
Block(2,0,-2,quark:limestone:1)
Block(2,0,-1,quark:limestone:1)
Block(2,0,0,quark:limestone:1)
Block(2,1,-2,quark:limestone:1)
Block(2,1,-1,quark:limestone:1)
Block(2,1,0,quark:limestone:1)
Block(2,2,-2,quark:limestone:1)
Block(2,2,-1,quark:limestone:1)
Block(2,2,0,quark:limestone:1)
Block(2,3,-2,quark:limestone:1)
Block(2,3,-1,quark:limestone:1)
Block(2,3,0,quark:limestone:1)
Block(2,4,-2,quark:limestone:1)
Block(2,4,-1,quark:limestone:1)
Block(2,4,0,quark:limestone:1)
Block(2,5,-2,quark:limestone:1)
Block(2,5,-1,quark:limestone:1)
Block(2,5,0,quark:limestone:1)
Block(2,6,-2,quark:limestone:1)
Block(2,6,-1,quark:limestone:1)
Block(2,6,0,quark:limestone:1)
Block(2,7,-2,quark:limestone:1)
Block(2,7,-1,quark:limestone:1)
Block(2,7,0,quark:limestone:1)
Block(2,8,-2,quark:limestone:1)
Block(2,8,-1,quark:limestone:1)
Block(2,8,0,quark:limestone:1)
Block(2,9,-2,quark:limestone:1)
Block(2,9,-1,quark:limestone:1)
Block(2,9,0,quark:limestone:1)
Block(2,10,-2,minecraft:iron_bars)
Block(2,10,-1,minecraft:iron_bars)
Block(2,11,-2,minecraft:iron_bars)
Block(2,11,-1,minecraft:iron_bars)
Block(2,12,-2,minecraft:iron_bars)
Block(2,12,-1,minecraft:iron_bars)
Block(2,12,0,minecraft:iron_bars)
Block(2,13,-2,minecraft:iron_bars)
Block(2,13,-1,minecraft:iron_bars)
Block(2,14,-2,minecraft:iron_bars)
Block(2,14,-1,minecraft:iron_bars)
Block(2,15,-1,minecraft:iron_bars)
Block(2,15,0,minecraft:iron_bars)
Block(2,15,1,minecraft:iron_bars)
Block(2,15,8,minecraft:iron_bars)
Block(2,16,-1,minecraft:iron_bars)
Block(2,16,0,minecraft:iron_bars)
Block(2,17,-1,minecraft:iron_bars)
Block(2,17,0,minecraft:iron_bars)
Block(2,17,1,minecraft:iron_bars)
Block(2,17,8,minecraft:iron_bars)
Block(2,18,-1,minecraft:iron_bars)
Block(2,18,0,minecraft:iron_bars)
Block(2,19,-1,minecraft:iron_bars)
Block(2,19,0,minecraft:iron_bars)
Block(2,20,0,minecraft:iron_bars)
Block(2,20,1,minecraft:iron_bars)
Block(2,20,2,minecraft:iron_bars)
Block(2,20,7,minecraft:iron_bars)
Block(2,20,8,minecraft:iron_bars)
Block(2,21,0,minecraft:iron_bars)
Block(2,21,1,minecraft:iron_bars)
Block(2,21,8,minecraft:iron_bars)
Block(2,22,0,minecraft:iron_bars)
Block(2,22,1,minecraft:iron_bars)
Block(2,22,2,minecraft:iron_bars)
Block(2,22,7,minecraft:iron_bars)
Block(2,22,8,minecraft:iron_bars)
Block(2,23,0,minecraft:iron_bars)
Block(2,23,1,minecraft:iron_bars)
Block(2,23,8,minecraft:iron_bars)
Block(2,24,0,minecraft:iron_bars)
Block(2,24,1,minecraft:iron_bars)
Block(2,24,2,minecraft:iron_bars)
Block(2,24,7,minecraft:iron_bars)
Block(2,24,8,minecraft:iron_bars)
Block(2,25,0,minecraft:iron_bars)
Block(2,25,1,minecraft:iron_bars)
Block(2,25,2,minecraft:iron_bars)
Block(2,25,7,minecraft:iron_bars)
Block(2,25,8,minecraft:iron_bars)
Block(2,26,0,minecraft:iron_bars)
Block(2,26,1,minecraft:iron_bars)
Block(2,26,8,minecraft:iron_bars)
Block(2,27,-1,minecraft:iron_bars)
Block(2,27,0,minecraft:iron_bars)
Block(2,28,-1,minecraft:iron_bars)
Block(2,28,0,minecraft:iron_bars)
Block(2,28,7,minecraft:iron_bars)
Block(2,28,8,minecraft:iron_bars)
Block(2,29,-1,minecraft:iron_bars)
Block(2,29,0,minecraft:iron_bars)
Block(2,29,1,minecraft:iron_bars)
Block(2,29,8,minecraft:iron_bars)
Block(2,30,-1,minecraft:iron_bars)
Block(2,30,0,minecraft:iron_bars)
Block(2,37,4,minecraft:iron_bars)
Block(2,37,5,minecraft:iron_bars)
Block(2,38,3,minecraft:iron_bars)
Block(2,38,4,minecraft:iron_bars)
Block(2,40,3,minecraft:iron_bars)
Block(2,40,4,minecraft:iron_bars)
Block(2,40,5,minecraft:iron_bars)
Block(2,41,3,minecraft:iron_bars)
Block(2,41,4,minecraft:iron_bars)
Block(2,42,4,minecraft:iron_bars)
Block(2,42,5,minecraft:iron_bars)
Block(2,43,3,minecraft:iron_bars)
Block(2,43,4,minecraft:iron_bars)
Block(2,43,5,minecraft:iron_bars)
Block(3,0,-2,quark:limestone:1)
Block(3,0,-1,quark:limestone:1)
Block(3,0,0,quark:limestone:1)
Block(3,1,-2,quark:limestone:1)
Block(3,1,-1,quark:limestone:1)
Block(3,1,0,quark:limestone:1)
Block(3,2,-2,quark:limestone:1)
Block(3,2,-1,quark:limestone:1)
Block(3,2,0,quark:limestone:1)
Block(3,3,-2,quark:limestone:1)
Block(3,3,-1,quark:limestone:1)
Block(3,3,0,quark:limestone:1)
Block(3,4,-2,quark:limestone:1)
Block(3,4,-1,quark:limestone:1)
Block(3,4,0,quark:limestone:1)
Block(3,5,-2,quark:limestone:1)
Block(3,5,-1,quark:limestone:1)
Block(3,5,0,quark:limestone:1)
Block(3,6,-2,quark:limestone:1)
Block(3,6,-1,quark:limestone:1)
Block(3,6,0,quark:limestone:1)
Block(3,7,-2,quark:limestone:1)
Block(3,7,-1,quark:limestone:1)
Block(3,7,0,quark:limestone:1)
Block(3,8,-2,quark:limestone:1)
Block(3,8,-1,quark:limestone:1)
Block(3,8,0,quark:limestone:1)
Block(3,9,-2,quark:limestone:1)
Block(3,9,-1,quark:limestone:1)
Block(3,9,0,quark:limestone:1)
Block(3,10,-2,minecraft:iron_bars)
Block(3,10,-1,minecraft:iron_bars)
Block(3,11,-2,minecraft:iron_bars)
Block(3,11,-1,minecraft:iron_bars)
Block(3,12,-2,minecraft:iron_bars)
Block(3,12,-1,minecraft:iron_bars)
Block(3,12,0,minecraft:iron_bars)
Block(3,13,-2,minecraft:iron_bars)
Block(3,13,-1,minecraft:iron_bars)
Block(3,14,-2,minecraft:iron_bars)
Block(3,14,-1,minecraft:iron_bars)
Block(3,15,-1,minecraft:iron_bars)
Block(3,15,0,minecraft:iron_bars)
Block(3,15,1,minecraft:iron_bars)
Block(3,15,8,minecraft:iron_bars)
Block(3,16,-1,minecraft:iron_bars)
Block(3,16,0,minecraft:iron_bars)
Block(3,17,-1,minecraft:iron_bars)
Block(3,17,0,minecraft:iron_bars)
Block(3,17,1,minecraft:iron_bars)
Block(3,17,8,minecraft:iron_bars)
Block(3,18,-1,minecraft:iron_bars)
Block(3,18,0,minecraft:iron_bars)
Block(3,19,-1,minecraft:iron_bars)
Block(3,19,0,minecraft:iron_bars)
Block(3,20,0,minecraft:iron_bars)
Block(3,20,1,minecraft:iron_bars)
Block(3,20,2,minecraft:iron_bars)
Block(3,20,7,minecraft:iron_bars)
Block(3,20,8,minecraft:iron_bars)
Block(3,21,0,minecraft:iron_bars)
Block(3,21,1,minecraft:iron_bars)
Block(3,21,8,minecraft:iron_bars)
Block(3,22,0,minecraft:iron_bars)
Block(3,22,1,minecraft:iron_bars)
Block(3,22,2,minecraft:iron_bars)
Block(3,22,7,minecraft:iron_bars)
Block(3,22,8,minecraft:iron_bars)
Block(3,23,0,minecraft:iron_bars)
Block(3,23,1,minecraft:iron_bars)
Block(3,23,8,minecraft:iron_bars)
Block(3,24,0,minecraft:iron_bars)
Block(3,24,1,minecraft:iron_bars)
Block(3,24,2,minecraft:iron_bars)
Block(3,24,7,minecraft:iron_bars)
Block(3,24,8,minecraft:iron_bars)
Block(3,25,0,minecraft:iron_bars)
Block(3,25,1,minecraft:iron_bars)
Block(3,25,2,minecraft:iron_bars)
Block(3,25,7,minecraft:iron_bars)
Block(3,25,8,minecraft:iron_bars)
Block(3,26,0,minecraft:iron_bars)
Block(3,26,1,minecraft:iron_bars)
Block(3,26,8,minecraft:iron_bars)
Block(3,28,1,minecraft:iron_bars)
Block(3,28,2,minecraft:iron_bars)
Block(3,29,0,minecraft:iron_bars)
Block(3,29,1,minecraft:iron_bars)
Block(3,29,8,minecraft:iron_bars)
Block(3,37,4,minecraft:iron_bars)
Block(3,37,5,minecraft:iron_bars)
Block(3,38,5,minecraft:iron_bars)
Block(3,38,6,minecraft:iron_bars)
Block(3,40,4,minecraft:iron_bars)
Block(3,40,5,minecraft:iron_bars)
Block(3,40,6,minecraft:iron_bars)
Block(3,41,5,minecraft:iron_bars)
Block(3,41,6,minecraft:iron_bars)
Block(3,42,4,minecraft:iron_bars)
Block(3,42,5,minecraft:iron_bars)
Block(3,43,4,minecraft:iron_bars)
Block(3,43,5,minecraft:iron_bars)
Block(3,43,6,minecraft:iron_bars)
Block(4,12,-1,minecraft:iron_bars)
Block(4,12,0,minecraft:iron_bars)
Block(4,13,0,minecraft:iron_bars)
Block(4,13,1,minecraft:iron_bars)
Block(4,13,8,minecraft:iron_bars)
Block(4,15,0,minecraft:iron_bars)
Block(4,15,1,minecraft:iron_bars)
Block(4,15,2,minecraft:iron_bars)
Block(4,15,7,minecraft:iron_bars)
Block(4,15,8,minecraft:iron_bars)
Block(4,17,0,minecraft:iron_bars)
Block(4,17,1,minecraft:iron_bars)
Block(4,17,8,minecraft:iron_bars)
Block(4,18,1,minecraft:iron_bars)
Block(4,18,2,minecraft:iron_bars)
Block(4,18,7,minecraft:iron_bars)
Block(4,18,8,minecraft:iron_bars)
Block(4,19,1,minecraft:iron_bars)
Block(4,19,2,minecraft:iron_bars)
Block(4,19,7,minecraft:iron_bars)
Block(4,19,8,minecraft:iron_bars)
Block(4,20,1,minecraft:iron_bars)
Block(4,20,2,minecraft:iron_bars)
Block(4,20,3,minecraft:iron_bars)
Block(4,20,6,minecraft:iron_bars)
Block(4,20,7,minecraft:iron_bars)
Block(4,20,8,minecraft:iron_bars)
Block(4,22,1,minecraft:iron_bars)
Block(4,22,2,minecraft:iron_bars)
Block(4,22,7,minecraft:iron_bars)
Block(4,22,8,minecraft:iron_bars)
Block(4,23,2,minecraft:iron_bars)
Block(4,23,3,minecraft:iron_bars)
Block(4,23,6,minecraft:iron_bars)
Block(4,23,7,minecraft:iron_bars)
Block(4,24,1,minecraft:iron_bars)
Block(4,24,2,minecraft:iron_bars)
Block(4,24,3,minecraft:iron_bars)
Block(4,24,6,minecraft:iron_bars)
Block(4,24,7,minecraft:iron_bars)
Block(4,24,8,minecraft:iron_bars)
Block(4,25,1,minecraft:iron_bars)
Block(4,25,2,minecraft:iron_bars)
Block(4,25,3,minecraft:iron_bars)
Block(4,25,6,minecraft:iron_bars)
Block(4,25,7,minecraft:iron_bars)
Block(4,25,8,minecraft:iron_bars)
Block(4,26,2,minecraft:iron_bars)
Block(4,26,3,minecraft:iron_bars)
Block(4,27,2,minecraft:iron_bars)
Block(4,27,3,minecraft:iron_bars)
Block(4,27,8,minecraft:iron_bars)
Block(4,28,1,minecraft:iron_bars)
Block(4,28,2,minecraft:iron_bars)
Block(4,38,5,minecraft:iron_bars)
Block(4,38,6,minecraft:iron_bars)
Block(4,39,6,minecraft:iron_bars)
Block(4,39,7,minecraft:iron_bars)
Block(4,40,5,minecraft:iron_bars)
Block(4,40,6,minecraft:iron_bars)
Block(4,40,7,minecraft:iron_bars)
Block(4,41,5,minecraft:iron_bars)
Block(4,41,6,minecraft:iron_bars)
Block(4,42,6,minecraft:iron_bars)
Block(4,42,7,minecraft:iron_bars)
Block(4,43,5,minecraft:iron_bars)
Block(4,43,6,minecraft:iron_bars)
Block(4,43,7,minecraft:iron_bars)
Block(5,13,0,minecraft:iron_bars)
Block(5,13,1,minecraft:iron_bars)
Block(5,13,8,minecraft:iron_bars)
Block(5,14,1,minecraft:iron_bars)
Block(5,14,2,minecraft:iron_bars)
Block(5,14,7,minecraft:iron_bars)
Block(5,14,8,minecraft:iron_bars)
Block(5,15,1,minecraft:iron_bars)
Block(5,15,2,minecraft:iron_bars)
Block(5,15,3,minecraft:iron_bars)
Block(5,15,6,minecraft:iron_bars)
Block(5,15,7,minecraft:iron_bars)
Block(5,15,8,minecraft:iron_bars)
Block(5,18,1,minecraft:iron_bars)
Block(5,18,2,minecraft:iron_bars)
Block(5,18,3,minecraft:iron_bars)
Block(5,18,6,minecraft:iron_bars)
Block(5,18,7,minecraft:iron_bars)
Block(5,18,8,minecraft:iron_bars)
Block(5,19,1,minecraft:iron_bars)
Block(5,19,2,minecraft:iron_bars)
Block(5,19,3,minecraft:iron_bars)
Block(5,19,6,minecraft:iron_bars)
Block(5,19,7,minecraft:iron_bars)
Block(5,19,8,minecraft:iron_bars)
Block(5,20,2,minecraft:iron_bars)
Block(5,20,3,minecraft:iron_bars)
Block(5,20,4,minecraft:iron_bars)
Block(5,20,5,minecraft:iron_bars)
Block(5,20,6,minecraft:iron_bars)
Block(5,20,7,minecraft:iron_bars)
Block(5,22,3,minecraft:iron_bars)
Block(5,22,4,minecraft:iron_bars)
Block(5,22,5,minecraft:iron_bars)
Block(5,22,6,minecraft:iron_bars)
Block(5,23,2,minecraft:iron_bars)
Block(5,23,3,minecraft:iron_bars)
Block(5,23,6,minecraft:iron_bars)
Block(5,23,7,minecraft:iron_bars)
Block(5,24,2,minecraft:iron_bars)
Block(5,24,3,minecraft:iron_bars)
Block(5,24,4,minecraft:iron_bars)
Block(5,24,5,minecraft:iron_bars)
Block(5,24,6,minecraft:iron_bars)
Block(5,24,7,minecraft:iron_bars)
Block(5,25,2,minecraft:iron_bars)
Block(5,25,3,minecraft:iron_bars)
Block(5,25,4,minecraft:iron_bars)
Block(5,25,5,minecraft:iron_bars)
Block(5,25,6,minecraft:iron_bars)
Block(5,25,7,minecraft:iron_bars)
Block(5,26,2,minecraft:iron_bars)
Block(5,26,3,minecraft:iron_bars)
Block(5,27,2,minecraft:iron_bars)
Block(5,27,3,minecraft:iron_bars)
Block(5,27,7,minecraft:iron_bars)
Block(5,27,8,minecraft:iron_bars)
Block(5,28,3,minecraft:iron_bars)
Block(5,28,4,minecraft:iron_bars)
Block(5,39,6,minecraft:iron_bars)
Block(5,39,7,minecraft:iron_bars)
Block(5,40,6,minecraft:iron_bars)
Block(5,40,7,minecraft:iron_bars)
Block(5,40,8,minecraft:iron_bars)
Block(5,41,7,minecraft:iron_bars)
Block(5,41,8,minecraft:iron_bars)
Block(5,42,6,minecraft:iron_bars)
Block(5,42,7,minecraft:iron_bars)
Block(5,43,6,minecraft:iron_bars)
Block(5,43,7,minecraft:iron_bars)
Block(5,43,8,minecraft:iron_bars)
Block(6,13,2,minecraft:iron_bars)
Block(6,13,3,minecraft:iron_bars)
Block(6,13,6,minecraft:iron_bars)
Block(6,13,7,minecraft:iron_bars)
Block(6,14,1,minecraft:iron_bars)
Block(6,14,2,minecraft:iron_bars)
Block(6,14,7,minecraft:iron_bars)
Block(6,14,8,minecraft:iron_bars)
Block(6,15,2,minecraft:iron_bars)
Block(6,15,3,minecraft:iron_bars)
Block(6,15,4,minecraft:iron_bars)
Block(6,15,5,minecraft:iron_bars)
Block(6,15,6,minecraft:iron_bars)
Block(6,15,7,minecraft:iron_bars)
Block(6,17,3,minecraft:iron_bars)
Block(6,17,4,minecraft:iron_bars)
Block(6,17,5,minecraft:iron_bars)
Block(6,17,6,minecraft:iron_bars)
Block(6,18,2,minecraft:iron_bars)
Block(6,18,3,minecraft:iron_bars)
Block(6,18,6,minecraft:iron_bars)
Block(6,18,7,minecraft:iron_bars)
Block(6,19,2,minecraft:iron_bars)
Block(6,19,3,minecraft:iron_bars)
Block(6,19,6,minecraft:iron_bars)
Block(6,19,7,minecraft:iron_bars)
Block(6,20,3,minecraft:iron_bars)
Block(6,20,4,minecraft:iron_bars)
Block(6,20,5,minecraft:iron_bars)
Block(6,20,6,minecraft:iron_bars)
Block(6,21,4,minecraft:iron_bars)
Block(6,21,5,minecraft:iron_bars)
Block(6,22,3,minecraft:iron_bars)
Block(6,22,4,minecraft:iron_bars)
Block(6,22,5,minecraft:iron_bars)
Block(6,22,6,minecraft:iron_bars)
Block(6,23,4,minecraft:iron_bars)
Block(6,23,5,minecraft:iron_bars)
Block(6,24,3,minecraft:iron_bars)
Block(6,24,4,minecraft:iron_bars)
Block(6,24,5,minecraft:iron_bars)
Block(6,24,6,minecraft:iron_bars)
Block(6,25,3,minecraft:iron_bars)
Block(6,25,4,minecraft:iron_bars)
Block(6,25,5,minecraft:iron_bars)
Block(6,25,6,minecraft:iron_bars)
Block(6,26,4,minecraft:iron_bars)
Block(6,26,5,minecraft:iron_bars)
Block(6,27,6,minecraft:iron_bars)
Block(6,27,7,minecraft:iron_bars)
Block(6,27,8,minecraft:iron_bars)
Block(6,28,3,minecraft:iron_bars)
Block(6,28,4,minecraft:iron_bars)
Block(6,29,4,minecraft:iron_bars)
Block(6,29,5,minecraft:iron_bars)
Block(6,30,8,minecraft:iron_bars)
Block(6,40,7,minecraft:iron_bars)
Block(6,40,8,minecraft:iron_bars)
Block(6,41,7,minecraft:iron_bars)
Block(6,41,8,minecraft:iron_bars)
Block(6,42,8,minecraft:iron_bars)
Block(6,43,7,minecraft:iron_bars)
Block(6,43,8,minecraft:iron_bars)
Block(6,44,8,minecraft:iron_bars)
Block(7,0,4,quark:limestone:1)
Block(7,0,5,quark:limestone:1)
Block(7,0,6,quark:limestone:1)
Block(7,1,4,quark:limestone:1)
Block(7,1,5,quark:limestone:1)
Block(7,1,6,quark:limestone:1)
Block(7,2,4,quark:limestone:1)
Block(7,2,5,quark:limestone:1)
Block(7,2,6,quark:limestone:1)
Block(7,3,4,quark:limestone:1)
Block(7,3,5,quark:limestone:1)
Block(7,3,6,quark:limestone:1)
Block(7,4,4,quark:limestone:1)
Block(7,4,5,quark:limestone:1)
Block(7,4,6,quark:limestone:1)
Block(7,5,4,quark:limestone:1)
Block(7,5,5,quark:limestone:1)
Block(7,5,6,quark:limestone:1)
Block(7,6,4,quark:limestone:1)
Block(7,6,5,quark:limestone:1)
Block(7,6,6,quark:limestone:1)
Block(7,7,4,quark:limestone:1)
Block(7,7,5,quark:limestone:1)
Block(7,7,6,quark:limestone:1)
Block(7,8,4,quark:limestone:1)
Block(7,8,5,quark:limestone:1)
Block(7,8,6,quark:limestone:1)
Block(7,9,4,quark:limestone:1)
Block(7,9,5,quark:limestone:1)
Block(7,9,6,quark:limestone:1)
Block(7,12,3,minecraft:iron_bars)
Block(7,12,4,minecraft:iron_bars)
Block(7,12,5,minecraft:iron_bars)
Block(7,12,6,minecraft:iron_bars)
Block(7,13,2,minecraft:iron_bars)
Block(7,13,3,minecraft:iron_bars)
Block(7,13,6,minecraft:iron_bars)
Block(7,13,7,minecraft:iron_bars)
Block(7,15,3,minecraft:iron_bars)
Block(7,15,4,minecraft:iron_bars)
Block(7,15,5,minecraft:iron_bars)
Block(7,15,6,minecraft:iron_bars)
Block(7,16,4,minecraft:iron_bars)
Block(7,16,5,minecraft:iron_bars)
Block(7,17,3,minecraft:iron_bars)
Block(7,17,4,minecraft:iron_bars)
Block(7,17,5,minecraft:iron_bars)
Block(7,17,6,minecraft:iron_bars)
Block(7,18,4,minecraft:iron_bars)
Block(7,18,5,minecraft:iron_bars)
Block(7,19,4,minecraft:iron_bars)
Block(7,19,5,minecraft:iron_bars)
Block(7,20,4,minecraft:iron_bars)
Block(7,20,5,minecraft:iron_bars)
Block(7,21,4,minecraft:iron_bars)
Block(7,21,5,minecraft:iron_bars)
Block(7,22,4,minecraft:iron_bars)
Block(7,22,5,minecraft:iron_bars)
Block(7,23,4,minecraft:iron_bars)
Block(7,23,5,minecraft:iron_bars)
Block(7,24,4,minecraft:iron_bars)
Block(7,24,5,minecraft:iron_bars)
Block(7,25,4,minecraft:iron_bars)
Block(7,25,5,minecraft:iron_bars)
Block(7,26,4,minecraft:iron_bars)
Block(7,26,5,minecraft:iron_bars)
Block(7,27,5,minecraft:iron_bars)
Block(7,27,6,minecraft:iron_bars)
Block(7,27,7,minecraft:iron_bars)
Block(7,28,5,minecraft:iron_bars)
Block(7,28,6,minecraft:iron_bars)
Block(7,29,4,minecraft:iron_bars)
Block(7,29,5,minecraft:iron_bars)
Block(7,29,6,minecraft:iron_bars)
Block(7,30,5,minecraft:iron_bars)
Block(7,30,6,minecraft:iron_bars)
Block(7,30,7,minecraft:iron_bars)
Block(7,30,8,minecraft:iron_bars)
Block(7,40,8,minecraft:iron_bars)
Block(7,42,8,minecraft:iron_bars)
Block(7,43,8,minecraft:iron_bars)
Block(7,44,8,minecraft:iron_bars)

#######################################################################
# +-----------------------------------------------------------------+ #
# |                             Branches                            | #
# +-----------------------------------------------------------------+ #
#######################################################################

Branch(16,0,0,true,PowerLineNewC1R0,NORTH,100.0,0)

#######################################################################
# +-----------------------------------------------------------------+ #
# |                             Entities                            | #
# +-----------------------------------------------------------------+ #
#######################################################################


#######################################################################
# +-----------------------------------------------------------------+ #
# |                            Particles                            | #
# +-----------------------------------------------------------------+ #
#######################################################################


#######################################################################
# +-----------------------------------------------------------------+ #
# |                             Spawners                            | #
# +-----------------------------------------------------------------+ #
#######################################################################


#######################################################################
# +-----------------------------------------------------------------+ #
# |                             ModData                             | #
# +-----------------------------------------------------------------+ #
#######################################################################

