
#######################################################################
# +-----------------------------------------------------------------+ #
# |                            BO4 object                           | #
# +-----------------------------------------------------------------+ #
#######################################################################

Author: NLBlackEagle

Description: No description given

SettingsMode: WriteWithoutComments


#######################################################################
# +-----------------------------------------------------------------+ #
# |                          Main settings                          | #
# +-----------------------------------------------------------------+ #
#######################################################################

FixedRotation: 

Frequency: 0

SpawnHeight: highestBlock

UseCenterForHighestBlock: true

##############################
# Height Limits for the BO4. #
##############################

MinHeight: 0

MaxHeight: 255

InheritBO3: 

InheritBO3Rotation: NORTH

OverrideChildSettings: true

OverrideParentHeight: false

CanOverride: true

BranchFrequency: 0

BranchFrequencyGroup: 

MustBeBelowOther: false

MustBeInside: 

CannotBeInside: 

ReplacesBO3: 

MustBeInsideWorldBorders: true

CanSpawnOnWater: true

SpawnOnWaterOnly: false

SpawnUnderWater: false

SpawnAtWaterLevel: false

HeightOffset: 0

RemoveAir: false

ReplaceAbove: 

ReplaceBelow: 

ReplaceWithBiomeBlocks: true

ReplaceWithSurfaceBlock: GRASS

ReplaceWithGroundBlock: DIRT

ReplaceWithStoneBlock: STONE

SmoothRadius: 0

SmoothHeightOffset: 0

SmoothStartTop: false

SmoothStartWood: false

SmoothingSurfaceBlock: 

SmoothingGroundBlock: 

BO3Group: 

IsSpawnPoint: false

DoReplaceBlocks: false


#######################################################################
# +-----------------------------------------------------------------+ #
# |                              Blocks                             | #
# +-----------------------------------------------------------------+ #
#######################################################################

Block(-8,0,-7,quark:limestone:0)
Block(-8,0,-6,quark:limestone:0)
Block(-8,0,-5,quark:limestone:0)
Block(-8,0,-4,quark:limestone:0)
Block(-8,0,-3,quark:limestone:0)
Block(-8,1,-7,COBBLESTONE_STAIRS:2)
Block(-8,1,-6,COBBLESTONE_STAIRS:0)
Block(-8,1,-5,COBBLESTONE_STAIRS:0)
Block(-8,1,-4,COBBLESTONE_STAIRS:0)
Block(-8,1,-3,COBBLESTONE_STAIRS:0)
Block(-7,0,-7,quark:limestone:0)
RandomBlock(-7,0,-6,quark:iron_plate:1,70,STAINED_CLAY:15,30,STAINED_CLAY:7,30,quark:iron_plate:1,100)
RandomBlock(-7,0,-5,quark:iron_plate:1,70,STAINED_CLAY:15,30,STAINED_CLAY:7,30,quark:iron_plate:1,100)
RandomBlock(-7,0,-4,quark:iron_plate:1,70,STAINED_CLAY:15,30,STAINED_CLAY:7,30,quark:iron_plate:1,100)
Block(-7,0,-3,quark:limestone:0)
Block(-7,1,-7,COBBLESTONE_STAIRS:2)
RandomBlock(-7,1,-6,quark:iron_plate:1,70,STAINED_CLAY:15,30,STAINED_CLAY:7,30,quark:iron_plate:1,100)
RandomBlock(-7,1,-5,quark:iron_plate:1,70,STAINED_CLAY:15,30,STAINED_CLAY:7,30,quark:iron_plate:1,100)
RandomBlock(-7,1,-4,quark:iron_plate:1,70,STAINED_CLAY:15,30,STAINED_CLAY:7,30,quark:iron_plate:1,100)
Block(-7,1,-3,COBBLESTONE_STAIRS:3)
RandomBlock(-7,2,-6,quark:iron_plate:1,70,STAINED_CLAY:15,30,STAINED_CLAY:7,30,quark:iron_plate:1,100)
RandomBlock(-7,2,-5,quark:iron_plate:1,70,STAINED_CLAY:15,30,STAINED_CLAY:7,30,quark:iron_plate:1,100)
RandomBlock(-7,2,-4,quark:iron_plate:1,70,STAINED_CLAY:15,30,STAINED_CLAY:7,30,quark:iron_plate:1,100)
RandomBlock(-7,3,-6,quark:iron_plate:1,70,STAINED_CLAY:15,30,STAINED_CLAY:7,30,quark:iron_plate:1,100)
RandomBlock(-7,3,-5,quark:iron_plate:1,70,STAINED_CLAY:15,30,STAINED_CLAY:7,30,quark:iron_plate:1,100)
RandomBlock(-7,3,-4,quark:iron_plate:1,70,STAINED_CLAY:15,30,STAINED_CLAY:7,30,quark:iron_plate:1,100)
RandomBlock(-7,4,-6,quark:iron_plate:1,70,STAINED_CLAY:15,30,STAINED_CLAY:7,30,quark:iron_plate:1,100)
RandomBlock(-7,4,-5,quark:iron_plate:1,70,STAINED_CLAY:15,30,STAINED_CLAY:7,30,quark:iron_plate:1,100)
RandomBlock(-7,4,-4,IRON_FENCE:0,30,IRON_FENCE:0,30,LEAVES:7,30,quark:iron_plate_stairs:6,10,quark:iron_plate_stairs:0,10,quark:iron_plate_stairs:5,10,quark:iron_plate_stairs:3,10,quark:iron_plate_slab:8,10,quark:iron_plate_stairs:7,10,quark:iron_plate_stairs:1,10,quark:iron_plate_slab:0,10,quark:iron_plate_stairs:4,10,quark:iron_plate_stairs:2,10,IRON_FENCE:0,50,IRON_FENCE:0,50,LEAVES:7,100)
RandomBlock(-7,5,-6,quark:iron_plate:1,70,STAINED_CLAY:15,30,STAINED_CLAY:7,30,quark:iron_plate:1,100)
RandomBlock(-7,5,-5,quark:iron_plate:1,70,STAINED_CLAY:15,30,STAINED_CLAY:7,30,quark:iron_plate:1,100)
RandomBlock(-7,5,-4,IRON_FENCE:0,30,IRON_FENCE:0,30,LEAVES:7,30,quark:iron_plate_stairs:6,10,quark:iron_plate_stairs:0,10,quark:iron_plate_stairs:5,10,quark:iron_plate_stairs:3,10,quark:iron_plate_slab:8,10,quark:iron_plate_stairs:7,10,quark:iron_plate_stairs:1,10,quark:iron_plate_slab:0,10,quark:iron_plate_stairs:4,10,quark:iron_plate_stairs:2,10,IRON_FENCE:0,50,IRON_FENCE:0,50,LEAVES:7,100)
RandomBlock(-7,6,-6,IRON_FENCE:0,30,IRON_FENCE:0,30,LEAVES:7,30,quark:iron_plate_stairs:6,10,quark:iron_plate_stairs:0,10,quark:iron_plate_stairs:5,10,quark:iron_plate_stairs:3,10,quark:iron_plate_slab:8,10,quark:iron_plate_stairs:7,10,quark:iron_plate_stairs:1,10,quark:iron_plate_slab:0,10,quark:iron_plate_stairs:4,10,quark:iron_plate_stairs:2,10,IRON_FENCE:0,50,IRON_FENCE:0,50,LEAVES:7,100)
RandomBlock(-7,6,-5,quark:iron_plate:1,70,STAINED_CLAY:15,30,STAINED_CLAY:7,30,quark:iron_plate:1,100)
RandomBlock(-7,6,-4,IRON_FENCE:0,30,IRON_FENCE:0,30,LEAVES:7,30,quark:iron_plate_stairs:6,10,quark:iron_plate_stairs:0,10,quark:iron_plate_stairs:5,10,quark:iron_plate_stairs:3,10,quark:iron_plate_slab:8,10,quark:iron_plate_stairs:7,10,quark:iron_plate_stairs:1,10,quark:iron_plate_slab:0,10,quark:iron_plate_stairs:4,10,quark:iron_plate_stairs:2,10,IRON_FENCE:0,50,IRON_FENCE:0,50,LEAVES:7,100)
RandomBlock(-7,7,-6,IRON_FENCE:0,30,IRON_FENCE:0,30,LEAVES:7,30,quark:iron_plate_stairs:6,10,quark:iron_plate_stairs:0,10,quark:iron_plate_stairs:5,10,quark:iron_plate_stairs:3,10,quark:iron_plate_slab:8,10,quark:iron_plate_stairs:7,10,quark:iron_plate_stairs:1,10,quark:iron_plate_slab:0,10,quark:iron_plate_stairs:4,10,quark:iron_plate_stairs:2,10,IRON_FENCE:0,50,IRON_FENCE:0,50,LEAVES:7,100)
RandomBlock(-7,7,-5,quark:iron_plate:1,70,STAINED_CLAY:15,30,STAINED_CLAY:7,30,quark:iron_plate:1,100)
RandomBlock(-7,7,-4,quark:iron_plate:1,70,STAINED_CLAY:15,30,STAINED_CLAY:7,30,quark:iron_plate:1,100)
RandomBlock(-7,8,-6,IRON_FENCE:0,30,IRON_FENCE:0,30,LEAVES:7,30,quark:iron_plate_stairs:6,10,quark:iron_plate_stairs:0,10,quark:iron_plate_stairs:5,10,quark:iron_plate_stairs:3,10,quark:iron_plate_slab:8,10,quark:iron_plate_stairs:7,10,quark:iron_plate_stairs:1,10,quark:iron_plate_slab:0,10,quark:iron_plate_stairs:4,10,quark:iron_plate_stairs:2,10,IRON_FENCE:0,50,IRON_FENCE:0,50,LEAVES:7,100)
RandomBlock(-7,8,-5,quark:iron_plate:1,70,STAINED_CLAY:15,30,STAINED_CLAY:7,30,quark:iron_plate:1,100)
RandomBlock(-7,8,-4,quark:iron_plate:1,70,STAINED_CLAY:15,30,STAINED_CLAY:7,30,quark:iron_plate:1,100)
RandomBlock(-7,9,-6,quark:iron_plate:1,70,STAINED_CLAY:15,30,STAINED_CLAY:7,30,quark:iron_plate:1,100)
RandomBlock(-7,9,-5,quark:iron_plate:1,70,STAINED_CLAY:15,30,STAINED_CLAY:7,30,quark:iron_plate:1,100)
RandomBlock(-7,9,-4,IRON_FENCE:0,30,IRON_FENCE:0,30,LEAVES:7,30,quark:iron_plate_stairs:6,10,quark:iron_plate_stairs:0,10,quark:iron_plate_stairs:5,10,quark:iron_plate_stairs:3,10,quark:iron_plate_slab:8,10,quark:iron_plate_stairs:7,10,quark:iron_plate_stairs:1,10,quark:iron_plate_slab:0,10,quark:iron_plate_stairs:4,10,quark:iron_plate_stairs:2,10,IRON_FENCE:0,50,IRON_FENCE:0,50,LEAVES:7,100)
RandomBlock(-7,10,-6,quark:iron_plate:1,70,STAINED_CLAY:15,30,STAINED_CLAY:7,30,quark:iron_plate:1,100)
RandomBlock(-7,10,-5,quark:iron_plate:1,70,STAINED_CLAY:15,30,STAINED_CLAY:7,30,quark:iron_plate:1,100)
RandomBlock(-7,10,-4,IRON_FENCE:0,30,IRON_FENCE:0,30,LEAVES:7,30,quark:iron_plate_stairs:6,10,quark:iron_plate_stairs:0,10,quark:iron_plate_stairs:5,10,quark:iron_plate_stairs:3,10,quark:iron_plate_slab:8,10,quark:iron_plate_stairs:7,10,quark:iron_plate_stairs:1,10,quark:iron_plate_slab:0,10,quark:iron_plate_stairs:4,10,quark:iron_plate_stairs:2,10,IRON_FENCE:0,50,IRON_FENCE:0,50,LEAVES:7,100)
RandomBlock(-7,11,-6,quark:iron_plate:1,70,STAINED_CLAY:15,30,STAINED_CLAY:7,30,quark:iron_plate:1,100)
RandomBlock(-7,11,-5,quark:iron_plate:1,70,STAINED_CLAY:15,30,STAINED_CLAY:7,30,quark:iron_plate:1,100)
RandomBlock(-7,11,-4,IRON_FENCE:0,30,IRON_FENCE:0,30,LEAVES:7,30,quark:iron_plate_stairs:6,10,quark:iron_plate_stairs:0,10,quark:iron_plate_stairs:5,10,quark:iron_plate_stairs:3,10,quark:iron_plate_slab:8,10,quark:iron_plate_stairs:7,10,quark:iron_plate_stairs:1,10,quark:iron_plate_slab:0,10,quark:iron_plate_stairs:4,10,quark:iron_plate_stairs:2,10,IRON_FENCE:0,50,IRON_FENCE:0,50,LEAVES:7,100)
RandomBlock(-7,12,-6,IRON_FENCE:0,30,IRON_FENCE:0,30,LEAVES:7,30,quark:iron_plate_stairs:6,10,quark:iron_plate_stairs:0,10,quark:iron_plate_stairs:5,10,quark:iron_plate_stairs:3,10,quark:iron_plate_slab:8,10,quark:iron_plate_stairs:7,10,quark:iron_plate_stairs:1,10,quark:iron_plate_slab:0,10,quark:iron_plate_stairs:4,10,quark:iron_plate_stairs:2,10,IRON_FENCE:0,50,IRON_FENCE:0,50,LEAVES:7,100)
RandomBlock(-7,12,-5,quark:iron_plate:1,70,STAINED_CLAY:15,30,STAINED_CLAY:7,30,quark:iron_plate:1,100)
RandomBlock(-7,12,-4,IRON_FENCE:0,30,IRON_FENCE:0,30,LEAVES:7,30,quark:iron_plate_stairs:6,10,quark:iron_plate_stairs:0,10,quark:iron_plate_stairs:5,10,quark:iron_plate_stairs:3,10,quark:iron_plate_slab:8,10,quark:iron_plate_stairs:7,10,quark:iron_plate_stairs:1,10,quark:iron_plate_slab:0,10,quark:iron_plate_stairs:4,10,quark:iron_plate_stairs:2,10,IRON_FENCE:0,50,IRON_FENCE:0,50,LEAVES:7,100)
RandomBlock(-7,13,-6,IRON_FENCE:0,30,IRON_FENCE:0,30,LEAVES:7,30,quark:iron_plate_stairs:6,10,quark:iron_plate_stairs:0,10,quark:iron_plate_stairs:5,10,quark:iron_plate_stairs:3,10,quark:iron_plate_slab:8,10,quark:iron_plate_stairs:7,10,quark:iron_plate_stairs:1,10,quark:iron_plate_slab:0,10,quark:iron_plate_stairs:4,10,quark:iron_plate_stairs:2,10,IRON_FENCE:0,50,IRON_FENCE:0,50,LEAVES:7,100)
RandomBlock(-7,13,-5,quark:iron_plate:1,70,STAINED_CLAY:15,30,STAINED_CLAY:7,30,quark:iron_plate:1,100)
RandomBlock(-7,13,-4,IRON_FENCE:0,30,IRON_FENCE:0,30,LEAVES:7,30,quark:iron_plate_stairs:6,10,quark:iron_plate_stairs:0,10,quark:iron_plate_stairs:5,10,quark:iron_plate_stairs:3,10,quark:iron_plate_slab:8,10,quark:iron_plate_stairs:7,10,quark:iron_plate_stairs:1,10,quark:iron_plate_slab:0,10,quark:iron_plate_stairs:4,10,quark:iron_plate_stairs:2,10,IRON_FENCE:0,50,IRON_FENCE:0,50,LEAVES:7,100)
RandomBlock(-7,14,-6,IRON_FENCE:0,30,IRON_FENCE:0,30,LEAVES:7,30,quark:iron_plate_stairs:6,10,quark:iron_plate_stairs:0,10,quark:iron_plate_stairs:5,10,quark:iron_plate_stairs:3,10,quark:iron_plate_slab:8,10,quark:iron_plate_stairs:7,10,quark:iron_plate_stairs:1,10,quark:iron_plate_slab:0,10,quark:iron_plate_stairs:4,10,quark:iron_plate_stairs:2,10,IRON_FENCE:0,50,IRON_FENCE:0,50,LEAVES:7,100)
RandomBlock(-7,14,-5,quark:iron_plate:1,70,STAINED_CLAY:15,30,STAINED_CLAY:7,30,quark:iron_plate:1,100)
RandomBlock(-7,14,-4,quark:iron_plate:1,70,STAINED_CLAY:15,30,STAINED_CLAY:7,30,quark:iron_plate:1,100)
RandomBlock(-7,15,-6,IRON_FENCE:0,30,IRON_FENCE:0,30,LEAVES:7,30,quark:iron_plate_stairs:6,10,quark:iron_plate_stairs:0,10,quark:iron_plate_stairs:5,10,quark:iron_plate_stairs:3,10,quark:iron_plate_slab:8,10,quark:iron_plate_stairs:7,10,quark:iron_plate_stairs:1,10,quark:iron_plate_slab:0,10,quark:iron_plate_stairs:4,10,quark:iron_plate_stairs:2,10,IRON_FENCE:0,50,IRON_FENCE:0,50,LEAVES:7,100)
RandomBlock(-7,15,-5,quark:iron_plate:1,70,STAINED_CLAY:15,30,STAINED_CLAY:7,30,quark:iron_plate:1,100)
RandomBlock(-7,15,-4,quark:iron_plate:1,70,STAINED_CLAY:15,30,STAINED_CLAY:7,30,quark:iron_plate:1,100)
RandomBlock(-7,16,-6,IRON_FENCE:0,30,IRON_FENCE:0,30,LEAVES:7,30,quark:iron_plate_stairs:6,10,quark:iron_plate_stairs:0,10,quark:iron_plate_stairs:5,10,quark:iron_plate_stairs:3,10,quark:iron_plate_slab:8,10,quark:iron_plate_stairs:7,10,quark:iron_plate_stairs:1,10,quark:iron_plate_slab:0,10,quark:iron_plate_stairs:4,10,quark:iron_plate_stairs:2,10,IRON_FENCE:0,50,IRON_FENCE:0,50,LEAVES:7,100)
RandomBlock(-7,16,-5,IRON_FENCE:0,30,IRON_FENCE:0,30,LEAVES:7,30,quark:iron_plate_stairs:6,10,quark:iron_plate_stairs:0,10,quark:iron_plate_stairs:5,10,quark:iron_plate_stairs:3,10,quark:iron_plate_slab:8,10,quark:iron_plate_stairs:7,10,quark:iron_plate_stairs:1,10,quark:iron_plate_slab:0,10,quark:iron_plate_stairs:4,10,quark:iron_plate_stairs:2,10,IRON_FENCE:0,50,IRON_FENCE:0,50,LEAVES:7,100)
RandomBlock(-7,16,-4,IRON_FENCE:0,30,IRON_FENCE:0,30,LEAVES:7,30,quark:iron_plate_stairs:6,10,quark:iron_plate_stairs:0,10,quark:iron_plate_stairs:5,10,quark:iron_plate_stairs:3,10,quark:iron_plate_slab:8,10,quark:iron_plate_stairs:7,10,quark:iron_plate_stairs:1,10,quark:iron_plate_slab:0,10,quark:iron_plate_stairs:4,10,quark:iron_plate_stairs:2,10,IRON_FENCE:0,50,IRON_FENCE:0,50,LEAVES:7,100)
Block(-7,17,-6,quark:iron_plate_slab:0)
Block(-7,17,-5,COBBLESTONE_STAIRS:0)
Block(-7,17,-4,quark:iron_plate_slab:0)
Block(-7,18,-6,IRON_FENCE:0)
Block(-7,18,-5,IRON_FENCE:0)
Block(-7,18,-4,IRON_FENCE:0)
Block(-6,0,-7,quark:limestone:0)
RandomBlock(-6,0,-6,quark:iron_plate:1,70,STAINED_CLAY:15,30,STAINED_CLAY:7,30,quark:iron_plate:1,100)
Block(-6,0,-5,srparasites:deadblood)
RandomBlock(-6,0,-4,quark:iron_plate:1,70,STAINED_CLAY:15,30,STAINED_CLAY:7,30,quark:iron_plate:1,100)
Block(-6,0,-3,quark:limestone:0)
Block(-6,1,-7,COBBLESTONE_STAIRS:2)
RandomBlock(-6,1,-6,quark:iron_plate:1,70,STAINED_CLAY:15,30,STAINED_CLAY:7,30,quark:iron_plate:1,100)
Block(-6,1,-5,srparasites:deadblood)
RandomBlock(-6,1,-4,quark:iron_plate:1,70,STAINED_CLAY:15,30,STAINED_CLAY:7,30,quark:iron_plate:1,100)
Block(-6,1,-3,COBBLESTONE_STAIRS:3)
RandomBlock(-6,2,-6,quark:iron_plate:1,70,STAINED_CLAY:15,30,STAINED_CLAY:7,30,quark:iron_plate:1,100)
Block(-6,2,-5,srparasites:deadblood)
RandomBlock(-6,2,-4,quark:iron_plate:1,70,STAINED_CLAY:15,30,STAINED_CLAY:7,30,quark:iron_plate:1,100)
RandomBlock(-6,3,-6,quark:iron_plate:1,70,STAINED_CLAY:15,30,STAINED_CLAY:7,30,quark:iron_plate:1,100)
Block(-6,3,-5,srparasites:deadblood)
RandomBlock(-6,3,-4,quark:iron_plate:1,70,STAINED_CLAY:15,30,STAINED_CLAY:7,30,quark:iron_plate:1,100)
RandomBlock(-6,4,-6,quark:iron_plate:1,70,STAINED_CLAY:15,30,STAINED_CLAY:7,30,quark:iron_plate:1,100)
Block(-6,4,-5,srparasites:deadblood)
RandomBlock(-6,4,-4,quark:iron_plate:1,70,STAINED_CLAY:15,30,STAINED_CLAY:7,30,quark:iron_plate:1,100)
RandomBlock(-6,5,-6,quark:iron_plate:1,70,STAINED_CLAY:15,30,STAINED_CLAY:7,30,quark:iron_plate:1,100)
Block(-6,5,-5,srparasites:deadblood)
RandomBlock(-6,5,-4,quark:iron_plate:1,70,STAINED_CLAY:15,30,STAINED_CLAY:7,30,quark:iron_plate:1,100)
RandomBlock(-6,6,-6,quark:iron_plate:1,70,STAINED_CLAY:15,30,STAINED_CLAY:7,30,quark:iron_plate:1,100)
Block(-6,6,-5,srparasites:deadblood)
RandomBlock(-6,6,-4,quark:iron_plate:1,70,STAINED_CLAY:15,30,STAINED_CLAY:7,30,quark:iron_plate:1,100)
RandomBlock(-6,7,-6,quark:iron_plate:1,70,STAINED_CLAY:15,30,STAINED_CLAY:7,30,quark:iron_plate:1,100)
Block(-6,7,-5,srparasites:deadblood)
RandomBlock(-6,7,-4,quark:iron_plate:1,70,STAINED_CLAY:15,30,STAINED_CLAY:7,30,quark:iron_plate:1,100)
RandomBlock(-6,8,-6,quark:iron_plate:1,70,STAINED_CLAY:15,30,STAINED_CLAY:7,30,quark:iron_plate:1,100)
Block(-6,8,-5,srparasites:deadblood)
RandomBlock(-6,8,-4,quark:iron_plate:1,70,STAINED_CLAY:15,30,STAINED_CLAY:7,30,quark:iron_plate:1,100)
RandomBlock(-6,9,-6,quark:iron_plate:1,70,STAINED_CLAY:15,30,STAINED_CLAY:7,30,quark:iron_plate:1,100)
Block(-6,9,-5,srparasites:deadblood)
RandomBlock(-6,9,-4,quark:iron_plate:1,70,STAINED_CLAY:15,30,STAINED_CLAY:7,30,quark:iron_plate:1,100)
RandomBlock(-6,10,-6,quark:iron_plate:1,70,STAINED_CLAY:15,30,STAINED_CLAY:7,30,quark:iron_plate:1,100)
Block(-6,10,-5,srparasites:deadblood)
RandomBlock(-6,10,-4,quark:iron_plate:1,70,STAINED_CLAY:15,30,STAINED_CLAY:7,30,quark:iron_plate:1,100)
RandomBlock(-6,11,-6,quark:iron_plate:1,70,STAINED_CLAY:15,30,STAINED_CLAY:7,30,quark:iron_plate:1,100)
Block(-6,11,-5,srparasites:deadblood)
RandomBlock(-6,11,-4,quark:iron_plate:1,70,STAINED_CLAY:15,30,STAINED_CLAY:7,30,quark:iron_plate:1,100)
RandomBlock(-6,12,-6,quark:iron_plate:1,70,STAINED_CLAY:15,30,STAINED_CLAY:7,30,quark:iron_plate:1,100)
Block(-6,12,-5,srparasites:deadblood)
RandomBlock(-6,12,-4,quark:iron_plate:1,70,STAINED_CLAY:15,30,STAINED_CLAY:7,30,quark:iron_plate:1,100)
RandomBlock(-6,13,-6,quark:iron_plate:1,70,STAINED_CLAY:15,30,STAINED_CLAY:7,30,quark:iron_plate:1,100)
Block(-6,13,-5,srparasites:deadblood)
RandomBlock(-6,13,-4,quark:iron_plate:1,70,STAINED_CLAY:15,30,STAINED_CLAY:7,30,quark:iron_plate:1,100)
RandomBlock(-6,14,-6,quark:iron_plate:1,70,STAINED_CLAY:15,30,STAINED_CLAY:7,30,quark:iron_plate:1,100)
Block(-6,14,-5,srparasites:deadblood)
RandomBlock(-6,14,-4,quark:iron_plate:1,70,STAINED_CLAY:15,30,STAINED_CLAY:7,30,quark:iron_plate:1,100)
RandomBlock(-6,15,-6,quark:iron_plate:1,70,STAINED_CLAY:15,30,STAINED_CLAY:7,30,quark:iron_plate:1,100)
Block(-6,15,-5,srparasites:deadblood)
RandomBlock(-6,15,-4,quark:iron_plate:1,70,STAINED_CLAY:15,30,STAINED_CLAY:7,30,quark:iron_plate:1,100)
RandomBlock(-6,16,-6,IRON_FENCE:0,30,IRON_FENCE:0,30,LEAVES:7,30,quark:iron_plate_stairs:6,10,quark:iron_plate_stairs:0,10,quark:iron_plate_stairs:5,10,quark:iron_plate_stairs:3,10,quark:iron_plate_slab:8,10,quark:iron_plate_stairs:7,10,quark:iron_plate_stairs:1,10,quark:iron_plate_slab:0,10,quark:iron_plate_stairs:4,10,quark:iron_plate_stairs:2,10,IRON_FENCE:0,50,IRON_FENCE:0,50,LEAVES:7,100)
RandomBlock(-6,16,-5,quark:iron_plate:1,70,STAINED_CLAY:15,30,STAINED_CLAY:7,30,quark:iron_plate:1,100)
RandomBlock(-6,16,-4,quark:iron_plate:1,70,STAINED_CLAY:15,30,STAINED_CLAY:7,30,quark:iron_plate:1,100)
Block(-6,17,-6,COBBLESTONE_STAIRS:2)
Block(-6,17,-5,quark:basalt_wall:0)
Block(-6,17,-4,COBBLESTONE_STAIRS:3)
Block(-6,18,-6,IRON_FENCE:0)
Block(-6,18,-5,IRON_FENCE:0)
Block(-6,18,-4,IRON_FENCE:0)
Block(-5,0,-7,quark:limestone:0)
RandomBlock(-5,0,-6,quark:iron_plate:1,70,STAINED_CLAY:15,30,STAINED_CLAY:7,30,quark:iron_plate:1,100)
RandomBlock(-5,0,-5,quark:iron_plate:1,70,STAINED_CLAY:15,30,STAINED_CLAY:7,30,quark:iron_plate:1,100)
RandomBlock(-5,0,-4,quark:iron_plate:1,70,STAINED_CLAY:15,30,STAINED_CLAY:7,30,quark:iron_plate:1,100)
Block(-5,0,-3,quark:limestone:0)
Block(-5,1,-7,COBBLESTONE_STAIRS:2)
RandomBlock(-5,1,-6,quark:iron_plate:1,70,STAINED_CLAY:15,30,STAINED_CLAY:7,30,quark:iron_plate:1,100)
RandomBlock(-5,1,-5,quark:iron_plate:1,70,STAINED_CLAY:15,30,STAINED_CLAY:7,30,quark:iron_plate:1,100)
RandomBlock(-5,1,-4,quark:iron_plate:1,70,STAINED_CLAY:15,30,STAINED_CLAY:7,30,quark:iron_plate:1,100)
Block(-5,1,-3,COBBLESTONE_STAIRS:3)
RandomBlock(-5,2,-6,quark:iron_plate:1,70,STAINED_CLAY:15,30,STAINED_CLAY:7,30,quark:iron_plate:1,100)
RandomBlock(-5,2,-5,quark:iron_plate:1,70,STAINED_CLAY:15,30,STAINED_CLAY:7,30,quark:iron_plate:1,100)
RandomBlock(-5,2,-4,quark:iron_plate:1,70,STAINED_CLAY:15,30,STAINED_CLAY:7,30,quark:iron_plate:1,100)
RandomBlock(-5,3,-6,quark:iron_plate:1,70,STAINED_CLAY:15,30,STAINED_CLAY:7,30,quark:iron_plate:1,100)
RandomBlock(-5,3,-5,quark:iron_plate:1,70,STAINED_CLAY:15,30,STAINED_CLAY:7,30,quark:iron_plate:1,100)
RandomBlock(-5,3,-4,IRON_FENCE:0,30,IRON_FENCE:0,30,LEAVES:7,30,quark:iron_plate_stairs:6,10,quark:iron_plate_stairs:0,10,quark:iron_plate_stairs:5,10,quark:iron_plate_stairs:3,10,quark:iron_plate_slab:8,10,quark:iron_plate_stairs:7,10,quark:iron_plate_stairs:1,10,quark:iron_plate_slab:0,10,quark:iron_plate_stairs:4,10,quark:iron_plate_stairs:2,10,IRON_FENCE:0,50,IRON_FENCE:0,50,LEAVES:7,100)
RandomBlock(-5,4,-6,quark:iron_plate:1,70,STAINED_CLAY:15,30,STAINED_CLAY:7,30,quark:iron_plate:1,100)
RandomBlock(-5,4,-5,quark:iron_plate:1,70,STAINED_CLAY:15,30,STAINED_CLAY:7,30,quark:iron_plate:1,100)
RandomBlock(-5,4,-4,IRON_FENCE:0,30,IRON_FENCE:0,30,LEAVES:7,30,quark:iron_plate_stairs:6,10,quark:iron_plate_stairs:0,10,quark:iron_plate_stairs:5,10,quark:iron_plate_stairs:3,10,quark:iron_plate_slab:8,10,quark:iron_plate_stairs:7,10,quark:iron_plate_stairs:1,10,quark:iron_plate_slab:0,10,quark:iron_plate_stairs:4,10,quark:iron_plate_stairs:2,10,IRON_FENCE:0,50,IRON_FENCE:0,50,LEAVES:7,100)
RandomBlock(-5,5,-6,quark:iron_plate:1,70,STAINED_CLAY:15,30,STAINED_CLAY:7,30,quark:iron_plate:1,100)
RandomBlock(-5,5,-5,quark:iron_plate:1,70,STAINED_CLAY:15,30,STAINED_CLAY:7,30,quark:iron_plate:1,100)
RandomBlock(-5,5,-4,IRON_FENCE:0,30,IRON_FENCE:0,30,LEAVES:7,30,quark:iron_plate_stairs:6,10,quark:iron_plate_stairs:0,10,quark:iron_plate_stairs:5,10,quark:iron_plate_stairs:3,10,quark:iron_plate_slab:8,10,quark:iron_plate_stairs:7,10,quark:iron_plate_stairs:1,10,quark:iron_plate_slab:0,10,quark:iron_plate_stairs:4,10,quark:iron_plate_stairs:2,10,IRON_FENCE:0,50,IRON_FENCE:0,50,LEAVES:7,100)
RandomBlock(-5,6,-6,IRON_FENCE:0,30,IRON_FENCE:0,30,LEAVES:7,30,quark:iron_plate_stairs:6,10,quark:iron_plate_stairs:0,10,quark:iron_plate_stairs:5,10,quark:iron_plate_stairs:3,10,quark:iron_plate_slab:8,10,quark:iron_plate_stairs:7,10,quark:iron_plate_stairs:1,10,quark:iron_plate_slab:0,10,quark:iron_plate_stairs:4,10,quark:iron_plate_stairs:2,10,IRON_FENCE:0,50,IRON_FENCE:0,50,LEAVES:7,100)
RandomBlock(-5,6,-5,quark:iron_plate:1,70,STAINED_CLAY:15,30,STAINED_CLAY:7,30,quark:iron_plate:1,100)
RandomBlock(-5,6,-4,IRON_FENCE:0,30,IRON_FENCE:0,30,LEAVES:7,30,quark:iron_plate_stairs:6,10,quark:iron_plate_stairs:0,10,quark:iron_plate_stairs:5,10,quark:iron_plate_stairs:3,10,quark:iron_plate_slab:8,10,quark:iron_plate_stairs:7,10,quark:iron_plate_stairs:1,10,quark:iron_plate_slab:0,10,quark:iron_plate_stairs:4,10,quark:iron_plate_stairs:2,10,IRON_FENCE:0,50,IRON_FENCE:0,50,LEAVES:7,100)
RandomBlock(-5,7,-6,IRON_FENCE:0,30,IRON_FENCE:0,30,LEAVES:7,30,quark:iron_plate_stairs:6,10,quark:iron_plate_stairs:0,10,quark:iron_plate_stairs:5,10,quark:iron_plate_stairs:3,10,quark:iron_plate_slab:8,10,quark:iron_plate_stairs:7,10,quark:iron_plate_stairs:1,10,quark:iron_plate_slab:0,10,quark:iron_plate_stairs:4,10,quark:iron_plate_stairs:2,10,IRON_FENCE:0,50,IRON_FENCE:0,50,LEAVES:7,100)
RandomBlock(-5,7,-5,quark:iron_plate:1,70,STAINED_CLAY:15,30,STAINED_CLAY:7,30,quark:iron_plate:1,100)
RandomBlock(-5,7,-4,quark:iron_plate:1,70,STAINED_CLAY:15,30,STAINED_CLAY:7,30,quark:iron_plate:1,100)
RandomBlock(-5,8,-6,IRON_FENCE:0,30,IRON_FENCE:0,30,LEAVES:7,30,quark:iron_plate_stairs:6,10,quark:iron_plate_stairs:0,10,quark:iron_plate_stairs:5,10,quark:iron_plate_stairs:3,10,quark:iron_plate_slab:8,10,quark:iron_plate_stairs:7,10,quark:iron_plate_stairs:1,10,quark:iron_plate_slab:0,10,quark:iron_plate_stairs:4,10,quark:iron_plate_stairs:2,10,IRON_FENCE:0,50,IRON_FENCE:0,50,LEAVES:7,100)
RandomBlock(-5,8,-5,quark:iron_plate:1,70,STAINED_CLAY:15,30,STAINED_CLAY:7,30,quark:iron_plate:1,100)
RandomBlock(-5,8,-4,quark:iron_plate:1,70,STAINED_CLAY:15,30,STAINED_CLAY:7,30,quark:iron_plate:1,100)
RandomBlock(-5,9,-6,IRON_FENCE:0,30,IRON_FENCE:0,30,LEAVES:7,30,quark:iron_plate_stairs:6,10,quark:iron_plate_stairs:0,10,quark:iron_plate_stairs:5,10,quark:iron_plate_stairs:3,10,quark:iron_plate_slab:8,10,quark:iron_plate_stairs:7,10,quark:iron_plate_stairs:1,10,quark:iron_plate_slab:0,10,quark:iron_plate_stairs:4,10,quark:iron_plate_stairs:2,10,IRON_FENCE:0,50,IRON_FENCE:0,50,LEAVES:7,100)
RandomBlock(-5,9,-5,quark:iron_plate:1,70,STAINED_CLAY:15,30,STAINED_CLAY:7,30,quark:iron_plate:1,100)
RandomBlock(-5,9,-4,quark:iron_plate:1,70,STAINED_CLAY:15,30,STAINED_CLAY:7,30,quark:iron_plate:1,100)
RandomBlock(-5,10,-6,IRON_FENCE:0,30,IRON_FENCE:0,30,LEAVES:7,30,quark:iron_plate_stairs:6,10,quark:iron_plate_stairs:0,10,quark:iron_plate_stairs:5,10,quark:iron_plate_stairs:3,10,quark:iron_plate_slab:8,10,quark:iron_plate_stairs:7,10,quark:iron_plate_stairs:1,10,quark:iron_plate_slab:0,10,quark:iron_plate_stairs:4,10,quark:iron_plate_stairs:2,10,IRON_FENCE:0,50,IRON_FENCE:0,50,LEAVES:7,100)
RandomBlock(-5,10,-5,quark:iron_plate:1,70,STAINED_CLAY:15,30,STAINED_CLAY:7,30,quark:iron_plate:1,100)
RandomBlock(-5,10,-4,quark:iron_plate:1,70,STAINED_CLAY:15,30,STAINED_CLAY:7,30,quark:iron_plate:1,100)
RandomBlock(-5,11,-6,quark:iron_plate:1,70,STAINED_CLAY:15,30,STAINED_CLAY:7,30,quark:iron_plate:1,100)
RandomBlock(-5,11,-5,quark:iron_plate:1,70,STAINED_CLAY:15,30,STAINED_CLAY:7,30,quark:iron_plate:1,100)
RandomBlock(-5,11,-4,IRON_FENCE:0,30,IRON_FENCE:0,30,LEAVES:7,30,quark:iron_plate_stairs:6,10,quark:iron_plate_stairs:0,10,quark:iron_plate_stairs:5,10,quark:iron_plate_stairs:3,10,quark:iron_plate_slab:8,10,quark:iron_plate_stairs:7,10,quark:iron_plate_stairs:1,10,quark:iron_plate_slab:0,10,quark:iron_plate_stairs:4,10,quark:iron_plate_stairs:2,10,IRON_FENCE:0,50,IRON_FENCE:0,50,LEAVES:7,100)
RandomBlock(-5,12,-6,quark:iron_plate:1,70,STAINED_CLAY:15,30,STAINED_CLAY:7,30,quark:iron_plate:1,100)
RandomBlock(-5,12,-5,quark:iron_plate:1,70,STAINED_CLAY:15,30,STAINED_CLAY:7,30,quark:iron_plate:1,100)
RandomBlock(-5,12,-4,IRON_FENCE:0,30,IRON_FENCE:0,30,LEAVES:7,30,quark:iron_plate_stairs:6,10,quark:iron_plate_stairs:0,10,quark:iron_plate_stairs:5,10,quark:iron_plate_stairs:3,10,quark:iron_plate_slab:8,10,quark:iron_plate_stairs:7,10,quark:iron_plate_stairs:1,10,quark:iron_plate_slab:0,10,quark:iron_plate_stairs:4,10,quark:iron_plate_stairs:2,10,IRON_FENCE:0,50,IRON_FENCE:0,50,LEAVES:7,100)
RandomBlock(-5,13,-6,quark:iron_plate:1,70,STAINED_CLAY:15,30,STAINED_CLAY:7,30,quark:iron_plate:1,100)
RandomBlock(-5,13,-5,quark:iron_plate:1,70,STAINED_CLAY:15,30,STAINED_CLAY:7,30,quark:iron_plate:1,100)
RandomBlock(-5,13,-4,IRON_FENCE:0,30,IRON_FENCE:0,30,LEAVES:7,30,quark:iron_plate_stairs:6,10,quark:iron_plate_stairs:0,10,quark:iron_plate_stairs:5,10,quark:iron_plate_stairs:3,10,quark:iron_plate_slab:8,10,quark:iron_plate_stairs:7,10,quark:iron_plate_stairs:1,10,quark:iron_plate_slab:0,10,quark:iron_plate_stairs:4,10,quark:iron_plate_stairs:2,10,IRON_FENCE:0,50,IRON_FENCE:0,50,LEAVES:7,100)
RandomBlock(-5,14,-6,IRON_FENCE:0,30,IRON_FENCE:0,30,LEAVES:7,30,quark:iron_plate_stairs:6,10,quark:iron_plate_stairs:0,10,quark:iron_plate_stairs:5,10,quark:iron_plate_stairs:3,10,quark:iron_plate_slab:8,10,quark:iron_plate_stairs:7,10,quark:iron_plate_stairs:1,10,quark:iron_plate_slab:0,10,quark:iron_plate_stairs:4,10,quark:iron_plate_stairs:2,10,IRON_FENCE:0,50,IRON_FENCE:0,50,LEAVES:7,100)
RandomBlock(-5,14,-5,quark:iron_plate:1,70,STAINED_CLAY:15,30,STAINED_CLAY:7,30,quark:iron_plate:1,100)
RandomBlock(-5,14,-4,IRON_FENCE:0,30,IRON_FENCE:0,30,LEAVES:7,30,quark:iron_plate_stairs:6,10,quark:iron_plate_stairs:0,10,quark:iron_plate_stairs:5,10,quark:iron_plate_stairs:3,10,quark:iron_plate_slab:8,10,quark:iron_plate_stairs:7,10,quark:iron_plate_stairs:1,10,quark:iron_plate_slab:0,10,quark:iron_plate_stairs:4,10,quark:iron_plate_stairs:2,10,IRON_FENCE:0,50,IRON_FENCE:0,50,LEAVES:7,100)
RandomBlock(-5,15,-6,IRON_FENCE:0,30,IRON_FENCE:0,30,LEAVES:7,30,quark:iron_plate_stairs:6,10,quark:iron_plate_stairs:0,10,quark:iron_plate_stairs:5,10,quark:iron_plate_stairs:3,10,quark:iron_plate_slab:8,10,quark:iron_plate_stairs:7,10,quark:iron_plate_stairs:1,10,quark:iron_plate_slab:0,10,quark:iron_plate_stairs:4,10,quark:iron_plate_stairs:2,10,IRON_FENCE:0,50,IRON_FENCE:0,50,LEAVES:7,100)
Block(-5,15,-5,srparasites:deadblood)
RandomBlock(-5,15,-4,quark:iron_plate:1,70,STAINED_CLAY:15,30,STAINED_CLAY:7,30,quark:iron_plate:1,100)
RandomBlock(-5,16,-6,IRON_FENCE:0,30,IRON_FENCE:0,30,LEAVES:7,30,quark:iron_plate_stairs:6,10,quark:iron_plate_stairs:0,10,quark:iron_plate_stairs:5,10,quark:iron_plate_stairs:3,10,quark:iron_plate_slab:8,10,quark:iron_plate_stairs:7,10,quark:iron_plate_stairs:1,10,quark:iron_plate_slab:0,10,quark:iron_plate_stairs:4,10,quark:iron_plate_stairs:2,10,IRON_FENCE:0,50,IRON_FENCE:0,50,LEAVES:7,100)
RandomBlock(-5,16,-5,quark:iron_plate:1,70,STAINED_CLAY:15,30,STAINED_CLAY:7,30,quark:iron_plate:1,100)
RandomBlock(-5,16,-4,quark:iron_plate:1,70,STAINED_CLAY:15,30,STAINED_CLAY:7,30,quark:iron_plate:1,100)
Block(-5,17,-6,quark:iron_plate_slab:0)
Block(-5,17,-5,COBBLESTONE_STAIRS:1)
Block(-5,17,-4,quark:iron_plate_slab:0)
Block(-5,18,-6,IRON_FENCE:0)
Block(-5,18,-5,IRON_FENCE:0)
Block(-5,18,-4,IRON_FENCE:0)
Block(-4,0,-7,quark:limestone:0)
Block(-4,0,-6,quark:limestone:0)
Block(-4,0,-5,quark:limestone:0)
Block(-4,0,-4,quark:limestone:0)
Block(-4,0,-3,quark:limestone:0)
Block(-4,1,-7,COBBLESTONE_STAIRS:2)
Block(-4,1,-6,COBBLESTONE_STAIRS:1)
Block(-4,1,-5,COBBLESTONE_STAIRS:1)
Block(-4,1,-4,COBBLESTONE_STAIRS:1)
Block(-4,1,-3,COBBLESTONE_STAIRS:1)
Block(-4,14,-6,COBBLESTONE_STAIRS:6)
RandomBlock(-4,14,-5,quark:iron_plate:1,70,STAINED_CLAY:15,30,STAINED_CLAY:7,30,quark:iron_plate:1,100)
Block(-4,14,-4,COBBLESTONE_STAIRS:7)
RandomBlock(-4,15,-6,quark:iron_plate:1,70,STAINED_CLAY:15,30,STAINED_CLAY:7,30,quark:iron_plate:1,100)
Block(-4,15,-5,srparasites:deadblood)
RandomBlock(-4,15,-4,quark:iron_plate:1,70,STAINED_CLAY:15,30,STAINED_CLAY:7,30,quark:iron_plate:1,100)
Block(-4,16,-6,COBBLESTONE_STAIRS:2)
RandomBlock(-4,16,-5,quark:iron_plate:1,70,STAINED_CLAY:15,30,STAINED_CLAY:7,30,quark:iron_plate:1,100)
Block(-4,16,-4,COBBLESTONE_STAIRS:3)
Block(-3,14,-6,COBBLESTONE_STAIRS:6)
RandomBlock(-3,14,-5,quark:iron_plate:1,70,STAINED_CLAY:15,30,STAINED_CLAY:7,30,quark:iron_plate:1,100)
Block(-3,14,-4,COBBLESTONE_STAIRS:7)
RandomBlock(-3,15,-6,quark:iron_plate:1,70,STAINED_CLAY:15,30,STAINED_CLAY:7,30,quark:iron_plate:1,100)
Block(-3,15,-5,srparasites:deadblood)
RandomBlock(-3,15,-4,quark:iron_plate:1,70,STAINED_CLAY:15,30,STAINED_CLAY:7,30,quark:iron_plate:1,100)
Block(-3,16,-6,COBBLESTONE_STAIRS:2)
RandomBlock(-3,16,-5,quark:iron_plate:1,70,STAINED_CLAY:15,30,STAINED_CLAY:7,30,quark:iron_plate:1,100)
Block(-3,16,-4,COBBLESTONE_STAIRS:3)
Block(-2,14,-6,COBBLESTONE_STAIRS:6)
RandomBlock(-2,14,-5,quark:iron_plate:1,70,STAINED_CLAY:15,30,STAINED_CLAY:7,30,quark:iron_plate:1,100)
Block(-2,14,-4,COBBLESTONE_STAIRS:7)
RandomBlock(-2,15,-6,quark:iron_plate:1,70,STAINED_CLAY:15,30,STAINED_CLAY:7,30,quark:iron_plate:1,100)
Block(-2,15,-5,srparasites:deadblood)
RandomBlock(-2,15,-4,quark:iron_plate:1,70,STAINED_CLAY:15,30,STAINED_CLAY:7,30,quark:iron_plate:1,100)
Block(-2,16,-6,COBBLESTONE_STAIRS:2)
RandomBlock(-2,16,-5,IRON_FENCE:0,30,IRON_FENCE:0,30,LEAVES:7,30,quark:iron_plate_stairs:6,10,quark:iron_plate_stairs:0,10,quark:iron_plate_stairs:5,10,quark:iron_plate_stairs:3,10,quark:iron_plate_slab:8,10,quark:iron_plate_stairs:7,10,quark:iron_plate_stairs:1,10,quark:iron_plate_slab:0,10,quark:iron_plate_stairs:4,10,quark:iron_plate_stairs:2,10,IRON_FENCE:0,50,IRON_FENCE:0,50,LEAVES:7,100)
Block(-2,16,-4,COBBLESTONE_STAIRS:3)
Block(-1,14,-6,COBBLESTONE_STAIRS:6)
RandomBlock(-1,14,-5,quark:iron_plate:1,70,STAINED_CLAY:15,30,STAINED_CLAY:7,30,quark:iron_plate:1,100)
Block(-1,14,-4,COBBLESTONE_STAIRS:7)
RandomBlock(-1,15,-6,quark:iron_plate:1,70,STAINED_CLAY:15,30,STAINED_CLAY:7,30,quark:iron_plate:1,100)
Block(-1,15,-5,srparasites:deadblood)
RandomBlock(-1,15,-4,quark:iron_plate:1,70,STAINED_CLAY:15,30,STAINED_CLAY:7,30,quark:iron_plate:1,100)
Block(-1,16,-6,COBBLESTONE_STAIRS:2)
RandomBlock(-1,16,-5,IRON_FENCE:0,30,IRON_FENCE:0,30,LEAVES:7,30,quark:iron_plate_stairs:6,10,quark:iron_plate_stairs:0,10,quark:iron_plate_stairs:5,10,quark:iron_plate_stairs:3,10,quark:iron_plate_slab:8,10,quark:iron_plate_stairs:7,10,quark:iron_plate_stairs:1,10,quark:iron_plate_slab:0,10,quark:iron_plate_stairs:4,10,quark:iron_plate_stairs:2,10,IRON_FENCE:0,50,IRON_FENCE:0,50,LEAVES:7,100)
Block(-1,16,-4,COBBLESTONE_STAIRS:3)
Block(0,9,-5,COBBLESTONE_STAIRS:4)
Block(0,10,-6,COBBLE_WALL:0)
RandomBlock(0,10,-5,quark:iron_plate:1,70,STAINED_CLAY:15,30,STAINED_CLAY:7,30,quark:iron_plate:1,100)
Block(0,10,-4,COBBLE_WALL:0)
Block(0,11,-6,COBBLE_WALL:0)
RandomBlock(0,11,-5,quark:iron_plate:1,70,STAINED_CLAY:15,30,STAINED_CLAY:7,30,quark:iron_plate:1,100)
Block(0,11,-4,COBBLE_WALL:0)
Block(0,12,-6,COBBLE_WALL:0)
RandomBlock(0,12,-5,quark:iron_plate:1,70,STAINED_CLAY:15,30,STAINED_CLAY:7,30,quark:iron_plate:1,100)
Block(0,12,-4,COBBLE_WALL:0)
Block(0,13,-6,COBBLE_WALL:0)
RandomBlock(0,13,-5,quark:iron_plate:1,70,STAINED_CLAY:15,30,STAINED_CLAY:7,30,quark:iron_plate:1,100)
Block(0,13,-4,COBBLE_WALL:0)
Block(0,14,-6,COBBLE_WALL:0)
RandomBlock(0,14,-5,quark:iron_plate:1,70,STAINED_CLAY:15,30,STAINED_CLAY:7,30,quark:iron_plate:1,100)
Block(0,14,-4,COBBLE_WALL:0)
RandomBlock(0,15,-6,quark:iron_plate:1,70,STAINED_CLAY:15,30,STAINED_CLAY:7,30,quark:iron_plate:1,100)
Block(0,15,-5,srparasites:deadblood)
RandomBlock(0,15,-4,quark:iron_plate:1,70,STAINED_CLAY:15,30,STAINED_CLAY:7,30,quark:iron_plate:1,100)
Block(0,16,-6,COBBLESTONE_STAIRS:2)
RandomBlock(0,16,-5,IRON_FENCE:0,30,IRON_FENCE:0,30,LEAVES:7,30,quark:iron_plate_stairs:6,10,quark:iron_plate_stairs:0,10,quark:iron_plate_stairs:5,10,quark:iron_plate_stairs:3,10,quark:iron_plate_slab:8,10,quark:iron_plate_stairs:7,10,quark:iron_plate_stairs:1,10,quark:iron_plate_slab:0,10,quark:iron_plate_stairs:4,10,quark:iron_plate_stairs:2,10,IRON_FENCE:0,50,IRON_FENCE:0,50,LEAVES:7,100)
Block(0,16,-4,COBBLESTONE_STAIRS:3)
Block(1,0,-5,quark:world_stone_pavement:2)
Block(1,1,-5,quark:world_stone_pavement:2)
Block(1,2,-5,quark:world_stone_pavement:2)
Block(1,3,-5,quark:world_stone_pavement:2)
Block(1,4,-5,quark:world_stone_pavement:2)
Block(1,5,-5,quark:basalt_wall:0)
Block(1,6,-5,quark:basalt_wall:0)
Block(1,7,-5,quark:basalt_wall:0)
Block(1,8,-5,quark:basalt_wall:0)
Block(1,9,-6,COBBLESTONE_STAIRS:6)
RandomBlock(1,9,-5,quark:iron_plate:1,70,STAINED_CLAY:15,30,STAINED_CLAY:7,30,quark:iron_plate:1,100)
Block(1,9,-4,COBBLESTONE_STAIRS:7)
RandomBlock(1,10,-6,quark:iron_plate:1,70,STAINED_CLAY:15,30,STAINED_CLAY:7,30,quark:iron_plate:1,100)
Block(1,10,-5,srparasites:deadblood)
RandomBlock(1,10,-4,quark:iron_plate:1,70,STAINED_CLAY:15,30,STAINED_CLAY:7,30,quark:iron_plate:1,100)
RandomBlock(1,11,-6,quark:iron_plate:1,70,STAINED_CLAY:15,30,STAINED_CLAY:7,30,quark:iron_plate:1,100)
Block(1,11,-5,srparasites:deadblood)
RandomBlock(1,11,-4,quark:iron_plate:1,70,STAINED_CLAY:15,30,STAINED_CLAY:7,30,quark:iron_plate:1,100)
RandomBlock(1,12,-6,quark:iron_plate:1,70,STAINED_CLAY:15,30,STAINED_CLAY:7,30,quark:iron_plate:1,100)
Block(1,12,-5,srparasites:deadblood)
RandomBlock(1,12,-4,quark:iron_plate:1,70,STAINED_CLAY:15,30,STAINED_CLAY:7,30,quark:iron_plate:1,100)
RandomBlock(1,13,-6,quark:iron_plate:1,70,STAINED_CLAY:15,30,STAINED_CLAY:7,30,quark:iron_plate:1,100)
Block(1,13,-5,srparasites:deadblood)
RandomBlock(1,13,-4,quark:iron_plate:1,70,STAINED_CLAY:15,30,STAINED_CLAY:7,30,quark:iron_plate:1,100)
RandomBlock(1,14,-6,quark:iron_plate:1,70,STAINED_CLAY:15,30,STAINED_CLAY:7,30,quark:iron_plate:1,100)
Block(1,14,-5,srparasites:deadblood)
RandomBlock(1,14,-4,quark:iron_plate:1,70,STAINED_CLAY:15,30,STAINED_CLAY:7,30,quark:iron_plate:1,100)
RandomBlock(1,15,-6,quark:iron_plate:1,70,STAINED_CLAY:15,30,STAINED_CLAY:7,30,quark:iron_plate:1,100)
Block(1,15,-5,srparasites:deadblood)
RandomBlock(1,15,-4,quark:iron_plate:1,70,STAINED_CLAY:15,30,STAINED_CLAY:7,30,quark:iron_plate:1,100)
Block(1,16,-6,COBBLESTONE_STAIRS:2)
RandomBlock(1,16,-5,quark:iron_plate:1,70,STAINED_CLAY:15,30,STAINED_CLAY:7,30,quark:iron_plate:1,100)
Block(1,16,-4,COBBLESTONE_STAIRS:3)
Block(2,9,-6,COBBLESTONE_STAIRS:6)
RandomBlock(2,9,-5,quark:iron_plate:1,70,STAINED_CLAY:15,30,STAINED_CLAY:7,30,quark:iron_plate:1,100)
Block(2,9,-4,COBBLESTONE_STAIRS:7)
RandomBlock(2,10,-6,quark:iron_plate:1,70,STAINED_CLAY:15,30,STAINED_CLAY:7,30,quark:iron_plate:1,100)
Block(2,10,-5,srparasites:deadblood)
RandomBlock(2,10,-4,quark:iron_plate:1,70,STAINED_CLAY:15,30,STAINED_CLAY:7,30,quark:iron_plate:1,100)
Block(2,11,-6,COBBLE_WALL:0)
RandomBlock(2,11,-5,quark:iron_plate:1,70,STAINED_CLAY:15,30,STAINED_CLAY:7,30,quark:iron_plate:1,100)
Block(2,11,-4,COBBLE_WALL:0)
Block(2,12,-6,COBBLE_WALL:0)
RandomBlock(2,12,-5,quark:iron_plate:1,70,STAINED_CLAY:15,30,STAINED_CLAY:7,30,quark:iron_plate:1,100)
Block(2,12,-4,COBBLE_WALL:0)
Block(2,13,-6,COBBLE_WALL:0)
RandomBlock(2,13,-5,quark:iron_plate:1,70,STAINED_CLAY:15,30,STAINED_CLAY:7,30,quark:iron_plate:1,100)
Block(2,13,-4,COBBLE_WALL:0)
Block(2,14,-6,COBBLE_WALL:0)
RandomBlock(2,14,-5,quark:iron_plate:1,70,STAINED_CLAY:15,30,STAINED_CLAY:7,30,quark:iron_plate:1,100)
Block(2,14,-4,COBBLE_WALL:0)
Block(2,15,-6,COBBLE_WALL:0)
RandomBlock(2,15,-5,quark:iron_plate:1,70,STAINED_CLAY:15,30,STAINED_CLAY:7,30,quark:iron_plate:1,100)
Block(2,15,-4,COBBLE_WALL:0)
Block(2,16,-5,COBBLESTONE_STAIRS:1)
Block(3,9,-6,COBBLESTONE_STAIRS:6)
RandomBlock(3,9,-5,quark:iron_plate:1,70,STAINED_CLAY:15,30,STAINED_CLAY:7,30,quark:iron_plate:1,100)
Block(3,9,-4,COBBLESTONE_STAIRS:7)
RandomBlock(3,10,-6,quark:iron_plate:1,70,STAINED_CLAY:15,30,STAINED_CLAY:7,30,quark:iron_plate:1,100)
Block(3,10,-5,srparasites:deadblood)
RandomBlock(3,10,-4,quark:iron_plate:1,70,STAINED_CLAY:15,30,STAINED_CLAY:7,30,quark:iron_plate:1,100)
Block(3,11,-6,COBBLESTONE_STAIRS:2)
RandomBlock(3,11,-5,IRON_FENCE:0,30,IRON_FENCE:0,30,LEAVES:7,30,quark:iron_plate_stairs:6,10,quark:iron_plate_stairs:0,10,quark:iron_plate_stairs:5,10,quark:iron_plate_stairs:3,10,quark:iron_plate_slab:8,10,quark:iron_plate_stairs:7,10,quark:iron_plate_stairs:1,10,quark:iron_plate_slab:0,10,quark:iron_plate_stairs:4,10,quark:iron_plate_stairs:2,10,IRON_FENCE:0,50,IRON_FENCE:0,50,LEAVES:7,100)
Block(3,11,-4,COBBLESTONE_STAIRS:3)
Block(3,13,-5,quark:basalt_wall:0)
Block(4,9,-6,COBBLESTONE_STAIRS:6)
RandomBlock(4,9,-5,quark:iron_plate:1,70,STAINED_CLAY:15,30,STAINED_CLAY:7,30,quark:iron_plate:1,100)
Block(4,9,-4,COBBLESTONE_STAIRS:7)
RandomBlock(4,10,-6,quark:iron_plate:1,70,STAINED_CLAY:15,30,STAINED_CLAY:7,30,quark:iron_plate:1,100)
Block(4,10,-5,srparasites:deadblood)
RandomBlock(4,10,-4,quark:iron_plate:1,70,STAINED_CLAY:15,30,STAINED_CLAY:7,30,quark:iron_plate:1,100)
Block(4,11,-6,COBBLESTONE_STAIRS:2)
RandomBlock(4,11,-5,quark:iron_plate:1,70,STAINED_CLAY:15,30,STAINED_CLAY:7,30,quark:iron_plate:1,100)
Block(4,11,-4,COBBLESTONE_STAIRS:3)
Block(4,13,-5,quark:basalt_wall:0)
Block(5,9,-6,COBBLESTONE_STAIRS:6)
RandomBlock(5,9,-5,quark:iron_plate:1,70,STAINED_CLAY:15,30,STAINED_CLAY:7,30,quark:iron_plate:1,100)
Block(5,9,-4,COBBLESTONE_STAIRS:7)
RandomBlock(5,10,-6,quark:iron_plate:1,70,STAINED_CLAY:15,30,STAINED_CLAY:7,30,quark:iron_plate:1,100)
Block(5,10,-5,srparasites:deadblood)
RandomBlock(5,10,-4,quark:iron_plate:1,70,STAINED_CLAY:15,30,STAINED_CLAY:7,30,quark:iron_plate:1,100)
Block(5,11,-6,COBBLESTONE_STAIRS:2)
RandomBlock(5,11,-5,quark:iron_plate:1,70,STAINED_CLAY:15,30,STAINED_CLAY:7,30,quark:iron_plate:1,100)
Block(5,11,-4,COBBLESTONE_STAIRS:3)
Block(5,13,-5,quark:basalt_wall:0)
Block(6,9,-6,COBBLESTONE_STAIRS:6)
RandomBlock(6,9,-5,quark:iron_plate:1,70,STAINED_CLAY:15,30,STAINED_CLAY:7,30,quark:iron_plate:1,100)
Block(6,9,-4,COBBLESTONE_STAIRS:7)
RandomBlock(6,10,-6,quark:iron_plate:1,70,STAINED_CLAY:15,30,STAINED_CLAY:7,30,quark:iron_plate:1,100)
Block(6,10,-5,srparasites:deadblood)
RandomBlock(6,10,-4,quark:iron_plate:1,70,STAINED_CLAY:15,30,STAINED_CLAY:7,30,quark:iron_plate:1,100)
Block(6,11,-6,COBBLESTONE_STAIRS:2)
RandomBlock(6,11,-5,quark:iron_plate:1,70,STAINED_CLAY:15,30,STAINED_CLAY:7,30,quark:iron_plate:1,100)
Block(6,11,-4,COBBLESTONE_STAIRS:3)
Block(6,13,-5,quark:basalt_wall:0)
Block(7,9,-6,COBBLESTONE_STAIRS:6)
RandomBlock(7,9,-5,quark:iron_plate:1,70,STAINED_CLAY:15,30,STAINED_CLAY:7,30,quark:iron_plate:1,100)
Block(7,9,-4,COBBLESTONE_STAIRS:7)
RandomBlock(7,10,-6,quark:iron_plate:1,70,STAINED_CLAY:15,30,STAINED_CLAY:7,30,quark:iron_plate:1,100)
Block(7,10,-5,srparasites:deadblood)
RandomBlock(7,10,-4,quark:iron_plate:1,70,STAINED_CLAY:15,30,STAINED_CLAY:7,30,quark:iron_plate:1,100)
Block(7,11,-6,COBBLESTONE_STAIRS:2)
RandomBlock(7,11,-5,IRON_FENCE:0,30,IRON_FENCE:0,30,LEAVES:7,30,quark:iron_plate_stairs:6,10,quark:iron_plate_stairs:0,10,quark:iron_plate_stairs:5,10,quark:iron_plate_stairs:3,10,quark:iron_plate_slab:8,10,quark:iron_plate_stairs:7,10,quark:iron_plate_stairs:1,10,quark:iron_plate_slab:0,10,quark:iron_plate_stairs:4,10,quark:iron_plate_stairs:2,10,IRON_FENCE:0,50,IRON_FENCE:0,50,LEAVES:7,100)
Block(7,11,-4,COBBLESTONE_STAIRS:3)
Block(7,13,-5,quark:basalt_wall:0)

#######################################################################
# +-----------------------------------------------------------------+ #
# |                             Branches                            | #
# +-----------------------------------------------------------------+ #
#######################################################################

Branch(16,0,0,true,brutal_pipesmall_05C1R0,NORTH,100.0,0)

#######################################################################
# +-----------------------------------------------------------------+ #
# |                             Entities                            | #
# +-----------------------------------------------------------------+ #
#######################################################################


#######################################################################
# +-----------------------------------------------------------------+ #
# |                            Particles                            | #
# +-----------------------------------------------------------------+ #
#######################################################################


#######################################################################
# +-----------------------------------------------------------------+ #
# |                             Spawners                            | #
# +-----------------------------------------------------------------+ #
#######################################################################


#######################################################################
# +-----------------------------------------------------------------+ #
# |                             ModData                             | #
# +-----------------------------------------------------------------+ #
#######################################################################

