
#######################################################################
# +-----------------------------------------------------------------+ #
# |                            BO4 object                           | #
# +-----------------------------------------------------------------+ #
#######################################################################

Author: NLBlackEagle

Description: No description given

SettingsMode: WriteWithoutComments


#######################################################################
# +-----------------------------------------------------------------+ #
# |                          Main settings                          | #
# +-----------------------------------------------------------------+ #
#######################################################################

FixedRotation: 

Frequency: 0

SpawnHeight: highestBlock

UseCenterForHighestBlock: true

##############################
# Height Limits for the BO4. #
##############################

MinHeight: 0

MaxHeight: 255

InheritBO3: 

InheritBO3Rotation: NORTH

OverrideChildSettings: true

OverrideParentHeight: false

CanOverride: true

BranchFrequency: 0

BranchFrequencyGroup: 

MustBeBelowOther: false

MustBeInside: 

CannotBeInside: 

ReplacesBO3: 

MustBeInsideWorldBorders: true
CanSpawnOnWater: true

SpawnOnWaterOnly: false

SpawnUnderWater: false

SpawnAtWaterLevel: false

HeightOffset: 0

RemoveAir: false

ReplaceAbove: 

ReplaceBelow: 

ReplaceWithBiomeBlocks: true

ReplaceWithSurfaceBlock: GRASS

ReplaceWithGroundBlock: DIRT

ReplaceWithStoneBlock: STONE

SmoothRadius: 0

SmoothHeightOffset: 0

SmoothStartTop: false

SmoothStartWood: false

SmoothingSurfaceBlock: 

SmoothingGroundBlock: 

BO3Group: 

IsSpawnPoint: false

DoReplaceBlocks: false


#######################################################################
# +-----------------------------------------------------------------+ #
# |                              Blocks                             | #
# +-----------------------------------------------------------------+ #
#######################################################################

RandomBlock(1,0,4,quark:iron_plate:1,70,STAINED_CLAY:15,30,STAINED_CLAY:7,30,STAINED_CLAY:8,30,quark:iron_plate:1,100)
RandomBlock(1,0,5,quark:iron_plate:1,70,STAINED_CLAY:15,30,STAINED_CLAY:7,30,STAINED_CLAY:8,30,quark:iron_plate:1,100)
RandomBlock(1,0,6,minecraft:iron_bars,30,minecraft:iron_bars,30,minecraft:leaves2:1,30,quark:iron_plate_stairs:6,10,quark:iron_plate_stairs:0,10,quark:iron_plate_stairs:5,10,quark:iron_plate_stairs,10,quark:iron_plate_slab:8,10,quark:iron_plate_stairs:7,10,quark:iron_plate_stairs:1,10,quark:iron_plate_slab,10,quark:iron_plate_stairs:4,10,quark:iron_plate_stairs:2,10,minecraft:iron_bars,50,minecraft:iron_bars,50,minecraft:leaves2:1,100)
RandomBlock(1,1,4,minecraft:iron_bars,30,minecraft:iron_bars,30,minecraft:leaves2:1,30,quark:iron_plate_stairs:6,10,quark:iron_plate_stairs:0,10,quark:iron_plate_stairs:5,10,quark:iron_plate_stairs,10,quark:iron_plate_slab:8,10,quark:iron_plate_stairs:7,10,quark:iron_plate_stairs:1,10,quark:iron_plate_slab,10,quark:iron_plate_stairs:4,10,quark:iron_plate_stairs:2,10,minecraft:iron_bars,50,minecraft:iron_bars,50,minecraft:leaves2:1,100)
RandomBlock(1,1,5,minecraft:iron_bars,30,minecraft:iron_bars,30,minecraft:leaves2:1,30,quark:iron_plate_stairs:6,10,quark:iron_plate_stairs:0,10,quark:iron_plate_stairs:5,10,quark:iron_plate_stairs,10,quark:iron_plate_slab:8,10,quark:iron_plate_stairs:7,10,quark:iron_plate_stairs:1,10,quark:iron_plate_slab,10,quark:iron_plate_stairs:4,10,quark:iron_plate_stairs:2,10,minecraft:iron_bars,50,minecraft:iron_bars,50,minecraft:leaves2:1,100)
RandomBlock(1,1,6,minecraft:iron_bars,30,minecraft:iron_bars,30,minecraft:leaves2:1,30,quark:iron_plate_stairs:6,10,quark:iron_plate_stairs:0,10,quark:iron_plate_stairs:5,10,quark:iron_plate_stairs,10,quark:iron_plate_slab:8,10,quark:iron_plate_stairs:7,10,quark:iron_plate_stairs:1,10,quark:iron_plate_slab,10,quark:iron_plate_stairs:4,10,quark:iron_plate_stairs:2,10,minecraft:iron_bars,50,minecraft:iron_bars,50,minecraft:leaves2:1,100)
RandomBlock(1,2,4,minecraft:iron_bars,30,minecraft:iron_bars,30,minecraft:leaves2:1,30,quark:iron_plate_stairs:6,10,quark:iron_plate_stairs:0,10,quark:iron_plate_stairs:5,10,quark:iron_plate_stairs,10,quark:iron_plate_slab:8,10,quark:iron_plate_stairs:7,10,quark:iron_plate_stairs:1,10,quark:iron_plate_slab,10,quark:iron_plate_stairs:4,10,quark:iron_plate_stairs:2,10,minecraft:iron_bars,50,minecraft:iron_bars,50,minecraft:leaves2:1,100)
RandomBlock(1,2,5,minecraft:iron_bars,30,minecraft:iron_bars,30,minecraft:leaves2:1,30,quark:iron_plate_stairs:6,10,quark:iron_plate_stairs:0,10,quark:iron_plate_stairs:5,10,quark:iron_plate_stairs,10,quark:iron_plate_slab:8,10,quark:iron_plate_stairs:7,10,quark:iron_plate_stairs:1,10,quark:iron_plate_slab,10,quark:iron_plate_stairs:4,10,quark:iron_plate_stairs:2,10,minecraft:iron_bars,50,minecraft:iron_bars,50,minecraft:leaves2:1,100)
RandomBlock(1,2,6,minecraft:iron_bars,30,minecraft:iron_bars,30,minecraft:leaves2:1,30,quark:iron_plate_stairs:6,10,quark:iron_plate_stairs:0,10,quark:iron_plate_stairs:5,10,quark:iron_plate_stairs,10,quark:iron_plate_slab:8,10,quark:iron_plate_stairs:7,10,quark:iron_plate_stairs:1,10,quark:iron_plate_slab,10,quark:iron_plate_stairs:4,10,quark:iron_plate_stairs:2,10,minecraft:iron_bars,50,minecraft:iron_bars,50,minecraft:leaves2:1,100)
RandomBlock(1,3,4,minecraft:iron_bars,30,minecraft:iron_bars,30,minecraft:leaves2:1,30,quark:iron_plate_stairs:6,10,quark:iron_plate_stairs:0,10,quark:iron_plate_stairs:5,10,quark:iron_plate_stairs,10,quark:iron_plate_slab:8,10,quark:iron_plate_stairs:7,10,quark:iron_plate_stairs:1,10,quark:iron_plate_slab,10,quark:iron_plate_stairs:4,10,quark:iron_plate_stairs:2,10,minecraft:iron_bars,50,minecraft:iron_bars,50,minecraft:leaves2:1,100)
RandomBlock(1,3,5,minecraft:iron_bars,30,minecraft:iron_bars,30,minecraft:leaves2:1,30,quark:iron_plate_stairs:6,10,quark:iron_plate_stairs:0,10,quark:iron_plate_stairs:5,10,quark:iron_plate_stairs,10,quark:iron_plate_slab:8,10,quark:iron_plate_stairs:7,10,quark:iron_plate_stairs:1,10,quark:iron_plate_slab,10,quark:iron_plate_stairs:4,10,quark:iron_plate_stairs:2,10,minecraft:iron_bars,50,minecraft:iron_bars,50,minecraft:leaves2:1,100)
RandomBlock(1,3,6,minecraft:iron_bars,30,minecraft:iron_bars,30,minecraft:leaves2:1,30,quark:iron_plate_stairs:6,10,quark:iron_plate_stairs:0,10,quark:iron_plate_stairs:5,10,quark:iron_plate_stairs,10,quark:iron_plate_slab:8,10,quark:iron_plate_stairs:7,10,quark:iron_plate_stairs:1,10,quark:iron_plate_slab,10,quark:iron_plate_stairs:4,10,quark:iron_plate_stairs:2,10,minecraft:iron_bars,50,minecraft:iron_bars,50,minecraft:leaves2:1,100)
RandomBlock(1,4,4,minecraft:iron_bars,30,minecraft:iron_bars,30,minecraft:leaves2:1,30,quark:iron_plate_stairs:6,10,quark:iron_plate_stairs:0,10,quark:iron_plate_stairs:5,10,quark:iron_plate_stairs,10,quark:iron_plate_slab:8,10,quark:iron_plate_stairs:7,10,quark:iron_plate_stairs:1,10,quark:iron_plate_slab,10,quark:iron_plate_stairs:4,10,quark:iron_plate_stairs:2,10,minecraft:iron_bars,50,minecraft:iron_bars,50,minecraft:leaves2:1,100)
RandomBlock(1,4,5,quark:iron_plate:1,70,STAINED_CLAY:15,30,STAINED_CLAY:7,30,STAINED_CLAY:8,30,quark:iron_plate:1,100)
RandomBlock(1,4,6,minecraft:iron_bars,30,minecraft:iron_bars,30,minecraft:leaves2:1,30,quark:iron_plate_stairs:6,10,quark:iron_plate_stairs:0,10,quark:iron_plate_stairs:5,10,quark:iron_plate_stairs,10,quark:iron_plate_slab:8,10,quark:iron_plate_stairs:7,10,quark:iron_plate_stairs:1,10,quark:iron_plate_slab,10,quark:iron_plate_stairs:4,10,quark:iron_plate_stairs:2,10,minecraft:iron_bars,50,minecraft:iron_bars,50,minecraft:leaves2:1,100)
RandomBlock(1,5,4,minecraft:iron_bars,30,minecraft:iron_bars,30,minecraft:leaves2:1,30,quark:iron_plate_stairs:6,10,quark:iron_plate_stairs:0,10,quark:iron_plate_stairs:5,10,quark:iron_plate_stairs,10,quark:iron_plate_slab:8,10,quark:iron_plate_stairs:7,10,quark:iron_plate_stairs:1,10,quark:iron_plate_slab,10,quark:iron_plate_stairs:4,10,quark:iron_plate_stairs:2,10,minecraft:iron_bars,50,minecraft:iron_bars,50,minecraft:leaves2:1,100)
RandomBlock(1,5,5,minecraft:iron_bars,30,minecraft:iron_bars,30,minecraft:leaves2:1,30,quark:iron_plate_stairs:6,10,quark:iron_plate_stairs:0,10,quark:iron_plate_stairs:5,10,quark:iron_plate_stairs,10,quark:iron_plate_slab:8,10,quark:iron_plate_stairs:7,10,quark:iron_plate_stairs:1,10,quark:iron_plate_slab,10,quark:iron_plate_stairs:4,10,quark:iron_plate_stairs:2,10,minecraft:iron_bars,50,minecraft:iron_bars,50,minecraft:leaves2:1,100)
RandomBlock(1,5,6,minecraft:iron_bars,30,minecraft:iron_bars,30,minecraft:leaves2:1,30,quark:iron_plate_stairs:6,10,quark:iron_plate_stairs:0,10,quark:iron_plate_stairs:5,10,quark:iron_plate_stairs,10,quark:iron_plate_slab:8,10,quark:iron_plate_stairs:7,10,quark:iron_plate_stairs:1,10,quark:iron_plate_slab,10,quark:iron_plate_stairs:4,10,quark:iron_plate_stairs:2,10,minecraft:iron_bars,50,minecraft:iron_bars,50,minecraft:leaves2:1,100)
RandomBlock(1,6,4,minecraft:iron_bars,30,minecraft:iron_bars,30,minecraft:leaves2:1,30,quark:iron_plate_stairs:6,10,quark:iron_plate_stairs:0,10,quark:iron_plate_stairs:5,10,quark:iron_plate_stairs,10,quark:iron_plate_slab:8,10,quark:iron_plate_stairs:7,10,quark:iron_plate_stairs:1,10,quark:iron_plate_slab,10,quark:iron_plate_stairs:4,10,quark:iron_plate_stairs:2,10,minecraft:iron_bars,50,minecraft:iron_bars,50,minecraft:leaves2:1,100)
RandomBlock(1,6,5,quark:iron_plate:1,70,STAINED_CLAY:15,30,STAINED_CLAY:7,30,STAINED_CLAY:8,30,quark:iron_plate:1,100)
RandomBlock(1,6,6,quark:iron_plate:1,70,STAINED_CLAY:15,30,STAINED_CLAY:7,30,STAINED_CLAY:8,30,quark:iron_plate:1,100)
RandomBlock(1,7,4,quark:iron_plate:1,70,STAINED_CLAY:15,30,STAINED_CLAY:7,30,STAINED_CLAY:8,30,quark:iron_plate:1,100)
RandomBlock(1,7,5,quark:iron_plate:1,70,STAINED_CLAY:15,30,STAINED_CLAY:7,30,STAINED_CLAY:8,30,quark:iron_plate:1,100)
RandomBlock(1,7,6,quark:iron_plate:1,70,STAINED_CLAY:15,30,STAINED_CLAY:7,30,STAINED_CLAY:8,30,quark:iron_plate:1,100)
RandomBlock(1,8,4,quark:iron_plate:1,70,STAINED_CLAY:15,30,STAINED_CLAY:7,30,STAINED_CLAY:8,30,quark:iron_plate:1,100)
RandomBlock(1,8,5,quark:iron_plate:1,70,STAINED_CLAY:15,30,STAINED_CLAY:7,30,STAINED_CLAY:8,30,quark:iron_plate:1,100)
RandomBlock(1,8,6,quark:iron_plate:1,70,STAINED_CLAY:15,30,STAINED_CLAY:7,30,STAINED_CLAY:8,30,quark:iron_plate:1,100)
RandomBlock(1,9,4,quark:iron_plate:1,70,STAINED_CLAY:15,30,STAINED_CLAY:7,30,STAINED_CLAY:8,30,quark:iron_plate:1,100)
RandomBlock(1,9,5,quark:iron_plate:1,70,STAINED_CLAY:15,30,STAINED_CLAY:7,30,STAINED_CLAY:8,30,quark:iron_plate:1,100)
RandomBlock(1,9,6,quark:iron_plate:1,70,STAINED_CLAY:15,30,STAINED_CLAY:7,30,STAINED_CLAY:8,30,quark:iron_plate:1,100)
RandomBlock(1,10,4,quark:iron_plate:1,70,STAINED_CLAY:15,30,STAINED_CLAY:7,30,STAINED_CLAY:8,30,quark:iron_plate:1,100)
RandomBlock(1,10,5,quark:iron_plate:1,70,STAINED_CLAY:15,30,STAINED_CLAY:7,30,STAINED_CLAY:8,30,quark:iron_plate:1,100)
RandomBlock(1,10,6,quark:iron_plate:1,70,STAINED_CLAY:15,30,STAINED_CLAY:7,30,STAINED_CLAY:8,30,quark:iron_plate:1,100)
RandomBlock(1,11,4,quark:iron_plate:1,70,STAINED_CLAY:15,30,STAINED_CLAY:7,30,STAINED_CLAY:8,30,quark:iron_plate:1,100)
RandomBlock(1,11,5,quark:iron_plate:1,70,STAINED_CLAY:15,30,STAINED_CLAY:7,30,STAINED_CLAY:8,30,quark:iron_plate:1,100)
RandomBlock(1,11,6,quark:iron_plate:1,70,STAINED_CLAY:15,30,STAINED_CLAY:7,30,STAINED_CLAY:8,30,quark:iron_plate:1,100)
RandomBlock(1,12,4,quark:iron_plate:1,70,STAINED_CLAY:15,30,STAINED_CLAY:7,30,STAINED_CLAY:8,30,quark:iron_plate:1,100)
RandomBlock(1,12,5,quark:iron_plate:1,70,STAINED_CLAY:15,30,STAINED_CLAY:7,30,STAINED_CLAY:8,30,quark:iron_plate:1,100)
RandomBlock(1,12,6,quark:iron_plate:1,70,STAINED_CLAY:15,30,STAINED_CLAY:7,30,STAINED_CLAY:8,30,quark:iron_plate:1,100)
RandomBlock(1,13,4,quark:iron_plate:1,70,STAINED_CLAY:15,30,STAINED_CLAY:7,30,STAINED_CLAY:8,30,quark:iron_plate:1,100)
RandomBlock(1,13,5,quark:iron_plate:1,70,STAINED_CLAY:15,30,STAINED_CLAY:7,30,STAINED_CLAY:8,30,quark:iron_plate:1,100)
RandomBlock(1,13,6,quark:iron_plate:1,70,STAINED_CLAY:15,30,STAINED_CLAY:7,30,STAINED_CLAY:8,30,quark:iron_plate:1,100)
RandomBlock(1,14,4,quark:iron_plate:1,70,STAINED_CLAY:15,30,STAINED_CLAY:7,30,STAINED_CLAY:8,30,quark:iron_plate:1,100)
RandomBlock(1,14,5,quark:iron_plate:1,70,STAINED_CLAY:15,30,STAINED_CLAY:7,30,STAINED_CLAY:8,30,quark:iron_plate:1,100)
RandomBlock(1,14,6,quark:iron_plate:1,70,STAINED_CLAY:15,30,STAINED_CLAY:7,30,STAINED_CLAY:8,30,quark:iron_plate:1,100)
RandomBlock(1,15,4,quark:iron_plate:1,70,STAINED_CLAY:15,30,STAINED_CLAY:7,30,STAINED_CLAY:8,30,quark:iron_plate:1,100)
RandomBlock(1,15,5,quark:iron_plate:1,70,STAINED_CLAY:15,30,STAINED_CLAY:7,30,STAINED_CLAY:8,30,quark:iron_plate:1,100)
RandomBlock(1,15,6,quark:iron_plate:1,70,STAINED_CLAY:15,30,STAINED_CLAY:7,30,STAINED_CLAY:8,30,quark:iron_plate:1,100)
RandomBlock(1,16,4,quark:iron_plate:1,70,STAINED_CLAY:15,30,STAINED_CLAY:7,30,STAINED_CLAY:8,30,quark:iron_plate:1,100)
RandomBlock(1,16,5,quark:iron_plate:1,70,STAINED_CLAY:15,30,STAINED_CLAY:7,30,STAINED_CLAY:8,30,quark:iron_plate:1,100)
RandomBlock(1,16,6,quark:iron_plate:1,70,STAINED_CLAY:15,30,STAINED_CLAY:7,30,STAINED_CLAY:8,30,quark:iron_plate:1,100)
RandomBlock(1,17,4,quark:iron_plate:1,70,STAINED_CLAY:15,30,STAINED_CLAY:7,30,STAINED_CLAY:8,30,quark:iron_plate:1,100)
RandomBlock(1,17,5,quark:iron_plate:1,70,STAINED_CLAY:15,30,STAINED_CLAY:7,30,STAINED_CLAY:8,30,quark:iron_plate:1,100)
RandomBlock(1,17,6,quark:iron_plate:1,70,STAINED_CLAY:15,30,STAINED_CLAY:7,30,STAINED_CLAY:8,30,quark:iron_plate:1,100)
RandomBlock(1,18,4,quark:iron_plate:1,70,STAINED_CLAY:15,30,STAINED_CLAY:7,30,STAINED_CLAY:8,30,quark:iron_plate:1,100)
RandomBlock(1,18,5,quark:iron_plate:1,70,STAINED_CLAY:15,30,STAINED_CLAY:7,30,STAINED_CLAY:8,30,quark:iron_plate:1,100)
RandomBlock(1,18,6,quark:iron_plate:1,70,STAINED_CLAY:15,30,STAINED_CLAY:7,30,STAINED_CLAY:8,30,quark:iron_plate:1,100)
RandomBlock(1,19,4,quark:iron_plate:1,70,STAINED_CLAY:15,30,STAINED_CLAY:7,30,STAINED_CLAY:8,30,quark:iron_plate:1,100)
RandomBlock(1,19,5,quark:iron_plate:1,70,STAINED_CLAY:15,30,STAINED_CLAY:7,30,STAINED_CLAY:8,30,quark:iron_plate:1,100)
RandomBlock(1,19,6,quark:iron_plate:1,70,STAINED_CLAY:15,30,STAINED_CLAY:7,30,STAINED_CLAY:8,30,quark:iron_plate:1,100)
RandomBlock(2,0,4,minecraft:iron_bars,30,minecraft:iron_bars,30,minecraft:leaves2:1,30,quark:iron_plate_stairs:6,10,quark:iron_plate_stairs:0,10,quark:iron_plate_stairs:5,10,quark:iron_plate_stairs,10,quark:iron_plate_slab:8,10,quark:iron_plate_stairs:7,10,quark:iron_plate_stairs:1,10,quark:iron_plate_slab,10,quark:iron_plate_stairs:4,10,quark:iron_plate_stairs:2,10,minecraft:iron_bars,50,minecraft:iron_bars,50,minecraft:leaves2:1,100)
Block(2,0,5,AIR:0)
RandomBlock(2,0,6,minecraft:iron_bars,30,minecraft:iron_bars,30,minecraft:leaves2:1,30,quark:iron_plate_stairs:6,10,quark:iron_plate_stairs:0,10,quark:iron_plate_stairs:5,10,quark:iron_plate_stairs,10,quark:iron_plate_slab:8,10,quark:iron_plate_stairs:7,10,quark:iron_plate_stairs:1,10,quark:iron_plate_slab,10,quark:iron_plate_stairs:4,10,quark:iron_plate_stairs:2,10,minecraft:iron_bars,50,minecraft:iron_bars,50,minecraft:leaves2:1,100)
RandomBlock(2,1,4,quark:iron_plate:1,70,STAINED_CLAY:15,30,STAINED_CLAY:7,30,STAINED_CLAY:8,30,quark:iron_plate:1,100)
Block(2,1,5,AIR:0)
RandomBlock(2,1,6,minecraft:iron_bars,30,minecraft:iron_bars,30,minecraft:leaves2:1,30,quark:iron_plate_stairs:6,10,quark:iron_plate_stairs:0,10,quark:iron_plate_stairs:5,10,quark:iron_plate_stairs,10,quark:iron_plate_slab:8,10,quark:iron_plate_stairs:7,10,quark:iron_plate_stairs:1,10,quark:iron_plate_slab,10,quark:iron_plate_stairs:4,10,quark:iron_plate_stairs:2,10,minecraft:iron_bars,50,minecraft:iron_bars,50,minecraft:leaves2:1,100)
RandomBlock(2,2,4,minecraft:iron_bars,30,minecraft:iron_bars,30,minecraft:leaves2:1,30,quark:iron_plate_stairs:6,10,quark:iron_plate_stairs:0,10,quark:iron_plate_stairs:5,10,quark:iron_plate_stairs,10,quark:iron_plate_slab:8,10,quark:iron_plate_stairs:7,10,quark:iron_plate_stairs:1,10,quark:iron_plate_slab,10,quark:iron_plate_stairs:4,10,quark:iron_plate_stairs:2,10,minecraft:iron_bars,50,minecraft:iron_bars,50,minecraft:leaves2:1,100)
Block(2,2,5,AIR:0)
RandomBlock(2,2,6,quark:iron_plate:1,70,STAINED_CLAY:15,30,STAINED_CLAY:7,30,STAINED_CLAY:8,30,quark:iron_plate:1,100)
RandomBlock(2,3,4,quark:iron_plate:1,70,STAINED_CLAY:15,30,STAINED_CLAY:7,30,STAINED_CLAY:8,30,quark:iron_plate:1,100)
Block(2,3,5,AIR:0)
RandomBlock(2,3,6,minecraft:iron_bars,30,minecraft:iron_bars,30,minecraft:leaves2:1,30,quark:iron_plate_stairs:6,10,quark:iron_plate_stairs:0,10,quark:iron_plate_stairs:5,10,quark:iron_plate_stairs,10,quark:iron_plate_slab:8,10,quark:iron_plate_stairs:7,10,quark:iron_plate_stairs:1,10,quark:iron_plate_slab,10,quark:iron_plate_stairs:4,10,quark:iron_plate_stairs:2,10,minecraft:iron_bars,50,minecraft:iron_bars,50,minecraft:leaves2:1,100)
RandomBlock(2,4,4,quark:iron_plate:1,70,STAINED_CLAY:15,30,STAINED_CLAY:7,30,STAINED_CLAY:8,30,quark:iron_plate:1,100)
Block(2,4,5,AIR:0)
RandomBlock(2,4,6,minecraft:iron_bars,30,minecraft:iron_bars,30,minecraft:leaves2:1,30,quark:iron_plate_stairs:6,10,quark:iron_plate_stairs:0,10,quark:iron_plate_stairs:5,10,quark:iron_plate_stairs,10,quark:iron_plate_slab:8,10,quark:iron_plate_stairs:7,10,quark:iron_plate_stairs:1,10,quark:iron_plate_slab,10,quark:iron_plate_stairs:4,10,quark:iron_plate_stairs:2,10,minecraft:iron_bars,50,minecraft:iron_bars,50,minecraft:leaves2:1,100)
RandomBlock(2,5,4,minecraft:iron_bars,30,minecraft:iron_bars,30,minecraft:leaves2:1,30,quark:iron_plate_stairs:6,10,quark:iron_plate_stairs:0,10,quark:iron_plate_stairs:5,10,quark:iron_plate_stairs,10,quark:iron_plate_slab:8,10,quark:iron_plate_stairs:7,10,quark:iron_plate_stairs:1,10,quark:iron_plate_slab,10,quark:iron_plate_stairs:4,10,quark:iron_plate_stairs:2,10,minecraft:iron_bars,50,minecraft:iron_bars,50,minecraft:leaves2:1,100)
Block(2,5,5,AIR:0)
RandomBlock(2,5,6,minecraft:iron_bars,30,minecraft:iron_bars,30,minecraft:leaves2:1,30,quark:iron_plate_stairs:6,10,quark:iron_plate_stairs:0,10,quark:iron_plate_stairs:5,10,quark:iron_plate_stairs,10,quark:iron_plate_slab:8,10,quark:iron_plate_stairs:7,10,quark:iron_plate_stairs:1,10,quark:iron_plate_slab,10,quark:iron_plate_stairs:4,10,quark:iron_plate_stairs:2,10,minecraft:iron_bars,50,minecraft:iron_bars,50,minecraft:leaves2:1,100)
RandomBlock(2,6,4,quark:iron_plate:1,70,STAINED_CLAY:15,30,STAINED_CLAY:7,30,STAINED_CLAY:8,30,quark:iron_plate:1,100)
Block(2,6,5,AIR:0)
RandomBlock(2,6,6,minecraft:iron_bars,30,minecraft:iron_bars,30,minecraft:leaves2:1,30,quark:iron_plate_stairs:6,10,quark:iron_plate_stairs:0,10,quark:iron_plate_stairs:5,10,quark:iron_plate_stairs,10,quark:iron_plate_slab:8,10,quark:iron_plate_stairs:7,10,quark:iron_plate_stairs:1,10,quark:iron_plate_slab,10,quark:iron_plate_stairs:4,10,quark:iron_plate_stairs:2,10,minecraft:iron_bars,50,minecraft:iron_bars,50,minecraft:leaves2:1,100)
RandomBlock(2,7,4,quark:iron_plate:1,70,STAINED_CLAY:15,30,STAINED_CLAY:7,30,STAINED_CLAY:8,30,quark:iron_plate:1,100)
Block(2,7,5,AIR:0)
RandomBlock(2,7,6,quark:iron_plate:1,70,STAINED_CLAY:15,30,STAINED_CLAY:7,30,STAINED_CLAY:8,30,quark:iron_plate:1,100)
RandomBlock(2,8,4,quark:iron_plate:1,70,STAINED_CLAY:15,30,STAINED_CLAY:7,30,STAINED_CLAY:8,30,quark:iron_plate:1,100)
Block(2,8,5,AIR:0)
RandomBlock(2,8,6,quark:iron_plate:1,70,STAINED_CLAY:15,30,STAINED_CLAY:7,30,STAINED_CLAY:8,30,quark:iron_plate:1,100)
RandomBlock(2,9,4,quark:iron_plate:1,70,STAINED_CLAY:15,30,STAINED_CLAY:7,30,STAINED_CLAY:8,30,quark:iron_plate:1,100)
Block(2,9,5,AIR:0)
RandomBlock(2,9,6,quark:iron_plate:1,70,STAINED_CLAY:15,30,STAINED_CLAY:7,30,STAINED_CLAY:8,30,quark:iron_plate:1,100)
RandomBlock(2,10,4,quark:iron_plate:1,70,STAINED_CLAY:15,30,STAINED_CLAY:7,30,STAINED_CLAY:8,30,quark:iron_plate:1,100)
Block(2,10,5,AIR:0)
RandomBlock(2,10,6,quark:iron_plate:1,70,STAINED_CLAY:15,30,STAINED_CLAY:7,30,STAINED_CLAY:8,30,quark:iron_plate:1,100)
RandomBlock(2,11,4,quark:iron_plate:1,70,STAINED_CLAY:15,30,STAINED_CLAY:7,30,STAINED_CLAY:8,30,quark:iron_plate:1,100)
Block(2,11,5,AIR:0)
RandomBlock(2,11,6,quark:iron_plate:1,70,STAINED_CLAY:15,30,STAINED_CLAY:7,30,STAINED_CLAY:8,30,quark:iron_plate:1,100)
RandomBlock(2,12,4,minecraft:iron_bars,30,minecraft:iron_bars,30,minecraft:leaves2:1,30,quark:iron_plate_stairs:6,10,quark:iron_plate_stairs:0,10,quark:iron_plate_stairs:5,10,quark:iron_plate_stairs,10,quark:iron_plate_slab:8,10,quark:iron_plate_stairs:7,10,quark:iron_plate_stairs:1,10,quark:iron_plate_slab,10,quark:iron_plate_stairs:4,10,quark:iron_plate_stairs:2,10,minecraft:iron_bars,50,minecraft:iron_bars,50,minecraft:leaves2:1,100)
Block(2,12,5,AIR:0)
RandomBlock(2,12,6,quark:iron_plate:1,70,STAINED_CLAY:15,30,STAINED_CLAY:7,30,STAINED_CLAY:8,30,quark:iron_plate:1,100)
RandomBlock(2,13,4,quark:iron_plate:1,70,STAINED_CLAY:15,30,STAINED_CLAY:7,30,STAINED_CLAY:8,30,quark:iron_plate:1,100)
Block(2,13,5,AIR:0)
RandomBlock(2,13,6,quark:iron_plate:1,70,STAINED_CLAY:15,30,STAINED_CLAY:7,30,STAINED_CLAY:8,30,quark:iron_plate:1,100)
RandomBlock(2,14,4,quark:iron_plate:1,70,STAINED_CLAY:15,30,STAINED_CLAY:7,30,STAINED_CLAY:8,30,quark:iron_plate:1,100)
Block(2,14,5,AIR:0)
RandomBlock(2,14,6,quark:iron_plate:1,70,STAINED_CLAY:15,30,STAINED_CLAY:7,30,STAINED_CLAY:8,30,quark:iron_plate:1,100)
RandomBlock(2,15,4,quark:iron_plate:1,70,STAINED_CLAY:15,30,STAINED_CLAY:7,30,STAINED_CLAY:8,30,quark:iron_plate:1,100)
Block(2,15,5,AIR:0)
RandomBlock(2,15,6,quark:iron_plate:1,70,STAINED_CLAY:15,30,STAINED_CLAY:7,30,STAINED_CLAY:8,30,quark:iron_plate:1,100)
RandomBlock(2,16,4,quark:iron_plate:1,70,STAINED_CLAY:15,30,STAINED_CLAY:7,30,STAINED_CLAY:8,30,quark:iron_plate:1,100)
Block(2,16,5,AIR:0)
RandomBlock(2,16,6,quark:iron_plate:1,70,STAINED_CLAY:15,30,STAINED_CLAY:7,30,STAINED_CLAY:8,30,quark:iron_plate:1,100)
RandomBlock(2,17,4,quark:iron_plate:1,70,STAINED_CLAY:15,30,STAINED_CLAY:7,30,STAINED_CLAY:8,30,quark:iron_plate:1,100)
Block(2,17,5,AIR:0)
RandomBlock(2,17,6,quark:iron_plate:1,70,STAINED_CLAY:15,30,STAINED_CLAY:7,30,STAINED_CLAY:8,30,quark:iron_plate:1,100)
RandomBlock(2,18,4,quark:iron_plate:1,70,STAINED_CLAY:15,30,STAINED_CLAY:7,30,STAINED_CLAY:8,30,quark:iron_plate:1,100)
Block(2,18,5,AIR:0)
RandomBlock(2,18,6,quark:iron_plate:1,70,STAINED_CLAY:15,30,STAINED_CLAY:7,30,STAINED_CLAY:8,30,quark:iron_plate:1,100)
RandomBlock(2,19,4,quark:iron_plate:1,70,STAINED_CLAY:15,30,STAINED_CLAY:7,30,STAINED_CLAY:8,30,quark:iron_plate:1,100)
Block(2,19,5,AIR:0)
RandomBlock(2,19,6,quark:iron_plate:1,70,STAINED_CLAY:15,30,STAINED_CLAY:7,30,STAINED_CLAY:8,30,quark:iron_plate:1,100)
RandomBlock(3,0,4,quark:iron_plate:1,70,STAINED_CLAY:15,30,STAINED_CLAY:7,30,STAINED_CLAY:8,30,quark:iron_plate:1,100)
RandomBlock(3,0,5,quark:iron_plate:1,70,STAINED_CLAY:15,30,STAINED_CLAY:7,30,STAINED_CLAY:8,30,quark:iron_plate:1,100)
RandomBlock(3,0,6,quark:iron_plate:1,70,STAINED_CLAY:15,30,STAINED_CLAY:7,30,STAINED_CLAY:8,30,quark:iron_plate:1,100)
RandomBlock(3,1,4,quark:iron_plate:1,70,STAINED_CLAY:15,30,STAINED_CLAY:7,30,STAINED_CLAY:8,30,quark:iron_plate:1,100)
RandomBlock(3,1,5,quark:iron_plate:1,70,STAINED_CLAY:15,30,STAINED_CLAY:7,30,STAINED_CLAY:8,30,quark:iron_plate:1,100)
RandomBlock(3,1,6,quark:iron_plate:1,70,STAINED_CLAY:15,30,STAINED_CLAY:7,30,STAINED_CLAY:8,30,quark:iron_plate:1,100)
RandomBlock(3,2,4,quark:iron_plate:1,70,STAINED_CLAY:15,30,STAINED_CLAY:7,30,STAINED_CLAY:8,30,quark:iron_plate:1,100)
RandomBlock(3,2,5,quark:iron_plate:1,70,STAINED_CLAY:15,30,STAINED_CLAY:7,30,STAINED_CLAY:8,30,quark:iron_plate:1,100)
RandomBlock(3,2,6,quark:iron_plate:1,70,STAINED_CLAY:15,30,STAINED_CLAY:7,30,STAINED_CLAY:8,30,quark:iron_plate:1,100)
RandomBlock(3,3,4,quark:iron_plate:1,70,STAINED_CLAY:15,30,STAINED_CLAY:7,30,STAINED_CLAY:8,30,quark:iron_plate:1,100)
RandomBlock(3,3,5,quark:iron_plate:1,70,STAINED_CLAY:15,30,STAINED_CLAY:7,30,STAINED_CLAY:8,30,quark:iron_plate:1,100)
RandomBlock(3,3,6,quark:iron_plate:1,70,STAINED_CLAY:15,30,STAINED_CLAY:7,30,STAINED_CLAY:8,30,quark:iron_plate:1,100)
RandomBlock(3,4,4,quark:iron_plate:1,70,STAINED_CLAY:15,30,STAINED_CLAY:7,30,STAINED_CLAY:8,30,quark:iron_plate:1,100)
RandomBlock(3,4,5,quark:iron_plate:1,70,STAINED_CLAY:15,30,STAINED_CLAY:7,30,STAINED_CLAY:8,30,quark:iron_plate:1,100)
RandomBlock(3,4,6,quark:iron_plate:1,70,STAINED_CLAY:15,30,STAINED_CLAY:7,30,STAINED_CLAY:8,30,quark:iron_plate:1,100)
RandomBlock(3,5,4,quark:iron_plate:1,70,STAINED_CLAY:15,30,STAINED_CLAY:7,30,STAINED_CLAY:8,30,quark:iron_plate:1,100)
RandomBlock(3,5,5,quark:iron_plate:1,70,STAINED_CLAY:15,30,STAINED_CLAY:7,30,STAINED_CLAY:8,30,quark:iron_plate:1,100)
RandomBlock(3,5,6,minecraft:iron_bars,30,minecraft:iron_bars,30,minecraft:leaves2:1,30,quark:iron_plate_stairs:6,10,quark:iron_plate_stairs:0,10,quark:iron_plate_stairs:5,10,quark:iron_plate_stairs,10,quark:iron_plate_slab:8,10,quark:iron_plate_stairs:7,10,quark:iron_plate_stairs:1,10,quark:iron_plate_slab,10,quark:iron_plate_stairs:4,10,quark:iron_plate_stairs:2,10,minecraft:iron_bars,50,minecraft:iron_bars,50,minecraft:leaves2:1,100)
RandomBlock(3,6,4,quark:iron_plate:1,70,STAINED_CLAY:15,30,STAINED_CLAY:7,30,STAINED_CLAY:8,30,quark:iron_plate:1,100)
RandomBlock(3,6,5,minecraft:iron_bars,30,minecraft:iron_bars,30,minecraft:leaves2:1,30,quark:iron_plate_stairs:6,10,quark:iron_plate_stairs:0,10,quark:iron_plate_stairs:5,10,quark:iron_plate_stairs,10,quark:iron_plate_slab:8,10,quark:iron_plate_stairs:7,10,quark:iron_plate_stairs:1,10,quark:iron_plate_slab,10,quark:iron_plate_stairs:4,10,quark:iron_plate_stairs:2,10,minecraft:iron_bars,50,minecraft:iron_bars,50,minecraft:leaves2:1,100)
RandomBlock(3,6,6,minecraft:iron_bars,30,minecraft:iron_bars,30,minecraft:leaves2:1,30,quark:iron_plate_stairs:6,10,quark:iron_plate_stairs:0,10,quark:iron_plate_stairs:5,10,quark:iron_plate_stairs,10,quark:iron_plate_slab:8,10,quark:iron_plate_stairs:7,10,quark:iron_plate_stairs:1,10,quark:iron_plate_slab,10,quark:iron_plate_stairs:4,10,quark:iron_plate_stairs:2,10,minecraft:iron_bars,50,minecraft:iron_bars,50,minecraft:leaves2:1,100)
RandomBlock(3,7,4,quark:iron_plate:1,70,STAINED_CLAY:15,30,STAINED_CLAY:7,30,STAINED_CLAY:8,30,quark:iron_plate:1,100)
RandomBlock(3,7,5,quark:iron_plate:1,70,STAINED_CLAY:15,30,STAINED_CLAY:7,30,STAINED_CLAY:8,30,quark:iron_plate:1,100)
RandomBlock(3,7,6,minecraft:iron_bars,30,minecraft:iron_bars,30,minecraft:leaves2:1,30,quark:iron_plate_stairs:6,10,quark:iron_plate_stairs:0,10,quark:iron_plate_stairs:5,10,quark:iron_plate_stairs,10,quark:iron_plate_slab:8,10,quark:iron_plate_stairs:7,10,quark:iron_plate_stairs:1,10,quark:iron_plate_slab,10,quark:iron_plate_stairs:4,10,quark:iron_plate_stairs:2,10,minecraft:iron_bars,50,minecraft:iron_bars,50,minecraft:leaves2:1,100)
RandomBlock(3,8,4,quark:iron_plate:1,70,STAINED_CLAY:15,30,STAINED_CLAY:7,30,STAINED_CLAY:8,30,quark:iron_plate:1,100)
RandomBlock(3,8,5,quark:iron_plate:1,70,STAINED_CLAY:15,30,STAINED_CLAY:7,30,STAINED_CLAY:8,30,quark:iron_plate:1,100)
RandomBlock(3,8,6,quark:iron_plate:1,70,STAINED_CLAY:15,30,STAINED_CLAY:7,30,STAINED_CLAY:8,30,quark:iron_plate:1,100)
RandomBlock(3,9,4,quark:iron_plate:1,70,STAINED_CLAY:15,30,STAINED_CLAY:7,30,STAINED_CLAY:8,30,quark:iron_plate:1,100)
RandomBlock(3,9,5,quark:iron_plate:1,70,STAINED_CLAY:15,30,STAINED_CLAY:7,30,STAINED_CLAY:8,30,quark:iron_plate:1,100)
RandomBlock(3,9,6,quark:iron_plate:1,70,STAINED_CLAY:15,30,STAINED_CLAY:7,30,STAINED_CLAY:8,30,quark:iron_plate:1,100)
RandomBlock(3,10,4,quark:iron_plate:1,70,STAINED_CLAY:15,30,STAINED_CLAY:7,30,STAINED_CLAY:8,30,quark:iron_plate:1,100)
RandomBlock(3,10,5,quark:iron_plate:1,70,STAINED_CLAY:15,30,STAINED_CLAY:7,30,STAINED_CLAY:8,30,quark:iron_plate:1,100)
RandomBlock(3,10,6,quark:iron_plate:1,70,STAINED_CLAY:15,30,STAINED_CLAY:7,30,STAINED_CLAY:8,30,quark:iron_plate:1,100)
RandomBlock(3,11,4,minecraft:iron_bars,30,minecraft:iron_bars,30,minecraft:leaves2:1,30,quark:iron_plate_stairs:6,10,quark:iron_plate_stairs:0,10,quark:iron_plate_stairs:5,10,quark:iron_plate_stairs,10,quark:iron_plate_slab:8,10,quark:iron_plate_stairs:7,10,quark:iron_plate_stairs:1,10,quark:iron_plate_slab,10,quark:iron_plate_stairs:4,10,quark:iron_plate_stairs:2,10,minecraft:iron_bars,50,minecraft:iron_bars,50,minecraft:leaves2:1,100)
RandomBlock(3,11,5,quark:iron_plate:1,70,STAINED_CLAY:15,30,STAINED_CLAY:7,30,STAINED_CLAY:8,30,quark:iron_plate:1,100)
RandomBlock(3,11,6,quark:iron_plate:1,70,STAINED_CLAY:15,30,STAINED_CLAY:7,30,STAINED_CLAY:8,30,quark:iron_plate:1,100)
RandomBlock(3,12,4,minecraft:iron_bars,30,minecraft:iron_bars,30,minecraft:leaves2:1,30,quark:iron_plate_stairs:6,10,quark:iron_plate_stairs:0,10,quark:iron_plate_stairs:5,10,quark:iron_plate_stairs,10,quark:iron_plate_slab:8,10,quark:iron_plate_stairs:7,10,quark:iron_plate_stairs:1,10,quark:iron_plate_slab,10,quark:iron_plate_stairs:4,10,quark:iron_plate_stairs:2,10,minecraft:iron_bars,50,minecraft:iron_bars,50,minecraft:leaves2:1,100)
RandomBlock(3,12,5,minecraft:iron_bars,30,minecraft:iron_bars,30,minecraft:leaves2:1,30,quark:iron_plate_stairs:6,10,quark:iron_plate_stairs:0,10,quark:iron_plate_stairs:5,10,quark:iron_plate_stairs,10,quark:iron_plate_slab:8,10,quark:iron_plate_stairs:7,10,quark:iron_plate_stairs:1,10,quark:iron_plate_slab,10,quark:iron_plate_stairs:4,10,quark:iron_plate_stairs:2,10,minecraft:iron_bars,50,minecraft:iron_bars,50,minecraft:leaves2:1,100)
RandomBlock(3,12,6,quark:iron_plate:1,70,STAINED_CLAY:15,30,STAINED_CLAY:7,30,STAINED_CLAY:8,30,quark:iron_plate:1,100)
RandomBlock(3,13,4,minecraft:iron_bars,30,minecraft:iron_bars,30,minecraft:leaves2:1,30,quark:iron_plate_stairs:6,10,quark:iron_plate_stairs:0,10,quark:iron_plate_stairs:5,10,quark:iron_plate_stairs,10,quark:iron_plate_slab:8,10,quark:iron_plate_stairs:7,10,quark:iron_plate_stairs:1,10,quark:iron_plate_slab,10,quark:iron_plate_stairs:4,10,quark:iron_plate_stairs:2,10,minecraft:iron_bars,50,minecraft:iron_bars,50,minecraft:leaves2:1,100)
RandomBlock(3,13,5,quark:iron_plate:1,70,STAINED_CLAY:15,30,STAINED_CLAY:7,30,STAINED_CLAY:8,30,quark:iron_plate:1,100)
RandomBlock(3,13,6,quark:iron_plate:1,70,STAINED_CLAY:15,30,STAINED_CLAY:7,30,STAINED_CLAY:8,30,quark:iron_plate:1,100)
RandomBlock(3,14,4,quark:iron_plate:1,70,STAINED_CLAY:15,30,STAINED_CLAY:7,30,STAINED_CLAY:8,30,quark:iron_plate:1,100)
RandomBlock(3,14,5,quark:iron_plate:1,70,STAINED_CLAY:15,30,STAINED_CLAY:7,30,STAINED_CLAY:8,30,quark:iron_plate:1,100)
RandomBlock(3,14,6,quark:iron_plate:1,70,STAINED_CLAY:15,30,STAINED_CLAY:7,30,STAINED_CLAY:8,30,quark:iron_plate:1,100)
RandomBlock(3,15,4,quark:iron_plate:1,70,STAINED_CLAY:15,30,STAINED_CLAY:7,30,STAINED_CLAY:8,30,quark:iron_plate:1,100)
RandomBlock(3,15,5,quark:iron_plate:1,70,STAINED_CLAY:15,30,STAINED_CLAY:7,30,STAINED_CLAY:8,30,quark:iron_plate:1,100)
RandomBlock(3,15,6,quark:iron_plate:1,70,STAINED_CLAY:15,30,STAINED_CLAY:7,30,STAINED_CLAY:8,30,quark:iron_plate:1,100)
RandomBlock(3,16,4,quark:iron_plate:1,70,STAINED_CLAY:15,30,STAINED_CLAY:7,30,STAINED_CLAY:8,30,quark:iron_plate:1,100)
RandomBlock(3,16,5,quark:iron_plate:1,70,STAINED_CLAY:15,30,STAINED_CLAY:7,30,STAINED_CLAY:8,30,quark:iron_plate:1,100)
RandomBlock(3,16,6,quark:iron_plate:1,70,STAINED_CLAY:15,30,STAINED_CLAY:7,30,STAINED_CLAY:8,30,quark:iron_plate:1,100)
RandomBlock(3,17,4,quark:iron_plate:1,70,STAINED_CLAY:15,30,STAINED_CLAY:7,30,STAINED_CLAY:8,30,quark:iron_plate:1,100)
RandomBlock(3,17,5,quark:iron_plate:1,70,STAINED_CLAY:15,30,STAINED_CLAY:7,30,STAINED_CLAY:8,30,quark:iron_plate:1,100)
RandomBlock(3,17,6,quark:iron_plate:1,70,STAINED_CLAY:15,30,STAINED_CLAY:7,30,STAINED_CLAY:8,30,quark:iron_plate:1,100)
RandomBlock(3,18,4,quark:iron_plate:1,70,STAINED_CLAY:15,30,STAINED_CLAY:7,30,STAINED_CLAY:8,30,quark:iron_plate:1,100)
RandomBlock(3,18,5,quark:iron_plate:1,70,STAINED_CLAY:15,30,STAINED_CLAY:7,30,STAINED_CLAY:8,30,quark:iron_plate:1,100)
RandomBlock(3,18,6,quark:iron_plate:1,70,STAINED_CLAY:15,30,STAINED_CLAY:7,30,STAINED_CLAY:8,30,quark:iron_plate:1,100)
RandomBlock(3,19,4,quark:iron_plate:1,70,STAINED_CLAY:15,30,STAINED_CLAY:7,30,STAINED_CLAY:8,30,quark:iron_plate:1,100)
RandomBlock(3,19,5,quark:iron_plate:1,70,STAINED_CLAY:15,30,STAINED_CLAY:7,30,STAINED_CLAY:8,30,quark:iron_plate:1,100)
RandomBlock(3,19,6,quark:iron_plate:1,70,STAINED_CLAY:15,30,STAINED_CLAY:7,30,STAINED_CLAY:8,30,quark:iron_plate:1,100)
Block(7,750,8,AIR:0)

#######################################################################
# +-----------------------------------------------------------------+ #
# |                             Branches                            | #
# +-----------------------------------------------------------------+ #
#######################################################################


#######################################################################
# +-----------------------------------------------------------------+ #
# |                             Entities                            | #
# +-----------------------------------------------------------------+ #
#######################################################################


#######################################################################
# +-----------------------------------------------------------------+ #
# |                            Particles                            | #
# +-----------------------------------------------------------------+ #
#######################################################################


#######################################################################
# +-----------------------------------------------------------------+ #
# |                             Spawners                            | #
# +-----------------------------------------------------------------+ #
#######################################################################


#######################################################################
# +-----------------------------------------------------------------+ #
# |                             ModData                             | #
# +-----------------------------------------------------------------+ #
#######################################################################

