
#######################################################################
# +-----------------------------------------------------------------+ #
# |                            BO4 object                           | #
# +-----------------------------------------------------------------+ #
#######################################################################

Author: NLBlackEagle

Description: No description given

SettingsMode: WriteWithoutComments


#######################################################################
# +-----------------------------------------------------------------+ #
# |                          Main settings                          | #
# +-----------------------------------------------------------------+ #
#######################################################################

FixedRotation: 

Frequency: 0

SpawnHeight: highestBlock

UseCenterForHighestBlock: true

##############################
# Height Limits for the BO4. #
##############################

MinHeight: 0

MaxHeight: 255

InheritBO3: 

InheritBO3Rotation: NORTH

OverrideChildSettings: true

OverrideParentHeight: false

CanOverride: true

BranchFrequency: 0

BranchFrequencyGroup: 

MustBeBelowOther: false

MustBeInside: 

CannotBeInside: 

ReplacesBO3: 

MustBeInsideWorldBorders: true

CanSpawnOnWater: true

SpawnOnWaterOnly: false

SpawnUnderWater: false

SpawnAtWaterLevel: false

HeightOffset: 0

RemoveAir: false

ReplaceAbove: 

ReplaceBelow: 

ReplaceWithBiomeBlocks: true

ReplaceWithSurfaceBlock: GRASS

ReplaceWithGroundBlock: DIRT

ReplaceWithStoneBlock: STONE

SmoothRadius: 0

SmoothHeightOffset: 0

SmoothStartTop: false

SmoothStartWood: false

SmoothingSurfaceBlock: 

SmoothingGroundBlock: 

BO3Group: 

IsSpawnPoint: false

DoReplaceBlocks: false


#######################################################################
# +-----------------------------------------------------------------+ #
# |                              Blocks                             | #
# +-----------------------------------------------------------------+ #
#######################################################################

Block(-8,0,0,quark:limestone:0)
Block(-8,0,1,quark:limestone:0)
Block(-8,0,2,quark:limestone:0)
Block(-8,0,3,quark:limestone:0)
Block(-8,0,4,quark:limestone:0)
Block(-8,1,0,COBBLESTONE_STAIRS:0)
Block(-8,1,1,COBBLESTONE_STAIRS:0)
Block(-8,1,2,COBBLESTONE_STAIRS:0)
Block(-8,1,3,COBBLESTONE_STAIRS:0)
Block(-8,1,4,COBBLESTONE_STAIRS:3)
Block(-7,0,0,quark:limestone:0)
RandomBlock(-7,0,1,quark:iron_plate:1,70,STAINED_CLAY:15,30,STAINED_CLAY:7,30,quark:iron_plate:1,100)
RandomBlock(-7,0,2,quark:iron_plate:1,70,STAINED_CLAY:15,30,STAINED_CLAY:7,30,quark:iron_plate:1,100)
RandomBlock(-7,0,3,quark:iron_plate:1,70,STAINED_CLAY:15,30,STAINED_CLAY:7,30,quark:iron_plate:1,100)
Block(-7,0,4,quark:limestone:0)
Block(-7,1,0,COBBLESTONE_STAIRS:2)
RandomBlock(-7,1,1,quark:iron_plate:1,70,STAINED_CLAY:15,30,STAINED_CLAY:7,30,quark:iron_plate:1,100)
RandomBlock(-7,1,2,quark:iron_plate:1,70,STAINED_CLAY:15,30,STAINED_CLAY:7,30,quark:iron_plate:1,100)
RandomBlock(-7,1,3,quark:iron_plate:1,70,STAINED_CLAY:15,30,STAINED_CLAY:7,30,quark:iron_plate:1,100)
Block(-7,1,4,COBBLESTONE_STAIRS:3)
RandomBlock(-7,2,1,quark:iron_plate:1,70,STAINED_CLAY:15,30,STAINED_CLAY:7,30,quark:iron_plate:1,100)
RandomBlock(-7,2,2,quark:iron_plate:1,70,STAINED_CLAY:15,30,STAINED_CLAY:7,30,quark:iron_plate:1,100)
RandomBlock(-7,2,3,IRON_FENCE:0,30,IRON_FENCE:0,30,LEAVES:7,30,quark:iron_plate_stairs:6,10,quark:iron_plate_stairs:0,10,quark:iron_plate_stairs:5,10,quark:iron_plate_stairs:3,10,quark:iron_plate_slab:8,10,quark:iron_plate_stairs:7,10,quark:iron_plate_stairs:1,10,quark:iron_plate_slab:0,10,quark:iron_plate_stairs:4,10,quark:iron_plate_stairs:2,10,IRON_FENCE:0,50,IRON_FENCE:0,50,LEAVES:7,100)
RandomBlock(-7,3,1,quark:iron_plate:1,70,STAINED_CLAY:15,30,STAINED_CLAY:7,30,quark:iron_plate:1,100)
RandomBlock(-7,3,2,quark:iron_plate:1,70,STAINED_CLAY:15,30,STAINED_CLAY:7,30,quark:iron_plate:1,100)
RandomBlock(-7,3,3,IRON_FENCE:0,30,IRON_FENCE:0,30,LEAVES:7,30,quark:iron_plate_stairs:6,10,quark:iron_plate_stairs:0,10,quark:iron_plate_stairs:5,10,quark:iron_plate_stairs:3,10,quark:iron_plate_slab:8,10,quark:iron_plate_stairs:7,10,quark:iron_plate_stairs:1,10,quark:iron_plate_slab:0,10,quark:iron_plate_stairs:4,10,quark:iron_plate_stairs:2,10,IRON_FENCE:0,50,IRON_FENCE:0,50,LEAVES:7,100)
RandomBlock(-7,4,1,IRON_FENCE:0,30,IRON_FENCE:0,30,LEAVES:7,30,quark:iron_plate_stairs:6,10,quark:iron_plate_stairs:0,10,quark:iron_plate_stairs:5,10,quark:iron_plate_stairs:3,10,quark:iron_plate_slab:8,10,quark:iron_plate_stairs:7,10,quark:iron_plate_stairs:1,10,quark:iron_plate_slab:0,10,quark:iron_plate_stairs:4,10,quark:iron_plate_stairs:2,10,IRON_FENCE:0,50,IRON_FENCE:0,50,LEAVES:7,100)
RandomBlock(-7,4,2,quark:iron_plate:1,70,STAINED_CLAY:15,30,STAINED_CLAY:7,30,quark:iron_plate:1,100)
RandomBlock(-7,4,3,IRON_FENCE:0,30,IRON_FENCE:0,30,LEAVES:7,30,quark:iron_plate_stairs:6,10,quark:iron_plate_stairs:0,10,quark:iron_plate_stairs:5,10,quark:iron_plate_stairs:3,10,quark:iron_plate_slab:8,10,quark:iron_plate_stairs:7,10,quark:iron_plate_stairs:1,10,quark:iron_plate_slab:0,10,quark:iron_plate_stairs:4,10,quark:iron_plate_stairs:2,10,IRON_FENCE:0,50,IRON_FENCE:0,50,LEAVES:7,100)
RandomBlock(-7,5,1,IRON_FENCE:0,30,IRON_FENCE:0,30,LEAVES:7,30,quark:iron_plate_stairs:6,10,quark:iron_plate_stairs:0,10,quark:iron_plate_stairs:5,10,quark:iron_plate_stairs:3,10,quark:iron_plate_slab:8,10,quark:iron_plate_stairs:7,10,quark:iron_plate_stairs:1,10,quark:iron_plate_slab:0,10,quark:iron_plate_stairs:4,10,quark:iron_plate_stairs:2,10,IRON_FENCE:0,50,IRON_FENCE:0,50,LEAVES:7,100)
RandomBlock(-7,5,2,IRON_FENCE:0,30,IRON_FENCE:0,30,LEAVES:7,30,quark:iron_plate_stairs:6,10,quark:iron_plate_stairs:0,10,quark:iron_plate_stairs:5,10,quark:iron_plate_stairs:3,10,quark:iron_plate_slab:8,10,quark:iron_plate_stairs:7,10,quark:iron_plate_stairs:1,10,quark:iron_plate_slab:0,10,quark:iron_plate_stairs:4,10,quark:iron_plate_stairs:2,10,IRON_FENCE:0,50,IRON_FENCE:0,50,LEAVES:7,100)
RandomBlock(-7,5,3,IRON_FENCE:0,30,IRON_FENCE:0,30,LEAVES:7,30,quark:iron_plate_stairs:6,10,quark:iron_plate_stairs:0,10,quark:iron_plate_stairs:5,10,quark:iron_plate_stairs:3,10,quark:iron_plate_slab:8,10,quark:iron_plate_stairs:7,10,quark:iron_plate_stairs:1,10,quark:iron_plate_slab:0,10,quark:iron_plate_stairs:4,10,quark:iron_plate_stairs:2,10,IRON_FENCE:0,50,IRON_FENCE:0,50,LEAVES:7,100)
Block(-7,6,1,quark:iron_plate_slab:0)
Block(-7,6,2,quark:iron_plate_slab:0)
Block(-7,6,3,quark:iron_plate_slab:0)
Block(-7,7,1,IRON_FENCE:0)
Block(-7,7,2,IRON_FENCE:0)
Block(-7,7,3,IRON_FENCE:0)
Block(-6,0,-5,quark:limestone:0)
Block(-6,0,-4,quark:limestone:0)
Block(-6,0,-3,quark:limestone:0)
Block(-6,0,0,quark:limestone:0)
RandomBlock(-6,0,1,quark:iron_plate:1,70,STAINED_CLAY:15,30,STAINED_CLAY:7,30,quark:iron_plate:1,100)
Block(-6,0,2,srparasites:deadblood:1)
RandomBlock(-6,0,3,quark:iron_plate:1,70,STAINED_CLAY:15,30,STAINED_CLAY:7,30,quark:iron_plate:1,100)
Block(-6,0,4,quark:limestone:0)
RandomBlock(-6,0,6,quark:iron_plate:1,70,STAINED_CLAY:15,30,STAINED_CLAY:7,30,quark:iron_plate:1,100)
Block(-6,1,-5,COBBLESTONE_STAIRS:2)
Block(-6,1,-4,COBBLESTONE_STAIRS:0)
Block(-6,1,-3,COBBLESTONE_STAIRS:0)
Block(-6,1,0,COBBLESTONE_STAIRS:2)
RandomBlock(-6,1,1,quark:iron_plate:1,70,STAINED_CLAY:15,30,STAINED_CLAY:7,30,quark:iron_plate:1,100)
Block(-6,1,2,srparasites:deadblood:1)
RandomBlock(-6,1,3,quark:iron_plate:1,70,STAINED_CLAY:15,30,STAINED_CLAY:7,30,quark:iron_plate:1,100)
Block(-6,1,4,COBBLESTONE_STAIRS:3)
RandomBlock(-6,1,6,quark:iron_plate:1,70,STAINED_CLAY:15,30,STAINED_CLAY:7,30,quark:iron_plate:1,100)
RandomBlock(-6,2,1,quark:iron_plate:1,70,STAINED_CLAY:15,30,STAINED_CLAY:7,30,quark:iron_plate:1,100)
Block(-6,2,2,srparasites:deadblood:1)
RandomBlock(-6,2,3,quark:iron_plate:1,70,STAINED_CLAY:15,30,STAINED_CLAY:7,30,quark:iron_plate:1,100)
RandomBlock(-6,2,6,quark:iron_plate:1,70,STAINED_CLAY:15,30,STAINED_CLAY:7,30,quark:iron_plate:1,100)
RandomBlock(-6,3,1,quark:iron_plate:1,70,STAINED_CLAY:15,30,STAINED_CLAY:7,30,quark:iron_plate:1,100)
Block(-6,3,2,srparasites:deadblood:1)
RandomBlock(-6,3,3,quark:iron_plate:1,70,STAINED_CLAY:15,30,STAINED_CLAY:7,30,quark:iron_plate:1,100)
RandomBlock(-6,3,6,quark:iron_plate:1,70,STAINED_CLAY:15,30,STAINED_CLAY:7,30,quark:iron_plate:1,100)
RandomBlock(-6,4,1,quark:iron_plate:1,70,STAINED_CLAY:15,30,STAINED_CLAY:7,30,quark:iron_plate:1,100)
Block(-6,4,2,srparasites:deadblood)
RandomBlock(-6,4,3,quark:iron_plate:1,70,STAINED_CLAY:15,30,STAINED_CLAY:7,30,quark:iron_plate:1,100)
RandomBlock(-6,4,4,quark:iron_plate:1,70,STAINED_CLAY:15,30,STAINED_CLAY:7,30,quark:iron_plate:1,100)
RandomBlock(-6,4,5,quark:iron_plate:1,70,STAINED_CLAY:15,30,STAINED_CLAY:7,30,quark:iron_plate:1,100)
RandomBlock(-6,4,6,quark:iron_plate:1,70,STAINED_CLAY:15,30,STAINED_CLAY:7,30,quark:iron_plate:1,100)
RandomBlock(-6,5,1,quark:iron_plate:1,70,STAINED_CLAY:15,30,STAINED_CLAY:7,30,quark:iron_plate:1,100)
RandomBlock(-6,5,2,quark:iron_plate:1,70,STAINED_CLAY:15,30,STAINED_CLAY:7,30,quark:iron_plate:1,100)
RandomBlock(-6,5,3,quark:iron_plate:1,70,STAINED_CLAY:15,30,STAINED_CLAY:7,30,quark:iron_plate:1,100)
Block(-6,6,1,quark:iron_plate_slab:0)
Block(-6,6,2,quark:basalt_wall:0)
Block(-6,6,3,quark:iron_plate_slab:0)
Block(-6,7,1,IRON_FENCE:0)
Block(-6,7,2,IRON_FENCE:0)
Block(-6,7,3,IRON_FENCE:0)
Block(-5,0,-5,quark:limestone:0)
RandomBlock(-5,0,-4,quark:iron_plate:1,70,STAINED_CLAY:15,30,STAINED_CLAY:7,30,quark:iron_plate:1,100)
Block(-5,0,-3,quark:limestone:0)
Block(-5,0,0,quark:limestone:0)
RandomBlock(-5,0,1,quark:iron_plate:1,70,STAINED_CLAY:15,30,STAINED_CLAY:7,30,quark:iron_plate:1,100)
RandomBlock(-5,0,2,quark:iron_plate:1,70,STAINED_CLAY:15,30,STAINED_CLAY:7,30,quark:iron_plate:1,100)
RandomBlock(-5,0,3,quark:iron_plate:1,70,STAINED_CLAY:15,30,STAINED_CLAY:7,30,quark:iron_plate:1,100)
Block(-5,0,4,quark:limestone:0)
Block(-5,1,-5,COBBLESTONE_STAIRS:2)
RandomBlock(-5,1,-4,quark:iron_plate:1,70,STAINED_CLAY:15,30,STAINED_CLAY:7,30,quark:iron_plate:1,100)
Block(-5,1,-3,COBBLESTONE_STAIRS:3)
Block(-5,1,0,COBBLESTONE_STAIRS:2)
RandomBlock(-5,1,1,quark:iron_plate:1,70,STAINED_CLAY:15,30,STAINED_CLAY:7,30,quark:iron_plate:1,100)
RandomBlock(-5,1,2,quark:iron_plate:1,70,STAINED_CLAY:15,30,STAINED_CLAY:7,30,quark:iron_plate:1,100)
RandomBlock(-5,1,3,quark:iron_plate:1,70,STAINED_CLAY:15,30,STAINED_CLAY:7,30,quark:iron_plate:1,100)
Block(-5,1,4,COBBLESTONE_STAIRS:3)
RandomBlock(-5,2,-4,quark:iron_plate:1,70,STAINED_CLAY:15,30,STAINED_CLAY:7,30,quark:iron_plate:1,100)
RandomBlock(-5,2,1,IRON_FENCE:0,30,IRON_FENCE:0,30,LEAVES:7,30,quark:iron_plate_stairs:6,10,quark:iron_plate_stairs:0,10,quark:iron_plate_stairs:5,10,quark:iron_plate_stairs:3,10,quark:iron_plate_slab:8,10,quark:iron_plate_stairs:7,10,quark:iron_plate_stairs:1,10,quark:iron_plate_slab:0,10,quark:iron_plate_stairs:4,10,quark:iron_plate_stairs:2,10,IRON_FENCE:0,50,IRON_FENCE:0,50,LEAVES:7,100)
RandomBlock(-5,2,2,quark:iron_plate:1,70,STAINED_CLAY:15,30,STAINED_CLAY:7,30,quark:iron_plate:1,100)
RandomBlock(-5,2,3,quark:iron_plate:1,70,STAINED_CLAY:15,30,STAINED_CLAY:7,30,quark:iron_plate:1,100)
RandomBlock(-5,3,-4,quark:iron_plate:1,70,STAINED_CLAY:15,30,STAINED_CLAY:7,30,quark:iron_plate:1,100)
RandomBlock(-5,3,1,IRON_FENCE:0,30,IRON_FENCE:0,30,LEAVES:7,30,quark:iron_plate_stairs:6,10,quark:iron_plate_stairs:0,10,quark:iron_plate_stairs:5,10,quark:iron_plate_stairs:3,10,quark:iron_plate_slab:8,10,quark:iron_plate_stairs:7,10,quark:iron_plate_stairs:1,10,quark:iron_plate_slab:0,10,quark:iron_plate_stairs:4,10,quark:iron_plate_stairs:2,10,IRON_FENCE:0,50,IRON_FENCE:0,50,LEAVES:7,100)
RandomBlock(-5,3,2,quark:iron_plate:1,70,STAINED_CLAY:15,30,STAINED_CLAY:7,30,quark:iron_plate:1,100)
RandomBlock(-5,3,3,quark:iron_plate:1,70,STAINED_CLAY:15,30,STAINED_CLAY:7,30,quark:iron_plate:1,100)
RandomBlock(-5,4,-4,quark:iron_plate:1,70,STAINED_CLAY:15,30,STAINED_CLAY:7,30,quark:iron_plate:1,100)
RandomBlock(-5,4,1,quark:iron_plate:1,70,STAINED_CLAY:15,30,STAINED_CLAY:7,30,quark:iron_plate:1,100)
Block(-5,4,2,srparasites:deadblood)
RandomBlock(-5,4,3,quark:iron_plate:1,70,STAINED_CLAY:15,30,STAINED_CLAY:7,30,quark:iron_plate:1,100)
RandomBlock(-5,5,-4,quark:iron_plate:1,70,STAINED_CLAY:15,30,STAINED_CLAY:7,30,quark:iron_plate:1,100)
RandomBlock(-5,5,1,quark:iron_plate:1,70,STAINED_CLAY:15,30,STAINED_CLAY:7,30,quark:iron_plate:1,100)
RandomBlock(-5,5,2,quark:iron_plate:1,70,STAINED_CLAY:15,30,STAINED_CLAY:7,30,quark:iron_plate:1,100)
RandomBlock(-5,5,3,quark:iron_plate:1,70,STAINED_CLAY:15,30,STAINED_CLAY:7,30,quark:iron_plate:1,100)
RandomBlock(-5,6,-4,quark:iron_plate:1,70,STAINED_CLAY:15,30,STAINED_CLAY:7,30,quark:iron_plate:1,100)
Block(-5,6,1,quark:iron_plate_slab:0)
Block(-5,6,2,quark:iron_plate_slab:0)
Block(-5,6,3,quark:iron_plate_slab:0)
RandomBlock(-5,7,-4,quark:iron_plate:1,70,STAINED_CLAY:15,30,STAINED_CLAY:7,30,quark:iron_plate:1,100)
Block(-5,7,1,IRON_FENCE:0)
Block(-5,7,2,IRON_FENCE:0)
Block(-5,7,3,IRON_FENCE:0)
RandomBlock(-5,8,-4,quark:iron_plate:1,70,STAINED_CLAY:15,30,STAINED_CLAY:7,30,quark:iron_plate:1,100)
RandomBlock(-5,9,-4,quark:iron_plate:1,70,STAINED_CLAY:15,30,STAINED_CLAY:7,30,quark:iron_plate:1,100)
RandomBlock(-5,10,-4,quark:iron_plate:1,70,STAINED_CLAY:15,30,STAINED_CLAY:7,30,quark:iron_plate:1,100)
RandomBlock(-5,11,-4,quark:iron_plate:1,70,STAINED_CLAY:15,30,STAINED_CLAY:7,30,quark:iron_plate:1,100)
RandomBlock(-5,12,-4,quark:iron_plate:1,70,STAINED_CLAY:15,30,STAINED_CLAY:7,30,quark:iron_plate:1,100)
RandomBlock(-5,13,-4,quark:iron_plate:1,70,STAINED_CLAY:15,30,STAINED_CLAY:7,30,quark:iron_plate:1,100)
RandomBlock(-5,14,-4,quark:iron_plate:1,70,STAINED_CLAY:15,30,STAINED_CLAY:7,30,quark:iron_plate:1,100)
RandomBlock(-5,15,-4,quark:iron_plate:1,70,STAINED_CLAY:15,30,STAINED_CLAY:7,30,quark:iron_plate:1,100)
Block(-4,0,-5,quark:limestone:0)
Block(-4,0,-4,quark:limestone:0)
Block(-4,0,-3,quark:limestone:0)
Block(-4,0,0,quark:limestone:0)
Block(-4,0,1,quark:limestone:0)
Block(-4,0,2,quark:limestone:0)
Block(-4,0,3,quark:limestone:0)
Block(-4,0,4,quark:limestone:0)
Block(-4,1,-5,COBBLESTONE_STAIRS:2)
Block(-4,1,-4,COBBLESTONE_STAIRS:1)
Block(-4,1,-3,COBBLESTONE_STAIRS:3)
Block(-4,1,0,COBBLESTONE_STAIRS:2)
Block(-4,1,1,COBBLESTONE_STAIRS:1)
Block(-4,1,2,COBBLESTONE_STAIRS:1)
Block(-4,1,3,COBBLESTONE_STAIRS:1)
Block(-4,1,4,COBBLESTONE_STAIRS:1)
Block(-4,3,1,COBBLESTONE_STAIRS:6)
RandomBlock(-4,3,2,quark:iron_plate:1,70,STAINED_CLAY:15,30,STAINED_CLAY:7,30,quark:iron_plate:1,100)
Block(-4,3,3,COBBLESTONE_STAIRS:7)
RandomBlock(-4,4,1,quark:iron_plate:1,70,STAINED_CLAY:15,30,STAINED_CLAY:7,30,quark:iron_plate:1,100)
Block(-4,4,2,srparasites:deadblood)
RandomBlock(-4,4,3,quark:iron_plate:1,70,STAINED_CLAY:15,30,STAINED_CLAY:7,30,quark:iron_plate:1,100)
Block(-4,5,1,COBBLESTONE_STAIRS:2)
RandomBlock(-4,5,2,quark:iron_plate:1,70,STAINED_CLAY:15,30,STAINED_CLAY:7,30,quark:iron_plate:1,100)
Block(-4,5,3,COBBLESTONE_STAIRS:3)
RandomBlock(-4,15,-4,quark:iron_plate:1,70,STAINED_CLAY:15,30,STAINED_CLAY:7,30,quark:iron_plate:1,100)
Block(-3,0,-6,quark:limestone:0)
Block(-3,0,-5,quark:limestone:0)
Block(-3,0,-4,quark:limestone:0)
Block(-3,0,-3,quark:limestone:0)
Block(-3,0,-2,quark:limestone:0)
Block(-3,1,-6,COBBLESTONE_STAIRS:2)
Block(-3,1,-5,COBBLESTONE_STAIRS:0)
Block(-3,1,-4,COBBLESTONE_STAIRS:0)
Block(-3,1,-3,COBBLESTONE_STAIRS:0)
Block(-3,1,-2,COBBLESTONE_STAIRS:3)
Block(-3,3,1,COBBLESTONE_STAIRS:6)
RandomBlock(-3,3,2,quark:iron_plate:1,70,STAINED_CLAY:15,30,STAINED_CLAY:7,30,quark:iron_plate:1,100)
Block(-3,3,3,COBBLESTONE_STAIRS:7)
RandomBlock(-3,4,1,quark:iron_plate:1,70,STAINED_CLAY:15,30,STAINED_CLAY:7,30,quark:iron_plate:1,100)
Block(-3,4,2,srparasites:deadblood)
RandomBlock(-3,4,3,quark:iron_plate:1,70,STAINED_CLAY:15,30,STAINED_CLAY:7,30,quark:iron_plate:1,100)
Block(-3,5,1,COBBLESTONE_STAIRS:2)
RandomBlock(-3,5,2,quark:iron_plate:1,70,STAINED_CLAY:15,30,STAINED_CLAY:7,30,quark:iron_plate:1,100)
Block(-3,5,3,COBBLESTONE_STAIRS:3)
RandomBlock(-3,15,-4,quark:iron_plate:1,70,STAINED_CLAY:15,30,STAINED_CLAY:7,30,quark:iron_plate:1,100)
Block(-2,0,-7,quark:limestone:0)
Block(-2,0,-6,quark:limestone:0)
Block(-2,0,-5,quark:world_stone_pavement:2)
Block(-2,0,-4,quark:world_stone_pavement:2)
Block(-2,0,-3,quark:world_stone_pavement:2)
Block(-2,0,-2,quark:limestone:0)
Block(-2,0,-1,quark:limestone:0)
Block(-2,1,-7,COBBLESTONE_STAIRS:2)
Block(-2,1,-6,COBBLESTONE_STAIRS:0)
Block(-2,1,-5,quark:world_stone_pavement:2)
RandomBlock(-2,1,-4,quark:iron_plate:1,70,STAINED_CLAY:15,30,STAINED_CLAY:7,30,quark:iron_plate:1,100)
Block(-2,1,-3,quark:world_stone_pavement:2)
Block(-2,1,-2,COBBLESTONE_STAIRS:0)
Block(-2,1,-1,COBBLESTONE_STAIRS:3)
Block(-2,2,-5,quark:world_stone_pavement:2)
Block(-2,2,-4,quark:framed_glass:0)
Block(-2,2,-3,quark:world_stone_pavement:2)
Block(-2,3,-5,quark:world_stone_pavement:2)
Block(-2,3,-4,quark:framed_glass:0)
Block(-2,3,-3,quark:world_stone_pavement:2)
Block(-2,3,1,COBBLESTONE_STAIRS:6)
RandomBlock(-2,3,2,quark:iron_plate:1,70,STAINED_CLAY:15,30,STAINED_CLAY:7,30,quark:iron_plate:1,100)
Block(-2,3,3,COBBLESTONE_STAIRS:7)
Block(-2,4,-5,quark:world_stone_pavement:2)
Block(-2,4,-4,quark:framed_glass:0)
Block(-2,4,-3,quark:world_stone_pavement:2)
RandomBlock(-2,4,1,quark:iron_plate:1,70,STAINED_CLAY:15,30,STAINED_CLAY:7,30,quark:iron_plate:1,100)
Block(-2,4,2,srparasites:deadblood)
RandomBlock(-2,4,3,quark:iron_plate:1,70,STAINED_CLAY:15,30,STAINED_CLAY:7,30,quark:iron_plate:1,100)
Block(-2,5,-5,quark:world_stone_pavement:2)
Block(-2,5,-4,quark:framed_glass:0)
Block(-2,5,-3,quark:world_stone_pavement:2)
Block(-2,5,1,COBBLESTONE_STAIRS:2)
RandomBlock(-2,5,2,quark:iron_plate:1,70,STAINED_CLAY:15,30,STAINED_CLAY:7,30,quark:iron_plate:1,100)
Block(-2,5,3,COBBLESTONE_STAIRS:3)
Block(-2,6,-5,quark:world_stone_pavement:2)
Block(-2,6,-4,quark:framed_glass:0)
Block(-2,6,-3,quark:world_stone_pavement:2)
Block(-2,7,-5,quark:world_stone_pavement:2)
Block(-2,7,-4,quark:framed_glass:0)
Block(-2,7,-3,quark:world_stone_pavement:2)
Block(-2,8,-5,quark:world_stone_pavement:2)
Block(-2,8,-4,quark:framed_glass:0)
Block(-2,8,-3,quark:world_stone_pavement:2)
Block(-2,9,-5,quark:world_stone_pavement:2)
Block(-2,9,-4,quark:framed_glass:0)
Block(-2,9,-3,quark:world_stone_pavement:2)
Block(-2,10,-5,quark:world_stone_pavement:2)
Block(-2,10,-4,quark:framed_glass:0)
Block(-2,10,-3,quark:world_stone_pavement:2)
Block(-2,11,-5,quark:world_stone_pavement:2)
Block(-2,11,-4,quark:framed_glass:0)
Block(-2,11,-3,quark:world_stone_pavement:2)
Block(-2,12,-5,quark:world_stone_pavement:2)
Block(-2,12,-4,quark:world_stone_pavement:2)
Block(-2,12,-3,quark:world_stone_pavement:2)
Block(-2,13,-5,COBBLESTONE_STAIRS:0)
Block(-2,13,-4,COBBLESTONE_STAIRS:0)
Block(-2,13,-3,COBBLESTONE_STAIRS:0)
RandomBlock(-2,15,-4,quark:iron_plate:1,70,STAINED_CLAY:15,30,STAINED_CLAY:7,30,quark:iron_plate:1,100)
Block(-1,0,-7,quark:limestone:0)
Block(-1,0,-6,quark:world_stone_pavement:2)
Block(-1,0,-5,quark:world_stone_pavement:2)
Block(-1,0,-4,quark:world_stone_pavement:2)
Block(-1,0,-3,quark:world_stone_pavement:2)
Block(-1,0,-2,quark:world_stone_pavement:2)
Block(-1,0,-1,quark:limestone:0)
Block(-1,1,-7,COBBLESTONE_STAIRS:2)
Block(-1,1,-6,quark:world_stone_pavement:2)
Block(-1,1,-5,srparasites:deadblood:1)
Block(-1,1,-4,srparasites:deadblood:1)
Block(-1,1,-3,srparasites:deadblood:1)
Block(-1,1,-2,quark:world_stone_pavement:2)
Block(-1,1,-1,COBBLESTONE_STAIRS:3)
Block(-1,2,-6,quark:world_stone_pavement:2)
Block(-1,2,-5,srparasites:deadblood:1)
Block(-1,2,-4,srparasites:deadblood:1)
Block(-1,2,-3,srparasites:deadblood:1)
Block(-1,2,-2,quark:world_stone_pavement:2)
Block(-1,3,-6,quark:world_stone_pavement:2)
Block(-1,3,-5,srparasites:deadblood:1)
Block(-1,3,-4,srparasites:deadblood:1)
Block(-1,3,-3,srparasites:deadblood:1)
Block(-1,3,-2,quark:world_stone_pavement:2)
Block(-1,3,1,COBBLESTONE_STAIRS:6)
RandomBlock(-1,3,2,quark:iron_plate:1,70,STAINED_CLAY:15,30,STAINED_CLAY:7,30,quark:iron_plate:1,100)
Block(-1,3,3,COBBLESTONE_STAIRS:7)
Block(-1,4,-6,quark:world_stone_pavement:2)
Block(-1,4,-5,srparasites:deadblood:1)
Block(-1,4,-4,srparasites:deadblood:1)
Block(-1,4,-3,srparasites:deadblood:1)
Block(-1,4,-2,quark:world_stone_pavement:2)
RandomBlock(-1,4,1,quark:iron_plate:1,70,STAINED_CLAY:15,30,STAINED_CLAY:7,30,quark:iron_plate:1,100)
Block(-1,4,2,srparasites:deadblood)
RandomBlock(-1,4,3,quark:iron_plate:1,70,STAINED_CLAY:15,30,STAINED_CLAY:7,30,quark:iron_plate:1,100)
Block(-1,5,-6,quark:world_stone_pavement:2)
Block(-1,5,-5,srparasites:deadblood:1)
Block(-1,5,-4,srparasites:deadblood:1)
Block(-1,5,-3,srparasites:deadblood:1)
Block(-1,5,-2,quark:world_stone_pavement:2)
Block(-1,5,1,COBBLESTONE_STAIRS:2)
RandomBlock(-1,5,2,quark:iron_plate:1,70,STAINED_CLAY:15,30,STAINED_CLAY:7,30,quark:iron_plate:1,100)
Block(-1,5,3,COBBLESTONE_STAIRS:3)
Block(-1,6,-6,quark:world_stone_pavement:2)
Block(-1,6,-5,srparasites:deadblood:1)
Block(-1,6,-4,srparasites:deadblood:1)
Block(-1,6,-3,srparasites:deadblood:1)
Block(-1,6,-2,quark:world_stone_pavement:2)
Block(-1,7,-6,quark:world_stone_pavement:2)
Block(-1,7,-5,srparasites:deadblood:1)
Block(-1,7,-4,srparasites:deadblood:1)
Block(-1,7,-3,srparasites:deadblood:1)
Block(-1,7,-2,quark:world_stone_pavement:2)
Block(-1,8,-6,quark:world_stone_pavement:2)
Block(-1,8,-5,srparasites:deadblood:1)
Block(-1,8,-4,srparasites:deadblood:1)
Block(-1,8,-3,srparasites:deadblood:1)
Block(-1,8,-2,quark:world_stone_pavement:2)
Block(-1,9,-6,quark:world_stone_pavement:2)
Block(-1,9,-5,srparasites:deadblood:1)
Block(-1,9,-4,srparasites:deadblood:1)
Block(-1,9,-3,srparasites:deadblood:1)
Block(-1,9,-2,quark:world_stone_pavement:2)
Block(-1,10,-6,quark:world_stone_pavement:2)
Block(-1,10,-5,srparasites:deadblood:1)
Block(-1,10,-4,srparasites:deadblood:1)
Block(-1,10,-3,srparasites:deadblood:1)
Block(-1,10,-2,quark:world_stone_pavement:2)
Block(-1,11,-6,quark:world_stone_pavement:2)
Block(-1,11,-5,srparasites:deadblood)
Block(-1,11,-4,srparasites:deadblood)
Block(-1,11,-3,srparasites:deadblood)
Block(-1,11,-2,quark:world_stone_pavement:2)
Block(-1,12,-6,quark:world_stone_pavement:2)
RandomBlock(-1,12,-5,quark:iron_plate:1,70,STAINED_CLAY:15,30,STAINED_CLAY:7,30,quark:iron_plate:1,100)
RandomBlock(-1,12,-4,quark:iron_plate:1,70,STAINED_CLAY:15,30,STAINED_CLAY:7,30,quark:iron_plate:1,100)
RandomBlock(-1,12,-3,quark:iron_plate:1,70,STAINED_CLAY:15,30,STAINED_CLAY:7,30,quark:iron_plate:1,100)
Block(-1,12,-2,quark:world_stone_pavement:2)
Block(-1,13,-6,COBBLESTONE_STAIRS:2)
RandomBlock(-1,13,-5,quark:iron_plate:1,70,STAINED_CLAY:15,30,STAINED_CLAY:7,30,quark:iron_plate:1,100)
RandomBlock(-1,13,-4,quark:iron_plate:1,70,STAINED_CLAY:15,30,STAINED_CLAY:7,30,quark:iron_plate:1,100)
RandomBlock(-1,13,-3,quark:iron_plate:1,70,STAINED_CLAY:15,30,STAINED_CLAY:7,30,quark:iron_plate:1,100)
Block(-1,13,-2,COBBLESTONE_STAIRS:3)
Block(-1,14,-5,IRON_FENCE:0)
Block(-1,14,-4,IRON_FENCE:0)
Block(-1,14,-3,IRON_FENCE:0)
RandomBlock(-1,15,-4,quark:iron_plate:1,70,STAINED_CLAY:15,30,STAINED_CLAY:7,30,quark:iron_plate:1,100)
Block(0,0,-7,quark:limestone:0)
Block(0,0,-6,quark:world_stone_pavement:2)
Block(0,0,-5,quark:world_stone_pavement:2)
Block(0,0,-4,quark:world_stone_pavement:2)
Block(0,0,-3,quark:world_stone_pavement:2)
Block(0,0,-2,quark:world_stone_pavement:2)
Block(0,0,-1,quark:limestone:0)
Block(0,1,-7,COBBLESTONE_STAIRS:2)
RandomBlock(0,1,-6,quark:iron_plate:1,70,STAINED_CLAY:15,30,STAINED_CLAY:7,30,quark:iron_plate:1,100)
Block(0,1,-5,srparasites:deadblood:1)
Block(0,1,-4,srparasites:deadblood:1)
Block(0,1,-3,srparasites:deadblood:1)
RandomBlock(0,1,-2,quark:iron_plate:1,70,STAINED_CLAY:15,30,STAINED_CLAY:7,30,quark:iron_plate:1,100)
Block(0,1,-1,COBBLESTONE_STAIRS:3)
Block(0,2,-6,quark:framed_glass:0)
Block(0,2,-5,srparasites:deadblood:1)
Block(0,2,-4,srparasites:deadblood:1)
Block(0,2,-3,srparasites:deadblood:1)
Block(0,2,-2,quark:framed_glass:0)
Block(0,3,-6,quark:framed_glass:0)
Block(0,3,-5,srparasites:deadblood:1)
Block(0,3,-4,srparasites:deadblood:1)
Block(0,3,-3,srparasites:deadblood:1)
Block(0,3,-2,quark:framed_glass:0)
Block(0,3,1,COBBLESTONE_STAIRS:6)
RandomBlock(0,3,2,quark:iron_plate:1,70,STAINED_CLAY:15,30,STAINED_CLAY:7,30,quark:iron_plate:1,100)
Block(0,3,3,COBBLESTONE_STAIRS:7)
Block(0,4,-6,quark:framed_glass:0)
Block(0,4,-5,srparasites:deadblood:1)
Block(0,4,-4,srparasites:deadblood:1)
Block(0,4,-3,srparasites:deadblood:1)
Block(0,4,-2,quark:framed_glass:0)
RandomBlock(0,4,1,quark:iron_plate:1,70,STAINED_CLAY:15,30,STAINED_CLAY:7,30,quark:iron_plate:1,100)
Block(0,4,2,srparasites:deadblood)
RandomBlock(0,4,3,quark:iron_plate:1,70,STAINED_CLAY:15,30,STAINED_CLAY:7,30,quark:iron_plate:1,100)
Block(0,5,-6,quark:framed_glass:0)
Block(0,5,-5,srparasites:deadblood:1)
Block(0,5,-4,srparasites:deadblood:1)
Block(0,5,-3,srparasites:deadblood:1)
Block(0,5,-2,quark:framed_glass:0)
Block(0,5,1,COBBLESTONE_STAIRS:2)
RandomBlock(0,5,2,quark:iron_plate:1,70,STAINED_CLAY:15,30,STAINED_CLAY:7,30,quark:iron_plate:1,100)
Block(0,5,3,COBBLESTONE_STAIRS:3)
Block(0,6,-6,quark:framed_glass:0)
Block(0,6,-5,srparasites:deadblood:1)
Block(0,6,-4,srparasites:deadblood:1)
Block(0,6,-3,srparasites:deadblood:1)
Block(0,6,-2,quark:framed_glass:0)
Block(0,7,-6,quark:framed_glass:0)
Block(0,7,-5,srparasites:deadblood:1)
Block(0,7,-4,srparasites:deadblood:1)
Block(0,7,-3,srparasites:deadblood:1)
Block(0,7,-2,quark:framed_glass:0)
Block(0,8,-6,quark:framed_glass:0)
Block(0,8,-5,srparasites:deadblood:1)
Block(0,8,-4,srparasites:deadblood:1)
Block(0,8,-3,srparasites:deadblood:1)
Block(0,8,-2,quark:framed_glass:0)
Block(0,9,-6,quark:framed_glass:0)
Block(0,9,-5,srparasites:deadblood:1)
Block(0,9,-4,srparasites:deadblood:1)
Block(0,9,-3,srparasites:deadblood:1)
Block(0,9,-2,quark:framed_glass:0)
Block(0,10,-6,quark:framed_glass:0)
Block(0,10,-5,srparasites:deadblood:1)
Block(0,10,-4,srparasites:deadblood:1)
Block(0,10,-3,srparasites:deadblood:1)
Block(0,10,-2,quark:framed_glass:0)
Block(0,11,-6,quark:framed_glass:0)
Block(0,11,-5,srparasites:deadblood)
Block(0,11,-4,srparasites:deadblood:1)
Block(0,11,-3,srparasites:deadblood)
Block(0,11,-2,quark:framed_glass:0)
Block(0,12,-6,quark:world_stone_pavement:2)
RandomBlock(0,12,-5,quark:iron_plate:1,70,STAINED_CLAY:15,30,STAINED_CLAY:7,30,quark:iron_plate:1,100)
RandomBlock(0,12,-4,quark:iron_plate:1,70,STAINED_CLAY:15,30,STAINED_CLAY:7,30,quark:iron_plate:1,100)
RandomBlock(0,12,-3,quark:iron_plate:1,70,STAINED_CLAY:15,30,STAINED_CLAY:7,30,quark:iron_plate:1,100)
Block(0,12,-2,quark:world_stone_pavement:2)
Block(0,13,-6,COBBLESTONE_STAIRS:2)
RandomBlock(0,13,-5,quark:iron_plate:1,70,STAINED_CLAY:15,30,STAINED_CLAY:7,30,quark:iron_plate:1,100)
RandomBlock(0,13,-4,quark:iron_plate:1,70,STAINED_CLAY:15,30,STAINED_CLAY:7,30,quark:iron_plate:1,100)
RandomBlock(0,13,-3,quark:iron_plate:1,70,STAINED_CLAY:15,30,STAINED_CLAY:7,30,quark:iron_plate:1,100)
Block(0,13,-2,COBBLESTONE_STAIRS:3)
Block(0,14,-5,IRON_FENCE:0)
RandomBlock(0,14,-4,quark:iron_plate:1,70,STAINED_CLAY:15,30,STAINED_CLAY:7,30,quark:iron_plate:1,100)
Block(0,14,-3,IRON_FENCE:0)
RandomBlock(0,15,-4,quark:iron_plate:1,70,STAINED_CLAY:15,30,STAINED_CLAY:7,30,quark:iron_plate:1,100)
Block(1,0,-7,quark:limestone:0)
Block(1,0,-6,quark:world_stone_pavement:2)
Block(1,0,-5,quark:world_stone_pavement:2)
Block(1,0,-4,quark:world_stone_pavement:2)
Block(1,0,-3,quark:world_stone_pavement:2)
Block(1,0,-2,quark:world_stone_pavement:2)
Block(1,0,-1,quark:limestone:0)
Block(1,1,-7,COBBLESTONE_STAIRS:2)
Block(1,1,-6,quark:world_stone_pavement:2)
Block(1,1,-5,srparasites:deadblood:1)
Block(1,1,-4,srparasites:deadblood:1)
Block(1,1,-3,srparasites:deadblood:1)
Block(1,1,-2,quark:world_stone_pavement:2)
Block(1,1,-1,COBBLESTONE_STAIRS:3)
Block(1,2,-6,quark:world_stone_pavement:2)
Block(1,2,-5,srparasites:deadblood:1)
Block(1,2,-4,srparasites:deadblood:1)
Block(1,2,-3,srparasites:deadblood:1)
Block(1,2,-2,quark:world_stone_pavement:2)
Block(1,3,-6,quark:world_stone_pavement:2)
Block(1,3,-5,srparasites:deadblood:1)
Block(1,3,-4,srparasites:deadblood:1)
Block(1,3,-3,srparasites:deadblood:1)
Block(1,3,-2,quark:world_stone_pavement:2)
Block(1,3,1,COBBLESTONE_STAIRS:6)
RandomBlock(1,3,2,quark:iron_plate:1,70,STAINED_CLAY:15,30,STAINED_CLAY:7,30,quark:iron_plate:1,100)
Block(1,3,3,COBBLESTONE_STAIRS:7)
Block(1,4,-6,quark:world_stone_pavement:2)
Block(1,4,-5,srparasites:deadblood:1)
Block(1,4,-4,srparasites:deadblood:1)
Block(1,4,-3,srparasites:deadblood:1)
Block(1,4,-2,quark:world_stone_pavement:2)
RandomBlock(1,4,1,quark:iron_plate:1,70,STAINED_CLAY:15,30,STAINED_CLAY:7,30,quark:iron_plate:1,100)
Block(1,4,2,srparasites:deadblood)
RandomBlock(1,4,3,quark:iron_plate:1,70,STAINED_CLAY:15,30,STAINED_CLAY:7,30,quark:iron_plate:1,100)
Block(1,5,-6,quark:world_stone_pavement:2)
Block(1,5,-5,srparasites:deadblood:1)
Block(1,5,-4,srparasites:deadblood:1)
Block(1,5,-3,srparasites:deadblood:1)
Block(1,5,-2,quark:world_stone_pavement:2)
Block(1,5,1,COBBLESTONE_STAIRS:2)
RandomBlock(1,5,2,quark:iron_plate:1,70,STAINED_CLAY:15,30,STAINED_CLAY:7,30,quark:iron_plate:1,100)
Block(1,5,3,COBBLESTONE_STAIRS:3)
Block(1,6,-6,quark:world_stone_pavement:2)
Block(1,6,-5,srparasites:deadblood:1)
Block(1,6,-4,srparasites:deadblood:1)
Block(1,6,-3,srparasites:deadblood:1)
Block(1,6,-2,quark:world_stone_pavement:2)
Block(1,7,-6,quark:world_stone_pavement:2)
Block(1,7,-5,srparasites:deadblood:1)
Block(1,7,-4,srparasites:deadblood:1)
Block(1,7,-3,srparasites:deadblood:1)
Block(1,7,-2,quark:world_stone_pavement:2)
Block(1,8,-6,quark:world_stone_pavement:2)
Block(1,8,-5,srparasites:deadblood:1)
Block(1,8,-4,srparasites:deadblood:1)
Block(1,8,-3,srparasites:deadblood:1)
Block(1,8,-2,quark:world_stone_pavement:2)
Block(1,9,-6,quark:world_stone_pavement:2)
Block(1,9,-5,srparasites:deadblood:1)
Block(1,9,-4,srparasites:deadblood:1)
Block(1,9,-3,srparasites:deadblood:1)
Block(1,9,-2,quark:world_stone_pavement:2)
Block(1,10,-6,quark:world_stone_pavement:2)
Block(1,10,-5,srparasites:deadblood:1)
Block(1,10,-4,srparasites:deadblood:1)
Block(1,10,-3,srparasites:deadblood:1)
Block(1,10,-2,quark:world_stone_pavement:2)
Block(1,11,-6,quark:world_stone_pavement:2)
Block(1,11,-5,srparasites:deadblood)
Block(1,11,-4,srparasites:deadblood)
Block(1,11,-3,srparasites:deadblood)
Block(1,11,-2,quark:world_stone_pavement:2)
Block(1,12,-6,quark:world_stone_pavement:2)
RandomBlock(1,12,-5,quark:iron_plate:1,70,STAINED_CLAY:15,30,STAINED_CLAY:7,30,quark:iron_plate:1,100)
RandomBlock(1,12,-4,quark:iron_plate:1,70,STAINED_CLAY:15,30,STAINED_CLAY:7,30,quark:iron_plate:1,100)
RandomBlock(1,12,-3,quark:iron_plate:1,70,STAINED_CLAY:15,30,STAINED_CLAY:7,30,quark:iron_plate:1,100)
Block(1,12,-2,quark:world_stone_pavement:2)
Block(1,13,-6,COBBLESTONE_STAIRS:2)
RandomBlock(1,13,-5,quark:iron_plate:1,70,STAINED_CLAY:15,30,STAINED_CLAY:7,30,quark:iron_plate:1,100)
RandomBlock(1,13,-4,quark:iron_plate:1,70,STAINED_CLAY:15,30,STAINED_CLAY:7,30,quark:iron_plate:1,100)
RandomBlock(1,13,-3,quark:iron_plate:1,70,STAINED_CLAY:15,30,STAINED_CLAY:7,30,quark:iron_plate:1,100)
Block(1,13,-2,COBBLESTONE_STAIRS:3)
Block(1,14,-5,IRON_FENCE:0)
Block(1,14,-4,IRON_FENCE:0)
Block(1,14,-3,IRON_FENCE:0)
Block(2,0,-7,quark:limestone:0)
Block(2,0,-6,quark:limestone:0)
Block(2,0,-5,quark:world_stone_pavement:2)
Block(2,0,-4,quark:world_stone_pavement:2)
Block(2,0,-3,quark:world_stone_pavement:2)
Block(2,0,-2,quark:limestone:0)
Block(2,0,-1,quark:limestone:0)
Block(2,1,-7,COBBLESTONE_STAIRS:1)
Block(2,1,-6,COBBLESTONE_STAIRS:2)
Block(2,1,-5,quark:world_stone_pavement:2)
RandomBlock(2,1,-4,quark:iron_plate:1,70,STAINED_CLAY:15,30,STAINED_CLAY:7,30,quark:iron_plate:1,100)
Block(2,1,-3,quark:world_stone_pavement:2)
Block(2,1,-2,COBBLESTONE_STAIRS:1)
Block(2,1,-1,COBBLESTONE_STAIRS:1)
Block(2,2,-5,quark:world_stone_pavement:2)
RandomBlock(2,2,-4,quark:iron_plate:1,70,STAINED_CLAY:15,30,STAINED_CLAY:7,30,quark:iron_plate:1,100)
Block(2,2,-3,quark:world_stone_pavement:2)
Block(2,3,-5,quark:world_stone_pavement:2)
RandomBlock(2,3,-4,quark:iron_plate:1,70,STAINED_CLAY:15,30,STAINED_CLAY:7,30,quark:iron_plate:1,100)
Block(2,3,-3,quark:world_stone_pavement:2)
Block(2,3,1,COBBLESTONE_STAIRS:6)
RandomBlock(2,3,2,quark:iron_plate:1,70,STAINED_CLAY:15,30,STAINED_CLAY:7,30,quark:iron_plate:1,100)
Block(2,3,3,COBBLESTONE_STAIRS:7)
Block(2,4,-5,quark:world_stone_pavement:2)
Block(2,4,-4,srparasites:deadblood)
Block(2,4,-3,quark:world_stone_pavement:2)
RandomBlock(2,4,1,quark:iron_plate:1,70,STAINED_CLAY:15,30,STAINED_CLAY:7,30,quark:iron_plate:1,100)
Block(2,4,2,srparasites:deadblood)
RandomBlock(2,4,3,quark:iron_plate:1,70,STAINED_CLAY:15,30,STAINED_CLAY:7,30,quark:iron_plate:1,100)
Block(2,5,-5,quark:world_stone_pavement:2)
RandomBlock(2,5,-4,quark:iron_plate:1,70,STAINED_CLAY:15,30,STAINED_CLAY:7,30,quark:iron_plate:1,100)
Block(2,5,-3,quark:world_stone_pavement:2)
Block(2,5,1,COBBLESTONE_STAIRS:2)
RandomBlock(2,5,2,quark:iron_plate:1,70,STAINED_CLAY:15,30,STAINED_CLAY:7,30,quark:iron_plate:1,100)
Block(2,5,3,COBBLESTONE_STAIRS:3)
Block(2,6,-5,quark:world_stone_pavement:2)
Block(2,6,-4,quark:world_stone_pavement:2)
Block(2,6,-3,quark:world_stone_pavement:2)
Block(2,7,-5,quark:world_stone_pavement:2)
Block(2,7,-4,quark:framed_glass:0)
Block(2,7,-3,quark:world_stone_pavement:2)
Block(2,8,-5,quark:world_stone_pavement:2)
Block(2,8,-4,quark:framed_glass:0)
Block(2,8,-3,quark:world_stone_pavement:2)
Block(2,9,-5,quark:world_stone_pavement:2)
Block(2,9,-4,quark:framed_glass:0)
Block(2,9,-3,quark:world_stone_pavement:2)
Block(2,10,-5,quark:world_stone_pavement:2)
Block(2,10,-4,quark:framed_glass:0)
Block(2,10,-3,quark:world_stone_pavement:2)
Block(2,11,-5,quark:world_stone_pavement:2)
Block(2,11,-4,quark:framed_glass:0)
Block(2,11,-3,quark:world_stone_pavement:2)
Block(2,12,-5,quark:world_stone_pavement:2)
Block(2,12,-4,quark:world_stone_pavement:2)
Block(2,12,-3,quark:world_stone_pavement:2)
Block(2,13,-5,COBBLESTONE_STAIRS:1)
Block(2,13,-4,COBBLESTONE_STAIRS:1)
Block(2,13,-3,COBBLESTONE_STAIRS:1)
Block(3,0,-6,quark:limestone:0)
Block(3,0,-5,quark:limestone:0)
Block(3,0,-4,quark:limestone:0)
Block(3,0,-3,quark:limestone:0)
Block(3,0,-2,quark:limestone:0)
Block(3,1,-6,COBBLESTONE_STAIRS:2)
Block(3,1,-5,COBBLESTONE_STAIRS:1)
Block(3,1,-4,COBBLESTONE_STAIRS:1)
Block(3,1,-3,COBBLESTONE_STAIRS:1)
Block(3,1,-2,COBBLESTONE_STAIRS:3)
RandomBlock(3,3,-5,quark:iron_plate:1,70,STAINED_CLAY:15,30,STAINED_CLAY:7,30,quark:iron_plate:1,100)
RandomBlock(3,3,-4,quark:iron_plate:1,70,STAINED_CLAY:15,30,STAINED_CLAY:7,30,quark:iron_plate:1,100)
RandomBlock(3,3,-3,quark:iron_plate:1,70,STAINED_CLAY:15,30,STAINED_CLAY:7,30,quark:iron_plate:1,100)
Block(3,3,1,COBBLESTONE_STAIRS:6)
RandomBlock(3,3,2,quark:iron_plate:1,70,STAINED_CLAY:15,30,STAINED_CLAY:7,30,quark:iron_plate:1,100)
Block(3,3,3,COBBLESTONE_STAIRS:7)
RandomBlock(3,4,-5,quark:iron_plate:1,70,STAINED_CLAY:15,30,STAINED_CLAY:7,30,quark:iron_plate:1,100)
Block(3,4,-4,srparasites:deadblood)
RandomBlock(3,4,-3,quark:iron_plate:1,70,STAINED_CLAY:15,30,STAINED_CLAY:7,30,quark:iron_plate:1,100)
RandomBlock(3,4,1,quark:iron_plate:1,70,STAINED_CLAY:15,30,STAINED_CLAY:7,30,quark:iron_plate:1,100)
Block(3,4,2,srparasites:deadblood)
RandomBlock(3,4,3,quark:iron_plate:1,70,STAINED_CLAY:15,30,STAINED_CLAY:7,30,quark:iron_plate:1,100)
RandomBlock(3,5,-5,quark:iron_plate:1,70,STAINED_CLAY:15,30,STAINED_CLAY:7,30,quark:iron_plate:1,100)
RandomBlock(3,5,-4,quark:iron_plate:1,70,STAINED_CLAY:15,30,STAINED_CLAY:7,30,quark:iron_plate:1,100)
RandomBlock(3,5,-3,quark:iron_plate:1,70,STAINED_CLAY:15,30,STAINED_CLAY:7,30,quark:iron_plate:1,100)
Block(3,5,1,COBBLESTONE_STAIRS:2)
RandomBlock(3,5,2,IRON_FENCE:0,30,IRON_FENCE:0,30,LEAVES:7,30,quark:iron_plate_stairs:6,10,quark:iron_plate_stairs:0,10,quark:iron_plate_stairs:5,10,quark:iron_plate_stairs:3,10,quark:iron_plate_slab:8,10,quark:iron_plate_stairs:7,10,quark:iron_plate_stairs:1,10,quark:iron_plate_slab:0,10,quark:iron_plate_stairs:4,10,quark:iron_plate_stairs:2,10,IRON_FENCE:0,50,IRON_FENCE:0,50,LEAVES:7,100)
Block(3,5,3,COBBLESTONE_STAIRS:3)
Block(4,3,-5,COBBLESTONE_STAIRS:6)
RandomBlock(4,3,-4,quark:iron_plate:1,70,STAINED_CLAY:15,30,STAINED_CLAY:7,30,quark:iron_plate:1,100)
Block(4,3,-3,COBBLESTONE_STAIRS:7)
Block(4,3,1,COBBLESTONE_STAIRS:6)
RandomBlock(4,3,2,quark:iron_plate:1,70,STAINED_CLAY:15,30,STAINED_CLAY:7,30,quark:iron_plate:1,100)
Block(4,3,3,COBBLESTONE_STAIRS:7)
RandomBlock(4,4,-5,quark:iron_plate:1,70,STAINED_CLAY:15,30,STAINED_CLAY:7,30,quark:iron_plate:1,100)
Block(4,4,-4,srparasites:deadblood)
RandomBlock(4,4,-3,quark:iron_plate:1,70,STAINED_CLAY:15,30,STAINED_CLAY:7,30,quark:iron_plate:1,100)
RandomBlock(4,4,1,quark:iron_plate:1,70,STAINED_CLAY:15,30,STAINED_CLAY:7,30,quark:iron_plate:1,100)
Block(4,4,2,srparasites:deadblood)
RandomBlock(4,4,3,quark:iron_plate:1,70,STAINED_CLAY:15,30,STAINED_CLAY:7,30,quark:iron_plate:1,100)
Block(4,5,-5,COBBLESTONE_STAIRS:2)
RandomBlock(4,5,-4,quark:iron_plate:1,70,STAINED_CLAY:15,30,STAINED_CLAY:7,30,quark:iron_plate:1,100)
Block(4,5,-3,COBBLESTONE_STAIRS:3)
Block(4,5,1,COBBLESTONE_STAIRS:2)
RandomBlock(4,5,2,IRON_FENCE:0,30,IRON_FENCE:0,30,LEAVES:7,30,quark:iron_plate_stairs:6,10,quark:iron_plate_stairs:0,10,quark:iron_plate_stairs:5,10,quark:iron_plate_stairs:3,10,quark:iron_plate_slab:8,10,quark:iron_plate_stairs:7,10,quark:iron_plate_stairs:1,10,quark:iron_plate_slab:0,10,quark:iron_plate_stairs:4,10,quark:iron_plate_stairs:2,10,IRON_FENCE:0,50,IRON_FENCE:0,50,LEAVES:7,100)
Block(4,5,3,COBBLESTONE_STAIRS:3)
Block(5,3,-5,COBBLESTONE_STAIRS:6)
RandomBlock(5,3,-4,quark:iron_plate:1,70,STAINED_CLAY:15,30,STAINED_CLAY:7,30,quark:iron_plate:1,100)
Block(5,3,-3,COBBLESTONE_STAIRS:7)
Block(5,3,1,COBBLESTONE_STAIRS:6)
RandomBlock(5,3,2,quark:iron_plate:1,70,STAINED_CLAY:15,30,STAINED_CLAY:7,30,quark:iron_plate:1,100)
Block(5,3,3,COBBLESTONE_STAIRS:7)
RandomBlock(5,4,-5,quark:iron_plate:1,70,STAINED_CLAY:15,30,STAINED_CLAY:7,30,quark:iron_plate:1,100)
Block(5,4,-4,srparasites:deadblood)
RandomBlock(5,4,-3,quark:iron_plate:1,70,STAINED_CLAY:15,30,STAINED_CLAY:7,30,quark:iron_plate:1,100)
RandomBlock(5,4,1,quark:iron_plate:1,70,STAINED_CLAY:15,30,STAINED_CLAY:7,30,quark:iron_plate:1,100)
Block(5,4,2,srparasites:deadblood)
RandomBlock(5,4,3,quark:iron_plate:1,70,STAINED_CLAY:15,30,STAINED_CLAY:7,30,quark:iron_plate:1,100)
Block(5,5,-5,COBBLESTONE_STAIRS:2)
RandomBlock(5,5,-4,quark:iron_plate:1,70,STAINED_CLAY:15,30,STAINED_CLAY:7,30,quark:iron_plate:1,100)
Block(5,5,-3,COBBLESTONE_STAIRS:3)
Block(5,5,1,COBBLESTONE_STAIRS:2)
RandomBlock(5,5,2,IRON_FENCE:0,30,IRON_FENCE:0,30,LEAVES:7,30,quark:iron_plate_stairs:6,10,quark:iron_plate_stairs:0,10,quark:iron_plate_stairs:5,10,quark:iron_plate_stairs:3,10,quark:iron_plate_slab:8,10,quark:iron_plate_stairs:7,10,quark:iron_plate_stairs:1,10,quark:iron_plate_slab:0,10,quark:iron_plate_stairs:4,10,quark:iron_plate_stairs:2,10,IRON_FENCE:0,50,IRON_FENCE:0,50,LEAVES:7,100)
Block(5,5,3,COBBLESTONE_STAIRS:3)
Block(6,3,-5,COBBLESTONE_STAIRS:6)
RandomBlock(6,3,-4,quark:iron_plate:1,70,STAINED_CLAY:15,30,STAINED_CLAY:7,30,quark:iron_plate:1,100)
Block(6,3,-3,COBBLESTONE_STAIRS:7)
Block(6,3,1,COBBLESTONE_STAIRS:6)
RandomBlock(6,3,2,quark:iron_plate:1,70,STAINED_CLAY:15,30,STAINED_CLAY:7,30,quark:iron_plate:1,100)
Block(6,3,3,COBBLESTONE_STAIRS:7)
RandomBlock(6,4,-5,quark:iron_plate:1,70,STAINED_CLAY:15,30,STAINED_CLAY:7,30,quark:iron_plate:1,100)
Block(6,4,-4,srparasites:deadblood)
RandomBlock(6,4,-3,quark:iron_plate:1,70,STAINED_CLAY:15,30,STAINED_CLAY:7,30,quark:iron_plate:1,100)
RandomBlock(6,4,1,quark:iron_plate:1,70,STAINED_CLAY:15,30,STAINED_CLAY:7,30,quark:iron_plate:1,100)
Block(6,4,2,srparasites:deadblood)
RandomBlock(6,4,3,quark:iron_plate:1,70,STAINED_CLAY:15,30,STAINED_CLAY:7,30,quark:iron_plate:1,100)
Block(6,5,-5,COBBLESTONE_STAIRS:2)
RandomBlock(6,5,-4,quark:iron_plate:1,70,STAINED_CLAY:15,30,STAINED_CLAY:7,30,quark:iron_plate:1,100)
Block(6,5,-3,COBBLESTONE_STAIRS:3)
Block(6,5,1,COBBLESTONE_STAIRS:2)
RandomBlock(6,5,2,quark:iron_plate:1,70,STAINED_CLAY:15,30,STAINED_CLAY:7,30,quark:iron_plate:1,100)
Block(6,5,3,COBBLESTONE_STAIRS:3)
Block(7,3,-5,COBBLESTONE_STAIRS:6)
RandomBlock(7,3,-4,quark:iron_plate:1,70,STAINED_CLAY:15,30,STAINED_CLAY:7,30,quark:iron_plate:1,100)
Block(7,3,-3,COBBLESTONE_STAIRS:7)
Block(7,3,-2,COBBLESTONE_STAIRS:4)
Block(7,3,-1,COBBLESTONE_STAIRS:4)
Block(7,3,0,COBBLESTONE_STAIRS:4)
Block(7,3,1,COBBLESTONE_STAIRS:4)
RandomBlock(7,3,2,quark:iron_plate:1,70,STAINED_CLAY:15,30,STAINED_CLAY:7,30,quark:iron_plate:1,100)
Block(7,3,3,COBBLESTONE_STAIRS:7)
RandomBlock(7,4,-5,quark:iron_plate:1,70,STAINED_CLAY:15,30,STAINED_CLAY:7,30,quark:iron_plate:1,100)
Block(7,4,-4,srparasites:deadblood)
RandomBlock(7,4,-3,quark:iron_plate:1,70,STAINED_CLAY:15,30,STAINED_CLAY:7,30,quark:iron_plate:1,100)
RandomBlock(7,4,-2,quark:iron_plate:1,70,STAINED_CLAY:15,30,STAINED_CLAY:7,30,quark:iron_plate:1,100)
RandomBlock(7,4,-1,quark:iron_plate:1,70,STAINED_CLAY:15,30,STAINED_CLAY:7,30,quark:iron_plate:1,100)
RandomBlock(7,4,0,quark:iron_plate:1,70,STAINED_CLAY:15,30,STAINED_CLAY:7,30,quark:iron_plate:1,100)
RandomBlock(7,4,1,quark:iron_plate:1,70,STAINED_CLAY:15,30,STAINED_CLAY:7,30,quark:iron_plate:1,100)
Block(7,4,2,srparasites:deadblood)
RandomBlock(7,4,3,quark:iron_plate:1,70,STAINED_CLAY:15,30,STAINED_CLAY:7,30,quark:iron_plate:1,100)
Block(7,5,-5,COBBLESTONE_STAIRS:2)
RandomBlock(7,5,-4,quark:iron_plate:1,70,STAINED_CLAY:15,30,STAINED_CLAY:7,30,quark:iron_plate:1,100)
Block(7,5,-3,COBBLESTONE_STAIRS:0)
Block(7,5,-2,COBBLESTONE_STAIRS:0)
Block(7,5,-1,COBBLESTONE_STAIRS:0)
Block(7,5,0,COBBLESTONE_STAIRS:0)
Block(7,5,1,COBBLESTONE_STAIRS:2)
RandomBlock(7,5,2,quark:iron_plate:1,70,STAINED_CLAY:15,30,STAINED_CLAY:7,30,quark:iron_plate:1,100)
Block(7,5,3,COBBLESTONE_STAIRS:3)

#######################################################################
# +-----------------------------------------------------------------+ #
# |                             Branches                            | #
# +-----------------------------------------------------------------+ #
#######################################################################

Branch(16,0,0,true,brutal_pipesmall_01C1R0,NORTH,100.0,0)

#######################################################################
# +-----------------------------------------------------------------+ #
# |                             Entities                            | #
# +-----------------------------------------------------------------+ #
#######################################################################


#######################################################################
# +-----------------------------------------------------------------+ #
# |                            Particles                            | #
# +-----------------------------------------------------------------+ #
#######################################################################


#######################################################################
# +-----------------------------------------------------------------+ #
# |                             Spawners                            | #
# +-----------------------------------------------------------------+ #
#######################################################################


#######################################################################
# +-----------------------------------------------------------------+ #
# |                             ModData                             | #
# +-----------------------------------------------------------------+ #
#######################################################################

