
#######################################################################
# +-----------------------------------------------------------------+ #
# |                            BO4 object                           | #
# +-----------------------------------------------------------------+ #
#######################################################################

Author: NLBlackEagle

Description: No description given

SettingsMode: WriteWithoutComments


#######################################################################
# +-----------------------------------------------------------------+ #
# |                          Main settings                          | #
# +-----------------------------------------------------------------+ #
#######################################################################

FixedRotation: 

Frequency: 0

SpawnHeight: randomY

UseCenterForHighestBlock: true

##############################
# Height Limits for the BO4. #
##############################

MinHeight: 1

MaxHeight: 1

InheritBO3: 

InheritBO3Rotation: NORTH

OverrideChildSettings: true

OverrideParentHeight: true

CanOverride: true

BranchFrequency: 0

BranchFrequencyGroup: 

MustBeBelowOther: false

MustBeInside: 

CannotBeInside: 

ReplacesBO3: 

MustBeInsideWorldBorders: true
CanSpawnOnWater: true

SpawnOnWaterOnly: false

SpawnUnderWater: false

SpawnAtWaterLevel: false

HeightOffset: 0

RemoveAir: false

ReplaceAbove: 

ReplaceBelow: 

ReplaceWithBiomeBlocks: true

ReplaceWithSurfaceBlock: GRASS

ReplaceWithGroundBlock: DIRT

ReplaceWithStoneBlock: STONE

SmoothRadius: 0

SmoothHeightOffset: 0

SmoothStartTop: false

SmoothStartWood: false

SmoothingSurfaceBlock: 

SmoothingGroundBlock: 

BO3Group: 

IsSpawnPoint: false

DoReplaceBlocks: false


#######################################################################
# +-----------------------------------------------------------------+ #
# |                              Blocks                             | #
# +-----------------------------------------------------------------+ #
#######################################################################

RandomBlock(1,0,4,quark:iron_plate:1,70,STAINED_CLAY:15,30,STAINED_CLAY:7,30,STAINED_CLAY:8,30,quark:iron_plate:1,100)
RandomBlock(1,0,5,quark:iron_plate:1,70,STAINED_CLAY:15,30,STAINED_CLAY:7,30,STAINED_CLAY:8,30,quark:iron_plate:1,100)
RandomBlock(1,0,6,quark:iron_plate:1,70,STAINED_CLAY:15,30,STAINED_CLAY:7,30,STAINED_CLAY:8,30,quark:iron_plate:1,100)
RandomBlock(1,1,4,quark:iron_plate:1,70,STAINED_CLAY:15,30,STAINED_CLAY:7,30,STAINED_CLAY:8,30,quark:iron_plate:1,100)
RandomBlock(1,1,5,quark:iron_plate:1,70,STAINED_CLAY:15,30,STAINED_CLAY:7,30,STAINED_CLAY:8,30,quark:iron_plate:1,100)
RandomBlock(1,1,6,quark:iron_plate:1,70,STAINED_CLAY:15,30,STAINED_CLAY:7,30,STAINED_CLAY:8,30,quark:iron_plate:1,100)
RandomBlock(1,2,4,quark:iron_plate:1,70,STAINED_CLAY:15,30,STAINED_CLAY:7,30,STAINED_CLAY:8,30,quark:iron_plate:1,100)
RandomBlock(1,2,5,quark:iron_plate:1,70,STAINED_CLAY:15,30,STAINED_CLAY:7,30,STAINED_CLAY:8,30,quark:iron_plate:1,100)
RandomBlock(1,2,6,quark:iron_plate:1,70,STAINED_CLAY:15,30,STAINED_CLAY:7,30,STAINED_CLAY:8,30,quark:iron_plate:1,100)
RandomBlock(1,3,4,quark:iron_plate:1,70,STAINED_CLAY:15,30,STAINED_CLAY:7,30,STAINED_CLAY:8,30,quark:iron_plate:1,100)
RandomBlock(1,3,5,quark:iron_plate:1,70,STAINED_CLAY:15,30,STAINED_CLAY:7,30,STAINED_CLAY:8,30,quark:iron_plate:1,100)
RandomBlock(1,3,6,quark:iron_plate:1,70,STAINED_CLAY:15,30,STAINED_CLAY:7,30,STAINED_CLAY:8,30,quark:iron_plate:1,100)
RandomBlock(1,4,4,quark:iron_plate:1,70,STAINED_CLAY:15,30,STAINED_CLAY:7,30,STAINED_CLAY:8,30,quark:iron_plate:1,100)
RandomBlock(1,4,5,quark:iron_plate:1,70,STAINED_CLAY:15,30,STAINED_CLAY:7,30,STAINED_CLAY:8,30,quark:iron_plate:1,100)
RandomBlock(1,4,6,minecraft:iron_bars,30,minecraft:iron_bars,30,minecraft:leaves2:1,30,quark:iron_plate_stairs:6,10,quark:iron_plate_stairs:0,10,quark:iron_plate_stairs:5,10,quark:iron_plate_stairs,10,quark:iron_plate_slab:8,10,quark:iron_plate_stairs:7,10,quark:iron_plate_stairs:1,10,quark:iron_plate_slab,10,quark:iron_plate_stairs:4,10,quark:iron_plate_stairs:2,10,minecraft:iron_bars,50,minecraft:iron_bars,50,minecraft:leaves2:1,100)
RandomBlock(1,5,4,quark:iron_plate:1,70,STAINED_CLAY:15,30,STAINED_CLAY:7,30,STAINED_CLAY:8,30,quark:iron_plate:1,100)
RandomBlock(1,5,5,minecraft:iron_bars,30,minecraft:iron_bars,30,minecraft:leaves2:1,30,quark:iron_plate_stairs:6,10,quark:iron_plate_stairs:0,10,quark:iron_plate_stairs:5,10,quark:iron_plate_stairs,10,quark:iron_plate_slab:8,10,quark:iron_plate_stairs:7,10,quark:iron_plate_stairs:1,10,quark:iron_plate_slab,10,quark:iron_plate_stairs:4,10,quark:iron_plate_stairs:2,10,minecraft:iron_bars,50,minecraft:iron_bars,50,minecraft:leaves2:1,100)
RandomBlock(1,5,6,minecraft:iron_bars,30,minecraft:iron_bars,30,minecraft:leaves2:1,30,quark:iron_plate_stairs:6,10,quark:iron_plate_stairs:0,10,quark:iron_plate_stairs:5,10,quark:iron_plate_stairs,10,quark:iron_plate_slab:8,10,quark:iron_plate_stairs:7,10,quark:iron_plate_stairs:1,10,quark:iron_plate_slab,10,quark:iron_plate_stairs:4,10,quark:iron_plate_stairs:2,10,minecraft:iron_bars,50,minecraft:iron_bars,50,minecraft:leaves2:1,100)
RandomBlock(1,6,4,quark:iron_plate:1,70,STAINED_CLAY:15,30,STAINED_CLAY:7,30,STAINED_CLAY:8,30,quark:iron_plate:1,100)
RandomBlock(1,6,5,quark:iron_plate:1,70,STAINED_CLAY:15,30,STAINED_CLAY:7,30,STAINED_CLAY:8,30,quark:iron_plate:1,100)
RandomBlock(1,6,6,minecraft:iron_bars,30,minecraft:iron_bars,30,minecraft:leaves2:1,30,quark:iron_plate_stairs:6,10,quark:iron_plate_stairs:0,10,quark:iron_plate_stairs:5,10,quark:iron_plate_stairs,10,quark:iron_plate_slab:8,10,quark:iron_plate_stairs:7,10,quark:iron_plate_stairs:1,10,quark:iron_plate_slab,10,quark:iron_plate_stairs:4,10,quark:iron_plate_stairs:2,10,minecraft:iron_bars,50,minecraft:iron_bars,50,minecraft:leaves2:1,100)
RandomBlock(1,7,4,minecraft:iron_bars,30,minecraft:iron_bars,30,minecraft:leaves2:1,30,quark:iron_plate_stairs:6,10,quark:iron_plate_stairs:0,10,quark:iron_plate_stairs:5,10,quark:iron_plate_stairs,10,quark:iron_plate_slab:8,10,quark:iron_plate_stairs:7,10,quark:iron_plate_stairs:1,10,quark:iron_plate_slab,10,quark:iron_plate_stairs:4,10,quark:iron_plate_stairs:2,10,minecraft:iron_bars,50,minecraft:iron_bars,50,minecraft:leaves2:1,100)
RandomBlock(1,7,5,minecraft:iron_bars,30,minecraft:iron_bars,30,minecraft:leaves2:1,30,quark:iron_plate_stairs:6,10,quark:iron_plate_stairs:0,10,quark:iron_plate_stairs:5,10,quark:iron_plate_stairs,10,quark:iron_plate_slab:8,10,quark:iron_plate_stairs:7,10,quark:iron_plate_stairs:1,10,quark:iron_plate_slab,10,quark:iron_plate_stairs:4,10,quark:iron_plate_stairs:2,10,minecraft:iron_bars,50,minecraft:iron_bars,50,minecraft:leaves2:1,100)
RandomBlock(1,7,6,minecraft:iron_bars,30,minecraft:iron_bars,30,minecraft:leaves2:1,30,quark:iron_plate_stairs:6,10,quark:iron_plate_stairs:0,10,quark:iron_plate_stairs:5,10,quark:iron_plate_stairs,10,quark:iron_plate_slab:8,10,quark:iron_plate_stairs:7,10,quark:iron_plate_stairs:1,10,quark:iron_plate_slab,10,quark:iron_plate_stairs:4,10,quark:iron_plate_stairs:2,10,minecraft:iron_bars,50,minecraft:iron_bars,50,minecraft:leaves2:1,100)
RandomBlock(1,8,4,quark:iron_plate:1,70,STAINED_CLAY:15,30,STAINED_CLAY:7,30,STAINED_CLAY:8,30,quark:iron_plate:1,100)
RandomBlock(1,8,5,minecraft:iron_bars,30,minecraft:iron_bars,30,minecraft:leaves2:1,30,quark:iron_plate_stairs:6,10,quark:iron_plate_stairs:0,10,quark:iron_plate_stairs:5,10,quark:iron_plate_stairs,10,quark:iron_plate_slab:8,10,quark:iron_plate_stairs:7,10,quark:iron_plate_stairs:1,10,quark:iron_plate_slab,10,quark:iron_plate_stairs:4,10,quark:iron_plate_stairs:2,10,minecraft:iron_bars,50,minecraft:iron_bars,50,minecraft:leaves2:1,100)
RandomBlock(1,8,6,minecraft:iron_bars,30,minecraft:iron_bars,30,minecraft:leaves2:1,30,quark:iron_plate_stairs:6,10,quark:iron_plate_stairs:0,10,quark:iron_plate_stairs:5,10,quark:iron_plate_stairs,10,quark:iron_plate_slab:8,10,quark:iron_plate_stairs:7,10,quark:iron_plate_stairs:1,10,quark:iron_plate_slab,10,quark:iron_plate_stairs:4,10,quark:iron_plate_stairs:2,10,minecraft:iron_bars,50,minecraft:iron_bars,50,minecraft:leaves2:1,100)
RandomBlock(1,9,4,minecraft:iron_bars,30,minecraft:iron_bars,30,minecraft:leaves2:1,30,quark:iron_plate_stairs:6,10,quark:iron_plate_stairs:0,10,quark:iron_plate_stairs:5,10,quark:iron_plate_stairs,10,quark:iron_plate_slab:8,10,quark:iron_plate_stairs:7,10,quark:iron_plate_stairs:1,10,quark:iron_plate_slab,10,quark:iron_plate_stairs:4,10,quark:iron_plate_stairs:2,10,minecraft:iron_bars,50,minecraft:iron_bars,50,minecraft:leaves2:1,100)
RandomBlock(1,9,5,minecraft:iron_bars,30,minecraft:iron_bars,30,minecraft:leaves2:1,30,quark:iron_plate_stairs:6,10,quark:iron_plate_stairs:0,10,quark:iron_plate_stairs:5,10,quark:iron_plate_stairs,10,quark:iron_plate_slab:8,10,quark:iron_plate_stairs:7,10,quark:iron_plate_stairs:1,10,quark:iron_plate_slab,10,quark:iron_plate_stairs:4,10,quark:iron_plate_stairs:2,10,minecraft:iron_bars,50,minecraft:iron_bars,50,minecraft:leaves2:1,100)
RandomBlock(1,9,6,minecraft:iron_bars,30,minecraft:iron_bars,30,minecraft:leaves2:1,30,quark:iron_plate_stairs:6,10,quark:iron_plate_stairs:0,10,quark:iron_plate_stairs:5,10,quark:iron_plate_stairs,10,quark:iron_plate_slab:8,10,quark:iron_plate_stairs:7,10,quark:iron_plate_stairs:1,10,quark:iron_plate_slab,10,quark:iron_plate_stairs:4,10,quark:iron_plate_stairs:2,10,minecraft:iron_bars,50,minecraft:iron_bars,50,minecraft:leaves2:1,100)
RandomBlock(1,10,4,quark:iron_plate:1,70,STAINED_CLAY:15,30,STAINED_CLAY:7,30,STAINED_CLAY:8,30,quark:iron_plate:1,100)
RandomBlock(1,10,5,quark:iron_plate:1,70,STAINED_CLAY:15,30,STAINED_CLAY:7,30,STAINED_CLAY:8,30,quark:iron_plate:1,100)
RandomBlock(1,10,6,minecraft:iron_bars,30,minecraft:iron_bars,30,minecraft:leaves2:1,30,quark:iron_plate_stairs:6,10,quark:iron_plate_stairs:0,10,quark:iron_plate_stairs:5,10,quark:iron_plate_stairs,10,quark:iron_plate_slab:8,10,quark:iron_plate_stairs:7,10,quark:iron_plate_stairs:1,10,quark:iron_plate_slab,10,quark:iron_plate_stairs:4,10,quark:iron_plate_stairs:2,10,minecraft:iron_bars,50,minecraft:iron_bars,50,minecraft:leaves2:1,100)
RandomBlock(1,11,4,quark:iron_plate:1,70,STAINED_CLAY:15,30,STAINED_CLAY:7,30,STAINED_CLAY:8,30,quark:iron_plate:1,100)
RandomBlock(1,11,5,quark:iron_plate:1,70,STAINED_CLAY:15,30,STAINED_CLAY:7,30,STAINED_CLAY:8,30,quark:iron_plate:1,100)
RandomBlock(1,11,6,quark:iron_plate:1,70,STAINED_CLAY:15,30,STAINED_CLAY:7,30,STAINED_CLAY:8,30,quark:iron_plate:1,100)
RandomBlock(1,12,4,minecraft:iron_bars,30,minecraft:iron_bars,30,minecraft:leaves2:1,30,quark:iron_plate_stairs:6,10,quark:iron_plate_stairs:0,10,quark:iron_plate_stairs:5,10,quark:iron_plate_stairs,10,quark:iron_plate_slab:8,10,quark:iron_plate_stairs:7,10,quark:iron_plate_stairs:1,10,quark:iron_plate_slab,10,quark:iron_plate_stairs:4,10,quark:iron_plate_stairs:2,10,minecraft:iron_bars,50,minecraft:iron_bars,50,minecraft:leaves2:1,100)
RandomBlock(1,12,5,quark:iron_plate:1,70,STAINED_CLAY:15,30,STAINED_CLAY:7,30,STAINED_CLAY:8,30,quark:iron_plate:1,100)
RandomBlock(1,12,6,quark:iron_plate:1,70,STAINED_CLAY:15,30,STAINED_CLAY:7,30,STAINED_CLAY:8,30,quark:iron_plate:1,100)
RandomBlock(1,13,4,minecraft:iron_bars,30,minecraft:iron_bars,30,minecraft:leaves2:1,30,quark:iron_plate_stairs:6,10,quark:iron_plate_stairs:0,10,quark:iron_plate_stairs:5,10,quark:iron_plate_stairs,10,quark:iron_plate_slab:8,10,quark:iron_plate_stairs:7,10,quark:iron_plate_stairs:1,10,quark:iron_plate_slab,10,quark:iron_plate_stairs:4,10,quark:iron_plate_stairs:2,10,minecraft:iron_bars,50,minecraft:iron_bars,50,minecraft:leaves2:1,100)
RandomBlock(1,13,5,minecraft:iron_bars,30,minecraft:iron_bars,30,minecraft:leaves2:1,30,quark:iron_plate_stairs:6,10,quark:iron_plate_stairs:0,10,quark:iron_plate_stairs:5,10,quark:iron_plate_stairs,10,quark:iron_plate_slab:8,10,quark:iron_plate_stairs:7,10,quark:iron_plate_stairs:1,10,quark:iron_plate_slab,10,quark:iron_plate_stairs:4,10,quark:iron_plate_stairs:2,10,minecraft:iron_bars,50,minecraft:iron_bars,50,minecraft:leaves2:1,100)
RandomBlock(1,13,6,quark:iron_plate:1,70,STAINED_CLAY:15,30,STAINED_CLAY:7,30,STAINED_CLAY:8,30,quark:iron_plate:1,100)
RandomBlock(1,14,4,minecraft:iron_bars,30,minecraft:iron_bars,30,minecraft:leaves2:1,30,quark:iron_plate_stairs:6,10,quark:iron_plate_stairs:0,10,quark:iron_plate_stairs:5,10,quark:iron_plate_stairs,10,quark:iron_plate_slab:8,10,quark:iron_plate_stairs:7,10,quark:iron_plate_stairs:1,10,quark:iron_plate_slab,10,quark:iron_plate_stairs:4,10,quark:iron_plate_stairs:2,10,minecraft:iron_bars,50,minecraft:iron_bars,50,minecraft:leaves2:1,100)
RandomBlock(1,14,5,quark:iron_plate:1,70,STAINED_CLAY:15,30,STAINED_CLAY:7,30,STAINED_CLAY:8,30,quark:iron_plate:1,100)
RandomBlock(1,14,6,quark:iron_plate:1,70,STAINED_CLAY:15,30,STAINED_CLAY:7,30,STAINED_CLAY:8,30,quark:iron_plate:1,100)
RandomBlock(1,15,4,minecraft:iron_bars,30,minecraft:iron_bars,30,minecraft:leaves2:1,30,quark:iron_plate_stairs:6,10,quark:iron_plate_stairs:0,10,quark:iron_plate_stairs:5,10,quark:iron_plate_stairs,10,quark:iron_plate_slab:8,10,quark:iron_plate_stairs:7,10,quark:iron_plate_stairs:1,10,quark:iron_plate_slab,10,quark:iron_plate_stairs:4,10,quark:iron_plate_stairs:2,10,minecraft:iron_bars,50,minecraft:iron_bars,50,minecraft:leaves2:1,100)
RandomBlock(1,15,5,minecraft:iron_bars,30,minecraft:iron_bars,30,minecraft:leaves2:1,30,quark:iron_plate_stairs:6,10,quark:iron_plate_stairs:0,10,quark:iron_plate_stairs:5,10,quark:iron_plate_stairs,10,quark:iron_plate_slab:8,10,quark:iron_plate_stairs:7,10,quark:iron_plate_stairs:1,10,quark:iron_plate_slab,10,quark:iron_plate_stairs:4,10,quark:iron_plate_stairs:2,10,minecraft:iron_bars,50,minecraft:iron_bars,50,minecraft:leaves2:1,100)
RandomBlock(1,15,6,quark:iron_plate:1,70,STAINED_CLAY:15,30,STAINED_CLAY:7,30,STAINED_CLAY:8,30,quark:iron_plate:1,100)
RandomBlock(1,16,4,minecraft:iron_bars,30,minecraft:iron_bars,30,minecraft:leaves2:1,30,quark:iron_plate_stairs:6,10,quark:iron_plate_stairs:0,10,quark:iron_plate_stairs:5,10,quark:iron_plate_stairs,10,quark:iron_plate_slab:8,10,quark:iron_plate_stairs:7,10,quark:iron_plate_stairs:1,10,quark:iron_plate_slab,10,quark:iron_plate_stairs:4,10,quark:iron_plate_stairs:2,10,minecraft:iron_bars,50,minecraft:iron_bars,50,minecraft:leaves2:1,100)
RandomBlock(1,16,5,quark:iron_plate:1,70,STAINED_CLAY:15,30,STAINED_CLAY:7,30,STAINED_CLAY:8,30,quark:iron_plate:1,100)
RandomBlock(1,16,6,quark:iron_plate:1,70,STAINED_CLAY:15,30,STAINED_CLAY:7,30,STAINED_CLAY:8,30,quark:iron_plate:1,100)
RandomBlock(1,17,4,minecraft:iron_bars,30,minecraft:iron_bars,30,minecraft:leaves2:1,30,quark:iron_plate_stairs:6,10,quark:iron_plate_stairs:0,10,quark:iron_plate_stairs:5,10,quark:iron_plate_stairs,10,quark:iron_plate_slab:8,10,quark:iron_plate_stairs:7,10,quark:iron_plate_stairs:1,10,quark:iron_plate_slab,10,quark:iron_plate_stairs:4,10,quark:iron_plate_stairs:2,10,minecraft:iron_bars,50,minecraft:iron_bars,50,minecraft:leaves2:1,100)
RandomBlock(1,17,5,quark:iron_plate:1,70,STAINED_CLAY:15,30,STAINED_CLAY:7,30,STAINED_CLAY:8,30,quark:iron_plate:1,100)
RandomBlock(1,17,6,quark:iron_plate:1,70,STAINED_CLAY:15,30,STAINED_CLAY:7,30,STAINED_CLAY:8,30,quark:iron_plate:1,100)
RandomBlock(1,18,4,quark:iron_plate:1,70,STAINED_CLAY:15,30,STAINED_CLAY:7,30,STAINED_CLAY:8,30,quark:iron_plate:1,100)
RandomBlock(1,18,5,quark:iron_plate:1,70,STAINED_CLAY:15,30,STAINED_CLAY:7,30,STAINED_CLAY:8,30,quark:iron_plate:1,100)
RandomBlock(1,18,6,quark:iron_plate:1,70,STAINED_CLAY:15,30,STAINED_CLAY:7,30,STAINED_CLAY:8,30,quark:iron_plate:1,100)
RandomBlock(1,19,4,quark:iron_plate:1,70,STAINED_CLAY:15,30,STAINED_CLAY:7,30,STAINED_CLAY:8,30,quark:iron_plate:1,100)
RandomBlock(1,19,5,quark:iron_plate:1,70,STAINED_CLAY:15,30,STAINED_CLAY:7,30,STAINED_CLAY:8,30,quark:iron_plate:1,100)
RandomBlock(1,19,6,quark:iron_plate:1,70,STAINED_CLAY:15,30,STAINED_CLAY:7,30,STAINED_CLAY:8,30,quark:iron_plate:1,100)
RandomBlock(1,20,4,quark:iron_plate:1,70,STAINED_CLAY:15,30,STAINED_CLAY:7,30,STAINED_CLAY:8,30,quark:iron_plate:1,100)
RandomBlock(1,20,5,quark:iron_plate:1,70,STAINED_CLAY:15,30,STAINED_CLAY:7,30,STAINED_CLAY:8,30,quark:iron_plate:1,100)
RandomBlock(1,20,6,quark:iron_plate:1,70,STAINED_CLAY:15,30,STAINED_CLAY:7,30,STAINED_CLAY:8,30,quark:iron_plate:1,100)
RandomBlock(1,21,4,quark:iron_plate:1,70,STAINED_CLAY:15,30,STAINED_CLAY:7,30,STAINED_CLAY:8,30,quark:iron_plate:1,100)
RandomBlock(1,21,5,quark:iron_plate:1,70,STAINED_CLAY:15,30,STAINED_CLAY:7,30,STAINED_CLAY:8,30,quark:iron_plate:1,100)
RandomBlock(1,21,6,quark:iron_plate:1,70,STAINED_CLAY:15,30,STAINED_CLAY:7,30,STAINED_CLAY:8,30,quark:iron_plate:1,100)
RandomBlock(1,22,4,quark:iron_plate:1,70,STAINED_CLAY:15,30,STAINED_CLAY:7,30,STAINED_CLAY:8,30,quark:iron_plate:1,100)
RandomBlock(1,22,5,quark:iron_plate:1,70,STAINED_CLAY:15,30,STAINED_CLAY:7,30,STAINED_CLAY:8,30,quark:iron_plate:1,100)
RandomBlock(1,22,6,quark:iron_plate:1,70,STAINED_CLAY:15,30,STAINED_CLAY:7,30,STAINED_CLAY:8,30,quark:iron_plate:1,100)
RandomBlock(1,23,4,minecraft:iron_bars,30,minecraft:iron_bars,30,minecraft:leaves2:1,30,quark:iron_plate_stairs:6,10,quark:iron_plate_stairs:0,10,quark:iron_plate_stairs:5,10,quark:iron_plate_stairs,10,quark:iron_plate_slab:8,10,quark:iron_plate_stairs:7,10,quark:iron_plate_stairs:1,10,quark:iron_plate_slab,10,quark:iron_plate_stairs:4,10,quark:iron_plate_stairs:2,10,minecraft:iron_bars,50,minecraft:iron_bars,50,minecraft:leaves2:1,100)
RandomBlock(1,23,5,quark:iron_plate:1,70,STAINED_CLAY:15,30,STAINED_CLAY:7,30,STAINED_CLAY:8,30,quark:iron_plate:1,100)
RandomBlock(1,23,6,quark:iron_plate:1,70,STAINED_CLAY:15,30,STAINED_CLAY:7,30,STAINED_CLAY:8,30,quark:iron_plate:1,100)
RandomBlock(1,24,4,minecraft:iron_bars,30,minecraft:iron_bars,30,minecraft:leaves2:1,30,quark:iron_plate_stairs:6,10,quark:iron_plate_stairs:0,10,quark:iron_plate_stairs:5,10,quark:iron_plate_stairs,10,quark:iron_plate_slab:8,10,quark:iron_plate_stairs:7,10,quark:iron_plate_stairs:1,10,quark:iron_plate_slab,10,quark:iron_plate_stairs:4,10,quark:iron_plate_stairs:2,10,minecraft:iron_bars,50,minecraft:iron_bars,50,minecraft:leaves2:1,100)
RandomBlock(1,24,5,quark:iron_plate:1,70,STAINED_CLAY:15,30,STAINED_CLAY:7,30,STAINED_CLAY:8,30,quark:iron_plate:1,100)
RandomBlock(1,24,6,quark:iron_plate:1,70,STAINED_CLAY:15,30,STAINED_CLAY:7,30,STAINED_CLAY:8,30,quark:iron_plate:1,100)
RandomBlock(1,25,4,minecraft:iron_bars,30,minecraft:iron_bars,30,minecraft:leaves2:1,30,quark:iron_plate_stairs:6,10,quark:iron_plate_stairs:0,10,quark:iron_plate_stairs:5,10,quark:iron_plate_stairs,10,quark:iron_plate_slab:8,10,quark:iron_plate_stairs:7,10,quark:iron_plate_stairs:1,10,quark:iron_plate_slab,10,quark:iron_plate_stairs:4,10,quark:iron_plate_stairs:2,10,minecraft:iron_bars,50,minecraft:iron_bars,50,minecraft:leaves2:1,100)
RandomBlock(1,25,5,minecraft:iron_bars,30,minecraft:iron_bars,30,minecraft:leaves2:1,30,quark:iron_plate_stairs:6,10,quark:iron_plate_stairs:0,10,quark:iron_plate_stairs:5,10,quark:iron_plate_stairs,10,quark:iron_plate_slab:8,10,quark:iron_plate_stairs:7,10,quark:iron_plate_stairs:1,10,quark:iron_plate_slab,10,quark:iron_plate_stairs:4,10,quark:iron_plate_stairs:2,10,minecraft:iron_bars,50,minecraft:iron_bars,50,minecraft:leaves2:1,100)
RandomBlock(1,25,6,quark:iron_plate:1,70,STAINED_CLAY:15,30,STAINED_CLAY:7,30,STAINED_CLAY:8,30,quark:iron_plate:1,100)
RandomBlock(1,26,4,minecraft:iron_bars,30,minecraft:iron_bars,30,minecraft:leaves2:1,30,quark:iron_plate_stairs:6,10,quark:iron_plate_stairs:0,10,quark:iron_plate_stairs:5,10,quark:iron_plate_stairs,10,quark:iron_plate_slab:8,10,quark:iron_plate_stairs:7,10,quark:iron_plate_stairs:1,10,quark:iron_plate_slab,10,quark:iron_plate_stairs:4,10,quark:iron_plate_stairs:2,10,minecraft:iron_bars,50,minecraft:iron_bars,50,minecraft:leaves2:1,100)
RandomBlock(1,26,5,quark:iron_plate:1,70,STAINED_CLAY:15,30,STAINED_CLAY:7,30,STAINED_CLAY:8,30,quark:iron_plate:1,100)
RandomBlock(1,26,6,quark:iron_plate:1,70,STAINED_CLAY:15,30,STAINED_CLAY:7,30,STAINED_CLAY:8,30,quark:iron_plate:1,100)
RandomBlock(1,27,4,quark:iron_plate:1,70,STAINED_CLAY:15,30,STAINED_CLAY:7,30,STAINED_CLAY:8,30,quark:iron_plate:1,100)
RandomBlock(1,27,5,quark:iron_plate:1,70,STAINED_CLAY:15,30,STAINED_CLAY:7,30,STAINED_CLAY:8,30,quark:iron_plate:1,100)
RandomBlock(1,27,6,quark:iron_plate:1,70,STAINED_CLAY:15,30,STAINED_CLAY:7,30,STAINED_CLAY:8,30,quark:iron_plate:1,100)
RandomBlock(1,28,4,minecraft:iron_bars,30,minecraft:iron_bars,30,minecraft:leaves2:1,30,quark:iron_plate_stairs:6,10,quark:iron_plate_stairs:0,10,quark:iron_plate_stairs:5,10,quark:iron_plate_stairs,10,quark:iron_plate_slab:8,10,quark:iron_plate_stairs:7,10,quark:iron_plate_stairs:1,10,quark:iron_plate_slab,10,quark:iron_plate_stairs:4,10,quark:iron_plate_stairs:2,10,minecraft:iron_bars,50,minecraft:iron_bars,50,minecraft:leaves2:1,100)
RandomBlock(1,28,5,quark:iron_plate:1,70,STAINED_CLAY:15,30,STAINED_CLAY:7,30,STAINED_CLAY:8,30,quark:iron_plate:1,100)
RandomBlock(1,28,6,quark:iron_plate:1,70,STAINED_CLAY:15,30,STAINED_CLAY:7,30,STAINED_CLAY:8,30,quark:iron_plate:1,100)
RandomBlock(1,29,4,minecraft:iron_bars,30,minecraft:iron_bars,30,minecraft:leaves2:1,30,quark:iron_plate_stairs:6,10,quark:iron_plate_stairs:0,10,quark:iron_plate_stairs:5,10,quark:iron_plate_stairs,10,quark:iron_plate_slab:8,10,quark:iron_plate_stairs:7,10,quark:iron_plate_stairs:1,10,quark:iron_plate_slab,10,quark:iron_plate_stairs:4,10,quark:iron_plate_stairs:2,10,minecraft:iron_bars,50,minecraft:iron_bars,50,minecraft:leaves2:1,100)
RandomBlock(1,29,5,quark:iron_plate:1,70,STAINED_CLAY:15,30,STAINED_CLAY:7,30,STAINED_CLAY:8,30,quark:iron_plate:1,100)
RandomBlock(1,29,6,quark:iron_plate:1,70,STAINED_CLAY:15,30,STAINED_CLAY:7,30,STAINED_CLAY:8,30,quark:iron_plate:1,100)
RandomBlock(1,30,4,minecraft:iron_bars,30,minecraft:iron_bars,30,minecraft:leaves2:1,30,quark:iron_plate_stairs:6,10,quark:iron_plate_stairs:0,10,quark:iron_plate_stairs:5,10,quark:iron_plate_stairs,10,quark:iron_plate_slab:8,10,quark:iron_plate_stairs:7,10,quark:iron_plate_stairs:1,10,quark:iron_plate_slab,10,quark:iron_plate_stairs:4,10,quark:iron_plate_stairs:2,10,minecraft:iron_bars,50,minecraft:iron_bars,50,minecraft:leaves2:1,100)
RandomBlock(1,30,5,minecraft:iron_bars,30,minecraft:iron_bars,30,minecraft:leaves2:1,30,quark:iron_plate_stairs:6,10,quark:iron_plate_stairs:0,10,quark:iron_plate_stairs:5,10,quark:iron_plate_stairs,10,quark:iron_plate_slab:8,10,quark:iron_plate_stairs:7,10,quark:iron_plate_stairs:1,10,quark:iron_plate_slab,10,quark:iron_plate_stairs:4,10,quark:iron_plate_stairs:2,10,minecraft:iron_bars,50,minecraft:iron_bars,50,minecraft:leaves2:1,100)
RandomBlock(1,30,6,quark:iron_plate:1,70,STAINED_CLAY:15,30,STAINED_CLAY:7,30,STAINED_CLAY:8,30,quark:iron_plate:1,100)
RandomBlock(1,31,4,minecraft:iron_bars,30,minecraft:iron_bars,30,minecraft:leaves2:1,30,quark:iron_plate_stairs:6,10,quark:iron_plate_stairs:0,10,quark:iron_plate_stairs:5,10,quark:iron_plate_stairs,10,quark:iron_plate_slab:8,10,quark:iron_plate_stairs:7,10,quark:iron_plate_stairs:1,10,quark:iron_plate_slab,10,quark:iron_plate_stairs:4,10,quark:iron_plate_stairs:2,10,minecraft:iron_bars,50,minecraft:iron_bars,50,minecraft:leaves2:1,100)
RandomBlock(1,31,5,quark:iron_plate:1,70,STAINED_CLAY:15,30,STAINED_CLAY:7,30,STAINED_CLAY:8,30,quark:iron_plate:1,100)
RandomBlock(1,31,6,quark:iron_plate:1,70,STAINED_CLAY:15,30,STAINED_CLAY:7,30,STAINED_CLAY:8,30,quark:iron_plate:1,100)
RandomBlock(1,32,4,minecraft:iron_bars,30,minecraft:iron_bars,30,minecraft:leaves2:1,30,quark:iron_plate_stairs:6,10,quark:iron_plate_stairs:0,10,quark:iron_plate_stairs:5,10,quark:iron_plate_stairs,10,quark:iron_plate_slab:8,10,quark:iron_plate_stairs:7,10,quark:iron_plate_stairs:1,10,quark:iron_plate_slab,10,quark:iron_plate_stairs:4,10,quark:iron_plate_stairs:2,10,minecraft:iron_bars,50,minecraft:iron_bars,50,minecraft:leaves2:1,100)
RandomBlock(1,32,5,minecraft:iron_bars,30,minecraft:iron_bars,30,minecraft:leaves2:1,30,quark:iron_plate_stairs:6,10,quark:iron_plate_stairs:0,10,quark:iron_plate_stairs:5,10,quark:iron_plate_stairs,10,quark:iron_plate_slab:8,10,quark:iron_plate_stairs:7,10,quark:iron_plate_stairs:1,10,quark:iron_plate_slab,10,quark:iron_plate_stairs:4,10,quark:iron_plate_stairs:2,10,minecraft:iron_bars,50,minecraft:iron_bars,50,minecraft:leaves2:1,100)
RandomBlock(1,32,6,quark:iron_plate:1,70,STAINED_CLAY:15,30,STAINED_CLAY:7,30,STAINED_CLAY:8,30,quark:iron_plate:1,100)
RandomBlock(1,33,4,minecraft:iron_bars,30,minecraft:iron_bars,30,minecraft:leaves2:1,30,quark:iron_plate_stairs:6,10,quark:iron_plate_stairs:0,10,quark:iron_plate_stairs:5,10,quark:iron_plate_stairs,10,quark:iron_plate_slab:8,10,quark:iron_plate_stairs:7,10,quark:iron_plate_stairs:1,10,quark:iron_plate_slab,10,quark:iron_plate_stairs:4,10,quark:iron_plate_stairs:2,10,minecraft:iron_bars,50,minecraft:iron_bars,50,minecraft:leaves2:1,100)
RandomBlock(1,33,5,quark:iron_plate:1,70,STAINED_CLAY:15,30,STAINED_CLAY:7,30,STAINED_CLAY:8,30,quark:iron_plate:1,100)
RandomBlock(1,33,6,quark:iron_plate:1,70,STAINED_CLAY:15,30,STAINED_CLAY:7,30,STAINED_CLAY:8,30,quark:iron_plate:1,100)
RandomBlock(1,34,4,quark:iron_plate:1,70,STAINED_CLAY:15,30,STAINED_CLAY:7,30,STAINED_CLAY:8,30,quark:iron_plate:1,100)
RandomBlock(1,34,5,quark:iron_plate:1,70,STAINED_CLAY:15,30,STAINED_CLAY:7,30,STAINED_CLAY:8,30,quark:iron_plate:1,100)
RandomBlock(1,34,6,quark:iron_plate:1,70,STAINED_CLAY:15,30,STAINED_CLAY:7,30,STAINED_CLAY:8,30,quark:iron_plate:1,100)
RandomBlock(1,35,4,quark:iron_plate:1,70,STAINED_CLAY:15,30,STAINED_CLAY:7,30,STAINED_CLAY:8,30,quark:iron_plate:1,100)
RandomBlock(1,35,5,quark:iron_plate:1,70,STAINED_CLAY:15,30,STAINED_CLAY:7,30,STAINED_CLAY:8,30,quark:iron_plate:1,100)
RandomBlock(1,35,6,minecraft:iron_bars,30,minecraft:iron_bars,30,minecraft:leaves2:1,30,quark:iron_plate_stairs:6,10,quark:iron_plate_stairs:0,10,quark:iron_plate_stairs:5,10,quark:iron_plate_stairs,10,quark:iron_plate_slab:8,10,quark:iron_plate_stairs:7,10,quark:iron_plate_stairs:1,10,quark:iron_plate_slab,10,quark:iron_plate_stairs:4,10,quark:iron_plate_stairs:2,10,minecraft:iron_bars,50,minecraft:iron_bars,50,minecraft:leaves2:1,100)
RandomBlock(1,36,4,quark:iron_plate:1,70,STAINED_CLAY:15,30,STAINED_CLAY:7,30,STAINED_CLAY:8,30,quark:iron_plate:1,100)
RandomBlock(1,36,5,minecraft:iron_bars,30,minecraft:iron_bars,30,minecraft:leaves2:1,30,quark:iron_plate_stairs:6,10,quark:iron_plate_stairs:0,10,quark:iron_plate_stairs:5,10,quark:iron_plate_stairs,10,quark:iron_plate_slab:8,10,quark:iron_plate_stairs:7,10,quark:iron_plate_stairs:1,10,quark:iron_plate_slab,10,quark:iron_plate_stairs:4,10,quark:iron_plate_stairs:2,10,minecraft:iron_bars,50,minecraft:iron_bars,50,minecraft:leaves2:1,100)
RandomBlock(1,36,6,minecraft:iron_bars,30,minecraft:iron_bars,30,minecraft:leaves2:1,30,quark:iron_plate_stairs:6,10,quark:iron_plate_stairs:0,10,quark:iron_plate_stairs:5,10,quark:iron_plate_stairs,10,quark:iron_plate_slab:8,10,quark:iron_plate_stairs:7,10,quark:iron_plate_stairs:1,10,quark:iron_plate_slab,10,quark:iron_plate_stairs:4,10,quark:iron_plate_stairs:2,10,minecraft:iron_bars,50,minecraft:iron_bars,50,minecraft:leaves2:1,100)
RandomBlock(1,37,4,quark:iron_plate:1,70,STAINED_CLAY:15,30,STAINED_CLAY:7,30,STAINED_CLAY:8,30,quark:iron_plate:1,100)
RandomBlock(1,37,5,minecraft:iron_bars,30,minecraft:iron_bars,30,minecraft:leaves2:1,30,quark:iron_plate_stairs:6,10,quark:iron_plate_stairs:0,10,quark:iron_plate_stairs:5,10,quark:iron_plate_stairs,10,quark:iron_plate_slab:8,10,quark:iron_plate_stairs:7,10,quark:iron_plate_stairs:1,10,quark:iron_plate_slab,10,quark:iron_plate_stairs:4,10,quark:iron_plate_stairs:2,10,minecraft:iron_bars,50,minecraft:iron_bars,50,minecraft:leaves2:1,100)
RandomBlock(1,37,6,minecraft:iron_bars,30,minecraft:iron_bars,30,minecraft:leaves2:1,30,quark:iron_plate_stairs:6,10,quark:iron_plate_stairs:0,10,quark:iron_plate_stairs:5,10,quark:iron_plate_stairs,10,quark:iron_plate_slab:8,10,quark:iron_plate_stairs:7,10,quark:iron_plate_stairs:1,10,quark:iron_plate_slab,10,quark:iron_plate_stairs:4,10,quark:iron_plate_stairs:2,10,minecraft:iron_bars,50,minecraft:iron_bars,50,minecraft:leaves2:1,100)
RandomBlock(1,38,4,quark:iron_plate:1,70,STAINED_CLAY:15,30,STAINED_CLAY:7,30,STAINED_CLAY:8,30,quark:iron_plate:1,100)
RandomBlock(1,38,5,quark:iron_plate:1,70,STAINED_CLAY:15,30,STAINED_CLAY:7,30,STAINED_CLAY:8,30,quark:iron_plate:1,100)
RandomBlock(1,38,6,minecraft:iron_bars,30,minecraft:iron_bars,30,minecraft:leaves2:1,30,quark:iron_plate_stairs:6,10,quark:iron_plate_stairs:0,10,quark:iron_plate_stairs:5,10,quark:iron_plate_stairs,10,quark:iron_plate_slab:8,10,quark:iron_plate_stairs:7,10,quark:iron_plate_stairs:1,10,quark:iron_plate_slab,10,quark:iron_plate_stairs:4,10,quark:iron_plate_stairs:2,10,minecraft:iron_bars,50,minecraft:iron_bars,50,minecraft:leaves2:1,100)
RandomBlock(1,39,4,quark:iron_plate:1,70,STAINED_CLAY:15,30,STAINED_CLAY:7,30,STAINED_CLAY:8,30,quark:iron_plate:1,100)
RandomBlock(1,39,5,quark:iron_plate:1,70,STAINED_CLAY:15,30,STAINED_CLAY:7,30,STAINED_CLAY:8,30,quark:iron_plate:1,100)
RandomBlock(1,39,6,quark:iron_plate:1,70,STAINED_CLAY:15,30,STAINED_CLAY:7,30,STAINED_CLAY:8,30,quark:iron_plate:1,100)
RandomBlock(1,40,4,quark:iron_plate:1,70,STAINED_CLAY:15,30,STAINED_CLAY:7,30,STAINED_CLAY:8,30,quark:iron_plate:1,100)
RandomBlock(1,40,5,quark:iron_plate:1,70,STAINED_CLAY:15,30,STAINED_CLAY:7,30,STAINED_CLAY:8,30,quark:iron_plate:1,100)
RandomBlock(1,40,6,quark:iron_plate:1,70,STAINED_CLAY:15,30,STAINED_CLAY:7,30,STAINED_CLAY:8,30,quark:iron_plate:1,100)
RandomBlock(1,41,4,minecraft:iron_bars,30,minecraft:iron_bars,30,minecraft:leaves2:1,30,quark:iron_plate_stairs:6,10,quark:iron_plate_stairs:0,10,quark:iron_plate_stairs:5,10,quark:iron_plate_stairs,10,quark:iron_plate_slab:8,10,quark:iron_plate_stairs:7,10,quark:iron_plate_stairs:1,10,quark:iron_plate_slab,10,quark:iron_plate_stairs:4,10,quark:iron_plate_stairs:2,10,minecraft:iron_bars,50,minecraft:iron_bars,50,minecraft:leaves2:1,100)
RandomBlock(1,41,5,quark:iron_plate:1,70,STAINED_CLAY:15,30,STAINED_CLAY:7,30,STAINED_CLAY:8,30,quark:iron_plate:1,100)
RandomBlock(1,41,6,quark:iron_plate:1,70,STAINED_CLAY:15,30,STAINED_CLAY:7,30,STAINED_CLAY:8,30,quark:iron_plate:1,100)
RandomBlock(1,42,4,quark:iron_plate:1,70,STAINED_CLAY:15,30,STAINED_CLAY:7,30,STAINED_CLAY:8,30,quark:iron_plate:1,100)
RandomBlock(1,42,5,quark:iron_plate:1,70,STAINED_CLAY:15,30,STAINED_CLAY:7,30,STAINED_CLAY:8,30,quark:iron_plate:1,100)
RandomBlock(1,42,6,quark:iron_plate:1,70,STAINED_CLAY:15,30,STAINED_CLAY:7,30,STAINED_CLAY:8,30,quark:iron_plate:1,100)
RandomBlock(1,43,4,minecraft:iron_bars,30,minecraft:iron_bars,30,minecraft:leaves2:1,30,quark:iron_plate_stairs:6,10,quark:iron_plate_stairs:0,10,quark:iron_plate_stairs:5,10,quark:iron_plate_stairs,10,quark:iron_plate_slab:8,10,quark:iron_plate_stairs:7,10,quark:iron_plate_stairs:1,10,quark:iron_plate_slab,10,quark:iron_plate_stairs:4,10,quark:iron_plate_stairs:2,10,minecraft:iron_bars,50,minecraft:iron_bars,50,minecraft:leaves2:1,100)
RandomBlock(1,43,5,quark:iron_plate:1,70,STAINED_CLAY:15,30,STAINED_CLAY:7,30,STAINED_CLAY:8,30,quark:iron_plate:1,100)
RandomBlock(1,43,6,minecraft:iron_bars,30,minecraft:iron_bars,30,minecraft:leaves2:1,30,quark:iron_plate_stairs:6,10,quark:iron_plate_stairs:0,10,quark:iron_plate_stairs:5,10,quark:iron_plate_stairs,10,quark:iron_plate_slab:8,10,quark:iron_plate_stairs:7,10,quark:iron_plate_stairs:1,10,quark:iron_plate_slab,10,quark:iron_plate_stairs:4,10,quark:iron_plate_stairs:2,10,minecraft:iron_bars,50,minecraft:iron_bars,50,minecraft:leaves2:1,100)
RandomBlock(1,44,4,quark:iron_plate:1,70,STAINED_CLAY:15,30,STAINED_CLAY:7,30,STAINED_CLAY:8,30,quark:iron_plate:1,100)
RandomBlock(1,44,5,quark:iron_plate:1,70,STAINED_CLAY:15,30,STAINED_CLAY:7,30,STAINED_CLAY:8,30,quark:iron_plate:1,100)
RandomBlock(1,44,6,quark:iron_plate:1,70,STAINED_CLAY:15,30,STAINED_CLAY:7,30,STAINED_CLAY:8,30,quark:iron_plate:1,100)
RandomBlock(1,45,4,minecraft:iron_bars,30,minecraft:iron_bars,30,minecraft:leaves2:1,30,quark:iron_plate_stairs:6,10,quark:iron_plate_stairs:0,10,quark:iron_plate_stairs:5,10,quark:iron_plate_stairs,10,quark:iron_plate_slab:8,10,quark:iron_plate_stairs:7,10,quark:iron_plate_stairs:1,10,quark:iron_plate_slab,10,quark:iron_plate_stairs:4,10,quark:iron_plate_stairs:2,10,minecraft:iron_bars,50,minecraft:iron_bars,50,minecraft:leaves2:1,100)
RandomBlock(1,45,5,quark:iron_plate:1,70,STAINED_CLAY:15,30,STAINED_CLAY:7,30,STAINED_CLAY:8,30,quark:iron_plate:1,100)
RandomBlock(1,45,6,minecraft:iron_bars,30,minecraft:iron_bars,30,minecraft:leaves2:1,30,quark:iron_plate_stairs:6,10,quark:iron_plate_stairs:0,10,quark:iron_plate_stairs:5,10,quark:iron_plate_stairs,10,quark:iron_plate_slab:8,10,quark:iron_plate_stairs:7,10,quark:iron_plate_stairs:1,10,quark:iron_plate_slab,10,quark:iron_plate_stairs:4,10,quark:iron_plate_stairs:2,10,minecraft:iron_bars,50,minecraft:iron_bars,50,minecraft:leaves2:1,100)
RandomBlock(1,46,4,quark:iron_plate:1,70,STAINED_CLAY:15,30,STAINED_CLAY:7,30,STAINED_CLAY:8,30,quark:iron_plate:1,100)
RandomBlock(1,46,5,quark:iron_plate:1,70,STAINED_CLAY:15,30,STAINED_CLAY:7,30,STAINED_CLAY:8,30,quark:iron_plate:1,100)
RandomBlock(1,46,6,minecraft:iron_bars,30,minecraft:iron_bars,30,minecraft:leaves2:1,30,quark:iron_plate_stairs:6,10,quark:iron_plate_stairs:0,10,quark:iron_plate_stairs:5,10,quark:iron_plate_stairs,10,quark:iron_plate_slab:8,10,quark:iron_plate_stairs:7,10,quark:iron_plate_stairs:1,10,quark:iron_plate_slab,10,quark:iron_plate_stairs:4,10,quark:iron_plate_stairs:2,10,minecraft:iron_bars,50,minecraft:iron_bars,50,minecraft:leaves2:1,100)
RandomBlock(1,47,4,minecraft:iron_bars,30,minecraft:iron_bars,30,minecraft:leaves2:1,30,quark:iron_plate_stairs:6,10,quark:iron_plate_stairs:0,10,quark:iron_plate_stairs:5,10,quark:iron_plate_stairs,10,quark:iron_plate_slab:8,10,quark:iron_plate_stairs:7,10,quark:iron_plate_stairs:1,10,quark:iron_plate_slab,10,quark:iron_plate_stairs:4,10,quark:iron_plate_stairs:2,10,minecraft:iron_bars,50,minecraft:iron_bars,50,minecraft:leaves2:1,100)
RandomBlock(1,47,5,minecraft:iron_bars,30,minecraft:iron_bars,30,minecraft:leaves2:1,30,quark:iron_plate_stairs:6,10,quark:iron_plate_stairs:0,10,quark:iron_plate_stairs:5,10,quark:iron_plate_stairs,10,quark:iron_plate_slab:8,10,quark:iron_plate_stairs:7,10,quark:iron_plate_stairs:1,10,quark:iron_plate_slab,10,quark:iron_plate_stairs:4,10,quark:iron_plate_stairs:2,10,minecraft:iron_bars,50,minecraft:iron_bars,50,minecraft:leaves2:1,100)
RandomBlock(1,47,6,minecraft:iron_bars,30,minecraft:iron_bars,30,minecraft:leaves2:1,30,quark:iron_plate_stairs:6,10,quark:iron_plate_stairs:0,10,quark:iron_plate_stairs:5,10,quark:iron_plate_stairs,10,quark:iron_plate_slab:8,10,quark:iron_plate_stairs:7,10,quark:iron_plate_stairs:1,10,quark:iron_plate_slab,10,quark:iron_plate_stairs:4,10,quark:iron_plate_stairs:2,10,minecraft:iron_bars,50,minecraft:iron_bars,50,minecraft:leaves2:1,100)
RandomBlock(1,48,4,minecraft:iron_bars,30,minecraft:iron_bars,30,minecraft:leaves2:1,30,quark:iron_plate_stairs:6,10,quark:iron_plate_stairs:0,10,quark:iron_plate_stairs:5,10,quark:iron_plate_stairs,10,quark:iron_plate_slab:8,10,quark:iron_plate_stairs:7,10,quark:iron_plate_stairs:1,10,quark:iron_plate_slab,10,quark:iron_plate_stairs:4,10,quark:iron_plate_stairs:2,10,minecraft:iron_bars,50,minecraft:iron_bars,50,minecraft:leaves2:1,100)
RandomBlock(1,48,5,minecraft:iron_bars,30,minecraft:iron_bars,30,minecraft:leaves2:1,30,quark:iron_plate_stairs:6,10,quark:iron_plate_stairs:0,10,quark:iron_plate_stairs:5,10,quark:iron_plate_stairs,10,quark:iron_plate_slab:8,10,quark:iron_plate_stairs:7,10,quark:iron_plate_stairs:1,10,quark:iron_plate_slab,10,quark:iron_plate_stairs:4,10,quark:iron_plate_stairs:2,10,minecraft:iron_bars,50,minecraft:iron_bars,50,minecraft:leaves2:1,100)
RandomBlock(1,48,6,minecraft:iron_bars,30,minecraft:iron_bars,30,minecraft:leaves2:1,30,quark:iron_plate_stairs:6,10,quark:iron_plate_stairs:0,10,quark:iron_plate_stairs:5,10,quark:iron_plate_stairs,10,quark:iron_plate_slab:8,10,quark:iron_plate_stairs:7,10,quark:iron_plate_stairs:1,10,quark:iron_plate_slab,10,quark:iron_plate_stairs:4,10,quark:iron_plate_stairs:2,10,minecraft:iron_bars,50,minecraft:iron_bars,50,minecraft:leaves2:1,100)
RandomBlock(1,49,4,minecraft:iron_bars,30,minecraft:iron_bars,30,minecraft:leaves2:1,30,quark:iron_plate_stairs:6,10,quark:iron_plate_stairs:0,10,quark:iron_plate_stairs:5,10,quark:iron_plate_stairs,10,quark:iron_plate_slab:8,10,quark:iron_plate_stairs:7,10,quark:iron_plate_stairs:1,10,quark:iron_plate_slab,10,quark:iron_plate_stairs:4,10,quark:iron_plate_stairs:2,10,minecraft:iron_bars,50,minecraft:iron_bars,50,minecraft:leaves2:1,100)
RandomBlock(1,49,5,minecraft:iron_bars,30,minecraft:iron_bars,30,minecraft:leaves2:1,30,quark:iron_plate_stairs:6,10,quark:iron_plate_stairs:0,10,quark:iron_plate_stairs:5,10,quark:iron_plate_stairs,10,quark:iron_plate_slab:8,10,quark:iron_plate_stairs:7,10,quark:iron_plate_stairs:1,10,quark:iron_plate_slab,10,quark:iron_plate_stairs:4,10,quark:iron_plate_stairs:2,10,minecraft:iron_bars,50,minecraft:iron_bars,50,minecraft:leaves2:1,100)
RandomBlock(1,49,6,minecraft:iron_bars,30,minecraft:iron_bars,30,minecraft:leaves2:1,30,quark:iron_plate_stairs:6,10,quark:iron_plate_stairs:0,10,quark:iron_plate_stairs:5,10,quark:iron_plate_stairs,10,quark:iron_plate_slab:8,10,quark:iron_plate_stairs:7,10,quark:iron_plate_stairs:1,10,quark:iron_plate_slab,10,quark:iron_plate_stairs:4,10,quark:iron_plate_stairs:2,10,minecraft:iron_bars,50,minecraft:iron_bars,50,minecraft:leaves2:1,100)
RandomBlock(1,50,4,minecraft:iron_bars,30,minecraft:iron_bars,30,minecraft:leaves2:1,30,quark:iron_plate_stairs:6,10,quark:iron_plate_stairs:0,10,quark:iron_plate_stairs:5,10,quark:iron_plate_stairs,10,quark:iron_plate_slab:8,10,quark:iron_plate_stairs:7,10,quark:iron_plate_stairs:1,10,quark:iron_plate_slab,10,quark:iron_plate_stairs:4,10,quark:iron_plate_stairs:2,10,minecraft:iron_bars,50,minecraft:iron_bars,50,minecraft:leaves2:1,100)
RandomBlock(1,50,5,quark:iron_plate:1,70,STAINED_CLAY:15,30,STAINED_CLAY:7,30,STAINED_CLAY:8,30,quark:iron_plate:1,100)
RandomBlock(1,50,6,minecraft:iron_bars,30,minecraft:iron_bars,30,minecraft:leaves2:1,30,quark:iron_plate_stairs:6,10,quark:iron_plate_stairs:0,10,quark:iron_plate_stairs:5,10,quark:iron_plate_stairs,10,quark:iron_plate_slab:8,10,quark:iron_plate_stairs:7,10,quark:iron_plate_stairs:1,10,quark:iron_plate_slab,10,quark:iron_plate_stairs:4,10,quark:iron_plate_stairs:2,10,minecraft:iron_bars,50,minecraft:iron_bars,50,minecraft:leaves2:1,100)
RandomBlock(1,51,4,minecraft:iron_bars,30,minecraft:iron_bars,30,minecraft:leaves2:1,30,quark:iron_plate_stairs:6,10,quark:iron_plate_stairs:0,10,quark:iron_plate_stairs:5,10,quark:iron_plate_stairs,10,quark:iron_plate_slab:8,10,quark:iron_plate_stairs:7,10,quark:iron_plate_stairs:1,10,quark:iron_plate_slab,10,quark:iron_plate_stairs:4,10,quark:iron_plate_stairs:2,10,minecraft:iron_bars,50,minecraft:iron_bars,50,minecraft:leaves2:1,100)
RandomBlock(1,51,5,minecraft:iron_bars,30,minecraft:iron_bars,30,minecraft:leaves2:1,30,quark:iron_plate_stairs:6,10,quark:iron_plate_stairs:0,10,quark:iron_plate_stairs:5,10,quark:iron_plate_stairs,10,quark:iron_plate_slab:8,10,quark:iron_plate_stairs:7,10,quark:iron_plate_stairs:1,10,quark:iron_plate_slab,10,quark:iron_plate_stairs:4,10,quark:iron_plate_stairs:2,10,minecraft:iron_bars,50,minecraft:iron_bars,50,minecraft:leaves2:1,100)
RandomBlock(1,51,6,minecraft:iron_bars,30,minecraft:iron_bars,30,minecraft:leaves2:1,30,quark:iron_plate_stairs:6,10,quark:iron_plate_stairs:0,10,quark:iron_plate_stairs:5,10,quark:iron_plate_stairs,10,quark:iron_plate_slab:8,10,quark:iron_plate_stairs:7,10,quark:iron_plate_stairs:1,10,quark:iron_plate_slab,10,quark:iron_plate_stairs:4,10,quark:iron_plate_stairs:2,10,minecraft:iron_bars,50,minecraft:iron_bars,50,minecraft:leaves2:1,100)
RandomBlock(1,52,4,minecraft:iron_bars,30,minecraft:iron_bars,30,minecraft:leaves2:1,30,quark:iron_plate_stairs:6,10,quark:iron_plate_stairs:0,10,quark:iron_plate_stairs:5,10,quark:iron_plate_stairs,10,quark:iron_plate_slab:8,10,quark:iron_plate_stairs:7,10,quark:iron_plate_stairs:1,10,quark:iron_plate_slab,10,quark:iron_plate_stairs:4,10,quark:iron_plate_stairs:2,10,minecraft:iron_bars,50,minecraft:iron_bars,50,minecraft:leaves2:1,100)
RandomBlock(1,52,5,quark:iron_plate:1,70,STAINED_CLAY:15,30,STAINED_CLAY:7,30,STAINED_CLAY:8,30,quark:iron_plate:1,100)
RandomBlock(1,52,6,quark:iron_plate:1,70,STAINED_CLAY:15,30,STAINED_CLAY:7,30,STAINED_CLAY:8,30,quark:iron_plate:1,100)
RandomBlock(1,53,4,quark:iron_plate:1,70,STAINED_CLAY:15,30,STAINED_CLAY:7,30,STAINED_CLAY:8,30,quark:iron_plate:1,100)
RandomBlock(1,53,5,quark:iron_plate:1,70,STAINED_CLAY:15,30,STAINED_CLAY:7,30,STAINED_CLAY:8,30,quark:iron_plate:1,100)
RandomBlock(1,53,6,quark:iron_plate:1,70,STAINED_CLAY:15,30,STAINED_CLAY:7,30,STAINED_CLAY:8,30,quark:iron_plate:1,100)
RandomBlock(1,54,4,quark:iron_plate:1,70,STAINED_CLAY:15,30,STAINED_CLAY:7,30,STAINED_CLAY:8,30,quark:iron_plate:1,100)
RandomBlock(1,54,5,quark:iron_plate:1,70,STAINED_CLAY:15,30,STAINED_CLAY:7,30,STAINED_CLAY:8,30,quark:iron_plate:1,100)
RandomBlock(1,54,6,quark:iron_plate:1,70,STAINED_CLAY:15,30,STAINED_CLAY:7,30,STAINED_CLAY:8,30,quark:iron_plate:1,100)
RandomBlock(1,55,4,quark:iron_plate:1,70,STAINED_CLAY:15,30,STAINED_CLAY:7,30,STAINED_CLAY:8,30,quark:iron_plate:1,100)
RandomBlock(1,55,5,quark:iron_plate:1,70,STAINED_CLAY:15,30,STAINED_CLAY:7,30,STAINED_CLAY:8,30,quark:iron_plate:1,100)
RandomBlock(1,55,6,quark:iron_plate:1,70,STAINED_CLAY:15,30,STAINED_CLAY:7,30,STAINED_CLAY:8,30,quark:iron_plate:1,100)
RandomBlock(1,56,4,quark:iron_plate:1,70,STAINED_CLAY:15,30,STAINED_CLAY:7,30,STAINED_CLAY:8,30,quark:iron_plate:1,100)
RandomBlock(1,56,5,quark:iron_plate:1,70,STAINED_CLAY:15,30,STAINED_CLAY:7,30,STAINED_CLAY:8,30,quark:iron_plate:1,100)
RandomBlock(1,56,6,quark:iron_plate:1,70,STAINED_CLAY:15,30,STAINED_CLAY:7,30,STAINED_CLAY:8,30,quark:iron_plate:1,100)
RandomBlock(1,57,4,quark:iron_plate:1,70,STAINED_CLAY:15,30,STAINED_CLAY:7,30,STAINED_CLAY:8,30,quark:iron_plate:1,100)
RandomBlock(1,57,5,quark:iron_plate:1,70,STAINED_CLAY:15,30,STAINED_CLAY:7,30,STAINED_CLAY:8,30,quark:iron_plate:1,100)
RandomBlock(1,57,6,quark:iron_plate:1,70,STAINED_CLAY:15,30,STAINED_CLAY:7,30,STAINED_CLAY:8,30,quark:iron_plate:1,100)
RandomBlock(1,58,4,quark:iron_plate:1,70,STAINED_CLAY:15,30,STAINED_CLAY:7,30,STAINED_CLAY:8,30,quark:iron_plate:1,100)
RandomBlock(1,58,5,quark:iron_plate:1,70,STAINED_CLAY:15,30,STAINED_CLAY:7,30,STAINED_CLAY:8,30,quark:iron_plate:1,100)
RandomBlock(1,58,6,quark:iron_plate:1,70,STAINED_CLAY:15,30,STAINED_CLAY:7,30,STAINED_CLAY:8,30,quark:iron_plate:1,100)
RandomBlock(1,59,4,quark:iron_plate:1,70,STAINED_CLAY:15,30,STAINED_CLAY:7,30,STAINED_CLAY:8,30,quark:iron_plate:1,100)
RandomBlock(1,59,5,quark:iron_plate:1,70,STAINED_CLAY:15,30,STAINED_CLAY:7,30,STAINED_CLAY:8,30,quark:iron_plate:1,100)
RandomBlock(1,59,6,quark:iron_plate:1,70,STAINED_CLAY:15,30,STAINED_CLAY:7,30,STAINED_CLAY:8,30,quark:iron_plate:1,100)
RandomBlock(1,60,4,quark:iron_plate:1,70,STAINED_CLAY:15,30,STAINED_CLAY:7,30,STAINED_CLAY:8,30,quark:iron_plate:1,100)
RandomBlock(1,60,5,quark:iron_plate:1,70,STAINED_CLAY:15,30,STAINED_CLAY:7,30,STAINED_CLAY:8,30,quark:iron_plate:1,100)
RandomBlock(1,60,6,quark:iron_plate:1,70,STAINED_CLAY:15,30,STAINED_CLAY:7,30,STAINED_CLAY:8,30,quark:iron_plate:1,100)
RandomBlock(1,61,4,quark:iron_plate:1,70,STAINED_CLAY:15,30,STAINED_CLAY:7,30,STAINED_CLAY:8,30,quark:iron_plate:1,100)
RandomBlock(1,61,5,quark:iron_plate:1,70,STAINED_CLAY:15,30,STAINED_CLAY:7,30,STAINED_CLAY:8,30,quark:iron_plate:1,100)
RandomBlock(1,61,6,quark:iron_plate:1,70,STAINED_CLAY:15,30,STAINED_CLAY:7,30,STAINED_CLAY:8,30,quark:iron_plate:1,100)
RandomBlock(1,62,4,quark:iron_plate:1,70,STAINED_CLAY:15,30,STAINED_CLAY:7,30,STAINED_CLAY:8,30,quark:iron_plate:1,100)
RandomBlock(1,62,5,quark:iron_plate:1,70,STAINED_CLAY:15,30,STAINED_CLAY:7,30,STAINED_CLAY:8,30,quark:iron_plate:1,100)
RandomBlock(1,62,6,quark:iron_plate:1,70,STAINED_CLAY:15,30,STAINED_CLAY:7,30,STAINED_CLAY:8,30,quark:iron_plate:1,100)
RandomBlock(1,63,4,quark:iron_plate:1,70,STAINED_CLAY:15,30,STAINED_CLAY:7,30,STAINED_CLAY:8,30,quark:iron_plate:1,100)
RandomBlock(1,63,5,quark:iron_plate:1,70,STAINED_CLAY:15,30,STAINED_CLAY:7,30,STAINED_CLAY:8,30,quark:iron_plate:1,100)
RandomBlock(1,63,6,quark:iron_plate:1,70,STAINED_CLAY:15,30,STAINED_CLAY:7,30,STAINED_CLAY:8,30,quark:iron_plate:1,100)
RandomBlock(1,64,4,quark:iron_plate:1,70,STAINED_CLAY:15,30,STAINED_CLAY:7,30,STAINED_CLAY:8,30,quark:iron_plate:1,100)
RandomBlock(1,64,5,quark:iron_plate:1,70,STAINED_CLAY:15,30,STAINED_CLAY:7,30,STAINED_CLAY:8,30,quark:iron_plate:1,100)
RandomBlock(1,64,6,quark:iron_plate:1,70,STAINED_CLAY:15,30,STAINED_CLAY:7,30,STAINED_CLAY:8,30,quark:iron_plate:1,100)
RandomBlock(1,65,4,quark:iron_plate:1,70,STAINED_CLAY:15,30,STAINED_CLAY:7,30,STAINED_CLAY:8,30,quark:iron_plate:1,100)
RandomBlock(1,65,5,quark:iron_plate:1,70,STAINED_CLAY:15,30,STAINED_CLAY:7,30,STAINED_CLAY:8,30,quark:iron_plate:1,100)
RandomBlock(1,65,6,quark:iron_plate:1,70,STAINED_CLAY:15,30,STAINED_CLAY:7,30,STAINED_CLAY:8,30,quark:iron_plate:1,100)
RandomBlock(2,0,4,quark:iron_plate:1,70,STAINED_CLAY:15,30,STAINED_CLAY:7,30,STAINED_CLAY:8,30,quark:iron_plate:1,100)
Block(2,0,5,AIR:0)
RandomBlock(2,0,6,quark:iron_plate:1,70,STAINED_CLAY:15,30,STAINED_CLAY:7,30,STAINED_CLAY:8,30,quark:iron_plate:1,100)
RandomBlock(2,1,4,quark:iron_plate:1,70,STAINED_CLAY:15,30,STAINED_CLAY:7,30,STAINED_CLAY:8,30,quark:iron_plate:1,100)
Block(2,1,5,AIR:0)
RandomBlock(2,1,6,quark:iron_plate:1,70,STAINED_CLAY:15,30,STAINED_CLAY:7,30,STAINED_CLAY:8,30,quark:iron_plate:1,100)
RandomBlock(2,2,4,minecraft:iron_bars,30,minecraft:iron_bars,30,minecraft:leaves2:1,30,quark:iron_plate_stairs:6,10,quark:iron_plate_stairs:0,10,quark:iron_plate_stairs:5,10,quark:iron_plate_stairs,10,quark:iron_plate_slab:8,10,quark:iron_plate_stairs:7,10,quark:iron_plate_stairs:1,10,quark:iron_plate_slab,10,quark:iron_plate_stairs:4,10,quark:iron_plate_stairs:2,10,minecraft:iron_bars,50,minecraft:iron_bars,50,minecraft:leaves2:1,100)
Block(2,2,5,AIR:0)
RandomBlock(2,2,6,quark:iron_plate:1,70,STAINED_CLAY:15,30,STAINED_CLAY:7,30,STAINED_CLAY:8,30,quark:iron_plate:1,100)
RandomBlock(2,3,4,minecraft:iron_bars,30,minecraft:iron_bars,30,minecraft:leaves2:1,30,quark:iron_plate_stairs:6,10,quark:iron_plate_stairs:0,10,quark:iron_plate_stairs:5,10,quark:iron_plate_stairs,10,quark:iron_plate_slab:8,10,quark:iron_plate_stairs:7,10,quark:iron_plate_stairs:1,10,quark:iron_plate_slab,10,quark:iron_plate_stairs:4,10,quark:iron_plate_stairs:2,10,minecraft:iron_bars,50,minecraft:iron_bars,50,minecraft:leaves2:1,100)
Block(2,3,5,AIR:0)
RandomBlock(2,3,6,minecraft:iron_bars,30,minecraft:iron_bars,30,minecraft:leaves2:1,30,quark:iron_plate_stairs:6,10,quark:iron_plate_stairs:0,10,quark:iron_plate_stairs:5,10,quark:iron_plate_stairs,10,quark:iron_plate_slab:8,10,quark:iron_plate_stairs:7,10,quark:iron_plate_stairs:1,10,quark:iron_plate_slab,10,quark:iron_plate_stairs:4,10,quark:iron_plate_stairs:2,10,minecraft:iron_bars,50,minecraft:iron_bars,50,minecraft:leaves2:1,100)
RandomBlock(2,4,4,quark:iron_plate:1,70,STAINED_CLAY:15,30,STAINED_CLAY:7,30,STAINED_CLAY:8,30,quark:iron_plate:1,100)
Block(2,4,5,AIR:0)
RandomBlock(2,4,6,minecraft:iron_bars,30,minecraft:iron_bars,30,minecraft:leaves2:1,30,quark:iron_plate_stairs:6,10,quark:iron_plate_stairs:0,10,quark:iron_plate_stairs:5,10,quark:iron_plate_stairs,10,quark:iron_plate_slab:8,10,quark:iron_plate_stairs:7,10,quark:iron_plate_stairs:1,10,quark:iron_plate_slab,10,quark:iron_plate_stairs:4,10,quark:iron_plate_stairs:2,10,minecraft:iron_bars,50,minecraft:iron_bars,50,minecraft:leaves2:1,100)
RandomBlock(2,5,4,quark:iron_plate:1,70,STAINED_CLAY:15,30,STAINED_CLAY:7,30,STAINED_CLAY:8,30,quark:iron_plate:1,100)
Block(2,5,5,AIR:0)
RandomBlock(2,5,6,minecraft:iron_bars,30,minecraft:iron_bars,30,minecraft:leaves2:1,30,quark:iron_plate_stairs:6,10,quark:iron_plate_stairs:0,10,quark:iron_plate_stairs:5,10,quark:iron_plate_stairs,10,quark:iron_plate_slab:8,10,quark:iron_plate_stairs:7,10,quark:iron_plate_stairs:1,10,quark:iron_plate_slab,10,quark:iron_plate_stairs:4,10,quark:iron_plate_stairs:2,10,minecraft:iron_bars,50,minecraft:iron_bars,50,minecraft:leaves2:1,100)
RandomBlock(2,6,4,minecraft:iron_bars,30,minecraft:iron_bars,30,minecraft:leaves2:1,30,quark:iron_plate_stairs:6,10,quark:iron_plate_stairs:0,10,quark:iron_plate_stairs:5,10,quark:iron_plate_stairs,10,quark:iron_plate_slab:8,10,quark:iron_plate_stairs:7,10,quark:iron_plate_stairs:1,10,quark:iron_plate_slab,10,quark:iron_plate_stairs:4,10,quark:iron_plate_stairs:2,10,minecraft:iron_bars,50,minecraft:iron_bars,50,minecraft:leaves2:1,100)
Block(2,6,5,AIR:0)
RandomBlock(2,6,6,quark:iron_plate:1,70,STAINED_CLAY:15,30,STAINED_CLAY:7,30,STAINED_CLAY:8,30,quark:iron_plate:1,100)
RandomBlock(2,7,4,minecraft:iron_bars,30,minecraft:iron_bars,30,minecraft:leaves2:1,30,quark:iron_plate_stairs:6,10,quark:iron_plate_stairs:0,10,quark:iron_plate_stairs:5,10,quark:iron_plate_stairs,10,quark:iron_plate_slab:8,10,quark:iron_plate_stairs:7,10,quark:iron_plate_stairs:1,10,quark:iron_plate_slab,10,quark:iron_plate_stairs:4,10,quark:iron_plate_stairs:2,10,minecraft:iron_bars,50,minecraft:iron_bars,50,minecraft:leaves2:1,100)
Block(2,7,5,AIR:0)
RandomBlock(2,7,6,minecraft:iron_bars,30,minecraft:iron_bars,30,minecraft:leaves2:1,30,quark:iron_plate_stairs:6,10,quark:iron_plate_stairs:0,10,quark:iron_plate_stairs:5,10,quark:iron_plate_stairs,10,quark:iron_plate_slab:8,10,quark:iron_plate_stairs:7,10,quark:iron_plate_stairs:1,10,quark:iron_plate_slab,10,quark:iron_plate_stairs:4,10,quark:iron_plate_stairs:2,10,minecraft:iron_bars,50,minecraft:iron_bars,50,minecraft:leaves2:1,100)
RandomBlock(2,8,4,minecraft:iron_bars,30,minecraft:iron_bars,30,minecraft:leaves2:1,30,quark:iron_plate_stairs:6,10,quark:iron_plate_stairs:0,10,quark:iron_plate_stairs:5,10,quark:iron_plate_stairs,10,quark:iron_plate_slab:8,10,quark:iron_plate_stairs:7,10,quark:iron_plate_stairs:1,10,quark:iron_plate_slab,10,quark:iron_plate_stairs:4,10,quark:iron_plate_stairs:2,10,minecraft:iron_bars,50,minecraft:iron_bars,50,minecraft:leaves2:1,100)
Block(2,8,5,AIR:0)
RandomBlock(2,8,6,minecraft:iron_bars,30,minecraft:iron_bars,30,minecraft:leaves2:1,30,quark:iron_plate_stairs:6,10,quark:iron_plate_stairs:0,10,quark:iron_plate_stairs:5,10,quark:iron_plate_stairs,10,quark:iron_plate_slab:8,10,quark:iron_plate_stairs:7,10,quark:iron_plate_stairs:1,10,quark:iron_plate_slab,10,quark:iron_plate_stairs:4,10,quark:iron_plate_stairs:2,10,minecraft:iron_bars,50,minecraft:iron_bars,50,minecraft:leaves2:1,100)
RandomBlock(2,9,4,minecraft:iron_bars,30,minecraft:iron_bars,30,minecraft:leaves2:1,30,quark:iron_plate_stairs:6,10,quark:iron_plate_stairs:0,10,quark:iron_plate_stairs:5,10,quark:iron_plate_stairs,10,quark:iron_plate_slab:8,10,quark:iron_plate_stairs:7,10,quark:iron_plate_stairs:1,10,quark:iron_plate_slab,10,quark:iron_plate_stairs:4,10,quark:iron_plate_stairs:2,10,minecraft:iron_bars,50,minecraft:iron_bars,50,minecraft:leaves2:1,100)
Block(2,9,5,AIR:0)
RandomBlock(2,9,6,minecraft:iron_bars,30,minecraft:iron_bars,30,minecraft:leaves2:1,30,quark:iron_plate_stairs:6,10,quark:iron_plate_stairs:0,10,quark:iron_plate_stairs:5,10,quark:iron_plate_stairs,10,quark:iron_plate_slab:8,10,quark:iron_plate_stairs:7,10,quark:iron_plate_stairs:1,10,quark:iron_plate_slab,10,quark:iron_plate_stairs:4,10,quark:iron_plate_stairs:2,10,minecraft:iron_bars,50,minecraft:iron_bars,50,minecraft:leaves2:1,100)
RandomBlock(2,10,4,minecraft:iron_bars,30,minecraft:iron_bars,30,minecraft:leaves2:1,30,quark:iron_plate_stairs:6,10,quark:iron_plate_stairs:0,10,quark:iron_plate_stairs:5,10,quark:iron_plate_stairs,10,quark:iron_plate_slab:8,10,quark:iron_plate_stairs:7,10,quark:iron_plate_stairs:1,10,quark:iron_plate_slab,10,quark:iron_plate_stairs:4,10,quark:iron_plate_stairs:2,10,minecraft:iron_bars,50,minecraft:iron_bars,50,minecraft:leaves2:1,100)
Block(2,10,5,AIR:0)
RandomBlock(2,10,6,quark:iron_plate:1,70,STAINED_CLAY:15,30,STAINED_CLAY:7,30,STAINED_CLAY:8,30,quark:iron_plate:1,100)
RandomBlock(2,11,4,quark:iron_plate:1,70,STAINED_CLAY:15,30,STAINED_CLAY:7,30,STAINED_CLAY:8,30,quark:iron_plate:1,100)
Block(2,11,5,AIR:0)
RandomBlock(2,11,6,quark:iron_plate:1,70,STAINED_CLAY:15,30,STAINED_CLAY:7,30,STAINED_CLAY:8,30,quark:iron_plate:1,100)
RandomBlock(2,12,4,quark:iron_plate:1,70,STAINED_CLAY:15,30,STAINED_CLAY:7,30,STAINED_CLAY:8,30,quark:iron_plate:1,100)
Block(2,12,5,AIR:0)
RandomBlock(2,12,6,quark:iron_plate:1,70,STAINED_CLAY:15,30,STAINED_CLAY:7,30,STAINED_CLAY:8,30,quark:iron_plate:1,100)
RandomBlock(2,13,4,minecraft:iron_bars,30,minecraft:iron_bars,30,minecraft:leaves2:1,30,quark:iron_plate_stairs:6,10,quark:iron_plate_stairs:0,10,quark:iron_plate_stairs:5,10,quark:iron_plate_stairs,10,quark:iron_plate_slab:8,10,quark:iron_plate_stairs:7,10,quark:iron_plate_stairs:1,10,quark:iron_plate_slab,10,quark:iron_plate_stairs:4,10,quark:iron_plate_stairs:2,10,minecraft:iron_bars,50,minecraft:iron_bars,50,minecraft:leaves2:1,100)
Block(2,13,5,AIR:0)
RandomBlock(2,13,6,quark:iron_plate:1,70,STAINED_CLAY:15,30,STAINED_CLAY:7,30,STAINED_CLAY:8,30,quark:iron_plate:1,100)
RandomBlock(2,14,4,quark:iron_plate:1,70,STAINED_CLAY:15,30,STAINED_CLAY:7,30,STAINED_CLAY:8,30,quark:iron_plate:1,100)
Block(2,14,5,AIR:0)
RandomBlock(2,14,6,quark:iron_plate:1,70,STAINED_CLAY:15,30,STAINED_CLAY:7,30,STAINED_CLAY:8,30,quark:iron_plate:1,100)
RandomBlock(2,15,4,minecraft:iron_bars,30,minecraft:iron_bars,30,minecraft:leaves2:1,30,quark:iron_plate_stairs:6,10,quark:iron_plate_stairs:0,10,quark:iron_plate_stairs:5,10,quark:iron_plate_stairs,10,quark:iron_plate_slab:8,10,quark:iron_plate_stairs:7,10,quark:iron_plate_stairs:1,10,quark:iron_plate_slab,10,quark:iron_plate_stairs:4,10,quark:iron_plate_stairs:2,10,minecraft:iron_bars,50,minecraft:iron_bars,50,minecraft:leaves2:1,100)
Block(2,15,5,AIR:0)
RandomBlock(2,15,6,quark:iron_plate:1,70,STAINED_CLAY:15,30,STAINED_CLAY:7,30,STAINED_CLAY:8,30,quark:iron_plate:1,100)
RandomBlock(2,16,4,minecraft:iron_bars,30,minecraft:iron_bars,30,minecraft:leaves2:1,30,quark:iron_plate_stairs:6,10,quark:iron_plate_stairs:0,10,quark:iron_plate_stairs:5,10,quark:iron_plate_stairs,10,quark:iron_plate_slab:8,10,quark:iron_plate_stairs:7,10,quark:iron_plate_stairs:1,10,quark:iron_plate_slab,10,quark:iron_plate_stairs:4,10,quark:iron_plate_stairs:2,10,minecraft:iron_bars,50,minecraft:iron_bars,50,minecraft:leaves2:1,100)
Block(2,16,5,AIR:0)
RandomBlock(2,16,6,quark:iron_plate:1,70,STAINED_CLAY:15,30,STAINED_CLAY:7,30,STAINED_CLAY:8,30,quark:iron_plate:1,100)
RandomBlock(2,17,4,minecraft:iron_bars,30,minecraft:iron_bars,30,minecraft:leaves2:1,30,quark:iron_plate_stairs:6,10,quark:iron_plate_stairs:0,10,quark:iron_plate_stairs:5,10,quark:iron_plate_stairs,10,quark:iron_plate_slab:8,10,quark:iron_plate_stairs:7,10,quark:iron_plate_stairs:1,10,quark:iron_plate_slab,10,quark:iron_plate_stairs:4,10,quark:iron_plate_stairs:2,10,minecraft:iron_bars,50,minecraft:iron_bars,50,minecraft:leaves2:1,100)
Block(2,17,5,AIR:0)
RandomBlock(2,17,6,quark:iron_plate:1,70,STAINED_CLAY:15,30,STAINED_CLAY:7,30,STAINED_CLAY:8,30,quark:iron_plate:1,100)
RandomBlock(2,18,4,minecraft:iron_bars,30,minecraft:iron_bars,30,minecraft:leaves2:1,30,quark:iron_plate_stairs:6,10,quark:iron_plate_stairs:0,10,quark:iron_plate_stairs:5,10,quark:iron_plate_stairs,10,quark:iron_plate_slab:8,10,quark:iron_plate_stairs:7,10,quark:iron_plate_stairs:1,10,quark:iron_plate_slab,10,quark:iron_plate_stairs:4,10,quark:iron_plate_stairs:2,10,minecraft:iron_bars,50,minecraft:iron_bars,50,minecraft:leaves2:1,100)
Block(2,18,5,AIR:0)
RandomBlock(2,18,6,quark:iron_plate:1,70,STAINED_CLAY:15,30,STAINED_CLAY:7,30,STAINED_CLAY:8,30,quark:iron_plate:1,100)
RandomBlock(2,19,4,quark:iron_plate:1,70,STAINED_CLAY:15,30,STAINED_CLAY:7,30,STAINED_CLAY:8,30,quark:iron_plate:1,100)
Block(2,19,5,AIR:0)
RandomBlock(2,19,6,quark:iron_plate:1,70,STAINED_CLAY:15,30,STAINED_CLAY:7,30,STAINED_CLAY:8,30,quark:iron_plate:1,100)
RandomBlock(2,20,4,quark:iron_plate:1,70,STAINED_CLAY:15,30,STAINED_CLAY:7,30,STAINED_CLAY:8,30,quark:iron_plate:1,100)
Block(2,20,5,AIR:0)
RandomBlock(2,20,6,quark:iron_plate:1,70,STAINED_CLAY:15,30,STAINED_CLAY:7,30,STAINED_CLAY:8,30,quark:iron_plate:1,100)
RandomBlock(2,21,4,quark:iron_plate:1,70,STAINED_CLAY:15,30,STAINED_CLAY:7,30,STAINED_CLAY:8,30,quark:iron_plate:1,100)
Block(2,21,5,AIR:0)
RandomBlock(2,21,6,quark:iron_plate:1,70,STAINED_CLAY:15,30,STAINED_CLAY:7,30,STAINED_CLAY:8,30,quark:iron_plate:1,100)
RandomBlock(2,22,4,minecraft:iron_bars,30,minecraft:iron_bars,30,minecraft:leaves2:1,30,quark:iron_plate_stairs:6,10,quark:iron_plate_stairs:0,10,quark:iron_plate_stairs:5,10,quark:iron_plate_stairs,10,quark:iron_plate_slab:8,10,quark:iron_plate_stairs:7,10,quark:iron_plate_stairs:1,10,quark:iron_plate_slab,10,quark:iron_plate_stairs:4,10,quark:iron_plate_stairs:2,10,minecraft:iron_bars,50,minecraft:iron_bars,50,minecraft:leaves2:1,100)
Block(2,22,5,AIR:0)
RandomBlock(2,22,6,quark:iron_plate:1,70,STAINED_CLAY:15,30,STAINED_CLAY:7,30,STAINED_CLAY:8,30,quark:iron_plate:1,100)
RandomBlock(2,23,4,minecraft:iron_bars,30,minecraft:iron_bars,30,minecraft:leaves2:1,30,quark:iron_plate_stairs:6,10,quark:iron_plate_stairs:0,10,quark:iron_plate_stairs:5,10,quark:iron_plate_stairs,10,quark:iron_plate_slab:8,10,quark:iron_plate_stairs:7,10,quark:iron_plate_stairs:1,10,quark:iron_plate_slab,10,quark:iron_plate_stairs:4,10,quark:iron_plate_stairs:2,10,minecraft:iron_bars,50,minecraft:iron_bars,50,minecraft:leaves2:1,100)
Block(2,23,5,AIR:0)
RandomBlock(2,23,6,quark:iron_plate:1,70,STAINED_CLAY:15,30,STAINED_CLAY:7,30,STAINED_CLAY:8,30,quark:iron_plate:1,100)
RandomBlock(2,24,4,minecraft:iron_bars,30,minecraft:iron_bars,30,minecraft:leaves2:1,30,quark:iron_plate_stairs:6,10,quark:iron_plate_stairs:0,10,quark:iron_plate_stairs:5,10,quark:iron_plate_stairs,10,quark:iron_plate_slab:8,10,quark:iron_plate_stairs:7,10,quark:iron_plate_stairs:1,10,quark:iron_plate_slab,10,quark:iron_plate_stairs:4,10,quark:iron_plate_stairs:2,10,minecraft:iron_bars,50,minecraft:iron_bars,50,minecraft:leaves2:1,100)
Block(2,24,5,AIR:0)
RandomBlock(2,24,6,quark:iron_plate:1,70,STAINED_CLAY:15,30,STAINED_CLAY:7,30,STAINED_CLAY:8,30,quark:iron_plate:1,100)
RandomBlock(2,25,4,minecraft:iron_bars,30,minecraft:iron_bars,30,minecraft:leaves2:1,30,quark:iron_plate_stairs:6,10,quark:iron_plate_stairs:0,10,quark:iron_plate_stairs:5,10,quark:iron_plate_stairs,10,quark:iron_plate_slab:8,10,quark:iron_plate_stairs:7,10,quark:iron_plate_stairs:1,10,quark:iron_plate_slab,10,quark:iron_plate_stairs:4,10,quark:iron_plate_stairs:2,10,minecraft:iron_bars,50,minecraft:iron_bars,50,minecraft:leaves2:1,100)
Block(2,25,5,AIR:0)
RandomBlock(2,25,6,quark:iron_plate:1,70,STAINED_CLAY:15,30,STAINED_CLAY:7,30,STAINED_CLAY:8,30,quark:iron_plate:1,100)
RandomBlock(2,26,4,quark:iron_plate:1,70,STAINED_CLAY:15,30,STAINED_CLAY:7,30,STAINED_CLAY:8,30,quark:iron_plate:1,100)
Block(2,26,5,AIR:0)
RandomBlock(2,26,6,quark:iron_plate:1,70,STAINED_CLAY:15,30,STAINED_CLAY:7,30,STAINED_CLAY:8,30,quark:iron_plate:1,100)
RandomBlock(2,27,4,minecraft:iron_bars,30,minecraft:iron_bars,30,minecraft:leaves2:1,30,quark:iron_plate_stairs:6,10,quark:iron_plate_stairs:0,10,quark:iron_plate_stairs:5,10,quark:iron_plate_stairs,10,quark:iron_plate_slab:8,10,quark:iron_plate_stairs:7,10,quark:iron_plate_stairs:1,10,quark:iron_plate_slab,10,quark:iron_plate_stairs:4,10,quark:iron_plate_stairs:2,10,minecraft:iron_bars,50,minecraft:iron_bars,50,minecraft:leaves2:1,100)
Block(2,27,5,AIR:0)
RandomBlock(2,27,6,quark:iron_plate:1,70,STAINED_CLAY:15,30,STAINED_CLAY:7,30,STAINED_CLAY:8,30,quark:iron_plate:1,100)
RandomBlock(2,28,4,minecraft:iron_bars,30,minecraft:iron_bars,30,minecraft:leaves2:1,30,quark:iron_plate_stairs:6,10,quark:iron_plate_stairs:0,10,quark:iron_plate_stairs:5,10,quark:iron_plate_stairs,10,quark:iron_plate_slab:8,10,quark:iron_plate_stairs:7,10,quark:iron_plate_stairs:1,10,quark:iron_plate_slab,10,quark:iron_plate_stairs:4,10,quark:iron_plate_stairs:2,10,minecraft:iron_bars,50,minecraft:iron_bars,50,minecraft:leaves2:1,100)
Block(2,28,5,AIR:0)
RandomBlock(2,28,6,quark:iron_plate:1,70,STAINED_CLAY:15,30,STAINED_CLAY:7,30,STAINED_CLAY:8,30,quark:iron_plate:1,100)
RandomBlock(2,29,4,minecraft:iron_bars,30,minecraft:iron_bars,30,minecraft:leaves2:1,30,quark:iron_plate_stairs:6,10,quark:iron_plate_stairs:0,10,quark:iron_plate_stairs:5,10,quark:iron_plate_stairs,10,quark:iron_plate_slab:8,10,quark:iron_plate_stairs:7,10,quark:iron_plate_stairs:1,10,quark:iron_plate_slab,10,quark:iron_plate_stairs:4,10,quark:iron_plate_stairs:2,10,minecraft:iron_bars,50,minecraft:iron_bars,50,minecraft:leaves2:1,100)
Block(2,29,5,AIR:0)
RandomBlock(2,29,6,quark:iron_plate:1,70,STAINED_CLAY:15,30,STAINED_CLAY:7,30,STAINED_CLAY:8,30,quark:iron_plate:1,100)
RandomBlock(2,30,4,minecraft:iron_bars,30,minecraft:iron_bars,30,minecraft:leaves2:1,30,quark:iron_plate_stairs:6,10,quark:iron_plate_stairs:0,10,quark:iron_plate_stairs:5,10,quark:iron_plate_stairs,10,quark:iron_plate_slab:8,10,quark:iron_plate_stairs:7,10,quark:iron_plate_stairs:1,10,quark:iron_plate_slab,10,quark:iron_plate_stairs:4,10,quark:iron_plate_stairs:2,10,minecraft:iron_bars,50,minecraft:iron_bars,50,minecraft:leaves2:1,100)
Block(2,30,5,AIR:0)
RandomBlock(2,30,6,quark:iron_plate:1,70,STAINED_CLAY:15,30,STAINED_CLAY:7,30,STAINED_CLAY:8,30,quark:iron_plate:1,100)
RandomBlock(2,31,4,quark:iron_plate:1,70,STAINED_CLAY:15,30,STAINED_CLAY:7,30,STAINED_CLAY:8,30,quark:iron_plate:1,100)
Block(2,31,5,AIR:0)
RandomBlock(2,31,6,quark:iron_plate:1,70,STAINED_CLAY:15,30,STAINED_CLAY:7,30,STAINED_CLAY:8,30,quark:iron_plate:1,100)
RandomBlock(2,32,4,minecraft:iron_bars,30,minecraft:iron_bars,30,minecraft:leaves2:1,30,quark:iron_plate_stairs:6,10,quark:iron_plate_stairs:0,10,quark:iron_plate_stairs:5,10,quark:iron_plate_stairs,10,quark:iron_plate_slab:8,10,quark:iron_plate_stairs:7,10,quark:iron_plate_stairs:1,10,quark:iron_plate_slab,10,quark:iron_plate_stairs:4,10,quark:iron_plate_stairs:2,10,minecraft:iron_bars,50,minecraft:iron_bars,50,minecraft:leaves2:1,100)
Block(2,32,5,AIR:0)
RandomBlock(2,32,6,quark:iron_plate:1,70,STAINED_CLAY:15,30,STAINED_CLAY:7,30,STAINED_CLAY:8,30,quark:iron_plate:1,100)
RandomBlock(2,33,4,quark:iron_plate:1,70,STAINED_CLAY:15,30,STAINED_CLAY:7,30,STAINED_CLAY:8,30,quark:iron_plate:1,100)
Block(2,33,5,AIR:0)
RandomBlock(2,33,6,quark:iron_plate:1,70,STAINED_CLAY:15,30,STAINED_CLAY:7,30,STAINED_CLAY:8,30,quark:iron_plate:1,100)
RandomBlock(2,34,4,quark:iron_plate:1,70,STAINED_CLAY:15,30,STAINED_CLAY:7,30,STAINED_CLAY:8,30,quark:iron_plate:1,100)
Block(2,34,5,AIR:0)
RandomBlock(2,34,6,quark:iron_plate:1,70,STAINED_CLAY:15,30,STAINED_CLAY:7,30,STAINED_CLAY:8,30,quark:iron_plate:1,100)
RandomBlock(2,35,4,quark:iron_plate:1,70,STAINED_CLAY:15,30,STAINED_CLAY:7,30,STAINED_CLAY:8,30,quark:iron_plate:1,100)
Block(2,35,5,AIR:0)
RandomBlock(2,35,6,quark:iron_plate:1,70,STAINED_CLAY:15,30,STAINED_CLAY:7,30,STAINED_CLAY:8,30,quark:iron_plate:1,100)
RandomBlock(2,36,4,minecraft:iron_bars,30,minecraft:iron_bars,30,minecraft:leaves2:1,30,quark:iron_plate_stairs:6,10,quark:iron_plate_stairs:0,10,quark:iron_plate_stairs:5,10,quark:iron_plate_stairs,10,quark:iron_plate_slab:8,10,quark:iron_plate_stairs:7,10,quark:iron_plate_stairs:1,10,quark:iron_plate_slab,10,quark:iron_plate_stairs:4,10,quark:iron_plate_stairs:2,10,minecraft:iron_bars,50,minecraft:iron_bars,50,minecraft:leaves2:1,100)
Block(2,36,5,AIR:0)
RandomBlock(2,36,6,minecraft:iron_bars,30,minecraft:iron_bars,30,minecraft:leaves2:1,30,quark:iron_plate_stairs:6,10,quark:iron_plate_stairs:0,10,quark:iron_plate_stairs:5,10,quark:iron_plate_stairs,10,quark:iron_plate_slab:8,10,quark:iron_plate_stairs:7,10,quark:iron_plate_stairs:1,10,quark:iron_plate_slab,10,quark:iron_plate_stairs:4,10,quark:iron_plate_stairs:2,10,minecraft:iron_bars,50,minecraft:iron_bars,50,minecraft:leaves2:1,100)
RandomBlock(2,37,4,quark:iron_plate:1,70,STAINED_CLAY:15,30,STAINED_CLAY:7,30,STAINED_CLAY:8,30,quark:iron_plate:1,100)
Block(2,37,5,AIR:0)
RandomBlock(2,37,6,minecraft:iron_bars,30,minecraft:iron_bars,30,minecraft:leaves2:1,30,quark:iron_plate_stairs:6,10,quark:iron_plate_stairs:0,10,quark:iron_plate_stairs:5,10,quark:iron_plate_stairs,10,quark:iron_plate_slab:8,10,quark:iron_plate_stairs:7,10,quark:iron_plate_stairs:1,10,quark:iron_plate_slab,10,quark:iron_plate_stairs:4,10,quark:iron_plate_stairs:2,10,minecraft:iron_bars,50,minecraft:iron_bars,50,minecraft:leaves2:1,100)
RandomBlock(2,38,4,minecraft:iron_bars,30,minecraft:iron_bars,30,minecraft:leaves2:1,30,quark:iron_plate_stairs:6,10,quark:iron_plate_stairs:0,10,quark:iron_plate_stairs:5,10,quark:iron_plate_stairs,10,quark:iron_plate_slab:8,10,quark:iron_plate_stairs:7,10,quark:iron_plate_stairs:1,10,quark:iron_plate_slab,10,quark:iron_plate_stairs:4,10,quark:iron_plate_stairs:2,10,minecraft:iron_bars,50,minecraft:iron_bars,50,minecraft:leaves2:1,100)
Block(2,38,5,AIR:0)
RandomBlock(2,38,6,quark:iron_plate:1,70,STAINED_CLAY:15,30,STAINED_CLAY:7,30,STAINED_CLAY:8,30,quark:iron_plate:1,100)
RandomBlock(2,39,4,quark:iron_plate:1,70,STAINED_CLAY:15,30,STAINED_CLAY:7,30,STAINED_CLAY:8,30,quark:iron_plate:1,100)
Block(2,39,5,AIR:0)
RandomBlock(2,39,6,quark:iron_plate:1,70,STAINED_CLAY:15,30,STAINED_CLAY:7,30,STAINED_CLAY:8,30,quark:iron_plate:1,100)
RandomBlock(2,40,4,minecraft:iron_bars,30,minecraft:iron_bars,30,minecraft:leaves2:1,30,quark:iron_plate_stairs:6,10,quark:iron_plate_stairs:0,10,quark:iron_plate_stairs:5,10,quark:iron_plate_stairs,10,quark:iron_plate_slab:8,10,quark:iron_plate_stairs:7,10,quark:iron_plate_stairs:1,10,quark:iron_plate_slab,10,quark:iron_plate_stairs:4,10,quark:iron_plate_stairs:2,10,minecraft:iron_bars,50,minecraft:iron_bars,50,minecraft:leaves2:1,100)
Block(2,40,5,AIR:0)
RandomBlock(2,40,6,quark:iron_plate:1,70,STAINED_CLAY:15,30,STAINED_CLAY:7,30,STAINED_CLAY:8,30,quark:iron_plate:1,100)
RandomBlock(2,41,4,minecraft:iron_bars,30,minecraft:iron_bars,30,minecraft:leaves2:1,30,quark:iron_plate_stairs:6,10,quark:iron_plate_stairs:0,10,quark:iron_plate_stairs:5,10,quark:iron_plate_stairs,10,quark:iron_plate_slab:8,10,quark:iron_plate_stairs:7,10,quark:iron_plate_stairs:1,10,quark:iron_plate_slab,10,quark:iron_plate_stairs:4,10,quark:iron_plate_stairs:2,10,minecraft:iron_bars,50,minecraft:iron_bars,50,minecraft:leaves2:1,100)
Block(2,41,5,AIR:0)
RandomBlock(2,41,6,quark:iron_plate:1,70,STAINED_CLAY:15,30,STAINED_CLAY:7,30,STAINED_CLAY:8,30,quark:iron_plate:1,100)
RandomBlock(2,42,4,minecraft:iron_bars,30,minecraft:iron_bars,30,minecraft:leaves2:1,30,quark:iron_plate_stairs:6,10,quark:iron_plate_stairs:0,10,quark:iron_plate_stairs:5,10,quark:iron_plate_stairs,10,quark:iron_plate_slab:8,10,quark:iron_plate_stairs:7,10,quark:iron_plate_stairs:1,10,quark:iron_plate_slab,10,quark:iron_plate_stairs:4,10,quark:iron_plate_stairs:2,10,minecraft:iron_bars,50,minecraft:iron_bars,50,minecraft:leaves2:1,100)
Block(2,42,5,AIR:0)
RandomBlock(2,42,6,minecraft:iron_bars,30,minecraft:iron_bars,30,minecraft:leaves2:1,30,quark:iron_plate_stairs:6,10,quark:iron_plate_stairs:0,10,quark:iron_plate_stairs:5,10,quark:iron_plate_stairs,10,quark:iron_plate_slab:8,10,quark:iron_plate_stairs:7,10,quark:iron_plate_stairs:1,10,quark:iron_plate_slab,10,quark:iron_plate_stairs:4,10,quark:iron_plate_stairs:2,10,minecraft:iron_bars,50,minecraft:iron_bars,50,minecraft:leaves2:1,100)
RandomBlock(2,43,4,minecraft:iron_bars,30,minecraft:iron_bars,30,minecraft:leaves2:1,30,quark:iron_plate_stairs:6,10,quark:iron_plate_stairs:0,10,quark:iron_plate_stairs:5,10,quark:iron_plate_stairs,10,quark:iron_plate_slab:8,10,quark:iron_plate_stairs:7,10,quark:iron_plate_stairs:1,10,quark:iron_plate_slab,10,quark:iron_plate_stairs:4,10,quark:iron_plate_stairs:2,10,minecraft:iron_bars,50,minecraft:iron_bars,50,minecraft:leaves2:1,100)
Block(2,43,5,AIR:0)
RandomBlock(2,43,6,minecraft:iron_bars,30,minecraft:iron_bars,30,minecraft:leaves2:1,30,quark:iron_plate_stairs:6,10,quark:iron_plate_stairs:0,10,quark:iron_plate_stairs:5,10,quark:iron_plate_stairs,10,quark:iron_plate_slab:8,10,quark:iron_plate_stairs:7,10,quark:iron_plate_stairs:1,10,quark:iron_plate_slab,10,quark:iron_plate_stairs:4,10,quark:iron_plate_stairs:2,10,minecraft:iron_bars,50,minecraft:iron_bars,50,minecraft:leaves2:1,100)
RandomBlock(2,44,4,minecraft:iron_bars,30,minecraft:iron_bars,30,minecraft:leaves2:1,30,quark:iron_plate_stairs:6,10,quark:iron_plate_stairs:0,10,quark:iron_plate_stairs:5,10,quark:iron_plate_stairs,10,quark:iron_plate_slab:8,10,quark:iron_plate_stairs:7,10,quark:iron_plate_stairs:1,10,quark:iron_plate_slab,10,quark:iron_plate_stairs:4,10,quark:iron_plate_stairs:2,10,minecraft:iron_bars,50,minecraft:iron_bars,50,minecraft:leaves2:1,100)
Block(2,44,5,AIR:0)
RandomBlock(2,44,6,minecraft:iron_bars,30,minecraft:iron_bars,30,minecraft:leaves2:1,30,quark:iron_plate_stairs:6,10,quark:iron_plate_stairs:0,10,quark:iron_plate_stairs:5,10,quark:iron_plate_stairs,10,quark:iron_plate_slab:8,10,quark:iron_plate_stairs:7,10,quark:iron_plate_stairs:1,10,quark:iron_plate_slab,10,quark:iron_plate_stairs:4,10,quark:iron_plate_stairs:2,10,minecraft:iron_bars,50,minecraft:iron_bars,50,minecraft:leaves2:1,100)
RandomBlock(2,45,4,minecraft:iron_bars,30,minecraft:iron_bars,30,minecraft:leaves2:1,30,quark:iron_plate_stairs:6,10,quark:iron_plate_stairs:0,10,quark:iron_plate_stairs:5,10,quark:iron_plate_stairs,10,quark:iron_plate_slab:8,10,quark:iron_plate_stairs:7,10,quark:iron_plate_stairs:1,10,quark:iron_plate_slab,10,quark:iron_plate_stairs:4,10,quark:iron_plate_stairs:2,10,minecraft:iron_bars,50,minecraft:iron_bars,50,minecraft:leaves2:1,100)
Block(2,45,5,AIR:0)
RandomBlock(2,45,6,minecraft:iron_bars,30,minecraft:iron_bars,30,minecraft:leaves2:1,30,quark:iron_plate_stairs:6,10,quark:iron_plate_stairs:0,10,quark:iron_plate_stairs:5,10,quark:iron_plate_stairs,10,quark:iron_plate_slab:8,10,quark:iron_plate_stairs:7,10,quark:iron_plate_stairs:1,10,quark:iron_plate_slab,10,quark:iron_plate_stairs:4,10,quark:iron_plate_stairs:2,10,minecraft:iron_bars,50,minecraft:iron_bars,50,minecraft:leaves2:1,100)
RandomBlock(2,46,4,minecraft:iron_bars,30,minecraft:iron_bars,30,minecraft:leaves2:1,30,quark:iron_plate_stairs:6,10,quark:iron_plate_stairs:0,10,quark:iron_plate_stairs:5,10,quark:iron_plate_stairs,10,quark:iron_plate_slab:8,10,quark:iron_plate_stairs:7,10,quark:iron_plate_stairs:1,10,quark:iron_plate_slab,10,quark:iron_plate_stairs:4,10,quark:iron_plate_stairs:2,10,minecraft:iron_bars,50,minecraft:iron_bars,50,minecraft:leaves2:1,100)
Block(2,46,5,AIR:0)
RandomBlock(2,46,6,minecraft:iron_bars,30,minecraft:iron_bars,30,minecraft:leaves2:1,30,quark:iron_plate_stairs:6,10,quark:iron_plate_stairs:0,10,quark:iron_plate_stairs:5,10,quark:iron_plate_stairs,10,quark:iron_plate_slab:8,10,quark:iron_plate_stairs:7,10,quark:iron_plate_stairs:1,10,quark:iron_plate_slab,10,quark:iron_plate_stairs:4,10,quark:iron_plate_stairs:2,10,minecraft:iron_bars,50,minecraft:iron_bars,50,minecraft:leaves2:1,100)
RandomBlock(2,47,4,quark:iron_plate:1,70,STAINED_CLAY:15,30,STAINED_CLAY:7,30,STAINED_CLAY:8,30,quark:iron_plate:1,100)
Block(2,47,5,AIR:0)
RandomBlock(2,47,6,minecraft:iron_bars,30,minecraft:iron_bars,30,minecraft:leaves2:1,30,quark:iron_plate_stairs:6,10,quark:iron_plate_stairs:0,10,quark:iron_plate_stairs:5,10,quark:iron_plate_stairs,10,quark:iron_plate_slab:8,10,quark:iron_plate_stairs:7,10,quark:iron_plate_stairs:1,10,quark:iron_plate_slab,10,quark:iron_plate_stairs:4,10,quark:iron_plate_stairs:2,10,minecraft:iron_bars,50,minecraft:iron_bars,50,minecraft:leaves2:1,100)
RandomBlock(2,48,4,minecraft:iron_bars,30,minecraft:iron_bars,30,minecraft:leaves2:1,30,quark:iron_plate_stairs:6,10,quark:iron_plate_stairs:0,10,quark:iron_plate_stairs:5,10,quark:iron_plate_stairs,10,quark:iron_plate_slab:8,10,quark:iron_plate_stairs:7,10,quark:iron_plate_stairs:1,10,quark:iron_plate_slab,10,quark:iron_plate_stairs:4,10,quark:iron_plate_stairs:2,10,minecraft:iron_bars,50,minecraft:iron_bars,50,minecraft:leaves2:1,100)
Block(2,48,5,AIR:0)
RandomBlock(2,48,6,quark:iron_plate:1,70,STAINED_CLAY:15,30,STAINED_CLAY:7,30,STAINED_CLAY:8,30,quark:iron_plate:1,100)
RandomBlock(2,49,4,quark:iron_plate:1,70,STAINED_CLAY:15,30,STAINED_CLAY:7,30,STAINED_CLAY:8,30,quark:iron_plate:1,100)
Block(2,49,5,AIR:0)
RandomBlock(2,49,6,minecraft:iron_bars,30,minecraft:iron_bars,30,minecraft:leaves2:1,30,quark:iron_plate_stairs:6,10,quark:iron_plate_stairs:0,10,quark:iron_plate_stairs:5,10,quark:iron_plate_stairs,10,quark:iron_plate_slab:8,10,quark:iron_plate_stairs:7,10,quark:iron_plate_stairs:1,10,quark:iron_plate_slab,10,quark:iron_plate_stairs:4,10,quark:iron_plate_stairs:2,10,minecraft:iron_bars,50,minecraft:iron_bars,50,minecraft:leaves2:1,100)
RandomBlock(2,50,4,quark:iron_plate:1,70,STAINED_CLAY:15,30,STAINED_CLAY:7,30,STAINED_CLAY:8,30,quark:iron_plate:1,100)
Block(2,50,5,AIR:0)
RandomBlock(2,50,6,minecraft:iron_bars,30,minecraft:iron_bars,30,minecraft:leaves2:1,30,quark:iron_plate_stairs:6,10,quark:iron_plate_stairs:0,10,quark:iron_plate_stairs:5,10,quark:iron_plate_stairs,10,quark:iron_plate_slab:8,10,quark:iron_plate_stairs:7,10,quark:iron_plate_stairs:1,10,quark:iron_plate_slab,10,quark:iron_plate_stairs:4,10,quark:iron_plate_stairs:2,10,minecraft:iron_bars,50,minecraft:iron_bars,50,minecraft:leaves2:1,100)
RandomBlock(2,51,4,minecraft:iron_bars,30,minecraft:iron_bars,30,minecraft:leaves2:1,30,quark:iron_plate_stairs:6,10,quark:iron_plate_stairs:0,10,quark:iron_plate_stairs:5,10,quark:iron_plate_stairs,10,quark:iron_plate_slab:8,10,quark:iron_plate_stairs:7,10,quark:iron_plate_stairs:1,10,quark:iron_plate_slab,10,quark:iron_plate_stairs:4,10,quark:iron_plate_stairs:2,10,minecraft:iron_bars,50,minecraft:iron_bars,50,minecraft:leaves2:1,100)
Block(2,51,5,AIR:0)
RandomBlock(2,51,6,minecraft:iron_bars,30,minecraft:iron_bars,30,minecraft:leaves2:1,30,quark:iron_plate_stairs:6,10,quark:iron_plate_stairs:0,10,quark:iron_plate_stairs:5,10,quark:iron_plate_stairs,10,quark:iron_plate_slab:8,10,quark:iron_plate_stairs:7,10,quark:iron_plate_stairs:1,10,quark:iron_plate_slab,10,quark:iron_plate_stairs:4,10,quark:iron_plate_stairs:2,10,minecraft:iron_bars,50,minecraft:iron_bars,50,minecraft:leaves2:1,100)
RandomBlock(2,52,4,quark:iron_plate:1,70,STAINED_CLAY:15,30,STAINED_CLAY:7,30,STAINED_CLAY:8,30,quark:iron_plate:1,100)
Block(2,52,5,AIR:0)
RandomBlock(2,52,6,minecraft:iron_bars,30,minecraft:iron_bars,30,minecraft:leaves2:1,30,quark:iron_plate_stairs:6,10,quark:iron_plate_stairs:0,10,quark:iron_plate_stairs:5,10,quark:iron_plate_stairs,10,quark:iron_plate_slab:8,10,quark:iron_plate_stairs:7,10,quark:iron_plate_stairs:1,10,quark:iron_plate_slab,10,quark:iron_plate_stairs:4,10,quark:iron_plate_stairs:2,10,minecraft:iron_bars,50,minecraft:iron_bars,50,minecraft:leaves2:1,100)
RandomBlock(2,53,4,quark:iron_plate:1,70,STAINED_CLAY:15,30,STAINED_CLAY:7,30,STAINED_CLAY:8,30,quark:iron_plate:1,100)
Block(2,53,5,AIR:0)
RandomBlock(2,53,6,quark:iron_plate:1,70,STAINED_CLAY:15,30,STAINED_CLAY:7,30,STAINED_CLAY:8,30,quark:iron_plate:1,100)
RandomBlock(2,54,4,quark:iron_plate:1,70,STAINED_CLAY:15,30,STAINED_CLAY:7,30,STAINED_CLAY:8,30,quark:iron_plate:1,100)
Block(2,54,5,AIR:0)
RandomBlock(2,54,6,quark:iron_plate:1,70,STAINED_CLAY:15,30,STAINED_CLAY:7,30,STAINED_CLAY:8,30,quark:iron_plate:1,100)
RandomBlock(2,55,4,quark:iron_plate:1,70,STAINED_CLAY:15,30,STAINED_CLAY:7,30,STAINED_CLAY:8,30,quark:iron_plate:1,100)
Block(2,55,5,AIR:0)
RandomBlock(2,55,6,quark:iron_plate:1,70,STAINED_CLAY:15,30,STAINED_CLAY:7,30,STAINED_CLAY:8,30,quark:iron_plate:1,100)
RandomBlock(2,56,4,quark:iron_plate:1,70,STAINED_CLAY:15,30,STAINED_CLAY:7,30,STAINED_CLAY:8,30,quark:iron_plate:1,100)
Block(2,56,5,AIR:0)
RandomBlock(2,56,6,quark:iron_plate:1,70,STAINED_CLAY:15,30,STAINED_CLAY:7,30,STAINED_CLAY:8,30,quark:iron_plate:1,100)
RandomBlock(2,57,4,quark:iron_plate:1,70,STAINED_CLAY:15,30,STAINED_CLAY:7,30,STAINED_CLAY:8,30,quark:iron_plate:1,100)
Block(2,57,5,AIR:0)
RandomBlock(2,57,6,quark:iron_plate:1,70,STAINED_CLAY:15,30,STAINED_CLAY:7,30,STAINED_CLAY:8,30,quark:iron_plate:1,100)
RandomBlock(2,58,4,minecraft:iron_bars,30,minecraft:iron_bars,30,minecraft:leaves2:1,30,quark:iron_plate_stairs:6,10,quark:iron_plate_stairs:0,10,quark:iron_plate_stairs:5,10,quark:iron_plate_stairs,10,quark:iron_plate_slab:8,10,quark:iron_plate_stairs:7,10,quark:iron_plate_stairs:1,10,quark:iron_plate_slab,10,quark:iron_plate_stairs:4,10,quark:iron_plate_stairs:2,10,minecraft:iron_bars,50,minecraft:iron_bars,50,minecraft:leaves2:1,100)
Block(2,58,5,AIR:0)
RandomBlock(2,58,6,quark:iron_plate:1,70,STAINED_CLAY:15,30,STAINED_CLAY:7,30,STAINED_CLAY:8,30,quark:iron_plate:1,100)
RandomBlock(2,59,4,quark:iron_plate:1,70,STAINED_CLAY:15,30,STAINED_CLAY:7,30,STAINED_CLAY:8,30,quark:iron_plate:1,100)
Block(2,59,5,AIR:0)
RandomBlock(2,59,6,quark:iron_plate:1,70,STAINED_CLAY:15,30,STAINED_CLAY:7,30,STAINED_CLAY:8,30,quark:iron_plate:1,100)
RandomBlock(2,60,4,quark:iron_plate:1,70,STAINED_CLAY:15,30,STAINED_CLAY:7,30,STAINED_CLAY:8,30,quark:iron_plate:1,100)
Block(2,60,5,AIR:0)
RandomBlock(2,60,6,quark:iron_plate:1,70,STAINED_CLAY:15,30,STAINED_CLAY:7,30,STAINED_CLAY:8,30,quark:iron_plate:1,100)
RandomBlock(2,61,4,quark:iron_plate:1,70,STAINED_CLAY:15,30,STAINED_CLAY:7,30,STAINED_CLAY:8,30,quark:iron_plate:1,100)
Block(2,61,5,AIR:0)
RandomBlock(2,61,6,quark:iron_plate:1,70,STAINED_CLAY:15,30,STAINED_CLAY:7,30,STAINED_CLAY:8,30,quark:iron_plate:1,100)
RandomBlock(2,62,4,quark:iron_plate:1,70,STAINED_CLAY:15,30,STAINED_CLAY:7,30,STAINED_CLAY:8,30,quark:iron_plate:1,100)
Block(2,62,5,AIR:0)
RandomBlock(2,62,6,quark:iron_plate:1,70,STAINED_CLAY:15,30,STAINED_CLAY:7,30,STAINED_CLAY:8,30,quark:iron_plate:1,100)
RandomBlock(2,63,4,quark:iron_plate:1,70,STAINED_CLAY:15,30,STAINED_CLAY:7,30,STAINED_CLAY:8,30,quark:iron_plate:1,100)
Block(2,63,5,AIR:0)
RandomBlock(2,63,6,quark:iron_plate:1,70,STAINED_CLAY:15,30,STAINED_CLAY:7,30,STAINED_CLAY:8,30,quark:iron_plate:1,100)
RandomBlock(2,64,4,quark:iron_plate:1,70,STAINED_CLAY:15,30,STAINED_CLAY:7,30,STAINED_CLAY:8,30,quark:iron_plate:1,100)
Block(2,64,5,AIR:0)
RandomBlock(2,64,6,quark:iron_plate:1,70,STAINED_CLAY:15,30,STAINED_CLAY:7,30,STAINED_CLAY:8,30,quark:iron_plate:1,100)
RandomBlock(2,65,4,quark:iron_plate:1,70,STAINED_CLAY:15,30,STAINED_CLAY:7,30,STAINED_CLAY:8,30,quark:iron_plate:1,100)
Block(2,65,5,AIR:0)
RandomBlock(2,65,6,quark:iron_plate:1,70,STAINED_CLAY:15,30,STAINED_CLAY:7,30,STAINED_CLAY:8,30,quark:iron_plate:1,100)
RandomBlock(3,0,4,quark:iron_plate:1,70,STAINED_CLAY:15,30,STAINED_CLAY:7,30,STAINED_CLAY:8,30,quark:iron_plate:1,100)
RandomBlock(3,0,5,quark:iron_plate:1,70,STAINED_CLAY:15,30,STAINED_CLAY:7,30,STAINED_CLAY:8,30,quark:iron_plate:1,100)
RandomBlock(3,0,6,quark:iron_plate:1,70,STAINED_CLAY:15,30,STAINED_CLAY:7,30,STAINED_CLAY:8,30,quark:iron_plate:1,100)
RandomBlock(3,1,4,minecraft:iron_bars,30,minecraft:iron_bars,30,minecraft:leaves2:1,30,quark:iron_plate_stairs:6,10,quark:iron_plate_stairs:0,10,quark:iron_plate_stairs:5,10,quark:iron_plate_stairs,10,quark:iron_plate_slab:8,10,quark:iron_plate_stairs:7,10,quark:iron_plate_stairs:1,10,quark:iron_plate_slab,10,quark:iron_plate_stairs:4,10,quark:iron_plate_stairs:2,10,minecraft:iron_bars,50,minecraft:iron_bars,50,minecraft:leaves2:1,100)
RandomBlock(3,1,5,quark:iron_plate:1,70,STAINED_CLAY:15,30,STAINED_CLAY:7,30,STAINED_CLAY:8,30,quark:iron_plate:1,100)
RandomBlock(3,1,6,quark:iron_plate:1,70,STAINED_CLAY:15,30,STAINED_CLAY:7,30,STAINED_CLAY:8,30,quark:iron_plate:1,100)
RandomBlock(3,2,4,minecraft:iron_bars,30,minecraft:iron_bars,30,minecraft:leaves2:1,30,quark:iron_plate_stairs:6,10,quark:iron_plate_stairs:0,10,quark:iron_plate_stairs:5,10,quark:iron_plate_stairs,10,quark:iron_plate_slab:8,10,quark:iron_plate_stairs:7,10,quark:iron_plate_stairs:1,10,quark:iron_plate_slab,10,quark:iron_plate_stairs:4,10,quark:iron_plate_stairs:2,10,minecraft:iron_bars,50,minecraft:iron_bars,50,minecraft:leaves2:1,100)
RandomBlock(3,2,5,minecraft:iron_bars,30,minecraft:iron_bars,30,minecraft:leaves2:1,30,quark:iron_plate_stairs:6,10,quark:iron_plate_stairs:0,10,quark:iron_plate_stairs:5,10,quark:iron_plate_stairs,10,quark:iron_plate_slab:8,10,quark:iron_plate_stairs:7,10,quark:iron_plate_stairs:1,10,quark:iron_plate_slab,10,quark:iron_plate_stairs:4,10,quark:iron_plate_stairs:2,10,minecraft:iron_bars,50,minecraft:iron_bars,50,minecraft:leaves2:1,100)
RandomBlock(3,2,6,quark:iron_plate:1,70,STAINED_CLAY:15,30,STAINED_CLAY:7,30,STAINED_CLAY:8,30,quark:iron_plate:1,100)
RandomBlock(3,3,4,minecraft:iron_bars,30,minecraft:iron_bars,30,minecraft:leaves2:1,30,quark:iron_plate_stairs:6,10,quark:iron_plate_stairs:0,10,quark:iron_plate_stairs:5,10,quark:iron_plate_stairs,10,quark:iron_plate_slab:8,10,quark:iron_plate_stairs:7,10,quark:iron_plate_stairs:1,10,quark:iron_plate_slab,10,quark:iron_plate_stairs:4,10,quark:iron_plate_stairs:2,10,minecraft:iron_bars,50,minecraft:iron_bars,50,minecraft:leaves2:1,100)
RandomBlock(3,3,5,minecraft:iron_bars,30,minecraft:iron_bars,30,minecraft:leaves2:1,30,quark:iron_plate_stairs:6,10,quark:iron_plate_stairs:0,10,quark:iron_plate_stairs:5,10,quark:iron_plate_stairs,10,quark:iron_plate_slab:8,10,quark:iron_plate_stairs:7,10,quark:iron_plate_stairs:1,10,quark:iron_plate_slab,10,quark:iron_plate_stairs:4,10,quark:iron_plate_stairs:2,10,minecraft:iron_bars,50,minecraft:iron_bars,50,minecraft:leaves2:1,100)
RandomBlock(3,3,6,quark:iron_plate:1,70,STAINED_CLAY:15,30,STAINED_CLAY:7,30,STAINED_CLAY:8,30,quark:iron_plate:1,100)
RandomBlock(3,4,4,minecraft:iron_bars,30,minecraft:iron_bars,30,minecraft:leaves2:1,30,quark:iron_plate_stairs:6,10,quark:iron_plate_stairs:0,10,quark:iron_plate_stairs:5,10,quark:iron_plate_stairs,10,quark:iron_plate_slab:8,10,quark:iron_plate_stairs:7,10,quark:iron_plate_stairs:1,10,quark:iron_plate_slab,10,quark:iron_plate_stairs:4,10,quark:iron_plate_stairs:2,10,minecraft:iron_bars,50,minecraft:iron_bars,50,minecraft:leaves2:1,100)
RandomBlock(3,4,5,quark:iron_plate:1,70,STAINED_CLAY:15,30,STAINED_CLAY:7,30,STAINED_CLAY:8,30,quark:iron_plate:1,100)
RandomBlock(3,4,6,minecraft:iron_bars,30,minecraft:iron_bars,30,minecraft:leaves2:1,30,quark:iron_plate_stairs:6,10,quark:iron_plate_stairs:0,10,quark:iron_plate_stairs:5,10,quark:iron_plate_stairs,10,quark:iron_plate_slab:8,10,quark:iron_plate_stairs:7,10,quark:iron_plate_stairs:1,10,quark:iron_plate_slab,10,quark:iron_plate_stairs:4,10,quark:iron_plate_stairs:2,10,minecraft:iron_bars,50,minecraft:iron_bars,50,minecraft:leaves2:1,100)
RandomBlock(3,5,4,minecraft:iron_bars,30,minecraft:iron_bars,30,minecraft:leaves2:1,30,quark:iron_plate_stairs:6,10,quark:iron_plate_stairs:0,10,quark:iron_plate_stairs:5,10,quark:iron_plate_stairs,10,quark:iron_plate_slab:8,10,quark:iron_plate_stairs:7,10,quark:iron_plate_stairs:1,10,quark:iron_plate_slab,10,quark:iron_plate_stairs:4,10,quark:iron_plate_stairs:2,10,minecraft:iron_bars,50,minecraft:iron_bars,50,minecraft:leaves2:1,100)
RandomBlock(3,5,5,quark:iron_plate:1,70,STAINED_CLAY:15,30,STAINED_CLAY:7,30,STAINED_CLAY:8,30,quark:iron_plate:1,100)
RandomBlock(3,5,6,quark:iron_plate:1,70,STAINED_CLAY:15,30,STAINED_CLAY:7,30,STAINED_CLAY:8,30,quark:iron_plate:1,100)
RandomBlock(3,6,4,minecraft:iron_bars,30,minecraft:iron_bars,30,minecraft:leaves2:1,30,quark:iron_plate_stairs:6,10,quark:iron_plate_stairs:0,10,quark:iron_plate_stairs:5,10,quark:iron_plate_stairs,10,quark:iron_plate_slab:8,10,quark:iron_plate_stairs:7,10,quark:iron_plate_stairs:1,10,quark:iron_plate_slab,10,quark:iron_plate_stairs:4,10,quark:iron_plate_stairs:2,10,minecraft:iron_bars,50,minecraft:iron_bars,50,minecraft:leaves2:1,100)
RandomBlock(3,6,5,minecraft:iron_bars,30,minecraft:iron_bars,30,minecraft:leaves2:1,30,quark:iron_plate_stairs:6,10,quark:iron_plate_stairs:0,10,quark:iron_plate_stairs:5,10,quark:iron_plate_stairs,10,quark:iron_plate_slab:8,10,quark:iron_plate_stairs:7,10,quark:iron_plate_stairs:1,10,quark:iron_plate_slab,10,quark:iron_plate_stairs:4,10,quark:iron_plate_stairs:2,10,minecraft:iron_bars,50,minecraft:iron_bars,50,minecraft:leaves2:1,100)
RandomBlock(3,6,6,quark:iron_plate:1,70,STAINED_CLAY:15,30,STAINED_CLAY:7,30,STAINED_CLAY:8,30,quark:iron_plate:1,100)
RandomBlock(3,7,4,minecraft:iron_bars,30,minecraft:iron_bars,30,minecraft:leaves2:1,30,quark:iron_plate_stairs:6,10,quark:iron_plate_stairs:0,10,quark:iron_plate_stairs:5,10,quark:iron_plate_stairs,10,quark:iron_plate_slab:8,10,quark:iron_plate_stairs:7,10,quark:iron_plate_stairs:1,10,quark:iron_plate_slab,10,quark:iron_plate_stairs:4,10,quark:iron_plate_stairs:2,10,minecraft:iron_bars,50,minecraft:iron_bars,50,minecraft:leaves2:1,100)
RandomBlock(3,7,5,quark:iron_plate:1,70,STAINED_CLAY:15,30,STAINED_CLAY:7,30,STAINED_CLAY:8,30,quark:iron_plate:1,100)
RandomBlock(3,7,6,quark:iron_plate:1,70,STAINED_CLAY:15,30,STAINED_CLAY:7,30,STAINED_CLAY:8,30,quark:iron_plate:1,100)
RandomBlock(3,8,4,quark:iron_plate:1,70,STAINED_CLAY:15,30,STAINED_CLAY:7,30,STAINED_CLAY:8,30,quark:iron_plate:1,100)
RandomBlock(3,8,5,quark:iron_plate:1,70,STAINED_CLAY:15,30,STAINED_CLAY:7,30,STAINED_CLAY:8,30,quark:iron_plate:1,100)
RandomBlock(3,8,6,quark:iron_plate:1,70,STAINED_CLAY:15,30,STAINED_CLAY:7,30,STAINED_CLAY:8,30,quark:iron_plate:1,100)
RandomBlock(3,9,4,minecraft:iron_bars,30,minecraft:iron_bars,30,minecraft:leaves2:1,30,quark:iron_plate_stairs:6,10,quark:iron_plate_stairs:0,10,quark:iron_plate_stairs:5,10,quark:iron_plate_stairs,10,quark:iron_plate_slab:8,10,quark:iron_plate_stairs:7,10,quark:iron_plate_stairs:1,10,quark:iron_plate_slab,10,quark:iron_plate_stairs:4,10,quark:iron_plate_stairs:2,10,minecraft:iron_bars,50,minecraft:iron_bars,50,minecraft:leaves2:1,100)
RandomBlock(3,9,5,quark:iron_plate:1,70,STAINED_CLAY:15,30,STAINED_CLAY:7,30,STAINED_CLAY:8,30,quark:iron_plate:1,100)
RandomBlock(3,9,6,quark:iron_plate:1,70,STAINED_CLAY:15,30,STAINED_CLAY:7,30,STAINED_CLAY:8,30,quark:iron_plate:1,100)
RandomBlock(3,10,4,quark:iron_plate:1,70,STAINED_CLAY:15,30,STAINED_CLAY:7,30,STAINED_CLAY:8,30,quark:iron_plate:1,100)
RandomBlock(3,10,5,quark:iron_plate:1,70,STAINED_CLAY:15,30,STAINED_CLAY:7,30,STAINED_CLAY:8,30,quark:iron_plate:1,100)
RandomBlock(3,10,6,quark:iron_plate:1,70,STAINED_CLAY:15,30,STAINED_CLAY:7,30,STAINED_CLAY:8,30,quark:iron_plate:1,100)
RandomBlock(3,11,4,quark:iron_plate:1,70,STAINED_CLAY:15,30,STAINED_CLAY:7,30,STAINED_CLAY:8,30,quark:iron_plate:1,100)
RandomBlock(3,11,5,quark:iron_plate:1,70,STAINED_CLAY:15,30,STAINED_CLAY:7,30,STAINED_CLAY:8,30,quark:iron_plate:1,100)
RandomBlock(3,11,6,quark:iron_plate:1,70,STAINED_CLAY:15,30,STAINED_CLAY:7,30,STAINED_CLAY:8,30,quark:iron_plate:1,100)
RandomBlock(3,12,4,quark:iron_plate:1,70,STAINED_CLAY:15,30,STAINED_CLAY:7,30,STAINED_CLAY:8,30,quark:iron_plate:1,100)
RandomBlock(3,12,5,quark:iron_plate:1,70,STAINED_CLAY:15,30,STAINED_CLAY:7,30,STAINED_CLAY:8,30,quark:iron_plate:1,100)
RandomBlock(3,12,6,quark:iron_plate:1,70,STAINED_CLAY:15,30,STAINED_CLAY:7,30,STAINED_CLAY:8,30,quark:iron_plate:1,100)
RandomBlock(3,13,4,quark:iron_plate:1,70,STAINED_CLAY:15,30,STAINED_CLAY:7,30,STAINED_CLAY:8,30,quark:iron_plate:1,100)
RandomBlock(3,13,5,quark:iron_plate:1,70,STAINED_CLAY:15,30,STAINED_CLAY:7,30,STAINED_CLAY:8,30,quark:iron_plate:1,100)
RandomBlock(3,13,6,quark:iron_plate:1,70,STAINED_CLAY:15,30,STAINED_CLAY:7,30,STAINED_CLAY:8,30,quark:iron_plate:1,100)
RandomBlock(3,14,4,quark:iron_plate:1,70,STAINED_CLAY:15,30,STAINED_CLAY:7,30,STAINED_CLAY:8,30,quark:iron_plate:1,100)
RandomBlock(3,14,5,quark:iron_plate:1,70,STAINED_CLAY:15,30,STAINED_CLAY:7,30,STAINED_CLAY:8,30,quark:iron_plate:1,100)
RandomBlock(3,14,6,quark:iron_plate:1,70,STAINED_CLAY:15,30,STAINED_CLAY:7,30,STAINED_CLAY:8,30,quark:iron_plate:1,100)
RandomBlock(3,15,4,quark:iron_plate:1,70,STAINED_CLAY:15,30,STAINED_CLAY:7,30,STAINED_CLAY:8,30,quark:iron_plate:1,100)
RandomBlock(3,15,5,quark:iron_plate:1,70,STAINED_CLAY:15,30,STAINED_CLAY:7,30,STAINED_CLAY:8,30,quark:iron_plate:1,100)
RandomBlock(3,15,6,quark:iron_plate:1,70,STAINED_CLAY:15,30,STAINED_CLAY:7,30,STAINED_CLAY:8,30,quark:iron_plate:1,100)
RandomBlock(3,16,4,minecraft:iron_bars,30,minecraft:iron_bars,30,minecraft:leaves2:1,30,quark:iron_plate_stairs:6,10,quark:iron_plate_stairs:0,10,quark:iron_plate_stairs:5,10,quark:iron_plate_stairs,10,quark:iron_plate_slab:8,10,quark:iron_plate_stairs:7,10,quark:iron_plate_stairs:1,10,quark:iron_plate_slab,10,quark:iron_plate_stairs:4,10,quark:iron_plate_stairs:2,10,minecraft:iron_bars,50,minecraft:iron_bars,50,minecraft:leaves2:1,100)
RandomBlock(3,16,5,quark:iron_plate:1,70,STAINED_CLAY:15,30,STAINED_CLAY:7,30,STAINED_CLAY:8,30,quark:iron_plate:1,100)
RandomBlock(3,16,6,quark:iron_plate:1,70,STAINED_CLAY:15,30,STAINED_CLAY:7,30,STAINED_CLAY:8,30,quark:iron_plate:1,100)
RandomBlock(3,17,4,minecraft:iron_bars,30,minecraft:iron_bars,30,minecraft:leaves2:1,30,quark:iron_plate_stairs:6,10,quark:iron_plate_stairs:0,10,quark:iron_plate_stairs:5,10,quark:iron_plate_stairs,10,quark:iron_plate_slab:8,10,quark:iron_plate_stairs:7,10,quark:iron_plate_stairs:1,10,quark:iron_plate_slab,10,quark:iron_plate_stairs:4,10,quark:iron_plate_stairs:2,10,minecraft:iron_bars,50,minecraft:iron_bars,50,minecraft:leaves2:1,100)
RandomBlock(3,17,5,quark:iron_plate:1,70,STAINED_CLAY:15,30,STAINED_CLAY:7,30,STAINED_CLAY:8,30,quark:iron_plate:1,100)
RandomBlock(3,17,6,quark:iron_plate:1,70,STAINED_CLAY:15,30,STAINED_CLAY:7,30,STAINED_CLAY:8,30,quark:iron_plate:1,100)
RandomBlock(3,18,4,quark:iron_plate:1,70,STAINED_CLAY:15,30,STAINED_CLAY:7,30,STAINED_CLAY:8,30,quark:iron_plate:1,100)
RandomBlock(3,18,5,quark:iron_plate:1,70,STAINED_CLAY:15,30,STAINED_CLAY:7,30,STAINED_CLAY:8,30,quark:iron_plate:1,100)
RandomBlock(3,18,6,quark:iron_plate:1,70,STAINED_CLAY:15,30,STAINED_CLAY:7,30,STAINED_CLAY:8,30,quark:iron_plate:1,100)
RandomBlock(3,19,4,quark:iron_plate:1,70,STAINED_CLAY:15,30,STAINED_CLAY:7,30,STAINED_CLAY:8,30,quark:iron_plate:1,100)
RandomBlock(3,19,5,quark:iron_plate:1,70,STAINED_CLAY:15,30,STAINED_CLAY:7,30,STAINED_CLAY:8,30,quark:iron_plate:1,100)
RandomBlock(3,19,6,quark:iron_plate:1,70,STAINED_CLAY:15,30,STAINED_CLAY:7,30,STAINED_CLAY:8,30,quark:iron_plate:1,100)
RandomBlock(3,20,4,quark:iron_plate:1,70,STAINED_CLAY:15,30,STAINED_CLAY:7,30,STAINED_CLAY:8,30,quark:iron_plate:1,100)
RandomBlock(3,20,5,quark:iron_plate:1,70,STAINED_CLAY:15,30,STAINED_CLAY:7,30,STAINED_CLAY:8,30,quark:iron_plate:1,100)
RandomBlock(3,20,6,quark:iron_plate:1,70,STAINED_CLAY:15,30,STAINED_CLAY:7,30,STAINED_CLAY:8,30,quark:iron_plate:1,100)
RandomBlock(3,21,4,quark:iron_plate:1,70,STAINED_CLAY:15,30,STAINED_CLAY:7,30,STAINED_CLAY:8,30,quark:iron_plate:1,100)
RandomBlock(3,21,5,quark:iron_plate:1,70,STAINED_CLAY:15,30,STAINED_CLAY:7,30,STAINED_CLAY:8,30,quark:iron_plate:1,100)
RandomBlock(3,21,6,quark:iron_plate:1,70,STAINED_CLAY:15,30,STAINED_CLAY:7,30,STAINED_CLAY:8,30,quark:iron_plate:1,100)
RandomBlock(3,22,4,quark:iron_plate:1,70,STAINED_CLAY:15,30,STAINED_CLAY:7,30,STAINED_CLAY:8,30,quark:iron_plate:1,100)
RandomBlock(3,22,5,quark:iron_plate:1,70,STAINED_CLAY:15,30,STAINED_CLAY:7,30,STAINED_CLAY:8,30,quark:iron_plate:1,100)
RandomBlock(3,22,6,quark:iron_plate:1,70,STAINED_CLAY:15,30,STAINED_CLAY:7,30,STAINED_CLAY:8,30,quark:iron_plate:1,100)
RandomBlock(3,23,4,minecraft:iron_bars,30,minecraft:iron_bars,30,minecraft:leaves2:1,30,quark:iron_plate_stairs:6,10,quark:iron_plate_stairs:0,10,quark:iron_plate_stairs:5,10,quark:iron_plate_stairs,10,quark:iron_plate_slab:8,10,quark:iron_plate_stairs:7,10,quark:iron_plate_stairs:1,10,quark:iron_plate_slab,10,quark:iron_plate_stairs:4,10,quark:iron_plate_stairs:2,10,minecraft:iron_bars,50,minecraft:iron_bars,50,minecraft:leaves2:1,100)
RandomBlock(3,23,5,quark:iron_plate:1,70,STAINED_CLAY:15,30,STAINED_CLAY:7,30,STAINED_CLAY:8,30,quark:iron_plate:1,100)
RandomBlock(3,23,6,quark:iron_plate:1,70,STAINED_CLAY:15,30,STAINED_CLAY:7,30,STAINED_CLAY:8,30,quark:iron_plate:1,100)
RandomBlock(3,24,4,quark:iron_plate:1,70,STAINED_CLAY:15,30,STAINED_CLAY:7,30,STAINED_CLAY:8,30,quark:iron_plate:1,100)
RandomBlock(3,24,5,quark:iron_plate:1,70,STAINED_CLAY:15,30,STAINED_CLAY:7,30,STAINED_CLAY:8,30,quark:iron_plate:1,100)
RandomBlock(3,24,6,quark:iron_plate:1,70,STAINED_CLAY:15,30,STAINED_CLAY:7,30,STAINED_CLAY:8,30,quark:iron_plate:1,100)
RandomBlock(3,25,4,quark:iron_plate:1,70,STAINED_CLAY:15,30,STAINED_CLAY:7,30,STAINED_CLAY:8,30,quark:iron_plate:1,100)
RandomBlock(3,25,5,quark:iron_plate:1,70,STAINED_CLAY:15,30,STAINED_CLAY:7,30,STAINED_CLAY:8,30,quark:iron_plate:1,100)
RandomBlock(3,25,6,quark:iron_plate:1,70,STAINED_CLAY:15,30,STAINED_CLAY:7,30,STAINED_CLAY:8,30,quark:iron_plate:1,100)
RandomBlock(3,26,4,quark:iron_plate:1,70,STAINED_CLAY:15,30,STAINED_CLAY:7,30,STAINED_CLAY:8,30,quark:iron_plate:1,100)
RandomBlock(3,26,5,quark:iron_plate:1,70,STAINED_CLAY:15,30,STAINED_CLAY:7,30,STAINED_CLAY:8,30,quark:iron_plate:1,100)
RandomBlock(3,26,6,quark:iron_plate:1,70,STAINED_CLAY:15,30,STAINED_CLAY:7,30,STAINED_CLAY:8,30,quark:iron_plate:1,100)
RandomBlock(3,27,4,quark:iron_plate:1,70,STAINED_CLAY:15,30,STAINED_CLAY:7,30,STAINED_CLAY:8,30,quark:iron_plate:1,100)
RandomBlock(3,27,5,quark:iron_plate:1,70,STAINED_CLAY:15,30,STAINED_CLAY:7,30,STAINED_CLAY:8,30,quark:iron_plate:1,100)
RandomBlock(3,27,6,quark:iron_plate:1,70,STAINED_CLAY:15,30,STAINED_CLAY:7,30,STAINED_CLAY:8,30,quark:iron_plate:1,100)
RandomBlock(3,28,4,minecraft:iron_bars,30,minecraft:iron_bars,30,minecraft:leaves2:1,30,quark:iron_plate_stairs:6,10,quark:iron_plate_stairs:0,10,quark:iron_plate_stairs:5,10,quark:iron_plate_stairs,10,quark:iron_plate_slab:8,10,quark:iron_plate_stairs:7,10,quark:iron_plate_stairs:1,10,quark:iron_plate_slab,10,quark:iron_plate_stairs:4,10,quark:iron_plate_stairs:2,10,minecraft:iron_bars,50,minecraft:iron_bars,50,minecraft:leaves2:1,100)
RandomBlock(3,28,5,quark:iron_plate:1,70,STAINED_CLAY:15,30,STAINED_CLAY:7,30,STAINED_CLAY:8,30,quark:iron_plate:1,100)
RandomBlock(3,28,6,quark:iron_plate:1,70,STAINED_CLAY:15,30,STAINED_CLAY:7,30,STAINED_CLAY:8,30,quark:iron_plate:1,100)
RandomBlock(3,29,4,quark:iron_plate:1,70,STAINED_CLAY:15,30,STAINED_CLAY:7,30,STAINED_CLAY:8,30,quark:iron_plate:1,100)
RandomBlock(3,29,5,quark:iron_plate:1,70,STAINED_CLAY:15,30,STAINED_CLAY:7,30,STAINED_CLAY:8,30,quark:iron_plate:1,100)
RandomBlock(3,29,6,quark:iron_plate:1,70,STAINED_CLAY:15,30,STAINED_CLAY:7,30,STAINED_CLAY:8,30,quark:iron_plate:1,100)
RandomBlock(3,30,4,quark:iron_plate:1,70,STAINED_CLAY:15,30,STAINED_CLAY:7,30,STAINED_CLAY:8,30,quark:iron_plate:1,100)
RandomBlock(3,30,5,quark:iron_plate:1,70,STAINED_CLAY:15,30,STAINED_CLAY:7,30,STAINED_CLAY:8,30,quark:iron_plate:1,100)
RandomBlock(3,30,6,quark:iron_plate:1,70,STAINED_CLAY:15,30,STAINED_CLAY:7,30,STAINED_CLAY:8,30,quark:iron_plate:1,100)
RandomBlock(3,31,4,quark:iron_plate:1,70,STAINED_CLAY:15,30,STAINED_CLAY:7,30,STAINED_CLAY:8,30,quark:iron_plate:1,100)
RandomBlock(3,31,5,quark:iron_plate:1,70,STAINED_CLAY:15,30,STAINED_CLAY:7,30,STAINED_CLAY:8,30,quark:iron_plate:1,100)
RandomBlock(3,31,6,quark:iron_plate:1,70,STAINED_CLAY:15,30,STAINED_CLAY:7,30,STAINED_CLAY:8,30,quark:iron_plate:1,100)
RandomBlock(3,32,4,quark:iron_plate:1,70,STAINED_CLAY:15,30,STAINED_CLAY:7,30,STAINED_CLAY:8,30,quark:iron_plate:1,100)
RandomBlock(3,32,5,quark:iron_plate:1,70,STAINED_CLAY:15,30,STAINED_CLAY:7,30,STAINED_CLAY:8,30,quark:iron_plate:1,100)
RandomBlock(3,32,6,quark:iron_plate:1,70,STAINED_CLAY:15,30,STAINED_CLAY:7,30,STAINED_CLAY:8,30,quark:iron_plate:1,100)
RandomBlock(3,33,4,quark:iron_plate:1,70,STAINED_CLAY:15,30,STAINED_CLAY:7,30,STAINED_CLAY:8,30,quark:iron_plate:1,100)
RandomBlock(3,33,5,quark:iron_plate:1,70,STAINED_CLAY:15,30,STAINED_CLAY:7,30,STAINED_CLAY:8,30,quark:iron_plate:1,100)
RandomBlock(3,33,6,quark:iron_plate:1,70,STAINED_CLAY:15,30,STAINED_CLAY:7,30,STAINED_CLAY:8,30,quark:iron_plate:1,100)
RandomBlock(3,34,4,quark:iron_plate:1,70,STAINED_CLAY:15,30,STAINED_CLAY:7,30,STAINED_CLAY:8,30,quark:iron_plate:1,100)
RandomBlock(3,34,5,quark:iron_plate:1,70,STAINED_CLAY:15,30,STAINED_CLAY:7,30,STAINED_CLAY:8,30,quark:iron_plate:1,100)
RandomBlock(3,34,6,quark:iron_plate:1,70,STAINED_CLAY:15,30,STAINED_CLAY:7,30,STAINED_CLAY:8,30,quark:iron_plate:1,100)
RandomBlock(3,35,4,minecraft:iron_bars,30,minecraft:iron_bars,30,minecraft:leaves2:1,30,quark:iron_plate_stairs:6,10,quark:iron_plate_stairs:0,10,quark:iron_plate_stairs:5,10,quark:iron_plate_stairs,10,quark:iron_plate_slab:8,10,quark:iron_plate_stairs:7,10,quark:iron_plate_stairs:1,10,quark:iron_plate_slab,10,quark:iron_plate_stairs:4,10,quark:iron_plate_stairs:2,10,minecraft:iron_bars,50,minecraft:iron_bars,50,minecraft:leaves2:1,100)
RandomBlock(3,35,5,quark:iron_plate:1,70,STAINED_CLAY:15,30,STAINED_CLAY:7,30,STAINED_CLAY:8,30,quark:iron_plate:1,100)
RandomBlock(3,35,6,quark:iron_plate:1,70,STAINED_CLAY:15,30,STAINED_CLAY:7,30,STAINED_CLAY:8,30,quark:iron_plate:1,100)
RandomBlock(3,36,4,minecraft:iron_bars,30,minecraft:iron_bars,30,minecraft:leaves2:1,30,quark:iron_plate_stairs:6,10,quark:iron_plate_stairs:0,10,quark:iron_plate_stairs:5,10,quark:iron_plate_stairs,10,quark:iron_plate_slab:8,10,quark:iron_plate_stairs:7,10,quark:iron_plate_stairs:1,10,quark:iron_plate_slab,10,quark:iron_plate_stairs:4,10,quark:iron_plate_stairs:2,10,minecraft:iron_bars,50,minecraft:iron_bars,50,minecraft:leaves2:1,100)
RandomBlock(3,36,5,minecraft:iron_bars,30,minecraft:iron_bars,30,minecraft:leaves2:1,30,quark:iron_plate_stairs:6,10,quark:iron_plate_stairs:0,10,quark:iron_plate_stairs:5,10,quark:iron_plate_stairs,10,quark:iron_plate_slab:8,10,quark:iron_plate_stairs:7,10,quark:iron_plate_stairs:1,10,quark:iron_plate_slab,10,quark:iron_plate_stairs:4,10,quark:iron_plate_stairs:2,10,minecraft:iron_bars,50,minecraft:iron_bars,50,minecraft:leaves2:1,100)
RandomBlock(3,36,6,quark:iron_plate:1,70,STAINED_CLAY:15,30,STAINED_CLAY:7,30,STAINED_CLAY:8,30,quark:iron_plate:1,100)
RandomBlock(3,37,4,minecraft:iron_bars,30,minecraft:iron_bars,30,minecraft:leaves2:1,30,quark:iron_plate_stairs:6,10,quark:iron_plate_stairs:0,10,quark:iron_plate_stairs:5,10,quark:iron_plate_stairs,10,quark:iron_plate_slab:8,10,quark:iron_plate_stairs:7,10,quark:iron_plate_stairs:1,10,quark:iron_plate_slab,10,quark:iron_plate_stairs:4,10,quark:iron_plate_stairs:2,10,minecraft:iron_bars,50,minecraft:iron_bars,50,minecraft:leaves2:1,100)
RandomBlock(3,37,5,quark:iron_plate:1,70,STAINED_CLAY:15,30,STAINED_CLAY:7,30,STAINED_CLAY:8,30,quark:iron_plate:1,100)
RandomBlock(3,37,6,quark:iron_plate:1,70,STAINED_CLAY:15,30,STAINED_CLAY:7,30,STAINED_CLAY:8,30,quark:iron_plate:1,100)
RandomBlock(3,38,4,minecraft:iron_bars,30,minecraft:iron_bars,30,minecraft:leaves2:1,30,quark:iron_plate_stairs:6,10,quark:iron_plate_stairs:0,10,quark:iron_plate_stairs:5,10,quark:iron_plate_stairs,10,quark:iron_plate_slab:8,10,quark:iron_plate_stairs:7,10,quark:iron_plate_stairs:1,10,quark:iron_plate_slab,10,quark:iron_plate_stairs:4,10,quark:iron_plate_stairs:2,10,minecraft:iron_bars,50,minecraft:iron_bars,50,minecraft:leaves2:1,100)
RandomBlock(3,38,5,minecraft:iron_bars,30,minecraft:iron_bars,30,minecraft:leaves2:1,30,quark:iron_plate_stairs:6,10,quark:iron_plate_stairs:0,10,quark:iron_plate_stairs:5,10,quark:iron_plate_stairs,10,quark:iron_plate_slab:8,10,quark:iron_plate_stairs:7,10,quark:iron_plate_stairs:1,10,quark:iron_plate_slab,10,quark:iron_plate_stairs:4,10,quark:iron_plate_stairs:2,10,minecraft:iron_bars,50,minecraft:iron_bars,50,minecraft:leaves2:1,100)
