
#######################################################################
# +-----------------------------------------------------------------+ #
# |                            BO4 object                           | #
# +-----------------------------------------------------------------+ #
#######################################################################

# This is the config file of a custom object.
# If you add this object correctly to your BiomeConfigs, it will spawn in the world.

# This is the creator of this BO4 object
Author: NLBlackEagle

# A short description of this BO4 object
Description: No description given

# The settings mode, WriteAll, WriteDisable or WriteDisable. See WorldConfig.
SettingsMode: WriteDisable


#######################################################################
# +-----------------------------------------------------------------+ #
# |                          Main settings                          | #
# +-----------------------------------------------------------------+ #
#######################################################################

# If this BO4 should spawn with a fixed rotation, set it here.
# For example: NORTH, EAST, SOUTH or WEST. Empty by default
FixedRotation: 

# This BO4 can only spawn at least Frequency chunks distance away from any other BO4 with the exact same name.
# You can use this to make this BO4 spawn in groups or make sure that this BO4 only spawns once every X chunks.
Frequency: 0

# The spawn height of the BO4: randomY, highestBlock or highestSolidBlock.
SpawnHeight: highestBlock

# When set to true, uses the center of the structure (determined by minimum structure size) when checking the highestBlock to spawn at.
UseCenterForHighestBlock: true

##############################
# Height Limits for the BO4. #
##############################

# When in randomY mode used as the minimum Y or in atMinY mode as the actual Y to spawn this BO4 at.
MinHeight: 0

# When in randomY mode used as the maximum Y to spawn this BO4 at.
MaxHeight: 256

# Copies the blocks and branches of an existing BO4 into this BO4. You can still add blocks and branches in this BO4, they will be added on top of the inherited blocks and branches.
InheritBO3: 

# Rotates the inheritedBO3's resources (blocks, spawners, checks etc) and branches, defaults to NORTH (no rotation).
InheritBO3Rotation: NORTH

# Defaults to true, if true and this is the starting BO4 for this branching structure then this BO4's smoothing and height settings are used for all children (branches).
OverrideChildSettings: true

# Defaults to false, if true then this branch uses it's own height settings (SpawnHeight, minHeight, maxHeight, spawnAtWaterLevel) instead of those defined in the starting BO4 for this branching structure.
OverrideParentHeight: false

# If this is set to true then this BO4 can spawn on top of or inside an existing BO4. If this is set to false then this BO4 will use a bounding box to detect collisions with other BO4's, if a collision is detected then this BO4 won't spawn and the current branch is rolled back.
CanOverride: false

# This branch can only spawn at least branchFrequency chunks (x,z) distance away from any other branch with the exact same name.
BranchFrequency: 0

# Define groups that this branch belongs to along with a minimum (x,z) range in chunks that this branch must have between it and any other members of this group if it is to be allowed to spawn. Syntax is "GroupName:Frequency, GoupName2:Frequency2" etc so for example a branch that belongs to 3 groups: "BranchFrequencyGroup: Ships:10, Vehicles:5, FloatingThings:3".
BranchFrequencyGroup: 

# If this is set to true then this BO4 can only spawn underneath an existing BO4. Used to make sure that dungeons only appear underneath buildings.
MustBeBelowOther: false

# Used with CanOverride: true. A comma-seperated list of BO4s, this BO4's bounding box must collide with one of the BO4's in the list or this BO4 fails to spawn and the current branch is rolled back. AND/OR is supported, comma is OR, space is AND, f.e: branch1, branch2 branch3, branch 4.
MustBeInside: 

# Used with CanOverride: true. A comma-seperated list of BO4s, this BO4's bounding box cannot collide with any of the BO4's in the list or this BO4 fails to spawn and the current branch is rolled back.
CannotBeInside: 

# Used with CanOverride: true. A comma-seperated list of BO4s, if this BO4's bounding box collides with any of the BO4's in the list then those BO4's won't spawn any blocks. This does not remove or roll back any BO4's.
ReplacesBO3: 

# If this is set to true then this BO4 can only spawn inside world borders. Used to make sure that dungeons only appear inside the world borders.
MustBeInsideWorldBorders: true
# Defaults to true. Set to false if the BO4 is not allowed to spawn on a water block
CanSpawnOnWater: true

# Defaults to false. Set to true if the BO4 is allowed to spawn only on a water block
SpawnOnWaterOnly: false

# Defaults to false. Set to true if the BO4 and its smoothing area should ignore water when looking for the highest block to spawn on. Defaults to false (things spawn on top of water)
SpawnUnderWater: false

# Defaults to false. Set to true if the BO4 should spawn at water level
SpawnAtWaterLevel: false

# Spawns the BO4 at a Y offset of this value. Handy when using highestBlock for lowering BO4s into the surrounding terrain when there are layers of ground included in the BO4, also handy when using SpawnAtWaterLevel to lower objects like ships into the water.
HeightOffset: 0

# If set to true removes all AIR blocks from the BO4 so that it can be flooded or buried.
RemoveAir: false

# Replaces all the non-air blocks that are above this BO4 or its smoothing area with the given block material (should be WATER or AIR or NONE), also applies to smoothing areas although OTG intentionally leaves some of the terrain above them intact. WATER can be used in combination with SpawnUnderWater to fill any air blocks underneath waterlevel with water (and any above waterlevel with air).
ReplaceAbove: 

# Replaces all air blocks underneath the BO4 (but not its smoothing area) with the specified material until a solid block is found.
ReplaceBelow: 

# Defaults to true. If set to true then every block in the BO4 of the materials defined in ReplaceWithGroundBlock or ReplaceWithSurfaceBlock will be replaced by the GroundBlock or SurfaceBlock materials configured for the biome the block is spawned in.
ReplaceWithBiomeBlocks: true

# Defaults to GRASS, Replaces all the blocks of the given material in the BO4 with the SurfaceBlock configured for the biome it spawns in.
ReplaceWithSurfaceBlock: GRASS

# Defaults to DIRT, Replaces all the blocks of the given material in the BO4 with the GroundBlock configured for the biome it spawns in.
ReplaceWithGroundBlock: DIRT

# Defaults to STONE, Replaces all the blocks of the given material in the BO4 with the StoneBlock configured for the biome it spawns in.
ReplaceWithStoneBlock: STONE

# Makes the terrain around the BO4 slope evenly towards the edges of the BO4. The given value is the distance in blocks around the BO4 from where the slope should start and can be any positive number.
SmoothRadius: 0

# Moves the smoothing area up or down relative to the BO4 (at the points where the smoothing area is connected to the BO4). Handy when using SmoothStartTop: false and the BO4 has some layers of ground included, in that case we can set the HeightOffset to a negative value to lower the BO4 into the ground and we can set the SmoothHeightOffset to a positive value to move the smoothing area starting height up.
SmoothHeightOffset: 0

# Should the smoothing area be attached at the bottom or the top of the edges of the BO4? Defaults to false (bottom). Using this setting can make things slower so try to avoid using it and use SmoothHeightOffset instead if for instance you have a BO4 with some ground layers included. The only reason you should need to use this setting is if you have a BO4 with edges that have an irregular height (like some hills).
SmoothStartTop: false

# Should the smoothing area attach itself to "log" block or ignore them? Defaults to false (ignore logs).
SmoothStartWood: false

# The block used for smoothing area surface blocks, defaults to biome SurfaceBlock.
SmoothingSurfaceBlock: 

# The block used for smoothing area ground blocks, defaults to biome GroundBlock.
SmoothingGroundBlock: 

# Define groups that this BO4 belongs to along with a minimum range in chunks that this BO4 must have between it and any other members of this group if it is to be allowed to spawn. Syntax is "GroupName:Frequency, GoupName2:Frequency2" etc so for example a BO4 that belongs to 3 groups: "BO4Group: Ships:10, Vehicles:5, FloatingThings:3".
BO3Group: 

# Defaults to false. Set to true if this BO4 should spawn at the player spawn point. When the server starts the spawn point is determined and the BO4's for the biome it is in are loaded, one of these BO4s that has IsSpawnPoint set to true (if any) is selected randomly and is spawned at the spawn point regardless of its rarity (so even Rarity:0, IsSpawnPoint: true BO4's can get spawned as the spawn point!).
IsSpawnPoint: false

# Defaults to true. Set to false to make the BO4 ignore any ReplacedBlocks settings in Biome Configs.
DoReplaceBlocks: true


#######################################################################
# +-----------------------------------------------------------------+ #
# |                              Blocks                             | #
# +-----------------------------------------------------------------+ #
#######################################################################

# All the blocks used in the BO4 are listed here. Possible blocks:
# Block(x,y,z,id[.data][,nbtfile.nbt)
# RandomBlock(x,y,z,id[:data][,nbtfile.nbt],chance[,id[:data][,nbtfile.nbt],chance[,...]])
#  So RandomBlock(0,0,0,CHEST,chest.nbt,50,CHEST,anotherchest.nbt,100) will spawn a chest at
#  the BO4 origin, and give it a 50% chance to have the contents of chest.nbt, or, if that
#  fails, a 100% percent chance to have the contents of anotherchest.nbt.
# MinecraftObject(x,y,z,name) (TODO: This may not work anymore and needs to be tested.
#  Spawns an object in the Mojang NBT structure format. For example, 
#  MinecraftObject(0,0,0,minecraft:igloo/igloo_bottom)
#  spawns the bottom part of an igloo.
Block(-8,0,-7,minecraft:concrete)
Block(-8,0,-6,minecraft:concrete)
Block(-8,0,-5,minecraft:concrete)
Block(-8,0,-4,minecraft:concrete)
Block(-8,0,-3,minecraft:concrete)
Block(-8,0,-2,minecraft:concrete)
Block(-8,0,-1,minecraft:concrete)
Block(-8,0,0,minecraft:concrete)
Block(-8,0,1,minecraft:concrete)
Block(-8,0,2,minecraft:concrete)
Block(-8,0,3,minecraft:concrete)
Block(-8,0,4,minecraft:concrete)
Block(-8,0,5,minecraft:concrete)
Block(-8,0,6,minecraft:concrete)
Block(-8,0,7,minecraft:concrete)
Block(-8,0,8,minecraft:concrete)
Block(-8,1,-7,minecraft:concrete)
Block(-8,1,-6,STATIONARY_WATER:0)
Block(-8,1,-5,STATIONARY_WATER:0)
Block(-8,1,-4,minecraft:dirt:8)
Block(-8,1,-3,DIRT:1)
Block(-8,1,-2,minecraft:dirt)
Block(-8,1,-1,SOIL:7)
Block(-8,1,0,DIRT:2)
Block(-8,1,1,STATIONARY_WATER:0)
Block(-8,1,2,minecraft:concrete)
Block(-8,1,3,minecraft:dirt)
Block(-8,1,4,minecraft:stonebrick:14)
Block(-8,1,5,STATIONARY_WATER:0)
Block(-8,1,6,minecraft:stonebrick:14)
Block(-8,1,7,minecraft:stonebrick:14)
Block(-8,1,8,minecraft:stonebrick:14)
Block(-8,2,-7,minecraft:concrete)
Block(-8,2,-6,AIR:0)
Block(-8,2,-5,WATER_LILY:0)
Block(-8,2,-4,SUGAR_CANE_BLOCK:0)
Block(-8,2,-3,AIR:0)
Block(-8,2,-2,AIR:0)
Block(-8,2,-1,CROPS:7)
Block(-8,2,0,AIR:0)
Block(-8,2,1,AIR:0)
Block(-8,2,2,minecraft:concrete)
Block(-8,2,3,minecraft:tallgrass:13)
Block(-8,2,4,AIR:0)
Block(-8,2,5,AIR:0)
Block(-8,2,6,CROPS:7)
Block(-8,2,7,minecraft:glowstone)
Block(-8,2,8,CROPS:7)
Block(-8,3,-7,minecraft:concrete)
Block(-8,3,-6,AIR:0)
Block(-8,3,-5,AIR:0)
Block(-8,3,-4,SUGAR_CANE_BLOCK:0)
Block(-8,3,-3,AIR:0)
Block(-8,3,-2,AIR:0)
Block(-8,3,-1,AIR:0)
Block(-8,3,0,AIR:0)
Block(-8,3,1,AIR:0)
Block(-8,3,2,minecraft:glass)
Block(-8,3,3,AIR:0)
Block(-8,3,4,AIR:0)
Block(-8,3,5,AIR:0)
Block(-8,3,6,AIR:0)
Block(-8,3,7,AIR:0)
Block(-8,3,8,AIR:0)
Block(-8,4,-7,minecraft:concrete)
Block(-8,4,-6,AIR:0)
Block(-8,4,-5,AIR:0)
Block(-8,4,-4,SUGAR_CANE_BLOCK:0)
Block(-8,4,-3,AIR:0)
Block(-8,4,-2,AIR:0)
Block(-8,4,-1,AIR:0)
Block(-8,4,0,AIR:0)
Block(-8,4,1,AIR:0)
Block(-8,4,2,minecraft:glass)
Block(-8,4,3,AIR:0)
Block(-8,4,4,AIR:0)
Block(-8,4,5,AIR:0)
Block(-8,4,6,AIR:0)
Block(-8,4,7,AIR:0)
Block(-8,4,8,AIR:0)
Block(-8,5,-7,minecraft:concrete)
Block(-8,5,-6,minecraft:concrete)
Block(-8,5,-5,minecraft:concrete)
Block(-8,5,-4,minecraft:concrete)
Block(-8,5,-3,minecraft:concrete)
Block(-8,5,-2,minecraft:concrete)
Block(-8,5,-1,minecraft:concrete)
Block(-8,5,0,minecraft:concrete)
Block(-8,5,1,minecraft:concrete)
Block(-8,5,2,minecraft:concrete)
Block(-8,5,3,AIR:0)
Block(-8,5,4,AIR:0)
Block(-8,5,5,AIR:0)
Block(-8,5,6,AIR:0)
Block(-8,5,7,AIR:0)
Block(-8,5,8,AIR:0)
Block(-8,6,-7,minecraft:concrete)
Block(-8,6,-6,quark:grate)
Block(-8,6,-5,quark:grate)
Block(-8,6,-4,minecraft:concrete)
Block(-8,6,-3,CONCRETE:15)
Block(-8,6,-2,CONCRETE:15)
Block(-8,6,-1,minecraft:concrete)
Block(-8,6,0,quark:grate)
Block(-8,6,1,quark:grate)
Block(-8,6,2,minecraft:concrete)
Block(-8,6,3,AIR:0)
Block(-8,6,4,AIR:0)
Block(-8,6,5,AIR:0)
Block(-8,6,6,AIR:0)
Block(-8,6,7,AIR:0)
Block(-8,6,8,AIR:0)
Block(-8,7,-7,minecraft:concrete)
Block(-8,7,-6,AIR:0)
Block(-8,7,-5,AIR:0)
Block(-8,7,-4,AIR:0)
Block(-8,7,-3,AIR:0)
Block(-8,7,-2,AIR:0)
Block(-8,7,-1,AIR:0)
Block(-8,7,0,AIR:0)
Block(-8,7,1,AIR:0)
Block(-8,7,2,minecraft:concrete)
Block(-8,7,3,AIR:0)
Block(-8,7,4,AIR:0)
Block(-8,7,5,AIR:0)
Block(-8,7,6,AIR:0)
Block(-8,7,7,AIR:0)
Block(-8,7,8,AIR:0)
Block(-8,8,-7,minecraft:concrete)
Block(-8,8,-6,AIR:0)
Block(-8,8,-5,AIR:0)
Block(-8,8,-4,AIR:0)
Block(-8,8,-3,AIR:0)
Block(-8,8,-2,AIR:0)
Block(-8,8,-1,AIR:0)
Block(-8,8,0,AIR:0)
Block(-8,8,1,AIR:0)
Block(-8,8,2,minecraft:concrete)
Block(-8,8,3,AIR:0)
Block(-8,8,4,AIR:0)
Block(-8,8,5,AIR:0)
Block(-8,8,6,AIR:0)
Block(-8,8,7,AIR:0)
Block(-8,8,8,AIR:0)
Block(-8,9,-7,minecraft:concrete)
Block(-8,9,-6,AIR:0)
Block(-8,9,-5,AIR:0)
Block(-8,9,-4,AIR:0)
Block(-8,9,-3,AIR:0)
Block(-8,9,-2,AIR:0)
Block(-8,9,-1,AIR:0)
Block(-8,9,0,AIR:0)
Block(-8,9,1,AIR:0)
Block(-8,9,2,minecraft:concrete)
Block(-8,9,3,AIR:0)
Block(-8,9,4,AIR:0)
Block(-8,9,5,AIR:0)
Block(-8,9,6,AIR:0)
Block(-8,9,7,AIR:0)
Block(-8,9,8,AIR:0)
Block(-8,10,-7,minecraft:concrete)
Block(-8,10,-6,AIR:0)
Block(-8,10,-5,AIR:0)
Block(-8,10,-4,AIR:0)
Block(-8,10,-3,AIR:0)
Block(-8,10,-2,AIR:0)
Block(-8,10,-1,AIR:0)
Block(-8,10,0,AIR:0)
Block(-8,10,1,AIR:0)
Block(-8,10,2,minecraft:concrete)
Block(-8,10,3,minecraft:concrete)
Block(-8,10,4,minecraft:concrete)
Block(-8,10,5,minecraft:concrete)
Block(-8,10,6,minecraft:concrete)
Block(-8,10,7,minecraft:concrete)
Block(-8,10,8,minecraft:concrete)
Block(-8,11,-7,minecraft:concrete)
Block(-8,11,-6,minecraft:concrete)
Block(-8,11,-5,minecraft:concrete)
Block(-8,11,-4,minecraft:concrete)
Block(-8,11,-3,minecraft:concrete)
Block(-8,11,-2,minecraft:concrete)
Block(-8,11,-1,minecraft:concrete)
Block(-8,11,0,minecraft:concrete)
Block(-8,11,1,minecraft:concrete)
Block(-8,11,2,minecraft:concrete)
Block(-8,11,3,minecraft:concrete)
Block(-8,11,4,minecraft:concrete)
Block(-8,11,5,minecraft:concrete)
Block(-8,11,6,minecraft:concrete)
Block(-8,11,7,minecraft:concrete)
Block(-8,11,8,minecraft:concrete)
Block(-8,12,-7,minecraft:concrete)
Block(-8,12,-6,minecraft:concrete)
Block(-8,12,-5,minecraft:concrete)
Block(-8,12,-4,minecraft:concrete)
Block(-8,12,-3,minecraft:concrete)
Block(-8,12,-2,minecraft:concrete)
Block(-8,12,-1,minecraft:concrete)
Block(-8,12,0,minecraft:concrete)
Block(-8,12,1,minecraft:concrete)
Block(-8,12,2,minecraft:concrete)
Block(-8,12,3,minecraft:concrete)
Block(-8,12,4,minecraft:concrete)
Block(-8,12,5,minecraft:concrete)
Block(-8,12,6,minecraft:concrete)
Block(-8,12,7,minecraft:iron_block:0)
Block(-8,12,8,AIR:0)
Block(-8,13,-7,minecraft:concrete)
Block(-8,13,-6,minecraft:iron_block)
Block(-8,13,-5,minecraft:stone)
Block(-8,13,-4,AIR:0)
Block(-8,13,-3,minecraft:stonebrick)
Block(-8,13,-2,AIR:0)
Block(-8,13,-1,AIR:0)
Block(-8,13,0,AIR:0)
Block(-8,13,1,minecraft:stonebrick)
Block(-8,13,2,AIR:0)
Block(-8,13,3,minecraft:iron_block)
Block(-8,13,4,minecraft:concrete)
Block(-8,13,5,minecraft:concrete)
Block(-8,13,6,minecraft:concrete)
Block(-8,13,7,minecraft:iron_block:0)
Block(-8,13,8,AIR:0)
Block(-8,14,-7,minecraft:concrete)
Block(-8,14,-6,minecraft:iron_block)
Block(-8,14,-5,AIR:0)
Block(-8,14,-4,AIR:0)
Block(-8,14,-3,AIR:0)
Block(-8,14,-2,AIR:0)
Block(-8,14,-1,AIR:0)
Block(-8,14,0,AIR:0)
Block(-8,14,1,AIR:0)
Block(-8,14,2,AIR:0)
Block(-8,14,3,minecraft:iron_block)
Block(-8,14,4,minecraft:concrete)
Block(-8,14,5,minecraft:concrete)
Block(-8,14,6,minecraft:concrete)
Block(-8,14,7,minecraft:iron_block:0)
Block(-8,14,8,AIR:0)
Block(-8,15,-7,minecraft:concrete)
Block(-8,15,-6,minecraft:iron_block)
Block(-8,15,-5,AIR:0)
Block(-8,15,-4,AIR:0)
Block(-8,15,-3,AIR:0)
Block(-8,15,-2,AIR:0)
Block(-8,15,-1,AIR:0)
Block(-8,15,0,AIR:0)
Block(-8,15,1,AIR:0)
Block(-8,15,2,AIR:0)
Block(-8,15,3,minecraft:iron_block)
Block(-8,15,4,minecraft:concrete)
Block(-8,15,5,minecraft:concrete)
Block(-8,15,6,minecraft:concrete)
Block(-8,15,7,minecraft:iron_block:0)
Block(-8,15,8,AIR:0)
Block(-8,16,-7,minecraft:concrete)
Block(-8,16,-6,minecraft:iron_block)
Block(-8,16,-5,AIR:0)
Block(-8,16,-4,AIR:0)
Block(-8,16,-3,AIR:0)
Block(-8,16,-2,AIR:0)
Block(-8,16,-1,AIR:0)
Block(-8,16,0,AIR:0)
Block(-8,16,1,AIR:0)
Block(-8,16,2,AIR:0)
Block(-8,16,3,minecraft:iron_block)
Block(-8,16,4,minecraft:concrete)
Block(-8,16,5,minecraft:concrete)
Block(-8,16,6,minecraft:concrete)
Block(-8,16,7,minecraft:iron_block:0)
Block(-8,16,8,AIR:0)
Block(-8,17,-7,minecraft:concrete)
Block(-8,17,-6,minecraft:iron_block)
Block(-8,17,-5,AIR:0)
Block(-8,17,-4,AIR:0)
Block(-8,17,-3,AIR:0)
Block(-8,17,-2,AIR:0)
Block(-8,17,-1,AIR:0)
Block(-8,17,0,AIR:0)
Block(-8,17,1,AIR:0)
Block(-8,17,2,AIR:0)
Block(-8,17,3,minecraft:iron_block)
Block(-8,17,4,minecraft:concrete)
Block(-8,17,5,minecraft:concrete)
Block(-8,17,6,minecraft:concrete)
Block(-8,17,7,minecraft:iron_block:0)
Block(-8,17,8,AIR:0)
Block(-8,18,-7,minecraft:concrete)
Block(-8,18,-6,minecraft:iron_block)
Block(-8,18,-5,minecraft:iron_block)
Block(-8,18,-4,minecraft:iron_block)
Block(-8,18,-3,minecraft:iron_block)
Block(-8,18,-2,minecraft:iron_block)
Block(-8,18,-1,minecraft:iron_block)
Block(-8,18,0,minecraft:iron_block)
Block(-8,18,1,minecraft:iron_block)
Block(-8,18,2,minecraft:iron_block)
Block(-8,18,3,minecraft:iron_block)
Block(-8,18,4,minecraft:concrete)
Block(-8,18,5,minecraft:concrete)
Block(-8,18,6,minecraft:concrete)
Block(-8,18,7,minecraft:iron_block:0)
Block(-8,18,8,AIR:0)
Block(-8,19,-7,minecraft:concrete)
Block(-8,19,-6,minecraft:concrete)
Block(-8,19,-5,minecraft:concrete)
Block(-8,19,-4,minecraft:concrete)
Block(-8,19,-3,minecraft:concrete)
Block(-8,19,-2,minecraft:concrete)
Block(-8,19,-1,minecraft:concrete)
Block(-8,19,0,minecraft:concrete)
Block(-8,19,1,minecraft:concrete)
Block(-8,19,2,minecraft:concrete)
Block(-8,19,3,minecraft:concrete)
Block(-8,19,4,minecraft:concrete)
Block(-8,19,5,minecraft:concrete)
Block(-8,19,6,minecraft:concrete)
Block(-8,19,7,minecraft:iron_block:0)
Block(-8,19,8,AIR:0)
Block(-8,20,-7,minecraft:concrete)
Block(-8,20,-6,minecraft:furnace:4)
Block(-8,20,-5,minecraft:furnace:4)
Block(-8,20,-4,minecraft:furnace:4)
Block(-8,20,-3,minecraft:stone)
Block(-8,20,-2,AIR:0)
Block(-8,20,-1,quark:framed_glass)
Block(-8,20,0,minecraft:stone)
Block(-8,20,1,AIR:0)
Block(-8,20,2,AIR:0)
Block(-8,20,3,AIR:0)
Block(-8,20,4,minecraft:stone)
Block(-8,20,5,minecraft:bone_block)
Block(-8,20,6,minecraft:concrete)
Block(-8,20,7,minecraft:iron_block:0)
Block(-8,20,8,AIR:0)
Block(-8,21,-7,minecraft:concrete)
Block(-8,21,-6,quark:grate)
Block(-8,21,-5,quark:grate)
Block(-8,21,-4,quark:grate)
Block(-8,21,-3,AIR:0)
Block(-8,21,-2,AIR:0)
Block(-8,21,-1,quark:framed_glass)
Block(-8,21,0,AIR:0)
Block(-8,21,1,AIR:0)
Block(-8,21,2,AIR:0)
Block(-8,21,3,AIR:0)
Block(-8,21,4,AIR:0)
Block(-8,21,5,AIR:0)
Block(-8,21,6,CONCRETE:15)
Block(-8,21,7,minecraft:iron_block:0)
Block(-8,21,8,AIR:0)
Block(-8,22,-7,minecraft:concrete)
Block(-8,22,-6,minecraft:stone_brick_stairs:2)
Block(-8,22,-5,minecraft:iron_block)
Block(-8,22,-4,minecraft:stone_brick_stairs)
Block(-8,22,-3,AIR:0)
Block(-8,22,-2,minecraft:planks,../../../../Chests/Loot/manhunt_vagrant_scrap.nbt)
Block(-8,22,-1,quark:framed_glass)
Block(-8,22,0,AIR:0)
Block(-8,22,1,AIR:0)
Block(-8,22,2,AIR:0)
Block(-8,22,3,AIR:0)
Block(-8,22,4,AIR:0)
Block(-8,22,5,AIR:0)
Block(-8,22,6,CONCRETE:14)
Block(-8,22,7,minecraft:iron_block:0)
Block(-8,22,8,minecraft:iron_block:0)
Block(-8,23,-7,minecraft:concrete)
Block(-8,23,-6,minecraft:iron_block:1)
Block(-8,23,-5,quark:stone_marble_bricks_slab:8)
Block(-8,23,-4,quark:stone_marble_bricks_slab:8)
Block(-8,23,-3,quark:stone_marble_bricks_slab:8)
Block(-8,23,-2,minecraft:iron_block:1)
Block(-8,23,-1,minecraft:concrete)
Block(-8,23,0,AIR:0)
Block(-8,23,1,AIR:0)
Block(-8,23,2,AIR:0)
Block(-8,23,3,AIR:0)
Block(-8,23,4,AIR:0)
Block(-8,23,5,AIR:0)
Block(-8,23,6,minecraft:concrete)
Block(-8,23,7,minecraft:concrete)
Block(-8,23,8,minecraft:concrete)
Block(-8,24,-7,minecraft:concrete)
Block(-8,24,-6,minecraft:planks:3)
Block(-8,24,-5,AIR:0)
Block(-8,24,-4,AIR:0)
Block(-8,24,-3,AIR:0)
Block(-8,24,-2,minecraft:furnace)
Block(-8,24,-1,quark:framed_glass_pane)
Block(-8,24,0,AIR:0)
Block(-8,24,1,AIR:0)
Block(-8,24,2,AIR:0)
Block(-8,24,3,AIR:0)
Block(-8,24,4,AIR:0)
Block(-8,24,5,AIR:0)
Block(-8,24,6,quark:framed_glass_pane)
Block(-8,24,7,minecraft:planks:8,../../../../Chests/Loot/manhunt_vagrant_scrap.nbt)
Block(-8,24,8,minecraft:planks:8,../../../../Chests/Loot/manhunt_vagrant_scrap.nbt)
Block(-8,25,-7,minecraft:concrete)
Block(-8,25,-6,minecraft:stonebrick:3)
Block(-8,25,-5,AIR:0)
Block(-8,25,-4,AIR:0)
Block(-8,25,-3,AIR:0)
Block(-8,25,-2,quark:grate)
Block(-8,25,-1,quark:framed_glass_pane)
Block(-8,25,0,AIR:0)
Block(-8,25,1,AIR:0)
Block(-8,25,2,AIR:0)
Block(-8,25,3,AIR:0)
Block(-8,25,4,AIR:0)
Block(-8,25,5,AIR:0)
Block(-8,25,6,quark:framed_glass_pane)
Block(-8,25,7,AIR:0)
Block(-8,25,8,minecraft:stonebrick:5)
Block(-8,26,-7,minecraft:concrete)
Block(-8,26,-6,minecraft:planks:2,../../../../Chests/Loot/manhunt_vagrant_scrap.nbt)
Block(-8,26,-5,AIR:0)
Block(-8,26,-4,AIR:0)
Block(-8,26,-3,AIR:0)
Block(-8,26,-2,minecraft:stone_brick_stairs:2)
Block(-8,26,-1,quark:framed_glass_pane)
Block(-8,26,0,AIR:0)
Block(-8,26,1,AIR:0)
Block(-8,26,2,AIR:0)
Block(-8,26,3,AIR:0)
Block(-8,26,4,AIR:0)
Block(-8,26,5,WEB:0)
Block(-8,26,6,quark:framed_glass_pane)
Block(-8,26,7,AIR:0)
Block(-8,26,8,minecraft:glowstone)
Block(-8,27,-7,minecraft:concrete)
Block(-8,27,-6,minecraft:concrete)
Block(-8,27,-5,minecraft:concrete)
Block(-8,27,-4,minecraft:concrete)
Block(-8,27,-3,minecraft:concrete)
Block(-8,27,-2,minecraft:concrete)
Block(-8,27,-1,minecraft:concrete)
Block(-8,27,0,minecraft:concrete)
Block(-8,27,1,minecraft:concrete)
Block(-8,27,2,minecraft:concrete)
Block(-8,27,3,minecraft:concrete)
Block(-8,27,4,minecraft:concrete)
Block(-8,27,5,minecraft:concrete)
Block(-8,27,6,minecraft:concrete)
Block(-8,27,7,minecraft:concrete)
Block(-8,27,8,minecraft:concrete)
Block(-7,0,-7,minecraft:concrete)
Block(-7,0,-6,minecraft:concrete)
Block(-7,0,-5,minecraft:concrete)
Block(-7,0,-4,minecraft:concrete)
Block(-7,0,-3,minecraft:concrete)
Block(-7,0,-2,minecraft:concrete)
Block(-7,0,-1,minecraft:concrete)
Block(-7,0,0,minecraft:concrete)
Block(-7,0,1,minecraft:concrete)
Block(-7,0,2,minecraft:concrete)
Block(-7,0,3,minecraft:concrete)
Block(-7,0,4,minecraft:concrete)
Block(-7,0,5,minecraft:concrete)
Block(-7,0,6,minecraft:concrete)
Block(-7,0,7,minecraft:concrete)
Block(-7,0,8,minecraft:concrete)
Block(-7,1,-7,minecraft:concrete)
Block(-7,1,-6,STATIONARY_WATER:0)
Block(-7,1,-5,STATIONARY_WATER:0)
Block(-7,1,-4,STATIONARY_WATER:0)
Block(-7,1,-3,DIRT:1)
Block(-7,1,-2,DIRT:1)
Block(-7,1,-1,SOIL:7)
Block(-7,1,0,STATIONARY_WATER:0)
Block(-7,1,1,STATIONARY_WATER:0)
Block(-7,1,2,minecraft:concrete)
Block(-7,1,3,minecraft:stonebrick:14)
Block(-7,1,4,minecraft:stonebrick:14)
Block(-7,1,5,STATIONARY_WATER:0)
Block(-7,1,6,minecraft:dirt)
Block(-7,1,7,minecraft:stonebrick:14)
Block(-7,1,8,minecraft:stonebrick:14)
Block(-7,2,-7,minecraft:concrete)
Block(-7,2,-6,minecraft:water:1)
Block(-7,2,-5,AIR:0)
Block(-7,2,-4,minecraft:water:2)
Block(-7,2,-3,minecraft:tallgrass:4)
Block(-7,2,-2,AIR:0)
Block(-7,2,-1,CROPS:7)
Block(-7,2,0,AIR:0)
Block(-7,2,1,minecraft:water:2)
Block(-7,2,2,minecraft:concrete)
Block(-7,2,3,AIR:0)
Block(-7,2,4,minecraft:tallgrass:2)
Block(-7,2,5,AIR:0)
Block(-7,2,6,AIR:0)
Block(-7,2,7,CROPS:7)
Block(-7,2,8,minecraft:glowstone)
Block(-7,3,-7,minecraft:concrete)
Block(-7,3,-6,AIR:0)
Block(-7,3,-5,AIR:0)
Block(-7,3,-4,AIR:0)
Block(-7,3,-3,AIR:0)
Block(-7,3,-2,AIR:0)
Block(-7,3,-1,AIR:0)
Block(-7,3,0,AIR:0)
Block(-7,3,1,AIR:0)
Block(-7,3,2,minecraft:glass)
Block(-7,3,3,AIR:0)
Block(-7,3,4,AIR:0)
Block(-7,3,5,AIR:0)
Block(-7,3,6,AIR:0)
Block(-7,3,7,AIR:0)
Block(-7,3,8,AIR:0)
Block(-7,4,-7,minecraft:concrete)
Block(-7,4,-6,AIR:0)
Block(-7,4,-5,AIR:0)
Block(-7,4,-4,AIR:0)
Block(-7,4,-3,AIR:0)
Block(-7,4,-2,AIR:0)
Block(-7,4,-1,AIR:0)
Block(-7,4,0,AIR:0)
Block(-7,4,1,AIR:0)
Block(-7,4,2,minecraft:glass)
Block(-7,4,3,AIR:0)
Block(-7,4,4,AIR:0)
Block(-7,4,5,AIR:0)
Block(-7,4,6,AIR:0)
Block(-7,4,7,AIR:0)
Block(-7,4,8,AIR:0)
Block(-7,5,-7,minecraft:concrete)
Block(-7,5,-6,minecraft:concrete)
Block(-7,5,-5,minecraft:concrete)
Block(-7,5,-4,minecraft:concrete)
Block(-7,5,-3,minecraft:concrete)
Block(-7,5,-2,minecraft:concrete)
Block(-7,5,-1,minecraft:concrete)
Block(-7,5,0,minecraft:concrete)
Block(-7,5,1,minecraft:concrete)
Block(-7,5,2,minecraft:concrete)
Block(-7,5,3,AIR:0)
Block(-7,5,4,AIR:0)
Block(-7,5,5,AIR:0)
Block(-7,5,6,AIR:0)
Block(-7,5,7,AIR:0)
Block(-7,5,8,AIR:0)
Block(-7,6,-7,minecraft:concrete)
Block(-7,6,-6,quark:grate)
Block(-7,6,-5,quark:grate)
Block(-7,6,-4,minecraft:concrete)
Block(-7,6,-3,CONCRETE:15)
Block(-7,6,-2,CONCRETE:15)
Block(-7,6,-1,minecraft:concrete)
Block(-7,6,0,quark:grate)
Block(-7,6,1,quark:grate)
Block(-7,6,2,minecraft:concrete)
Block(-7,6,3,AIR:0)
Block(-7,6,4,AIR:0)
Block(-7,6,5,AIR:0)
Block(-7,6,6,AIR:0)
Block(-7,6,7,AIR:0)
Block(-7,6,8,AIR:0)
Block(-7,7,-7,minecraft:concrete)
Block(-7,7,-6,AIR:0)
Block(-7,7,-5,AIR:0)
Block(-7,7,-4,AIR:0)
Block(-7,7,-3,AIR:0)
Block(-7,7,-2,AIR:0)
Block(-7,7,-1,AIR:0)
Block(-7,7,0,AIR:0)
Block(-7,7,1,AIR:0)
Block(-7,7,2,minecraft:concrete)
Block(-7,7,3,AIR:0)
Block(-7,7,4,AIR:0)
Block(-7,7,5,AIR:0)
Block(-7,7,6,AIR:0)
Block(-7,7,7,AIR:0)
Block(-7,7,8,AIR:0)
Block(-7,8,-7,minecraft:concrete)
Block(-7,8,-6,AIR:0)
Block(-7,8,-5,AIR:0)
Block(-7,8,-4,AIR:0)
Block(-7,8,-3,AIR:0)
Block(-7,8,-2,AIR:0)
Block(-7,8,-1,AIR:0)
Block(-7,8,0,AIR:0)
Block(-7,8,1,AIR:0)
Block(-7,8,2,minecraft:concrete)
Block(-7,8,3,AIR:0)
Block(-7,8,4,AIR:0)
Block(-7,8,5,AIR:0)
Block(-7,8,6,AIR:0)
Block(-7,8,7,AIR:0)
Block(-7,8,8,AIR:0)
Block(-7,9,-7,minecraft:concrete)
Block(-7,9,-6,AIR:0)
Block(-7,9,-5,AIR:0)
Block(-7,9,-4,AIR:0)
Block(-7,9,-3,AIR:0)
Block(-7,9,-2,AIR:0)
Block(-7,9,-1,AIR:0)
Block(-7,9,0,AIR:0)
Block(-7,9,1,AIR:0)
Block(-7,9,2,minecraft:concrete)
Block(-7,9,3,AIR:0)
Block(-7,9,4,AIR:0)
Block(-7,9,5,AIR:0)
Block(-7,9,6,minecraft:stonebrick:2)
Block(-7,9,7,AIR:0)
Block(-7,9,8,AIR:0)
Block(-7,10,-7,minecraft:concrete)
Block(-7,10,-6,AIR:0)
Block(-7,10,-5,AIR:0)
Block(-7,10,-4,AIR:0)
Block(-7,10,-3,AIR:0)
Block(-7,10,-2,AIR:0)
Block(-7,10,-1,AIR:0)
Block(-7,10,0,AIR:0)
Block(-7,10,1,AIR:0)
Block(-7,10,2,minecraft:concrete)
Block(-7,10,3,minecraft:concrete)
Block(-7,10,4,minecraft:concrete)
Block(-7,10,5,minecraft:concrete)
Block(-7,10,6,minecraft:concrete)
Block(-7,10,7,minecraft:concrete)
Block(-7,10,8,minecraft:concrete)
Block(-7,11,-7,minecraft:concrete)
Block(-7,11,-6,minecraft:concrete)
Block(-7,11,-5,minecraft:concrete)
Block(-7,11,-4,minecraft:concrete)
Block(-7,11,-3,minecraft:concrete)
Block(-7,11,-2,minecraft:concrete)
Block(-7,11,-1,minecraft:concrete)
Block(-7,11,0,minecraft:concrete)
Block(-7,11,1,minecraft:concrete)
Block(-7,11,2,minecraft:concrete)
Block(-7,11,3,minecraft:concrete)
Block(-7,11,4,minecraft:concrete)
Block(-7,11,5,minecraft:concrete)
Block(-7,11,6,minecraft:concrete)
Block(-7,11,7,minecraft:concrete)
Block(-7,11,8,minecraft:concrete)
Block(-7,12,-7,minecraft:concrete)
Block(-7,12,-6,minecraft:concrete)
Block(-7,12,-5,minecraft:concrete)
Block(-7,12,-4,minecraft:concrete)
Block(-7,12,-3,minecraft:concrete)
Block(-7,12,-2,minecraft:concrete)
Block(-7,12,-1,minecraft:concrete)
Block(-7,12,0,minecraft:concrete)
Block(-7,12,1,minecraft:concrete)
Block(-7,12,2,minecraft:concrete)
Block(-7,12,3,minecraft:concrete)
Block(-7,12,4,minecraft:concrete)
Block(-7,12,5,minecraft:concrete)
Block(-7,12,6,minecraft:concrete)
Block(-7,12,7,minecraft:concrete)
Block(-7,12,8,AIR:0)
Block(-7,13,-7,minecraft:concrete)
Block(-7,13,-6,minecraft:concrete)
Block(-7,13,-5,minecraft:stone)
Block(-7,13,-4,minecraft:tallgrass)
Block(-7,13,-3,minecraft:concrete)
Block(-7,13,-2,AIR:0)
Block(-7,13,-1,minecraft:stone)
Block(-7,13,0,minecraft:concrete)
Block(-7,13,1,AIR:0)
Block(-7,13,2,AIR:0)
Block(-7,13,3,minecraft:concrete)
Block(-7,13,4,minecraft:concrete)
Block(-7,13,5,minecraft:concrete)
Block(-7,13,6,minecraft:concrete)
Block(-7,13,7,minecraft:concrete)
Block(-7,13,8,AIR:0)
Block(-7,14,-7,minecraft:concrete)
Block(-7,14,-6,minecraft:concrete)
Block(-7,14,-5,AIR:0)
Block(-7,14,-4,AIR:0)
Block(-7,14,-3,minecraft:concrete)
Block(-7,14,-2,AIR:0)
Block(-7,14,-1,AIR:0)
Block(-7,14,0,minecraft:concrete)
Block(-7,14,1,AIR:0)
Block(-7,14,2,AIR:0)
Block(-7,14,3,minecraft:concrete)
Block(-7,14,4,minecraft:concrete)
Block(-7,14,5,minecraft:concrete)
Block(-7,14,6,minecraft:concrete)
Block(-7,14,7,minecraft:concrete)
Block(-7,14,8,AIR:0)
Block(-7,15,-7,minecraft:concrete)
Block(-7,15,-6,minecraft:concrete)
Block(-7,15,-5,AIR:0)
Block(-7,15,-4,AIR:0)
Block(-7,15,-3,minecraft:concrete)
Block(-7,15,-2,AIR:0)
Block(-7,15,-1,AIR:0)
Block(-7,15,0,minecraft:concrete)
Block(-7,15,1,AIR:0)
Block(-7,15,2,AIR:0)
Block(-7,15,3,minecraft:concrete)
Block(-7,15,4,minecraft:concrete)
Block(-7,15,5,minecraft:concrete)
Block(-7,15,6,minecraft:concrete)
Block(-7,15,7,minecraft:concrete)
Block(-7,15,8,AIR:0)
Block(-7,16,-7,minecraft:concrete)
Block(-7,16,-6,minecraft:concrete)
Block(-7,16,-5,minecraft:concrete)
Block(-7,16,-4,minecraft:concrete)
Block(-7,16,-3,minecraft:concrete)
Block(-7,16,-2,minecraft:concrete)
Block(-7,16,-1,minecraft:concrete)
Block(-7,16,0,minecraft:concrete)
Block(-7,16,1,minecraft:concrete)
Block(-7,16,2,minecraft:concrete)
Block(-7,16,3,minecraft:concrete)
Block(-7,16,4,minecraft:concrete)
Block(-7,16,5,minecraft:concrete)
Block(-7,16,6,minecraft:concrete)
Block(-7,16,7,minecraft:concrete)
Block(-7,16,8,AIR:0)
Block(-7,17,-7,minecraft:concrete)
Block(-7,17,-6,minecraft:concrete)
Block(-7,17,-5,minecraft:concrete)
Block(-7,17,-4,minecraft:concrete)
Block(-7,17,-3,minecraft:concrete)
Block(-7,17,-2,minecraft:concrete)
Block(-7,17,-1,minecraft:concrete)
Block(-7,17,0,minecraft:concrete)
Block(-7,17,1,minecraft:concrete)
Block(-7,17,2,minecraft:concrete)
Block(-7,17,3,minecraft:concrete)
Block(-7,17,4,minecraft:concrete)
Block(-7,17,5,minecraft:concrete)
Block(-7,17,6,minecraft:concrete)
Block(-7,17,7,minecraft:concrete)
Block(-7,17,8,AIR:0)
Block(-7,18,-7,minecraft:concrete)
Block(-7,18,-6,minecraft:concrete)
Block(-7,18,-5,minecraft:concrete)
Block(-7,18,-4,minecraft:concrete)
Block(-7,18,-3,minecraft:concrete)
Block(-7,18,-2,minecraft:concrete)
Block(-7,18,-1,minecraft:concrete)
Block(-7,18,0,minecraft:concrete)
Block(-7,18,1,minecraft:concrete)
Block(-7,18,2,minecraft:concrete)
Block(-7,18,3,minecraft:concrete)
Block(-7,18,4,minecraft:concrete)
Block(-7,18,5,minecraft:concrete)
Block(-7,18,6,minecraft:concrete)
Block(-7,18,7,minecraft:concrete)
Block(-7,18,8,AIR:0)
Block(-7,19,-7,minecraft:concrete)
Block(-7,19,-6,minecraft:concrete)
Block(-7,19,-5,minecraft:concrete)
Block(-7,19,-4,minecraft:concrete)
Block(-7,19,-3,minecraft:concrete)
Block(-7,19,-2,minecraft:concrete)
Block(-7,19,-1,minecraft:concrete)
Block(-7,19,0,minecraft:concrete)
Block(-7,19,1,minecraft:concrete)
Block(-7,19,2,minecraft:concrete)
Block(-7,19,3,minecraft:concrete)
Block(-7,19,4,minecraft:concrete)
Block(-7,19,5,minecraft:concrete)
Block(-7,19,6,minecraft:concrete)
Block(-7,19,7,minecraft:iron_bars:0)
Block(-7,19,8,minecraft:iron_bars:0)
Block(-7,20,-7,minecraft:concrete)
Block(-7,20,-6,minecraft:furnace:5)
Block(-7,20,-5,minecraft:furnace:5)
Block(-7,20,-4,minecraft:furnace:5)
Block(-7,20,-3,minecraft:stonebrick)
Block(-7,20,-2,minecraft:stonebrick)
Block(-7,20,-1,minecraft:concrete)
Block(-7,20,0,AIR:0)
Block(-7,20,1,AIR:0)
Block(-7,20,2,AIR:0)
Block(-7,20,3,minecraft:stone)
Block(-7,20,4,minecraft:stonebrick)
Block(-7,20,5,AIR:0)
Block(-7,20,6,minecraft:concrete)
Block(-7,20,7,minecraft:iron_bars:0)
Block(-7,20,8,minecraft:iron_bars:0)
Block(-7,21,-7,minecraft:concrete)
Block(-7,21,-6,quark:grate)
Block(-7,21,-5,quark:grate)
Block(-7,21,-4,quark:grate)
Block(-7,21,-3,AIR:0)
Block(-7,21,-2,minecraft:stonebrick)
Block(-7,21,-1,minecraft:concrete)
Block(-7,21,0,AIR:0)
Block(-7,21,1,AIR:0)
Block(-7,21,2,AIR:0)
Block(-7,21,3,AIR:0)
Block(-7,21,4,AIR:0)
Block(-7,21,5,AIR:0)
Block(-7,21,6,CONCRETE:14)
Block(-7,21,7,minecraft:concrete)
Block(-7,21,8,AIR:0)
Block(-7,22,-7,minecraft:concrete)
Block(-7,22,-6,minecraft:stone_brick_stairs:2)
Block(-7,22,-5,minecraft:iron_block)
Block(-7,22,-4,minecraft:stone_brick_stairs)
Block(-7,22,-3,AIR:0)
Block(-7,22,-2,minecraft:bookshelf:0)
Block(-7,22,-1,minecraft:concrete)
Block(-7,22,0,AIR:0)
Block(-7,22,1,AIR:0)
Block(-7,22,2,AIR:0)
Block(-7,22,3,AIR:0)
Block(-7,22,4,AIR:0)
Block(-7,22,5,AIR:0)
Block(-7,22,6,CONCRETE:15)
Block(-7,22,7,minecraft:concrete)
Block(-7,22,8,minecraft:concrete)
Block(-7,23,-7,minecraft:concrete)
Block(-7,23,-6,minecraft:iron_block:1)
Block(-7,23,-5,quark:stone_marble_bricks_slab:8)
Block(-7,23,-4,quark:stone_marble_bricks_slab:8)
Block(-7,23,-3,quark:stone_marble_bricks_slab:8)
Block(-7,23,-2,minecraft:iron_block:1)
Block(-7,23,-1,minecraft:concrete)
Block(-7,23,0,AIR:0)
Block(-7,23,1,AIR:0)
Block(-7,23,2,AIR:0)
Block(-7,23,3,AIR:0)
Block(-7,23,4,AIR:0)
Block(-7,23,5,AIR:0)
Block(-7,23,6,minecraft:concrete)
Block(-7,23,7,minecraft:concrete)
Block(-7,23,8,minecraft:concrete)
Block(-7,24,-7,minecraft:concrete)
Block(-7,24,-6,minecraft:stonebrick:2)
Block(-7,24,-5,minecraft:stonebrick)
Block(-7,24,-4,AIR:0)
Block(-7,24,-3,AIR:0)
Block(-7,24,-2,minecraft:planks:3,../../../../Chests/Loot/manhunt_vagrant_scrap.nbt)
Block(-7,24,-1,quark:framed_glass_pane)
Block(-7,24,0,AIR:0)
Block(-7,24,1,AIR:0)
Block(-7,24,2,AIR:0)
Block(-7,24,3,AIR:0)
Block(-7,24,4,AIR:0)
Block(-7,24,5,AIR:0)
Block(-7,24,6,minecraft:concrete)
Block(-7,24,7,AIR:0)
Block(-7,24,8,minecraft:bone_block)
Block(-7,25,-7,minecraft:concrete)
Block(-7,25,-6,minecraft:stonebrick:3)
Block(-7,25,-5,AIR:0)
Block(-7,25,-4,AIR:0)
Block(-7,25,-3,AIR:0)
Block(-7,25,-2,AIR:0)
Block(-7,25,-1,quark:framed_glass_pane)
Block(-7,25,0,AIR:0)
Block(-7,25,1,AIR:0)
Block(-7,25,2,AIR:0)
Block(-7,25,3,AIR:0)
Block(-7,25,4,AIR:0)
Block(-7,25,5,AIR:0)
Block(-7,25,6,minecraft:concrete)
Block(-7,25,7,AIR:0)
Block(-7,25,8,AIR:0)
Block(-7,26,-7,minecraft:concrete)
Block(-7,26,-6,minecraft:planks:10,../../../../Chests/Loot/manhunt_vagrant_scrap.nbt)
Block(-7,26,-5,AIR:0)
Block(-7,26,-4,AIR:0)
Block(-7,26,-3,AIR:0)
Block(-7,26,-2,minecraft:planks,../../../../Chests/Loot/manhunt_vagrant_scrap.nbt)
Block(-7,26,-1,quark:framed_glass_pane)
Block(-7,26,0,AIR:0)
Block(-7,26,1,AIR:0)
Block(-7,26,2,WEB:0)
Block(-7,26,3,AIR:0)
Block(-7,26,4,AIR:0)
Block(-7,26,5,AIR:0)
Block(-7,26,6,minecraft:concrete)
Block(-7,26,7,AIR:0)
Block(-7,26,8,AIR:0)
Block(-7,27,-7,minecraft:concrete)
Block(-7,27,-6,minecraft:concrete)
Block(-7,27,-5,minecraft:concrete)
Block(-7,27,-4,minecraft:concrete)
Block(-7,27,-3,minecraft:concrete)
Block(-7,27,-2,minecraft:concrete)
Block(-7,27,-1,minecraft:concrete)
Block(-7,27,0,minecraft:concrete)
Block(-7,27,1,minecraft:concrete)
Block(-7,27,2,minecraft:concrete)
Block(-7,27,3,minecraft:concrete)
Block(-7,27,4,minecraft:concrete)
Block(-7,27,5,minecraft:concrete)
Block(-7,27,6,minecraft:concrete)
Block(-7,27,7,minecraft:concrete)
Block(-7,27,8,minecraft:concrete)
Block(-6,0,-7,minecraft:concrete)
Block(-6,0,-6,minecraft:concrete)
Block(-6,0,-5,minecraft:concrete)
Block(-6,0,-4,minecraft:concrete)
Block(-6,0,-3,minecraft:concrete)
Block(-6,0,-2,minecraft:concrete)
Block(-6,0,-1,minecraft:concrete)
Block(-6,0,0,minecraft:concrete)
Block(-6,0,1,minecraft:concrete)
Block(-6,0,2,minecraft:concrete)
Block(-6,0,3,minecraft:concrete)
Block(-6,0,4,minecraft:concrete)
Block(-6,0,5,minecraft:concrete)
Block(-6,0,6,minecraft:concrete)
Block(-6,0,7,minecraft:concrete)
Block(-6,0,8,minecraft:concrete)
Block(-6,1,-7,minecraft:concrete)
Block(-6,1,-6,minecraft:dirt)
Block(-6,1,-5,STATIONARY_WATER:0)
Block(-6,1,-4,DIRT:2)
Block(-6,1,-3,SOIL:7)
Block(-6,1,-2,minecraft:dirt)
Block(-6,1,-1,DIRT:2)
Block(-6,1,0,STATIONARY_WATER:0)
Block(-6,1,1,STATIONARY_WATER:0)
Block(-6,1,2,minecraft:concrete)
Block(-6,1,3,minecraft:stonebrick:14)
Block(-6,1,4,minecraft:stonebrick:14)
Block(-6,1,5,STATIONARY_WATER:0)
Block(-6,1,6,minecraft:dirt)
Block(-6,1,7,minecraft:dirt)
Block(-6,1,8,minecraft:stonebrick:14)
Block(-6,2,-7,minecraft:concrete)
Block(-6,2,-6,AIR:0)
Block(-6,2,-5,minecraft:water:1)
Block(-6,2,-4,RED_MUSHROOM:0)
Block(-6,2,-3,CROPS:7)
Block(-6,2,-2,AIR:0)
Block(-6,2,-1,minecraft:tallgrass:13)
Block(-6,2,0,minecraft:water:1)
Block(-6,2,1,minecraft:water:2)
Block(-6,2,2,minecraft:concrete)
Block(-6,2,3,AIR:0)
Block(-6,2,4,AIR:0)
Block(-6,2,5,AIR:0)
Block(-6,2,6,AIR:0)
Block(-6,2,7,AIR:0)
Block(-6,2,8,minecraft:tallgrass:2)
Block(-6,3,-7,minecraft:concrete)
Block(-6,3,-6,AIR:0)
Block(-6,3,-5,AIR:0)
Block(-6,3,-4,AIR:0)
Block(-6,3,-3,AIR:0)
Block(-6,3,-2,AIR:0)
Block(-6,3,-1,AIR:0)
Block(-6,3,0,AIR:0)
Block(-6,3,1,AIR:0)
Block(-6,3,2,minecraft:glass)
Block(-6,3,3,AIR:0)
Block(-6,3,4,AIR:0)
Block(-6,3,5,AIR:0)
Block(-6,3,6,AIR:0)
Block(-6,3,7,AIR:0)
Block(-6,3,8,AIR:0)
Block(-6,4,-7,minecraft:concrete)
Block(-6,4,-6,AIR:0)
Block(-6,4,-5,AIR:0)
Block(-6,4,-4,AIR:0)
Block(-6,4,-3,AIR:0)
Block(-6,4,-2,AIR:0)
Block(-6,4,-1,AIR:0)
Block(-6,4,0,AIR:0)
Block(-6,4,1,AIR:0)
Block(-6,4,2,minecraft:glass)
Block(-6,4,3,AIR:0)
Block(-6,4,4,AIR:0)
Block(-6,4,5,AIR:0)
Block(-6,4,6,AIR:0)
Block(-6,4,7,AIR:0)
Block(-6,4,8,AIR:0)
Block(-6,5,-7,minecraft:concrete)
Block(-6,5,-6,minecraft:concrete)
Block(-6,5,-5,minecraft:concrete)
Block(-6,5,-4,minecraft:concrete)
Block(-6,5,-3,minecraft:concrete)
Block(-6,5,-2,minecraft:concrete)
Block(-6,5,-1,minecraft:concrete)
Block(-6,5,0,minecraft:concrete)
Block(-6,5,1,minecraft:concrete)
Block(-6,5,2,minecraft:concrete)
Block(-6,5,3,AIR:0)
Block(-6,5,4,AIR:0)
Block(-6,5,5,AIR:0)
Block(-6,5,6,minecraft:stonebrick:2)
Block(-6,5,7,AIR:0)
Block(-6,5,8,AIR:0)
Block(-6,6,-7,minecraft:concrete)
Block(-6,6,-6,quark:grate)
Block(-6,6,-5,quark:grate)
Block(-6,6,-4,minecraft:concrete)
Block(-6,6,-3,CONCRETE:15)
Block(-6,6,-2,CONCRETE:15)
Block(-6,6,-1,minecraft:concrete)
Block(-6,6,0,quark:grate)
Block(-6,6,1,quark:grate)
Block(-6,6,2,minecraft:concrete)
Block(-6,6,3,AIR:0)
Block(-6,6,4,AIR:0)
Block(-6,6,5,AIR:0)
Block(-6,6,6,minecraft:stonebrick:2)
Block(-6,6,7,AIR:0)
Block(-6,6,8,AIR:0)
Block(-6,7,-7,minecraft:concrete)
Block(-6,7,-6,AIR:0)
Block(-6,7,-5,AIR:0)
Block(-6,7,-4,AIR:0)
Block(-6,7,-3,AIR:0)
Block(-6,7,-2,AIR:0)
Block(-6,7,-1,minecraft:stone)
Block(-6,7,0,AIR:0)
Block(-6,7,1,AIR:0)
Block(-6,7,2,minecraft:concrete)
Block(-6,7,3,AIR:0)
Block(-6,7,4,AIR:0)
Block(-6,7,5,AIR:0)
Block(-6,7,6,minecraft:stonebrick:2)
Block(-6,7,7,AIR:0)
Block(-6,7,8,AIR:0)
Block(-6,8,-7,minecraft:concrete)
Block(-6,8,-6,AIR:0)
Block(-6,8,-5,AIR:0)
Block(-6,8,-4,AIR:0)
Block(-6,8,-3,AIR:0)
Block(-6,8,-2,AIR:0)
Block(-6,8,-1,AIR:0)
Block(-6,8,0,AIR:0)
Block(-6,8,1,AIR:0)
Block(-6,8,2,minecraft:concrete)
Block(-6,8,3,AIR:0)
Block(-6,8,4,AIR:0)
Block(-6,8,5,AIR:0)
Block(-6,8,6,minecraft:stonebrick:2)
Block(-6,8,7,minecraft:stonebrick:2)
Block(-6,8,8,AIR:0)
Block(-6,9,-7,minecraft:concrete)
Block(-6,9,-6,AIR:0)
Block(-6,9,-5,AIR:0)
Block(-6,9,-4,AIR:0)
Block(-6,9,-3,AIR:0)
Block(-6,9,-2,AIR:0)
Block(-6,9,-1,AIR:0)
Block(-6,9,0,AIR:0)
Block(-6,9,1,AIR:0)
Block(-6,9,2,minecraft:concrete)
Block(-6,9,3,AIR:0)
Block(-6,9,4,AIR:0)
Block(-6,9,5,AIR:0)
Block(-6,9,6,minecraft:stonebrick:2)
Block(-6,9,7,minecraft:stonebrick:2)
Block(-6,9,8,AIR:0)
Block(-6,10,-7,minecraft:concrete)
Block(-6,10,-6,AIR:0)
Block(-6,10,-5,AIR:0)
Block(-6,10,-4,AIR:0)
Block(-6,10,-3,AIR:0)
Block(-6,10,-2,AIR:0)
Block(-6,10,-1,AIR:0)
Block(-6,10,0,AIR:0)
Block(-6,10,1,AIR:0)
Block(-6,10,2,minecraft:concrete)
Block(-6,10,3,minecraft:concrete)
Block(-6,10,4,minecraft:concrete)
Block(-6,10,5,minecraft:concrete)
Block(-6,10,6,minecraft:concrete)
Block(-6,10,7,minecraft:concrete)
Block(-6,10,8,minecraft:concrete)
Block(-6,11,-7,minecraft:concrete)
Block(-6,11,-6,minecraft:concrete)
Block(-6,11,-5,minecraft:concrete)
Block(-6,11,-4,minecraft:concrete)
Block(-6,11,-3,minecraft:concrete)
Block(-6,11,-2,minecraft:concrete)
Block(-6,11,-1,minecraft:concrete)
Block(-6,11,0,minecraft:concrete)
Block(-6,11,1,minecraft:concrete)
Block(-6,11,2,minecraft:concrete)
Block(-6,11,3,minecraft:concrete)
Block(-6,11,4,minecraft:concrete)
Block(-6,11,5,minecraft:concrete)
Block(-6,11,6,minecraft:concrete)
Block(-6,11,7,minecraft:concrete)
Block(-6,11,8,minecraft:concrete)
Block(-6,12,-7,minecraft:concrete)
Block(-6,12,-6,minecraft:concrete)
Block(-6,12,-5,minecraft:concrete)
Block(-6,12,-4,minecraft:concrete)
Block(-6,12,-3,minecraft:concrete)
Block(-6,12,-2,minecraft:concrete)
Block(-6,12,-1,minecraft:concrete)
Block(-6,12,0,minecraft:concrete)
Block(-6,12,1,minecraft:concrete)
Block(-6,12,2,minecraft:concrete)
Block(-6,12,3,minecraft:concrete)
Block(-6,12,4,minecraft:concrete)
Block(-6,12,5,minecraft:concrete)
Block(-6,12,6,minecraft:concrete)
Block(-6,12,7,minecraft:concrete)
Block(-6,12,8,AIR:0)
Block(-6,13,-7,minecraft:concrete)
Block(-6,13,-6,minecraft:bone_block)
Block(-6,13,-5,AIR:0)
Block(-6,13,-4,AIR:0)
Block(-6,13,-3,AIR:0)
Block(-6,13,-2,AIR:0)
Block(-6,13,-1,minecraft:stonebrick)
Block(-6,13,0,AIR:0)
Block(-6,13,1,AIR:0)
Block(-6,13,2,minecraft:stone)
Block(-6,13,3,AIR:0)
Block(-6,13,4,minecraft:concrete)
Block(-6,13,5,minecraft:concrete)
Block(-6,13,6,minecraft:concrete)
Block(-6,13,7,minecraft:concrete)
Block(-6,13,8,AIR:0)
Block(-6,14,-7,minecraft:concrete)
Block(-6,14,-6,AIR:0)
Block(-6,14,-5,AIR:0)
Block(-6,14,-4,AIR:0)
Block(-6,14,-3,AIR:0)
Block(-6,14,-2,AIR:0)
Block(-6,14,-1,AIR:0)
Block(-6,14,0,AIR:0)
Block(-6,14,1,AIR:0)
Block(-6,14,2,AIR:0)
Block(-6,14,3,AIR:0)
Block(-6,14,4,minecraft:concrete)
Block(-6,14,5,minecraft:concrete)
Block(-6,14,6,minecraft:concrete)
Block(-6,14,7,minecraft:concrete)
Block(-6,14,8,AIR:0)
Block(-6,15,-7,minecraft:concrete)
Block(-6,15,-6,AIR:0)
Block(-6,15,-5,WEB:0)
Block(-6,15,-4,AIR:0)
Block(-6,15,-3,AIR:0)
Block(-6,15,-2,AIR:0)
Block(-6,15,-1,AIR:0)
Block(-6,15,0,AIR:0)
Block(-6,15,1,AIR:0)
Block(-6,15,2,AIR:0)
Block(-6,15,3,AIR:0)
Block(-6,15,4,minecraft:concrete)
Block(-6,15,5,minecraft:concrete)
Block(-6,15,6,minecraft:concrete)
Block(-6,15,7,minecraft:concrete)
Block(-6,15,8,AIR:0)
Block(-6,16,-7,minecraft:concrete)
Block(-6,16,-6,minecraft:concrete)
Block(-6,16,-5,minecraft:concrete)
Block(-6,16,-4,minecraft:concrete)
Block(-6,16,-3,minecraft:concrete)
Block(-6,16,-2,minecraft:concrete)
Block(-6,16,-1,minecraft:concrete)
Block(-6,16,0,minecraft:concrete)
Block(-6,16,1,minecraft:concrete)
Block(-6,16,2,minecraft:concrete)
Block(-6,16,3,minecraft:concrete)
Block(-6,16,4,minecraft:concrete)
Block(-6,16,5,minecraft:concrete)
Block(-6,16,6,minecraft:concrete)
Block(-6,16,7,minecraft:concrete)
Block(-6,16,8,AIR:0)
Block(-6,17,-7,minecraft:concrete)
Block(-6,17,-6,AIR:0)
Block(-6,17,-5,AIR:0)
Block(-6,17,-4,AIR:0)
Block(-6,17,-3,AIR:0)
Block(-6,17,-2,AIR:0)
Block(-6,17,-1,AIR:0)
Block(-6,17,0,minecraft:iron_door)
Block(-6,17,1,AIR:0)
Block(-6,17,2,minecraft:stone)
Block(-6,17,3,minecraft:tallgrass)
Block(-6,17,4,AIR:0)
Block(-6,17,5,minecraft:tallgrass)
Block(-6,17,6,minecraft:concrete)
Block(-6,17,7,minecraft:concrete)
Block(-6,17,8,AIR:0)
Block(-6,18,-7,minecraft:concrete)
Block(-6,18,-6,AIR:0)
Block(-6,18,-5,AIR:0)
Block(-6,18,-4,WEB:0)
Block(-6,18,-3,AIR:0)
Block(-6,18,-2,LEVER:2)
Block(-6,18,-1,AIR:0)
Block(-6,18,0,minecraft:iron_door:9)
Block(-6,18,1,AIR:0)
Block(-6,18,2,AIR:0)
Block(-6,18,3,WEB:0)
Block(-6,18,4,AIR:0)
Block(-6,18,5,AIR:0)
Block(-6,18,6,minecraft:concrete)
Block(-6,18,7,minecraft:concrete)
Block(-6,18,8,AIR:0)
Block(-6,19,-7,minecraft:concrete)
Block(-6,19,-6,minecraft:concrete)
Block(-6,19,-5,minecraft:concrete)
Block(-6,19,-4,minecraft:concrete)
Block(-6,19,-3,minecraft:concrete)
Block(-6,19,-2,minecraft:concrete)
Block(-6,19,-1,minecraft:concrete)
Block(-6,19,0,minecraft:concrete)
Block(-6,19,1,minecraft:concrete)
Block(-6,19,2,minecraft:concrete)
Block(-6,19,3,minecraft:concrete)
Block(-6,19,4,minecraft:concrete)
Block(-6,19,5,minecraft:concrete)
Block(-6,19,6,minecraft:concrete)
Block(-6,19,7,minecraft:iron_bars:0)
Block(-6,19,8,minecraft:iron_bars:0)
Block(-6,20,-7,minecraft:concrete)
Block(-6,20,-6,minecraft:stonebrick)
Block(-6,20,-5,minecraft:stone)
Block(-6,20,-4,AIR:0)
Block(-6,20,-3,minecraft:stone)
Block(-6,20,-2,minecraft:stonebrick)
Block(-6,20,-1,minecraft:concrete)
Block(-6,20,0,AIR:0)
Block(-6,20,1,minecraft:stone)
Block(-6,20,2,minecraft:stonebrick)
Block(-6,20,3,AIR:0)
Block(-6,20,4,AIR:0)
Block(-6,20,5,AIR:0)
Block(-6,20,6,minecraft:concrete)
Block(-6,20,7,minecraft:iron_bars:0)
Block(-6,20,8,minecraft:iron_bars:0)
Block(-6,21,-7,minecraft:concrete)
Block(-6,21,-6,AIR:0)
Block(-6,21,-5,AIR:0)
Block(-6,21,-4,AIR:0)
Block(-6,21,-3,AIR:0)
Block(-6,21,-2,minecraft:stonebrick)
Block(-6,21,-1,minecraft:concrete)
Block(-6,21,0,AIR:0)
Block(-6,21,1,AIR:0)
Block(-6,21,2,AIR:0)
Block(-6,21,3,AIR:0)
Block(-6,21,4,AIR:0)
Block(-6,21,5,AIR:0)
Block(-6,21,6,minecraft:concrete)
Block(-6,21,7,minecraft:concrete)
Block(-6,21,8,AIR:0)
Block(-6,22,-7,minecraft:concrete)
Block(-6,22,-6,AIR:0)
Block(-6,22,-5,WEB:0)
Block(-6,22,-4,AIR:0)
Block(-6,22,-3,AIR:0)
Block(-6,22,-2,minecraft:bookshelf:0)
Block(-6,22,-1,minecraft:concrete)
Block(-6,22,0,AIR:0)
Block(-6,22,1,AIR:0)
Block(-6,22,2,AIR:0)
Block(-6,22,3,AIR:0)
Block(-6,22,4,AIR:0)
Block(-6,22,5,AIR:0)
Block(-6,22,6,minecraft:concrete)
Block(-6,22,7,minecraft:concrete)
Block(-6,22,8,minecraft:concrete)
Block(-6,23,-7,minecraft:concrete)
Block(-6,23,-6,minecraft:iron_block:1)
Block(-6,23,-5,quark:stone_marble_bricks_slab:8)
Block(-6,23,-4,quark:stone_marble_bricks_slab:8)
Block(-6,23,-3,quark:stone_marble_bricks_slab:8)
Block(-6,23,-2,minecraft:iron_block:1)
Block(-6,23,-1,minecraft:concrete)
Block(-6,23,0,AIR:0)
Block(-6,23,1,AIR:0)
Block(-6,23,2,AIR:0)
Block(-6,23,3,AIR:0)
Block(-6,23,4,AIR:0)
Block(-6,23,5,AIR:0)
Block(-6,23,6,minecraft:concrete)
Block(-6,23,7,minecraft:concrete)
Block(-6,23,8,minecraft:concrete)
Block(-6,24,-7,minecraft:concrete)
Block(-6,24,-6,minecraft:stonebrick:10)
Block(-6,24,-5,AIR:0)
Block(-6,24,-4,AIR:0)
Block(-6,24,-3,AIR:0)
Block(-6,24,-2,minecraft:stonebrick)
Block(-6,24,-1,quark:framed_glass_pane)
Block(-6,24,0,AIR:0)
Block(-6,24,1,AIR:0)
Block(-6,24,2,AIR:0)
Block(-6,24,3,AIR:0)
Block(-6,24,4,AIR:0)
Block(-6,24,5,AIR:0)
Block(-6,24,6,quark:framed_glass_pane)
Block(-6,24,7,AIR:0)
Block(-6,24,8,AIR:0)
Block(-6,25,-7,minecraft:concrete)
Block(-6,25,-6,minecraft:stonebrick:10)
Block(-6,25,-5,AIR:0)
Block(-6,25,-4,AIR:0)
Block(-6,25,-3,AIR:0)
Block(-6,25,-2,minecraft:stonebrick)
Block(-6,25,-1,quark:framed_glass_pane)
Block(-6,25,0,AIR:0)
Block(-6,25,1,AIR:0)
Block(-6,25,2,AIR:0)
Block(-6,25,3,minecraft:glowstone)
Block(-6,25,4,AIR:0)
Block(-6,25,5,AIR:0)
Block(-6,25,6,quark:framed_glass_pane)
Block(-6,25,7,AIR:0)
Block(-6,25,8,AIR:0)
Block(-6,26,-7,minecraft:concrete)
Block(-6,26,-6,AIR:0)
Block(-6,26,-5,AIR:0)
Block(-6,26,-4,AIR:0)
Block(-6,26,-3,AIR:0)
Block(-6,26,-2,minecraft:planks,../../../../Chests/Loot/manhunt_vagrant_scrap.nbt)
Block(-6,26,-1,quark:framed_glass_pane)
Block(-6,26,0,AIR:0)
Block(-6,26,1,AIR:0)
Block(-6,26,2,AIR:0)
Block(-6,26,3,AIR:0)
Block(-6,26,4,AIR:0)
Block(-6,26,5,AIR:0)
Block(-6,26,6,quark:framed_glass_pane)
Block(-6,26,7,AIR:0)
Block(-6,26,8,AIR:0)
Block(-6,27,-7,minecraft:concrete)
Block(-6,27,-6,minecraft:concrete)
Block(-6,27,-5,minecraft:concrete)
Block(-6,27,-4,minecraft:concrete)
Block(-6,27,-3,minecraft:concrete)
Block(-6,27,-2,minecraft:concrete)
Block(-6,27,-1,minecraft:concrete)
Block(-6,27,0,minecraft:concrete)
Block(-6,27,1,minecraft:concrete)
Block(-6,27,2,minecraft:concrete)
Block(-6,27,3,minecraft:concrete)
Block(-6,27,4,minecraft:concrete)
Block(-6,27,5,minecraft:concrete)
Block(-6,27,6,minecraft:concrete)
Block(-6,27,7,minecraft:concrete)
Block(-6,27,8,minecraft:concrete)
Block(-5,0,-7,minecraft:concrete)
Block(-5,0,-6,minecraft:concrete)
Block(-5,0,-5,minecraft:concrete)
Block(-5,0,-4,minecraft:concrete)
Block(-5,0,-3,minecraft:concrete)
Block(-5,0,-2,minecraft:concrete)
Block(-5,0,-1,minecraft:concrete)
Block(-5,0,0,minecraft:concrete)
Block(-5,0,1,minecraft:concrete)
Block(-5,0,2,minecraft:concrete)
Block(-5,0,3,minecraft:concrete)
Block(-5,0,4,minecraft:concrete)
Block(-5,0,5,minecraft:concrete)
Block(-5,0,6,minecraft:concrete)
Block(-5,0,7,minecraft:concrete)
Block(-5,0,8,minecraft:concrete)
Block(-5,1,-7,minecraft:concrete)
Block(-5,1,-6,SOIL:7)
Block(-5,1,-5,minecraft:dirt)
Block(-5,1,-4,DIRT:2)
Block(-5,1,-3,minecraft:dirt)
Block(-5,1,-2,DIRT:1)
Block(-5,1,-1,minecraft:dirt:8)
Block(-5,1,0,minecraft:dirt)
Block(-5,1,1,minecraft:dirt)
Block(-5,1,2,minecraft:concrete)
Block(-5,1,3,minecraft:concrete)
Block(-5,1,4,minecraft:stonebrick:14)
Block(-5,1,5,STATIONARY_WATER:0)
Block(-5,1,6,minecraft:stonebrick:14)
Block(-5,1,7,minecraft:stonebrick:14)
Block(-5,1,8,minecraft:stonebrick:14)
Block(-5,2,-7,minecraft:concrete)
Block(-5,2,-6,CROPS:7)
Block(-5,2,-5,RED_MUSHROOM:0)
Block(-5,2,-4,minecraft:tallgrass:13)
Block(-5,2,-3,AIR:0)
Block(-5,2,-2,minecraft:tallgrass:13)
Block(-5,2,-1,minecraft:glowstone)
Block(-5,2,0,CROPS:7)
Block(-5,2,1,CROPS:7)
Block(-5,2,2,minecraft:concrete)
Block(-5,2,3,minecraft:concrete)
Block(-5,2,4,minecraft:grass)
Block(-5,2,5,AIR:0)
Block(-5,2,6,CROPS:7)
Block(-5,2,7,minecraft:grass)
Block(-5,2,8,minecraft:glowstone)
Block(-5,3,-7,minecraft:concrete)
Block(-5,3,-6,AIR:0)
Block(-5,3,-5,AIR:0)
Block(-5,3,-4,AIR:0)
Block(-5,3,-3,AIR:0)
Block(-5,3,-2,AIR:0)
Block(-5,3,-1,AIR:0)
Block(-5,3,0,AIR:0)
Block(-5,3,1,AIR:0)
Block(-5,3,2,minecraft:concrete)
Block(-5,3,3,minecraft:concrete)
Block(-5,3,4,AIR:0)
Block(-5,3,5,AIR:0)
Block(-5,3,6,AIR:0)
Block(-5,3,7,AIR:0)
Block(-5,3,8,AIR:0)
Block(-5,4,-7,minecraft:concrete)
Block(-5,4,-6,AIR:0)
Block(-5,4,-5,AIR:0)
Block(-5,4,-4,AIR:0)
Block(-5,4,-3,AIR:0)
Block(-5,4,-2,AIR:0)
Block(-5,4,-1,AIR:0)
Block(-5,4,0,AIR:0)
Block(-5,4,1,AIR:0)
Block(-5,4,2,minecraft:concrete)
Block(-5,4,3,minecraft:concrete)
Block(-5,4,4,AIR:0)
Block(-5,4,5,AIR:0)
Block(-5,4,6,AIR:0)
Block(-5,4,7,AIR:0)
Block(-5,4,8,AIR:0)
Block(-5,5,-7,minecraft:concrete)
Block(-5,5,-6,minecraft:concrete)
Block(-5,5,-5,minecraft:concrete)
Block(-5,5,-4,minecraft:concrete)
Block(-5,5,-3,minecraft:concrete)
Block(-5,5,-2,minecraft:concrete)
Block(-5,5,-1,minecraft:concrete)
Block(-5,5,0,minecraft:concrete)
Block(-5,5,1,minecraft:concrete)
Block(-5,5,2,minecraft:concrete)
Block(-5,5,3,minecraft:concrete)
Block(-5,5,4,AIR:0)
Block(-5,5,5,AIR:0)
Block(-5,5,6,AIR:0)
Block(-5,5,7,AIR:0)
Block(-5,5,8,AIR:0)
Block(-5,6,-7,minecraft:concrete)
Block(-5,6,-6,quark:grate)
Block(-5,6,-5,quark:grate)
Block(-5,6,-4,minecraft:concrete)
Block(-5,6,-3,CONCRETE:15)
Block(-5,6,-2,CONCRETE:15)
Block(-5,6,-1,minecraft:concrete)
Block(-5,6,0,quark:grate)
Block(-5,6,1,quark:grate)
Block(-5,6,2,minecraft:concrete)
Block(-5,6,3,minecraft:concrete)
Block(-5,6,4,AIR:0)
Block(-5,6,5,AIR:0)
Block(-5,6,6,AIR:0)
Block(-5,6,7,AIR:0)
Block(-5,6,8,AIR:0)
Block(-5,7,-7,minecraft:concrete)
Block(-5,7,-6,AIR:0)
Block(-5,7,-5,AIR:0)
Block(-5,7,-4,AIR:0)
Block(-5,7,-3,AIR:0)
Block(-5,7,-2,AIR:0)
Block(-5,7,-1,AIR:0)
Block(-5,7,0,AIR:0)
Block(-5,7,1,AIR:0)
Block(-5,7,2,minecraft:concrete)
Block(-5,7,3,minecraft:concrete)
Block(-5,7,4,AIR:0)
Block(-5,7,5,AIR:0)
Block(-5,7,6,AIR:0)
Block(-5,7,7,AIR:0)
Block(-5,7,8,AIR:0)
Block(-5,8,-7,minecraft:concrete)
Block(-5,8,-6,AIR:0)
Block(-5,8,-5,AIR:0)
Block(-5,8,-4,AIR:0)
Block(-5,8,-3,AIR:0)
Block(-5,8,-2,AIR:0)
Block(-5,8,-1,AIR:0)
Block(-5,8,0,AIR:0)
Block(-5,8,1,AIR:0)
Block(-5,8,2,minecraft:concrete)
Block(-5,8,3,minecraft:concrete)
Block(-5,8,4,minecraft:iron_bars:0)
Block(-5,8,5,minecraft:iron_bars:0)
Block(-5,8,6,minecraft:iron_bars:0)
Block(-5,8,7,minecraft:iron_bars:0)
Block(-5,8,8,minecraft:iron_bars:0)
Block(-5,9,-7,minecraft:concrete)
Block(-5,9,-6,minecraft:glowstone)
Block(-5,9,-5,AIR:0)
Block(-5,9,-4,AIR:0)
Block(-5,9,-3,AIR:0)
Block(-5,9,-2,AIR:0)
Block(-5,9,-1,AIR:0)
Block(-5,9,0,AIR:0)
Block(-5,9,1,AIR:0)
Block(-5,9,2,minecraft:concrete)
Block(-5,9,3,minecraft:concrete)
Block(-5,9,4,minecraft:concrete)
Block(-5,9,5,minecraft:concrete)
Block(-5,9,6,minecraft:concrete)
Block(-5,9,7,minecraft:concrete)
Block(-5,9,8,minecraft:concrete)
Block(-5,10,-7,minecraft:concrete)
Block(-5,10,-6,AIR:0)
Block(-5,10,-5,AIR:0)
Block(-5,10,-4,AIR:0)
Block(-5,10,-3,AIR:0)
Block(-5,10,-2,AIR:0)
Block(-5,10,-1,AIR:0)
Block(-5,10,0,AIR:0)
Block(-5,10,1,AIR:0)
Block(-5,10,2,minecraft:concrete)
Block(-5,10,3,minecraft:concrete)
Block(-5,10,4,minecraft:concrete)
Block(-5,10,5,minecraft:concrete)
Block(-5,10,6,minecraft:concrete)
Block(-5,10,7,minecraft:concrete)
Block(-5,10,8,minecraft:concrete)
Block(-5,11,-7,minecraft:concrete)
Block(-5,11,-6,minecraft:concrete)
Block(-5,11,-5,minecraft:concrete)
Block(-5,11,-4,minecraft:concrete)
Block(-5,11,-3,minecraft:concrete)
Block(-5,11,-2,minecraft:concrete)
Block(-5,11,-1,minecraft:concrete)
Block(-5,11,0,minecraft:concrete)
Block(-5,11,1,minecraft:concrete)
Block(-5,11,2,minecraft:concrete)
Block(-5,11,3,minecraft:concrete)
Block(-5,11,4,minecraft:concrete)
Block(-5,11,5,minecraft:concrete)
Block(-5,11,6,minecraft:concrete)
Block(-5,11,7,minecraft:concrete)
Block(-5,11,8,minecraft:concrete)
Block(-5,12,-7,minecraft:concrete)
Block(-5,12,-6,minecraft:concrete)
Block(-5,12,-5,minecraft:concrete)
Block(-5,12,-4,minecraft:concrete)
Block(-5,12,-3,minecraft:concrete)
Block(-5,12,-2,minecraft:concrete)
Block(-5,12,-1,minecraft:concrete)
Block(-5,12,0,minecraft:concrete)
Block(-5,12,1,minecraft:concrete)
Block(-5,12,2,minecraft:concrete)
Block(-5,12,3,minecraft:concrete)
Block(-5,12,4,minecraft:concrete)
Block(-5,12,5,minecraft:concrete)
Block(-5,12,6,minecraft:concrete)
Block(-5,12,7,minecraft:iron_block:0)
Block(-5,12,8,minecraft:stonebrick)
Block(-5,13,-7,minecraft:concrete)
Block(-5,13,-6,AIR:0)
Block(-5,13,-5,minecraft:stone)
Block(-5,13,-4,minecraft:stonebrick)
Block(-5,13,-3,AIR:0)
Block(-5,13,-2,AIR:0)
Block(-5,13,-1,AIR:0)
Block(-5,13,0,minecraft:tallgrass)
Block(-5,13,1,AIR:0)
Block(-5,13,2,minecraft:stonebrick)
Block(-5,13,3,minecraft:bone_block)
Block(-5,13,4,minecraft:concrete)
Block(-5,13,5,minecraft:concrete)
Block(-5,13,6,minecraft:concrete)
Block(-5,13,7,minecraft:iron_block:0)
Block(-5,13,8,AIR:0)
Block(-5,14,-7,minecraft:concrete)
Block(-5,14,-6,AIR:0)
Block(-5,14,-5,AIR:0)
Block(-5,14,-4,AIR:0)
Block(-5,14,-3,AIR:0)
Block(-5,14,-2,AIR:0)
Block(-5,14,-1,AIR:0)
Block(-5,14,0,AIR:0)
Block(-5,14,1,AIR:0)
Block(-5,14,2,AIR:0)
Block(-5,14,3,AIR:0)
Block(-5,14,4,minecraft:concrete)
Block(-5,14,5,minecraft:concrete)
Block(-5,14,6,minecraft:concrete)
Block(-5,14,7,minecraft:iron_block:0)
Block(-5,14,8,AIR:0)
Block(-5,15,-7,minecraft:concrete)
Block(-5,15,-6,AIR:0)
Block(-5,15,-5,AIR:0)
Block(-5,15,-4,AIR:0)
Block(-5,15,-3,AIR:0)
Block(-5,15,-2,AIR:0)
Block(-5,15,-1,AIR:0)
Block(-5,15,0,AIR:0)
Block(-5,15,1,AIR:0)
Block(-5,15,2,AIR:0)
Block(-5,15,3,AIR:0)
Block(-5,15,4,minecraft:concrete)
Block(-5,15,5,minecraft:concrete)
Block(-5,15,6,minecraft:concrete)
Block(-5,15,7,minecraft:iron_block:0)
Block(-5,15,8,AIR:0)
Block(-5,16,-7,minecraft:concrete)
Block(-5,16,-6,minecraft:concrete)
Block(-5,16,-5,minecraft:concrete)
Block(-5,16,-4,minecraft:concrete)
Block(-5,16,-3,minecraft:concrete)
Block(-5,16,-2,minecraft:concrete)
Block(-5,16,-1,minecraft:concrete)
Block(-5,16,0,minecraft:concrete)
Block(-5,16,1,minecraft:concrete)
Block(-5,16,2,minecraft:concrete)
Block(-5,16,3,minecraft:concrete)
Block(-5,16,4,minecraft:concrete)
Block(-5,16,5,minecraft:concrete)
Block(-5,16,6,minecraft:concrete)
Block(-5,16,7,minecraft:iron_block:0)
Block(-5,16,8,AIR:0)
Block(-5,17,-7,minecraft:concrete)
Block(-5,17,-6,OBSERVER:5)
Block(-5,17,-5,quark:basalt_speleothem:2)
Block(-5,17,-4,OBSERVER:5)
Block(-5,17,-3,quark:stone_basalt_stairs:2)
Block(-5,17,-2,quark:world_stone_pavement:3)
Block(-5,17,-1,quark:basalt_speleothem:2)
Block(-5,17,0,minecraft:concrete)
Block(-5,17,1,minecraft:tallgrass)
Block(-5,17,2,minecraft:stonebrick)
Block(-5,17,3,AIR:0)
Block(-5,17,4,minecraft:stone)
Block(-5,17,5,minecraft:stonebrick)
Block(-5,17,6,minecraft:concrete)
Block(-5,17,7,minecraft:iron_block:0)
Block(-5,17,8,AIR:0)
Block(-5,18,-7,minecraft:concrete)
Block(-5,18,-6,OBSERVER:5)
Block(-5,18,-5,AIR:0)
Block(-5,18,-4,OBSERVER:5)
Block(-5,18,-3,AIR:0)
Block(-5,18,-2,quark:stone_basalt_stairs:5)
Block(-5,18,-1,quark:basalt_speleothem:2)
Block(-5,18,0,minecraft:concrete)
Block(-5,18,1,AIR:0)
Block(-5,18,2,AIR:0)
Block(-5,18,3,AIR:0)
Block(-5,18,4,AIR:0)
Block(-5,18,5,AIR:0)
Block(-5,18,6,minecraft:concrete)
Block(-5,18,7,minecraft:iron_block:0)
Block(-5,18,8,AIR:0)
Block(-5,19,-7,minecraft:concrete)
Block(-5,19,-6,minecraft:concrete)
Block(-5,19,-5,minecraft:concrete)
Block(-5,19,-4,minecraft:concrete)
Block(-5,19,-3,minecraft:concrete)
Block(-5,19,-2,minecraft:concrete)
Block(-5,19,-1,minecraft:concrete)
Block(-5,19,0,minecraft:concrete)
Block(-5,19,1,minecraft:concrete)
Block(-5,19,2,minecraft:concrete)
Block(-5,19,3,minecraft:concrete)
Block(-5,19,4,minecraft:concrete)
Block(-5,19,5,minecraft:concrete)
Block(-5,19,6,minecraft:concrete)
Block(-5,19,7,minecraft:iron_block:0)
Block(-5,19,8,AIR:0)
Block(-5,20,-7,minecraft:concrete)
Block(-5,20,-6,AIR:0)
Block(-5,20,-5,minecraft:stonebrick)
Block(-5,20,-4,AIR:0)
Block(-5,20,-3,AIR:0)
Block(-5,20,-2,minecraft:stonebrick:3)
Block(-5,20,-1,minecraft:concrete)
Block(-5,20,0,minecraft:bone_block)
Block(-5,20,1,AIR:0)
Block(-5,20,2,AIR:0)
Block(-5,20,3,minecraft:concrete)
Block(-5,20,4,quark:iron_plate_stairs:0)
Block(-5,20,5,quark:iron_plate_stairs:0)
Block(-5,20,6,minecraft:concrete)
Block(-5,20,7,minecraft:iron_block:0)
Block(-5,20,8,AIR:0)
Block(-5,21,-7,minecraft:concrete)
Block(-5,21,-6,AIR:0)
Block(-5,21,-5,AIR:0)
Block(-5,21,-4,AIR:0)
Block(-5,21,-3,AIR:0)
Block(-5,21,-2,minecraft:stonebrick)
Block(-5,21,-1,minecraft:concrete)
Block(-5,21,0,AIR:0)
Block(-5,21,1,AIR:0)
Block(-5,21,2,AIR:0)
Block(-5,21,3,minecraft:concrete)
Block(-5,21,4,AIR:0)
Block(-5,21,5,AIR:0)
Block(-5,21,6,minecraft:concrete)
Block(-5,21,7,minecraft:iron_block:0)
Block(-5,21,8,AIR:0)
Block(-5,22,-7,minecraft:concrete)
Block(-5,22,-6,minecraft:planks:9,../../../../Chests/Loot/manhunt_vagrant_scrap.nbt)
Block(-5,22,-5,minecraft:planks:9,../../../../Chests/Loot/manhunt_vagrant_scrap.nbt)
Block(-5,22,-4,minecraft:planks:9,../../../../Chests/Loot/manhunt_vagrant_scrap.nbt)
Block(-5,22,-3,minecraft:planks:9,../../../../Chests/Loot/manhunt_vagrant_scrap.nbt)
Block(-5,22,-2,minecraft:bookshelf:0)
Block(-5,22,-1,minecraft:concrete)
Block(-5,22,0,AIR:0)
Block(-5,22,1,AIR:0)
Block(-5,22,2,AIR:0)
Block(-5,22,3,minecraft:concrete)
Block(-5,22,4,AIR:0)
Block(-5,22,5,AIR:0)
Block(-5,22,6,minecraft:concrete)
Block(-5,22,7,minecraft:iron_block:0)
Block(-5,22,8,minecraft:iron_block:0)
Block(-5,23,-7,minecraft:concrete)
Block(-5,23,-6,minecraft:iron_block:1)
Block(-5,23,-5,quark:stone_marble_bricks_slab:8)
Block(-5,23,-4,quark:stone_marble_bricks_slab:8)
Block(-5,23,-3,quark:stone_marble_bricks_slab:8)
Block(-5,23,-2,minecraft:iron_block:1)
Block(-5,23,-1,minecraft:concrete)
Block(-5,23,0,AIR:0)
Block(-5,23,1,AIR:0)
Block(-5,23,2,AIR:0)
Block(-5,23,3,minecraft:concrete)
Block(-5,23,4,AIR:0)
Block(-5,23,5,AIR:0)
Block(-5,23,6,minecraft:concrete)
Block(-5,23,7,minecraft:concrete)
Block(-5,23,8,minecraft:concrete)
Block(-5,24,-7,minecraft:concrete)
Block(-5,24,-6,minecraft:stonebrick:10)
Block(-5,24,-5,AIR:0)
Block(-5,24,-4,AIR:0)
Block(-5,24,-3,AIR:0)
Block(-5,24,-2,minecraft:stonebrick:3)
Block(-5,24,-1,quark:framed_glass_pane)
Block(-5,24,0,AIR:0)
Block(-5,24,1,AIR:0)
Block(-5,24,2,minecraft:stonebrick)
Block(-5,24,3,minecraft:concrete)
Block(-5,24,4,AIR:0)
Block(-5,24,5,AIR:0)
Block(-5,24,6,minecraft:concrete)
Block(-5,24,7,minecraft:tallgrass)
Block(-5,24,8,AIR:0)
Block(-5,25,-7,minecraft:concrete)
Block(-5,25,-6,minecraft:stonebrick:10)
Block(-5,25,-5,AIR:0)
Block(-5,25,-4,AIR:0)
Block(-5,25,-3,AIR:0)
Block(-5,25,-2,minecraft:stonebrick)
Block(-5,25,-1,quark:framed_glass_pane)
Block(-5,25,0,AIR:0)
Block(-5,25,1,AIR:0)
Block(-5,25,2,AIR:0)
Block(-5,25,3,minecraft:concrete)
Block(-5,25,4,AIR:0)
Block(-5,25,5,AIR:0)
Block(-5,25,6,minecraft:concrete)
Block(-5,25,7,AIR:0)
Block(-5,25,8,AIR:0)
Block(-5,26,-7,minecraft:concrete)
Block(-5,26,-6,AIR:0)
Block(-5,26,-5,AIR:0)
Block(-5,26,-4,AIR:0)
Block(-5,26,-3,AIR:0)
Block(-5,26,-2,minecraft:planks,../../../../Chests/Loot/manhunt_vagrant_scrap.nbt)
Block(-5,26,-1,quark:framed_glass_pane)
Block(-5,26,0,WEB:0)
Block(-5,26,1,AIR:0)
Block(-5,26,2,AIR:0)
Block(-5,26,3,minecraft:concrete)
Block(-5,26,4,AIR:0)
Block(-5,26,5,WEB:0)
Block(-5,26,6,minecraft:concrete)
Block(-5,26,7,AIR:0)
Block(-5,26,8,AIR:0)
Block(-5,27,-7,minecraft:concrete)
Block(-5,27,-6,minecraft:concrete)
Block(-5,27,-5,minecraft:concrete)
Block(-5,27,-4,minecraft:concrete)
Block(-5,27,-3,minecraft:concrete)
Block(-5,27,-2,minecraft:concrete)
Block(-5,27,-1,minecraft:concrete)
Block(-5,27,0,minecraft:concrete)
Block(-5,27,1,minecraft:concrete)
Block(-5,27,2,minecraft:concrete)
Block(-5,27,3,minecraft:concrete)
Block(-5,27,4,minecraft:concrete)
Block(-5,27,5,minecraft:concrete)
Block(-5,27,6,minecraft:concrete)
Block(-5,27,7,minecraft:concrete)
Block(-5,27,8,minecraft:concrete)
Block(-4,0,-7,minecraft:concrete)
Block(-4,0,-6,minecraft:concrete)
Block(-4,0,-5,minecraft:concrete)
Block(-4,0,-4,minecraft:concrete)
Block(-4,0,-3,minecraft:concrete)
Block(-4,0,-2,minecraft:concrete)
Block(-4,0,-1,minecraft:concrete)
Block(-4,0,0,minecraft:concrete)
Block(-4,0,1,minecraft:concrete)
Block(-4,0,2,minecraft:concrete)
Block(-4,0,3,minecraft:concrete)
Block(-4,0,4,minecraft:concrete)
Block(-4,0,5,minecraft:concrete)
Block(-4,0,6,minecraft:concrete)
Block(-4,0,7,minecraft:concrete)
Block(-4,0,8,minecraft:concrete)
Block(-4,1,-7,minecraft:concrete)
Block(-4,1,-6,SOIL:7)
Block(-4,1,-5,DIRT:1)
Block(-4,1,-4,SOIL:7)
Block(-4,1,-3,minecraft:dirt)
Block(-4,1,-2,minecraft:dirt)
Block(-4,1,-1,DIRT:1)
Block(-4,1,0,DIRT:1)
Block(-4,1,1,DIRT:1)
Block(-4,1,2,minecraft:concrete)
Block(-4,1,3,minecraft:concrete)
Block(-4,1,4,minecraft:stonebrick:14)
Block(-4,1,5,STATIONARY_WATER:0)
Block(-4,1,6,minecraft:stonebrick:14)
Block(-4,1,7,minecraft:stonebrick:14)
Block(-4,1,8,minecraft:stonebrick:14)
Block(-4,2,-7,minecraft:concrete)
Block(-4,2,-6,CROPS:7)
Block(-4,2,-5,minecraft:tallgrass:13)
Block(-4,2,-4,AIR:0)
Block(-4,2,-3,AIR:0)
Block(-4,2,-2,AIR:0)
Block(-4,2,-1,minecraft:grass)
Block(-4,2,0,minecraft:grass)
Block(-4,2,1,AIR:0)
Block(-4,2,2,minecraft:concrete)
Block(-4,2,3,minecraft:concrete)
Block(-4,2,4,AIR:0)
Block(-4,2,5,AIR:0)
Block(-4,2,6,AIR:0)
Block(-4,2,7,CROPS:7)
Block(-4,2,8,CROPS:7)
Block(-4,3,-7,minecraft:concrete)
Block(-4,3,-6,AIR:0)
Block(-4,3,-5,AIR:0)
Block(-4,3,-4,AIR:0)
Block(-4,3,-3,AIR:0)
Block(-4,3,-2,AIR:0)
Block(-4,3,-1,AIR:0)
Block(-4,3,0,AIR:0)
Block(-4,3,1,AIR:0)
Block(-4,3,2,minecraft:concrete)
Block(-4,3,3,minecraft:concrete)
Block(-4,3,4,AIR:0)
Block(-4,3,5,AIR:0)
Block(-4,3,6,AIR:0)
Block(-4,3,7,AIR:0)
Block(-4,3,8,AIR:0)
Block(-4,4,-7,minecraft:concrete)
Block(-4,4,-6,AIR:0)
Block(-4,4,-5,AIR:0)
Block(-4,4,-4,AIR:0)
Block(-4,4,-3,AIR:0)
Block(-4,4,-2,AIR:0)
Block(-4,4,-1,AIR:0)
Block(-4,4,0,AIR:0)
Block(-4,4,1,AIR:0)
Block(-4,4,2,minecraft:concrete)
Block(-4,4,3,minecraft:concrete)
Block(-4,4,4,AIR:0)
Block(-4,4,5,AIR:0)
Block(-4,4,6,AIR:0)
Block(-4,4,7,AIR:0)
Block(-4,4,8,AIR:0)
Block(-4,5,-7,minecraft:concrete)
Block(-4,5,-6,minecraft:concrete)
Block(-4,5,-5,minecraft:concrete)
Block(-4,5,-4,minecraft:concrete)
Block(-4,5,-3,minecraft:concrete)
Block(-4,5,-2,minecraft:concrete)
Block(-4,5,-1,minecraft:concrete)
Block(-4,5,0,minecraft:concrete)
Block(-4,5,1,minecraft:concrete)
Block(-4,5,2,minecraft:concrete)
Block(-4,5,3,minecraft:concrete)
Block(-4,5,4,AIR:0)
Block(-4,5,5,AIR:0)
Block(-4,5,6,AIR:0)
Block(-4,5,7,AIR:0)
Block(-4,5,8,AIR:0)
Block(-4,6,-7,minecraft:concrete)
Block(-4,6,-6,quark:grate)
Block(-4,6,-5,quark:grate)
Block(-4,6,-4,minecraft:concrete)
Block(-4,6,-3,CONCRETE:15)
Block(-4,6,-2,CONCRETE:15)
Block(-4,6,-1,minecraft:concrete)
Block(-4,6,0,quark:grate)
Block(-4,6,1,quark:grate)
Block(-4,6,2,minecraft:concrete)
Block(-4,6,3,minecraft:concrete)
Block(-4,6,4,AIR:0)
Block(-4,6,5,AIR:0)
Block(-4,6,6,AIR:0)
Block(-4,6,7,AIR:0)
Block(-4,6,8,AIR:0)
Block(-4,7,-7,minecraft:concrete)
Block(-4,7,-6,AIR:0)
Block(-4,7,-5,AIR:0)
Block(-4,7,-4,AIR:0)
Block(-4,7,-3,AIR:0)
Block(-4,7,-2,minecraft:stonebrick)
Block(-4,7,-1,AIR:0)
Block(-4,7,0,AIR:0)
Block(-4,7,1,AIR:0)
Block(-4,7,2,minecraft:concrete)
Block(-4,7,3,minecraft:concrete)
Block(-4,7,4,AIR:0)
Block(-4,7,5,AIR:0)
Block(-4,7,6,minecraft:glowstone)
Block(-4,7,7,AIR:0)
Block(-4,7,8,AIR:0)
Block(-4,8,-7,minecraft:concrete)
Block(-4,8,-6,AIR:0)
Block(-4,8,-5,AIR:0)
Block(-4,8,-4,AIR:0)
Block(-4,8,-3,AIR:0)
Block(-4,8,-2,AIR:0)
Block(-4,8,-1,AIR:0)
Block(-4,8,0,AIR:0)
Block(-4,8,1,AIR:0)
Block(-4,8,2,minecraft:concrete)
Block(-4,8,3,minecraft:concrete)
Block(-4,8,4,minecraft:iron_bars:0)
Block(-4,8,5,minecraft:iron_bars:0)
Block(-4,8,6,minecraft:iron_bars:0)
Block(-4,8,7,minecraft:iron_bars:0)
Block(-4,8,8,minecraft:iron_bars:0)
Block(-4,9,-7,minecraft:concrete)
Block(-4,9,-6,AIR:0)
Block(-4,9,-5,AIR:0)
Block(-4,9,-4,AIR:0)
Block(-4,9,-3,AIR:0)
Block(-4,9,-2,AIR:0)
Block(-4,9,-1,AIR:0)
Block(-4,9,0,AIR:0)
Block(-4,9,1,AIR:0)
Block(-4,9,2,minecraft:concrete)
Block(-4,9,3,minecraft:concrete)
Block(-4,9,4,minecraft:concrete)
Block(-4,9,5,minecraft:concrete)
Block(-4,9,6,minecraft:concrete)
Block(-4,9,7,minecraft:concrete)
Block(-4,9,8,minecraft:concrete)
Block(-4,10,-7,minecraft:concrete)
Block(-4,10,-6,AIR:0)
Block(-4,10,-5,AIR:0)
Block(-4,10,-4,AIR:0)
Block(-4,10,-3,AIR:0)
Block(-4,10,-2,AIR:0)
Block(-4,10,-1,AIR:0)
Block(-4,10,0,AIR:0)
Block(-4,10,1,AIR:0)
Block(-4,10,2,minecraft:concrete)
Block(-4,10,3,minecraft:concrete)
Block(-4,10,4,minecraft:concrete)
Block(-4,10,5,minecraft:concrete)
Block(-4,10,6,minecraft:concrete)
Block(-4,10,7,minecraft:concrete)
Block(-4,10,8,minecraft:concrete)
Block(-4,11,-7,minecraft:concrete)
Block(-4,11,-6,minecraft:concrete)
Block(-4,11,-5,minecraft:concrete)
Block(-4,11,-4,minecraft:concrete)
Block(-4,11,-3,minecraft:concrete)
Block(-4,11,-2,minecraft:concrete)
Block(-4,11,-1,minecraft:concrete)
Block(-4,11,0,minecraft:concrete)
Block(-4,11,1,minecraft:concrete)
Block(-4,11,2,minecraft:concrete)
Block(-4,11,3,minecraft:concrete)
Block(-4,11,4,minecraft:concrete)
Block(-4,11,5,minecraft:concrete)
Block(-4,11,6,minecraft:concrete)
Block(-4,11,7,minecraft:concrete)
Block(-4,11,8,minecraft:concrete)
Block(-4,12,-7,minecraft:concrete)
Block(-4,12,-6,minecraft:concrete)
Block(-4,12,-5,minecraft:concrete)
Block(-4,12,-4,minecraft:concrete)
Block(-4,12,-3,minecraft:concrete)
Block(-4,12,-2,minecraft:concrete)
Block(-4,12,-1,minecraft:concrete)
Block(-4,12,0,minecraft:concrete)
Block(-4,12,1,minecraft:concrete)
Block(-4,12,2,minecraft:concrete)
Block(-4,12,3,minecraft:concrete)
Block(-4,12,4,minecraft:concrete)
Block(-4,12,5,minecraft:concrete)
Block(-4,12,6,minecraft:concrete)
Block(-4,12,7,AIR:0)
Block(-4,12,8,AIR:0)
Block(-4,13,-7,minecraft:concrete)
Block(-4,13,-6,minecraft:concrete)
Block(-4,13,-5,minecraft:concrete)
Block(-4,13,-4,minecraft:concrete)
Block(-4,13,-3,minecraft:concrete)
Block(-4,13,-2,minecraft:concrete)
Block(-4,13,-1,minecraft:concrete)
Block(-4,13,0,minecraft:concrete)
Block(-4,13,1,minecraft:concrete)
Block(-4,13,2,minecraft:concrete)
Block(-4,13,3,minecraft:concrete)
Block(-4,13,4,minecraft:concrete)
Block(-4,13,5,minecraft:concrete)
Block(-4,13,6,minecraft:concrete)
Block(-4,13,7,AIR:0)
Block(-4,13,8,AIR:0)
Block(-4,14,-7,minecraft:concrete)
Block(-4,14,-6,minecraft:concrete)
Block(-4,14,-5,minecraft:concrete)
Block(-4,14,-4,minecraft:concrete)
Block(-4,14,-3,minecraft:concrete)
Block(-4,14,-2,minecraft:concrete)
Block(-4,14,-1,minecraft:concrete)
Block(-4,14,0,minecraft:concrete)
Block(-4,14,1,minecraft:concrete)
Block(-4,14,2,minecraft:concrete)
Block(-4,14,3,minecraft:concrete)
Block(-4,14,4,minecraft:concrete)
Block(-4,14,5,minecraft:concrete)
Block(-4,14,6,minecraft:concrete)
Block(-4,14,7,AIR:0)
Block(-4,14,8,AIR:0)
Block(-4,15,-7,minecraft:concrete)
Block(-4,15,-6,minecraft:concrete)
Block(-4,15,-5,minecraft:concrete)
Block(-4,15,-4,minecraft:concrete)
Block(-4,15,-3,minecraft:concrete)
Block(-4,15,-2,minecraft:concrete)
Block(-4,15,-1,minecraft:concrete)
Block(-4,15,0,minecraft:concrete)
Block(-4,15,1,minecraft:concrete)
Block(-4,15,2,minecraft:concrete)
Block(-4,15,3,minecraft:concrete)
Block(-4,15,4,minecraft:concrete)
Block(-4,15,5,minecraft:concrete)
Block(-4,15,6,minecraft:concrete)
Block(-4,15,7,AIR:0)
Block(-4,15,8,AIR:0)
Block(-4,16,-7,minecraft:concrete)
Block(-4,16,-6,minecraft:concrete)
Block(-4,16,-5,minecraft:concrete)
Block(-4,16,-4,minecraft:concrete)
Block(-4,16,-3,minecraft:concrete)
Block(-4,16,-2,minecraft:concrete)
Block(-4,16,-1,minecraft:concrete)
Block(-4,16,0,minecraft:concrete)
Block(-4,16,1,minecraft:concrete)
Block(-4,16,2,minecraft:concrete)
Block(-4,16,3,minecraft:concrete)
Block(-4,16,4,minecraft:concrete)
Block(-4,16,5,minecraft:concrete)
Block(-4,16,6,minecraft:concrete)
Block(-4,16,7,AIR:0)
Block(-4,16,8,AIR:0)
Block(-4,17,-7,minecraft:concrete)
Block(-4,17,-6,minecraft:concrete)
Block(-4,17,-5,minecraft:concrete)
Block(-4,17,-4,minecraft:concrete)
Block(-4,17,-3,minecraft:trapdoor:6)
Block(-4,17,-2,minecraft:trapdoor:6)
Block(-4,17,-1,minecraft:trapdoor:6)
Block(-4,17,0,minecraft:concrete)
Block(-4,17,1,minecraft:iron_door:4)
Block(-4,17,2,minecraft:iron_door:4)
Block(-4,17,3,minecraft:concrete)
Block(-4,17,4,minecraft:iron_door:4)
Block(-4,17,5,minecraft:iron_door:4)
Block(-4,17,6,minecraft:concrete)
Block(-4,17,7,AIR:0)
Block(-4,17,8,AIR:0)
Block(-4,18,-7,minecraft:concrete)
Block(-4,18,-6,minecraft:concrete)
Block(-4,18,-5,minecraft:concrete)
Block(-4,18,-4,minecraft:concrete)
Block(-4,18,-3,minecraft:trapdoor:6)
Block(-4,18,-2,quark:stone_basalt_slab:8)
Block(-4,18,-1,minecraft:trapdoor:6)
Block(-4,18,0,minecraft:concrete)
Block(-4,18,1,minecraft:iron_door:8)
Block(-4,18,2,minecraft:iron_door:9)
Block(-4,18,3,minecraft:concrete)
Block(-4,18,4,minecraft:iron_door:8)
Block(-4,18,5,minecraft:iron_door:9)
Block(-4,18,6,minecraft:concrete)
Block(-4,18,7,AIR:0)
Block(-4,18,8,AIR:0)
Block(-4,19,-7,minecraft:concrete)
Block(-4,19,-6,minecraft:concrete)
Block(-4,19,-5,minecraft:concrete)
Block(-4,19,-4,minecraft:concrete)
Block(-4,19,-3,minecraft:concrete)
Block(-4,19,-2,minecraft:concrete)
Block(-4,19,-1,minecraft:concrete)
Block(-4,19,0,minecraft:concrete)
Block(-4,19,1,minecraft:concrete)
Block(-4,19,2,minecraft:concrete)
Block(-4,19,3,minecraft:concrete)
Block(-4,19,4,minecraft:concrete)
Block(-4,19,5,minecraft:concrete)
Block(-4,19,6,minecraft:concrete)
Block(-4,19,7,AIR:0)
Block(-4,19,8,AIR:0)
Block(-4,20,-7,minecraft:concrete)
Block(-4,20,-6,minecraft:planks:1,../../../../Chests/Loot/manhunt_vagrant_scrap.nbt)
Block(-4,20,-5,minecraft:planks:1,../../../../Chests/Loot/manhunt_vagrant_scrap.nbt)
Block(-4,20,-4,minecraft:planks:9,../../../../Chests/Loot/manhunt_vagrant_scrap.nbt)
Block(-4,20,-3,minecraft:stonebrick)
Block(-4,20,-2,minecraft:stonebrick)
Block(-4,20,-1,minecraft:concrete)
Block(-4,20,0,AIR:0)
Block(-4,20,1,minecraft:stonebrick)
Block(-4,20,2,AIR:0)
Block(-4,20,3,minecraft:iron_bars:0)
Block(-4,20,4,minecraft:concrete)
Block(-4,20,5,minecraft:concrete)
Block(-4,20,6,minecraft:concrete)
Block(-4,20,7,AIR:0)
Block(-4,20,8,AIR:0)
Block(-4,21,-7,minecraft:concrete)
Block(-4,21,-6,minecraft:stonebrick:4)
Block(-4,21,-5,minecraft:stonebrick:4)
Block(-4,21,-4,minecraft:stonebrick:4)
Block(-4,21,-3,AIR:0)
Block(-4,21,-2,AIR:0)
Block(-4,21,-1,minecraft:concrete)
Block(-4,21,0,AIR:0)
Block(-4,21,1,AIR:0)
Block(-4,21,2,AIR:0)
Block(-4,21,3,minecraft:iron_bars:0)
Block(-4,21,4,quark:iron_plate_stairs:0)
Block(-4,21,5,quark:iron_plate_stairs:0)
Block(-4,21,6,minecraft:concrete)
Block(-4,21,7,AIR:0)
Block(-4,21,8,AIR:0)
Block(-4,22,-7,minecraft:concrete)
Block(-4,22,-6,minecraft:concrete)
Block(-4,22,-5,minecraft:concrete)
Block(-4,22,-4,minecraft:concrete)
Block(-4,22,-3,minecraft:concrete)
Block(-4,22,-2,minecraft:concrete)
Block(-4,22,-1,minecraft:concrete)
Block(-4,22,0,AIR:0)
Block(-4,22,1,AIR:0)
Block(-4,22,2,AIR:0)
Block(-4,22,3,minecraft:iron_bars:0)
Block(-4,22,4,AIR:0)
Block(-4,22,5,AIR:0)
Block(-4,22,6,minecraft:concrete)
Block(-4,22,7,AIR:0)
Block(-4,22,8,AIR:0)
Block(-4,23,-7,minecraft:concrete)
Block(-4,23,-6,minecraft:iron_block:1)
Block(-4,23,-5,quark:stone_marble_bricks_slab:8)
Block(-4,23,-4,quark:stone_marble_bricks_slab:8)
Block(-4,23,-3,quark:stone_marble_bricks_slab:8)
Block(-4,23,-2,minecraft:iron_block:1)
Block(-4,23,-1,minecraft:concrete)
Block(-4,23,0,AIR:0)
Block(-4,23,1,AIR:0)
Block(-4,23,2,AIR:0)
Block(-4,23,3,minecraft:iron_bars:0)
Block(-4,23,4,AIR:0)
Block(-4,23,5,AIR:0)
Block(-4,23,6,minecraft:concrete)
Block(-4,23,7,minecraft:concrete)
Block(-4,23,8,minecraft:concrete)
Block(-4,24,-7,minecraft:concrete)
Block(-4,24,-6,minecraft:stonebrick:10)
Block(-4,24,-5,AIR:0)
Block(-4,24,-4,AIR:0)
Block(-4,24,-3,AIR:0)
Block(-4,24,-2,minecraft:planks)
Block(-4,24,-1,quark:framed_glass_pane)
Block(-4,24,0,AIR:0)
Block(-4,24,1,AIR:0)
Block(-4,24,2,AIR:0)
Block(-4,24,3,minecraft:iron_bars:0)
Block(-4,24,4,AIR:0)
Block(-4,24,5,AIR:0)
Block(-4,24,6,quark:framed_glass_pane)
Block(-4,24,7,AIR:0)
Block(-4,24,8,minecraft:stonebrick)
Block(-4,25,-7,minecraft:concrete)
Block(-4,25,-6,minecraft:stonebrick:10)
Block(-4,25,-5,AIR:0)
Block(-4,25,-4,AIR:0)
Block(-4,25,-3,AIR:0)
Block(-4,25,-2,minecraft:bookshelf:0)
Block(-4,25,-1,quark:framed_glass_pane)
Block(-4,25,0,AIR:0)
Block(-4,25,1,AIR:0)
Block(-4,25,2,AIR:0)
Block(-4,25,3,minecraft:iron_bars:0)
Block(-4,25,4,AIR:0)
Block(-4,25,5,AIR:0)
Block(-4,25,6,quark:framed_glass_pane)
Block(-4,25,7,AIR:0)
Block(-4,25,8,AIR:0)
Block(-4,26,-7,minecraft:concrete)
Block(-4,26,-6,AIR:0)
Block(-4,26,-5,AIR:0)
Block(-4,26,-4,AIR:0)
Block(-4,26,-3,AIR:0)
Block(-4,26,-2,minecraft:planks,../../../../Chests/Loot/manhunt_vagrant_scrap.nbt)
Block(-4,26,-1,quark:framed_glass_pane)
Block(-4,26,0,AIR:0)
Block(-4,26,1,AIR:0)
Block(-4,26,2,AIR:0)
Block(-4,26,3,minecraft:iron_bars:0)
Block(-4,26,4,AIR:0)
Block(-4,26,5,AIR:0)
Block(-4,26,6,quark:framed_glass_pane)
Block(-4,26,7,AIR:0)
Block(-4,26,8,AIR:0)
Block(-4,27,-7,minecraft:concrete)
Block(-4,27,-6,minecraft:concrete)
Block(-4,27,-5,minecraft:concrete)
Block(-4,27,-4,minecraft:concrete)
Block(-4,27,-3,minecraft:concrete)
Block(-4,27,-2,minecraft:concrete)
Block(-4,27,-1,minecraft:concrete)
Block(-4,27,0,minecraft:concrete)
Block(-4,27,1,minecraft:concrete)
Block(-4,27,2,minecraft:concrete)
Block(-4,27,3,minecraft:concrete)
Block(-4,27,4,minecraft:concrete)
Block(-4,27,5,minecraft:concrete)
Block(-4,27,6,minecraft:concrete)
Block(-4,27,7,minecraft:concrete)
Block(-4,27,8,minecraft:concrete)
Block(-3,0,-7,minecraft:concrete)
Block(-3,0,-6,minecraft:concrete)
Block(-3,0,-5,minecraft:concrete)
Block(-3,0,-4,minecraft:concrete)
Block(-3,0,-3,minecraft:concrete)
Block(-3,0,-2,minecraft:concrete)
Block(-3,0,-1,minecraft:concrete)
Block(-3,0,0,minecraft:concrete)
Block(-3,0,1,minecraft:concrete)
Block(-3,0,2,minecraft:concrete)
Block(-3,0,3,minecraft:concrete)
Block(-3,0,4,minecraft:concrete)
Block(-3,0,5,minecraft:concrete)
Block(-3,0,6,minecraft:concrete)
Block(-3,0,7,minecraft:concrete)
Block(-3,0,8,minecraft:concrete)
Block(-3,1,-7,minecraft:concrete)
Block(-3,1,-6,DIRT:1)
Block(-3,1,-5,SOIL:7)
Block(-3,1,-4,DIRT:2)
Block(-3,1,-3,minecraft:dirt:8)
Block(-3,1,-2,SOIL:7)
Block(-3,1,-1,DIRT:2)
Block(-3,1,0,SOIL:7)
Block(-3,1,1,DIRT:1)
Block(-3,1,2,minecraft:concrete)
Block(-3,1,3,minecraft:concrete)
Block(-3,1,4,minecraft:dirt)
Block(-3,1,5,STATIONARY_WATER:0)
Block(-3,1,6,minecraft:dirt)
Block(-3,1,7,minecraft:stonebrick:14)
Block(-3,1,8,minecraft:stonebrick:14)
Block(-3,2,-7,minecraft:concrete)
Block(-3,2,-6,minecraft:tallgrass:13)
Block(-3,2,-5,AIR:0)
Block(-3,2,-4,AIR:0)
Block(-3,2,-3,minecraft:grass)
Block(-3,2,-2,AIR:0)
Block(-3,2,-1,AIR:0)
Block(-3,2,0,AIR:0)
Block(-3,2,1,minecraft:grass)
Block(-3,2,2,minecraft:concrete)
Block(-3,2,3,minecraft:concrete)
Block(-3,2,4,SUGAR_CANE_BLOCK:0)
Block(-3,2,5,AIR:0)
Block(-3,2,6,minecraft:leaves:5)
Block(-3,2,7,AIR:0)
Block(-3,2,8,minecraft:grass)
Block(-3,3,-7,minecraft:concrete)
Block(-3,3,-6,AIR:0)
Block(-3,3,-5,AIR:0)
Block(-3,3,-4,AIR:0)
Block(-3,3,-3,AIR:0)
Block(-3,3,-2,AIR:0)
Block(-3,3,-1,AIR:0)
Block(-3,3,0,AIR:0)
Block(-3,3,1,minecraft:leaves:13)
Block(-3,3,2,minecraft:concrete)
Block(-3,3,3,minecraft:concrete)
Block(-3,3,4,SUGAR_CANE_BLOCK:0)
Block(-3,3,5,AIR:0)
Block(-3,3,6,AIR:0)
Block(-3,3,7,AIR:0)
Block(-3,3,8,AIR:0)
Block(-3,4,-7,minecraft:concrete)
Block(-3,4,-6,AIR:0)
Block(-3,4,-5,AIR:0)
Block(-3,4,-4,AIR:0)
Block(-3,4,-3,AIR:0)
Block(-3,4,-2,AIR:0)
Block(-3,4,-1,AIR:0)
Block(-3,4,0,AIR:0)
Block(-3,4,1,minecraft:leaves:5)
Block(-3,4,2,minecraft:concrete)
Block(-3,4,3,minecraft:concrete)
Block(-3,4,4,SUGAR_CANE_BLOCK:0)
Block(-3,4,5,AIR:0)
Block(-3,4,6,AIR:0)
Block(-3,4,7,AIR:0)
Block(-3,4,8,AIR:0)
Block(-3,5,-7,minecraft:concrete)
Block(-3,5,-6,minecraft:concrete)
Block(-3,5,-5,minecraft:concrete)
Block(-3,5,-4,minecraft:concrete)
Block(-3,5,-3,minecraft:concrete)
Block(-3,5,-2,minecraft:concrete)
Block(-3,5,-1,minecraft:concrete)
Block(-3,5,0,minecraft:concrete)
Block(-3,5,1,minecraft:concrete)
Block(-3,5,2,minecraft:concrete)
Block(-3,5,3,minecraft:concrete)
Block(-3,5,4,AIR:0)
Block(-3,5,5,AIR:0)
Block(-3,5,6,AIR:0)
Block(-3,5,7,AIR:0)
Block(-3,5,8,AIR:0)
Block(-3,6,-7,minecraft:concrete)
Block(-3,6,-6,quark:grate)
Block(-3,6,-5,quark:grate)
Block(-3,6,-4,minecraft:concrete)
Block(-3,6,-3,CONCRETE:15)
Block(-3,6,-2,CONCRETE:15)
Block(-3,6,-1,minecraft:concrete)
Block(-3,6,0,quark:grate)
Block(-3,6,1,quark:grate)
Block(-3,6,2,minecraft:concrete)
Block(-3,6,3,minecraft:concrete)
Block(-3,6,4,AIR:0)
Block(-3,6,5,AIR:0)
Block(-3,6,6,AIR:0)
Block(-3,6,7,AIR:0)
Block(-3,6,8,AIR:0)
Block(-3,7,-7,minecraft:concrete)
Block(-3,7,-6,AIR:0)
Block(-3,7,-5,AIR:0)
Block(-3,7,-4,AIR:0)
Block(-3,7,-3,AIR:0)
Block(-3,7,-2,AIR:0)
Block(-3,7,-1,AIR:0)
Block(-3,7,0,AIR:0)
Block(-3,7,1,AIR:0)
Block(-3,7,2,minecraft:concrete)
Block(-3,7,3,minecraft:concrete)
Block(-3,7,4,AIR:0)
Block(-3,7,5,AIR:0)
Block(-3,7,6,AIR:0)
Block(-3,7,7,AIR:0)
Block(-3,7,8,AIR:0)
Block(-3,8,-7,minecraft:concrete)
Block(-3,8,-6,AIR:0)
Block(-3,8,-5,AIR:0)
Block(-3,8,-4,AIR:0)
Block(-3,8,-3,AIR:0)
Block(-3,8,-2,AIR:0)
Block(-3,8,-1,AIR:0)
Block(-3,8,0,AIR:0)
Block(-3,8,1,AIR:0)
Block(-3,8,2,minecraft:concrete)
Block(-3,8,3,minecraft:concrete)
Block(-3,8,4,minecraft:iron_bars:0)
Block(-3,8,5,minecraft:iron_bars:0)
Block(-3,8,6,minecraft:iron_bars:0)
Block(-3,8,7,minecraft:iron_bars:0)
Block(-3,8,8,minecraft:iron_bars:0)
Block(-3,9,-7,minecraft:concrete)
Block(-3,9,-6,AIR:0)
Block(-3,9,-5,AIR:0)
Block(-3,9,-4,AIR:0)
Block(-3,9,-3,AIR:0)
Block(-3,9,-2,AIR:0)
Block(-3,9,-1,AIR:0)
Block(-3,9,0,AIR:0)
Block(-3,9,1,AIR:0)
Block(-3,9,2,minecraft:concrete)
Block(-3,9,3,minecraft:concrete)
Block(-3,9,4,minecraft:concrete)
Block(-3,9,5,minecraft:concrete)
Block(-3,9,6,minecraft:concrete)
Block(-3,9,7,minecraft:concrete)
Block(-3,9,8,minecraft:concrete)
Block(-3,10,-7,minecraft:concrete)
Block(-3,10,-6,AIR:0)
Block(-3,10,-5,AIR:0)
Block(-3,10,-4,AIR:0)
Block(-3,10,-3,AIR:0)
Block(-3,10,-2,AIR:0)
Block(-3,10,-1,AIR:0)
Block(-3,10,0,AIR:0)
Block(-3,10,1,AIR:0)
Block(-3,10,2,minecraft:concrete)
Block(-3,10,3,minecraft:concrete)
Block(-3,10,4,minecraft:concrete)
Block(-3,10,5,minecraft:concrete)
Block(-3,10,6,minecraft:concrete)
Block(-3,10,7,minecraft:concrete)
Block(-3,10,8,minecraft:concrete)
Block(-3,11,-7,minecraft:concrete)
Block(-3,11,-6,minecraft:concrete)
Block(-3,11,-5,minecraft:concrete)
Block(-3,11,-4,minecraft:concrete)
Block(-3,11,-3,minecraft:concrete)
Block(-3,11,-2,minecraft:concrete)
Block(-3,11,-1,minecraft:concrete)
Block(-3,11,0,minecraft:concrete)
Block(-3,11,1,minecraft:concrete)
Block(-3,11,2,minecraft:concrete)
Block(-3,11,3,minecraft:concrete)
Block(-3,11,4,minecraft:concrete)
Block(-3,11,5,minecraft:concrete)
Block(-3,11,6,minecraft:concrete)
Block(-3,11,7,minecraft:concrete)
Block(-3,11,8,minecraft:concrete)
Block(-3,12,-7,minecraft:concrete)
Block(-3,12,-6,minecraft:concrete)
Block(-3,12,-5,minecraft:concrete)
Block(-3,12,-4,minecraft:concrete)
Block(-3,12,-3,minecraft:concrete)
Block(-3,12,-2,minecraft:concrete)
Block(-3,12,-1,minecraft:concrete)
Block(-3,12,0,minecraft:concrete)
Block(-3,12,1,minecraft:concrete)
Block(-3,12,2,minecraft:concrete)
Block(-3,12,3,minecraft:concrete)
Block(-3,12,4,minecraft:concrete)
Block(-3,12,5,minecraft:concrete)
Block(-3,12,6,minecraft:concrete)
Block(-3,12,7,AIR:0)
Block(-3,12,8,minecraft:stone)
Block(-3,13,-7,minecraft:concrete)
Block(-3,13,-6,minecraft:concrete)
Block(-3,13,-5,minecraft:concrete)
Block(-3,13,-4,minecraft:concrete)
Block(-3,13,-3,minecraft:concrete)
Block(-3,13,-2,minecraft:concrete)
Block(-3,13,-1,minecraft:concrete)
Block(-3,13,0,minecraft:concrete)
Block(-3,13,1,minecraft:concrete)
Block(-3,13,2,minecraft:concrete)
Block(-3,13,3,minecraft:concrete)
Block(-3,13,4,minecraft:concrete)
Block(-3,13,5,minecraft:concrete)
Block(-3,13,6,minecraft:concrete)
Block(-3,13,7,AIR:0)
Block(-3,13,8,AIR:0)
Block(-3,14,-7,minecraft:concrete)
Block(-3,14,-6,minecraft:concrete)
Block(-3,14,-5,minecraft:concrete)
Block(-3,14,-4,minecraft:concrete)
Block(-3,14,-3,minecraft:concrete)
Block(-3,14,-2,minecraft:concrete)
Block(-3,14,-1,minecraft:concrete)
Block(-3,14,0,minecraft:concrete)
Block(-3,14,1,minecraft:concrete)
Block(-3,14,2,minecraft:concrete)
Block(-3,14,3,minecraft:concrete)
Block(-3,14,4,minecraft:concrete)
Block(-3,14,5,minecraft:concrete)
Block(-3,14,6,minecraft:concrete)
Block(-3,14,7,AIR:0)
Block(-3,14,8,AIR:0)
Block(-3,15,-7,minecraft:concrete)
Block(-3,15,-6,minecraft:concrete)
Block(-3,15,-5,minecraft:concrete)
Block(-3,15,-4,minecraft:concrete)
Block(-3,15,-3,minecraft:concrete)
Block(-3,15,-2,minecraft:concrete)
Block(-3,15,-1,minecraft:concrete)
Block(-3,15,0,minecraft:concrete)
Block(-3,15,1,minecraft:concrete)
Block(-3,15,2,minecraft:concrete)
Block(-3,15,3,minecraft:concrete)
Block(-3,15,4,minecraft:concrete)
Block(-3,15,5,minecraft:concrete)
Block(-3,15,6,minecraft:concrete)
Block(-3,15,7,AIR:0)
Block(-3,15,8,AIR:0)
Block(-3,16,-7,minecraft:concrete)
Block(-3,16,-6,minecraft:stonebrick)
Block(-3,16,-5,minecraft:stonebrick:3)
Block(-3,16,-4,minecraft:stonebrick)
Block(-3,16,-3,minecraft:stonebrick:3)
Block(-3,16,-2,minecraft:stonebrick)
Block(-3,16,-1,minecraft:stonebrick:3)
Block(-3,16,0,minecraft:stonebrick)
Block(-3,16,1,DARK_OAK_STAIRS:1)
Block(-3,16,2,DARK_OAK_STAIRS:1)
Block(-3,16,3,minecraft:concrete)
Block(-3,16,4,minecraft:concrete)
Block(-3,16,5,minecraft:concrete)
Block(-3,16,6,minecraft:concrete)
Block(-3,16,7,AIR:0)
Block(-3,16,8,AIR:0)
Block(-3,17,-7,minecraft:concrete)
Block(-3,17,-6,AIR:0)
Block(-3,17,-5,AIR:0)
Block(-3,17,-4,AIR:0)
Block(-3,17,-3,AIR:0)
Block(-3,17,-2,AIR:0)
Block(-3,17,-1,AIR:0)
Block(-3,17,0,AIR:0)
Block(-3,17,1,CARPET:15)
Block(-3,17,2,CARPET:15)
Block(-3,17,3,minecraft:concrete)
Block(-3,17,4,minecraft:stone)
Block(-3,17,5,minecraft:stone)
Block(-3,17,6,minecraft:concrete)
Block(-3,17,7,AIR:0)
Block(-3,17,8,AIR:0)
Block(-3,18,-7,minecraft:concrete)
Block(-3,18,-6,quark:basalt_speleothem:2)
Block(-3,18,-5,AIR:0)
Block(-3,18,-4,AIR:0)
Block(-3,18,-3,AIR:0)
Block(-3,18,-2,WEB:0)
Block(-3,18,-1,AIR:0)
Block(-3,18,0,quark:basalt_speleothem:2)
Block(-3,18,1,AIR:0)
Block(-3,18,2,AIR:0)
Block(-3,18,3,minecraft:concrete)
Block(-3,18,4,AIR:0)
Block(-3,18,5,AIR:0)
Block(-3,18,6,minecraft:concrete)
Block(-3,18,7,AIR:0)
Block(-3,18,8,AIR:0)
Block(-3,19,-7,minecraft:concrete)
Block(-3,19,-6,minecraft:concrete)
Block(-3,19,-5,minecraft:concrete)
Block(-3,19,-4,minecraft:concrete)
Block(-3,19,-3,minecraft:concrete)
Block(-3,19,-2,minecraft:concrete)
Block(-3,19,-1,minecraft:concrete)
Block(-3,19,0,minecraft:concrete)
Block(-3,19,1,minecraft:concrete)
Block(-3,19,2,minecraft:concrete)
Block(-3,19,3,minecraft:concrete)
Block(-3,19,4,minecraft:concrete)
Block(-3,19,5,minecraft:concrete)
Block(-3,19,6,minecraft:concrete)
Block(-3,19,7,AIR:0)
Block(-3,19,8,AIR:0)
Block(-3,20,-7,minecraft:concrete)
Block(-3,20,-6,AIR:0)
Block(-3,20,-5,minecraft:stonebrick)
Block(-3,20,-4,AIR:0)
Block(-3,20,-3,minecraft:stone)
Block(-3,20,-2,AIR:0)
Block(-3,20,-1,quark:framed_glass_pane)
Block(-3,20,0,AIR:0)
Block(-3,20,1,minecraft:stone)
Block(-3,20,2,AIR:0)
Block(-3,20,3,minecraft:iron_bars:0)
Block(-3,20,4,minecraft:concrete)
Block(-3,20,5,minecraft:concrete)
Block(-3,20,6,minecraft:concrete)
Block(-3,20,7,AIR:0)
Block(-3,20,8,AIR:0)
Block(-3,21,-7,minecraft:concrete)
Block(-3,21,-6,AIR:0)
Block(-3,21,-5,AIR:0)
Block(-3,21,-4,AIR:0)
Block(-3,21,-3,AIR:0)
Block(-3,21,-2,AIR:0)
Block(-3,21,-1,quark:framed_glass_pane)
Block(-3,21,0,AIR:0)
Block(-3,21,1,AIR:0)
Block(-3,21,2,AIR:0)
Block(-3,21,3,minecraft:iron_bars:0)
Block(-3,21,4,minecraft:concrete)
Block(-3,21,5,minecraft:concrete)
Block(-3,21,6,minecraft:concrete)
Block(-3,21,7,AIR:0)
Block(-3,21,8,AIR:0)
Block(-3,22,-7,minecraft:concrete)
Block(-3,22,-6,AIR:0)
Block(-3,22,-5,AIR:0)
Block(-3,22,-4,AIR:0)
Block(-3,22,-3,AIR:0)
Block(-3,22,-2,AIR:0)
Block(-3,22,-1,quark:framed_glass_pane)
Block(-3,22,0,AIR:0)
Block(-3,22,1,AIR:0)
Block(-3,22,2,AIR:0)
Block(-3,22,3,minecraft:iron_bars:0)
Block(-3,22,4,quark:iron_plate_stairs:0)
Block(-3,22,5,quark:iron_plate_stairs:0)
Block(-3,22,6,minecraft:concrete)
Block(-3,22,7,AIR:0)
Block(-3,22,8,AIR:0)
Block(-3,23,-7,minecraft:concrete)
Block(-3,23,-6,minecraft:iron_block:1)
Block(-3,23,-5,minecraft:iron_block:1)
Block(-3,23,-4,minecraft:iron_block:1)
Block(-3,23,-3,minecraft:iron_block:1)
Block(-3,23,-2,minecraft:iron_block:1)
Block(-3,23,-1,minecraft:concrete)
Block(-3,23,0,AIR:0)
Block(-3,23,1,AIR:0)
Block(-3,23,2,AIR:0)
Block(-3,23,3,minecraft:iron_bars:0)
Block(-3,23,4,AIR:0)
Block(-3,23,5,AIR:0)
Block(-3,23,6,minecraft:concrete)
Block(-3,23,7,minecraft:concrete)
Block(-3,23,8,minecraft:concrete)
Block(-3,24,-7,minecraft:concrete)
Block(-3,24,-6,minecraft:stonebrick:10)
Block(-3,24,-5,AIR:0)
Block(-3,24,-4,AIR:0)
Block(-3,24,-3,minecraft:stonebrick)
Block(-3,24,-2,minecraft:planks:3,../../../../Chests/Loot/manhunt_vagrant_scrap.nbt)
Block(-3,24,-1,quark:framed_glass_pane)
Block(-3,24,0,AIR:0)
Block(-3,24,1,AIR:0)
Block(-3,24,2,AIR:0)
Block(-3,24,3,minecraft:iron_bars:0)
Block(-3,24,4,AIR:0)
Block(-3,24,5,AIR:0)
Block(-3,24,6,minecraft:concrete)
Block(-3,24,7,DARK_OAK_DOOR:0)
Block(-3,24,8,minecraft:concrete)
Block(-3,25,-7,minecraft:concrete)
Block(-3,25,-6,minecraft:stonebrick:10)
Block(-3,25,-5,AIR:0)
Block(-3,25,-4,AIR:0)
Block(-3,25,-3,AIR:0)
Block(-3,25,-2,minecraft:bookshelf:0)
Block(-3,25,-1,quark:framed_glass_pane)
Block(-3,25,0,AIR:0)
Block(-3,25,1,AIR:0)
Block(-3,25,2,AIR:0)
Block(-3,25,3,minecraft:iron_bars:0)
Block(-3,25,4,AIR:0)
Block(-3,25,5,AIR:0)
Block(-3,25,6,minecraft:concrete)
Block(-3,25,7,DARK_OAK_DOOR:9)
Block(-3,25,8,minecraft:concrete)
Block(-3,26,-7,minecraft:concrete)
Block(-3,26,-6,AIR:0)
Block(-3,26,-5,AIR:0)
Block(-3,26,-4,AIR:0)
Block(-3,26,-3,AIR:0)
Block(-3,26,-2,minecraft:planks:3,../../../../Chests/Loot/manhunt_vagrant_scrap.nbt)
Block(-3,26,-1,quark:framed_glass_pane)
Block(-3,26,0,WEB:0)
Block(-3,26,1,AIR:0)
Block(-3,26,2,WEB:0)
Block(-3,26,3,minecraft:iron_bars:0)
Block(-3,26,4,WEB:0)
Block(-3,26,5,AIR:0)
Block(-3,26,6,minecraft:concrete)
Block(-3,26,7,minecraft:trapdoor:15)
Block(-3,26,8,minecraft:concrete)
Block(-3,27,-7,minecraft:concrete)
Block(-3,27,-6,minecraft:concrete)
Block(-3,27,-5,minecraft:concrete)
Block(-3,27,-4,minecraft:concrete)
Block(-3,27,-3,minecraft:concrete)
Block(-3,27,-2,minecraft:concrete)
Block(-3,27,-1,minecraft:concrete)
Block(-3,27,0,minecraft:concrete)
Block(-3,27,1,minecraft:concrete)
Block(-3,27,2,minecraft:concrete)
Block(-3,27,3,minecraft:concrete)
Block(-3,27,4,minecraft:concrete)
Block(-3,27,5,minecraft:concrete)
Block(-3,27,6,minecraft:concrete)
Block(-3,27,7,minecraft:concrete)
Block(-3,27,8,minecraft:concrete)
Block(-2,0,-7,minecraft:concrete)
Block(-2,0,-6,minecraft:concrete)
Block(-2,0,-5,minecraft:concrete)
Block(-2,0,-4,minecraft:concrete)
Block(-2,0,-3,minecraft:concrete)
Block(-2,0,-2,minecraft:concrete)
Block(-2,0,-1,minecraft:concrete)
Block(-2,0,0,minecraft:concrete)
Block(-2,0,1,minecraft:concrete)
Block(-2,0,2,minecraft:concrete)
Block(-2,0,3,minecraft:concrete)
Block(-2,0,4,minecraft:concrete)
Block(-2,0,5,minecraft:concrete)
Block(-2,0,6,minecraft:concrete)
Block(-2,0,7,minecraft:concrete)
Block(-2,0,8,minecraft:concrete)
Block(-2,1,-7,minecraft:concrete)
Block(-2,1,-6,minecraft:dirt:8)
Block(-2,1,-5,SOIL:7)
Block(-2,1,-4,STATIONARY_WATER:0)
Block(-2,1,-3,STATIONARY_WATER:0)
Block(-2,1,-2,DIRT:2)
Block(-2,1,-1,minecraft:sand)
Block(-2,1,0,minecraft:sand)
Block(-2,1,1,minecraft:dirt:8)
Block(-2,1,2,minecraft:concrete)
Block(-2,1,3,minecraft:stonebrick:14)
Block(-2,1,4,minecraft:stonebrick:14)
Block(-2,1,5,STATIONARY_WATER:0)
Block(-2,1,6,minecraft:stonebrick:14)
Block(-2,1,7,minecraft:dirt)
Block(-2,1,8,minecraft:stonebrick:14)
Block(-2,2,-7,minecraft:concrete)
Block(-2,2,-6,minecraft:leaves:13)
Block(-2,2,-5,CROPS:7)
Block(-2,2,-4,minecraft:water:2)
Block(-2,2,-3,AIR:0)
Block(-2,2,-2,SUGAR_CANE_BLOCK:0)
Block(-2,2,-1,AIR:0)
Block(-2,2,0,AIR:0)
Block(-2,2,1,minecraft:leaves:5)
Block(-2,2,2,minecraft:concrete)
Block(-2,2,3,AIR:0)
Block(-2,2,4,AIR:0)
Block(-2,2,5,AIR:0)
Block(-2,2,6,CROPS:7)
Block(-2,2,7,AIR:0)
Block(-2,2,8,CROPS:7)
Block(-2,3,-7,minecraft:concrete)
Block(-2,3,-6,AIR:0)
Block(-2,3,-5,AIR:0)
Block(-2,3,-4,AIR:0)
Block(-2,3,-3,AIR:0)
Block(-2,3,-2,SUGAR_CANE_BLOCK:0)
Block(-2,3,-1,AIR:0)
Block(-2,3,0,AIR:0)
Block(-2,3,1,minecraft:leaves:13)
Block(-2,3,2,minecraft:glass)
Block(-2,3,3,AIR:0)
Block(-2,3,4,AIR:0)
Block(-2,3,5,AIR:0)
Block(-2,3,6,AIR:0)
Block(-2,3,7,AIR:0)
Block(-2,3,8,AIR:0)
Block(-2,4,-7,minecraft:concrete)
Block(-2,4,-6,AIR:0)
Block(-2,4,-5,AIR:0)
Block(-2,4,-4,AIR:0)
Block(-2,4,-3,AIR:0)
Block(-2,4,-2,SUGAR_CANE_BLOCK:0)
Block(-2,4,-1,AIR:0)
Block(-2,4,0,AIR:0)
Block(-2,4,1,AIR:0)
Block(-2,4,2,minecraft:glass)
Block(-2,4,3,AIR:0)
Block(-2,4,4,AIR:0)
Block(-2,4,5,AIR:0)
Block(-2,4,6,AIR:0)
Block(-2,4,7,AIR:0)
Block(-2,4,8,AIR:0)
Block(-2,5,-7,minecraft:concrete)
Block(-2,5,-6,minecraft:concrete)
Block(-2,5,-5,minecraft:concrete)
Block(-2,5,-4,minecraft:concrete)
Block(-2,5,-3,minecraft:concrete)
Block(-2,5,-2,minecraft:concrete)
Block(-2,5,-1,minecraft:concrete)
Block(-2,5,0,minecraft:concrete)
Block(-2,5,1,minecraft:concrete)
Block(-2,5,2,minecraft:concrete)
Block(-2,5,3,AIR:0)
Block(-2,5,4,AIR:0)
Block(-2,5,5,AIR:0)
Block(-2,5,6,AIR:0)
Block(-2,5,7,AIR:0)
Block(-2,5,8,AIR:0)
Block(-2,6,-7,minecraft:concrete)
Block(-2,6,-6,quark:grate)
Block(-2,6,-5,quark:grate)
Block(-2,6,-4,minecraft:concrete)
Block(-2,6,-3,CONCRETE:15)
Block(-2,6,-2,CONCRETE:15)
Block(-2,6,-1,minecraft:concrete)
Block(-2,6,0,quark:grate)
Block(-2,6,1,quark:grate)
Block(-2,6,2,minecraft:concrete)
Block(-2,6,3,AIR:0)
Block(-2,6,4,AIR:0)
Block(-2,6,5,AIR:0)
Block(-2,6,6,AIR:0)
Block(-2,6,7,AIR:0)
Block(-2,6,8,AIR:0)
Block(-2,7,-7,minecraft:concrete)
Block(-2,7,-6,AIR:0)
Block(-2,7,-5,AIR:0)
Block(-2,7,-4,AIR:0)
Block(-2,7,-3,minecraft:stone)
Block(-2,7,-2,AIR:0)
Block(-2,7,-1,AIR:0)
Block(-2,7,0,AIR:0)
Block(-2,7,1,AIR:0)
Block(-2,7,2,minecraft:concrete)
Block(-2,7,3,AIR:0)
Block(-2,7,4,AIR:0)
Block(-2,7,5,AIR:0)
Block(-2,7,6,AIR:0)
Block(-2,7,7,AIR:0)
Block(-2,7,8,AIR:0)
Block(-2,8,-7,minecraft:concrete)
Block(-2,8,-6,AIR:0)
Block(-2,8,-5,AIR:0)
Block(-2,8,-4,AIR:0)
Block(-2,8,-3,AIR:0)
Block(-2,8,-2,AIR:0)
Block(-2,8,-1,AIR:0)
Block(-2,8,0,AIR:0)
Block(-2,8,1,AIR:0)
Block(-2,8,2,minecraft:concrete)
Block(-2,8,3,AIR:0)
Block(-2,8,4,AIR:0)
Block(-2,8,5,AIR:0)
Block(-2,8,6,AIR:0)
Block(-2,8,7,AIR:0)
Block(-2,8,8,minecraft:stonebrick:2)
Block(-2,9,-7,minecraft:concrete)
Block(-2,9,-6,AIR:0)
Block(-2,9,-5,AIR:0)
Block(-2,9,-4,AIR:0)
Block(-2,9,-3,AIR:0)
Block(-2,9,-2,AIR:0)
Block(-2,9,-1,AIR:0)
Block(-2,9,0,AIR:0)
Block(-2,9,1,AIR:0)
Block(-2,9,2,minecraft:concrete)
Block(-2,9,3,AIR:0)
Block(-2,9,4,AIR:0)
Block(-2,9,5,AIR:0)
Block(-2,9,6,AIR:0)
Block(-2,9,7,AIR:0)
Block(-2,9,8,minecraft:stonebrick:2)
Block(-2,10,-7,minecraft:concrete)
Block(-2,10,-6,AIR:0)
Block(-2,10,-5,AIR:0)
Block(-2,10,-4,AIR:0)
Block(-2,10,-3,AIR:0)
Block(-2,10,-2,AIR:0)
Block(-2,10,-1,AIR:0)
Block(-2,10,0,AIR:0)
Block(-2,10,1,AIR:0)
Block(-2,10,2,minecraft:concrete)
Block(-2,10,3,minecraft:concrete)
Block(-2,10,4,minecraft:concrete)
Block(-2,10,5,minecraft:concrete)
Block(-2,10,6,minecraft:concrete)
Block(-2,10,7,minecraft:concrete)
Block(-2,10,8,minecraft:concrete)
Block(-2,11,-7,minecraft:concrete)
Block(-2,11,-6,minecraft:concrete)
Block(-2,11,-5,minecraft:concrete)
Block(-2,11,-4,minecraft:concrete)
Block(-2,11,-3,minecraft:concrete)
Block(-2,11,-2,minecraft:concrete)
Block(-2,11,-1,minecraft:concrete)
Block(-2,11,0,minecraft:concrete)
Block(-2,11,1,minecraft:concrete)
Block(-2,11,2,minecraft:concrete)
Block(-2,11,3,minecraft:concrete)
Block(-2,11,4,minecraft:concrete)
Block(-2,11,5,minecraft:concrete)
Block(-2,11,6,minecraft:concrete)
Block(-2,11,7,minecraft:concrete)
Block(-2,11,8,minecraft:concrete)
Block(-2,12,-7,minecraft:concrete)
Block(-2,12,-6,minecraft:concrete)
Block(-2,12,-5,minecraft:concrete)
Block(-2,12,-4,minecraft:concrete)
Block(-2,12,-3,minecraft:concrete)
Block(-2,12,-2,minecraft:concrete)
Block(-2,12,-1,minecraft:concrete)
Block(-2,12,0,minecraft:concrete)
Block(-2,12,1,minecraft:concrete)
Block(-2,12,2,minecraft:concrete)
Block(-2,12,3,minecraft:concrete)
Block(-2,12,4,minecraft:concrete)
Block(-2,12,5,minecraft:concrete)
Block(-2,12,6,minecraft:concrete)
Block(-2,12,7,AIR:0)
Block(-2,12,8,AIR:0)
Block(-2,13,-7,minecraft:concrete)
Block(-2,13,-6,minecraft:concrete)
Block(-2,13,-5,minecraft:concrete)
Block(-2,13,-4,minecraft:concrete)
Block(-2,13,-3,minecraft:concrete)
Block(-2,13,-2,minecraft:concrete)
Block(-2,13,-1,minecraft:concrete)
Block(-2,13,0,minecraft:concrete)
Block(-2,13,1,minecraft:concrete)
Block(-2,13,2,minecraft:concrete)
Block(-2,13,3,minecraft:concrete)
Block(-2,13,4,minecraft:concrete)
Block(-2,13,5,minecraft:concrete)
Block(-2,13,6,minecraft:concrete)
Block(-2,13,7,AIR:0)
Block(-2,13,8,AIR:0)
Block(-2,14,-7,minecraft:concrete)
Block(-2,14,-6,minecraft:concrete)
Block(-2,14,-5,minecraft:concrete)
Block(-2,14,-4,minecraft:concrete)
Block(-2,14,-3,minecraft:concrete)
Block(-2,14,-2,minecraft:concrete)
Block(-2,14,-1,minecraft:concrete)
Block(-2,14,0,minecraft:concrete)
Block(-2,14,1,minecraft:concrete)
Block(-2,14,2,minecraft:concrete)
Block(-2,14,3,minecraft:concrete)
Block(-2,14,4,minecraft:concrete)
Block(-2,14,5,minecraft:concrete)
Block(-2,14,6,minecraft:concrete)
Block(-2,14,7,AIR:0)
Block(-2,14,8,AIR:0)
Block(-2,15,-7,minecraft:concrete)
Block(-2,15,-6,minecraft:concrete)
Block(-2,15,-5,minecraft:concrete)
Block(-2,15,-4,minecraft:concrete)
Block(-2,15,-3,minecraft:concrete)
Block(-2,15,-2,minecraft:concrete)
Block(-2,15,-1,minecraft:concrete)
Block(-2,15,0,minecraft:concrete)
Block(-2,15,1,minecraft:concrete)
Block(-2,15,2,minecraft:concrete)
Block(-2,15,3,minecraft:concrete)
Block(-2,15,4,minecraft:concrete)
Block(-2,15,5,minecraft:concrete)
Block(-2,15,6,minecraft:concrete)
Block(-2,15,7,AIR:0)
Block(-2,15,8,AIR:0)
Block(-2,16,-7,minecraft:concrete)
Block(-2,16,-6,CARPET:15)
Block(-2,16,-5,CARPET:15)
Block(-2,16,-4,CARPET:15)
Block(-2,16,-3,CARPET:15)
Block(-2,16,-2,CARPET:15)
Block(-2,16,-1,CARPET:15)
Block(-2,16,0,CARPET:15)
Block(-2,16,1,CARPET:15)
Block(-2,16,2,CARPET:15)
Block(-2,16,3,minecraft:concrete)
Block(-2,16,4,minecraft:concrete)
Block(-2,16,5,minecraft:concrete)
Block(-2,16,6,minecraft:concrete)
Block(-2,16,7,AIR:0)
Block(-2,16,8,AIR:0)
Block(-2,17,-7,minecraft:concrete)
Block(-2,17,-6,AIR:0)
Block(-2,17,-5,AIR:0)
Block(-2,17,-4,AIR:0)
Block(-2,17,-3,AIR:0)
Block(-2,17,-2,AIR:0)
Block(-2,17,-1,AIR:0)
Block(-2,17,0,AIR:0)
Block(-2,17,1,AIR:0)
Block(-2,17,2,AIR:0)
Block(-2,17,3,minecraft:concrete)
Block(-2,17,4,minecraft:tallgrass)
Block(-2,17,5,AIR:0)
Block(-2,17,6,minecraft:concrete)
Block(-2,17,7,AIR:0)
Block(-2,17,8,AIR:0)
Block(-2,18,-7,minecraft:concrete)
Block(-2,18,-6,AIR:0)
Block(-2,18,-5,AIR:0)
Block(-2,18,-4,AIR:0)
Block(-2,18,-3,AIR:0)
Block(-2,18,-2,AIR:0)
Block(-2,18,-1,AIR:0)
Block(-2,18,0,AIR:0)
Block(-2,18,1,AIR:0)
Block(-2,18,2,WEB:0)
Block(-2,18,3,minecraft:concrete)
Block(-2,18,4,AIR:0)
Block(-2,18,5,AIR:0)
Block(-2,18,6,minecraft:concrete)
Block(-2,18,7,AIR:0)
Block(-2,18,8,AIR:0)
Block(-2,19,-7,minecraft:concrete)
Block(-2,19,-6,minecraft:concrete)
Block(-2,19,-5,minecraft:concrete)
Block(-2,19,-4,minecraft:concrete)
Block(-2,19,-3,minecraft:concrete)
Block(-2,19,-2,minecraft:concrete)
Block(-2,19,-1,minecraft:concrete)
Block(-2,19,0,minecraft:concrete)
Block(-2,19,1,minecraft:concrete)
Block(-2,19,2,minecraft:concrete)
Block(-2,19,3,minecraft:concrete)
Block(-2,19,4,minecraft:concrete)
Block(-2,19,5,minecraft:concrete)
Block(-2,19,6,minecraft:concrete)
Block(-2,19,7,AIR:0)
Block(-2,19,8,AIR:0)
Block(-2,20,-7,minecraft:concrete)
Block(-2,20,-6,minecraft:concrete)
Block(-2,20,-5,quark:framed_glass_pane)
Block(-2,20,-4,AIR:0)
Block(-2,20,-3,quark:framed_glass_pane)
Block(-2,20,-2,quark:framed_glass_pane)
Block(-2,20,-1,quark:framed_glass)
Block(-2,20,0,AIR:0)
Block(-2,20,1,AIR:0)
Block(-2,20,2,AIR:0)
Block(-2,20,3,minecraft:concrete)
Block(-2,20,4,minecraft:concrete)
Block(-2,20,5,minecraft:concrete)
Block(-2,20,6,minecraft:concrete)
Block(-2,20,7,AIR:0)
Block(-2,20,8,AIR:0)
Block(-2,21,-7,minecraft:concrete)
Block(-2,21,-6,minecraft:concrete)
Block(-2,21,-5,quark:framed_glass_pane)
Block(-2,21,-4,AIR:0)
Block(-2,21,-3,quark:framed_glass_pane)
Block(-2,21,-2,quark:framed_glass_pane)
Block(-2,21,-1,quark:framed_glass)
Block(-2,21,0,AIR:0)
Block(-2,21,1,AIR:0)
Block(-2,21,2,AIR:0)
Block(-2,21,3,minecraft:concrete)
Block(-2,21,4,minecraft:concrete)
Block(-2,21,5,minecraft:concrete)
Block(-2,21,6,minecraft:concrete)
Block(-2,21,7,AIR:0)
Block(-2,21,8,AIR:0)
Block(-2,22,-7,minecraft:concrete)
Block(-2,22,-6,minecraft:concrete)
Block(-2,22,-5,quark:framed_glass_pane)
Block(-2,22,-4,quark:framed_glass_pane)
Block(-2,22,-3,quark:framed_glass_pane)
Block(-2,22,-2,quark:framed_glass_pane)
Block(-2,22,-1,quark:framed_glass)
Block(-2,22,0,AIR:0)
Block(-2,22,1,AIR:0)
Block(-2,22,2,AIR:0)
Block(-2,22,3,minecraft:concrete)
Block(-2,22,4,minecraft:concrete)
Block(-2,22,5,minecraft:concrete)
Block(-2,22,6,minecraft:concrete)
Block(-2,22,7,AIR:0)
Block(-2,22,8,WEB:0)
